File: data/doubleLayers/dl_1-25/ppms/data/DD205_3_HYST_100OE_50K.DAT
[Header]
; VSM Data File (default extension .dat)
; Copyright (c) 2003-2013, Quantum Design, Inc. All rights reserved.
TITLE,
FILEOPENTIME,22204882.94,09/15/2018,9:00 am
BYAPP,VSM,2.0,2.0
INFO,PPMS VSM Option Release 1.4.10 Build 1,APPNAME
INFO,Quantum Design Linear Motor Servo Controller,MOTOR_MODULE_NAME
INFO,3101-100 M1,MOTOR_HW_VERSION
INFO,MMC1014,MOTOR_SERIAL_NUMBER
INFO,SRV No X-over 01.03.11,MOTOR_SOFTWARE_VERSION
INFO,Quantum Design VSM Detection Module,VSM_MODULE_NAME
INFO,3101-150 F0,VSM_HW_VERSION
INFO,VSM707,VSM_SERIAL_NUMBER
INFO,VSM No X-over 01.02.05 May 20 2008 13:51:47,VSM_SOFTWARE_VERSION
INFO,704,PREAMP_SERIAL_NUMBER
INFO,822,COIL_SERIAL_NUMBER
INFO,0,MOMENT_UNITS
INFO,CoFe2O4,SAMPLE_MATERIAL
INFO,Double Layer blue,SAMPLE_COMMENT
INFO,,SAMPLE_MASS
INFO,,SAMPLE_VOLUME
INFO,,SAMPLE_MOLECULAR_WEIGHT
INFO,,SAMPLE_SIZE
INFO,,SAMPLE_SHAPE
DATATYPE,COMMENT,1
DATATYPE,TIME,2
STARTUPAXIS,X,2
STARTUPAXIS,Y1,5
[Data]
Comment,Time Stamp (sec),Temperature (K),Magnetic Field (Oe),Moment (emu),M. Std. Err. (emu),Transport Action,Averaging Time (sec),Frequency (Hz),Peak Amplitude (mm),Center Position (mm),Coil Signal' (mV),Coil Signal" (mV),Range (mV),M. Quad. Signal (emu),M. Raw' (emu),M. Raw" (emu),Min. Temperature (K),Max. Temperature (K),Min. Field (Oe),Max. Field (Oe),Mass (grams),Motor Lag (deg),Pressure (Torr),VSM Status (code),Motor Status (code),Measure Status (code),Measure Count,PPMS Status (code),System Temp. (K),System Field (Oe),Sample Position (deg),Bridge 1 Resistance (ohms),Bridge 1 Excitation (에),Bridge 2 Resistance (ohms),Bridge 2 Excitation (에),Bridge 3 Resistance (ohms),Bridge 3 Excitation (에),Bridge 4 Resistance (ohms),Bridge 4 Excitation (에),Signal 1 Vin (V),Signal 2 Vin (V),Digital Inputs (code),Drive 1 Iout (mA),Drive 1 Ipower (W),Drive 2 Iout (mA),Drive 2 Ipower (W),Pressure (),Map 20 (),Map 21 (),Map 22 (),Map 23 (),Map 24 (),Map 25 (),Map 26 (),Map 27 (),Map 28 (),Map 29 ()
,22204898.88,50.009182,-0.0152237731963396,,,2,,,,17.1599995830655,,,,,,,50.009182,50.009182,-0.0152237731963396,-0.0152237731963396,,,19.112494,,,,-99999999,4369,50.1835,-0.0152237731963396,,,,,,,,,,,,,,,,,,,,,,,50.009182,,,,
,22205068.04,49.9983311,4758.28662109375,7.49022672156625E-5,3.29647297247506E-7,1,0.999253354069792,40.0298881530762,1.99791903670004,17.1499997377396,0.000846736760673554,0.000149126484138719,0.25,-3.00065943824784E-7,7.48811694230865E-5,2.5742823988442E-7,49.9981194,49.9985428,4750.8935546875,4765.6796875,56.4124751184483,20.5312415997073,18.732843,0,0,0,40,4449,50.17965,4758.28662109375,,,,,,,,,,,,,0,,,,-0.0049,,,,,,49.9983311,,,,
,22205168.57,49.9941101,9784.810546875,6.55285835165128E-5,3.55183571468231E-7,1,0.999253354069792,40.0298881530762,1.99796224890692,17.1499997377396,0.000741185400115306,0.000129318621385038,0.25,-3.66575703425392E-7,6.55273374192672E-5,1.20777078406155E-7,49.9941101,49.9941101,9777.5185546875,9792.1025390625,56.6344576179098,20.5368501379722,19.112494,0,0,0,40,4449,50.18915,9784.810546875,,,,,,,,,,,,,0,,,,0,,,,,,49.9941101,,,,
,22205266.865,50.000412,14694.4291992187,5.63043715733034E-5,3.05404173806744E-7,1,0.999253354069792,40.0298881530762,1.99799229916597,17.1499997377396,0.000637833297087531,0.000106666149399192,0.25,-7.10382564882942E-7,5.63208605905806E-5,-2.92576017511384E-7,50.000412,50.000412,14684.4111328125,14704.447265625,56.6758839294291,20.5404461995614,18.732843,0,0,0,40,4449,50.1904,14694.4291992187,,,,,,,,,,,,,0,,,,-0.00245,,,,,,50.000412,,,,
,22205368.29,50.0060654,19764.0400390625,4.73115617113521E-5,4.83613364513946E-7,1,0.999253354069792,40.0298881530762,1.99798890004099,17.1499997377396,0.000535837424332202,9.1141540186248E-5,0.25,-4.64091304041893E-7,4.73373690913583E-5,-1.14277515948456E-7,50.0060654,50.0060654,19756.46875,19771.611328125,56.5695824508137,20.537896278781,19.492144,0,0,0,40,4449,50.18425,19764.0400390625,,,,,,,,,,,,,0,,,,-0.0049,,,,,,50.0060654,,,,
,22205470.305,50.0077248,24861.37890625,3.77769712248252E-5,6.45604684797549E-7,1,0.999253354069792,40.0298881530762,1.99815144247451,17.1499997377396,0.000431007030775762,5.61268208084942E-5,0.25,-1.84335430143389E-6,3.78189105179627E-5,-1.56658443793165E-6,50.0077248,50.0077248,24858.951171875,24863.806640625,56.5789619930445,20.540203795431,19.112494,0,0,0,40,4449,50.1814,24861.37890625,,,,,,,,,,,,,0,,,,-0.0049,,,,,,50.0077248,,,,
,22205570.22,50.0058174,29856.626953125,2.79140754029995E-5,5.34591673041031E-7,1,0.999253354069792,40.0298881530762,1.99797157226115,17.1499997377396,0.000319118405990796,3.82484319038303E-5,0.25,-1.64651631038104E-6,2.79546020834856E-5,-1.44390572721578E-6,50.0058174,50.0058174,29851.73046875,29861.5234375,56.7517018957945,20.5377976937286,19.492144,0,0,0,40,4449,50.1738,29856.626953125,,,,,,,,,,,,,0,,,,-0.0049,,,,,,50.0058174,,,,
,22205662.205,50.0051117,34454.419921875,1.99270129657801E-5,5.22445943239414E-7,1,0.999253354069792,40.0298881530762,1.99805646844935,17.1499997377396,0.00023032133666598,1.37154490211003E-5,0.25,-2.37599149842283E-6,1.99694868213039E-5,-2.23414250833563E-6,50.0051117,50.0051117,34449.2578125,34459.58203125,56.7391958394868,20.5402130448224,19.492144,0,0,0,40,4449,50.1695,34454.419921875,,,,,,,,,,,,,0,,,,0,,,,,,50.0051117,,,,
,22205757.66,50.0046272,39226.353515625,1.05688481640785E-5,5.62104637820821E-7,1,0.999253354069792,40.0298881530762,1.99802147291586,17.1499997377396,0.000124548901796475,-5.85862444448209E-6,0.25,-2.42002658736535E-6,1.0602288331055E-5,-2.34748321306679E-6,50.0046272,50.0046272,39216.16015625,39236.546875,56.8275198621599,20.5420748441284,19.112494,0,0,0,40,4449,50.1652,39226.353515625,,,,,,,,,,,,,0,,,,0.00245,,,,,,50.0046272,,,,
,22205851.9,50.0032158,43933.90625,1.49113643232009E-6,5.08476723792768E-7,1,0.999253354069792,40.0298881530762,1.99806866349465,17.1499997377396,2.12169934086827E-5,-2.10586662526847E-5,0.25,-2.12842092443981E-6,1.50895677790597E-6,-2.12149619454016E-6,50.0032158,50.0032158,43924.01171875,43943.80078125,56.7243448976214,20.5408832971602,18.732843,0,0,0,40,4449,50.16535,43933.90625,,,,,,,,,,,,,0,,,,0.00245,,,,,,50.0032158,,,,
,22205943.4,50.0031967,48507.03125,-8.99504662547915E-6,8.93445045342433E-7,1,0.999253354069792,40.0298881530762,1.99803062615221,17.1499997377396,-9.60228082020003E-5,-5.07537737202942E-5,0.25,-2.86429295237844E-6,-8.99255852263274E-6,-2.93360168869943E-6,50.0031967,50.0031967,48502.0078125,48512.0546875,56.8681645451599,20.538400784529,19.492144,0,0,0,40,4449,50.1614,48507.03125,,,,,,,,,,,,,0,,,,0,,,,,,50.0031967,,,,
,22206035.205,50.0033703,53097.10546875,-1.71574148147671E-5,7.04699662249498E-7,1,0.999253354069792,40.0298881530762,1.99798132633415,17.1499997377396,-0.00018853235707884,-6.71505621939864E-5,0.25,-2.84436606882418E-6,-1.71751510101679E-5,-2.97072875285689E-6,50.0032425,50.0034981,53094.5859375,53099.625,56.4437402592175,20.5396550955329,19.112494,0,0,0,40,4449,50.1587,53097.10546875,,,,,,,,,,,,,0,,,,-0.0049,,,,,,50.0033703,,,,
,22206130.065,50.0030251,57836.740234375,-2.36819281602383E-5,7.38370764065766E-7,1,0.999253354069792,40.0298881530762,1.9980524335896,17.1499997377396,-0.000261505901926531,-8.5970720378378E-5,0.25,-3.33310563722423E-6,-2.37159643815612E-5,-3.50500222777942E-6,50.0030251,50.0030251,57831.73046875,57841.75,56.8243933480829,20.5420378516581,19.871798,0,0,0,40,4449,50.1563,57836.740234375,,,,,,,,,,,,,0,,,,-0.0049,,,,,,50.0030251,,,,
,22206222.04,50.0029144,62435.646484375,-3.36992276566309E-5,7.78316821814236E-7,1,0.999253354069792,40.0298881530762,1.99795065949009,17.1499997377396,-0.000373954732172879,-0.000112488382844939,0.25,-3.875045449692E-6,-3.37608131031905E-5,-4.11552713485083E-6,50.0029144,50.0029144,62430.33203125,62440.9609375,56.6321127323521,20.541848283104,19.492144,0,0,0,40,4449,50.1571,62435.646484375,,,,,,,,,,,,,0,,,,0,,,,,,50.0029144,,,,
,22206318.105,50.0036469,67238.27734375,-4.15045980015734E-5,7.76009346567199E-7,1,0.999253354069792,40.0298881530762,1.9980370410257,17.1499997377396,-0.000459478050367942,-0.000145306647121372,0.25,-5.37013015351722E-6,-4.1585229227805E-5,-5.6652026178946E-6,50.0036469,50.0036469,67223.140625,67253.4140625,56.8931766577752,20.5400804580162,19.492144,0,0,0,40,4449,50.15345,67238.27734375,,,,,,,,,,,,,0,,,,-0.00245,,,,,,50.0036469,,,,
,22206412.68,50.0042076,71963.4375,-4.87354888207073E-5,9.47638635002373E-7,1,0.999253354069792,40.0298881530762,1.99813028779744,17.1499997377396,-0.000544171366968438,-0.000145519434733914,0.25,-4.09233574594854E-6,-4.8854717019515E-5,-4.42889093043351E-6,50.0042076,50.0042076,71956.0859375,71970.7890625,56.6837002146214,20.5390914035843,19.492144,0,0,0,40,4449,50.14795,71963.4375,,,,,,,,,,,,,0,,,,0.00245,,,,,,50.0042076,,,,
,22206505.305,50.00395205,76593.63671875,-5.73490353032057E-5,8.80979976091896E-7,1,0.999253354069792,40.0298881530762,1.99803958134676,17.1499997377396,-0.000644361889591953,-0.000149387492974551,0.25,-2.89166423690904E-6,-5.75126186499822E-5,-3.27714468940303E-6,50.0038834,50.0040207,76588.640625,76598.6328125,56.9291315696599,20.5392810809417,19.492144,0,0,0,40,4449,50.14625,76593.63671875,,,,,,,,,,,,,0,,,,-0.0049,,,,,,50.00395205,,,,
,22206600.255,50.004097,81339.796875,-6.50511413277961E-5,7.43791089339288E-7,1,0.999253354069792,40.0298881530762,1.99805903433796,17.1499997377396,-0.000730506559577372,-0.000172446379659643,0.25,-3.54771513233185E-6,-6.52465932413017E-5,-3.98018445995832E-6,50.004097,50.004097,81337.328125,81342.265625,56.6719757868329,20.5396397291779,19.492144,0,0,0,40,4449,50.14215,81339.796875,,,,,,,,,,,,,0,,,,-0.0049,,,,,,50.004097,,,,
,22206693.985,50.0029888,86025.10546875,-7.12889889134201E-5,1.01037161053536E-6,1,0.999253354069792,40.0298881530762,1.99797451878839,17.1499997377396,-0.000803325600315738,-0.000174115357001835,0.25,-2.581933838115E-6,-7.15235767857255E-5,-3.04504282468263E-6,50.0029297,50.0030479,86020.140625,86030.0703125,56.6344576179098,20.5381986326802,19.492144,0,0,0,40,4449,50.14255,86025.10546875,,,,,,,,,,,,,0,,,,0,,,,,,50.0029888,,,,
,22206806.76,50.0024509,89428.578125,-7.34794615715647E-5,7.97967276764805E-7,1,0.999253354069792,40.0298881530762,1.99802679446675,17.1499997377396,-0.000821749192163658,-0.000215103556747474,0.25,-5.80587593300923E-6,-7.37100111482563E-5,-6.28978548963491E-6,50.002346,50.0025558,89416.0390625,89441.1171875,56.5969394489868,20.5399295379365,19.492144,0,0,0,40,4449,50.13935,89428.578125,,,,,,,,,,,,,0,,,,0.00245,,,,,,50.0024509,,,,
,22206897.33,50.0007858,84902.00390625,-6.24084515520215E-5,9.7947126971354E-7,1,0.999253354069792,40.0298881530762,1.99794325074065,17.1499997377396,-0.000694622873662136,-0.000200387058869487,0.25,-6.48840247663861E-6,-6.25843125348852E-5,-6.90991463750928E-6,50.0007858,50.0007858,84899.671875,84904.3359375,56.7079306987175,20.5389233673362,19.871798,0,0,0,40,4449,50.1401,84902.00390625,,,,,,,,,,,,,0,,,,0,,,,,,50.0007858,,,,
,22206990.36,50.0009956,80250.16015625,-4.82828674513415E-5,7.22403345916921E-7,1,0.999253354069792,40.0298881530762,1.99799261080566,17.1499997377396,-0.000539475889533196,-0.000142984253205446,0.25,-3.95479778920143E-6,-4.84173991644743E-5,-4.28114961787585E-6,50.0009956,50.0009956,80245.484375,80254.8359375,56.8705094307176,20.5422626931661,19.492144,0,0,0,40,4449,50.1405,80250.16015625,,,,,,,,,,,,,0,,,,0,,,,,,50.0009956,,,,
,22207083.405,50.0002022,75599.5703125,-3.61158971630197E-5,8.845025768227E-7,1,0.999253354069792,40.0298881530762,1.99813684341916,17.1499997377396,-0.00040071293298695,-0.000122407767759913,0.25,-4.31883960061669E-6,-3.6201038950862E-5,-4.57012602013311E-6,50.0002022,50.0002022,75591.9609375,75607.1796875,56.6594697305252,20.5422916935892,19.871798,0,0,0,40,4449,50.13725,75599.5703125,,,,,,,,,,,,,0,,,,-0.00245,,,,,,50.0002022,,,,
,22207179.545,50.0009613,70793.69921875,-2.38739661956713E-5,1.0777329332748E-6,1,0.999253354069792,40.0298881530762,1.99810875870997,17.1499997377396,-0.000257167935771798,-0.000123601575506456,0.25,-6.61959635032102E-6,-2.39003722893737E-5,-6.79858238797218E-6,50.0009613,50.0009613,70783.6171875,70803.78125,56.7688977232175,20.542967643802,19.112494,0,0,0,40,4449,50.1381,70793.69921875,,,,,,,,,,,,,0,,,,0,,,,,,50.0009613,,,,
,22207273.095,50.0002098,66118.37890625,-1.19923016789597E-5,9.96859211354843E-7,1,0.999253354069792,40.0298881530762,1.99806324690331,17.1499997377396,-0.000128895808258319,-6.34847904998209E-5,0.25,-3.44856892703501E-6,-1.20021493312862E-5,-3.53926846376956E-6,50.0002098,50.0002098,66110.78125,66125.9765625,56.7345060683714,20.5412189349599,19.871798,0,0,0,40,4449,50.14115,66118.37890625,,,,,,,,,,,,,0,,,,0.0049,,,,,,50.0002098,,,,
,22207367.295,50.0005188,61410.12109375,-2.14218723807949E-6,6.09898638309139E-7,1,0.999253354069792,40.0298881530762,1.99804035207265,17.1499997377396,-1.32161113497064E-5,-6.59123286603777E-5,0.25,-5.43232512265382E-6,-2.11043853716943E-6,-5.46094866091702E-6,50.0005188,50.0005188,61407.6875,61412.5546875,56.8290831191983,20.541103536666,19.871798,0,0,0,40,4449,50.1341,61410.12109375,,,,,,,,,,,,,0,,,,0,,,,,,50.0005188,,,,
,22207460.75,49.99946785,56737.28515625,9.19375219148977E-6,6.3888487260861E-7,1,0.999253354069792,40.0298881530762,1.99798652496155,17.1499997377396,0.000112132753359451,-2.57221515820988E-5,0.25,-3.9229310007096E-6,9.24266451089404E-6,-3.86838473104163E-6,49.9992752,49.9996605,56724.91015625,56749.66015625,56.5953761919483,20.5425763369578,19.492144,0,0,0,40,4449,50.14205,56737.28515625,,,,,,,,,,,,,0,,,,0.00245,,,,,,49.99946785,,,,
,22207554.56,49.9994736,52049.703125,1.89799145976823E-5,7.12968711339382E-7,1,0.999253354069792,40.0298881530762,1.99793368961401,17.1499997377396,0.000221449033859048,2.49438252604645E-6,0.25,-3.19231202060513E-6,1.90429843291628E-5,-3.06591801830109E-6,49.9994736,49.9994736,52042.359375,52057.046875,56.7118388413137,20.5399844036151,19.871798,0,0,0,40,4449,50.1423,52049.703125,,,,,,,,,,,,,0,,,,0.0049,,,,,,49.9994736,,,,
,22207647.055,50.0002899,47427.17578125,2.7696076976942E-5,5.47034770518055E-7,1,0.999253354069792,40.0298881530762,1.99799303788738,17.1499997377396,0.000320681577770978,1.70115907651481E-5,0.25,-3.47945841081883E-6,2.77739307909633E-5,-3.28966028067564E-6,50.0002899,50.0002899,47419.6875,47434.6640625,56.8345545188329,20.5420810470345,19.492144,0,0,0,40,4449,50.13925,47427.17578125,,,,,,,,,,,,,0,,,,-0.00245,,,,,,50.0002899,,,,
,22207740.015,50.00089645,42779.185546875,3.61958986908083E-5,5.62604903968903E-7,1,0.999253354069792,40.0298881530762,1.99801547021277,17.1499997377396,0.000414310648663016,4.83399481759567E-5,0.25,-2.24316816171085E-6,3.62731114301963E-5,-1.98768517822383E-6,50.0008507,50.0009422,42776.78515625,42781.5859375,56.926005055583,20.5424533001703,19.871798,0,0,0,40,4449,50.14135,42779.185546875,,,,,,,,,,,,,0,,,,-0.00245,,,,,,50.00089645,,,,
,22207833.02,49.9995766,38129.072265625,4.53241557531039E-5,4.04327641569542E-7,1,0.999253354069792,40.0298881530762,1.9980444776739,17.1499997377396,0.000519235858104302,5.7436928687753E-5,0.25,-3.08401425795496E-6,4.54121546462332E-5,-2.76096469373434E-6,49.9995766,49.9995766,38124.21484375,38133.9296875,57.0979633298137,20.5415848851728,19.871798,0,0,0,40,4449,50.13575,38129.072265625,,,,,,,,,,,,,0,,,,0.0049,,,,,,49.9995766,,,,
,22207926.635,49.9999237,33454.419921875,5.3282716352754E-5,5.54272695619997E-7,1,0.999253354069792,40.0298881530762,1.99810341135376,17.1499997377396,0.000609209725226604,7.34529007562133E-5,0.25,-3.10322427862355E-6,5.33695307164835E-5,-2.71895807835997E-6,49.9999237,49.9999237,33446.9921875,33461.84765625,56.8486238321791,20.5443703103078,19.871798,0,0,0,40,4449,50.1414,33454.419921875,,,,,,,,,,,,,0,,,,-0.00245,,,,,,49.9999237,,,,
,22208018.47,49.9997482,28864.3828125,6.02816665008199E-5,4.32278874450273E-7,1,0.999253354069792,40.0298881530762,1.99811794518983,17.1499997377396,0.000685822935170553,0.000101106361734136,0.25,-1.92042918276433E-6,6.03535251848861E-5,-1.4804273517651E-6,49.9997482,49.9997482,28859.478515625,28869.287109375,57.017455592333,20.5461251596359,19.112494,0,0,0,40,4449,50.14105,28864.3828125,,,,,,,,,,,,,0,,,,-0.00245,,,,,,49.9997482,,,,
,22208111.035,49.9996147,24236.6953125,6.56327505319328E-5,4.27206903167014E-7,1,0.999253354069792,40.0298881530762,1.99812230168445,17.1499997377396,0.000746324372872468,0.000111116839116623,0.25,-1.99966133111263E-6,6.56937728224997E-5,-1.51738302579673E-6,49.9996147,49.9996147,24231.72265625,24241.66796875,56.9525804252368,20.5435850592973,20.251448,0,0,0,40,4449,50.1368,24236.6953125,,,,,,,,,,,,,0,,,,0,,,,,,49.9996147,,,,
,22208204.35,49.9998627,19572.09765625,7.20204885565006E-5,3.93990576154633E-7,1,0.999253354069792,40.0298881530762,1.99817368375069,17.1499997377396,0.000817211354704634,0.000130568044487159,0.25,-1.43032375377984E-6,7.20634638784773E-5,-8.9794678550591E-7,49.9998627,49.9998627,19564.580078125,19579.615234375,56.8744175733137,20.5452176731591,19.871798,0,0,0,40,4449,50.1379,19572.09765625,,,,,,,,,,,,,0,,,,0,,,,,,49.9998627,,,,
,22208294.62,50.0001907,15061.845703125,7.62897165301276E-5,3.75163595434406E-7,1,0.999253354069792,40.0298881530762,1.99822930031825,17.1499997377396,0.000864569171192096,0.000143249931101504,0.25,-1.07703724746251E-6,7.63133097068421E-5,-5.10986620916266E-7,50.0001907,50.0001907,15056.5712890625,15067.1201171875,56.648526931256,20.5459468852779,19.871798,0,0,0,40,4449,50.14,15061.845703125,,,,,,,,,,,,,0,,,,-0.00245,,,,,,50.0001907,,,,
,22208392.705,50.0002823,10159.5087890625,8.10077192917096E-5,3.18241937743911E-7,1,0.999253354069792,40.0298881530762,1.99822872762505,17.1499997377396,0.000917009634422512,0.00015644273523478,0.25,-7.57954068618086E-7,8.10088188310369E-5,-1.55477817768597E-7,50.0002823,50.0002823,10149.482421875,10169.53515625,57.027616763083,20.5439745821274,19.492144,0,0,0,40,4449,50.1405,10159.5087890625,,,,,,,,,,,,,0,,,,0,,,,,,50.0002823,,,,
,22208486.075,49.9996567,5492.1357421875,8.37603406462942E-5,3.02834649223954E-7,1,0.999253354069792,40.0298881530762,1.99835272299324,17.1499997377396,0.000946871261826245,0.000168019641747093,0.25,-2.27656819208061E-7,8.3737844307093E-5,3.95721660026877E-7,49.9996567,49.9996567,5482.10107421875,5502.17041015625,56.8736359447945,20.5471884208892,19.871798,0,0,0,40,4449,50.1425,5492.1357421875,,,,,,,,,,,,,0,,,,0,,,,,,49.9996567,,,,
,22208579.995,49.9999962,798.139068603516,8.22337756053546E-5,2.85901653859056E-7,1,0.999253354069792,40.0298881530762,1.99830158262989,17.1499997377396,0.000929674624823635,0.000163429647488244,0.25,-3.55468548025071E-7,8.2196260835937E-5,2.56524506116957E-7,49.9999962,49.9999962,793.217834472656,803.060302734375,56.7798405224868,20.5468017494857,20.251448,0,0,0,40,4449,50.1389,798.139068603516,,,,,,,,,,,,,0,,,,0,,,,,,49.9999962,,,,
,22208671.32,50.000061,-3762.599609375,6.46515813266613E-5,3.37185638187477E-7,1,0.999253354069792,40.0298881530762,1.99838951045931,17.1499997377396,0.000729885129681808,0.000134809394154428,0.25,2.78228490850683E-7,6.46256327412438E-5,7.59237705039453E-7,50.000061,50.000061,-3765.0068359375,-3760.1923828125,56.8837971155445,20.54682775803,19.871798,0,0,0,40,4449,50.13985,-3762.599609375,,,,,,,,,,,,,0,,,,0.0049,,,,,,50.000061,,,,
,22208767.555,49.9991913,-8573.9375,5.82948938954411E-5,3.27101074777653E-7,1,0.999253354069792,40.0298881530762,1.99839087509498,17.1499997377396,0.000658416862607108,0.000120793686336071,0.25,1.81267796985186E-7,5.82855603722858E-5,6.14914327446655E-7,49.9991913,49.9991913,-8583.6337890625,-8564.2412109375,56.8978664288906,20.5487531012063,19.492144,0,0,0,40,4449,50.14225,-8573.9375,,,,,,,,,,,,,0,,,,-0.00245,,,,,,49.9991913,,,,
,22208858.245,50.0004311,-13106.9672851562,4.20528852363413E-5,3.91474310172811E-7,1,0.999253354069792,40.0298881530762,1.99844143281516,17.1499997377396,0.000474314980410372,9.14831484496623E-5,0.25,5.1360055138139E-7,4.20532657017536E-5,8.26079826464797E-7,50.0004311,50.0004311,-13112.05078125,-13101.8837890625,57.0237086204868,20.5484816732478,19.871798,0,0,0,40,4449,50.1415,-13106.9672851562,,,,,,,,,,,,,0,,,,-0.0049,,,,,,50.0004311,,,,
,22208950.99,50.0012817,-17742.2646484375,1.25138211438011E-5,4.3827087558403E-7,1,0.999253354069792,40.0298881530762,1.99836930884363,17.1499997377396,0.000139012770780712,3.92209238370172E-5,0.25,1.21374058528985E-6,1.25092003859538E-5,1.30690222811027E-6,50.0012817,50.0012817,-17749.99609375,-17734.533203125,56.9697762526599,20.5494210772126,19.871798,0,0,0,40,4449,50.1377,-17742.2646484375,,,,,,,,,,,,,0,,,,0,,,,,,50.0012817,,,,
,22209045.99,50.0010071,-22489.662109375,-2.12185991285925E-5,4.94217399100485E-7,1,0.999253354069792,40.0298881530762,1.9984948848416,17.1499997377396,-0.000242188447125247,-3.10035794454877E-5,0.25,1.08201056175439E-6,-2.12395324677143E-5,9.26027957130262E-7,50.0010071,50.0010071,-22497.248046875,-22482.076171875,56.9908802226791,20.5483926738442,19.492144,0,0,0,40,4449,50.1393,-22489.662109375,,,,,,,,,,,,,0,,,,0,,,,,,50.0010071,,,,
,22209137.765,50.0022736,-27077.29296875,-4.22743042733459E-5,4.41014350765348E-7,1,0.999253354069792,40.0298881530762,1.99829061435734,17.1499997377396,-0.000480887914690158,-7.12269515843892E-5,0.25,1.3188299556463E-6,-4.23203515098383E-5,1.00940712452621E-6,50.0022736,50.0022736,-27084.736328125,-27069.849609375,56.9900985941599,20.5527108152791,19.871798,0,0,0,40,4449,50.1356,-27077.29296875,,,,,,,,,,,,,0,,,,-0.0049,,,,,,50.0022736,,,,
,22209229.235,50.0030479,-31647.16796875,-5.17691106604678E-5,4.71801987096011E-7,1,0.999253354069792,40.0298881530762,1.99836519755124,17.1499997377396,-0.000588236264662108,-9.18252203420895E-5,0.25,1.20822229546425E-6,-5.18352318601253E-5,8.31539066111385E-7,50.0030479,50.0030479,-31652.09375,-31642.2421875,56.9760292808137,20.5500219140193,19.871798,0,0,0,40,4449,50.13385,-31647.16796875,,,,,,,,,,,,,0,,,,0.00245,,,,,,50.0030479,,,,
,22209321.28,50.0018501,-36249.103515625,-5.49445533977327E-5,5.34236772207605E-7,1,0.999253354069792,40.0298881530762,1.99828336466214,17.1499997377396,-0.000625487554603054,-9.16865216045916E-5,0.25,1.79104090465913E-6,-5.5031791180955E-5,1.3951301917788E-6,50.0018501,50.0018501,-36254.1171875,-36244.08984375,56.8322096332752,20.5506277430447,20.251448,0,0,0,40,4449,50.13485,-36249.103515625,,,,,,,,,,,,,0,,,,0.00245,,,,,,50.0018501,,,,
,22209414.69,50.0016747,-40916.41796875,-5.3084800124177E-5,5.44940686294119E-7,1,0.999253354069792,40.0298881530762,1.99817474494596,17.1499997377396,-0.000605177746024983,-8.44381648098991E-5,0.25,2.09476485535068E-6,-5.31843943944507E-5,1.716442075593E-6,50.0016747,50.0016747,-40921.44140625,-40911.39453125,56.9713395096983,20.550733067484,19.492144,0,0,0,40,4449,50.1308,-40916.41796875,,,,,,,,,,,,,0,,,,-0.0049,,,,,,50.0016747,,,,
,22209507.41,50.0024261,-45551.86328125,-5.03243055683826E-5,6.39994717337386E-7,1,0.999253354069792,40.0298881530762,1.99811813860728,17.1499997377396,-0.000573664541675788,-8.09493970838947E-5,0.25,1.9041605981589E-6,-5.04297553904277E-5,1.54917050988954E-6,50.0024261,50.0024261,-45559.19140625,-45544.53515625,57.3129111726022,20.5512138168057,19.871798,0,0,0,40,4449,50.1312,-45551.86328125,,,,,,,,,,,,,0,,,,0,,,,,,50.0024261,,,,
,22209600.43,50.0026588,-50198.876953125,-4.60226580034867E-5,7.00459984069234E-7,1,0.999253354069792,40.0298881530762,1.99829617245961,17.1499997377396,-0.000526504240424926,-6.45191667937088E-5,0.25,2.57974042352998E-6,-4.61352833069413E-5,2.26053661945369E-6,50.0026588,50.0026588,-50206.2265625,-50191.52734375,56.9252234270637,20.5489295765699,20.251448,0,0,0,40,4449,50.1294,-50198.876953125,,,,,,,,,,,,,0,,,,-0.0049,,,,,,50.0026588,,,,
,22209692.32,50.0004005,-54790.677734375,-4.23806681361484E-5,7.81167270794965E-7,1,0.999253354069792,40.0298881530762,1.99823778084181,17.1499997377396,-0.000486115305459301,-5.28177085562577E-5,0.25,2.95548571552285E-6,-4.24973695822239E-5,2.66660543387677E-6,50.0004005,50.0004005,-54803.15234375,-54778.203125,57.0291800201214,20.5510556826827,19.871798,0,0,0,40,4449,50.1262,-54790.677734375,,,,,,,,,,,,,0,,,,0,,,,,,50.0004005,,,,
,22209788.785,50.0011177,-59610.484375,-3.76604926921677E-5,9.63064856805254E-7,1,0.999253354069792,40.0298881530762,1.99817461460283,17.1499997377396,-0.000432027922719967,-4.7077515994025E-5,0.25,2.61122701113045E-6,-3.7772082068002E-5,2.35826072123802E-6,50.0011177,50.0011177,-59620.2578125,-59600.7109375,57.0964000727753,20.5500901518634,19.871798,0,0,0,40,4449,50.1273,-59610.484375,,,,,,,,,,,,,0,,,,0,,,,,,50.0011177,,,,
,22209885.025,50.0010986,-64420.46875,-3.40333324246527E-5,7.8616921330554E-7,1,0.999253354069792,40.0298881530762,1.99832623742073,17.1499997377396,-0.000394065197414277,-2.28418719645883E-5,0.25,4.09596556574602E-6,-3.4152877026832E-5,3.87556248963447E-6,50.0010986,50.0010986,-64428.12109375,-64412.81640625,56.953362053756,20.5516087607286,19.871798,0,0,0,40,4449,50.1298,-64420.46875,,,,,,,,,,,,,0,,,,-0.00245,,,,,,50.0010986,,,,
,22209978.93,50.0032043,-69115.01953125,-3.12192948299376E-5,6.011826912674E-7,1,0.999253354069792,40.0298881530762,1.99822612263435,17.1499997377396,-0.00036098365121826,-2.40034111755771E-5,0.25,3.48558525220608E-6,-3.1332858414676E-5,3.28615161035691E-6,50.0032043,50.0032043,-69124.984375,-69105.0546875,56.8259566051214,20.5513909050418,19.871798,0,0,0,40,4449,50.12715,-69115.01953125,,,,,,,,,,,,,0,,,,0.00245,,,,,,50.0032043,,,,
,22210075.51,50.0027657,-73941.8125,-2.54048034617957E-5,7.63242811949404E-7,1,0.999253354069792,40.0298881530762,1.99835220717634,17.1499997377396,-0.000297191438687831,-7.52317621434977E-7,0.25,4.49067623026479E-6,-2.55127333298053E-5,4.33642659757059E-6,50.0027657,50.0027657,-73952.0546875,-73931.5703125,56.8525319747752,20.5527185187388,19.871798,0,0,0,40,4449,50.12225,-73941.8125,,,,,,,,,,,,,0,,,,0,,,,,,50.0027657,,,,
,22210169.065,50.0019035,-78616.51171875,-2.15235445189994E-5,8.28644224959542E-7,1,0.999253354069792,40.0298881530762,1.99841000420089,17.1499997377396,-0.000252768800700502,4.57487747137283E-6,0.25,4.26210448146603E-6,-2.16214023202208E-5,4.13559580360399E-6,50.0019035,50.0019035,-78619.015625,-78614.0078125,57.0330881627176,20.5531174394855,19.871798,0,0,0,40,4449,50.1168,-78616.51171875,,,,,,,,,,,,,0,,,,0,,,,,,50.0019035,,,,
,22210264.83,50.0035477,-83401.28515625,-1.72513624006755E-5,6.58010275283533E-7,1,0.999253354069792,40.0298881530762,1.99837260956584,17.1499997377396,-0.000205325701534679,1.87447546018936E-5,0.25,4.74356940713335E-6,-1.7340966717219E-5,4.64899778123571E-6,50.0035477,50.0035477,-83411.2265625,-83391.34375,57.017455592333,20.5549211294043,20.251448,0,0,0,40,4449,50.1174,-83401.28515625,,,,,,,,,,,,,0,,,,0.00245,,,,,,50.0035477,,,,
,22210355.8,50.0021973,-87950.61328125,-1.3383168209271E-5,1.01072203002012E-6,1,0.999253354069792,40.0298881530762,1.9984029426287,17.1499997377396,-0.000160804782279745,2.2894665287468E-5,0.25,4.4146478046017E-6,-1.34590758656492E-5,4.3457445611165E-6,50.0021973,50.0021973,-87958,-87943.2265625,56.8931766577752,20.5542811048338,19.492144,0,0,0,40,4449,50.11575,-87950.61328125,,,,,,,,,,,,,0,,,,-0.0049,,,,,,50.0021973,,,,
,22210468.21,50.0008316,-87531.16796875,-1.66950136779888E-5,8.8505163666986E-7,1,0.999253354069792,40.0298881530762,1.99839061727088,17.1499997377396,-0.000198994007834741,1.96220222671679E-5,0.25,4.71946320643664E-6,-1.67845227007321E-5,4.63047191876787E-6,50.0008316,50.0008316,-87533.6328125,-87528.703125,57.0846756449868,20.5531634143584,20.251448,0,0,0,40,4449,50.114,-87531.16796875,,,,,,,,,,,,,0,,,,0,,,,,,50.0008316,,,,
,22210560.33,49.9993553,-82929.44921875,-2.18295214145325E-5,8.90358183613047E-7,1,0.999253354069792,40.0298881530762,1.99844326492311,17.1499997377396,-0.000256276170106997,3.94161198900036E-6,0.25,4.25905486425342E-6,-2.19313857645456E-5,4.13312971950521E-6,49.9993553,49.9993553,-82932.078125,-82926.8203125,57.0635716749676,20.5543951455436,20.251448,0,0,0,40,4449,50.1182,-82929.44921875,,,,,,,,,,,,,0,,,,0,,,,,,49.9993553,,,,
,22210655.33,49.9987259,-78181.84765625,-2.87947339651109E-5,7.32070506156012E-7,1,0.999253354069792,40.0298881530762,1.99832059580628,17.1499997377396,-0.000333257419827533,-2.11206359811841E-5,0.25,3.30014170556649E-6,-2.89095682594131E-5,3.12278189856963E-6,49.9987259,49.9987259,-78184.328125,-78179.3671875,57.1253203279868,20.5541078137336,19.492144,0,0,0,40,4449,50.1216,-78181.84765625,,,,,,,,,,,,,0,,,,0,,,,,,49.9987259,,,,
,22210750.015,49.998951,-73447.27734375,-3.53977361505656E-5,6.39265291201031E-7,1,0.999253354069792,40.0298881530762,1.99837799625393,17.1499997377396,-0.000410220184414459,-2.26155964133969E-5,0.25,4.35532364767716E-6,-3.55349024399518E-5,4.13411225707123E-6,49.998951,49.998951,-73457.2265625,-73437.328125,56.8955215433329,20.553863050402,20.251448,0,0,0,40,4449,50.122,-73447.27734375,,,,,,,,,,,,,0,,,,0,,,,,,49.998951,,,,
,22210847.205,49.9991112,-68592.9140625,-3.95588823886168E-5,7.35987222613096E-7,1,0.999253354069792,40.0298881530762,1.9984374808327,17.1499997377396,-0.000458965709365522,-2.19697170519979E-5,0.25,5.16233701526124E-6,-3.97069456552352E-5,4.91123700252573E-6,49.9991112,49.9991112,-68600.125,-68585.703125,56.7915649502752,20.5559192135648,20.251448,0,0,0,40,4449,50.11685,-68592.9140625,,,,,,,,,,,,,0,,,,0.00245,,,,,,49.9991112,,,,
,22210946.975,49.9996815,-63605.974609375,-4.60230824372322E-5,7.14421439425284E-7,1,0.999253354069792,40.0298881530762,1.99824583281601,17.1499997377396,-0.000528556396459552,-5.48164421230232E-5,0.25,3.42818395429132E-6,-4.61688032866281E-5,3.12360190350526E-6,49.9996605,49.9997025,-63613.5078125,-63598.44140625,57.1073428720445,20.5534532472224,19.492144,0,0,0,40,4449,50.1235,-63605.974609375,,,,,,,,,,,,,0,,,,0,,,,,,49.9996815,,,,
,22211044.055,49.997715,-58753.51953125,-5.11275726717271E-5,6.74682785869003E-7,1,0.999253354069792,40.0298881530762,1.99817109880228,17.1499997377396,-0.000586225240757094,-6.54083605833806E-5,0.25,3.41351290644352E-6,-5.12762290034488E-5,3.06882400264066E-6,49.997715,49.997715,-58760.875,-58746.1640625,57.0237086204868,20.5524113616586,19.492144,0,0,0,40,4449,50.12265,-58753.51953125,,,,,,,,,,,,,0,,,,-0.00245,,,,,,49.997715,,,,
,22211141.395,49.9985504,-53889.076171875,-5.58588527729124E-5,5.97029720514271E-7,1,0.999253354069792,40.0298881530762,1.9981492926919,17.1499997377396,-0.000639354880211972,-7.68681388335198E-5,0.25,3.25546969948445E-6,-5.60059062993057E-5,2.87226324319981E-6,49.9985504,49.9985504,-53899.0859375,-53879.06640625,56.9385111118906,20.5517952037274,19.871798,0,0,0,40,4449,50.1244,-53889.076171875,,,,,,,,,,,,,0,,,,0,,,,,,49.9985504,,,,
,22211238.68,49.9993172,-49026.98828125,-6.12026574903076E-5,5.17706240832232E-7,1,0.999253354069792,40.0298881530762,1.99819620828287,17.1600002795458,-0.000699676135707241,-8.81053684455887E-5,0.25,3.2274783758675E-6,-6.13475415672478E-5,2.80121411351569E-6,49.9993172,49.9993172,-49036.96875,-49017.0078125,56.9689946241406,20.5494729122044,20.251448,0,0,0,40,4449,50.12325,-49026.98828125,,,,,,,,,,,,,0,,,,-0.00245,,,,,,49.9993172,,,,
,22211334.805,49.9979248,-44222.03515625,-6.49374982036599E-5,5.69115848334181E-7,1,0.999253354069792,40.0298881530762,1.9981108320561,17.1499997377396,-0.000740752547741109,-0.000101344543478886,0.25,2.73256121528671E-6,-6.50712363925596E-5,2.27351508126177E-6,49.9979248,49.9979248,-44224.43359375,-44219.63671875,56.7329428113329,20.5521447957761,19.492144,0,0,0,40,4449,50.1272,-44222.03515625,,,,,,,,,,,,,0,,,,0,,,,,,49.9979248,,,,
,22211426.345,49.9987679,-39646.984375,-6.94138966029038E-5,5.47885826961332E-7,1,0.999253354069792,40.0298881530762,1.99815848696595,17.1499997377396,-0.000791297785216163,-0.000110276996562576,0.25,2.75154870470385E-6,-6.95396637644406E-5,2.25548301943041E-6,49.9987679,49.9987679,-39656.91796875,-39637.05078125,56.800944492506,20.5519336492197,19.871798,0,0,0,40,4449,50.12545,-39646.984375,,,,,,,,,,,,,0,,,,0,,,,,,49.9987679,,,,
,22211520.04,49.9992638,-34965.09375,-7.30752182285686E-5,4.35582471505245E-7,1,0.999253354069792,40.0298881530762,1.99820690356538,17.1499997377396,-0.000830662855778166,-0.000128239161211198,0.25,1.82557855245304E-6,-7.31821657969353E-5,1.29699610566774E-6,49.9992638,49.9992638,-34970.05859375,-34960.12890625,56.7767140084099,20.5477590677691,20.251448,0,0,0,40,4449,50.12705,-34965.09375,,,,,,,,,,,,,0,,,,0,,,,,,49.9992638,,,,
,22211615.235,49.9990425,-30207.826171875,-7.57377275770766E-5,4.50762024368175E-7,1,0.999253354069792,40.0298881530762,1.99800622327765,17.1499997377396,-0.000859942932219644,-0.000136670029790174,0.25,1.55981513383732E-6,-7.58269490507111E-5,1.00722741056895E-6,49.9990425,49.9990425,-30212.98828125,-30202.6640625,56.9682129956214,20.5500640432233,19.871798,0,0,0,40,4449,50.1253,-30207.826171875,,,,,,,,,,,,,0,,,,0,,,,,,49.9990425,,,,
,22211708.025,49.9985313,-25570.7041015625,-7.85285106594633E-5,4.81672031298875E-7,1,0.999253354069792,40.0298881530762,1.99817498204081,17.1499997377396,-0.000890325657357778,-0.000148084298338293,0.25,1.05468533160189E-6,-7.85972016845161E-5,4.77583458634429E-7,49.9985313,49.9985313,-25575.783203125,-25565.625,56.9815006804483,20.546213058493,19.871798,0,0,0,40,4449,50.12775,-25570.7041015625,,,,,,,,,,,,,0,,,,-0.0049,,,,,,49.9985313,,,,
,22211803.725,49.9994202,-20788.3505859375,-8.17844832551729E-5,4.80911394319734E-7,1,0.999253354069792,40.0298881530762,1.99818589537431,17.1499997377396,-0.000926576228587935,-0.000156552823410345,0.25,8.9196760499409E-7,-8.18330679954624E-5,2.87712619096407E-7,49.9994202,49.9994202,-20793.326171875,-20783.375,56.9525804252368,20.5500181729774,20.251448,0,0,0,40,4449,50.12685,-20788.3505859375,,,,,,,,,,,,,0,,,,-0.00245,,,,,,49.9994202,,,,
,22211894.4,49.9999161,-16256.2104492187,-8.39405912037883E-5,4.18590058393058E-7,1,0.999253354069792,40.0298881530762,1.9981782854215,17.1499997377396,-0.000950340980071659,-0.000162993715148223,0.25,7.09417929469241E-7,-8.39681441202136E-5,8.69349648776654E-8,49.9999161,49.9999161,-16266.1484375,-16246.2724609375,56.8939582862945,20.5481214134195,20.251448,0,0,0,40,4449,50.1271,-16256.2104492187,,,,,,,,,,,,,0,,,,0.00245,,,,,,49.9999161,,,,
,22211988.065,50.0005035,-11576.0029296875,-8.55971974456974E-5,3.9726471582887E-7,1,0.999253354069792,40.0298881530762,1.99813374096253,17.1499997377396,-0.000967819685811278,-0.00017178064610102,0.25,2.2804125828975E-7,-8.56000464796047E-5,-4.08274689564546E-7,50.0005035,50.0005035,-11578.521484375,-11573.484375,56.8267382336406,20.5458531837106,20.631098,0,0,0,40,4449,50.12475,-11576.0029296875,,,,,,,,,,,,,0,,,,0,,,,,,50.0005035,,,,
,22212084.79,49.9987221,-6742.88500976563,-8.64058067367722E-5,3.61111618392677E-7,1,0.999253354069792,40.0298881530762,1.99820638209522,17.1499997377396,-0.000975629822212316,-0.000179611983284691,0.25,-3.2175792324343E-7,-8.63832796191689E-5,-9.64638651822832E-7,49.9987221,49.9987221,-6750.4697265625,-6735.30029296875,56.8118872917752,20.5461804076359,19.871798,0,0,0,40,4449,50.1277,-6742.88500976563,,,,,,,,,,,,,0,,,,-0.00245,,,,,,49.9987221,,,,
,22212178.055,50.0001831,-2079.67956542969,-8.46455998937322E-5,3.18369845913952E-7,1,0.999253354069792,40.0298881530762,1.99828978467909,17.1499997377396,-0.000954955518333916,-0.000179435369680821,0.25,-6.26060976987579E-7,-8.46031366846275E-5,-1.25561092793123E-6,50.0001831,50.0001831,-2082.0703125,-2077.28881835938,56.9299131981791,20.548392288452,19.871798,0,0,0,40,4449,50.1214,-2079.67956542969,,,,,,,,,,,,,0,,,,0.00245,,,,,,50.0001831,,,,
,22212269.67,50.0010719,2496.10266113281,-6.34581739764338E-5,2.91843669785336E-7,1,0.999253354069792,40.0298881530762,1.99830026724924,17.1499997377396,-0.000714383912225858,-0.000143158911990064,0.25,-1.23363642916887E-6,-6.3421863241264E-5,-1.70530523618585E-6,50.0010719,50.0010719,2486.10791015625,2506.09741210938,56.7204367550252,20.5462628806584,19.492144,0,0,0,40,4449,50.12815,2496.10266113281,,,,,,,,,,,,,0,,,,-0.00245,,,,,,50.0010719,,,,
,22212362.22,50.000309,7122.7333984375,-5.68577873267388E-5,3.88685412506634E-7,1,0.999253354069792,40.0298881530762,1.99842451603883,17.1499997377396,-0.000639754601383106,-0.000131073437287462,0.25,-1.35053662333839E-6,-5.68355193230086E-5,-1.77331738557004E-6,50.000309,50.000309,7120.13037109375,7125.33642578125,57.0909286731407,20.5470027289745,19.871798,0,0,0,40,4449,50.12575,7122.7333984375,,,,,,,,,,,,,0,,,,0.00245,,,,,,50.000309,,,,
,22212456.115,49.9998856,11816.1669921875,-4.22004093831351E-5,3.79809168218977E-7,1,0.999253354069792,40.0298881530762,1.99835002076298,17.1499997377396,-0.000474315343604153,-0.000100719606907516,0.25,-1.30495917393318E-6,-4.21919116020221E-5,-1.61867925754158E-6,49.9998856,49.9998856,11808.671875,11823.662109375,56.8861420011022,20.5476536515002,19.871798,0,0,0,40,4449,50.1325,11816.1669921875,,,,,,,,,,,,,0,,,,0,,,,,,49.9998856,,,,
,22212547.98,50.0003929,16408.65234375,-1.42922850074403E-5,3.27441863956388E-7,1,0.999253354069792,40.0298881530762,1.99830222640417,17.1499997377396,-0.000158702663033066,-4.50639465405516E-5,0.25,-1.41035490804963E-6,-1.42857332095011E-5,-1.51675166223063E-6,50.0003929,50.0003929,16396.22265625,16421.08203125,57.0846756449868,20.544309064662,20.251448,0,0,0,40,4449,50.126,16408.65234375,,,,,,,,,,,,,0,,,,0.00245,,,,,,50.0003929,,,,
,22212638.03,50.0002022,20908.7763671875,1.98103784155398E-5,4.27021097072615E-7,1,0.999253354069792,40.0298881530762,1.99833349417483,17.1499997377396,0.000227757173029182,1.96191509099436E-5,0.25,-1.83479104091764E-6,1.98342417427887E-5,-1.6892818396831E-6,50.0002022,50.0002022,20903.912109375,20913.640625,56.8947399148137,20.5452597431708,20.251448,0,0,0,40,4449,50.1262,20908.7763671875,,,,,,,,,,,,,0,,,,0,,,,,,50.0002022,,,,
,22212732.845,50.0012741,25648.572265625,4.78471581659951E-5,4.5955309671422E-7,1,0.999253354069792,40.0298881530762,1.99826131654428,17.1499997377396,0.000545159437641748,7.54501789662283E-5,0.25,-1.94941060489702E-6,4.78987775933849E-5,-1.59882716161548E-6,50.0012741,50.0012741,25641.09375,25656.05078125,56.6235148186406,20.5418412889611,20.251448,0,0,0,40,4449,50.1235,25648.572265625,,,,,,,,,,,,,0,,,,0.0049,,,,,,50.0012741,,,,
,22212826.23,50.0024071,30314.083984375,6.26635445168395E-5,4.18928075656022E-7,1,0.999253354069792,40.0298881530762,1.99841420707474,17.1499997377396,0.00071301004519412,0.0001054826387649,0.25,-1.96373264393674E-6,6.27426108083988E-5,-1.50729711018792E-6,50.0024071,50.0024071,30309.078125,30319.08984375,56.8329912617945,20.5410327275185,20.251448,0,0,0,40,4449,50.12305,30314.083984375,,,,,,,,,,,,,0,,,,-0.0049,,,,,,50.0024071,,,,
,22212922.53,50.0010719,35129.115234375,6.77038426593379E-5,4.87496416979275E-7,1,0.999253354069792,40.0298881530762,1.99835790781999,17.1499997377396,0.000772248962647991,0.000104485228412432,0.25,-2.95811125819644E-6,6.78127244913482E-5,-2.4701654374062E-6,50.0010719,50.0010719,35121.67578125,35136.5546875,56.9213152844676,20.542812860571,19.871798,0,0,0,40,4449,50.12785,35129.115234375,,,,,,,,,,,,,0,,,,-0.00245,,,,,,50.0010719,,,,
,22213017.765,50.0024834,39886.69140625,6.81408372614959E-5,4.79527548884499E-7,1,0.999253354069792,40.0298881530762,1.99817086543751,17.1499997377396,0.000777919678847135,0.000102025851995399,0.25,-3.25132248360217E-6,6.82689978536925E-5,-2.76542262248597E-6,50.0024834,50.0024834,39879.23828125,39894.14453125,56.8243933480829,20.5415829993065,19.871798,0,0,0,40,4449,50.119,39886.69140625,,,,,,,,,,,,,0,,,,0,,,,,,50.0024834,,,,
,22213113.11,50.0021057,44652.595703125,6.71223841747656E-5,6.58244421373837E-7,1,0.999253354069792,40.0298881530762,1.99834721623661,17.1499997377396,0.000766722389390883,9.95173165702836E-5,0.25,-3.28783649720934E-6,6.72652740024373E-5,-2.814627940449E-6,50.0021057,50.0021057,44647.44921875,44657.7421875,56.8556584888522,20.5401245398686,20.251448,0,0,0,40,4449,50.1214,44652.595703125,,,,,,,,,,,,,0,,,,0,,,,,,50.0021057,,,,
,22213206.005,50.0008392,49295.130859375,6.43155861456704E-5,7.40244827137993E-7,1,0.999253354069792,40.0298881530762,1.99842361986267,17.1499997377396,0.000736067741915772,8.86209431681584E-5,0.25,-3.74248826385365E-6,6.44711216803008E-5,-3.29556013222592E-6,50.0008392,50.0008392,49284.83203125,49305.4296875,56.8791073444291,20.5424152738938,20.251448,0,0,0,40,4449,50.1221,49295.130859375,,,,,,,,,,,,,0,,,,-0.00245,,,,,,50.0008392,,,,
,22213302.05,50.0004272,54097.287109375,6.06101571942773E-5,5.66219609950293E-7,1,0.999253354069792,40.0298881530762,1.99826344423568,17.1499997377396,0.000694994676201105,7.6665439360234E-5,0.25,-4.1277140729852E-6,6.07744287333202E-5,-3.71348182481809E-6,50.0004272,50.0004272,54092.21875,54102.35546875,56.6821369575829,20.538263221452,20.251448,0,0,0,40,4449,50.1223,54097.287109375,,,,,,,,,,,,,0,,,,-0.00245,,,,,,50.0004272,,,,
,22213395.305,50.0016823,58757.73046875,5.74491907151684E-5,9.02997573816773E-7,1,0.999253354069792,40.0298881530762,1.99828712131811,17.1499997377396,0.000659759372649614,6.78522557488301E-5,0.25,-4.33401155646502E-6,5.76196393842446E-5,-3.94790974083829E-6,50.0016823,50.0016823,58745.1328125,58770.328125,56.7993812354675,20.5403284862345,19.871798,0,0,0,40,4449,50.11855,58757.73046875,,,,,,,,,,,,,0,,,,-0.00245,,,,,,50.0016823,,,,
,22213492.875,50.0031509,63635.587890625,5.37446619919435E-5,7.95626478366543E-7,1,0.999253354069792,40.0298881530762,1.99831765693258,17.1499997377396,0.00062073740114721,4.46353109870731E-5,0.25,-5.7133556819034E-6,5.39265060987434E-5,-5.36223009169221E-6,50.0031509,50.0031509,63627.8203125,63643.35546875,56.8501870892175,20.5417688815803,20.631098,0,0,0,40,4449,50.118,63635.587890625,,,,,,,,,,,,,0,,,,-0.0049,,,,,,50.0031509,,,,
,22213584.75,50.0028572,68225.80078125,5.0260191605055E-5,7.32814041632278E-7,1,0.999253354069792,40.0298881530762,1.99835482832818,17.1499997377396,0.000580194340401916,4.40537409999507E-5,0.25,-5.13520947069337E-6,5.04379961493818E-5,-4.81165433399433E-6,50.0028572,50.0028572,68215.6953125,68235.90625,56.6922981283329,20.5400153907761,20.251448,0,0,0,40,4449,50.11335,68225.80078125,,,,,,,,,,,,,0,,,,0,,,,,,50.0028572,,,,
,22213681.5,50.0023994,73061.2578125,4.67806617151177E-5,9.76494485417511E-7,1,0.999253354069792,40.0298881530762,1.99833540300485,17.1499997377396,0.000542241853348032,2.91877512250331E-5,0.25,-5.81794758191881E-6,4.69616407886425E-5,-5.52531275062759E-6,50.0023994,50.0023994,73053.765625,73068.75,56.6313311038329,20.5389867332531,20.251448,0,0,0,40,4449,50.11405,73061.2578125,,,,,,,,,,,,,0,,,,-0.0049,,,,,,50.0023994,,,,
,22213778.25,50.001976,77899.01953125,4.20096534432943E-5,6.44548092177913E-7,1,0.999253354069792,40.0298881530762,1.99823150659834,17.1499997377396,0.000488300336101209,1.89583175419211E-5,0.25,-5.86027271839323E-6,4.2183563974774E-5,-5.60456819030377E-6,50.001976,50.001976,77896.546875,77901.4921875,56.7259081546598,20.5411285695759,19.871798,0,0,0,40,4449,50.1124,77899.01953125,,,,,,,,,,,,,0,,,,0,,,,,,50.001976,,,,
,22213872.69,49.9989548,82619.703125,3.8461070750659E-5,1.06460465905736E-6,1,0.999253354069792,40.0298881530762,1.99825597749204,17.1499997377396,0.000447626751370084,1.45813309023476E-5,0.25,-5.6064042862521E-6,3.86279457598273E-5,-5.3777576699252E-6,49.9989548,49.9989548,82610.265625,82629.140625,56.6149169049291,20.5398253715726,20.631098,0,0,0,40,4449,50.1174,82619.703125,,,,,,,,,,,,,0,,,,-0.00735,,,,,,49.9989548,,,,
,22213962.79,49.9989548,87122.98046875,3.49916850026822E-5,9.29200137796813E-7,1,0.999253354069792,40.0298881530762,1.99813077001747,17.1499997377396,0.000408893431341037,4.26692225507566E-6,0.25,-5.89077162243659E-6,3.51534929281046E-5,-5.68959225707169E-6,49.9989548,49.9989548,87118.203125,87127.7578125,56.8603482599676,20.5419535837444,19.492144,0,0,0,40,4449,50.1134,87122.98046875,,,,,,,,,,,,,0,,,,-0.00245,,,,,,49.9989548,,,,
,22214077.405,49.9985847,88272.80078125,3.49434999248758E-5,8.49028695845344E-7,1,0.999253354069792,40.0298881530762,1.99821499791646,17.1499997377396,0.000408661717512162,2.58115685639155E-6,0.25,-6.0299063511842E-6,3.51072290479822E-5,-5.83059451887042E-6,49.9985847,49.9985847,88262.71875,88282.8828125,56.8353361473522,20.5414628995573,20.251448,0,0,0,40,4449,50.11385,88272.80078125,,,,,,,,,,,,,0,,,,-0.0049,,,,,,49.9985847,,,,
,22214176.835,49.9974327,83302.21875,3.96785711077427E-5,9.09141328974105E-7,1,0.999253354069792,40.0298881530762,1.99808221202549,17.1499997377396,0.000463990827479207,2.63840521089579E-6,0.25,-6.87694669752704E-6,3.98586313004579E-5,-6.64550224723722E-6,49.9974327,49.9974327,83294.5625,83309.875,56.7016776705637,20.5423877392901,19.871798,0,0,0,40,4449,50.11785,83302.21875,,,,,,,,,,,,,0,,,,0,,,,,,49.9974327,,,,
,22214277.635,49.998394,78260.58203125,4.47205171395695E-5,7.91721965775699E-7,1,0.999253354069792,40.0298881530762,1.99816592688427,17.1499997377396,0.000518153153817577,2.93701301319278E-5,0.25,-5.42775940334752E-6,4.4900940574322E-5,-5.15335783308419E-6,49.998394,49.998394,78245.5234375,78275.640625,56.8494054606983,20.5407472100554,20.251448,0,0,0,40,4449,50.1177,78260.58203125,,,,,,,,,,,,,0,,,,0.00245,,,,,,49.998394,,,,
,22214378.92,49.9977722,73197.546875,4.9201083342688E-5,8.12953517498468E-7,1,0.999253354069792,40.0298881530762,1.99812062509504,17.1499997377396,0.000567072782888046,4.83613203390954E-5,0.25,-4.56053524186982E-6,4.93813667131864E-5,-4.24819108691668E-6,49.9977722,49.9977722,73192.5390625,73202.5546875,56.7743691228522,20.5405732273871,20.251448,0,0,0,40,4449,50.1184,73197.546875,,,,,,,,,,,,,0,,,,-0.0049,,,,,,49.9977722,,,,
,22214481.005,49.9987793,68094.70703125,5.25034663508014E-5,7.70827144571782E-7,1,0.999253354069792,40.0298881530762,1.99805037788781,17.1499997377396,0.000605852179794843,4.68359260025413E-5,0.25,-5.29191992169092E-6,5.26885183551075E-5,-4.95359493118625E-6,49.9987793,49.9987793,68089.65625,68099.7578125,56.5719273363714,20.5417733733816,19.871798,0,0,0,40,4449,50.1224,68094.70703125,,,,,,,,,,,,,0,,,,0.00245,,,,,,49.9987793,,,,
,22214580.425,49.9981575,63127.142578125,5.71439860542968E-5,8.43388029938904E-7,1,0.999253354069792,40.0298881530762,1.99815963161104,17.1499997377396,0.000657407663063673,6.15305276764618E-5,0.25,-4.83309527608872E-6,5.73277078629976E-5,-4.4558302227097E-6,49.9981575,49.9981575,63117.09765625,63137.1875,56.8978664288906,20.5410448174684,19.871798,0,0,0,40,4449,50.12195,63127.142578125,,,,,,,,,,,,,0,,,,0,,,,,,49.9981575,,,,
,22214681.835,49.9973679,58056.810546875,6.10512339299612E-5,6.54228476408221E-7,1,0.999253354069792,40.0298881530762,1.99810192757206,17.1499997377396,0.000701309052868542,7.0619117661595E-5,0.25,-4.73705813871723E-6,6.1231461792825E-5,-4.32617504772556E-6,49.9973679,49.9973679,58049.1953125,58064.42578125,56.9822823089676,20.5414804783299,20.251448,0,0,0,40,4449,50.12245,58056.810546875,,,,,,,,,,,,,0,,,,0,,,,,,49.9973679,,,,
,22214781.635,49.9976311,53068.8671875,6.45229568922083E-5,6.14654752355831E-7,1,0.999253354069792,40.0298881530762,1.99821913950654,17.1499997377396,0.00074018477196133,7.95323731997897E-5,0.25,-4.57868012867538E-6,6.46961195948447E-5,-4.13678056533059E-6,49.9976311,49.9976311,53056.4609375,53081.2734375,56.7563916669098,20.5409420479772,19.871798,0,0,0,40,4449,50.1231,53068.8671875,,,,,,,,,,,,,0,,,,-0.00245,,,,,,49.9976311,,,,
,22214877.93,50.0000458,48256.296875,6.84733763591419E-5,7.3972051667283E-7,1,0.999253354069792,40.0298881530762,1.99814747134975,17.1499997377396,0.000782818777199942,9.81782777987767E-5,0.25,-3.64599999774778E-6,6.86332040373035E-5,-3.16819666948578E-6,50.0000458,50.0000458,48253.75390625,48258.83984375,56.926005055583,20.5419164943506,19.871798,0,0,0,40,4449,50.12305,48256.296875,,,,,,,,,,,,,0,,,,0,,,,,,50.0000458,,,,
,22214971.025,49.9996605,43603.263671875,7.14748543443276E-5,6.69655193335044E-7,1,0.999253354069792,40.0298881530762,1.9983353274197,17.1499997377396,0.000817229441104872,0.000101315910233732,0.25,-3.91270703948896E-6,7.16262669864084E-5,-3.4082513372335E-6,49.9996605,49.9996605,43596.015625,43610.51171875,56.5461335952368,20.5382210568633,20.251448,0,0,0,40,4449,50.1223,43603.263671875,,,,,,,,,,,,,0,,,,0,,,,,,49.9996605,,,,
,22215066.11,49.9988632,38851.03515625,7.42000151838942E-5,6.52256928488383E-7,1,0.999253354069792,40.0298881530762,1.99838415813099,17.1499997377396,0.000847354443758278,0.000109891092564049,0.25,-3.64857943686825E-6,7.4336527042926E-5,-3.11845994998552E-6,49.9988632,49.9988632,38843.6171875,38858.453125,57.0049495360253,20.5391327602802,20.251448,0,0,0,40,4449,50.1247,38851.03515625,,,,,,,,,,,,,0,,,,-0.0049,,,,,,49.9988632,,,,
,22215156.78,49.9990196,34321.267578125,7.73517466197287E-5,5.00104616427387E-7,1,0.999253354069792,40.0298881530762,1.99842448106705,17.1499997377396,0.000881862955502773,0.00012172493395237,0.25,-3.17260385440148E-6,7.74713581283307E-5,-2.61399341171479E-6,49.9990196,49.9990196,34316.20703125,34326.328125,56.9377294833714,20.5420428595457,20.251448,0,0,0,40,4449,50.1275,34321.267578125,,,,,,,,,,,,,0,,,,0,,,,,,49.9990196,,,,
,22215252.78,49.9984589,29521.447265625,8.0183618377699E-5,4.46834530206137E-7,1,0.999253354069792,40.0298881530762,1.99831293025441,17.1499997377396,0.000913495082195816,0.000128201936174735,0.25,-3.11096861062316E-6,8.02857628191562E-5,-2.52677503406782E-6,49.9984589,49.9984589,29513.84375,29529.05078125,56.7243448976214,20.5414072079891,20.251448,0,0,0,40,4449,50.12315,29521.447265625,,,,,,,,,,,,,0,,,,0.00245,,,,,,49.9984589,,,,
,22215344.315,49.9993553,24948.5419921875,8.23569783794353E-5,4.63312997853186E-7,1,0.999253354069792,40.0298881530762,1.99835317336209,17.1499997377396,0.000935782501809007,0.000144184372449483,0.25,-2.09031969316778E-6,8.24333491127157E-5,-1.48534080851378E-6,49.9993553,49.9993553,24941.013671875,24956.0703125,57.0862389020253,20.5401809924042,20.251448,0,0,0,40,4449,50.12215,24948.5419921875,,,,,,,,,,,,,0,,,,-0.0049,,,,,,49.9993553,,,,
,22215438.96,49.99853325,20216,8.4692273627852E-5,3.89202160478016E-7,1,0.999253354069792,40.0298881530762,1.99849034573523,17.1499997377396,0.000961110886578293,0.000153915233645556,0.25,-1.65107605206816E-6,8.47452910451238E-5,-1.02535921280748E-6,49.9984322,49.9986343,20208.662109375,20223.337890625,56.8775440873906,20.5417641150653,19.871798,0,0,0,40,4449,50.126,20216,,,,,,,,,,,,,0,,,,-0.00245,,,,,,49.99853325,,,,
,22215530.96,49.9987335,15618.6489257813,8.57279722438463E-5,3.74949249171118E-7,1,0.999253354069792,40.0298881530762,1.9983690312126,17.1499997377396,0.000971962809407552,0.000159082271004544,0.25,-1.37859775462878E-6,8.57578977133516E-5,-7.42745970042411E-7,49.9987335,49.9987335,15611.2333984375,15626.064453125,57.0487207331022,20.5415892338284,20.251448,0,0,0,40,4449,50.12295,15618.6489257813,,,,,,,,,,,,,0,,,,0.00245,,,,,,49.9987335,,,,
,22215626.29,49.9990616,10854.1142578125,8.70393788339881E-5,3.57367604340503E-7,1,0.999253354069792,40.0298881530762,1.99837615642961,17.1499997377396,0.000985403456363869,0.000168032512416848,0.25,-8.209771908184E-7,8.70434551418921E-5,-1.7377876402706E-7,49.9990616,49.9990616,10839.3037109375,10868.9248046875,56.7391958394868,20.5429525923613,19.871798,0,0,0,40,4449,50.1287,10854.1142578125,,,,,,,,,,,,,0,,,,-0.00245,,,,,,49.9990616,,,,
,22215719.47,49.9993629,6198.90576171875,8.74723261828943E-5,3.03022904986681E-7,1,0.999253354069792,40.0298881530762,1.99827943468211,17.1499997377396,0.000989372496161903,0.000172439572019726,0.25,-5.05437073960776E-7,8.74533300977885E-5,1.45612264273061E-7,49.9993629,49.9993629,6191.41845703125,6206.39306640625,56.719655126506,20.5425555083465,19.871798,0,0,0,40,4449,50.1257,6198.90576171875,,,,,,,,,,,,,0,,,,-0.00245,,,,,,49.9993629,,,,
,22215814.01,49.9995499,1470.41766357422,8.46878533385885E-5,3.37715228545527E-7,1,0.999253354069792,40.0298881530762,1.99835017840791,17.1499997377396,0.000956778391903247,0.000172098544719217,0.25,-3.11104448008933E-8,8.46484670279045E-5,5.99016959666797E-7,49.9995499,49.9995499,1462.826171875,1478.00915527344,57.0495023616214,20.5427864069745,20.251448,0,0,0,40,4449,50.1288,1470.41766357422,,,,,,,,,,,,,0,,,,0,,,,,,49.9995499,,,,
,22215844.135,50.0002899,0.038059432990849,7.72384924932694E-5,3.24980221047866E-7,1,0.999253354069792,40.0298881530762,1.99840044525761,17.1499997377396,0.000873000416744351,0.000154725234906943,0.25,-2.25863507086879E-7,7.72004586896831E-5,3.488607862439E-7,50.0002899,50.0002899,0.0152237731963396,0.0608950927853584,56.8290831191983,20.5432427707254,20.251448,0,0,0,40,4417,50.1274,0.038059432990849,,,,,,,,,,,,,0,,,,-0.0049,,,,,,50.0002899,,,,