File: data/doubleLayers/dl_1-25/ppms/data/DD205_3_HYST_100OE_200K.DAT
[Header]
; VSM Data File (default extension .dat)
; Copyright (c) 2003-2013, Quantum Design, Inc. All rights reserved.
TITLE,
FILEOPENTIME,22239832.55,09/15/2018,6:42 pm
BYAPP,VSM,2.0,2.0
INFO,PPMS VSM Option Release 1.4.10 Build 1,APPNAME
INFO,Quantum Design Linear Motor Servo Controller,MOTOR_MODULE_NAME
INFO,3101-100 M1,MOTOR_HW_VERSION
INFO,MMC1014,MOTOR_SERIAL_NUMBER
INFO,SRV No X-over 01.03.11,MOTOR_SOFTWARE_VERSION
INFO,Quantum Design VSM Detection Module,VSM_MODULE_NAME
INFO,3101-150 F0,VSM_HW_VERSION
INFO,VSM707,VSM_SERIAL_NUMBER
INFO,VSM No X-over 01.02.05 May 20 2008 13:51:47,VSM_SOFTWARE_VERSION
INFO,704,PREAMP_SERIAL_NUMBER
INFO,822,COIL_SERIAL_NUMBER
INFO,0,MOMENT_UNITS
INFO,CoFe2O4,SAMPLE_MATERIAL
INFO,Double Layer blue,SAMPLE_COMMENT
INFO,,SAMPLE_MASS
INFO,,SAMPLE_VOLUME
INFO,,SAMPLE_MOLECULAR_WEIGHT
INFO,,SAMPLE_SIZE
INFO,,SAMPLE_SHAPE
DATATYPE,COMMENT,1
DATATYPE,TIME,2
STARTUPAXIS,X,2
STARTUPAXIS,Y1,5
[Data]
Comment,Time Stamp (sec),Temperature (K),Magnetic Field (Oe),Moment (emu),M. Std. Err. (emu),Transport Action,Averaging Time (sec),Frequency (Hz),Peak Amplitude (mm),Center Position (mm),Coil Signal' (mV),Coil Signal" (mV),Range (mV),M. Quad. Signal (emu),M. Raw' (emu),M. Raw" (emu),Min. Temperature (K),Max. Temperature (K),Min. Field (Oe),Max. Field (Oe),Mass (grams),Motor Lag (deg),Pressure (Torr),VSM Status (code),Motor Status (code),Measure Status (code),Measure Count,PPMS Status (code),System Temp. (K),System Field (Oe),Sample Position (deg),Bridge 1 Resistance (ohms),Bridge 1 Excitation (에),Bridge 2 Resistance (ohms),Bridge 2 Excitation (에),Bridge 3 Resistance (ohms),Bridge 3 Excitation (에),Bridge 4 Resistance (ohms),Bridge 4 Excitation (에),Signal 1 Vin (V),Signal 2 Vin (V),Digital Inputs (code),Drive 1 Iout (mA),Drive 1 Ipower (W),Drive 2 Iout (mA),Drive 2 Ipower (W),Pressure (),Map 20 (),Map 21 (),Map 22 (),Map 23 (),Map 24 (),Map 25 (),Map 26 (),Map 27 (),Map 28 (),Map 29 ()
,22239848.38,200.4311676,-0.319699227809906,,,2,,,,16.3899997735024,,,,,,,200.4311676,200.4311676,-0.319699227809906,-0.319699227809906,,,26.705515,,,,-99999999,4369,200.6545,-0.319699227809906,,,,,,,,,,,,,,,,,,,,,,,200.4311676,,,,
,22239995.205,200.2954407,4420.79370117188,5.78908301348445E-5,4.25890303029835E-7,1,0.999253354069792,40.0298881530762,1.99829278456954,16.380000859499,0.000656954932478285,0.000115870713174808,0.25,1.50910981578056E-7,5.80899366717066E-5,2.14147240720724E-7,200.2954407,200.2954407,4410.82568359375,4430.76171875,56.3061736398329,20.5138781487338,26.705515,0,0,0,40,4449,200.2677,4420.79370117188,,,,,,,,,,,,,0,,,,0,,,,,,200.2954407,,,,
,22240089.685,200.1821442,9139.513671875,5.60496634940971E-5,5.35113961909082E-7,1,0.999253354069792,40.0298881530762,1.99822371954728,16.380000859499,0.000635852649157425,0.000113275514117121,0.25,2.42447032395277E-7,5.62425498794014E-5,3.03964080750064E-7,200.1821442,200.1821442,9132.07421875,9146.953125,56.1920558760252,20.5207085499215,27.464817,0,0,0,40,4449,200.15935,9139.513671875,,,,,,,,,,,,,0,,,,-0.00245,,,,,,200.1821442,,,,
,22240183.78,200.1009064,13844.388671875,4.6372899826289E-5,8.1065002567306E-7,1,0.999253354069792,40.0298881530762,1.99837055441555,16.380000859499,0.000524042729248779,0.000105648133483336,0.25,1.25072613354827E-6,4.65314835413611E-5,1.30518452462086E-6,200.1009064,200.1009064,13834.275390625,13854.501953125,56.7712426087752,20.5237657950945,27.464817,0,0,0,40,4449,200.11275,13844.388671875,,,,,,,,,,,,,0,,,,0,,,,,,200.1009064,,,,
,22240279.445,200.0482483,18624.025390625,3.42430430916354E-5,6.51119130353348E-7,1,0.999253354069792,40.0298881530762,1.99832159135416,16.380000859499,0.000383357663955742,9.87496503132339E-5,0.25,2.75016996854633E-6,3.43582430337021E-5,2.79663285799796E-6,200.0482483,200.0482483,18616.322265625,18631.728515625,56.7001144135252,20.5229209147794,27.085165,0,0,0,40,4449,200.0944,18624.025390625,,,,,,,,,,,,,0,,,,-0.0049,,,,,,200.0482483,,,,
,22240375.03,200.0166168,23401.3134765625,1.81707389443752E-5,9.56580659118396E-7,1,0.999253354069792,40.0298881530762,1.99827357735534,16.380000859499,0.000205698921543341,3.92820839279155E-5,0.25,3.04011469820243E-7,1.82331406690711E-5,3.24646237529077E-7,200.0162811,200.0169525,23389.0234375,23413.603515625,56.7657712091406,20.5224216541035,27.085165,0,0,0,40,4449,200.0963,23401.3134765625,,,,,,,,,,,,,0,,,,0,,,,,,200.0166168,,,,
,22240472.305,200.0046387,28264.337890625,5.67790540503243E-6,8.09700438294464E-7,1,0.999253354069792,40.0298881530762,1.9980463712431,16.380000859499,5.95438194039622E-5,3.9478765833025E-5,0.25,2.4915142877815E-6,5.69483010058623E-6,2.50622601011634E-6,200.0046387,200.0046387,28257.15625,28271.51953125,56.5781803645252,20.5220025294456,27.085165,0,0,0,40,4449,200.0981,28264.337890625,,,,,,,,,,,,,0,,,,-0.0049,,,,,,200.0046387,,,,
,22240566.735,200.00365445,32984.552734375,-1.08094636656959E-5,1.09550194653388E-6,1,0.999253354069792,40.0298881530762,1.99830044397922,16.380000859499,-0.000126649401263087,1.27982759504386E-6,0.25,1.99010252799042E-6,-1.08489283844688E-5,1.98536659974444E-6,200.0033264,200.0039825,32974.9296875,32994.17578125,56.5226847396598,20.523748260659,27.464817,0,0,0,40,4449,200.10355,32984.552734375,,,,,,,,,,,,,0,,,,-0.00245,,,,,,200.00365445,,,,
,22240660.85,200.0026855,37686.833984375,-2.34286570596167E-5,1.68301263805275E-6,1,0.999253354069792,40.0298881530762,1.99815708855685,16.380000859499,-0.0002705083733256,-2.01157417125757E-5,0.25,2.29713255264804E-6,-2.35120314313311E-5,2.27995180050831E-6,200.0026855,200.0026855,37676.80078125,37696.8671875,56.6266413327175,20.5241848261583,27.085165,0,0,0,40,4449,200.09795,37686.833984375,,,,,,,,,,,,,0,,,,-0.00245,,,,,,200.0026855,,,,
,22240754.4,200.0056,42362.04296875,-4.08337084847444E-5,2.05271443865202E-6,1,0.999253354069792,40.0298881530762,1.99814558317166,16.380000859499,-0.000468903664196273,-4.98091685456495E-5,0.25,2.70435161645458E-6,-4.0977631095383E-5,2.67000200608117E-6,200.0052948,200.0059052,42354.4921875,42369.59375,56.6571248449675,20.52537047272,27.085165,0,0,0,40,4449,200.09285,42362.04296875,,,,,,,,,,,,,0,,,,-0.0049,,,,,,200.0056,,,,
,22240850.605,200.007431,47172.35546875,-5.27675230419766E-5,1.83547147857031E-6,1,0.999253354069792,40.0298881530762,1.99807350683683,16.380000859499,-0.000597801861227291,-0.000111118325154417,0.25,-6.23905066819049E-7,-5.2949114971113E-5,-6.8240878616515E-7,200.007431,200.007431,47167.515625,47177.1953125,56.7462304961599,20.5276006794354,27.464817,0,0,0,40,4449,200.0854,47172.35546875,,,,,,,,,,,,,0,,,,0,,,,,,200.007431,,,,
,22240944.525,200.0106735,51864.890625,-7.25102144234537E-5,2.11396401421849E-6,1,0.999253354069792,40.0298881530762,1.99822256568931,16.380000859499,-0.000829155466469566,-0.000108766836848427,0.25,3.01253735736763E-6,-7.27638881120365E-5,2.94565981872092E-6,200.010437,200.01091,51859.89453125,51869.88671875,56.381209977679,20.5272887524653,27.085165,0,0,0,40,4449,200.07545,51864.890625,,,,,,,,,,,,,0,,,,0.00245,,,,,,200.0106735,,,,
,22241038.79,200.012085,56577.3828125,-8.6360860775665E-5,2.78932157076919E-6,1,0.999253354069792,40.0298881530762,1.99811049779377,16.380000859499,-0.000983520317346828,-0.000152365983505448,0.25,1.57680963539767E-6,-8.66608654052883E-5,1.49038968925317E-6,200.012085,200.012085,56567.46875,56587.296875,56.6071006197368,20.5262417184894,27.464817,0,0,0,40,4449,200.064,56577.3828125,,,,,,,,,,,,,0,,,,-0.00245,,,,,,200.012085,,,,
,22241135.66,200.0133972,61417.44921875,-0.000105140474316844,1.72867914727817E-6,1,0.999253354069792,40.0298881530762,1.99822232502144,16.380000859499,-0.00119411482445403,-0.000204748290315525,0.25,2.24815912893669E-7,-0.0001055039412756,1.13975042048268E-7,200.0133972,200.0133972,61414.90234375,61419.99609375,56.5930313063906,20.5295707039319,27.085165,0,0,0,40,4449,200.0517,61417.44921875,,,,,,,,,,,,,0,,,,0,,,,,,200.0133972,,,,
,22241229.16,200.013382,66093.01171875,-0.000120222245108625,2.36061580061121E-6,1,0.999253354069792,40.0298881530762,1.99818671704551,16.380000859499,-0.00136246140705345,-0.000250923850545389,0.25,-1.22382578513827E-6,-0.000120636316543267,-1.35542795059502E-6,200.013382,200.013382,66088.140625,66097.8828125,56.6711941583137,20.5260056141888,27.085165,0,0,0,40,4449,200.0418,66093.01171875,,,,,,,,,,,,,0,,,,0,,,,,,200.013382,,,,
,22241324.155,200.0136261,70838.20703125,-0.00013654437164771,2.89015208623468E-6,1,0.999253354069792,40.0298881530762,1.99818876169401,16.380000859499,-0.00154835507881876,-0.000279720353240844,0.25,-9.26002157963467E-7,-0.000137015195175433,-1.07357277251217E-6,200.0136261,200.0136261,70825.8984375,70850.515625,56.7290346687368,20.5275367087996,27.085165,0,0,0,40,4449,200.031,70838.20703125,,,,,,,,,,,,,0,,,,0,,,,,,200.0136261,,,,
,22241417.64,200.0142822,75513.5390625,-0.000155629159277817,2.9349832762728E-6,1,0.999253354069792,40.0298881530762,1.99825466372735,16.380000859499,-0.00177339017669508,-0.000269502631938436,0.25,3.28872530871436E-6,-0.000156170420656972,3.13587515550541E-6,200.0142517,200.0143127,75508.1875,75518.890625,56.5781803645252,20.5264715004168,27.085165,0,0,0,40,4449,200.01985,75513.5390625,,,,,,,,,,,,,0,,,,-0.00245,,,,,,200.0142822,,,,
,22241514.565,200.0138397,80359.765625,-0.000167812218144082,2.40960542115055E-6,1,0.999253354069792,40.0298881530762,1.99826586487454,16.380000859499,-0.00191298197585005,-0.000286251770521654,0.25,3.92893482269126E-6,-0.00016839630243246,3.76581932571164E-6,200.0138397,200.0138397,80351.9453125,80367.5859375,56.5867782782368,20.5266176857231,27.085165,0,0,0,40,4449,200.00675,80359.765625,,,,,,,,,,,,,0,,,,0,,,,,,200.0138397,,,,
,22241609.305,200.0131683,85095.28125,-0.000190886235240666,3.27145048132228E-6,1,0.999253354069792,40.0298881530762,1.99827806878692,16.380000859499,-0.00216817932482022,-0.000370812627927117,0.25,4.87602159964279E-7,-0.000191546503446269,2.88731556713154E-7,200.0131683,200.0131683,85090.6796875,85099.8828125,56.5992843345444,20.5238771155216,26.705515,0,0,0,40,4449,200.00335,85095.28125,,,,,,,,,,,,,0,,,,0,,,,,,200.0131683,,,,
,22241697.47,200.0147705,89500.8359375,-0.000204496072482216,3.0325077810195E-6,1,0.999253354069792,40.0298881530762,1.99832164279192,16.380000859499,-0.00232808705288618,-0.000366901763770042,0.25,3.1957542861186E-6,-0.000205206266947096,2.9923566504155E-6,200.0147705,200.0147705,89498.3984375,89503.2734375,56.6094455052945,20.5256740071288,26.705515,0,0,0,40,4449,199.9823,89500.8359375,,,,,,,,,,,,,0,,,,0.0049,,,,,,200.0147705,,,,
,22241804.455,200.0092468,86139.08203125,-0.000189376654741487,2.52783187943899E-6,1,0.999253354069792,40.0298881530762,1.99823011133234,16.380000859499,-0.00215406582310768,-0.000350124247200579,0.25,2.04690482912064E-6,-0.000190033376298169,1.85507041151017E-6,200.0092468,200.0092468,86134.15625,86144.0078125,56.7149653553906,20.5251273332346,26.705515,0,0,0,40,4449,199.97365,86139.08203125,,,,,,,,,,,,,0,,,,-0.0049,,,,,,200.0092468,,,,
,22241895.63,200.0040131,81580.37109375,-0.000173373886771371,2.98703457595374E-6,1,0.999253354069792,40.0298881530762,1.9982696443442,16.380000859499,-0.00196633438373423,-0.000353625583493286,0.25,-1.03948498303584E-6,-0.000173972026003885,-1.22556622463252E-6,200.0040131,200.0040131,81570.1875,81590.5546875,56.6156985334483,20.5216718890247,27.085165,0,0,0,40,4449,199.9697,81580.37109375,,,,,,,,,,,,,0,,,,-0.0049,,,,,,200.0040131,,,,
,22241990.25,200.0005341,76849.2265625,-0.000159112589198685,2.85575008448541E-6,1,0.999253354069792,40.0298881530762,1.99838918200946,16.380000859499,-0.00180382280319914,-0.000329556962750169,0.25,-1.39410896514433E-6,-0.000159661027981293,-1.56675973250487E-6,200.0005341,200.0005341,76841.484375,76856.96875,56.7016776705637,20.531810275598,27.464817,0,0,0,40,4449,199.9766,76849.2265625,,,,,,,,,,,,,0,,,,0,,,,,,200.0005341,,,,
,22242085.07,199.9962616,72108.265625,-0.000144718565010006,2.31726872498936E-6,1,0.999253354069792,40.0298881530762,1.99834255857641,16.380000859499,-0.00165021558101446,-0.000244391721137152,0.25,3.60694428507579E-6,-0.000145222513878034,3.46643776844745E-6,199.9962616,199.9962616,72103.09375,72113.4375,56.7782772654483,20.5300827454937,27.085165,0,0,0,40,4449,199.9823,72108.265625,,,,,,,,,,,,,0,,,,0,,,,,,199.9962616,,,,
,22242179.825,199.9918671,67372.6640625,-0.000128539617431341,2.19167503496465E-6,1,0.999253354069792,40.0298881530762,1.99837097851153,16.380000859499,-0.00146611243747178,-0.000214973615682143,0.25,3.3888547038319E-6,-0.000128987408204226,3.26441473737518E-6,199.9918671,199.9918671,67365.234375,67380.09375,56.6086638767752,20.5284381812348,27.464817,0,0,0,40,4449,199.99085,67372.6640625,,,,,,,,,,,,,0,,,,-0.00245,,,,,,199.9918671,,,,
,22242278.75,199.9891663,62427.505859375,-0.000108463453341937,1.79266672383792E-6,1,0.999253354069792,40.0298881530762,1.99825362156898,16.380000859499,-0.00123205494715977,-0.000210183145821722,0.25,3.2347160850199E-7,-0.000108838594138876,2.09459468414242E-7,199.9891663,199.9891663,62422.515625,62432.49609375,56.6680676442368,20.5278148729183,27.844467,0,0,0,40,4449,200.00115,62427.505859375,,,,,,,,,,,,,0,,,,-0.0049,,,,,,199.9891663,,,,
,22242374.015,199.9916534,57666.47265625,-9.53414795492718E-5,2.315647796285E-6,1,0.999253354069792,40.0298881530762,1.99830751548605,16.380000859499,-0.00108915429726891,-0.000149481939094831,0.25,3.39174351714609E-6,-9.56745033974862E-5,3.30205284944345E-6,199.9916534,199.9916534,57653.9921875,57678.953125,56.6156985334483,20.5284717083643,27.464817,0,0,0,40,4449,200.00425,57666.47265625,,,,,,,,,,,,,0,,,,0,,,,,,199.9916534,,,,
,22242468.03,199.9921417,52966.326171875,-7.81041143937139E-5,1.8918016655393E-6,1,0.999253354069792,40.0298881530762,1.99840852179926,16.380000859499,-0.000888830878575685,-0.000142335434995306,0.25,1.02837018543547E-6,-7.83750444189175E-5,9.48684113612071E-7,199.9921417,199.9921417,52956.31640625,52976.3359375,56.8032893780637,20.5307668450634,27.085165,0,0,0,40,4449,200.0121,52966.326171875,,,,,,,,,,,,,0,,,,-0.00245,,,,,,199.9921417,,,,
,22242566.14,199.9934692,48063.798828125,-6.06093235641351E-5,1.46152402017101E-6,1,0.999253354069792,40.0298881530762,1.9984133710328,16.380000859499,-0.000693679106616532,-8.77733008811103E-5,0.25,2.7956800411953E-6,-6.08216803840305E-5,2.740612182407E-6,199.9934692,199.9934692,48054.04296875,48073.5546875,56.8658196596022,20.5293936241001,27.464817,0,0,0,40,4449,200.0183,48063.798828125,,,,,,,,,,,,,0,,,,0.0049,,,,,,199.9934692,,,,
,22242661.97,199.9905243,43273.466796875,-4.57917295807036E-5,1.82877708435378E-6,1,0.999253354069792,40.0298881530762,1.99846038328754,16.380000859499,-0.000523164996936799,-7.17121419656892E-5,0.25,1.63706628541492E-6,-4.59516566743356E-5,1.59372495387733E-6,199.9905243,199.9905243,43265.84765625,43281.0859375,56.7446672391214,20.532135150834,27.085165,0,0,0,40,4449,200.02695,43273.466796875,,,,,,,,,,,,,0,,,,0.00245,,,,,,199.9905243,,,,
,22242754.25,199.9902954,38663.712890625,-2.82509585689184E-5,1.61804209419774E-6,1,0.999253354069792,40.0298881530762,1.99832621285897,16.380000859499,-0.000325440352814534,-2.87090279196507E-5,0.25,2.37792486820447E-6,-2.83510851817151E-5,2.35585479520775E-6,199.9902954,199.9902954,38658.75390625,38668.671875,56.7032409276022,20.5284023591481,26.705515,0,0,0,40,4449,200.03385,38663.712890625,,,,,,,,,,,,,0,,,,0.0049,,,,,,199.9902954,,,,
,22242851.12,199.990509,33821.365234375,-1.46567915975679E-5,1.06283748074779E-6,1,0.999253354069792,40.0298881530762,1.99850797817019,16.380000859499,-0.00017388075109625,1.40393785811655E-5,0.25,3.78202419288173E-6,-1.47114728574522E-5,3.77934509763173E-6,199.990509,199.990509,33811.359375,33831.37109375,56.7774956369291,20.528372472872,27.085165,0,0,0,40,4449,200.03965,33821.365234375,,,,,,,,,,,,,0,,,,-0.00245,,,,,,199.990509,,,,
,22242944.205,199.988266,29168.9248046875,6.98406212235665E-7,1.24140303913154E-6,1,0.999253354069792,40.0298881530762,1.99849340711523,16.380000859499,5.94557458546756E-6,1.28034597051281E-5,0.25,1.00630718587303E-6,6.99735477558667E-7,1.0105338064645E-6,199.988266,199.988266,29158.962890625,29178.88671875,56.8525319747752,20.5278318603553,27.085165,0,0,0,40,4449,200.0459,29168.9248046875,,,,,,,,,,,,,0,,,,0,,,,,,199.988266,,,,
,22243037.85,199.9821472,24488.4296875,1.48721959487658E-5,9.14603051654367E-7,1,0.999253354069792,40.0298881530762,1.99859279998982,16.380000859499,0.000166507645370504,4.29603847314492E-5,0.25,1.20031837801341E-6,1.49222618873608E-5,1.22049078501888E-6,199.9821472,199.9821472,24481.25390625,24495.60546875,56.8025077495445,20.52932121905,27.464817,0,0,0,40,4449,200.0592,24488.4296875,,,,,,,,,,,,,0,,,,0.0049,,,,,,199.9821472,,,,
,22243140.415,199.98355865,19361.283203125,2.95082425257856E-5,8.25439864067346E-7,1,0.999253354069792,40.0298881530762,1.99856776690992,16.380000859499,0.000331695256059881,7.7591662527495E-5,0.25,1.70816637942931E-6,2.96082922765318E-5,1.74592081220394E-6,199.9831238,199.9839935,19354.080078125,19368.486328125,56.8798889729483,20.5299092741274,27.085165,0,0,0,40,4449,200.0739,19361.283203125,,,,,,,,,,,,,0,,,,-0.00245,,,,,,199.98355865,,,,
,22243239.08,199.9865723,14432.177734375,4.37465589507082E-5,6.59863094610191E-7,1,0.999253354069792,40.0298881530762,1.99849273334113,16.380000859499,0.000496106368096937,8.98128267614487E-5,0.25,3.1168358054559E-7,4.38972659226533E-5,3.6006341685849E-7,199.9865723,199.9865723,14422.23046875,14442.125,56.8251749766022,20.5306455077571,27.085165,0,0,0,40,4449,200.0858,14432.177734375,,,,,,,,,,,,,0,,,,-0.00245,,,,,,199.9865723,,,,
,22243336.725,199.9933777,9549.82373046875,5.60247359837124E-5,5.39070238108907E-7,1,0.999253354069792,40.0298881530762,1.99857945745314,16.380000859499,0.000636096612239736,0.000110856635134644,0.25,3.19776456917634E-8,5.6218111843154E-5,9.27619058831935E-8,199.9933777,199.9933777,9539.9873046875,9559.66015625,56.8970848003714,20.5338053366754,27.464817,0,0,0,40,4449,200.08935,9549.82373046875,,,,,,,,,,,,,0,,,,-0.00245,,,,,,199.9933777,,,,
,22243432.31,199.9998169,4774.09887695313,6.02126275798157E-5,4.01019032473393E-7,1,0.999253354069792,40.0298881530762,1.99847895093408,16.380000859499,0.000683664176475303,0.00011883830140041,0.25,7.92796333500482E-9,6.04204607737177E-5,7.32555691984595E-8,199.9998169,199.9998169,4771.30615234375,4776.8916015625,56.8157954343714,20.5338390191408,27.085165,0,0,0,40,4449,200.0874,4774.09887695313,,,,,,,,,,,,,0,,,,0,,,,,,199.9998169,,,,
,22243527.815,200.0072021,-1.83863878250122,3.65047199281425E-5,3.23996413073986E-7,1,0.999253354069792,40.0298881530762,1.99855566815831,16.380000859499,0.000415493145193324,6.6307086202763E-5,0.25,-5.01000892926122E-7,3.66312552032882E-5,-4.63095984397779E-7,200.0072021,200.0072021,-12.0106563568115,8.33337879180908,56.8540952318137,20.5343618656574,26.705515,0,0,0,40,4449,200.0766,-1.83863878250122,,,,,,,,,,,,,0,,,,0,,,,,,200.0072021,,,,
,22243624.745,200.0142975,-4843.4345703125,-3.77258924649857E-5,3.83506650264707E-7,1,0.999253354069792,40.0298881530762,1.99865146721467,16.380000859499,-0.000426720871413872,-8.40222966618793E-5,0.25,-8.46742560111302E-7,-3.7855177409068E-5,-8.90583192249086E-7,200.0142975,200.0142975,-4850.8515625,-4836.017578125,56.8986480574099,20.5352928498921,26.705515,0,0,0,40,4449,200.06575,-4843.4345703125,,,,,,,,,,,,,0,,,,0.00245,,,,,,200.0142975,,,,
,22243723.29,200.0209503,-9769.62158203125,-5.21228448915341E-5,5.2897470960183E-7,1,0.999253354069792,40.0298881530762,1.99856889580442,16.380000859499,-0.000588656927613033,-0.000121182814366752,0.25,-1.61913993546188E-6,-5.2300982014224E-5,-1.68118754564046E-6,200.0209503,200.0209503,-9774.6015625,-9764.6416015625,56.8626931455252,20.5353839908532,27.464817,0,0,0,40,4449,200.0463,-9769.62158203125,,,,,,,,,,,,,0,,,,0,,,,,,200.0209503,,,,
,22243822.555,200.02392575,-14729.4228515625,-4.16364932376485E-5,7.38957601179748E-7,1,0.999253354069792,40.0298881530762,1.99857091130922,16.380000859499,-0.000470151270519143,-9.72463790900318E-5,0.25,-1.33253020108338E-6,-4.17787570915627E-5,-1.38216425482402E-6,200.0232391,200.0246124,-14737.0244140625,-14721.8212890625,56.8806706014676,20.5343496312716,27.464817,0,0,0,40,4449,200.0238,-14729.4228515625,,,,,,,,,,,,,0,,,,-0.0049,,,,,,200.02392575,,,,
,22243912.715,200.0243683,-19236.6748046875,-3.11893606367333E-5,9.17276588892478E-7,1,0.999253354069792,40.0298881530762,1.99871502962087,16.380000859499,-0.00034881796310705,-9.23726901297082E-5,0.25,-2.71733358858796E-6,-3.12940801514162E-5,-2.76039920020982E-6,200.0243683,200.0243683,-19239.076171875,-19234.2734375,56.8970848003714,20.5368253703744,27.464817,0,0,0,40,4449,200.007,-19236.6748046875,,,,,,,,,,,,,0,,,,0,,,,,,200.0243683,,,,
,22244004.61,200.0231781,-23829.2607421875,-1.61124029208672E-5,1.19741849190535E-6,1,0.999253354069792,40.0298881530762,1.99871160001201,16.380000859499,-0.000177540745768936,-6.3024235264357E-5,0.25,-2.75154754918845E-6,-1.61650543920768E-5,-2.7784213451932E-6,200.0231781,200.0231781,-23836.69140625,-23821.830078125,56.8697278021983,20.5371961042705,26.705515,0,0,0,40,4449,199.98775,-23829.2607421875,,,,,,,,,,,,,0,,,,-0.00245,,,,,,200.0231781,,,,
,22244097.125,200.0185699,-28454.21484375,-3.52663037144277E-6,1.08834075053053E-6,1,0.999253354069792,40.0298881530762,1.99859934189269,16.380000859499,-3.40124182551674E-5,-4.16900367270217E-5,0.25,-3.05896961894317E-6,-3.53551209719287E-6,-3.07332708474678E-6,200.0185699,200.0185699,-28464.0078125,-28444.421875,56.9549253107945,20.5363598732474,27.464817,0,0,0,40,4449,199.9742,-28454.21484375,,,,,,,,,,,,,0,,,,-0.0049,,,,,,200.0185699,,,,
,22244190.555,200.0152893,-33121.595703125,1.15462896532303E-5,9.62371174533028E-7,1,0.999253354069792,40.0298881530762,1.99860976171953,16.380000859499,0.000139323849202896,-2.45217493200253E-5,0.25,-4.16488247564953E-6,1.15906319687134E-5,-4.1668531911535E-6,200.0151672,200.0154114,-33126.515625,-33116.67578125,56.9283499411406,20.5371767445282,27.085165,0,0,0,40,4449,199.96495,-33121.595703125,,,,,,,,,,,,,0,,,,-0.00245,,,,,,200.0152893,,,,
,22244282.11,200.0120392,-37695.94140625,2.76348123433866E-5,1.31623093925115E-6,1,0.999253354069792,40.0298881530762,1.99871432311483,16.38999953866,0.000319674829180415,2.07555886926839E-5,0.25,-2.97179549782711E-6,2.77334265386712E-5,-2.95240959213991E-6,200.0120392,200.0120392,-37703.5234375,-37688.359375,56.9189703989099,20.5382324359509,27.464817,0,0,0,40,4449,199.96015,-37695.94140625,,,,,,,,,,,,,0,,,,0,,,,,,200.0120392,,,,
,22244374.57,200.0106049,-42318.541015625,4.06869345694402E-5,1.50515835005615E-6,1,0.999253354069792,40.0298881530762,1.99859242184851,16.380000859499,0.000467304157999448,4.97193744697521E-5,0.25,-2.6877426168719E-6,4.08303226311553E-5,-2.65345285297399E-6,200.0106049,200.0106049,-42321.11328125,-42315.96875,56.8986480574099,20.5369213884057,27.464817,0,0,0,40,4449,199.9503,-42318.541015625,,,,,,,,,,,,,0,,,,-0.0049,,,,,,200.0106049,,,,
,22244471.72,200.0088654,-47173.4609375,5.67555957757202E-5,1.66180071754773E-6,1,0.999253354069792,40.0298881530762,1.99875494228624,16.380000859499,0.000650547232108284,7.72031734572099E-5,0.25,-3.05849769093928E-6,5.69548871729859E-5,-3.00840024874342E-6,200.0088654,200.0088654,-47183.5390625,-47163.3828125,56.9846271945253,20.5372689049691,27.464817,0,0,0,40,4449,199.94205,-47173.4609375,,,,,,,,,,,,,0,,,,0,,,,,,200.0088654,,,,
,22244564.265,200.0103455,-51798.24609375,7.28829765633426E-5,1.5728295672213E-6,1,0.999253354069792,40.0298881530762,1.99882597572397,16.380000859499,0.000837126854244032,8.93844590805521E-5,0.25,-4.78684499056289E-6,7.3139824186457E-5,-4.72562863548415E-6,200.0103455,200.0103455,-51800.9375,-51795.5546875,56.9822823089676,20.5377267052306,27.085165,0,0,0,40,4449,199.93385,-51798.24609375,,,,,,,,,,,,,0,,,,0,,,,,,200.0103455,,,,
,22244664.77,200.011795,-56820.212890625,8.67636066486864E-5,1.93366359682993E-6,1,0.999253354069792,40.0298881530762,1.99879361685321,16.380000859499,0.000989573259910991,0.000146539349188541,0.25,-2.16427964833475E-6,8.70656198796323E-5,-2.07939034566551E-6,200.011795,200.011795,-56827.71484375,-56812.7109375,56.9619599674676,20.5400429066222,27.085165,0,0,0,40,4449,199.9228,-56820.212890625,,,,,,,,,,,,,0,,,,0.00245,,,,,,200.011795,,,,
,22244759.995,200.0054321,-61580.09765625,0.000106504367670232,2.1330756284054E-6,1,0.999253354069792,40.0298881530762,1.99873996174634,16.380000859499,0.00121992859268761,0.000149733891857821,0.25,-5.31077786038338E-6,0.000106877966021174,-5.21597787233372E-6,200.0054321,200.0054321,-61584.8671875,-61575.328125,57.054973761256,20.5387818075843,27.464817,0,0,0,40,4449,199.9206,-61580.09765625,,,,,,,,,,,,,0,,,,-0.0049,,,,,,200.0054321,,,,
,22244853.03,200.0050201,-66227.1953125,0.000119261791216336,2.17200998546987E-6,1,0.999253354069792,40.0298881530762,1.99864621175431,16.380000859499,0.00136145835906698,0.000193782466173507,0.25,-3.64640202177747E-6,0.000119677726912709,-3.53255384926539E-6,200.0050201,200.0050201,-66236.921875,-66217.46875,56.994006736756,20.540569696508,27.464817,0,0,0,40,4449,199.914,-66227.1953125,,,,,,,,,,,,,0,,,,-0.00245,,,,,,200.0050201,,,,
,22244951.75,199.9984894,-71164.1875,0.000136586611541326,2.41013747493906E-6,1,0.999253354069792,40.0298881530762,1.99868573210127,16.380000859499,0.0015593336978026,0.000221533953959319,0.25,-4.21127353145045E-6,0.000137063072575675,-4.08133435864758E-6,199.9984894,199.9984894,-71174.1484375,-71154.2265625,57.0260535060445,20.5384701629578,27.464817,0,0,0,40,4449,199.91975,-71164.1875,,,,,,,,,,,,,0,,,,-0.00245,,,,,,199.9984894,,,,
,22245053.39,199.9997559,-76243.5078125,0.000157562425178057,2.36991073732207E-6,1,0.999253354069792,40.0298881530762,1.99870254369722,16.380000859499,0.00179487718528823,0.000278248863311872,0.25,-2.8593871083258E-6,0.000158109983898768,-2.7029666605932E-6,199.9997559,199.9997559,-76251.03125,-76235.984375,56.9924434797176,20.5399317868225,27.085165,0,0,0,40,4449,199.9176,-76243.5078125,,,,,,,,,,,,,0,,,,0.0049,,,,,,199.9997559,,,,
,22245150.095,200.0020905,-81075.89453125,0.000175088753198967,2.23744725193191E-6,1,0.999253354069792,40.0298881530762,1.99869384584956,16.38999953866,0.00199639834964629,0.000298387908005213,0.25,-4.12903789216069E-6,0.000175698258329009,-3.95891042503217E-6,200.0020905,200.0020905,-81083.359375,-81068.4296875,56.9815006804483,20.5405032707055,27.464817,0,0,0,40,4449,199.9136,-81075.89453125,,,,,,,,,,,,,0,,,,0,,,,,,200.0020905,,,,
,22245248.36,200.0120544,-85985.14453125,0.00019413816873,2.68293689608218E-6,1,0.999253354069792,40.0298881530762,1.99878672102151,16.380000859499,0.00221678135181359,0.000313132966113148,0.25,-6.13941612492179E-6,0.000194815617585912,-5.9566253564667E-6,200.0120544,200.0120544,-85990.203125,-85980.0859375,57.0135474497368,20.5389893851432,27.464817,0,0,0,40,4449,199.9043,-85985.14453125,,,,,,,,,,,,,0,,,,0,,,,,,200.0120544,,,,
,22245364.79,200.0232849,-89194.61328125,0.000201734515684404,2.18908834836172E-6,1,0.999253354069792,40.0298881530762,1.99875563180601,16.380000859499,0.00229798599809277,0.000357053434367536,0.25,-3.59027756654431E-6,0.000202435501542863,-3.39097767021444E-6,200.0232849,200.0232849,-89207.0390625,-89182.1875,56.9830639374868,20.5393086842575,27.464817,0,0,0,40,4449,199.8799,-89194.61328125,,,,,,,,,,,,,0,,,,-0.0049,,,,,,200.0232849,,,,
,22245459.755,200.0203857,-84450.7734375,0.000189191898225236,2.51170550405229E-6,1,0.999253354069792,40.0298881530762,1.99876089978821,16.380000859499,0.00215402425007819,0.000341143237669089,0.25,-2.81376124234588E-6,0.000189848679971685,-2.624482586584E-6,200.0203857,200.0203857,-84460.671875,-84440.875,56.9674313671022,20.5406369769163,27.464817,0,0,0,40,4449,199.8634,-84450.7734375,,,,,,,,,,,,,0,,,,0,,,,,,200.0203857,,,,
,22245564.21,200.0198669,-79226.265625,0.000172798656832465,2.00530725163574E-6,1,0.999253354069792,40.0298881530762,1.99900540726432,16.380000859499,0.00200170289564943,0.000115297821153697,0.25,-1.98562628705061E-5,0.000173416701934026,-1.97426617568513E-5,200.0198669,200.0198669,-79238.75,-79213.78125,57.190195495083,20.546251934737,27.085165,0,0,0,40,4449,199.8466,-79226.265625,,,,,,,,,,,,,0,,,,-0.00245,,,,,,200.0198669,,,,
,22245664.895,200.0177155,-74197.0234375,0.000149569563925734,2.09490665557102E-6,1,0.999253354069792,40.0298881530762,1.99884431539161,16.380000859499,0.00170105818457248,0.000280747395234991,0.25,-1.25320282275376E-6,0.000150087683977655,-1.09943909557398E-6,200.0177155,200.0177155,-74206.96875,-74187.078125,57.0612267894099,20.5412627225613,27.844467,0,0,0,40,4449,199.8329,-74197.0234375,,,,,,,,,,,,,0,,,,0,,,,,,200.0177155,,,,
,22245757.45,200.0089874,-69572.4453125,0.000130755304430616,2.74612370276258E-6,1,0.999253354069792,40.0298881530762,1.99885765792451,16.38999953866,0.0014963824163961,0.000191940980452458,0.25,-5.80616488854181E-6,0.000131213238084112,-5.6877254640913E-6,200.0089874,200.0089874,-69575.03125,-69569.859375,56.9947883652753,20.5415919677672,27.464817,0,0,0,40,4449,199.8261,-69572.4453125,,,,,,,,,,,,,0,,,,-0.00245,,,,,,200.0089874,,,,
,22245852.275,200.0054016,-64832.666015625,0.000110984320624282,2.48210193544317E-6,1,0.999253354069792,40.0298881530762,1.99872616869073,16.380000859499,0.00126590917703239,0.000186697462835685,0.25,-2.83358787368424E-6,0.00011137077681072,-2.72557026284718E-6,200.0054016,200.0054016,-64837.734375,-64827.59765625,56.8736359447945,20.5382329414808,27.844467,0,0,0,40,4449,199.8248,-64832.666015625,,,,,,,,,,,,,0,,,,0.0049,,,,,,200.0054016,,,,
,22245944.835,199.9980621,-60207.986328125,9.96891317828675E-5,1.91892994254769E-6,1,0.999253354069792,40.0298881530762,1.9987025961518,16.380000859499,0.00113682021489298,0.00016908248629061,0.25,-2.42322006359845E-6,0.000100036126346058,-2.32556134073263E-6,199.9980621,199.9980621,-60220.3125,-60195.66015625,57.0026046504676,20.5426335579811,27.844467,0,0,0,40,4449,199.8285,-60207.986328125,,,,,,,,,,,,,0,,,,-0.00245,,,,,,199.9980621,,,,
,22246039.44,199.9934998,-55478.16796875,8.14689033261941E-5,1.54323075447298E-6,1,0.999253354069792,40.0298881530762,1.99873885137692,16.380000859499,0.000931269809280771,0.00012545195490275,0.25,-3.10147010623451E-6,8.17536636989725E-5,-3.02535957707628E-6,199.9934998,199.9934998,-55483.24609375,-55473.08984375,57.047939104583,20.5402844432369,27.464817,0,0,0,40,4449,199.83575,-55478.16796875,,,,,,,,,,,,,0,,,,0,,,,,,199.9934998,,,,
,22246133.22,199.9869995,-50791.369140625,6.9377000442906E-5,1.81635597920816E-6,1,0.999253354069792,40.0298881530762,1.99875173979026,16.380000859499,0.000800655487656225,6.30539270758076E-5,0.25,-6.49640549926444E-6,6.96236119174753E-5,-6.44476624960929E-6,199.9869995,199.9869995,-50796.5,-50786.23828125,56.9549253107945,20.5399361829913,27.464817,0,0,0,40,4449,199.8452,-50791.369140625,,,,,,,,,,,,,0,,,,0,,,,,,199.9869995,,,,
,22246231.55,199.9856262,-45879.173828125,5.28454265118386E-5,1.31911969945845E-6,1,0.999253354069792,40.0298881530762,1.99877492787631,16.380000859499,0.000606154844616354,6.94621173848461E-5,0.25,-3.06119779423563E-6,5.30312513380085E-5,-3.01523160093062E-6,199.9856262,199.9856262,-45889.0859375,-45869.26171875,56.9869720800829,20.5379994043216,27.464817,0,0,0,40,4449,199.85965,-45879.173828125,,,,,,,,,,,,,0,,,,-0.00245,,,,,,199.9856262,,,,
,22246329.82,199.9831696,-40966.90234375,3.5807376573551E-5,1.27172626765101E-6,1,0.999253354069792,40.0298881530762,1.99878801142879,16.380000859499,0.000411964857797964,3.99291870295596E-5,0.25,-2.70283680192333E-6,3.59339593081711E-5,-2.67378721188696E-6,199.9831696,199.9831696,-40976.98046875,-40956.82421875,56.9322580837368,20.5383478780014,27.085165,0,0,0,40,4449,199.87295,-40966.90234375,,,,,,,,,,,,,0,,,,0,,,,,,199.9831696,,,,
,22246425.335,199.9731445,-36194.501953125,2.09746929582573E-5,1.26468372092585E-6,1,0.999253354069792,40.0298881530762,1.99870605972276,16.380000859499,0.000242821994618277,1.46538850190326E-5,0.25,-2.35242267736487E-6,2.10496708043344E-5,-2.33802291767221E-6,199.9731445,199.9731445,-36199.59375,-36189.41015625,56.953362053756,20.5379215892112,27.844467,0,0,0,40,4449,199.89195,-36194.501953125,,,,,,,,,,,,,0,,,,-0.0049,,,,,,199.9731445,,,,
,22246525.33,199.9613342,-31195.140625,3.84418662334698E-6,1.02657388669807E-6,1,0.999253354069792,40.0298881530762,1.9987135730186,16.380000859499,4.91722652125699E-5,-2.41929339150894E-5,0.25,-2.79811997853024E-6,3.86047601083384E-6,-2.80365010217926E-6,199.9613342,199.9613342,-31197.650390625,-31192.630859375,57.0807675023906,20.5367041673141,27.844467,0,0,0,40,4449,199.9298,-31195.140625,,,,,,,,,,,,,0,,,,0,,,,,,199.9613342,,,,
,22246626.93,199.9628754,-26117.5771484375,-1.16170928573826E-5,1.4511739511137E-6,1,0.999253354069792,40.0298881530762,1.99868673185361,16.380000859499,-0.000124854703929922,-6.35853377752679E-5,0.25,-3.5817840003415E-6,-1.16533587471149E-5,-3.60667471247862E-6,199.9628754,199.9628754,-26130.099609375,-26105.0546875,56.9408559974483,20.5389265366515,27.844467,0,0,0,40,4449,199.9645,-26117.5771484375,,,,,,,,,,,,,0,,,,-0.00245,,,,,,199.9628754,,,,
,22246729.96,199.9742584,-20968.642578125,-2.56989532262672E-5,8.57296698000156E-7,1,0.999253354069792,40.0298881530762,1.99883739029661,16.380000859499,-0.00029136026357889,-5.34948222868393E-5,0.25,-2.47027304238219E-7,-2.57874346648245E-5,-2.75623429896805E-7,199.9742584,199.9742584,-20978.5078125,-20958.77734375,57.1096877576022,20.5358143010776,27.844467,0,0,0,40,4449,199.9856,-20968.642578125,,,,,,,,,,,,,0,,,,0,,,,,,199.9742584,,,,
,22246831.6,199.9906921,-15888.6196289062,-4.06561336633027E-5,8.55875614146249E-7,1,0.999253354069792,40.0298881530762,1.9988409569671,16.380000859499,-0.000457914790966146,-0.000102028621262395,0.25,-1.92280524886452E-6,-4.07944217104843E-5,-1.97341054054837E-6,199.9906921,199.9906921,-15896.41015625,-15880.8291015625,56.9815006804483,20.5380547919996,27.844467,0,0,0,40,4449,199.9899,-15888.6196289062,,,,,,,,,,,,,0,,,,0,,,,,,199.9906921,,,,
,22246930.065,200.0057373,-10969.4985351562,-5.35333770976802E-5,5.00428301522632E-7,1,0.999253354069792,40.0298881530762,1.99880309711342,16.380000859499,-0.000605783868443318,-0.000117976187378671,0.25,-1.09057821176228E-6,-5.37169816434736E-5,-1.15233149820464E-6,200.0057373,200.0057373,-10979.5087890625,-10959.48828125,56.9424192544868,20.5362390965348,27.085165,0,0,0,40,4449,199.98235,-10969.4985351562,,,,,,,,,,,,,0,,,,0,,,,,,200.0057373,,,,
,22247027.905,200.0155792,-6078.76000976563,-6.05004255084124E-5,4.52962587632851E-7,1,0.999253354069792,40.0298881530762,1.99887679805107,16.380000859499,-0.000685217742639878,-0.000130046890316954,0.25,-9.42900782189088E-7,-6.07082021658679E-5,-1.01179418032116E-6,200.0155792,200.0155792,-6086.4599609375,-6071.06005859375,57.0838940164676,20.537660782406,27.085165,0,0,0,40,4449,199.96455,-6078.76000976563,,,,,,,,,,,,,0,,,,0.0049,,,,,,200.0155792,,,,
,22247128.61,200.0224762,-1042.49493408203,-4.98807942339411E-5,4.04227950693146E-7,1,0.999253354069792,40.0298881530762,1.99876958755059,16.380000859499,-0.000565903330104946,-0.000101509057684717,0.25,-2.74924913897148E-7,-5.00526221798577E-5,-3.30065834522617E-7,200.0224762,200.0224762,-1047.66772460938,-1037.32214355469,56.9142806277945,20.5364803358929,27.464817,0,0,0,40,4449,199.9447,-1042.49493408203,,,,,,,,,,,,,0,,,,0.00245,,,,,,200.0224762,,,,
,22247227.015,200.0210114,3870.68383789063,2.88570439819916E-5,3.3165092371812E-7,1,0.999253354069792,40.0298881530762,1.99879237820108,16.380000859499,0.000327048960782088,6.06896174971383E-5,0.25,3.32006975475022E-7,2.89562660373357E-5,3.6448747480371E-7,200.0210114,200.0210114,3860.79833984375,3880.5693359375,56.9056827140829,20.5365293526445,27.085165,0,0,0,40,4449,199.9238,3870.68383789063,,,,,,,,,,,,,0,,,,0,,,,,,200.0210114,,,,
,22247319.07,200.0180206,8474.5078125,5.37487361394495E-5,4.44698528355506E-7,1,0.999253354069792,40.0298881530762,1.99863485572328,16.380000859499,0.000610233497388456,0.000106570289705522,0.25,4.94850366853121E-8,5.39341795396693E-5,1.07947835639078E-7,200.0180206,200.0180206,8469.4423828125,8479.5732421875,56.9908802226791,20.5353854726844,27.464817,0,0,0,40,4449,199.9135,8474.5078125,,,,,,,,,,,,,0,,,,-0.00245,,,,,,200.0180206,,,,
,22247414.74,200.0156555,13254.9501953125,4.78285688440981E-5,5.92420711082945E-7,1,0.999253354069792,40.0298881530762,1.99871105816977,16.380000859499,0.000541649262014513,0.000102837513056552,0.25,7.48773613269705E-7,4.79928381135629E-5,8.03155139428763E-7,200.0156555,200.0156555,13247.1962890625,13262.7041015625,56.7782772654483,20.5336768125867,27.464817,0,0,0,40,4449,199.9018,13254.9501953125,,,,,,,,,,,,,0,,,,0,,,,,,200.0156555,,,,
,22247507.085,200.01137545,17870.7197265625,3.65174790325606E-5,7.95088698760433E-7,1,0.999253354069792,40.0298881530762,1.99872114483864,16.380000859499,0.000412694005744482,8.34778147831098E-5,0.25,1.00855174720152E-6,3.66424422480831E-5,1.05152185930833E-6,200.0109253,200.0118256,17865.634765625,17875.8046875,56.9377294833714,20.5342636702592,27.464817,0,0,0,40,4449,199.88995,17870.7197265625,,,,,,,,,,,,,0,,,,-0.00245,,,,,,200.01137545,,,,
,22247599,200.0108337,22465.7333984375,2.37422280361258E-5,8.2423259832457E-7,1,0.999253354069792,40.0298881530762,1.9986865538602,16.380000859499,0.000266339330896389,6.5636949254756E-5,0.25,1.65649010852855E-6,2.38224013333459E-5,1.68784155521461E-6,200.0108337,200.0108337,22453.177734375,22478.2890625,56.8056342636214,20.532950994056,27.464817,0,0,0,40,4449,199.88405,22465.7333984375,,,,,,,,,,,,,0,,,,-0.0049,,,,,,200.0108337,,,,
,22247696.19,200.0069885,27321.1708984375,8.84809051616806E-6,1.18633918057225E-6,1,0.999253354069792,40.0298881530762,1.99888139316792,16.380000859499,9.76622230779841E-5,3.37019535032001E-5,0.25,1.43083903439991E-6,8.87709695720796E-6,1.44531505020885E-6,200.0069885,200.0069885,27311.09765625,27331.244140625,57.1526773261599,20.5366390027726,27.464817,0,0,0,40,4449,199.8771,27321.1708984375,,,,,,,,,,,,,0,,,,0.0049,,,,,,200.0069885,,,,
,22247796.33,200.0029602,32326.294921875,-6.1510369951231E-6,1.14296594321262E-6,1,0.999253354069792,40.0298881530762,1.99870578761257,16.380000859499,-7.33114796110952E-5,7.80297259848561E-6,0.25,1.75545973913203E-6,-6.17416478883139E-6,1.754904736431E-6,200.0029602,200.0029602,32318.771484375,32333.818359375,56.7993812354675,20.5361181426191,27.085165,0,0,0,40,4449,199.87545,32326.294921875,,,,,,,,,,,,,0,,,,0,,,,,,200.0029602,,,,
,22247887.315,199.9922714,36873.501953125,-2.10653049745621E-5,1.10931146076893E-6,1,0.999253354069792,40.0298881530762,1.99863591476717,16.380000859499,-0.000241907407506231,-2.59746708485123E-5,0.25,1.37115311242067E-6,-2.11395289725718E-5,1.35326970724311E-6,199.9920654,199.9924774,36870.859375,36876.14453125,56.9822823089676,20.5314328869806,27.464817,0,0,0,40,4449,199.8769,36873.501953125,,,,,,,,,,,,,0,,,,0.0049,,,,,,199.9922714,,,,
,22247986.405,199.98631285,41828.44921875,-3.84781313881575E-5,1.38424126493262E-6,1,0.999253354069792,40.0298881530762,1.99863084983508,16.380000859499,-0.000438468716989565,-6.70294663670529E-5,0.25,7.79826445703461E-7,-3.86118764405057E-5,7.41291378484692E-7,199.9862518,199.9863739,41823.45703125,41833.44140625,56.831428004756,20.5328867535052,27.464817,0,0,0,40,4449,199.89475,41828.44921875,,,,,,,,,,,,,0,,,,0.00245,,,,,,199.98631285,,,,
,22248087.695,199.9871826,46891.0078125,-5.53646574220368E-5,1.66585128774462E-6,1,0.999253354069792,40.0298881530762,1.99862594263301,16.380000859499,-0.000629853261074162,-0.000102437946263448,0.25,5.94239892368414E-7,-5.55565481032525E-5,5.37098903430656E-7,199.9871826,199.9871826,46886.03515625,46895.98046875,56.7626446950637,20.5316439543689,27.085165,0,0,0,40,4449,199.90765,46891.0078125,,,,,,,,,,,,,0,,,,0.00245,,,,,,199.9871826,,,,
,22248190.405,199.9930878,52021.205078125,-7.1332042999517E-5,1.90751954726697E-6,1,0.999253354069792,40.0298881530762,1.99861115079001,16.380000859499,-0.000813457778822177,-0.000120706447176349,0.25,1.7583120252403E-6,-7.15803431449475E-5,1.68828658102759E-6,199.9930878,199.9930878,52018.66796875,52023.7421875,56.7149653553906,20.5308722038961,27.464817,0,0,0,40,4449,199.91015,52021.205078125,,,,,,,,,,,,,0,,,,-0.0049,,,,,,199.9930878,,,,
,22248291.13,200.0066681,57058.046875,-8.87064678559397E-5,1.68347577396302E-6,1,0.999253354069792,40.0298881530762,1.99863270350505,16.380000859499,-0.00101196269405809,-0.000148036394123062,0.25,2.36887162707426E-6,-8.90154249803069E-5,2.2826191541821E-6,200.0066681,200.0066681,57050.6484375,57065.4453125,56.8478422036599,20.529774130072,27.464817,0,0,0,40,4449,199.9026,57058.046875,,,,,,,,,,,,,0,,,,-0.0049,,,,,,200.0066681,,,,
,22248389.33,200.0214233,61966.0390625,-0.000106590168444977,2.35199249187911E-6,1,0.999253354069792,40.0298881530762,1.99869682005005,16.380000859499,-0.00121956241366982,-0.000157470298427127,0.25,4.64412736947431E-6,-0.000106963297698566,4.54692233616247E-6,200.0214233,200.0214233,61958.59765625,61973.48046875,56.7978179784291,20.5281827032156,27.085165,0,0,0,40,4449,199.88095,61966.0390625,,,,,,,,,,,,,0,,,,-0.0049,,,,,,200.0214233,,,,
,22248487.95,200.0278625,66894.0390625,-0.000123821316097849,2.89358192394679E-6,1,0.999253354069792,40.0298881530762,1.99872086615419,16.380000859499,-0.00140853959562888,-0.000230094442329156,0.25,1.24118077451597E-6,-0.000124250360763624,1.11417851502177E-6,200.0278625,200.0278625,66881.7578125,66906.3203125,56.8525319747752,20.5294973149866,27.844467,0,0,0,40,4449,199.8547,66894.0390625,,,,,,,,,,,,,0,,,,0,,,,,,200.0278625,,,,
,22248586.33,200.0350952,71811.7265625,-0.000138198528899115,1.99838193846286E-6,1,0.999253354069792,40.0298881530762,1.99875884662769,16.380000859499,-0.00157299610299994,-0.000251755829094993,0.25,1.83059442496912E-6,-0.000138677868756876,1.69067891750025E-6,200.0350952,200.0350952,71799.0390625,71824.4140625,56.6938613853714,20.5311476331283,27.464817,0,0,0,40,4449,199.82455,71811.7265625,,,,,,,,,,,,,0,,,,0.00245,,,,,,200.0350952,,,,
,22248684.645,200.0353546,76727.22265625,-0.000155416850466442,2.64937982321307E-6,1,0.999253354069792,40.0298881530762,1.99871602060836,16.380000859499,-0.00177042807081035,-0.000274558740707221,0.25,2.81195512018421E-6,-0.000155956749767198,2.65754498610246E-6,200.0353546,200.0353546,76717.234375,76737.2109375,56.7079306987175,20.5297500274963,27.844467,0,0,0,40,4449,199.7938,76727.22265625,,,,,,,,,,,,,0,,,,0,,,,,,200.0353546,,,,
,22248779.12,200.0292206,81448.15625,-0.000172412025914654,3.21328502554661E-6,1,0.999253354069792,40.0298881530762,1.99874118531855,16.380000859499,-0.00196380001443708,-0.000306041833864398,0.25,2.99089113158092E-6,-0.000173010910605665,2.81952470342799E-6,200.0292206,200.0292206,81440.59375,81455.71875,56.5766171074867,20.5275641861074,27.085165,0,0,0,40,4449,199.7747,81448.15625,,,,,,,,,,,,,0,,,,0,,,,,,200.0292206,,,,
,22248871.595,200.02448275,86071.41015625,-0.000187950704708778,3.23214950272831E-6,1,0.999253354069792,40.0298881530762,1.998732642511,16.380000859499,-0.00213980877981147,-0.000339216507260506,0.25,2.7674560241234E-6,-0.00018860312578164,2.57934544450496E-6,200.0241089,200.0248566,86063.765625,86079.0546875,56.7337244398522,20.5286155594313,27.844467,0,0,0,40,4449,199.75825,86071.41015625,,,,,,,,,,,,,0,,,,0,,,,,,200.02448275,,,,
,22248979.605,200.0207977,89605.31640625,-0.000200174190129948,2.05585261107541E-6,1,0.999253354069792,40.0298881530762,1.998809496393,16.380000859499,-0.00227659751954721,-0.000375453355141111,0.25,1.70003524140796E-6,-0.000200867797202916,1.49569928304797E-6,200.0207977,200.0207977,89595.3828125,89615.25,56.658688102006,20.5279603048399,27.464817,0,0,0,40,4449,199.7369,89605.31640625,,,,,,,,,,,,,0,,,,-0.00735,,,,,,200.0207977,,,,
,22249067.51,200.0106049,85214.30078125,-0.000183223794547182,2.21088500781743E-6,1,0.999253354069792,40.0298881530762,1.99886537632467,16.380000859499,-0.00208693491679132,-0.000326049153585718,0.25,3.10805109919691E-6,-0.000183860309519136,2.92598308174383E-6,200.0106049,200.0106049,85209.2890625,85219.3125,56.9181887703906,20.5313997183596,27.464817,0,0,0,40,4449,199.73205,85214.30078125,,,,,,,,,,,,,0,,,,-0.0049,,,,,,200.0106049,,,,
,22249158.535,199.9976959,80666.03515625,-0.000170310806645591,3.31106944324325E-6,1,0.999253354069792,40.0298881530762,1.99881804069858,16.380000859499,-0.00193488284036169,-0.000331443756821939,0.25,3.90315992305465E-7,-0.00017089985349724,2.1207469087246E-7,199.9976959,199.9976959,80660.9921875,80671.078125,56.7673344661791,20.5293062330618,27.844467,0,0,0,40,4449,199.7385,80666.03515625,,,,,,,,,,,,,0,,,,0,,,,,,199.9976959,,,,
,22249257.54,199.9877472,75717.01953125,-0.000151530290706575,2.03404278163209E-6,1,0.999253354069792,40.0298881530762,1.99886718160564,16.380000859499,-0.00171860074262049,-0.000311941007030803,0.25,-1.1527621932326E-6,-0.000152052797828892,-1.31687972416799E-6,199.9877472,199.9877472,75712.15625,75721.8828125,56.8095424062176,20.5310410005815,27.464817,0,0,0,40,4449,199.7535,75717.01953125,,,,,,,,,,,,,0,,,,0.00245,,,,,,199.9877472,,,,
,22249350.54,199.9833069,71066.16796875,-0.000133486618962597,2.18487747926946E-6,1,0.999253354069792,40.0298881530762,1.99879001647555,16.380000859499,-0.0015188024406583,-0.000246556650164734,0.25,1.47060269256566E-6,-0.000133949516360049,1.33433176080399E-6,199.9833069,199.9833069,71053.625,71078.7109375,57.0018230219483,20.5320719026331,27.844467,0,0,0,40,4449,199.7632,71066.16796875,,,,,,,,,,,,,0,,,,0,,,,,,199.9833069,,,,
,22249443.945,199.9757233,66397.9765625,-0.000120298486821773,2.91198195509586E-6,1,0.999253354069792,40.0298881530762,1.99874721796839,16.380000859499,-0.00137166187701616,-0.000205257118616862,0.25,2.81691168675307E-6,-0.000120717231475999,2.69901596492334E-6,199.9757233,199.9757233,66390.8515625,66405.1015625,56.8564401173714,20.5330148882201,27.844467,0,0,0,40,4449,199.7926,66397.9765625,,,,,,,,,,,,,0,,,,-0.00245,,,,,,199.9757233,,,,
,22249536.785,199.9720154,61757.310546875,-0.000105927841385903,1.58020440281107E-6,1,0.999253354069792,40.0298881530762,1.99876236166702,16.380000859499,-0.00119903180352082,-0.000231308560132236,0.25,-1.97249389195715E-6,-0.000106291817219505,-2.09190941107602E-6,199.9720154,199.9720154,61747.2421875,61767.37890625,56.8439340610637,20.5307541220538,27.085165,0,0,0,40,4449,199.8158,61757.310546875,,,,,,,,,,,,,0,,,,-0.0049,,,,,,199.9720154,,,,
,22249634.095,199.9757385,56894.45703125,-8.65714155455432E-5,2.48521008155782E-6,1,0.999253354069792,40.0298881530762,1.99880610249793,16.380000859499,-0.000989021450058721,-0.000136811696230636,0.25,2.98762794753871E-6,-8.68737396186641E-5,2.90574396440528E-6,199.9757385,199.9757385,56884.53515625,56904.37890625,56.9244417985445,20.5326308192465,27.085165,0,0,0,40,4449,199.83495,56894.45703125,,,,,,,,,,,,,0,,,,0.0049,,,,,,199.9757385,,,,
,22249730.165,199.98156735,52092.0390625,-7.2316299065932E-5,2.00571343161299E-6,1,0.999253354069792,40.0298881530762,1.99873767868067,16.380000859499,-0.000818781221691039,-0.000156644748482186,0.25,-1.23480259212262E-6,-7.25648293225469E-5,-1.31624643306918E-6,199.9811401,199.9819946,52086.97265625,52097.10546875,56.8572217458906,20.5312909547505,27.464817,0,0,0,40,4449,199.84635,52092.0390625,,,,,,,,,,,,,0,,,,0,,,,,,199.98156735,,,,
,22249829.305,199.9856033,47136.98046875,-5.41980187696451E-5,1.41672243448356E-6,1,0.999253354069792,40.0298881530762,1.99874054991836,16.380000859499,-0.000619457440278122,-8.39172881057159E-5,0.25,2.0230580366199E-6,-5.43874085435213E-5,1.97208853830034E-6,199.9853668,199.9858398,47129.44140625,47144.51953125,56.9963516223137,20.5319589209858,27.844467,0,0,0,40,4449,199.8582,47136.98046875,,,,,,,,,,,,,0,,,,-0.0049,,,,,,199.9856033,,,,
,22249930.265,199.9881592,42089.55859375,-3.99298765200118E-5,1.61799632923914E-6,1,0.999253354069792,40.0298881530762,1.99881344378902,16.38999953866,-0.000453356770329683,-7.93217830010403E-5,0.25,-4.9946610975423E-8,-4.00677442668465E-5,-9.29055995794424E-8,199.9881592,199.9881592,42077.3125,42101.8046875,57.044812590506,20.5329588592406,27.464817,0,0,0,40,4449,199.86895,42089.55859375,,,,,,,,,,,,,0,,,,0,,,,,,199.9881592,,,,
,22250028.32,199.9893799,37189.62109375,-2.19996245263878E-5,1.23154679481075E-6,1,0.999253354069792,40.0298881530762,1.99878243100914,16.380000859499,-0.000249644076508328,-4.44621729832941E-5,0.25,-9.43956304044199E-8,-2.20755042085352E-5,-1.183409617509E-7,199.9893799,199.9893799,37184.5390625,37194.703125,57.0362146767945,20.532718930924,27.085165,0,0,0,40,4449,199.87545,37189.62109375,,,,,,,,,,,,,0,,,,0,,,,,,199.9893799,,,,
,22250124.78,199.9895782,32367.5263671875,-9.25807235044904E-6,1.35362069082815E-6,1,0.999253354069792,40.0298881530762,1.99882142847838,16.380000859499,-0.000106627210193102,-9.68378646713581E-6,0.25,7.55226822594178E-7,-9.2908569276592E-6,7.47877017824487E-7,199.9895782,199.9895782,32362.509765625,32372.54296875,56.994006736756,20.532196261494,27.464817,0,0,0,40,4449,199.8866,32367.5263671875,,,,,,,,,,,,,0,,,,-0.0049,,,,,,199.9895782,,,,
,22250224.25,199.9918365,27397.8857421875,6.31020258260558E-6,1.19440797031323E-6,1,0.999253354069792,40.0298881530762,1.99891904428744,16.38999953866,7.11102633168504E-5,1.5634777602554E-5,0.25,2.80710008489862E-7,6.33168971635453E-6,2.88479158679801E-7,199.9918365,199.9918365,27390.46484375,27405.306640625,57.0096393071407,20.5318634906262,27.464817,0,0,0,40,4449,199.89475,27397.8857421875,,,,,,,,,,,,,0,,,,0,,,,,,199.9918365,,,,
,22250324.97,199.9927826,22362.837890625,2.19278636129944E-5,8.29913421099064E-7,1,0.999253354069792,40.0298881530762,1.99889539079706,16.380000859499,0.000247233712747553,5.35846354938291E-5,0.25,9.09788306205095E-7,2.20025929697876E-5,9.36602464341432E-7,199.9927826,199.9927826,22352.611328125,22373.064453125,56.912717370756,20.5346806937245,27.844467,0,0,0,40,4449,199.8987,22362.837890625,,,,,,,,,,,,,0,,,,0,,,,,,199.9927826,,,,
,22250421.795,199.9989777,17525.61328125,3.75057845796486E-5,8.76130838675546E-7,1,0.999253354069792,40.0298881530762,1.99888234410705,16.380000859499,0.000424624728237695,8.15475073894083E-5,0.25,6.66353286831404E-7,3.76345443576436E-5,7.09213518025623E-7,199.9989777,199.9989777,17515.2890625,17535.9375,56.9611783389483,20.5347733380634,27.464817,0,0,0,40,4449,199.8999,17525.61328125,,,,,,,,,,,,,0,,,,0.00245,,,,,,199.9989777,,,,
,22250521.305,200.0017242,12550.4609375,4.92266101291321E-5,5.49682793719101E-7,1,0.999253354069792,40.0298881530762,1.99898049431138,16.380000859499,0.000558533825877307,0.000100214453374827,0.25,2.73806713909199E-7,4.93962397184154E-5,3.28076818253138E-7,200.0017242,200.0017242,12547.75390625,12553.16796875,57.0369963053137,20.5351534976417,27.464817,0,0,0,40,4449,199.89735,12550.4609375,,,,,,,,,,,,,0,,,,-0.0049,,,,,,200.0017242,,,,
,22250611.235,200.0010071,8055.21557617187,5.87635973628959E-5,3.93449157198462E-7,1,0.999253354069792,40.0298881530762,1.99892293182112,16.380000859499,0.000667418878729607,0.000115623982040972,0.25,-2.56538492971938E-8,5.89664604495643E-5,3.8003002398632E-8,200.0010071,200.0010071,8050.20751953125,8060.2236328125,56.861911517006,20.5358627575519,27.085165,0,0,0,40,4449,199.89695,8055.21557617187,,,,,,,,,,,,,0,,,,-0.0049,,,,,,200.0010071,,,,
,22250700.17,199.999588,3609.59362792969,5.8829756594329E-5,3.14280848988608E-7,1,0.999253354069792,40.0298881530762,1.99892604327184,16.380000859499,0.00066807525651062,0.000116306619392073,0.25,2.28704878127694E-8,5.90327864316642E-5,8.68457227436255E-8,199.999588,199.999588,3606.77587890625,3612.41137695313,57.0104209356599,20.5370261602049,27.464817,0,0,0,40,4449,199.8964,3609.59362792969,,,,,,,,,,,,,0,,,,0,,,,,,199.999588,,,,
,22250772.775,199.9997864,-0.372982427477837,3.75673524822527E-5,3.67425756671018E-7,1,0.999253354069792,40.0298881530762,1.99894030590439,16.380000859499,0.000428321539736748,6.44784739922436E-5,0.25,-8.4770251574172E-7,3.76979351720853E-5,-8.09794532381491E-7,199.9997864,199.9997864,-0.380594313144684,-0.365370541810989,57.0158923352945,20.5361596725037,27.464817,0,0,0,40,4417,199.89685,-0.372982427477837,,,,,,,,,,,,,0,,,,0,,,,,,199.9997864,,,,