File: data/doubleLayers/dl_1-25/ppms/data/DD205_3_HYST_100OE_50K.DAT
[Header]
; VSM Data File (default extension .dat)
; Copyright (c) 2003-2013, Quantum Design, Inc. All rights reserved.
TITLE,
FILEOPENTIME,32533134.52,01/12/2019,9:01 pm
BYAPP,VSM,2.0,2.0
INFO,PPMS VSM Option Release 1.4.10 Build 1,APPNAME
INFO,Quantum Design Linear Motor Servo Controller,MOTOR_MODULE_NAME
INFO,3101-100 M1,MOTOR_HW_VERSION
INFO,MMC1014,MOTOR_SERIAL_NUMBER
INFO,SRV No X-over 01.03.11,MOTOR_SOFTWARE_VERSION
INFO,Quantum Design VSM Detection Module,VSM_MODULE_NAME
INFO,3101-150 F0,VSM_HW_VERSION
INFO,VSM707,VSM_SERIAL_NUMBER
INFO,VSM No X-over 01.02.05 May 20 2008 13:51:47,VSM_SOFTWARE_VERSION
INFO,704,PREAMP_SERIAL_NUMBER
INFO,822,COIL_SERIAL_NUMBER
INFO,0,MOMENT_UNITS
INFO,DD205_4,SAMPLE_MATERIAL
INFO,Double Layer Blue 1.25,SAMPLE_COMMENT
INFO,26.73,SAMPLE_MASS
INFO,,SAMPLE_VOLUME
INFO,,SAMPLE_MOLECULAR_WEIGHT
INFO,,SAMPLE_SIZE
INFO,,SAMPLE_SHAPE
DATATYPE,COMMENT,1
DATATYPE,TIME,2
STARTUPAXIS,X,2
STARTUPAXIS,Y1,5
[Data]
Comment,Time Stamp (sec),Temperature (K),Magnetic Field (Oe),Moment (emu),M. Std. Err. (emu),Transport Action,Averaging Time (sec),Frequency (Hz),Peak Amplitude (mm),Center Position (mm),Coil Signal' (mV),Coil Signal" (mV),Range (mV),M. Quad. Signal (emu),M. Raw' (emu),M. Raw" (emu),Min. Temperature (K),Max. Temperature (K),Min. Field (Oe),Max. Field (Oe),Mass (grams),Motor Lag (deg),Pressure (Torr),VSM Status (code),Motor Status (code),Measure Status (code),Measure Count,PPMS Status (code),System Temp. (K),System Field (Oe),Sample Position (deg),Bridge 1 Resistance (ohms),Bridge 1 Excitation (에),Bridge 2 Resistance (ohms),Bridge 2 Excitation (에),Bridge 3 Resistance (ohms),Bridge 3 Excitation (에),Bridge 4 Resistance (ohms),Bridge 4 Excitation (에),Signal 1 Vin (V),Signal 2 Vin (V),Digital Inputs (code),Drive 1 Iout (mA),Drive 1 Ipower (W),Drive 2 Iout (mA),Drive 2 Ipower (W),Pressure (),Map 20 (),Map 21 (),Map 22 (),Map 23 (),Map 24 (),Map 25 (),Map 26 (),Map 27 (),Map 28 (),Map 29 ()
,32533148.73,49.9999046,-0.0608950927853584,,,2,,,,20.9699993366003,,,,,,,49.9999046,49.9999046,-0.0608950927853584,-0.0608950927853584,,,16.454937,,,,-99999999,4369,50.0427,-0.0608950927853584,,,,,,,,,,,,,,,,,,,,,,,49.9999046,,,,
,32533298.14,50.0057526,4478.62670898438,6.16259539277944E-5,3.17175808634534E-7,1,0.999253354069792,40.0298881530762,2.00839471342411,20.9599994122982,0.000699865870692691,0.000124574569793792,0.25,-1.3464125883121E-7,6.16040017199301E-5,3.24004204763523E-7,50.0057526,50.0057526,4470.93212890625,4486.3212890625,57.1206305568714,20.6012207055676,16.454937,0,0,0,40,4449,50.02795,4478.62670898438,,,,,,,,,,,,,0,,,,0,,,,,,50.0057526,,,,
,32533391.5,50.0037308,9142.45263671875,5.08737269290792E-5,5.49803996577164E-7,1,0.999253354069792,40.0298881530762,2.0086297070937,20.9599994122982,0.000578866792605206,9.78052378636119E-5,0.25,-5.5733320582358E-7,5.08705686633599E-5,-1.78781470233253E-7,50.0037308,50.0037308,9137.609375,9147.2958984375,57.1565854687561,20.6051073592948,17.214239,0,0,0,40,4449,50.0256,9142.45263671875,,,,,,,,,,,,,0,,,,0,,,,,,50.0037308,,,,
,32533486.155,50.0021515,13875.3642578125,3.80791565492702E-5,5.10349187618463E-7,1,0.999253354069792,40.0298881530762,2.00856309020415,20.9599994122982,0.000434636705042152,6.62426460652605E-5,0.25,-1.0312906547126E-6,3.80908889223759E-5,-7.48511133824513E-7,50.0021515,50.0021515,13865.404296875,13885.32421875,56.9283499411406,20.6062178219546,16.834587,0,0,0,40,4449,50.0249,13875.3642578125,,,,,,,,,,,,,0,,,,-0.00245,,,,,,50.0021515,,,,
,32533578.085,50.0019493,18470.2890625,2.61904948455936E-5,6.9851815757539E-7,1,0.999253354069792,40.0298881530762,2.00855360293431,20.9599994122982,0.000302779672318056,2.46686248039351E-5,0.25,-2.54864604887474E-6,2.6218747675627E-5,-2.35548472421656E-6,50.0019493,50.0019493,18463.025390625,18477.552734375,57.0635716749676,20.6120289257097,16.454937,0,0,0,40,4449,50.024,18470.2890625,,,,,,,,,,,,,0,,,,0.00245,,,,,,50.0019493,,,,
,32533671.925,50.0005379,23160.4267578125,1.4254309037475E-5,8.0597222136645E-7,1,0.999253354069792,40.0298881530762,2.00854685336866,20.9599994122982,0.000167162352398113,4.90350199733028E-7,0.25,-2.52523773448711E-6,1.42817369920544E-5,-2.42157614415405E-6,50.0005379,50.0005379,23155.34375,23165.509765625,57.1690915250637,20.6117198632321,16.834587,0,0,0,40,4449,50.02445,23160.4267578125,,,,,,,,,,,,,0,,,,0.0049,,,,,,50.0005379,,,,
,32533766.625,50.00047875,27893.3427734375,3.33595621738375E-6,8.95566132800572E-7,1,0.999253354069792,40.0298881530762,2.00859523172563,20.9599994122982,4.28504217247507E-5,-2.05266936913541E-5,0.25,-2.40665191361527E-6,3.35655399641382E-6,-2.38426394330187E-6,50.0002823,50.0006752,27888.248046875,27898.4375,57.2824276603522,20.613090017679,16.834587,0,0,0,40,4449,50.0244,27893.3427734375,,,,,,,,,,,,,0,,,,0,,,,,,50.00047875,,,,
,32533860.515,50.0022087,32585.9814453125,-1.2122751384813E-5,1.02554091691337E-6,1,0.999253354069792,40.0298881530762,2.0085579352878,20.9599994122982,-0.000130468224435292,-6.5764494626673E-5,0.25,-3.60058728991082E-6,-1.21101842046711E-5,-3.6931220228086E-6,50.0022087,50.0022087,32575.837890625,32596.125,57.2621053188522,20.6110051393615,16.454937,0,0,0,40,4449,50.02235,32585.9814453125,,,,,,,,,,,,,0,,,,0,,,,,,50.0022087,,,,
,32533953.21,50.0030708,37218.58984375,-2.36207567531734E-5,1.33654673548029E-6,1,0.999253354069792,40.0298881530762,2.00869783596501,20.9599994122982,-0.000260835858819643,-9.18576399939009E-5,0.25,-3.82345190492837E-6,-2.36255813021029E-5,-3.99981923461327E-6,50.0030708,50.0030708,37208.6953125,37228.484375,57.2238055214099,20.6093190669846,16.834587,0,0,0,40,4449,50.021,37218.58984375,,,,,,,,,,,,,0,,,,0,,,,,,50.0030708,,,,
,32534046.76,50.0004387,41894.0078125,-3.5513009311896E-5,1.64989349167479E-6,1,0.999253354069792,40.0298881530762,2.00871761221134,20.9599994122982,-0.000397278604705645,-0.000110257177054888,0.25,-3.29986126131711E-6,-3.55468128724455E-5,-3.56027270795285E-6,50.0004387,50.0004387,41886.81640625,41901.19921875,57.3848209963715,20.613996704448,17.214239,0,0,0,40,4449,50.0211,41894.0078125,,,,,,,,,,,,,0,,,,-0.0049,,,,,,50.0004387,,,,
,32534139.93,50.0016479,46549.140625,-5.03682942626807E-5,1.38703761390493E-6,1,0.999253354069792,40.0298881530762,2.00865339757665,20.9599994122982,-0.000560396126179779,-0.000174109398228665,0.25,-6.23899985351899E-6,-5.04172359603529E-5,-6.60892532544436E-6,50.0016479,50.0016479,46544.3203125,46553.9609375,57.4160861371407,20.6165349144914,16.834587,0,0,0,40,4449,50.0187,46549.140625,,,,,,,,,,,,,0,,,,-0.00245,,,,,,50.0016479,,,,
,32534234.95,50.00131225,51299.267578125,-6.45423734496104E-5,1.77358674240657E-6,1,0.999253354069792,40.0298881530762,2.00866705452521,20.9599994122982,-0.000724148537432264,-0.000190486263812478,0.25,-5.12915134331624E-6,-6.46407662536424E-5,-5.5942148028482E-6,50.0011711,50.0014534,51291.56640625,51306.96875,57.3988903097176,20.6117563298016,16.834587,0,0,0,40,4449,50.01825,51299.267578125,,,,,,,,,,,,,0,,,,0,,,,,,50.00131225,,,,
,32534331.515,50.002224,56124.396484375,-7.88709560471253E-5,1.65263038448165E-6,1,0.999253354069792,40.0298881530762,2.00861126330521,20.9599994122982,-0.000882788762611822,-0.000245642116982307,0.25,-7.40044880690211E-6,-7.90016435530036E-5,-7.96636025264879E-6,50.002224,50.002224,56114.46484375,56134.328125,57.3543374841214,20.609379470128,16.834587,0,0,0,40,4449,50.0183,56124.396484375,,,,,,,,,,,,,0,,,,0,,,,,,50.002224,,,,
,32534428.205,50.0005646,60957.244140625,-9.26907111622482E-5,1.50782507635799E-6,1,0.999253354069792,40.0298881530762,2.0085510015241,20.9599994122982,-0.00104712938094616,-0.000236103103100109,0.25,-4.08284787213148E-6,-9.28968556084766E-5,-4.7301634767524E-6,50.0005646,50.0005646,60947.1953125,60967.29296875,57.2425646058714,20.6114355726054,17.214239,0,0,0,40,4449,50.01565,60957.244140625,,,,,,,,,,,,,0,,,,0,,,,,,50.0005646,,,,
,32534524.555,50.0019035,65774.859375,-0.000111504211917561,2.1736098067967E-6,1,0.999253354069792,40.0298881530762,2.00862002348764,20.9599994122982,-0.0012530736071019,-0.000322514885659129,0.25,-8.29490395733205E-6,-0.000111752809798181,-9.07385536182199E-6,50.0019035,50.0019035,65774.859375,65774.859375,57.5442732142945,20.6073582371565,17.214239,0,0,0,40,4449,50.0152,65774.859375,,,,,,,,,,,,,0,,,,-0.0049,,,,,,50.0019035,,,,
,32534622.9,50.00131225,70690.203125,-0.000120105602172437,2.11290750555297E-6,1,0.999253354069792,40.0298881530762,2.0086337137237,20.9599994122982,-0.00135998193281896,-0.000291981654860838,0.25,-4.07597111609458E-6,-0.000120430994364782,-4.89114844157871E-6,50.0012169,50.0014076,70682.9140625,70697.4921875,57.3082214014868,20.6096236370646,17.214239,0,0,0,40,4449,50.01465,70690.203125,,,,,,,,,,,,,0,,,,0.00245,,,,,,50.00131225,,,,
,32534720.555,50.0009346,75570.6953125,-0.000135917380149448,2.14937185133382E-6,1,0.999253354069792,40.0298881530762,2.00877823774497,20.9599994122982,-0.00152870609165944,-0.000390273670425997,0.25,-9.87048772828184E-6,-0.000136277383879966,-1.07971586912558E-5,50.0009346,50.0009346,75565.65625,75575.734375,57.4942489890638,20.6069454906941,17.593889,0,0,0,40,4449,50.01245,75570.6953125,,,,,,,,,,,,,0,,,,-0.00245,,,,,,50.0009346,,,,
,32534816.915,50.000248,80389.30859375,-0.000155948138888149,2.37806360071863E-6,1,0.999253354069792,40.0298881530762,2.0087199598428,20.9599994122982,-0.00175856379959265,-0.000423940727835052,0.25,-9.24188164255073E-6,-0.000156403908514597,-1.02850522699288E-5,50.000248,50.000248,80379.390625,80399.2265625,57.4840878183138,20.608311612059,16.834587,0,0,0,40,4449,50.0121,80389.30859375,,,,,,,,,,,,,0,,,,0,,,,,,50.000248,,,,
,32534911.385,50.0007782,85110.1171875,-0.000170011221598658,1.99856947010913E-6,1,0.999253354069792,40.0298881530762,2.00873147106336,20.9599994122982,-0.00191952408297987,-0.000450892264260396,0.25,-9.09538107268363E-6,-0.000170543892249561,-1.0214427754608E-5,50.0007782,50.0007782,85102.7421875,85117.4921875,57.413741251583,20.6096194377282,17.214239,0,0,0,40,4449,50.0116,85110.1171875,,,,,,,,,,,,,0,,,,0.0049,,,,,,50.0007782,,,,
,32535001.78,50.0004845,89630.765625,-0.00018150501839442,1.98502696749453E-6,1,0.999253354069792,40.0298881530762,2.00865169811811,20.9599994122982,-0.00205296630684465,-0.000462296632214065,0.25,-8.04902903381596E-6,-0.000182112884995326,-9.22219855399641E-6,50.0004845,50.0004845,89625.6484375,89635.8828125,57.3449579418907,20.6098285176841,17.214239,0,0,0,40,4449,50.0101,89630.765625,,,,,,,,,,,,,0,,,,-0.00245,,,,,,50.0004845,,,,
,32535112.415,49.9998322,85883.82421875,-0.000169543905831271,2.14163888221694E-6,1,0.999253354069792,40.0298881530762,2.00872585221277,20.9599994122982,-0.00192331789345973,-0.000399295578738278,0.25,-4.65488995369017E-6,-0.000170107976211636,-5.75292460337192E-6,49.9998322,49.9998322,85878.8984375,85888.75,57.4770531616407,20.6088841382054,17.214239,0,0,0,40,4449,50.012,85883.82421875,,,,,,,,,,,,,0,,,,0,,,,,,49.9998322,,,,
,32535210.465,50.0001564,80980.76171875,-0.000154362538840825,2.55988125651996E-6,1,0.999253354069792,40.0298881530762,2.00870428374553,20.9599994122982,-0.00174902047668003,-0.000373263327949209,0.25,-5.0812061021577E-6,-0.000154843429468227,-6.09858032572519E-6,50.0001564,50.0001564,80975.9765625,80985.546875,57.4090514804676,20.6093734185162,16.834587,0,0,0,40,4449,50.0104,80980.76171875,,,,,,,,,,,,,0,,,,0.00245,,,,,,50.0001564,,,,
,32535303.875,50.0009041,76311.5390625,-0.000140185389909307,2.31125943153118E-6,1,0.999253354069792,40.0298881530762,2.00873925926013,20.9599994122982,-0.00158374973365494,-0.000363369632654277,0.25,-6.74591253650825E-6,-0.000140583378414139,-7.68905276580166E-6,50.0009041,50.0009041,76306.5859375,76316.4921875,57.4325003360445,20.610963565225,17.214239,0,0,0,40,4449,50.01145,76311.5390625,,,,,,,,,,,,,0,,,,-0.0049,,,,,,50.0009041,,,,
,32535397.345,49.9996414,71637.93359375,-0.000124574403960115,1.54067363655582E-6,1,0.999253354069792,40.0298881530762,2.00878061852095,20.9599994122982,-0.0014077958831322,-0.000319258969609365,0.25,-5.66764592811507E-6,-0.000124907060903888,-6.51529374609469E-6,49.9996414,49.9996414,71627.921875,71647.9453125,57.4528226775445,20.6143124585559,17.593889,0,0,0,40,4449,50.0123,71637.93359375,,,,,,,,,,,,,0,,,,0,,,,,,49.9996414,,,,
,32535495.665,50.0000534,66724.84765625,-0.000109839190959368,2.1572617838934E-6,1,0.999253354069792,40.0298881530762,2.00877655963765,20.9599994122982,-0.00124142524281052,-0.000279184192205899,0.25,-4.78879279798006E-6,-0.000110111434744353,-5.54508412405227E-6,50.0000534,50.0000534,66714.828125,66734.8671875,57.3762230826599,20.6135604310759,17.214239,0,0,0,40,4449,50.0125,66724.84765625,,,,,,,,,,,,,0,,,,-0.0049,,,,,,50.0000534,,,,
,32535591.91,49.9990005,61914.212890625,-9.29742765183022E-5,2.219087314008E-6,1,0.999253354069792,40.0298881530762,2.00884225399511,20.9599994122982,-0.00104757857756249,-0.000253256380838428,0.25,-5.53590988095277E-6,-9.31751142112303E-5,-6.18745671924413E-6,49.9990005,49.9990005,61906.51171875,61921.9140625,57.3754414541407,20.6106996960316,17.214239,0,0,0,40,4449,50.01335,61914.212890625,,,,,,,,,,,,,0,,,,-0.0049,,,,,,49.9990005,,,,
,32535691.205,49.9989548,56948.302734375,-7.58714522316507E-5,1.63569123960841E-6,1,0.999253354069792,40.0298881530762,2.00883538055782,20.9599994122982,-0.000852993532931523,-0.0002159973705206,0.25,-5.33403765049373E-6,-7.60124691161447E-5,-5.87343081426251E-6,49.9989548,49.9989548,56938.1328125,56958.47265625,57.6075851243522,20.609801712703,17.214239,0,0,0,40,4449,50.0138,56948.302734375,,,,,,,,,,,,,0,,,,0,,,,,,49.9989548,,,,
,32535790.79,49.9990082,51971.32421875,-6.31447212538801E-5,1.53671745551266E-6,1,0.999253354069792,40.0298881530762,2.00892584569024,20.9599994122982,-0.000710053505279445,-0.000178178626218018,0.25,-4.29746489545151E-6,-6.32480800035982E-5,-4.75040855402146E-6,49.9990082,49.9990082,51966.265625,51976.3828125,57.5411467002176,20.6142183139857,17.214239,0,0,0,40,4449,50.0143,51971.32421875,,,,,,,,,,,,,0,,,,0.00245,,,,,,49.9990082,,,,
,32535888.43,49.99995615,47091.080078125,-5.04700387481622E-5,1.57301895712995E-6,1,0.999253354069792,40.0298881530762,2.00896243259511,20.9599994122982,-0.000570767975139439,-0.00012366897079444,0.25,-1.78667882169669E-6,-5.05521624655387E-5,-2.14872291292427E-6,49.9995308,50.0003815,47083.33984375,47098.8203125,57.4098331089868,20.6149064582469,16.834587,0,0,0,40,4449,50.01355,47091.080078125,,,,,,,,,,,,,0,,,,-0.00245,,,,,,49.99995615,,,,
,32535984.73,50.0004978,42278.36328125,-3.67130828604114E-5,1.38387374105269E-6,1,0.999253354069792,40.0298881530762,1.99632120959369,20.9599994122982,-0.000405866182531759,-0.00012679708995248,0.25,-4.6036688404282E-6,-3.67401466408026E-5,-4.87471393934629E-6,50.0000267,50.0009689,42275.88671875,42280.83984375,57.5856995258138,20.615478203347,17.214239,0,0,0,40,4449,50.0131,42278.36328125,,,,,,,,,,,,,0,,,,0.0049,,,,,,50.0004978,,,,
,32536080.83,50.0013161,37478.0859375,-2.28866009857583E-5,1.20312658085629E-6,1,0.999253354069792,40.0298881530762,1.99632582607285,20.9599994122982,-0.000251435195319699,-8.74327577877201E-5,0.25,-3.61201214553505E-6,-2.28922212830505E-5,-3.78274964340633E-6,50.0013161,50.0013161,37473.015625,37483.15625,57.4606389627369,20.6180749352633,16.834587,0,0,0,40,4449,50.0117,37478.0859375,,,,,,,,,,,,,0,,,,-0.00245,,,,,,50.0013161,,,,
,32536174.96,49.9987335,32770.4326171875,-8.90554507035102E-6,1.23489059590328E-6,1,0.999253354069792,40.0298881530762,1.99648672106735,20.9599994122982,-9.26296442750753E-5,-6.28348338378959E-5,0.25,-3.95416865093201E-6,-8.88683570921113E-6,-4.0236432525901E-6,49.9987335,49.9987335,32765.255859375,32775.609375,57.8147166819484,20.6160855034374,16.834587,0,0,0,40,4449,50.0133,32770.4326171875,,,,,,,,,,,,,0,,,,0,,,,,,49.9987335,,,,
,32536269.76,49.9992561,28033.0458984375,4.74026558605252E-6,6.71345470387827E-7,1,0.999253354069792,40.0298881530762,1.99649787718618,20.9599994122982,5.82966857993201E-5,-1.65517859573672E-5,0.25,-2.31836391981151E-6,4.76146767268117E-6,-2.28560126986921E-6,49.9992561,49.9992561,28028.091796875,28038,57.4043617093522,20.617626338149,16.834587,0,0,0,40,4449,50.0136,28033.0458984375,,,,,,,,,,,,,0,,,,0,,,,,,49.9992561,,,,
,32536362.42,50.0007763,23403.171875,1.83318982108418E-5,6.30826413807228E-7,1,0.999253354069792,40.0298881530762,1.99643734855493,20.9599994122982,0.000211863164688905,1.10782643202945E-5,0.25,-2.32261868553646E-6,1.83605341558002E-5,-2.18878266624359E-6,50.0005913,50.0009613,23400.47265625,23405.87109375,57.7607843141215,20.6197420229231,17.214239,0,0,0,40,4449,50.0136,23403.171875,,,,,,,,,,,,,0,,,,-0.00245,,,,,,50.0007763,,,,
,32536455.54,50.0002556,18748.0185546875,2.9731857281464E-5,6.88606141640436E-7,1,0.999253354069792,40.0298881530762,1.99651078932969,20.9599994122982,0.000341849515532713,2.73361175123705E-5,0.25,-2.93821391464463E-6,2.97646268188659E-5,-2.71902069725114E-6,50.0002556,50.0002556,18742.876953125,18753.16015625,57.688092861833,20.6196215602749,16.834587,0,0,0,40,4449,50.0133,18748.0185546875,,,,,,,,,,,,,0,,,,0,,,,,,50.0002556,,,,
,32536550.635,49.9996681,13995.8325195313,4.15224226118909E-5,6.62169488226633E-7,1,0.999253354069792,40.0298881530762,1.99654183540547,20.9599994122982,0.000471122072445521,7.24370325634841E-5,0.25,-1.06992636683562E-6,4.15349446846502E-5,-7.6158229887672E-7,49.9996681,49.9996681,13990.875,14000.7900390625,57.5974239536023,20.6169086682458,17.214239,0,0,0,40,4449,50.0136,13995.8325195313,,,,,,,,,,,,,0,,,,-0.0049,,,,,,49.9996681,,,,
,32536645.75,50.0002289,9243.27294921875,5.42831022305512E-5,4.89472451276893E-7,1,0.999253354069792,40.0298881530762,1.99648465958822,20.9599994122982,0.000614262847584111,0.000102841123818965,0.25,-6.75873874473933E-7,5.42804032867303E-5,-2.71943732248476E-7,50.0002289,50.0002289,9238.1123046875,9248.43359375,57.5466180998522,20.6187943431908,16.834587,0,0,0,40,4449,50.01245,9243.27294921875,,,,,,,,,,,,,0,,,,-0.0049,,,,,,50.0002289,,,,
,32536739.635,49.9995689,4550.31982421875,6.49940909734257E-5,3.74956284238351E-7,1,0.999253354069792,40.0298881530762,1.99648756640958,20.9599994122982,0.000734079453337615,0.000129867088431532,0.25,-2.10447654675437E-7,6.49713644771007E-5,2.73290124466646E-7,49.9995689,49.9995689,4545.5859375,4555.0537109375,57.6599542351407,20.619462936592,16.834587,0,0,0,40,4449,50.0132,4550.31982421875,,,,,,,,,,,,,0,,,,-0.0049,,,,,,49.9995689,,,,
,32536830.705,49.9999619,-3.67917346954346,7.27713294371676E-5,2.76522508427218E-7,1,0.999253354069792,40.0298881530762,1.99658012910119,20.9599994122982,0.000821271911233194,0.000148375534263228,0.25,2.92327805282707E-8,7.27310090384693E-5,5.70518001384343E-7,49.9999619,49.9999619,-13.6663942337036,6.3080472946167,57.5716302124676,20.6209562594753,17.214239,0,0,0,40,4449,50.0139,-3.67917346954346,,,,,,,,,,,,,0,,,,-0.0049,,,,,,49.9999619,,,,
,32536925.6,49.999588,-4742.86669921875,7.77568515802129E-5,3.66013510422664E-7,1,0.999253354069792,40.0298881530762,1.99658491601742,20.9599994122982,0.000876521482797611,0.000165120661611559,0.25,6.11333546539532E-7,7.77239189638358E-5,1.18974845776249E-6,49.999588,49.999588,-4747.97998046875,-4737.75341796875,57.8108085393523,20.6216904200816,16.834587,0,0,0,40,4449,50.01255,-4742.86669921875,,,,,,,,,,,,,0,,,,0,,,,,,49.999588,,,,
,32537021.705,50.00011635,-9546.6337890625,7.89843325848233E-5,3.7787741426131E-7,1,0.999253354069792,40.0298881530762,1.99662138594113,20.9599994122982,0.000888437987945463,0.000179687017505411,0.25,1.676716626573E-6,7.89618344350203E-5,2.26406848452361E-6,50.0000801,50.0001526,-9551.283203125,-9541.984375,57.5856995258138,20.6187892454343,17.593889,0,0,0,40,4449,50.0115,-9546.6337890625,,,,,,,,,,,,,0,,,,0,,,,,,50.00011635,,,,
,32537116.47,50.0016747,-14284.58984375,6.87871713100211E-5,6.73152075120357E-7,1,0.999253354069792,40.0298881530762,1.99666532164093,20.9599994122982,0.000772442648447262,0.00016488840453782,0.25,2.20103903048429E-6,6.87794255776462E-5,2.71225900885552E-6,50.0016747,50.0016747,-14289.3759765625,-14279.8037109375,57.7787617700638,20.6209354730399,17.593889,0,0,0,40,4449,50.0112,-14284.58984375,,,,,,,,,,,,,0,,,,0,,,,,,50.0016747,,,,
,32537209.76,50.0011368,-18946.548828125,4.59339011787063E-5,8.21171692969505E-7,1,0.999253354069792,40.0298881530762,1.99679248459754,20.9599994122982,0.000516759037880928,0.0001057981257878,0.25,1.08630357238628E-6,4.59433322014661E-5,1.42699066416473E-6,50.0011368,50.0011368,-18951.662109375,-18941.435546875,57.5419283287369,20.6214830213893,16.834587,0,0,0,40,4449,50.0118,-18946.548828125,,,,,,,,,,,,,0,,,,0,,,,,,50.0011368,,,,
,32537307.61,50.0013199,-23836.326171875,2.40681171265682E-5,9.81761478538075E-7,1,0.999253354069792,40.0298881530762,1.99659914719176,20.9599994122982,0.000264800414793975,8.88306700516867E-5,0.25,3.52437817094902E-6,2.40577609613885E-5,3.70422314799486E-6,50.0013199,50.0013199,-23848.70703125,-23823.9453125,57.6841847192369,20.6208038942533,17.593889,0,0,0,40,4449,50.01,-23836.326171875,,,,,,,,,,,,,0,,,,0,,,,,,50.0013199,,,,
,32537403.805,50.0011711,-28644.0537109375,1.4806973523462E-5,9.51591692227107E-7,1,0.999253354069792,40.0298881530762,1.99650908074403,20.9599994122982,0.000160973036561015,6.56094991907636E-5,0.25,3.13742930315075E-6,1.47974859995252E-5,3.24894028517263E-6,50.0011711,50.0011711,-28651.537109375,-28636.5703125,57.6404135221599,20.6199963944437,17.214239,0,0,0,40,4449,50.00955,-28644.0537109375,,,,,,,,,,,,,0,,,,0,,,,,,50.0011711,,,,
,32537499.865,50.0008392,-33443.677734375,1.79128380909581E-5,9.05181598466078E-7,1,0.999253354069792,40.0298881530762,1.99651353569951,20.9599994122982,0.000197342069048866,6.52280101545572E-5,0.25,2.54357771046938E-6,1.79153202383208E-5,2.67712260743511E-6,50.0008392,50.0008392,-33448.8125,-33438.54296875,57.6490114358715,20.6197435962944,17.593889,0,0,0,40,4449,50.00855,-33443.677734375,,,,,,,,,,,,,0,,,,-0.0049,,,,,,50.0008392,,,,
,32537600.46,50.0010376,-38473.62109375,2.67144311835305E-5,1.24027861751782E-6,1,0.999253354069792,40.0298881530762,1.99663657948101,20.9599994122982,0.000291767874552327,0.000111962310803847,0.25,5.09056331063457E-6,2.67160966445872E-5,5.29100199450599E-6,50.0008507,50.0012245,-38481.28515625,-38465.95703125,57.81315342491,20.6198605856547,17.214239,0,0,0,40,4449,50.0085,-38473.62109375,,,,,,,,,,,,,0,,,,-0.0049,,,,,,50.0010376,,,,
,32537694.485,50.0017014,-43173.06640625,3.82854283552948E-5,1.56040850031177E-6,1,0.999253354069792,40.0298881530762,1.99656982708491,20.9599994122982,0.000426113110029992,0.00011671797593024,0.25,3.42835041283702E-6,3.83252370463376E-5,3.70843907074891E-6,50.0017014,50.0017014,-43182.76171875,-43163.37109375,57.5927341824868,20.619393457996,17.593889,0,0,0,40,4449,50.00695,-43173.06640625,,,,,,,,,,,,,0,,,,0,,,,,,50.0017014,,,,
,32537790.67,50.0010681,-47977.95703125,4.98793809340358E-5,1.61415201410924E-6,1,0.999253354069792,40.0298881530762,1.9966594645091,20.9599994122982,0.000554017011442959,0.000159310024890662,0.25,5.1067571476029E-6,4.99389723633344E-5,5.47039582477295E-6,50.0010681,50.0010681,-47985.2265625,-47970.6875,57.70138054666,20.6179340477669,17.214239,0,0,0,40,4449,50.0064,-47977.95703125,,,,,,,,,,,,,0,,,,-0.00245,,,,,,50.0010681,,,,
,32537887.405,50.001339,-52812.896484375,6.37372403043009E-5,1.4536635956015E-6,1,0.999253354069792,40.0298881530762,1.99667641966997,20.9599994122982,0.000714053431161138,0.000170583713091288,0.25,3.61175469366299E-6,6.38491553010087E-5,4.0666964634471E-6,50.001339,50.001339,-52817.8515625,-52807.94140625,57.8264411097369,20.6229958280107,17.593889,0,0,0,40,4449,50.0053,-52812.896484375,,,,,,,,,,,,,0,,,,-0.0049,,,,,,50.001339,,,,
,32537984.89,50.0011978,-57687.421875,7.7603063880927E-5,1.41633531249052E-6,1,0.999253354069792,40.0298881530762,1.99675352387769,20.9599994122982,0.000868867412053222,0.00021196142878289,0.25,4.77619505346928E-6,7.77545427678182E-5,5.32549866746043E-6,50.0011978,50.0011978,-57700.06640625,-57674.77734375,57.6099300099099,20.6195609845537,17.593889,0,0,0,40,4449,50.00315,-57687.421875,,,,,,,,,,,,,0,,,,0,,,,,,50.0011978,,,,
,32538085.645,50.0004082,-62719.853515625,9.50293430482936E-5,2.02539648210126E-6,1,0.999253354069792,40.0298881530762,1.99675941916529,20.9599994122982,0.00106690905981076,0.00024466212069267,0.25,4.5368122584417E-6,9.52455639510817E-5,5.1986742783887E-6,50.0004082,50.0004082,-62727.33203125,-62712.375,57.6443216647561,20.6188449613526,17.593889,0,0,0,40,4449,50.00425,-62719.853515625,,,,,,,,,,,,,0,,,,-0.0049,,,,,,50.0004082,,,,
,32538184.68,50.0007782,-67672.46875,0.000106238683649878,1.95552533290826E-6,1,0.999253354069792,40.0298881530762,1.99667180263427,20.9599994122982,0.00119679636352217,0.000252208537319536,0.25,3.19619039931019E-6,0.000106515798963842,3.92196896694799E-6,50.0007782,50.0007782,-67680.0546875,-67664.8828125,57.8381655375254,20.623537287288,17.593889,0,0,0,40,4449,50.00255,-67672.46875,,,,,,,,,,,,,0,,,,-0.00245,,,,,,50.0007782,,,,
,32538282.92,50.0021591,-72578.80859375,0.000119651610042755,1.50004611836459E-6,1,0.999253354069792,40.0298881530762,1.99671721530411,20.9599994122982,0.00134990787894255,0.00027455951736797,0.25,2.76799325741004E-6,0.000119993289360057,3.57215441694441E-6,50.0021591,50.0021591,-72586.40625,-72571.2109375,57.6357237510446,20.6219302925773,17.214239,0,0,0,40,4449,50.00095,-72578.80859375,,,,,,,,,,,,,0,,,,0,,,,,,50.0021591,,,,
,32538380.695,50.0012169,-77466.1328125,0.00013857044524539,2.26140685018799E-6,1,0.999253354069792,40.0298881530762,1.99667084776451,20.9599994122982,0.00155862085952679,0.000345854670540502,0.25,5.67540130002522E-6,0.00013897634648175,6.6016642244382E-6,50.0012169,50.0012169,-77473.4140625,-77458.8515625,57.708415203333,20.6230468622537,17.973541,0,0,0,40,4449,49.9997,-77466.1328125,,,,,,,,,,,,,0,,,,0,,,,,,50.0012169,,,,
,32538478.58,50.0010071,-82358.6484375,0.000149765490070228,2.08793235135427E-6,1,0.999253354069792,40.0298881530762,1.99675016921232,20.9599994122982,0.00168983988581218,0.000346379742812534,0.25,3.72272273145543E-6,0.000150247206240486,4.7018493742855E-6,50.0010071,50.0010071,-82361.21875,-82356.078125,57.7279559163138,20.6218887691273,17.214239,0,0,0,40,4449,49.9986,-82358.6484375,,,,,,,,,,,,,0,,,,0,,,,,,50.0010071,,,,
,32538571.135,50.001667,-86982.95703125,0.000165956591796481,1.87112310084948E-6,1,0.999253354069792,40.0298881530762,1.99664332536282,20.9599994122982,0.00187287402590343,0.000383102773647598,0.25,4.07348671932851E-6,0.000166517878891119,5.14312778538869E-6,50.001667,50.001667,-86993.0703125,-86972.84375,57.515352959083,20.6233568782866,17.214239,0,0,0,40,4449,49.99735,-86982.95703125,,,,,,,,,,,,,0,,,,0,,,,,,50.001667,,,,
,32538680.93,49.9994087,-88552.484375,0.000173071717011276,2.16819060060466E-6,1,0.999253354069792,40.0298881530762,1.99658207872903,20.9599994122982,0.00195147188644366,0.000409285477627385,0.25,5.11376177821015E-6,0.000173660892703542,6.22697431467676E-6,49.9994087,49.9994087,-88557.5625,-88547.40625,57.6341604940061,20.6258057332977,17.593889,0,0,0,40,4449,49.99605,-88552.484375,,,,,,,,,,,,,0,,,,0,,,,,,49.9994087,,,,
,32538770.47,49.9983025,-84078.07421875,0.000155015998964246,1.83755087712394E-6,1,0.999253354069792,40.0298881530762,1.99667078560483,20.9599994122982,0.00174838060240493,0.000362678444174083,0.25,4.22463311763306E-6,0.000155521798338044,5.23411980358436E-6,49.9983025,49.9983025,-84080.6328125,-84075.515625,57.3918556530445,20.6225467980584,17.214239,0,0,0,40,4449,49.9981,-84078.07421875,,,,,,,,,,,,,0,,,,0.0049,,,,,,49.9983025,,,,
,32538868.005,49.9992752,-79203.21875,0.000140804525692634,2.20577099858206E-6,1,0.999253354069792,40.0298881530762,1.99665661080224,20.9599994122982,0.00158760293107131,0.000330475834169384,0.25,3.92087181686085E-6,0.000141238296669295,4.85147159992715E-6,49.9992752,49.9992752,-79213.328125,-79193.109375,57.7600026856023,20.6244378464538,17.214239,0,0,0,40,4449,49.99815,-79203.21875,,,,,,,,,,,,,0,,,,-0.00245,,,,,,49.9992752,,,,
,32538963.945,49.9998245,-74406.23046875,0.000128291535189741,1.73103109311731E-6,1,0.999253354069792,40.0298881530762,1.99667431599965,20.9599994122982,0.00144881346782522,0.000286840469131784,0.25,2.30530757631932E-6,0.000128671519539987,3.161059014158E-6,49.9998245,49.9998245,-74416.34375,-74396.1171875,57.6544828355061,20.6239231615395,17.593889,0,0,0,40,4449,49.99915,-74406.23046875,,,,,,,,,,,,,0,,,,0,,,,,,49.9998245,,,,
,32539057.81,49.99873545,-69713.9140625,0.000112829571937993,1.15300824607928E-6,1,0.999253354069792,40.0298881530762,1.99661558950076,20.9599994122982,0.00127418933477683,0.000250748481096423,0.25,1.88737199893204E-6,0.00011314351990459,2.64965389895838E-6,49.9987221,49.9987488,-69719.078125,-69708.75,57.7091968318523,20.6232232841858,17.593889,0,0,0,40,4449,49.9998,-69713.9140625,,,,,,,,,,,,,0,,,,-0.0049,,,,,,49.99873545,,,,
,32539157.815,49.9989166,-64719.34375,9.80903082515512E-5,1.52525160117349E-6,1,0.999253354069792,40.0298881530762,1.99678038641092,20.9599994122982,0.00110431586054022,0.000236226154100384,0.25,3.24377513311791E-6,9.8331828899684E-5,3.91984197063166E-6,49.9989166,49.9989166,-64726.98828125,-64711.69921875,57.7209212596407,20.6203856545129,17.214239,0,0,0,40,4449,50.00065,-64719.34375,,,,,,,,,,,,,0,,,,-0.00245,,,,,,49.9989166,,,,
,32539253.3,50.0000343,-59946.9453125,8.2199106081649E-5,1.36441314536753E-6,1,0.999253354069792,40.0298881530762,1.99655479576632,20.9599994122982,0.000921550204974406,0.000217744462630172,0.25,4.46427803264375E-6,8.23721641991543E-5,5.04183777575603E-6,50.0000343,50.0000343,-59959.63671875,-59934.25390625,57.4723633905253,20.6196361748386,17.593889,0,0,0,40,4449,50.0008,-59946.9453125,,,,,,,,,,,,,0,,,,0.00245,,,,,,50.0000343,,,,
,32539349.375,49.9999695,-55144.626953125,7.25682331271516E-5,1.23538363451256E-6,1,0.999253354069792,40.0298881530762,1.996687909498,20.9599994122982,0.000811431432884701,0.000203422021399952,0.25,4.92613738009434E-6,7.26980007118479E-5,5.4435495313431E-6,49.9999695,49.9999695,-55152.15234375,-55137.1015625,57.7756352559869,20.6203754222458,17.593889,0,0,0,40,4449,50.00135,-55144.626953125,,,,,,,,,,,,,0,,,,0.0049,,,,,,49.9999695,,,,
,32539446.535,49.9999542,-50287.85546875,5.6782501167382E-5,1.36221851771446E-6,1,0.999253354069792,40.0298881530762,1.996725648448,20.9599994122982,0.000634350777616404,0.000161546817714569,0.25,4.06276061373135E-6,5.68692321261948E-5,4.47175460658276E-6,49.9999542,49.9999542,-50290.22265625,-50285.48828125,57.7037254322177,20.6213787154067,17.593889,0,0,0,40,4449,50.0018,-50287.85546875,,,,,,,,,,,,,0,,,,0,,,,,,49.9999542,,,,
,32539544.46,49.9979706,-45395.689453125,4.18239218886974E-5,1.27341330124964E-6,1,0.999253354069792,40.0298881530762,1.99660360095575,20.9599994122982,0.000465917858566981,0.00012551277124925,0.25,3.5689964613808E-6,4.18734116102902E-5,3.87373506209208E-6,49.9979706,49.9979706,-45403.03125,-45388.34765625,57.423902422333,20.6196282142256,17.593889,0,0,0,40,4449,50.0003,-45395.689453125,,,,,,,,,,,,,0,,,,0,,,,,,49.9979706,,,,
,32539640.18,49.9986877,-40610.14453125,2.85004648624861E-5,1.05563442530079E-6,1,0.999253354069792,40.0298881530762,1.99662259672166,20.9599994122982,0.000314077742729829,0.000104072962570636,0.25,4.07131447247575E-6,2.85153106979459E-5,4.28285295075068E-6,49.9986877,49.9986877,-40620.21484375,-40600.07421875,58.0124686973138,20.618891305039,17.214239,0,0,0,40,4449,50.00315,-40610.14453125,,,,,,,,,,,,,0,,,,0.0049,,,,,,49.9986877,,,,
,32539734.775,50.0000343,-35885.875,1.51419559594912E-5,1.11644692318848E-6,1,0.999253354069792,40.0298881530762,1.99666237755693,20.9599994122982,0.000163780269525741,7.21972750180136E-5,0.25,3.65813386527748E-6,1.51351154354425E-5,3.77284216263298E-6,50.0000343,50.0000343,-35893.52734375,-35878.22265625,58.0179400969485,20.6182242293287,17.593889,0,0,0,40,4449,50.0028,-35885.875,,,,,,,,,,,,,0,,,,-0.00245,,,,,,50.0000343,,,,
,32539830.725,49.999382,-31088.3720703125,3.70822093323368E-7,8.21592362410501E-7,1,0.999253354069792,40.0298881530762,1.99668999701239,20.9599994122982,1.31973742017379E-6,1.67038618453579E-5,0.25,1.41072876124897E-6,3.6089177087736E-7,1.41491544126018E-6,49.999382,49.999382,-31090.87890625,-31085.865234375,57.7615659426407,20.6182421865932,17.214239,0,0,0,40,4449,50.00265,-31088.3720703125,,,,,,,,,,,,,0,,,,-0.00245,,,,,,49.999382,,,,
,32539925.39,50.0002823,-26358.3154296875,-1.1670112944052E-5,7.56489984608392E-7,1,0.999253354069792,40.0298881530762,1.99671134482685,20.9599994122982,-0.000135150611627591,-5.72564075169201E-6,0.25,1.59587176148884E-6,-1.16910402869123E-5,1.5112629581235E-6,50.0002823,50.0002823,-26368.20703125,-26348.423828125,57.8725571923715,20.6165772036916,17.593889,0,0,0,40,4449,50.00305,-26358.3154296875,,,,,,,,,,,,,0,,,,-0.0049,,,,,,50.0002823,,,,
,32540020.055,49.9989891,-21626.060546875,-2.33610029609333E-5,6.2441094387343E-7,1,0.999253354069792,40.0298881530762,1.99669411308677,20.9599994122982,-0.000266030801726832,-3.60968445967298E-5,0.25,1.01494611213093E-6,-2.33807986351459E-5,8.42783614466001E-7,49.9989891,49.9989891,-21636.078125,-21616.04296875,57.5098815594484,20.6182452613264,17.214239,0,0,0,40,4449,50.0035,-21626.060546875,,,,,,,,,,,,,0,,,,0.00245,,,,,,49.9989891,,,,
,32540117.79,49.9996948,-16741.3857421875,-3.58685547339364E-5,7.02535980406169E-7,1,0.999253354069792,40.0298881530762,1.99665135178862,20.9599994122982,-0.00040593603277682,-6.87842152599775E-5,0.25,3.75143857541327E-7,-3.58805606229386E-5,1.09143344501002E-7,49.9996948,49.9996948,-16748.794921875,-16733.9765625,57.4043617093522,20.6188695803377,17.593889,0,0,0,40,4449,50.00425,-16741.3857421875,,,,,,,,,,,,,0,,,,0,,,,,,49.9996948,,,,
,32540214.13,49.999382,-11926.3276367188,-4.71310925424602E-5,5.84110271317156E-7,1,0.999253354069792,40.0298881530762,1.99661325354586,20.9599994122982,-0.000532197055872274,-9.61943280892368E-5,0.25,-2.31311785710601E-8,-4.71307480920182E-5,-3.73534055697249E-7,49.999382,49.999382,-11936.3203125,-11916.3349609375,57.545836471333,20.6169837654505,17.214239,0,0,0,40,4449,50.00475,-11926.3276367188,,,,,,,,,,,,,0,,,,0.0049,,,,,,49.999382,,,,
,32540309.43,49.9993286,-7163.0107421875,-5.87844950669844E-5,4.08770132693142E-7,1,0.999253354069792,40.0298881530762,1.99683458846179,20.9599994122982,-0.000664390699499781,-0.000116084381930446,0.25,3.15061907591131E-7,-5.87721031416403E-5,-1.22451421275112E-7,49.9993286,49.9993286,-7172.888671875,-7153.1328125,57.5286406439099,20.6156799078491,17.973541,0,0,0,40,4449,50.0039,-7163.0107421875,,,,,,,,,,,,,0,,,,0,,,,,,49.9993286,,,,
,32540402.83,49.9988785,-2494.86730957031,-6.8908858634562E-5,3.48039242880456E-7,1,0.999253354069792,40.0298881530762,1.99680566520372,20.9599994122982,-0.000777009579784318,-0.000145080590441498,0.25,-4.30949859305344E-7,-6.88734412689072E-5,-9.43459451140163E-7,49.9988785,49.9988785,-2499.92065429687,-2489.81396484375,58.0781254929292,20.6123174631129,17.973541,0,0,0,40,4449,50.004,-2494.86730957031,,,,,,,,,,,,,0,,,,-0.00245,,,,,,49.9988785,,,,
,32540496.5,49.9986496,2184.16943359375,-7.38796271464059E-5,3.37775862825765E-7,1,0.999253354069792,40.0298881530762,1.99689037862096,20.9599994122982,-0.000832220688098714,-0.000160332572952281,0.25,-8.85666127356883E-7,-7.38375704419294E-5,-1.43491835283436E-6,49.9986496,49.9986496,2178.94897460938,2189.38989257813,57.8561429934677,20.6111236961559,17.214239,0,0,0,40,4449,50.0044,2184.16943359375,,,,,,,,,,,,,0,,,,0.0049,,,,,,49.9986496,,,,
,32540591.285,50.0002556,6920.2451171875,-7.84526797669728E-5,4.17469918162025E-7,1,0.999253354069792,40.0298881530762,1.99679373726555,20.9599994122982,-0.000882738583343603,-0.000176649706780073,0.25,-1.50411753430468E-6,-7.84208953234697E-5,-2.0875232724277E-6,50.0002556,50.0002556,6917.634765625,6922.85546875,57.4090514804676,20.6131661379308,17.214239,0,0,0,40,4449,50.00485,6920.2451171875,,,,,,,,,,,,,0,,,,0,,,,,,50.0002556,,,,
,32540687.2,50.000145,11718.7719726563,-7.45224478061057E-5,4.75916140380407E-7,1,0.999253354069792,40.0298881530762,1.99679891023593,20.9599994122982,-0.000838379666578825,-0.00016976251349173,0.25,-1.59941842667124E-6,-7.45094321480609E-5,-2.15347874869212E-6,50.000145,50.000145,11706.2998046875,11731.244140625,57.7834515411792,20.6122588023856,17.593889,0,0,0,40,4449,50.00355,11718.7719726563,,,,,,,,,,,,,0,,,,0.00245,,,,,,50.000145,,,,
,32540784.32,49.9984131,16571.5517578125,-5.71793513271819E-5,6.28471654990032E-7,1,0.999253354069792,40.0298881530762,1.99684286286521,20.9599994122982,-0.000641485412441192,-0.000141205111613385,0.25,-2.19424101504032E-6,-5.71772519794463E-5,-2.61902085220235E-6,49.9984131,49.9984131,16558.9765625,16584.126953125,58.04686035216,20.6155047126974,17.593889,0,0,0,40,4449,50.00485,16571.5517578125,,,,,,,,,,,,,0,,,,0.00245,,,,,,49.9984131,,,,
,32540878.045,50.0009804,21253.6396484375,-3.32047529194092E-5,7.673293220626E-7,1,0.999253354069792,40.0298881530762,1.99689156429339,20.9599994122982,-0.000371150990546926,-9.01937691190192E-5,0.25,-1.99819795727245E-6,-3.32067667217561E-5,-2.24475280624364E-6,50.0009804,50.0009804,21241.291015625,21265.98828125,57.3082214014868,20.6121469043116,17.973541,0,0,0,40,4449,50.0037,21253.6396484375,,,,,,,,,,,,,0,,,,0,,,,,,50.0009804,,,,
,32540974.43,50.0017509,26071.2138671875,-1.69158791155254E-5,8.92313681054679E-7,1,0.999253354069792,40.0298881530762,1.99677466267471,20.9599994122982,-0.000187620542964179,-5.42792893169889E-5,0.25,-1.7548004252366E-6,-1.69160070340423E-5,-1.88065577334151E-6,50.0017509,50.0017509,26068.87109375,26073.556640625,57.5982055821215,20.6139165436822,17.593889,0,0,0,40,4449,50.0022,26071.2138671875,,,,,,,,,,,,,0,,,,0,,,,,,50.0017509,,,,
,32541070.275,50.0015488,30861.8876953125,-1.46177667907793E-5,8.87120883464238E-7,1,0.999253354069792,40.0298881530762,1.9967196679972,20.9599994122982,-0.000160087485442262,-5.84792872206921E-5,0.25,-2.53985622269238E-6,-1.46142785636872E-5,-2.64942603916826E-6,50.0015488,50.0015488,30851.966796875,30871.80859375,57.5169162161215,20.6138797027128,17.593889,0,0,0,40,4449,50.0012,30861.8876953125,,,,,,,,,,,,,0,,,,0,,,,,,50.0015488,,,,
,32541165.775,49.9995842,35637.513671875,-1.89482806884462E-5,1.21230590407864E-6,1,0.999253354069792,40.0298881530762,1.9968449649954,20.9599994122982,-0.000206823098196633,-8.00369719567858E-5,0.25,-3.66548625766269E-6,-1.89460800631208E-5,-3.80784906496043E-6,49.9995842,49.9995842,35630.05859375,35644.96875,57.9608812150446,20.6094759552987,17.973541,0,0,0,40,4449,50.00195,35637.513671875,,,,,,,,,,,,,0,,,,-0.00245,,,,,,49.9995842,,,,
,32541263.745,49.9996681,40532.326171875,-2.8113844650054E-5,1.01921135610044E-6,1,0.999253354069792,40.0298881530762,1.99687784159796,20.9599994122982,-0.000313259064671725,-8.37531071086519E-5,0.25,-2.34351677563323E-6,-2.81404126171297E-5,-2.54961472119836E-6,49.9996681,49.9996681,40527.5859375,40537.06640625,57.87412044941,20.6111000220526,17.593889,0,0,0,40,4449,50.00235,40532.326171875,,,,,,,,,,,,,0,,,,-0.0049,,,,,,49.9996681,,,,
,32541358.205,50.0018578,45255.2421875,-4.12311987567371E-5,1.200700352187E-6,1,0.999253354069792,40.0298881530762,1.99665457201905,20.9599994122982,-0.000460753910412324,-0.000115781955272136,0.25,-2.8152816131876E-6,-4.12847039970898E-5,-3.1145078441469E-6,50.0018578,50.0018578,45245.3515625,45265.1328125,57.6005504676792,20.613849558143,17.593889,0,0,0,40,4449,50.0001,45255.2421875,,,,,,,,,,,,,0,,,,-0.00245,,,,,,50.0018578,,,,
,32541454.36,50.0025826,50060.41015625,-5.76840615599143E-5,1.18450205393381E-6,1,0.999253354069792,40.0298881530762,1.9967274325212,20.9599994122982,-0.000641717148678861,-0.000179114532061587,0.25,-5.45287245738455E-6,-5.77621276294036E-5,-5.87121291805138E-6,50.0025826,50.0025826,50047.86328125,50072.95703125,57.3973270526791,20.6144720134272,17.593889,0,0,0,40,4449,49.9989,50060.41015625,,,,,,,,,,,,,0,,,,-0.0049,,,,,,50.0025826,,,,
,32541550.015,50.0017929,54840.53515625,-7.24520331894422E-5,1.30646460309661E-6,1,0.999253354069792,40.0298881530762,1.99658298310521,20.9599994122982,-0.000809978435022267,-0.000203643544760369,0.25,-4.96736314421326E-6,-7.25801451301573E-5,-5.48438228887824E-6,50.0017929,50.0017929,54830.36328125,54850.70703125,57.8084636537946,20.6132754683113,17.593889,0,0,0,40,4449,49.99705,54840.53515625,,,,,,,,,,,,,0,,,,0.00245,,,,,,50.0017929,,,,
,32541644.585,50.000885,59570.751953125,-8.38702089027809E-5,1.20292304859103E-6,1,0.999253354069792,40.0298881530762,1.99659620405098,20.9599994122982,-0.000940209195748262,-0.000222605870198881,0.25,-4.59278581024233E-6,-8.40450311138761E-5,-5.18269387119557E-6,50.0008392,50.0009308,59563.140625,59578.36328125,57.5817913832176,20.6116799427514,17.214239,0,0,0,40,4449,49.9967,59570.751953125,,,,,,,,,,,,,0,,,,0,,,,,,50.000885,,,,
,32541743.53,50.0001526,64513.73828125,-9.99196646554146E-5,1.75972148360422E-6,1,0.999253354069792,40.0298881530762,1.99660843372724,20.9599994122982,-0.00112640039838912,-0.000231740967528901,0.25,-2.52069738574667E-6,-0.000100170060599387,-3.20766248814404E-6,50.0001526,50.0001526,64506.0546875,64521.421875,57.5341120435445,20.6098045955671,17.593889,0,0,0,40,4449,49.99585,64513.73828125,,,,,,,,,,,,,0,,,,-0.0049,,,,,,50.0001526,,,,
,32541839.235,50.0010319,69296.69140625,-0.000111240818542484,2.10038588485854E-6,1,0.999253354069792,40.0298881530762,1.99667964490361,20.9599994122982,-0.00125056840445575,-0.000278952247038653,0.25,-4.66118992079329E-6,-0.000111529546819462,-5.42170622847626E-6,50.0006104,50.0014534,69289.1875,69304.1953125,57.7279559163138,20.6086688263087,17.593889,0,0,0,40,4449,49.9944,69296.69140625,,,,,,,,,,,,,0,,,,0,,,,,,50.0010319,,,,
,32541934.02,50.0003853,74036.6640625,-0.000125364111538609,1.74875689448155E-6,1,0.999253354069792,40.0298881530762,1.99665512837617,20.9599994122982,-0.0014140092749599,-0.000289823013000056,0.25,-3.0933179285841E-6,-0.000125727979827912,-3.93304223929956E-6,50.0003853,50.0003853,74026.96875,74046.359375,57.3332335141022,20.6113656069336,17.593889,0,0,0,40,4449,49.99545,74036.6640625,,,,,,,,,,,,,0,,,,-0.00245,,,,,,50.0003853,,,,
,32542030.895,50.0013084,78877.7890625,-0.000140465683340352,1.77678336261442E-6,1,0.999253354069792,40.0298881530762,1.99669343842725,20.9599994122982,-0.00158575429557197,-0.000318726204902248,0.25,-2.94362427792491E-6,-0.000140902922447465,-3.86976451758714E-6,50.0013084,50.0013084,78870.125,78885.453125,57.5755383550638,20.6127045795564,17.214239,0,0,0,40,4449,49.9934,78877.7890625,,,,,,,,,,,,,0,,,,0,,,,,,50.0013084,,,,
,32542128.765,50.0014057,83770.99609375,-0.000152408266746494,1.74167098974376E-6,1,0.999253354069792,40.0298881530762,1.99681669913581,20.9599994122982,-0.00171514116081249,-0.000378517781667758,0.25,-6.08639129688641E-6,-0.000152891357549648,-7.08649421546771E-6,50.0013847,50.0014267,83758.421875,83783.5703125,57.3215090863138,20.6090975858977,17.214239,0,0,0,40,4449,49.99225,83770.99609375,,,,,,,,,,,,,0,,,,-0.00245,,,,,,50.0014057,,,,
,32542221.82,50.0007458,88421.65625,-0.000167751188376945,2.18834582445496E-6,1,0.999253354069792,40.0298881530762,1.99658969602173,20.9599994122982,-0.00189133336766467,-0.000397509880881441,0.25,-5.0272498870205E-6,-0.000168320981740302,-6.10696853872767E-6,50.0006676,50.000824,88416.7734375,88426.5390625,57.5137897020446,20.6102407238567,17.593889,0,0,0,40,4449,49.99215,88421.65625,,,,,,,,,,,,,0,,,,0,,,,,,50.0007458,,,,
,32542333.055,49.9989395,87101.04296875,-0.000168026851806925,1.86974480959243E-6,1,0.999253354069792,40.0298881530762,1.99661366843339,20.9599994122982,-0.00189395334919309,-0.000400519634022595,0.25,-5.23996010210628E-6,-0.000168588663936774,-6.3265455544113E-6,49.9987869,49.9990921,87088.609375,87113.4765625,57.5114448164869,20.6079298535704,17.973541,0,0,0,40,4449,49.9932,87101.04296875,,,,,,,,,,,,,0,,,,-0.0049,,,,,,49.9989395,,,,
,32542426.765,49.9997864,82417.484375,-0.000150268267078541,1.26771196476323E-6,1,0.999253354069792,40.0298881530762,1.99667403723814,20.9599994122982,-0.00169263738148111,-0.000363246104501889,0.25,-5.12202612930827E-6,-0.000150742882980041,-6.10900074508384E-6,49.9997864,49.9997864,82410.0078125,82424.9609375,57.6216544376984,20.6128957074574,17.214239,0,0,0,40,4449,49.99345,82417.484375,,,,,,,,,,,,,0,,,,0,,,,,,49.9997864,,,,
,32542526.435,49.9986954,77433.83203125,-0.000136360852218222,1.7686809226355E-6,1,0.999253354069792,40.0298881530762,1.99664694488451,20.9599994122982,-0.0015391612417852,-0.000310142729165341,0.25,-2.92015190102508E-6,-0.000136777496060851,-3.82325297869736E-6,49.9986954,49.9986954,77426.28125,77441.3828125,57.332451885583,20.6113534219521,17.973541,0,0,0,40,4449,49.9948,77433.83203125,,,,,,,,,,,,,0,,,,0,,,,,,49.9986954,,,,
,32542625.485,49.9991722,72482.55859375,-0.000121065040580925,2.0657914021232E-6,1,0.999253354069792,40.0298881530762,1.99669440657984,20.9599994122982,-0.00136226642406069,-0.000297678116321872,0.25,-4.55518840005875E-6,-0.000121398532621515,-5.37438328243694E-6,49.9991722,49.9991722,72477.875,72487.2421875,57.8358206519677,20.6101742231471,17.593889,0,0,0,40,4449,49.9956,72482.55859375,,,,,,,,,,,,,0,,,,0,,,,,,49.9991722,,,,
,32542719.565,49.9993362,67779.859375,-0.000104707458453973,1.79874835763927E-6,1,0.999253354069792,40.0298881530762,1.99664525317475,20.9599994122982,-0.00117474541165869,-0.000275258190186675,0.25,-5.50650907101238E-6,-0.000104965055844427,-6.22830139502789E-6,49.9993362,49.9993362,67774.9140625,67784.8046875,57.4887775894292,20.6114575671867,17.214239,0,0,0,40,4449,49.9959,67779.859375,,,,,,,,,,,,,0,,,,0,,,,,,49.9993362,,,,
,32542819.69,49.9994392,62774.421875,-9.07734814441299E-5,1.52762654974682E-6,1,0.999253354069792,40.0298881530762,1.99668855450085,20.9599994122982,-0.00101628597602071,-0.000249333515093028,0.25,-5.71448750280622E-6,-9.09706699360104E-5,-6.35026699321028E-6,49.9994392,49.9994392,62771.796875,62777.046875,57.6529195784676,20.614284977313,17.973541,0,0,0,40,4449,49.9957,62774.421875,,,,,,,,,,,,,0,,,,0.0049,,,,,,49.9994392,,,,
,32542912.84,49.9994392,58118.396484375,-7.88983188996518E-5,1.24580249396221E-6,1,0.999253354069792,40.0298881530762,1.99684728782246,20.9599994122982,-0.000883308928764341,-0.000216163784770899,0.25,-4.91398060493721E-6,-7.90534319686952E-5,-5.4721056915242E-6,49.9994392,49.9994392,58113.390625,58123.40234375,57.7474966292946,20.6119852107586,17.214239,0,0,0,40,4449,49.99805,58118.396484375,,,,,,,,,,,,,0,,,,-0.00245,,,,,,49.9994392,,,,
,32543010.21,49.9988842,53253.23828125,-6.35729866125968E-5,1.28522211238692E-6,1,0.999253354069792,40.0298881530762,1.99679587753964,20.9599994122982,-0.000712979613224903,-0.000166199098137838,0.25,-3.25321752847165E-6,-6.36883200186573E-5,-3.70586010686398E-6,49.9986229,49.9991455,53240.5625,53265.9140625,57.3949821671215,20.6091706021152,17.593889,0,0,0,40,4449,49.9977,53253.23828125,,,,,,,,,,,,,0,,,,0,,,,,,49.9988842,,,,
,32543104.94,49.9994392,48517.853515625,-5.07505208062054E-5,1.43784289572329E-6,1,0.999253354069792,40.0298881530762,1.99672461628972,20.9599994122982,-0.000564916375687612,-0.000155477348260451,0.25,-4.61098553511008E-6,-5.08166036708636E-5,-4.97956323836208E-6,49.9994392,49.9994392,48507.89453125,48527.8125,57.7076335748138,20.6133438744155,17.214239,0,0,0,40,4449,49.9985,48517.853515625,,,,,,,,,,,,,0,,,,0,,,,,,49.9994392,,,,
,32543200.015,49.9990616,43765.162109375,-3.74150208497347E-5,1.2221512248016E-6,1,0.999253354069792,40.0298881530762,1.99671084857715,20.9599994122982,-0.000416421053057385,-0.000114324023060406,0.25,-3.37269112460139E-6,-3.74548600885628E-5,-3.64624425631497E-6,49.9990616,49.9990616,43755.26953125,43775.0546875,57.4606389627369,20.6126336212421,17.973541,0,0,0,40,4449,49.99985,43765.162109375,,,,,,,,,,,,,0,,,,0,,,,,,49.9990616,,,,
,32543294.735,50.00071905,39029.677734375,-2.17439796316779E-5,9.66443763724514E-7,1,0.999253354069792,40.0298881530762,1.99672110432312,20.9599994122982,-0.00024012492082791,-7.65453860701836E-5,0.25,-2.85347552322159E-6,-2.17552678679154E-5,-3.01469567302787E-6,50.0006218,50.0008163,39022.30859375,39037.046875,57.6568277210638,20.6160003848413,17.593889,0,0,0,40,4449,49.99975,39029.677734375,,,,,,,,,,,,,0,,,,0,,,,,,50.00071905,,,,
,32543390.695,49.9990425,34234.98828125,-9.93006281842889E-6,1.14731924697229E-6,1,0.999253354069792,40.0298881530762,1.99694505105503,20.9599994122982,-0.000107203193045993,-4.85044576763171E-5,0.25,-2.50097742560403E-6,-9.9239111529594E-6,-2.57630621109938E-6,49.9990425,49.9990425,34229.85546875,34240.12109375,57.5020652742561,20.6113303537046,17.973541,0,0,0,40,4449,50.0007,34234.98828125,,,,,,,,,,,,,0,,,,0,,,,,,49.9990425,,,,
,32543483.44,50.0000534,29600.4951171875,4.23403794920288E-6,5.6692040786945E-7,1,0.999253354069792,40.0298881530762,1.99683469521193,20.9599994122982,5.42852435377674E-5,-2.70121658877962E-5,0.25,-3.15202008147612E-6,4.26121940009756E-6,-3.12402843032153E-6,50.0000534,50.0000534,29593.01953125,29607.970703125,57.6740235484869,20.6117629742825,17.593889,0,0,0,40,4449,50.00065,29600.4951171875,,,,,,,,,,,,,0,,,,0,,,,,,50.0000534,,,,
,32543577.335,49.9994659,24907.42578125,1.50963836976772E-5,7.31998194075408E-7,1,0.999253354069792,40.0298881530762,1.99677034103104,20.9599994122982,0.000174094828034265,1.14379854266203E-5,0.25,-1.70786898205717E-6,1.51196429587749E-5,-1.59782563467286E-6,49.9994659,49.9994659,24905.03515625,24909.81640625,57.7209212596407,20.6128193005652,17.593889,0,0,0,40,4449,50.00215,24907.42578125,,,,,,,,,,,,,0,,,,0,,,,,,49.9994659,,,,
,32543673.53,49.99849895,20099.4384765625,2.75532008692214E-5,6.48559168012534E-7,1,0.999253354069792,40.0298881530762,1.99677389809737,20.9599994122982,0.000314718227291411,3.72343904130715E-5,0.25,-1.66980949809511E-6,2.75777183293193E-5,-1.46660189655223E-6,49.9984589,49.998539,20091.861328125,20107.015625,57.5075366738907,20.6155584118002,17.214239,0,0,0,40,4449,50.00125,20099.4384765625,,,,,,,,,,,,,0,,,,0,,,,,,49.99849895,,,,
,32543768.195,49.9995422,15370.4780273438,3.96729095722121E-5,4.71094354892171E-7,1,0.999253354069792,40.0298881530762,1.99684530455543,20.9599994122982,0.000451813754847671,6.04636343586922E-5,0.25,-1.7977119888307E-6,3.9693469729009E-5,-1.5034981586773E-6,49.9995422,49.9995422,15360.3779296875,15380.578125,57.6716786629292,20.6153120772815,17.973541,0,0,0,40,4449,50.00315,15370.4780273438,,,,,,,,,,,,,0,,,,0,,,,,,49.9995422,,,,
,32543861.555,49.9998055,10700.3354492187,5.13850487838744E-5,3.69207821226157E-7,1,0.999253354069792,40.0298881530762,1.99680097525941,20.9599994122982,0.000580672241501022,0.000102515605666581,0.25,-1.84231953160506E-7,5.13828712721734E-5,1.97942235503197E-7,49.9998055,49.9998055,10697.705078125,10702.9658203125,57.9663526146792,20.618080192323,17.214239,0,0,0,40,4449,50.0034,10700.3354492187,,,,,,,,,,,,,0,,,,0.0049,,,,,,49.9998055,,,,
,32543955.92,49.9999084,5984.6591796875,6.26187419687652E-5,3.4915197589889E-7,1,0.999253354069792,40.0298881530762,1.99693868926655,20.9599994122982,0.000707410548446442,0.000125371617539816,0.25,-1.83630950287032E-7,6.26007709831035E-5,2.82415664983856E-7,49.9999084,49.9999084,5974.70166015625,5994.61669921875,57.8530164793907,20.6127784855712,17.593889,0,0,0,40,4449,50.0034,5984.6591796875,,,,,,,,,,,,,0,,,,0.00245,,,,,,49.9999084,,,,
,32544049.75,50.0001106,1296.06884765625,7.15289273680384E-5,3.16961896136264E-7,1,0.999253354069792,40.0298881530762,1.99692010145754,20.9599994122982,0.000807665367700026,0.000144461008294703,0.25,-9.62542478180499E-8,7.14928246706578E-5,4.35926696746709E-7,50.0001106,50.0001106,1290.96899414062,1301.16870117188,57.6114932669484,20.6144791865749,17.593889,0,0,0,40,4449,50.00365,1296.06884765625,,,,,,,,,,,,,0,,,,0.00245,,,,,,50.0001106,,,,
,32544077.18,50.0004921,-0.152237728238106,7.29051965916227E-5,3.42098940569563E-7,1,0.999253354069792,40.0298881530762,1.99687071365404,20.9599994122982,0.000822910240060913,0.000148580173756476,0.25,2.14545148233683E-8,7.28646223895479E-5,5.63732537487715E-7,50.0004921,50.0004921,-0.1674614995718,-0.137013956904411,57.586481154333,20.6159386452398,17.973541,0,0,0,40,4417,50.004,-0.152237728238106,,,,,,,,,,,,,0,,,,-0.00245,,,,,,50.0004921,,,,