File: data/doubleLayers/dl_1-25/ppms/data/DD205_3_HYST_300KREPEAT.DAT
[Header]
; VSM Data File (default extension .dat)
; Copyright (c) 2003-2013, Quantum Design, Inc. All rights reserved.
TITLE,
FILEOPENTIME,33034559.02,01/18/2019,4:18 pm
BYAPP,VSM,2.0,2.0
INFO,PPMS VSM Option Release 1.4.10 Build 1,APPNAME
INFO,Quantum Design Linear Motor Servo Controller,MOTOR_MODULE_NAME
INFO,3101-100 M1,MOTOR_HW_VERSION
INFO,MMC1014,MOTOR_SERIAL_NUMBER
INFO,SRV No X-over 01.03.11,MOTOR_SOFTWARE_VERSION
INFO,Quantum Design VSM Detection Module,VSM_MODULE_NAME
INFO,3101-150 F0,VSM_HW_VERSION
INFO,VSM707,VSM_SERIAL_NUMBER
INFO,VSM No X-over 01.02.05 May 20 2008 13:51:47,VSM_SOFTWARE_VERSION
INFO,704,PREAMP_SERIAL_NUMBER
INFO,822,COIL_SERIAL_NUMBER
INFO,0,MOMENT_UNITS
INFO,DD205_4,SAMPLE_MATERIAL
INFO,Double Layer Blue 1.25,SAMPLE_COMMENT
INFO,26.73,SAMPLE_MASS
INFO,,SAMPLE_VOLUME
INFO,,SAMPLE_MOLECULAR_WEIGHT
INFO,,SAMPLE_SIZE
INFO,,SAMPLE_SHAPE
DATATYPE,COMMENT,1
DATATYPE,TIME,2
STARTUPAXIS,X,2
STARTUPAXIS,Y1,5
[Data]
Comment,Time Stamp (sec),Temperature (K),Magnetic Field (Oe),Moment (emu),M. Std. Err. (emu),Transport Action,Averaging Time (sec),Frequency (Hz),Peak Amplitude (mm),Center Position (mm),Coil Signal' (mV),Coil Signal" (mV),Range (mV),M. Quad. Signal (emu),M. Raw' (emu),M. Raw" (emu),Min. Temperature (K),Max. Temperature (K),Min. Field (Oe),Max. Field (Oe),Mass (grams),Motor Lag (deg),Pressure (Torr),VSM Status (code),Motor Status (code),Measure Status (code),Measure Count,PPMS Status (code),System Temp. (K),System Field (Oe),Sample Position (deg),Bridge 1 Resistance (ohms),Bridge 1 Excitation (에),Bridge 2 Resistance (ohms),Bridge 2 Excitation (에),Bridge 3 Resistance (ohms),Bridge 3 Excitation (에),Bridge 4 Resistance (ohms),Bridge 4 Excitation (에),Signal 1 Vin (V),Signal 2 Vin (V),Digital Inputs (code),Drive 1 Iout (mA),Drive 1 Ipower (W),Drive 2 Iout (mA),Drive 2 Ipower (W),Pressure (),Map 20 (),Map 21 (),Map 22 (),Map 23 (),Map 24 (),Map 25 (),Map 26 (),Map 27 (),Map 28 (),Map 29 ()
,33034574.86,300.018219,0.0608950927853584,,,2,,,,19.0600003090501,,,,,,,300.018219,300.018219,0.0608950927853584,0.0608950927853584,,,25.186911,,,,-99999999,4369,300.3406,0.0608950927853584,,,,,,,,,,,,,,,,,,,,,,,300.018219,,,,
,33034728.845,300.0497131,4801.33203125,5.2725774737229E-5,5.94540276171366E-7,1,0.999253354069792,40.0298881530762,1.99887288905534,19.0500002354383,0.000596070399735841,0.000107302750683091,0.25,3.45511780659901E-7,5.27238803820481E-5,3.80454591067385E-7,300.0497131,300.0497131,4793.56103515625,4809.10302734375,56.3937160339867,20.4646647245919,26.325863,0,0,0,40,4449,300.2697,4801.33203125,,,,,,,,,,,,,0,,,,0,,,,,,300.0497131,,,,
,33034835.67,300.0510559,10139.556640625,4.69019122245037E-5,8.90501388386956E-7,1,0.999253354069792,40.0298881530762,1.99884507222548,19.0500002354383,0.000530565783955062,9.34764960921837E-5,0.25,1.3306139254048E-7,4.69003423887515E-5,1.64128553560324E-7,300.0510559,300.0510559,10131.9892578125,10147.1240234375,56.607882248256,20.4713524161133,26.325863,0,0,0,40,4449,300.22495,10139.556640625,,,,,,,,,,,,,0,,,,0,,,,,,300.0510559,,,,
,33034942.565,300.0408936,15482.2338867188,3.37863583883477E-5,1.41604735798112E-6,1,0.999253354069792,40.0298881530762,1.99883953655154,19.0600007772446,0.000380408512612244,7.76687309659683E-5,0.25,1.00876654873034E-6,3.3784637242068E-5,1.0310997649092E-6,300.0408936,300.0408936,15474.744140625,15489.7236328125,56.7204367550252,20.4758706930513,27.085165,0,0,0,40,4449,300.1826,15482.2338867188,,,,,,,,,,,,,0,,,,-0.00245,,,,,,300.0408936,,,,
,33035042.72,300.0298157,20489.544921875,2.08741246141719E-5,1.87992726713523E-6,1,0.999253354069792,40.0298881530762,1.99878570098592,19.0500002354383,0.000235857823003733,4.31530939179285E-5,0.25,1.96347213461041E-7,2.08733533646666E-5,2.1014626053766E-7,300.0298157,300.0298157,20487.1015625,20491.98828125,56.851750346256,20.4776087151992,26.705515,0,0,0,40,4449,300.1639,20489.544921875,,,,,,,,,,,,,0,,,,0,,,,,,300.0298157,,,,
,33035140.295,300.02566525,25364.90625,6.82971888192467E-6,9.96187156137603E-7,1,0.999253354069792,40.0298881530762,1.99859475530257,19.0500002354383,7.52911908387965E-5,2.49175768289233E-5,0.25,1.01858791474647E-6,6.82883738935361E-6,1.02306952219037E-6,300.0250854,300.0262451,25354.837890625,25374.974609375,56.9986965078714,20.4811979133452,26.705515,0,0,0,40,4449,300.1438,25364.90625,,,,,,,,,,,,,0,,,,-0.0049,,,,,,300.02566525,,,,
,33035238.515,300.0195923,30275.01171875,-7.35594105770254E-6,9.92611179615857E-7,1,0.999253354069792,40.0298881530762,1.99870358697593,19.0500002354383,-8.29549596295502E-5,-1.61124344679689E-5,0.25,-1.49264273330543E-7,-7.35562003304796E-6,-1.54115387901818E-7,300.0195923,300.0195923,30262.576171875,30287.447265625,56.8986480574099,20.4790221730795,26.705515,0,0,0,40,4449,300.12905,30275.01171875,,,,,,,,,,,,,0,,,,-0.0049,,,,,,300.0195923,,,,
,33035334.695,300.01474,35082.603515625,-2.19737368752596E-5,1.24979991057186E-6,1,0.999253354069792,40.0298881530762,1.99860727541818,19.0500002354383,-0.000248398142584455,-4.46334152347572E-5,0.25,-1.37006440020299E-7,-2.19729871333251E-5,-1.51491393576899E-7,300.01474,300.01474,35079.95703125,35085.25,56.861911517006,20.4806352026837,26.705515,0,0,0,40,4449,300.1378,35082.603515625,,,,,,,,,,,,,0,,,,0,,,,,,300.01474,,,,
,33035431.58,300.011322,39922.591796875,-3.74221753182228E-5,1.99422021948259E-6,1,0.999253354069792,40.0298881530762,1.99872544524279,19.0500002354383,-0.000426320964899894,-5.71730210239169E-5,0.25,1.43170814421042E-6,-3.74220023241087E-5,1.40701647696884E-6,300.011322,300.011322,39912.75390625,39932.4296875,56.8001628639868,20.4812468031615,27.085165,0,0,0,40,4449,300.13505,39922.591796875,,,,,,,,,,,,,0,,,,0.00245,,,,,,300.011322,,,,
,33035528.19,300.0032196,44753.330078125,-5.11402336246109E-5,1.792953962828E-6,1,0.999253354069792,40.0298881530762,1.99850217367034,19.0500002354383,-0.000577168695439943,-0.000109113439915949,0.25,-7.82144960230529E-7,-5.11382119471319E-5,-8.15770865332702E-7,300.0027161,300.0037231,44745.99609375,44760.6640625,56.851750346256,20.4829116738714,27.085165,0,0,0,40,4449,300.12295,44753.330078125,,,,,,,,,,,,,0,,,,-0.0049,,,,,,300.0032196,,,,
,33035625.165,300.0111389,49600.97265625,-6.54911156425351E-5,1.45898232353496E-6,1,0.999253354069792,40.0298881530762,1.99857924557558,19.0500002354383,-0.000741006111334508,-0.000129081099213243,0.25,-5.99753560946961E-8,-6.54891319362058E-5,-1.03016974280698E-7,300.0111389,300.0111389,49594.13671875,49607.80859375,56.7774956369291,20.4779366051466,26.325863,0,0,0,40,4449,300.1178,49600.97265625,,,,,,,,,,,,,0,,,,0,,,,,,300.0111389,,,,
,33035723.695,300.00608825,54526.30859375,-8.38457092226006E-5,1.89212073636971E-6,1,0.999253354069792,40.0298881530762,1.99844757175462,19.0500002354383,-0.000946716469340505,-0.000176243817149951,0.25,-1.04865588325966E-6,-8.38425524057386E-5,-1.10366904089173E-6,300.0055237,300.0066528,54521.3125,54531.3046875,57.0088576786214,20.4740308882952,26.705515,0,0,0,40,4449,300.1085,54526.30859375,,,,,,,,,,,,,0,,,,0.0049,,,,,,300.00608825,,,,
,33035815.63,300.0035095,59121.443359375,-9.57338354508617E-5,1.9287353816707E-6,1,0.999253354069792,40.0298881530762,1.99833176260106,19.0500002354383,-0.00108509324178663,-0.000176947869833684,0.25,9.4784432429713E-7,-9.57316537847058E-5,8.85038459646455E-7,300.0035095,300.0035095,59118.6796875,59124.20703125,56.8392442899483,20.4752414588866,27.085165,0,0,0,40,4449,300.1099,59121.443359375,,,,,,,,,,,,,0,,,,-0.00245,,,,,,300.0035095,,,,
,33035911.155,300.0040283,63897.06640625,-0.00010983754962505,1.87736238323122E-6,1,0.999253354069792,40.0298881530762,1.99823353044738,19.0500002354383,-0.00124483648016384,-0.000203333824597465,0.25,1.05848676544756E-6,-0.000109835032131137,9.86512743335235E-7,300.0040283,300.0040283,63887.00390625,63907.12890625,56.7485753817175,20.4753883093569,26.705515,0,0,0,40,4449,300.10625,63897.06640625,,,,,,,,,,,,,0,,,,0,,,,,,300.0040283,,,,
,33036005.93,300.0000305,68632.5703125,-0.000125327984381706,2.57428070746014E-6,1,0.999253354069792,40.0298881530762,1.99802621356547,19.0500002354383,-0.00141660718913886,-0.000253047671429029,0.25,-6.53884131401337E-7,-0.000125323919770148,-7.3585564796727E-7,300.0000305,300.0000305,68629.9921875,68635.1484375,56.7282530402175,20.4789820570484,26.705515,0,0,0,40,4449,300.1118,68632.5703125,,,,,,,,,,,,,0,,,,-0.00245,,,,,,300.0000305,,,,
,33036103.555,299.9959717,73512.9140625,-0.000142471755380082,2.30818125557453E-6,1,0.999253354069792,40.0298881530762,1.99793522867215,19.0500002354383,-0.00161250111282809,-0.00027504331818084,0.25,3.70911432234921E-7,-0.00014246789423481,2.77807761213333E-7,299.9959717,299.9959717,73502.796875,73523.03125,56.6375841319868,20.4773892708513,27.085165,0,0,0,40,4449,300.10665,73512.9140625,,,,,,,,,,,,,0,,,,-0.0049,,,,,,299.9959717,,,,
,33036201.04,300.0031738,78385.96484375,-0.000153239509531532,3.05419555482715E-6,1,0.999253354069792,40.0298881530762,1.99777398171075,19.0500002354383,-0.00172938131918048,-0.000323835383903921,0.25,-2.0788558692203E-6,-0.000153233710561643,-2.17880052542403E-6,300.0031738,300.0031738,78381.078125,78390.8515625,56.7110572127945,20.4803388474818,27.464817,0,0,0,40,4449,300.10415,78385.96484375,,,,,,,,,,,,,0,,,,-0.00245,,,,,,300.0031738,,,,
,33036296.2,300.0045776,83142.0546875,-0.000169821773957181,2.34946133821327E-6,1,0.999253354069792,40.0298881530762,1.99778038033868,19.0500002354383,-0.00191952613036331,-0.000341562437861005,0.25,-7.73132135522893E-7,-0.000169816350471651,-8.83800727329476E-7,300.0045776,300.0045776,83134.609375,83149.5,56.5383173100444,20.4812210228173,27.085165,0,0,0,40,4449,300.10245,83142.0546875,,,,,,,,,,,,,0,,,,0.00245,,,,,,300.0045776,,,,
,33036389.105,300.0051575,87785.578125,-0.000184851140123307,2.79426217475753E-6,1,0.999253354069792,40.0298881530762,1.99771966536443,19.0500002354383,-0.00209216868545071,-0.000355483204979265,0.25,5.99014705058661E-7,-0.000184846184000947,4.78653516006506E-7,300.0051575,300.0051575,87778.0546875,87793.1015625,56.6610329875637,20.4815520846778,26.705515,0,0,0,40,4449,300.0964,87785.578125,,,,,,,,,,,,,0,,,,-0.00245,,,,,,300.0051575,,,,
,33036497.315,300.0014648,87750.76953125,-0.000187951584798652,2.91809590497246E-6,1,0.999253354069792,40.0298881530762,1.99764883585228,19.0500002354383,-0.00213362292196582,-0.000324291659862609,0.25,3.89263223540005E-6,-0.000187948708171331,3.77015755965703E-6,300.0014648,300.0014648,87743.359375,87758.1796875,56.5007991411214,20.4824842577351,27.464817,0,0,0,40,4449,300.09825,87750.76953125,,,,,,,,,,,,,0,,,,-0.00245,,,,,,300.0014648,,,,
,33036590.235,299.993042,83104.43359375,-0.000170603271781814,2.75123763344154E-6,1,0.999253354069792,40.0298881530762,1.99774961404564,19.0500002354383,-0.00193290604418515,-0.000316727649932868,0.25,1.55727837399165E-6,-0.000170599415336097,1.44603355872471E-6,299.993042,299.993042,83094.3046875,83114.5625,56.5547315089483,20.4843791113355,27.085165,0,0,0,40,4449,300.10515,83104.43359375,,,,,,,,,,,,,0,,,,-0.00245,,,,,,299.993042,,,,
,33036685.72,299.9900208,78328,-0.000156782642032091,2.97367438008959E-6,1,0.999253354069792,40.0298881530762,1.99763637458576,19.0500002354383,-0.00177929993431019,-0.00027330302301144,0.25,3.00053013786452E-6,-0.000156780129346214,2.89812854484799E-6,299.9900208,299.9900208,78320.5390625,78335.4609375,56.6407106460637,20.4839408536899,26.705515,0,0,0,40,4449,300.11105,78328,,,,,,,,,,,,,0,,,,0,,,,,,299.9900208,,,,
,33036782.945,299.989563,73469.8125,-0.000142388756068244,2.56175409063293E-6,1,0.999253354069792,40.0298881530762,1.99705954362126,19.0500002354383,-0.00161278297894188,-0.000263830186033227,0.25,1.33795119581302E-6,-0.00014238556232073,1.24487860330197E-6,299.989563,299.989563,73462.25,73477.375,56.6305494753137,20.487284510013,26.705515,0,0,0,40,4449,300.1217,73469.8125,,,,,,,,,,,,,0,,,,0.0049,,,,,,299.989563,,,,
,33036877.72,299.9876404,68731.46875,-0.000123813574451519,1.55815781007819E-6,1,0.999253354069792,40.0298881530762,1.99712495270852,19.0500002354383,-0.00139976969567343,-0.000244791355629673,0.25,-1.95790768410469E-7,-0.000123809909084602,-2.7677939736928E-7,299.9876404,299.9876404,68724.1015625,68738.8359375,56.6579064734868,20.4861215402754,27.085165,0,0,0,40,4449,300.1231,68731.46875,,,,,,,,,,,,,0,,,,-0.00245,,,,,,299.9876404,,,,
,33036973.35,299.9830627,63953.40234375,-0.000109193930685108,2.39329077992172E-6,1,0.999253354069792,40.0298881530762,1.99715295995783,19.0500002354383,-0.00124123612469635,-0.000177035182684374,0.25,3.26322161694694E-6,-0.000109192959053804,3.19161929792252E-6,299.9830627,299.9830627,63941.0078125,63965.796875,56.6672860157175,20.4856826167751,27.085165,0,0,0,40,4449,300.14635,63953.40234375,,,,,,,,,,,,,0,,,,-0.00245,,,,,,299.9830627,,,,
,33037070.565,299.9875183,59090.0234375,-9.35288982038001E-5,2.16658680698499E-6,1,0.999253354069792,40.0298881530762,1.99705340562905,19.0500002354383,-0.00105700723231946,-0.000186894311761275,0.25,-3.23301508690752E-7,-9.35260023101736E-5,-3.84613186023312E-7,299.9875183,299.9875183,59082.2421875,59097.8046875,56.6141352764098,20.4862659440331,27.085165,0,0,0,40,4449,300.15915,59090.0234375,,,,,,,,,,,,,0,,,,0.00245,,,,,,299.9875183,,,,
,33037167.285,299.9863586,54257.212890625,-7.88812365688047E-5,1.84436221555516E-6,1,0.999253354069792,40.0298881530762,1.99707058498769,19.0500002354383,-0.000894615829770853,-0.00013950008324731,0.25,1.33027085996347E-6,-7.88798442060861E-5,1.27845670447522E-6,299.9863586,299.9863586,54244.765625,54269.66015625,56.7954730928714,20.4853570781421,27.085165,0,0,0,40,4449,300.1696,54257.212890625,,,,,,,,,,,,,0,,,,-0.00245,,,,,,299.9863586,,,,
,33037262.15,299.9923401,49514.732421875,-6.53989806630044E-5,1.8469136433712E-6,1,0.999253354069792,40.0298881530762,1.99713159195666,19.0500002354383,-0.000744247861646982,-0.000101132883914748,0.25,2.38758570857097E-6,-6.53986529667029E-5,2.34454258417815E-6,299.9923401,299.9923401,49507.26953125,49522.1953125,56.6821369575829,20.488507447252,26.705515,0,0,0,40,4449,300.1766,49514.732421875,,,,,,,,,,,,,0,,,,0,,,,,,299.9923401,,,,
,33037356.72,299.9805908,44789.244140625,-5.07273456291518E-5,1.5353330180866E-6,1,0.999253354069792,40.0298881530762,1.99712051636711,19.0500002354383,-0.000576223305982387,-8.45442617046694E-5,0.25,1.31257549574075E-6,-5.07267562883684E-5,1.27917100901067E-6,299.9805908,299.9805908,44779.1171875,44799.37109375,57.0612267894099,20.486933959818,26.705515,0,0,0,40,4449,300.20065,44789.244140625,,,,,,,,,,,,,0,,,,-0.00245,,,,,,299.9805908,,,,
,33037452.01,299.9848022,40028.34765625,-3.59443540944104E-5,1.47135746648138E-6,1,0.999253354069792,40.0298881530762,1.99712205541075,19.0500002354383,-0.000412086195711224,-3.80542318055146E-5,0.25,2.86244712329261E-6,-3.59452018711544E-5,2.8386955913411E-6,299.9848022,299.9848022,40020.765625,40035.9296875,56.9400743689291,20.4891920087207,27.464817,0,0,0,40,4449,300.2007,40028.34765625,,,,,,,,,,,,,0,,,,0,,,,,,299.9848022,,,,
,33037547.385,299.9878235,35261.134765625,-2.14509855161095E-5,1.09779842753786E-6,1,0.999253354069792,40.0298881530762,1.99707724726334,19.0500002354383,-0.000242408134237225,-4.29841670696162E-5,0.25,-8.4616450101987E-8,-2.14503071819179E-5,-9.87537312206819E-8,299.9878235,299.9878235,35248.765625,35273.50390625,56.9385111118906,20.4909301770374,27.085165,0,0,0,40,4449,300.2116,35261.134765625,,,,,,,,,,,,,0,,,,0,,,,,,299.9878235,,,,
,33037644.015,299.9809265,30428.626953125,-5.74570566444067E-6,1.0532791377577E-6,1,0.999253354069792,40.0298881530762,1.99706548757995,19.0500002354383,-6.47936665761851E-5,-1.229641523468E-5,0.25,-9.19070656885543E-8,-5.74547935695503E-6,-9.56955266941274E-8,299.9809265,299.9809265,30421.05859375,30436.1953125,56.5633294226598,20.4914049427982,27.464817,0,0,0,40,4449,300.22905,30428.626953125,,,,,,,,,,,,,0,,,,0,,,,,,299.9809265,,,,
,33037740.38,299.9857178,25613.4013671875,6.12171669555048E-6,7.76111714155505E-7,1,0.999253354069792,40.0298881530762,1.9972388038522,19.0500002354383,6.57039332213213E-5,3.23549205633453E-5,0.25,1.80031855973147E-6,6.12034973386491E-6,1.80430940922639E-6,299.9857178,299.9857178,25603.4453125,25623.357421875,56.6594697305252,20.4919509023916,27.464817,0,0,0,40,4449,300.2391,25613.4013671875,,,,,,,,,,,,,0,,,,-0.0049,,,,,,299.9857178,,,,
,33037835.54,299.9929504,20858.490234375,1.97217069996117E-5,6.53820649924634E-7,1,0.999253354069792,40.0298881530762,1.99698088580094,19.0500002354383,0.000221885474484691,4.51186366906311E-5,0.25,5.73123292762282E-7,1.97207486465437E-5,5.8614477264277E-7,299.9929504,299.9929504,20850.994140625,20865.986328125,56.7345060683714,20.4937908608086,27.464817,0,0,0,40,4449,300.2354,20858.490234375,,,,,,,,,,,,,0,,,,0,,,,,,299.9929504,,,,
,33037930.21,299.9841309,16126.1264648438,3.23881323886757E-5,6.03493139713807E-7,1,0.999253354069792,40.0298881530762,1.99707787426,19.0500002354383,0.000364532168309063,7.33958808089998E-5,0.25,8.78940893579535E-7,3.23866077726474E-5,9.00346268690922E-7,299.9841309,299.9841309,16113.646484375,16138.6064453125,56.6946430138906,20.4932839126076,27.085165,0,0,0,40,4449,300.24875,16126.1264648438,,,,,,,,,,,,,0,,,,0.0049,,,,,,299.9841309,,,,
,33038025.805,299.99038695,11348.7358398438,4.42165101659425E-5,5.05612942013106E-7,1,0.999253354069792,40.0298881530762,1.99704562446687,19.0500002354383,0.000499680319766581,8.85043156333809E-5,0.25,1.65724958487181E-7,4.42151008199691E-5,1.95002570097098E-7,299.989563,299.9912109,11346.3037109375,11351.16796875,56.7946914643522,20.4951066574,27.464817,0,0,0,40,4449,300.25715,11348.7358398438,,,,,,,,,,,,,0,,,,0,,,,,,299.99038695,,,,
,33038119.205,299.986969,6677.95288085938,5.27998057513377E-5,4.36908556495415E-7,1,0.999253354069792,40.0298881530762,1.99689546656993,19.0500002354383,0.000598185027050073,9.67328427231297E-5,0.25,-5.931538215165E-7,5.27986510930564E-5,-5.58143145053907E-7,299.986969,299.986969,6673.107421875,6682.79833984375,56.8017261210252,20.4957329923694,27.085165,0,0,0,40,4449,300.2655,6677.95288085938,,,,,,,,,,,,,0,,,,0,,,,,,299.986969,,,,
,33038209.91,299.9910889,2147.30444335938,4.78105607875132E-5,4.50944401946142E-7,1,0.999253354069792,40.0298881530762,1.99711539444713,19.0500002354383,0.000540934035273635,9.21215403788243E-5,0.25,-1.37411913779225E-7,4.78092415167457E-5,-1.05701191730561E-7,299.9910889,299.9910889,2139.71508789062,2154.89379882813,56.7946914643522,20.4950795655699,27.464817,0,0,0,40,4449,300.27295,2147.30444335938,,,,,,,,,,,,,0,,,,-0.00245,,,,,,299.9910889,,,,
,33038300.22,299.9902344,-2363.98034667969,-4.72733258824083E-5,4.83633521533185E-7,1,0.999253354069792,40.0298881530762,1.99704121699769,19.0500002354383,-0.000532922003045306,-0.000102134512924908,0.25,-8.41428911593885E-7,-4.72713748245048E-5,-8.72754003586152E-7,299.9902344,299.9902344,-2373.79809570313,-2354.16259765625,56.8454973181022,20.4973666110894,27.085165,0,0,0,40,4449,300.26995,-2363.98034667969,,,,,,,,,,,,,0,,,,-0.00245,,,,,,299.9902344,,,,
,33038394.8,299.9968872,-7093.2998046875,-5.17358813195104E-5,4.58871740166557E-7,1,0.999253354069792,40.0298881530762,1.99706111821773,19.0500002354383,-0.000584223857971006,-0.000106068139374926,0.25,-4.1604470462943E-7,-5.17340709158109E-5,-4.5031695329174E-7,299.9968872,299.9968872,-7098.251953125,-7088.34765625,56.8376810329099,20.4984055610766,27.085165,0,0,0,40,4449,300.27495,-7093.2998046875,,,,,,,,,,,,,0,,,,-0.0049,,,,,,299.9968872,,,,
,33038492.145,300.0072632,-11959.001953125,-4.24279409579327E-5,5.34421208182843E-7,1,0.999253354069792,40.0298881530762,1.9971056598491,19.0500002354383,-0.000478493552147834,-9.06293682155593E-5,0.25,-6.63312398217208E-7,-4.24262293831927E-5,-6.91386211749897E-7,300.0072632,300.0072632,-11966.4091796875,-11951.5947265625,56.6211699330829,20.4962957378348,27.085165,0,0,0,40,4449,300.26815,-11959.001953125,,,,,,,,,,,,,0,,,,0.0049,,,,,,300.0072632,,,,
,33038589.06,300.0051575,-16801.5546875,-3.11799208636295E-5,6.96613804542265E-7,1,0.999253354069792,40.0298881530762,1.99700003801991,19.0500002354383,-0.000350297898369142,-7.42475339350267E-5,0.25,-1.16383890438453E-6,-3.117821986832E-5,-1.18443165464194E-6,300.0051575,300.0051575,-16814.12109375,-16788.98828125,56.8540952318137,20.4983085249867,26.705515,0,0,0,40,4449,300.26505,-16801.5546875,,,,,,,,,,,,,0,,,,-0.00245,,,,,,300.0051575,,,,
,33038685.04,300.0057068,-21598.9072265625,-1.7900353075425E-5,9.358607575229E-7,1,0.999253354069792,40.0298881530762,1.99721549299211,19.0500002354383,-0.000201505888591833,-4.04389086303577E-5,0.25,-4.74439270481801E-7,-1.78995056115267E-5,-4.86256419876427E-7,300.0057068,300.0057068,-21606.4140625,-21591.400390625,56.7884384361983,20.4990500385628,27.085165,0,0,0,40,4449,300.2597,-21598.9072265625,,,,,,,,,,,,,0,,,,0,,,,,,300.0057068,,,,
,33038782.605,300.0073242,-26476.44140625,-3.23604065367841E-6,7.0188687207723E-7,1,0.999253354069792,40.0298881530762,1.99729293020072,19.0500002354383,-3.45997931274931E-5,-1.78729572737046E-5,0.25,-1.01969104914178E-6,-3.23527084619042E-6,-1.02179737494271E-6,300.0073242,300.0073242,-26478.9375,-26473.9453125,56.5523866233906,20.4972283157201,27.085165,0,0,0,40,4449,300.2586,-26476.44140625,,,,,,,,,,,,,0,,,,0,,,,,,300.0073242,,,,
,33038877.275,300.0123291,-31206.7509765625,1.05091289629387E-5,1.13149642431538E-6,1,0.999253354069792,40.0298881530762,1.9973136242935,19.0500002354383,0.000120901954685622,8.76917787734647E-6,0.25,-1.04539293160258E-6,1.05095038450591E-5,-1.0384296151821E-6,300.0123291,300.0123291,-31216.615234375,-31196.88671875,57.047939104583,20.4979373577072,27.085165,0,0,0,40,4449,300.2625,-31206.7509765625,,,,,,,,,,,,,0,,,,0,,,,,,300.0123291,,,,
,33038972.625,300.0058594,-35971.38671875,2.40597271283641E-5,1.07624039740592E-6,1,0.999253354069792,40.0298881530762,1.99719584664994,19.0500002354383,0.000275613504084597,2.68015055449341E-5,0.25,-1.79853548745148E-6,2.40601988664307E-5,-1.78262724381748E-6,300.0058594,300.0058594,-35979.00390625,-35963.76953125,56.7993812354675,20.5009311377041,26.705515,0,0,0,40,4449,300.2423,-35971.38671875,,,,,,,,,,,,,0,,,,0,,,,,,300.0058594,,,,
,33039070.565,300.0078888,-40866.59375,4.07016401320617E-5,1.07113895532838E-6,1,0.999253354069792,40.0298881530762,1.99718608545887,19.0500002354383,0.000466355876569133,4.47335684913843E-5,0.25,-3.09613365629638E-6,4.07024708868277E-5,-3.06924907876664E-6,300.0074768,300.0083008,-40871.3203125,-40861.8671875,57.1198489283522,20.4979360486004,27.464817,0,0,0,40,4449,300.2359,-40866.59375,,,,,,,,,,,,,0,,,,-0.00245,,,,,,300.0078888,,,,
,33039168.14,300.0073242,-45743.654296875,5.35365339232759E-5,1.42821788151516E-6,1,0.999253354069792,40.0298881530762,1.99718192834028,19.0500002354383,0.00060990007589674,7.91319811764639E-5,0.25,-2.2780672160675E-6,5.35364483669967E-5,-2.24279748287808E-6,300.0073242,300.0073242,-45753.671875,-45733.63671875,56.7665528376599,20.4987108518897,26.705515,0,0,0,40,4449,300.23335,-45743.654296875,,,,,,,,,,,,,0,,,,-0.0049,,,,,,300.0073242,,,,
,33039267.275,300.0143127,-50701.04296875,6.7532743902227E-5,1.48109167967818E-6,1,0.999253354069792,40.0298881530762,1.99696204116027,19.0500002354383,0.000766021135265511,0.000118543964295188,0.25,-1.21675448590914E-6,6.75315332296982E-5,-1.17236428839897E-6,300.0143127,300.0143127,-50711.09765625,-50690.98828125,56.8236117195637,20.5034302554633,27.464817,0,0,0,40,4449,300.23145,-50701.04296875,,,,,,,,,,,,,0,,,,0.00245,,,,,,300.0143127,,,,
,33039364.78,300.0126648,-55573.625,8.57750328878695E-5,1.72626043448093E-6,1,0.999253354069792,40.0298881530762,1.99727130055182,19.0500002354383,0.000972726882145643,0.000152664082230897,0.25,-1.36178994599528E-6,8.57733842118569E-5,-1.30547671296082E-6,300.0126648,300.0126648,-55578.6953125,-55568.5546875,56.6477453027368,20.5046107429782,27.464817,0,0,0,40,4449,300.21565,-55573.625,,,,,,,,,,,,,0,,,,0,,,,,,300.0126648,,,,
,33039462.265,300.0083618,-60445.4609375,9.76919130154309E-5,2.12387527659934E-6,1,0.999253354069792,40.0298881530762,1.99733152497443,19.0500002354383,0.00110574433801521,0.000186331189206819,0.25,-4.49892398525563E-7,9.76893341949438E-5,-3.85861376923676E-7,300.0083618,300.0083618,-60455.2421875,-60435.6796875,56.8853603725829,20.4985394404215,27.464817,0,0,0,40,4449,300.20445,-60445.4609375,,,,,,,,,,,,,0,,,,0,,,,,,300.0083618,,,,
,33039560.655,300.0106812,-65363.361328125,0.000112569077100147,1.41964772543575E-6,1,0.999253354069792,40.0298881530762,1.99729299699377,19.0500002354383,0.00127917138087585,0.000185493669674706,0.25,-3.10104902460361E-6,0.000112567793978802,-3.02727857159634E-6,300.0106812,300.0106812,-65373.3515625,-65353.37109375,57.0096393071407,20.4975068906672,27.464817,0,0,0,40,4449,300.19755,-65363.361328125,,,,,,,,,,,,,0,,,,0,,,,,,300.0106812,,,,
,33039658.7,300.0139771,-70260.36328125,0.000129657370706938,1.791989184033E-6,1,0.999253354069792,40.0298881530762,1.99710683493384,19.0500002354383,0.00147111263800319,0.000225807885736995,0.25,-2.49508856856702E-6,0.000129655179566519,-2.41024942804762E-6,300.0139771,300.0139771,-70270.3203125,-70250.40625,56.7642079521022,20.5001753433334,27.085165,0,0,0,40,4449,300.17995,-70260.36328125,,,,,,,,,,,,,0,,,,-0.0049,,,,,,300.0139771,,,,
,33039757.525,300.0137024,-75199.8046875,0.000145357216532461,2.39522750780846E-6,1,0.999253354069792,40.0298881530762,1.9971893201782,19.0500002354383,0.00164469388582541,0.000279808375336129,0.25,-4.40718010195179E-7,0.00014535323077989,-3.45790537210508E-7,300.0137024,300.0137024,-75207.1953125,-75192.4140625,56.7470121246791,20.4998054003539,26.705515,0,0,0,40,4449,300.1691,-75199.8046875,,,,,,,,,,,,,0,,,,0,,,,,,300.0137024,,,,
,33039853.685,300.0114746,-80006.9296875,0.000160535150578391,2.02067624622251E-6,1,0.999253354069792,40.0298881530762,1.99726717247999,19.0500002354383,0.00182454040547763,0.000262613745640775,0.25,-4.59147603252353E-6,0.00016053344932028,-4.48664199609388E-6,300.0114746,300.0114746,-80014.4140625,-79999.4453125,56.8353361473522,20.5008962825838,26.705515,0,0,0,40,4449,300.1598,-80006.9296875,,,,,,,,,,,,,0,,,,0,,,,,,300.0114746,,,,
,33039951.07,300.0163574,-84874.796875,0.000177758914651824,1.96155174763567E-6,1,0.999253354069792,40.0298881530762,1.99746443547294,19.0500002354383,0.00201364905185111,0.000330274108886166,0.25,-1.59537014784305E-6,0.000177754735515871,-1.47953046398619E-6,300.0155334,300.0171814,-84882.4296875,-84867.1640625,56.9033378285253,20.5014035974639,27.464817,0,0,0,40,4449,300.1455,-84874.796875,,,,,,,,,,,,,0,,,,-0.0049,,,,,,300.0163574,,,,
,33040045.175,300.0184631,-89576.36328125,0.000191764646265764,2.35418028883805E-6,1,0.999253354069792,40.0298881530762,1.99736340474776,19.0500002354383,0.00217001029851974,0.000368923078743114,0.25,-6.02986121394418E-7,0.000191759407710027,-4.78200908747379E-7,300.0184631,300.0184631,-89583.90625,-89568.8203125,56.7688977232175,20.5038070427305,27.464817,0,0,0,40,4449,300.1346,-89576.36328125,,,,,,,,,,,,,0,,,,-0.0049,,,,,,300.0184631,,,,
,33040156.735,300.0028992,-85874.58203125,0.000177942542587419,1.99871440164295E-6,1,0.999253354069792,40.0298881530762,1.99730135162628,19.0500002354383,0.00201540186157699,0.000331578166417565,0.25,-1.50959173908029E-6,0.000177938390144453,-1.3936598216779E-6,300.0028992,300.0028992,-85879.5625,-85869.6015625,56.9682129956214,20.5055881190665,27.085165,0,0,0,40,4449,300.13185,-85874.58203125,,,,,,,,,,,,,0,,,,-0.00245,,,,,,300.0028992,,,,
,33040251.515,299.9997253,-81137.86328125,0.000167573753074551,2.19616288475171E-6,1,0.999253354069792,40.0298881530762,1.99728077157137,19.0500002354383,0.00189477932674929,0.000330526055045468,0.25,1.93896464901773E-7,0.00016756879735797,3.0316243991844E-7,299.9997253,299.9997253,-81142.9140625,-81132.8125,56.8064158921406,20.4972035423566,27.085165,0,0,0,40,4449,300.1285,-81137.86328125,,,,,,,,,,,,,0,,,,-0.0049,,,,,,299.9997253,,,,
,33040347.615,299.9885559,-76334.625,0.000152275317956325,2.72472739106856E-6,1,0.999253354069792,40.0298881530762,1.99731934204213,19.0500002354383,0.00172818896169717,0.000263653387227919,0.25,-3.06924148183003E-6,0.000152272984228746,-2.96974407454522E-6,299.9885559,299.9885559,-76339.5390625,-76329.7109375,56.7345060683714,20.4980147710008,27.085165,0,0,0,40,4449,300.1512,-76334.625,,,,,,,,,,,,,0,,,,0.0049,,,,,,299.9885559,,,,
,33040446.295,299.9910889,-71402.45703125,0.000134927886355865,1.91978023466336E-6,1,0.999253354069792,40.0298881530762,1.99718093813539,19.0500002354383,0.00153049753929107,0.00023771212335006,0.25,-2.35626620315179E-6,0.000134925561203325,-2.26800395192402E-6,299.9910889,299.9910889,-71412.6328125,-71392.28125,56.709493955756,20.50393716145,27.085165,0,0,0,40,4449,300.15405,-71402.45703125,,,,,,,,,,,,,0,,,,0.00245,,,,,,299.9910889,,,,
,33040543.515,299.9794006,-66542.53125,0.00011676742001353,1.58787844881437E-6,1,0.999253354069792,40.0298881530762,1.99733661947759,19.0500002354383,0.00132736468897168,0.000189780801573117,0.25,-3.4496953876673E-6,0.000116766373576965,-3.37318457969024E-6,299.9794006,299.9794006,-66555,-66530.0625,56.7118388413137,20.500102123197,27.085165,0,0,0,40,4449,300.169,-66542.53125,,,,,,,,,,,,,0,,,,0,,,,,,299.9794006,,,,
,33040641.875,299.9906006,-61627.54296875,0.000101768886282766,1.47936465783483E-6,1,0.999253354069792,40.0298881530762,1.99695524347489,19.0500002354383,0.00115627349095704,0.000167582024027751,0.25,-2.81136632324604E-6,0.000101767800781561,-2.74460952342384E-6,299.9906006,299.9906006,-61632.09765625,-61622.98828125,56.8525319747752,20.5037387201417,27.085165,0,0,0,40,4449,300.182,-61627.54296875,,,,,,,,,,,,,0,,,,-0.0049,,,,,,299.9906006,,,,
,33040739.83,299.9850464,-56733.193359375,8.57863353284109E-5,1.71404933015618E-6,1,0.999253354069792,40.0298881530762,1.99736452896021,19.0500002354383,0.000971823228629534,0.000158902574952612,0.25,-8.12752707139539E-7,8.57844121981227E-5,-7.56461234590019E-7,299.9850464,299.9850464,-56735.69140625,-56730.6953125,56.6117903908521,20.5007885060474,27.464817,0,0,0,40,4449,300.199,-56733.193359375,,,,,,,,,,,,,0,,,,0,,,,,,299.9850464,,,,
,33040837.235,299.9920349,-51863.3359375,7.32113337677921E-5,1.50166612869299E-6,1,0.999253354069792,40.0298881530762,1.99698196768014,19.0500002354383,0.000833068615985555,0.000113351075292105,0.25,-2.65992156732096E-6,7.32109608738067E-5,-2.6117675161736E-6,299.9920349,299.9920349,-51872.984375,-51853.6875,57.0635716749676,20.5027034156862,27.085165,0,0,0,40,4449,300.1955,-51863.3359375,,,,,,,,,,,,,0,,,,0.00245,,,,,,299.9920349,,,,
,33040934.18,299.9885559,-47018.7265625,5.71915678789371E-5,1.65849908713136E-6,1,0.999253354069792,40.0298881530762,1.99686542644384,19.0500002354383,0.000648657776841699,0.000100585748451102,0.25,-1.01289531560089E-6,5.71905811579081E-5,-9.75264285398858E-7,299.9885559,299.9885559,-47026.21875,-47011.234375,56.9049010855637,20.5021790674159,27.085165,0,0,0,40,4449,300.184,-47018.7265625,,,,,,,,,,,,,0,,,,-0.00245,,,,,,299.9885559,,,,
,33041031.605,299.9855042,-42148.673828125,4.29112893683542E-5,1.42029893715107E-6,1,0.999253354069792,40.0298881530762,1.99688101644854,19.0500002354383,0.000486970083921575,7.38932607978691E-5,0.25,-8.99533290969697E-7,4.29106434983378E-5,-8.71265504897711E-7,299.9855042,299.9855042,-42153.84375,-42143.50390625,56.9095908566791,20.5028772650231,26.705515,0,0,0,40,4449,300.2105,-42148.673828125,,,,,,,,,,,,,0,,,,0,,,,,,299.9855042,,,,
,33041129.355,299.9885864,-37263.71875,2.79884196736576E-5,1.47516389263179E-6,1,0.999253354069792,40.0298881530762,1.99686972030648,19.0500002354383,0.000318970850885428,4.03940291808829E-5,0.25,-1.2767152255811E-6,2.79884485807178E-5,-1.25823824992909E-6,299.9885864,299.9885864,-37270.95703125,-37256.48046875,56.7946914643522,20.5027136282538,27.464817,0,0,0,40,4449,300.2231,-37263.71875,,,,,,,,,,,,,0,,,,-0.00245,,,,,,299.9885864,,,,
,33041226.235,299.9872131,-32424.048828125,1.38145933742117E-5,9.73274664798706E-7,1,0.999253354069792,40.0298881530762,1.99695127504633,19.0500002354383,0.000156509975811413,2.53328047064806E-5,0.25,-1.53128646747362E-7,1.38142932599064E-5,-1.44012726108866E-7,299.9872131,299.9872131,-32434.02734375,-32414.0703125,56.6274229612368,20.5015592905034,26.705515,0,0,0,40,4449,300.22005,-32424.048828125,,,,,,,,,,,,,0,,,,0.00245,,,,,,299.9872131,,,,
,33041322.45,299.9866943,-27614.7099609375,-1.30935617724439E-6,1.04101734035189E-6,1,0.999253354069792,40.0298881530762,1.99697117766041,19.0500002354383,-1.31693532702113E-5,-1.20105529879488E-5,0.25,-8.35301181987152E-7,-1.30876665935274E-6,-8.3614131101067E-7,299.9866943,299.9866943,-27617.373046875,-27612.046875,56.7556100383906,20.5028520439058,27.085165,0,0,0,40,4449,300.24075,-27614.7099609375,,,,,,,,,,,,,0,,,,0.0049,,,,,,299.9866943,,,,
,33041418.58,299.9888611,-22811.873046875,-1.47914992272081E-5,1.02059492969375E-6,1,0.999253354069792,40.0298881530762,1.99707048174313,19.0500002354383,-0.000165687758540559,-3.8088762524145E-5,0.25,-8.054933403747E-7,-1.47905349384221E-5,-8.15244137750158E-7,299.9888611,299.9888611,-22819.267578125,-22804.478515625,56.9588334533906,20.5010089374499,27.464817,0,0,0,40,4449,300.2538,-22811.873046875,,,,,,,,,,,,,0,,,,0,,,,,,299.9888611,,,,
,33041514.375,299.9931335,-18022.1328125,-2.76888222770654E-5,7.87537788820172E-7,1,0.999253354069792,40.0298881530762,1.9971992296747,19.0500002354383,-0.000309915413943325,-7.28130238984854E-5,0.25,-1.64122842495302E-6,-2.76869222268655E-5,-1.65949428993035E-6,299.9931335,299.9931335,-18032.037109375,-18012.228515625,56.7595181809868,20.4987005413484,26.705515,0,0,0,40,4449,300.25765,-18022.1328125,,,,,,,,,,,,,0,,,,0.0049,,,,,,299.9931335,,,,
,33041609.155,299.9908142,-13284.0654296875,-3.91537957321586E-5,5.55696864254394E-7,1,0.999253354069792,40.0298881530762,1.99735427157504,19.0500002354383,-0.000441031371903714,-8.70495527496784E-5,0.25,-9.13111278260875E-7,-3.91520407111125E-5,-9.3900457709443E-7,299.9908142,299.9908142,-13289.2197265625,-13278.9111328125,56.6782288149868,20.4962711559855,27.464817,0,0,0,40,4449,300.26215,-13284.0654296875,,,,,,,,,,,,,0,,,,-0.00245,,,,,,299.9908142,,,,
,33041704.265,299.9940186,-8530.9453125,-5.00850692074058E-5,5.40740969207092E-7,1,0.999253354069792,40.0298881530762,1.99709933385792,19.0500002354383,-0.000565971495123709,-0.000100498515764509,0.25,-2.09375279492676E-7,-5.00834504204194E-5,-2.42554101974284E-7,299.9940186,299.9940186,-8540.8828125,-8521.0078125,56.8087607776983,20.4951167022987,26.705515,0,0,0,40,4449,300.2578,-8530.9453125,,,,,,,,,,,,,0,,,,-0.00245,,,,,,299.9940186,,,,
,33041800.85,299.9882202,-3702.96826171875,-5.11857518562222E-5,4.8828479088827E-7,1,0.999253354069792,40.0298881530762,1.99706076089551,19.0500002354383,-0.000578816464591141,-0.000100294980953897,0.25,-8.1229869550128E-10,-5.11842473138594E-5,-3.47496536021834E-8,299.9882202,299.9882202,-3708.048828125,-3697.8876953125,56.4804767996214,20.4936700598626,26.705515,0,0,0,40,4449,300.2766,-3702.96826171875,,,,,,,,,,,,,0,,,,-0.00245,,,,,,299.9882202,,,,
,33041892.31,299.9931946,867.636932373047,3.5422504410896E-5,3.73469978933803E-7,1,0.999253354069792,40.0298881530762,1.99709371300264,19.0500002354383,0.000399451100086651,7.58637087793998E-5,0.25,5.71340053177552E-7,3.54210775890205E-5,5.94817133222298E-7,299.9931946,299.9931946,859.99658203125,875.277282714844,56.8900501436983,20.4963946519498,27.085165,0,0,0,40,4449,300.2817,867.636932373047,,,,,,,,,,,,,0,,,,0,,,,,,299.9931946,,,,
,33041986.515,299.9959717,5575.30590820313,5.25657512380593E-5,5.14859880859058E-7,1,0.999253354069792,40.0298881530762,1.99719576862236,19.0500002354383,0.000593752240072119,0.000107090067656025,0.25,3.62015683828642E-7,5.2563953024665E-5,3.96846967677425E-7,299.9959717,299.9959717,5570.54736328125,5580.064453125,56.8118872917752,20.492105625841,27.085165,0,0,0,40,4449,300.2813,5575.30590820313,,,,,,,,,,,,,0,,,,0,,,,,,299.9959717,,,,
,33042085.535,299.9990234,10526.150390625,4.6385778538055E-5,6.75746874239963E-7,1,0.999253354069792,40.0298881530762,1.9971139615236,19.0500002354383,0.00052369999645682,9.58025432517879E-5,0.25,4.35001550142472E-7,4.63841124798937E-5,4.65710060539261E-7,299.9988708,299.999176,10519.044921875,10533.255859375,56.597721077506,20.4951551755849,26.705515,0,0,0,40,4449,300.27445,10526.150390625,,,,,,,,,,,,,0,,,,0,,,,,,299.9990234,,,,
,33042184.875,300.000946,15491.3852539062,3.46113557592381E-5,7.3815232483068E-7,1,0.999253354069792,40.0298881530762,1.99713301596957,19.0500002354383,0.000390168366371566,7.4952598843429E-5,0.25,6.31240078132362E-7,3.46099093949378E-5,6.54123462718863E-7,300.000946,300.000946,15486.345703125,15496.4248046875,56.658688102006,20.4926908284603,27.464817,0,0,0,40,4449,300.27815,15491.3852539062,,,,,,,,,,,,,0,,,,0,,,,,,300.000946,,,,
,33042281.09,300.0021667,20298.775390625,2.30122149838485E-5,6.66312728110464E-7,1,0.999253354069792,40.0298881530762,1.99709297740651,19.0500002354383,0.000259929196763284,4.68256089188567E-5,0.25,1.53753748793866E-7,2.30114296588179E-5,1.68962122014784E-7,300.0021667,300.0021667,20288.73046875,20308.8203125,56.7329428113329,20.4916688222201,27.844467,0,0,0,40,4449,300.2768,20298.775390625,,,,,,,,,,,,,0,,,,-0.00245,,,,,,300.0021667,,,,
,33042377.86,300.005249,25136.1484375,6.71075944586841E-6,9.67938480174597E-7,1,0.999253354069792,40.0298881530762,1.997217106135,19.0500002354383,7.28540574510568E-5,3.06843152793129E-5,0.25,1.55057161997323E-6,6.70953569303658E-6,1.55495741257455E-6,300.005249,300.005249,25126.072265625,25146.224609375,56.7274714116983,20.4907542178718,27.085165,0,0,0,40,4449,300.27995,25136.1484375,,,,,,,,,,,,,0,,,,0,,,,,,300.005249,,,,
,33042476.595,300.0084229,30069.3623046875,-7.30678813487371E-6,6.83970983893849E-7,1,0.999253354069792,40.0298881530762,1.99728922632147,19.0500002354383,-8.43144086158528E-5,-4.62714933766651E-6,0.25,8.56805808732826E-7,-7.30713556699633E-6,8.51959430889192E-7,300.0084229,300.0084229,30064.65625,30074.068359375,56.5406621956021,20.4902238435932,27.464817,0,0,0,40,4449,300.2648,30069.3623046875,,,,,,,,,,,,,0,,,,0.0049,,,,,,300.0084229,,,,
,33042574.665,300.0126648,34971.94140625,-2.09775183216261E-5,9.6219346625212E-7,1,0.999253354069792,40.0298881530762,1.99721367327371,19.0500002354383,-0.000241174690608516,-1.83635300645785E-5,0.25,2.01067604842734E-6,-2.09782161410076E-5,1.99678991865376E-6,300.0126648,300.0126648,34967.0234375,34976.859375,56.6930797568522,20.4890349696709,27.085165,0,0,0,40,4449,300.25815,34971.94140625,,,,,,,,,,,,,0,,,,-0.0049,,,,,,300.0126648,,,,
,33042674.775,300.0089722,39977.064453125,-3.54776755445186E-5,1.08742917864595E-6,1,0.999253354069792,40.0298881530762,1.99716683681962,19.0500002354383,-0.000402659260344145,-6.11390472110513E-5,0.25,7.40337762658789E-7,-3.5477108841243E-5,7.16957686811183E-7,300.0089722,300.0089722,39969.83984375,39984.2890625,56.8283014906791,20.4896794402241,27.464817,0,0,0,40,4449,300.2424,39977.064453125,,,,,,,,,,,,,0,,,,0,,,,,,300.0089722,,,,
,33042774.585,300.0102844,44964.79296875,-5.28078223811071E-5,1.54522921695949E-6,1,0.999253354069792,40.0298881530762,1.99729333836397,19.0500002354383,-0.000602623450046094,-7.23272356849999E-5,0.25,2.75387883087292E-6,-5.28080654264892E-5,2.71906846752829E-6,300.0102844,300.0102844,44962.3984375,44967.1875,56.6962062709291,20.4894551016932,27.464817,0,0,0,40,4449,300.2399,44964.79296875,,,,,,,,,,,,,0,,,,0,,,,,,300.0102844,,,,
,33042873.36,300.0092468,49902.904296875,-6.8049218826256E-5,1.62565277364391E-6,1,0.999253354069792,40.0298881530762,1.99728016716803,19.0500002354383,-0.000775235177500851,-0.000100778202495252,0.25,2.87872689811248E-6,-6.80490962910093E-5,2.83393952298494E-6,300.0092468,300.0092468,49890.51171875,49915.296875,56.7579549239483,20.4879261033328,26.705515,0,0,0,40,4449,300.2284,49902.904296875,,,,,,,,,,,,,0,,,,-0.00245,,,,,,300.0092468,,,,
,33042972.34,300.0122375,54847.501953125,-8.21982051953257E-5,1.54293088182716E-6,1,0.999253354069792,40.0298881530762,1.99733017155047,19.0500002354383,-0.00093569223837054,-0.000126089189048094,0.25,3.09223677746141E-6,-8.21977986342521E-5,3.0382108141978E-6,300.0122375,300.0122375,54837.54296875,54857.4609375,56.5453519667175,20.4872806187803,27.085165,0,0,0,40,4449,300.2223,54847.501953125,,,,,,,,,,,,,0,,,,0,,,,,,300.0122375,,,,
,33043071.985,300.0162354,59827.830078125,-9.69026766854511E-5,1.73182662976548E-6,1,0.999253354069792,40.0298881530762,1.99688658112431,19.0500002354383,-0.00110201610578878,-0.00015339632745912,0.25,3.22237600163658E-6,-9.69019099552419E-5,3.15877012827815E-6,300.0162354,300.0162354,59820.37890625,59835.28125,56.6633778731214,20.4945429432073,27.464817,0,0,0,40,4449,300.20465,59827.830078125,,,,,,,,,,,,,0,,,,0,,,,,,300.0162354,,,,
,33043170.795,300.0116882,64768.296875,-0.000116000986462999,2.09491732678136E-6,1,0.999253354069792,40.0298881530762,1.99678724894051,19.0500002354383,-0.00131854217339399,-0.000187113414170569,0.25,3.54842282366217E-6,-0.000115999890205424,3.47237978143461E-6,300.0116882,300.0116882,64763.28125,64773.3125,56.5101786833521,20.4952412967876,27.464817,0,0,0,40,4449,300.1916,64768.296875,,,,,,,,,,,,,0,,,,-0.0049,,,,,,300.0116882,,,,
,33043270.04,300.0128479,69728.67578125,-0.000131850176647725,2.00846270014838E-6,1,0.999253354069792,40.0298881530762,1.99718250295404,19.0500002354383,-0.00149658041363296,-0.00022655456090906,0.25,2.80969880257594E-6,-0.000131848131262445,2.72340756771467E-6,300.0128479,300.0128479,69721.046875,69736.3046875,56.628204589756,20.4953365865457,27.464817,0,0,0,40,4449,300.1866,69728.67578125,,,,,,,,,,,,,0,,,,0,,,,,,300.0128479,,,,
,33043370.165,300.0144348,74733.81640625,-0.000147466218040153,2.28839340900563E-6,1,0.999253354069792,40.0298881530762,1.99721742518876,19.0500002354383,-0.00167363421198276,-0.000254694624293816,0.25,3.02711854954023E-6,-0.000147463854625879,2.93072858325344E-6,300.0144348,300.0144348,74723.890625,74743.7421875,56.6117903908521,20.4883850672311,27.464817,0,0,0,40,4449,300.17505,74733.81640625,,,,,,,,,,,,,0,,,,0,,,,,,300.0144348,,,,
,33043470.585,300.0163574,79752.18359375,-0.000162253002617344,2.20763394521161E-6,1,0.999253354069792,40.0298881530762,1.99713420995023,19.0500002354383,-0.0018447821815903,-0.000260585852344432,0.25,5.06694462281047E-6,-0.000162251532176787,4.96096546143799E-6,300.0163574,300.0163574,79747.2265625,79757.140625,56.3530713509867,20.4898320636958,27.844467,0,0,0,40,4449,300.1525,79752.18359375,,,,,,,,,,,,,0,,,,0.00245,,,,,,300.0163574,,,,
,33043568.78,300.0063782,84663.35546875,-0.000175729559769645,2.225876391619E-6,1,0.999253354069792,40.0298881530762,1.99730482559825,19.0500002354383,-0.00199193505316583,-0.000318250183283957,0.25,2.30474460374969E-6,-0.000175725964931137,2.19020201276982E-6,300.0063782,300.0063782,84650.9453125,84675.765625,56.7438856106022,20.4912649978263,27.844467,0,0,0,40,4449,300.14895,84663.35546875,,,,,,,,,,,,,0,,,,-0.0049,,,,,,300.0063782,,,,
,33043662.525,300.0145874,89349.19140625,-0.000195132710075654,2.97470882071478E-6,1,0.999253354069792,40.0298881530762,1.99720949705518,19.0500002354383,-0.00221084610312293,-0.000358723440057013,0.25,2.08600403186149E-6,-0.000195128364464711,1.95898138427781E-6,300.0145874,300.0145874,89344.3984375,89353.984375,56.6657227586791,20.4914108045055,27.464817,0,0,0,40,4449,300.1444,89349.19140625,,,,,,,,,,,,,0,,,,0.00245,,,,,,300.0145874,,,,
,33043774.54,300.0047302,86078.67578125,-0.000182586323632106,1.87385095404052E-6,1,0.999253354069792,40.0298881530762,1.99711660071587,19.0500002354383,-0.00207222353054477,-0.000314756474866618,0.25,3.79903921212938E-6,-0.000182583516861629,3.68002641844994E-6,300.0047302,300.0047302,86068.6015625,86088.75,56.5969394489868,20.4905611974971,27.085165,0,0,0,40,4449,300.1393,86078.67578125,,,,,,,,,,,,,0,,,,0,,,,,,300.0047302,,,,
,33043871.84,299.9951172,81215.171875,-0.000165633224485889,2.69509931177807E-6,1,0.999253354069792,40.0298881530762,1.99708807008683,19.0500002354383,-0.00188063946203809,-0.000280641522369786,0.25,3.87850924901121E-6,-0.000165631008272836,3.77040153403692E-6,299.9945984,299.995636,81209.96875,81220.375,56.6829185861022,20.4912139349898,27.464817,0,0,0,40,4449,300.1463,81215.171875,,,,,,,,,,,,,0,,,,0.0049,,,,,,299.9951172,,,,
,33043974.07,299.9917908,76103.64453125,-0.00014954051077374,2.24257899793459E-6,1,0.999253354069792,40.0298881530762,1.99711976795463,19.0500002354383,-0.00169726272332901,-0.000257315302683853,0.25,3.15368489281392E-6,-0.000149538292468722,3.05596674932362E-6,299.9917908,299.9917908,76095.8671875,76111.421875,56.6250780756791,20.4905601004986,27.464817,0,0,0,40,4449,300.15765,76103.64453125,,,,,,,,,,,,,0,,,,-0.00245,,,,,,299.9917908,,,,
,33044072.565,299.9924011,71180.16796875,-0.000135469238673864,2.21598811085429E-6,1,0.999253354069792,40.0298881530762,1.99712441660771,19.0500002354383,-0.00153598778921276,-0.000242173238462568,0.25,2.05499982398412E-6,-0.000135466694458701,1.96638888934826E-6,299.9924011,299.9924011,71177.609375,71182.7265625,56.7438856106022,20.4924507865331,27.464817,0,0,0,40,4449,300.15875,71180.16796875,,,,,,,,,,,,,0,,,,-0.0049,,,,,,299.9924011,,,,
,33044170.775,299.98776245,66271.95703125,-0.000119559381269713,1.68659807354843E-6,1,0.999253354069792,40.0298881530762,1.99729897490496,19.0500002354383,-0.00135941682920919,-0.000192357624300199,0.25,3.70525686992913E-6,-0.00011955838687731,3.62690574774036E-6,299.9874573,299.9880676,66264.609375,66279.3046875,56.7688977232175,20.4903274286866,27.464817,0,0,0,40,4449,300.17025,66271.95703125,,,,,,,,,,,,,0,,,,0.00245,,,,,,299.98776245,,,,
,33044267.935,299.985321,61413.427734375,-0.000104892672287629,1.73505560393035E-6,1,0.999253354069792,40.0298881530762,1.99730862475164,19.0500002354383,-0.00119026123539233,-0.000182598965514384,0.25,2.02726591223625E-6,-0.000104891002816198,1.95848128992319E-6,299.985321,299.985321,61405.76171875,61421.09375,56.7485753817175,20.4916933836756,27.085165,0,0,0,40,4449,300.1801,61413.427734375,,,,,,,,,,,,,0,,,,-0.00245,,,,,,299.985321,,,,
,33044363.6,299.9923096,56630.64453125,-8.7321737595457E-5,1.73350836370641E-6,1,0.999253354069792,40.0298881530762,1.9973969506062,19.0500002354383,-0.000996449582433606,-0.000120089509303277,0.25,4.51072446447728E-6,-8.73221730629421E-5,4.4533135769197E-6,299.9923096,299.9923096,56628.23046875,56633.05859375,56.7431039820829,20.4885580434884,27.844467,0,0,0,40,4449,300.1818,56630.64453125,,,,,,,,,,,,,0,,,,0.0049,,,,,,299.9923096,,,,
,33044460.02,299.9911194,51810.7890625,-7.22103495186275E-5,1.81311717064076E-6,1,0.999253354069792,40.0298881530762,1.99726009460226,19.0500002354383,-0.000825060602846724,-9.29252998472785E-5,0.25,4.29393839969107E-6,-7.22110810007119E-5,4.24639385216335E-6,299.9911194,299.9911194,51805.71484375,51815.86328125,56.6751023009098,20.4926864541205,27.085165,0,0,0,40,4449,300.19515,51810.7890625,,,,,,,,,,,,,0,,,,0.00245,,,,,,299.9911194,,,,
,33044560.195,299.98828125,46802.791015625,-5.68166212293559E-5,1.29266380751069E-6,1,0.999253354069792,40.0298881530762,1.99739633381527,19.0500002354383,-0.000646805720368064,-8.70399362881991E-5,0.25,2.14787299269306E-6,-5.68163921631558E-5,2.11045658251506E-6,299.9880981,299.9884644,46792.8515625,46812.73046875,56.7876568076791,20.4898295466551,27.844467,0,0,0,40,4449,300.20295,46802.791015625,,,,,,,,,,,,,0,,,,0,,,,,,299.98828125,,,,
,33044658.735,299.9942017,41879.9765625,-4.34059366444445E-5,1.64212291945286E-6,1,0.999253354069792,40.0298881530762,1.99745511263708,19.0500002354383,-0.00049629348602546,-5.41311859701565E-5,0.25,2.73428409217065E-6,-4.34064704364249E-5,2.7056355399084E-6,299.9942017,299.9942017,41870.046875,41889.90625,56.6610329875637,20.4863504153486,27.464817,0,0,0,40,4449,300.2134,41879.9765625,,,,,,,,,,,,,0,,,,0,,,,,,299.9942017,,,,
,33044756.485,299.9906616,36992.412109375,-2.8413221514679E-5,1.20948866285551E-6,1,0.999253354069792,40.0298881530762,1.99724513327224,19.0500002354383,-0.000324505709862382,-3.73463863839015E-5,0.25,1.62044005031413E-6,-2.84134623895854E-5,1.60167168075206E-6,299.9906616,299.9906616,36982.421875,37002.40234375,56.8361177758714,20.4918994722078,27.464817,0,0,0,40,4449,300.2193,36992.412109375,,,,,,,,,,,,,0,,,,-0.0049,,,,,,299.9906616,,,,
,33044854.4,299.9833069,32102.9306640625,-1.25143906222718E-5,1.1063637804591E-6,1,0.999253354069792,40.0298881530762,1.99724857049814,19.0500002354383,-0.000143201691597606,-1.48599172959915E-5,0.25,8.54228327294595E-7,-1.25145924290718E-5,8.45949718560611E-7,299.9833069,299.9833069,32095.646484375,32110.21484375,56.7477937531983,20.4939509021387,27.085165,0,0,0,40,4449,300.23775,32102.9306640625,,,,,,,,,,,,,0,,,,0.0049,,,,,,299.9833069,,,,
,33044952.225,299.9851227,27213.0185546875,1.78735836226225E-6,7.85753552500724E-7,1,0.999253354069792,40.0298881530762,1.99719690494623,19.0500002354383,1.76113147372153E-5,1.85190785167056E-5,0.25,1.32789016434348E-6,1.78642976899676E-6,1.32903170648826E-6,299.9850159,299.9852295,27207.841796875,27218.1953125,56.6962062709291,20.4924859166583,27.844467,0,0,0,40,4449,300.2414,27213.0185546875,,,,,,,,,,,,,0,,,,-0.00245,,,,,,299.9851227,,,,
,33045049.855,299.9862061,22330.1962890625,1.50872236994639E-5,9.3593797243311E-7,1,0.999253354069792,40.0298881530762,1.99732096203199,19.0500002354383,0.000168835486735422,3.99232111475143E-5,0.25,9.16055134789485E-7,1.50861789836952E-5,9.25999322693551E-7,299.9862061,299.9862061,22325.068359375,22335.32421875,56.7798405224868,20.4950822380719,27.464817,0,0,0,40,4449,300.2501,22330.1962890625,,,,,,,,,,,,,0,,,,0,,,,,,299.9862061,,,,
,33045147.125,299.9897461,17470.0146484375,2.90664592510563E-5,6.20369723676371E-7,1,0.999253354069792,40.0298881530762,1.99719710137228,19.0500002354383,0.000327320522433516,6.4974255360044E-5,0.25,7.09396977586956E-7,2.90651383253059E-5,7.28603526178435E-7,299.9897461,299.9897461,17457.41015625,17482.619140625,56.8189219484483,20.4946597772261,27.085165,0,0,0,40,4449,300.25865,17470.0146484375,,,,,,,,,,,,,0,,,,-0.00245,,,,,,299.9897461,,,,
,33045242.93,299.9858398,12680.1918945313,4.14291800422694E-5,6.05976153230773E-7,1,0.999253354069792,40.0298881530762,1.9972853054344,19.0500002354383,0.000468400920049296,8.19774540583684E-5,0.25,7.06459329702976E-8,4.14279230251816E-5,9.80731189411536E-8,299.9858398,299.9858398,12675.173828125,12685.2099609375,56.9596150819099,20.4943675038081,27.085165,0,0,0,40,4449,300.26425,12680.1918945313,,,,,,,,,,,,,0,,,,0,,,,,,299.9858398,,,,
,33045341.61,299.98527525,7749.78662109375,5.11241511065474E-5,4.3835418126839E-7,1,0.999253354069792,40.0298881530762,1.99730927585455,19.0500002354383,0.000576869570539367,0.000107799338453269,0.25,6.73995920469774E-7,5.11222097731689E-5,7.07850211206332E-7,299.9849548,299.9855957,7742.392578125,7757.1806640625,56.9369478548522,20.4952988143261,27.844467,0,0,0,40,4449,300.2869,7749.78662109375,,,,,,,,,,,,,0,,,,-0.0049,,,,,,299.98527525,,,,
,33045439.39,299.9923096,2861.59338378906,5.04688125761752E-5,3.81483708438832E-7,1,0.999253354069792,40.0298881530762,1.99729400345503,19.0500002354383,0.00057016109069903,0.000102431399475761,0.25,3.1294546961485E-7,5.04671145460594E-5,3.46400206615337E-7,299.9923096,299.9923096,2854.16479492187,2869.02197265625,57.0995265868522,20.4960996470125,27.464817,0,0,0,40,4449,300.29135,2861.59338378906,,,,,,,,,,,,,0,,,,0.00245,,,,,,299.9923096,,,,
,33045497.68,299.9891968,-0.289251700043678,6.94919943721711E-6,3.37101442942917E-7,1,0.999253354069792,40.0298881530762,1.99737099035369,19.0500002354383,8.02514711646636E-5,4.05371014950492E-6,0.25,-8.45594912240907E-7,6.94955570999506E-6,-8.4096072595797E-7,299.9891968,299.9891968,-0.304475486278534,-0.274027913808823,56.8658196596022,20.4954055522861,27.085165,0,0,0,40,4417,300.2884,-0.289251700043678,,,,,,,,,,,,,0,,,,-0.00245,,,,,,299.9891968,,,,