File: data/doubleLayers/dl_1-25/ppms/data/DD205_3_HYST_INIT_300K.DAT
[Header]
; VSM Data File (default extension .dat)
; Copyright (c) 2003-2013, Quantum Design, Inc. All rights reserved.
TITLE,
FILEOPENTIME,32434578.53,01/11/2019,5:38 pm
BYAPP,VSM,2.0,2.0
INFO,PPMS VSM Option Release 1.4.10 Build 1,APPNAME
INFO,Quantum Design Linear Motor Servo Controller,MOTOR_MODULE_NAME
INFO,3101-100 M1,MOTOR_HW_VERSION
INFO,MMC1014,MOTOR_SERIAL_NUMBER
INFO,SRV No X-over 01.03.11,MOTOR_SOFTWARE_VERSION
INFO,Quantum Design VSM Detection Module,VSM_MODULE_NAME
INFO,3101-150 F0,VSM_HW_VERSION
INFO,VSM707,VSM_SERIAL_NUMBER
INFO,VSM No X-over 01.02.05 May 20 2008 13:51:47,VSM_SOFTWARE_VERSION
INFO,704,PREAMP_SERIAL_NUMBER
INFO,822,COIL_SERIAL_NUMBER
INFO,0,MOMENT_UNITS
INFO,DD205_4,SAMPLE_MATERIAL
INFO,Double Layer Blue 1.25,SAMPLE_COMMENT
INFO,26.73,SAMPLE_MASS
INFO,,SAMPLE_VOLUME
INFO,,SAMPLE_MOLECULAR_WEIGHT
INFO,,SAMPLE_SIZE
INFO,,SAMPLE_SHAPE
DATATYPE,COMMENT,1
DATATYPE,TIME,2
STARTUPAXIS,X,2
STARTUPAXIS,Y1,5
[Data]
Comment,Time Stamp (sec),Temperature (K),Magnetic Field (Oe),Moment (emu),M. Std. Err. (emu),Transport Action,Averaging Time (sec),Frequency (Hz),Peak Amplitude (mm),Center Position (mm),Coil Signal' (mV),Coil Signal" (mV),Range (mV),M. Quad. Signal (emu),M. Raw' (emu),M. Raw" (emu),Min. Temperature (K),Max. Temperature (K),Min. Field (Oe),Max. Field (Oe),Mass (grams),Motor Lag (deg),Pressure (Torr),VSM Status (code),Motor Status (code),Measure Status (code),Measure Count,PPMS Status (code),System Temp. (K),System Field (Oe),Sample Position (deg),Bridge 1 Resistance (ohms),Bridge 1 Excitation (에),Bridge 2 Resistance (ohms),Bridge 2 Excitation (에),Bridge 3 Resistance (ohms),Bridge 3 Excitation (에),Bridge 4 Resistance (ohms),Bridge 4 Excitation (에),Signal 1 Vin (V),Signal 2 Vin (V),Digital Inputs (code),Drive 1 Iout (mA),Drive 1 Ipower (W),Drive 2 Iout (mA),Drive 2 Ipower (W),Pressure (),Map 20 (),Map 21 (),Map 22 (),Map 23 (),Map 24 (),Map 25 (),Map 26 (),Map 27 (),Map 28 (),Map 29 ()
,32434594.44,300.0076294,0.19790905714035,,,2,,,,19.5600002416968,,,,,,,300.0076294,300.0076294,0.19790905714035,0.19790905714035,,,22.909004,,,,-99999999,4369,300.3777,0.19790905714035,,,,,,,,,,,,,,,,,,,,,,,300.0076294,,,,
,32434730.78,300.0351257,3817.81335449219,4.8132083499699E-5,6.53730336262463E-7,1,0.999253354069792,40.0298881530762,1.97470174720146,19.5499993860722,0.000539508266689953,8.7265743108267E-5,0.25,-5.38849344680698E-7,4.81309458776347E-5,-5.06926089587342E-7,300.0351257,300.0351257,3807.79443359375,3827.83227539063,56.2045619323329,20.5194160381846,22.909004,0,0,0,40,4449,300.3213,3817.81335449219,,,,,,,,,,,,,0,,,,0,,,,,,300.0351257,,,,
,32434814.26,300.0352936,7985.20849609375,4.38672129360091E-5,9.48173642940058E-7,1,0.999253354069792,40.0298881530762,1.97463856781596,19.5499993860722,0.000489862716915273,9.00698271153757E-5,0.25,4.50992786378638E-7,4.38655529460734E-5,4.80042149109946E-7,300.0346375,300.0359497,7977.705078125,7992.7119140625,56.1514111930252,20.5348206591899,22.909004,0,0,0,40,4449,300.2968,7985.20849609375,,,,,,,,,,,,,0,,,,0.00245,,,,,,300.0352936,,,,
,32434896.95,300.0330505,12121.1708984375,3.60302751846512E-5,1.74181294526352E-6,1,0.999253354069792,40.0298881530762,1.97468637544985,19.5499993860722,0.000401745163351023,7.75142987900869E-5,0.25,6.86323495842264E-7,3.60287071165048E-5,7.1015735360308E-7,300.0330505,300.0330505,12116.271484375,12126.0703125,56.8814522299868,20.5313056251216,22.909004,0,0,0,40,4449,300.2862,12121.1708984375,,,,,,,,,,,,,0,,,,0,,,,,,300.0330505,,,,
,32434972.39,300.03237915,15889.4506835938,2.46611266555971E-5,2.29573716015408E-6,1,0.999253354069792,40.0298881530762,1.97438875864078,19.5499993860722,0.000275264653395655,5.11572616271614E-5,0.25,3.00781575639093E-7,2.46601668629016E-5,3.17090155948173E-7,300.032196,300.0325623,15884.4140625,15894.4873046875,56.5492601093137,20.5370060074205,22.909004,0,0,0,40,4449,300.263,15889.4506835938,,,,,,,,,,,,,0,,,,-0.00245,,,,,,300.03237915,,,,
,32435046.26,300.0224609,19580.0380859375,1.55883055913515E-5,1.64871082935632E-6,1,0.999253354069792,40.0298881530762,1.97428082655633,19.5499993860722,0.000174559932646854,2.90213670843616E-5,0.25,-1.06113504665841E-7,1.55879010373509E-5,-9.58025097064903E-8,300.0224609,300.0224609,19572.55859375,19587.517578125,56.6266413327175,20.539965695018,23.288654,0,0,0,40,4449,300.248,19580.0380859375,,,,,,,,,,,,,0,,,,0.00245,,,,,,300.0224609,,,,
,32435123.225,300.0189819,23427.9326171875,6.29098313910562E-6,1.84918066971597E-6,1,0.999253354069792,40.0298881530762,1.97419156373181,19.5499993860722,6.58165709662738E-5,3.84214638829726E-5,0.25,2.34529503474948E-6,6.28924290990923E-6,2.34938090361039E-6,300.0189819,300.0189819,23425.3359375,23430.529296875,56.6227331901214,20.5434838264605,22.909004,0,0,0,40,4449,300.2354,23427.9326171875,,,,,,,,,,,,,0,,,,0,,,,,,300.0189819,,,,
,32435200.225,300.0185547,27276.560546875,-8.1774653332279E-6,1.8339649408471E-6,1,0.999253354069792,40.0298881530762,1.97416851641489,19.5499993860722,-9.25570959169263E-5,-9.51113219327721E-6,0.25,5.66403748176377E-7,-8.17759214929411E-6,5.60987483475503E-7,300.0185547,300.0185547,27274.275390625,27278.845703125,56.7391958394868,20.5432172314942,22.909004,0,0,0,40,4449,300.2337,27276.560546875,,,,,,,,,,,,,0,,,,0,,,,,,300.0185547,,,,
,32435275.875,300.0118408,31059.3154296875,-1.81709359881E-5,2.48668213774051E-6,1,0.999253354069792,40.0298881530762,1.97408839241115,19.5499993860722,-0.00020859383374445,-4.20486875330531E-6,0.25,2.77225312008384E-6,-1.81722209787186E-5,2.76018200368073E-6,300.0118408,300.0118408,31046.84765625,31071.783203125,56.7071490701983,20.5444951477383,23.288654,0,0,0,40,4449,300.22295,31059.3154296875,,,,,,,,,,,,,0,,,,-0.00245,,,,,,300.0118408,,,,
,32435353.02,300.0092468,34915.01953125,-3.15474690884315E-5,1.9259351834132E-6,1,0.999253354069792,40.0298881530762,1.97405891070425,19.5499993860722,-0.000359622770784716,-2.18581315460679E-5,0.25,3.5113239527091E-6,-3.15488437942241E-5,3.49042317731496E-6,300.0092468,300.0092468,34905.03125,34925.0078125,56.5945945634291,20.5445387108298,22.909004,0,0,0,40,4449,300.2166,34915.01953125,,,,,,,,,,,,,0,,,,0,,,,,,300.0092468,,,,
,32435430.08,300.0119019,38765.576171875,-4.0588630167132E-5,2.49966345876566E-6,1,0.999253354069792,40.0298881530762,1.97394840893825,19.5499993860722,-0.000460782194274195,-3.89704508694313E-5,0.25,3.54744224334668E-6,-4.05897554732358E-5,3.52060207610305E-6,300.0119019,300.0119019,38758.015625,38773.13671875,56.7126204698329,20.5434146471618,23.288654,0,0,0,40,4449,300.20505,38765.576171875,,,,,,,,,,,,,0,,,,0.00245,,,,,,300.0119019,,,,
,32435508.55,300.0079041,42686.083984375,-5.45582646873168E-5,2.53374956174312E-6,1,0.999253354069792,40.0298881530762,1.97382198819244,19.5499993860722,-0.000613488084812096,-8.61249397706604E-5,0.25,1.75068597435785E-6,-5.4557799333233E-5,1.7147307881535E-6,300.0079041,300.0079041,42681.0390625,42691.12890625,57.044812590506,20.5441043763968,23.288654,0,0,0,40,4449,300.20685,42686.083984375,,,,,,,,,,,,,0,,,,0,,,,,,300.0079041,,,,
,32435585.24,300.0171814,46522.1015625,-6.79346521762816E-5,3.87211964391189E-6,1,0.999253354069792,40.0298881530762,1.97383204318958,19.5499993860722,-0.000765681952402276,-9.69805244581367E-5,0.25,3.09743677003553E-6,-6.79346556535417E-5,3.05267856390205E-6,300.0171814,300.0171814,46514.44140625,46529.76171875,56.8189219484483,20.5447747216287,23.288654,0,0,0,40,4449,300.21065,46522.1015625,,,,,,,,,,,,,0,,,,-0.00245,,,,,,300.0171814,,,,
,32435661.555,300.0083313,50335.29296875,-7.73733730924198E-5,2.28957701260114E-6,1,0.999253354069792,40.0298881530762,1.9737620840164,19.5499993860722,-0.000868536381326869,-0.000130645948685357,0.25,1.72175851717292E-6,-7.73722171074291E-5,1.67087932127512E-6,300.0083313,300.0083313,50327.7578125,50342.828125,56.8572217458906,20.5450554060558,22.909004,0,0,0,40,4449,300.1972,50335.29296875,,,,,,,,,,,,,0,,,,0.00245,,,,,,300.0083313,,,,
,32435736.545,300.0083618,54083.255859375,-9.16394248963486E-5,2.35646510041062E-6,1,0.999253354069792,40.0298881530762,1.97378287464066,19.5499993860722,-0.00102633008813903,-0.000168339514129329,0.25,8.22630536842555E-7,-9.16372606687252E-5,7.62458603024782E-7,300.0083618,300.0083618,54080.5234375,54085.98828125,56.966649738583,20.5448218277165,22.909004,0,0,0,40,4449,300.19075,54083.255859375,,,,,,,,,,,,,0,,,,0,,,,,,300.0083618,,,,
,32435813.485,300.0038452,57928.94921875,-0.000105914597146369,3.01731294504738E-6,1,0.999253354069792,40.0298881530762,1.9737304950466,19.5499993860722,-0.00118132424641442,-0.000222569113708108,0.25,-1.55432904127605E-6,-0.000105910475397696,-1.62373657872296E-6,300.0038452,300.0038452,57918.70703125,57939.19140625,56.7290346687368,20.5475684197042,22.909004,0,0,0,40,4449,300.18885,57928.94921875,,,,,,,,,,,,,0,,,,0,,,,,,300.0038452,,,,
,32435889.82,300.0070801,61744.16015625,-0.000113168525596494,3.30454892551758E-6,1,0.999253354069792,40.0298881530762,1.97379718246578,19.5499993860722,-0.00126200929352222,-0.000239336719947569,0.25,-1.79646369554648E-6,-0.000113164026109384,-1.87055711843921E-6,300.0070801,300.0070801,61736.89453125,61751.42578125,56.6797920720252,20.5471920441714,22.909004,0,0,0,40,4449,300.16915,61744.16015625,,,,,,,,,,,,,0,,,,-0.00735,,,,,,300.0070801,,,,
,32435966.29,300.0137024,65565.65625,-0.000130360412453369,3.26103319008618E-6,1,0.999253354069792,40.0298881530762,1.97366394628372,19.5499993860722,-0.00146392369459238,-0.000216274892941891,0.25,3.24306855322619E-6,-0.000130358684097001,3.15764159594907E-6,300.0137024,300.0137024,65560.671875,65570.640625,57.0213637349291,20.5481428858842,22.909004,0,0,0,40,4449,300.16315,65565.65625,,,,,,,,,,,,,0,,,,0,,,,,,300.0137024,,,,
,32436041.585,300.0062256,69331.32421875,-0.000135554043480306,3.90424956539611E-6,1,0.999253354069792,40.0298881530762,1.97362691395067,19.5499993860722,-0.00152070249420845,-0.000233648737867098,0.25,2.588626171221E-6,-0.000135551775992516,2.499909693409E-6,300.0062256,300.0062256,69323.953125,69338.6953125,56.5312826533714,20.5505398103146,23.288654,0,0,0,40,4449,300.18155,69331.32421875,,,,,,,,,,,,,0,,,,0.00245,,,,,,300.0062256,,,,
,32436116.49,300.0054016,73074.4375,-0.000155556081564326,3.97777908577588E-6,1,0.999253354069792,40.0298881530762,1.97361487923851,19.5499993860722,-0.00174692786840527,-0.000257479589169473,0.25,3.92246921767869E-6,-0.000155554112477135,3.82072784039005E-6,300.0054016,300.0054016,73066.4609375,73082.4140625,56.9682129956214,20.5489078293259,22.529354,0,0,0,40,4449,300.1743,73074.4375,,,,,,,,,,,,,0,,,,0.00245,,,,,,300.0054016,,,,
,32436192.105,300.0116577,76853.36328125,-0.000171220506455901,4.40139605454976E-6,1,0.999253354069792,40.0298881530762,1.97359575739101,19.5499993860722,-0.00191695133151441,-0.000317305280704258,0.25,1.28546790267633E-6,-0.000171216328476499,1.17367670704827E-6,300.0116577,300.0116577,76845.8125,76860.9140625,56.7696793517368,20.5508086793673,22.909004,0,0,0,40,4449,300.17315,76853.36328125,,,,,,,,,,,,,0,,,,-0.0049,,,,,,300.0116577,,,,
,32436269.14,300.0080566,80704.5703125,-0.000178708020937789,4.03041864647073E-6,1,0.999253354069792,40.0298881530762,1.97355853840287,19.5499993860722,-0.00199554368409488,-0.000361193865309654,0.25,-1.34320713179244E-6,-0.000178701941743378,-1.4596966076918E-6,300.0080566,300.0080566,80699.59375,80709.546875,56.5406621956021,20.5511306047454,22.909004,0,0,0,40,4449,300.165,80704.5703125,,,,,,,,,,,,,0,,,,0,,,,,,300.0080566,,,,
,32436345.04,300.0089111,84497.91015625,-0.000188306675924969,4.50390471829179E-6,1,0.999253354069792,40.0298881530762,1.97351380295325,19.5499993860722,-0.00210827502206906,-0.000348300058474293,0.25,1.47213812274728E-6,-0.000188302156425471,1.34942145993085E-6,300.0089111,300.0089111,84493.09375,84502.7265625,56.5883415352752,20.5527929046596,22.909004,0,0,0,40,4449,300.14965,84497.91015625,,,,,,,,,,,,,0,,,,0,,,,,,300.0089111,,,,
,32436416.955,300.0112,88093.87890625,-0.000203913304164837,5.89195911604411E-6,1,0.999253354069792,40.0298881530762,1.97355431846334,19.5499993860722,-0.00227709088597007,-0.000411576678698608,0.25,-1.4828422366319E-6,-0.000203906400817594,-1.61551441146205E-6,300.0112,300.0112,88091.578125,88096.1796875,56.8845787440637,20.5542738805397,23.288654,0,0,0,40,4449,300.15065,88093.87890625,,,,,,,,,,,,,0,,,,0,,,,,,300.0112,,,,
,32436506.145,300.0076599,88480.234375,-0.000204485691227553,5.41565620655245E-6,1,0.999253354069792,40.0298881530762,1.97361201092226,19.5499993860722,-0.00228808225383128,-0.00038656460786941,0.25,8.54290535876724E-7,-0.000204480319116883,7.21187322164762E-7,300.0076599,300.0076599,88472.984375,88487.484375,56.9150622563137,20.5551131976319,22.909004,0,0,0,40,4449,300.14275,88480.234375,,,,,,,,,,,,,0,,,,0,,,,,,300.0076599,,,,
,32436578.895,300.0018311,84844.3359375,-0.000193480181517544,5.53672921379745E-6,1,0.999253354069792,40.0298881530762,1.97347503320593,19.5499993860722,-0.00216406070635393,-0.000369964167277845,0.25,4.30205486722829E-7,-0.000193474882308212,3.04153229648064E-7,300.0018311,300.0018311,84834.421875,84854.25,57.014329078256,20.5553310654109,22.529354,0,0,0,40,4449,300.13515,84844.3359375,,,,,,,,,,,,,0,,,,0,,,,,,300.0018311,,,,
,32436653.795,299.9998779,81100.3828125,-0.00017793525818872,5.38983261625269E-6,1,0.999253354069792,40.0298881530762,1.97351306086317,19.5499993860722,-0.00198926355900419,-0.000345816727715378,0.25,-1.02478521144828E-7,-0.000177930063099864,-2.18496960391491E-7,299.9998779,299.9998779,81090.15625,81110.609375,56.8478422036599,20.5574176005899,23.288654,0,0,0,40,4449,300.14595,81100.3828125,,,,,,,,,,,,,0,,,,-0.00245,,,,,,299.9998779,,,,
,32436731.115,299.9965515,77233.8828125,-0.000162579776367003,4.12546374499695E-6,1,0.999253354069792,40.0298881530762,1.97356750266508,19.5499993860722,-0.00182398103945091,-0.000279391774824596,0.25,3.17894849804347E-6,-0.00016257717571857,3.07274420071379E-6,299.9965515,299.9965515,77231.2578125,77236.5078125,56.922878541506,20.5567139735794,23.288654,0,0,0,40,4449,300.1504,77233.8828125,,,,,,,,,,,,,0,,,,0.00245,,,,,,299.9965515,,,,
,32436807.16,299.9929199,73432.36328125,-0.000155801594492873,3.43659057343867E-6,1,0.999253354069792,40.0298881530762,1.97351211919273,19.5499993860722,-0.00174826488327476,-0.000265572169386902,0.25,3.24007459292808E-6,-0.00015579924242455,3.13819605110751E-6,299.9929199,299.9929199,73427.234375,73437.4921875,56.8681645451599,20.5575516798545,23.288654,0,0,0,40,4449,300.15575,73432.36328125,,,,,,,,,,,,,0,,,,-0.00245,,,,,,299.9929199,,,,
,32436884.92,299.9919739,69546.21484375,-0.00014353909819399,3.03069765013228E-6,1,0.999253354069792,40.0298881530762,1.97357433524482,19.5499993860722,-0.00161245052306204,-0.0002346585516949,0.25,3.88121188972705E-6,-0.000143537515613604,3.78722934436477E-6,299.9919739,299.9919739,69543.828125,69548.6015625,56.9424192544868,20.559213992691,23.288654,0,0,0,40,4449,300.1438,69546.21484375,,,,,,,,,,,,,0,,,,-0.0049,,,,,,299.9919739,,,,
,32436959.945,299.9873962,65797.53515625,-0.000131580512319162,2.67380932375086E-6,1,0.999253354069792,40.0298881530762,1.97347096188678,19.5499993860722,-0.00147574271696077,-0.000228355295763525,0.25,2.37217611630427E-6,-0.000131578302611358,2.28598431968212E-6,299.9873962,299.9873962,65790.0859375,65804.984375,57.1472059265253,20.5617868203441,22.909004,0,0,0,40,4449,300.16595,65797.53515625,,,,,,,,,,,,,0,,,,-0.00245,,,,,,299.9873962,,,,
,32437034.835,299.9882813,62053.74609375,-0.000119092155661559,3.37515925892078E-6,1,0.999253354069792,40.0298881530762,1.97349740316109,19.5499993860722,-0.00133637092988292,-0.000202791430888582,0.25,2.49530736120899E-6,-0.000119090375203238,2.41721758592521E-6,299.9882813,299.9882813,62041.29296875,62066.19921875,57.0205821064099,20.5598816787466,22.909004,0,0,0,40,4449,300.1794,62053.74609375,,,,,,,,,,,,,0,,,,0.0049,,,,,,299.9882813,,,,
,32437110.75,299.9877625,58258.0625,-0.000102686093858297,3.40671423791736E-6,1,0.999253354069792,40.0298881530762,1.9735214728265,19.5499993860722,-0.00114493231834756,-0.0002173061100911,0.25,-1.64496675773619E-6,-0.000102682067016701,-1.71225130005913E-6,299.9877625,299.9877625,58253.0546875,58263.0703125,57.0080760501022,20.5605917186313,23.288654,0,0,0,40,4449,300.1845,58258.0625,,,,,,,,,,,,,0,,,,0,,,,,,299.9877625,,,,
,32437186.775,299.9866943,54456.96875,-9.37743097723074E-5,2.47714936309404E-6,1,0.999253354069792,40.0298881530762,1.97342402760639,19.5499993860722,-0.0010526244693816,-0.000157419934364379,0.25,2.16657325621559E-6,-9.37730379201192E-5,2.10496638555476E-6,299.9866943,299.9866943,54449.45703125,54464.48046875,56.8712910592368,20.5622240483739,23.668306,0,0,0,40,4449,300.18565,54456.96875,,,,,,,,,,,,,0,,,,0,,,,,,299.9866943,,,,
,32437263.38,299.989563,50629.232421875,-8.12148805475153E-5,2.65670716133609E-6,1,0.999253354069792,40.0298881530762,1.97354754893552,19.5499993860722,-0.000910613789854994,-0.000142603838731348,0.25,1.31661829503202E-6,-8.12133999516833E-5,1.26323286156684E-6,299.989563,299.989563,50621.78125,50636.68359375,56.7610814380252,20.5602449237258,23.288654,0,0,0,40,4449,300.20095,50629.232421875,,,,,,,,,,,,,0,,,,-0.0049,,,,,,299.989563,,,,
,32437338.515,299.981781,46873.61328125,-7.08298469653509E-5,3.00999233828662E-6,1,0.999253354069792,40.0298881530762,1.97344999015045,19.5499993860722,-0.000800630587801529,-8.68730040649752E-5,0.25,4.50147809391558E-6,-7.08307770521156E-5,4.45478197420271E-6,299.981781,299.981781,46868.49609375,46878.73046875,57.1683098965445,20.56324801965,23.288654,0,0,0,40,4449,300.20035,46873.61328125,,,,,,,,,,,,,0,,,,0.00245,,,,,,299.981781,,,,
,32437414.555,299.9892883,43072.484375,-5.88307518548438E-5,2.12114433236289E-6,1,0.999253354069792,40.0298881530762,1.97348049799156,19.5499993860722,-0.000662985900337403,-8.38257383347129E-5,0.25,2.69528244393916E-6,-5.88308209576745E-5,2.65649319180619E-6,299.9892883,299.9892883,43065.13671875,43079.83203125,57.004167907506,20.5634609792372,23.288654,0,0,0,40,4449,300.2089,43072.484375,,,,,,,,,,,,,0,,,,0.00245,,,,,,299.9892883,,,,
,32437488.17,299.9811096,39391.701171875,-4.69538587824208E-5,2.41091535957393E-6,1,0.999253354069792,40.0298881530762,1.97357542103102,19.5499993860722,-0.00053142677785704,-5.38524046769176E-5,0.25,3.31863078154581E-6,-4.69546955076267E-5,3.28761626157981E-6,299.9811096,299.9811096,39386.63671875,39396.765625,57.0721695886791,20.5629834638379,22.909004,0,0,0,40,4449,300.2324,39391.701171875,,,,,,,,,,,,,0,,,,0,,,,,,299.9811096,,,,
,32437562.71,299.9889221,35668.90234375,-3.20389685524533E-5,2.24202034743185E-6,1,0.999253354069792,40.0298881530762,1.97352660394696,19.5499993860722,-0.000362458721485003,-3.76208612473145E-5,0.25,2.18617769821829E-6,-3.20394785752145E-5,2.16499905802483E-6,299.9889221,299.9889221,35658.82421875,35678.98046875,57.0674798175637,20.5649401156379,23.288654,0,0,0,40,4449,300.23485,35668.90234375,,,,,,,,,,,,,0,,,,0,,,,,,299.9889221,,,,
,32437635.69,299.9876404,32021.2646484375,-1.90370408347933E-5,2.05273839843645E-6,1,0.999253354069792,40.0298881530762,1.97347946967344,19.5499993860722,-0.000215832882154843,-1.96367719293586E-5,0.25,1.54196030914571E-6,-1.90375048022119E-5,1.52935948433552E-6,299.9876404,299.9876404,32011.43359375,32031.095703125,57.0799858738714,20.5667805976001,23.668306,0,0,0,40,4449,300.24105,32021.2646484375,,,,,,,,,,,,,0,,,,-0.00245,,,,,,299.9876404,,,,
,32437711.295,299.99368285,28242.8056640625,-1.09766895734782E-5,1.12174610594273E-6,1,0.999253354069792,40.0298881530762,1.97354156651274,19.5499993860722,-0.000132445964435995,3.48155656403138E-5,0.25,5.01561185799405E-6,-1.0979678518361E-5,5.00821927628929E-6,299.9934692,299.9938965,28237.7109375,28247.900390625,57.3332335141022,20.5646791861543,23.288654,0,0,0,40,4449,300.24435,28242.8056640625,,,,,,,,,,,,,0,,,,-0.0049,,,,,,299.99368285,,,,
,32437788.335,299.9862366,24392.306640625,1.39818196917821E-6,1.19648172686665E-6,1,0.999253354069792,40.0298881530762,1.97347280815279,19.5499993860722,1.4208917333139E-5,1.09249639973597E-5,0.25,7.34892337189123E-7,1.39765583196648E-6,7.35794577589613E-7,299.9862366,299.9862366,24384.703125,24399.91015625,56.9893169656406,20.5668956763886,22.909004,0,0,0,40,4449,300.25615,24392.306640625,,,,,,,,,,,,,0,,,,-0.00245,,,,,,299.9862366,,,,
,32437861.625,299.9912415,20726.5712890625,1.3072414100667E-5,1.17398422706351E-6,1,0.999253354069792,40.0298881530762,1.97349676780366,19.5499993860722,0.000145857678909933,2.70614366004953E-5,0.25,1.5547348915398E-7,1.30719280916126E-5,1.64110703218477E-7,299.9912415,299.9912415,20716.6328125,20736.509765625,56.8361177758714,20.5651338757183,23.288654,0,0,0,40,4449,300.25975,20726.5712890625,,,,,,,,,,,,,0,,,,0.00245,,,,,,299.9912415,,,,
,32437937.17,299.9898682,16953.64453125,2.36585430552284E-5,1.43913907899652E-6,1,0.999253354069792,40.0298881530762,1.97355949461677,19.5499993860722,0.000265166105176982,4.21444504652122E-5,0.25,-3.29758565499716E-7,2.36580677778038E-5,-3.14097568168151E-7,299.9898682,299.9898682,16948.58203125,16958.70703125,56.8963031718522,20.5645393614669,23.668306,0,0,0,40,4449,300.26265,16953.64453125,,,,,,,,,,,,,0,,,,0.00245,,,,,,299.9898682,,,,
,32438012.94,299.9956665,13165.7026367188,3.40374967189417E-5,9.52915802197047E-7,1,0.999253354069792,40.0298881530762,1.9735684020146,19.5499993860722,0.000379705492937408,7.09646700237011E-5,0.25,4.49557561877955E-7,3.40361929421162E-5,4.72077771480182E-7,299.9956665,299.9956665,13160.7265625,13170.6787109375,57.1456426694868,20.5656030101164,22.909004,0,0,0,40,4449,300.2631,13165.7026367188,,,,,,,,,,,,,0,,,,0,,,,,,299.9956665,,,,
,32438091.435,299.98962405,9245.56298828125,4.31154017291775E-5,7.92703880276018E-7,1,0.999253354069792,40.0298881530762,1.97353272171607,19.5499993860722,0.00048298171689991,7.8254837197384E-5,0.25,-4.71158181939747E-7,4.31144469964758E-5,-4.42582100429949E-7,299.9895325,299.9897156,9238.0302734375,9253.095703125,57.0416860764291,20.5671967169125,22.909004,0,0,0,40,4449,300.27035,9245.56298828125,,,,,,,,,,,,,0,,,,-0.0049,,,,,,299.98962405,,,,
,32438171.745,299.9916077,5229.49609375,4.91236186517809E-5,5.39219432190801E-7,1,0.999253354069792,40.0298881530762,1.97344192097884,19.5499993860722,0.000549773461275015,9.19750848368636E-5,0.25,-2.84678481564809E-7,4.91223586650825E-5,-2.52107714252105E-7,299.9916077,299.9916077,5224.54345703125,5234.44873046875,57.0487207331022,20.5683873719299,22.909004,0,0,0,40,4449,300.28,5229.49609375,,,,,,,,,,,,,0,,,,-0.00245,,,,,,299.9916077,,,,
,32438251.255,299.9976807,1255.45501708984,4.21889359552695E-5,4.68049062080032E-7,1,0.999253354069792,40.0298881530762,1.97337842784779,19.5499993860722,0.000472260906419591,7.83393692265084E-5,0.25,-3.02584736684812E-7,4.21878819309486E-5,-2.74595521031935E-7,299.9976807,299.9976807,1250.37280273438,1260.53723144531,57.1323549846599,20.5721438449586,22.909004,0,0,0,40,4449,300.2853,1255.45501708984,,,,,,,,,,,,,0,,,,-0.00245,,,,,,299.9976807,,,,
,32438326.225,299.9920959,-2487.95690917969,-4.56715550669479E-5,5.29143145017709E-7,1,0.999253354069792,40.0298881530762,1.97333344445072,19.5499993860722,-0.000509571427679509,-9.44009652712934E-5,0.25,-5.30833604120402E-7,-4.56698544163767E-5,-5.61102777269357E-7,299.9920959,299.9920959,-2498.1240234375,-2477.78979492187,56.9861904515637,20.5727615965629,23.288654,0,0,0,40,4449,300.2893,-2487.95690917969,,,,,,,,,,,,,0,,,,0,,,,,,299.9920959,,,,
,32438404.22,299.99440005,-6387.56665039063,-4.71486666467711E-5,5.2162456205092E-7,1,0.999253354069792,40.0298881530762,1.97336319532785,19.5499993860722,-0.000524323468433383,-0.000107475732805463,0.25,-1.44428634668955E-6,-4.71463148699709E-5,-1.47549050134452E-6,299.9940491,299.994751,-6392.56103515625,-6382.572265625,57.0846756449868,20.5731915627774,23.668306,0,0,0,40,4449,300.28605,-6387.56665039063,,,,,,,,,,,,,0,,,,-0.0049,,,,,,299.99440005,,,,
,32438484.84,300.0001526,-10419.0498046875,-3.9830369546816E-5,7.07043358791497E-7,1,0.999253354069792,40.0298881530762,1.97333208903769,19.5499993860722,-0.000444751712593918,-8.02926079188666E-5,0.25,-2.80965207039388E-7,-3.98289986617694E-5,-3.07336282016726E-7,300.0001526,300.0001526,-10421.3916015625,-10416.7080078125,57.1776894387753,20.5725582436777,23.668306,0,0,0,40,4449,300.2824,-10419.0498046875,,,,,,,,,,,,,0,,,,-0.00245,,,,,,300.0001526,,,,
,32438566.14,300.0040283,-14482.3681640625,-3.05393894860093E-5,1.0289956591325E-6,1,0.999253354069792,40.0298881530762,1.97330093140136,19.5499993860722,-0.000339404654156286,-7.07823127865522E-5,0.25,-1.04015340936202E-6,-3.05377897043448E-5,-1.06033400360133E-6,300.0040283,300.0040283,-14489.892578125,-14474.84375,56.6594697305252,20.5749940539868,22.909004,0,0,0,40,4449,300.2773,-14482.3681640625,,,,,,,,,,,,,0,,,,0,,,,,,300.0040283,,,,
,32438648.14,300.00720215,-18579.8291015625,-1.81830115318297E-5,1.30196932488823E-6,1,0.999253354069792,40.0298881530762,1.97335331302614,19.5499993860722,-0.000199951050924102,-5.44616164981571E-5,0.25,-1.72102658605503E-6,-1.8181329540999E-5,-1.73299964885421E-6,300.006897,300.0075073,-18587.224609375,-18572.43359375,57.1722180391407,20.5759629647525,23.288654,0,0,0,40,4449,300.2764,-18579.8291015625,,,,,,,,,,,,,0,,,,0,,,,,,300.00720215,,,,
,32438729.2,300.005127,-22632.5068359375,-7.06921293625971E-6,1.11718964034124E-6,1,0.999253354069792,40.0298881530762,1.97326121940837,19.5499993860722,-7.84535971251321E-5,-1.70179419387739E-5,0.25,-2.97462297500929E-7,-7.06880578762722E-6,-3.02124692376857E-7,300.005127,300.005127,-22639.984375,-22625.029296875,57.115940785756,20.5781073993839,22.909004,0,0,0,40,4449,300.2699,-22632.5068359375,,,,,,,,,,,,,0,,,,0.00245,,,,,,300.005127,,,,
,32438809.545,300.0077515,-26647.671875,4.54252239670058E-6,1.29835550281421E-6,1,0.999253354069792,40.0298881530762,1.9733283631737,19.5499993860722,5.43135061209983E-5,-1.15701474263978E-5,0.25,-1.8219389316916E-6,4.54358982444311E-6,-1.81888530271537E-6,300.0077515,300.0077515,-26657.716796875,-26637.626953125,57.2957153451791,20.5768597229647,23.288654,0,0,0,40,4449,300.26055,-26647.671875,,,,,,,,,,,,,0,,,,0,,,,,,300.0077515,,,,
,32438891.3,300.0051575,-30733.291015625,1.83887496491248E-5,1.50909214137828E-6,1,0.999253354069792,40.0298881530762,1.97322262032766,19.5499993860722,0.000206384705322743,3.09253566059017E-5,0.25,-4.19639861230945E-7,1.83884804933049E-5,-4.07496718246363E-7,300.0051575,300.0051575,-30741.17578125,-30725.40625,57.0729512171983,20.5801347002991,23.288654,0,0,0,40,4449,300.26495,-30733.291015625,,,,,,,,,,,,,0,,,,0,,,,,,300.0051575,,,,
,32438973.665,300.0118408,-34850.10546875,2.88663390305603E-5,2.09432794092987E-6,1,0.999253354069792,40.0298881530762,1.97336965164619,19.5499993860722,0.000323024229712632,5.41938055679043E-5,0.25,-1.53874383571051E-7,2.88655778369257E-5,-1.34842734093438E-7,300.0118408,300.0118408,-34852.5390625,-34847.671875,57.1948852661984,20.5747940846236,22.909004,0,0,0,40,4449,300.243,-34850.10546875,,,,,,,,,,,,,0,,,,0.00245,,,,,,300.0118408,,,,
,32439056.8,300.0163879,-39003.00390625,4.6264292789271E-5,2.40408355968052E-6,1,0.999253354069792,40.0298881530762,1.97342835687196,19.5499993860722,0.000516264021861633,9.5308901589207E-5,0.25,5.0917063223029E-7,4.62625698890284E-5,5.39622311354389E-7,300.0163879,300.0163879,-39010.34375,-38995.6640625,57.3770047111791,20.5742134400921,23.668306,0,0,0,40,4449,300.2392,-39003.00390625,,,,,,,,,,,,,0,,,,-0.0098,,,,,,300.0163879,,,,
,32439138.755,300.0138245,-43098.1953125,5.73646842322769E-5,2.22953151856526E-6,1,0.999253354069792,40.0298881530762,1.97341859092697,19.5499993860722,0.000646230931801105,8.29656631905271E-5,0.25,-2.51797172504343E-6,5.73646287731769E-5,-2.48015448204609E-6,300.0138245,300.0138245,-43103.21875,-43093.171875,57.1706547821022,20.5749058297479,23.288654,0,0,0,40,4449,300.2369,-43098.1953125,,,,,,,,,,,,,0,,,,-0.0049,,,,,,300.0138245,,,,
,32439222.205,300.0167542,-47269.09765625,6.86280937573584E-5,3.37452732464307E-6,1,0.999253354069792,40.0298881530762,1.97341957285412,19.5499993860722,0.000770897518374277,0.000112066590366735,0.25,-1.8664895866029E-6,6.8627268910694E-5,-1.82132353936131E-6,300.0167542,300.0167542,-47276.75,-47261.4453125,57.2324034351214,20.5770892573473,23.668306,0,0,0,40,4449,300.2294,-47269.09765625,,,,,,,,,,,,,0,,,,0.00245,,,,,,300.0167542,,,,
,32439304.73,300.0084839,-51394.5859375,8.53150803564964E-5,2.88525642397325E-6,1,0.999253354069792,40.0298881530762,1.97338306633067,19.5499993860722,0.000957162754537753,0.000146023710105489,0.25,-1.72006191677605E-6,8.53136894301977E-5,-1.66398578305046E-6,300.0084839,300.0084839,-51404.86328125,-51384.30859375,57.1729996676599,20.5770823548894,23.668306,0,0,0,40,4449,300.2245,-51394.5859375,,,,,,,,,,,,,0,,,,0,,,,,,300.0084839,,,,
,32439387.82,300.0061951,-55546.541015625,9.68979393540576E-5,2.56084445324227E-6,1,0.999253354069792,40.0298881530762,1.97333818243469,19.5499993860722,0.00108433175778153,0.000181760266004512,0.25,-5.29970984703534E-7,9.68954378758407E-5,-4.66385784308401E-7,300.0061951,300.0061951,-55556.671875,-55536.41015625,57.1370447557753,20.5782296914743,22.909004,0,0,0,40,4449,300.21925,-55546.541015625,,,,,,,,,,,,,0,,,,-0.0049,,,,,,300.0061951,,,,
,32439471.32,300.0098572,-59721.97265625,0.000107965665136358,4.51091964513078E-6,1,0.999253354069792,40.0298881530762,1.97334435084988,19.5499993860722,0.00121029183723036,0.000190379116622345,0.25,-1.67653328900669E-6,0.000107963581437354,-1.60572421834125E-6,300.0098572,300.0098572,-59729.46875,-59714.4765625,57.1808159528522,20.5793566264601,23.288654,0,0,0,40,4449,300.2157,-59721.97265625,,,,,,,,,,,,,0,,,,0.00245,,,,,,300.0098572,,,,
,32439553.275,300.0124817,-63817.53515625,0.000122782669237499,3.34968536685148E-6,1,0.999253354069792,40.0298881530762,1.97341423288798,19.5499993860722,0.00136793473445144,0.000265585858187503,0.25,2.4826330601203E-6,0.00012277741975195,2.56295322229377E-6,300.0124817,300.0124817,-63822.3359375,-63812.734375,57.0135474497368,20.5789608367948,23.288654,0,0,0,40,4449,300.20285,-63817.53515625,,,,,,,,,,,,,0,,,,0,,,,,,300.0124817,,,,
,32439637.055,300.0184021,-68005.1171875,0.000135460554735129,3.65803421120116E-6,1,0.999253354069792,40.0298881530762,1.97341311097738,19.5499993860722,0.00152865174906103,0.000180614214324871,0.25,-7.31386716977317E-6,0.000135461319654948,-7.22504244448059E-6,300.0184021,300.0184021,-68010.046875,-68000.1875,57.1456426694868,20.5805184273555,23.668306,0,0,0,40,4449,300.18585,-68005.1171875,,,,,,,,,,,,,0,,,,-0.0049,,,,,,300.0184021,,,,
,32439720.51,300.0126343,-72174.80078125,0.00014708067896758,3.23592711919959E-6,1,0.999253354069792,40.0298881530762,1.97339856427162,19.5499993860722,0.0016479881594763,0.000264121529303513,0.25,-1.8576299502611E-6,0.000147077567938353,-1.76146374363131E-6,300.0126343,300.0126343,-72182.1171875,-72167.484375,57.1558038402368,20.5804274614555,23.288654,0,0,0,40,4449,300.1752,-72174.80078125,,,,,,,,,,,,,0,,,,0.00245,,,,,,300.0126343,,,,
,32439803.72,300.0166626,-76332.40625,0.000167351210719821,3.99802258233836E-6,1,0.999253354069792,40.0298881530762,1.97335302128067,19.5499993860722,0.00188904608876662,0.000219850629907063,0.25,-9.32870622217449E-6,0.000167352365257818,-9.21918809546893E-6,300.0165405,300.0167847,-76339.921875,-76324.890625,56.9900985941599,20.5834140459636,23.288654,0,0,0,40,4449,300.17225,-76332.40625,,,,,,,,,,,,,0,,,,-0.0049,,,,,,300.0166626,,,,
,32439888.125,300.0141296,-80552.6953125,0.000174373718924549,4.78871528391137E-6,1,0.999253354069792,40.0298881530762,1.9734122715673,19.5499993860722,0.0019516207439979,0.00032577366659261,0.25,-1.07168920913811E-6,0.000174369302224761,-9.57951500662998E-7,300.0141296,300.0141296,-80557.71875,-80547.671875,57.1440794124484,20.5813002650588,23.668306,0,0,0,40,4449,300.1662,-80552.6953125,,,,,,,,,,,,,0,,,,0.00245,,,,,,300.0141296,,,,
,32439972.85,300.0070801,-84785.06640625,0.000187714216029325,5.6018556067779E-6,1,0.999253354069792,40.0298881530762,1.97338452514603,19.5499993860722,0.00208397304007415,0.000448409560904357,0.25,7.58670681356674E-6,0.000187703826418357,7.70876086520095E-6,300.0070801,300.0070801,-84790.171875,-84779.9609375,57.1479875550445,20.5825122669569,22.909004,0,0,0,40,4449,300.15915,-84785.06640625,,,,,,,,,,,,,0,,,,-0.00245,,,,,,300.0070801,,,,
,32440053.1,300.0051575,-88797.12890625,0.000206547233320975,5.6877282034968E-6,1,0.999253354069792,40.0298881530762,1.97338799224801,19.5499993860722,0.00230370498420997,0.000431945213398892,0.25,2.85135743955427E-6,0.000206539410372193,2.98567578832682E-6,300.0051575,300.0051575,-88801.96875,-88792.2890625,57.1331366131791,20.5833710257832,23.288654,0,0,0,40,4449,300.1585,-88797.12890625,,,,,,,,,,,,,0,,,,0.00245,,,,,,300.0051575,,,,
,32440149.845,300.0128479,-87323.76953125,0.000191974120522214,6.20904826329933E-6,1,0.999253354069792,40.0298881530762,1.9733806467741,19.5499993860722,0.00212476404965436,0.000496088439277452,0.25,1.11134674568772E-5,0.000191961281554885,1.12381146839758E-5,300.0128479,300.0128479,-87328.8671875,-87318.671875,56.9705578811791,20.5811884575441,22.909004,0,0,0,40,4449,300.1474,-87323.76953125,,,,,,,,,,,,,0,,,,0.0049,,,,,,300.0128479,,,,
,32440230.1,300.0047302,-83311.33203125,0.000182353538200924,5.29337368306249E-6,1,0.999253354069792,40.0298881530762,1.97341575557938,19.5499993860722,0.00203548400056811,0.000372154677395057,0.25,1.69429771413647E-6,0.00018234715273602,1.81308263573663E-6,300.0047302,300.0047302,-83316.390625,-83306.2734375,57.159711982833,20.5832531649107,23.288654,0,0,0,40,4449,300.1461,-83311.33203125,,,,,,,,,,,,,0,,,,-0.0049,,,,,,300.0047302,,,,
,32440311.945,299.9984436,-79220.625,0.000172762540052641,2.90261760359772E-6,1,0.999253354069792,40.0298881530762,1.97335749456897,19.5499993860722,0.00193815989634098,0.000296076701893002,0.25,-3.44810774186048E-6,0.000172759814390499,-3.33530610989879E-6,299.9984436,299.9984436,-79223.1328125,-79218.1171875,57.1815975813714,20.5839272495701,23.288654,0,0,0,40,4449,300.14815,-79220.625,,,,,,,,,,,,,0,,,,0,,,,,,299.9984436,,,,
,32440397.61,299.991272,-74940.38671875,0.000156863136936254,3.33866166592541E-6,1,0.999253354069792,40.0298881530762,1.97345862805835,19.5499993860722,0.001755695008386,0.000292979798720125,0.25,-9.7196478509846E-7,0.000156859284883828,-8.69493481373482E-7,299.991272,299.991272,-74955.34375,-74925.4296875,57.0565370182945,20.5817339200956,23.288654,0,0,0,40,4449,300.1463,-74940.38671875,,,,,,,,,,,,,0,,,,0,,,,,,299.991272,,,,
,32440480.845,299.9927673,-70780.4765625,0.000145956861533308,3.8455491072085E-6,1,0.999253354069792,40.0298881530762,1.97343973252567,19.5499993860722,0.00163581930742692,0.000259861329289408,0.25,-2.04449521698161E-6,0.000145954007006638,-1.94902155425649E-6,299.9927673,299.9927673,-70782.703125,-70778.25,57.3129111726022,20.5814741007052,23.288654,0,0,0,40,4449,300.16435,-70780.4765625,,,,,,,,,,,,,0,,,,0,,,,,,299.9927673,,,,
,32440564.62,299.9891052,-66593.12890625,0.000130252716120538,3.26819176825687E-6,1,0.999253354069792,40.0298881530762,1.9733907968758,19.5499993860722,0.00146803735744291,0.000184233577077068,0.25,-6.08775391034814E-6,0.000130252969106361,-6.00234245121917E-6,299.9891052,299.9891052,-66595.609375,-66590.6484375,57.1761261817368,20.5816286678676,23.288654,0,0,0,40,4449,300.16855,-66593.12890625,,,,,,,,,,,,,0,,,,-0.00245,,,,,,299.9891052,,,,
,32440647.34,299.9901428,-62458.169921875,0.000117669417205941,2.91984340194585E-6,1,0.999253354069792,40.0298881530762,1.97338357800546,19.5499993860722,0.00132418964876293,0.000178097498993948,0.25,-4.45654409838016E-6,0.000117668954883284,-4.37933735820195E-6,299.9901428,299.9901428,-62468.15234375,-62448.1875,57.2128627221407,20.58033204355,23.288654,0,0,0,40,4449,300.17875,-62458.169921875,,,,,,,,,,,,,0,,,,0.0049,,,,,,299.9901428,,,,
,32440729.925,299.9837646,-58332.86328125,0.00010590329984032,3.37791596336639E-6,1,0.999253354069792,40.0298881530762,1.97338747138519,19.5499993860722,0.00118979734537879,0.000171747197723172,0.25,-2.98614570605508E-6,0.000105902232710291,-2.91662284347663E-6,299.9837646,299.9837646,-58335.41796875,-58330.30859375,57.0299616486406,20.5808497095379,23.288654,0,0,0,40,4449,300.1937,-58332.86328125,,,,,,,,,,,,,0,,,,-0.00245,,,,,,299.9837646,,,,
,32440809.82,299.98727415,-54337.501953125,9.52273696278027E-5,2.83464691719158E-6,1,0.999253354069792,40.0298881530762,1.97332681183554,19.5499993860722,0.00106719250662617,0.000169619575150899,0.25,-1.32643164964835E-6,9.52255029108733E-5,-1.26389855819481E-6,299.9872131,299.9873352,-54342.796875,-54332.20703125,57.3816944822945,20.5807475742326,23.668306,0,0,0,40,4449,300.20665,-54337.501953125,,,,,,,,,,,,,0,,,,-0.0049,,,,,,299.98727415,,,,
,32440890.565,299.9917908,-50302.548828125,7.76263064610403E-5,2.29386923291915E-6,1,0.999253354069792,40.0298881530762,1.97330282579361,19.5499993860722,0.000881609454676361,7.08594897791421E-5,0.25,-7.11077073562992E-6,7.76287292876715E-5,-7.05957072875247E-6,299.9917908,299.9917908,-50305.3203125,-50299.77734375,57.1776894387753,20.5810885756478,22.909004,0,0,0,40,4449,300.2014,-50302.548828125,,,,,,,,,,,,,0,,,,-0.0049,,,,,,299.9917908,,,,
,32440973.42,299.9828186,-46162.166015625,6.65453172260836E-5,1.82880937902343E-6,1,0.999253354069792,40.0298881530762,1.97327964235996,19.5499993860722,0.000750616284650617,9.03942571091885E-5,0.25,-3.44355794191877E-6,6.65456718500772E-5,-3.39970320878607E-6,299.9828186,299.9828186,-46172.48046875,-46151.8515625,57.1503324406022,20.5805168417208,23.668306,0,0,0,40,4449,300.2099,-46162.166015625,,,,,,,,,,,,,0,,,,0,,,,,,299.9828186,,,,
,32441057.32,299.9866943,-41969.322265625,5.18585656883131E-5,2.19220260197336E-6,1,0.999253354069792,40.0298881530762,1.97327030118073,19.5499993860722,0.000583501174877082,7.8807616750107E-5,0.25,-1.93543354657893E-6,5.18583412220492E-5,-1.9012463685788E-6,299.9866943,299.9866943,-41979.359375,-41959.28515625,57.1307917276214,20.5805133114769,23.668306,0,0,0,40,4449,300.21485,-41969.322265625,,,,,,,,,,,,,0,,,,0,,,,,,299.9866943,,,,
,32441139.125,299.9916992,-37879.146484375,3.86718847820923E-5,1.92412759960683E-6,1,0.999253354069792,40.0298881530762,1.97326752111961,19.5499993860722,0.000441839975825563,2.00212426317249E-5,0.25,-4.90921253705767E-6,3.86739924277492E-5,-4.88359449230684E-6,299.9916992,299.9916992,-37881.6640625,-37876.62890625,57.3074397729676,20.5792939300094,23.668306,0,0,0,40,4449,300.22355,-37879.146484375,,,,,,,,,,,,,0,,,,0,,,,,,299.9916992,,,,
,32441219.805,299.9862061,-33851.5234375,2.73399069739499E-5,1.72615303119855E-6,1,0.999253354069792,40.0298881530762,1.97325923463637,19.5499993860722,0.000307982522182002,3.9460376657135E-5,0.25,-1.20706614011001E-6,2.73399105789699E-5,-1.18900589478297E-6,299.9862061,299.9862061,-33854.0078125,-33849.0390625,57.2300585495638,20.5803566659919,23.668306,0,0,0,40,4449,300.23775,-33851.5234375,,,,,,,,,,,,,0,,,,0.0049,,,,,,299.9862061,,,,
,32441300.76,299.9901733,-29801.6806640625,1.45232833736348E-5,1.24895400496533E-6,1,0.999253354069792,40.0298881530762,1.97327224036554,19.5499993860722,0.000167470896520777,-1.35133502584108E-6,0.25,-2.63712742111693E-6,1.45245998804477E-5,-2.62746713898476E-6,299.9901733,299.9901733,-29806.568359375,-29796.79296875,57.1042163579676,20.5814312907314,23.288654,0,0,0,40,4449,300.2458,-29801.6806640625,,,,,,,,,,,,,0,,,,0,,,,,,299.9901733,,,,
,32441382,299.9855957,-25743.3505859375,2.64817917814566E-6,1.29761660684116E-6,1,0.999253354069792,40.0298881530762,1.97323971084378,19.5499993860722,3.36412852581519E-5,-1.8168186761753E-5,0.25,-2.08397563899964E-6,2.64947854523793E-6,-2.0821661631029E-6,299.9855957,299.9855957,-25748.490234375,-25738.2109375,57.2120810936214,20.5795656929497,22.909004,0,0,0,40,4449,300.24695,-25743.3505859375,,,,,,,,,,,,,0,,,,0,,,,,,299.9855957,,,,
,32441463.82,299.9889221,-21653.236328125,-9.31690935484293E-6,1.22348892397873E-6,1,0.999253354069792,40.0298881530762,1.97324493420323,19.5499993860722,-0.000104165429392424,-1.7997039730737E-5,0.25,4.37707597603555E-9,-9.31663997851064E-6,-1.78119114581183E-9,299.9889221,299.9889221,-21660.62109375,-21645.8515625,57.0557553897753,20.5789356594323,23.288654,0,0,0,40,4449,300.2531,-21653.236328125,,,,,,,,,,,,,0,,,,0.00245,,,,,,299.9889221,,,,
,32441544.26,299.9902649,-17633.0224609375,-2.1808249697904E-5,1.09745193742493E-6,1,0.999253354069792,40.0298881530762,1.97331201229903,19.5499993860722,-0.000241395954383941,-5.61743489819684E-5,0.25,-1.24621655160262E-6,-2.1806785976547E-5,-1.2606057684521E-6,299.9902649,299.9902649,-17642.97265625,-17623.072265625,57.1511140691214,20.5780472799771,23.668306,0,0,0,40,4449,300.25605,-17633.0224609375,,,,,,,,,,,,,0,,,,0.00245,,,,,,299.9902649,,,,
,32441628.735,299.9928894,-13410.2099609375,-3.24591450589415E-5,9.10535025118995E-7,1,0.999253354069792,40.0298881530762,1.97328378418445,19.5499993860722,-0.000362073111668086,-6.752139537032E-5,0.25,-4.15898154609578E-7,-3.24579135219341E-5,-4.3737390122138E-7,299.9928894,299.9928894,-13415.0478515625,-13405.3720703125,57.0596635323714,20.5778632659251,22.909004,0,0,0,40,4449,300.25885,-13410.2099609375,,,,,,,,,,,,,0,,,,0,,,,,,299.9928894,,,,
,32441710.595,299.986145,-9322.7265625,-4.30494254096886E-5,7.31060329772087E-7,1,0.999253354069792,40.0298881530762,1.97337634270311,19.5499993860722,-0.00047956404181817,-9.33787879863354E-5,0.25,-8.93565421913442E-7,-4.30475740773019E-5,-9.22056400056887E-7,299.986145,299.986145,-9327.515625,-9317.9375,57.0127658212176,20.5754790438363,22.909004,0,0,0,40,4449,300.2796,-9322.7265625,,,,,,,,,,,,,0,,,,-0.0049,,,,,,299.986145,,,,
,32441792.215,299.9944153,-5241.67456054687,-4.91271799951921E-5,4.87966394013392E-7,1,0.999253354069792,40.0298881530762,1.97328377787061,19.5499993860722,-0.000548309631154814,-0.000100410063376793,0.25,-4.69836326258032E-7,-4.91254147921456E-5,-5.0238729748688E-7,299.9944153,299.9944153,-5249.28564453125,-5234.0634765625,57.1636201254291,20.5756764377976,22.909004,0,0,0,40,4449,300.2784,-5241.67456054687,,,,,,,,,,,,,0,,,,-0.00245,,,,,,299.9944153,,,,
,32441871.515,299.9877625,-1274.18225097656,-4.1820439116976E-5,4.70005987393203E-7,1,0.999253354069792,40.0298881530762,1.97317642602765,19.5499993860722,-0.000467071964092847,-8.3525174234282E-5,0.25,-2.25833029386299E-7,-4.18190604336993E-5,-2.53562907759041E-7,299.9877625,299.9877625,-1279.16662597656,-1269.19787597656,56.9963516223137,20.5792998650096,23.668306,0,0,0,40,4449,300.27855,-1274.18225097656,,,,,,,,,,,,,0,,,,-0.00245,,,,,,299.9877625,,,,
,32441949.705,299.9923096,2628.69689941406,4.59379809109344E-5,3.56831909688497E-7,1,0.999253354069792,40.0298881530762,1.97326935494871,19.5499993860722,0.000514431038163689,8.39655650339808E-5,0.25,-4.48508256897232E-7,4.59369214341055E-5,-4.18033386071749E-7,299.9923096,299.9923096,2623.77490234375,2633.61889648438,56.946327397083,20.5771313714734,23.288654,0,0,0,40,4449,300.2837,2628.69689941406,,,,,,,,,,,,,0,,,,0,,,,,,299.9923096,,,,
,32442030.22,300.0013428,6653.53173828125,4.70815449818378E-5,5.13529392960122E-7,1,0.999253354069792,40.0298881530762,1.9732905491303,19.5499993860722,0.000525266500972652,9.74607209159374E-5,0.25,5.60427486673005E-7,4.70797693634847E-5,5.9161163950212E-7,300.0013428,300.0013428,6648.53955078125,6658.52392578125,57.126101956506,20.5766138107941,23.288654,0,0,0,40,4449,300.28765,6653.53173828125,,,,,,,,,,,,,0,,,,0.00245,,,,,,300.0013428,,,,
,32442112.5,299.9971924,10769.6650390625,4.03812650133344E-5,8.36142648166344E-7,1,0.999253354069792,40.0298881530762,1.97326446661702,19.5499993860722,0.000449048010846593,9.20224967709632E-5,0.25,1.23499148640028E-6,4.03792504432648E-5,1.26169706759859E-6,299.9971924,299.9971924,10762.0087890625,10777.3212890625,57.180034324333,20.5767335937157,23.668306,0,0,0,40,4449,300.28685,10769.6650390625,,,,,,,,,,,,,0,,,,0.00245,,,,,,299.9971924,,,,
,32442191.32,300.0009155,14705,2.92026420514882E-5,1.01591371046361E-6,1,0.999253354069792,40.0298881530762,1.97325290708619,19.5499993860722,0.000325377367638129,6.28550687337803E-5,0.25,5.62808803752829E-7,2.92014014697558E-5,5.82117877027117E-7,300.0009155,300.0009155,14695.15625,14714.84375,57.1847240954484,20.5767357405333,23.668306,0,0,0,40,4449,300.2818,14705,,,,,,,,,,,,,0,,,,-0.00245,,,,,,300.0009155,,,,
,32442272.87,300,18783.1044921875,1.85079652029118E-5,1.07494508322005E-6,1,0.999253354069792,40.0298881530762,1.9732847438254,19.5499993860722,0.000203330319760466,5.65147384085626E-5,0.25,1.84853652317832E-6,1.8506194046147E-5,1.8607206838009E-6,300,300,18778.013671875,18788.1953125,57.1948852661984,20.5753571951825,23.288654,0,0,0,40,4449,300.276,18783.1044921875,,,,,,,,,,,,,0,,,,-0.00245,,,,,,300,,,,
,32442353.86,300.0084534,22830.8642578125,4.99336667808864E-6,1.41402874851112E-6,1,0.999253354069792,40.0298881530762,1.97327340501575,19.5499993860722,5.58679868016753E-5,9.41391172967357E-6,0.25,-2.306743125405E-8,4.99323259155728E-6,-1.97673897926491E-8,300.0084534,300.0084534,22825.6484375,22836.080078125,57.0002597649099,20.577434763344,23.288654,0,0,0,40,4449,300.2757,22830.8642578125,,,,,,,,,,,,,0,,,,0,,,,,,300.0084534,,,,
,32442436.655,300.012085,26969.2880859375,-7.15919759244801E-6,1.27275146770786E-6,1,0.999253354069792,40.0298881530762,1.97323199952388,19.5499993860722,-8.12008737350254E-5,-7.13501370947065E-6,0.25,6.02142985099975E-7,-7.15938044567878E-6,5.97398281974604E-7,300.012085,300.012085,26959.06640625,26979.509765625,57.129228470583,20.5767436572099,22.909004,0,0,0,40,4449,300.2606,26969.2880859375,,,,,,,,,,,,,0,,,,-0.0049,,,,,,300.012085,,,,
,32442519.745,300.0096893,31122.4921875,-2.04384415389961E-5,1.50670093838592E-6,1,0.999253354069792,40.0298881530762,1.97322481998815,19.5499993860722,-0.00023302345940544,-1.33978061971142E-5,0.25,2.34263048743034E-6,-2.04393767374599E-5,2.32907846588308E-6,300.0094299,300.0099487,31117.57421875,31127.41015625,57.1268835850253,20.5760898521648,23.668306,0,0,0,40,4449,300.2573,31122.4921875,,,,,,,,,,,,,0,,,,0.00245,,,,,,300.0096893,,,,
,32442600.605,300.0177917,35160.0078125,-3.06629189824714E-5,1.94681398981861E-6,1,0.999253354069792,40.0298881530762,1.97317309844854,19.5499993860722,-0.000344033804879906,-5.21473828575363E-5,0.25,6.47737996692058E-7,-3.06624231859822E-5,6.27508901475818E-7,300.0177917,300.0177917,35150.265625,35169.75,57.0104209356599,20.5766591954778,23.668306,0,0,0,40,4449,300.2463,35160.0078125,,,,,,,,,,,,,0,,,,-0.0049,,,,,,300.0177917,,,,
,32442685.16,300.0135803,39387.896484375,-4.36369603454876E-5,2.45572144949263E-6,1,0.999253354069792,40.0298881530762,1.97320992092386,19.5499993860722,-0.000488886219536806,-7.83886067615761E-5,0.25,5.48285429601257E-7,-4.36360171716216E-5,5.19534195158805E-7,300.0135803,300.0135803,39378.10546875,39397.6875,57.044812590506,20.577379948235,23.288654,0,0,0,40,4449,300.23385,39387.896484375,,,,,,,,,,,,,0,,,,0,,,,,,300.0135803,,,,
,32442768.1,300.0153809,43533.4375,-5.62183767873251E-5,2.37992871040149E-6,1,0.999253354069792,40.0298881530762,1.97310857896073,19.5499993860722,-0.000626553522582601,-0.000119786638203244,0.25,-9.75628679991594E-7,-5.62160542113651E-5,-1.01258397325358E-6,300.0153809,300.0153809,43526.01171875,43540.86328125,56.976810909333,20.5769280816233,23.288654,0,0,0,40,4449,300.235,43533.4375,,,,,,,,,,,,,0,,,,-0.00245,,,,,,300.0153809,,,,
,32442850.115,300.0136108,47634.26953125,-7.27766025038216E-5,2.68867255485257E-6,1,0.999253354069792,40.0298881530762,1.97303763338133,19.5499993860722,-0.000820202577649814,-0.000102333566964157,0.25,3.45408960653457E-6,-7.27767055495927E-5,3.40615311837963E-6,300.0136108,300.0136108,47629.28125,47639.2578125,56.8955215433329,20.5771135894785,23.668306,0,0,0,40,4449,300.2262,47634.26953125,,,,,,,,,,,,,0,,,,0,,,,,,300.0136108,,,,
,32442933.065,300.0094299,51779.578125,-8.30681892411727E-5,2.71485453419524E-6,1,0.999253354069792,40.0298881530762,1.97320203386225,19.5499993860722,-0.000928108767485039,-0.000163890985948516,0.25,-2.68640764960143E-7,-8.30655562256317E-5,-3.23179288944767E-7,300.0094299,300.0094299,51772.0703125,51787.0859375,57.1128142716791,20.575341799275,23.288654,0,0,0,40,4449,300.2167,51779.578125,,,,,,,,,,,,,0,,,,0.00245,,,,,,300.0094299,,,,
,32443019.385,300.013916,56095.171875,-9.84632247734816E-5,3.20673414816648E-6,1,0.999253354069792,40.0298881530762,1.97310387595615,19.5499993860722,-0.00110351862747873,-0.000174308998070132,0.25,1.46587018760603E-6,-9.84612644181767E-5,1.40123642626141E-6,300.013916,300.013916,56085.10546875,56105.23828125,57.0541921327368,20.5762786676685,23.288654,0,0,0,40,4449,300.21,56095.171875,,,,,,,,,,,,,0,,,,-0.00245,,,,,,300.013916,,,,
,32443101.755,300.0115356,60210.71484375,-0.000106253686575452,2.39163184930406E-6,1,0.999253354069792,40.0298881530762,1.97307712529571,19.5499993860722,-0.00119239112312407,-0.000178996774312536,0.25,2.39595944755239E-6,-0.000106252118760776,2.3262558969147E-6,300.0115356,300.0115356,60207.98046875,60213.44921875,56.9643048530253,20.5747510811569,23.668306,0,0,0,40,4449,300.2028,60210.71484375,,,,,,,,,,,,,0,,,,0,,,,,,300.0115356,,,,
,32443186.7,300.0195618,64456.669921875,-0.000128737691426219,2.87009340776995E-6,1,0.999253354069792,40.0298881530762,1.97308123280863,19.5499993860722,-0.00143804886611814,-0.000255332024694516,0.25,-5.37485669596239E-7,-0.000128733508203234,-6.21749766009845E-7,300.0195618,300.0195618,64446.76953125,64466.5703125,57.105779615006,20.5733252848476,22.909004,0,0,0,40,4449,300.20005,64456.669921875,,,,,,,,,,,,,0,,,,-0.00245,,,,,,300.0195618,,,,
,32443268.975,300.0135498,68569.79296875,-0.000136236265173938,3.50058359388227E-6,1,0.999253354069792,40.0298881530762,1.97309578726005,19.5499993860722,-0.00153144409007962,-0.000214667272425546,0.25,4.39947764615725E-6,-0.000136235125266987,4.31024706444718E-6,300.0135498,300.0135498,68564.8046875,68574.78125,56.7180918694675,20.5754165768927,23.288654,0,0,0,40,4449,300.19065,68569.79296875,,,,,,,,,,,,,0,,,,0,,,,,,300.0135498,,,,
,32443349.995,300.0137024,72617.82421875,-0.000149428935090046,2.26990285901745E-6,1,0.999253354069792,40.0298881530762,1.9730993833519,19.5499993860722,-0.00167663683185935,-0.000253407623552978,0.25,3.21945822113889E-6,-0.000149426640093877,3.12173098410086E-6,300.0137024,300.0137024,72612.8359375,72622.8125,57.0221453634483,20.5738429153597,23.288654,0,0,0,40,4449,300.18215,72617.82421875,,,,,,,,,,,,,0,,,,0,,,,,,300.0137024,,,,
,32443433.635,300.0109253,76801.48828125,-0.000164086346965026,3.38833889775076E-6,1,0.999253354069792,40.0298881530762,1.97308522340085,19.5499993860722,-0.00185007476129778,-0.000226372891570988,0.25,8.17704760994594E-6,-0.000164086880259412,8.06970762179147E-6,300.0109253,300.0109253,76796.59375,76806.3828125,56.8931766577752,20.5746387753422,23.288654,0,0,0,40,4449,300.1683,76801.48828125,,,,,,,,,,,,,0,,,,0.0049,,,,,,300.0109253,,,,
,32443518.18,300.0132141,81027.4453125,-0.000173768706484695,4.67960224852126E-6,1,0.999253354069792,40.0298881530762,1.9731952306583,19.5499993860722,-0.00193443015593953,-0.00038356941883519,0.25,-4.20618838632593E-6,-0.000173760872891278,-4.31936572735148E-6,300.0132141,300.0132141,81019.921875,81034.96875,56.7931282073137,20.5733084862029,23.288654,0,0,0,40,4449,300.15995,81027.4453125,,,,,,,,,,,,,0,,,,-0.00245,,,,,,300.0132141,,,,
,32443602.61,300.010376,85245.9296875,-0.000188842839406983,4.31692999615465E-6,1,0.999253354069792,40.0298881530762,1.97320660247804,19.5499993860722,-0.00210041433780463,-0.000427444654240237,0.25,-5.51929319675203E-6,-0.000188833742795606,-5.6421296377215E-6,300.010376,300.010376,85243.5,85248.359375,56.8580033744099,20.5719718494362,23.288654,0,0,0,40,4449,300.15355,85245.9296875,,,,,,,,,,,,,0,,,,0.0049,,,,,,300.010376,,,,
,32443682.04,300.0118408,89216.765625,-0.000201745161998852,4.4643191670408E-6,1,0.999253354069792,40.0298881530762,1.97313010009698,19.5499993860722,-0.00224849209050275,-0.000429767973656177,0.25,-3.49338012473705E-6,-0.000201737012391697,-3.62454678311165E-6,300.0118408,300.0118408,89211.671875,89221.859375,56.7845302936022,20.5738944974648,23.288654,0,0,0,40,4449,300.1448,89216.765625,,,,,,,,,,,,,0,,,,0.00245,,,,,,300.0118408,,,,
,32443698.67,300.0108337,89999.49609375,-0.000210096643367732,3.45084834316222E-6,1,0.999253354069792,40.0298881530762,1.97311266045242,19.5499993860722,-0.00235543921820943,-0.000367393077600212,0.25,3.53295893375236E-6,-0.000210092831978159,3.39618304169561E-6,300.0108337,300.0108337,89999.4921875,89999.5,56.9830639374868,20.5733136653176,23.288654,0,0,0,40,4417,300.14685,89999.49609375,,,,,,,,,,,,,0,,,,-0.0049,,,,,,300.0108337,,,,