File: data/doubleLayers/dl_1-25/ppms/data/DD205_3_FCC_100OE_3_SLOWER.DAT
[Header]
; VSM Data File (default extension .dat)
; Copyright (c) 2003-2013, Quantum Design, Inc. All rights reserved.
TITLE,
FILEOPENTIME,22786473.13,09/22/2018,2:32 am
BYAPP,VSM,2.0,2.0
INFO,PPMS VSM Option Release 1.4.10 Build 1,APPNAME
INFO,Quantum Design Linear Motor Servo Controller,MOTOR_MODULE_NAME
INFO,3101-100 M1,MOTOR_HW_VERSION
INFO,MMC1014,MOTOR_SERIAL_NUMBER
INFO,SRV No X-over 01.03.11,MOTOR_SOFTWARE_VERSION
INFO,Quantum Design VSM Detection Module,VSM_MODULE_NAME
INFO,3101-150 F0,VSM_HW_VERSION
INFO,VSM707,VSM_SERIAL_NUMBER
INFO,VSM No X-over 01.02.05 May 20 2008 13:51:47,VSM_SOFTWARE_VERSION
INFO,704,PREAMP_SERIAL_NUMBER
INFO,822,COIL_SERIAL_NUMBER
INFO,0,MOMENT_UNITS
INFO,,SAMPLE_MATERIAL
INFO,,SAMPLE_COMMENT
INFO,,SAMPLE_MASS
INFO,,SAMPLE_VOLUME
INFO,,SAMPLE_MOLECULAR_WEIGHT
INFO,,SAMPLE_SIZE
INFO,,SAMPLE_SHAPE
DATATYPE,COMMENT,1
DATATYPE,TIME,2
STARTUPAXIS,X,2
STARTUPAXIS,Y1,5
[Data]
Comment,Time Stamp (sec),Temperature (K),Magnetic Field (Oe),Moment (emu),M. Std. Err. (emu),Transport Action,Averaging Time (sec),Frequency (Hz),Peak Amplitude (mm),Center Position (mm),Coil Signal' (mV),Coil Signal" (mV),Range (mV),M. Quad. Signal (emu),M. Raw' (emu),M. Raw" (emu),Min. Temperature (K),Max. Temperature (K),Min. Field (Oe),Max. Field (Oe),Mass (grams),Motor Lag (deg),Pressure (Torr),VSM Status (code),Motor Status (code),Measure Status (code),Measure Count,PPMS Status (code),System Temp. (K),System Field (Oe),Sample Position (deg),Bridge 1 Resistance (ohms),Bridge 1 Excitation (에),Bridge 2 Resistance (ohms),Bridge 2 Excitation (에),Bridge 3 Resistance (ohms),Bridge 3 Excitation (에),Bridge 4 Resistance (ohms),Bridge 4 Excitation (에),Signal 1 Vin (V),Signal 2 Vin (V),Digital Inputs (code),Drive 1 Iout (mA),Drive 1 Ipower (W),Drive 2 Iout (mA),Drive 2 Ipower (W),Pressure (),Map 20 (),Map 21 (),Map 22 (),Map 23 (),Map 24 (),Map 25 (),Map 26 (),Map 27 (),Map 28 (),Map 29 ()
,22787452.915,349.7917175,99.6852722167969,1.50307392248756E-5,4.09674046718329E-7,1,0.999253354069792,40.0298881530762,1.9748589861742,15.1699995622039,0.000168841463696878,2.34931159491373E-5,0.25,-4.99126047963212E-7,1.50044752745179E-5,-4.89891446209213E-7,349.7917175,349.7917175,99.6852722167969,99.6852722167969,56.8197035769676,20.6219373703523,22.909004,0,0,0,40,4369,351.2917,99.6852722167969,,,,,,,,,,,,,0,,,,0,,,,,,349.7917175,,,,
,22787652.6,346.992569,99.6852722167969,1.5706986692953E-5,4.74119119122252E-7,1,0.999253354069792,40.0298881530762,1.97460093537003,15.1699995622039,0.000176171566496527,2.60559869314557E-5,0.25,-3.86811371978035E-7,1.56809482876069E-5,-3.7730547552605E-7,346.970459,347.014679,99.6852722167969,99.6852722167969,56.9275683126214,20.6188436295398,22.909004,0,0,0,40,4370,346.1649,99.6852722167969,,,,,,,,,,,,,0,,,,-0.00245,,,,,,346.992569,,,,
,22787869.735,343.4935913,99.6852722167969,1.56512362513534E-5,3.74306731613832E-7,1,0.999253354069792,40.0298881530762,1.97401961175999,15.1699995622039,0.000175760759297417,2.4555951358941E-5,0.25,-5.11207213659662E-7,1.56272223093578E-5,-5.01487617637681E-7,343.4935913,343.4935913,99.6852722167969,99.6852722167969,56.310081782429,20.6262495393486,22.909004,0,0,0,40,4374,342.52925,99.6852722167969,,,,,,,,,,,,,0,,,,0,,,,,,343.4935913,,,,
,22788094.525,339.9629517,99.6852722167969,1.59758982333696E-5,5.22775839082946E-7,1,0.999253354069792,40.0298881530762,1.97373698769598,15.1699995622039,0.000178050636592932,3.28788337739903E-5,0.25,1.77840698705913E-7,1.59529105291056E-5,1.86810039361616E-7,339.9629517,339.9629517,99.6852722167969,99.6852722167969,56.5531682519098,20.625484778334,22.529354,0,0,0,40,4374,338.5917,99.6852722167969,,,,,,,,,,,,,0,,,,0.0049,,,,,,339.9629517,,,,
,22788279.585,336.9914551,99.6852722167969,1.59309924810112E-5,4.61911388456851E-7,1,0.999253354069792,40.0298881530762,1.99986868331812,15.0699997320771,0.000180752289260489,2.77802344011249E-5,0.25,-3.02383539376404E-7,1.59099722628147E-5,-2.92687950223554E-7,336.9914551,336.9914551,99.6852722167969,99.6852722167969,56.6031924771406,20.6335298554399,22.529354,0,0,0,40,4374,335.4095,99.6852722167969,,,,,,,,,,,,,0,,,,-0.00245,,,,,,336.9914551,,,,
,22788493.97,333.4697266,99.6852722167969,1.6289221611825E-5,4.22396893507725E-7,1,0.999253354069792,40.0298881530762,1.99963609635484,15.0699997320771,0.000185854801088599,2.24227603990433E-5,0.25,-8.38301740304916E-7,1.62700214913881E-5,-8.276709429799E-7,333.4697266,333.4697266,99.6852722167969,99.6852722167969,56.5766171074867,20.6428629309196,22.909004,0,0,0,40,4374,331.78535,99.6852722167969,,,,,,,,,,,,,0,,,,-0.0049,,,,,,333.4697266,,,,
,22788705.865,329.9858398,99.6852722167969,1.69812749171314E-5,4.39702223763663E-7,1,0.999253354069792,40.0298881530762,1.99898630745602,15.0800002738833,0.000193385091712151,2.52718803420882E-5,0.25,-7.05918417582413E-7,1.69632152772859E-5,-6.9500170575455E-7,329.9858398,329.9858398,99.6852722167969,99.6852722167969,56.7360693254098,20.6553439433784,22.909004,0,0,0,40,4374,328.21545,99.6852722167969,,,,,,,,,,,,,0,,,,-0.00245,,,,,,329.9858398,,,,
,22788888.36,326.967865,99.6852722167969,1.69417919994727E-5,4.45229343660069E-7,1,0.999253354069792,40.0298881530762,1.99903107099513,15.089999884367,0.000191532265798122,3.34591448879703E-5,0.25,2.45426705562776E-8,1.69251182859821E-5,3.47523082117308E-8,326.967865,326.967865,99.6852722167969,99.6852722167969,56.7384142109675,20.6511723530218,22.529354,0,0,0,40,4374,325.14105,99.6852722167969,,,,,,,,,,,,,0,,,,0.0049,,,,,,326.967865,,,,
,22789103.445,323.4552307,99.6852722167969,1.71966356185376E-5,3.11134791592474E-7,1,0.999253354069792,40.0298881530762,1.99865716091567,15.089999884367,0.000195635229785564,2.6843668681543E-5,0.25,-6.0461693763485E-7,1.71822068703044E-5,-5.9357403966699E-7,323.4552307,323.4552307,99.6852722167969,99.6852722167969,56.5906864208329,20.6598232259031,22.909004,0,0,0,40,4374,321.51045,99.6852722167969,,,,,,,,,,,,,0,,,,0,,,,,,323.4552307,,,,
,22789315.84,319.9963989,99.6852722167969,1.70480179350317E-5,3.58660979743706E-7,1,0.999253354069792,40.0298881530762,1.9990833895251,15.089999884367,0.000192333924215113,3.62826151148521E-5,0.25,2.54697885221592E-7,1.70352577727796E-5,2.65077732951195E-7,319.9963989,319.9963989,99.6852722167969,99.6852722167969,56.9455457685637,20.6653571784767,22.529354,0,0,0,40,4374,317.928,99.6852722167969,,,,,,,,,,,,,0,,,,0,,,,,,319.9963989,,,,
,22789498.235,316.999176,99.6852722167969,1.72857142224086E-5,4.31472385370262E-7,1,0.999253354069792,40.0298881530762,1.99943424789279,15.1000004261732,0.000195377034355139,3.50192570324382E-5,0.25,1.00866948715156E-7,1.72746965672403E-5,1.11641439984963E-7,316.999176,316.999176,99.6852722167969,99.6852722167969,57.054973761256,20.6623353453529,22.909004,0,0,0,40,4374,314.84045,99.6852722167969,,,,,,,,,,,,,0,,,,-0.0049,,,,,,316.999176,,,,
,22789713.965,313.4743347,99.6852722167969,1.74896427208122E-5,3.64307094390773E-7,1,0.999253354069792,40.0298881530762,1.99954722268005,15.1000004261732,0.000198631796950866,3.01594797177526E-5,0.25,-3.64611543865001E-7,1.74809673220419E-5,-3.5330852816498E-7,313.4743347,313.4743347,99.6852722167969,99.6852722167969,56.9658681100637,20.6591961248474,23.288654,0,0,0,40,4374,311.2011,99.6852722167969,,,,,,,,,,,,,0,,,,-0.0049,,,,,,313.4743347,,,,
,22789927.585,309.9751587,99.6852722167969,1.75477288459178E-5,4.19361172220965E-7,1,0.999253354069792,40.0298881530762,1.99988291979683,15.1000004261732,0.000199415062937424,2.98820734191085E-5,0.25,-4.00092284926091E-7,1.75412241844446E-5,-3.88628988044494E-7,309.9751587,309.9751587,99.6852722167969,99.6852722167969,56.9353845978137,20.6575499077849,23.288654,0,0,0,40,4374,307.5967,99.6852722167969,,,,,,,,,,,,,0,,,,0,,,,,,309.9751587,,,,
,22790109.79,306.9748535,99.6852722167969,1.81510924048887E-5,4.31239050497876E-7,1,0.999253354069792,40.0298881530762,1.99990950800271,15.1199996471405,0.000205372313333448,3.62471628842416E-5,0.25,5.7174699540797E-8,1.81459932097768E-5,6.89968992224612E-8,306.9748535,306.9748535,99.6852722167969,99.6852722167969,56.9893169656406,20.6549523425806,23.288654,0,0,0,40,4374,304.5303,99.6852722167969,,,,,,,,,,,,,0,,,,0.00245,,,,,,306.9748535,,,,
,22790322.565,303.4717712,99.6852722167969,1.79350199351527E-5,4.21463601762245E-7,1,0.999253354069792,40.0298881530762,2.00015241147199,15.1199996471405,0.000204355503969836,2.78641824380285E-5,0.25,-6.46644362065955E-7,1.79326809448844E-5,-6.34680840290493E-7,303.4717712,303.4717712,99.6852722167969,99.6852722167969,57.2292769210445,20.6516378024198,23.288654,0,0,0,40,4374,300.9436,99.6852722167969,,,,,,,,,,,,,0,,,,0,,,,,,303.4717712,,,,
,22790534.505,299.9935608,99.6852722167969,1.85278977492156E-5,3.79165119093336E-7,1,0.999253354069792,40.0298881530762,2.00027180454926,15.1199996471405,0.000211038005540519,2.94320046058733E-5,0.25,-6.11553151868104E-7,1.8527746771966E-5,-5.99102917120096E-7,299.9935608,299.9935608,99.6852722167969,99.6852722167969,56.976810909333,20.6490059779937,22.909004,0,0,0,40,4374,297.385,99.6852722167969,,,,,,,,,,,,,0,,,,0,,,,,,299.9935608,,,,
,22790716.06,296.9829102,99.6852722167969,1.88036906475403E-5,4.10603782938402E-7,1,0.999253354069792,40.0298881530762,2.00029596067005,15.1500003412366,0.00021295134539877,3.71081660772214E-5,0.25,1.78912838113296E-8,1.88051297251638E-5,3.06665850478652E-8,296.9829102,296.9829102,99.6852722167969,99.6852722167969,56.902556200006,20.6421844636905,23.288654,0,0,0,40,4374,294.3323,99.6852722167969,,,,,,,,,,,,,0,,,,-0.0049,,,,,,296.9829102,,,,
,22790929.215,293.490509,99.6852722167969,1.91786676575184E-5,3.58710362338767E-7,1,0.999253354069792,40.0298881530762,2.00034619329299,15.1500003412366,0.000217517921667961,3.61937771312727E-5,0.25,-1.28477763045255E-7,1.91826301485451E-5,-1.152821462839E-7,293.490509,293.490509,99.6852722167969,99.6852722167969,56.8408075469868,20.6434467547851,23.668306,0,0,0,40,4374,290.7542,99.6852722167969,,,,,,,,,,,,,0,,,,0,,,,,,293.490509,,,,
,22791140.7,289.9848938,99.6852722167969,1.87668162972889E-5,3.93391086463115E-7,1,0.999253354069792,40.0298881530762,2.00040605861654,15.1500003412366,0.00021241166055815,3.81223710737104E-5,0.25,1.12424454560923E-7,1.87728821109511E-5,1.25591390277889E-7,289.9848938,289.9848938,99.6852722167969,99.6852722167969,57.0416860764291,20.6420418518359,22.909004,0,0,0,40,4374,287.2078,99.6852722167969,,,,,,,,,,,,,0,,,,0,,,,,,289.9848938,,,,
,22791324.035,286.9638062,99.6852722167969,1.94334219082483E-5,3.90276697793398E-7,1,0.999253354069792,40.0298881530762,2.00052731639512,15.1699995622039,0.000222073268851828,2.74802595533166E-5,0.25,-9.42942891449401E-7,1.94425546278332E-5,-9.29579702713918E-7,286.9638062,286.9638062,99.6852722167969,99.6852722167969,56.9752476522945,20.6419922835396,23.668306,0,0,0,40,4374,284.1331,99.6852722167969,,,,,,,,,,,,,0,,,,-0.00245,,,,,,286.9638062,,,,
,22791534.075,283.4967957,99.6852722167969,2.00321821377291E-5,4.33576684617904E-7,1,0.999253354069792,40.0298881530762,2.00066949691458,15.1699995622039,0.000227893860091475,3.44813974964588E-5,0.25,-4.29694656448817E-7,2.00437034786008E-5,-4.15521965904689E-7,283.4967957,283.4967957,99.6852722167969,99.6852722167969,56.9455457685637,20.6434170475271,23.668306,0,0,0,40,4374,280.6121,99.6852722167969,,,,,,,,,,,,,0,,,,0,,,,,,283.4967957,,,,
,22791746.345,279.9843445,99.6852722167969,1.94043387789162E-5,3.98680292367711E-7,1,0.999253354069792,40.0298881530762,2.0006649262622,15.1699995622039,0.000220972604326886,3.22855094693682E-5,0.25,-5.15184568793702E-7,1.94180166809623E-5,-5.01360298782082E-7,279.9843445,279.9843445,99.6852722167969,99.6852722167969,57.2191157502945,20.6435247325965,23.668306,0,0,0,40,4374,277.0602,99.6852722167969,,,,,,,,,,,,,0,,,,-0.0049,,,,,,279.9843445,,,,
,22791927.5,276.9776917,99.6852722167969,1.93258548342184E-5,4.16206262407676E-7,1,0.999253354069792,40.0298881530762,1.97472479883095,15.2099998667836,0.00021657060602276,3.64084444077081E-5,0.25,-9.81214456038578E-8,1.93412554227568E-5,-8.38907999914331E-8,276.9776917,276.9776917,99.6852722167969,99.6852722167969,57.1065612435253,20.6376590973934,23.668306,0,0,0,40,4374,274.0295,99.6852722167969,,,,,,,,,,,,,0,,,,-0.0049,,,,,,276.9776917,,,,
,22792137.59,273.4970703,99.6852722167969,1.93770483335511E-5,3.8239782908124E-7,1,0.999253354069792,40.0298881530762,1.974718704978,15.2099998667836,0.000217163138763776,3.6552882310018E-5,0.25,-9.47132565130078E-8,1.9394901296121E-5,-8.02302323308888E-8,273.4970703,273.4970703,99.6852722167969,99.6852722167969,56.8673829166406,20.638995269243,23.668306,0,0,0,40,4374,270.5347,99.6852722167969,,,,,,,,,,,,,0,,,,0,,,,,,273.4970703,,,,
,22792348.95,269.9659729,99.6852722167969,1.95981879118485E-5,3.76316090461649E-7,1,0.999253354069792,40.0298881530762,1.97471739167026,15.2099998667836,0.000220446067583612,3.2492799079414E-5,0.25,-4.96226273762272E-7,1.96190254808886E-5,-4.81773052571306E-7,269.9659729,269.9659729,99.6852722167969,99.6852722167969,56.7829670365637,20.6402089883299,23.668306,0,0,0,40,4374,267.0039,99.6852722167969,,,,,,,,,,,,,0,,,,0.0049,,,,,,269.9659729,,,,
,22792528.485,266.9934998,99.6852722167969,1.97116823230324E-5,3.34647201674942E-7,1,0.999253354069792,40.0298881530762,2.00028222747866,15.2399996295571,0.000223689975913137,3.76862024529538E-5,0.25,-9.38117576091333E-8,1.97344237426273E-5,-7.86557713589512E-8,266.9934998,266.9934998,99.6852722167969,99.6852722167969,56.9947883652753,20.642505974559,24.047956,0,0,0,40,4374,264.0081,99.6852722167969,,,,,,,,,,,,,0,,,,-0.00245,,,,,,266.9934998,,,,
,22792741.085,263.4691772,99.6852722167969,1.99925792524469E-5,4.34811082278153E-7,1,0.999253354069792,40.0298881530762,2.00029721019211,15.2399996295571,0.000226426699453971,4.10026308010624E-5,0.25,1.49244158341348E-7,2.00179653241424E-5,1.65169557147844E-7,263.4691772,263.4691772,99.6852722167969,99.6852722167969,56.7079306987175,20.6481095864129,23.668306,0,0,0,40,4374,260.4673,99.6852722167969,,,,,,,,,,,,,0,,,,0.00245,,,,,,263.4691772,,,,
,22792949.285,259.9950562,99.6852722167969,2.06496366155407E-5,3.0176374806045E-7,1,0.999253354069792,40.0298881530762,2.0003822968025,15.2399996295571,0.000234817725545807,3.71024695629847E-5,0.25,-3.09403156823576E-7,2.0678778174952E-5,-2.93319369030822E-7,259.9950562,259.9950562,99.6852722167969,99.6852722167969,56.8376810329099,20.6447775459928,23.288654,0,0,0,40,4374,256.99485,99.6852722167969,,,,,,,,,,,,,0,,,,0,,,,,,259.9950562,,,,
touchdown = 9.4999996945262 mm,22793137.63,256.8613892,99.6852722167969,2.08628535212669E-5,3.00736317890615E-7,1,0.999253354069792,40.0298881530762,2.00032156087717,15.2799999341369,0.000237371203971187,3.68580495813068E-5,0.25,-3.68439057781916E-7,2.08946658229566E-5,-3.52059361238907E-7,256.8613892,256.8613892,99.6852722167969,99.6852722167969,56.9080275996406,20.6444988916428,23.288654,0,0,0,40,4374,253.8505,99.6852722167969,,,,,,,,,,,,,0,,,,0,,,,,,256.8613892,,,,
,22793339.73,253.4923248,99.6852722167969,2.07759366691583E-5,4.00864110575697E-7,1,0.999253354069792,40.0298881530762,2.00028630935505,15.2799999341369,0.000235791834813552,4.02527124632801E-5,0.25,-5.47247383064195E-8,2.08098424574288E-5,-3.76760317062836E-8,253.4923248,253.4923248,99.6852722167969,99.6852722167969,56.8947399148137,20.648781899606,23.668306,0,0,0,40,4374,250.494,99.6852722167969,,,,,,,,,,,,,0,,,,0,,,,,,253.4923248,,,,
,22793549.64,249.9871216,99.6852722167969,2.04053268273045E-5,3.92272496759774E-7,1,0.999253354069792,40.0298881530762,2.00030371314389,15.2799999341369,0.000232702037236039,3.32794297530101E-5,0.25,-6.05831033427263E-7,2.04416169620049E-5,-5.89773627125099E-7,249.9871216,249.9871216,99.6852722167969,99.6852722167969,56.8431524325445,20.6452242397581,23.668306,0,0,0,40,4374,246.9918,99.6852722167969,,,,,,,,,,,,,0,,,,-0.00245,,,,,,249.9871216,,,,
touchdown = 9.53999999910593 mm,22793750.5,246.6355896,99.6852722167969,2.10351969253816E-5,3.87270784948472E-7,1,0.999253354069792,40.0298881530762,1.97464048043606,15.3200002387166,0.000236138326518003,3.87020308995112E-5,0.25,-1.95496446804852E-7,2.10747306278718E-5,-1.77920635219002E-7,246.6355896,246.6355896,99.6852722167969,99.6852722167969,56.6704125297944,20.6357067990581,22.909004,0,0,0,40,4374,243.6309,99.6852722167969,,,,,,,,,,,,,0,,,,-0.0049,,,,,,246.6355896,,,,
,22793939.095,243.4751587,99.6852722167969,2.09402203500031E-5,3.45873869145904E-7,1,0.999253354069792,40.0298881530762,1.9743954361795,15.3200002387166,0.000234891279744682,3.95588678742466E-5,0.25,-1.02822045585458E-7,2.09818194423755E-5,-8.48849498432917E-8,243.4751587,243.4751587,99.6852722167969,99.6852722167969,57.126101956506,20.6391647335619,23.288654,0,0,0,40,4374,240.5025,99.6852722167969,,,,,,,,,,,,,0,,,,-0.0049,,,,,,243.4751587,,,,
,22794147.375,239.99647525,99.6852722167969,2.03438373729531E-5,4.27984438571956E-7,1,0.999253354069792,40.0298881530762,1.97437870614209,15.3200002387166,0.000228947557710838,3.42851447524346E-5,0.25,-4.70570928072243E-7,2.03870517046402E-5,-4.53624758708323E-7,239.9781647,240.0147858,99.6852722167969,99.6852722167969,56.8454973181022,20.6399760356021,23.288654,0,0,0,40,4374,237.0291,99.6852722167969,,,,,,,,,,,,,0,,,,-0.0049,,,,,,239.99647525,,,,
,22794352.41,236.5902252,99.6852722167969,,,2,,,,15.3799999141693,,,,,,,236.5902252,236.5902252,99.6852722167969,99.6852722167969,,,23.288654,,,,-99999999,4374,233.6026,99.6852722167969,,,,,,,,,,,,,,,,,,,,,,,236.5902252,,,,
,22794538.225,233.4803925,99.6852722167969,2.0672748342846E-5,4.01387828075358E-7,1,0.999253354069792,40.0298881530762,2.00029518664479,15.37000015378,0.000234510837724266,4.16654393268888E-5,0.25,8.33419495672545E-8,2.07208366885784E-5,1.02388087593053E-7,233.4803925,233.4803925,99.6852722167969,99.6852722167969,56.9697762526599,20.6420578085895,22.909004,0,0,0,40,4374,230.49965,99.6852722167969,,,,,,,,,,,,,0,,,,0.0049,,,,,,233.4803925,,,,
,22794748.11,229.9815979,99.6852722167969,2.06392907582663E-5,3.58083120514696E-7,1,0.999253354069792,40.0298881530762,2.00050109304937,15.37000015378,0.000235307669580374,3.51226940680156E-5,0.25,-4.88235080662058E-7,2.06903171918318E-5,-4.70258385115308E-7,229.9815979,229.9815979,99.6852722167969,99.6852722167969,57.0901470446214,20.6421292765202,22.909004,0,0,0,40,4374,227.0077,99.6852722167969,,,,,,,,,,,,,0,,,,-0.00245,,,,,,229.9815979,,,,
,22794968.09,226.3221893,99.6852722167969,,,2,,,,15.4299998292327,,,,,,,226.3221893,226.3221893,99.6852722167969,99.6852722167969,,,22.909004,,,,-99999999,4374,223.338,99.6852722167969,,,,,,,,,,,,,,,,,,,,,,,226.3221893,,,,
,22795136.23,223.4887238,99.6852722167969,2.08388199692654E-5,3.63711864316948E-7,1,0.999253354069792,40.0298881530762,2.00015100486773,15.4200000688434,0.000238378188655927,3.09549636998364E-5,0.25,-8.90761075139117E-7,2.08953584902895E-5,-8.73088260575013E-7,223.4887238,223.4887238,99.6852722167969,99.6852722167969,57.0924919301791,20.6423693619738,23.288654,0,0,0,40,4374,220.5291,99.6852722167969,,,,,,,,,,,,,0,,,,-0.0049,,,,,,223.4887238,,,,
,22795345.67,219.9996948,99.6852722167969,2.08978759788096E-5,3.93958534570085E-7,1,0.999253354069792,40.0298881530762,2.00036114090573,15.4200000688434,0.000238181203459276,3.63773414675162E-5,0.25,-4.2456680326949E-7,2.09565978914556E-5,-4.05245534490344E-7,219.9996948,219.9996948,99.6852722167969,99.6852722167969,57.1018714724099,20.6445734717244,22.529354,0,0,0,40,4374,217.04195,99.6852722167969,,,,,,,,,,,,,0,,,,-0.0049,,,,,,219.9996948,,,,
,22795555.71,216.48477935,99.6852722167969,2.07522462454356E-5,3.59350246562777E-7,1,0.999253354069792,40.0298881530762,2.00034536172966,15.4200000688434,0.000236848811053078,3.43925976045536E-5,0.25,-5.74785115017132E-7,2.08131702793006E-5,-5.55682742268147E-7,216.4676208,216.5019379,99.6852722167969,99.6852722167969,56.8462789466214,20.6467633873879,22.529354,0,0,0,40,4374,213.5415,99.6852722167969,,,,,,,,,,,,,0,,,,-0.00245,,,,,,216.48477935,,,,
,22795735.595,213.4714966,99.6852722167969,2.10321381366305E-5,4.33657336310636E-7,1,0.999253354069792,40.0298881530762,1.97458101803518,15.4600003734231,0.000236785125344788,3.63226536127227E-5,0.25,-4.1431015787156E-7,2.10958360115268E-5,-3.94132091978387E-7,213.4714966,213.4714966,99.6852722167969,99.6852722167969,56.7157469839098,20.6361994742944,22.529354,0,0,0,40,4374,210.54515,99.6852722167969,,,,,,,,,,,,,0,,,,-0.00245,,,,,,213.4714966,,,,
,22795942.96,209.9989014,99.6852722167969,2.11541838783885E-5,3.79341750518581E-7,1,0.999253354069792,40.0298881530762,1.97452459185374,15.4600003734231,0.000237567212819943,4.00657835633002E-5,0.25,-1.02638733999938E-7,2.12203645890797E-5,-8.09640509773087E-8,209.9989014,209.9989014,99.6852722167969,99.6852722167969,56.6625962446021,20.6414698558099,22.149702,0,0,0,40,4374,207.09345,99.6852722167969,,,,,,,,,,,,,0,,,,0.00245,,,,,,209.9989014,,,,
,22796154.255,206.4835968,99.6852722167969,2.12052367015557E-5,3.79289381970609E-7,1,0.999253354069792,40.0298881530762,1.97439040814983,15.4600003734231,0.000239057556240973,3.49529340756712E-5,0.25,-5.67791533807312E-7,2.12745181597205E-5,-5.47105682275343E-7,206.4835968,206.4835968,99.6852722167969,99.6852722167969,56.5578580230252,20.6427518797531,22.149702,0,0,0,40,4374,203.5753,99.6852722167969,,,,,,,,,,,,,0,,,,0,,,,,,206.4835968,,,,
,22796331.625,203.4985962,99.6852722167969,2.10315164392247E-5,3.09512777922424E-7,1,0.999253354069792,40.0298881530762,2.00024789116602,15.5100002884865,0.000239076886459654,4.092017532869E-5,0.25,-5.16390109409931E-8,2.11017299454912E-5,-2.90573814673886E-8,203.4985962,203.4985962,99.6852722167969,99.6852722167969,57.075296102756,20.6496381486819,22.529354,0,0,0,40,4374,200.6215,99.6852722167969,,,,,,,,,,,,,0,,,,0,,,,,,203.4985962,,,,
,22796541.785,199.9778748,99.6852722167969,2.08666196349856E-5,3.31603959503388E-7,1,0.999253354069792,40.0298881530762,2.00018933419463,15.5100002884865,0.000237942288009875,3.64599698056003E-5,0.25,-4.16306622374602E-7,2.09390550046318E-5,-3.94659841500061E-7,199.9778748,199.9778748,99.6852722167969,99.6852722167969,56.9799374234099,20.6496608721485,21.770052,0,0,0,40,4374,197.1235,99.6852722167969,,,,,,,,,,,,,0,,,,0.0049,,,,,,199.9778748,,,,
,22796751.1,196.4916382,99.6852722167969,2.07792375998833E-5,4.05159083900264E-7,1,0.999253354069792,40.0298881530762,1.99995319352977,15.5100002884865,0.000237056876312812,3.56664069684336E-5,0.25,-4.71481031036575E-7,2.08537536370439E-5,-4.49645163897958E-7,196.4916382,196.4916382,99.6852722167969,99.6852722167969,56.9346029692945,20.648250533887,21.770052,0,0,0,40,4374,193.6343,99.6852722167969,,,,,,,,,,,,,0,,,,0,,,,,,196.4916382,,,,
,22796932.305,193.4706421,99.6852722167969,2.08140858101674E-5,4.08342629000797E-7,1,0.999253354069792,40.0298881530762,2.00013458736686,15.5699998140335,0.000236580510505485,4.10109624407093E-5,0.25,-8.3416630737594E-9,2.08901853971995E-5,1.56610770099917E-8,193.4706421,193.4706421,99.6852722167969,99.6852722167969,56.9267866841022,20.6477265842381,22.149702,0,0,0,40,4374,190.6163,99.6852722167969,,,,,,,,,,,,,0,,,,-0.00245,,,,,,193.4706421,,,,
,22797140.725,189.9689102,99.6852722167969,2.09184477254353E-5,3.26838298748561E-7,1,0.999253354069792,40.0298881530762,2.00011698660058,15.5699998140335,0.000238732208371837,3.58027849716352E-5,0.25,-4.8561162058696E-7,2.09977788598392E-5,-4.62705862718719E-7,189.9540863,189.9837341,99.6852722167969,99.6852722167969,56.872072687756,20.6511626727708,22.529354,0,0,0,40,4374,187.14705,99.6852722167969,,,,,,,,,,,,,0,,,,0.00245,,,,,,189.9689102,,,,
,22797349.775,186.4807892,99.6852722167969,2.09364463366444E-5,3.26737371060735E-7,1,0.999253354069792,40.0298881530762,2.00007810606951,15.5699998140335,0.000238831195456227,3.6571603465213E-5,0.25,-4.21997934906207E-7,2.10180310384448E-5,-3.98262153610295E-7,186.4807892,186.4807892,99.6852722167969,99.6852722167969,56.8580033744099,20.646686777888,21.770052,0,0,0,40,4374,183.6613,99.6852722167969,,,,,,,,,,,,,0,,,,0.0049,,,,,,186.4807892,,,,
,22797528.15,183.4985657,99.6852722167969,2.02347729709859E-5,3.05865599030767E-7,1,0.999253354069792,40.0298881530762,2.00003835932687,15.6199997290969,0.000230684295063961,3.62642628388324E-5,0.25,-3.27825740519952E-7,2.0315369980545E-5,-3.04074037651179E-7,183.4985657,183.4985657,99.6852722167969,99.6852722167969,56.9424192544868,20.6502215225749,21.770052,0,0,0,40,4374,180.6939,99.6852722167969,,,,,,,,,,,,,0,,,,0.00245,,,,,,183.4985657,,,,
,22797740.505,179.9630737,99.6852722167969,2.06959675038687E-5,3.35800917210011E-7,1,0.999253354069792,40.0298881530762,1.99993866195746,15.6199997290969,0.000235688877254178,3.86286794061804E-5,0.25,-2.00901398946686E-7,2.07804347766503E-5,-1.75409353827876E-7,179.9630737,179.9630737,99.6852722167969,99.6852722167969,56.8103240347368,20.6515424932543,22.149702,0,0,0,40,4374,177.1267,99.6852722167969,,,,,,,,,,,,,0,,,,-0.00245,,,,,,179.9630737,,,,
,22797946.12,176.491745,99.6852722167969,2.04233426359068E-5,3.29415659368084E-7,1,0.999253354069792,40.0298881530762,1.99972956997828,15.6199997290969,0.000232736129498281,3.72499955487908E-5,0.25,-2.75447896881476E-7,2.05089004670882E-5,-2.49954831260692E-7,176.491745,176.491745,99.6852722167969,99.6852722167969,57.2277136640061,20.6566622264779,21.3904,0,0,0,40,4374,173.7521,99.6852722167969,,,,,,,,,,,,,0,,,,0.0049,,,,,,176.491745,,,,
,22798124.125,173.4782867,99.6852722167969,2.0649329299145E-5,3.83744159264638E-7,1,0.999253354069792,40.0298881530762,1.99952328084123,15.6900007277727,0.000235506542041589,3.65253916679926E-5,0.25,-3.79077659242632E-7,2.07377876283374E-5,-3.53124893860538E-7,173.4782867,173.4782867,99.6852722167969,99.6852722167969,57.0573186468137,20.6572990975861,21.3904,0,0,0,40,4374,170.8125,99.6852722167969,,,,,,,,,,,,,0,,,,-0.0049,,,,,,173.4782867,,,,
,22798334.42,169.9689178,99.6852722167969,2.07617636418844E-5,3.03006780319165E-7,1,0.999253354069792,40.0298881530762,1.99951445957767,15.6900007277727,0.000237075718798147,3.52102442116824E-5,0.25,-5.15407785597894E-7,2.08529845038391E-5,-4.89139177045725E-7,169.9689178,169.9689178,99.6852722167969,99.6852722167969,56.7337244398522,20.657471060322,21.3904,0,0,0,40,4374,167.3098,99.6852722167969,,,,,,,,,,,,,0,,,,0,,,,,,169.9689178,,,,
,22798543.97,166.486618,99.6852722167969,2.03356402187233E-5,3.24253406637903E-7,1,0.999253354069792,40.0298881530762,1.99942028690664,15.6900007277727,0.000231929254475322,3.61728772230439E-5,0.25,-3.57596383432856E-7,2.04267837304391E-5,-3.30428087207798E-7,166.486618,166.486618,99.6852722167969,99.6852722167969,57.1534589546791,20.6570044460447,21.770052,0,0,0,40,4374,163.8054,99.6852722167969,,,,,,,,,,,,,0,,,,0.0049,,,,,,166.486618,,,,
,22798724.15,163.4628601,99.6852722167969,2.04648972231166E-5,3.37942629553684E-7,1,0.999253354069792,40.0298881530762,1.9993992394949,15.7500002533197,0.000233726752505541,3.46463908792404E-5,0.25,-5.15324377824489E-7,2.05585589086343E-5,-4.87956745134025E-7,163.4628601,163.4628601,99.6852722167969,99.6852722167969,56.5930313063906,20.660459217309,21.770052,0,0,0,40,4374,160.7967,99.6852722167969,,,,,,,,,,,,,0,,,,0,,,,,,163.4628601,,,,
,22798932.225,159.9983063,99.6852722167969,2.03514498501455E-5,3.39219328879378E-7,1,0.999253354069792,40.0298881530762,1.99931498790657,15.7500002533197,0.000232255822447511,3.55344295940658E-5,0.25,-4.18567740626611E-7,2.04463696642807E-5,-3.90037623543027E-7,159.9983063,159.9983063,99.6852722167969,99.6852722167969,56.6915164998137,20.660020589972,21.01075,0,0,0,40,4374,157.33335,99.6852722167969,,,,,,,,,,,,,0,,,,-0.0049,,,,,,159.9983063,,,,
,22799142.06,156.4770508,99.6852722167969,2.07137116353132E-5,2.69521371744991E-7,1,0.999253354069792,40.0298881530762,1.99933273047328,15.7500002533197,0.000236696218294655,3.45503383158324E-5,0.25,-5.69499620515937E-7,2.08124763433361E-5,-5.40163496017427E-7,156.4770508,156.4770508,99.6852722167969,99.6852722167969,56.607882248256,20.6563531287466,21.770052,0,0,0,40,4374,153.8449,99.6852722167969,,,,,,,,,,,,,0,,,,-0.0049,,,,,,156.4770508,,,,
,22799320.985,153.4848328,99.6852722167969,2.07268709919246E-5,3.34338692043808E-7,1,0.999253354069792,40.0298881530762,1.99945482185141,15.820000320673,0.000236883376151625,3.4550217955294E-5,0.25,-5.73130277203994E-7,2.08273131481461E-5,-5.42912426522716E-7,153.4848328,153.4848328,99.6852722167969,99.6852722167969,56.6641595016406,20.6639567060805,21.3904,0,0,0,40,4374,150.8732,99.6852722167969,,,,,,,,,,,,,0,,,,-0.0049,,,,,,153.4848328,,,,
,22799529.12,149.9665375,99.6852722167969,2.05229337944207E-5,3.25058686019069E-7,1,0.999253354069792,40.0298881530762,1.99959051442417,15.820000320673,0.000234172397977203,3.66039101806166E-5,0.25,-3.58657979321813E-7,2.06238708833205E-5,-3.26634881168435E-7,149.9665375,149.9665375,99.6852722167969,99.6852722167969,56.7853119221214,20.6618952665911,20.631098,0,0,0,40,4374,147.42405,99.6852722167969,,,,,,,,,,,,,0,,,,0,,,,,,149.9665375,,,,
,22799737.89,146.4772034,99.6852722167969,2.0886602271971E-5,3.22002602349934E-7,1,0.999253354069792,40.0298881530762,1.99918710841108,15.8099997788668,0.000238674969383806,3.50756845030403E-5,0.25,-5.57276457494031E-7,2.09914257922734E-5,-5.24430574539985E-7,146.4772034,146.4772034,99.6852722167969,99.6852722167969,56.8306463762368,20.6632957765258,20.631098,0,0,0,40,4374,143.96025,99.6852722167969,,,,,,,,,,,,,0,,,,0.0049,,,,,,146.4772034,,,,
,22799917.235,143.473053,99.6852722167969,2.06948987860693E-5,3.22982274219281E-7,1,0.999253354069792,40.0298881530762,1.99920802894913,15.87999984622,0.000235776293825273,3.89263632355373E-5,0.25,-1.86715079432758E-7,2.0799586157862E-5,-1.51231102569903E-7,143.473053,143.473053,99.6852722167969,99.6852722167969,56.5007991411214,20.6631718954625,21.01075,0,0,0,40,4374,140.97755,99.6852722167969,,,,,,,,,,,,,0,,,,-0.00245,,,,,,143.473053,,,,
,22800124.65,139.99656675,99.6852722167969,2.05823058593785E-5,2.80304107202561E-7,1,0.999253354069792,40.0298881530762,1.99904837033614,15.87999984622,0.000234699263913708,3.75371729208999E-5,0.25,-2.90605271986073E-7,2.06882185474354E-5,-2.54463563063038E-7,139.9802551,140.0128784,99.6852722167969,99.6852722167969,56.7102755842752,20.6653778885851,21.01075,0,0,0,40,4374,137.52535,99.6852722167969,,,,,,,,,,,,,0,,,,0,,,,,,139.99656675,,,,
,22800335.535,136.4705048,99.6852722167969,2.0642706753804E-5,3.76614451995179E-7,1,0.999253354069792,40.0298881530762,1.99891938332234,15.87999984622,0.000235323986224602,3.80332452791852E-5,0.25,-2.59111556755729E-7,2.07504286792412E-5,-2.21172207946042E-7,136.4705048,136.4705048,99.6852722167969,99.6852722167969,57.1675282680253,20.6655289160763,21.3904,0,0,0,40,4374,134.0184,99.6852722167969,,,,,,,,,,,,,0,,,,0.00245,,,,,,136.4705048,,,,
,22800512.86,133.4806976,99.6852722167969,2.06535769584003E-5,3.38581997816173E-7,1,0.999253354069792,40.0298881530762,1.99916316252693,15.9499999135733,0.000236097119110686,3.45804630104193E-5,0.25,-5.6648231441616E-7,2.07632188505763E-5,-5.28754887164574E-7,133.4806976,133.4806976,99.6852722167969,99.6852722167969,56.5727089648906,20.6680495712045,20.251448,0,0,0,40,4374,131.0754,99.6852722167969,,,,,,,,,,,,,0,,,,0.0049,,,,,,133.4806976,,,,
,22800721.415,129.9976501,99.6852722167969,2.0791681627014E-5,3.22337391341847E-7,1,0.999253354069792,40.0298881530762,1.99914056364328,15.9499999135733,0.000237272397430247,3.7200542287019E-5,0.25,-3.62254862191E-7,2.09030389513576E-5,-3.21417413327727E-7,129.9976501,129.9976501,99.6852722167969,99.6852722167969,56.7970363499099,20.665732337901,21.01075,0,0,0,40,4374,127.61055,99.6852722167969,,,,,,,,,,,,,0,,,,0.00245,,,,,,129.9976501,,,,
,22800931.46,126.4664841,99.6852722167969,2.06318590278495E-5,3.24754456958392E-7,1,0.999253354069792,40.0298881530762,1.99921652345985,15.9499999135733,0.000234898197051826,4.02004826942038E-5,0.25,-7.29306433111682E-8,2.0743044732521E-5,-2.89471427996824E-8,126.4664841,126.4664841,99.6852722167969,99.6852722167969,57.2667950899676,20.6653566967379,20.631098,0,0,0,40,4374,124.1315,99.6852722167969,,,,,,,,,,,,,0,,,,-0.00245,,,,,,126.4664841,,,,
,22801137.615,122.996376,99.6852722167969,2.06224813641487E-5,2.71176904098556E-7,1,0.999253354069792,40.0298881530762,1.99917970976455,16.0099994391203,0.0002360776927736,3.28789925421024E-5,0.25,-7.16935427500086E-7,2.07362021616884E-5,-6.74406340244002E-7,122.996376,122.996376,99.6852722167969,99.6852722167969,56.8798889729483,20.6656670104355,20.631098,0,0,0,40,4374,120.725,99.6852722167969,,,,,,,,,,,,,0,,,,0,,,,,,122.996376,,,,
,22801346.055,119.4834518,99.6852722167969,2.08088119447045E-5,2.98689863615515E-7,1,0.999253354069792,40.0298881530762,1.99904116396305,16.0099994391203,0.000237467121092919,3.74065833624205E-5,0.25,-3.53854385113507E-7,2.09237844473115E-5,-3.0664100714462E-7,119.4834518,119.4834518,99.6852722167969,99.6852722167969,56.8572217458906,20.6606666726599,20.251448,0,0,0,40,4374,117.28095,99.6852722167969,,,,,,,,,,,,,0,,,,-0.00245,,,,,,119.4834518,,,,
,22801552.69,115.9922333,99.6852722167969,2.06631127555075E-5,2.99085953955972E-7,1,0.999253354069792,40.0298881530762,1.99904366634993,16.0099994391203,0.000236087031122078,3.55926225233539E-5,0.25,-4.9039220719474E-7,2.07785215927625E-5,-4.4181234932374E-7,115.9922333,115.9922333,99.6852722167969,99.6852722167969,57.3824761108138,20.6606341499192,20.631098,0,0,0,40,4374,113.8794,99.6852722167969,,,,,,,,,,,,,0,,,,-0.00245,,,,,,115.9922333,,,,
,22801730.94,112.983963,99.6852722167969,2.10507215806061E-5,3.24467092803092E-7,1,0.999253354069792,40.0298881530762,1.99934454370544,16.0799995064735,0.000240381485562119,3.72728043444222E-5,0.25,-4.13537087174118E-7,2.11687337297796E-5,-3.61207709106288E-7,112.983963,112.983963,99.6852722167969,99.6852722167969,56.9807190519291,20.6627023677707,20.251448,0,0,0,40,4374,110.9468,99.6852722167969,,,,,,,,,,,,,0,,,,0,,,,,,112.983963,,,,
,22801939.095,109.4812088,99.6852722167969,2.04785511558648E-5,2.61615355631073E-7,1,0.999253354069792,40.0298881530762,1.99901877918412,16.0799995064735,0.000233720911889131,3.68069419738613E-5,0.25,-3.56738381458003E-7,2.05937762097131E-5,-3.0262395147223E-7,109.4812088,109.4812088,99.6852722167969,99.6852722167969,57.1300100991022,20.6623254440492,20.251448,0,0,0,40,4374,107.5067,99.6852722167969,,,,,,,,,,,,,0,,,,-0.00245,,,,,,109.4812088,,,,
,22802145.025,105.9941101,99.6852722167969,2.07756247776911E-5,2.35299017665278E-7,1,0.999253354069792,40.0298881530762,1.99899737698411,16.0799995064735,0.000236420087651451,4.1286731691075E-5,0.25,-1.83806062807825E-8,2.08918467477617E-5,4.17005764225105E-8,105.9941101,105.9941101,99.6852722167969,99.6852722167969,56.9424192544868,20.6633035565948,19.871798,0,0,0,40,4374,104.1177,99.6852722167969,,,,,,,,,,,,,0,,,,-0.0049,,,,,,105.9941101,,,,
touchdown = 10.3700002655387 mm,22802324.875,102.9793701,99.6852722167969,2.06860933216938E-5,3.0844605908587E-7,1,0.999253354069792,40.0298881530762,1.99892045529522,16.1499995738268,0.000235915668154601,3.81300419344765E-5,0.25,-2.83089475066613E-7,2.08026087385688E-5,-2.2162794861656E-7,102.9793701,102.9793701,99.6852722167969,99.6852722167969,56.9009929429675,20.6564298063949,19.871798,0,0,0,40,4374,101.1544,99.6852722167969,,,,,,,,,,,,,0,,,,0,,,,,,102.9793701,,,,
,22802532.91,99.4999008,99.6852722167969,2.07956742748697E-5,2.91183873315297E-7,1,0.999253354069792,40.0298881530762,1.99891887116165,16.1499995738268,0.0002372501984193,3.78300132054819E-5,0.25,-3.32661019350767E-7,2.09126659192163E-5,-2.67123354131132E-7,99.4999008,99.4999008,99.6852722167969,99.6852722167969,57.3050948874099,20.6629434387973,19.871798,0,0,0,40,4374,97.7056,99.6852722167969,,,,,,,,,,,,,0,,,,0.00245,,,,,,99.4999008,,,,
,22802743.605,95.96206665,99.6852722167969,2.04308027902271E-5,3.08123771893718E-7,1,0.999253354069792,40.0298881530762,1.99916524828165,16.1499995738268,0.000233463740327889,3.51445627357912E-5,0.25,-5.0923790626061E-7,2.05456695025718E-5,-4.41387063237417E-7,95.9399567,95.9841766,99.6852722167969,99.6852722167969,57.2128627221407,20.6649360336053,19.871798,0,0,0,40,4374,94.1924,99.6852722167969,,,,,,,,,,,,,0,,,,-0.00245,,,,,,95.96206665,,,,
touchdown = 10.4400003328919 mm,22802942.43,92.6444321,99.6852722167969,2.0727280999318E-5,3.06856647275912E-7,1,0.999253354069792,40.0298881530762,1.99893052719587,16.21999964118,0.000236685219936029,3.63724016683596E-5,0.25,-4.57686807253314E-7,2.0842503709006E-5,-3.83798778847951E-7,92.6444321,92.6444321,99.6852722167969,99.6852722167969,57.2363115777176,20.6564013061184,19.492144,0,0,0,40,4374,90.9034,99.6852722167969,,,,,,,,,,,,,0,,,,0,,,,,,92.6444321,,,,
,22803128.58,89.48236465,99.6852722167969,2.05605516298391E-5,2.79109433728875E-7,1,0.999253354069792,40.0298881530762,1.99889696550654,16.21999964118,0.000234163525742609,3.94589001577051E-5,0.25,-1.61396609925504E-7,2.06722055506449E-5,-8.16925901994469E-8,89.4595795,89.5051498,99.6852722167969,99.6852722167969,56.8048526351022,20.6625082890003,19.871798,0,0,0,40,4374,87.83365,99.6852722167969,,,,,,,,,,,,,0,,,,0.00245,,,,,,89.48236465,,,,
,22803335.28,85.9720306,99.6852722167969,2.06411864314632E-5,3.48794228938623E-7,1,0.999253354069792,40.0298881530762,1.9989127393758,16.2300001829863,0.000235178578082807,3.892042760306E-5,0.25,-2.28427840635136E-7,2.07511549514396E-5,-1.42912663636616E-7,85.9720306,85.9720306,99.6852722167969,99.6852722167969,57.2066096939868,20.6623030873599,19.112494,0,0,0,40,4374,84.461,99.6852722167969,,,,,,,,,,,,,0,,,,0,,,,,,85.9720306,,,,
,22803530.7,82.6333313,99.6852722167969,,,2,,,,16.3000004002452,,,,,,,82.6333313,82.6333313,99.6852722167969,99.6852722167969,,,19.112494,,,,-99999999,4374,81.263,99.6852722167969,,,,,,,,,,,,,,,,,,,,,,,82.6333313,,,,
,22803716.875,79.4773254,99.6852722167969,2.05634572080191E-5,3.17296354232787E-7,1,0.999253354069792,40.0298881530762,1.99865953822243,16.2899997085333,0.000234854517231321,3.49947910747194E-5,0.25,-5.70888706299603E-7,2.06677359622898E-5,-4.74935858186742E-7,79.4773254,79.4773254,99.6852722167969,99.6852722167969,56.7079306987175,20.6667442761665,19.112494,0,0,0,40,4374,78.2084,99.6852722167969,,,,,,,,,,,,,0,,,,-0.0049,,,,,,79.4773254,,,,
,22803923.41,75.9667664,99.6852722167969,2.04586356145149E-5,2.63963032769995E-7,1,0.999253354069792,40.0298881530762,1.99849357711823,16.2899997085333,0.000232651096836106,4.00149780007748E-5,0.25,-1.16857050301526E-7,2.05546509093431E-5,-1.15998585711463E-8,75.9667664,75.9667664,99.6852722167969,99.6852722167969,56.8963031718522,20.667919894145,18.732843,0,0,0,40,4374,74.8246,99.6852722167969,,,,,,,,,,,,,0,,,,-0.00245,,,,,,75.9667664,,,,
,22804136.67,72.3772049,99.6852722167969,,,2,,,,16.3599999257922,,,,,,,72.3772049,72.3772049,99.6852722167969,99.6852722167969,,,18.353191,,,,-99999999,4374,71.3206,99.6852722167969,,,,,,,,,,,,,,,,,,,,,,,72.3772049,,,,
,22804309.88,69.4692612,99.6852722167969,2.08175636854947E-5,2.52092006569234E-7,1,0.999253354069792,40.0298881530762,1.99862931371583,16.3499992340803,0.000236488246291828,4.11634019577955E-5,0.25,-9.29591661322181E-8,2.08995400015551E-5,3.0117349831535E-8,69.4692612,69.4692612,99.6852722167969,99.6852722167969,56.9603967104291,20.6675167145088,18.732843,0,0,0,40,4374,68.4397,99.6852722167969,,,,,,,,,,,,,0,,,,-0.0049,,,,,,69.4692612,,,,
,22804517.395,65.9840927,99.6852722167969,2.10784980167416E-5,3.51131303752219E-7,1,0.999253354069792,40.0298881530762,1.99842888066871,16.3499992340803,0.000239946887293909,3.802090199009E-5,0.25,-4.23138504264624E-7,2.11517765132781E-5,-2.90739208670608E-7,65.9840927,65.9840927,99.6852722167969,99.6852722167969,57.2581971762561,20.6677283054062,18.732843,0,0,0,40,4374,65.00745,99.6852722167969,,,,,,,,,,,,,0,,,,0,,,,,,65.9840927,,,,
,22804723.94,62.4835434,99.6852722167969,2.1065795528513E-5,2.39546834564744E-7,1,0.999253354069792,40.0298881530762,1.99832551607706,16.3499992340803,0.000239317040319723,3.97138690720957E-5,0.25,-2.77427911701109E-7,2.11238443735296E-5,-1.36153253604046E-7,62.4835434,62.4835434,99.6852722167969,99.6852722167969,57.4801796757176,20.6692846462054,17.973541,0,0,0,40,4370,61.61605,99.6852722167969,,,,,,,,,,,,,0,,,,0,,,,,,62.4835434,,,,
,22804901.77,59.4682083,99.6852722167969,2.09666705805774E-5,3.89449350359519E-7,1,0.999253354069792,40.0298881530762,1.99825412941628,16.4100006222725,0.000238334715974142,3.7744943549269E-5,0.25,-4.3727444822738E-7,2.10111103335067E-5,-2.90569120600364E-7,59.4682083,59.4682083,99.6852722167969,99.6852722167969,57.3160376866791,20.6665315017306,17.593889,0,0,0,40,4370,58.6926,99.6852722167969,,,,,,,,,,,,,0,,,,-0.00245,,,,,,59.4682083,,,,
,22805108.525,55.9933853,99.6852722167969,2.07724951848306E-5,3.7425216313885E-7,1,0.999253354069792,40.0298881530762,1.99824038453412,16.4100006222725,0.000234833535613839,4.33378044883792E-5,0.25,8.95037194957095E-8,2.07936274233686E-5,2.41220645002604E-7,55.9933853,55.9933853,99.6852722167969,99.6852722167969,57.1690915250637,20.6688666078562,17.973541,0,0,0,40,4370,55.2893,99.6852722167969,,,,,,,,,,,,,0,,,,-0.0049,,,,,,55.9933853,,,,
,22805316.36,52.4945641,99.6852722167969,2.06265195950133E-5,2.8755991367591E-7,1,0.999253354069792,40.0298881530762,1.99836629826149,16.4100006222725,0.000233644273296592,3.91783475660104E-5,0.25,-2.51393015216462E-7,2.06287335804881E-5,-9.80976285828143E-8,52.4945641,52.4945641,99.6852722167969,99.6852722167969,57.1745629246983,20.6651503829302,17.214239,0,0,0,40,4370,51.8484,99.6852722167969,,,,,,,,,,,,,0,,,,0,,,,,,52.4945641,,,,
,22805494.035,49.4782181,99.6852722167969,2.0880148120696E-5,3.12440197477936E-7,1,0.999253354069792,40.0298881530762,1.99835559795616,16.4700001478195,0.000236027776805294,4.1130610684414E-5,0.25,-1.20900561704681E-7,2.08622740406967E-5,3.41264028423603E-8,49.4782181,49.4782181,99.6852722167969,99.6852722167969,57.054973761256,20.6650633592078,16.834587,0,0,0,40,4370,48.922,99.6852722167969,,,,,,,,,,,,,0,,,,0.0049,,,,,,49.4782181,,,,
,22805700.5,45.99139025,99.6852722167969,2.10522360592235E-5,3.42878182641986E-7,1,0.999253354069792,40.0298881530762,1.99844191291257,16.4700001478195,0.000238073049614212,3.95356003063431E-5,0.25,-2.86290194286047E-7,2.10132898723718E-5,-1.33021088941136E-7,45.9731255,46.009655,99.6852722167969,99.6852722167969,57.0823307594291,20.6668111336294,16.834587,0,0,0,40,4370,45.52435,99.6852722167969,,,,,,,,,,,,,0,,,,-0.00245,,,,,,45.99139025,,,,
,22805908.275,42.4760933,99.6852722167969,2.11928521864074E-5,2.7466643958499E-7,1,0.999253354069792,40.0298881530762,1.99845619202551,16.4700001478195,0.000239196914045835,4.10495596346169E-5,0.25,-1.67434062060678E-7,2.11319975457674E-5,-1.97578500084364E-8,42.4760933,42.4760933,99.6852722167969,99.6852722167969,57.0424677049483,20.6650202701642,16.454937,0,0,0,40,4370,42.10275,99.6852722167969,,,,,,,,,,,,,0,,,,0,,,,,,42.4760933,,,,
,22806086.9,39.4766006,99.6852722167969,2.13538032762372E-5,2.87849425766609E-7,1,0.999253354069792,40.0298881530762,1.99850267818097,16.5199991315603,0.000241196163592776,3.93443323230345E-5,0.25,-3.37863956349058E-7,2.12778188423531E-5,-1.95674042027404E-7,39.4766006,39.4766006,99.6852722167969,99.6852722167969,56.9072459711214,20.6649705345478,16.075285,0,0,0,40,4370,39.1585,99.6852722167969,,,,,,,,,,,,,0,,,,0.0049,,,,,,39.4766006,,,,
,22806293.9,35.99051285,99.6852722167969,2.11165631903421E-5,2.93181865898035E-7,1,0.999253354069792,40.0298881530762,1.9986204923148,16.5199991315603,0.000237901444643706,4.14354153033991E-5,0.25,-9.80312763043832E-8,2.10249047372277E-5,3.25308072766194E-8,35.973362,36.0076637,99.6852722167969,99.6852722167969,57.2339666921599,20.6632729847172,15.315984,0,0,0,40,4370,35.7391,99.6852722167969,,,,,,,,,,,,,0,,,,0,,,,,,35.99051285,,,,
,22806503.26,32.4657478,99.6852722167969,2.09049779502827E-5,3.26597160104331E-7,1,0.999253354069792,40.0298881530762,1.99871713977249,16.5199991315603,0.000235870369131136,3.83537780722665E-5,0.25,-3.23218854171204E-7,2.08040543793728E-5,-2.01783617528194E-7,32.4657478,32.4657478,99.6852722167969,99.6852722167969,57.1440794124484,20.6636853619883,14.936333,0,0,0,40,4370,32.2756,99.6852722167969,,,,,,,,,,,,,0,,,,0,,,,,,32.4657478,,,,
,22806681.285,29.4954853,99.6852722167969,2.07623465496996E-5,3.01148775914029E-7,1,0.999253354069792,40.0298881530762,1.99874818461471,16.5599994361401,0.000233691534110058,4.08350084099599E-5,0.25,-6.94130194101084E-8,2.06535550385287E-5,4.33494593258134E-8,29.4954853,29.4954853,99.6852722167969,99.6852722167969,57.1933220091599,20.6626266021067,14.936333,0,0,0,40,4370,29.329,99.6852722167969,,,,,,,,,,,,,0,,,,-0.00245,,,,,,29.4954853,,,,
,22806891.625,25.9815044,99.6852722167969,2.11105944352786E-5,2.71824428083379E-7,1,0.999253354069792,40.0298881530762,1.99861758936621,16.5599994361401,0.000237947766590071,3.9154546788184E-5,0.25,-2.73359666052711E-7,2.09951360651609E-5,-1.6384844270898E-7,25.9815044,25.9815044,99.6852722167969,99.6852722167969,57.2238055214099,20.6658994339378,14.177031,0,0,0,40,4370,25.8248,99.6852722167969,,,,,,,,,,,,,0,,,,0,,,,,,25.9815044,,,,
,22807100.99,22.4804611,99.6852722167969,2.11620245955939E-5,3.02719821376423E-7,1,0.999253354069792,40.0298881530762,1.99837847622692,16.5599994361401,0.000237843078334035,4.27176093529701E-5,0.25,3.94884490875976E-8,2.10413136035881E-5,1.43420822857457E-7,22.4804611,22.4804611,99.6852722167969,99.6852722167969,57.2222422643714,20.6659501813794,14.177031,0,0,0,40,4370,22.3514,99.6852722167969,,,,,,,,,,,,,0,,,,-0.00245,,,,,,22.4804611,,,,
,22807280.57,19.4709816,99.6852722167969,2.09648097154872E-5,3.31805415153079E-7,1,0.999253354069792,40.0298881530762,1.99845599642046,16.5899991989136,0.000236046753233592,3.99197436821827E-5,0.25,-1.72451063737882E-7,2.08449717721597E-5,-7.00539318211029E-8,19.4709816,19.4709816,99.6852722167969,99.6852722167969,57.1518956976407,20.6639594380878,13.417728,0,0,0,40,4370,19.3654,99.6852722167969,,,,,,,,,,,,,0,,,,0,,,,,,19.4709816,,,,
,22807488.645,15.9798117,99.6852722167969,2.11631956614567E-5,2.63555268342568E-7,1,0.999253354069792,40.0298881530762,1.99822470668902,16.5899991989136,0.000238743531622264,3.75366800314268E-5,0.25,-4.18976169462768E-7,2.10434033567391E-5,-3.14499446827021E-7,15.9798117,15.9798117,99.6852722167969,99.6852722167969,57.3543374841214,20.6659510377283,12.658426,0,0,0,40,4370,15.913,99.6852722167969,,,,,,,,,,,,,0,,,,0,,,,,,15.9798117,,,,
,22807699.22,12.4688663,99.6852722167969,2.12512162272256E-5,2.93188344907158E-7,1,0.999253354069792,40.0298881530762,1.99810603337062,16.5899991989136,0.000239305153850148,4.00560132427204E-5,0.25,-2.10328395759915E-7,2.1130105937098E-5,-1.06629106769845E-7,12.4688663,12.4688663,99.6852722167969,99.6852722167969,57.1175040427945,20.6645712667165,12.658426,0,0,0,40,4370,12.39945,99.6852722167969,,,,,,,,,,,,,0,,,,0.00245,,,,,,12.4688663,,,,
,22807980.245,10.0046101,99.6852722167969,2.1335024964412E-5,3.13956676664321E-7,1,0.999253354069792,40.0298881530762,1.99796598603841,16.610000282526,0.000239854395101773,4.23488697203488E-5,0.25,-2.100390150649E-8,2.12126179652225E-5,8.2011966266235E-8,10.0046101,10.0046101,99.6852722167969,99.6852722167969,56.9244417985445,20.6670779874015,11.519473,0,0,0,40,4369,9.9905,99.6852722167969,,,,,,,,,,,,,0,,,,0,,,,,,10.0046101,,,,