File: data/doubleLayers/dl_1-25/ppms/data/DD205_3_ZFCW_100OE.DAT
[Header]
; VSM Data File (default extension .dat)
; Copyright (c) 2003-2013, Quantum Design, Inc. All rights reserved.
TITLE,
FILEOPENTIME,22150655.19,09/14/2018,5:56 pm
BYAPP,VSM,2.0,2.0
INFO,PPMS VSM Option Release 1.4.10 Build 1,APPNAME
INFO,Quantum Design Linear Motor Servo Controller,MOTOR_MODULE_NAME
INFO,3101-100 M1,MOTOR_HW_VERSION
INFO,MMC1014,MOTOR_SERIAL_NUMBER
INFO,SRV No X-over 01.03.11,MOTOR_SOFTWARE_VERSION
INFO,Quantum Design VSM Detection Module,VSM_MODULE_NAME
INFO,3101-150 F0,VSM_HW_VERSION
INFO,VSM707,VSM_SERIAL_NUMBER
INFO,VSM No X-over 01.02.05 May 20 2008 13:51:47,VSM_SOFTWARE_VERSION
INFO,704,PREAMP_SERIAL_NUMBER
INFO,822,COIL_SERIAL_NUMBER
INFO,0,MOMENT_UNITS
INFO,CoFe2O4,SAMPLE_MATERIAL
INFO,Double Layer blue,SAMPLE_COMMENT
INFO,,SAMPLE_MASS
INFO,,SAMPLE_VOLUME
INFO,,SAMPLE_MOLECULAR_WEIGHT
INFO,,SAMPLE_SIZE
INFO,,SAMPLE_SHAPE
DATATYPE,COMMENT,1
DATATYPE,TIME,2
STARTUPAXIS,X,2
STARTUPAXIS,Y1,5
[Data]
Comment,Time Stamp (sec),Temperature (K),Magnetic Field (Oe),Moment (emu),M. Std. Err. (emu),Transport Action,Averaging Time (sec),Frequency (Hz),Peak Amplitude (mm),Center Position (mm),Coil Signal' (mV),Coil Signal" (mV),Range (mV),M. Quad. Signal (emu),M. Raw' (emu),M. Raw" (emu),Min. Temperature (K),Max. Temperature (K),Min. Field (Oe),Max. Field (Oe),Mass (grams),Motor Lag (deg),Pressure (Torr),VSM Status (code),Motor Status (code),Measure Status (code),Measure Count,PPMS Status (code),System Temp. (K),System Field (Oe),Sample Position (deg),Bridge 1 Resistance (ohms),Bridge 1 Excitation (에),Bridge 2 Resistance (ohms),Bridge 2 Excitation (에),Bridge 3 Resistance (ohms),Bridge 3 Excitation (에),Bridge 4 Resistance (ohms),Bridge 4 Excitation (에),Signal 1 Vin (V),Signal 2 Vin (V),Digital Inputs (code),Drive 1 Iout (mA),Drive 1 Ipower (W),Drive 2 Iout (mA),Drive 2 Ipower (W),Pressure (),Map 20 (),Map 21 (),Map 22 (),Map 23 (),Map 24 (),Map 25 (),Map 26 (),Map 27 (),Map 28 (),Map 29 ()
,22153641.13,10.0333719,99.5939254760742,,,2,,,,16.790000025332,,,,,,,10.0333719,10.0333719,99.5939254760742,99.5939254760742,,,14.177031,,,,-99999999,4373,9.9984,99.5939254760742,,,,,,,,,,,,,,,,,,,,,,,10.0333719,,,,
,22153846.94,12.51679945,99.5939254760742,5.22429600177794E-7,2.54833712497312E-7,1,0.999253354069792,40.0298881530762,1.99833507149617,16.780000180006,5.89050080677371E-6,9.45991344971531E-7,0.25,-8.62489122205668E-9,5.19468886803613E-7,-6.05574840800191E-9,12.4828777,12.5507212,99.5939254760742,99.5939254760742,55.8348516427367,20.5280572474679,14.936333,0,0,0,40,4370,12.6598,99.5939254760742,,,,,,,,,,,,,0,,,,0,,,,,,12.51679945,,,,
,22153988.065,16.0201263,99.5939254760742,3.95158345670835E-7,1.93090635435072E-7,1,0.999253354069792,40.0298881530762,1.99830155030354,16.780000180006,5.01838605931349E-6,-2.45499636236802E-6,0.25,-2.88548582311514E-7,3.94275411046776E-7,-2.84981938636237E-7,16.0201263,16.0201263,99.5939254760742,99.5939254760742,56.557076394506,20.5276835347149,15.695635,0,0,0,40,4370,16.2018,99.5939254760742,,,,,,,,,,,,,0,,,,0,,,,,,16.0201263,,,,
,22154128.98,19.5455971,99.5939254760742,6.96771923667046E-7,2.42334674167213E-7,1,0.999253354069792,40.0298881530762,1.99826286699501,16.780000180006,8.58314491552356E-6,-2.83296811670292E-6,0.25,-3.7574880517913E-7,6.94585386258499E-7,-3.70213082816379E-7,19.5455971,19.5455971,99.5939254760742,99.5939254760742,56.8478422036599,20.5311446538453,16.834587,0,0,0,40,4370,19.7572,99.5939254760742,,,,,,,,,,,,,0,,,,0,,,,,,19.5455971,,,,
,22154270.26,23.0252266,99.5939254760742,2.92023095147913E-7,2.47285517569525E-7,1,0.999253354069792,40.0298881530762,1.99826987768905,16.8099999427795,4.24798671057742E-6,-4.84563775333612E-6,0.25,-4.82905719224206E-7,2.9276847062638E-7,-4.78723030970583E-7,23.0252266,23.0252266,99.5939254760742,99.5939254760742,56.3905895199098,20.5335914634716,17.593889,0,0,0,40,4370,23.3181,99.5939254760742,,,,,,,,,,,,,0,,,,0,,,,,,23.0252266,,,,
,22154413.32,26.5494747,99.5939254760742,4.31027658613681E-7,2.28345947398545E-7,1,0.999253354069792,40.0298881530762,1.99818544599394,16.8099999427795,5.50460387121643E-6,-2.83562338053596E-6,0.25,-3.28898528593782E-7,4.30385292180955E-7,-3.24862195259032E-7,26.5494747,26.5494747,99.5939254760742,99.5939254760742,57.0135474497368,20.5345438805427,17.593889,0,0,0,40,4370,26.93815,99.5939254760742,,,,,,,,,,,,,0,,,,0,,,,,,26.5494747,,,,
,22154555.095,30.0562,99.5939254760742,4.17889047423005E-7,2.70898778964542E-7,1,0.999253354069792,40.0298881530762,1.99800717836517,16.8099999427795,5.84313255544371E-6,-5.57511269003874E-6,0.25,-5.70252798642939E-7,4.18900790680109E-7,-5.65014396852423E-7,30.0562,30.0562,99.5939254760742,99.5939254760742,56.6938613853714,20.5349200616289,17.973541,0,0,0,40,4370,30.50215,99.5939254760742,,,,,,,,,,,,,0,,,,0.0049,,,,,,30.0562,,,,
,22154694.135,33.507,99.5939254760742,2.05395087129673E-7,2.44183418414387E-7,1,0.999253354069792,40.0298881530762,1.99822034659854,16.8200004845858,2.80388242740062E-6,-2.34427017958617E-6,0.25,-2.45057477209791E-7,2.05894994937904E-7,-2.4269541943506E-7,33.507,33.507,99.5939254760742,99.5939254760742,56.8103240347368,20.5316414018088,18.732843,0,0,0,40,4370,34.01305,99.5939254760742,,,,,,,,,,,,,0,,,,-0.00245,,,,,,33.507,,,,
,22154836.97,37.0247593,99.5939254760742,6.51998486781421E-7,3.01484377357419E-7,1,0.999253354069792,40.0298881530762,1.99837986836314,16.8200004845858,7.96930368467468E-6,-2.19039239835094E-6,0.25,-3.11384723987134E-7,6.51389898405578E-7,-3.05964584390858E-7,36.9913597,37.0581589,99.5939254760742,99.5939254760742,56.7954730928714,20.5313701289054,19.112494,0,0,0,40,4370,37.62505,99.5939254760742,,,,,,,,,,,,,0,,,,-0.0049,,,,,,37.0247593,,,,
,22154979.765,40.5526772,99.5939254760742,2.31967018680038E-7,2.353451026527E-7,1,0.999253354069792,40.0298881530762,1.99859212326446,16.8200004845858,4.43615378101859E-6,-9.67217955058959E-6,0.25,-8.99966316452514E-7,2.37401910278635E-7,-8.95547068859895E-7,40.5526772,40.5526772,99.5939254760742,99.5939254760742,56.8040710065829,20.5301951842119,19.492144,0,0,0,40,4370,41.23695,99.5939254760742,,,,,,,,,,,,,0,,,,0.00245,,,,,,40.5526772,,,,
,22155120.15,44.0133553,99.5939254760742,4.18750080526852E-7,1.87809176300562E-7,1,0.999253354069792,40.0298881530762,1.99849939642291,16.8099999427795,4.92637178237449E-6,-2.7867497409838E-7,0.25,-1.0008856513521E-7,4.18569052039843E-7,-9.68584617282167E-8,44.0133553,44.0133553,99.5939254760742,99.5939254760742,56.7376325824483,20.533455239845,19.492144,0,0,0,40,4370,44.7976,99.5939254760742,,,,,,,,,,,,,0,,,,0,,,,,,44.0133553,,,,
,22155264.86,47.5424232,99.5939254760742,3.34836428232852E-7,2.03625946489572E-7,1,0.999253354069792,40.0298881530762,1.99869275723269,16.8099999427795,4.71306660419933E-6,-4.48937336364416E-6,0.25,-4.57895158934584E-7,3.37885650440092E-7,-4.54946830484544E-7,47.5424232,47.5424232,99.5939254760742,99.5939254760742,56.7063674416791,20.539816117163,19.871798,0,0,0,40,4374,48.4782,99.5939254760742,,,,,,,,,,,,,0,,,,0,,,,,,47.5424232,,,,
,22155408.16,51.0590324,99.5939254760742,1.50736619057146E-7,3.02343538947481E-7,1,0.999253354069792,40.0298881530762,1.99881452773586,16.8099999427795,3.10539545705035E-6,-7.46680610006516E-6,0.25,-6.87582523610561E-7,1.55862579350202E-7,-6.86551369849316E-7,51.0590324,51.0590324,99.5939254760742,99.5939254760742,56.6407106460637,20.5411849131922,20.251448,0,0,0,40,4374,52.14585,99.5939254760742,,,,,,,,,,,,,0,,,,0,,,,,,51.0590324,,,,
,22155551.035,54.5101013,99.5939254760742,5.00297131148312E-7,2.2416926891171E-7,1,0.999253354069792,40.0298881530762,1.99868245328699,16.7999994009733,6.6398853899248E-6,-4.40864079736015E-6,0.25,-4.79600173402683E-7,5.04394283257719E-7,-4.76551552324675E-7,54.5101013,54.5101013,99.5939254760742,99.5939254760742,56.9056827140829,20.5391348844253,21.3904,0,0,0,40,4374,55.81545,99.5939254760742,,,,,,,,,,,,,0,,,,0.0049,,,,,,54.5101013,,,,
,22155697.05,58.059391,99.5939254760742,3.32090765060086E-7,2.79180238606975E-7,1,0.999253354069792,40.0298881530762,1.99896220952727,16.7999994009733,3.99461334242574E-6,-6.11706789390135E-7,0.25,-1.13670932531682E-7,3.33616640960101E-7,-1.11611748307992E-7,58.059391,58.059391,99.5939254760742,99.5939254760742,56.9510171681983,20.5387705297918,21.770052,0,0,0,40,4374,59.53815,99.5939254760742,,,,,,,,,,,,,0,,,,0,,,,,,58.059391,,,,
,22155838.07,61.5113716,99.5939254760742,4.76990943008046E-7,2.52915871162015E-7,1,0.999253354069792,40.0298881530762,1.99890288365531,16.7999994009733,6.55343410004491E-6,-5.40815004213154E-6,0.25,-5.62402422578618E-7,4.82127468760253E-7,-5.60965496996144E-7,61.5113716,61.5113716,99.5939254760742,99.5939254760742,57.2761746321984,20.5381469324009,21.770052,0,0,0,40,4374,63.1157,99.5939254760742,,,,,,,,,,,,,0,,,,-0.00245,,,,,,61.5113716,,,,
,22155959.885,64.5400848,99.5939254760742,4.21030623997413E-7,2.52211082163183E-7,1,0.999253354069792,40.0298881530762,1.99881126507912,16.7900007218122,5.61926070208545E-6,-3.84722346276866E-6,0.25,-4.14368051384264E-7,4.2511601296077E-7,-4.13247661115441E-7,64.5400848,64.5400848,99.5939254760742,99.5939254760742,56.963523224506,20.5346625969308,22.149702,0,0,0,40,4374,66.211,99.5939254760742,,,,,,,,,,,,,0,,,,-0.0049,,,,,,64.5400848,,,,
,22156103.775,68.0463562,99.5939254760742,6.46098354199553E-7,1.85693789601339E-7,1,0.999253354069792,40.0298881530762,1.99896112600311,16.7900007218122,7.72817977452175E-6,-8.82048315893825E-7,0.25,-1.92991118703146E-7,6.49893722761057E-7,-1.90075429806226E-7,68.0463562,68.0463562,99.5939254760742,99.5939254760742,56.9103724851983,20.5411320145711,22.149702,0,0,0,40,4374,69.87985,99.5939254760742,,,,,,,,,,,,,0,,,,-0.0049,,,,,,68.0463562,,,,
,22156247.135,71.5131226,99.5939254760742,5.62316391988985E-7,2.56678558282317E-7,1,0.999253354069792,40.0298881530762,1.99889708711423,16.7900007218122,6.35183695212261E-6,1.34411619351678E-6,0.25,1.81953663800398E-8,5.6479996135726E-7,2.1269586457162E-8,71.5131226,71.5131226,99.5939254760742,99.5939254760742,56.902556200006,20.5408491882313,22.529354,0,0,0,40,4374,73.5408,99.5939254760742,,,,,,,,,,,,,0,,,,-0.00245,,,,,,71.5131226,,,,
,22156369.19,74.5778427,99.5939254760742,5.90342694906135E-7,3.16484169180177E-7,1,0.999253354069792,40.0298881530762,1.99889879539702,16.780000180006,7.67621222906158E-6,-4.24958181397759E-6,0.25,-4.78802364792858E-7,5.9559959906608E-7,-4.78199778932509E-7,74.5778427,74.5778427,99.5939254760742,99.5939254760742,56.9713395096983,20.5425476903426,22.149702,0,0,0,40,4374,76.62545,99.5939254760742,,,,,,,,,,,,,0,,,,0,,,,,,74.5778427,,,,
,22156510.4,78.03045655,99.5939254760742,5.63283391743046E-7,2.51656790937929E-7,1,0.999253354069792,40.0298881530762,1.99896881773856,16.780000180006,6.77674063813502E-6,-9.66576709609265E-7,0.25,-1.8488397377818E-7,5.67022296187486E-7,-1.8324055199476E-7,77.9922638,78.0686493,99.5939254760742,99.5939254760742,56.9314764552176,20.5422754226274,22.529354,0,0,0,40,4374,80.1995,99.5939254760742,,,,,,,,,,,,,0,,,,0,,,,,,78.03045655,,,,
,22156652.06,81.538147,99.5939254760742,4.57417358241943E-7,2.47712505929254E-7,1,0.999253354069792,40.0298881530762,1.99906032391662,16.780000180006,5.54384389594442E-6,-1.01155072925688E-6,0.25,-1.69884854873343E-7,4.60574323597772E-7,-1.68839129413263E-7,81.538147,81.538147,99.5939254760742,99.5939254760742,56.946327397083,20.5462458054589,23.288654,0,0,0,40,4374,83.7866,99.5939254760742,,,,,,,,,,,,,0,,,,0.00245,,,,,,81.538147,,,,
,22156793.935,85.0500412,99.5939254760742,8.27885331415459E-7,3.33442580985334E-7,1,0.999253354069792,40.0298881530762,1.99888699025412,16.7500004172325,1.03714482978322E-5,-3.74519675521601E-6,0.25,-4.75516407450601E-7,8.34285761077888E-7,-4.74835346627801E-7,85.0500412,85.0500412,99.5939254760742,99.5939254760742,57.0323065341983,20.5396385258878,22.909004,0,0,0,40,4374,87.35545,99.5939254760742,,,,,,,,,,,,,0,,,,-0.0049,,,,,,85.0500412,,,,
,22156934.475,88.5176163,99.5939254760742,5.66162351069323E-7,2.64189871046174E-7,1,0.999253354069792,40.0298881530762,1.99891714774941,16.7500004172325,6.69666479353412E-6,-3.17307148387633E-7,0.25,-1.27738780032012E-7,5.69779101450394E-7,-1.26361672244558E-7,88.5176163,88.5176163,99.5939254760742,99.5939254760742,57.105779615006,20.5411664797775,23.288654,0,0,0,40,4374,90.90315,99.5939254760742,,,,,,,,,,,,,0,,,,0.0049,,,,,,88.5176163,,,,
,22157079.1,92.058075,99.5939254760742,5.35441485547828E-7,2.57113939669837E-7,1,0.999253354069792,40.0298881530762,1.99891489758018,16.7500004172325,6.85662886889816E-6,-3.27159235092764E-6,0.25,-3.81855309724852E-7,5.39765321710819E-7,-3.8216510112532E-7,92.058075,92.058075,99.5939254760742,99.5939254760742,56.8916134007368,20.5400886689764,23.288654,0,0,0,40,4374,94.5819,99.5939254760742,,,,,,,,,,,,,0,,,,0.00245,,,,,,92.058075,,,,
,22157224.77,95.6563797,99.5939254760742,7.16266972785839E-7,2.49165798161614E-7,1,0.999253354069792,40.0298881530762,1.9989777606273,16.7299993336201,8.78269193843512E-6,-2.16588881268126E-6,0.25,-3.16319853240544E-7,7.21341620123501E-7,-3.15816785325904E-7,95.6563797,95.6563797,99.5939254760742,99.5939254760742,56.8689461736791,20.5451404466316,23.288654,0,0,0,40,4374,98.30585,99.5939254760742,,,,,,,,,,,,,0,,,,0,,,,,,95.6563797,,,,
,22157362.65,99.0049362,99.5939254760742,6.1810821096895E-7,2.27101678686372E-7,1,0.999253354069792,40.0298881530762,1.99899555419902,16.7299993336201,8.10475677941133E-6,-4.8638190648859E-6,0.25,-5.36026129619504E-7,6.23240432706121E-7,-5.37212549895118E-7,99.0049362,99.0049362,99.5939254760742,99.5939254760742,56.9166255133522,20.5445150884642,23.288654,0,0,0,40,4374,101.7949,99.5939254760742,,,,,,,,,,,,,0,,,,0,,,,,,99.0049362,,,,
,22157505.67,102.5518112,99.5939254760742,7.21852851959373E-7,3.01738116238416E-7,1,0.999253354069792,40.0298881530762,1.99906430731756,16.7299993336201,8.87186331482368E-6,-2.3054553923798E-6,0.25,-3.29268687568386E-7,7.26894812044913E-7,-3.29095736800411E-7,102.5518112,102.5518112,99.5939254760742,99.5939254760742,57.1135959001984,20.5441359859087,24.047956,0,0,0,40,4374,105.4045,99.5939254760742,,,,,,,,,,,,,0,,,,0,,,,,,102.5518112,,,,
,22157646.77,106.0523758,99.5939254760742,3.3793341119565E-7,2.83570615326194E-7,1,0.999253354069792,40.0298881530762,1.9990172730719,16.6999995708466,4.29305175928862E-6,-1.87861462238979E-6,0.25,-2.24334745250892E-7,3.40453190880969E-7,-2.24703979510808E-7,106.0523758,106.0523758,99.5939254760742,99.5939254760742,56.7939098358329,20.5433039072625,23.668306,0,0,0,40,4374,108.95375,99.5939254760742,,,,,,,,,,,,,0,,,,0.00245,,,,,,106.0523758,,,,
,22157786.11,109.5441971,99.5939254760742,5.169957591487E-7,2.5014204140029E-7,1,0.999253354069792,40.0298881530762,1.99905188951511,16.7100001126528,6.87624073571941E-6,-4.6381336081622E-6,0.25,-4.98146488117231E-7,5.21182558471815E-7,-4.99652313281378E-7,109.5441971,109.5441971,99.5939254760742,99.5939254760742,56.8642564025637,20.5441599057006,23.668306,0,0,0,40,4374,112.45885,99.5939254760742,,,,,,,,,,,,,0,,,,0.0049,,,,,,109.5441971,,,,
,22157926.7,113.0569382,99.5939254760742,7.73077214911347E-7,2.47297847947026E-7,1,0.999253354069792,40.0298881530762,1.99898226494537,16.6999995708466,8.66907510213675E-6,2.27032814086215E-6,0.25,6.41958130016387E-8,7.7726799060537E-7,6.64171263076534E-8,113.0569382,113.0569382,99.5939254760742,99.5939254760742,56.9596150819099,20.5435084380949,24.047956,0,0,0,40,4374,115.99375,99.5939254760742,,,,,,,,,,,,,0,,,,0,,,,,,113.0569382,,,,
,22158068.235,116.5600128,99.5939254760742,5.58481721817642E-7,2.81411252319251E-7,1,0.999253354069792,40.0298881530762,1.99887570889457,16.669999808073,6.46989441623375E-6,4.52273678124966E-7,0.25,-5.79414233878047E-8,5.61729927464187E-7,-5.6986687224382E-8,116.5600128,116.5600128,99.5939254760742,99.5939254760742,56.8658196596022,20.5428266865797,24.047956,0,0,0,40,4374,119.5488,99.5939254760742,,,,,,,,,,,,,0,,,,0.00245,,,,,,116.5600128,,,,
,22158208.68,120.0402679,99.5939254760742,6.2069768280303E-7,2.53947356068834E-7,1,0.999253354069792,40.0298881530762,1.99873079060268,16.669999808073,7.05020078535306E-6,1.30072937995431E-6,0.25,5.82287109333148E-9,6.24117241807763E-7,7.2090803948244E-9,120.0402679,120.0402679,99.5939254760742,99.5939254760742,56.9033378285253,20.5460366103637,24.047956,0,0,0,40,4374,123.0719,99.5939254760742,,,,,,,,,,,,,0,,,,0.00245,,,,,,120.0402679,,,,
,22158348.85,123.5344696,99.5939254760742,3.49399304030588E-7,2.65053840194077E-7,1,0.999253354069792,40.0298881530762,1.99877113092649,16.669999808073,4.21156127704372E-6,-6.58955312302933E-7,0.25,-1.18964331740087E-7,3.51559816015188E-7,-1.1888749823072E-7,123.5053253,123.5636139,99.5939254760742,99.5939254760742,56.9377294833714,20.5434355223414,24.047956,0,0,0,40,4374,126.5949,99.5939254760742,,,,,,,,,,,,,0,,,,-0.00245,,,,,,123.5344696,,,,
,22158489.86,127.0248642,99.5939254760742,9.35806246720823E-7,2.92724208062234E-7,1,0.999253354069792,40.0298881530762,1.99864834718426,16.6400000452995,1.154184662014E-5,-3.27415324719846E-6,0.25,-4.512279441898E-7,9.41771405582961E-7,-4.51805046583558E-7,127.0248642,127.0248642,99.5939254760742,99.5939254760742,56.9134989992753,20.5412492738245,24.427608,0,0,0,40,4374,130.1468,99.5939254760742,,,,,,,,,,,,,0,,,,0,,,,,,127.0248642,,,,
,22158629.97,130.5348358,99.5939254760742,7.66244370638126E-7,2.98839767172499E-7,1,0.999253354069792,40.0298881530762,1.99894330750977,16.6400000452995,9.72867483024441E-6,-4.2726657018077E-6,0.25,-5.09296566794282E-7,7.71314520020446E-7,-5.10555326220549E-7,130.5348358,130.5348358,99.5939254760742,99.5939254760742,56.7790588939676,20.539106697397,24.807261,0,0,0,40,4374,133.6767,99.5939254760742,,,,,,,,,,,,,0,,,,0,,,,,,130.5348358,,,,
,22158770.82,134.0057373,99.5939254760742,9.09700311710549E-7,2.90684967604846E-7,1,0.999253354069792,40.0298881530762,1.99875535770645,16.6400000452995,1.11721935962907E-5,-2.91936785122989E-6,0.25,-4.15348604892449E-7,9.15262826886504E-7,-4.15871190226776E-7,134.0057373,134.0057373,99.5939254760742,99.5939254760742,56.8142321773329,20.5388299352213,24.807261,0,0,0,40,4374,137.21745,99.5939254760742,,,,,,,,,,,,,0,,,,0.00245,,,,,,134.0057373,,,,
,22158894.465,137.0742798,99.5939254760742,9.46069777740663E-7,2.92229479637169E-7,1,0.999253354069792,40.0298881530762,1.99900274833868,16.6200008243322,1.17913147017697E-5,-4.02340526230421E-6,0.25,-5.18668087630776E-7,9.51920029897286E-7,-5.19694055344492E-7,137.0381317,137.1104279,99.5939254760742,99.5939254760742,57.0158923352945,20.5374795836046,24.427608,0,0,0,40,4374,140.32675,99.5939254760742,,,,,,,,,,,,,0,,,,0,,,,,,137.0742798,,,,
,22159034.665,140.5606232,99.5939254760742,1.07873627277413E-6,2.70940637093904E-7,1,0.999253354069792,40.0298881530762,1.99886921608019,16.610000282526,1.31698805262519E-5,-3.02336613787182E-6,0.25,-4.53857388160497E-7,1.08504987156666E-6,-4.54345929263445E-7,140.5250092,140.5962372,99.5939254760742,99.5939254760742,56.8869236296214,20.5375579299605,24.427608,0,0,0,40,4374,143.8596,99.5939254760742,,,,,,,,,,,,,0,,,,0.0049,,,,,,140.5606232,,,,
,22159172.79,144.0009613,99.5939254760742,9.8357980055647E-7,2.87003545636016E-7,1,0.999253354069792,40.0298881530762,1.99914346868721,16.610000282526,1.21773664699048E-5,-3.72592969121792E-6,0.25,-4.98955948795252E-7,9.89373677400842E-7,-4.99857532010165E-7,144.0009613,144.0009613,99.5939254760742,99.5939254760742,56.9095908566791,20.5323312632447,25.186911,0,0,0,40,4374,147.33225,99.5939254760742,,,,,,,,,,,,,0,,,,0,,,,,,144.0009613,,,,
,22159313.795,147.5177917,99.5939254760742,7.19591171324958E-7,2.99659227407676E-7,1,0.999253354069792,40.0298881530762,1.9989867809731,16.5699999779463,8.43885211330541E-6,-3.61242669810367E-8,0.25,-1.28534383857251E-7,7.23372250260435E-7,-1.28028358332893E-7,147.5177917,147.5177917,99.5939254760742,99.5939254760742,56.9361662263329,20.5264571373378,24.807261,0,0,0,40,4374,150.8695,99.5939254760742,,,,,,,,,,,,,0,,,,-0.00245,,,,,,147.5177917,,,,
,22159455.54,151.034317,99.5939254760742,1.1126718364806E-6,2.81378681610609E-7,1,0.999253354069792,40.0298881530762,1.99903585963946,16.5699999779463,1.31927377317391E-5,-8.88837414266779E-7,0.25,-2.71930482449835E-7,1.11852327455027E-6,-2.71546932479765E-7,151.034317,151.034317,99.5939254760742,99.5939254760742,56.9815006804483,20.5324155651831,24.807261,0,0,0,40,4374,154.4236,99.5939254760742,,,,,,,,,,,,,0,,,,0,,,,,,151.034317,,,,
,22159595.53,154.5145721,99.5939254760742,9.06180792161837E-7,2.80725791888212E-7,1,0.999253354069792,40.0298881530762,1.99934740468045,16.5699999779463,1.05325622985663E-5,4.95863932792427E-7,0.25,-1.14171155676434E-7,9.10695066011329E-7,-1.13368961120118E-7,154.5145721,154.5145721,99.5939254760742,99.5939254760742,56.9603967104291,20.5286887671528,25.186911,0,0,0,40,4374,157.93835,99.5939254760742,,,,,,,,,,,,,0,,,,0.0049,,,,,,154.5145721,,,,
,22159736.595,158.0611572,99.5939254760742,1.29966797784707E-6,2.11566383651151E-7,1,0.999253354069792,40.0298881530762,1.99906669207554,16.5299996733665,1.52915236209474E-5,-3.74629926772591E-7,0.25,-2.59161638588271E-7,1.30615142779451E-6,-2.58503970404583E-7,158.0611572,158.0611572,99.5939254760742,99.5939254760742,56.8775440873906,20.5340930818456,25.186911,0,0,0,40,4374,161.46855,99.5939254760742,,,,,,,,,,,,,0,,,,-0.00245,,,,,,158.0611572,,,,
,22159877.89,161.5718842,99.5939254760742,1.14092088051832E-6,2.55239974573757E-7,1,0.999253354069792,40.0298881530762,1.99902835066467,16.5400002151728,1.32357071324877E-5,7.4246972158017E-7,0.25,-1.33232678670441E-7,1.14636277743098E-6,-1.32248955586717E-7,161.5718842,161.5718842,99.5939254760742,99.5939254760742,57.0252718775253,20.5341106563436,25.566563,0,0,0,40,4374,165.02325,99.5939254760742,,,,,,,,,,,,,0,,,,-0.00245,,,,,,161.5718842,,,,
,22160015.895,165.036499,99.5939254760742,1.15603991001082E-6,3.58465884631725E-7,1,0.999253354069792,40.0298881530762,1.99908999908917,16.5299996733665,1.3478378412033E-5,3.60131036082996E-7,0.25,-1.69442510817377E-7,1.1614851027645E-6,-1.68633821004539E-7,165.036499,165.036499,99.5939254760742,99.5939254760742,56.6203883045637,20.5369185504806,24.807261,0,0,0,40,4374,168.4734,99.5939254760742,,,,,,,,,,,,,0,,,,0,,,,,,165.036499,,,,
,22160158.555,168.5629578,99.5939254760742,1.35814259167942E-6,2.81771748760901E-7,1,0.999253354069792,40.0298881530762,1.99885539768166,16.4899993687868,1.57212217476095E-5,1.05581352528708E-6,0.25,-1.43340252686347E-7,1.36432387981451E-6,-1.4217681897804E-7,168.5629578,168.5629578,99.5939254760742,99.5939254760742,56.8587850029291,20.5345718837425,25.186911,0,0,0,40,4374,172.04815,99.5939254760742,,,,,,,,,,,,,0,,,,0,,,,,,168.5629578,,,,
,22160299.18,172.0449677,99.5939254760742,1.8162985704558E-6,3.23715342532267E-7,1,0.999253354069792,40.0298881530762,1.99905552509972,16.4899993687868,2.13580021817233E-5,-5.06065110485525E-7,0.25,-3.60368373003467E-7,1.82459416260886E-6,-3.59585581159101E-7,172.0449677,172.0449677,99.5939254760742,99.5939254760742,57.0377779338329,20.5367158735377,25.186911,0,0,0,40,4374,175.5775,99.5939254760742,,,,,,,,,,,,,0,,,,0.0049,,,,,,172.0449677,,,,
,22160437.94,175.5001984,99.5939254760742,1.4559240371811E-6,2.99286947607165E-7,1,0.999253354069792,40.0298881530762,1.99923740694798,16.4899993687868,1.74069278751488E-5,-2.05604739369746E-6,0.25,-4.34011765742396E-7,1.46259937788261E-6,-4.34014973298684E-7,175.5001984,175.5001984,99.5939254760742,99.5939254760742,57.2136443506599,20.5374537725936,25.186911,0,0,0,40,4374,179.064,99.5939254760742,,,,,,,,,,,,,0,,,,0,,,,,,175.5001984,,,,
,22160578.34,179.0557251,99.5939254760742,1.39571109073898E-6,3.27894005371287E-7,1,0.999253354069792,40.0298881530762,1.9989886121615,16.4500009268522,1.6786418761018E-5,-2.56471814314773E-6,0.25,-4.68297580460395E-7,1.40201382287117E-6,-4.68515539256553E-7,179.0557251,179.0557251,99.5939254760742,99.5939254760742,57.2707032325638,20.5376934035442,25.566563,0,0,0,40,4374,182.5732,99.5939254760742,,,,,,,,,,,,,0,,,,0.00245,,,,,,179.0557251,,,,
,22160717.73,182.5210571,99.5939254760742,1.54670611115681E-6,2.5914122322862E-7,1,0.999253354069792,40.0298881530762,1.99882633088194,16.4500009268522,1.82929125401705E-5,-1.08105738538535E-6,0.25,-3.63960135318721E-7,1.55332929285989E-6,-3.63573725340736E-7,182.5210571,182.5210571,99.5939254760742,99.5939254760742,57.251162519583,20.5377831002098,25.946213,0,0,0,40,4374,186.0773,99.5939254760742,,,,,,,,,,,,,0,,,,0,,,,,,182.5210571,,,,
,22160860.765,186.0356903,99.5939254760742,1.72783113683807E-6,3.10400447620588E-7,1,0.999253354069792,40.0298881530762,1.99840038799344,16.4500009268522,2.04355148886757E-5,-1.24703587579686E-6,0.25,-4.10029330847043E-7,1.73503695270614E-6,-4.09617896488062E-7,186.0356903,186.0356903,99.5939254760742,99.5939254760742,56.5867782782368,20.5409494181845,25.566563,0,0,0,40,4374,189.6683,99.5939254760742,,,,,,,,,,,,,0,,,,-0.00245,,,,,,186.0356903,,,,
,22160998.55,189.5094147,99.5939254760742,2.10825127830889E-6,2.84568995287018E-7,1,0.999253354069792,40.0298881530762,1.99807000738958,16.4000000804663,2.37807962207445E-5,5.0822197248156E-6,0.25,8.12480217115655E-8,2.11614335740667E-6,8.39499427863868E-8,189.5094147,189.5094147,99.5939254760742,99.5939254760742,57.0213637349291,20.5327522234397,25.566563,0,0,0,40,4374,193.1315,99.5939254760742,,,,,,,,,,,,,0,,,,0,,,,,,189.5094147,,,,
,22161142.84,193.0523376,99.5939254760742,2.2394829449215E-6,3.48419327200793E-7,1,0.999253354069792,40.0298881530762,1.99794721758418,16.4000000804663,2.54433058312468E-5,4.32418744064536E-6,0.25,-8.18111927645214E-9,2.24772520517624E-6,-5.72759614836043E-9,193.0523376,193.0523376,99.5939254760742,99.5939254760742,57.0440309619868,20.5349490363173,25.566563,0,0,0,40,4374,196.76405,99.5939254760742,,,,,,,,,,,,,0,,,,0,,,,,,193.0523376,,,,
,22161282.9,196.5438843,99.5939254760742,2.3610802768641E-6,3.14182538928782E-7,1,0.999253354069792,40.0298881530762,1.99816777749476,16.4000000804663,2.75339832362352E-5,4.75161977272574E-7,0.25,-3.68245697984803E-7,2.36989880323995E-6,-3.66998399557508E-7,196.5438843,196.5438843,99.5939254760742,99.5939254760742,56.9517987967176,20.5318756027077,25.566563,0,0,0,40,4374,200.28545,99.5939254760742,,,,,,,,,,,,,0,,,,-0.00245,,,,,,196.5438843,,,,
,22161422.25,200.0228729,99.5939254760742,2.04295541288955E-6,2.79473754878011E-7,1,0.999253354069792,40.0298881530762,1.99787438579832,16.3499992340803,2.42816514130398E-5,-2.25835868851848E-6,0.25,-5.5374456070814E-7,2.05060028791049E-6,-5.53489659898055E-7,200.0228729,200.0228729,99.5939254760742,99.5939254760742,56.5625477941406,20.5305420149551,25.946213,0,0,0,40,4374,203.7838,99.5939254760742,,,,,,,,,,,,,0,,,,0,,,,,,200.0228729,,,,
,22161562.12,203.5044556,99.5939254760742,2.62289222796696E-6,3.88421359007303E-7,1,0.999253354069792,40.0298881530762,1.99797263798596,16.3499992340803,3.0684376612803E-5,-8.93274770160292E-8,0.25,-4.63317105842977E-7,2.63213887475169E-6,-4.62140757541069E-7,203.5044556,203.5044556,99.5939254760742,99.5939254760742,56.7712426087752,20.5329383407893,26.325863,0,0,0,40,4374,207.28275,99.5939254760742,,,,,,,,,,,,,0,,,,0.0049,,,,,,203.5044556,,,,
,22161703.55,207.0049744,99.5939254760742,2.68706318605874E-6,3.6066859775496E-7,1,0.999253354069792,40.0298881530762,1.99800760249698,16.3499992340803,3.12566910945618E-5,9.17742046088814E-7,0.25,-3.85668385357502E-7,2.69612824557719E-6,-3.84180108971006E-7,207.0049744,207.0049744,99.5939254760742,99.5939254760742,56.7751507513714,20.5350304951483,25.566563,0,0,0,40,4374,210.8414,99.5939254760742,,,,,,,,,,,,,0,,,,0.0049,,,,,,207.0049744,,,,
,22161823.655,210.0466919,99.5939254760742,2.66850454937304E-6,3.9740247609532E-7,1,0.999253354069792,40.0298881530762,1.99793908520004,16.3100007921457,3.04806405221298E-5,4.11385902049611E-6,0.25,-1.00741736550887E-7,2.67695078220507E-6,-9.83896477467621E-8,210.0466919,210.0466919,99.5939254760742,99.5939254760742,56.5297193963329,20.5337513945136,25.946213,0,0,0,40,4374,213.8501,99.5939254760742,,,,,,,,,,,,,0,,,,-0.0049,,,,,,210.0466919,,,,
,22161964.375,213.519928,99.5939254760742,3.43754518331128E-6,3.79087611209956E-7,1,0.999253354069792,40.0298881530762,1.99787973939086,16.3100007921457,3.92646550417542E-5,5.26755159096573E-6,0.25,-1.324497242592E-7,3.44802949972665E-6,-1.29481408397968E-7,213.519928,213.519928,99.5939254760742,99.5939254760742,56.7970363499099,20.5326967877341,26.325863,0,0,0,40,4374,217.3868,99.5939254760742,,,,,,,,,,,,,0,,,,0,,,,,,213.519928,,,,
,22162105.875,217.0357971,99.5939254760742,3.64559829581462E-6,2.97152256862468E-7,1,0.999253354069792,40.0298881530762,1.99813609685566,16.3100007921457,4.21452718117419E-5,2.68261689306879E-6,0.25,-3.96314343181852E-7,3.65653148155595E-6,-3.93960409387721E-7,217.0357971,217.0357971,99.5939254760742,99.5939254760742,56.577398736006,20.5355995593109,25.946213,0,0,0,40,4374,220.933,99.5939254760742,,,,,,,,,,,,,0,,,,0,,,,,,217.0357971,,,,
,22162245.875,220.5275726,99.5939254760742,3.93904680544859E-6,3.05969917634373E-7,1,0.999253354069792,40.0298881530762,1.99816120246139,16.2599999457598,4.62578552514897E-5,-1.27955267638671E-6,0.25,-7.96381412531376E-7,3.95073557280797E-6,-7.94882134308895E-7,220.5275726,220.5275726,99.5939254760742,99.5939254760742,56.7102755842752,20.5335942430097,26.325863,0,0,0,40,4374,224.45185,99.5939254760742,,,,,,,,,,,,,0,,,,-0.00245,,,,,,220.5275726,,,,
,22162384.665,224.0151672,99.5939254760742,4.5196522025496E-6,2.82720198915944E-7,1,0.999253354069792,40.0298881530762,1.99835400547443,16.2599999457598,5.09453782166044E-5,1.08020745404598E-5,0.25,1.67857680173787E-7,4.5315129649302E-6,1.72482660534758E-7,224.0151672,224.0151672,99.5939254760742,99.5939254760742,56.8462789466214,20.5355877875342,26.705515,0,0,0,40,4374,227.9411,99.5939254760742,,,,,,,,,,,,,0,,,,0.00245,,,,,,224.0151672,,,,
,22162525.305,227.5002136,99.5939254760742,4.29433652905456E-6,3.28523294780709E-7,1,0.999253354069792,40.0298881530762,1.9982004020058,16.2599999457598,4.97816858455395E-5,2.27743922398442E-6,0.25,-5.44326090542903E-7,4.30573643826324E-6,-5.41811189540571E-7,227.4692688,227.5311584,99.5939254760742,99.5939254760742,56.7970363499099,20.534616853595,25.946213,0,0,0,40,4374,231.4658,99.5939254760742,,,,,,,,,,,,,0,,,,0,,,,,,227.5002136,,,,
,22162666.625,231.0111694,99.5939254760742,5.22925033476883E-6,3.281461895639E-7,1,0.999253354069792,40.0298881530762,1.99846718603086,16.2099990993738,5.98670825012194E-5,7.11240526815261E-6,0.25,-2.80206441062925E-7,5.24214956484503E-6,-2.76225253366441E-7,231.0111694,231.0111694,99.5939254760742,99.5939254760742,56.7368509539291,20.5330456622539,26.325863,0,0,0,40,4374,235.0252,99.5939254760742,,,,,,,,,,,,,0,,,,-0.0049,,,,,,231.0111694,,,,
,22162807.455,234.5106354,99.5939254760742,5.67652973310283E-6,3.47652881947877E-7,1,0.999253354069792,40.0298881530762,1.99863694840592,16.2099990993738,6.54447977404539E-5,5.07073476384279E-6,0.25,-5.37690288261054E-7,5.6900455991225E-6,-5.33958798128616E-7,234.5106354,234.5106354,99.5939254760742,99.5939254760742,56.6711941583137,20.5353994935887,26.705515,0,0,0,40,4374,238.5624,99.5939254760742,,,,,,,,,,,,,0,,,,0.00245,,,,,,234.5106354,,,,
,22162949.6,238.0055084,99.5939254760742,6.23544711744114E-6,3.56642636135474E-7,1,0.999253354069792,40.0298881530762,1.99853863278652,16.2099990993738,7.05131662236294E-5,1.34280276294751E-5,0.25,1.02449137218562E-7,6.24893239193374E-6,1.08031576861822E-7,238.0055084,238.0055084,99.5939254760742,99.5939254760742,56.8759808303522,20.5354060779267,26.705515,0,0,0,40,4374,242.1334,99.5939254760742,,,,,,,,,,,,,0,,,,-0.0049,,,,,,238.0055084,,,,
,22163088.175,241.5092773,99.5939254760742,6.96644003034496E-6,3.74598075979104E-7,1,0.999253354069792,40.0298881530762,1.99836754461974,16.160000115633,8.04091634910028E-5,5.51122819224618E-6,0.25,-7.22230588397445E-7,6.98136310716413E-6,-7.17828950306841E-7,241.5092773,241.5092773,99.5939254760742,99.5939254760742,56.882233858506,20.5362927845118,26.325863,0,0,0,40,4374,245.6212,99.5939254760742,,,,,,,,,,,,,0,,,,-0.00245,,,,,,241.5092773,,,,
,22163233.03,245.08673855,99.5939254760742,7.4845568803351E-6,4.05059162764096E-7,1,0.999253354069792,40.0298881530762,1.99842214005984,16.160000115633,8.56785388280257E-5,9.96959609011232E-6,0.25,-4.18690518748013E-7,7.49934378868372E-6,-4.13285872777825E-7,245.0594482,245.1140289,99.5939254760742,99.5939254760742,56.7548284098714,20.5381426267605,26.325863,0,0,0,40,4374,249.2577,99.5939254760742,,,,,,,,,,,,,0,,,,-0.00245,,,,,,245.08673855,,,,
,22163372.7,248.5930939,99.5939254760742,7.84214666920707E-6,3.63601470892183E-7,1,0.999253354069792,40.0298881530762,1.99860042747361,16.160000115633,9.0243862576066E-5,7.70447612591755E-6,0.25,-6.803645229684E-7,7.85686392207535E-6,-6.75192441443762E-7,248.5930939,248.5930939,99.5939254760742,99.5939254760742,56.8368994043906,20.5348939333497,26.325863,0,0,0,40,4374,252.76405,99.5939254760742,,,,,,,,,,,,,0,,,,0,,,,,,248.5930939,,,,
,22163509.505,252.0063477,99.5939254760742,8.49773669357804E-6,3.38955766960087E-7,1,0.999253354069792,40.0298881530762,1.9984602774992,16.1099992692471,9.67222990123601E-5,1.43871569913017E-5,0.25,-2.04247161792014E-7,8.51222273787068E-6,-1.97766944206392E-7,252.0063477,252.0063477,99.5939254760742,99.5939254760742,56.8877052581406,20.5342220256092,27.085165,0,0,0,40,4374,256.18865,99.5939254760742,,,,,,,,,,,,,0,,,,-0.00245,,,,,,252.0063477,,,,
,22163652.5,255.5227203,99.5939254760742,9.36000226232739E-6,4.32628140965641E-7,1,0.999253354069792,40.0298881530762,1.99842514619771,16.1099992692471,0.000105809802900795,1.99502865581603E-5,0.25,1.3740295921333E-7,9.37450386929108E-6,1.45009379120416E-7,255.5227203,255.5227203,99.5939254760742,99.5939254760742,56.7360693254098,20.5363657577553,26.705515,0,0,0,40,4374,259.7847,99.5939254760742,,,,,,,,,,,,,0,,,,0.00245,,,,,,255.5227203,,,,
,22163794.17,259.0467224,99.5939254760742,9.77758876876298E-6,3.90625328302071E-7,1,0.999253354069792,40.0298881530762,1.99842895175657,16.1099992692471,0.00011053609345883,2.07265412996034E-5,0.25,1.33840119227778E-7,9.79152333169465E-6,1.4162896957929E-7,259.0467224,259.0467224,99.5939254760742,99.5939254760742,56.8830154870253,20.5355073505107,27.085165,0,0,0,40,4374,263.33335,99.5939254760742,,,,,,,,,,,,,0,,,,0,,,,,,259.0467224,,,,
,22163935.495,262.5479126,99.5939254760742,1.12405935482704E-5,3.29545332767928E-7,1,0.999253354069792,40.0298881530762,1.99836679166667,16.0499997437,0.000127842248896765,1.92881135178481E-5,0.25,-2.46344576726092E-7,1.12555203536974E-5,-2.38073225105038E-7,262.5479126,262.5479126,99.5939254760742,99.5939254760742,56.4664074862752,20.5306711092729,26.705515,0,0,0,40,4374,266.8668,99.5939254760742,,,,,,,,,,,,,0,,,,0,,,,,,262.5479126,,,,
,22164073.795,266.0152588,99.5939254760742,1.13877366298952E-5,3.88382623612304E-7,1,0.999253354069792,40.0298881530762,1.99837996623553,16.0499997437,0.000129113947876933,2.17683687936452E-5,0.25,-5.25884995958196E-8,1.14012994120988E-5,-4.40790225794685E-8,266.0152588,266.0152588,99.5939254760742,99.5939254760742,56.8736359447945,20.5327906389683,26.325863,0,0,0,40,4374,270.3503,99.5939254760742,,,,,,,,,,,,,0,,,,0.00245,,,,,,266.0152588,,,,
,22164214.75,269.5405273,99.5939254760742,1.18742947431253E-5,3.78295853073909E-7,1,0.999253354069792,40.0298881530762,1.99844281269413,16.0499997437,0.000134596466792703,2.28183754330915E-5,0.25,-4.39202404610584E-8,1.18869328023997E-5,-3.51667426286302E-8,269.5405273,269.5405273,99.5939254760742,99.5939254760742,56.8572217458906,20.5334405996019,27.085165,0,0,0,40,4374,273.8659,99.5939254760742,,,,,,,,,,,,,0,,,,-0.00245,,,,,,269.5405273,,,,
,22164356.33,273.0533142,99.5939254760742,1.32718078073669E-5,3.58668362653943E-7,1,0.999253354069792,40.0298881530762,1.99840445143555,16.0000007599592,0.000151671909217172,1.82531655342853E-5,0.25,-6.88788703402142E-7,1.32847318911179E-5,-6.79748732020826E-7,273.0533142,273.0533142,99.5939254760742,99.5939254760742,56.5539498804291,20.5267613356046,27.464817,0,0,0,40,4374,277.40965,99.5939254760742,,,,,,,,,,,,,0,,,,0,,,,,,273.0533142,,,,
,22164495.63,276.5016785,99.5939254760742,1.38945977692756E-5,4.4113008111743E-7,1,0.999253354069792,40.0298881530762,1.99840550582699,16.0000007599592,0.000158111334598792,2.29056108831028E-5,0.25,-3.85569023880515E-7,1.39061637957142E-5,-3.75894843895208E-7,276.5016785,276.5016785,99.5939254760742,99.5939254760742,56.8236117195637,20.5313740456911,26.705515,0,0,0,40,4374,280.90065,99.5939254760742,,,,,,,,,,,,,0,,,,0,,,,,,276.5016785,,,,
,22164637.71,280.0132751,99.5939254760742,1.38366209054654E-5,3.81550428925373E-7,1,0.999253354069792,40.0298881530762,1.99846445002737,16.0000007599592,0.000156578611973587,2.77561544286994E-5,0.25,5.31763261048937E-8,1.38460843745491E-5,6.30081854855903E-8,280.0132751,280.0132751,99.5939254760742,99.5939254760742,56.6493085597752,20.5316863840686,26.705515,0,0,0,40,4374,284.4766,99.5939254760742,,,,,,,,,,,,,0,,,,0,,,,,,280.0132751,,,,
,22164757.89,283.0037231,99.5939254760742,1.3897520223967E-5,3.58801187657793E-7,1,0.999253354069792,40.0298881530762,1.99851801027829,15.9499999135733,0.000158275669055554,2.19860052821816E-5,0.25,-4.66655461518136E-7,1.39058999545051E-5,-4.5721187313575E-7,283.0037231,283.0037231,99.5939254760742,99.5939254760742,56.6321127323521,20.5318886384092,27.464817,0,0,0,40,4374,287.49955,99.5939254760742,,,,,,,,,,,,,0,,,,0.0049,,,,,,283.0037231,,,,
,22164900.68,286.5194702,99.5939254760742,1.48107124259841E-5,3.6542792128013E-7,1,0.999253354069792,40.0298881530762,1.9984732713808,15.9499999135733,0.000168909892632464,2.19326573961965E-5,0.25,-6.29180639602267E-7,1.48178625641429E-5,-6.19267687681457E-7,286.5194702,286.5194702,99.5939254760742,99.5939254760742,56.6039741056598,20.5366682406903,27.464817,0,0,0,40,4374,291.1037,99.5939254760742,,,,,,,,,,,,,0,,,,0.00245,,,,,,286.5194702,,,,
,22165041.415,290.0262756,99.5939254760742,1.53488165146996E-5,3.60325723546453E-7,1,0.999253354069792,40.0298881530762,1.99844433205013,15.9499999135733,0.000174279711537915,2.7011745750695E-5,0.25,-2.73308080544595E-7,1.5354034669384E-5,-2.62981636909548E-7,290.0262756,290.0262756,99.5939254760742,99.5939254760742,56.8877052581406,20.5380776226681,27.085165,0,0,0,40,4374,294.65215,99.5939254760742,,,,,,,,,,,,,0,,,,0.00245,,,,,,290.0262756,,,,
,22165164.14,293.0556335,99.5939254760742,1.55939310512866E-5,3.94792622933518E-7,1,0.999253354069792,40.0298881530762,1.9986547667732,15.8900003880262,0.000177445807708546,2.52246276545914E-5,0.25,-4.73509042781547E-7,1.55976702330132E-5,-4.63161830849681E-7,293.0556335,293.0556335,99.5939254760742,99.5939254760742,56.6242964471598,20.5308199564519,27.464817,0,0,0,40,4374,297.7345,99.5939254760742,,,,,,,,,,,,,0,,,,-0.0049,,,,,,293.0556335,,,,
,22165305.635,296.5266418,99.5939254760742,1.57145117733417E-5,3.58080225391593E-7,1,0.999253354069792,40.0298881530762,1.99863916288094,15.8900003880262,0.000179618781643214,2.06578203825207E-5,0.25,-8.97454553476234E-7,1.57166021833414E-5,-8.87157341049586E-7,296.5266418,296.5266418,99.5939254760742,99.5939254760742,56.7618630665445,20.5311553417075,27.085165,0,0,0,40,4374,301.30555,99.5939254760742,,,,,,,,,,,,,0,,,,0,,,,,,296.5266418,,,,
,22165447.54,300.0534363,99.5939254760742,1.63859683229135E-5,4.04977640622967E-7,1,0.999253354069792,40.0298881530762,1.99854800271587,15.8900003880262,0.000186476066800962,2.60719610055688E-5,0.25,-5.34888209800853E-7,1.63858138125161E-5,-5.24196493561604E-7,300.0534363,300.0534363,99.5939254760742,99.5939254760742,56.8697278021983,20.5322453982748,27.464817,0,0,0,40,4374,304.87555,99.5939254760742,,,,,,,,,,,,,0,,,,0,,,,,,300.0534363,,,,
,22165568.87,303.0160828,99.5939254760742,1.59586264284767E-5,4.71214108354928E-7,1,0.999253354069792,40.0298881530762,1.99872816739213,15.8399995416403,0.000181107903540419,2.82851844814722E-5,0.25,-2.6510188069354E-7,1.59566210061084E-5,-2.54791217663637E-7,303.0160828,303.0160828,99.5939254760742,99.5939254760742,56.8126689202945,20.5324239263678,27.464817,0,0,0,40,4374,307.92815,99.5939254760742,,,,,,,,,,,,,0,,,,0.0049,,,,,,303.0160828,,,,
,22165712.515,306.5531616,99.5939254760742,1.61433277922745E-5,4.05704990416575E-7,1,0.999253354069792,40.0298881530762,1.99847052235633,15.8399995416403,0.000183687822171556,2.55490789090959E-5,0.25,-5.38184506609258E-7,1.61394354041761E-5,-5.27793554455372E-7,306.5531616,306.5531616,99.5939254760742,99.5939254760742,56.7587365524675,20.5355517791002,27.844467,0,0,0,40,4374,311.5718,99.5939254760742,,,,,,,,,,,,,0,,,,0.0049,,,,,,306.5531616,,,,
,22165854.345,310.0566406,99.5939254760742,1.62559850491544E-5,4.62818172717934E-7,1,0.999253354069792,40.0298881530762,1.99828634012826,15.8399995416403,0.000183411718976209,3.44888863760912E-5,0.25,2.33292069507073E-7,1.62495522184494E-5,2.43385677866709E-7,310.0566406,310.0566406,99.5939254760742,99.5939254760742,56.7462304961599,20.5376285468243,27.844467,0,0,0,40,4374,315.1451,99.5939254760742,,,,,,,,,,,,,0,,,,-0.0049,,,,,,310.0566406,,,,
,22165973.08,313.0141602,99.5939254760742,1.59062496928827E-5,4.07068704375394E-7,1,0.999253354069792,40.0298881530762,1.99842807169601,15.7900005578995,0.000180201513678283,2.94595525487355E-5,0.25,-1.50567538373397E-7,1.58985244778193E-5,-1.40638599879665E-7,313.0141602,313.0141602,99.5939254760742,99.5939254760742,56.5179949685444,20.5334620339986,27.464817,0,0,0,40,4374,318.1476,99.5939254760742,,,,,,,,,,,,,0,,,,-0.0049,,,,,,313.0141602,,,,
,22166115.96,316.502594,99.5939254760742,1.57430579687554E-5,3.48865492160923E-7,1,0.999253354069792,40.0298881530762,1.9984224175725,15.7900005578995,0.000179255619873022,2.38109219721865E-5,0.25,-6.21326451324125E-7,1.57337588972056E-5,-6.11317154349677E-7,316.502594,316.502594,99.5939254760742,99.5939254760742,56.8658196596022,20.539625111297,27.085165,0,0,0,40,4374,321.7505,99.5939254760742,,,,,,,,,,,,,0,,,,0.00245,,,,,,316.502594,,,,
,22166261.155,320.0785522,99.5939254760742,1.53910869107714E-5,4.5482825234324E-7,1,0.999253354069792,40.0298881530762,1.99858203736828,15.7900005578995,0.000174969881331767,2.48322362600217E-5,0.25,-4.69822131169471E-7,1.53799692278235E-5,-4.60183871647028E-7,320.0785522,320.0785522,99.5939254760742,99.5939254760742,56.8243933480829,20.5406075986477,27.844467,0,0,0,40,4374,325.4222,99.5939254760742,,,,,,,,,,,,,0,,,,-0.0049,,,,,,320.0785522,,,,
,22166400.195,323.5099487,99.5939254760742,1.5001910310923E-5,4.90492782426001E-7,1,0.999253354069792,40.0298881530762,1.99894355104386,15.7299991697073,0.000170039525775111,2.71788133274245E-5,0.25,-1.94927299733278E-7,1.49891068377025E-5,-1.85813780964642E-7,323.5099487,323.5099487,99.5939254760742,99.5939254760742,56.6594697305252,20.5275522724614,27.844467,0,0,0,40,4374,328.9338,99.5939254760742,,,,,,,,,,,,,0,,,,0.00245,,,,,,323.5099487,,,,
,22166541.225,327.0163574,99.5939254760742,1.44750333144582E-5,4.93285151386645E-7,1,0.999253354069792,40.0298881530762,1.99873960894618,15.7299991697073,0.000163722409203849,2.80032994953306E-5,0.25,-3.01241603596046E-8,1.44608106457639E-5,-2.15667285289693E-8,327.0163574,327.0163574,99.5939254760742,99.5939254760742,56.7118388413137,20.5378586999514,27.844467,0,0,0,40,4374,332.49945,99.5939254760742,,,,,,,,,,,,,0,,,,0,,,,,,327.0163574,,,,
,22166682.735,330.5151062,99.5939254760742,1.48691191736267E-5,5.07039215539637E-7,1,0.999253354069792,40.0298881530762,1.9987238293082,15.7299991697073,0.000168672482015983,2.57912039859532E-5,0.25,-2.93623168489716E-7,1.48528510611775E-5,-2.84640635419531E-7,330.5151062,330.5151062,99.5939254760742,99.5939254760742,56.7751507513714,20.5405279015255,27.464817,0,0,0,40,4374,336.04725,99.5939254760742,,,,,,,,,,,,,0,,,,0.00245,,,,,,330.5151062,,,,
,22166826.62,334.0440369,99.5939254760742,1.44164819049228E-5,3.88831820416831E-7,1,0.999253354069792,40.0298881530762,1.99893749986832,15.6699996441603,0.000163986675077957,2.23943688647667E-5,0.25,-5.15567573519732E-7,1.43990773817259E-5,-5.06637211761804E-7,334.0440369,334.0440369,99.5939254760742,99.5939254760742,56.8845787440637,20.5357209333697,28.224119,0,0,0,40,4374,339.6671,99.5939254760742,,,,,,,,,,,,,0,,,,0.00245,,,,,,334.0440369,,,,
,22166966.475,337.5097046,99.5939254760742,1.46647295793848E-5,4.18665488874909E-7,1,0.999253354069792,40.0298881530762,1.9988048963253,15.6699996441603,0.000166196601860953,2.61444614389804E-5,0.25,-2.26320230058742E-7,1.4645100318196E-5,-2.17667294664154E-7,337.5097046,337.5097046,99.5939254760742,99.5939254760742,56.5899047923137,20.5424834649126,27.844467,0,0,0,40,4374,343.19155,99.5939254760742,,,,,,,,,,,,,0,,,,0,,,,,,337.5097046,,,,
,22167110.235,341.063385,99.5939254760742,1.45874188155928E-5,4.31893711407308E-7,1,0.999253354069792,40.0298881530762,1.99870911629475,15.6699996441603,0.000165894531251522,2.25265628838632E-5,0.25,-5.32595216797877E-7,1.45662874031102E-5,-5.23598819146837E-7,341.063385,341.063385,99.5939254760742,99.5939254760742,56.6766655579483,20.5438626934152,28.603769,0,0,0,40,4374,346.8086,99.5939254760742,,,,,,,,,,,,,0,,,,0,,,,,,341.063385,,,,
,22167250.14,344.5662537,99.5939254760742,1.39162844908182E-5,4.06218143407361E-7,1,0.999253354069792,40.0298881530762,1.99875930835024,15.6100001186132,0.000157497118603281,2.58184816384703E-5,0.25,-1.24791365386717E-7,1.38942470069516E-5,-1.1683656110886E-7,344.5662537,344.5662537,99.5939254760742,99.5939254760742,56.7008960420445,20.5361710702747,27.844467,0,0,0,40,4374,350.31165,99.5939254760742,,,,,,,,,,,,,0,,,,0,,,,,,344.5662537,,,,
,22167401.89,348.0160522,99.5939254760742,1.30562037207193E-5,4.56142584244029E-7,1,0.999253354069792,40.0298881530762,1.99883508619094,15.6100001186132,0.000148669669598918,1.89162927518505E-5,0.25,-5.86517099291804E-7,1.30342595680764E-5,-5.7827140803152E-7,348.0160522,348.0160522,99.5939254760742,99.5939254760742,56.7431039820829,20.5412286594446,28.224119,0,0,0,40,4374,351.8401,99.5939254760742,,,,,,,,,,,,,0,,,,-0.00245,,,,,,348.0160522,,,,
,22167855.89,349.8675995,99.5939254760742,1.3163752619944E-5,4.04555451574613E-7,1,0.999253354069792,40.0298881530762,1.99904255001807,15.6100001186132,0.000149244270124948,2.28585188005421E-5,0.25,-2.56307304664418E-7,1.31406176439599E-5,-2.48554782558751E-7,349.8644104,349.8707886,99.5939254760742,99.5939254760742,57.146424298006,20.5391903172059,27.844467,0,0,0,40,4369,352.0977,99.5939254760742,,,,,,,,,,,,,0,,,,0,,,,,,349.8675995,,,,