File: data/doubleLayers/dl_1-25/ppms/data/DD205_3_HYST_100OE_20K.DAT
[Header]
; VSM Data File (default extension .dat)
; Copyright (c) 2003-2013, Quantum Design, Inc. All rights reserved.
TITLE,
FILEOPENTIME,32521182.06,01/12/2019,5:42 pm
BYAPP,VSM,2.0,2.0
INFO,PPMS VSM Option Release 1.4.10 Build 1,APPNAME
INFO,Quantum Design Linear Motor Servo Controller,MOTOR_MODULE_NAME
INFO,3101-100 M1,MOTOR_HW_VERSION
INFO,MMC1014,MOTOR_SERIAL_NUMBER
INFO,SRV No X-over 01.03.11,MOTOR_SOFTWARE_VERSION
INFO,Quantum Design VSM Detection Module,VSM_MODULE_NAME
INFO,3101-150 F0,VSM_HW_VERSION
INFO,VSM707,VSM_SERIAL_NUMBER
INFO,VSM No X-over 01.02.05 May 20 2008 13:51:47,VSM_SOFTWARE_VERSION
INFO,704,PREAMP_SERIAL_NUMBER
INFO,822,COIL_SERIAL_NUMBER
INFO,0,MOMENT_UNITS
INFO,DD205_4,SAMPLE_MATERIAL
INFO,Double Layer Blue 1.25,SAMPLE_COMMENT
INFO,26.73,SAMPLE_MASS
INFO,,SAMPLE_VOLUME
INFO,,SAMPLE_MOLECULAR_WEIGHT
INFO,,SAMPLE_SIZE
INFO,,SAMPLE_SHAPE
DATATYPE,COMMENT,1
DATATYPE,TIME,2
STARTUPAXIS,X,2
STARTUPAXIS,Y1,5
[Data]
Comment,Time Stamp (sec),Temperature (K),Magnetic Field (Oe),Moment (emu),M. Std. Err. (emu),Transport Action,Averaging Time (sec),Frequency (Hz),Peak Amplitude (mm),Center Position (mm),Coil Signal' (mV),Coil Signal" (mV),Range (mV),M. Quad. Signal (emu),M. Raw' (emu),M. Raw" (emu),Min. Temperature (K),Max. Temperature (K),Min. Field (Oe),Max. Field (Oe),Mass (grams),Motor Lag (deg),Pressure (Torr),VSM Status (code),Motor Status (code),Measure Status (code),Measure Count,PPMS Status (code),System Temp. (K),System Field (Oe),Sample Position (deg),Bridge 1 Resistance (ohms),Bridge 1 Excitation (에),Bridge 2 Resistance (ohms),Bridge 2 Excitation (에),Bridge 3 Resistance (ohms),Bridge 3 Excitation (에),Bridge 4 Resistance (ohms),Bridge 4 Excitation (에),Signal 1 Vin (V),Signal 2 Vin (V),Digital Inputs (code),Drive 1 Iout (mA),Drive 1 Ipower (W),Drive 2 Iout (mA),Drive 2 Ipower (W),Pressure (),Map 20 (),Map 21 (),Map 22 (),Map 23 (),Map 24 (),Map 25 (),Map 26 (),Map 27 (),Map 28 (),Map 29 ()
,32521196.64,20.000803,-0.121790185570717,,,2,,,,21.120000013113,,,,,,,20.000803,20.000803,-0.121790185570717,-0.121790185570717,,,12.278775,,,,-99999999,4369,20.0201,-0.121790185570717,,,,,,,,,,,,,,,,,,,,,,,20.000803,,,,
,32521340.985,20.004797,4336.41381835937,6.41333545647647E-5,3.93484808921452E-7,1,0.999253354069792,40.0298881530762,1.99653265592747,21.1100000888109,0.000720627037115958,0.000127517382379336,0.25,-5.68488746135595E-8,6.37798004430871E-5,2.70868183459799E-7,20.004797,20.004797,4326.41650390625,4346.4111328125,56.597721077506,20.5933445542332,12.658426,0,0,0,40,4449,20.0094,4336.41381835937,,,,,,,,,,,,,0,,,,-0.0049,,,,,,20.004797,,,,
,32521435.76,20.0021915,9072.6484375,5.16805255059573E-5,4.3866237653211E-7,1,0.999253354069792,40.0298881530762,1.99665174656871,21.1100000888109,0.000580424384185985,0.000105677904480801,0.25,1.92693594714907E-7,5.14121181999174E-5,4.73202858002577E-7,20.0021915,20.0021915,9062.7744140625,9082.5224609375,56.9181887703906,20.5985196040649,12.658426,0,0,0,40,4449,20.00795,9072.6484375,,,,,,,,,,,,,0,,,,-0.0049,,,,,,20.0021915,,,,
,32521529.61,20.0026627,13762.8276367188,3.91062847958884E-5,4.38422051596356E-7,1,0.999253354069792,40.0298881530762,1.9965993361862,21.1100000888109,0.000440624883556091,7.29436691512417E-5,0.25,-4.94762572666115E-7,3.89221970032563E-5,-2.66052817182161E-7,20.0026627,20.0026627,13755.638671875,13770.0166015625,56.8142321773329,20.6036769092787,12.278775,0,0,0,40,4449,20.00535,13762.8276367188,,,,,,,,,,,,,0,,,,-0.0049,,,,,,20.0026627,,,,
,32521624.845,20.0033646,18522.94921875,2.62680988281214E-5,6.79700409619802E-7,1,0.999253354069792,40.0298881530762,1.99660838970172,21.1100000888109,0.000296705401496379,4.56662592538225E-5,0.25,-6.3905001305562E-7,2.61579238495279E-5,-4.75621033773573E-7,20.0033646,20.0033646,18517.87890625,18528.01953125,56.9643048530253,20.6038624722613,12.658426,0,0,0,40,4449,20.003,18522.94921875,,,,,,,,,,,,,0,,,,0,,,,,,20.0033646,,,,
,32521719.38,20.0021496,23247.794921875,1.38214502073154E-5,7.37389575320786E-7,1,0.999253354069792,40.0298881530762,1.99648942064932,21.1100000888109,0.000156753362983198,2.08513671503994E-5,0.25,-6.23589926455164E-7,1.37718238316961E-5,-5.32540421139213E-7,20.0021496,20.0021496,23240.314453125,23255.275390625,56.7391958394868,20.6067578803882,12.658426,0,0,0,40,4449,20.00145,23247.794921875,,,,,,,,,,,,,0,,,,0,,,,,,20.0021496,,,,
,32521821.845,20.0008621,28367.9384765625,-9.66031395225199E-7,7.97883045824247E-7,1,0.999253354069792,40.0298881530762,1.9964655334716,21.1100000888109,-8.75628859184069E-6,-1.3745381121423E-5,0.25,-1.04780053836468E-6,-9.55775933968747E-7,-1.05075106601627E-6,20.0008621,20.0008621,28363.02734375,28372.849609375,57.0283983916022,20.606052556621,12.278775,0,0,0,40,4449,20.0007,28367.9384765625,,,,,,,,,,,,,0,,,,0.0049,,,,,,20.0008621,,,,
,32521924.28,19.999464,33488.02734375,-1.43255155232244E-5,1.14133263387035E-6,1,0.999253354069792,40.0298881530762,1.99653417007913,21.1100000888109,-0.000155435607821593,-6.17798491565512E-5,0.25,-2.91100403125739E-6,-1.4264975422586E-5,-3.00207137910087E-6,19.999464,19.999464,33480.7265625,33495.328125,57.3043132588907,20.6066642511972,12.658426,0,0,0,40,4449,20.00035,33488.02734375,,,,,,,,,,,,,0,,,,-0.00245,,,,,,19.999464,,,,
,32522020.905,20.0018883,38317.794921875,-2.73968391805911E-5,1.51719221761492E-6,1,0.999253354069792,40.0298881530762,1.99653196336485,21.1100000888109,-0.000302166882838073,-9.17397203974374E-5,0.25,-3.21300329320739E-6,-2.7310805569575E-5,-3.40035532319201E-6,20.0018883,20.0018883,38312.828125,38322.76171875,56.7712426087752,20.6094603077159,12.658426,0,0,0,40,4449,20,38317.794921875,,,,,,,,,,,,,0,,,,0,,,,,,20.0018883,,,,
,32522119.585,20.0004482,43247.7734375,-3.94785013374934E-5,1.00836047811379E-6,1,0.999253354069792,40.0298881530762,1.99655239865994,21.1100000888109,-0.000440182351300291,-0.000107053928810508,0.25,-2.38803373309831E-6,-3.93906235181776E-5,-2.66997315332842E-6,20.0004482,20.0004482,43240.29296875,43255.25390625,56.9869720800829,20.6057420752748,12.278775,0,0,0,40,4449,19.9981,43247.7734375,,,,,,,,,,,,,0,,,,-0.0049,,,,,,20.0004482,,,,
,32522213.415,19.9995613,47940.91796875,-5.80562468730082E-5,1.53111709097812E-6,1,0.999253354069792,40.0298881530762,1.99656607010468,21.1100000888109,-0.000645100607220159,-0.000171598495476184,0.25,-4.75574007181983E-6,-5.79457642531557E-5,-5.17602732932905E-6,19.9995613,19.9995613,47928.46484375,47953.37109375,57.6920010044292,20.606367551116,12.658426,0,0,0,40,4449,19.9969,47940.91796875,,,,,,,,,,,,,0,,,,0.0049,,,,,,19.9995613,,,,
,32522309.53,20.0018616,52743.416015625,-7.23629768400625E-5,2.86506772612808E-6,1,0.999253354069792,40.0298881530762,1.99649895027011,21.1100000888109,-0.000800811320957309,-0.000234077176644819,0.25,-7.70441512513633E-6,-7.22468244179338E-5,-8.23425674854948E-6,20.0018616,20.0018616,52736.0078125,52750.82421875,56.9588334533906,20.6087584754773,12.658426,0,0,0,40,4449,19.99965,52743.416015625,,,,,,,,,,,,,0,,,,0.0049,,,,,,20.0018616,,,,
,32522403.815,20.0007677,57453.650390625,-8.42629885079913E-5,2.38262044686771E-6,1,0.999253354069792,40.0298881530762,1.99641442225847,21.1100000888109,-0.000942532412500477,-0.000219206007499006,0.25,-4.2313754359152E-6,-8.42014780763951E-5,-4.85670104143475E-6,20.0004902,20.0010452,57448.65625,57458.64453125,57.8577062505061,20.6105498046433,12.278775,0,0,0,40,4449,19.9976,57453.650390625,,,,,,,,,,,,,0,,,,0,,,,,,20.0007677,,,,
,32522497.655,20.0003014,62144.125,-0.000103937850872049,2.43894910902547E-6,1,0.999253354069792,40.0298881530762,1.99644538882128,21.1100000888109,-0.00116733966716925,-0.000247194576895857,0.25,-3.1546889111055E-6,-0.000103923068077642,-3.92836953356703E-6,20.0003014,20.0003014,62136.58984375,62151.66015625,56.8189219484483,20.6061383503286,12.658426,0,0,0,40,4449,19.996,62144.125,,,,,,,,,,,,,0,,,,-0.00245,,,,,,20.0003014,,,,
,32522592.09,20.0021362,66866.95703125,-0.000114519837122577,1.79611704879644E-6,1,0.999253354069792,40.0298881530762,1.99631655043728,21.1100000888109,-0.00128184451571629,-0.000299142151335364,0.25,-5.84065783535906E-6,-0.000114534554796696,-6.6931961976432E-6,20.0021362,20.0021362,66864.5078125,66869.40625,57.5106631879676,20.6104675826103,12.658426,0,0,0,40,4449,19.9915,66866.95703125,,,,,,,,,,,,,0,,,,0,,,,,,20.0021362,,,,
,32522685.735,20.000967,71550.1015625,-0.000125303639174265,3.20364060096166E-6,1,0.999253354069792,40.0298881530762,1.99637215265903,21.1100000888109,-0.00139870952528912,-0.000352093327992264,0.25,-8.57685033056027E-6,-0.000125353903329939,-9.50874501295447E-6,20.000967,20.000967,71542.53125,71557.671875,57.1847240954484,20.6107355583509,13.038077,0,0,0,40,4449,19.99275,71550.1015625,,,,,,,,,,,,,0,,,,0,,,,,,20.000967,,,,
,32522777.495,20.00115585,76133.41796875,-0.000146395613971264,3.96989041276933E-6,1,0.999253354069792,40.0298881530762,1.99634911255355,21.1100000888109,-0.00163064228374287,-0.000434274268802106,0.25,-1.20432951734905E-5,-0.000146494324122457,-1.31295543539013E-5,20.0011482,20.0011635,76121.25,76145.5859375,57.5364569291022,20.609317438619,13.038077,0,0,0,40,4449,19.9915,76133.41796875,,,,,,,,,,,,,0,,,,0.00245,,,,,,20.00115585,,,,
,32522872.025,20.0017147,80859.18359375,-0.000159462402881548,4.5528898844379E-6,1,0.999253354069792,40.0298881530762,1.99625303429284,21.1100000888109,-0.00177725489709188,-0.000470417299609468,0.25,-1.2886080612064E-5,-0.000159630071831594,-1.40613513192667E-5,20.0017147,20.0017147,80854.1796875,80864.1875,57.2456911199484,20.6111605030208,13.038077,0,0,0,40,4449,19.9902,80859.18359375,,,,,,,,,,,,,0,,,,-0.00245,,,,,,20.0017147,,,,
,32522968.04,20.0030155,85657.16796875,-0.00016771500386434,3.92989980673053E-6,1,0.999253354069792,40.0298881530762,1.99627426531295,21.1100000888109,-0.00187491002142995,-0.000467131942577063,0.25,-1.11108369049651E-5,-0.000167967729285185,-1.23314466020195E-5,20.0030155,20.0030155,85652.140625,85662.1953125,57.1933220091599,20.6099717735148,13.038077,0,0,0,40,4449,19.988,85657.16796875,,,,,,,,,,,,,0,,,,0,,,,,,20.0030155,,,,
,32523082.68,20.001297,89677.03125,-0.000185501159737795,4.07893839559422E-6,1,0.999253354069792,40.0298881530762,1.99634926724269,21.1100000888109,-0.00208099706489477,-0.000480100980013763,0.25,-9.0597479962509E-6,-0.000185854924353751,-1.03901476253838E-5,20.001297,20.001297,89674.796875,89679.265625,57.5520894994869,20.6116716078122,12.658426,0,0,0,40,4449,19.9866,89677.03125,,,,,,,,,,,,,0,,,,0,,,,,,20.001297,,,,
,32523168.52,20.0003815,85386.765625,-0.000182060538295964,3.83149533903142E-6,1,0.999253354069792,40.0298881530762,1.99620176282646,21.1100000888109,-0.00203601224531273,-0.000502387777048997,0.25,-1.16471239968547E-5,-0.000182334352510376,-1.29720922675887E-5,20.0003815,20.0003815,85384.234375,85389.296875,57.3215090863138,20.6139055202207,13.417728,0,0,0,40,4449,19.9865,85386.765625,,,,,,,,,,,,,0,,,,-0.00245,,,,,,20.0003815,,,,
,32523260.65,20.0019245,80783.109375,-0.000157402844352159,2.59464057133357E-6,1,0.999253354069792,40.0298881530762,1.99635026926302,21.1100000888109,-0.0017698510176615,-0.000378379367613719,0.25,-5.11739905789868E-6,-0.00015762247101607,-6.26523554845526E-6,20.0019245,20.0019245,80780.703125,80785.515625,57.2519441481022,20.6165388981656,13.038077,0,0,0,40,4449,19.9816,80783.109375,,,,,,,,,,,,,0,,,,-0.0049,,,,,,20.0019245,,,,
,32523356.025,19.9989624,76014.34765625,-0.000143183718174986,3.65830069091724E-6,1,0.999253354069792,40.0298881530762,1.99603178910113,21.1100000888109,-0.00159542827476495,-0.000420129916386197,0.25,-1.13764817603098E-5,-0.000143281844051305,-1.24385402813618E-5,19.9989624,19.9989624,76011.828125,76016.8671875,57.2910255740638,20.6205083083022,13.038077,0,0,0,40,4449,19.9866,76014.34765625,,,,,,,,,,,,,0,,,,0,,,,,,19.9989624,,,,
,32523453.57,19.999649,71138.046875,-0.000126004314663452,3.45638507700815E-6,1,0.999253354069792,40.0298881530762,1.99596923781287,21.1100000888109,-0.00141017386293461,-0.000331989356402547,0.25,-6.67786064736907E-6,-0.000126064865104386,-7.61355309870318E-6,19.999649,19.999649,71127.9375,71148.15625,57.3058765159291,20.6154346144507,13.038077,0,0,0,40,4449,19.9872,71138.046875,,,,,,,,,,,,,0,,,,0,,,,,,19.999649,,,,
,32523548.015,19.9970188,66417.58984375,-0.000111918764601531,1.44282104558522E-6,1,0.999253354069792,40.0298881530762,1.9960458774854,21.1100000888109,-0.00125937073314256,-0.000254278210511516,0.25,-2.34154975107402E-6,-0.000111953703995238,-3.17327535405975E-6,19.9970188,19.9970188,66410,66425.1796875,57.6865296047946,20.6140422034813,13.417728,0,0,0,40,4449,19.98635,66417.58984375,,,,,,,,,,,,,0,,,,-0.00245,,,,,,19.9970188,,,,
,32523640.96,19.9984007,61771.41796875,-0.000106460299950521,2.17573968829042E-6,1,0.999253354069792,40.0298881530762,1.99610873734776,21.1100000888109,-0.00119511788572269,-0.000254909780022254,0.25,-3.3875103163214E-6,-0.000106440338375844,-4.17994599255264E-6,19.9980812,19.9987202,61766.50390625,61776.33203125,57.4590757056984,20.6141641272572,13.038077,0,0,0,40,4449,19.98935,61771.41796875,,,,,,,,,,,,,0,,,,0.0049,,,,,,19.9984007,,,,
,32523732.92,19.9988441,57173.375,-8.49434237667645E-5,2.44250048727494E-6,1,0.999253354069792,40.0298881530762,1.99604628594967,21.1100000888109,-0.000950222989804067,-0.000219420541462257,0.25,-4.13174455550019E-6,-8.48801262982832E-5,-4.76197308372248E-6,19.9988441,19.9988441,57168.52734375,57178.22265625,57.1096877576022,20.6141511272108,13.417728,0,0,0,40,4449,19.9904,57173.375,,,,,,,,,,,,,0,,,,-0.00245,,,,,,19.9988441,,,,
,32523826.1,19.9993286,52518.47265625,-7.03739048254315E-5,2.44407366003093E-6,1,0.999253354069792,40.0298881530762,1.99612853148291,21.1100000888109,-0.000783045344529697,-0.000203174471355012,0.25,-5.32777574600614E-6,-7.02754139011582E-5,-5.84454542260114E-6,19.9993286,19.9993286,52511.140625,52525.8046875,57.0112025641791,20.6165588339502,13.038077,0,0,0,40,4449,19.99015,52518.47265625,,,,,,,,,,,,,0,,,,-0.0049,,,,,,19.9993286,,,,
,32523922.51,19.9996185,47698.16796875,-6.31044133244492E-5,3.82025105967533E-6,1,0.999253354069792,40.0298881530762,1.99615503000543,21.1100000888109,-0.000697660924065155,-0.000205228705551722,0.25,-6.83244033290164E-6,-6.29705583368807E-5,-7.28667748880973E-6,19.9996185,19.9996185,47693.2734375,47703.0625,57.6310339799292,20.6185027456394,13.417728,0,0,0,40,4449,19.98985,47698.16796875,,,,,,,,,,,,,0,,,,0.0049,,,,,,19.9996185,,,,
,32524017.2,20.0024824,42965.546875,-3.96795594554897E-5,1.27152665695336E-6,1,0.999253354069792,40.0298881530762,1.99604173671533,21.1100000888109,-0.000444535268588983,-9.51729809133779E-5,0.25,-1.30045330144763E-6,-3.9598038327271E-5,-1.58547920606953E-6,20.0022793,20.0026855,42955.59375,42975.5,57.6318156084484,20.617020838165,13.417728,0,0,0,40,4449,19.98895,42965.546875,,,,,,,,,,,,,0,,,,0,,,,,,20.0024824,,,,
,32524110.665,19.9981136,38294.984375,-2.77352819569597E-5,1.61615059654223E-6,1,0.999253354069792,40.0298881530762,1.99621465798608,21.1100000888109,-0.000303481595831404,-0.000106036095039957,0.25,-4.422453059454E-6,-2.76398032879017E-5,-4.60938837909236E-6,19.9976482,19.998579,38282.51171875,38307.45703125,57.2066096939868,20.6189317800977,13.038077,0,0,0,40,4449,19.99215,38294.984375,,,,,,,,,,,,,0,,,,0,,,,,,19.9981136,,,,
,32524203.075,19.9983349,33675.265625,-1.34076542206243E-5,1.39859438292888E-6,1,0.999253354069792,40.0298881530762,1.99607180197869,21.1100000888109,-0.000145227070365235,-5.90337089837733E-5,0.25,-2.8330890346313E-6,-1.33504826790048E-5,-2.918174355813E-6,19.9983349,19.9983349,33665.4765625,33685.0546875,57.6365053795638,20.6204417356545,13.417728,0,0,0,40,4449,19.9936,33675.265625,,,,,,,,,,,,,0,,,,0,,,,,,19.9983349,,,,
,32524294.85,19.9994926,29087.37109375,1.03328251256425E-6,7.84851392356119E-7,1,0.999253354069792,40.0298881530762,1.99612210048422,21.1100000888109,1.51884274388067E-5,-1.77370753666714E-5,0.25,-1.76150877139307E-6,1.04174701686443E-6,-1.74877588858183E-6,19.9994926,19.9994926,29082.5703125,29092.171875,57.4293738219676,20.620265902723,12.658426,0,0,0,40,4449,19.9904,29087.37109375,,,,,,,,,,,,,0,,,,0,,,,,,19.9994926,,,,
,32524388.36,19.9983845,24414.984375,1.38445382567232E-5,5.97128409038074E-7,1,0.999253354069792,40.0298881530762,1.99610359698398,21.1100000888109,0.000158624054925183,1.18561520268727E-5,0.25,-1.42815957919456E-6,1.38017090871148E-5,-1.33306772369699E-6,19.9983845,19.9983845,24405.064453125,24424.904296875,57.4981571316599,20.6191166996756,13.038077,0,0,0,40,4449,19.99735,24414.984375,,,,,,,,,,,,,0,,,,0,,,,,,19.9983845,,,,
,32524482.63,19.9973927,19702.33984375,2.72289784297606E-5,6.02064082976662E-7,1,0.999253354069792,40.0298881530762,1.99615584085642,21.1100000888109,0.000307563912596822,4.71310540934407E-5,0.25,-6.82380859497518E-7,2.7118030741938E-5,-5.10867849983815E-7,19.9973927,19.9973927,19692.669921875,19712.009765625,57.3394865422561,20.6185451707855,13.038077,0,0,0,40,4449,19.998,19702.33984375,,,,,,,,,,,,,0,,,,0.00245,,,,,,19.9973927,,,,
,32524574.335,19.9983368,15120.0522460938,3.93587069761274E-5,5.42254581075963E-7,1,0.999253354069792,40.0298881530762,1.99619523516157,21.1100000888109,0.000443210735707012,7.4681880701662E-5,0.25,-3.88517760921347E-7,3.91776015526606E-5,-1.55129120615555E-7,19.9983368,19.9983368,15115.130859375,15124.9736328125,57.8350390234484,20.6181690986934,12.658426,0,0,0,40,4449,19.9976,15120.0522460938,,,,,,,,,,,,,0,,,,-0.0049,,,,,,19.9983368,,,,
,32524667.265,19.9976807,10477.4428710938,5.18694466183511E-5,4.55779517741924E-7,1,0.999253354069792,40.0298881530762,1.99635475090145,21.1100000888109,0.000582269765082021,0.000107518397727309,0.25,3.17732051952905E-7,5.16052001902427E-5,6.03997515805839E-7,19.9976807,19.9976807,10467.48046875,10487.4052734375,57.2738297466407,20.6206504461106,13.417728,0,0,0,40,4449,20.0004,10477.4428710938,,,,,,,,,,,,,0,,,,0,,,,,,19.9976807,,,,
,32524758.675,19.9996605,5906.84887695313,6.29875637891661E-5,3.33148558632254E-7,1,0.999253354069792,40.0298881530762,1.99631736185709,21.1100000888109,0.000708729123967346,0.000119773234666179,0.25,-5.49422910266306E-7,6.26496372317675E-5,-2.17902587959431E-7,19.9996605,19.9996605,5904.49853515625,5909.19921875,57.393418910083,20.6219663143881,13.797379,0,0,0,40,4449,20.0013,5906.84887695313,,,,,,,,,,,,,0,,,,0,,,,,,19.9996605,,,,
,32524850.525,19.9993267,1315.8681640625,7.39548364902727E-5,3.01371708056019E-7,1,0.999253354069792,40.0298881530762,1.99605179419739,21.1100000888109,0.000830370562831075,0.000148525974877227,0.25,8.61264304826137E-8,7.35332151871502E-5,4.48699166173426E-7,19.9993267,19.9993267,1310.97839355469,1320.75793457031,57.1143775287176,20.6252499529311,13.038077,0,0,0,40,4449,20.00085,1315.8681640625,,,,,,,,,,,,,0,,,,-0.0049,,,,,,19.9993267,,,,
,32524940.225,19.9988899,-3164.38110351562,8.02670688285322E-5,3.6475618344883E-7,1,0.999253354069792,40.0298881530762,1.99618315490756,21.1100000888109,0.00090058099810713,0.000165813363930486,0.25,4.92230568952258E-7,7.98157731765934E-5,8.92821854442439E-7,19.9988899,19.9988899,-3172.02416992188,-3156.73803710937,57.1573670972753,20.6226883906362,13.038077,0,0,0,40,4449,20.0005,-3164.38110351562,,,,,,,,,,,,,0,,,,0,,,,,,19.9988899,,,,
,32525031.89,19.9990768,-7747.13623046875,8.77150231560358E-5,3.38788239869332E-7,1,0.999253354069792,40.0298881530762,1.99616561608179,21.1100000888109,0.000985016835874272,0.000178070818397998,0.25,2.25985283565816E-7,8.7251046309998E-5,6.94042713956591E-7,19.9990768,19.9990768,-7757.00390625,-7737.2685546875,57.5778832406215,20.623186766167,13.417728,0,0,0,40,4449,20.00055,-7747.13623046875,,,,,,,,,,,,,0,,,,0.0049,,,,,,19.9990768,,,,
,32525124.1,20.0048943,-12354.880859375,8.91234000098149E-5,5.37190621391436E-7,1,0.999253354069792,40.0298881530762,1.99602646776697,21.1100000888109,0.001000203605938,0.000186243493786174,0.25,6.67470130991154E-7,8.86826173143162E-5,1.17101035957013E-6,20.0048943,20.0048943,-12359.876953125,-12349.884765625,57.4270289364099,20.6256789682953,13.417728,0,0,0,40,4449,19.9973,-12354.880859375,,,,,,,,,,,,,0,,,,-0.00245,,,,,,20.0048943,,,,
,32525216.815,19.9994926,-16990,8.08203737543527E-5,5.95723937736482E-7,1,0.999253354069792,40.0298881530762,1.99625321296952,21.1100000888109,0.000906971557747334,0.000171925849994197,0.25,8.40892457894513E-7,8.04526231599379E-5,1.32309233228937E-6,19.9994926,19.9994926,-16997.6640625,-16982.3359375,57.7232661451984,20.622591543939,13.417728,0,0,0,40,4449,19.99925,-16990,,,,,,,,,,,,,0,,,,0.00245,,,,,,19.9994926,,,,
,32525310.58,20.001152,-21677.4912109375,6.10037309618229E-5,5.79803980706653E-7,1,0.999253354069792,40.0298881530762,1.99620685373837,21.1100000888109,0.000683393034927683,0.000138140056395799,0.25,1.3553864677613E-6,6.07489277786387E-5,1.73531056920618E-6,20.001152,20.001152,-21680.099609375,-21674.8828125,57.2652318329291,20.6230484196554,13.417728,0,0,0,40,4449,19.9984,-21677.4912109375,,,,,,,,,,,,,0,,,,-0.00245,,,,,,20.001152,,,,
,32525404.09,20.0000973,-26349.8779296875,4.14368992099914E-5,6.24375642406148E-7,1,0.999253354069792,40.0298881530762,1.99618705150977,21.1100000888109,0.000467065527960153,7.90704556686293E-5,0.25,-4.06227615399172E-7,4.12918768048359E-5,-1.31783444383288E-7,20.0000973,20.0000973,-26357.34375,-26342.412109375,57.5653771843138,20.6244815667841,13.038077,0,0,0,40,4449,19.99685,-26349.8779296875,,,,,,,,,,,,,0,,,,0,,,,,,20.0000973,,,,
,32525497.39,20.0017185,-31014.705078125,2.7171369293663E-5,1.04439284817843E-6,1,0.999253354069792,40.0298881530762,1.9962947726702,21.1100000888109,0.000308006924702992,4.31235658534115E-5,0.25,-1.05020010740522E-6,2.70948775013045E-5,-8.61616089940327E-7,20.0017185,20.0017185,-31024.36328125,-31005.046875,57.4223391652945,20.6226526285518,13.038077,0,0,0,40,4449,19.9949,-31014.705078125,,,,,,,,,,,,,0,,,,-0.00245,,,,,,20.0017185,,,,
,32525589.85,20.0015163,-35632.181640625,3.12393033264E-5,1.09559202895974E-6,1,0.999253354069792,40.0298881530762,1.99613949391696,21.1100000888109,0.000351138436080665,6.70144711358718E-5,0.25,3.32882039020012E-7,3.11560254241781E-5,5.51142791950695E-7,20.0015163,20.0015163,-35637.359375,-35627.00390625,57.7740719989484,20.6267703380341,13.797379,0,0,0,40,4449,19.99455,-35632.181640625,,,,,,,,,,,,,0,,,,0.0049,,,,,,20.0015163,,,,
,32525685.51,20.0015602,-40414.705078125,3.50610844131905E-5,1.53830173919154E-6,1,0.999253354069792,40.0298881530762,1.99610919655083,21.1100000888109,0.000397279862305495,5.86402290933572E-5,0.25,-1.10605582262776E-6,3.4995912193101E-5,-8.52223726739397E-7,20.0015602,20.0015602,-40419.53125,-40409.87890625,57.2871174314676,20.6293261117722,13.417728,0,0,0,40,4449,19.9936,-40414.705078125,,,,,,,,,,,,,0,,,,0,,,,,,20.0015602,,,,
,32525778.055,20.0015965,-45039.951171875,4.47561198982184E-5,2.06403628846072E-6,1,0.999253354069792,40.0298881530762,1.99606387519546,21.1100000888109,0.00050881886511135,6.68596971601757E-5,0.25,-2.12941994162048E-6,4.47000040738409E-5,-1.79971011750271E-6,20.0015965,20.0015965,-45042.390625,-45037.51171875,57.8178431960254,20.6274923065708,13.038077,0,0,0,40,4449,19.992,-45039.951171875,,,,,,,,,,,,,0,,,,0,,,,,,20.0015965,,,,
,32525873.775,19.9999962,-49822.775390625,5.77436715582117E-5,3.261876335885E-6,1,0.999253354069792,40.0298881530762,1.99618337129492,21.1100000888109,0.000656592408178051,8.76486498677424E-5,0.25,-2.63323397242446E-6,5.76990188445366E-5,-2.20447065858129E-6,19.9999962,19.9999962,-49825.171875,-49820.37890625,57.4551675631022,20.6263767222282,13.038077,0,0,0,40,4449,19.9923,-49822.775390625,,,,,,,,,,,,,0,,,,0,,,,,,19.9999962,,,,
,32525969.475,20.0010986,-54604.46875,7.11543626412223E-5,2.11596925610877E-6,1,0.999253354069792,40.0298881530762,1.9961275664687,21.1100000888109,0.000802784544721209,0.000145032549151191,0.25,2.92847696470051E-8,7.11091269305116E-5,5.57542108310915E-7,20.0010986,20.0010986,-54611.99609375,-54596.94140625,57.6818398336792,20.6279393680421,13.417728,0,0,0,40,4449,19.991,-54604.46875,,,,,,,,,,,,,0,,,,0,,,,,,20.0010986,,,,
,32526064.915,20.0012798,-59376.927734375,8.17258710286585E-5,2.68373881344664E-6,1,0.999253354069792,40.0298881530762,1.99623971802198,21.1100000888109,0.000927915303289265,0.000136780312184826,0.25,-2.61494089763878E-6,8.17311305791189E-5,-2.00619591704895E-6,20.0012798,20.0012798,-59379.4453125,-59374.41015625,57.7193580026023,20.6271864690617,13.417728,0,0,0,40,4449,19.9892,-59376.927734375,,,,,,,,,,,,,0,,,,-0.0049,,,,,,20.0012798,,,,
,32526158.22,20.0017452,-64039.46484375,0.000100303064405483,2.47778396218826E-6,1,0.999253354069792,40.0298881530762,1.99623213730445,21.1100000888109,0.00113846167879353,0.000172735881242689,0.25,-2.78385981620842E-6,0.000100349426892033,-2.03882977726466E-6,20.0017452,20.0017452,-64046.96484375,-64031.96484375,57.2863358029484,20.6269192310488,13.038077,0,0,0,40,4449,19.98745,-64039.46484375,,,,,,,,,,,,,0,,,,0.00245,,,,,,20.0017452,,,,
,32526252.765,20.0019531,-68764.1328125,0.000110787239141774,3.10811292190866E-6,1,0.999253354069792,40.0298881530762,1.99614957484054,21.1100000888109,0.00125175084436647,0.000225152353591192,0.25,-3.5977123599298E-8,0.000110861845431185,7.84194495260508E-7,20.0019531,20.0019531,-68768.984375,-68759.28125,57.5270773868715,20.6280635244865,13.417728,0,0,0,40,4449,19.9861,-68764.1328125,,,,,,,,,,,,,0,,,,-0.0049,,,,,,20.0019531,,,,
,32526347.815,20.00449945,-73516.109375,0.000132180335254907,2.45148667724693E-6,1,0.999253354069792,40.0298881530762,1.99616530489931,21.1100000888109,0.00148537021728574,0.000317011125143092,0.25,4.23530331086388E-6,0.00013229025155367,5.21151868595466E-6,20.0039082,20.0050907,-73521.09375,-73511.125,57.7904861978523,20.6310012403311,13.417728,0,0,0,40,4449,19.9831,-73516.109375,,,,,,,,,,,,,0,,,,0,,,,,,20.00449945,,,,
,32526441.275,20.0014095,-78185.65625,0.000137190064462675,4.13356108560765E-6,1,0.999253354069792,40.0298881530762,1.99623263909847,21.1100000888109,0.00155529245574094,0.000256929810573315,0.25,-1.98222194507234E-6,0.000137401384208295,-9.85867122089705E-7,20.0014095,20.0014095,-78193.2734375,-78178.0390625,57.7459333722561,20.6286668260951,13.417728,0,0,0,40,4449,19.9824,-78185.65625,,,,,,,,,,,,,0,,,,0,,,,,,20.0014095,,,,
,32526537.025,20.00233935,-82970.78125,0.000158029129612127,5.04469923374802E-6,1,0.999253354069792,40.0298881530762,1.99630381995316,21.1100000888109,0.00179811474815449,0.000263395114933215,0.25,-5.15834430488861E-6,0.000158349198212048,-4.02988495122913E-6,20.0021553,20.0025234,-82980.734375,-82960.828125,57.7482782578138,20.6291992338308,13.038077,0,0,0,40,4449,19.9811,-82970.78125,,,,,,,,,,,,,0,,,,0.00245,,,,,,20.00233935,,,,
,32526628.9,20.0019035,-87562.8515625,0.000170011529606262,3.4015083637587E-6,1,0.999253354069792,40.0298881530762,1.99628572539045,21.1100000888109,0.00193131854892844,0.00030419688181126,0.25,-3.70034736295481E-6,0.000170396709856536,-2.49982422443023E-6,20.0019035,20.0019035,-87567.8203125,-87557.8828125,57.6263442088138,20.6292375392645,13.417728,0,0,0,40,4449,19.9784,-87562.8515625,,,,,,,,,,,,,0,,,,0,,,,,,20.0019035,,,,
,32526737.625,20.0007553,-87915.859375,0.000170696191378672,3.37194762746519E-6,1,0.999253354069792,40.0298881530762,1.99619314345744,21.1100000888109,0.00193079322334158,0.00035135081414021,0.25,3.4557877738583E-7,0.000171058132187,1.55824382712582E-6,20.0007553,20.0007553,-87918.078125,-87913.640625,57.5786648691407,20.6306181473972,13.038077,0,0,0,40,4449,19.9785,-87915.859375,,,,,,,,,,,,,0,,,,0,,,,,,20.0007553,,,,
,32526828.03,19.9996548,-83401.2734375,0.000155315986813585,3.70352455489509E-6,1,0.999253354069792,40.0298881530762,1.99631156052422,21.1100000888109,0.00175612923451847,0.000320971704657086,0.25,4.20213755746519E-7,0.000155595836857356,1.53787074530753E-6,19.9996548,19.9996548,-83406.3125,-83396.234375,57.2964969736984,20.6283423974286,13.797379,0,0,0,40,4449,19.9782,-83401.2734375,,,,,,,,,,,,,0,,,,-0.00245,,,,,,19.9996548,,,,
,32526923.21,20.0001106,-78640.984375,0.000142853405664515,4.02883758469245E-6,1,0.999253354069792,40.0298881530762,1.99614777917235,21.1100000888109,0.00161824712810633,0.000274418186993747,0.25,-1.45417504525566E-6,0.000143073958477032,-4.16923352370453E-7,20.0001106,20.0001106,-78648.4765625,-78633.4921875,57.7224845166792,20.6315781866994,13.038077,0,0,0,40,4449,19.979,-78640.984375,,,,,,,,,,,,,0,,,,-0.00245,,,,,,20.0001106,,,,
,32527019.32,19.99936485,-73838.8046875,0.000130391117246618,4.08619634652621E-6,1,0.999253354069792,40.0298881530762,1.99622164139589,21.1100000888109,0.00148124506230811,0.000224455862105863,0.25,-3.63162870180223E-6,0.000130560345911007,-2.67760259206305E-6,19.9990387,19.999691,-73846.390625,-73831.21875,57.7279559163138,20.6310816204302,13.038077,0,0,0,40,4449,19.9806,-73838.8046875,,,,,,,,,,,,,0,,,,0,,,,,,19.99936485,,,,
,32527112.05,19.9989948,-69206.6796875,0.000113056791421088,2.72917597233254E-6,1,0.999253354069792,40.0298881530762,1.99633072765573,21.1100000888109,0.00127797763162028,0.000227434987329113,0.25,-2.44939570784009E-7,0.00011313873858032,5.91428859692496E-7,19.9989948,19.9989948,-69214.1953125,-69199.1640625,57.3942005386022,20.6271427812428,13.417728,0,0,0,40,4449,19.9821,-69206.6796875,,,,,,,,,,,,,0,,,,0.00245,,,,,,19.9989948,,,,
,32527212.885,19.9984627,-64167.29296875,9.74324898250448E-5,3.2115264357432E-6,1,0.999253354069792,40.0298881530762,1.99613539677323,21.1100000888109,0.00109375001988262,0.000234872004633563,0.25,3.23615007696357E-6,9.74344785622942E-5,3.96136084837054E-6,19.9984627,19.9984627,-64172.328125,-64162.2578125,57.7076335748138,20.6281673600499,13.417728,0,0,0,40,4449,19.9818,-64167.29296875,,,,,,,,,,,,,0,,,,-0.0049,,,,,,19.9984627,,,,
,32527314.97,19.9973736,-59062.490234375,8.78274289205714E-5,2.09578641243976E-6,1,0.999253354069792,40.0298881530762,1.99600751223591,21.1100000888109,0.00098689745865429,0.000203306578391437,0.25,2.1808585597068E-6,8.77933220054212E-5,2.83408848208632E-6,19.9973736,19.9973736,-59069.890625,-59055.08984375,57.3261988574291,20.630585833147,13.417728,0,0,0,40,4449,19.98105,-59062.490234375,,,,,,,,,,,,,0,,,,0,,,,,,19.9973736,,,,
,32527412.785,19.9979973,-54175.173828125,7.23079390331709E-5,2.4432761594351E-6,1,0.999253354069792,40.0298881530762,1.99618779896503,21.1100000888109,0.000811691594156138,0.000170113256557386,0.25,2.04462425302845E-6,7.22439655660496E-5,2.57985720984911E-6,19.9979973,19.9979973,-54177.609375,-54172.73828125,57.85379810791,20.628889917433,13.797379,0,0,0,40,4449,19.986,-54175.173828125,,,,,,,,,,,,,0,,,,0,,,,,,19.9979973,,,,
,32527510.955,19.9969101,-49268.287109375,5.68552197336083E-5,1.97267139273403E-6,1,0.999253354069792,40.0298881530762,1.99618479288572,21.1100000888109,0.000639575834333681,0.000124467200268108,0.25,7.92492065349047E-7,5.6783092805205E-5,1.21040666981267E-6,19.9969101,19.9969101,-49275.6796875,-49260.89453125,57.5935158110061,20.6269901934549,13.417728,0,0,0,40,4449,19.9877,-49268.287109375,,,,,,,,,,,,,0,,,,0,,,,,,19.9969101,,,,
,32527606.695,19.9985695,-44482.59375,4.25016494385195E-5,1.23413052456127E-6,1,0.999253354069792,40.0298881530762,1.9964071773315,21.1100000888109,0.000478340175855614,9.07021346847217E-5,0.25,3.91442795272454E-7,4.24283017567731E-5,7.00140274415757E-7,19.9985695,19.9985695,-44487.41015625,-44477.77734375,57.5395834431792,20.6264357089317,13.417728,0,0,0,40,4449,19.9863,-44482.59375,,,,,,,,,,,,,0,,,,0,,,,,,19.9985695,,,,
,32527700.745,19.9984455,-39783.39453125,2.89230203187307E-5,1.33891498865435E-6,1,0.999253354069792,40.0298881530762,1.9962395946934,21.1100000888109,0.000327064638379478,5.20559861761436E-5,0.25,-5.85096099415061E-7,2.88649704731526E-5,-3.76888491477469E-7,19.9984455,19.9984455,-39785.921875,-39780.8671875,57.7506231433715,20.6241077382945,13.417728,0,0,0,40,4449,19.9897,-39783.39453125,,,,,,,,,,,,,0,,,,0,,,,,,19.9984455,,,,
,32527796.205,19.9984856,-35013.71484375,1.59447175594148E-5,1.12409421315941E-6,1,0.999253354069792,40.0298881530762,1.99625454670701,21.1100000888109,0.000177918126478149,4.14510775276182E-5,0.25,8.13768172435027E-7,1.58966694900185E-5,9.23071215188114E-7,19.9984856,19.9984856,-35018.60546875,-35008.82421875,57.4106147375061,20.6254908068236,13.797379,0,0,0,40,4449,19.9898,-35013.71484375,,,,,,,,,,,,,0,,,,0,,,,,,19.9984856,,,,
,32527891.88,19.9981823,-30231.208984375,1.54506316343051E-6,7.86300582198895E-7,1,0.999253354069792,40.0298881530762,1.99614837321126,21.1100000888109,1.72202557558273E-5,4.07456179108192E-6,0.25,8.45086993826267E-8,1.53960567068315E-6,9.47248381954091E-8,19.9981823,19.9981823,-30236.111328125,-30226.306640625,57.6904377473907,20.6255922172425,13.038077,0,0,0,40,4449,19.99255,-30231.208984375,,,,,,,,,,,,,0,,,,-0.00245,,,,,,19.9981823,,,,
,32527985.815,19.9980965,-25536.4453125,-9.44271122290301E-6,5.46235474204182E-7,1,0.999253354069792,40.0298881530762,1.9961771797491,21.1100000888109,-0.000107093790290393,-1.42947225820784E-5,0.25,4.23002356907904E-7,-9.41103291429329E-6,3.59669459754114E-7,19.9980965,19.9980965,-25538.91796875,-25533.97265625,57.6286890943715,20.6272643871251,13.038077,0,0,0,40,4449,19.9928,-25536.4453125,,,,,,,,,,,,,0,,,,-0.00245,,,,,,19.9980965,,,,
,32528081.04,19.9977264,-20776.48828125,-2.4579642716063E-5,5.53426647902423E-7,1,0.999253354069792,40.0298881530762,1.99609393023199,21.1100000888109,-0.000276419394560976,-4.94768703533337E-5,0.25,1.57908154290948E-9,-2.44782550334404E-5,-1.52329595997864E-7,19.9977264,19.9977264,-20786.419921875,-20766.556640625,57.413741251583,20.6270450859773,13.797379,0,0,0,40,4449,19.99465,-20776.48828125,,,,,,,,,,,,,0,,,,0.00245,,,,,,19.9977264,,,,
,32528175.805,19.9978428,-16039.3374023438,-3.76163788109112E-5,5.1505396033209E-7,1,0.999253354069792,40.0298881530762,1.99614873834108,21.1100000888109,-0.000422363795760147,-7.83940309652263E-5,0.25,-2.50187159297346E-7,-3.74427700851413E-5,-4.72776278817839E-7,19.9978428,19.9978428,-16049.16796875,-16029.5068359375,57.5262957583522,20.6266302436521,13.797379,0,0,0,40,4449,19.99755,-16039.3374023438,,,,,,,,,,,,,0,,,,-0.0049,,,,,,19.9978428,,,,
,32528269.675,19.9963074,-11351.6967773438,-4.90524724543674E-5,4.34551542149609E-7,1,0.999253354069792,40.0298881530762,1.99639785567823,21.1100000888109,-0.000551972791669264,-9.45466880684137E-5,0.25,3.38123454565716E-7,-4.88096938396182E-5,6.1065394946328E-8,19.9963074,19.9963074,-11356.6748046875,-11346.71875,57.4817429327561,20.6249188155949,13.417728,0,0,0,40,4449,19.99915,-11351.6967773438,,,,,,,,,,,,,0,,,,-0.00245,,,,,,19.9963074,,,,
,32528366.79,19.9980373,-6495.9384765625,-6.15340241147723E-5,3.28549079296819E-7,1,0.999253354069792,40.0298881530762,1.99653218766605,21.1100000888109,-0.000690686170087098,-0.000127073661380596,0.25,-3.54853369084104E-7,-6.12018179515428E-5,-6.76527359717207E-7,19.9980373,19.9980373,-6503.43603515625,-6488.44091796875,57.5583425276407,20.6184072631835,13.038077,0,0,0,40,4449,19.99905,-6495.9384765625,,,,,,,,,,,,,0,,,,0,,,,,,19.9980373,,,,
,32528460.525,20.0009041,-1809.72540283203,-7.21928921842691E-5,3.38809305817903E-7,1,0.999253354069792,40.0298881530762,1.99648639849316,21.1100000888109,-0.000809055752431988,-0.000154706779727382,0.25,-9.44204397892567E-7,-7.17789214978991E-5,-1.29536892169892E-6,20.0009041,20.0009041,-1814.890625,-1804.56018066406,57.4520410490253,20.6202870180408,13.417728,0,0,0,40,4449,19.999,-1809.72540283203,,,,,,,,,,,,,0,,,,0,,,,,,20.0009041,,,,
,32528553.335,19.9997387,2822.96411132813,-7.86909831543492E-5,2.88341570427621E-7,1,0.999253354069792,40.0298881530762,1.99640362428246,21.1100000888109,-0.000882050481393262,-0.000167757929715568,0.25,-9.46070012804286E-7,-7.8244623789531E-5,-1.33440989608145E-6,19.9997387,19.9997387,2812.947265625,2832.98095703125,57.2886806885061,20.6221824995204,13.417728,0,0,0,40,4449,19.99915,2822.96411132813,,,,,,,,,,,,,0,,,,0,,,,,,19.9997387,,,,
,32528647.595,19.9996128,7535.27880859375,-8.61429574693972E-5,3.82010391423587E-7,1,0.999253354069792,40.0298881530762,1.99629514362108,21.1100000888109,-0.000965186973727575,-0.000187353613114695,0.25,-1.3328179344115E-6,-8.56799962547384E-5,-1.78526783869498E-6,19.9996128,19.9996128,7532.78125,7537.7763671875,57.3809128537753,20.6216414833174,13.417728,0,0,0,40,4449,19.9992,7535.27880859375,,,,,,,,,,,,,0,,,,0,,,,,,19.9996128,,,,
,32528740.505,19.9999199,12183.6586914062,-8.88322595754134E-5,4.95283951720977E-7,1,0.999253354069792,40.0298881530762,1.99634414867805,21.1100000888109,-0.000994726031943649,-0.000198812615133462,0.25,-1.83657341927644E-6,-8.83849828070732E-5,-2.33159998126549E-6,19.9999199,19.9999199,12181.11328125,12186.2041015625,57.7224845166792,20.6220955724809,13.797379,0,0,0,40,4449,19.9988,12183.6586914062,,,,,,,,,,,,,0,,,,0,,,,,,19.9999199,,,,
,32528835.275,20.0001736,16918.853515625,-8.07083972312468E-5,4.76135192368264E-7,1,0.999253354069792,40.0298881530762,1.99624815157697,21.1100000888109,-0.000905009444917509,-0.000175585919341822,0.25,-1.18698868046786E-6,-8.03385371985827E-5,-1.66656234520838E-6,20.0001736,20.0001736,16908.82421875,16928.8828125,57.5575608991215,20.6218072152786,13.417728,0,0,0,40,4449,19.99845,16918.853515625,,,,,,,,,,,,,0,,,,0,,,,,,20.0001736,,,,
,32528928.265,20.0007896,21566.078125,-6.0533255838528E-5,5.5471798097296E-7,1,0.999253354069792,40.0298881530762,1.99615287789861,21.1100000888109,-0.000675950016670373,-0.000149060030954049,0.25,-2.41146012099011E-6,-6.02730281014537E-5,-2.78370519022579E-6,20.0007896,20.0007896,21556.001953125,21576.154296875,57.444224763833,20.6235364107459,13.417728,0,0,0,40,4449,19.997,21566.078125,,,,,,,,,,,,,0,,,,-0.0049,,,,,,20.0007896,,,,
,32529023.07,20.0010891,26303.556640625,-4.11326385610362E-5,5.79438053314885E-7,1,0.999253354069792,40.0298881530762,1.99615570709993,21.1100000888109,-0.000459542263124821,-0.00010125716594318,0.25,-1.62044692812855E-6,-4.09751552259914E-5,-1.88555110126895E-6,20.0010891,20.0010891,26298.619140625,26308.494140625,57.5247325013138,20.6224309995748,13.417728,0,0,0,40,4449,19.9952,26303.556640625,,,,,,,,,,,,,0,,,,-0.00245,,,,,,20.0010891,,,,
,32529118.77,20.0008507,31089.45703125,-3.13266713912354E-5,9.00110582917059E-7,1,0.999253354069792,40.0298881530762,1.99630930749062,21.1100000888109,-0.000347306695123012,-9.31899479108371E-5,0.25,-2.65050803763495E-6,-3.12123783724697E-5,-2.85617171072673E-6,20.0008507,20.0008507,31082.115234375,31096.798828125,57.3043132588907,20.6223914533656,13.417728,0,0,0,40,4449,19.994,31089.45703125,,,,,,,,,,,,,0,,,,0.0049,,,,,,20.0008507,,,,
,32529217.735,20.0010509,36034.197265625,-3.16494223170929E-5,1.09013616330206E-6,1,0.999253354069792,40.0298881530762,1.9963286484104,21.1100000888109,-0.000351547457371554,-9.15248450710245E-5,0.25,-2.43399595102291E-6,-3.15516541544299E-5,-2.65026647248585E-6,20.0010509,20.0010509,36029.20703125,36039.1875,57.69121937591,20.6214185375719,13.797379,0,0,0,40,4449,19.9923,36034.197265625,,,,,,,,,,,,,0,,,,0,,,,,,20.0010509,,,,
,32529314.54,20.002634,40874.666015625,-4.08093870104861E-5,1.42082340307588E-6,1,0.999253354069792,40.0298881530762,1.99624220029323,21.1100000888109,-0.000451117473727313,-0.000131310881643625,0.25,-4.3072971523911E-6,-4.06953134231111E-5,-4.59182796889113E-6,20.002634,20.002634,40861.859375,40887.47265625,57.6083667528715,20.6236847644442,13.038077,0,0,0,40,4449,19.99125,40874.666015625,,,,,,,,,,,,,0,,,,0,,,,,,20.002634,,,,
,32529408.865,20.0019455,45587.646484375,-4.99126991608201E-5,1.11336471010335E-6,1,0.999253354069792,40.0298881530762,1.99632840883764,21.1100000888109,-0.000557524961571954,-0.000130217631695975,0.25,-2.55995400602042E-6,-4.98169464714298E-5,-2.92046977987029E-6,20.0019455,20.0019455,45585.0703125,45590.22265625,57.6216544376984,20.6183011047152,13.797379,0,0,0,40,4449,19.9903,45587.646484375,,,,,,,,,,,,,0,,,,0,,,,,,20.0019455,,,,
,32529504.975,20.0001335,50389.908203125,-6.62604296189838E-5,1.65176440325521E-6,1,0.999253354069792,40.0298881530762,1.99629474168633,21.1100000888109,-0.000735135551686339,-0.000202603316303426,0.25,-6.02237919387063E-6,-6.61462451807012E-5,-6.50519637129249E-6,20.0001335,20.0001335,50387.296875,50392.51953125,57.4098331089868,20.6204741884815,13.797379,0,0,0,40,4449,19.987,50389.908203125,,,,,,,,,,,,,0,,,,-0.0049,,,,,,20.0001335,,,,
,32529602.39,20.0003166,55260.1171875,-8.51329439799312E-5,1.84487487410628E-6,1,0.999253354069792,40.0298881530762,1.9961236358733,21.1100000888109,-0.000952943577426995,-0.000215763922813069,0.25,-3.77708443955664E-6,-8.50564785902915E-5,-4.4073622140722E-6,20.0003166,20.0003166,55249.98828125,55270.24609375,57.3863842534099,20.6239290719006,13.797379,0,0,0,40,4449,19.98795,55260.1171875,,,,,,,,,,,,,0,,,,0,,,,,,20.0003166,,,,
,32529696.935,20.0001621,59985.712890625,-0.000100100234558736,2.75641470185635E-6,1,0.999253354069792,40.0298881530762,1.99628323809442,21.1100000888109,-0.00112062449110782,-0.000256320541461215,0.25,-4.66046179097606E-6,-0.000100053870502852,-5.40500472022269E-6,19.9996738,20.0006504,59973.29296875,59998.1328125,57.5997688391599,20.618489123579,13.038077,0,0,0,40,4449,19.987,59985.712890625,,,,,,,,,,,,,0,,,,0,,,,,,20.0001621,,,,
,32529791.025,20.0011759,64686.041015625,-0.000109290364288739,2.89620768108911E-6,1,0.999253354069792,40.0298881530762,1.99624811158254,21.1100000888109,-0.00122166248601383,-0.000293022468054821,0.25,-6.24567814697378E-6,-0.000109278254931015,-7.05987193440827E-6,20.0011635,20.0011883,64675.828125,64696.25390625,57.7201396311215,20.620444057282,13.417728,0,0,0,40,4449,19.987,64686.041015625,,,,,,,,,,,,,0,,,,0,,,,,,20.0011759,,,,
,32529885.54,19.9995537,69411.28125,-0.000126855357742734,2.77047608128679E-6,1,0.999253354069792,40.0298881530762,1.99624670018461,21.1100000888109,-0.00141615227384246,-0.000353799474616342,0.25,-8.45276662196646E-6,-0.000126884958437785,-9.39730257977993E-6,19.9995537,19.9995537,69404.0390625,69418.5234375,57.7600026856023,20.6165276201941,13.417728,0,0,0,40,4449,19.98655,69411.28125,,,,,,,,,,,,,0,,,,0,,,,,,19.9995537,,,,
,32529982.595,20.001667,74264.34375,-0.000134515961702281,2.52406771430029E-6,1,0.999253354069792,40.0298881530762,1.99654732251357,21.1100000888109,-0.00151028019182357,-0.000332151963569742,0.25,-5.14835701195168E-6,-0.000134629834871313,-6.14170305150745E-6,20.001667,20.001667,74256.796875,74271.890625,57.3926372815638,20.6141209299179,13.417728,0,0,0,40,4449,19.9845,74264.34375,,,,,,,,,,,,,0,,,,0.00245,,,,,,20.001667,,,,
,32530079.515,20.0009308,79107.33203125,-0.000157506381017593,3.52150590438585E-6,1,0.999253354069792,40.0298881530762,1.99633487044728,21.1100000888109,-0.0017691487267437,-0.000387632171621016,0.25,-5.91673662281144E-6,-0.000157700463714257,-7.07042785151367E-6,20.0009308,20.0009308,79099.7890625,79114.875,57.5286406439099,20.6153252287666,13.797379,0,0,0,40,4449,19.98235,79107.33203125,,,,,,,,,,,,,0,,,,-0.00245,,,,,,20.0009308,,,,
,32530175.14,20.0012646,83890.953125,-0.000174262229724636,5.27011851749431E-6,1,0.999253354069792,40.0298881530762,1.99647009034301,21.1100000888109,-0.00194583520890977,-0.000497599151606915,0.25,-1.26208281053535E-5,-0.000174495055660216,-1.38957480232172E-5,20.0012646,20.0012646,83883.5234375,83898.3828125,57.7474966292946,20.6151374239581,13.417728,0,0,0,40,4449,19.9796,83890.953125,,,,,,,,,,,,,0,,,,-0.0049,,,,,,20.0012646,,,,
,32530265.475,20.0014973,88406.5703125,-0.000189418552251101,4.23672716383616E-6,1,0.999253354069792,40.0298881530762,1.99639344513517,21.1100000888109,-0.00212393240887204,-0.000495070782311543,0.25,-9.67541555957981E-6,-0.000189760561160031,-1.10392626778798E-5,20.0014973,20.0014973,88401.546875,88411.59375,57.4684552479292,20.6144205223442,13.417728,0,0,0,40,4449,19.9809,88406.5703125,,,,,,,,,,,,,0,,,,-0.0049,,,,,,20.0014973,,,,
,32530368.53,20.0015926,87323.5234375,-0.000184391699802604,4.16306202224064E-6,1,0.999253354069792,40.0298881530762,1.99634424911843,21.1100000888109,-0.00207276127110262,-0.000451891106217948,0.25,-6.76364182966529E-6,-0.000184729840568571,-8.08927552868966E-6,20.0015926,20.0015926,87318.46875,87328.578125,57.7717271133907,20.6161670729799,13.797379,0,0,0,40,4449,19.9799,87323.5234375,,,,,,,,,,,,,0,,,,0.00245,,,,,,20.0015926,,,,
,32530459.995,19.9998093,82750.32421875,-0.00017008551306829,4.35516115647032E-6,1,0.999253354069792,40.0298881530762,1.99646565914746,21.1100000888109,-0.00190963641874255,-0.000426735871270152,0.25,-7.1083356374682E-6,-0.000170336124615058,-8.34614816654099E-6,19.9998093,19.9998093,82745.28125,82755.3671875,57.5700669554292,20.6152949179743,13.038077,0,0,0,40,4449,19.97975,82750.32421875,,,,,,,,,,,,,0,,,,0.00245,,,,,,19.9998093,,,,
,32530555.015,19.9995003,77998.55859375,-0.000153404662960634,2.95042387975133E-6,1,0.999253354069792,40.0298881530762,1.99631727806835,21.1100000888109,-0.00172021598409346,-0.000392498402996268,0.25,-7.08596254012154E-6,-0.000153570985452203,-8.21378738602729E-6,19.9995003,19.9995003,77990.9765625,78006.140625,57.6740235484869,20.6176463251477,13.038077,0,0,0,40,4449,19.9817,77998.55859375,,,,,,,,,,,,,0,,,,-0.00245,,,,,,19.9995003,,,,
,32530649.475,20.0007172,73280.03125,-0.000140731217572582,3.15782922365402E-6,1,0.999253354069792,40.0298881530762,1.99631520338962,21.1100000888109,-0.00157660095015424,-0.000364971006479623,0.25,-6.93596268647798E-6,-0.000140827688064589,-7.97821205533243E-6,20.0007172,20.0007172,73267.8515625,73292.2109375,57.4371901071599,20.6179447203929,13.038077,0,0,0,40,4449,19.9819,73280.03125,,,,,,,,,,,,,0,,,,-0.0049,,,,,,20.0007172,,,,
,32530742.025,19.999424,68651.91796875,-0.000121807147527251,2.95362078475056E-6,1,0.999253354069792,40.0298881530762,1.99633212534633,21.1100000888109,-0.00136266346692186,-0.000323617940339693,0.25,-6.69111242309241E-6,-0.000121838164882563,-7.59743936086958E-6,19.999424,19.999424,68649.2890625,68654.546875,57.5950790680446,20.6171369062363,13.797379,0,0,0,40,4449,19.9825,68651.91796875,,,,,,,,,,,,,0,,,,0.00245,,,,,,19.999424,,,,
,32530837.805,19.9980068,63864.015625,-0.000106187374531902,2.4180748305493E-6,1,0.999253354069792,40.0298881530762,1.99649180492369,21.1100000888109,-0.00118785236748589,-0.000280137018512294,0.25,-5.66257859279025E-6,-0.000106170758735995,-6.45350824343688E-6,19.9980068,19.9980068,63861.6015625,63866.4296875,57.3910740245253,20.6171728618519,13.797379,0,0,0,40,4449,19.98405,63864.015625,,,,,,,,,,,,,0,,,,-0.0049,,,,,,19.9980068,,,,
,32530933.96,19.9981174,59055.6171875,-8.31523086801287E-5,2.86626843786293E-6,1,0.999253354069792,40.0298881530762,1.99646714127692,21.1100000888109,-0.000930834458283285,-0.00021324478149282,0.25,-3.89989768906696E-6,-8.31063090695685E-5,-4.51797915346162E-6,19.9981174,19.9981174,59047.94921875,59063.28515625,57.85379810791,20.6103353451005,13.038077,0,0,0,40,4449,19.98585,59055.6171875,,,,,,,,,,,,,0,,,,-0.00245,,,,,,19.9981174,,,,
,32531028.755,20.0014229,54320.236328125,-7.84061369573876E-5,1.62293313423133E-6,1,0.999253354069792,40.0298881530762,1.99620521086018,21.1100000888109,-0.000874224178718069,-0.000217434707598769,0.25,-5.13906532015475E-6,-7.83161904422792E-5,-5.71762398671269E-6,20.0014229,20.0014229,54315.16015625,54325.3125,57.3762230826599,20.6192604603832,13.038077,0,0,0,40,4449,19.9813,54320.236328125,,,,,,,,,,,,,0,,,,0,,,,,,20.0014229,,,,
,32531127.1,19.9993038,49402.5078125,-5.94364823703809E-5,1.40286424614798E-6,1,0.999253354069792,40.0298881530762,1.99627572729114,21.1100000888109,-0.000667190572892446,-0.000138231413478822,0.25,-1.547086749831E-6,-5.93565901618819E-5,-1.98327400820367E-6,19.9993038,19.9993038,49392.359375,49412.65625,57.2746113751599,20.6183728268346,13.797379,0,0,0,40,4449,19.9826,49402.5078125,,,,,,,,,,,,,0,,,,0,,,,,,19.9993038,,,,
,32531219.445,19.9991026,44787.97265625,-4.68922827567012E-5,1.45523547490374E-6,1,0.999253354069792,40.0298881530762,1.99646149855052,21.1100000888109,-0.000524293807217266,-0.000119465940523432,0.25,-2.15129364278263E-6,-4.68003183388552E-5,-2.48941297987862E-6,19.9987965,19.9994087,44755.77734375,44820.16796875,57.8170615675061,20.6182420976715,13.038077,0,0,0,40,4449,19.98575,44787.97265625,,,,,,,,,,,,,0,,,,0,,,,,,19.9991026,,,,
,32531314.75,19.99716,40024.478515625,-3.13860197032111E-5,1.27150156901544E-6,1,0.999253354069792,40.0298881530762,1.9964982014636,21.1100000888109,-0.000347155344083328,-9.99147651471749E-5,0.25,-3.21775922931301E-6,-3.12962342843213E-5,-3.43571588412363E-6,19.99716,19.99716,40016.9765625,40031.98046875,57.7310824303907,20.6206237817177,13.417728,0,0,0,40,4449,19.98705,40024.478515625,,,,,,,,,,,,,0,,,,0.0049,,,,,,19.99716,,,,
,32531408.48,19.9984322,35342.091796875,-1.8333073278714E-5,1.43807177694695E-6,1,0.999253354069792,40.0298881530762,1.99636259706172,21.1100000888109,-0.000201851703997964,-6.28703201941262E-5,0.25,-2.2855685368775E-6,-1.82689995047701E-5,-2.4079684173202E-6,19.9984322,19.9984322,35329.6796875,35354.50390625,57.1925403806407,20.6191601731596,13.797379,0,0,0,40,4449,19.98795,35342.091796875,,,,,,,,,,,,,0,,,,-0.00245,,,,,,19.9984322,,,,
,32531502.775,19.9980907,30626.7841796875,-2.72623634170137E-6,8.2642153401824E-7,1,0.999253354069792,40.0298881530762,1.99639405452659,21.1100000888109,-2.71576834453515E-5,-2.51846148379928E-5,0.25,-1.74744061367125E-6,-2.70584263006539E-6,-1.76053735163785E-6,19.9980907,19.9980907,30621.80078125,30631.767578125,57.6748051770061,20.6234245463267,13.797379,0,0,0,40,4449,19.99,30626.7841796875,,,,,,,,,,,,,0,,,,0,,,,,,19.9980907,,,,
,32531599.3,19.9987583,25804.15234375,1.01395524505344E-5,8.30864803593448E-7,1,0.999253354069792,40.0298881530762,1.99635671372066,21.1100000888109,0.000114388203465822,1.88185208995604E-5,0.25,-1.46239133632393E-7,1.01038007927481E-5,-7.92102253720046E-8,19.9987583,19.9987583,25794.12890625,25814.17578125,57.5020652742561,20.6168750693471,13.797379,0,0,0,40,4449,19.99105,25804.15234375,,,,,,,,,,,,,0,,,,0,,,,,,19.9987583,,,,
,32531692.055,19.9987679,21169.2099609375,2.32928909683433E-5,6.34889627888451E-7,1,0.999253354069792,40.0298881530762,1.99627171951951,21.1100000888109,0.000263490216587118,3.84662505884473E-5,0.25,-7.51265077422514E-7,2.32024218515227E-5,-6.01776223027481E-7,19.9987679,19.9987679,21161.849609375,21176.5703125,57.2902439455445,20.6215161102138,13.038077,0,0,0,40,4449,19.9936,21169.2099609375,,,,,,,,,,,,,0,,,,-0.00245,,,,,,19.9987679,,,,
,32531788.695,19.9986954,16337.16015625,3.59353586746409E-5,6.50288266677436E-7,1,0.999253354069792,40.0298881530762,1.9963841731384,21.1100000888109,0.000406569755932377,5.79829878482107E-5,0.25,-1.26649412762876E-6,3.57794725821329E-5,-1.04626124568779E-6,19.9986954,19.9986954,16329.705078125,16344.615234375,57.4778347901599,20.6196692394183,13.797379,0,0,0,40,4449,19.9954,16337.16015625,,,,,,,,,,,,,0,,,,-0.00735,,,,,,19.9986954,,,,
,32531880.965,19.9981861,11726.95703125,4.89477745938922E-5,4.97599190331007E-7,1,0.999253354069792,40.0298881530762,1.99631310777731,21.1100000888109,0.000550182981839998,9.77460636504154E-5,0.25,-3.6033214116226E-8,4.87053650606705E-5,2.40264185011573E-7,19.9981861,19.9981861,11722.0458984375,11731.8681640625,57.3480844559676,20.6220012935834,13.038077,0,0,0,40,4449,19.9966,11726.95703125,,,,,,,,,,,,,0,,,,-0.0049,,,,,,19.9981861,,,,
,32531973.945,19.9980602,7076.83227539063,6.04695931273771E-5,4.2932459291302E-7,1,0.999253354069792,40.0298881530762,1.99637901134189,21.1100000888109,0.000679600239158473,0.000119915852092326,0.25,-9.492040727051E-8,6.01480369676705E-5,2.26117375570285E-7,19.9980602,19.9980602,7069.60546875,7084.05908203125,57.3840393678522,20.6228504343532,13.038077,0,0,0,40,4449,19.99805,7076.83227539063,,,,,,,,,,,,,0,,,,0,,,,,,19.9980602,,,,
,32532066.73,19.9997787,2441.06799316406,7.13635252350911E-5,3.31717288826048E-7,1,0.999253354069792,40.0298881530762,1.99641182372117,21.1100000888109,0.00080146863983002,0.000143319725272419,0.25,7.50521124906259E-8,7.09610544480336E-5,4.29859675839291E-7,19.9997787,19.9997787,2435.95654296875,2446.17944335938,57.3035316303714,20.6218947225582,13.417728,0,0,0,40,4449,19.9979,2441.06799316406,,,,,,,,,,,,,0,,,,0,,,,,,19.9997787,,,,
,32532116.985,20.0046558,-0.129402071237564,7.57619508217612E-5,3.34458129143782E-7,1,0.999253354069792,40.0298881530762,1.99621414515766,21.1100000888109,0.000850107004658804,0.00015538329044594,0.25,3.80173635091992E-7,7.53244462692991E-5,7.45115367694224E-7,20.0046558,20.0046558,-0.137013956904411,-0.121790185570717,57.383257739333,20.6247701740713,13.797379,0,0,0,40,4417,19.9943,-0.129402071237564,,,,,,,,,,,,,0,,,,0.00245,,,,,,20.0046558,,,,