File: data/doubleLayers/dl_1-25/ppms/data/DD205_3_HYST_100OE_150K.DAT
[Header]
; VSM Data File (default extension .dat)
; Copyright (c) 2003-2013, Quantum Design, Inc. All rights reserved.
TITLE,
FILEOPENTIME,22228139.72,09/15/2018,3:27 pm
BYAPP,VSM,2.0,2.0
INFO,PPMS VSM Option Release 1.4.10 Build 1,APPNAME
INFO,Quantum Design Linear Motor Servo Controller,MOTOR_MODULE_NAME
INFO,3101-100 M1,MOTOR_HW_VERSION
INFO,MMC1014,MOTOR_SERIAL_NUMBER
INFO,SRV No X-over 01.03.11,MOTOR_SOFTWARE_VERSION
INFO,Quantum Design VSM Detection Module,VSM_MODULE_NAME
INFO,3101-150 F0,VSM_HW_VERSION
INFO,VSM707,VSM_SERIAL_NUMBER
INFO,VSM No X-over 01.02.05 May 20 2008 13:51:47,VSM_SOFTWARE_VERSION
INFO,704,PREAMP_SERIAL_NUMBER
INFO,822,COIL_SERIAL_NUMBER
INFO,0,MOMENT_UNITS
INFO,CoFe2O4,SAMPLE_MATERIAL
INFO,Double Layer blue,SAMPLE_COMMENT
INFO,,SAMPLE_MASS
INFO,,SAMPLE_VOLUME
INFO,,SAMPLE_MOLECULAR_WEIGHT
INFO,,SAMPLE_SIZE
INFO,,SAMPLE_SHAPE
DATATYPE,COMMENT,1
DATATYPE,TIME,2
STARTUPAXIS,X,2
STARTUPAXIS,Y1,5
[Data]
Comment,Time Stamp (sec),Temperature (K),Magnetic Field (Oe),Moment (emu),M. Std. Err. (emu),Transport Action,Averaging Time (sec),Frequency (Hz),Peak Amplitude (mm),Center Position (mm),Coil Signal' (mV),Coil Signal" (mV),Range (mV),M. Quad. Signal (emu),M. Raw' (emu),M. Raw" (emu),Min. Temperature (K),Max. Temperature (K),Min. Field (Oe),Max. Field (Oe),Mass (grams),Motor Lag (deg),Pressure (Torr),VSM Status (code),Motor Status (code),Measure Status (code),Measure Count,PPMS Status (code),System Temp. (K),System Field (Oe),Sample Position (deg),Bridge 1 Resistance (ohms),Bridge 1 Excitation (에),Bridge 2 Resistance (ohms),Bridge 2 Excitation (에),Bridge 3 Resistance (ohms),Bridge 3 Excitation (에),Bridge 4 Resistance (ohms),Bridge 4 Excitation (에),Signal 1 Vin (V),Signal 2 Vin (V),Digital Inputs (code),Drive 1 Iout (mA),Drive 1 Ipower (W),Drive 2 Iout (mA),Drive 2 Ipower (W),Pressure (),Map 20 (),Map 21 (),Map 22 (),Map 23 (),Map 24 (),Map 25 (),Map 26 (),Map 27 (),Map 28 (),Map 29 ()
,22228154.5,150.4360962,-0.3349229991436,,,2,,,,16.6900001952052,,,,,,,150.4360962,150.4360962,-0.3349229991436,-0.3349229991436,,,25.186911,,,,-99999999,4369,150.5415,-0.3349229991436,,,,,,,,,,,,,,,,,,,,,,,150.4360962,,,,
,22228306.5,150.2371216,4585.71923828125,5.64638212100487E-5,4.57060035756963E-7,1,0.999253354069792,40.0298881530762,1.99823396444889,16.6800003498793,0.000641054524190792,0.000116699632489326,0.25,4.2837005201894E-7,5.67393748924517E-5,5.20761408716825E-7,150.2371216,150.2371216,4575.591796875,4595.8466796875,56.424981174756,20.5111260951921,25.946213,0,0,0,40,4449,150.17025,4585.71923828125,,,,,,,,,,,,,0,,,,-0.00245,,,,,,150.2371216,,,,
,22228397.77,150.1270752,9147.03515625,5.47726684963067E-5,6.26943387748297E-7,1,0.999253354069792,40.0298881530762,1.99832877291244,16.6800003498793,0.000621424249750225,0.000115852551544906,0.25,6.48109458403039E-7,5.50397957374484E-5,7.38749815001185E-7,150.1270752,150.1270752,9141.908203125,9152.162109375,56.6141352764098,20.5182545562058,25.566563,0,0,0,40,4449,150.10305,9147.03515625,,,,,,,,,,,,,0,,,,-0.0049,,,,,,150.1270752,,,,
,22228492.975,150.0550842,13902.0869140625,4.63419908343348E-5,1.08119775841462E-6,1,0.999253354069792,40.0298881530762,1.99828547009437,16.6800003498793,0.000521290202093281,0.000123701734045856,0.25,2.80760721258828E-6,4.65645327900583E-5,2.89520411468538E-6,150.0550842,150.0550842,13899.431640625,13904.7421875,56.5281561392944,20.5268908082568,25.186911,0,0,0,40,4449,150.0807,13902.0869140625,,,,,,,,,,,,,0,,,,0.00245,,,,,,150.0550842,,,,
,22228587.425,150.017334,18624.466796875,3.4980400885495E-5,8.83612465267162E-7,1,0.999253354069792,40.0298881530762,1.99826327593606,16.6800003498793,0.000398020557695203,6.73262625446738E-5,0.25,-1.71702787024049E-7,3.5152100909927E-5,-1.16947676584853E-7,150.017334,150.017334,18611.85546875,18637.078125,56.882233858506,20.5262732010745,25.566563,0,0,0,40,4449,150.0827,18624.466796875,,,,,,,,,,,,,0,,,,-0.00245,,,,,,150.017334,,,,
,22228678.15,150.0020294,23159.697265625,2.10832631722877E-5,1.32025091076574E-6,1,0.999253354069792,40.0298881530762,1.99817058596661,16.6800003498793,0.000234492877899764,7.15200993283997E-5,0.25,2.61851071773194E-6,2.11824625389003E-5,2.66476788262674E-6,150.0020294,150.0020294,23149.787109375,23169.607421875,56.8837971155445,20.5253648554594,25.946213,0,0,0,40,4449,150.08885,23159.697265625,,,,,,,,,,,,,0,,,,-0.00245,,,,,,150.0020294,,,,
,22228769.88,149.9985809,27745.0859375,6.14401285280928E-6,1.19933278268626E-6,1,0.999253354069792,40.0298881530762,1.99824490580286,16.6800003498793,6.78174830967218E-5,2.38289878624569E-5,0.25,1.02576345808299E-6,6.17251552480759E-6,1.04050597211016E-6,149.9985809,149.9985809,27742.69140625,27747.48046875,56.5906864208329,20.5248663244537,25.566563,0,0,0,40,4449,150.0908,27745.0859375,,,,,,,,,,,,,0,,,,0,,,,,,149.9985809,,,,
,22228864.055,150.0016174,32449.8916015625,-8.93743389435449E-6,1.14118806074834E-6,1,0.999253354069792,40.0298881530762,1.99819131578162,16.6800003498793,-0.000103249731771106,-8.24952148165975E-6,0.25,8.31177631498247E-7,-8.98257269614952E-6,8.2116437130951E-7,150.0016174,150.0016174,32444.939453125,32454.84375,56.6094455052945,20.5230235731171,25.566563,0,0,0,40,4449,150.08985,32449.8916015625,,,,,,,,,,,,,0,,,,0.00245,,,,,,150.0016174,,,,
,22228959.605,150.0034714,37227.458984375,-2.43086847916684E-5,1.81852723156119E-6,1,0.999253354069792,40.0298881530762,1.99813217208306,16.6800003498793,-0.000279712385569809,-2.8786376743821E-5,0.25,1.70205787807868E-6,-2.44305912384759E-5,1.67219799791797E-6,150.0032959,150.0036469,37222.46484375,37232.453125,56.6110087623329,20.5209793856051,25.946213,0,0,0,40,4449,150.08785,37227.458984375,,,,,,,,,,,,,0,,,,0,,,,,,150.0034714,,,,
,22229054.65,150.0061798,41977.48828125,-3.76406660124335E-5,1.88788664904201E-6,1,0.999253354069792,40.0298881530762,1.99817913046906,16.6800003498793,-0.00042806303572019,-7.36608415838374E-5,0.25,7.68788751126685E-8,-3.78254446580129E-5,1.82689334061586E-8,150.0061035,150.0062561,41969.7890625,41985.1875,56.6407106460637,20.5196231691657,25.566563,0,0,0,40,4449,150.0843,41977.48828125,,,,,,,,,,,,,0,,,,0,,,,,,150.0061798,,,,
,22229150.105,150.0061646,46747.884765625,-5.45576031303121E-5,1.62906722573089E-6,1,0.999253354069792,40.0298881530762,1.99829677849265,16.6800003498793,-0.000623716443167991,-8.82139104996448E-5,0.25,1.74356659644589E-6,-5.48280321762172E-5,1.66688083932732E-6,150.0061646,150.0061646,46737.859375,46757.91015625,56.4703156288714,20.5249883481511,25.186911,0,0,0,40,4449,150.0753,46747.884765625,,,,,,,,,,,,,0,,,,0,,,,,,150.0061646,,,,
,22229247.815,150.0102997,51630.3359375,-6.86326238345518E-5,1.99039557896271E-6,1,0.999253354069792,40.0298881530762,1.99828962546454,16.6800003498793,-0.000781846438477373,-0.000126916235777846,0.25,7.90559516036645E-7,-6.89706879796476E-5,6.87543467680308E-7,150.0102997,150.0102997,51625.53125,51635.140625,56.4765686570252,20.5219446659439,25.566563,0,0,0,40,4449,150.06665,51630.3359375,,,,,,,,,,,,,0,,,,0.0049,,,,,,150.0102997,,,,
,22229341.78,150.0093079,56327.587890625,-8.72232741093436E-5,1.8620691412434E-6,1,0.999253354069792,40.0298881530762,1.99827384955349,16.6800003498793,-0.000997822914188321,-0.000137162820737552,0.25,3.1267843859278E-6,-8.7656291365801E-5,3.00669394341819E-6,150.0093079,150.0093079,56322.51953125,56332.65625,56.5039256551983,20.5238074385655,25.566563,0,0,0,40,4449,150.0548,56327.587890625,,,,,,,,,,,,,0,,,,0.00245,,,,,,150.0093079,,,,
,22229434.345,150.0041962,60953.029296875,-0.000105433408328183,2.46996638107532E-6,1,0.999253354069792,40.0298881530762,1.99813398005762,16.6800003498793,-0.00120289381834485,-0.000183996912866886,0.25,2.17734677412937E-6,-0.000105954454620049,2.0248308249368E-6,150.0041962,150.0041962,60945.828125,60960.23046875,56.5695824508137,20.5202792774336,25.566563,0,0,0,40,4449,150.05185,60953.029296875,,,,,,,,,,,,,0,,,,-0.00245,,,,,,150.0041962,,,,
,22229530.555,150.0039978,65763.671875,-0.000121499882703123,1.63957841154915E-6,1,0.999253354069792,40.0298881530762,1.99830256749321,16.6800003498793,-0.0013815218446776,-0.000239544591437268,0.25,9.03873437872856E-8,-0.000122096716479162,-9.66264593506509E-8,150.0039978,150.0039978,65758.8046875,65768.5390625,56.4781319140637,20.5236086788638,25.566563,0,0,0,40,4449,150.05075,65763.671875,,,,,,,,,,,,,0,,,,0,,,,,,150.0039978,,,,
,22229634.095,150.0051117,70938.5859375,-0.000139071744082264,2.66427132762705E-6,1,0.999253354069792,40.0298881530762,1.99828628905838,16.6800003498793,-0.00158243563825778,-0.000267741831688204,0.25,6.69588734273786E-7,-0.000139755921499337,4.59070643704096E-7,150.0051117,150.0051117,70931.1640625,70946.0078125,56.9424192544868,20.5197487375883,25.566563,0,0,0,40,4449,150.0458,70938.5859375,,,,,,,,,,,,,0,,,,-0.00245,,,,,,150.0051117,,,,
,22229736.365,150.01000975,76048.83984375,-0.000154256010786196,2.07719097405194E-6,1,0.999253354069792,40.0298881530762,1.9982373535978,16.6800003498793,-0.00175186391177746,-0.000315960081552414,0.25,-9.28670727540719E-7,-0.000155012477334816,-1.16955887250682E-6,150.0099487,150.0100708,76033.578125,76064.1015625,56.5492601093137,20.520914421477,25.566563,0,0,0,40,4449,150.03425,76048.83984375,,,,,,,,,,,,,0,,,,0,,,,,,150.01000975,,,,
,22229836.565,150.0153503,81057.48046875,-0.00017343164932531,1.80469315741962E-6,1,0.999253354069792,40.0298881530762,1.99827146797829,16.6800003498793,-0.00197241595080844,-0.000339491831242452,0.25,3.40465720871919E-7,-0.000174284436784942,7.73424570048355E-8,150.015274,150.0154266,81052.2734375,81062.6875,56.2248842738329,20.5205537738968,25.566563,0,0,0,40,4449,150.01895,81057.48046875,,,,,,,,,,,,,0,,,,0.00245,,,,,,150.0153503,,,,
,22229938.215,150.0200195,86139.75,-0.000190588907429949,3.01377439670016E-6,1,0.999253354069792,40.0298881530762,1.99837018006478,16.6800003498793,-0.00216215698952847,-0.00040462508939699,0.25,-2.40006286557478E-6,-0.00019152202387113,-2.70183895058435E-6,150.0200195,150.0200195,86129.8046875,86149.6953125,57.2480360055061,20.5243610376173,25.946213,0,0,0,40,4449,150.00165,86139.75,,,,,,,,,,,,,0,,,,-0.00245,,,,,,150.0200195,,,,
,22230057.75,150.02272035,88992.75390625,-0.000199273964696411,2.56822807956462E-6,1,0.999253354069792,40.0298881530762,1.99830648387977,16.6800003498793,-0.00226842403466375,-0.000378223156433689,0.25,1.43294660258203E-6,-0.000200255695753652,1.13734019505579E-6,150.022522,150.0229187,88987.7265625,88997.78125,56.8025077495445,20.5241816074368,25.946213,0,0,0,40,4449,149.9726,88992.75390625,,,,,,,,,,,,,0,,,,0.0049,,,,,,150.02272035,,,,
,22230153.46,150.0176849,84207.23046875,-0.000188892970161094,3.20685337546831E-6,1,0.999253354069792,40.0298881530762,1.99819773590468,16.6800003498793,-0.00214728334417121,-0.000374898969924084,0.25,-8.30736520837714E-8,-0.000189821181872186,-3.71389217450307E-7,150.0176849,150.0176849,84204.671875,84209.7890625,56.760299809506,20.5236225797625,25.946213,0,0,0,40,4449,149.9606,84207.23046875,,,,,,,,,,,,,0,,,,-0.0049,,,,,,150.0176849,,,,
,22230257.065,150.0156097,79026.02734375,-0.000168239087320256,4.02431914565503E-6,1,0.999253354069792,40.0298881530762,1.99815613021533,16.6800003498793,-0.00192331783985817,-0.000271524391398487,0.25,5.41375724902807E-6,-0.000169074005590943,5.18294513980818E-6,150.0156097,150.0156097,79015.8125,79036.2421875,56.7517018957945,20.5232534351248,25.566563,0,0,0,40,4449,149.9465,79026.02734375,,,,,,,,,,,,,0,,,,0,,,,,,150.0156097,,,,
,22230348.865,150.0079041,74437.71875,-0.000155195554606106,3.54714480661838E-6,1,0.999253354069792,40.0298881530762,1.99821535615635,16.6800003498793,-0.00176859723667542,-0.000282953479398341,0.25,2.13841755394097E-6,-0.000155961250810214,1.91067843345869E-6,150.0079041,150.0079041,74432.6015625,74442.8359375,56.587559906756,20.5219790041649,25.566563,0,0,0,40,4449,149.9395,74437.71875,,,,,,,,,,,,,0,,,,0,,,,,,150.0079041,,,,
,22230442.63,150.0053787,69752.16796875,-0.000136341457741751,2.4671310551143E-6,1,0.999253354069792,40.0298881530762,1.99825619970975,16.6800003498793,-0.00155231906966309,-0.000256892571572992,0.25,1.14843118493658E-6,-0.000137012880119919,9.44076222034016E-7,150.0046997,150.0060577,69749.5625,69754.7734375,56.811105663256,20.5238107543205,25.566563,0,0,0,40,4449,149.9371,69752.16796875,,,,,,,,,,,,,0,,,,0.0049,,,,,,150.0053787,,,,
,22230537.245,150.0009918,65024.08203125,-0.000121143854557965,2.61217909930973E-6,1,0.999253354069792,40.0298881530762,1.99828020820068,16.6800003498793,-0.00137560470775454,-0.000249483045517417,0.25,-8.45731581553074E-7,-0.000121737440745031,-1.03708940659922E-6,150.0009918,150.0009918,65016.53125,65031.6328125,56.719655126506,20.5269947446539,25.566563,0,0,0,40,4449,149.9357,65024.08203125,,,,,,,,,,,,,0,,,,0.00245,,,,,,150.0009918,,,,
,22230631.79,149.9967651,60295.740234375,-0.000101941407506382,1.90734460115772E-6,1,0.999253354069792,40.0298881530762,1.99826811915771,16.6800003498793,-0.00116587526081359,-0.000162138589777838,0.25,3.49308350171111E-6,-0.000102447323750048,3.35219523551307E-6,149.9966583,149.9968719,60288.08984375,60303.390625,56.4750053999867,20.5257960099267,25.186911,0,0,0,40,4449,149.9395,60295.740234375,,,,,,,,,,,,,0,,,,0.00245,,,,,,149.9967651,,,,
,22230732.08,149.9922028,55282.982421875,-8.59756840087405E-5,1.8746406023773E-6,1,0.999253354069792,40.0298881530762,1.99827246810419,16.6800003498793,-0.000981653143838781,-0.000146091617425275,0.25,2.12434368303959E-6,-8.64010181861378E-5,2.00103847911869E-6,149.9922028,149.9922028,55275.40234375,55290.5625,56.8017261210252,20.5249007589431,25.946213,0,0,0,40,4449,149.9458,55282.982421875,,,,,,,,,,,,,0,,,,0.0049,,,,,,149.9922028,,,,
,22230830.75,149.985733,50352.833984375,-6.82725761041436E-5,2.0263525721172E-6,1,0.999253354069792,40.0298881530762,1.99841855867674,16.6900008916855,-0.000777150110156141,-0.000129948239310079,0.25,4.62062640639847E-7,-6.86083668732074E-5,3.57793554975797E-7,149.985733,149.985733,50347.875,50357.79296875,56.5093970548329,20.5291280780534,25.566563,0,0,0,40,4449,149.9558,50352.833984375,,,,,,,,,,,,,0,,,,0,,,,,,149.985733,,,,
,22230925.355,149.9792786,45625.646484375,-5.27674129163351E-5,2.16935104253631E-6,1,0.999253354069792,40.0298881530762,1.99823193431373,16.6800003498793,-0.000603496599585587,-8.37977654298789E-5,0.25,1.82010258273138E-6,-5.30291926509326E-5,1.74645333500753E-6,149.9792786,149.9792786,45615.5859375,45635.70703125,56.8642564025637,20.5277137513316,25.946213,0,0,0,40,4449,149.97815,45625.646484375,,,,,,,,,,,,,0,,,,0,,,,,,149.9792786,,,,
,22231027.805,149.9768829,40503.16796875,-3.36224491948924E-5,1.31065621621007E-6,1,0.999253354069792,40.0298881530762,1.9982098647342,16.6800003498793,-0.000389062800704491,-2.73874245992789E-5,0.25,3.44748627049642E-6,-3.37928148993354E-5,3.41162028422043E-6,149.9768829,149.9768829,40498.109375,40508.2265625,56.8064158921406,20.5271349448305,25.566563,0,0,0,40,4449,150.00515,40503.16796875,,,,,,,,,,,,,0,,,,-0.00245,,,,,,149.9768829,,,,
,22231129.695,149.9803925,35410.55078125,-1.80474433705675E-5,2.37510723048907E-6,1,0.999253354069792,40.0298881530762,1.9982237357727,16.6800003498793,-0.000211656323534265,1.48116759956632E-6,0.25,3.27398480543944E-6,-1.81411198643771E-5,3.26162579440242E-6,149.9803925,149.9803925,35405.65234375,35415.44921875,56.780622151006,20.5303512434626,25.566563,0,0,0,40,4449,150.0197,35410.55078125,,,,,,,,,,,,,0,,,,0.0049,,,,,,149.9803925,,,,
,22231232.755,149.9851379,30260.869140625,-4.68293350000084E-8,1.10467000029802E-6,1,0.999253354069792,40.0298881530762,1.99826234122894,16.6800003498793,-2.14540614051364E-6,9.16705950035242E-6,0.25,8.14498284212971E-7,-4.83453581454098E-8,8.18418422877681E-7,149.9851379,149.9851379,30253.359375,30268.37890625,56.8509687177368,20.5278490007131,25.566563,0,0,0,40,4449,150.0359,30260.869140625,,,,,,,,,,,,,0,,,,0.0049,,,,,,149.9851379,,,,
,22231336.72,149.9928436,25063.74609375,1.50263868543731E-5,1.28798461811898E-6,1,0.999253354069792,40.0298881530762,1.99820101033885,16.6800003498793,0.000169867074529583,3.5258926637379E-5,0.25,4.83891538598434E-7,1.50992870402423E-5,5.10067851716895E-7,149.9928436,149.9928436,25056.416015625,25071.076171875,56.6571248449675,20.5256769744005,25.946213,0,0,0,40,4449,150.0429,25063.74609375,,,,,,,,,,,,,0,,,,0,,,,,,149.9928436,,,,
,22231437.82,149.999176,20011.650390625,3.09726145671891E-5,8.28374488998488E-7,1,0.999253354069792,40.0298881530762,1.99815274531128,16.6800003498793,0.000351465279068313,6.49752418073836E-5,0.25,3.19995531385481E-7,3.11239123927057E-5,3.70772093185152E-7,149.999176,149.999176,20009.224609375,20014.076171875,57.065134932006,20.5212878053086,25.566563,0,0,0,40,4449,150.04175,20011.650390625,,,,,,,,,,,,,0,,,,0.00245,,,,,,149.999176,,,,
,22231542.27,150.0073395,14792.0844726562,4.45860009547297E-5,6.48402482698461E-7,1,0.999253354069792,40.0298881530762,1.99817839002769,16.6800003498793,0.000508088706376888,8.12598356124263E-5,0.25,-6.19329989476324E-7,4.48054615117649E-5,-5.5132006969856E-7,150.0071106,150.0075684,14777.203125,14806.9658203125,56.9041194570445,20.5266352008034,25.946213,0,0,0,40,4449,150.0332,14792.0844726562,,,,,,,,,,,,,0,,,,0.00245,,,,,,150.0073395,,,,
,22231643.63,150.0102234,9725.02734375,5.6402870373592E-5,5.9382467932478E-7,1,0.999253354069792,40.0298881530762,1.99816927650885,16.6800003498793,0.000640972830676085,0.000112978724897898,0.25,1.12011044133887E-7,5.66790110847095E-5,2.02673460203972E-7,150.0102234,150.0102234,9715.033203125,9735.021484375,56.7735874943329,20.5248843478517,26.325863,0,0,0,40,4449,150.0252,9725.02734375,,,,,,,,,,,,,0,,,,-0.00245,,,,,,150.0102234,,,,
,22231742.39,150.0104065,4789.87060546875,6.3379887130667E-5,4.6266507460226E-7,1,0.999253354069792,40.0298881530762,1.99821837796856,16.6800003498793,0.000720273635702343,0.000126977741730618,0.25,1.27448227116751E-7,6.36901296827401E-5,2.29575012180638E-7,150.0104065,150.0104065,4787.55419921875,4792.18701171875,56.882233858506,20.5278063737448,25.946213,0,0,0,40,4449,150.0132,4789.87060546875,,,,,,,,,,,,,0,,,,0,,,,,,150.0104065,,,,
,22231831.53,150.0090942,333.150619506836,5.49824469893484E-5,2.71126082875822E-7,1,0.999253354069792,40.0298881530762,1.99822950075118,16.6800003498793,0.000625058547894099,0.00010892782476029,0.25,2.51068345121861E-9,5.52517263242553E-5,9.07267106420922E-8,150.0090942,150.0090942,328.082794189453,338.218444824219,57.0659165605253,20.5310850290627,25.566563,0,0,0,40,4449,150.006,333.150619506836,,,,,,,,,,,,,0,,,,0.0049,,,,,,150.0090942,,,,
,22231926.075,150.0078278,-4390.46997070313,1.67715703381803E-5,3.39707253824053E-7,1,0.999253354069792,40.0298881530762,1.99819352736688,16.6800003498793,0.000192130467701501,2.47948187659865E-5,0.25,-7.40862063775156E-7,1.68549069479842E-5,-7.17623348146618E-7,150.0078278,150.0078278,-4400.44873046875,-4380.4912109375,56.7423223535637,20.5304456711369,25.566563,0,0,0,40,4449,149.9999,-4390.46997070313,,,,,,,,,,,,,0,,,,0,,,,,,150.0078278,,,,
,22232020.595,150.006958,-9114.470703125,-1.85723775861299E-5,6.22652642095447E-7,1,0.999253354069792,40.0298881530762,1.9981812517645,16.6800003498793,-0.000208343519870774,-5.28013294338584E-5,0.25,-1.40906450038716E-6,-1.86611096784414E-5,-1.4456573808819E-6,150.006958,150.006958,-9119.525390625,-9109.416015625,56.8157954343714,20.5302854856922,26.325863,0,0,0,40,4449,149.99575,-9114.470703125,,,,,,,,,,,,,0,,,,0,,,,,,150.006958,,,,
,22232118.335,150.0081177,-14002.0483398438,-3.59151553970538E-5,1.04721487676947E-6,1,0.999253354069792,40.0298881530762,1.99819950712552,16.6800003498793,-0.000406706754625473,-8.02418077171618E-5,0.25,-8.01549482857249E-7,-3.60898513523708E-5,-8.62755339426842E-7,150.0081177,150.0081177,-14011.9794921875,-13992.1171875,56.790783321756,20.5299288614561,25.566563,0,0,0,40,4449,149.98565,-14002.0483398438,,,,,,,,,,,,,0,,,,-0.00245,,,,,,150.0081177,,,,
,22232217.89,150.0076141,-18974.2177734375,-2.9429968857677E-5,8.23112904776773E-7,1,0.999253354069792,40.0298881530762,1.99824246890942,16.6800003498793,-0.000332205192512634,-7.18952560178222E-5,0.25,-1.19713610728744E-6,-2.95722912253485E-5,-1.24981371946929E-6,150.0076141,150.0076141,-18979.158203125,-18969.27734375,56.9377294833714,20.5380706068191,25.946213,0,0,0,40,4449,149.9831,-18974.2177734375,,,,,,,,,,,,,0,,,,0,,,,,,150.0076141,,,,
,22232312.035,150.002533,-23681.4794921875,-1.73134912160034E-5,1.3405800446073E-6,1,0.999253354069792,40.0298881530762,1.99843143183607,16.6800003498793,-0.000196747153672442,-3.48669537353753E-5,0.25,-5.06236482134171E-8,-1.73982769679105E-5,-7.83377078973459E-8,150.002533,150.002533,-23686.462890625,-23676.49609375,56.9588334533906,20.5388439456488,25.566563,0,0,0,40,4449,149.97975,-23681.4794921875,,,,,,,,,,,,,0,,,,0,,,,,,150.002533,,,,
,22232406.605,149.9962921,-28406.5234375,-2.48264118518354E-6,9.24400513731639E-7,1,0.999253354069792,40.0298881530762,1.99836978162566,16.6800003498793,-2.95539046847511E-5,2.70689798858155E-6,0.25,6.70560579977693E-7,-2.49587405710717E-6,6.69920844930826E-7,149.9962921,149.9962921,-28409.08984375,-28403.95703125,56.8916134007368,20.5383345734202,25.566563,0,0,0,40,4449,149.98145,-28406.5234375,,,,,,,,,,,,,0,,,,0,,,,,,149.9962921,,,,
,22232508.52,149.9958649,-33498.056640625,1.32110485908797E-5,1.38607736796746E-6,1,0.999253354069792,40.0298881530762,1.99832481431027,16.6800003498793,0.000151774890867966,1.71063814095328E-5,0.25,-7.96631344760591E-7,1.32770914984562E-5,-7.79704886536262E-7,149.9958649,149.9958649,-33505.6875,-33490.42578125,56.9213152844676,20.5347077970268,25.946213,0,0,0,40,4449,149.9885,-33498.056640625,,,,,,,,,,,,,0,,,,0,,,,,,149.9958649,,,,
,22232610.54,149.9998474,-38597.7265625,2.8827932894106E-5,1.11604216040472E-6,1,0.999253354069792,40.0298881530762,1.99838349116762,16.6800003498793,0.000330800103660299,3.96172365819127E-5,0.25,-1.53693247432539E-6,2.89717483627914E-5,-1.49915490168058E-6,149.9998474,149.9998474,-38607.6796875,-38587.7734375,56.8783257159099,20.5375814385553,25.946213,0,0,0,40,4449,149.98655,-38597.7265625,,,,,,,,,,,,,0,,,,-0.0049,,,,,,149.9998474,,,,
,22232715.405,150.0067291,-43839.734375,4.5616854514672E-5,1.3734918482311E-6,1,0.999253354069792,40.0298881530762,1.99841777512686,16.6800003498793,0.000522770849564815,6.66566102471161E-5,0.25,-2.0829678339466E-6,4.58439085778841E-5,-2.02171551083384E-6,150.0067291,150.0067291,-43844.52734375,-43834.94140625,57.1511140691214,20.5379449762607,26.325863,0,0,0,40,4449,149.9807,-43839.734375,,,,,,,,,,,,,0,,,,0.0049,,,,,,150.0067291,,,,
,22232822.795,150.0137482,-49207.09375,6.29247177739302E-5,1.42774485828291E-6,1,0.999253354069792,40.0298881530762,1.99835272499433,16.6800003498793,0.00071722814157744,0.00011416065050236,0.25,-9.18912262620788E-7,6.32349109693652E-5,-8.25157166894732E-7,150.0137482,150.0137482,-49212.0546875,-49202.1328125,56.8392442899483,20.5389776802883,25.946213,0,0,0,40,4449,149.95805,-49207.09375,,,,,,,,,,,,,0,,,,-0.0049,,,,,,150.0137482,,,,
,22232926.47,150.0211945,-54386.4609375,7.99680944016864E-5,1.73585143088994E-6,1,0.999253354069792,40.0298881530762,1.99828988702134,16.6800003498793,0.000910406145499543,0.000151157919349653,0.25,-6.32543793385186E-7,8.03615365408337E-5,-5.11178449695552E-7,150.0211945,150.0211945,-54394.046875,-54378.875,56.8736359447945,20.5373641473403,25.946213,0,0,0,40,4449,149.94035,-54386.4609375,,,,,,,,,,,,,0,,,,0,,,,,,150.0211945,,,,
,22233029.89,150.02188875,-59555.7734375,9.89082307126388E-5,1.82219894228479E-6,1,0.999253354069792,40.0298881530762,1.99828318442033,16.6800003498793,0.00112912892348621,0.000169165244391385,0.25,-2.3469477773554E-6,9.9397387747118E-5,-2.20502472089598E-6,150.021637,150.0221405,-59565.7421875,-59545.8046875,56.9580518248714,20.5413325807908,26.325863,0,0,0,40,4449,149.9184,-59555.7734375,,,,,,,,,,,,,0,,,,-0.00245,,,,,,150.02188875,,,,
,22233131.07,150.0227966,-64610.810546875,0.000114822177910671,2.50232461334521E-6,1,0.999253354069792,40.0298881530762,1.99840511548899,16.6800003498793,0.00130623922194334,0.000223034816221844,0.25,-3.80906623954992E-7,0.000115386521095124,-2.05223545324646E-7,150.0227966,150.0227966,-64618.15625,-64603.46484375,56.9986965078714,20.5420027212959,25.946213,0,0,0,40,4449,149.89535,-64610.810546875,,,,,,,,,,,,,0,,,,0,,,,,,150.0227966,,,,
,22233229.955,150.021347,-69555,0.000132404445915885,2.43303509118192E-6,1,0.999253354069792,40.0298881530762,1.99838025611336,16.6800003498793,0.00150737805924098,0.000250662582562999,0.25,-1.01220498728857E-6,0.000133056231789212,-8.13096557915855E-7,150.021347,150.021347,-69564.9296875,-69545.0703125,56.7790588939676,20.5400615982592,25.946213,0,0,0,40,4449,149.8741,-69555,,,,,,,,,,,,,0,,,,0.00245,,,,,,150.021347,,,,
,22233325.485,150.0166473,-74329.5625,0.000150635174736286,2.85494419027976E-6,1,0.999253354069792,40.0298881530762,1.99838518663475,16.6800003498793,0.00172445290743339,0.000230521297929972,0.25,-5.95803966758378E-6,0.00015138426316631,-5.75588234354664E-6,150.0166473,150.0166473,-74336.8828125,-74322.2421875,56.7587365524675,20.5395231978658,25.946213,0,0,0,40,4449,149.8636,-74329.5625,,,,,,,,,,,,,0,,,,0.00245,,,,,,150.0166473,,,,
,22233420.635,150.01579285,-79083.91015625,0.000165404120456755,2.2782172164744E-6,1,0.999253354069792,40.0298881530762,1.99835017035356,16.6800003498793,0.00188955648407366,0.000275740110910803,0.25,-4.55169712663629E-6,0.000166223748330385,-4.32076127489112E-6,150.0157776,150.0158081,-79088.8671875,-79078.953125,56.9275683126214,20.5420747418178,25.946213,0,0,0,40,4449,149.846,-79083.91015625,,,,,,,,,,,,,0,,,,0,,,,,,150.01579285,,,,
,22233517.61,150.011673,-83928.3515625,0.000184819957757975,2.84722452036936E-6,1,0.999253354069792,40.0298881530762,1.99839885907371,16.6800003498793,0.00210106065102976,0.000367557170594912,0.25,1.43078592519766E-7,0.000185728013239615,4.25854787315826E-7,150.011673,150.011673,-83941.03125,-83915.671875,56.7032409276022,20.5435791831424,25.946213,0,0,0,40,4449,149.8381,-83928.3515625,,,,,,,,,,,,,0,,,,-0.0049,,,,,,150.011673,,,,
,22233609.68,150.0115891,-88530.421875,0.000198233932747946,2.0864230521886E-6,1,0.999253354069792,40.0298881530762,1.99833075489853,16.6800003498793,0.00225848300495269,0.000365500950042178,0.25,-2.37171603716295E-6,0.000199211939966642,-2.08179939874677E-6,150.0114594,150.0117188,-88537.8984375,-88522.9453125,56.8681645451599,20.5421574144628,25.566563,0,0,0,40,4449,149.82645,-88530.421875,,,,,,,,,,,,,0,,,,0,,,,,,150.0115891,,,,
,22233719.555,150.0063934,-87051.3984375,0.000195556189756573,1.96158159108372E-6,1,0.999253354069792,40.0298881530762,1.99846632776889,16.6800003498793,0.00222894279980458,0.000355857751774101,0.25,-2.75595632906186E-6,0.00019652158217988,-2.47166471156038E-6,150.0063934,150.0063934,-87054.265625,-87048.53125,57.0065127930637,20.5416407393218,25.946213,0,0,0,40,4449,149.8198,-87051.3984375,,,,,,,,,,,,,0,,,,-0.00245,,,,,,150.0063934,,,,
,22233812.525,150.0003052,-82404.53125,0.000178014380449278,3.18421870941666E-6,1,0.999253354069792,40.0298881530762,1.99840117393495,16.6800003498793,0.00202811067342602,0.000328671858479709,0.25,-2.09223984226132E-6,0.00017889239345716,-1.83050331760605E-6,150.0003052,150.0003052,-82412.1015625,-82396.9609375,56.7532651528329,20.5420030936255,26.325863,0,0,0,40,4449,149.8243,-82404.53125,,,,,,,,,,,,,0,,,,0,,,,,,150.0003052,,,,
,22233905.515,149.9927826,-77757.02734375,0.000162534578773051,2.1681980246812E-6,1,0.999253354069792,40.0298881530762,1.99842162905727,16.6800003498793,0.00184102563587634,0.000361770916953729,0.25,3.5135385103601E-6,0.000163327799630719,3.77997664820191E-6,149.9927826,149.9927826,-77764.625,-77749.4296875,57.044812590506,20.5445809809906,25.946213,0,0,0,40,4449,149.83105,-77757.02734375,,,,,,,,,,,,,0,,,,-0.00245,,,,,,149.9927826,,,,
,22233998.67,149.9899139,-73104.90625,0.000145070665456819,1.96578655619502E-6,1,0.999253354069792,40.0298881530762,1.99830286731717,16.6800003498793,0.00164519666586828,0.00031094129403477,0.25,2.08512255525969E-6,0.000145780117799712,2.31848402810387E-6,149.9899139,149.9899139,-73112.453125,-73097.359375,57.0706063316407,20.5454684019115,25.566563,0,0,0,40,4449,149.83915,-73104.90625,,,,,,,,,,,,,0,,,,0.0049,,,,,,149.9899139,,,,
,22234092.015,149.9909821,-68435.42578125,0.000128921519890898,2.46219472652154E-6,1,0.999253354069792,40.0298881530762,1.99841193445042,16.6800003498793,0.00147226851073752,0.000218122951690326,0.25,-3.2681430645722E-6,0.000129559750507734,-3.08527844360139E-6,149.9909821,149.9909821,-68445.5234375,-68425.328125,56.9611783389483,20.545270967169,25.566563,0,0,0,40,4449,149.84745,-68435.42578125,,,,,,,,,,,,,0,,,,0,,,,,,149.9909821,,,,
,22234183.99,149.9878845,-63843.294921875,0.000113314653717683,1.97002005915664E-6,1,0.999253354069792,40.0298881530762,1.99829921954195,16.6800003498793,0.00128028431943449,0.000270282570254226,0.25,4.03829329578372E-6,0.000113864834922232,4.23349895917524E-6,149.9878845,149.9878845,-63853.32421875,-63833.265625,56.9947883652753,20.5425108366651,25.566563,0,0,0,40,4449,149.85845,-63843.294921875,,,,,,,,,,,,,0,,,,0,,,,,,149.9878845,,,,
,22234275.99,149.990448,-59243.138671875,9.52273955552235E-5,2.42851373899604E-6,1,0.999253354069792,40.0298881530762,1.9983506968551,16.6800003498793,0.00107981090289177,0.000204982087969778,0.25,1.44385125779199E-6,9.56926646756364E-5,1.59877332590317E-6,149.990448,149.990448,-59250.7734375,-59235.50390625,57.017455592333,20.5401765723426,25.566563,0,0,0,40,4449,149.86885,-59243.138671875,,,,,,,,,,,,,0,,,,0,,,,,,149.990448,,,,
,22234372.005,149.9903412,-54446.091796875,8.01015592025033E-5,2.35197751081487E-6,1,0.999253354069792,40.0298881530762,1.99841107332271,16.6800003498793,0.000909445508597808,0.000165964829732816,0.25,6.45682889224855E-7,8.04937203686562E-5,7.7360149366141E-7,149.9903412,149.9903412,-54453.68359375,-54438.5,56.7688977232175,20.544688927024,26.325863,0,0,0,40,4449,149.8749,-54446.091796875,,,,,,,,,,,,,0,,,,0,,,,,,149.9903412,,,,
,22234466.4,149.9905548,-49729.255859375,6.49483326949947E-5,2.32786747196716E-6,1,0.999253354069792,40.0298881530762,1.99857802730025,16.6800003498793,0.000737725136791205,0.000133051083126277,0.25,3.88853709386748E-7,6.52664479016769E-5,4.92220535071672E-7,149.9905548,149.9905548,-49736.828125,-49721.68359375,56.9174071418714,20.542024735748,26.325863,0,0,0,40,4449,149.8856,-49729.255859375,,,,,,,,,,,,,0,,,,-0.00245,,,,,,149.9905548,,,,
,22234560.77,149.9898376,-45011.837890625,5.0844886715146E-5,2.07641481575446E-6,1,0.999253354069792,40.0298881530762,1.99859725690598,16.6800003498793,0.000589074594544368,3.79032848021266E-5,0.25,-5.5228560925928E-6,5.11030020619962E-5,-5.47028639230358E-6,149.9898376,149.9898376,-45014.19921875,-45009.4765625,56.8408075469868,20.5424732562298,26.325863,0,0,0,40,4449,149.89465,-45011.837890625,,,,,,,,,,,,,0,,,,-0.0049,,,,,,149.9898376,,,,
,22234656.355,149.9890747,-40234.47265625,3.35124522085077E-5,1.51140963059813E-6,1,0.999253354069792,40.0298881530762,1.99837532568366,16.6800003498793,0.000385170810717951,4.25111176326262E-5,0.25,-2.09835964700954E-6,3.36801399308333E-5,-2.05598734543213E-6,149.9890747,149.9890747,-40246.89453125,-40222.05078125,56.9009929429675,20.5430253926623,25.946213,0,0,0,40,4449,149.9062,-40234.47265625,,,,,,,,,,,,,0,,,,0.0049,,,,,,149.9890747,,,,
,22234749.47,149.989975,-35579.34765625,1.85671206473527E-5,1.56904219915432E-6,1,0.999253354069792,40.0298881530762,1.99829557200911,16.6800003498793,0.000215833444626493,9.526782279203E-6,0.25,-2.3962803229931E-6,1.86619567339287E-5,-2.37877005112411E-6,149.989975,149.989975,-35584.40625,-35574.2890625,56.8775440873906,20.5432545003088,25.946213,0,0,0,40,4449,149.9137,-35579.34765625,,,,,,,,,,,,,0,,,,0,,,,,,149.989975,,,,
,22234844.165,149.9905243,-30849.6376953125,3.03680851285783E-6,1.2760865068501E-6,1,0.999253354069792,40.0298881530762,1.9983884487548,16.6800003498793,4.06602508543356E-5,-2.91961860871029E-5,0.25,-3.09696589780813E-6,3.05659391009171E-6,-3.10735158988272E-6,149.9905243,149.9905243,-30862.0390625,-30837.236328125,56.9721211382176,20.5429190704653,25.566563,0,0,0,40,4449,149.9204,-30849.6376953125,,,,,,,,,,,,,0,,,,0.0049,,,,,,149.9905243,,,,
,22234938.515,149.9886322,-26134.919921875,-1.15444128199304E-5,1.23667127186609E-6,1,0.999253354069792,40.0298881530762,1.99831689294073,16.6800003498793,-0.000127769488734554,-4.28335325046109E-5,0.25,-1.75652563103211E-6,-1.15982250167035E-5,-1.78343300206401E-6,149.9886322,149.9886322,-26144.9609375,-26124.87890625,56.9220969129868,20.5421877214132,26.325863,0,0,0,40,4449,149.9319,-26134.919921875,,,,,,,,,,,,,0,,,,-0.00245,,,,,,149.9886322,,,,
,22235036.01,149.9907074,-21260.337890625,-2.78374498112474E-5,8.43604564485248E-7,1,0.999253354069792,40.0298881530762,1.99833949497628,16.6800003498793,-0.000313365299585377,-7.30502250597455E-5,0.25,-1.57589279882377E-6,-2.79713891551193E-5,-1.62785640672844E-6,149.9907074,149.9907074,-21267.6953125,-21252.98046875,56.9822823089676,20.5431475710654,26.325863,0,0,0,40,4449,149.9398,-21260.337890625,,,,,,,,,,,,,0,,,,0.00245,,,,,,149.9907074,,,,
,22235128.79,149.9901962,-16623.099609375,-3.91716404638637E-5,9.50829860222276E-7,1,0.999253354069792,40.0298881530762,1.9983901979487,16.6800003498793,-0.000439116925436129,-0.0001133987781118,0.25,-3.14999411592509E-6,-3.93585856254491E-5,-3.22783986148302E-6,149.9899139,149.9904785,-16630.568359375,-16615.630859375,56.9166255133522,20.5431502984749,25.946213,0,0,0,40,4449,149.9456,-16623.099609375,,,,,,,,,,,,,0,,,,0,,,,,,149.9901962,,,,
,22235223.12,149.9904938,-11908.234375,-5.15324549556138E-5,7.43460582496337E-7,1,0.999253354069792,40.0298881530762,1.99822519062404,16.6800003498793,-0.000582524249877835,-0.000121113629342322,0.25,-1.67583785934633E-6,-5.17822738325058E-5,-1.76634820712519E-6,149.9904938,149.9904938,-11918.2783203125,-11898.1904296875,56.9213152844676,20.5406452479923,26.325863,0,0,0,40,4449,149.95455,-11908.234375,,,,,,,,,,,,,0,,,,-0.0049,,,,,,149.9904938,,,,
,22235315.505,149.9937897,-7292.35888671875,-6.00822986240355E-5,5.9948802891374E-7,1,0.999253354069792,40.0298881530762,1.99817199352934,16.6800003498793,-0.000681870805152803,-0.000125609715061243,0.25,-5.8190545252589E-7,-6.03757021494387E-5,-6.80921663642742E-7,149.9937897,149.9937897,-7294.8154296875,-7289.90234375,56.7821854080445,20.5382400035726,25.946213,0,0,0,40,4449,149.9587,-7292.35888671875,,,,,,,,,,,,,0,,,,-0.00245,,,,,,149.9937897,,,,
,22235407.77,149.9922028,-2679.35729980469,-6.28510265428963E-5,3.43916665678072E-7,1,0.999253354069792,40.0298881530762,1.99811232858987,16.6800003498793,-0.00071428464579482,-0.000125582795313269,0.25,-9.73107783313055E-8,-6.31587301701134E-5,-1.98573046467586E-7,149.9922028,149.9922028,-2686.94677734375,-2671.76782226562,56.7540467813522,20.5407664038211,25.566563,0,0,0,40,4449,149.96815,-2679.35729980469,,,,,,,,,,,,,0,,,,0,,,,,,149.9922028,,,,
,22235497.595,149.9945831,1808.26208496094,-3.36621232617957E-5,3.44129752351958E-7,1,0.999253354069792,40.0298881530762,1.99808337566413,16.6800003498793,-0.000381713387681557,-7.20925962017498E-5,0.25,-4.77271698194494E-7,-3.38262372978188E-5,-5.3360435861522E-7,149.9945831,149.9945831,1803.09948730469,1813.42468261719,57.014329078256,20.5336197744698,25.946213,0,0,0,40,4449,149.97115,1808.26208496094,,,,,,,,,,,,,0,,,,0,,,,,,149.9945831,,,,
,22235590.99,149.9986191,6476.55688476563,-2.47781049878939E-7,4.76897565860505E-7,1,0.999253354069792,40.0298881530762,1.99812670832438,16.6800003498793,-2.28664834156463E-6,-3.53345097947456E-6,0.25,-2.67659760923092E-7,-2.48566324310233E-7,-2.69367618607842E-7,149.9986115,149.9986267,6466.6318359375,6486.48193359375,56.9986965078714,20.535485039978,25.946213,0,0,0,40,4449,149.97095,6476.55688476563,,,,,,,,,,,,,0,,,,-0.00245,,,,,,149.9986191,,,,
,22235685.5,150.00148775,11199.2915039062,3.03418009522878E-5,5.80150141243588E-7,1,0.999253354069792,40.0298881530762,1.99811265501343,16.6800003498793,0.000344772084854997,6.09393843390105E-5,0.25,7.47226968913058E-8,3.04903366192122E-5,1.23556151639881E-7,150.0013123,150.0016632,11189.1318359375,11209.451171875,56.6985511564868,20.5375177229877,25.946213,0,0,0,40,4449,149.9693,11199.2915039062,,,,,,,,,,,,,0,,,,0.00245,,,,,,150.00148775,,,,
,22235776.34,150.0055542,15739.7749023438,3.5874273665429E-5,7.47494133004714E-7,1,0.999253354069792,40.0298881530762,1.99809351555089,16.6800003498793,0.000409646432929325,6.04974779609441E-5,0.25,-9.27808634808942E-7,3.60515377911313E-5,-8.75182189493423E-7,150.0055542,150.0055542,15737.3740234375,15742.17578125,57.2574155477368,20.5354874990437,25.946213,0,0,0,40,4449,149.96365,15739.7749023438,,,,,,,,,,,,,0,,,,0.00245,,,,,,150.0055542,,,,
,22235867.89,150.0068512,20314.443359375,2.76960360920561E-5,9.81832086645088E-7,1,0.999253354069792,40.0298881530762,1.99808592172331,16.6800003498793,0.000313003867256802,6.53892465538226E-5,0.25,9.27368941695252E-7,2.78302962542024E-5,9.75944799396728E-7,150.0068512,150.0068512,20309.6484375,20319.23828125,56.841589175506,20.5369525487106,25.566563,0,0,0,40,4449,149.957,20314.443359375,,,,,,,,,,,,,0,,,,0,,,,,,150.0068512,,,,
,22235964.16,150.0095215,25127.1494140625,1.52609437506665E-5,9.81495449080772E-7,1,0.999253354069792,40.0298881530762,1.99808123011915,16.6800003498793,0.000171810330551286,3.98158069461131E-5,0.25,8.44052326021901E-7,1.53344102463592E-5,8.72386754555958E-7,150.0095215,150.0095215,25122.048828125,25132.25,56.7040225561214,20.5391950108436,25.946213,0,0,0,40,4449,149.9465,25127.1494140625,,,,,,,,,,,,,0,,,,-0.00245,,,,,,150.0095215,,,,
,22236057.01,150.0110016,29767.654296875,-2.04645452409652E-7,1.20587325798972E-6,1,0.999253354069792,40.0298881530762,1.99800870540064,16.6800003498793,-2.21074027676836E-6,-1.06844513428771E-6,0.25,-5.83439247515577E-8,-2.05556483037659E-7,-5.89535777140549E-8,150.0110016,150.0110016,29760.232421875,29775.076171875,56.9963516223137,20.5385450288409,25.566563,0,0,0,40,4449,149.93525,29767.654296875,,,,,,,,,,,,,0,,,,0.00245,,,,,,150.0110016,,,,
,22236152.365,150.0116272,34532.513671875,-1.63459036041045E-5,1.48687798922199E-6,1,0.999253354069792,40.0298881530762,1.99806469533568,16.6800003498793,-0.000188240659847655,-1.84392037805873E-5,0.25,1.22526589228795E-6,-1.64279886172188E-5,1.20549863873712E-6,150.0116272,150.0116272,34527.7421875,34537.28515625,56.8587850029291,20.5386407415472,25.946213,0,0,0,40,4449,149.92635,34532.513671875,,,,,,,,,,,,,0,,,,-0.00245,,,,,,150.0116272,,,,
,22236246.025,150.0115662,39215.025390625,-3.0003325865593E-5,1.64154633334936E-6,1,0.999253354069792,40.0298881530762,1.99808843826874,16.6800003498793,-0.000344048945775463,-4.23182061573422E-5,0.25,1.50359454794392E-6,-3.0152842021435E-5,1.46379164819848E-6,150.0115662,150.0115662,39205.15234375,39224.8984375,56.8353361473522,20.5428154769854,25.946213,0,0,0,40,4449,149.91535,39215.025390625,,,,,,,,,,,,,0,,,,-0.0049,,,,,,150.0115662,,,,
,22236341.17,150.0109863,43969.943359375,-4.82271149498182E-5,1.72544281334417E-6,1,0.999253354069792,40.0298881530762,1.99788500232339,16.6800003498793,-0.000554292667736148,-6.04122430816444E-5,0.25,3.08553937278512E-6,-4.84685324694859E-5,3.02506764497641E-6,150.0109863,150.0109863,43962.421875,43977.46484375,56.8595666314483,20.5407594636579,25.566563,0,0,0,40,4449,149.906,43969.943359375,,,,,,,,,,,,,0,,,,-0.00245,,,,,,150.0109863,,,,
,22236437.08,150.0099487,48762.861328125,-6.63914254406213E-5,2.03646328070115E-6,1,0.999253354069792,40.0298881530762,1.99815468265304,16.6800003498793,-0.000763095614501053,-8.35515334373036E-5,0.25,4.21439611277422E-6,-6.67237685777952E-5,4.13130567033684E-6,150.0099487,150.0099487,48750.328125,48775.39453125,57.146424298006,20.5405978957194,26.325863,0,0,0,40,4449,149.89615,48762.861328125,,,,,,,,,,,,,0,,,,0.00245,,,,,,150.0099487,,,,
,22236531.125,150.0113831,53463.38671875,-8.00561236412698E-5,2.06807390732747E-6,1,0.999253354069792,40.0298881530762,1.99801801292893,16.6800003498793,-0.000916341561806895,-0.000122301183050661,0.25,3.18482359569518E-6,-8.04539680146394E-5,3.07570641501635E-6,150.0113831,150.0113831,53453.62890625,53473.14453125,56.6242964471598,20.5377861147693,25.946213,0,0,0,40,4449,149.8867,53463.38671875,,,,,,,,,,,,,0,,,,0.00245,,,,,,150.0113831,,,,
,22236623.585,150.0113678,58086.12109375,-9.41394190615296E-5,2.19719178817427E-6,1,0.999253354069792,40.0298881530762,1.99803261243105,16.6800003498793,-0.00107211738046707,-0.000175013027506763,0.25,1.00037121644413E-6,-9.46030647653961E-5,8.59033088335122E-7,150.0113678,150.0113678,58080.6640625,58091.578125,57.0018230219483,20.5373153302699,25.946213,0,0,0,40,4449,149.87695,58086.12109375,,,,,,,,,,,,,0,,,,-0.00245,,,,,,150.0113678,,,,
,22236716.67,150.0115662,62736.83203125,-0.000107802566582662,1.93951567016867E-6,1,0.999253354069792,40.0298881530762,1.99797950376658,16.6800003498793,-0.0012284253622292,-0.000196196669532005,0.25,1.51561537566513E-6,-0.000108334182770736,1.35610247570356E-6,150.0115662,150.0115662,62724.30859375,62749.35546875,56.9095908566791,20.5360368784415,25.946213,0,0,0,40,4449,149.86985,62736.83203125,,,,,,,,,,,,,0,,,,0.00245,,,,,,150.0115662,,,,
,22236811.82,150.0111237,67494.5234375,-0.000126591669558898,2.08328318548474E-6,1,0.999253354069792,40.0298881530762,1.99811555342397,16.6800003498793,-0.00144087514184391,-0.000240454682553184,0.25,8.95332442545332E-7,-0.000127214702161338,7.04299549705463E-7,150.0111237,150.0111237,67481.7109375,67507.3359375,56.7337244398522,20.5366287641529,25.946213,0,0,0,40,4449,149.85815,67494.5234375,,,,,,,,,,,,,0,,,,0,,,,,,150.0111237,,,,
,22236905.735,150.0106812,72189.74609375,-0.000139970563954824,2.40287577464589E-6,1,0.999253354069792,40.0298881530762,1.99817619856307,16.6800003498793,-0.00159364446558852,-0.000263336816569659,0.25,1.21255596073636E-6,-0.000140659927326499,1.00311562544202E-6,150.0106812,150.0106812,72184.875,72194.6171875,57.0049495360253,20.5348494356169,25.946213,0,0,0,40,4449,149.8476,72189.74609375,,,,,,,,,,,,,0,,,,-0.0049,,,,,,150.0106812,,,,
,22237000.705,150.0121765,76935.11328125,-0.000154470123231474,2.58464900096832E-6,1,0.999253354069792,40.0298881530762,1.99819239858971,16.6800003498793,-0.00175877960341438,-0.000290422548906883,0.25,1.3546233894608E-6,-0.000155231073530064,1.12434352209086E-6,150.0121155,150.0122375,76927.5,76942.7265625,56.8525319747752,20.5317334762369,25.946213,0,0,0,40,4449,149.83775,76935.11328125,,,,,,,,,,,,,0,,,,0,,,,,,150.0121765,,,,
,22237092.72,150.0123291,81536.11328125,-0.000172582777162594,2.79135751869174E-6,1,0.999253354069792,40.0298881530762,1.99825921546511,16.6800003498793,-0.00196428468535418,-0.000329013251222164,0.25,1.11451730391323E-6,-0.000173432513079881,8.56117712808379E-7,150.0123291,150.0123291,81531.2421875,81540.984375,56.4124751184483,20.5322879650435,25.566563,0,0,0,40,4449,149.827,81536.11328125,,,,,,,,,,,,,0,,,,0.00245,,,,,,150.0123291,,,,
,22237184.985,150.0112,86146.6015625,-0.000190252762455209,3.05486796182946E-6,1,0.999253354069792,40.0298881530762,1.9984883748509,16.6900008916855,-0.00215851017185204,-0.000403673072785153,0.25,-2.37239136226536E-6,-0.0001911842090954,-2.67400118530786E-6,150.0112,150.0112,86134.3125,86158.890625,56.7735874943329,20.5339075253851,25.946213,0,0,0,40,4449,149.81975,86146.6015625,,,,,,,,,,,,,0,,,,0.0049,,,,,,150.0112,,,,
,22237295.72,150.008316,89391.48046875,-0.000205317758473144,3.17488833034432E-6,1,0.999253354069792,40.0298881530762,1.99840481599907,16.6800003498793,-0.00233293048917551,-0.000414995130795379,0.25,-7.46884891697949E-7,-0.000206325891033087,-1.06276225377261E-6,150.008316,150.008316,89386.390625,89396.5703125,57.0088576786214,20.5337573901697,26.325863,0,0,0,40,4449,149.8091,89391.48046875,,,,,,,,,,,,,0,,,,0.0049,,,,,,150.008316,,,,
,22237385.63,150.0024261,84899.4609375,-0.000189291093618853,2.71656976676012E-6,1,0.999253354069792,40.0298881530762,1.99852531814654,16.6800003498793,-0.00216482663088364,-0.00030292996173546,0.25,6.32119149815581E-6,-0.000190231059735,6.06349057699254E-6,150.0024261,150.0024261,84894.5703125,84904.3515625,56.648526931256,20.5357315416865,25.946213,0,0,0,40,4449,149.8106,84899.4609375,,,,,,,,,,,,,0,,,,0,,,,,,150.0024261,,,,
,22237479.47,149.9967499,80205.63671875,-0.000170082646457851,2.66470858656931E-6,1,0.999253354069792,40.0298881530762,1.99831534957722,16.6800003498793,-0.00193671516673409,-0.000319465970341049,0.25,1.51994157614411E-6,-0.000170920735145379,1.26707585874425E-6,149.9967499,149.9967499,80200.59375,80210.6796875,56.6860451001791,20.5335155660845,25.946213,0,0,0,40,4449,149.8131,80205.63671875,,,,,,,,,,,,,0,,,,0,,,,,,149.9967499,,,,
,22237574.095,149.9945831,75476.7734375,-0.000150808152849126,2.38422868881083E-6,1,0.999253354069792,40.0298881530762,1.99832069791899,16.6800003498793,-0.00172256731974282,-0.000252679034010649,0.25,4.03853919611339E-6,-0.000151555252702128,3.82678255634739E-6,149.9945831,149.9945831,75466.9765625,75486.5703125,57.0807675023906,20.5331843911805,25.946213,0,0,0,40,4449,149.81905,75476.7734375,,,,,,,,,,,,,0,,,,0.00245,,,,,,149.9945831,,,,
,22237668.335,149.9924469,70763.8125,-0.000139868775535292,2.17298563586909E-6,1,0.999253354069792,40.0298881530762,1.9982885423566,16.6800003498793,-0.00158980532375562,-0.000279041176407175,0.25,-1.84997721059079E-7,-0.000140555505298943,-4.01402845909702E-7,149.9924469,149.9924469,70758.9765625,70768.6484375,56.6696309012752,20.5323599224682,26.325863,0,0,0,40,4449,149.827,70763.8125,,,,,,,,,,,,,0,,,,0,,,,,,149.9924469,,,,
,22237764.695,149.9904938,65948.31640625,-0.000117551351346808,2.42904855140202E-6,1,0.999253354069792,40.0298881530762,1.99822227151908,16.6800003498793,-0.00133027111698634,-0.000267936606703058,0.25,-3.09515273307236E-6,-0.000118123842047191,-3.29205889246593E-6,149.9904938,149.9904938,65940.671875,65955.9609375,56.8204852054868,20.5346830983832,26.325863,0,0,0,40,4449,149.8358,65948.31640625,,,,,,,,,,,,,0,,,,0.0049,,,,,,149.9904938,,,,
,22237858.38,149.9902954,61267.646484375,-0.000104224678945097,1.72768229539461E-6,1,0.999253354069792,40.0298881530762,1.99816574912025,16.6800003498793,-0.00118602192404155,-0.000199685637613476,0.25,5.87311270461504E-7,-0.000104737312126637,4.28581139221892E-7,149.9902954,149.9902954,61262.80859375,61272.484375,56.9588334533906,20.5337279186561,25.566563,0,0,0,40,4449,149.8449,61267.646484375,,,,,,,,,,,,,0,,,,0,,,,,,149.9902954,,,,
,22237952.47,149.9903717,56564.681640625,-8.55973079013916E-5,1.87442615465258E-6,1,0.999253354069792,40.0298881530762,1.99823678485151,16.6800003498793,-0.000975900047310072,-0.000153577682231766,0.25,1.39974151948929E-6,-8.60196620923812E-5,1.27346828327799E-6,149.9903717,149.9903717,56559.66015625,56569.703125,56.9111541137176,20.539243129503,26.325863,0,0,0,40,4449,149.85395,56564.681640625,,,,,,,,,,,,,0,,,,0.0049,,,,,,149.9903717,,,,
,22238043.595,149.9918823,52009.5546875,-7.14624151324266E-5,2.5323415931593E-6,1,0.999253354069792,40.0298881530762,1.99826370660246,16.6800003498793,-0.000807223919213041,-0.000171468313520637,0.25,-2.63531914502757E-6,-7.180902151894E-5,-2.75974248190023E-6,149.9918823,149.9918823,52007.1875,52011.921875,56.607882248256,20.5355064522524,26.325863,0,0,0,40,4449,149.8623,52009.5546875,,,,,,,,,,,,,0,,,,0.00245,,,,,,149.9918823,,,,
,22238137.35,149.9897308,47321.9609375,-5.32394034444412E-5,1.50930122026836E-6,1,0.999253354069792,40.0298881530762,1.99832169471442,16.6800003498793,-0.000601545603876126,-0.000126892274109388,0.25,-1.88787269484456E-6,-5.3497682354843E-5,-1.9804483967958E-6,149.9897308,149.9897308,47314.5390625,47329.3828125,56.7993812354675,20.5359110909875,26.325863,0,0,0,40,4449,149.8696,47321.9609375,,,,,,,,,,,,,0,,,,-0.0049,,,,,,149.9897308,,,,
,22238230.42,149.9917755,42668.955078125,-3.86815954546998E-5,1.51881409945564E-6,1,0.999253354069792,40.0298881530762,1.99826539566334,16.6800003498793,-0.000437078826033186,-9.20060607942994E-5,0.25,-1.35509944379546E-6,-3.88692288997532E-5,-1.42245880787559E-6,149.9917755,149.9917755,42666.58984375,42671.3203125,57.0190188493714,20.5354408608257,26.705515,0,0,0,40,4449,149.87555,42668.955078125,,,,,,,,,,,,,0,,,,0.00245,,,,,,149.9917755,,,,
,22238324.39,149.9897003,37974.044921875,-2.33387691120037E-5,1.45398356013396E-6,1,0.999253354069792,40.0298881530762,1.99824262481741,16.6800003498793,-0.000271042207602392,-1.34240298170038E-5,0.25,2.88458993291354E-6,-2.34577810239707E-5,2.86200113591324E-6,149.9897003,149.9897003,37968.97265625,37979.1171875,57.1237570709483,20.5366307989922,26.325863,0,0,0,40,4449,149.8862,37974.044921875,,,,,,,,,,,,,0,,,,0,,,,,,149.9897003,,,,
,22238417.895,149.9900208,33302.173828125,-1.09473154660993E-5,1.68935641549863E-6,1,0.999253354069792,40.0298881530762,1.99831555610475,16.6800003498793,-0.0001230128005504,-2.99888304265169E-5,0.25,-7.30805075645761E-7,-1.09998452689437E-5,-7.5166946856211E-7,149.9900208,149.9900208,33292.1171875,33312.23046875,57.1831608384099,20.5353145642212,26.325863,0,0,0,40,4449,149.8962,33302.173828125,,,,,,,,,,,,,0,,,,-0.0049,,,,,,149.9900208,,,,
,22238509.715,149.9905243,28711.9384765625,4.86825471691953E-6,1.16963772084688E-6,1,0.999253354069792,40.0298881530762,1.99823693316348,16.6800003498793,5.48935746814593E-5,1.22327799194703E-5,0.25,2.27972384476466E-7,4.8917622177271E-6,2.36795557535251E-7,149.9905243,149.9905243,28704.62109375,28719.255859375,56.9674313671022,20.5371500206335,26.325863,0,0,0,40,4449,149.9065,28711.9384765625,,,,,,,,,,,,,0,,,,-0.00245,,,,,,149.9905243,,,,
,22238599.77,149.9907684,24211.666015625,1.84678784374513E-5,1.12706180810006E-6,1,0.999253354069792,40.0298881530762,1.99826018426967,16.6800003498793,0.000212458783630859,2.22032520461531E-5,0.25,-1.26414604791151E-6,1.85604130523357E-5,-1.2410357241332E-6,149.9907684,149.9907684,24206.61328125,24216.71875,56.5023623981598,20.5349055340018,26.325863,0,0,0,40,4449,149.9128,24211.666015625,,,,,,,,,,,,,0,,,,-0.0049,,,,,,149.9907684,,,,
,22238692.475,149.9927063,19579.1083984375,3.15453218144272E-5,9.90984920752286E-7,1,0.999253354069792,40.0298881530762,1.99828307065854,16.6800003498793,0.000359554577069184,5.71784661307035E-5,0.25,-4.6600298482743E-7,3.1700666839321E-5,-4.1809871299168E-7,149.9927063,149.9927063,19573.79296875,19584.423828125,57.0182372208522,20.5368132147138,25.566563,0,0,0,40,4449,149.9221,19579.1083984375,,,,,,,,,,,,,0,,,,-0.0049,,,,,,149.9927063,,,,
,22238786.68,149.9900665,14869.7348632812,4.47452882396766E-5,7.85584441570588E-7,1,0.999253354069792,40.0298881530762,1.99838671742708,16.6800003498793,0.000509304023025127,8.52933360252876E-5,0.25,-2.93090747254876E-7,4.49650163271273E-5,-2.23158560014628E-7,149.9900665,149.9900665,14862.4130859375,14877.056640625,56.8736359447945,20.539922839777,26.325863,0,0,0,40,4449,149.9278,14869.7348632812,,,,,,,,,,,,,0,,,,0,,,,,,149.9900665,,,,
,22238879.55,149.9913177,10229.5048828125,5.59988543771808E-5,5.89994402513753E-7,1,0.999253354069792,40.0298881530762,1.99826541547545,16.6800003498793,0.000636952272396735,0.00010906737724803,0.25,-1.62163667039503E-7,5.62734719031757E-5,-7.34359616309594E-8,149.9913177,149.9913177,10224.41015625,10234.599609375,56.7868751791599,20.5355300729777,25.566563,0,0,0,40,4449,149.9376,10229.5048828125,,,,,,,,,,,,,0,,,,0,,,,,,149.9913177,,,,
,22238969.725,149.99061585,5721.55224609375,6.23052829378889E-5,3.5361137004263E-7,1,0.999253354069792,40.0298881530762,1.99829487466543,16.6800003498793,0.000708474140286548,0.000122610793548178,0.25,-6.98940521293339E-8,6.26106065070204E-5,2.95729960653881E-8,149.9902802,149.9909515,5716.7216796875,5726.3828125,56.7352876968906,20.5380186719624,26.325863,0,0,0,40,4449,149.94315,5721.55224609375,,,,,,,,,,,,,0,,,,0.00245,,,,,,149.99061585,,,,
,22239063.245,149.9941711,1048.04467773438,5.92964124949647E-5,3.51518827069E-7,1,0.999253354069792,40.0298881530762,1.99823073060942,16.6800003498793,0.000674253851386724,0.000116601271775146,0.25,-7.41379267722689E-8,5.95869601789071E-5,2.06582486553931E-8,149.9941711,149.9941711,1043.02624511719,1053.06311035156,56.6969878994483,20.5360321928938,25.566563,0,0,0,40,4449,149.9473,1048.04467773438,,,,,,,,,,,,,0,,,,0,,,,,,149.9941711,,,,
,22239085.45,149.9939117,-0.449101313948631,5.07600019108733E-5,3.5066057512714E-7,1,0.999253354069792,40.0298881530762,1.99838182131996,16.6800003498793,0.00057823194724526,9.40641515287468E-5,0.25,-5.6995780170226E-7,5.10095305618226E-5,-4.91267948451807E-7,149.9939117,149.9939117,-0.456713199615479,-0.441489428281784,57.0135474497368,20.5371905935537,26.705515,0,0,0,40,4417,149.9485,-0.449101313948631,,,,,,,,,,,,,0,,,,0,,,,,,149.9939117,,,,