File: data/doubleLayers/dl_1-25/ppms/data/DD205_3_HYST_100OE_200K.DAT
[Header]
; VSM Data File (default extension .dat)
; Copyright (c) 2003-2013, Quantum Design, Inc. All rights reserved.
TITLE,
FILEOPENTIME,32569631.08,01/13/2019,7:09 am
BYAPP,VSM,2.0,2.0
INFO,PPMS VSM Option Release 1.4.10 Build 1,APPNAME
INFO,Quantum Design Linear Motor Servo Controller,MOTOR_MODULE_NAME
INFO,3101-100 M1,MOTOR_HW_VERSION
INFO,MMC1014,MOTOR_SERIAL_NUMBER
INFO,SRV No X-over 01.03.11,MOTOR_SOFTWARE_VERSION
INFO,Quantum Design VSM Detection Module,VSM_MODULE_NAME
INFO,3101-150 F0,VSM_HW_VERSION
INFO,VSM707,VSM_SERIAL_NUMBER
INFO,VSM No X-over 01.02.05 May 20 2008 13:51:47,VSM_SOFTWARE_VERSION
INFO,704,PREAMP_SERIAL_NUMBER
INFO,822,COIL_SERIAL_NUMBER
INFO,0,MOMENT_UNITS
INFO,DD205_4,SAMPLE_MATERIAL
INFO,Double Layer Blue 1.25,SAMPLE_COMMENT
INFO,26.73,SAMPLE_MASS
INFO,,SAMPLE_VOLUME
INFO,,SAMPLE_MOLECULAR_WEIGHT
INFO,,SAMPLE_SIZE
INFO,,SAMPLE_SHAPE
DATATYPE,COMMENT,1
DATATYPE,TIME,2
STARTUPAXIS,X,2
STARTUPAXIS,Y1,5
[Data]
Comment,Time Stamp (sec),Temperature (K),Magnetic Field (Oe),Moment (emu),M. Std. Err. (emu),Transport Action,Averaging Time (sec),Frequency (Hz),Peak Amplitude (mm),Center Position (mm),Coil Signal' (mV),Coil Signal" (mV),Range (mV),M. Quad. Signal (emu),M. Raw' (emu),M. Raw" (emu),Min. Temperature (K),Max. Temperature (K),Min. Field (Oe),Max. Field (Oe),Mass (grams),Motor Lag (deg),Pressure (Torr),VSM Status (code),Motor Status (code),Measure Status (code),Measure Count,PPMS Status (code),System Temp. (K),System Field (Oe),Sample Position (deg),Bridge 1 Resistance (ohms),Bridge 1 Excitation (에),Bridge 2 Resistance (ohms),Bridge 2 Excitation (에),Bridge 3 Resistance (ohms),Bridge 3 Excitation (에),Bridge 4 Resistance (ohms),Bridge 4 Excitation (에),Signal 1 Vin (V),Signal 2 Vin (V),Digital Inputs (code),Drive 1 Iout (mA),Drive 1 Ipower (W),Drive 2 Iout (mA),Drive 2 Ipower (W),Pressure (),Map 20 (),Map 21 (),Map 22 (),Map 23 (),Map 24 (),Map 25 (),Map 26 (),Map 27 (),Map 28 (),Map 29 ()
,32569646.47,199.986084,-0.471936970949173,,,2,,,,20.2000004583597,,,,,,,199.986084,199.986084,-0.471936970949173,-0.471936970949173,,,22.529354,,,,-99999999,4369,199.9193,-0.471936970949173,,,,,,,,,,,,,,,,,,,,,,,199.986084,,,,
,32569799.18,199.9807129,4773.25170898438,4.74285435975878E-5,4.83907151474867E-7,1,0.999253354069792,40.0298881530762,1.99710314676166,20.1900005340576,0.000538580972773549,9.11105048528374E-5,0.25,-2.08404932402457E-7,4.75925068087292E-5,-1.57642871757167E-7,199.9807129,199.9807129,4765.80322265625,4780.7001953125,56.5305010248521,20.5820218046785,22.529354,0,0,0,40,4449,199.9461,4773.25170898438,,,,,,,,,,,,,0,,,,-0.0049,,,,,,199.9807129,,,,
,32569898.495,199.9847565,9734.61572265625,4.37558587449803E-5,5.79311540479515E-7,1,0.999253354069792,40.0298881530762,1.9972345232844,20.1900005340576,0.000498575797766269,7.44501044180759E-5,0.25,-1.03910287051584E-6,4.39080474797856E-5,-9.95266691825696E-7,199.9847565,199.9847565,9727.3056640625,9741.92578125,56.7563916669098,20.5841883048534,22.529354,0,0,0,40,4449,199.9564,9734.61572265625,,,,,,,,,,,,,0,,,,0,,,,,,199.9847565,,,,
,32569999.11,199.9877777,14767.0859375,3.29605625933196E-5,8.97453272387617E-7,1,0.999253354069792,40.0298881530762,1.99713074193688,20.1900005340576,0.000375409275747974,5.68911975789547E-5,0.25,-7.11123468297158E-7,3.30751305795861E-5,-6.77916000443145E-7,199.9877777,199.9877777,14759.5869140625,14774.5849609375,57.1104693861214,20.5870966071819,22.529354,0,0,0,40,4449,199.96885,14767.0859375,,,,,,,,,,,,,0,,,,0.00245,,,,,,199.9877777,,,,
,32570098.29,199.9917603,19721.904296875,1.9659562350025E-5,8.94736484014592E-7,1,0.999253354069792,40.0298881530762,1.99736798845887,20.1900005340576,0.000228445484511084,8.00196701688488E-6,0.25,-2.70946154224899E-6,1.97303676581857E-5,-2.69758235216396E-6,199.9917603,199.9917603,19716.9375,19726.87109375,57.4536043060638,20.5870973214778,22.909004,0,0,0,40,4449,199.9744,19721.904296875,,,,,,,,,,,,,0,,,,0,,,,,,199.9917603,,,,
,32570200.225,199.9967804,24819.30078125,3.96320589562284E-6,1.30008236307024E-6,1,0.999253354069792,40.0298881530762,1.99739106117746,20.1900005340576,4.96417780245621E-5,-1.90482933292407E-5,0.25,-2.36682087883659E-6,3.97944190560926E-6,-2.37072034645536E-6,199.9967804,199.9967804,24814.60546875,24823.99609375,57.1143775287176,20.5868560250848,22.529354,0,0,0,40,4449,199.9725,24819.30078125,,,,,,,,,,,,,0,,,,0.0049,,,,,,199.9967804,,,,
,32570298.82,200.0000305,29744.865234375,-1.00823395114939E-5,1.80566668358885E-6,1,0.999253354069792,40.0298881530762,1.99761911437985,20.1900005340576,-0.000114534757646725,-1.92858711760328E-5,0.25,5.1887323225583E-8,-1.01172099105E-5,4.12167327355071E-8,200.0000305,200.0000305,29732.580078125,29757.150390625,57.1542405831984,20.5807377109459,23.288654,0,0,0,40,4449,199.97215,29744.865234375,,,,,,,,,,,,,0,,,,-0.0049,,,,,,200.0000305,,,,
,32570400.72,200.0004272,34839.40625,-2.60758992715338E-5,1.72623370854773E-6,1,0.999253354069792,40.0298881530762,1.99750179283234,20.1900005340576,-0.000293145727831076,-6.74854538321811E-5,0.25,-1.4174527624386E-6,-2.6164425380135E-5,-1.45035318447769E-6,200.0004272,200.0004272,34834.5234375,34844.2890625,57.4223391652945,20.5882326284362,22.529354,0,0,0,40,4449,199.9698,34839.40625,,,,,,,,,,,,,0,,,,0.0049,,,,,,200.0004272,,,,
,32570499.615,200.0056305,39781.517578125,-4.12400440375719E-5,1.89551665367677E-6,1,0.999253354069792,40.0298881530762,1.99766524620156,20.1900005340576,-0.000462548191017519,-0.000113127183820721,0.25,-2.80465544434536E-6,-4.13794581728245E-5,-2.85854742196495E-6,200.0056305,200.0056305,39771.71484375,39791.3203125,57.5434915857753,20.5893368755412,23.288654,0,0,0,40,4449,199.9629,39781.517578125,,,,,,,,,,,,,0,,,,0.0049,,,,,,200.0056305,,,,
,32570599.8,200.0053406,44787.65234375,-5.72532802585661E-5,2.00579534742989E-6,1,0.999253354069792,40.0298881530762,1.99767955840264,20.1900005340576,-0.000646698437525,-0.000130907429983603,0.25,-1.5900996013153E-6,-5.74493195153895E-5,-1.65683767215486E-6,200.0053406,200.0053406,44779.68359375,44795.62109375,57.413741251583,20.5870460585792,22.909004,0,0,0,40,4449,199.9614,44787.65234375,,,,,,,,,,,,,0,,,,0.0049,,,,,,200.0053406,,,,
,32570698.78,200.010025,49734.826171875,-7.29760179631687E-5,2.59949286269796E-6,1,0.999253354069792,40.0298881530762,1.99767113487227,20.1900005340576,-0.000826995488792916,-0.000151277177237833,0.25,-6.54332617597787E-7,-7.322737393625E-5,-7.34502056761084E-7,200.010025,200.010025,49727,49742.65234375,57.3293253715061,20.5837383624681,22.529354,0,0,0,40,4449,199.9509,49734.826171875,,,,,,,,,,,,,0,,,,0,,,,,,200.010025,,,,
,32570800.305,200.0078735,54810.1328125,-8.75683240748073E-5,2.26572560941674E-6,1,0.999253354069792,40.0298881530762,1.99769769805341,20.1900005340576,-0.000989968196984512,-0.000195386056263297,0.25,-2.00623046461836E-6,-8.78686772383309E-5,-2.10645070225537E-6,200.0078735,200.0078735,54805.03125,54815.234375,57.2941520881407,20.5805250511244,22.149702,0,0,0,40,4449,199.94505,54810.1328125,,,,,,,,,,,,,0,,,,-0.00245,,,,,,200.0078735,,,,
,32570894.39,200.0086975,59512.58203125,-0.000100149866265225,2.21999457957594E-6,1,0.999253354069792,40.0298881530762,1.99771153226016,20.1900005340576,-0.00114265162202173,-0.000163345100528893,0.25,3.00162428977822E-6,-0.00010049903697756,2.90551155020148E-6,200.0086975,200.0086975,59507.33984375,59517.82421875,57.6466665503138,20.5780898806015,22.909004,0,0,0,40,4449,199.9373,59512.58203125,,,,,,,,,,,,,0,,,,0,,,,,,200.0086975,,,,
,32570989.175,200.011322,64248.25,-0.000111742365428841,2.47246625838728E-6,1,0.999253354069792,40.0298881530762,1.99755032885453,20.1900005340576,-0.00127958177130366,-0.000154803826729977,0.25,5.76609584786518E-6,-0.000112134535616805,5.66744850383737E-6,200.011322,200.011322,64245.53515625,64250.96484375,57.4059249663907,20.5825158352331,22.529354,0,0,0,40,4449,199.9279,64248.25,,,,,,,,,,,,,0,,,,0,,,,,,200.011322,,,,
,32571083.935,200.00994875,68985.98046875,-0.000125457993254787,2.73759511860328E-6,1,0.999253354069792,40.0298881530762,1.99758592821103,20.1900005340576,-0.00143968617897118,-0.000156420779102613,0.25,8.00552886166744E-6,-0.000125899952533806,7.90033905549593E-6,200.0096741,200.0102234,68983.484375,68988.4765625,57.5583425276407,20.5833577627619,22.149702,0,0,0,40,4449,199.9177,68985.98046875,,,,,,,,,,,,,0,,,,-0.0049,,,,,,200.00994875,,,,
,32571181.96,200.0138092,73885.9765625,-0.000142862060754667,2.96803256818049E-6,1,0.999253354069792,40.0298881530762,1.99742978246854,20.1900005340576,-0.0016307795395534,-0.000227074732828998,0.25,4.8009706093751E-6,-0.000143360778758121,4.6666046461114E-6,200.0138092,200.0138092,73880.8125,73891.140625,57.3949821671215,20.5813323785033,22.909004,0,0,0,40,4449,199.9094,73885.9765625,,,,,,,,,,,,,0,,,,-0.0049,,,,,,200.0138092,,,,
,32571280.235,200.0109253,78796.63671875,-0.000169634174173231,2.76878757349094E-6,1,0.999253354069792,40.0298881530762,1.99745802713105,20.1900005340576,-0.00192377871798614,-0.000342377908829445,0.25,-7.09628435667918E-7,-0.000170219650883058,-8.90939525205626E-7,200.0109253,200.0109253,78789.25,78804.0234375,57.3136928011214,20.5825366689793,22.909004,0,0,0,40,4449,199.89655,78796.63671875,,,,,,,,,,,,,0,,,,0,,,,,,200.0109253,,,,
,32571380.66,200.0100098,83817.36328125,-0.000173781671210842,3.12664314461519E-6,1,0.999253354069792,40.0298881530762,1.99737907166643,20.1900005340576,-0.00199003699159432,-0.000239619081686711,0.25,9.06385967184349E-6,-0.000174391828984221,8.91236858965434E-6,200.0100098,200.0100098,83807.3203125,83827.40625,57.403580080833,20.5817288490846,22.909004,0,0,0,40,4449,199.88995,83817.36328125,,,,,,,,,,,,,0,,,,0.00245,,,,,,200.0100098,,,,
,32571477.18,200.011673,88640.49609375,-0.000187444014717406,3.16424774124548E-6,1,0.999253354069792,40.0298881530762,1.99742954343525,20.1900005340576,-0.0021415350808689,-0.000287293718969003,0.25,7.23566442290354E-6,-0.000188099503589943,7.06391449944285E-6,200.011673,200.011673,88635.453125,88645.5390625,57.2112994651022,20.5798063388565,23.288654,0,0,0,40,4449,199.8819,88640.49609375,,,,,,,,,,,,,0,,,,-0.0049,,,,,,200.011673,,,,
,32571587.79,200.0058136,86773.61328125,-0.000184634735665064,2.97460621713476E-6,1,0.999253354069792,40.0298881530762,1.99754889960928,20.1900005340576,-0.00211077968509566,-0.000275979166706077,0.25,7.74635870092656E-6,-0.000185281068970242,7.57915220511246E-6,200.0058136,200.0058136,86763.7421875,86783.484375,57.4856510753522,20.5772900806445,22.909004,0,0,0,40,4449,199.87935,86773.61328125,,,,,,,,,,,,,0,,,,-0.00245,,,,,,200.0058136,,,,
,32571685.93,200.0022049,81870.29296875,-0.000170024474454611,3.16470553513219E-6,1,0.999253354069792,40.0298881530762,1.99756877237825,20.1900005340576,-0.00194872318106454,-0.000225623919718369,0.25,9.64658564417897E-6,-0.000170622288560136,9.500888416657E-6,200.0019226,200.0024872,81865.28125,81875.3046875,57.4207759082561,20.5791779803281,23.288654,0,0,0,40,4449,199.87755,81870.29296875,,,,,,,,,,,,,0,,,,0,,,,,,200.0022049,,,,
,32571785.84,199.9949493,76873.8671875,-0.000158890042039705,3.0549585630454E-6,1,0.999253354069792,40.0298881530762,1.99749755714122,20.1900005340576,-0.00180737482428832,-0.00028955813445129,0.25,2.07934458153073E-6,-0.000159441392830028,1.91884114349239E-6,199.9949493,199.9949493,76866.2734375,76881.4609375,57.5466180998522,20.5818405842973,22.529354,0,0,0,40,4449,199.8839,76873.8671875,,,,,,,,,,,,,0,,,,0,,,,,,199.9949493,,,,
,32571886.94,199.9930115,71820.5625,-0.00013506368480297,2.19263183627871E-6,1,0.999253354069792,40.0298881530762,1.99749747436642,20.1900005340576,-0.00154622884169201,-0.000189249110763233,0.25,6.78039043820698E-6,-0.000135537626817133,6.66095756015396E-6,199.9930115,199.9930115,71812.9296875,71828.1953125,57.4567308201407,20.580997748599,22.909004,0,0,0,40,4449,199.88935,71820.5625,,,,,,,,,,,,,0,,,,0,,,,,,199.9930115,,,,
,32571986.62,199.9940186,66839.63671875,-0.000130529498085962,2.8795704359564E-6,1,0.999253354069792,40.0298881530762,1.99759264023625,20.1900005340576,-0.00147950633040136,-0.000268598231480339,0.25,-9.9726035037193E-7,-0.000130979492805476,-1.13907996303902E-6,199.9940186,199.9940186,66829.890625,66849.3828125,57.3949821671215,20.5834132971683,22.909004,0,0,0,40,4449,199.89335,66839.63671875,,,,,,,,,,,,,0,,,,0,,,,,,199.9940186,,,,
,32572086.82,199.9889221,61829.23828125,-0.0001067794251546,2.3079205858078E-6,1,0.999253354069792,40.0298881530762,1.99767326236304,20.1900005340576,-0.00121946911051736,-0.000167248334980437,0.25,3.80873001323174E-6,-0.0001071524365274,3.70845137141092E-6,199.9889221,199.9889221,61826.65234375,61831.82421875,57.6599542351407,20.5824517794153,23.288654,0,0,0,40,4449,199.904,61829.23828125,,,,,,,,,,,,,0,,,,-0.00245,,,,,,199.9889221,,,,
,32572185.14,199.9920197,56913.609375,-9.7842723994323E-5,2.58773818056746E-6,1,0.999253354069792,40.0298881530762,1.99755837737752,20.1900005340576,-0.00110832272888036,-0.000205200344569195,0.25,-1.08781310221044E-6,-9.81796096050771E-5,-1.19573425330348E-6,199.9920197,199.9920197,56908.703125,56918.515625,57.6130565239869,20.5832472853941,22.909004,0,0,0,40,4449,199.9117,56913.609375,,,,,,,,,,,,,0,,,,-0.00245,,,,,,199.9920197,,,,
,32572285.75,199.9936829,51885.81640625,-7.77473211917021E-5,1.8843643260683E-6,1,0.999253354069792,40.0298881530762,1.9975934678465,20.1900005340576,-0.000881391783776865,-0.000159100962148851,0.25,-5.15572123325052E-7,-7.80153561640922E-5,-6.0029734154402E-7,199.9936829,199.9936829,51875.81640625,51895.81640625,57.5005020172176,20.5840892036447,22.909004,0,0,0,40,4449,199.91885,51885.81640625,,,,,,,,,,,,,0,,,,-0.0049,,,,,,199.9936829,,,,
,32572385.76,199.9880371,46885.962890625,-6.44648066212214E-5,1.80779298385481E-6,1,0.999253354069792,40.0298881530762,1.99755803255276,20.1900005340576,-0.000726837327337406,-0.000154737160988157,0.25,-2.43797771380034E-6,-6.46848914567236E-5,-2.5153133686892E-6,199.9880371,199.9880371,46878.4140625,46893.51171875,57.4731450190445,20.5843102087183,23.288654,0,0,0,40,4449,199.9305,46885.962890625,,,,,,,,,,,,,0,,,,0,,,,,,199.9880371,,,,
,32572486.985,199.9886169,41828.205078125,-4.67190226981992E-5,1.96747496761932E-6,1,0.999253354069792,40.0298881530762,1.99760868003251,20.1900005340576,-0.000527085735289266,-0.000110309160556738,0.25,-1.60509040939546E-6,-4.68786766073547E-5,-1.6606794446087E-6,199.9886169,199.9886169,41825.74609375,41830.6640625,57.4958122461022,20.5843271002316,22.909004,0,0,0,40,4449,199.9396,41828.205078125,,,,,,,,,,,,,0,,,,-0.00245,,,,,,199.9886169,,,,
,32572586.265,199.9912415,36865.876953125,-3.16115434302579E-5,1.22895413072281E-6,1,0.999253354069792,40.0298881530762,1.99760751815557,20.1900005340576,-0.000355924113476313,-7.8773307832843E-5,0.25,-1.45029342351002E-6,-3.17191645583303E-5,-1.48923067289195E-6,199.9912415,199.9912415,36858.640625,36873.11328125,57.6716786629292,20.584909386374,22.909004,0,0,0,40,4449,199.94675,36865.876953125,,,,,,,,,,,,,0,,,,-0.00245,,,,,,199.9912415,,,,
,32572685.955,199.9900208,31883.8876953125,-1.69271423056611E-5,1.40511001013183E-6,1,0.999253354069792,40.0298881530762,1.99762209439949,20.1900005340576,-0.000191197032262083,-3.86814319745474E-5,0.25,-4.68196106880658E-7,-1.69850962093249E-5,-4.88015408962784E-7,199.9900208,199.9900208,31876.275390625,31891.5,57.6763684340446,20.5858572079547,23.288654,0,0,0,40,4449,199.9556,31883.8876953125,,,,,,,,,,,,,0,,,,-0.0049,,,,,,199.9900208,,,,
,32572785.93,199.9876862,26886.1181640625,-4.04572973240124E-8,9.35270805471646E-7,1,0.999253354069792,40.0298881530762,1.99758675775641,20.1900005340576,1.06477326837816E-6,-8.85408122588676E-6,0.25,-7.73094749246279E-7,-3.97641251038166E-8,-7.75808027932116E-7,199.9876862,199.9876862,26884.0390625,26888.197265625,57.6279074658522,20.5853466933039,22.909004,0,0,0,40,4449,199.96465,26886.1181640625,,,,,,,,,,,,,0,,,,-0.0049,,,,,,199.9876862,,,,
,32572884.015,199.9897766,21983.3564453125,1.36373797915119E-5,1.24255748799414E-6,1,0.999253354069792,40.0298881530762,1.99765784400364,20.1900005340576,0.000157385220864327,1.19081387228908E-5,0.25,-1.31942598811237E-6,1.36858923499758E-5,-1.30926396926553E-6,199.9897766,199.9897766,21980.955078125,21985.7578125,57.5239508727946,20.5879063722428,23.288654,0,0,0,40,4449,199.9729,21983.3564453125,,,,,,,,,,,,,0,,,,0,,,,,,199.9897766,,,,
,32572977.375,199.9890289,17318.7041015625,2.72631292812901E-5,7.91362194905913E-7,1,0.999253354069792,40.0298881530762,1.99754816326106,20.1900005340576,0.000311898810677567,3.94704958626388E-5,0.25,-1.25746912046863E-6,2.73586193665307E-5,-1.23234089502973E-6,199.9890289,199.9890289,17313.7734375,17323.634765625,57.698254032583,20.5867559537629,23.288654,0,0,0,40,4449,199.9835,17318.7041015625,,,,,,,,,,,,,0,,,,0.00245,,,,,,199.9890289,,,,
,32573071.865,199.9885025,12593.7373046875,3.84316223147968E-5,7.29991735929631E-7,1,0.999253354069792,40.0298881530762,1.99767090450277,20.1900005340576,0.000438160493368131,6.44814519355579E-5,0.25,-9.93953506927992E-7,3.85653816116684E-5,-9.55778294478333E-7,199.9878845,199.9891205,12586.251953125,12601.22265625,57.698254032583,20.5916937983328,23.288654,0,0,0,40,4449,199.9892,12593.7373046875,,,,,,,,,,,,,0,,,,0,,,,,,199.9885025,,,,
,32573166.885,199.9904938,7848.19677734375,4.75016366147414E-5,5.11722697135434E-7,1,0.999253354069792,40.0298881530762,1.99753519448497,20.1900005340576,0.000540239562187335,8.71400998434268E-5,0.25,-5.72532544642719E-7,4.7666240325791E-5,-5.23009295599841E-7,199.9904938,199.9904938,7843.1748046875,7853.21875,57.3691884259868,20.5909482466933,22.909004,0,0,0,40,4449,199.9967,7848.19677734375,,,,,,,,,,,,,0,,,,-0.0049,,,,,,199.9904938,,,,
,32573262.04,199.9916077,3090.50366210937,4.74622362234056E-5,4.36614906259136E-7,1,0.999253354069792,40.0298881530762,1.99766349363416,20.1900005340576,0.000539056955705064,9.14917353609509E-5,0.25,-1.82819883776779E-7,4.76262701503526E-5,-1.3192798423894E-7,199.9916077,199.9916077,3080.36401367188,3100.64331054687,57.5184794731599,20.5915946873867,22.909004,0,0,0,40,4449,200.00015,3090.50366210937,,,,,,,,,,,,,0,,,,0.00245,,,,,,199.9916077,,,,
,32573353.08,199.9957428,-1457.76489257813,1.29464026990077E-5,3.46744407599711E-7,1,0.999253354069792,40.0298881530762,1.99779667376982,20.1900005340576,0.000147647840212769,2.15123378170338E-5,0.25,-3.53439250439819E-7,1.29914738476586E-5,-3.40600188508035E-7,199.9957428,199.9957428,-1460.38806152344,-1455.14172363281,57.4622022197753,20.5877236916531,22.909004,0,0,0,40,4449,200.0037,-1457.76489257813,,,,,,,,,,,,,0,,,,0,,,,,,199.9957428,,,,
,32573447.84,200.0002365,-6194.82495117187,-3.70005160371518E-5,4.77739059844686E-7,1,0.999253354069792,40.0298881530762,1.99778804254349,20.1900005340576,-0.000419726827075346,-7.44097521107156E-5,0.25,-1.28910787863502E-7,-3.71280930953026E-5,-1.69488611187109E-7,200.0001831,200.0002899,-6202.1787109375,-6187.47119140625,57.6263442088138,20.5907493567057,22.529354,0,0,0,40,4449,200.00095,-6194.82495117187,,,,,,,,,,,,,0,,,,0,,,,,,200.0002365,,,,
,32573545.21,200.0041199,-11060.6958007813,-4.02683236202001E-5,5.90148796261833E-7,1,0.999253354069792,40.0298881530762,1.99782406329898,20.1900005340576,-0.000457876642031974,-7.48079127201994E-5,0.25,4.03648365980268E-7,-4.0407761452985E-5,3.61427020925037E-7,200.0041199,200.0041199,-11065.576171875,-11055.8154296875,57.6052402387946,20.5905438582849,22.909004,0,0,0,40,4449,199.9964,-11060.6958007813,,,,,,,,,,,,,0,,,,0.0049,,,,,,200.0041199,,,,
,32573637.205,200.0055771,-15658.4721679687,-3.03193852117304E-5,7.89169970047451E-7,1,0.999253354069792,40.0298881530762,1.9979453994835,20.1900005340576,-0.000344587461487001,-5.73847040075767E-5,0.25,2.1084380357232E-7,-3.042427719708E-5,1.78780984757764E-7,200.0044556,200.0066986,-15663.6640625,-15653.2802734375,57.8115901678715,20.5894922544404,22.909004,0,0,0,40,4449,199.99055,-15658.4721679687,,,,,,,,,,,,,0,,,,-0.0049,,,,,,200.0055771,,,,
,32573733.155,200.0065155,-20455.7138671875,-1.81672243089085E-5,1.27630669382177E-6,1,0.999253354069792,40.0298881530762,1.99794034585554,20.1900005340576,-0.00020615979282678,-3.61972611617112E-5,0.25,-3.33841090025793E-8,-1.82299065546267E-5,-5.31152068802451E-8,200.0065155,200.0065155,-20465.736328125,-20445.69140625,57.9069488472177,20.5907006975513,22.909004,0,0,0,40,4449,199.9854,-20455.7138671875,,,,,,,,,,,,,0,,,,0.00245,,,,,,200.0065155,,,,
,32573829.25,200.0093231,-25255.4609375,-2.98622280233665E-6,1.19655470559722E-6,1,0.999253354069792,40.0298881530762,1.99800126069906,20.1900005340576,-3.46245332183794E-5,-1.71136246507714E-6,0.25,3.67900426022083E-7,-2.99692915879473E-6,3.65951675604013E-7,200.0093231,200.0093231,-25258.11328125,-25252.80859375,57.7396803441023,20.5903055360619,22.909004,0,0,0,40,4449,199.9752,-25255.4609375,,,,,,,,,,,,,0,,,,0,,,,,,200.0093231,,,,
,32573926.81,200.0105133,-30133.056640625,1.23654709998187E-5,1.42862101861015E-6,1,0.999253354069792,40.0298881530762,1.99784619832818,20.1900005340576,0.00013917866682181,3.11839527272224E-5,0.25,5.99588053713513E-7,1.24075200709707E-5,6.14963280181099E-7,200.0105133,200.0105133,-30140.337890625,-30125.775390625,57.5575608991215,20.5905226689054,22.909004,0,0,0,40,4449,199.96795,-30133.056640625,,,,,,,,,,,,,0,,,,0.0049,,,,,,200.0105133,,,,
,32574025.58,200.0087585,-35067.138671875,2.6094499957393E-5,1.62130198195791E-6,1,0.999253354069792,40.0298881530762,1.99796396827204,20.1900005340576,0.000293436485072054,6.7450896494566E-5,0.25,1.40986758327374E-6,2.61830914014994E-5,1.44276062691401E-6,200.0087585,200.0087585,-35077.12890625,-35057.1484375,57.8366022804869,20.5897432151673,22.909004,0,0,0,40,4449,199.9597,-35067.138671875,,,,,,,,,,,,,0,,,,0.00245,,,,,,200.0087585,,,,
,32574123.53,200.0107269,-39964.71875,3.89658836890414E-5,2.07651293579067E-6,1,0.999253354069792,40.0298881530762,1.99811555126028,20.1900005340576,0.000442182560942748,7.7849834033851E-5,0.25,9.00302167355988E-8,3.9100347482156E-5,1.32109184349275E-7,200.0107269,200.0107269,-39974.6640625,-39954.7734375,57.81315342491,20.5912725789518,22.909004,0,0,0,40,4449,199.95255,-39964.71875,,,,,,,,,,,,,0,,,,0.0049,,,,,,200.0107269,,,,
,32574220.165,200.0128784,-44792.609375,5.77431955500988E-5,1.88155905173877E-6,1,0.999253354069792,40.0298881530762,1.99812874627373,20.1900005340576,0.00065546239652251,0.000114261798633158,0.25,3.6291202971167E-8,5.79425733963888E-5,9.81952090897523E-8,200.0128784,200.0128784,-44797.640625,-44787.578125,57.6427584077176,20.5894123698167,22.909004,0,0,0,40,4449,199.939,-44792.609375,,,,,,,,,,,,,0,,,,0.00245,,,,,,200.0128784,,,,
,32574316.455,200.0115814,-49605.140625,6.97681748615262E-5,2.34883346108936E-6,1,0.999253354069792,40.0298881530762,1.99798874672831,20.1900005340576,0.00078901586462629,0.000154707800098402,0.25,1.5116237799554E-6,7.00075304394031E-5,1.59134058878502E-6,200.0115814,200.0115814,-49610.1171875,-49600.1640625,57.6568277210638,20.5907014584654,23.288654,0,0,0,40,4449,199.9354,-49605.140625,,,,,,,,,,,,,0,,,,0,,,,,,200.0115814,,,,
,32574413.025,200.0141754,-54434.572265625,9.04763527160499E-5,2.42281614213881E-6,1,0.999253354069792,40.0298881530762,1.99800204132642,20.1900005340576,0.00102523523552341,0.000188988316652311,0.25,9.35083398956723E-7,9.07878690773642E-5,1.0347293804131E-6,200.0141754,200.0141754,-54437.28125,-54431.86328125,57.7678189707946,20.5928533999952,22.909004,0,0,0,40,4449,199.9238,-54434.572265625,,,,,,,,,,,,,0,,,,0.0049,,,,,,200.0141754,,,,
,32574513.07,200.0119629,-59431.34765625,0.000108566502245268,2.14868196293651E-6,1,0.999253354069792,40.0298881530762,1.99809270447879,20.1900005340576,0.00122579655680369,0.0002525899938808,0.25,3.3953531208473E-6,0.000108937931538585,3.52253865603358E-6,200.0119629,200.0119629,-59438.6953125,-59424,57.7904861978523,20.5919295265015,22.909004,0,0,0,40,4449,199.9071,-59431.34765625,,,,,,,,,,,,,0,,,,-0.0049,,,,,,200.0119629,,,,
,32574609.67,200.0137177,-64261.728515625,0.000111476014273868,2.391251699806E-6,1,0.999253354069792,40.0298881530762,1.99817854366884,20.1900005340576,0.00126531760990064,0.000221259541614984,0.25,1.29695037153912E-7,0.000111860996555282,2.48448772202295E-7,200.0137177,200.0137177,-64271.73046875,-64251.7265625,57.6622991206984,20.5921148181251,22.529354,0,0,0,40,4449,199.89915,-64261.728515625,,,,,,,,,,,,,0,,,,-0.00245,,,,,,200.0137177,,,,
,32574707.085,200.0124054,-69128.5625,0.000140326307018096,3.4384846559481E-6,1,0.999253354069792,40.0298881530762,1.99836176807758,20.1900005340576,0.00158426160824196,0.000328433546028928,0.25,4.5573937944968E-6,0.000140806320992087,4.72175557900141E-6,200.0124054,200.0124054,-69133.4140625,-69123.7109375,57.4997203886984,20.5925015444843,22.909004,0,0,0,40,4449,199.88435,-69128.5625,,,,,,,,,,,,,0,,,,0,,,,,,200.0124054,,,,
,32574805.375,200.0143738,-74040.6171875,0.000152649860639152,1.84915521261211E-6,1,0.999253354069792,40.0298881530762,1.99822710268172,20.1900005340576,0.00172233088587844,0.000362732558396153,0.25,5.44053866002933E-6,0.000153171571242939,5.62065511294023E-6,200.0143738,200.0143738,-74045.6796875,-74035.5546875,57.8123717963907,20.5929536702707,23.288654,0,0,0,40,4449,199.8775,-74040.6171875,,,,,,,,,,,,,0,,,,-0.00245,,,,,,200.0143738,,,,
,32574907.125,200.0121918,-79125.17578125,0.000175343079964618,2.93809940948225E-6,1,0.999253354069792,40.0298881530762,1.99810785105457,20.1900005340576,0.00197701747139539,0.000423812565226159,0.25,6.8821232362917E-6,0.000175941768466009,7.09079335388336E-6,200.0121918,200.0121918,-79127.515625,-79122.8359375,57.7138866029676,20.5926190013293,23.288654,0,0,0,40,4449,199.8637,-79125.17578125,,,,,,,,,,,,,0,,,,0,,,,,,200.0121918,,,,
,32575006.555,200.01444245,-84094.6171875,0.000190530865359189,2.79252219585869E-6,1,0.999253354069792,40.0298881530762,1.99811820559855,20.1900005340576,0.0021474209434861,0.000465432458254987,0.25,7.91099189568521E-6,0.000191181022611878,8.13878900390496E-6,200.0140228,200.0148621,-84104.6015625,-84084.6328125,57.73186405891,20.5923887640126,22.529354,0,0,0,40,4449,199.8531,-84094.6171875,,,,,,,,,,,,,0,,,,0,,,,,,200.01444245,,,,
,32575100.73,200.0155182,-88801.6640625,0.00020574735373032,3.05468658043844E-6,1,0.999253354069792,40.0298881530762,1.99804946459813,20.1900005340576,0.00232791696807332,0.000450354552088544,0.25,3.94214870167407E-6,0.000206454342674745,4.1717789903033E-6,200.0155182,200.0155182,-88811.734375,-88791.59375,57.6513563214292,20.5934306663429,22.529354,0,0,0,40,4449,199.8446,-88801.6640625,,,,,,,,,,,,,0,,,,0,,,,,,200.0155182,,,,
,32575213.135,200.0062103,-86544.3671875,0.00020202904761187,3.39717367310012E-6,1,0.999253354069792,40.0298881530762,1.99797757246461,20.1900005340576,0.00227443790462558,0.000507446238172123,0.25,9.61826794341188E-6,0.000202717243321476,9.86384918711138E-6,200.0062103,200.0062103,-86549.4453125,-86539.2890625,57.6021137247176,20.5954177638246,23.288654,0,0,0,40,4449,199.83505,-86544.3671875,,,,,,,,,,,,,0,,,,-0.00245,,,,,,200.0062103,,,,
,32575307.765,200.0020905,-81814.921875,0.000180169170726928,2.46680938321779E-6,1,0.999253354069792,40.0298881530762,1.99811347139079,20.1900005340576,0.00204004360269582,0.000385928854966553,0.25,2.70708928178762E-6,0.000180789031554042,2.90622041374231E-6,200.0020905,200.0020905,-81822.3671875,-81807.4765625,57.7990841115638,20.5975083258224,22.529354,0,0,0,40,4449,199.83515,-81814.921875,,,,,,,,,,,,,0,,,,0.0049,,,,,,200.0020905,,,,
,32575404.095,199.9944611,-76998.89453125,0.000163925138926141,3.67974123436105E-6,1,0.999253354069792,40.0298881530762,1.9979485372772,20.1900005340576,0.00184525082121716,0.000412814016974095,0.25,7.89868874287217E-6,0.000164483356134742,8.09903319273595E-6,199.9944611,199.9944611,-77003.9609375,-76993.828125,57.6630807492176,20.5945236741865,22.909004,0,0,0,40,4449,199.8353,-76998.89453125,,,,,,,,,,,,,0,,,,0.00245,,,,,,199.9944611,,,,
,32575500.515,199.9896927,-72182.51171875,0.000151784922911633,2.93906292068204E-6,1,0.999253354069792,40.0298881530762,1.99779196993279,20.1900005340576,0.00171698431333828,0.000333151227869898,0.25,2.99109986721692E-6,0.00015230633023568,3.16200674836995E-6,199.9896851,199.9897003,-72187.8125,-72177.2109375,57.8147166819484,20.5962493288375,22.529354,0,0,0,40,4449,199.84505,-72182.51171875,,,,,,,,,,,,,0,,,,-0.0049,,,,,,199.9896927,,,,
,32575598.225,199.9910278,-67298.10546875,0.000126851719574883,2.61228092596228E-6,1,0.999253354069792,40.0298881530762,1.99797637447944,20.1900005340576,0.00143041757440432,0.000305221498740234,0.25,4.85782890262917E-6,0.000127284925078553,5.00909306194848E-6,199.9910278,199.9910278,-67305.625,-67290.5859375,57.7732903704292,20.5931007416497,22.909004,0,0,0,40,4449,199.8569,-67298.10546875,,,,,,,,,,,,,0,,,,-0.00245,,,,,,199.9910278,,,,
,32575695.37,199.9896545,-62442.904296875,0.000114695070920821,1.98120130420658E-6,1,0.999253354069792,40.0298881530762,1.99806723148127,20.1900005340576,0.00129684232529446,0.000256111290070745,0.25,2.64158167460575E-6,0.000115088579844969,2.77255042142142E-6,199.9896545,199.9896545,-62453.1875,-62432.62109375,57.6161830380638,20.5930566467529,22.909004,0,0,0,40,4449,199.8701,-62442.904296875,,,,,,,,,,,,,0,,,,-0.00245,,,,,,199.9896545,,,,
,32575792.08,199.9875183,-57610.33984375,9.94608911798276E-5,1.77680234430797E-6,1,0.999253354069792,40.0298881530762,1.99790895073905,20.1900005340576,0.00112576027980854,0.000214855095983461,0.25,1.65429919153022E-6,9.98027808745599E-5,1.76589052163806E-6,199.9875183,199.9875183,-57615.27734375,-57605.40234375,57.8217513386215,20.593766999941,23.288654,0,0,0,40,4449,199.8779,-57610.33984375,,,,,,,,,,,,,0,,,,0.0049,,,,,,199.9875183,,,,
,32575891.955,199.9894257,-52618.46875,8.06892676320711E-5,1.80558849542113E-6,1,0.999253354069792,40.0298881530762,1.99796964489809,20.1900005340576,0.00091324152703863,0.000174746862112402,0.25,1.38041068286736E-6,8.09665561313963E-5,1.4712526454903E-6,199.9894257,199.9894257,-52623.51953125,-52613.41796875,57.7732903704292,20.5925871215534,22.909004,0,0,0,40,4449,199.8865,-52618.46875,,,,,,,,,,,,,0,,,,0,,,,,,199.9894257,,,,
,32575988.93,199.9913635,-47771.21484375,6.73257944594057E-5,2.34756041400886E-6,1,0.999253354069792,40.0298881530762,1.99796226624388,20.1900005340576,0.000759219820580135,0.000161759696794609,0.25,2.55711215377956E-6,6.75556297693609E-5,2.63790623382936E-6,199.9913635,199.9913635,-47776.3203125,-47766.109375,57.7138866029676,20.5920531038736,22.529354,0,0,0,40,4449,199.89595,-47771.21484375,,,,,,,,,,,,,0,,,,0.0049,,,,,,199.9913635,,,,
,32576086.555,199.9912567,-42891.38671875,4.62245472815972E-5,1.8093372311617E-6,1,0.999253354069792,40.0298881530762,1.99775302043322,20.1900005340576,0.000523126174508959,0.00010003339259296,0.25,7.84998719194722E-7,4.63833693051503E-5,8.37215133025279E-7,199.9912567,199.9912567,-42898.8828125,-42883.890625,57.7201396311215,20.5926058897215,22.529354,0,0,0,40,4449,199.9024,-42891.38671875,,,,,,,,,,,,,0,,,,-0.00245,,,,,,199.9912567,,,,
,32576183.63,199.9888306,-38041.59765625,3.63280379306844E-5,1.68583062447621E-6,1,0.999253354069792,40.0298881530762,1.99790241531894,20.1900005340576,0.000406136951763894,0.000107520632823277,0.25,3.16267477159862E-6,3.64501157579474E-5,3.21257929823225E-6,199.9888306,199.9888306,-38051.9375,-38031.2578125,57.6732419199676,20.5916352503053,22.909004,0,0,0,40,4449,199.90945,-38041.59765625,,,,,,,,,,,,,0,,,,0.00245,,,,,,199.9888306,,,,
,32576280.485,199.98871615,-33199.65234375,2.01323554350794E-5,1.64834585395237E-6,1,0.999253354069792,40.0298881530762,1.9978395424991,20.1900005340576,0.000223794786034706,6.69095137622708E-5,0.25,2.39800221668323E-6,2.019930580124E-5,2.42792662286764E-6,199.988678,199.9887543,-33209.70703125,-33189.59765625,57.6990356611023,20.5918032282624,22.909004,0,0,0,40,4449,199.91995,-33199.65234375,,,,,,,,,,,,,0,,,,-0.00245,,,,,,199.98871615,,,,
,32576377.195,199.9890289,-28367.59375,5.20626795526493E-6,1.44301632411483E-6,1,0.999253354069792,40.0298881530762,1.99777365006349,20.1900005340576,5.72613598409762E-5,2.08178473979741E-5,0.25,9.29833290958759E-7,5.223245150042E-6,9.38651292445628E-7,199.9890289,199.9890289,-28372.58203125,-28362.60546875,57.708415203333,20.5903894698335,23.288654,0,0,0,40,4449,199.9275,-28367.59375,,,,,,,,,,,,,0,,,,-0.00245,,,,,,199.9890289,,,,
,32576471.88,199.9890594,-23635.0810546875,-8.66898986763338E-6,1.36302148661363E-6,1,0.999253354069792,40.0298881530762,1.99777944980819,20.1900005340576,-9.88317484699731E-5,-1.45971896107656E-5,0.25,2.19643780845295E-7,-8.69916079601794E-6,2.11050208522345E-7,199.9890594,199.9890594,-23640.29296875,-23629.869140625,57.8295676238138,20.5921348285341,22.909004,0,0,0,40,4449,199.94205,-23635.0810546875,,,,,,,,,,,,,0,,,,-0.0049,,,,,,199.9890594,,,,
,32576571.075,199.9890137,-18677.853515625,-2.21946702232033E-5,8.72099049469691E-7,1,0.999253354069792,40.0298881530762,1.99790538595499,20.1900005340576,-0.000255872634622884,-2.11109521362228E-5,0.25,1.99512617070212E-6,-2.2273458250174E-5,1.97802933957083E-6,199.9890137,199.9890137,-18677.853515625,-18677.853515625,57.566158812833,20.5895873539768,22.529354,0,0,0,40,4449,199.9458,-18677.853515625,,,,,,,,,,,,,0,,,,0,,,,,,199.9890137,,,,
,32576667.24,199.9906616,-13872.8081054687,-3.53636686284885E-5,6.88277436974918E-7,1,0.999253354069792,40.0298881530762,1.99788255280528,20.1900005340576,-0.000401249677468621,-7.07034590681375E-5,0.25,-8.64833706534861E-8,-3.54856649412706E-5,-1.25059308701486E-7,199.9906616,199.9906616,-13880.443359375,-13865.1728515625,57.6716786629292,20.5899246470186,22.529354,0,0,0,40,4449,199.9555,-13872.8081054687,,,,,,,,,,,,,0,,,,0.00245,,,,,,199.9906616,,,,
,32576763.93,199.9933624,-9037.7431640625,-4.56125595579158E-5,5.58126464013881E-7,1,0.999253354069792,40.0298881530762,1.99763627465838,20.1900005340576,-0.000518874086553958,-8.31367856906886E-5,0.25,5.9750323800399E-7,-4.57706653979586E-5,5.5011998628046E-7,199.9933624,199.9933624,-9047.92578125,-9027.560546875,57.5372385576215,20.589020816294,23.288654,0,0,0,40,4449,199.95825,-9037.7431640625,,,,,,,,,,,,,0,,,,0.00245,,,,,,199.9933624,,,,
,32576861.015,199.9914551,-4184.12158203125,-4.80053884616147E-5,5.07200812227083E-7,1,0.999253354069792,40.0298881530762,1.99786887407028,20.1900005340576,-0.000544526443503749,-9.68826467339153E-5,0.25,-1.96973089429341E-7,-4.81708854295376E-5,-2.49764497134093E-7,199.9914551,199.9914551,-4189.1591796875,-4179.083984375,57.7615659426407,20.5909996362903,23.288654,0,0,0,40,4449,199.9593,-4184.12158203125,,,,,,,,,,,,,0,,,,0,,,,,,199.9914551,,,,
,32576953.43,199.9947968,431.913070678711,-2.715916459333E-5,3.38459432335366E-7,1,0.999253354069792,40.0298881530762,1.99792303267985,20.1900005340576,-0.000307476974126276,-5.82563158083277E-5,0.25,-4.14754601704281E-7,-2.72524590460002E-5,-4.45690382701705E-7,199.9947968,199.9947968,424.479919433594,439.346221923828,57.6537012069869,20.5894374120206,22.529354,0,0,0,40,4449,199.97615,431.913070678711,,,,,,,,,,,,,0,,,,0,,,,,,199.9947968,,,,
,32577049.31,199.9978333,5221.33959960937,3.12063755860705E-5,5.39438060264893E-7,1,0.999253354069792,40.0298881530762,1.99801356208774,20.1900005340576,0.000355027568224995,5.70631031133546E-5,0.25,-3.93509461101157E-7,3.13145196742984E-5,-3.61003881536645E-7,199.9978333,199.9978333,5213.74853515625,5228.9306640625,57.6708970344099,20.5890574006025,23.288654,0,0,0,40,4449,199.97015,5221.33959960937,,,,,,,,,,,,,0,,,,-0.0049,,,,,,199.9978333,,,,
,32577146.74,200.0009918,10094.5341796875,4.13563284279883E-5,6.25211222338789E-7,1,0.999253354069792,40.0298881530762,1.99800296974435,20.1900005340576,0.000470937415244341,7.30976616675441E-5,0.25,-7.43865399319665E-7,4.14998919015873E-5,-7.01618641885163E-7,200.0009918,200.0009918,10082.185546875,10106.8828125,57.5825730117369,20.5882293558544,22.529354,0,0,0,40,4449,199.9685,10094.5341796875,,,,,,,,,,,,,0,,,,-0.0049,,,,,,200.0009918,,,,
,32577242.25,200.0027161,14869.7729492187,3.22297631976797E-5,8.50879446695249E-7,1,0.999253354069792,40.0298881530762,1.99787841751999,20.1900005340576,0.000369556333325014,4.21792978365817E-5,0.25,-1.88204881794431E-6,3.23430590616843E-5,-1.8536742987867E-6,200.0027161,200.0027161,14864.7451171875,14874.80078125,57.5098815594484,20.5903380525846,22.909004,0,0,0,40,4449,199.9654,14869.7729492187,,,,,,,,,,,,,0,,,,0.00245,,,,,,200.0027161,,,,
,32577339.205,200.007431,19712.330078125,1.9372037699431E-5,1.15540850245857E-6,1,0.999253354069792,40.0298881530762,1.99791145786371,20.1900005340576,0.000222216969401579,2.48474964368237E-5,0.25,-1.17569814064578E-6,1.94401834035167E-5,-1.15883092706636E-6,200.007431,200.007431,19707.40234375,19717.2578125,57.5982055821215,20.5907216049877,22.529354,0,0,0,40,4449,199.9572,19712.330078125,,,,,,,,,,,,,0,,,,0.00245,,,,,,200.007431,,,,
,32577435.085,200.0098724,24505.1015625,4.88105980888788E-6,1.29652824681531E-6,1,0.999253354069792,40.0298881530762,1.99782462766372,20.1900005340576,5.94150187370838E-5,-1.34686558295638E-5,0.25,-2.03433231336317E-6,4.90010482398812E-6,-2.03609182249509E-6,200.0098724,200.0098724,24500.005859375,24510.197265625,57.5958606965638,20.5898383983912,23.288654,0,0,0,40,4449,199.948,24505.1015625,,,,,,,,,,,,,0,,,,0.00245,,,,,,200.0098724,,,,
,32577534.605,200.0096588,29480.1728515625,-1.00420556136185E-5,1.3711966771961E-6,1,0.999253354069792,40.0298881530762,1.99781471070315,20.1900005340576,-0.000109840030388713,-4.36675503650886E-5,0.25,-2.10295249026473E-6,-1.00744636490158E-5,-2.12102305055146E-6,200.0096588,200.0096588,29467.5703125,29492.775390625,57.7537496574484,20.5889646519234,22.529354,0,0,0,40,4449,199.938,29480.1728515625,,,,,,,,,,,,,0,,,,0.00245,,,,,,200.0096588,,,,
,32577631.34,200.0128174,34313.060546875,-2.50778899647974E-5,1.35923798327372E-6,1,0.999253354069792,40.0298881530762,1.99776756593887,20.1900005340576,-0.000280065029683811,-7.5831551296414E-5,0.25,-2.32532218448998E-6,-2.51619813828685E-5,-2.36029691926273E-6,200.0128174,200.0128174,34305.8515625,34320.26953125,57.7107600888907,20.5879222291013,22.909004,0,0,0,40,4449,199.9305,34313.060546875,,,,,,,,,,,,,0,,,,-0.00245,,,,,,200.0128174,,,,
,32577725.54,200.0139618,39022.529296875,-3.92183473190283E-5,2.1712015894072E-6,1,0.999253354069792,40.0298881530762,1.9979858609595,20.1900005340576,-0.000443894183282306,-8.48307001275173E-5,0.25,-6.61541768295789E-7,-3.93530620754966E-5,-7.0588967368964E-7,200.0139618,200.0139618,39012.46875,39032.58984375,57.5161345876022,20.5898104644472,22.909004,0,0,0,40,4449,199.91845,39022.529296875,,,,,,,,,,,,,0,,,,-0.00245,,,,,,200.0139618,,,,
,32577823.855,200.0142365,43937.779296875,-5.32259279604313E-5,2.00339036717415E-6,1,0.999253354069792,40.0298881530762,1.99778194428732,20.1900005340576,-0.000598173126458922,-0.000139346626613171,0.25,-3.0324467150854E-6,-5.3406490996336E-5,-3.0998963731895E-6,200.0142365,200.0142365,43930.3046875,43945.25390625,57.6583909781023,20.5883005419829,22.909004,0,0,0,40,4449,199.90575,43937.779296875,,,,,,,,,,,,,0,,,,0,,,,,,200.0142365,,,,
,32577922.525,200.0129089,48866.111328125,-7.31347690250215E-5,2.20299336025644E-6,1,0.999253354069792,40.0298881530762,1.99777057906122,20.1900005340576,-0.000822290381956223,-0.000189289569415635,0.25,-3.9749969851031E-6,-7.33831100082581E-5,-4.06686032121048E-6,200.0124664,200.0133514,48853.578125,48878.64453125,57.2847725459099,20.5882495059357,23.288654,0,0,0,40,4449,199.89395,48866.111328125,,,,,,,,,,,,,0,,,,0,,,,,,200.0129089,,,,
,32578020.96,200.0118866,53786.091796875,-8.86908346367886E-5,2.3772406766026E-6,1,0.999253354069792,40.0298881530762,1.99766478361294,20.1900005340576,-0.000998954847267011,-0.000219119520635208,0.25,-3.90252236645914E-6,-8.89930186204161E-5,-4.01056568147434E-6,200.0118866,200.0118866,53781.30859375,53790.875,57.6122748954676,20.5895737862005,22.909004,0,0,0,40,4449,199.88225,53786.091796875,,,,,,,,,,,,,0,,,,-0.00245,,,,,,200.0118866,,,,
,32578116.64,200.0127563,58568.765625,-0.000103723149756507,2.04892693025225E-6,1,0.999253354069792,40.0298881530762,1.99777255193054,20.1900005340576,-0.00116684830887454,-0.000264800306579606,0.25,-5.3155664781946E-6,-0.000104075790236139,-5.4442991281914E-6,200.0127563,200.0127563,58558.55859375,58578.97265625,57.5692853269099,20.5867180912522,23.288654,0,0,0,40,4449,199.87185,58568.765625,,,,,,,,,,,,,0,,,,0,,,,,,200.0127563,,,,
,32578213.83,200.0175323,63426.9375,-0.000119338901824151,2.72358856084453E-6,1,0.999253354069792,40.0298881530762,1.99781720363026,20.1900005340576,-0.0013492067623992,-0.000266336286835082,0.25,-2.73866912250773E-6,-0.00011974825136092,-2.87485793057686E-6,200.0175323,200.0175323,63416.8671875,63437.0078125,57.8600511360638,20.5854117379269,23.288654,0,0,0,40,4449,199.8588,63426.9375,,,,,,,,,,,,,0,,,,0.0049,,,,,,200.0175323,,,,
,32578311.035,200.0130768,68286.83203125,-0.000138651950302004,2.24337613299829E-6,1,0.999253354069792,40.0298881530762,1.99775542161517,20.1900005340576,-0.00155972864070884,-0.000354226821801305,0.25,-7.12888374414357E-6,-0.000139123435951995,-7.30044197497039E-6,200.0130768,200.0130768,68279.2578125,68294.40625,57.4895592179484,20.5849724748043,22.909004,0,0,0,40,4449,199.8501,68286.83203125,,,,,,,,,,,,,0,,,,-0.00245,,,,,,200.0130768,,,,
,32578407.775,200.0111618,73119.8046875,-0.00015496130385322,2.69194902405688E-6,1,0.999253354069792,40.0298881530762,1.99790026903936,20.1900005340576,-0.00174397218976496,-0.00039215382338516,0.25,-7.63587742018202E-6,-0.000155488676957465,-7.82613020652398E-6,200.010498,200.0118256,73112.140625,73127.46875,57.6904377473907,20.5861731585044,22.909004,0,0,0,40,4449,199.83745,73119.8046875,,,,,,,,,,,,,0,,,,0,,,,,,200.0111618,,,,
,32578506.03,200.0145874,78032.67578125,-0.000171143021076362,2.70665477934252E-6,1,0.999253354069792,40.0298881530762,1.99785305072539,20.1900005340576,-0.00192857172553977,-0.000418529450414228,0.25,-7.15049676131117E-6,-0.000171726874339966,-7.35579498237606E-6,200.0145874,200.0145874,78030.09375,78035.2578125,57.4098331089868,20.584006733038,22.909004,0,0,0,40,4449,199.82645,78032.67578125,,,,,,,,,,,,,0,,,,0,,,,,,200.0145874,,,,
,32578604.025,200.0114136,82931.27734375,-0.000182893562638458,2.951455121962E-6,1,0.999253354069792,40.0298881530762,1.99787487680994,20.1900005340576,-0.00206208773514824,-0.000441055543542702,0.25,-7.09438751340079E-6,-0.000183518178519532,-7.31145962335719E-6,200.0114136,200.0114136,82928.8671875,82933.6875,57.6693337773715,20.5821630203784,22.909004,0,0,0,40,4449,199.828,82931.27734375,,,,,,,,,,,,,0,,,,-0.0049,,,,,,200.0114136,,,,
,32578697.18,200.0162201,87586.71484375,-0.000202800227045014,2.94100932755319E-6,1,0.999253354069792,40.0298881530762,1.9977493786126,20.1900005340576,-0.00229306941220843,-0.000450595881739369,0.25,-4.48071313452801E-6,-0.000203496431205606,-4.70928244535943E-6,200.0162201,200.0162201,87581.7734375,87591.65625,57.5700669554292,20.5848805262104,22.909004,0,0,0,40,4449,199.8041,87586.71484375,,,,,,,,,,,,,0,,,,-0.00735,,,,,,200.0162201,,,,
,32578805.055,200.0079346,87908.2578125,-0.000198834041477272,2.7668212551619E-6,1,0.999253354069792,40.0298881530762,1.99790681564918,20.1900005340576,-0.00224212715505142,-0.000477901051282537,0.25,-7.57192282707834E-6,-0.000199513348406712,-7.80698893903186E-6,200.0079346,200.0079346,87903.1953125,87913.3203125,57.4067065949099,20.5839699692898,22.909004,0,0,0,40,4449,199.7967,87908.2578125,,,,,,,,,,,,,0,,,,-0.0049,,,,,,200.0079346,,,,
,32578897.105,200.0055084,83304.83984375,-0.000182860077731685,1.90737053405293E-6,1,0.999253354069792,40.0298881530762,1.99776425214105,20.1900005340576,-0.00206522104444544,-0.000420109412176495,0.25,-5.25687989516646E-6,-0.00018348654787191,-5.46756930705049E-6,200.0055084,200.0055084,83299.90625,83309.7734375,57.5005020172176,20.5864441132169,22.909004,0,0,0,40,4449,199.7978,83304.83984375,,,,,,,,,,,,,0,,,,-0.0049,,,,,,200.0055084,,,,
,32578994.315,199.9965057,78445.734375,-0.00016843438714726,2.29849580940506E-6,1,0.999253354069792,40.0298881530762,1.99780748242498,20.1900005340576,-0.00189982897323878,-0.00040141426025206,0.25,-6.11383849779877E-6,-0.000169010076752683,-6.3126917763007E-6,199.9965057,199.9965057,78435.46875,78456,57.5184794731599,20.5844263229447,23.288654,0,0,0,40,4449,199.8031,78445.734375,,,,,,,,,,,,,0,,,,0,,,,,,199.9965057,,,,
,32579092.14,199.9905396,73554.859375,-0.000155641154236137,1.87558926120165E-6,1,0.999253354069792,40.0298881530762,1.99766523124571,20.1900005340576,-0.00175634504134322,-0.000365516202763271,0.25,-5.17477700121757E-6,-0.000156173587448711,-5.35723643623359E-6,199.9905396,199.9905396,73547.453125,73562.265625,57.413741251583,20.5867785646418,22.909004,0,0,0,40,4449,199.8171,73554.859375,,,,,,,,,,,,,0,,,,-0.0049,,,,,,199.9905396,,,,
,32579189.03,199.9900055,68711.53515625,-0.000133704152499042,2.5416232255115E-6,1,0.999253354069792,40.0298881530762,1.99778301416067,20.1900005340576,-0.00150890940235197,-0.000313843519658963,0.25,-4.42993443541004E-6,-0.000134161505025517,-4.58693255454645E-6,199.9900055,199.9900055,68709,68714.0703125,57.555997642083,20.5834427012088,23.288654,0,0,0,40,4449,199.8139,68711.53515625,,,,,,,,,,,,,0,,,,-0.0049,,,,,,199.9900055,,,,
,32579286.93,199.9883957,63818.8515625,-0.00012024707809211,1.82821684187945E-6,1,0.999253354069792,40.0298881530762,1.99763387563022,20.1900005340576,-0.00135673761061866,-0.000283420139795367,0.25,-4.0881732696303E-6,-0.000120658247345608,-4.22999553833747E-6,199.9882202,199.9885712,63816.41796875,63821.28515625,57.5137897020446,20.5861539657555,23.288654,0,0,0,40,4449,199.8265,63818.8515625,,,,,,,,,,,,,0,,,,0,,,,,,199.9883957,,,,
,32579385.63,199.9898529,58885.779296875,-0.00010251488422932,1.92801964557986E-6,1,0.999253354069792,40.0298881530762,1.99781312433791,20.1900005340576,-0.00115805010799413,-0.000234248290990038,0.25,-2.83333181257053E-6,-0.00010286606869692,-2.95221403417061E-6,199.9898529,199.9898529,58878.29296875,58893.265625,57.4653287338522,20.5851196926436,23.288654,0,0,0,40,4449,199.83795,58885.779296875,,,,,,,,,,,,,0,,,,0,,,,,,199.9898529,,,,
,32579482.045,199.9899445,54065.3671875,-8.82987677071071E-5,2.33291788940288E-6,1,0.999253354069792,40.0298881530762,1.99786795965253,20.1900005340576,-0.000992642576367113,-0.000229650933934317,0.25,-4.89649800386848E-6,-8.85986000318662E-5,-5.00756906522982E-6,199.9899445,199.9899445,54060.5859375,54070.1484375,57.6302523514099,20.5860299979152,23.288654,0,0,0,40,4449,199.84725,54065.3671875,,,,,,,,,,,,,0,,,,0,,,,,,199.9899445,,,,
,32579581.295,199.9921265,49105.466796875,-7.1053344187851E-5,2.33706476160505E-6,1,0.999253354069792,40.0298881530762,1.99777023157836,20.1900005340576,-0.000797088138290492,-0.000194267562560333,0.25,-4.77503039087175E-6,-7.12936882539025E-5,-4.86744765263356E-6,199.9921265,199.9921265,49092.8984375,49118.03515625,57.5388018146599,20.582019133006,22.909004,0,0,0,40,4449,199.8533,49105.466796875,,,,,,,,,,,,,0,,,,0.00245,,,,,,199.9921265,,,,
,32579678.125,199.990921,44264.787109375,-5.83418594675341E-5,1.83692041245345E-6,1,0.999253354069792,40.0298881530762,1.99775137785643,20.1900005340576,-0.000654559368530647,-0.000159068588659929,0.25,-3.88163340313738E-6,-5.85392241915434E-5,-3.95750246546259E-6,199.990921,199.990921,44259.734375,44269.83984375,57.5278590153907,20.5858888918365,22.909004,0,0,0,40,4449,199.86475,44264.787109375,,,,,,,,,,,,,0,,,,-0.00245,,,,,,199.990921,,,,
,32579775.07,199.9889069,39421.873046875,-3.9437595501895E-5,1.85646760467158E-6,1,0.999253354069792,40.0298881530762,1.99781054014444,20.1900005340576,-0.000444236250840071,-9.74034931030552E-5,0.25,-1.73172987470243E-6,-3.95719511868061E-5,-1.78001534130599E-6,199.9889069,199.9889069,39416.90234375,39426.84375,57.5513078709676,20.588675416024,22.909004,0,0,0,40,4449,199.8712,39421.873046875,,,,,,,,,,,,,0,,,,-0.00245,,,,,,199.9889069,,,,
,32579871.145,199.9894867,34619.794921875,-2.51480772750858E-5,1.8161720133934E-6,1,0.999253354069792,40.0298881530762,1.99767710921903,20.1900005340576,-0.000281147500396659,-7.42524039376951E-5,0.25,-2.17428034840945E-6,-2.52325915717055E-5,-2.20881571313319E-6,199.9894867,199.9894867,34615.26953125,34624.3203125,57.6716786629292,20.5866451248209,23.668306,0,0,0,40,4449,199.88045,34619.794921875,,,,,,,,,,,,,0,,,,-0.0049,,,,,,199.9894867,,,,
,32579966.375,199.9884186,29859.873046875,-1.06007268938141E-5,1.63622872009604E-6,1,0.999253354069792,40.0298881530762,1.99768954686538,20.1900005340576,-0.000115415179418154,-4.91384913037346E-5,0.25,-2.48816086883537E-6,-1.06346559282551E-5,-2.5081663274832E-6,199.9884186,199.9884186,29847.451171875,29872.294921875,57.6646440062561,20.5877017804569,23.288654,0,0,0,40,4449,199.8887,29859.873046875,,,,,,,,,,,,,0,,,,0,,,,,,199.9884186,,,,
,32580063.695,199.9866486,24994.669921875,5.24485571225339E-6,1.16003642657847E-6,1,0.999253354069792,40.0298881530762,1.99755675673934,20.1900005340576,6.4418058794453E-5,-1.78263576434177E-5,0.25,-2.481626269189E-6,5.26564325535022E-6,-2.48453901450874E-6,199.9866486,199.9866486,24984.642578125,25004.697265625,57.2558522906984,20.5905624816254,23.288654,0,0,0,40,4449,199.90365,24994.669921875,,,,,,,,,,,,,0,,,,0.0049,,,,,,199.9866486,,,,
,32580159.54,199.9894867,20204.716796875,1.87499659738653E-5,1.08042044247009E-6,1,0.999253354069792,40.0298881530762,1.99782176536632,20.1900005340576,0.000215760735532205,2.00836507609824E-5,0.25,-1.48725303665251E-6,1.88163116780128E-5,-1.47213141146321E-6,199.9894867,199.9894867,20197.21875,20212.21484375,57.6669888918138,20.5893962893901,22.909004,0,0,0,40,4449,199.9072,20204.716796875,,,,,,,,,,,,,0,,,,-0.0049,,,,,,199.9894867,,,,
,32580256.28,199.9917297,15370.3461914062,3.15666793061107E-5,9.08849832378574E-7,1,0.999253354069792,40.0298881530762,1.99781829951482,20.1900005340576,0.000358690396983815,6.00367685159271E-5,0.25,-1.93552148339931E-7,3.16758700539741E-5,-1.60061409697153E-7,199.9917297,199.9917297,15360.3466796875,15380.345703125,57.6255625802946,20.5898024925482,22.909004,0,0,0,40,4449,199.91545,15370.3461914062,,,,,,,,,,,,,0,,,,0.0049,,,,,,199.9917297,,,,
,32580352.485,199.98636625,10560.2192382813,4.33503445956651E-5,7.93075826789146E-7,1,0.999253354069792,40.0298881530762,1.99783397359105,20.1900005340576,0.00049354579100182,7.69527099553942E-5,0.25,-7.50068946436742E-7,4.35008181921073E-5,-7.05677675935144E-7,199.9862823,199.9864502,10547.814453125,10572.6240234375,57.4911224749868,20.5910670702979,22.909004,0,0,0,40,4449,199.9265,10560.2192382813,,,,,,,,,,,,,0,,,,-0.0049,,,,,,199.98636625,,,,
,32580448.325,199.9967194,5769.91650390625,4.92146721147565E-5,4.55691611259889E-7,1,0.999253354069792,40.0298881530762,1.99786531601523,20.1900005340576,0.000558252999785915,9.92617081101398E-5,0.25,1.9654716622984E-7,4.93843370474076E-5,2.50638391914095E-7,199.9967194,199.9967194,5759.98974609375,5779.84326171875,57.840510423083,20.5909904954656,22.909004,0,0,0,40,4449,199.92495,5769.91650390625,,,,,,,,,,,,,0,,,,0,,,,,,199.9967194,,,,
,32580541.69,199.9914093,1103.81817626953,4.24963704696288E-5,3.54383278903634E-7,1,0.999253354069792,40.0298881530762,1.99782954763218,20.1900005340576,0.000482779053840153,8.14410506679835E-5,0.25,-2.06423497866721E-7,4.26432829791067E-5,-1.60964758074698E-7,199.9914093,199.9914093,1101.267578125,1106.36877441406,57.6708970344099,20.5915749266959,22.529354,0,0,0,40,4449,199.9369,1103.81817626953,,,,,,,,,,,,,0,,,,0.0049,,,,,,199.9914093,,,,
,32580565.845,199.9953766,-0.121790185570717,3.4521871218251E-5,4.54151837441795E-7,1,0.999253354069792,40.0298881530762,1.99787586625647,20.1900005340576,0.000391978356854063,6.73989062897131E-5,0.25,-5.8551479576873E-8,3.46410910172654E-5,-2.12376910845879E-8,199.9953766,199.9953766,-0.137013956904411,-0.106566414237022,57.6482298073523,20.5904349282297,23.288654,0,0,0,40,4417,199.9292,-0.121790185570717,,,,,,,,,,,,,0,,,,0,,,,,,199.9953766,,,,