File: data/doubleLayers/dl_1-25/ppms/data/DD205_3_HYST_100OE_10K.DAT
[Header]
; VSM Data File (default extension .dat)
; Copyright (c) 2003-2013, Quantum Design, Inc. All rights reserved.
TITLE,
FILEOPENTIME,22182116.94,09/15/2018,2:40 am
BYAPP,VSM,2.0,2.0
INFO,PPMS VSM Option Release 1.4.10 Build 1,APPNAME
INFO,Quantum Design Linear Motor Servo Controller,MOTOR_MODULE_NAME
INFO,3101-100 M1,MOTOR_HW_VERSION
INFO,MMC1014,MOTOR_SERIAL_NUMBER
INFO,SRV No X-over 01.03.11,MOTOR_SOFTWARE_VERSION
INFO,Quantum Design VSM Detection Module,VSM_MODULE_NAME
INFO,3101-150 F0,VSM_HW_VERSION
INFO,VSM707,VSM_SERIAL_NUMBER
INFO,VSM No X-over 01.02.05 May 20 2008 13:51:47,VSM_SOFTWARE_VERSION
INFO,704,PREAMP_SERIAL_NUMBER
INFO,822,COIL_SERIAL_NUMBER
INFO,0,MOMENT_UNITS
INFO,CoFe2O4,SAMPLE_MATERIAL
INFO,Double Layer blue,SAMPLE_COMMENT
INFO,,SAMPLE_MASS
INFO,,SAMPLE_VOLUME
INFO,,SAMPLE_MOLECULAR_WEIGHT
INFO,,SAMPLE_SIZE
INFO,,SAMPLE_SHAPE
DATATYPE,COMMENT,1
DATATYPE,TIME,2
STARTUPAXIS,X,2
STARTUPAXIS,Y1,5
[Data]
Comment,Time Stamp (sec),Temperature (K),Magnetic Field (Oe),Moment (emu),M. Std. Err. (emu),Transport Action,Averaging Time (sec),Frequency (Hz),Peak Amplitude (mm),Center Position (mm),Coil Signal' (mV),Coil Signal" (mV),Range (mV),M. Quad. Signal (emu),M. Raw' (emu),M. Raw" (emu),Min. Temperature (K),Max. Temperature (K),Min. Field (Oe),Max. Field (Oe),Mass (grams),Motor Lag (deg),Pressure (Torr),VSM Status (code),Motor Status (code),Measure Status (code),Measure Count,PPMS Status (code),System Temp. (K),System Field (Oe),Sample Position (deg),Bridge 1 Resistance (ohms),Bridge 1 Excitation (에),Bridge 2 Resistance (ohms),Bridge 2 Excitation (에),Bridge 3 Resistance (ohms),Bridge 3 Excitation (에),Bridge 4 Resistance (ohms),Bridge 4 Excitation (에),Signal 1 Vin (V),Signal 2 Vin (V),Digital Inputs (code),Drive 1 Iout (mA),Drive 1 Ipower (W),Drive 2 Iout (mA),Drive 2 Ipower (W),Pressure (),Map 20 (),Map 21 (),Map 22 (),Map 23 (),Map 24 (),Map 25 (),Map 26 (),Map 27 (),Map 28 (),Map 29 ()
,22182134.28,10.0051613,99.5939254760742,,,2,,,,17.0399996006489,,,,,,,10.0051613,10.0051613,99.5939254760742,99.5939254760742,,,13.797379,,,,-99999999,4369,9.9795,99.5939254760742,,,,,,,,,,,,,,,,,,,,,,,10.0051613,,,,
,22182280.125,9.9950171,4203.6201171875,2.42439998823803E-5,3.23828199999431E-7,1,0.999253354069792,40.0298881530762,1.99685696815002,17.0200001448393,0.000272792249273435,4.63218717936098E-5,0.25,-1.88889642372046E-7,2.41111102147422E-5,-6.48943155214146E-8,9.9950171,9.9950171,4191.12255859375,4216.11767578125,56.9822823089676,20.5570965011894,13.417728,0,0,0,40,4449,9.988,4203.6201171875,,,,,,,,,,,,,0,,,,0.00245,,,,,,9.9950171,,,,
,22182374.17,9.9932699,8902.19140625,2.11158970018298E-5,3.71395016827161E-7,1,0.999253354069792,40.0298881530762,1.99686564405417,17.0200001448393,0.000238297884248521,3.68805539706526E-5,0.25,-4.81230639268759E-7,2.10090810267832E-5,-3.64440917507447E-7,9.9932699,9.9932699,8897.19140625,8907.19140625,56.8970848003714,20.5600297437156,13.417728,0,0,0,40,4449,9.9946,8902.19140625,,,,,,,,,,,,,0,,,,0.0049,,,,,,9.9932699,,,,
,22182468.84,9.9941177,13635.1499023437,1.90040276147355E-5,3.35263153910352E-7,1,0.999253354069792,40.0298881530762,1.9969636433861,17.0200001448393,0.000214992680968518,3.07960913209635E-5,0.25,-6.54117153579165E-7,1.89168201985173E-5,-5.41523876665468E-7,9.9941177,9.9941177,13625.291015625,13645.0087890625,56.6258597041983,20.5589458972674,13.797379,0,0,0,40,4449,10.00075,13635.1499023437,,,,,,,,,,,,,0,,,,-0.0049,,,,,,9.9941177,,,,
,22182561.72,9.99524165,18277.556640625,1.95384818464726E-5,5.14917152411175E-7,1,0.999253354069792,40.0298881530762,1.99716351914864,17.0200001448393,0.000221073106093166,3.2151104155278E-5,0.25,-6.36869236858763E-7,1.94571398919124E-5,-5.15227883842608E-7,9.9952316,9.9952517,18272.6640625,18282.44921875,57.1948852661984,20.5593538867273,13.417728,0,0,0,40,4449,10.00495,18277.556640625,,,,,,,,,,,,,0,,,,-0.00245,,,,,,9.99524165,,,,
,22182656.12,9.995307,22995.02734375,2.4514433042505E-5,4.5972919792108E-7,1,0.999253354069792,40.0298881530762,1.99686760151135,17.0200001448393,0.000277656954111554,3.92946696101123E-5,0.25,-9.00422079243882E-7,2.4424580861298E-5,-7.40406941778213E-7,9.995307,9.995307,22980.255859375,23009.798828125,57.1894138665637,20.5534970962811,13.797379,0,0,0,40,4449,10.00915,22995.02734375,,,,,,,,,,,,,0,,,,-0.00245,,,,,,9.995307,,,,
,22182750.87,9.9944935,27728.0859375,3.0175199784302E-5,4.55563440660041E-7,1,0.999253354069792,40.0298881530762,1.99708378046792,17.0200001448393,0.000342624351091483,4.47935295546354E-5,0.25,-1.43643644873572E-6,3.0081680097324E-5,-1.23085253621129E-6,9.9944935,9.9944935,27723.041015625,27733.130859375,57.2152076076984,20.5589517271273,13.417728,0,0,0,40,4449,10.0125,27728.0859375,,,,,,,,,,,,,0,,,,0,,,,,,9.9944935,,,,
,22182847.575,9.9951563,32563.001953125,3.10839435470257E-5,5.41985670277657E-7,1,0.999253354069792,40.0298881530762,1.9970162483363,17.0200001448393,0.000351569853573457,5.47661767307031E-5,0.25,-7.23188635447397E-7,3.0998517411506E-5,-5.07161378561567E-7,9.9951563,9.9951563,32555.310546875,32570.693359375,56.6516534453329,20.5558210494602,13.417728,0,0,0,40,4449,10.01615,32563.001953125,,,,,,,,,,,,,0,,,,0,,,,,,9.9951563,,,,
,22182940.05,9.9951525,37185.2734375,2.7285352203139E-5,6.47077267647808E-7,1,0.999253354069792,40.0298881530762,1.99717291989946,17.0200001448393,0.000308579234655237,4.92342276578887E-5,0.25,-5.39147828393923E-7,2.72231848368522E-5,-3.4509132661578E-7,9.9951525,9.9951525,37172.7578125,37197.7890625,57.0323065341983,20.5553007129398,13.797379,0,0,0,40,4449,10.02035,37185.2734375,,,,,,,,,,,,,0,,,,0.0049,,,,,,9.9951525,,,,
,22183044.305,9.9944649,42395.212890625,1.78457177373961E-5,7.15269378480831E-7,1,0.999253354069792,40.0298881530762,1.99699332507483,17.0200001448393,0.000203816934692493,2.16704736851089E-5,0.25,-1.2908053915416E-6,1.78217283663666E-5,-1.15947717353253E-6,9.9944649,9.9944649,42380.203125,42410.22265625,56.973684395256,20.5510761915743,13.797379,0,0,0,40,4449,10.0269,42395.212890625,,,,,,,,,,,,,0,,,,-0.00245,,,,,,9.9944649,,,,
,22183151.595,9.9938707,47757.58984375,9.64879081459904E-6,4.50056047613191E-7,1,0.999253354069792,40.0298881530762,1.99715202447317,17.0200001448393,0.00011369164744214,-7.26645560253293E-6,0.25,-2.38240105430776E-6,9.6536528765525E-6,-2.30845920896963E-6,9.9938707,9.9938707,47747.62890625,47767.55078125,56.8830154870253,20.5518219014161,13.797379,0,0,0,40,4449,10.03235,47757.58984375,,,,,,,,,,,,,0,,,,0,,,,,,9.9938707,,,,
,22183255.22,9.9936633,52937.373046875,-2.25193654402465E-6,6.63386508685551E-7,1,0.999253354069792,40.0298881530762,1.99704569726681,17.0200001448393,-2.2876938314459E-5,-1.86705333858973E-5,0.25,-1.24839976463542E-6,-2.24092118704345E-6,-1.26410692572056E-6,9.9935484,9.9937782,52924.94921875,52949.796875,57.0104209356599,20.5532231194678,13.417728,0,0,0,40,4449,10.0388,52937.373046875,,,,,,,,,,,,,0,,,,0,,,,,,9.9936633,,,,
,22183355.81,9.9938326,57965.091796875,-1.41126120453042E-5,9.59795011775738E-7,1,0.999253354069792,40.0298881530762,1.99698667948992,17.0200001448393,-0.000152936696658633,-6.43239487852538E-5,0.25,-3.15282009243368E-6,-1.40850213166226E-5,-3.25689977081464E-6,9.9938326,9.9938326,57957.921875,57972.26171875,57.0283983916022,20.5527694851531,13.038077,0,0,0,40,4449,10.045,57965.091796875,,,,,,,,,,,,,0,,,,-0.0049,,,,,,9.9938326,,,,
,22183463.395,9.993752,63342.6484375,-2.67242118228715E-5,8.09312898702238E-7,1,0.999253354069792,40.0298881530762,1.99720262437442,17.0200001448393,-0.000295352334856079,-9.09806506048477E-5,0.25,-3.23560411368977E-6,-2.67057373460526E-5,-3.43506418118002E-6,9.9936533,9.9938507,63340.421875,63344.875,57.0119841926983,20.5561024576838,13.417728,0,0,0,40,4449,10.0506,63342.6484375,,,,,,,,,,,,,0,,,,-0.00245,,,,,,9.993752,,,,
,22183568.85,9.9936428,68612.66796875,-3.7201047050423E-5,8.39927649594038E-7,1,0.999253354069792,40.0298881530762,1.99718986507043,17.0200001448393,-0.00041916158423358,-8.32587946528766E-5,0.25,-6.61702061542946E-7,-3.72212907569874E-5,-9.3765818031878E-7,9.9936428,9.9936428,68607.6484375,68617.6875,56.8845787440637,20.5553211329752,13.417728,0,0,0,40,4449,10.05845,68612.66796875,,,,,,,,,,,,,0,,,,0,,,,,,9.9936428,,,,
,22183674.165,9.9933491,73877.03515625,-5.16007399875199E-5,1.1863032235306E-6,1,0.999253354069792,40.0298881530762,1.99724970672195,17.0200001448393,-0.00057704896186321,-0.000141259544299475,0.25,-3.19515978085548E-6,-5.16348254416323E-5,-3.57789967830306E-6,9.9933491,9.9933491,73864.5078125,73889.5625,56.9596150819099,20.5561200676425,13.038077,0,0,0,40,4449,10.06525,73877.03515625,,,,,,,,,,,,,0,,,,0.0049,,,,,,9.9933491,,,,
,22183775.64,9.9932871,78947.83984375,-6.72434510345842E-5,1.08564677289967E-6,1,0.999253354069792,40.0298881530762,1.99704615728806,17.0200001448393,-0.000751974010005862,-0.000185447803130157,0.25,-4.2848108820416E-6,-6.73140703945365E-5,-4.78034099862844E-6,9.9932871,9.9932871,78942.8515625,78952.828125,56.4867298277752,20.5506083749049,13.038077,0,0,0,40,4449,10.06925,78947.83984375,,,,,,,,,,,,,0,,,,0,,,,,,9.9932871,,,,
,22183883.625,9.9948053,84348.1875,-8.40351634411896E-5,8.07788697658796E-7,1,0.999253354069792,40.0298881530762,1.99717956452958,17.0200001448393,-0.00094700955928804,-0.00019397446246552,0.25,-2.01550541320837E-6,-8.41812300330289E-5,-2.62229014660669E-6,9.9948053,9.9948053,84345.8125,84350.5625,56.3546346080252,20.5526725356522,13.417728,0,0,0,40,4449,10.0754,84348.1875,,,,,,,,,,,,,0,,,,0.0049,,,,,,9.9948053,,,,
,22183980.585,9.99520775,89194.13671875,-9.45331210717211E-5,1.31312523603041E-6,1,0.999253354069792,40.0298881530762,1.99732747542673,17.0200001448393,-0.00105955002105338,-0.000252732599211061,0.25,-5.31844389429205E-6,-9.47075027516465E-5,-5.9991492214432E-6,9.9952068,9.9952087,89189.5859375,89198.6875,56.5234663681791,20.5497578271744,13.038077,0,0,0,40,4449,10.0795,89194.13671875,,,,,,,,,,,,,0,,,,0,,,,,,9.99520775,,,,
,22184103.295,9.9989777,85804.203125,-8.54372075421677E-5,1.15018779987064E-6,1,0.999253354069792,40.0298881530762,1.99731970830615,17.0200001448393,-0.000961586470049577,-0.000204948120042696,0.25,-2.73223094986137E-6,-8.55896191037327E-5,-3.34824391737399E-6,9.9989777,9.9989777,85789.4765625,85818.9296875,56.8134505488137,20.5532159020135,13.038077,0,0,0,40,4449,10.07995,85804.203125,,,,,,,,,,,,,0,,,,0.00245,,,,,,9.9989777,,,,
,22184210.6,10.0027561,80438.69140625,-6.96554389450302E-5,9.03756991046362E-7,1,0.999253354069792,40.0298881530762,1.99738778147989,17.0200001448393,-0.000785458529846051,-0.000157182687085463,0.25,-1.34995318433488E-6,-6.97589083508643E-5,-1.85696540721304E-6,10.0027561,10.0027561,80431.453125,80445.9296875,56.7243448976214,20.5535537919957,12.658426,0,0,0,40,4449,10.0748,80438.69140625,,,,,,,,,,,,,0,,,,0.00245,,,,,,10.0027561,,,,
,22184308.76,10.004487,75531.625,-5.73940894412235E-5,1.17320973422863E-6,1,0.999253354069792,40.0298881530762,1.99737416372978,17.0200001448393,-0.000637529626507414,-0.000181744955687406,0.25,-5.72966029312528E-6,-5.74237549266717E-5,-6.15725729981084E-6,10.004487,10.004487,75526.71875,75536.53125,57.0471574760637,20.5537002599436,12.658426,0,0,0,40,4449,10.07165,75531.625,,,,,,,,,,,,,0,,,,-0.0049,,,,,,10.004487,,,,
,22184408.465,10.0046339,70548.6875,-4.55533990110325E-5,9.43424542897469E-7,1,0.999253354069792,40.0298881530762,1.99743174887677,17.0200001448393,-0.000506923238612558,-0.000138010651824237,0.25,-3.9977177823914E-6,-4.5562162417542E-5,-4.33760161041616E-6,10.0046339,10.0046339,70543.921875,70553.453125,56.946327397083,20.551872120203,13.417728,0,0,0,40,4449,10.06765,70548.6875,,,,,,,,,,,,,0,,,,0,,,,,,10.0046339,,,,
,22184504.345,10.0041981,65753.4140625,-3.16063253042426E-5,9.45327766634009E-7,1,0.999253354069792,40.0298881530762,1.99747699124736,17.0200001448393,-0.000353025363834842,-8.76947359147302E-5,0.25,-2.06250664684398E-6,-3.16044698220015E-5,-2.29812355632558E-6,10.0041075,10.0042887,65750.875,65755.953125,56.9627415959868,20.5555961823292,12.658426,0,0,0,40,4449,10.0627,65753.4140625,,,,,,,,,,,,,0,,,,0,,,,,,10.0041981,,,,
,22184601.1,10.0042276,60920.033203125,-1.81244166498154E-5,9.41751838487543E-7,1,0.999253354069792,40.0298881530762,1.99728992186878,17.0200001448393,-0.000200613334052568,-5.9798922667475E-5,0.25,-2.02668361408591E-6,-1.81090809994028E-5,-2.16156295465973E-6,10.0042276,10.0042276,60912.56640625,60927.5,56.9338213407753,20.5522616663418,12.658426,0,0,0,40,4449,10.05985,60920.033203125,,,,,,,,,,,,,0,,,,-0.00245,,,,,,10.0042276,,,,
,22184696.27,10.0037403,56159.701171875,-6.63525084914788E-6,7.78171227262355E-7,1,0.999253354069792,40.0298881530762,1.99729261052768,17.0200001448393,-7.24342801105776E-5,-2.72972920320969E-5,0.25,-1.2215872732243E-6,-6.62307247397677E-6,-1.27033776330024E-6,10.0037403,10.0037403,56154.78125,56164.62109375,56.9861904515637,20.5568601253303,12.658426,0,0,0,40,4449,10.05675,56159.701171875,,,,,,,,,,,,,0,,,,0,,,,,,10.0037403,,,,
,22184791.675,10.0034323,51392.111328125,5.33033322148453E-6,8.13841060489037E-7,1,0.999253354069792,40.0298881530762,1.99735761690924,17.0200001448393,6.34412286711294E-5,-7.36625729078542E-6,0.25,-1.61323112551109E-6,5.33725680172824E-6,-1.57230958414901E-6,10.0034323,10.0034323,51387.0234375,51397.19921875,56.8931766577752,20.5532427714823,12.658426,0,0,0,40,4449,10.0536,51392.111328125,,,,,,,,,,,,,0,,,,0.00245,,,,,,10.0034323,,,,
,22184890.415,10.0040884,46457.23046875,1.34524653545777E-5,6.16355998091453E-7,1,0.999253354069792,40.0298881530762,1.99750133960831,17.0200001448393,0.000155690740216508,5.54516737938013E-6,0.25,-1.9316888688057E-6,1.34471906799436E-5,-1.83047868537829E-6,10.0040884,10.0040884,46454.84765625,46459.61328125,56.770460980256,20.5538260741069,13.038077,0,0,0,40,4449,10.0484,46457.23046875,,,,,,,,,,,,,0,,,,-0.00245,,,,,,10.0040884,,,,
,22184988.93,10.0042076,41534.359375,2.44167828576106E-5,5.76065692855726E-7,1,0.999253354069792,40.0298881530762,1.99721662753679,17.0200001448393,0.000282329272734406,1.04302468787648E-5,0.25,-3.47028874127878E-6,2.43939770215772E-5,-3.28767215818018E-6,10.0042076,10.0042076,41526.890625,41541.828125,56.8423708040252,20.5535211571357,13.038077,0,0,0,40,4449,10.04635,41534.359375,,,,,,,,,,,,,0,,,,-0.00245,,,,,,10.0042076,,,,
,22185092.105,10.0032034,36377.384765625,3.72055652059942E-5,5.55769735204733E-7,1,0.999253354069792,40.0298881530762,1.99738241494761,17.0200001448393,0.000422545783574031,5.72942222597938E-5,0.25,-1.60735896747899E-6,3.71237178212354E-5,-1.34158344243078E-6,10.0032034,10.0032034,36369.83203125,36384.9375,57.0299616486406,20.5556365843383,13.038077,0,0,0,40,4449,10.0425,36377.384765625,,,,,,,,,,,,,0,,,,0,,,,,,10.0032034,,,,
,22185197.37,10.0035019,31117.87890625,4.51131428686918E-5,4.07886391392918E-7,1,0.999253354069792,40.0298881530762,1.99730820236869,17.0200001448393,0.000510096070945983,8.02668653676951E-5,0.25,-9.77077059892907E-7,4.49817146083922E-5,-6.66538271608606E-7,10.0035019,10.0035019,31102.921875,31132.8359375,56.526592882256,20.556942569496,13.038077,0,0,0,40,4449,10.04055,31117.87890625,,,,,,,,,,,,,0,,,,0.00245,,,,,,10.0035019,,,,
,22185303.51,10.00208,25812.53515625,5.53747088427818E-5,4.31776458312355E-7,1,0.999253354069792,40.0298881530762,1.99737280871317,17.0200001448393,0.000626655971170044,9.36521391132017E-5,0.25,-1.61267865805313E-6,5.5185162309873E-5,-1.24430195517988E-6,10.00208,10.00208,25804.87890625,25820.19140625,56.8267382336406,20.5556906137378,12.658426,0,0,0,40,4449,10.0381,25812.53515625,,,,,,,,,,,,,0,,,,-0.00245,,,,,,10.00208,,,,
,22185410.25,10.0025234,20475.71484375,6.50433816903584E-5,4.64583635616222E-7,1,0.999253354069792,40.0298881530762,1.9971566233422,17.0200001448393,0.000732703159457742,0.000126073881477774,0.25,-4.38969880736245E-7,6.47762211967469E-5,-3.20805397603589E-8,10.0025234,10.0025234,20463.16796875,20488.26171875,57.0831123879483,20.5559143294442,13.417728,0,0,0,40,4449,10.03615,20475.71484375,,,,,,,,,,,,,0,,,,-0.0049,,,,,,10.0025234,,,,
,22185515.015,10.0020657,15241.5122070313,7.23741662966831E-5,3.45004614666397E-7,1,0.999253354069792,40.0298881530762,1.99734792468005,17.0200001448393,0.000814842944698933,0.000140822390778779,0.25,-4.09942193721632E-7,7.20404944722659E-5,1.71222493379826E-8,10.0020657,10.0020657,15231.2431640625,15251.78125,57.1120326431599,20.5608668785563,13.038077,0,0,0,40,4449,10.03475,15241.5122070313,,,,,,,,,,,,,0,,,,0,,,,,,10.0020657,,,,
,22185621.265,10.0017509,9931.95361328125,7.91567240350845E-5,3.17203389507484E-7,1,0.999253354069792,40.0298881530762,1.99722709095703,17.0200001448393,0.000890670639741931,0.000154341002743484,0.25,-3.82182089929749E-7,7.87551225539088E-5,5.42567011830026E-8,10.0017509,10.0017509,9919.45703125,9944.4501953125,56.8259566051214,20.5579156417248,13.038077,0,0,0,40,4449,10.03285,9931.95361328125,,,,,,,,,,,,,0,,,,-0.00245,,,,,,10.0017509,,,,
,22185725.29,10.0035095,4734.23486328125,8.51006879517726E-5,3.45067839989936E-7,1,0.999253354069792,40.0298881530762,1.99735634497155,17.0200001448393,0.000956615800956384,0.000169363329466784,0.25,-6.82387084645327E-8,8.46341806697679E-5,3.66893518742238E-7,10.0035095,10.0035095,4726.6796875,4741.7900390625,56.7993812354675,20.5566711881096,13.038077,0,0,0,40,4449,10.0288,4734.23486328125,,,,,,,,,,,,,0,,,,0,,,,,,10.0035095,,,,
,22185829.8,10.0136747,-491.362503051758,7.50113223904132E-5,2.9857454639464E-7,1,0.999253354069792,40.0298881530762,1.99742663002728,17.0200001448393,0.000842856878529302,0.000150189351593799,0.25,4.34390363001965E-8,7.45814585581645E-5,4.06213283397502E-7,10.0136747,10.0136747,-496.5478515625,-486.177154541016,57.1909771236022,20.5560192051829,13.038077,0,0,0,40,4449,10.01935,-491.362503051758,,,,,,,,,,,,,0,,,,0.00245,,,,,,10.0136747,,,,
,22185937.11,9.9986048,-5853.072265625,7.21026078334283E-5,3.17289917126134E-7,1,0.999253354069792,40.0298881530762,1.99724022608972,17.0200001448393,0.000810595974514059,0.000143085547015757,0.25,-1.00324470502884E-7,7.17131135459251E-5,2.74349666974778E-7,9.9986048,9.9986048,-5860.54541015625,-5845.59912109375,56.7243448976214,20.5563005847617,13.038077,0,0,0,40,4449,10.0243,-5853.072265625,,,,,,,,,,,,,0,,,,0,,,,,,9.9986048,,,,
,22186037.745,9.996624,-10881.9013671875,6.99987861122028E-5,3.13460377213686E-7,1,0.999253354069792,40.0298881530762,1.99738340565731,17.0200001448393,0.000787031472449924,0.000140515113723327,0.25,1.37202063273375E-8,6.96471514700831E-5,4.02781663842818E-7,9.9966011,9.9966469,-10889.0322265625,-10874.7705078125,56.9689946241406,20.556725210707,13.038077,0,0,0,40,4449,10.0278,-10881.9013671875,,,,,,,,,,,,,0,,,,0.0049,,,,,,9.996624,,,,
,22186145.445,9.996294,-16266.5048828125,6.01186074746709E-5,3.3419612748394E-7,1,0.999253354069792,40.0298881530762,1.99742999964501,17.0200001448393,0.00067637074153756,0.000120241004148456,0.25,-5.59727304913652E-8,5.98454074089668E-5,3.01762302537632E-7,9.996294,9.996294,-16271.5712890625,-16261.4384765625,57.0909286731407,20.5554296798825,13.038077,0,0,0,40,4449,10.0299,-16266.5048828125,,,,,,,,,,,,,0,,,,0,,,,,,9.996294,,,,
,22186248.39,9.9972172,-21410.3515625,3.55445199163049E-5,4.10979663682169E-7,1,0.999253354069792,40.0298881530762,1.99725695009104,17.0200001448393,0.000401161540312664,6.49867820120789E-5,0.25,-5.90252055727062E-7,3.54040058798906E-5,-3.64394431254382E-7,9.9972172,9.9972172,-21412.765625,-21407.9375,56.7470121246791,20.5534307503399,12.658426,0,0,0,40,4449,10.0342,-21410.3515625,,,,,,,,,,,,,0,,,,-0.0049,,,,,,9.9972172,,,,
,22186354.45,9.9971418,-26709.955078125,4.07098731246782E-6,5.26959244656834E-7,1,0.999253354069792,40.0298881530762,1.9972852995889,17.0200001448393,4.62204955122361E-5,6.0596063855454E-6,0.25,-1.92107057377046E-7,4.05791954387253E-6,-1.64576997844538E-7,9.9971418,9.9971418,-26715.09375,-26704.81640625,57.0573186468137,20.5550249826718,13.038077,0,0,0,40,4449,10.037,-26709.955078125,,,,,,,,,,,,,0,,,,-0.00245,,,,,,9.9971418,,,,
,22186447.295,9.9981756,-31353.09765625,-1.19846905700318E-5,5.64200759266763E-7,1,0.999253354069792,40.0298881530762,1.99734484140583,17.0200001448393,-0.000133871068480769,-3.04878163125988E-5,0.25,-5.53832274253848E-7,-1.19445216288909E-5,-6.33983133116494E-7,9.9981756,9.9981756,-31358.11328125,-31348.08203125,57.1644017539484,20.5550510285514,13.038077,0,0,0,40,4449,10.0377,-31353.09765625,,,,,,,,,,,,,0,,,,0.0049,,,,,,9.9981756,,,,
,22186537.615,9.9969959,-35864.787109375,-1.87743983074447E-5,5.31843855418664E-7,1,0.999253354069792,40.0298881530762,1.99734550654343,17.0200001448393,-0.000215034981378131,-1.87405463662054E-5,0.25,1.71312702419233E-6,-1.87383886469497E-5,1.57701925664315E-6,9.9969959,9.9969959,-35869.82421875,-35859.75,57.0674798175637,20.5530662496194,12.658426,0,0,0,40,4449,10.0399,-35864.787109375,,,,,,,,,,,,,0,,,,-0.00245,,,,,,9.9969959,,,,
,22186630.065,9.9969978,-40484.828125,-1.89674978334625E-5,5.93450252603067E-7,1,0.999253354069792,40.0298881530762,1.99729111901253,17.0200001448393,-0.000217140595600918,-2.01112998392635E-5,0.25,1.62996230904076E-6,-1.89399563250215E-5,1.49057507396705E-6,9.9969978,9.9969978,-40492.48828125,-40477.16796875,57.0674798175637,20.558333441408,12.658426,0,0,0,40,4449,10.04135,-40484.828125,,,,,,,,,,,,,0,,,,-0.00245,,,,,,9.9969978,,,,
,22186723.995,9.9965849,-45182.693359375,-1.16670764331647E-5,9.19546335339072E-7,1,0.999253354069792,40.0298881530762,1.99743768890719,17.0200001448393,-0.000129750932489104,-3.3981764461184E-5,0.25,-9.1131517382341E-7,-1.16420570024343E-5,-9.94936944717336E-7,9.9965849,9.9965849,-45190.13671875,-45175.25,57.1792526958137,20.5583452800807,12.658426,0,0,0,40,4449,10.04435,-45182.693359375,,,,,,,,,,,,,0,,,,-0.0049,,,,,,9.9965849,,,,
,22186816.655,9.9970407,-49812.541015625,-5.01297012981181E-6,5.217878090486E-7,1,0.999253354069792,40.0298881530762,1.99728936500825,17.0200001448393,-5.92813253601085E-5,4.86828316383746E-6,0.25,1.3346951202476E-6,-5.01730417786357E-6,1.29627072129281E-6,9.9970407,9.9970407,-49817.3203125,-49807.76171875,57.0534105042176,20.5603318869403,12.658426,0,0,0,40,4449,10.04875,-49812.541015625,,,,,,,,,,,,,0,,,,-0.0049,,,,,,9.9970407,,,,
,22186908.03,9.9956837,-54379.251953125,4.76069322590395E-6,7.22898860116679E-7,1,0.999253354069792,40.0298881530762,1.99725927812141,17.0200001448393,4.88902650913253E-5,3.66176116263098E-5,0.25,2.38557118411765E-6,4.73993578807299E-6,2.41937499801344E-6,9.9956837,9.9956837,-54389.32421875,-54369.1796875,56.9346029692945,20.5608546846537,12.278775,0,0,0,40,4449,10.0527,-54379.251953125,,,,,,,,,,,,,0,,,,0.00245,,,,,,9.9956837,,,,
,22187000.125,9.9950066,-58979.44140625,1.33344184337316E-5,8.77111361443782E-7,1,0.999253354069792,40.0298881530762,1.99735017129462,17.0200001448393,0.000151023590731692,2.4837947055372E-5,0.25,-2.0446705596799E-7,1.33333238879925E-5,-1.05184219839439E-7,9.9950066,9.9950066,-58991.796875,-58967.0859375,57.0057311645445,20.5629080811683,13.038077,0,0,0,40,4449,10.0549,-58979.44140625,,,,,,,,,,,,,0,,,,0,,,,,,9.9950066,,,,
,22187091.415,9.99475,-63544.228515625,2.51335980670873E-5,9.42628183822902E-7,1,0.999253354069792,40.0298881530762,1.99748794367666,17.0200001448393,0.000280063056034103,7.31124425579262E-5,0.25,1.93984717200567E-6,2.51248908119577E-5,2.12722213002271E-6,9.99475,9.99475,-63549.2578125,-63539.19921875,56.8353361473522,20.5607864987172,12.658426,0,0,0,40,4449,10.06095,-63544.228515625,,,,,,,,,,,,,0,,,,0,,,,,,9.99475,,,,
,22187182.345,9.9952531,-68088.9140625,3.63086473156229E-5,1.08964235556198E-6,1,0.999253354069792,40.0298881530762,1.99729176834316,17.0200001448393,0.000408411175542615,8.51280440240504E-5,0.25,9.87686975181523E-7,3.63242279072452E-5,1.2573704453939E-6,9.9951639,9.9953423,-68096.484375,-68081.34375,57.2277136640061,20.5615186187994,12.278775,0,0,0,40,4449,10.06445,-68088.9140625,,,,,,,,,,,,,0,,,,-0.0049,,,,,,9.9952531,,,,
,22187273,9.9952641,-72615.91015625,4.80613570753054E-5,1.19811685403317E-6,1,0.999253354069792,40.0298881530762,1.99697974984936,17.0200001448393,0.000538675285827414,0.000124145536004593,0.25,2.32121891336E-6,4.80929343592713E-5,2.67750055873362E-6,9.9952641,9.9952641,-72623.4296875,-72608.390625,57.0471574760637,20.5611615958598,12.658426,0,0,0,40,4449,10.06765,-72615.91015625,,,,,,,,,,,,,0,,,,0,,,,,,9.9952641,,,,
,22187367.475,9.9952612,-77338.0390625,6.25173399851684E-5,1.27601823348058E-6,1,0.999253354069792,40.0298881530762,1.99722538755788,17.0200001448393,0.000701069743752619,0.000161442280195757,0.25,3.01268943137446E-6,6.25822484291352E-5,3.47316680217636E-6,9.9952612,9.9952612,-77350.3515625,-77325.7265625,57.1198489283522,20.5607847204365,13.038077,0,0,0,40,4449,10.0715,-77338.0390625,,,,,,,,,,,,,0,,,,0,,,,,,9.9952612,,,,
,22187458.775,9.9944525,-81902.84375,7.66995922561361E-5,1.07167658699838E-6,1,0.999253354069792,40.0298881530762,1.99734960556206,17.0200001448393,0.000864823191179482,0.000173902559195922,0.25,1.55999139236285E-6,7.68213328520984E-5,2.11655541098024E-6,9.9944525,9.9944525,-81907.6171875,-81898.0703125,57.0838940164676,20.5627479883187,13.038077,0,0,0,40,4449,10.0775,-81902.84375,,,,,,,,,,,,,0,,,,0,,,,,,9.9944525,,,,
,22187549.585,9.9950104,-86440.0390625,8.3206499149802E-5,1.07765087827035E-6,1,0.999253354069792,40.0298881530762,1.99753584208112,17.0300006866455,0.000936974537824581,0.000197646184450781,0.25,2.48708578055419E-6,8.33598672049189E-5,3.08569445239639E-6,9.9950104,9.9950104,-86444.90625,-86435.171875,57.1003082153714,20.5627453624002,12.658426,0,0,0,40,4449,10.0815,-86440.0390625,,,,,,,,,,,,,0,,,,0,,,,,,9.9950104,,,,
,22187656.25,9.9962759,-89282.23046875,9.21208940793083E-5,1.1928526538461E-6,1,0.999253354069792,40.0298881530762,1.99721517502778,17.0200001448393,0.00104181212849525,0.000194294662197874,0.25,5.92214914483807E-7,9.23238409675934E-5,1.24508256282726E-6,9.9962759,9.9962759,-89292.328125,-89272.1328125,56.9291315696599,20.5644339508591,12.278775,0,0,0,40,4449,10.086,-89282.23046875,,,,,,,,,,,,,0,,,,0.00245,,,,,,9.9962759,,,,
,22187742.775,9.9991617,-84961.05859375,8.36532407026547E-5,1.52084091295817E-6,1,0.999253354069792,40.0298881530762,1.99727410973171,17.0200001448393,0.000937826907230195,0.000220685636832014,0.25,4.44359057230759E-6,8.37848283081207E-5,5.05145394408718E-6,9.9991617,9.9991617,-84966.0546875,-84956.0625,57.3269804859484,20.5628847276499,12.658426,0,0,0,40,4449,10.08475,-84961.05859375,,,,,,,,,,,,,0,,,,0,,,,,,9.9991617,,,,
,22187839.56,10.0016565,-80123.36328125,6.84835911199773E-5,1.12674441343486E-6,1,0.999253354069792,40.0298881530762,1.99730348802078,17.0200001448393,0.000773445540402442,0.000147582920096709,0.25,7.13026402151021E-7,6.85881532270405E-5,1.2108689063745E-6,10.0016565,10.0016565,-80128.5703125,-80118.15625,56.8001628639868,20.5632424471732,12.658426,0,0,0,40,4449,10.0837,-80123.36328125,,,,,,,,,,,,,0,,,,0,,,,,,10.0016565,,,,
,22187933.965,10.0029354,-75406.19140625,5.7161361072776E-5,1.06780694259619E-6,1,0.999253354069792,40.0298881530762,1.99725242475424,17.0200001448393,0.000642498184924715,0.000138818526691528,0.25,1.97731440746172E-6,5.72176513864492E-5,2.39860545322195E-6,10.0029354,10.0029354,-75416.2265625,-75396.15625,57.1878506095253,20.5621319195118,12.658426,0,0,0,40,4449,10.08025,-75406.19140625,,,,,,,,,,,,,0,,,,0.00245,,,,,,10.0029354,,,,
,22188030.705,10.0039024,-70571.6953125,4.42413432738975E-5,1.1276691009752E-6,1,0.999253354069792,40.0298881530762,1.99725172288152,17.0200001448393,0.000500626470618626,8.77096234146305E-5,0.25,-2.13901876724284E-7,4.42802024230903E-5,1.1273753587354E-7,10.0039024,10.0039024,-70579.1015625,-70564.2890625,56.9306948266983,20.5564106538556,12.658426,0,0,0,40,4449,10.0773,-70571.6953125,,,,,,,,,,,,,0,,,,-0.00245,,,,,,10.0039024,,,,
,22188133.275,10.0040188,-65445.056640625,2.81644218232242E-5,7.74152002943105E-7,1,0.999253354069792,40.0298881530762,1.99728796094518,17.0200001448393,0.000315649146875183,7.20045376057351E-5,0.25,1.29531979200092E-6,2.81660236938032E-5,1.50506194525759E-6,10.0040188,10.0040188,-65452.39453125,-65437.71875,57.1175040427945,20.5595526044988,12.658426,0,0,0,40,4449,10.0731,-65445.056640625,,,,,,,,,,,,,0,,,,-0.0049,,,,,,10.0040188,,,,
,22188237.545,10.0035543,-60230.34765625,1.76729482004967E-5,9.9934834948239E-7,1,0.999253354069792,40.0298881530762,1.99746466592445,17.0200001448393,0.000197193736180543,4.95791025169933E-5,0.25,1.20326591881364E-6,1.76626084044863E-5,1.33472261361231E-6,10.0035543,10.0035543,-60235.25390625,-60225.44140625,57.0831123879483,20.5583928744741,12.658426,0,0,0,40,4449,10.0693,-60230.34765625,,,,,,,,,,,,,0,,,,0,,,,,,10.0035543,,,,
,22188337.97,10.0040035,-55215.705078125,4.61929569310276E-6,7.94018900392405E-7,1,0.999253354069792,40.0298881530762,1.9975542557128,17.0200001448393,5.28243960202214E-5,5.71226534932821E-6,0.25,-3.26697065987125E-7,4.6191402471284E-6,-2.92203715960929E-7,10.0040035,10.0040035,-55223.18359375,-55208.2265625,56.9572701963522,20.5592659968042,13.038077,0,0,0,40,4449,10.06515,-55215.705078125,,,,,,,,,,,,,0,,,,-0.0049,,,,,,10.0040035,,,,
,22188440.045,10.0043497,-50114.158203125,-1.02763270310162E-5,8.13243404641603E-7,1,0.999253354069792,40.0298881530762,1.9973963463623,17.0200001448393,-0.000111014569343619,-4.83970594773633E-5,0.25,-2.4368599029527E-6,-1.02473783970167E-5,-2.51006392364829E-6,10.0043497,10.0043497,-50121.5859375,-50106.73046875,57.1432977839291,20.5561276664722,13.038077,0,0,0,40,4449,10.0607,-50114.158203125,,,,,,,,,,,,,0,,,,0.00245,,,,,,10.0043497,,,,
,22188538.18,10.0039339,-45209.673828125,-1.91286734887035E-5,6.97466145376496E-7,1,0.999253354069792,40.0298881530762,1.99745263808466,17.0200001448393,-0.000213519631468051,-5.1354957323289E-5,0.25,-1.10758782262519E-6,-1.90905240328073E-5,-1.24531229345862E-6,10.0039339,10.0039339,-45219.64453125,-45199.703125,57.3371416566984,20.554424743639,12.658426,0,0,0,40,4449,10.0585,-45209.673828125,,,,,,,,,,,,,0,,,,-0.00245,,,,,,10.0039339,,,,
,22188639.305,10.0040922,-40154.66015625,-2.93461741674443E-5,7.89183474724305E-7,1,0.999253354069792,40.0298881530762,1.99742028913381,17.0200001448393,-0.000328540408655385,-7.23684067458971E-5,0.25,-1.13745620362582E-6,-2.92763077537486E-5,-1.34521757353766E-6,10.0040922,10.0040922,-40167.3203125,-40142,56.9134989992753,20.5548037284032,13.038077,0,0,0,40,4449,10.05515,-40154.66015625,,,,,,,,,,,,,0,,,,0.0049,,,,,,10.0040922,,,,
,22188740.375,10.0030193,-35105.0859375,-3.94779340048793E-5,6.09311186748347E-7,1,0.999253354069792,40.0298881530762,1.99708481419196,17.0200001448393,-0.000446012661566102,-7.30958226684509E-5,0.25,6.10207597726294E-7,-3.93780189291114E-5,3.32760736677703E-7,10.0030193,10.0030193,-35115.14453125,-35095.02734375,56.9885353371214,20.5500885033693,12.658426,0,0,0,40,4449,10.0515,-35105.0859375,,,,,,,,,,,,,0,,,,0.0049,,,,,,10.0030193,,,,
,22188840.27,10.0042238,-30113.0185546875,-4.9143228929309E-5,5.74210899517471E-7,1,0.999253354069792,40.0298881530762,1.99751164258308,17.0200001448393,-0.000552693948783477,-0.000103946288812603,0.25,-4.03756573482888E-7,-4.89848754980442E-5,-7.35174352243285E-7,10.0042238,10.0042238,-30118.029296875,-30108.0078125,56.8337728903137,20.5546044833331,12.278775,0,0,0,40,4449,10.0477,-30113.0185546875,,,,,,,,,,,,,0,,,,-0.00245,,,,,,10.0042238,,,,
,22188943.235,10.0029459,-24966.048828125,-5.73970244972582E-5,4.51643945524283E-7,1,0.999253354069792,40.0298881530762,1.99750423166953,17.0200001448393,-0.000644837682759136,-0.000123211937556427,0.25,-6.53295760426146E-7,-5.71803929449754E-5,-1.02393550327685E-6,10.0029459,10.0029459,-24976.197265625,-24955.900390625,56.9588334533906,20.5518266481469,12.658426,0,0,0,40,4449,10.0451,-24966.048828125,,,,,,,,,,,,,0,,,,0,,,,,,10.0029459,,,,
,22189039.125,10.00287055,-20173.888671875,-6.58082588384599E-5,3.65797440596873E-7,1,0.999253354069792,40.0298881530762,1.99750422807833,17.0200001448393,-0.000739708262675011,-0.000137138647555865,0.25,-4.07130126202053E-7,-6.55307246801071E-5,-8.13984323314953E-7,10.0027704,10.0029707,-20183.916015625,-20163.861328125,56.8267382336406,20.5506672513548,12.278775,0,0,0,40,4449,10.0437,-20173.888671875,,,,,,,,,,,,,0,,,,0,,,,,,10.00287055,,,,
,22189132.235,10.0035634,-15521.7280273438,-7.28455163742121E-5,3.84537076944212E-7,1,0.999253354069792,40.0298881530762,1.99754013383498,17.0200001448393,-0.00081906787269478,-0.000148351097281645,0.25,-1.72238348826325E-7,-7.25080873873454E-5,-6.00809929701441E-7,10.0035629,10.0035639,-15526.671875,-15516.7841796875,56.7227816405829,20.5541446754545,12.658426,0,0,0,40,4449,10.0399,-15521.7280273438,,,,,,,,,,,,,0,,,,-0.0049,,,,,,10.0035634,,,,
,22189223.105,10.0033054,-10979.1030273438,-7.85699827792273E-5,2.86531779983732E-7,1,0.999253354069792,40.0298881530762,1.99770617723407,17.0200001448393,-0.000882441723635395,-0.000163933594935404,0.25,-5.65013869163892E-7,-7.81728636432821E-5,-9.99521721999136E-7,10.0033054,10.0033054,-10989.171875,-10969.0341796875,56.7978179784291,20.5523937090063,12.658426,0,0,0,40,4449,10.0366,-10979.1030273438,,,,,,,,,,,,,0,,,,-0.00245,,,,,,10.0033054,,,,
,22189315.92,10.0045824,-6338.14306640625,-8.44912552640294E-5,3.22687911823511E-7,1,0.999253354069792,40.0298881530762,1.99765590459569,17.0200001448393,-0.000949035324531689,-0.000173658301986265,0.25,-4.08608586011877E-7,-8.40350051335503E-5,-8.47802748372429E-7,10.0045824,10.0045824,-6345.6474609375,-6330.638671875,56.9134989992753,20.5488300532634,12.658426,0,0,0,40,4449,10.03355,-6338.14306640625,,,,,,,,,,,,,0,,,,0,,,,,,10.0045824,,,,
,22189409.515,10.0072355,-1662.09106445313,-8.66636276279329E-5,3.27799513341423E-7,1,0.999253354069792,40.0298881530762,1.99781519856446,17.0200001448393,-0.000972811779545015,-0.000180377287218325,0.25,-6.50929528015301E-7,-8.61688831750822E-5,-1.07224734656136E-6,10.0072355,10.0072355,-1667.5419921875,-1656.64013671875,56.8759808303522,20.5507997357436,12.658426,0,0,0,40,4449,10.0258,-1662.09106445313,,,,,,,,,,,,,0,,,,-0.0049,,,,,,10.0072355,,,,
,22189497.34,10.0021496,2725.72863769531,-7.05496350471876E-5,2.98746748558882E-7,1,0.999253354069792,40.0298881530762,1.99769828681703,17.0200001448393,-0.000791775932944726,-0.000147722152687301,0.25,-6.03729461363071E-7,-7.01506765778069E-5,-9.51059809278282E-7,10.0021496,10.0021496,2720.63330078125,2730.82397460938,57.004167907506,20.552549759762,12.658426,0,0,0,40,4449,10.0226,2725.72863769531,,,,,,,,,,,,,0,,,,0,,,,,,10.0021496,,,,
,22189589.715,9.9977779,7342.96215820312,-7.09168451569754E-5,3.17238451015612E-7,1,0.999253354069792,40.0298881530762,1.99756780265825,17.0200001448393,-0.000795314503666667,-0.000152915758369582,0.25,-9.73990354475831E-7,-7.05357422689878E-5,-1.34452150825575E-6,9.9977779,9.9977779,7340.47265625,7345.45166015625,56.966649738583,20.5505149488803,12.658426,0,0,0,40,4449,10.02725,7342.96215820312,,,,,,,,,,,,,0,,,,0,,,,,,9.9977779,,,,
,22189682.035,9.9966507,11956.244140625,-6.98933490977083E-5,2.99577387610841E-7,1,0.999253354069792,40.0298881530762,1.99771570301883,17.0200001448393,-0.000783681559873846,-0.000153569718183283,0.25,-1.18466321356179E-6,-6.95419350341835E-5,-1.57287868350629E-6,9.9966507,9.9966507,11948.734375,11963.75390625,56.7470121246791,20.5511356119482,12.658426,0,0,0,40,4449,10.0301,11956.244140625,,,,,,,,,,,,,0,,,,-0.0049,,,,,,9.9966507,,,,
,22189775.445,9.9973965,16626.3837890625,-5.77686166065878E-5,3.63678994134492E-7,1,0.999253354069792,40.0298881530762,1.99763900836528,17.0200001448393,-0.000648629602089745,-0.000123326908972708,0.25,-6.35489992351735E-7,-5.75039045555756E-5,-9.77566417211345E-7,9.9973965,9.9973965,16621.427734375,16631.33984375,57.1839424669291,20.5488035804228,13.038077,0,0,0,40,4449,10.0332,16626.3837890625,,,,,,,,,,,,,0,,,,0.00245,,,,,,9.9973965,,,,
,22189862.82,9.9974365,20993.94140625,-3.66612837876175E-5,4.5131956028566E-7,1,0.999253354069792,40.0298881530762,1.99762957281027,17.0200001448393,-0.000411768358343129,-7.85063406516991E-5,0.25,-4.11202361989004E-7,-3.6508448471089E-5,-6.39039755199973E-7,9.9974365,9.9974365,20988.91796875,20998.96484375,56.9416376259676,20.5497083552116,12.278775,0,0,0,40,4449,10.0351,20993.94140625,,,,,,,,,,,,,0,,,,-0.00245,,,,,,9.9974365,,,,
,22189952.72,9.997467,25486.697265625,-9.90930076753695E-6,4.9489342583518E-7,1,0.999253354069792,40.0298881530762,1.99766115719348,17.0200001448393,-0.0001088147753126,-3.53680692030925E-5,0.25,-1.36424144570168E-6,-9.86425384023843E-6,-1.42396394068762E-6,9.997467,9.997467,25481.642578125,25491.751953125,56.7595181809868,20.5489397200653,13.038077,0,0,0,40,4449,10.03685,25486.697265625,,,,,,,,,,,,,0,,,,0.00245,,,,,,9.997467,,,,
,22190042.04,9.9971514,29952.068359375,1.0584009572054E-5,4.53739391368645E-7,1,0.999253354069792,40.0298881530762,1.99767188781613,17.0200001448393,0.0001192365249009,2.13003495109752E-5,0.25,-9.55040117578758E-9,1.05503794542659E-5,6.20510231204017E-8,9.9971514,9.9971514,29944.60546875,29959.53125,56.8767624588714,20.5486600377153,12.658426,0,0,0,40,4449,10.03825,29952.068359375,,,,,,,,,,,,,0,,,,-0.00245,,,,,,9.9971514,,,,
,22190136.61,9.997201,34677.068359375,2.02710882538763E-5,4.92263846084185E-7,1,0.999253354069792,40.0298881530762,1.99781301819726,17.0200001448393,0.000229978530605044,3.25872007269055E-5,0.25,-7.52863661969287E-7,2.02219216224303E-5,-6.09548150898443E-7,9.997201,9.997201,34667.34765625,34686.7890625,56.5750538504483,20.5498829997849,12.658426,0,0,0,40,4449,10.0417,34677.068359375,,,,,,,,,,,,,0,,,,-0.00245,,,,,,9.997201,,,,
,22190228.095,9.9973116,39249.650390625,2.25460414118181E-5,4.00000361238828E-7,1,0.999253354069792,40.0298881530762,1.99765802160812,17.0200001448393,0.000255995805551045,3.57024435450763E-5,0.25,-8.9038264726514E-7,2.2502813921082E-5,-7.27596452330698E-7,9.9973116,9.9973116,39239.67578125,39259.625,56.8259566051214,20.5497420601714,12.658426,0,0,0,40,4449,10.04405,39249.650390625,,,,,,,,,,,,,0,,,,-0.0049,,,,,,9.9973116,,,,
,22190320.635,9.9963589,43874.701171875,1.7096240655242E-5,5.01529732351925E-7,1,0.999253354069792,40.0298881530762,1.99764614915294,17.0200001448393,0.000195115400236202,2.20671836535073E-5,0.25,-1.12221635062319E-6,1.70751279023932E-5,-9.96162118969275E-7,9.9963589,9.9963589,43867.3515625,43882.05078125,56.7220000120637,20.5466126341052,12.278775,0,0,0,40,4449,10.0477,43874.701171875,,,,,,,,,,,,,0,,,,0,,,,,,9.9963589,,,,
,22190412.025,9.9962234,48443.033203125,9.04298808081731E-6,6.18162460394962E-7,1,0.999253354069792,40.0298881530762,1.9975367009219,17.0200001448393,0.000106426363683457,-5.95439986211622E-6,0.25,-2.15692728017614E-6,9.04764885690279E-6,-2.0877749274001E-6,9.9962234,9.9962234,48435.59375,48450.47265625,56.5484784807944,20.547657838568,12.278775,0,0,0,40,4449,10.0514,48443.033203125,,,,,,,,,,,,,0,,,,-0.0049,,,,,,9.9962234,,,,
,22190503.24,9.9956522,53003.05078125,8.71774983683171E-7,5.52586169935298E-7,1,0.999253354069792,40.0298881530762,1.99766624100062,17.0200001448393,1.65391155953429E-5,-3.53852694634585E-5,0.25,-3.29137641662671E-6,8.95486895898665E-7,-3.28235781309705E-6,9.9956522,9.9956522,52993.125,53012.9765625,56.7048041846406,20.5465426986041,13.038077,0,0,0,40,4449,10.05505,53003.05078125,,,,,,,,,,,,,0,,,,0,,,,,,9.9956522,,,,
,22190598.165,9.9957972,57745.810546875,-7.40557949436303E-6,8.25545696611786E-7,1,0.999253354069792,40.0298881530762,1.99764312747543,17.0200001448393,-7.89535127741801E-5,-4.11056595394208E-5,0.25,-2.30445823289641E-6,-7.38611086684552E-6,-2.35883036254541E-6,9.9957972,9.9957972,57735.9296875,57755.69140625,56.8931766577752,20.5436144849141,12.278775,0,0,0,40,4449,10.0599,57745.810546875,,,,,,,,,,,,,0,,,,0,,,,,,9.9957972,,,,
,22190689.36,9.9958019,62303.353515625,-1.97355221631167E-5,7.43207976080316E-7,1,0.999253354069792,40.0298881530762,1.9974527417604,17.0200001448393,-0.000216408652269382,-7.66815900218969E-5,0.25,-3.22946259718605E-6,-1.97137450993816E-5,-3.37668936193521E-6,9.9958019,9.9958019,62298.3046875,62308.40234375,56.9346029692945,20.5453634460698,12.658426,0,0,0,40,4449,10.0633,62303.353515625,,,,,,,,,,,,,0,,,,0,,,,,,9.9958019,,,,
,22190784.575,9.99525215,67065.0546875,-3.31972684734407E-5,7.38405735211079E-7,1,0.999253354069792,40.0298881530762,1.99768749068478,17.0200001448393,-0.000370796606205945,-9.25677123618878E-5,0.25,-2.20545715896771E-6,-3.31988866512045E-5,-2.45291834285198E-6,9.9951687,9.9953356,67057.078125,67073.03125,56.8705094307176,20.5443498719609,13.038077,0,0,0,40,4449,10.0674,67065.0546875,,,,,,,,,,,,,0,,,,-0.0049,,,,,,9.99525215,,,,
,22190877.545,9.9957809,71711.921875,-4.37373346121396E-5,6.18280667442157E-7,1,0.999253354069792,40.0298881530762,1.99760693853463,17.0200001448393,-0.0004877613996579,-0.000127210424142751,0.25,-3.36830428137713E-6,-4.37535192587937E-5,-3.69401634149845E-6,9.9957809,9.9957809,71709.3359375,71714.5078125,56.6493085597752,20.5450733357968,12.658426,0,0,0,40,4449,10.0702,71711.921875,,,,,,,,,,,,,0,,,,0,,,,,,9.9957809,,,,
,22190970.6,9.9958448,76360.10546875,-5.75772914404492E-5,7.56189262780424E-7,1,0.999253354069792,40.0298881530762,1.99779565916298,17.0200001448393,-0.000642837818980472,-0.000165151737397489,0.25,-4.22652665847356E-6,-5.76220149965626E-5,-4.65316983623403E-6,9.9958448,9.9958448,76352.40625,76367.8046875,56.9205336559483,20.5439959743949,13.038077,0,0,0,40,4449,10.07485,76360.10546875,,,,,,,,,,,,,0,,,,0,,,,,,9.9958448,,,,
,22191061.97,9.9950743,80930.9765625,-6.63413833389124E-5,9.39067208841787E-7,1,0.999253354069792,40.0298881530762,1.99762884973045,17.0200001448393,-0.000745749826837268,-0.000163346463553773,0.25,-2.48970922097555E-6,-6.64336551740162E-5,-2.97407212203112E-6,9.9950743,9.9950743,80920.7890625,80941.1640625,57.0416860764291,20.5442170687161,12.658426,0,0,0,40,4449,10.07985,80930.9765625,,,,,,,,,,,,,0,,,,0.00245,,,,,,9.9950743,,,,
,22191153.04,9.9948473,85481.91015625,-8.09464504979652E-5,8.80029535066713E-7,1,0.999253354069792,40.0298881530762,1.99766250141751,17.0200001448393,-0.000906785036982017,-0.000218584533712469,0.25,-4.74161442318021E-6,-8.10736188283281E-5,-5.33000177486895E-6,9.9948473,9.9948473,85469.5859375,85494.234375,56.4890747133329,20.5444249584292,13.038077,0,0,0,40,4449,10.0845,85481.91015625,,,,,,,,,,,,,0,,,,0,,,,,,9.9948473,,,,
,22191239.13,9.9946699,89785.08203125,-9.19956305996141E-5,8.06203173599765E-7,1,0.999253354069792,40.0298881530762,1.99765046826779,17.0200001448393,-0.00103295778208564,-0.000236829515381201,0.25,-4.36746431090544E-6,-9.21746986447049E-5,-5.02706925105279E-6,9.9946699,9.9946699,89772.6796875,89797.484375,56.8837971155445,20.5453356906237,13.038077,0,0,0,40,4449,10.0876,89785.08203125,,,,,,,,,,,,,0,,,,-0.00245,,,,,,9.9946699,,,,
,22191342.45,9.9985991,86079.015625,-8.26036670977535E-5,8.75028754512834E-7,1,0.999253354069792,40.0298881530762,1.99765810341065,17.0200001448393,-0.000928844503877428,-0.000203849919722103,0.25,-3.14227040268373E-6,-8.27490386506002E-5,-3.73845895558622E-6,9.9985991,9.9985991,86068.8984375,86089.1328125,56.9439825115252,20.5429678950095,12.658426,0,0,0,40,4449,10.0891,86079.015625,,,,,,,,,,,,,0,,,,0.00245,,,,,,9.9985991,,,,
,22191432.035,10.0013609,81600.50390625,-6.96020980299231E-5,7.43108072224427E-7,1,0.999253354069792,40.0298881530762,1.99773279841879,17.0200001448393,-0.000781303183222425,-0.000177938109983043,0.25,-3.19128032266345E-6,-6.96981894002514E-5,-3.6997338674955E-6,10.0013609,10.0013609,81590.578125,81610.4296875,56.9986965078714,20.5412212844407,13.038077,0,0,0,40,4449,10.087,81600.50390625,,,,,,,,,,,,,0,,,,-0.00245,,,,,,10.0013609,,,,
,22191527.905,10.002655,76809.2109375,-5.78804281182623E-5,7.26159643055744E-7,1,0.999253354069792,40.0298881530762,1.99791021151259,17.0200001448393,-0.000654551948026418,-0.000120110110762593,0.25,-1.90458274963139E-7,-5.79571044902272E-5,-6.13632400318334E-7,10.002655,10.002655,76801.8984375,76816.5234375,56.689171614256,20.542679054661,12.658426,0,0,0,40,4449,10.08395,76809.2109375,,,,,,,,,,,,,0,,,,-0.00245,,,,,,10.002655,,,,
,22191622.08,10.0031176,72100.7578125,-4.54396025847421E-5,6.50173222473715E-7,1,0.999253354069792,40.0298881530762,1.99776217113958,17.0200001448393,-0.000512436711511726,-0.000100885725262511,0.25,-7.33096076033202E-7,-4.5478285136748E-5,-1.06870993384314E-6,10.0031176,10.0031176,72093.265625,72108.25,56.5156500829868,20.5433719318067,13.038077,0,0,0,40,4449,10.0805,72100.7578125,,,,,,,,,,,,,0,,,,-0.0049,,,,,,10.0031176,,,,
,22191714.26,10.0045118,67492.91796875,-3.32831100523223E-5,7.63994126539414E-7,1,0.999253354069792,40.0298881530762,1.99774279053581,17.0200001448393,-0.000374281245182038,-7.89295074063314E-5,0.25,-9.83252754331336E-7,-3.32950875921147E-5,-1.2306194934698E-6,10.0045118,10.0045118,67485.3046875,67500.53125,56.7071490701983,20.5434670465159,12.658426,0,0,0,40,4449,10.0776,67492.91796875,,,,,,,,,,,,,0,,,,0.00245,,,,,,10.0045118,,,,
,22191804.51,10.0045614,62979.90625,-2.20854612373765E-5,6.73672168996882E-7,1,0.999253354069792,40.0298881530762,1.99780671431058,17.0200001448393,-0.000246565402194758,-6.1795026233779E-5,0.25,-1.48712837344909E-6,-2.20782892606098E-5,-1.65169486823198E-6,10.0045614,10.0045614,62972.4765625,62987.3359375,56.5078337977944,20.5433514068093,12.658426,0,0,0,40,4449,10.07345,62979.90625,,,,,,,,,,,,,0,,,,-0.00245,,,,,,10.0045614,,,,
,22191899.085,10.004384,58256.705078125,-1.05156009212893E-5,9.63347472772695E-7,1,0.999253354069792,40.0298881530762,1.99780734318021,17.0200001448393,-0.000113695780716356,-4.96601309261488E-5,0.25,-2.50068112787711E-6,-1.04942065849571E-5,-2.57826649719368E-6,10.004384,10.004384,58249.37890625,58264.03125,56.7423223535637,20.5462636681994,13.038077,0,0,0,40,4449,10.0706,58256.705078125,,,,,,,,,,,,,0,,,,-0.0049,,,,,,10.004384,,,,
,22191992.495,10.0038681,53586.359375,1.87072886985456E-7,4.25796144519701E-7,1,0.999253354069792,40.0298881530762,1.99777983556664,17.0200001448393,2.78363343576635E-6,-3.34446501702923E-6,0.25,-3.29919962310831E-7,1.89384797580103E-7,-3.2829537278362E-7,10.0038681,10.0038681,53581.2890625,53591.4296875,56.4890747133329,20.5476072398804,12.658426,0,0,0,40,4449,10.0667,53586.359375,,,,,,,,,,,,,0,,,,-0.0049,,,,,,10.0038681,,,,
,22192084.54,10.004425,48986.115234375,1.25003499920687E-5,5.62220931377118E-7,1,0.999253354069792,40.0298881530762,1.99783288775641,17.0200001448393,0.000142671855148684,1.65948880074445E-5,0.25,-7.81884665798871E-7,1.2491322188778E-5,-6.88953111065402E-7,10.004425,10.004425,48983.65234375,48988.578125,56.8564401173714,20.5466499285297,12.658426,0,0,0,40,4449,10.0621,48986.115234375,,,,,,,,,,,,,0,,,,0,,,,,,10.004425,,,,
,22192175.29,10.0051937,44450.69921875,2.23883354447617E-5,5.89267791485365E-7,1,0.999253354069792,40.0298881530762,1.99784766733511,17.0200001448393,0.000255544589867008,2.89497870940636E-5,0.25,-1.46570056520523E-6,2.23620264659263E-5,-1.30042296733018E-6,10.0051937,10.0051937,44445.8828125,44455.515625,56.6391473890252,20.5471865820287,13.038077,0,0,0,40,4449,10.0587,44450.69921875,,,,,,,,,,,,,0,,,,0,,,,,,10.0051937,,,,
,22192266.75,10.00441935,39880.126953125,2.98802449550708E-5,4.6827327813926E-7,1,0.999253354069792,40.0298881530762,1.99780743866124,17.0200001448393,0.000339567783455888,4.59361304369297E-5,0.25,-1.30359104755805E-6,2.98258572591472E-5,-1.0870812926052E-6,10.0041666,10.0046721,39872.61328125,39887.640625,56.7634263235829,20.5435042669045,12.658426,0,0,0,40,4449,10.05535,39880.126953125,,,,,,,,,,,,,0,,,,0.00245,,,,,,10.00441935,,,,
,22192355.895,10.0038967,35422.982421875,4.01210204242608E-5,4.78045157040108E-7,1,0.999253354069792,40.0298881530762,1.99786265420194,17.0200001448393,0.000450523461654573,9.06592944231692E-5,0.25,8.29335723580431E-7,4.00106938963461E-5,1.10799878544794E-6,10.0038967,10.0038967,35415.2421875,35430.72265625,57.0659165605253,20.5456545346056,12.278775,0,0,0,40,4449,10.05195,35422.982421875,,,,,,,,,,,,,0,,,,0.00245,,,,,,10.0038967,,,,
,22192447.53,10.0036716,30843.1796875,4.72028600470087E-5,4.67201888937943E-7,1,0.999253354069792,40.0298881530762,1.99783454611683,17.0200001448393,0.000532477636470566,9.16060081573969E-5,0.25,-3.46918623481085E-7,4.70593691439689E-5,-2.46547464445279E-8,10.0036716,10.0036716,30833.11328125,30853.24609375,56.9346029692945,20.5458124436517,12.278775,0,0,0,40,4449,10.0495,30843.1796875,,,,,,,,,,,,,0,,,,0.00245,,,,,,10.0036716,,,,
,22192541.52,10.0033388,26145.2890625,5.68438348987209E-5,3.98365942224096E-7,1,0.999253354069792,40.0298881530762,1.99773297537521,17.0200001448393,0.000641729128706126,0.000105554170834025,0.25,-8.21921250926781E-7,5.66457610114908E-5,-4.45766638406206E-7,10.0033388,10.0033388,26140.357421875,26150.220703125,57.1831608384099,20.5478207274888,12.278775,0,0,0,40,4449,10.0467,26145.2890625,,,,,,,,,,,,,0,,,,-0.0049,,,,,,10.0033388,,,,
,22192634.145,10.0030251,21517.5634765625,6.42429817813731E-5,4.76626736906991E-7,1,0.999253354069792,40.0298881530762,1.99781946339133,17.0200001448393,0.000725536187260838,0.000115947490966791,0.25,-1.20425319766566E-6,6.39905697505111E-5,-7.95063628953315E-7,10.0030251,10.0030251,21512.279296875,21522.84765625,57.0158923352945,20.5447751961101,12.278775,0,0,0,40,4449,10.0438,21517.5634765625,,,,,,,,,,,,,0,,,,-0.0049,,,,,,10.0030251,,,,
,22192725.835,10.0027647,16935.7392578125,7.1589756129557E-5,3.47439703655004E-7,1,0.999253354069792,40.0298881530762,1.99782948457204,17.0200001448393,0.000806285733687931,0.000139565535406106,0.25,-3.94778195771024E-7,7.12708391031984E-5,3.59940827412647E-8,10.0027647,10.0027647,16930.685546875,16940.79296875,56.7337244398522,20.5442950836185,12.658426,0,0,0,40,4449,10.042,16935.7392578125,,,,,,,,,,,,,0,,,,0,,,,,,10.0027647,,,,
,22192820.205,10.002533,12220.8149414062,7.75126041682413E-5,3.74815964565214E-7,1,0.999253354069792,40.0298881530762,1.99781514592607,17.0200001448393,0.000872174502211394,0.000153504295898554,0.25,-1.83015384481096E-7,7.71330693876082E-5,2.5639808881445E-7,10.002533,10.002533,12213.453125,12228.1767578125,56.9893169656406,20.5446591300747,12.658426,0,0,0,40,4449,10.03975,12220.8149414062,,,,,,,,,,,,,0,,,,-0.0049,,,,,,10.002533,,,,
,22192915.51,10.0029488,7455.33935546875,8.35243707818861E-5,3.82221272980001E-7,1,0.999253354069792,40.0298881530762,1.99770515467399,17.0200001448393,0.000939143517721905,0.000166808082336348,0.25,-3.70498272890031E-8,8.30824897389153E-5,4.06321937257138E-7,10.0029488,10.0029488,7450.5654296875,7460.11328125,56.7876568076791,20.5477473826193,12.658426,0,0,0,40,4449,10.03625,7455.33935546875,,,,,,,,,,,,,0,,,,0,,,,,,10.0029488,,,,
,22193008.335,10.0060091,2812.31274414062,8.7641154724283E-5,2.99225398016085E-7,1,0.999253354069792,40.0298881530762,1.99761186464601,17.0200001448393,0.000984973509843807,0.000175537969515134,0.25,4.08338577390746E-8,8.71495157454241E-5,4.76787771006889E-7,10.0060091,10.0060091,2802.4111328125,2822.21435546875,56.5007991411214,20.5486554137805,12.278775,0,0,0,40,4449,10.03095,2812.31274414062,,,,,,,,,,,,,0,,,,0,,,,,,10.0060091,,,,
,22193065.975,10.0128489,-0.411041855812073,8.11526282674785E-5,2.78279448198952E-7,1,0.999253354069792,40.0298881530762,1.99769184318563,17.0200001448393,0.00091211659316285,0.000161639234799124,0.25,-2.83035972633549E-8,8.06865754687212E-5,3.63009354835087E-7,10.0128489,10.0128489,-0.411041855812073,-0.411041855812073,56.7165286124291,20.5466216535659,12.278775,0,0,0,40,4417,10.01945,-0.411041855812073,,,,,,,,,,,,,0,,,,0,,,,,,10.0128489,,,,