File: data/doubleLayers/dl_1-25/ppms/data/DD205_3_HYST_100OE_300K.DAT
[Header]
; VSM Data File (default extension .dat)
; Copyright (c) 2003-2013, Quantum Design, Inc. All rights reserved.
TITLE,
FILEOPENTIME,32594133.61,01/13/2019,1:57 pm
BYAPP,VSM,2.0,2.0
INFO,PPMS VSM Option Release 1.4.10 Build 1,APPNAME
INFO,Quantum Design Linear Motor Servo Controller,MOTOR_MODULE_NAME
INFO,3101-100 M1,MOTOR_HW_VERSION
INFO,MMC1014,MOTOR_SERIAL_NUMBER
INFO,SRV No X-over 01.03.11,MOTOR_SOFTWARE_VERSION
INFO,Quantum Design VSM Detection Module,VSM_MODULE_NAME
INFO,3101-150 F0,VSM_HW_VERSION
INFO,VSM707,VSM_SERIAL_NUMBER
INFO,VSM No X-over 01.02.05 May 20 2008 13:51:47,VSM_SOFTWARE_VERSION
INFO,704,PREAMP_SERIAL_NUMBER
INFO,822,COIL_SERIAL_NUMBER
INFO,0,MOMENT_UNITS
INFO,DD205_4,SAMPLE_MATERIAL
INFO,Double Layer Blue 1.25,SAMPLE_COMMENT
INFO,26.73,SAMPLE_MASS
INFO,,SAMPLE_VOLUME
INFO,,SAMPLE_MOLECULAR_WEIGHT
INFO,,SAMPLE_SIZE
INFO,,SAMPLE_SHAPE
DATATYPE,COMMENT,1
DATATYPE,TIME,2
STARTUPAXIS,X,2
STARTUPAXIS,Y1,5
[Data]
Comment,Time Stamp (sec),Temperature (K),Magnetic Field (Oe),Moment (emu),M. Std. Err. (emu),Transport Action,Averaging Time (sec),Frequency (Hz),Peak Amplitude (mm),Center Position (mm),Coil Signal' (mV),Coil Signal" (mV),Range (mV),M. Quad. Signal (emu),M. Raw' (emu),M. Raw" (emu),Min. Temperature (K),Max. Temperature (K),Min. Field (Oe),Max. Field (Oe),Mass (grams),Motor Lag (deg),Pressure (Torr),VSM Status (code),Motor Status (code),Measure Status (code),Measure Count,PPMS Status (code),System Temp. (K),System Field (Oe),Sample Position (deg),Bridge 1 Resistance (ohms),Bridge 1 Excitation (에),Bridge 2 Resistance (ohms),Bridge 2 Excitation (에),Bridge 3 Resistance (ohms),Bridge 3 Excitation (에),Bridge 4 Resistance (ohms),Bridge 4 Excitation (에),Signal 1 Vin (V),Signal 2 Vin (V),Digital Inputs (code),Drive 1 Iout (mA),Drive 1 Ipower (W),Drive 2 Iout (mA),Drive 2 Ipower (W),Pressure (),Map 20 (),Map 21 (),Map 22 (),Map 23 (),Map 24 (),Map 25 (),Map 26 (),Map 27 (),Map 28 (),Map 29 ()
,32594149.52,300.0003052,-0.456713199615479,,,2,,,,19.6100001567602,,,,,,,300.0003052,300.0003052,-0.456713199615479,-0.456713199615479,,,24.807261,,,,-99999999,4369,300.1944,-0.456713199615479,,,,,,,,,,,,,,,,,,,,,,,300.0003052,,,,
,32594296.045,299.9805298,4533.45336914063,4.93583367366531E-5,5.2608107630846E-7,1,0.999253354069792,40.0298881530762,1.99776709249579,19.6000002324581,0.000558907079944418,9.34758264011812E-5,0.25,-2.88392415674253E-7,4.93570910810559E-5,-2.55655950024386E-7,299.9805298,299.9805298,4526.02099609375,4540.8857421875,56.6399290175445,20.5787351150549,24.047956,0,0,0,40,4449,300.22825,4533.45336914063,,,,,,,,,,,,,0,,,,0,,,,,,299.9805298,,,,
,32594389.625,299.9718018,9212.04345703125,4.23533379435925E-5,6.84243894130257E-7,1,0.999253354069792,40.0298881530762,1.99786846679329,19.6000002324581,0.000477611680190839,9.17452959003486E-5,0.25,7.71936714009152E-7,4.23516088941615E-5,7.99974920865534E-7,299.9718018,299.9718018,9206.9580078125,9217.12890625,56.6813553290637,20.5804189241003,24.807261,0,0,0,40,4449,300.24485,9212.04345703125,,,,,,,,,,,,,0,,,,0,,,,,,299.9718018,,,,
,32594490.275,299.9803162,14242.091796875,3.10029431664024E-5,8.14665628273127E-7,1,0.999253354069792,40.0298881530762,1.99777048826886,19.6000002324581,0.000349185201014772,6.95415602972658E-5,0.25,7.76054276444981E-7,3.10015305004918E-5,7.96552344331396E-7,299.9803162,299.9803162,14229.4501953125,14254.7333984375,56.8853603725829,20.5836433494953,24.047956,0,0,0,40,4449,300.2623,14242.091796875,,,,,,,,,,,,,0,,,,-0.00245,,,,,,299.9803162,,,,
,32594590.11,299.990448,19232.08203125,1.67872528597556E-5,8.64994448426156E-7,1,0.999253354069792,40.0298881530762,1.99783424685579,19.6000002324581,0.000190591653497895,2.89312376583245E-5,0.25,-3.51035753765653E-7,1.6786993056408E-5,-3.3992493326016E-7,299.990448,299.990448,19216.931640625,19247.232421875,57.115940785756,20.5846420182983,24.427608,0,0,0,40,4449,300.2665,19232.08203125,,,,,,,,,,,,,0,,,,0.00245,,,,,,299.990448,,,,
,32594688.375,299.9925842,24144.5009765625,8.85827175782967E-7,1.13752317032976E-6,1,0.999253354069792,40.0298881530762,1.99785721222283,19.6000002324581,8.03241511226274E-6,1.32133683709278E-5,0.25,1.01455706645461E-6,8.85131005877433E-7,1.01511247991415E-6,299.9925842,299.9925842,24134.53515625,24154.466796875,56.9166255133522,20.5850246190995,24.807261,0,0,0,40,4449,300.2713,24144.5009765625,,,,,,,,,,,,,0,,,,-0.00245,,,,,,299.9925842,,,,
,32594785.01,299.9871216,28972.361328125,-1.34228885552054E-5,1.18996726035691E-6,1,0.999253354069792,40.0298881530762,1.99769810548391,19.6000002324581,-0.000151548577345681,-2.79589473993553E-5,0.25,-1.46095833557662E-7,-1.34224020721101E-5,-1.54949003243956E-7,299.9871216,299.9871216,28967.3984375,28977.32421875,57.200356665833,20.5869065125687,24.047956,0,0,0,40,4449,300.2863,28972.361328125,,,,,,,,,,,,,0,,,,-0.00245,,,,,,299.9871216,,,,
,32594880.635,299.9935913,33752.515625,-2.98769711443944E-5,1.41778851877534E-6,1,0.999253354069792,40.0298881530762,1.99771627879056,19.6000002324581,-0.000339224353679402,-5.12587858763383E-5,0.25,6.44886798567566E-7,-2.98765228538103E-5,6.25172819071177E-7,299.9935608,299.9936218,33714.96875,33790.0625,57.1401712698522,20.5846088927507,24.427608,0,0,0,40,4449,300.27995,33752.515625,,,,,,,,,,,,,0,,,,0,,,,,,299.9935913,,,,
,32594975.09,299.9963684,38472.28515625,-4.6536620826274E-5,1.60645084631468E-6,1,0.999253354069792,40.0298881530762,1.99789219027099,19.6000002324581,-0.000527441561945027,-8.55129455332463E-5,0.25,5.03673196297136E-7,-4.65355902825481E-5,4.73012880084368E-7,299.9963684,299.9963684,38467.359375,38477.2109375,56.9674313671022,20.5837769117257,24.807261,0,0,0,40,4449,300.27595,38472.28515625,,,,,,,,,,,,,0,,,,0.00245,,,,,,299.9963684,,,,
,32595069.58,300.0021057,43195.08203125,-6.07372908355954E-5,1.63920952534992E-6,1,0.999253354069792,40.0298881530762,1.99772993400297,19.6000002324581,-0.000687077757913225,-0.000118867484659272,0.25,1.47325334007141E-8,-6.07355139969129E-5,-2.52213945589488E-8,300.0021057,300.0021057,43189.703125,43200.4609375,57.2441278629099,20.5839596366376,24.807261,0,0,0,40,4449,300.2796,43195.08203125,,,,,,,,,,,,,0,,,,0,,,,,,300.0021057,,,,
,32595163.705,300.0066223,47900.486328125,-7.64157955598992E-5,1.96155332868474E-6,1,0.999253354069792,40.0298881530762,1.99776074254852,19.6000002324581,-0.000862782855084085,-0.000159177216450143,0.25,-8.32256424299357E-7,-7.64129934814053E-5,-8.82444090419603E-7,300.0066223,300.0066223,47893.08984375,47907.8828125,57.2027015513907,20.586788699791,24.427608,0,0,0,40,4449,300.2782,47900.486328125,,,,,,,,,,,,,0,,,,-0.00245,,,,,,300.0066223,,,,
,32595257.93,300.004425,52610.7890625,-9.21117633621163E-5,2.20636080576541E-6,1,0.999253354069792,40.0298881530762,1.9977129899374,19.6000002324581,-0.00104152261569537,-0.000182945492344482,0.25,-2.14467656095204E-7,-9.21089173571709E-5,-2.74920844518107E-7,300.004425,300.004425,52605.5703125,52616.0078125,57.2785195177561,20.5882180210022,24.427608,0,0,0,40,4449,300.27365,52610.7890625,,,,,,,,,,,,,0,,,,-0.0049,,,,,,300.004425,,,,
,32595351.685,299.9987793,57295.662109375,-0.000106084873805652,1.9546473400269E-6,1,0.999253354069792,40.0298881530762,1.997675960107,19.6000002324581,-0.00119509812383799,-0.000236089642955546,0.25,-2.4921765608595E-6,-0.000106080152727352,-2.56165684581194E-6,299.9987793,299.9987793,57293.55078125,57297.7734375,56.9682129956214,20.5871213466902,24.807261,0,0,0,40,4449,300.27245,57295.662109375,,,,,,,,,,,,,0,,,,0.00245,,,,,,299.9987793,,,,
,32595445.805,300.0083008,61998.470703125,-0.000121092249739141,2.27325067726533E-6,1,0.999253354069792,40.0298881530762,1.99777885536089,19.6000002324581,-0.00136905528061355,-0.000241651653466736,0.25,-3.82873101182232E-7,-0.000121088441479234,-4.62166898285634E-7,300.0083008,300.0083008,61995.7890625,62001.15234375,57.2988418592561,20.5872966128808,24.047956,0,0,0,40,4449,300.25875,61998.470703125,,,,,,,,,,,,,0,,,,-0.0049,,,,,,300.0083008,,,,
,32595540.01,300.0131836,66708.96875,-0.000137156828655214,2.47244992556514E-6,1,0.999253354069792,40.0298881530762,1.99780212753493,19.6000002324581,-0.00155181930099987,-0.000267233307996181,0.25,1.39046822938255E-7,-0.000137152875318811,4.93205231176453E-8,300.0131836,300.0131836,66704.25,66713.6875,57.2167708647368,20.5869053058215,24.427608,0,0,0,40,4449,300.25535,66708.96875,,,,,,,,,,,,,0,,,,0,,,,,,300.0131836,,,,
,32595634.93,300.0084229,71452.2890625,-0.000155050323391295,2.58042013761715E-6,1,0.999253354069792,40.0298881530762,1.9980622170956,19.6000002324581,-0.00175224236724153,-0.000315097111976774,0.25,-9.88708976659809E-7,-0.000155045142302866,-1.08999104340573E-6,300.0084229,300.0084229,71447.3125,71457.265625,57.2402197203138,20.5847611843787,24.427608,0,0,0,40,4449,300.24395,71452.2890625,,,,,,,,,,,,,0,,,,-0.0049,,,,,,300.0084229,,,,
,32595727.665,300.0180359,76087.953125,-0.000170172599093865,2.35284549739449E-6,1,0.999253354069792,40.0298881530762,1.99801184227085,19.6000002324581,-0.00192947875677361,-0.000308968821458472,0.25,2.1720940414852E-6,-0.000170168992530497,2.06097368071676E-6,300.0180359,300.0180359,76085.3984375,76090.5078125,57.3285437429868,20.5843762077639,24.427608,0,0,0,40,4449,300.25475,76087.953125,,,,,,,,,,,,,0,,,,-0.0098,,,,,,300.0180359,,,,
,32595821.815,300.0105591,80796.25,-0.000185102106049026,3.06323890308829E-6,1,0.999253354069792,40.0298881530762,1.99818483566107,19.6000002324581,-0.00209692842372165,-0.000347650648539832,0.25,1.34189421536481E-6,-0.000185097577766805,1.22119247799782E-6,300.0105591,300.0105591,80788.7421875,80803.7578125,57.1354814987368,20.5778178124569,24.427608,0,0,0,40,4449,300.2346,80796.25,,,,,,,,,,,,,0,,,,0.0049,,,,,,300.0105591,,,,
,32595913.665,300.0056458,85387.02734375,-0.000201121017308267,2.78422300999347E-6,1,0.999253354069792,40.0298881530762,1.99797139518218,19.6000002324581,-0.00227335561041773,-0.000405469296410038,0.25,-9.96888784717045E-7,-0.000201114546422295,-1.12781429386708E-6,300.0056458,300.0056458,85381.9453125,85392.109375,57.3058765159291,20.5844283958076,24.807261,0,0,0,40,4449,300.22295,85387.02734375,,,,,,,,,,,,,0,,,,-0.0049,,,,,,300.0056458,,,,
,32596004.055,300.0128479,89904.9375,-0.000219134187243493,2.89425816239506E-6,1,0.999253354069792,40.0298881530762,1.99804837944592,19.6000002324581,-0.00247806786282005,-0.000435964153627973,0.25,-5.70436588086774E-7,-0.00021912743094914,-7.1293788847091E-7,300.0128479,300.0128479,89894.75,89915.125,57.1964485232368,20.5849394264441,24.427608,0,0,0,40,4449,300.21585,89904.9375,,,,,,,,,,,,,0,,,,0.00245,,,,,,300.0128479,,,,
,32596112.92,300.0114746,85601.7734375,-0.000205461860888501,2.7097392693268E-6,1,0.999253354069792,40.0298881530762,1.99786595269836,19.6000002324581,-0.00232189641951881,-0.000416555386978106,0.25,-1.22664209631849E-6,-0.00020545507172392,-1.36038717545014E-6,300.0114746,300.0114746,85594.1875,85609.359375,57.3559007411599,20.586528194363,24.807261,0,0,0,40,4449,300.20825,85601.7734375,,,,,,,,,,,,,0,,,,-0.00245,,,,,,300.0114746,,,,
,32596207.525,300,80870.72265625,-0.000188812858713804,3.22339234892104E-6,1,0.999253354069792,40.0298881530762,1.99792055380676,19.6000002324581,-0.00213192109593672,-0.000393683406112191,0.25,-2.08814789756132E-6,-0.000188806056967966,-2.21117753924258E-6,300,300,80865.5625,80875.8828125,57.1808159528522,20.5824032970995,24.807261,0,0,0,40,4449,300.21225,80870.72265625,,,,,,,,,,,,,0,,,,0.0049,,,,,,300,,,,
,32596301.835,299.9955444,76156.77734375,-0.000171030218863104,2.90124307457746E-6,1,0.999253354069792,40.0298881530762,1.99806849198073,19.6000002324581,-0.00193491823887525,-0.000335576849312875,0.25,-3.03966030934469E-8,-0.00017102528633299,-1.42028211171528E-7,299.9955444,299.9955444,76151.8515625,76161.703125,57.3559007411599,20.5837332552083,24.807261,0,0,0,40,4449,300.2121,76156.77734375,,,,,,,,,,,,,0,,,,-0.00245,,,,,,299.9955444,,,,
,32596396.625,299.9947205,71418.171875,-0.000155788632379036,2.84898971074816E-6,1,0.999253354069792,40.0298881530762,1.99800480206112,19.6000002324581,-0.00176180301019776,-0.000309291169375945,0.25,-3.48344771563884E-7,-0.000155783924156161,-4.50135240887582E-7,299.9947205,299.9947205,71413.2265625,71423.1171875,57.3457395704099,20.5830607597877,24.047956,0,0,0,40,4449,300.22835,71418.171875,,,,,,,,,,,,,0,,,,-0.00245,,,,,,299.9947205,,,,
,32596491.38,299.991272,66679.5703125,-0.000140041663243292,2.90813150686706E-6,1,0.999253354069792,40.0298881530762,1.99816427331765,19.6000002324581,-0.00158789526022986,-0.000254656040505786,0.25,1.75459705237867E-6,-0.000140038791232993,1.66292858344882E-6,299.991272,299.991272,66669.375,66689.765625,57.4903408464676,20.5848433331459,24.047956,0,0,0,40,4449,300.2328,66679.5703125,,,,,,,,,,,,,0,,,,-0.0049,,,,,,299.991272,,,,
,32596587.255,299.9866943,61889.109375,-0.000122275218557034,2.15965670643858E-6,1,0.999253354069792,40.0298881530762,1.99807706708931,19.6000002324581,-0.00138461677673957,-0.000232567001514519,0.25,6.28122679154266E-7,-0.000122272131893052,5.48016862255695E-7,299.9865417,299.9868469,61876.6171875,61901.6015625,57.1417345268907,20.5880337179432,24.427608,0,0,0,40,4449,300.24,61889.109375,,,,,,,,,,,,,0,,,,-0.00245,,,,,,299.9866943,,,,
,32596682.02,299.9864197,57153.37109375,-0.000105575136475064,1.81315670650215E-6,1,0.999253354069792,40.0298881530762,1.99797772573859,19.6000002324581,-0.00119614194619964,-0.000196811972498114,0.25,8.94392528184042E-7,-0.000105572696702893,8.25138947668406E-7,299.9864197,299.9864197,57143.63671875,57163.10546875,57.4606389627369,20.5897629886944,24.807261,0,0,0,40,4449,300.2468,57153.37109375,,,,,,,,,,,,,0,,,,-0.00245,,,,,,299.9864197,,,,
,32596780.775,299.986908,52218.677734375,-8.90385245312691E-5,2.0654916666336E-6,1,0.999253354069792,40.0298881530762,1.99790462978878,19.6000002324581,-0.00100744515715768,-0.000173513980479861,0.25,8.8288145791549E-8,-8.90360228925797E-5,2.9836017251255E-8,299.986908,299.986908,52211.34375,52226.01171875,57.4528226775445,20.5901323380979,24.427608,0,0,0,40,4449,300.26585,52218.677734375,,,,,,,,,,,,,0,,,,-0.00245,,,,,,299.986908,,,,
,32596880.835,299.9887695,47213.501953125,-7.16431480748678E-5,1.68765575790942E-6,1,0.999253354069792,40.0298881530762,1.99805389883418,19.6000002324581,-0.000811782943309938,-0.000133253918918174,0.25,6.34200633506569E-7,-7.16414955451588E-5,5.87095600237731E-7,299.9887695,299.9887695,47208.70703125,47218.296875,57.5395834431792,20.5883745705288,24.427608,0,0,0,40,4449,300.2622,47213.501953125,,,,,,,,,,,,,0,,,,0,,,,,,299.9887695,,,,
,32596979.87,299.9921265,42265.9375,-5.68168447978106E-5,1.76378553834123E-6,1,0.999253354069792,40.0298881530762,1.99795953224145,19.6000002324581,-0.000643907154026968,-0.000104812496140048,0.25,5.79032419471616E-7,-5.68155741274694E-5,5.41631932979289E-7,299.9921265,299.9921265,42261.171875,42270.703125,57.342613056333,20.589783701588,24.047956,0,0,0,40,4449,300.2723,42265.9375,,,,,,,,,,,,,0,,,,0,,,,,,299.9921265,,,,
,32597078.76,299.9872131,37323.630859375,-4.10394694971307E-5,1.63509578340801E-6,1,0.999253354069792,40.0298881530762,1.9978978559133,19.6000002324581,-0.000463530727591575,-8.46933860840288E-5,0.25,-3.76261316544414E-7,-4.10380333407661E-5,-4.03281694931887E-7,299.9872131,299.9872131,37318.46484375,37328.796875,57.6427584077176,20.5914524733825,24.047956,0,0,0,40,4449,300.2879,37323.630859375,,,,,,,,,,,,,0,,,,0,,,,,,299.9872131,,,,
,32597177.84,299.9931641,32371.193359375,-2.4570585838954E-5,1.63851383922274E-6,1,0.999253354069792,40.0298881530762,1.9978778099903,19.6000002324581,-0.000277329060806735,-5.17849086638006E-5,0.25,-3.20628155409578E-7,-2.45696561154143E-5,-3.36820370015082E-7,299.9931641,299.9931641,32366.216796875,32376.169921875,57.3543374841214,20.5938104019512,24.807261,0,0,0,40,4449,300.28665,32371.193359375,,,,,,,,,,,,,0,,,,0,,,,,,299.9931641,,,,
,32597278.36,299.9906006,27346.2646484375,-9.1403150341628E-6,1.47301714540789E-6,1,0.999253354069792,40.0298881530762,1.99798485310017,19.6000002324581,-0.00010360783177907,-1.67514834945707E-5,0.25,1.02915749623846E-7,-9.14011603486185E-6,9.68794436961809E-8,299.9906006,299.9906006,27338.83203125,27353.697265625,57.3582456267176,20.5925912446127,24.047956,0,0,0,40,4449,300.29625,27346.2646484375,,,,,,,,,,,,,0,,,,0,,,,,,299.9906006,,,,
,32597376.18,299.9886169,22456.3828125,6.23663232524226E-6,1.27495317623555E-6,1,0.999253354069792,40.0298881530762,1.99814828308302,19.6000002324581,7.0945930621729E-5,1.00076307001491E-5,0.25,-1.96012031915577E-7,6.23657978957961E-6,-1.91885718576443E-7,299.9886169,299.9886169,22446.416015625,22466.349609375,57.4598573342176,20.5888915433034,24.807261,0,0,0,40,4449,300.3103,22456.3828125,,,,,,,,,,,,,0,,,,-0.00245,,,,,,299.9886169,,,,
,32597473.23,299.9866638,17606.2119140625,2.05746909861119E-5,1.13101228757676E-6,1,0.999253354069792,40.0298881530762,1.99781000637643,19.6000002324581,0.000232874000084369,3.95855616020111E-5,0.25,-6.53710489107179E-8,2.0574133959814E-5,-5.17625608800963E-8,299.9866638,299.9866638,17598.533203125,17613.890625,57.0588819038522,20.5966539124533,25.186911,0,0,0,40,4449,300.3171,17606.2119140625,,,,,,,,,,,,,0,,,,-0.0049,,,,,,299.9866638,,,,
,32597571.225,299.9910583,12708.8393554687,3.45348012717108E-5,7.7286023585912E-7,1,0.999253354069792,40.0298881530762,1.99803575496893,19.6000002324581,0.00039107254481095,6.55895736188964E-5,0.25,-1.85964651378315E-7,3.45339095469476E-5,-1.63100094263615E-7,299.9910583,299.9910583,12701.5029296875,12716.17578125,57.3449579418907,20.593978259147,24.807261,0,0,0,40,4449,300.3246,12708.8393554687,,,,,,,,,,,,,0,,,,-0.0049,,,,,,299.9910583,,,,
,32597668.44,299.9950867,7851.09741210937,4.58204654598564E-5,6.1835248927913E-7,1,0.999253354069792,40.0298881530762,1.99818057234507,19.6000002324581,0.000517795764753097,9.34453809053938E-5,0.25,3.20286599042675E-7,4.58188979121803E-5,3.50631768906591E-7,299.9950867,299.9950867,7843.75732421875,7858.4375,57.1753445532176,20.5890622427471,25.186911,0,0,0,40,4449,300.3262,7851.09741210937,,,,,,,,,,,,,0,,,,0,,,,,,299.9950867,,,,
,32597764.285,299.9912415,3060.68664550781,4.78279660418064E-5,4.64774391768112E-7,1,0.999253354069792,40.0298881530762,1.99818484451242,19.6000002324581,0.000541856884497759,8.96085544768152E-5,0.25,-3.66686237594597E-7,4.78267988925045E-5,-3.34967508949696E-7,299.9912415,299.9912415,3050.71826171875,3070.65502929687,57.5911709254484,20.5918570594613,24.807261,0,0,0,40,4449,300.3246,3060.68664550781,,,,,,,,,,,,,0,,,,-0.0049,,,,,,299.9912415,,,,
,32597858.515,299.99633785,-1647.04901123047,-4.1571505680025E-5,4.59455453387824E-7,1,0.999253354069792,40.0298881530762,1.99782765026697,19.6000002324581,-0.000469774958834984,-8.43390450914893E-5,0.25,-2.52833789614035E-7,-4.15701042667556E-5,-2.80390741244011E-7,299.9959106,299.9967651,-1649.73010253906,-1644.36791992187,57.5411467002176,20.5988943451939,24.807261,0,0,0,40,4449,300.3313,-1647.04901123047,,,,,,,,,,,,,0,,,,0,,,,,,299.99633785,,,,
,32597953.495,299.9989319,-6394.5556640625,-4.77221279602858E-5,5.71186223411876E-7,1,0.999253354069792,40.0298881530762,1.99805628686485,19.6000002324581,-0.00053877450065282,-0.000100082298285514,0.25,-5.77924978059829E-7,-4.77203262203129E-5,-6.09528807759377E-7,299.9989319,299.9989319,-6402.091796875,-6387.01953125,57.6482298073523,20.5908703275693,25.186911,0,0,0,40,4449,300.33315,-6394.5556640625,,,,,,,,,,,,,0,,,,0,,,,,,299.9989319,,,,
,32598051.16,300.0032043,-11275.3974609375,-3.80459663024094E-5,8.01650021209137E-7,1,0.999253354069792,40.0298881530762,1.99806883809507,19.6000002324581,-0.000430760359053142,-7.27167709244123E-5,0.25,1.64433798797441E-7,-3.8044939991072E-5,1.39239200566404E-7,300.0032043,300.0032043,-11285.56640625,-11265.228515625,57.5106631879676,20.5966874609861,24.807261,0,0,0,40,4449,300.32415,-11275.3974609375,,,,,,,,,,,,,0,,,,-0.00245,,,,,,300.0032043,,,,
,32598149.595,300.0046997,-16195.4541015625,-2.41119680646793E-5,8.79918556809874E-7,1,0.999253354069792,40.0298881530762,1.9978798229299,19.6000002324581,-0.000271537973222485,-5.43664805342709E-5,0.25,-6.28237184542427E-7,-2.41108330527892E-5,-6.4416830762933E-7,300.0046997,300.0046997,-16197.9931640625,-16192.9150390625,57.5606874131984,20.6001252292019,24.807261,0,0,0,40,4449,300.3221,-16195.4541015625,,,,,,,,,,,,,0,,,,0,,,,,,300.0046997,,,,
,32598246.69,300.0032959,-21047.53125,-1.00226272451924E-5,1.11610288428561E-6,1,0.999253354069792,40.0298881530762,1.99785816890151,19.6000002324581,-0.00011416083884179,-1.51426750345399E-5,0.25,3.97914971481999E-7,-1.00225922287699E-5,3.91279432169799E-7,300.0032959,300.0032959,-21050.25390625,-21044.80859375,57.1440794124484,20.6019127108708,24.807261,0,0,0,40,4449,300.3179,-21047.53125,,,,,,,,,,,,,0,,,,-0.00245,,,,,,300.0032959,,,,
,32598345.345,300.0103149,-25980.05859375,4.81629029278582E-6,1.28906070455427E-6,1,0.999253354069792,40.0298881530762,1.99794108124333,19.6000002324581,5.51608124488098E-5,5.54769756100437E-6,0.25,-3.44069767979385E-7,4.81637332688398E-6,-3.40879628666096E-7,300.0103149,300.0103149,-25992.84375,-25967.2734375,57.7005989181407,20.6011649863129,25.186911,0,0,0,40,4449,300.3109,-25980.05859375,,,,,,,,,,,,,0,,,,0,,,,,,300.0103149,,,,
,32598444.445,300.0091553,-30932.14453125,2.0973633875939E-5,1.29012843255561E-6,1,0.999253354069792,40.0298881530762,1.99788178081486,19.6000002324581,0.00023796125365045,3.71000667745919E-5,0.25,-3.54281175667074E-7,2.09732420486049E-5,-3.40437545939138E-7,300.0091553,300.0091553,-30939.732421875,-30924.556640625,57.5192611016792,20.6025675825459,24.807261,0,0,0,40,4449,300.30585,-30932.14453125,,,,,,,,,,,,,0,,,,0,,,,,,300.0091553,,,,
,32598544.27,300.0082092,-35921.94140625,3.55640606415697E-5,1.67371666626487E-6,1,0.999253354069792,40.0298881530762,1.99790271831823,19.6000002324581,0.000406596131365922,4.50646986816028E-5,0.25,-2.17812789280362E-6,3.55644385053318E-5,-2.15463172998635E-6,300.0082092,300.0082092,-35931.67578125,-35912.20703125,57.6537012069869,20.6031252712062,24.427608,0,0,0,40,4449,300.2956,-35921.94140625,,,,,,,,,,,,,0,,,,-0.00245,,,,,,300.0082092,,,,
,32598643.4,300.0129089,-40876.548828125,5.19676952176462E-5,1.86476996108669E-6,1,0.999253354069792,40.0298881530762,1.99788571131003,19.6000002324581,0.000590301334040845,8.79505980833404E-5,0.25,-1.22910557983769E-6,5.19669538722135E-5,-1.19486721456378E-6,300.0129089,300.0129089,-40883.89453125,-40869.203125,57.3957637956407,20.6031588827419,24.427608,0,0,0,40,4449,300.2888,-40876.548828125,,,,,,,,,,,,,0,,,,0.00245,,,,,,300.0129089,,,,
,32598742.125,300.0141602,-45809.05078125,6.96861472639661E-5,2.07502656371963E-6,1,0.999253354069792,40.0298881530762,1.99799793959362,19.6000002324581,0.000787703320108576,0.000140479768057093,0.25,3.43877388856122E-7,6.96838437786004E-5,3.89679163842423E-7,300.0141602,300.0141602,-45821.609375,-45796.4921875,57.4622022197753,20.6025004605819,25.186911,0,0,0,40,4449,300.2815,-45809.05078125,,,,,,,,,,,,,0,,,,0.00245,,,,,,300.0141602,,,,
,32598842.115,300.0121765,-50806.01953125,8.65657864206513E-5,2.02215970896025E-6,1,0.999253354069792,40.0298881530762,1.99798667421208,19.6000002324581,0.000980671300350415,0.000161965980850146,0.25,-6.81238556708E-7,8.65636650717488E-5,-6.2437406528836E-7,300.0121765,300.0121765,-50813.71484375,-50798.32421875,57.3793495967368,20.6010387224347,24.427608,0,0,0,40,4449,300.271,-50806.01953125,,,,,,,,,,,,,0,,,,0.00245,,,,,,300.0121765,,,,
,32598941.93,300.0142517,-55796.216796875,0.000102319768039813,2.10049561415012E-6,1,0.999253354069792,40.0298881530762,1.99794463728698,19.6000002324581,0.00116004408310189,0.000186098307925606,0.25,-1.27714398124732E-6,0.000102317568812544,-1.20999391776232E-6,300.0142517,300.0142517,-55801.234375,-55791.19921875,57.332451885583,20.6008436113289,24.427608,0,0,0,40,4449,300.2589,-55796.216796875,,,,,,,,,,,,,0,,,,0.00245,,,,,,300.0142517,,,,
,32599041.455,300.0176392,-60768.3203125,0.00011758452344399,2.02299619589917E-6,1,0.999253354069792,40.0298881530762,1.99787401916143,19.6000002324581,0.00133081686388937,0.000226814788013358,0.25,-3.21935057500034E-7,0.000117581238014712,-2.44890297906325E-7,300.0176392,300.0176392,-60773.390625,-60763.25,57.6325972369676,20.6016742684072,24.427608,0,0,0,40,4449,300.245,-60768.3203125,,,,,,,,,,,,,0,,,,-0.0049,,,,,,300.0176392,,,,
,32599143.805,300.013031,-65883.21875,0.000135784655277147,2.57969123510359E-6,1,0.999253354069792,40.0298881530762,1.99797660019728,19.6000002324581,0.00154217866599839,0.000231356127560966,0.25,-3.07459208519278E-6,0.000135782661748013,-2.98565103416068E-6,300.013031,300.013031,-65890.7890625,-65875.6484375,57.4942489890638,20.6022812955276,24.807261,0,0,0,40,4449,300.2337,-65883.21875,,,,,,,,,,,,,0,,,,0,,,,,,300.013031,,,,
,32599244.595,300.0181274,-70919.75390625,0.000150621366758107,2.52456840251618E-6,1,0.999253354069792,40.0298881530762,1.99805531576436,19.6000002324581,0.001709744263069,0.000262457259178486,0.25,-2.89669751637315E-6,0.000150618800038216,-2.79817431823585E-6,300.0181274,300.0181274,-70922.015625,-70917.4921875,57.2066096939868,20.5982501098385,24.807261,0,0,0,40,4449,300.22525,-70919.75390625,,,,,,,,,,,,,0,,,,-0.00245,,,,,,300.0181274,,,,
,32599344.71,300.0166626,-75924.515625,0.000168141170752565,3.23612983197128E-6,1,0.999253354069792,40.0298881530762,1.99805725181053,19.6000002324581,0.00190726748343998,0.000300782799215356,0.25,-2.54432440604966E-6,0.000168137873675156,-2.43449569452169E-6,300.0166626,300.0166626,-75929.3359375,-75919.6953125,57.6435400362369,20.5958811044784,24.807261,0,0,0,40,4449,300.211,-75924.515625,,,,,,,,,,,,,0,,,,-0.0049,,,,,,300.0166626,,,,
,32599445.43,300.0134583,-80957.296875,0.000184942826765461,3.04424987260474E-6,1,0.999253354069792,40.0298881530762,1.99811877124443,19.6000002324581,0.00208585100311096,0.000400482123378016,0.25,3.35625805599568E-6,0.000184935220006186,3.47673043754782E-6,300.0134583,300.0134583,-80967.3671875,-80947.2265625,57.4762715331215,20.5960179066221,24.427608,0,0,0,40,4449,300.1981,-80957.296875,,,,,,,,,,,,,0,,,,-0.0049,,,,,,300.0134583,,,,
,32599545.49,300.0096741,-85958.61328125,0.000199778167177275,2.9469610613881E-6,1,0.999253354069792,40.0298881530762,1.99803475585909,19.6000002324581,0.00226065397178195,0.000388868399122234,0.25,-2.38895048490131E-7,0.000199772511458655,-1.08814515916827E-7,300.0096741,300.0096741,-85963.5546875,-85953.671875,57.1604936113522,20.5965453186155,24.807261,0,0,0,40,4449,300.197,-85958.61328125,,,,,,,,,,,,,0,,,,0,,,,,,300.0096741,,,,
,32599657.6,300.0144043,-89438.5390625,0.000214752773981153,3.00835998568846E-6,1,0.999253354069792,40.0298881530762,1.997930969693,19.6000002324581,0.00242648553802552,0.000438184499357891,0.25,1.52789721667334E-6,0.000214745507349071,1.66755551185553E-6,300.0144043,300.0144043,-89440.921875,-89436.15625,57.4192126512176,20.5978866261894,24.807261,0,0,0,40,4449,300.1836,-89438.5390625,,,,,,,,,,,,,0,,,,-0.0049,,,,,,300.0144043,,,,
,32599751.445,300.0076599,-84750.20703125,0.000199564596481798,3.3168229225087E-6,1,0.999253354069792,40.0298881530762,1.9979367722723,19.6000002324581,0.00225465810568527,0.000408484219713078,0.25,1.53358625015417E-6,0.000199557802287784,1.66352910457519E-6,300.0076599,300.0076599,-84755.1171875,-84745.296875,57.3027500018522,20.5983682485054,24.807261,0,0,0,40,4449,300.17345,-84750.20703125,,,,,,,,,,,,,0,,,,-0.0049,,,,,,300.0076599,,,,
,32599850.94,300.0027466,-79778.00390625,0.000179425427054877,2.93553234685292E-6,1,0.999253354069792,40.0298881530762,1.99780263101791,19.6000002324581,0.00202699946259625,0.000367232017052253,0.25,1.37811968390923E-6,0.000179419336485865,1.49509641677231E-6,300.0027466,300.0027466,-79783.1171875,-79772.890625,57.4958122461022,20.596023031621,25.186911,0,0,0,40,4449,300.18225,-79778.00390625,,,,,,,,,,,,,0,,,,0.0049,,,,,,300.0027466,,,,
,32599951.175,299.9907837,-74768.10546875,0.000167843579591722,2.36526757808777E-6,1,0.999253354069792,40.0298881530762,1.99781654370403,19.6000002324581,0.0018962577049761,0.000343027162027787,0.25,1.24459820794025E-6,0.000167837970089794,1.35416401612521E-6,299.9907837,299.9907837,-74780.3828125,-74755.828125,57.3621537693137,20.5980662862679,25.186911,0,0,0,40,4449,300.1887,-74768.10546875,,,,,,,,,,,,,0,,,,0,,,,,,299.9907837,,,,
,32600051.97,299.9908142,-69731.4375,0.000150255985338759,2.83364960879645E-6,1,0.999253354069792,40.0298881530762,1.99781945511474,19.6000002324581,0.00169781486501855,0.000305608621388412,0.25,9.83704474532248E-7,0.000150251037070354,1.08191469666038E-6,299.9908142,299.9908142,-69739.1015625,-69723.7734375,57.4160861371407,20.5970542634906,25.186911,0,0,0,40,4449,300.1984,-69731.4375,,,,,,,,,,,,,0,,,,0.00245,,,,,,299.9908142,,,,
,32600148.79,299.9891968,-64892.001953125,0.000131167448534955,2.22583457073548E-6,1,0.999253354069792,40.0298881530762,1.99766304576505,19.6000002324581,0.00148546599481303,0.000246836501608474,0.25,-9.03088098946641E-7,0.000131164279938921,-8.17200736712073E-7,299.9891968,299.9891968,-64896.828125,-64887.17578125,57.3543374841214,20.6006870551907,24.427608,0,0,0,40,4449,300.20035,-64892.001953125,,,,,,,,,,,,,0,,,,0,,,,,,299.9891968,,,,
,32600244.735,299.9912109,-60096.888671875,0.000115988343551884,2.13790747335614E-6,1,0.999253354069792,40.0298881530762,1.99764051455015,19.6000002324581,0.00131620630149861,0.000202931262902924,0.25,-2.15466588211073E-6,0.000115986414837941,-2.0785919907311E-6,299.9912109,299.9912109,-60104.38671875,-60089.390625,57.4590757056984,20.599191290119,25.186911,0,0,0,40,4449,300.2119,-60096.888671875,,,,,,,,,,,,,0,,,,0.00245,,,,,,299.9912109,,,,
,32600340.655,299.9891663,-55304.765625,0.000101730530395071,2.27553624762335E-6,1,0.999253354069792,40.0298881530762,1.99772676192298,19.6000002324581,0.00114923274031261,0.000208163823379739,0.25,7.77284713988649E-7,0.000101727091069236,8.4400611124087E-7,299.9891663,299.9891663,-55307.1875,-55302.34375,57.4723633905253,20.5970361582071,24.807261,0,0,0,40,4449,300.21995,-55304.765625,,,,,,,,,,,,,0,,,,-0.00245,,,,,,299.9891663,,,,
,32600437.325,299.9894714,-50472.734375,8.21899695944603E-5,2.09401444489973E-6,1,0.999253354069792,40.0298881530762,1.9976240090501,19.6000002324581,0.000933580225240022,0.000138506009545802,0.25,-1.99469741627845E-6,8.21889068084241E-5,-1.94065639483243E-6,299.9894714,299.9894714,-50480.19140625,-50465.27734375,57.6482298073523,20.5964544009919,24.807261,0,0,0,40,4449,300.23175,-50472.734375,,,,,,,,,,,,,0,,,,0.0049,,,,,,299.9894714,,,,
,32600534.605,299.9863586,-45610.87890625,6.73678529265094E-5,1.45885003744929E-6,1,0.999253354069792,40.0298881530762,1.99769615549234,19.6000002324581,0.000761463995343942,0.000135355556459761,0.25,2.94297136061755E-7,6.73657176703762E-5,3.38584729797177E-7,299.9863586,299.9863586,-45618.36328125,-45603.39453125,57.5262957583522,20.5955361575415,24.427608,0,0,0,40,4449,300.2467,-45610.87890625,,,,,,,,,,,,,0,,,,0.00245,,,,,,299.9863586,,,,
,32600630.305,299.9773254,-40827.744140625,5.21771273507843E-5,1.39554885373166E-6,1,0.999253354069792,40.0298881530762,1.99762514195249,19.6000002324581,0.000593262650575187,8.45113307843274E-5,0.25,-1.56849530633393E-6,5.21766694909296E-5,-1.53410542202446E-6,299.9773254,299.9773254,-40835.2890625,-40820.19921875,57.555997642083,20.5959965700111,24.807261,0,0,0,40,4449,300.25065,-40827.744140625,,,,,,,,,,,,,0,,,,-0.00245,,,,,,299.9773254,,,,
,32600726.1,299.9895325,-36040.60546875,3.75646258186953E-5,1.68557749827863E-6,1,0.999253354069792,40.0298881530762,1.99761332054096,19.6000002324581,0.000427657932030883,5.77004335882942E-5,0.25,-1.40708959815903E-6,3.75644613046441E-5,-1.38229705830014E-6,299.9895325,299.9895325,-36053.1640625,-36028.046875,57.5302039009484,20.5958427355013,24.427608,0,0,0,40,4449,300.26675,-36040.60546875,,,,,,,,,,,,,0,,,,0,,,,,,299.9895325,,,,
,32600820.375,299.9887085,-31328.607421875,2.12312637030253E-5,1.42842126761276E-6,1,0.999253354069792,40.0298881530762,1.99752921022654,19.6000002324581,0.000243270618089807,2.35427153224083E-5,0.25,-1.59699537845544E-6,2.12316994036577E-5,-1.58294521380537E-6,299.9887085,299.9887085,-31330.93359375,-31326.28125,57.1972301517561,20.595624300663,25.186911,0,0,0,40,4449,300.271,-31328.607421875,,,,,,,,,,,,,0,,,,-0.0049,,,,,,299.9887085,,,,
,32600914.97,299.9938354,-26600.74609375,6.62616452725196E-6,1.04941857157466E-6,1,0.999253354069792,40.0298881530762,1.99739783973451,19.6000002324581,7.43352351066677E-5,1.64864277796768E-5,0.25,3.09656277625183E-7,6.62576570027495E-6,3.14022074836998E-7,299.9938354,299.9938354,-26608.44921875,-26593.04296875,57.2925888311022,20.5958422261595,24.807261,0,0,0,40,4449,300.2715,-26600.74609375,,,,,,,,,,,,,0,,,,0.00245,,,,,,299.9938354,,,,
,32601008.865,299.9919128,-21908.3095703125,-8.70954119958626E-6,1.11390829343339E-6,1,0.999253354069792,40.0298881530762,1.99750613668496,19.6000002324581,-9.67011599514239E-5,-2.7508527675902E-5,0.25,-9.23109398832808E-7,-8.70867577420773E-6,-9.28838142143972E-7,299.9919128,299.9919128,-21910.7421875,-21905.876953125,57.2245871499291,20.5949031869513,25.186911,0,0,0,40,4449,300.2789,-21908.3095703125,,,,,,,,,,,,,0,,,,0.00245,,,,,,299.9919128,,,,
,32601104.97,299.9857483,-17106.369140625,-2.1764144613249E-5,7.80762361702441E-7,1,0.999253354069792,40.0298881530762,1.9975601541588,19.6000002324581,-0.000246335293360545,-4.17080570389781E-5,0.25,8.3387922411484E-8,-2.17635652664055E-5,6.8989393016953E-8,299.9855347,299.9859619,-17113.65625,-17099.08203125,57.3082214014868,20.5937383694416,25.186911,0,0,0,40,4449,300.2904,-17106.369140625,,,,,,,,,,,,,0,,,,0.0049,,,,,,299.9857483,,,,
,32601201.19,299.9898682,-12298.7744140625,-3.49893611557135E-5,6.61549789587157E-7,1,0.999253354069792,40.0298881530762,1.99753820512866,19.6000002324581,-0.0003963001013252,-6.54312872317723E-5,0.25,2.77341613040223E-7,-3.49885177053757E-5,2.54169258839856E-7,299.9898682,299.9898682,-12311.1181640625,-12286.4306640625,57.1581487257945,20.5939584930199,25.186911,0,0,0,40,4449,300.29695,-12298.7744140625,,,,,,,,,,,,,0,,,,0.00245,,,,,,299.9898682,,,,
,32601293.835,299.9948425,-7665.73779296875,-4.58536757667499E-5,5.36197274258219E-7,1,0.999253354069792,40.0298881530762,1.99748562681857,19.6000002324581,-0.000518445508124322,-9.09053681693667E-5,0.25,-9.27006877800039E-8,-4.58522581713251E-5,-1.23077157994753E-7,299.9948425,299.9948425,-7673.408203125,-7658.0673828125,57.291807202583,20.5934056006018,24.427608,0,0,0,40,4449,300.3125,-7665.73779296875,,,,,,,,,,,,,0,,,,0,,,,,,299.9948425,,,,
,32601387.12,299.9894104,-3002.23706054687,-4.72272228363596E-5,4.91421599838351E-7,1,0.999253354069792,40.0298881530762,1.99737567588835,19.6000002324581,-0.0005329836209587,-9.91871733682856E-5,0.25,-5.87381848659446E-7,-4.72254437731903E-5,-6.18676430688657E-7,299.9894104,299.9894104,-3009.54052734375,-2994.93359375,57.2667950899676,20.5969597148771,24.807261,0,0,0,40,4449,300.3087,-3002.23706054687,,,,,,,,,,,,,0,,,,0,,,,,,299.9894104,,,,
,32601473.585,299.9999695,1316.92193603516,3.95457309319042E-5,3.81106289176324E-7,1,0.999253354069792,40.0298881530762,1.99740539324183,19.6000002324581,0.000447692866036711,7.50173927981011E-5,0.25,-2.1887213163015E-7,3.95446969280985E-5,-1.92640548748229E-7,299.9998169,300.0001221,1311.93884277344,1321.90502929688,57.0620084179291,20.5936968648704,24.807261,0,0,0,40,4449,300.3043,1316.92193603516,,,,,,,,,,,,,0,,,,-0.00245,,,,,,299.9999695,,,,
,32601565.885,299.9984436,5928.19311523437,4.82217834490722E-5,5.34403494204658E-7,1,0.999253354069792,40.0298881530762,1.99741891679769,19.6000002324581,0.000545828755209518,9.19860464271596E-5,0.25,-2.21799013414897E-7,4.82204970401759E-5,-1.8983375086295E-7,299.9984436,299.9984436,5918.39990234375,5937.986328125,57.3277621144676,20.5935529298282,24.427608,0,0,0,40,4449,300.2995,5928.19311523437,,,,,,,,,,,,,0,,,,0,,,,,,299.9984436,,,,
,32601661.325,299.9998169,10699.1088867187,3.9295772226634E-5,6.71267621659884E-7,1,0.999253354069792,40.0298881530762,1.99724537435048,19.6000002324581,0.000444659376515192,7.5517330316995E-5,0.25,-1.30814078846595E-7,3.92946907312578E-5,-1.0478821547504E-7,299.9998169,299.9998169,10691.6171875,10706.6005859375,57.3410497992945,20.5952372723309,25.186911,0,0,0,40,4449,300.3031,10699.1088867187,,,,,,,,,,,,,0,,,,0,,,,,,299.9998169,,,,
,32601757.09,300.0031738,15487.0122070313,2.6925879951825E-5,1.01196648484198E-6,1,0.999253354069792,40.0298881530762,1.99725726445659,19.6000002324581,0.000304806227007295,5.10575964460293E-5,0.25,-1.50452451792159E-7,2.69251772108711E-5,-1.32632664144189E-7,300.0031738,300.0031738,15479.396484375,15494.6279296875,57.3926372815638,20.5900293138268,24.427608,0,0,0,40,4449,300.29835,15487.0122070313,,,,,,,,,,,,,0,,,,0,,,,,,300.0031738,,,,
,32601851.715,300.01119995,20216.7744140625,1.32033982552757E-5,1.32417806637904E-6,1,0.999253354069792,40.0298881530762,1.99727011324463,19.6000002324581,0.000147282408548492,3.76395542649203E-5,0.25,1.04060137013355E-6,1.32023138161296E-5,1.04929843536284E-6,300.0109253,300.0114746,20211.80859375,20221.740234375,57.464547105333,20.591613296513,25.186911,0,0,0,40,4449,300.2867,20216.7744140625,,,,,,,,,,,,,0,,,,-0.00245,,,,,,300.01119995,,,,
,32601947.695,300.0082703,25011.8837890625,-2.20456940787584E-6,1.08589301056441E-6,1,0.999253354069792,40.0298881530762,1.99725022040238,19.6000002324581,-2.38049614244554E-5,-1.08242950913216E-5,0.25,-5.75165141231125E-7,-2.20412370881483E-6,-5.76603901220786E-7,300.0082703,300.0082703,25004.3515625,25019.416015625,57.2527257766214,20.5942461409334,25.186911,0,0,0,40,4449,300.28795,25011.8837890625,,,,,,,,,,,,,0,,,,0,,,,,,300.0082703,,,,
,32602045.76,300.00506595,29917.1494140625,-1.50763623747103E-5,1.60546297032678E-6,1,0.999253354069792,40.0298881530762,1.99724916983432,19.6000002324581,-0.000169055159334452,-3.78897441036168E-5,0.25,-7.38270845591709E-7,-1.50754276506921E-5,-7.48195332811485E-7,300.0044556,300.0056763,29912.23046875,29922.068359375,57.3551191126407,20.5912490351898,24.807261,0,0,0,40,4449,300.2882,29917.1494140625,,,,,,,,,,,,,0,,,,-0.00245,,,,,,300.00506595,,,,
,32602144.375,300.0099487,34844.951171875,-3.28291323939539E-5,1.10668290547046E-6,1,0.999253354069792,40.0298881530762,1.99718558353891,19.6000002324581,-0.000370605538939503,-6.81015448389653E-5,0.25,-3.34133134594023E-7,-3.28279336900909E-5,-3.55758804338925E-7,300.0099487,300.0099487,34839.87109375,34850.03125,57.5786648691407,20.5903415432783,24.427608,0,0,0,40,4449,300.28425,34844.951171875,,,,,,,,,,,,,0,,,,0,,,,,,300.0099487,,,,
,32602246.53,300.0133057,39949.685546875,-4.72073600135723E-5,2.12658896492005E-6,1,0.999253354069792,40.0298881530762,1.9973683275918,19.6000002324581,-0.000532866765056829,-9.85137447790589E-5,0.25,-5.31535494529763E-7,-4.7205600423992E-5,-5.6259673084166E-7,300.0133057,300.0133057,39947.41796875,39951.953125,57.2277136640061,20.5876872600739,24.807261,0,0,0,40,4449,300.274,39949.685546875,,,,,,,,,,,,,0,,,,0,,,,,,300.0133057,,,,
,32602347.39,300.0165405,44993.0078125,-6.52130355332842E-5,2.02143729194496E-6,1,0.999253354069792,40.0298881530762,1.99730748049504,19.6000002324581,-0.000734182408980267,-0.00014709270227935,0.25,-1.70766801371869E-6,-6.52099616780764E-5,-1.75050197536075E-6,300.0165405,300.0165405,44990.6796875,44995.3359375,57.1518956976407,20.5890698714527,24.807261,0,0,0,40,4449,300.24845,44993.0078125,,,,,,,,,,,,,0,,,,0.00245,,,,,,300.0165405,,,,
,32602447.445,300.0148926,49990.4140625,-8.47099136646759E-5,1.9986729133455E-6,1,0.999253354069792,40.0298881530762,1.99734942834671,19.6000002324581,-0.000957689887915612,-0.000168053882437517,0.25,-1.82929010523907E-7,-8.47072701435764E-5,-2.38565709863419E-7,300.0148926,300.0148926,49982.95703125,49997.87109375,56.9924434797176,20.589414182243,24.427608,0,0,0,40,4449,300.2443,49990.4140625,,,,,,,,,,,,,0,,,,0,,,,,,300.0148926,,,,
,32602546.545,300.0116272,54942.587890625,-9.7086444547121E-5,2.29152800059389E-6,1,0.999253354069792,40.0298881530762,1.99724910177715,19.6000002324581,-0.00109637008809377,-0.000199469888289891,0.25,-8.17349691845629E-7,-9.70830341636307E-5,-8.81024016939875E-7,300.0116272,300.0116272,54940.2578125,54944.91796875,56.8204852054868,20.5860605024837,24.807261,0,0,0,40,4449,300.2355,54942.587890625,,,,,,,,,,,,,0,,,,-0.00245,,,,,,300.0116272,,,,
,32602647.665,300.007782,59997.98046875,-0.000117206826458001,2.05666665250861E-6,1,0.999253354069792,40.0298881530762,1.9972840189341,19.6000002324581,-0.00132364225961694,-0.000240604965671362,0.25,-9.68482482607971E-7,-0.00011720274648801,-1.04526089261827E-6,300.007782,300.007782,59993.0546875,60002.90625,56.9807190519291,20.5865098589488,24.807261,0,0,0,40,4449,300.2296,59997.98046875,,,,,,,,,,,,,0,,,,0,,,,,,300.007782,,,,
,32602745.64,300.01374815,64895.7265625,-0.000131925885463846,2.34877862260049E-6,1,0.999253354069792,40.0298881530762,1.99728165732369,19.6000002324581,-0.00148865378345391,-0.000277816648085844,0.25,-1.70884342941614E-6,-0.000131920869759288,-1.79514359079758E-6,300.013031,300.0144653,64885.421875,64906.03125,56.9346029692945,20.5859307322762,25.186911,0,0,0,40,4449,300.22165,64895.7265625,,,,,,,,,,,,,0,,,,0.00245,,,,,,300.01374815,,,,
,32602843.35,300.0134277,69780.95703125,-0.0001463632176292,2.78669874612606E-6,1,0.999253354069792,40.0298881530762,1.99729999792834,19.6000002324581,-0.0016520690527429,-0.000305396535413904,0.25,-1.64610700233678E-6,-0.000146357829471075,-1.74174619839521E-6,300.0134277,300.0134277,69773.546875,69788.3671875,56.6844818431406,20.5843650919335,25.186911,0,0,0,40,4449,300.21005,69780.95703125,,,,,,,,,,,,,0,,,,0.00245,,,,,,300.0134277,,,,
,32602942.235,300.0089111,74723.828125,-0.000166682222200304,2.54421139260036E-6,1,0.999253354069792,40.0298881530762,1.9972283803331,19.6000002324581,-0.00188199975012216,-0.000344060641226336,0.25,-1.54573407348305E-6,-0.0001666763411773,-1.65452705967041E-6,300.0089111,300.0089111,74716.3515625,74731.3046875,56.6985511564868,20.5831256976082,24.807261,0,0,0,40,4449,300.20295,74723.828125,,,,,,,,,,,,,0,,,,0.0049,,,,,,300.0089111,,,,
,32603043.02,300.0220642,79761.82421875,-0.000182660873041426,3.30444284903928E-6,1,0.999253354069792,40.0298881530762,1.99717958622641,19.6000002324581,-0.00206417303659175,-0.000366597762490182,0.25,-7.71188027545317E-7,-0.000182654958054085,-8.90290387206179E-7,300.0220642,300.0220642,79754.28125,79769.3671875,56.9580518248714,20.5829682521417,24.807261,0,0,0,40,4449,300.18635,79761.82421875,,,,,,,,,,,,,0,,,,0.00245,,,,,,300.0220642,,,,
,32603142.715,300.0165405,84745.5,-0.000197693800301911,2.68241499602994E-6,1,0.999253354069792,40.0298881530762,1.99719843068214,19.6000002324581,-0.00223155395316414,-0.000411321112628304,0.25,-2.12130088163834E-6,-0.000197686614461589,-2.25000837678743E-6,300.0165405,300.0165405,84742.859375,84748.140625,57.3691884259868,20.5789405083956,24.807261,0,0,0,40,4449,300.1718,84745.5,,,,,,,,,,,,,0,,,,-0.0049,,,,,,300.0165405,,,,
,32603236.305,300.01147465,89423.40234375,-0.000216283226134311,3.23914219791333E-6,1,0.999253354069792,40.0298881530762,1.99718552954587,19.6000002324581,-0.00243510424246219,-0.000486195041691363,0.25,-5.52191454959357E-6,-0.000216273338057361,-5.66246358276498E-6,300.0108643,300.012085,89415.9921875,89430.8125,56.9408559974483,20.576670325471,24.427608,0,0,0,40,4449,300.16395,89423.40234375,,,,,,,,,,,,,0,,,,-0.00245,,,,,,300.01147465,,,,
,32603346.08,300.0071716,86048.984375,-0.000202095334554744,2.65740177334181E-6,1,0.999253354069792,40.0298881530762,1.9971306587453,19.6000002324581,-0.00227979696089229,-0.000428362468911824,0.25,-2.8668871671795E-6,-0.000202087605725999,-2.99840314566093E-6,300.0071716,300.0071716,86014.0703125,86083.8984375,56.7978179784291,20.5814386378418,25.186911,0,0,0,40,4449,300.1577,86048.984375,,,,,,,,,,,,,0,,,,0,,,,,,300.0071716,,,,
,32603443.885,300.0018921,81158.08984375,-0.000183873989537423,2.86777513976421E-6,1,0.999253354069792,40.0298881530762,1.99711532520009,19.6000002324581,-0.00207905754030352,-0.000361876395451157,0.25,-1.44512848480663E-7,-0.000183868583179725,-2.64395611654792E-7,300.0018921,300.0018921,81150.5703125,81165.609375,57.0158923352945,20.582767375318,25.186911,0,0,0,40,4449,300.15665,81158.08984375,,,,,,,,,,,,,0,,,,0,,,,,,300.0018921,,,,
,32603542.78,299.9980469,76214.12890625,-0.000170833658208317,3.91777154466875E-6,1,0.999253354069792,40.0298881530762,1.99709887856558,19.6000002324581,-0.00193093247897312,-0.000340038577448466,0.25,-4.72725244475479E-7,-0.000170828425324787,-5.84236914387803E-7,299.9980469,299.9980469,76211.4296875,76216.828125,56.9072459711214,20.5833884409432,25.566563,0,0,0,40,4449,300.1594,76214.12890625,,,,,,,,,,,,,0,,,,0.0049,,,,,,299.9980469,,,,
,32603641.705,299.9875183,71268.1484375,-0.000152280693240962,3.01368194275192E-6,1,0.999253354069792,40.0298881530762,1.99722551676265,19.6000002324581,-0.00171730712752848,-0.000326365627573412,0.25,-2.47603993009624E-6,-0.000152274732281278,-2.57550304957169E-6,299.9875183,299.9875183,71263.296875,71273,56.922878541506,20.5837629533702,24.807261,0,0,0,40,4449,300.1721,71268.1484375,,,,,,,,,,,,,0,,,,-0.00245,,,,,,299.9875183,,,,
,32603741.675,299.9873657,66272.92578125,-0.000136613957450964,1.91949587074871E-6,1,0.999253354069792,40.0298881530762,1.99720949198791,19.6000002324581,-0.00153964120862819,-0.000298422041193673,0.25,-2.71950050843592E-6,-0.000136608272712775,-2.8088282351845E-6,299.9873657,299.9873657,66265.4765625,66280.375,57.1206305568714,20.5861183356752,25.566563,0,0,0,40,4449,300.17305,66272.92578125,,,,,,,,,,,,,0,,,,0.00245,,,,,,299.9873657,,,,
,32603842.195,299.9887085,61247.3515625,-0.000120241706959064,2.30299634547803E-6,1,0.999253354069792,40.0298881530762,1.99714658391438,19.6000002324581,-0.0013587350744108,-0.000241581064909236,0.25,-5.30394326872332E-7,-0.000120237908488232,-6.09161542875332E-7,299.9887085,299.9887085,61237.8203125,61256.8828125,57.0487207331022,20.5884913287578,24.427608,0,0,0,40,4449,300.1941,61247.3515625,,,,,,,,,,,,,0,,,,0,,,,,,299.9887085,,,,
,32603940.745,299.9804993,56322.001953125,-0.000103834256580573,2.42390054151707E-6,1,0.999253354069792,40.0298881530762,1.99719045487093,19.6000002324581,-0.00117275590381677,-0.000212080081456321,0.25,-7.63830928123844E-7,-0.000103830799124108,-8.31919807945145E-7,299.9804993,299.9804993,56314.66796875,56329.3359375,56.8189219484483,20.5869207612691,25.186911,0,0,0,40,4449,300.2073,56322.001953125,,,,,,,,,,,,,0,,,,0,,,,,,299.9804993,,,,
,32604040.115,299.9881592,51354.36328125,-8.77662892581137E-5,2.52507385388573E-6,1,0.999253354069792,40.0298881530762,1.9972101528345,19.6000002324581,-0.000989838526999347,-0.000187613441162093,0.25,-1.38394417133091E-6,-8.77628514321581E-5,-1.44154124238369E-6,299.9881592,299.9881592,51347.07421875,51361.65234375,57.1370447557753,20.5871414030236,24.807261,0,0,0,40,4449,300.21845,51354.36328125,,,,,,,,,,,,,0,,,,0,,,,,,299.9881592,,,,
,32604137.735,299.9850159,46476.55078125,-7.0211260311956E-5,1.86963862956877E-6,1,0.999253354069792,40.0298881530762,1.9971977871537,19.6000002324581,-0.000795921528004801,-0.000126563773842966,0.25,9.72898181355517E-7,-7.02098801259742E-5,9.26710148912027E-7,299.9850159,299.9850159,46474.27734375,46478.82421875,57.146424298006,20.5873057052166,25.186911,0,0,0,40,4449,300.22635,46476.55078125,,,,,,,,,,,,,0,,,,0.0049,,,,,,299.9850159,,,,
,32604238.315,299.9894409,41448.728515625,-5.48255161400244E-5,1.69521905654576E-6,1,0.999253354069792,40.0298881530762,1.99715208779248,19.6000002324581,-0.000620427700191857,-0.000104979038228277,0.25,2.15737042321409E-7,-5.48240685793184E-5,1.79645305022535E-7,299.9894409,299.9894409,41446.0234375,41451.43359375,56.7290346687368,20.5884740274457,25.186911,0,0,0,40,4449,300.2347,41448.728515625,,,,,,,,,,,,,0,,,,0,,,,,,299.9894409,,,,
,32604336.655,299.987442,36534.154296875,-3.97066494592223E-5,1.44101669333434E-6,1,0.999253354069792,40.0298881530762,1.99716170431664,19.6000002324581,-0.000448810555199946,-7.90776028848127E-5,0.25,-1.13217261386087E-7,-3.97054240749063E-5,-1.39375514643335E-7,299.9873047,299.9875793,36528.98046875,36539.328125,57.1018714724099,20.5903559629599,25.566563,0,0,0,40,4449,300.25345,36534.154296875,,,,,,,,,,,,,0,,,,0,,,,,,299.987442,,,,
,32604434.79,299.9879456,31629.4453125,-2.32036760366548E-5,1.54105321419205E-6,1,0.999253354069792,40.0298881530762,1.9972419835423,19.6000002324581,-0.000260829230598988,-5.46146096257337E-5,0.25,-8.09051643349784E-7,-2.32024679999199E-5,-8.24332910296568E-7,299.9879456,299.9879456,31621.96484375,31636.92578125,57.1542405831984,20.588142754731,24.807261,0,0,0,40,4449,300.2525,31629.4453125,,,,,,,,,,,,,0,,,,0,,,,,,299.9879456,,,,
,32604532.305,299.9858093,26756.6162109375,-7.5509772121206E-6,1.30453932163225E-6,1,0.999253354069792,40.0298881530762,1.99722441407503,19.6000002324581,-8.3179966587208E-5,-2.75776348858662E-5,0.25,-1.13028136786506E-6,-7.55001165052388E-6,-1.13523389655268E-6,299.9858093,299.9858093,26748.978515625,26764.25390625,57.1815975813714,20.5890280166683,25.186911,0,0,0,40,4449,300.2696,26756.6162109375,,,,,,,,,,,,,0,,,,0.00245,,,,,,299.9858093,,,,
,32604630.36,299.9863892,21853.9580078125,8.14493713390293E-6,1.182848086931E-6,1,0.999253354069792,40.0298881530762,1.9971522681451,19.6000002324581,9.35031665383441E-5,7.90914810433371E-6,0.25,-7.11783872721428E-7,8.14517031928577E-6,-7.06380306536837E-7,299.9863892,299.9863892,21851.224609375,21856.69140625,57.0268351345637,20.5904814116476,25.186911,0,0,0,40,4449,300.2746,21853.9580078125,,,,,,,,,,,,,0,,,,-0.0049,,,,,,299.9863892,,,,
,32604728.705,299.9954529,16939.212890625,2.24030258456809E-5,1.07582969181549E-6,1,0.999253354069792,40.0298881530762,1.99724188250709,19.6000002324581,0.000255386802577997,3.21959335637786E-5,0.25,-1.03461667526575E-6,2.24030492142971E-5,-1.01976636576278E-6,299.9954529,299.9954529,16934.25,16944.17578125,57.2159892362176,20.5890297294847,24.807261,0,0,0,40,4449,300.2798,16939.212890625,,,,,,,,,,,,,0,,,,0.0049,,,,,,299.9954529,,,,
,32604828.65,299.9943848,11944.5336914062,3.62352497664165E-5,6.19986598524553E-7,1,0.999253354069792,40.0298881530762,1.99726086455658,19.6000002324581,0.000410212221736976,6.85875438449099E-5,0.25,-2.13352061280193E-7,3.62343212520301E-5,-1.89353751905686E-7,299.9943848,299.9943848,11936.9892578125,11952.078125,57.2011382943522,20.5890206103923,24.807261,0,0,0,40,4449,300.2816,11944.5336914062,,,,,,,,,,,,,0,,,,0,,,,,,299.9943848,,,,
,32604924.575,299.9924011,7149.22387695313,4.6675708048007E-5,5.90349034017946E-7,1,0.999253354069792,40.0298881530762,1.99715724305238,19.6000002324581,0.000528384267772322,8.83233809913399E-5,0.25,-2.76787117423471E-7,4.66745145776703E-5,-2.45849761194174E-7,299.9924011,299.9924011,7144.3408203125,7154.10693359375,56.9947883652753,20.5911822084513,25.186911,0,0,0,40,4449,300.2899,7149.22387695313,,,,,,,,,,,,,0,,,,-0.00245,,,,,,299.9924011,,,,
,32605020.29,299.99038695,2366.11181640625,4.63216233438997E-5,4.92195218363534E-7,1,0.999253354069792,40.0298881530762,1.99721600838029,19.6000002324581,0.000524224385986898,8.86154818035215E-5,0.25,-1.89850591570089E-7,4.63203842289638E-5,-1.59129106650643E-7,299.9901123,299.9906616,2361.04760742187,2371.17602539062,57.1714364106214,20.5883569130596,25.186911,0,0,0,40,4449,300.2935,2366.11181640625,,,,,,,,,,,,,0,,,,0,,,,,,299.99038695,,,,
,32605068.095,299.9938354,-0.342534884810448,1.09410518325738E-5,5.13437009917194E-7,1,0.999253354069792,40.0298881530762,1.99720392397636,19.6000002324581,0.000125282875381843,1.2486000417278E-5,0.25,-7.91564322252006E-7,1.09412529263142E-5,-7.84284365803661E-7,299.9938354,299.9938354,-0.365370541810989,-0.319699227809906,57.2011382943522,20.5916545018989,24.807261,0,0,0,40,4417,300.30575,-0.342534884810448,,,,,,,,,,,,,0,,,,-0.00245,,,,,,299.9938354,,,,