File: data/doubleLayers/dl_1-25/ppms/data/DD205_3_HYST_100OE_10KREPEAT.DAT
[Header]
; VSM Data File (default extension .dat)
; Copyright (c) 2003-2013, Quantum Design, Inc. All rights reserved.
TITLE,
FILEOPENTIME,32621241.63,01/13/2019,9:29 pm
BYAPP,VSM,2.0,2.0
INFO,PPMS VSM Option Release 1.4.10 Build 1,APPNAME
INFO,Quantum Design Linear Motor Servo Controller,MOTOR_MODULE_NAME
INFO,3101-100 M1,MOTOR_HW_VERSION
INFO,MMC1014,MOTOR_SERIAL_NUMBER
INFO,SRV No X-over 01.03.11,MOTOR_SOFTWARE_VERSION
INFO,Quantum Design VSM Detection Module,VSM_MODULE_NAME
INFO,3101-150 F0,VSM_HW_VERSION
INFO,VSM707,VSM_SERIAL_NUMBER
INFO,VSM No X-over 01.02.05 May 20 2008 13:51:47,VSM_SOFTWARE_VERSION
INFO,704,PREAMP_SERIAL_NUMBER
INFO,822,COIL_SERIAL_NUMBER
INFO,0,MOMENT_UNITS
INFO,DD205_4,SAMPLE_MATERIAL
INFO,Double Layer Blue 1.25,SAMPLE_COMMENT
INFO,26.73,SAMPLE_MASS
INFO,,SAMPLE_VOLUME
INFO,,SAMPLE_MOLECULAR_WEIGHT
INFO,,SAMPLE_SIZE
INFO,,SAMPLE_SHAPE
DATATYPE,COMMENT,1
DATATYPE,TIME,2
STARTUPAXIS,X,2
STARTUPAXIS,Y1,5
[Data]
Comment,Time Stamp (sec),Temperature (K),Magnetic Field (Oe),Moment (emu),M. Std. Err. (emu),Transport Action,Averaging Time (sec),Frequency (Hz),Peak Amplitude (mm),Center Position (mm),Coil Signal' (mV),Coil Signal" (mV),Range (mV),M. Quad. Signal (emu),M. Raw' (emu),M. Raw" (emu),Min. Temperature (K),Max. Temperature (K),Min. Field (Oe),Max. Field (Oe),Mass (grams),Motor Lag (deg),Pressure (Torr),VSM Status (code),Motor Status (code),Measure Status (code),Measure Count,PPMS Status (code),System Temp. (K),System Field (Oe),Sample Position (deg),Bridge 1 Resistance (ohms),Bridge 1 Excitation (에),Bridge 2 Resistance (ohms),Bridge 2 Excitation (에),Bridge 3 Resistance (ohms),Bridge 3 Excitation (에),Bridge 4 Resistance (ohms),Bridge 4 Excitation (에),Signal 1 Vin (V),Signal 2 Vin (V),Digital Inputs (code),Drive 1 Iout (mA),Drive 1 Ipower (W),Drive 2 Iout (mA),Drive 2 Ipower (W),Pressure (),Map 20 (),Map 21 (),Map 22 (),Map 23 (),Map 24 (),Map 25 (),Map 26 (),Map 27 (),Map 28 (),Map 29 ()
,32621256.83,10.0011206,100.309440612793,,,2,,,,20.6400000834465,,,,,,,10.0011206,10.0011206,100.309440612793,100.309440612793,,,13.038077,,,,-99999999,4369,9.9893,100.309440612793,,,,,,,,,,,,,,,,,,,,,,,10.0011206,,,,
,32621408.985,10.0015287,4579.03076171875,8.83512829104562E-6,5.05198967395079E-7,1,0.999253354069792,40.0298881530762,1.98596282361286,20.6300001591444,9.96678726599027E-5,1.24591917718131E-5,0.25,-4.5680604069994E-7,8.78889696824864E-6,-4.09255737411792E-7,10.0015287,10.0015287,4571.53369140625,4586.52783203125,56.4187281466021,20.5714557469287,12.658426,0,0,0,40,4449,9.97975,4579.03076171875,,,,,,,,,,,,,0,,,,0,,,,,,10.0015287,,,,
,32621509.075,10.0027008,9582.61572265625,-1.78946083889153E-6,4.94164390974453E-7,1,0.999253354069792,40.0298881530762,1.98609824478115,20.6300001591444,-1.64240428758692E-5,-2.36865148032772E-5,0.25,-1.79927997057723E-6,-1.77045464678922E-6,-1.79982923118636E-6,10.0027008,10.0027008,9577.572265625,9587.6591796875,56.1967456471406,20.5837113569126,13.038077,0,0,0,40,4449,9.97785,9582.61572265625,,,,,,,,,,,,,0,,,,0.00245,,,,,,10.0027008,,,,
,32621608.04,10.0010548,14527.7119140625,-8.74268359562137E-6,9.07607352281087E-7,1,0.999253354069792,40.0298881530762,1.9861911611426,20.6300001591444,-9.45932683512032E-5,-3.54350248391751E-5,0.25,-1.60606906456656E-6,-8.6921699521594E-6,-1.64942405379882E-6,10.0010548,10.0010548,14520.16015625,14535.263671875,56.7563916669098,20.5820160009321,12.658426,0,0,0,40,4449,9.9757,14527.7119140625,,,,,,,,,,,,,0,,,,0,,,,,,10.0010548,,,,
,32621707.585,10.00264215,19502.5185546875,-1.17829331433908E-5,9.48494584898221E-7,1,0.999253354069792,40.0298881530762,1.98632733220647,20.6300001591444,-0.000128091958131926,-4.47402016069421E-5,0.25,-1.88883845011996E-6,-1.17212817170607E-5,-1.953460224121E-6,10.002552,10.0027323,19492.357421875,19512.6796875,57.1472059265253,20.5858927080078,12.658426,0,0,0,40,4449,9.97625,19502.5185546875,,,,,,,,,,,,,0,,,,0,,,,,,10.00264215,,,,
,32621808.455,10.0014772,24544.880859375,-1.26208051696462E-5,1.18460849334926E-6,1,0.999253354069792,40.0298881530762,1.98632908870075,20.6300001591444,-0.000136812598615688,-5.0456095896289E-5,0.25,-2.24355174722212E-6,-1.25590351595435E-5,-2.3168792013055E-6,10.0014772,10.0014772,24535.115234375,24554.646484375,56.3632325217367,20.5924322157465,12.278775,0,0,0,40,4449,9.97325,24544.880859375,,,,,,,,,,,,,0,,,,-0.00245,,,,,,10.0014772,,,,
,32621908.575,10.002183,29547.720703125,-1.13806816438453E-5,1.55664670832851E-6,1,0.999253354069792,40.0298881530762,1.98633186210606,20.6300001591444,-0.000123725834374435,-4.3861052032262E-5,0.25,-1.87191544349709E-6,-1.13313466543455E-5,-1.94261112888411E-6,10.002183,10.002183,29537.42578125,29558.015625,56.8470605751406,20.5852430742441,13.038077,0,0,0,40,4449,9.9724,29547.720703125,,,,,,,,,,,,,0,,,,-0.0049,,,,,,10.002183,,,,
,32622007.305,10.0010605,34482.767578125,-1.61261196216959E-5,1.70823828760059E-6,1,0.999253354069792,40.0298881530762,1.98614512678933,20.6300001591444,-0.000175392268017024,-6.21402223743982E-5,0.25,-2.6457823274069E-6,-1.60640779930051E-5,-2.75090355412521E-6,10.0010605,10.0010605,34475.2578125,34490.27734375,56.4382688595829,20.5873416103495,12.658426,0,0,0,40,4449,9.9725,34482.767578125,,,,,,,,,,,,,0,,,,0,,,,,,10.0010605,,,,
,32622106.655,9.9976578,39449.833984375,-2.93922205770902E-5,2.2304273659303E-6,1,0.999253354069792,40.0298881530762,1.9860808768149,20.6300001591444,-0.000316245352025657,-0.000133224570338837,0.25,-6.59298897504326E-6,-2.92811388235682E-5,-6.78847986262368E-6,9.9976578,9.9976578,39442.421875,39457.24609375,56.9267866841022,20.591199051308,12.658426,0,0,0,40,4449,9.9694,39449.833984375,,,,,,,,,,,,,0,,,,0,,,,,,9.9976578,,,,
,32622204.495,10.0023842,44340.251953125,-3.54809194952763E-5,2.34724906865941E-6,1,0.999253354069792,40.0298881530762,1.98607727477983,20.6300001591444,-0.00038633327601622,-0.000136518412275827,0.25,-5.78037940573369E-6,-3.53798861166951E-5,-6.02877346675658E-6,10.0023842,10.0023842,44335.203125,44345.30078125,56.9580518248714,20.5883505612346,12.658426,0,0,0,40,4449,9.96805,44340.251953125,,,,,,,,,,,,,0,,,,-0.00245,,,,,,10.0023842,,,,
,32622304.95,9.9981852,49360.490234375,-5.27041401154199E-5,2.68068729412673E-6,1,0.999253354069792,40.0298881530762,1.98601141425916,20.6300001591444,-0.000577029593290752,-0.00018684477668213,0.25,-7.15229101494045E-6,-5.25911428142464E-5,-7.53232520668664E-6,9.9981852,9.9981852,49353.1640625,49367.81640625,56.8470605751406,20.5905099555834,12.278775,0,0,0,40,4449,9.96915,49360.490234375,,,,,,,,,,,,,0,,,,0,,,,,,9.9981852,,,,
,32622405.385,9.9955196,54380.541015625,-6.31565566328876E-5,2.50963734100438E-6,1,0.999253354069792,40.0298881530762,1.98597960631947,20.6300001591444,-0.000693225091038315,-0.000216105874707891,0.25,-7.86360536532668E-6,-6.30577125681448E-5,-8.32730472895588E-6,9.9955196,9.9955196,54375.296875,54385.78515625,56.831428004756,20.5906783619489,13.038077,0,0,0,40,4449,9.973,54380.541015625,,,,,,,,,,,,,0,,,,-0.00245,,,,,,9.9955196,,,,
,32622506.075,9.9960046,59412.619140625,-8.79800294950945E-5,3.37287244865593E-6,1,0.999253354069792,40.0298881530762,1.98605805755116,20.6300001591444,-0.000970027985109064,-0.000279958854364412,0.25,-9.06178248661014E-6,-8.78989257900152E-5,-9.71522618561887E-6,9.9959574,9.9960518,59407.44921875,59417.7890625,56.4742237714675,20.5915198552197,12.278775,0,0,0,40,4449,9.9778,59412.619140625,,,,,,,,,,,,,0,,,,0.00245,,,,,,9.9960046,,,,
,32622605.08,9.9958591,64360.892578125,-0.000103631606041197,3.57646369988593E-6,1,0.999253354069792,40.0298881530762,1.98592917352917,20.6300001591444,-0.00113896233559968,-0.000352559232955837,0.25,-1.26919038321101E-5,-0.000103568491552016,-1.34661528663795E-5,9.9958591,9.9958591,64355.85546875,64365.9296875,57.5982055821215,20.5899152230348,12.658426,0,0,0,40,4449,9.9816,64360.892578125,,,,,,,,,,,,,0,,,,0,,,,,,9.9958591,,,,
,32622703.005,9.99578,69256.203125,-0.000112744370678058,3.88950885646963E-6,1,0.999253354069792,40.0298881530762,1.98581986359508,20.6300001591444,-0.00124150878670665,-0.000373050788713129,0.25,-1.2864359504609E-5,-0.000112731597400835,-1.37080910028837E-5,9.99578,9.99578,69248.7109375,69263.6953125,57.1300100991022,20.5925421867026,12.278775,0,0,0,40,4449,9.9853,69256.203125,,,,,,,,,,,,,0,,,,0,,,,,,9.99578,,,,
,32622802.16,9.99435285,74213.703125,-0.000125449663496081,4.89849115822791E-6,1,0.999253354069792,40.0298881530762,1.98583779479501,20.6300001591444,-0.00137958976243969,-0.000428673821209858,0.25,-1.55135319059571E-5,-0.000125479095642126,-1.64525385441051E-5,9.9938965,9.9948092,74206.09375,74221.3125,56.9267866841022,20.5913667926398,12.658426,0,0,0,40,4449,9.98945,74213.703125,,,,,,,,,,,,,0,,,,0.0049,,,,,,9.99435285,,,,
,32622899.41,9.997818,79072.03515625,-0.000146841271999952,3.62529249011948E-6,1,0.999253354069792,40.0298881530762,1.98578917996148,20.6300001591444,-0.00163085764880675,-0.00041625544307305,0.25,-1.05537826700026E-5,-0.000146988186724228,-1.16374928057317E-5,9.997818,9.997818,79064.625,79079.4453125,56.872072687756,20.5901466714508,12.278775,0,0,0,40,4449,9.99305,79072.03515625,,,,,,,,,,,,,0,,,,-0.00245,,,,,,9.997818,,,,
,32622999.515,9.9951439,84077.80859375,-0.00016764504373703,3.89356012177528E-6,1,0.999253354069792,40.0298881530762,1.98603170410778,20.6300001591444,-0.00184568327713462,-0.000570696871545525,0.25,-2.05244073901195E-5,-0.000167814701475234,-2.17669224426023E-5,9.9951439,9.9951439,84072.8671875,84082.75,57.2542890336599,20.5885964358989,12.658426,0,0,0,40,4449,9.9962,84077.80859375,,,,,,,,,,,,,0,,,,0.00245,,,,,,9.9951439,,,,
,32623091.55,9.9957895,88678.359375,-0.000176697119868329,4.32103325187415E-6,1,0.999253354069792,40.0298881530762,1.98577302348086,20.6300001591444,-0.00193306450137651,-0.000672091937812941,0.25,-2.79073515249004E-5,-0.000176889582228105,-2.92209995218866E-5,9.9957895,9.9957895,88670.859375,88685.859375,57.5239508727946,20.5911650492949,12.278775,0,0,0,40,4449,10.0006,88678.359375,,,,,,,,,,,,,0,,,,0.00245,,,,,,9.9957895,,,,
,32623204.495,9.9979916,86773.88671875,-0.000169840811837623,5.33855610611991E-6,1,0.999253354069792,40.0298881530762,1.98579540254203,20.6300001591444,-0.00187666481159297,-0.000541219578238824,0.25,-1.75164689340894E-5,-0.000170069153388574,-1.87631602489597E-5,9.9979916,9.9979916,86763.7734375,86784,57.2417829773522,20.5887565048901,12.658426,0,0,0,40,4449,10.0019,86773.88671875,,,,,,,,,,,,,0,,,,-0.00245,,,,,,9.9979916,,,,
,32623301.51,9.9989414,81923.05078125,-0.000166457344049007,3.76798891828217E-6,1,0.999253354069792,40.0298881530762,1.98607604629191,20.6300001591444,-0.00185606832576084,-0.000434831126814409,0.25,-8.66752479714474E-6,-0.000166683658123401,-9.88451888282747E-6,9.9989414,9.9989414,81915.3515625,81930.75,57.2441278629099,20.5900556089712,12.658426,0,0,0,40,4449,10.00235,81923.05078125,,,,,,,,,,,,,0,,,,0.00245,,,,,,9.9989414,,,,
,32623405.225,10.0014687,76739.1875,-0.000145078046737747,4.10970486725653E-6,1,0.999253354069792,40.0298881530762,1.98609722900705,20.6300001591444,-0.0016023424039726,-0.000460537219646848,0.25,-1.48025802325404E-5,-0.000145164757255085,-1.58826663433404E-5,10.0014687,10.0014687,76731.71875,76746.65625,58.0937580633138,20.5918484043469,11.899124,0,0,0,40,4449,10.00015,76739.1875,,,,,,,,,,,,,0,,,,0,,,,,,10.0014687,,,,
,32623503.97,10.0029602,71803.09765625,-0.000119866877348611,3.19251299822297E-6,1,0.999253354069792,40.0298881530762,1.985984445747,20.6300001591444,-0.00132935853042437,-0.000346631253109597,0.25,-9.22525312936271E-6,-0.000119912192615794,-1.01178414957555E-5,10.0029602,10.0029602,71798.0625,71808.1328125,57.7576578000446,20.5874314909237,11.899124,0,0,0,40,4449,9.9979,71803.09765625,,,,,,,,,,,,,0,,,,-0.0049,,,,,,10.0029602,,,,
,32623601.485,10.0058632,66930.08984375,-0.000105711736407216,2.60256412788525E-6,1,0.999253354069792,40.0298881530762,1.9860306117111,20.6300001591444,-0.00116632991677254,-0.000336532423644969,0.25,-1.08843695424042E-5,-0.000105686982143005,-1.16744374580796E-5,10.0058632,10.0058632,66920.40625,66939.7734375,57.3605905122753,20.5948684913328,11.899124,0,0,0,40,4449,9.99485,66930.08984375,,,,,,,,,,,,,0,,,,0,,,,,,10.0058632,,,,
,32623700.735,10.0040398,61969.189453125,-9.29513164079096E-5,2.66299939156586E-6,1,0.999253354069792,40.0298881530762,1.98603696821796,20.6300001591444,-0.00102404584932286,-0.000301547663758879,0.25,-1.00815486704782E-5,-9.28840457734098E-5,-1.07741339596295E-5,10.0040398,10.0040398,61956.8984375,61981.48046875,57.1933220091599,20.5937139487353,11.899124,0,0,0,40,4449,9.9905,61969.189453125,,,,,,,,,,,,,0,,,,0.00245,,,,,,10.0040398,,,,
,32623800.195,10.0032768,56996.287109375,-7.14250620944296E-5,2.29414889465746E-6,1,0.999253354069792,40.0298881530762,1.98606982876563,20.6300001591444,-0.000788828873364502,-0.000218876887458558,0.25,-6.61337316015645E-6,-7.13483133882981E-5,-7.14201028295866E-6,10.0032768,10.0032768,56994.1796875,56998.39453125,57.5544343850446,20.59619761843,12.278775,0,0,0,40,4449,9.9856,56996.287109375,,,,,,,,,,,,,0,,,,-0.0049,,,,,,10.0032768,,,,
,32623899.655,10.0035429,52023.8046875,-6.27648044094681E-5,2.0883906190126E-6,1,0.999253354069792,40.0298881530762,1.98600014111919,20.6300001591444,-0.000686238843365439,-0.000228774421409064,0.25,-9.06828246273251E-6,-6.2642767191763E-5,-9.52481792432482E-6,10.0035429,10.0035429,52011.3359375,52036.2734375,57.1714364106214,20.5924801051707,12.658426,0,0,0,40,4449,9.983,52023.8046875,,,,,,,,,,,,,0,,,,-0.0049,,,,,,10.0035429,,,,
,32623999.54,10.0018845,47031.240234375,-4.49195338131299E-5,1.8637591901585E-6,1,0.999253354069792,40.0298881530762,1.98618035230013,20.6300001591444,-0.000494184117465456,-0.000145570077439021,0.25,-4.88088437388051E-6,-4.48216312661372E-5,-5.20326898838471E-6,10.0018845,10.0018845,47023.41796875,47039.0625,57.2152076076984,20.5935079730608,11.899124,0,0,0,40,4449,9.9798,47031.240234375,,,,,,,,,,,,,0,,,,0,,,,,,10.0018845,,,,
,32624097.05,10.0053759,42158.365234375,-2.90053281994276E-5,1.98992484081089E-6,1,0.999253354069792,40.0298881530762,1.98581837270638,20.6300001591444,-0.000314982342771079,-0.000115632386343813,0.25,-5.08976955860062E-6,-2.89137208760295E-5,-5.28949644128163E-6,10.0053759,10.0053759,42146.16015625,42170.5703125,57.0065127930637,20.5998096509519,12.278775,0,0,0,40,4449,9.97415,42158.365234375,,,,,,,,,,,,,0,,,,0.0049,,,,,,10.0053759,,,,
,32624193.97,10.0025549,37313.3515625,-1.89337920605988E-5,1.36463234304134E-6,1,0.999253354069792,40.0298881530762,1.98592817075448,20.6300001591444,-0.000203771132743694,-8.51768969476714E-5,0.25,-4.19322341203691E-6,-1.88586261294721E-5,-4.31698100687713E-6,10.0025549,10.0025549,37303.4375,37323.265625,57.5849178972945,20.5956465889905,12.278775,0,0,0,40,4449,9.9741,37313.3515625,,,,,,,,,,,,,0,,,,0,,,,,,10.0025549,,,,
,32624292.83,10.0013323,32373.49609375,-3.0749583222594E-6,1.25523338737592E-6,1,0.999253354069792,40.0298881530762,1.98604711028763,20.6300001591444,-2.94511027018085E-5,-3.40204259312646E-5,0.25,-2.48394091088825E-6,-3.04887936767026E-6,-2.49780370304772E-6,10.0013323,10.0013323,32365.703125,32381.2890625,57.0909286731407,20.5963208447518,11.899124,0,0,0,40,4449,9.97145,32373.49609375,,,,,,,,,,,,,0,,,,0,,,,,,10.0013323,,,,
,32624392.315,10.0012054,27401.173828125,9.82214625761672E-6,8.09846941385581E-7,1,0.999253354069792,40.0298881530762,1.98583414903089,20.6300001591444,0.000115799339570598,-1.26805768056069E-5,0.25,-2.89493219945263E-6,9.80746519972377E-6,-2.81979277528552E-6,10.0012054,10.0012054,27398.625,27403.72265625,57.0964000727753,20.6062985384081,12.278775,0,0,0,40,4449,9.97,27401.173828125,,,,,,,,,,,,,0,,,,0.0049,,,,,,10.0012054,,,,
,32624491.09,10.0006447,22466.02734375,2.25101960150029E-5,7.43746444354349E-7,1,0.999253354069792,40.0298881530762,1.98582414021545,20.6300001591444,0.000258000687910582,1.13041680751001E-5,0.25,-3.02272974207165E-6,2.24404199166122E-5,-2.86779477524118E-6,10.0006447,10.0006447,22455.82421875,22476.23046875,57.3949821671215,20.6005260806874,12.278775,0,0,0,40,4449,9.9701,22466.02734375,,,,,,,,,,,,,0,,,,-0.00245,,,,,,10.0006447,,,,
,32624590.69,10.00105,17486.14453125,3.55985026517823E-5,7.37655248099749E-7,1,0.999253354069792,40.0298881530762,1.98586726261303,20.6300001591444,0.000404285954233041,3.7543584077307E-5,0.25,-3.00994745181854E-6,3.54587273838762E-5,-2.78193132867981E-6,10.00105,10.00105,17478.5546875,17493.734375,57.2707032325638,20.6026433396898,12.278775,0,0,0,40,4449,9.97145,17486.14453125,,,,,,,,,,,,,0,,,,-0.00735,,,,,,10.00105,,,,
,32624688.705,9.99625495,12586.4267578125,4.87742922789125E-5,4.83911737915826E-7,1,0.999253354069792,40.0298881530762,1.9857971305361,20.6300001591444,0.000548459645185789,8.04358136521796E-5,0.25,-1.51178844505887E-6,4.8544943365876E-5,-1.22718065579493E-6,9.9958706,9.9966393,12576.4296875,12596.423828125,57.627125837333,20.6023825126745,12.278775,0,0,0,40,4449,9.97375,12586.4267578125,,,,,,,,,,,,,0,,,,0.00245,,,,,,9.99625495,,,,
,32624785.46,9.997324,7753.46655273437,5.99640661908871E-5,4.79782476598679E-7,1,0.999253354069792,40.0298881530762,1.98589573049775,20.6300001591444,0.000672092380528787,0.000109815656965544,0.25,-8.56768636709011E-7,5.96525980785658E-5,-5.32770061851051E-7,9.997324,9.997324,7748.55419921875,7758.37890625,57.3644986548715,20.6045153135138,11.899124,0,0,0,40,4449,9.97455,7753.46655273437,,,,,,,,,,,,,0,,,,-0.00245,,,,,,9.997324,,,,
,32624882.215,9.99773975,2915.84020996094,7.10233876806692E-5,2.776218745093E-7,1,0.999253354069792,40.0298881530762,1.98611500149632,20.6300001591444,0.000793696905936577,0.000142219509565921,0.25,9.93829133054312E-8,7.0625076277627E-5,4.52789154242641E-7,9.9975185,9.997961,2905.8974609375,2925.78295898438,57.2972786022176,20.6050597788163,12.278775,0,0,0,40,4449,9.97535,2915.84020996094,,,,,,,,,,,,,0,,,,0.00245,,,,,,9.99773975,,,,
,32624973.125,9.9990959,-1624.67010498047,7.74472511667782E-5,3.34048303811485E-7,1,0.999253354069792,40.0298881530762,1.98604381816002,20.6300001591444,0.000864302507717462,0.000161195169415707,0.25,6.6308401864121E-7,7.70045719463312E-5,1.0389590724439E-6,9.9990959,9.9990959,-1629.662109375,-1619.67810058594,57.2808644033138,20.6041711712519,12.278775,0,0,0,40,4449,9.97555,-1624.67010498047,,,,,,,,,,,,,0,,,,0,,,,,,9.9990959,,,,
,32625066.31,9.99779795,-6282.1337890625,8.61914310020261E-5,3.51390704848545E-7,1,0.999253354069792,40.0298881530762,1.98590121167694,20.6300001591444,0.000960981217881473,0.000185750263661393,0.25,1.27537678092198E-6,8.57211749008408E-5,1.71843757416019E-6,9.9969282,9.9986677,-6287.291015625,-6276.9765625,57.5044101598138,20.6072226935941,12.278775,0,0,0,40,4449,9.97825,-6282.1337890625,,,,,,,,,,,,,0,,,,0,,,,,,9.99779795,,,,
,32625160.755,9.9979782,-11003.2495117187,9.17622707690856E-5,5.95333919063428E-7,1,0.999253354069792,40.0298881530762,1.98597132415657,20.6300001591444,0.00102195077822024,0.00020652582569325,0.25,2.10307135973716E-6,9.12906210375204E-5,2.60346600920371E-6,9.9979782,9.9979782,-11015.9560546875,-10990.54296875,57.2019199228714,20.604022381697,12.278775,0,0,0,40,4449,9.9759,-11003.2495117187,,,,,,,,,,,,,0,,,,0.00245,,,,,,9.9979782,,,,
,32625257.395,9.9996462,-15835.7666015625,8.94535215756977E-5,6.68492068683005E-7,1,0.999253354069792,40.0298881530762,1.9860423775206,20.6300001591444,0.000995311401101682,0.000209134755340677,0.25,2.70859927430457E-6,8.90269510988702E-5,3.22539563209105E-6,9.9996462,9.9996462,-15843.333984375,-15828.19921875,57.881155106083,20.6057023763235,11.519473,0,0,0,40,4449,9.9766,-15835.7666015625,,,,,,,,,,,,,0,,,,-0.00245,,,,,,9.9996462,,,,
,32625353.71,10.0017586,-20647.9541015625,7.39571667384313E-5,8.88723696001869E-7,1,0.999253354069792,40.0298881530762,1.98600520802454,20.6300001591444,0.000822222568308909,0.000178700688951209,0.25,2.72673480151822E-6,7.36345207158666E-5,3.17685991935876E-6,10.0017586,10.0017586,-20660.55078125,-20635.357421875,57.7107600888907,20.6066126059544,11.519473,0,0,0,40,4449,9.9752,-20647.9541015625,,,,,,,,,,,,,0,,,,-0.00245,,,,,,10.0017586,,,,
,32625449.995,10.0000534,-25460.521484375,5.23744667050529E-5,8.91575970759866E-7,1,0.999253354069792,40.0298881530762,1.9858975854271,20.6300001591444,0.000577567200770126,0.000154239089024244,0.25,4.38425372357304E-6,5.21546950676298E-5,4.71012903504516E-6,10.0000534,10.0000534,-25463.0859375,-25457.95703125,57.6060218673138,20.607491687223,11.899124,0,0,0,40,4449,9.9753,-25460.521484375,,,,,,,,,,,,,0,,,,-0.0049,,,,,,10.0000534,,,,
,32625543.49,10.0011911,-30132.865234375,3.74685168303662E-5,1.22350175110039E-6,1,0.999253354069792,40.0298881530762,1.9859047594135,20.6300001591444,0.000412117236304046,0.000117451546684806,0.25,3.75747015529082E-6,3.73245035483489E-5,3.9992743722468E-6,10.0011911,10.0011911,-30145.2109375,-30120.51953125,57.5247325013138,20.6095468896657,11.899124,0,0,0,40,4449,9.97275,-30132.865234375,,,,,,,,,,,,,0,,,,-0.00245,,,,,,10.0011911,,,,
,32625638.945,10.0007401,-34902.697265625,3.21955993915916E-5,1.48776138897349E-6,1,0.999253354069792,40.0298881530762,1.98581328970794,20.6300001591444,0.000350985825711639,0.000119272874785148,0.25,4.85562270655579E-6,3.20760583284943E-5,5.06740369230649E-6,10.0007401,10.0007401,-34912.99609375,-34892.3984375,57.738898715583,20.6046489635994,11.519473,0,0,0,40,4449,9.97445,-34902.697265625,,,,,,,,,,,,,0,,,,0,,,,,,10.0007401,,,,
,32625735.105,9.9988575,-39709.40625,3.87477965361192E-5,1.29627927644568E-6,1,0.999253354069792,40.0298881530762,1.98591016434835,20.6300001591444,0.000425087974305722,0.000130028235177688,0.25,4.6246681389159E-6,3.86314210726927E-5,4.89167983838277E-6,9.9988575,9.9988575,-39714.33984375,-39704.47265625,57.7568761715253,20.6045185841103,11.519473,0,0,0,40,4449,9.9754,-39709.40625,,,,,,,,,,,,,0,,,,-0.0049,,,,,,9.9988575,,,,
,32625829.935,9.9987593,-44447.40625,4.46078355535985E-5,1.88553776393443E-6,1,0.999253354069792,40.0298881530762,1.98601255094673,20.6300001591444,0.000490480843182038,0.000145094379666915,0.25,4.90140583515242E-6,4.44985044701014E-5,5.21779328945783E-6,9.9987593,9.9987593,-44452.34765625,-44442.46484375,57.7138866029676,20.6051238931294,11.899124,0,0,0,40,4449,9.97675,-44447.40625,,,,,,,,,,,,,0,,,,0,,,,,,9.9987593,,,,
,32625925.155,9.9972262,-49207.724609375,5.87191664825812E-5,1.60758332481011E-6,1,0.999253354069792,40.0298881530762,1.9859472803676,20.6300001591444,0.000651811652737759,0.000158450814807617,0.25,3.53927720343812E-6,5.86249927055793E-5,3.96756353043367E-6,9.9966602,9.9977922,-49215.29296875,-49200.15625,57.8491083367946,20.6084902970729,12.278775,0,0,0,40,4449,9.98,-49207.724609375,,,,,,,,,,,,,0,,,,-0.0049,,,,,,9.9972262,,,,
,32626020.07,9.9956312,-53949.154296875,7.02103720616853E-5,1.59094309153047E-6,1,0.999253354069792,40.0298881530762,1.98603057833491,20.6300001591444,0.000780720880120718,0.000184283892833878,0.25,3.75868098814509E-6,7.01344970155081E-5,4.27696632299141E-6,9.9956312,9.9956312,-53956.94921875,-53941.359375,57.8967876764677,20.6067709546831,11.899124,0,0,0,40,4449,9.9829,-53949.154296875,,,,,,,,,,,,,0,,,,-0.0049,,,,,,9.9956312,,,,
,32626116.285,9.9966488,-58759.48046875,8.94588854148141E-5,2.3531579786566E-6,1,0.999253354069792,40.0298881530762,1.98606775802676,20.6300001591444,0.000992895127553266,0.000247931262433935,0.25,5.9455987425175E-6,8.93952163426232E-5,6.61008080290302E-6,9.9966488,9.9966488,-58764.40625,-58754.5546875,57.9538465583715,20.6075617436021,12.278775,0,0,0,40,4449,9.9873,-58759.48046875,,,,,,,,,,,,,0,,,,0,,,,,,9.9966488,,,,
,32626213.555,9.9960451,-63621.90625,0.000102553492006859,2.03387487266131E-6,1,0.999253354069792,40.0298881530762,1.98581595145924,20.6300001591444,0.00114649808489564,0.000240540828622151,0.25,2.92114112676956E-6,0.000102555831166563,3.68454808757897E-6,9.9960451,9.9960451,-63632.04296875,-63611.76953125,57.3652802833907,20.609084726076,11.899124,0,0,0,40,4449,9.9916,-63621.90625,,,,,,,,,,,,,0,,,,-0.0049,,,,,,9.9960451,,,,
,32626309.51,9.9965458,-68416.4453125,0.000115777179670692,2.41846918748438E-6,1,0.999253354069792,40.0298881530762,1.98586696185405,20.6300001591444,0.00129514910297485,0.000270375994745468,0.25,3.18568209088253E-6,0.000115829877586386,4.04541618285241E-6,9.9965458,9.9965458,-68424.1328125,-68408.7578125,57.5942974395253,20.6064220964398,11.519473,0,0,0,40,4449,9.99295,-68416.4453125,,,,,,,,,,,,,0,,,,0,,,,,,9.9965458,,,,
,32626405.11,9.9945288,-73193.671875,0.000128543994700699,2.32434773045639E-6,1,0.999253354069792,40.0298881530762,1.98582912779262,20.6300001591444,0.00143664690957989,0.000310689353596931,0.25,4.46711734456244E-6,0.000128647388330393,5.41755344433183E-6,9.9945288,9.9945288,-73196.0546875,-73191.2890625,57.7068519462946,20.6130169737912,11.899124,0,0,0,40,4449,9.9972,-73193.671875,,,,,,,,,,,,,0,,,,-0.0049,,,,,,9.9945288,,,,
,32626503.32,9.99681375,-78100.60546875,0.000149269907302323,2.16459981292086E-6,1,0.999253354069792,40.0298881530762,1.98573754980417,20.6300001591444,0.00165722112241435,0.00042556232029749,0.25,1.09449394226375E-5,0.000149406426658942,1.2048462204397E-5,9.9961042,9.9975233,-78108.1015625,-78093.109375,57.6419767791984,20.6094209596374,11.519473,0,0,0,40,4449,10.0019,-78100.60546875,,,,,,,,,,,,,0,,,,-0.0049,,,,,,9.99681375,,,,
,32626601.83,9.9959116,-83025.33984375,0.000165782532082424,2.37227089332153E-6,1,0.999253354069792,40.0298881530762,1.98585976837993,20.6300001591444,0.00183908855446802,0.00048535416426543,0.25,1.3282058152939E-5,0.000165987903365047,1.44998500543627E-5,9.9959116,9.9959116,-83040.2734375,-83010.40625,58.1805188289485,20.6138530021979,12.278775,0,0,0,40,4449,10.0037,-83025.33984375,,,,,,,,,,,,,0,,,,0,,,,,,9.9959116,,,,
,32626696.095,9.9967079,-87737.0859375,0.000183095978230825,2.77071890207498E-6,1,0.999253354069792,40.0298881530762,1.98567683688389,20.6300001591444,0.00204405818403852,0.000467233409942194,0.25,8.56352685708539E-6,0.000183427870732712,9.88292953056366E-6,9.9967079,9.9967079,-87742.1875,-87731.984375,57.6771500625638,20.6132053268398,11.899124,0,0,0,40,4449,10.0096,-87737.0859375,,,,,,,,,,,,,0,,,,0,,,,,,9.9967079,,,,
,32626805.585,9.9982929,-87813.2890625,0.000179552999021618,2.92716574480832E-6,1,0.999253354069792,40.0298881530762,1.9858376776544,20.6300001591444,0.00199454190217329,0.000514535141752968,0.25,1.33987775453676E-5,0.00017984388067363,1.47031561669451E-5,9.9982929,9.9982929,-87823.2109375,-87803.3671875,57.6701154058907,20.6135360274995,11.899124,0,0,0,40,4449,10.01165,-87813.2890625,,,,,,,,,,,,,0,,,,0.00245,,,,,,9.9982929,,,,
,32626899.52,10.00085735,-83121.609375,0.00016523482550557,2.99168728055035E-6,1,0.999253354069792,40.0298881530762,1.98560117701102,20.6300001591444,0.00183798689260927,0.000454862073485195,0.25,1.06766529090149E-5,0.000165459126611856,1.18855434344175E-5,10.0006618,10.0010529,-83131.546875,-83111.671875,57.8084636537946,20.6143186955458,11.899124,0,0,0,40,4449,10.01005,-83121.609375,,,,,,,,,,,,,0,,,,-0.00245,,,,,,10.00085735,,,,
,32627001.51,10.0034018,-78021.578125,0.000151831587321307,2.76389782560347E-6,1,0.999253354069792,40.0298881530762,1.98565048780576,20.6300001591444,0.00169365662214163,0.000387996687837371,0.25,7.14614157321849E-6,0.000151998565084703,8.26297499523671E-6,10.0034018,10.0034018,-78029.2421875,-78013.9140625,57.8092452823138,20.6198787004121,12.278775,0,0,0,40,4449,10.0078,-78021.578125,,,,,,,,,,,,,0,,,,0,,,,,,10.0034018,,,,
,32627101.765,10.0013504,-73009.60546875,0.000134573603157844,2.09563815917466E-6,1,0.999253354069792,40.0298881530762,1.98552350214588,20.6300001591444,0.00149912079471897,0.0003511378128347,0.25,6.98206283166232E-6,0.000134662844005232,7.97972905816671E-6,10.0013504,10.0013504,-73022.015625,-72997.1953125,57.6537012069869,20.6152482115631,11.899124,0,0,0,40,4449,10.0038,-73009.60546875,,,,,,,,,,,,,0,,,,0,,,,,,10.0013504,,,,
,32627200.965,10.0030088,-68057.47265625,0.000116316853270678,2.18474829552346E-6,1,0.999253354069792,40.0298881530762,1.98547856144784,20.6300001591444,0.00129408046995023,0.000309433567556533,0.25,6.56821057543579E-6,0.00011634122126595,7.43431613669465E-6,10.0030088,10.0030088,-68059.9609375,-68054.984375,57.5645955557946,20.6132661953432,11.519473,0,0,0,40,4449,10.0019,-68057.47265625,,,,,,,,,,,,,0,,,,-0.00245,,,,,,10.0030088,,,,
,32627300.125,10.0035095,-63098.287109375,9.5575169453892E-5,2.84631258554565E-6,1,0.999253354069792,40.0298881530762,1.98555458016789,20.6300001591444,0.00106132290815189,0.000262835032373219,0.25,6.16675261603099E-6,9.55471675058505E-5,6.87890066664918E-6,10.0035095,10.0035095,-63103.4140625,-63093.16015625,58.13831088891,20.6134407524652,11.899124,0,0,0,40,4449,9.99915,-63098.287109375,,,,,,,,,,,,,0,,,,0,,,,,,10.0035095,,,,
,32627397.24,10.00347325,-58245.8984375,8.42809275037469E-5,2.05437020897719E-6,1,0.999253354069792,40.0298881530762,1.98548738127662,20.6300001591444,0.000937967459985469,0.000217699724722772,0.25,4.19415770887495E-6,8.42272986932425E-5,4.82018548452896E-6,10.0028076,10.0041389,-58256.0859375,-58235.7109375,58.1289313466792,20.6087049670078,11.519473,0,0,0,40,4449,9.99505,-58245.8984375,,,,,,,,,,,,,0,,,,0.0049,,,,,,10.00347325,,,,
,32627486.05,10.0040388,-53808.478515625,6.75030378551352E-5,2.13059863502375E-6,1,0.999253354069792,40.0298881530762,1.98550668879853,20.6300001591444,0.000750441117868163,0.00017699412751933,0.25,3.60164567673698E-6,6.74292426009436E-5,4.09982560962897E-6,10.0040388,10.0040388,-53813.65234375,-53803.3046875,57.70138054666,20.6111930766306,11.899124,0,0,0,40,4449,9.9917,-53808.478515625,,,,,,,,,,,,,0,,,,0,,,,,,10.0040388,,,,
,32627575,10.0052242,-49363.501953125,5.4527972709768E-5,1.72135873376818E-6,1,0.999253354069792,40.0298881530762,1.98540909389379,20.6300001591444,0.00059979625869556,0.000176764180004394,0.25,5.93001099953647E-6,5.4421907453423E-5,6.32488249403415E-6,10.0052242,10.0052242,-49365.765625,-49361.23828125,57.8991325620254,20.6093432213389,11.519473,0,0,0,40,4449,9.9884,-49363.501953125,,,,,,,,,,,,,0,,,,-0.0049,,,,,,10.0052242,,,,
,32627665.81,10.0041971,-44826.25390625,4.0106970131828E-5,1.8818423771218E-6,1,0.999253354069792,40.0298881530762,1.98573161753408,20.6300001591444,0.000442580901323621,0.000121383839774365,0.25,3.59893796015303E-6,4.00161020904632E-5,3.88521883952275E-6,10.0041971,10.0041971,-44838.7421875,-44813.765625,57.5520894994869,20.6148965940933,12.278775,0,0,0,40,4449,9.9839,-44826.25390625,,,,,,,,,,,,,0,,,,0,,,,,,10.0041971,,,,
,32627758.045,10.0025892,-40213.458984375,2.98169272267769E-5,1.49772013732883E-6,1,0.999253354069792,40.0298881530762,1.98571523667124,20.6300001591444,0.000325497248034275,0.000108942388522732,0.25,4.35110196218361E-6,2.97232350412804E-5,4.55555512955584E-6,10.0025892,10.0025892,-40215.8046875,-40211.11328125,57.2488176340253,20.6095362953262,11.899124,0,0,0,40,4449,9.9815,-40213.458984375,,,,,,,,,,,,,0,,,,0,,,,,,10.0025892,,,,
,32627851.97,10.0017452,-35520.919921875,1.37463604295009E-5,1.40588088824429E-6,1,0.999253354069792,40.0298881530762,1.98552793705017,20.6300001591444,0.00014693589945079,6.71111790021812E-5,0.25,3.51775739367337E-6,1.36860565135818E-5,3.60489773860297E-6,10.0017452,10.0017452,-35528.28125,-35513.55859375,57.8147166819484,20.6115725598805,12.278775,0,0,0,40,4449,9.98,-35520.919921875,,,,,,,,,,,,,0,,,,0,,,,,,10.0017452,,,,
,32627944.055,10.0036764,-30918.6025390625,2.62850116296473E-6,9.67032173711036E-7,1,0.999253354069792,40.0298881530762,1.98541523788576,20.6300001591444,2.44831535350117E-5,3.28643823535543E-5,0.25,2.46246758993524E-6,2.60363574146907E-6,2.47277328173255E-6,10.0036764,10.0036764,-30921.326171875,-30915.87890625,57.9749505283907,20.6138506448143,11.519473,0,0,0,40,4449,9.97765,-30918.6025390625,,,,,,,,,,,,,0,,,,-0.00245,,,,,,10.0036764,,,,
,32628036.38,10.0010195,-26303.4736328125,-1.08105929405763E-5,9.01257667259058E-7,1,0.999253354069792,40.0298881530762,1.98538530643098,20.6300001591444,-0.000126258081363534,7.53857537804571E-6,0.25,2.61264814977531E-6,-1.07892491100853E-5,2.53226729747929E-6,10.0010195,10.0010195,-26308.298828125,-26298.6484375,57.5622506702369,20.614739760178,11.519473,0,0,0,40,4449,9.97825,-26303.4736328125,,,,,,,,,,,,,0,,,,0.00245,,,,,,10.0010195,,,,
,32628131.635,9.9995213,-21541.4697265625,-2.39726822105611E-5,7.38860872421923E-7,1,0.999253354069792,40.0298881530762,1.98546086110361,20.6300001591444,-0.000271747681943118,-2.84499845456161E-5,0.25,1.75074294593285E-6,-2.38867426821627E-5,1.59275295615886E-6,9.9995213,9.9995213,-21551.658203125,-21531.28125,57.6537012069869,20.6113707031156,11.519473,0,0,0,40,4449,9.9774,-21541.4697265625,,,,,,,,,,,,,0,,,,0.0049,,,,,,9.9995213,,,,
,32628231.37,10.0015306,-16559.728515625,-3.77703921924896E-5,5.22863998589374E-7,1,0.999253354069792,40.0298881530762,1.98565867234062,20.6300001591444,-0.000427558570818859,-4.71571530157106E-5,0.25,2.53581529146742E-6,-3.76146950591899E-5,2.29898658478016E-6,10.0015306,10.0015306,-16569.810546875,-16549.646484375,57.4121779945445,20.6132481220664,11.899124,0,0,0,40,4449,9.9768,-16559.728515625,,,,,,,,,,,,,0,,,,0.0049,,,,,,10.0015306,,,,
,32628327.005,9.9989691,-11779.3212890625,-4.96286497627594E-5,3.82181679473293E-7,1,0.999253354069792,40.0298881530762,1.98563775263151,20.6300001591444,-0.000556281443134758,-9.13768820171329E-5,0.25,6.81771900264463E-7,-4.93869574293421E-5,3.99235624273764E-7,9.9989691,9.9989691,-11781.810546875,-11776.83203125,57.6787133196022,20.6091220964753,11.519473,0,0,0,40,4449,9.97825,-11779.3212890625,,,,,,,,,,,,,0,,,,0,,,,,,9.9989691,,,,
,32628420.615,9.9984207,-7098.59130859375,-6.16013357341975E-5,4.40480321967161E-7,1,0.999253354069792,40.0298881530762,1.98556027798339,20.6300001591444,-0.000688873183368651,-0.000120788720470263,0.25,1.616070887503E-7,-6.12745122202725E-5,-1.64490262115471E-7,9.9984207,9.9984207,-7108.5927734375,-7088.58984375,57.505191788333,20.6100767512069,11.519473,0,0,0,40,4449,9.97955,-7098.59130859375,,,,,,,,,,,,,0,,,,0.0049,,,,,,9.9984207,,,,
,32628516.785,10.0024862,-2292.7255859375,-7.29226601105273E-5,3.19569940630874E-7,1,0.999253354069792,40.0298881530762,1.98549747017311,20.6300001591444,-0.000813690510686806,-0.000151371961110285,0.25,-5.88069822858853E-7,-7.25086561384612E-5,-9.45230204583829E-7,10.0024862,10.0024862,-2300.23486328125,-2285.21630859375,57.9077304757369,20.6087461699377,11.139823,0,0,0,40,4449,9.97825,-2292.7255859375,,,,,,,,,,,,,0,,,,0.0049,,,,,,10.0024862,,,,
,32628612.33,9.9996605,2478.32507324219,-7.97835668254086E-5,3.09624766774994E-7,1,0.999253354069792,40.0298881530762,1.98543438712589,20.6300001591444,-0.000889342859254209,-0.000170595568027778,0.25,-1.08857946339598E-6,-7.9329242899458E-5,-1.47779399407396E-6,9.9996605,9.9996605,2468.375,2488.27514648438,57.495030617583,20.6113915727871,11.899124,0,0,0,40,4449,9.9785,2478.32507324219,,,,,,,,,,,,,0,,,,0,,,,,,9.9996605,,,,
,32628708.985,9.9986639,7312.79638671875,-8.81870038689681E-5,4.31792028100128E-7,1,0.999253354069792,40.0298881530762,1.98547389129992,20.6300001591444,-0.000981663693393516,-0.000198104924484505,0.25,-2.02104513548928E-6,-8.77086080293203E-5,-2.47731717895592E-6,9.9986639,9.9986639,7307.93603515625,7317.65673828125,57.4778347901599,20.6100642047339,11.139823,0,0,0,40,4449,9.9809,7312.79638671875,,,,,,,,,,,,,0,,,,0.00245,,,,,,9.9986639,,,,
,32628806.185,9.9985743,12168.1860351562,-9.20110856590137E-5,6.04112478454786E-7,1,0.999253354069792,40.0298881530762,1.98550570538898,20.6300001591444,-0.00102445498584184,-0.000207826119206852,0.25,-2.16947927192639E-6,-9.15466532627155E-5,-2.67900191609175E-6,9.9985743,9.9985743,12165.595703125,12170.7763671875,57.423902422333,20.6109905837448,11.899124,0,0,0,40,4449,9.9816,12168.1860351562,,,,,,,,,,,,,0,,,,0,,,,,,9.9985743,,,,
,32628903.815,9.9997578,17050.654296875,-8.53144256834338E-5,6.66142572492343E-7,1,0.999253354069792,40.0298881530762,1.98536782746837,20.6300001591444,-0.000950372088978839,-0.000192046911936661,0.25,-1.91731117646759E-6,-8.49209596005013E-5,-2.42064548152463E-6,9.9997578,9.9997578,17038.373046875,17062.935546875,57.4106147375061,20.6092746702529,11.519473,0,0,0,40,4449,9.9789,17050.654296875,,,,,,,,,,,,,0,,,,-0.00245,,,,,,9.9997578,,,,
,32629003.085,10.0002022,22010.1650390625,-6.80870665836528E-5,8.69134448468901E-7,1,0.999253354069792,40.0298881530762,1.98523483859679,20.6300001591444,-0.0007542601945469,-0.000178551747238201,0.25,-3.76240173242943E-6,-6.77910504890991E-5,-4.17795031327092E-6,10.0002022,10.0002022,22004.9765625,22015.353515625,57.2988418592561,20.610299028772,11.899124,0,0,0,40,4449,9.9785,22010.1650390625,,,,,,,,,,,,,0,,,,0.00245,,,,,,10.0002022,,,,
,32629098.41,10.0005474,26776.126953125,-4.74113837329512E-5,1.02739967199898E-6,1,0.999253354069792,40.0298881530762,1.98526765538833,20.6300001591444,-0.0005217733900511,-0.000145018993677026,0.25,-4.44956720830494E-6,-4.72153933418668E-5,-4.74684018412568E-6,10.0005474,10.0005474,26768.6171875,26783.63671875,57.8358206519677,20.6094650016708,11.519473,0,0,0,40,4449,9.9781,26776.126953125,,,,,,,,,,,,,0,,,,-0.00245,,,,,,10.0005474,,,,
,32629196.89,9.9992886,31698.697265625,-3.36809683874469E-5,9.41183227590971E-7,1,0.999253354069792,40.0298881530762,1.98546961736719,20.6300001591444,-0.000369967116612697,-0.000108200805190236,0.25,-3.6097735376162E-6,-3.3555231323121E-5,-3.82945071655409E-6,9.9992886,9.9992886,31696.224609375,31701.169921875,57.6826214621984,20.6075176738963,11.519473,0,0,0,40,4449,9.97905,31698.697265625,,,,,,,,,,,,,0,,,,0,,,,,,9.9992886,,,,
,32629292.625,10.0001659,36483.9140625,-3.47082963800249E-5,1.50160762603855E-6,1,0.999253354069792,40.0298881530762,1.98534384666682,20.6300001591444,-0.000382886935631315,-0.000103366398187928,0.25,-2.98285036611216E-6,-3.46007895362462E-5,-3.21973306811676E-6,10.0001659,10.0001659,36473.96875,36493.859375,57.5755383550638,20.6076199883894,11.519473,0,0,0,40,4449,9.97975,36483.9140625,,,,,,,,,,,,,0,,,,-0.00245,,,,,,10.0001659,,,,
,32629387.185,10.0015764,41209.220703125,-3.99722242180728E-5,1.73246147065476E-6,1,0.999253354069792,40.0298881530762,1.98547376036352,20.6300001591444,-0.000436202762503729,-0.000146870578324102,0.25,-5.9055482106954E-6,-3.98501369869897E-5,-6.18126057238309E-6,10.0015764,10.0015764,41206.8359375,41211.60546875,57.7412436011407,20.608158152586,11.519473,0,0,0,40,4449,9.98005,41209.220703125,,,,,,,,,,,,,0,,,,-0.00245,,,,,,10.0015764,,,,
,32629482.72,9.9974957,45984.330078125,-4.98491808092516E-5,1.51568034817368E-6,1,0.999253354069792,40.0298881530762,1.98562011695481,20.6300001591444,-0.000547615483491565,-0.00016479475859373,0.25,-5.71259860061874E-6,-4.97330795734468E-5,-6.06832674998732E-6,9.9974957,9.9974957,45974.46875,45994.19140625,57.2925888311022,20.603869021909,11.519473,0,0,0,40,4449,9.98115,45984.330078125,,,,,,,,,,,,,0,,,,-0.0049,,,,,,9.9974957,,,,
,32629580.06,9.9994144,50851.896484375,-6.17011084538396E-5,1.89205219003681E-6,1,0.999253354069792,40.0298881530762,1.98540647318302,20.6300001591444,-0.000682747520388696,-0.000178138986010285,0.25,-4.75653023725222E-6,-6.16047015764861E-5,-5.20755892308121E-6,9.9994144,9.9994144,50846.75390625,50857.0390625,57.4973755031407,20.6094157677492,11.519473,0,0,0,40,4449,9.98345,50851.896484375,,,,,,,,,,,,,0,,,,-0.0098,,,,,,9.9994144,,,,
,32629677.485,9.9954395,55719.34375,-7.89355360605771E-5,1.9648611254113E-6,1,0.999253354069792,40.0298881530762,1.98544037820883,20.6300001591444,-0.000874424845756981,-0.000225030239498869,0.25,-5.81645219123295E-6,-7.88520772303929E-5,-6.40003815602481E-6,9.9954395,9.9954395,55714.3515625,55724.3359375,57.6060218673138,20.609437404071,11.139823,0,0,0,40,4449,9.98815,55719.34375,,,,,,,,,,,,,0,,,,0,,,,,,9.9954395,,,,
,32629775.555,9.9980087,60619.380859375,-8.97831775498764E-5,1.63546054491143E-6,1,0.999253354069792,40.0298881530762,1.98521187878282,20.6300001591444,-0.000994230255603664,-0.000260025315958164,0.25,-6.96922235412115E-6,-8.97275447589787E-5,-7.63723804674728E-6,9.9980087,9.9980087,60611.74609375,60627.015625,57.301968373333,20.6098369720517,11.519473,0,0,0,40,4449,9.9905,60619.380859375,,,,,,,,,,,,,0,,,,0,,,,,,9.9980087,,,,
,32629871.955,9.9981356,65437.697265625,-0.000109676146433524,2.17475637096974E-6,1,0.999253354069792,40.0298881530762,1.98517202029062,20.6300001591444,-0.00121697340528998,-0.000306994935131903,0.25,-7.55614773420012E-6,-0.0001096636522268,-8.37391342099105E-6,9.9981356,9.9981356,65435.1328125,65440.26171875,57.9663526146792,20.6086448747531,11.519473,0,0,0,40,4449,9.99415,65437.697265625,,,,,,,,,,,,,0,,,,0.00245,,,,,,9.9981356,,,,
,32629972.07,9.9957457,70442.86328125,-0.000124040330783263,1.73877202961466E-6,1,0.999253354069792,40.0298881530762,1.9853583946741,20.6300001591444,-0.00138011110522108,-0.00033058159006677,0.25,-7.05646989945319E-6,-0.000124091369191429,-7.97881583869025E-6,9.9957457,9.9957457,70437.9296875,70447.796875,57.1964485232368,20.6101047941162,11.139823,0,0,0,40,4449,9.9994,70442.86328125,,,,,,,,,,,,,0,,,,-0.0049,,,,,,9.9957457,,,,
,32630074.215,9.9976053,75548.15234375,-0.000142554293847315,2.56049421816017E-6,1,0.999253354069792,40.0298881530762,1.98533015830272,20.6300001591444,-0.00158702357245695,-0.000378552765824114,0.25,-7.98353964470754E-6,-0.000142673934642809,-9.03777513576391E-6,9.9976053,9.9976053,75545.5390625,75550.765625,57.7326456874292,20.6071363463892,11.899124,0,0,0,40,4449,10.0035,75548.15234375,,,,,,,,,,,,,0,,,,0,,,,,,9.9976053,,,,
,32630174.42,9.9935007,80559.30859375,-0.00015809101509367,2.21205095419988E-6,1,0.999253354069792,40.0298881530762,1.98529447482963,20.6300001591444,-0.00175971430254153,-0.000425133825184496,0.25,-9.32606929842758E-6,-0.000158281909834443,-1.04867234967195E-5,9.9935007,9.9935007,80554.25,80564.3671875,57.5200427301984,20.6116696898488,11.139823,0,0,0,40,4449,10.00735,80559.30859375,,,,,,,,,,,,,0,,,,-0.00245,,,,,,9.9935007,,,,
,32630274.02,9.9948254,85537.08203125,-0.000169952953490579,3.06857148191034E-6,1,0.999253354069792,40.0298881530762,1.98539682210484,20.6300001591444,-0.001893313166474,-0.000452870414373244,0.25,-9.65572491099739E-6,-0.000170222760711786,-1.08903389739812E-5,9.9948254,9.9948254,85532.1875,85541.9765625,57.4934673605446,20.6043253648794,11.519473,0,0,0,40,4449,10.01465,85537.08203125,,,,,,,,,,,,,0,,,,0,,,,,,9.9948254,,,,
,32630387.975,9.993228,89833.68359375,-0.000189379162314782,3.66397577502298E-6,1,0.999253354069792,40.0298881530762,1.9853204340216,20.6300001591444,-0.0021052498813647,-0.00053268249446823,0.25,-1.32566568394536E-5,-0.000189718281560824,-1.46240718823195E-5,9.993228,9.993228,89831.2578125,89836.109375,57.4973755031407,20.6069276149567,11.139823,0,0,0,40,4449,10.017,89833.68359375,,,,,,,,,,,,,0,,,,-0.0049,,,,,,9.993228,,,,
,32630480.29,9.9982576,85224.1171875,-0.000177233301352945,3.67050125289644E-6,1,0.999253354069792,40.0298881530762,1.98538258082083,20.6300001591444,-0.00196544868121686,-0.000521782968888107,0.25,-1.44686254039254E-5,-0.000177479237730696,-1.57656956159833E-5,9.9982576,9.9982576,85219.0625,85229.171875,57.6865296047946,20.6092340097445,11.139823,0,0,0,40,4449,10.0181,85224.1171875,,,,,,,,,,,,,0,,,,0,,,,,,9.9982576,,,,
,32630572.855,10.0007248,80598.0703125,-0.000155627206266964,2.80241166112184E-6,1,0.999253354069792,40.0298881530762,1.9853094849708,20.6300001591444,-0.00172898199465405,-0.000436981991686975,0.25,-1.08224795982923E-5,-0.000155803685864483,-1.19676545808893E-5,10.0007248,10.0007248,80585.46875,80610.671875,57.8819367346023,20.6109646065099,11.519473,0,0,0,40,4449,10.0138,80598.0703125,,,,,,,,,,,,,0,,,,0,,,,,,10.0007248,,,,
,32630663.08,10.0062666,76089.14453125,-0.000143899722172865,2.66890530607114E-6,1,0.999253354069792,40.0298881530762,1.98537385848634,20.6300001591444,-0.0015897630019434,-0.000450672178904426,0.25,-1.41525754968111E-5,-0.000143982118879542,-1.52238509280991E-5,10.0062666,10.0062666,76086.3828125,76091.90625,57.8280043667753,20.61003068785,11.139823,0,0,0,40,4449,10.0106,76089.14453125,,,,,,,,,,,,,0,,,,0,,,,,,10.0062666,,,,
,32630757.53,10.0027857,71365.4765625,-0.000128939737180243,2.23815667749087E-6,1,0.999253354069792,40.0298881530762,1.98526478029384,20.6300001591444,-0.00143576597960711,-0.000337569879313593,0.25,-6.79566791679025E-6,-0.00012900681855532,-7.75324849285668E-6,10.0027857,10.0027857,71357.8359375,71373.1171875,57.6232176947369,20.6087849634914,11.899124,0,0,0,40,4449,10.00735,71365.4765625,,,,,,,,,,,,,0,,,,0.0049,,,,,,10.0027857,,,,
,32630851.455,10.0039721,66669.890625,-0.000108414638337212,1.90949652653863E-6,1,0.999253354069792,40.0298881530762,1.9854624397819,20.6300001591444,-0.00120219876663604,-0.00030951369544246,0.25,-8.00175284248377E-6,-0.000108410212374173,-8.81036156681156E-6,10.0039721,10.0039721,66659.78125,66680,57.6802765766407,20.610592771347,11.139823,0,0,0,40,4449,10.0062,66669.890625,,,,,,,,,,,,,0,,,,0.0049,,,,,,10.0039721,,,,
,32630944.215,10.0045481,62033.845703125,-9.46950863652872E-5,1.78759970403021E-6,1,0.999253354069792,40.0298881530762,1.9850980701912,20.6300001591444,-0.00105081441006376,-0.000262561299523893,0.25,-6.30810793362871E-6,-9.46566084258918E-5,-7.01338105766849E-6,10.0045481,10.0045481,62031.17578125,62036.515625,57.7326456874292,20.6100853047727,11.519473,0,0,0,40,4449,10.0018,62033.845703125,,,,,,,,,,,,,0,,,,0.00245,,,,,,10.0045481,,,,
,32631036.07,10.0033169,57441.171875,-8.18598161345186E-5,1.70796783211721E-6,1,0.999253354069792,40.0298881530762,1.9852344463288,20.6300001591444,-0.000906229691585691,-0.000236991031435794,0.25,-6.35277898441224E-6,-8.17844745544999E-5,-6.95953008981264E-6,10.0033169,10.0033169,57438.67578125,57443.66796875,57.3230723433522,20.6131520249608,11.519473,0,0,0,40,4449,9.9991,57441.171875,,,,,,,,,,,,,0,,,,0.0049,,,,,,10.0033169,,,,
,32631126.9,10.0043354,52900.177734375,-6.61937324770506E-5,1.56781695044985E-6,1,0.999253354069792,40.0298881530762,1.98530194979299,20.6300001591444,-0.000730308182905079,-0.000203705455187179,0.25,-6.22114501287816E-6,-6.6095503092013E-5,-6.70668579475587E-6,10.0043354,10.0043354,52895.3046875,52905.05078125,57.8319125093715,20.6123898498546,11.519473,0,0,0,40,4449,9.99645,52900.177734375,,,,,,,,,,,,,0,,,,-0.00245,,,,,,10.0043354,,,,
,32631217.015,10.00405075,48398.169921875,-5.40403292092061E-5,1.35605156956288E-6,1,0.999253354069792,40.0298881530762,1.9851469755533,20.6300001591444,-0.000595682486312449,-0.000167467936145996,0.25,-5.19342523596119E-6,-5.39349940703789E-5,-5.58422267963645E-6,10.003686,10.0044155,48393.2265625,48403.11328125,57.2769562607176,20.613261658752,11.139823,0,0,0,40,4449,9.99155,48398.169921875,,,,,,,,,,,,,0,,,,0,,,,,,10.00405075,,,,
,32631308.05,10.0044394,43849.447265625,-3.83121301201876E-5,1.27260287984552E-6,1,0.999253354069792,40.0298881530762,1.98518504020775,20.6300001591444,-0.000418709090728841,-0.000137634550420949,0.25,-5.37632664629434E-6,-3.82074217941819E-5,-5.64526687422771E-6,10.0044394,10.0044394,43844.25,43854.64453125,57.6232176947369,20.615507972941,11.519473,0,0,0,40,4449,9.98685,43849.447265625,,,,,,,,,,,,,0,,,,-0.0049,,,,,,10.0044394,,,,
,32631398.61,10.0051937,39321.802734375,-2.69375748586334E-5,1.63208492741696E-6,1,0.999253354069792,40.0298881530762,1.98507568044305,20.6300001591444,-0.000288267536787475,-0.000129947178501442,0.25,-6.74826815923058E-6,-2.68303916245791E-5,-6.92569592831781E-6,10.0051937,10.0051937,39312.04296875,39331.5625,57.9874565846984,20.613107461501,11.139823,0,0,0,40,4449,9.98495,39321.802734375,,,,,,,,,,,,,0,,,,0,,,,,,10.0051937,,,,
,32631488.43,10.0032339,34832.109375,-1.30796749904417E-5,1.41131327310476E-6,1,0.999253354069792,40.0298881530762,1.98534097056602,20.6300001591444,-0.00013657189334848,-8.17331384117665E-5,0.25,-4.94413968948572E-6,-1.30102876538352E-5,-5.0221982785205E-6,10.0032339,10.0032339,34824.6484375,34839.5703125,58.0398256954869,20.615461828901,11.519473,0,0,0,40,4449,9.98215,34832.109375,,,,,,,,,,,,,0,,,,0.0049,,,,,,10.0032339,,,,
,32631577.785,10.0035009,30366.99609375,4.33106753319083E-7,8.4912684982709E-7,1,0.999253354069792,40.0298881530762,1.98523721726809,20.6300001591444,1.13128527128711E-5,-3.51173858261305E-5,0.25,-3.2139914574171E-6,4.53544307058613E-7,-3.20096223359235E-6,10.0035009,10.0035009,30362.009765625,30371.982421875,57.8616143931023,20.6137946211298,11.139823,0,0,0,40,4449,9.9817,30366.99609375,,,,,,,,,,,,,0,,,,0.00245,,,,,,10.0035009,,,,
,32631666.04,10.0013285,25954.060546875,1.12347902930556E-5,8.37764783432191E-7,1,0.999253354069792,40.0298881530762,1.98529035617582,20.6300001591444,0.00013238365085741,-1.44275706432134E-5,0.25,-3.30404779190523E-6,1.1216013103554E-5,-3.21851167187482E-6,10.0013285,10.0013285,25948.8984375,25959.22265625,57.6662072632946,20.6142267491998,11.139823,0,0,0,40,4449,9.9805,25954.060546875,,,,,,,,,,,,,0,,,,0,,,,,,10.0013285,,,,
,32631754.43,9.999176,21538.8740234375,2.30597244867132E-5,6.85465064016949E-7,1,0.999253354069792,40.0298881530762,1.98528332374888,20.6300001591444,0.000262432279811195,2.14676102931425E-5,0.25,-2.21108903993159E-6,2.29803691583396E-5,-2.05698739414656E-6,9.999176,9.999176,21531.294921875,21546.453125,57.8459818227177,20.6142148752018,11.519473,0,0,0,40,4449,9.9818,21538.8740234375,,,,,,,,,,,,,0,,,,0,,,,,,9.999176,,,,
,32631843.11,9.9994497,17106.30859375,3.61397162250983E-5,6.48775123318305E-7,1,0.999253354069792,40.0298881530762,1.98541762365677,20.6199996173382,0.000407418472887049,5.43778829318036E-5,0.25,-1.59984181608042E-6,3.59877086721792E-5,-1.37569789844967E-6,9.9994497,9.9994497,17098.734375,17113.8828125,57.3113479155637,20.6128415531715,11.139823,0,0,0,40,4449,9.981,17106.30859375,,,,,,,,,,,,,0,,,,0.00245,,,,,,9.9994497,,,,
,32631930.765,10.0016289,12726.40625,4.78410050641111E-5,5.42607952732091E-7,1,0.999253354069792,40.0298881530762,1.98525379542937,20.6300001591444,0.000538064866518192,7.75672284417183E-5,0.25,-1.60050338992922E-6,4.7617306598072E-5,-1.32029979263447E-6,10.0009966,10.0022612,12716.677734375,12736.134765625,57.9952728698907,20.6126626200084,11.519473,0,0,0,40,4449,9.9823,12726.40625,,,,,,,,,,,,,0,,,,0,,,,,,10.0016289,,,,
,32632016.965,9.9992828,8418.248046875,5.85942571816338E-5,3.86296448246955E-7,1,0.999253354069792,40.0298881530762,1.98529375317428,20.6300001591444,0.000656890829941476,0.000105554891442837,0.25,-9.94556173975675E-7,5.82937675768117E-5,-6.74303714482531E-7,9.9992828,9.9992828,8413.3232421875,8423.1728515625,57.7857964267369,20.6193433478292,11.519473,0,0,0,40,4449,9.9807,8418.248046875,,,,,,,,,,,,,0,,,,0.0049,,,,,,9.9992828,,,,
,32632102.3,9.9990501,4152.89013671875,6.87629781614171E-5,3.13624999243382E-7,1,0.999253354069792,40.0298881530762,1.98518795787039,20.6300001591444,0.000768912331220947,0.000133376193005393,0.25,-2.91393181207701E-7,6.83845979333506E-5,5.87021796599125E-8,9.9990501,9.9990501,4145.3447265625,4160.435546875,57.779543398583,20.6202165297207,11.519473,0,0,0,40,4449,9.9838,4152.89013671875,,,,,,,,,,,,,0,,,,0,,,,,,9.9990501,,,,
,32632187.205,10.0024004,-0.28163979947567,7.68856513006146E-5,3.39774239537887E-7,1,0.999253354069792,40.0298881530762,1.98529032640024,20.6300001591444,0.000858271663879072,0.000156532008850148,0.25,3.58025233823846E-7,7.64422496427083E-5,7.26552231763213E-7,10.0024004,10.0024004,-0.289251685142517,-0.274027913808823,57.7686005993138,20.6193052035898,11.519473,0,0,0,40,4417,9.9791,-0.28163979947567,,,,,,,,,,,,,0,,,,-0.00245,,,,,,10.0024004,,,,