File: data/doubleLayers/dl_1-25/ppms/data/DD205_3_HYST_FC100OE_10KREPEAT.DAT
[Header]
; VSM Data File (default extension .dat)
; Copyright (c) 2003-2013, Quantum Design, Inc. All rights reserved.
TITLE,
FILEOPENTIME,33051070.83,01/18/2019,8:53 pm
BYAPP,VSM,2.0,2.0
INFO,PPMS VSM Option Release 1.4.10 Build 1,APPNAME
INFO,Quantum Design Linear Motor Servo Controller,MOTOR_MODULE_NAME
INFO,3101-100 M1,MOTOR_HW_VERSION
INFO,MMC1014,MOTOR_SERIAL_NUMBER
INFO,SRV No X-over 01.03.11,MOTOR_SOFTWARE_VERSION
INFO,Quantum Design VSM Detection Module,VSM_MODULE_NAME
INFO,3101-150 F0,VSM_HW_VERSION
INFO,VSM707,VSM_SERIAL_NUMBER
INFO,VSM No X-over 01.02.05 May 20 2008 13:51:47,VSM_SOFTWARE_VERSION
INFO,704,PREAMP_SERIAL_NUMBER
INFO,822,COIL_SERIAL_NUMBER
INFO,0,MOMENT_UNITS
INFO,DD205_4,SAMPLE_MATERIAL
INFO,Double Layer Blue 1.25,SAMPLE_COMMENT
INFO,26.73,SAMPLE_MASS
INFO,,SAMPLE_VOLUME
INFO,,SAMPLE_MOLECULAR_WEIGHT
INFO,,SAMPLE_SIZE
INFO,,SAMPLE_SHAPE
DATATYPE,COMMENT,1
DATATYPE,TIME,2
STARTUPAXIS,X,2
STARTUPAXIS,Y1,5
[Data]
Comment,Time Stamp (sec),Temperature (K),Magnetic Field (Oe),Moment (emu),M. Std. Err. (emu),Transport Action,Averaging Time (sec),Frequency (Hz),Peak Amplitude (mm),Center Position (mm),Coil Signal' (mV),Coil Signal" (mV),Range (mV),M. Quad. Signal (emu),M. Raw' (emu),M. Raw" (emu),Min. Temperature (K),Max. Temperature (K),Min. Field (Oe),Max. Field (Oe),Mass (grams),Motor Lag (deg),Pressure (Torr),VSM Status (code),Motor Status (code),Measure Status (code),Measure Count,PPMS Status (code),System Temp. (K),System Field (Oe),Sample Position (deg),Bridge 1 Resistance (ohms),Bridge 1 Excitation (에),Bridge 2 Resistance (ohms),Bridge 2 Excitation (에),Bridge 3 Resistance (ohms),Bridge 3 Excitation (에),Bridge 4 Resistance (ohms),Bridge 4 Excitation (에),Signal 1 Vin (V),Signal 2 Vin (V),Digital Inputs (code),Drive 1 Iout (mA),Drive 1 Ipower (W),Drive 2 Iout (mA),Drive 2 Ipower (W),Pressure (),Map 20 (),Map 21 (),Map 22 (),Map 23 (),Map 24 (),Map 25 (),Map 26 (),Map 27 (),Map 28 (),Map 29 ()
,33051085.72,10.0006046,99.9745178222656,,,2,,,,20.210000218153,,,,,,,10.0006046,10.0006046,99.9745178222656,99.9745178222656,,,13.038077,,,,-99999999,4369,9.9895,99.9745178222656,,,,,,,,,,,,,,,,,,,,,,,10.0006046,,,,
,33051241.54,9.9982986,4723.9892578125,1.41120624129189E-5,3.67947479631906E-7,1,0.999253354069792,40.0298881530762,1.99448764155036,20.1999992132187,0.000158557207329002,2.72524216828357E-5,0.25,-8.20658171781175E-8,1.40350543679074E-5,-9.53082992639049E-9,9.9982986,9.9982986,4721.45068359375,4726.52783203125,56.4890747133329,20.5076745050405,13.038077,0,0,0,40,4449,9.9888,4723.9892578125,,,,,,,,,,,,,0,,,,0.0049,,,,,,9.9982986,,,,
,33051339.42,9.998683,9615.40673828125,5.71960691352404E-6,3.6453945618376E-7,1,0.999253354069792,40.0298881530762,1.99433139608113,20.1999992132187,6.37700306754556E-5,1.39203733748818E-5,0.25,2.20495503119608E-7,5.68908631212494E-6,2.50626275951933E-7,9.998683,9.998683,9602.7978515625,9628.015625,56.8306463762368,20.515116370814,12.658426,0,0,0,40,4449,9.9898,9615.40673828125,,,,,,,,,,,,,0,,,,0,,,,,,9.998683,,,,
,33051436.44,10.0009527,14463.1494140625,-1.44017983110509E-6,3.5486865437553E-7,1,0.999253354069792,40.0298881530762,1.99502945095864,20.1999992132187,-1.59889495883091E-5,-3.95549081137383E-6,0.25,-9.48712614988863E-8,-1.43283914079586E-6,-1.02804862200727E-7,10.0009527,10.0009527,14450.587890625,14475.7109375,56.5234663681791,20.5115243687038,12.658426,0,0,0,40,4449,9.98925,14463.1494140625,,,,,,,,,,,,,0,,,,0,,,,,,10.0009527,,,,
,33051536.015,10.0016136,19440.595703125,-6.23720928453836E-6,4.7240164361128E-7,1,0.999253354069792,40.0298881530762,1.99467403381411,20.1999992132187,-6.91820742786283E-5,-1.75981376740014E-5,0.25,-4.49925846337152E-7,-6.20792914757609E-6,-4.86438820082558E-7,10.0016136,10.0016136,19428.146484375,19453.044921875,56.6031924771406,20.5204404691706,12.278775,0,0,0,40,4449,9.9875,19440.595703125,,,,,,,,,,,,,0,,,,0,,,,,,10.0016136,,,,
,33051634.605,10.0015831,24365.6357421875,-7.12935476393098E-6,4.99236658701136E-7,1,0.999253354069792,40.0298881530762,1.99502788454044,20.1999992132187,-7.91616705450841E-5,-1.99416521469515E-5,0.25,-4.95523311710539E-7,-7.0993348146664E-6,-5.39751420207233E-7,10.0015831,10.0015831,24360.69921875,24370.572265625,56.9220969129868,20.5218953249938,12.658426,0,0,0,40,4449,9.9866,24365.6357421875,,,,,,,,,,,,,0,,,,-0.00245,,,,,,10.0015831,,,,
,33051730.815,10.0007658,29176.171875,-8.06493899660004E-6,5.54923981562039E-7,1,0.999253354069792,40.0298881530762,1.99485536300273,20.1999992132187,-9.09552071719645E-5,-1.49401841256112E-5,0.25,1.19649597880307E-7,-8.03941271288759E-6,6.50288400382868E-8,10.0007658,10.0007658,29168.775390625,29183.568359375,56.6328943608714,20.521569377188,12.658426,0,0,0,40,4449,9.9863,29176.171875,,,,,,,,,,,,,0,,,,0,,,,,,10.0007658,,,,
,33051826.29,9.9996276,33948.763671875,-1.32872719299216E-5,5.44854206682153E-7,1,0.999253354069792,40.0298881530762,1.99373658898323,20.1999992132187,-0.000148837704465331,-3.023437477308E-5,0.25,-2.99761887086446E-7,-1.32484973161986E-5,-3.91158466747744E-7,9.9995785,9.9996767,33941.21484375,33956.3125,57.1253203279868,20.5412284601449,12.658426,0,0,0,40,4449,9.9877,33948.763671875,,,,,,,,,,,,,0,,,,-0.00245,,,,,,9.9996276,,,,
,33051922.625,9.999651,38763.681640625,-2.29353380415875E-5,4.14533917418145E-7,1,0.999253354069792,40.0298881530762,1.99444061626536,20.1999992132187,-0.000258655920592663,-4.37425969642879E-5,0.25,2.40767140983455E-7,-2.28854353569716E-5,7.69769576706893E-8,9.999651,9.999651,38753.65625,38773.70703125,57.2152076076984,20.5306588359727,12.658426,0,0,0,40,4449,9.9899,38763.681640625,,,,,,,,,,,,,0,,,,0.0049,,,,,,9.999651,,,,
,33052019.925,9.9980917,43625.982421875,-3.61440412919343E-5,7.5430897747042E-7,1,0.999253354069792,40.0298881530762,1.99417162426646,20.1999992132187,-0.000410062847818876,-5.62647564355753E-5,0.25,1.51178415906852E-6,-3.60922055640005E-5,1.24693457235156E-6,9.9980917,9.9980917,43620.91796875,43631.046875,56.5523866233906,20.5359890514283,12.278775,0,0,0,40,4449,9.9893,43625.982421875,,,,,,,,,,,,,0,,,,0,,,,,,9.9980917,,,,
,33052117.595,9.9983387,48509.203125,-4.50662565617866E-5,5.89077487385946E-7,1,0.999253354069792,40.0298881530762,1.99388263820185,20.1999992132187,-0.00050877032231332,-8.52109754357585E-5,0.25,5.54849189421052E-7,-4.5014843614623E-5,2.22801799044058E-7,9.9983387,9.9983387,48499.3515625,48519.0546875,56.9650864815445,20.5375305382322,12.278775,0,0,0,40,4449,9.9933,48509.203125,,,,,,,,,,,,,0,,,,0.00245,,,,,,9.9983387,,,,
,33052213.565,9.9965754,53304.279296875,-6.63781097707759E-5,1.00845128425582E-6,1,0.999253354069792,40.0298881530762,1.99304880580749,20.1999992132187,-0.000753374726841029,-0.000103645143495216,0.25,2.76262683488905E-6,-6.63489762699844E-5,2.26850489606804E-6,9.9965754,9.9965754,53296.76953125,53311.7890625,57.1362631272561,20.5500684187531,13.038077,0,0,0,40,4449,9.99625,53304.279296875,,,,,,,,,,,,,0,,,,-0.00245,,,,,,9.9965754,,,,
,33052310.52,9.9964533,58152.00390625,-8.07557734390325E-5,8.46736828255626E-7,1,0.999253354069792,40.0298881530762,1.99325501497927,20.1999992132187,-0.000917708476649122,-0.000122694923871215,0.25,3.67104637494516E-6,-8.07608841602523E-5,3.0691438361753E-6,9.9964533,9.9964533,58144.51953125,58159.48828125,57.3215090863138,20.5458482904625,13.038077,0,0,0,40,4449,10.00065,58152.00390625,,,,,,,,,,,,,0,,,,0,,,,,,9.9964533,,,,
,33052407.97,9.996068,63022.595703125,-9.14015924219014E-5,1.01524019909678E-6,1,0.999253354069792,40.0298881530762,1.99193959125962,20.2099997550249,-0.0010374787835943,-0.000144540575039711,0.25,3.64916232377545E-6,-9.1445202385132E-5,2.96985077462335E-6,9.996068,9.996068,63012.671875,63032.51953125,57.0487207331022,20.5651974135741,12.658426,0,0,0,40,4449,10.0042,63022.595703125,,,,,,,,,,,,,0,,,,0,,,,,,9.996068,,,,
,33052507.595,9.9956579,68002.87109375,-0.000110417421769721,1.04006706079562E-6,1,0.999253354069792,40.0298881530762,1.99263357929419,20.1999992132187,-0.00124651033094982,-0.000217936357299327,0.25,5.75511440411628E-7,-0.000110490503963365,-2.42441532613131E-7,9.9956579,9.9956579,67995.3046875,68010.4375,57.0127658212176,20.5547108808213,12.658426,0,0,0,40,4449,10.00755,68002.87109375,,,,,,,,,,,,,0,,,,0.00245,,,,,,9.9956579,,,,
,33052608.935,9.9952507,73067.859375,-0.000124340956095275,1.11575033955921E-6,1,0.999253354069792,40.0298881530762,1.99185228529284,20.1999992132187,-0.00140045869120997,-0.000263787079316311,0.25,-9.86307803581795E-7,-0.000124464223184602,-1.90231797388954E-6,9.9952507,9.9952507,73062.8671875,73072.8515625,57.3871658819292,20.5624863508781,12.658426,0,0,0,40,4449,10.01065,73067.859375,,,,,,,,,,,,,0,,,,0.00245,,,,,,9.9952507,,,,
,33052707.515,9.99607325,77993.6640625,-0.000138009422416827,1.19934571197968E-6,1,0.999253354069792,40.0298881530762,1.99159828473721,20.1999992132187,-0.0015564150664026,-0.000284033804892242,0.25,-3.22234436071948E-7,-0.000138205894503495,-1.32854982354766E-6,9.9959993,9.9961472,77985.8515625,78001.4765625,57.1581487257945,20.5689106611384,12.658426,0,0,0,40,4449,10.01545,77993.6640625,,,,,,,,,,,,,0,,,,0.00245,,,,,,9.99607325,,,,
,33052808.34,9.9949121,83034.5,-0.000156930748997364,1.40974622179089E-6,1,0.999253354069792,40.0298881530762,1.9923269424716,20.1999992132187,-0.0017719949595742,-0.000318146948836762,0.25,6.7699345501962E-8,-0.000157216273942815,-1.06209156970425E-6,9.9949121,9.9949121,83024.4921875,83044.5078125,57.3910740245253,20.5588651763303,11.899124,0,0,0,40,4449,10.0199,83034.5,,,,,,,,,,,,,0,,,,-0.00245,,,,,,9.9949121,,,,
,33052902.855,9.9965897,87757.89453125,-0.000168228462204277,1.30290728880179E-6,1,0.999253354069792,40.0298881530762,1.99283160505357,20.1999992132187,-0.00190902442283171,-0.000294680226266005,0.25,4.17806048554675E-6,-0.000168619237382504,2.99171331328961E-6,9.9965897,9.9965897,87747.90625,87767.8828125,56.4070037188137,20.5560424115729,12.278775,0,0,0,40,4449,10.02535,87757.89453125,,,,,,,,,,,,,0,,,,0.0049,,,,,,9.9965897,,,,
,33053017.49,9.99802395,87655.53125,-0.000170747230258671,1.43615703418453E-6,1,0.999253354069792,40.0298881530762,1.99252445438851,20.1999992132187,-0.00193664302370097,-0.000302745811993408,0.25,3.91346635373361E-6,-0.000171140356071473,2.7082585029378E-6,9.9978437,9.9982042,87647.9921875,87663.0703125,56.4070037188137,20.5597956951966,12.278775,0,0,0,40,4449,10.02765,87655.53125,,,,,,,,,,,,,0,,,,0.00245,,,,,,9.99802395,,,,
,33053111.49,9.9999075,82954.5703125,-0.000154853740879835,1.32337050199904E-6,1,0.999253354069792,40.0298881530762,1.99195743601957,20.1999992132187,-0.00175007578099833,-0.000303582733404203,0.25,9.79119093425122E-7,-0.000155141162824031,-1.34301262156787E-7,9.9999075,9.9999075,82949.6171875,82959.5234375,56.963523224506,20.5673853304985,12.278775,0,0,0,40,4449,10.0267,82954.5703125,,,,,,,,,,,,,0,,,,0,,,,,,9.9999075,,,,
,33053211.695,10.0011196,77945.75390625,-0.00013936813985101,1.02138815445279E-6,1,0.999253354069792,40.0298881530762,1.99172544829348,20.1999992132187,-0.00157401671151554,-0.000274693448164283,0.25,7.51822835595909E-7,-0.000139573882805318,-2.62957279420861E-7,10.0011196,10.0011196,77940.7421875,77950.765625,57.1909771236022,20.5742464176186,12.658426,0,0,0,40,4449,10.024,77945.75390625,,,,,,,,,,,,,0,,,,-0.0049,,,,,,10.0011196,,,,
,33053311.735,10.0036707,72944.73046875,-0.000125294818691111,1.10924240700876E-6,1,0.999253354069792,40.0298881530762,1.99258226141103,20.1999992132187,-0.00141455817944103,-0.000249934157339852,0.25,4.21450767098455E-7,-0.000125428183041196,-5.00296510755052E-7,10.0036707,10.0036707,72937.1953125,72952.265625,57.3152560581599,20.5606842323577,11.899124,0,0,0,40,4449,10.02225,72944.73046875,,,,,,,,,,,,,0,,,,0.00245,,,,,,10.0036707,,,,
,33053412.345,10.0039425,67914.1015625,-0.000106824250251649,9.35534999659409E-7,1,0.999253354069792,40.0298881530762,1.9928837412616,20.1999992132187,-0.0012027134319643,-0.000229560074401874,0.25,-1.10027196653742E-6,-0.000106881849536245,-1.89270831266973E-6,10.0039425,10.0039425,67904.3828125,67923.8203125,57.0463758475445,20.5618055020271,12.278775,0,0,0,40,4449,10.01885,67914.1015625,,,,,,,,,,,,,0,,,,-0.00245,,,,,,10.0039425,,,,
,33053514.19,10.0028486,62823.474609375,-9.61322165987927E-5,1.01366915832405E-6,1,0.999253354069792,40.0298881530762,1.99305340111161,20.1999992132187,-0.00108587046603636,-0.000184650910768591,0.25,9.51214420885488E-7,-9.61548581677676E-5,2.36149665023074E-7,10.0028486,10.0028486,62810.91015625,62836.0390625,57.3957637956407,20.5614400109259,12.278775,0,0,0,40,4449,10.01595,62823.474609375,,,,,,,,,,,,,0,,,,0,,,,,,10.0028486,,,,
,33053614.33,10.0034585,57819.826171875,-7.8388428710336E-5,7.1075578899111E-7,1,0.999253354069792,40.0298881530762,1.99299652777527,20.1999992132187,-0.000876435035102236,-0.000198038076014368,0.25,-3.44277094493109E-6,-7.83387687541959E-5,-4.02491967463508E-6,10.003232,10.003685,57817.203125,57822.44921875,57.5348936720638,20.5602817558018,12.278775,0,0,0,40,4449,10.0122,57819.826171875,,,,,,,,,,,,,0,,,,0,,,,,,10.0034585,,,,
,33053714.835,10.0034161,52797.302734375,-6.4308448242493E-5,9.74785682313001E-7,1,0.999253354069792,40.0298881530762,1.99304364101345,20.1999992132187,-0.000722114836158053,-0.000143305085788858,0.25,-1.13189277578363E-6,-6.42487529927756E-5,-1.60739788377686E-6,10.0034161,10.0034161,52789.71484375,52804.890625,57.4285921934484,20.5613164980231,11.899124,0,0,0,40,4449,10.0079,52797.302734375,,,,,,,,,,,,,0,,,,0,,,,,,10.0034161,,,,
,33053816.695,10.0036526,47705.23828125,-4.79412879574516E-5,5.95527112771961E-7,1,0.999253354069792,40.0298881530762,1.99325436203347,20.1999992132187,-0.000536596777504267,-0.000115164735252635,0.25,-1.59085350057336E-6,-4.78666225688379E-5,-1.94062055403302E-6,10.0036526,10.0036526,47697.68359375,47712.79296875,57.2081729510253,20.5627024027265,12.278775,0,0,0,40,4449,10.00365,47705.23828125,,,,,,,,,,,,,0,,,,-0.00245,,,,,,10.0036526,,,,
,33053917.69,10.0028725,42654.625,-3.1996221612035E-5,6.62593333858553E-7,1,0.999253354069792,40.0298881530762,1.99336212824346,20.1999992132187,-0.000358366716783455,-7.45548156523537E-5,0.25,-8.63382613027948E-7,-3.19311207257275E-5,-1.0931521059214E-6,10.0028725,10.0028725,42644.58984375,42664.66015625,57.312129544083,20.5621698659157,12.278775,0,0,0,40,4449,10.00165,42654.625,,,,,,,,,,,,,0,,,,0.0049,,,,,,10.0028725,,,,
,33054016.96,10.00182295,37694.763671875,-1.91473870270208E-5,6.67073967296524E-7,1,0.999253354069792,40.0298881530762,1.99339910964434,20.1999992132187,-0.00021378427001625,-4.7726084864839E-5,0.25,-7.97957286884305E-7,-1.90964728448064E-5,-9.31674024279917E-7,10.0015812,10.0020647,37687.43359375,37702.09375,57.4582940771792,20.5652861577407,12.278775,0,0,0,40,4449,9.99815,37694.763671875,,,,,,,,,,,,,0,,,,-0.00245,,,,,,10.00182295,,,,
,33054113.665,10.0029373,32862.2421875,-5.75855861613959E-6,6.49696585465763E-7,1,0.999253354069792,40.0298881530762,1.99312666953506,20.1999992132187,-6.30975333820898E-5,-2.07819408885607E-5,0.25,-8.13644394858277E-7,-5.73638276846003E-6,-8.51009617203262E-7,10.0029373,10.0029373,32859.7578125,32864.7265625,57.2183341217753,20.5676883156301,12.278775,0,0,0,40,4449,9.9967,32862.2421875,,,,,,,,,,,,,0,,,,-0.0049,,,,,,10.0029373,,,,
,33054211.26,10.0027676,27984.7568359375,8.5425090699058E-6,4.69189942934411E-7,1,0.999253354069792,40.0298881530762,1.99314790153034,20.1999992132187,9.96930696991059E-5,-3.37285635557196E-6,0.25,-1.83327138246707E-6,8.52577378220505E-6,-1.77013301155038E-6,10.0027676,10.0027676,27977.3359375,27992.177734375,57.5020652742561,20.5681638733347,12.278775,0,0,0,40,4449,9.9958,27984.7568359375,,,,,,,,,,,,,0,,,,0,,,,,,10.0027676,,,,
,33054311.625,10.0024233,22967.4501953125,2.353808172803E-5,4.76572779654017E-7,1,0.999253354069792,40.0298881530762,1.99334321799329,20.1999992132187,0.000270666954168143,1.24495884835089E-5,0.25,-3.10932655594555E-6,2.3466068503925E-5,-2.94696080384908E-6,10.0024233,10.0024233,22964.986328125,22969.9140625,57.1096877576022,20.5667105149195,12.658426,0,0,0,40,4449,9.9958,22967.4501953125,,,,,,,,,,,,,0,,,,0.00245,,,,,,10.0024233,,,,
,33054409.725,10.0006857,18064.7216796875,3.78186175633487E-5,4.24769556377702E-7,1,0.999253354069792,40.0298881530762,1.99339918710985,20.1999992132187,0.000427455674908562,6.02948878456924E-5,0.25,-1.39457142595419E-6,3.76613725671714E-5,-1.15892943605878E-6,10.0006857,10.0006857,18062.251953125,18067.19140625,57.5372385576215,20.5665698549125,12.278775,0,0,0,40,4449,9.99335,18064.7216796875,,,,,,,,,,,,,0,,,,0.00245,,,,,,10.0006857,,,,
,33054506.335,10.00048735,13234.7373046875,5.06294356007089E-5,4.23899493079321E-7,1,0.999253354069792,40.0298881530762,1.99357072816762,20.1999992132187,0.000571600477421634,8.31464137941457E-5,0.25,-1.63097678930026E-6,5.03946353688675E-5,-1.33295282556972E-6,10.0004778,10.0004969,13229.7490234375,13239.7255859375,56.7251265261406,20.564758453944,12.658426,0,0,0,40,4449,9.9943,13234.7373046875,,,,,,,,,,,,,0,,,,-0.00245,,,,,,10.00048735,,,,
,33054602.68,9.999855,8419.32666015625,6.09745347717844E-5,3.56377336520894E-7,1,0.999253354069792,40.0298881530762,1.9930537308288,20.1999992132187,0.000684339071549603,0.000120289174643002,0.25,-1.40357861542568E-7,6.06570331331984E-5,1.88239644633459E-7,9.999855,9.999855,8411.962890625,8426.6904296875,57.0596635323714,20.5736783631639,12.658426,0,0,0,40,4449,9.9958,8419.32666015625,,,,,,,,,,,,,0,,,,0,,,,,,9.999855,,,,
,33054695.625,9.9987516,3773.54431152344,7.04208877924197E-5,3.77545880910607E-7,1,0.999253354069792,40.0298881530762,1.99323546636962,20.1999992132187,0.000789266959225875,0.000143937730834383,0.25,3.11494871521816E-7,7.00285918059033E-5,6.64805889657904E-7,9.9987516,9.9987516,3768.70385742188,3778.384765625,57.129228470583,20.5714576732701,12.278775,0,0,0,40,4449,9.9965,3773.54431152344,,,,,,,,,,,,,0,,,,-0.0049,,,,,,9.9987516,,,,
,33054791.63,9.9998093,-1021.11853027344,7.37454849922809E-5,3.34407604906258E-7,1,0.999253354069792,40.0298881530762,1.99298989295197,20.1999992132187,0.000826914749384718,0.000147240982907236,0.25,3.1373749413627E-8,7.33246730054786E-5,3.90117706483877E-7,9.9998093,9.9998093,-1028.35095214844,-1013.88610839844,57.1565854687561,20.5756447804844,12.658426,0,0,0,40,4449,9.9929,-1021.11853027344,,,,,,,,,,,,,0,,,,0,,,,,,9.9998093,,,,
,33054889.425,9.9979277,-5909.04809570312,7.91513023989732E-5,4.02334239686263E-7,1,0.999253354069792,40.0298881530762,1.99281562311297,20.1999992132187,0.000886896279709945,0.0001627246839544,0.25,4.22971617579771E-7,7.87212756523842E-5,8.3171232776014E-7,9.9979277,9.9979277,-5924.11572265625,-5893.98046875,57.4778347901599,20.5795685146718,11.899124,0,0,0,40,4449,9.9954,-5909.04809570312,,,,,,,,,,,,,0,,,,0,,,,,,9.9979277,,,,
,33054985.69,10.0008698,-10722.5693359375,8.47092432761223E-5,3.82327096225044E-7,1,0.999253354069792,40.0298881530762,1.9925840450777,20.1999992132187,0.000948298208222987,0.000180492787404708,0.25,9.83928525223274E-7,8.4277230671187E-5,1.44888651974245E-6,10.0008698,10.0008698,-10727.482421875,-10717.65625,57.6146197810253,20.5838427637006,12.278775,0,0,0,40,4449,9.9963,-10722.5693359375,,,,,,,,,,,,,0,,,,-0.00245,,,,,,10.0008698,,,,
,33055083.94,10.00103665,-15632.5625,8.19295469564437E-5,4.36924100552105E-7,1,0.999253354069792,40.0298881530762,1.99322803525632,20.1999992132187,0.000920219774680073,0.000161467360380282,0.25,-2.56017729439811E-7,8.15535209090183E-5,2.28709784799241E-7,10.0005808,10.0014925,-15645.1220703125,-15620.0029296875,57.6036769817561,20.5705276619248,11.899124,0,0,0,40,4449,9.99465,-15632.5625,,,,,,,,,,,,,0,,,,-0.00735,,,,,,10.00103665,,,,
,33055181.305,10.00082445,-20500.0546875,6.77327907502858E-5,4.39733147228526E-7,1,0.999253354069792,40.0298881530762,1.99341628309352,20.1999992132187,0.00076174104106425,0.00013046963886148,0.25,-5.09111919282275E-7,6.7455069681582E-5,-8.50785288388103E-8,10.0006828,10.0009661,-20502.630859375,-20497.478515625,57.3699700545061,20.5635291800888,12.278775,0,0,0,40,4449,9.9942,-20500.0546875,,,,,,,,,,,,,0,,,,0.0049,,,,,,10.00082445,,,,
,33055278.225,9.9988728,-25342.2109375,4.70033614725783E-5,5.31320684953198E-7,1,0.999253354069792,40.0298881530762,1.99377443658572,20.1999992132187,0.000526787432021158,0.000102730567132375,0.25,7.12526151879863E-7,4.68265959907156E-5,1.01642092185986E-6,9.9988728,9.9988728,-25354.599609375,-25329.822265625,57.0878021590637,20.5624853535448,12.278775,0,0,0,40,4449,9.99375,-25342.2109375,,,,,,,,,,,,,0,,,,0,,,,,,9.9988728,,,,
,33055375.08,9.9979343,-30182.37109375,3.18430099520673E-5,5.10903523732761E-7,1,0.999253354069792,40.0298881530762,1.99399535041732,20.1999992132187,0.000358758314863396,6.03800599370731E-5,0.25,-3.48625695997589E-7,3.17447674573017E-5,-1.31843368069076E-7,9.9979343,9.9979343,-30192.474609375,-30172.267578125,57.2058280654676,20.5621254244585,11.899124,0,0,0,40,4449,9.9956,-30182.37109375,,,,,,,,,,,,,0,,,,-0.00245,,,,,,9.9979343,,,,
,33055471.415,10.0019274,-34999.697265625,2.73774617498864E-5,5.8605498291478E-7,1,0.999253354069792,40.0298881530762,1.99398575091825,20.1999992132187,0.00031004086689975,4.39510538688643E-5,0.25,-1.01546472240941E-6,2.7311999871285E-5,-8.21597160150882E-7,10.0019274,10.0019274,-35004.8359375,-34994.55859375,56.5734905934098,20.5596734748228,11.519473,0,0,0,40,4449,9.9969,-34999.697265625,,,,,,,,,,,,,0,,,,-0.0049,,,,,,10.0019274,,,,
,33055569.9,9.9992456,-39919.712890625,3.13792547337542E-5,5.08804341768671E-7,1,0.999253354069792,40.0298881530762,1.99409758757145,20.1999992132187,0.000352875679575375,6.53623326172131E-5,0.25,1.59696132276987E-7,3.13113355682783E-5,3.83846542756692E-7,9.9992456,9.9992456,-39927.328125,-39912.09765625,57.4020168237945,20.5602040492952,12.278775,0,0,0,40,4449,9.99755,-39919.712890625,,,,,,,,,,,,,0,,,,0,,,,,,9.9992456,,,,
,33055668.06,9.9976645,-44827.27734375,4.03902050453522E-5,7.32378447616971E-7,1,0.999253354069792,40.0298881530762,1.99417463791396,20.1999992132187,0.000458522111072209,6.16244894126943E-5,0.25,-1.80220101573471E-6,4.03382194684226E-5,-1.5051493041348E-6,9.9976645,9.9976645,-44840.01953125,-44814.53515625,56.8814522299868,20.5594450337326,11.899124,0,0,0,40,4449,10.0012,-44827.27734375,,,,,,,,,,,,,0,,,,-0.00245,,,,,,9.9976645,,,,
,33055769.75,9.9963274,-49909.943359375,5.32150137593489E-5,6.58621314000608E-7,1,0.999253354069792,40.0298881530762,1.9941469601334,20.1999992132187,0.0006051288783771,7.73264024356443E-5,0.25,-2.72587547529563E-6,5.31771914337983E-5,-2.3305046866983E-6,9.9963274,9.9963274,-49917.59375,-49902.29296875,56.6727574153522,20.5550518395117,12.278775,0,0,0,40,4449,10.003,-49909.943359375,,,,,,,,,,,,,0,,,,0.00245,,,,,,9.9963274,,,,
,33055872.19,9.99623205,-55029.017578125,6.80044398091756E-5,6.3604131581417E-7,1,0.999253354069792,40.0298881530762,1.9943405911323,20.1999992132187,0.000771595769931158,0.000110967402967218,0.25,-2.41435567429103E-6,6.79831147210124E-5,-1.90792854775197E-6,9.9960556,9.9964085,-55038.87109375,-55019.1640625,56.973684395256,20.5561334045703,12.658426,0,0,0,40,4449,10.00645,-55029.017578125,,,,,,,,,,,,,0,,,,0.00245,,,,,,9.99623205,,,,
,33055974.11,9.9962711,-60121.296875,8.26800094545717E-5,8.49100061634609E-7,1,0.999253354069792,40.0298881530762,1.99329651653349,20.1999992132187,0.000941794935096337,0.000114407784561466,0.25,-4.75532078740873E-6,8.27080906165134E-5,-4.1394619980087E-6,9.9962711,9.9962711,-60131.23828125,-60111.35546875,57.5771016121022,20.574329126173,11.519473,0,0,0,40,4449,10.01,-60121.296875,,,,,,,,,,,,,0,,,,-0.0049,,,,,,9.9962711,,,,
,33056074.625,9.9959002,-65146.173828125,9.85730210895224E-5,6.93273417970777E-7,1,0.999253354069792,40.0298881530762,1.99359105497149,20.1999992132187,0.00111529762210676,0.000182012564833642,0.25,-1.63159285606267E-6,9.86218026201078E-5,-8.99765342067716E-7,9.9959002,9.9959002,-65153.51171875,-65138.8359375,57.0838940164676,20.5678271535187,11.899124,0,0,0,40,4449,10.01335,-65146.173828125,,,,,,,,,,,,,0,,,,0,,,,,,9.9959002,,,,
,33056173.68,9.9959335,-70095.9609375,0.000115608783148472,1.04792838666995E-6,1,0.999253354069792,40.0298881530762,1.99376289595788,20.1999992132187,0.0013092088249641,0.000210848401629786,0.25,-2.15061020695651E-6,0.000115717455254836,-1.2977487593485E-6,9.9959335,9.9959335,-70101.2109375,-70090.7109375,57.1323549846599,20.5662339377927,11.899124,0,0,0,40,4449,10.019,-70095.9609375,,,,,,,,,,,,,0,,,,0.00245,,,,,,9.9959335,,,,
,33056271.12,9.9964933,-74965.203125,0.000133557953473039,9.69655605723464E-7,1,0.999253354069792,40.0298881530762,1.9937388360467,20.1999992132187,0.00151086864241034,0.000255840430509173,0.25,-1.39919613545226E-6,0.000133728897514041,-4.21422580598049E-7,9.9964933,9.9964933,-74972.4921875,-74957.9140625,57.3637170263522,20.571694760077,11.519473,0,0,0,40,4449,10.0217,-74965.203125,,,,,,,,,,,,,0,,,,-0.0049,,,,,,9.9964933,,,,
,33056363.555,9.9956198,-79584.87109375,0.000146221522345844,1.3068388608157E-6,1,0.999253354069792,40.0298881530762,1.99400931265377,20.1999992132187,0.00165133180250318,0.000300216602379165,0.25,2.47766869791864E-7,0.000146448101878083,1.31002306196513E-6,9.9956198,9.9956198,-79589.9296875,-79579.8125,57.3621537693137,20.5643748735682,11.899124,0,0,0,40,4449,10.0262,-79584.87109375,,,,,,,,,,,,,0,,,,0.00245,,,,,,9.9956198,,,,
,33056456.52,9.9951677,-84232.3828125,0.000164393627982184,1.30879879362877E-6,1,0.999253354069792,40.0298881530762,1.99392622405058,20.1999992132187,0.00185386401447139,0.000355674101804894,0.25,1.8898651588632E-6,0.000164692745510914,3.073321684395E-6,9.9951677,9.9951677,-84237.5859375,-84227.1796875,57.2027015513907,20.5664560170371,11.519473,0,0,0,40,4449,10.0306,-84232.3828125,,,,,,,,,,,,,0,,,,-0.00245,,,,,,9.9951677,,,,
,33056541.72,9.9953136,-88489.8671875,0.000174174621695913,1.30913726822713E-6,1,0.999253354069792,40.0298881530762,1.99396476723942,20.1999992132187,0.00196841360652469,0.000356734827168463,0.25,2.29242710699676E-7,0.000174555434027495,1.46459683512093E-6,9.9953136,9.9953136,-88494.8359375,-88484.8984375,57.3144744296407,20.562250202717,12.278775,0,0,0,40,4449,10.0337,-88489.8671875,,,,,,,,,,,,,0,,,,0,,,,,,9.9953136,,,,
,33056645.24,9.9981623,-87273.5,0.000171305352160389,9.52248410620392E-7,1,0.999253354069792,40.0298881530762,1.99399678660838,20.1999992132187,0.00193873897095553,0.0003348208705504,0.25,-1.19579232887011E-6,0.000171675918857511,2.06027201279465E-8,9.9981623,9.9981623,-87278.2734375,-87268.7265625,56.8040710065829,20.5649855117732,11.519473,0,0,0,40,4449,10.03615,-87273.5,,,,,,,,,,,,,0,,,,-0.0049,,,,,,9.9981623,,,,
,33056732.375,10.0000701,-82916.1640625,0.000156605322220967,1.11022591984808E-6,1,0.999253354069792,40.0298881530762,1.99431312757123,20.1999992132187,0.00176264609078522,0.000358578499442584,0.25,3.54155219590417E-6,0.000156862922570057,4.67587526062175E-6,9.9998608,10.0002794,-82921.1953125,-82911.1328125,57.7107600888907,20.5584282512484,11.899124,0,0,0,40,4449,10.0338,-82916.1640625,,,,,,,,,,,,,0,,,,0,,,,,,10.0000701,,,,
,33056829.37,10.0025444,-78071.3125,0.000141313177052449,1.1537058606072E-6,1,0.999253354069792,40.0298881530762,1.99430869025357,20.1999992132187,0.0015993834743293,0.000271054966872167,0.25,-1.45420835067623E-6,0.000141528196684619,-4.26557724018856E-7,10.0025444,10.0025444,-78073.828125,-78068.796875,57.047939104583,20.5580883380731,12.278775,0,0,0,40,4449,10.0307,-78071.3125,,,,,,,,,,,,,0,,,,-0.00245,,,,,,10.0025444,,,,
,33056926.93,10.0037041,-73193.76953125,0.00012283926250768,1.18247095071945E-6,1,0.999253354069792,40.0298881530762,1.99435122984334,20.1999992132187,0.0013842364335115,0.00026635500627364,0.25,1.45622855344844E-6,0.000122958759440297,2.36150306319939E-6,10.0037041,10.0037041,-73206.0625,-73181.4765625,57.3801312252561,20.555826762486,11.899124,0,0,0,40,4449,10.02775,-73193.76953125,,,,,,,,,,,,,0,,,,-0.0049,,,,,,10.0037041,,,,
,33057027.67,10.0036945,-68161.9921875,0.000107161941907729,1.04497199676985E-6,1,0.999253354069792,40.0298881530762,1.99414988698661,20.1999992132187,0.00120859859528209,0.000223075187611957,0.25,4.52323130391967E-7,0.000107226853050816,1.24665641849656E-6,10.0036945,10.0036945,-68169.453125,-68154.53125,57.1565854687561,20.5523591354999,11.899124,0,0,0,40,4449,10.02425,-68161.9921875,,,,,,,,,,,,,0,,,,0.00245,,,,,,10.0036945,,,,
,33057128.225,10.003871,-63134.609375,9.31960662453699E-5,8.79522948436001E-7,1,0.999253354069792,40.0298881530762,1.99420936919357,20.1999992132187,0.00104856720885253,0.000205470772904524,0.25,1.41399591880422E-6,9.32032845120474E-5,2.10755060090583E-6,10.003871,10.003871,-63142.171875,-63127.046875,57.0385595623522,20.5550342324418,11.899124,0,0,0,40,4449,10.0201,-63134.609375,,,,,,,,,,,,,0,,,,0,,,,,,10.003871,,,,
,33057228.87,10.0042653,-58104.529296875,7.85312078252157E-5,7.67034295261575E-7,1,0.999253354069792,40.0298881530762,1.99420542980671,20.1999992132187,0.000880918798765034,0.000185453654883466,0.25,2.29037493491356E-6,7.84922151805056E-5,2.87406534687677E-6,10.0041628,10.0043678,-58114.46484375,-58094.59375,57.2269320354868,20.5531910393016,11.899124,0,0,0,40,4449,10.0172,-58104.529296875,,,,,,,,,,,,,0,,,,-0.00245,,,,,,10.0042653,,,,
,33057330.88,10.004508,-53004.9140625,6.20007830134532E-5,8.60803446686126E-7,1,0.999253354069792,40.0298881530762,1.99417900880833,20.1999992132187,0.00069669253981268,0.000137700768888997,0.25,1.04325928267673E-6,6.1944865376977E-5,1.5018848596955E-6,10.004508,10.004508,-53012.359375,-52997.46875,56.9033378285253,20.5570878911098,11.899124,0,0,0,40,4449,10.01285,-53004.9140625,,,,,,,,,,,,,0,,,,0,,,,,,10.004508,,,,
,33057433.88,10.0041895,-47860.78515625,4.62109941086144E-5,6.19531059483949E-7,1,0.999253354069792,40.0298881530762,1.99409431831681,20.1999992132187,0.000521953994037854,8.60336088522618E-5,0.25,-6.87850607166832E-7,4.61560672405921E-5,-3.47675580619226E-7,10.0041895,10.0041895,-47870.87890625,-47850.69140625,57.1769078102561,20.5543642863313,11.899124,0,0,0,40,4449,10.0086,-47860.78515625,,,,,,,,,,,,,0,,,,0,,,,,,10.0041895,,,,
,33057534.92,10.0035429,-42808.189453125,3.17499957616158E-5,7.68847188026935E-7,1,0.999253354069792,40.0298881530762,1.99398137370481,20.1999992132187,0.000356951780525512,6.71634323345664E-5,0.25,2.49005731124466E-7,3.16903015497607E-5,4.78253613792266E-7,10.0035429,10.0035429,-42823.28125,-42793.09765625,57.1550222117176,20.5543629883794,11.899124,0,0,0,40,4449,10.0066,-42808.189453125,,,,,,,,,,,,,0,,,,0.00245,,,,,,10.0035429,,,,
,33057636.08,10.0011244,-37753.427734375,1.68599614401603E-5,4.79371584289771E-7,1,0.999253354069792,40.0298881530762,1.99429635742517,20.1999992132187,0.000190776480696964,2.84256241255233E-5,0.25,-5.07346485768708E-7,1.68238048300962E-5,-3.86713043956835E-7,10.0011244,10.0011244,-37760.80859375,-37746.046875,56.3804283491598,20.5532613181392,11.899124,0,0,0,40,4449,10.0034,-37753.427734375,,,,,,,,,,,,,0,,,,0,,,,,,10.0011244,,,,
,33057736.81,10.0024986,-32719.0048828125,3.62197365670247E-6,5.1551938766343E-7,1,0.999253354069792,40.0298881530762,1.99408591932484,20.1999992132187,4.10241347053681E-5,5.73220476768398E-6,0.25,-1.41232342323045E-7,3.61247233588715E-6,-1.15872447277073E-7,10.0024986,10.0024986,-32723.927734375,-32714.08203125,57.0033862789868,20.5540523852425,11.519473,0,0,0,40,4449,10.00095,-32719.0048828125,,,,,,,,,,,,,0,,,,0.00245,,,,,,10.0024986,,,,
,33057838.085,10.0020647,-27657.017578125,-1.1312515965081E-5,5.44646134836445E-7,1,0.999253354069792,40.0298881530762,1.99407518922095,20.1999992132187,-0.000126627040465764,-2.5881015888291E-5,0.25,-2.72096820674586E-7,-1.12719824616982E-5,-3.46356168837205E-7,10.0020647,10.0020647,-27662.251953125,-27651.783203125,57.5098815594484,20.5573176577717,11.899124,0,0,0,40,4449,9.9993,-27657.017578125,,,,,,,,,,,,,0,,,,0,,,,,,10.0020647,,,,
,33057938.265,9.9996452,-22649.4931640625,-2.47183814997667E-5,4.85187465102967E-7,1,0.999253354069792,40.0298881530762,1.99351243690448,20.1999992132187,-0.000276021696462606,-5.90151098548516E-5,0.25,-8.24736010514246E-7,-2.46158816235624E-5,-9.78780690426639E-7,9.9996452,9.9996452,-22659.642578125,-22639.34375,57.3738781971022,20.5723473723475,11.899124,0,0,0,40,4449,9.99975,-22649.4931640625,,,,,,,,,,,,,0,,,,-0.00245,,,,,,9.9996452,,,,
,33058039.055,10.00105195,-17614.4697265625,-3.87820596352687E-5,3.61145810495763E-7,1,0.999253354069792,40.0298881530762,1.99371520881143,20.1999992132187,-0.00043352407741682,-8.90601712511754E-5,0.25,-9.9517537202889E-7,-3.86044694125452E-5,-1.22497100243462E-6,10.000845,10.0012589,-17622.056640625,-17606.8828125,57.1456426694868,20.5603961079867,12.278775,0,0,0,40,4449,9.99885,-17614.4697265625,,,,,,,,,,,,,0,,,,0.00245,,,,,,10.00105195,,,,
,33058134.625,10.0010548,-12836.7919921875,-5.11666217058509E-5,3.94612058330342E-7,1,0.999253354069792,40.0298881530762,1.99373135319505,20.1999992132187,-0.000571636699813068,-0.000117941518280529,0.25,-1.37384779745279E-6,-5.09102803395898E-5,-1.6589372063899E-6,10.0010548,10.0010548,-12844.3203125,-12829.263671875,56.9611783389483,20.5569309475945,11.899124,0,0,0,40,4449,10.0002,-12836.7919921875,,,,,,,,,,,,,0,,,,0,,,,,,10.0010548,,,,
,33058224.625,9.9993887,-8336.0439453125,-6.17113016333496E-5,2.88030064460004E-7,1,0.999253354069792,40.0298881530762,1.9937300137652,20.1999992132187,-0.00068978942313134,-0.000138837901083368,0.25,-1.37820668020449E-6,-6.13814011239877E-5,-1.70245092576671E-6,9.9993887,9.9993887,-8345.947265625,-8326.140625,57.0604451608906,20.555159891941,11.899124,0,0,0,40,4449,9.99975,-8336.0439453125,,,,,,,,,,,,,0,,,,-0.0049,,,,,,9.9993887,,,,
,33058315.165,9.9999647,-3812.93725585937,-7.07289605746841E-5,3.25112620302258E-7,1,0.999253354069792,40.0298881530762,1.99394939267625,20.1999992132187,-0.000792427013882282,-0.000147799456622347,0.25,-5.96274603807479E-7,-7.03336942959875E-5,-9.49751897491351E-7,9.9999647,9.9999647,-3823.01611328125,-3802.8583984375,57.129228470583,20.5517168927522,11.519473,0,0,0,40,4449,10.0005,-3812.93725585937,,,,,,,,,,,,,0,,,,0,,,,,,9.9999647,,,,
,33058402.48,10.0029716,553.325836181641,-7.37738132227172E-5,3.14326041150757E-7,1,0.999253354069792,40.0298881530762,1.99401400071721,20.1999992132187,-0.000826335100380354,-0.000154604791058942,0.25,-6.78346642058865E-7,-7.33481537750383E-5,-1.03171843817832E-6,10.0029716,10.0029716,550.739990234375,555.911682128906,57.4325003360445,20.5568630688456,12.278775,0,0,0,40,4449,9.99855,553.325836181641,,,,,,,,,,,,,0,,,,-0.0049,,,,,,10.0029716,,,,
,33058490.485,9.9994259,4950.50561523438,-7.73721032326836E-5,2.92502620078418E-7,1,0.999253354069792,40.0298881530762,1.99383684992716,20.1999992132187,-0.000866040243005162,-0.000166365667193565,0.25,-1.06328040267221E-6,-7.69433214545735E-5,-1.45392450618353E-6,9.9994259,9.9994259,4945.59423828125,4955.4169921875,56.6860451001791,20.5529367153159,11.899124,0,0,0,40,4449,10.0005,4950.50561523438,,,,,,,,,,,,,0,,,,-0.0049,,,,,,9.9994259,,,,
,33058581.055,9.99957655,9474.287109375,-8.27523137687412E-5,3.34121477636023E-7,1,0.999253354069792,40.0298881530762,1.9939100998875,20.1999992132187,-0.000928906958582486,-0.000165076307937542,0.25,4.15840527969299E-8,-8.23274664324735E-5,-4.10054081556621E-7,9.9992771,9.999876,9464.3466796875,9484.2275390625,57.0323065341983,20.5529889500736,11.899124,0,0,0,40,4449,10.0013,9474.287109375,,,,,,,,,,,,,0,,,,-0.0049,,,,,,9.99957655,,,,
,33058669.805,10.0003262,13911.8803710938,-8.21095599807159E-5,4.35662924111619E-7,1,0.999253354069792,40.0298881530762,1.99400807178801,20.1999992132187,-0.000920046822729801,-0.000175269869697391,0.25,-9.47963656999786E-7,-8.17130140169285E-5,-1.41802804958168E-6,10.0003262,10.0003262,13901.9287109375,13921.83203125,56.8689461736791,20.5541942287642,11.899124,0,0,0,40,4449,10.00035,13911.8803710938,,,,,,,,,,,,,0,,,,-0.00245,,,,,,10.0003262,,,,
,33058759.305,10.0002136,18385.1572265625,-7.43156650016584E-5,4.29846611397125E-7,1,0.999253354069792,40.0298881530762,1.99377540774824,20.1999992132187,-0.000832745005982173,-0.00015991325977462,0.25,-9.446879450717E-7,-7.39865462706418E-5,-1.39321722004988E-6,10.0002136,10.0002136,18370.029296875,18400.28515625,57.4199942797368,20.5512133171745,11.899124,0,0,0,40,4449,10.001,18385.1572265625,,,,,,,,,,,,,0,,,,0,,,,,,10.0002136,,,,
,33058851.11,9.9998975,22972.498046875,-5.49773743764828E-5,5.98670817419673E-7,1,0.999253354069792,40.0298881530762,1.99379762989552,20.1999992132187,-0.000617134946882956,-0.000113879432994124,0.25,-2.8453064240261E-7,-5.47610345842275E-5,-6.34329387981069E-7,9.9997387,10.0000563,22967.638671875,22977.357421875,57.1987934087945,20.5502915869563,11.899124,0,0,0,40,4449,9.9996,22972.498046875,,,,,,,,,,,,,0,,,,0,,,,,,9.9998975,,,,
,33058946.075,9.9996119,27720.6953125,-3.53293824721746E-5,5.35097375535234E-7,1,0.999253354069792,40.0298881530762,1.99386729274246,20.1999992132187,-0.000397265386591766,-7.05584044383361E-5,0.25,6.32026745667747E-8,-3.52090971196094E-5,-1.7195435771267E-7,9.9996119,9.9996119,27711.087890625,27730.302734375,56.6899532427752,20.5537282104413,11.899124,0,0,0,40,4449,10.00045,27720.6953125,,,,,,,,,,,,,0,,,,0,,,,,,9.9996119,,,,
,33059047.2,9.9996433,32775.703125,-2.72163879604182E-5,7.44084850020926E-7,1,0.999253354069792,40.0298881530762,1.99401417353455,20.1999992132187,-0.000306819540576268,-5.10688147697335E-5,0.25,3.50319260264666E-7,-2.7140259431086E-5,1.6175014060908E-7,9.9996433,9.9996433,32773.03515625,32778.37109375,57.0924919301791,20.5517543176709,11.899124,0,0,0,40,4449,10.0006,32775.703125,,,,,,,,,,,,,0,,,,0,,,,,,9.9996433,,,,
,33059147.385,9.9987535,37782.8203125,-2.98694804441667E-5,7.70665711963908E-7,1,0.999253354069792,40.0298881530762,1.99399207263457,20.1999992132187,-0.000336173198339522,-6.01493153606233E-5,0.25,2.82275905921979E-8,-2.97993505282486E-5,-1.83466626814759E-7,9.9987535,9.9987535,37775.41796875,37790.22265625,56.648526931256,20.5518753452067,11.899124,0,0,0,40,4449,10.00215,37782.8203125,,,,,,,,,,,,,0,,,,0,,,,,,9.9987535,,,,
,33059245.87,9.9975414,42705.650390625,-3.73352530950771E-5,7.35506270658329E-7,1,0.999253354069792,40.0298881530762,1.99396484749465,20.1999992132187,-0.00042001130476531,-7.74512987536485E-5,0.25,-1.57393027877549E-7,-3.72656360794267E-5,-4.27116285735253E-7,9.9975414,9.9975414,42693.0234375,42718.27734375,56.6805737005445,20.5462460212836,11.519473,0,0,0,40,4449,10.0035,42705.650390625,,,,,,,,,,,,,0,,,,-0.0049,,,,,,9.9975414,,,,
,33059344.305,9.9976625,47623.763671875,-4.93596684869167E-5,8.39662512674727E-7,1,0.999253354069792,40.0298881530762,1.9940956832662,20.1999992132187,-0.00055583536075726,-0.000101161606635496,0.25,-8.82448666577657E-8,-4.92937544556526E-5,-4.50325171489898E-7,9.9976625,9.9976625,47621.359375,47626.16796875,56.5007991411214,20.5496490183595,11.519473,0,0,0,40,4449,10.0064,47623.763671875,,,,,,,,,,,,,0,,,,-0.0049,,,,,,9.9976625,,,,
,33059445.495,9.9968777,52680.966796875,-5.9719630754539E-5,8.16921573301303E-7,1,0.999253354069792,40.0298881530762,1.99399014176621,20.1999992132187,-0.000674862923228313,-0.000111057717528724,0.25,9.08096279034553E-7,-5.96780162422026E-5,4.65016154074183E-7,9.9968777,9.9968777,52678.4296875,52683.50390625,56.760299809506,20.5477752212987,11.899124,0,0,0,40,4449,10.0095,52680.966796875,,,,,,,,,,,,,0,,,,0,,,,,,9.9968777,,,,
,33059546.175,9.9962206,57713.55078125,-7.50486896845795E-5,7.450313885584E-7,1,0.999253354069792,40.0298881530762,1.99389418511765,20.1999992132187,-0.000848656128661802,-0.00013858817977969,0.25,1.23549107449628E-6,-7.50340961671385E-5,6.76766756902355E-7,9.9962206,9.9962206,57706.01171875,57721.08984375,57.0964000727753,20.5475923998817,12.278775,0,0,0,40,4449,10.01355,57713.55078125,,,,,,,,,,,,,0,,,,0,,,,,,9.9962206,,,,
,33059647.17,9.9961166,62764.59765625,-8.8937723656701E-5,1.09564563716746E-6,1,0.999253354069792,40.0298881530762,1.99406814422799,20.1999992132187,-0.00100274673518277,-0.000183898985823493,0.25,-2.71029742705088E-7,-8.89496287756905E-5,-9.32779181783254E-7,9.9961166,9.9961166,62759.859375,62769.3359375,56.8736359447945,20.5474600399455,11.899124,0,0,0,40,4449,10.0186,62764.59765625,,,,,,,,,,,,,0,,,,0,,,,,,9.9961166,,,,
,33059744.675,9.9963732,67635.00390625,-0.000104251149780498,1.05524582050138E-6,1,0.999253354069792,40.0298881530762,1.99405669220487,20.1999992132187,-0.00117704236392322,-0.000209347051846915,0.25,2.3821618212732E-7,-0.00010431456044042,-5.34561098642545E-7,9.9963732,9.9963732,67627.515625,67642.4921875,57.2300585495638,20.5499391433848,11.899124,0,0,0,40,4449,10.0213,67635.00390625,,,,,,,,,,,,,0,,,,0,,,,,,9.9963732,,,,
,33059843.6,9.9958334,72582.52734375,-0.000120192931396516,7.80532426198926E-7,1,0.999253354069792,40.0298881530762,1.99339789098182,20.1999992132187,-0.0013578905718676,-0.000237391296591934,0.25,6.22119462674851E-7,-0.000120318900822605,-2.62419378059225E-7,9.9958334,9.9958334,72575.046875,72590.0078125,56.5844333926791,20.5628711582297,11.899124,0,0,0,40,4449,10.0244,72582.52734375,,,,,,,,,,,,,0,,,,0,,,,,,9.9958334,,,,
,33059943.795,9.9952774,77590.62890625,-0.000134858539111803,9.88013414727543E-7,1,0.999253354069792,40.0298881530762,1.99328335658067,20.1999992132187,-0.00152823591011551,-0.000243481489890049,0.25,2.7223116482018E-6,-0.000135068485224472,1.74240101505728E-6,9.9952774,9.9952774,77583.265625,77597.9921875,56.8267382336406,20.5578407358997,11.519473,0,0,0,40,4449,10.0279,77590.62890625,,,,,,,,,,,,,0,,,,0.00245,,,,,,9.9952774,,,,
,33060036.665,9.9968328,82234.30859375,-0.000145726746951397,1.0083779252366E-6,1,0.999253354069792,40.0298881530762,1.99292513458448,20.1999992132187,-0.00165535174574012,-0.000242773418119827,0.25,4.73401488177201E-6,-0.000146017136535781,3.69091364254304E-6,9.9968328,9.9968328,82226.734375,82241.8828125,56.4187281466021,20.5667143568279,11.519473,0,0,0,40,4449,10.0331,82234.30859375,,,,,,,,,,,,,0,,,,0,,,,,,9.9968328,,,,
,33060124.795,9.9957647,86637.5703125,-0.000160451583779946,1.1100466807949E-6,1,0.999253354069792,40.0298881530762,1.99319975715561,20.1999992132187,-0.00182366206871946,-0.000266053656954321,0.25,5.31924232783282E-6,-0.000160821640471374,4.18643951082698E-6,9.9957647,9.9957647,86630.140625,86645,57.0166739638137,20.5637963037543,12.278775,0,0,0,40,4449,10.03545,86637.5703125,,,,,,,,,,,,,0,,,,0,,,,,,9.9957647,,,,
,33060228.585,9.9967957,89174.48046875,-0.000169608469113834,1.12779953769126E-6,1,0.999253354069792,40.0298881530762,1.99318011291598,20.1999992132187,-0.00192138955489139,-0.000318285014390244,0.25,2.3389969461077E-6,-0.000170005172635533,1.14426624560834E-6,9.9967957,9.9967957,89166.90625,89182.0546875,57.2730481181214,20.5623300527565,11.899124,0,0,0,40,4449,10.0395,89174.48046875,,,,,,,,,,,,,0,,,,0.00245,,,,,,9.9967957,,,,
,33060312.39,10.0001984,84986.78515625,-0.000156949435085721,1.02434879041134E-6,1,0.999253354069792,40.0298881530762,1.99298604246138,20.1999992132187,-0.00178020836330643,-0.00027833256345529,0.25,3.60244021405994E-6,-0.000157282118962748,2.48538299977093E-6,10.0001984,10.0001984,84984.3125,84989.2578125,56.0873176544482,20.5665130730086,11.899124,0,0,0,40,4449,10.03775,84986.78515625,,,,,,,,,,,,,0,,,,0,,,,,,10.0001984,,,,
,33060404.87,10.0022345,80362.83203125,-0.000141214359564066,9.4457718214915E-7,1,0.999253354069792,40.0298881530762,1.99314617469149,20.1999992132187,-0.00159597630668946,-0.000280066304415769,0.25,6.23642275787576E-7,-0.000141447681586349,-3.9896413644987E-7,10.0022345,10.0022345,80355.328125,80370.3359375,56.2584943001598,20.5641490623826,11.899124,0,0,0,40,4449,10.0355,80362.83203125,,,,,,,,,,,,,0,,,,-0.00245,,,,,,10.0022345,,,,
,33060496.525,10.0031805,75778.7421875,-0.000128456142045097,1.02290749166012E-6,1,0.999253354069792,40.0298881530762,1.99328395917485,20.1999992132187,-0.00145354165955535,-0.000242643051296907,0.25,1.64419576668656E-6,-0.000128631033782344,7.05720593251912E-7,10.0031805,10.0031805,75770.984375,75786.5,56.7860935506406,20.5636532013384,11.519473,0,0,0,40,4449,10.03295,75778.7421875,,,,,,,,,,,,,0,,,,-0.00245,,,,,,10.0031805,,,,
,33060586.16,10.0038652,71300.3203125,-0.000114847967345602,8.83368232758458E-7,1,0.999253354069792,40.0298881530762,1.99309484830367,20.1999992132187,-0.0012948780541789,-0.00023955135316098,0.25,-5.35759534549656E-7,-0.000114947802116522,-1.38375050067212E-6,10.0038652,10.0038652,71297.765625,71302.875,56.2952308405636,20.5636210337127,11.899124,0,0,0,40,4449,10.0289,71300.3203125,,,,,,,,,,,,,0,,,,0.00245,,,,,,10.0038652,,,,
,33060675.1,10.0045099,66854.46484375,-0.000102494356396624,8.31197349344321E-7,1,0.999253354069792,40.0298881530762,1.99330164761566,20.1999992132187,-0.00116687114260459,-0.000149351679723371,0.25,5.23258006674275E-6,-0.000102586796788543,4.47483094838329E-6,10.0045099,10.0045099,66844.703125,66864.2265625,56.8243933480829,20.5678469113773,11.519473,0,0,0,40,4449,10.0275,66854.46484375,,,,,,,,,,,,,0,,,,0,,,,,,10.0045099,,,,
,33060767.41,10.0044937,62241.080078125,-9.01273321924938E-5,8.95610060605909E-7,1,0.999253354069792,40.0298881530762,1.99354543994372,20.1999992132187,-0.00102160560485643,-0.000154405865865056,0.25,2.55389134641254E-6,-9.01561144385285E-5,1.88349147900259E-6,10.0044937,10.0044937,62231.09765625,62251.0625,57.0104209356599,20.5648499926392,11.139823,0,0,0,40,4449,10.0234,62241.080078125,,,,,,,,,,,,,0,,,,-0.0049,,,,,,10.0044937,,,,
,33060862.975,10.0047913,57460.423828125,-7.4017135533983E-5,9.43045057069877E-7,1,0.999253354069792,40.0298881530762,1.99335283728095,20.1999992132187,-0.000838006936655105,-0.00012969305083758,0.25,1.83519386534688E-6,-7.40055294661795E-5,1.28397133709148E-6,10.0047913,10.0047913,57452.4375,57468.41015625,56.7407590965252,20.5603944926977,12.278775,0,0,0,40,4449,10.0193,57460.423828125,,,,,,,,,,,,,0,,,,-0.00245,,,,,,10.0047913,,,,
,33060951.51,10.0042686,53037.337890625,-6.14896026766911E-5,6.88290661092762E-7,1,0.999253354069792,40.0298881530762,1.99332463493478,20.1999992132187,-0.000696354432758666,-0.000104958644182471,0.25,1.76583617455106E-6,-6.14550971606109E-5,1.30880217359465E-6,10.0042686,10.0042686,53029.65625,53045.01953125,56.8079791491791,20.5658331275474,11.519473,0,0,0,40,4449,10.0147,53037.337890625,,,,,,,,,,,,,0,,,,-0.0049,,,,,,10.0042686,,,,
,33061042.64,10.004817,48481.978515625,-4.92163456102487E-5,6.63001497644669E-7,1,0.999253354069792,40.0298881530762,1.99348521933717,20.1999992132187,-0.000559256202243816,-7.22747480789032E-5,0.25,2.44971763471784E-6,-4.91736162330013E-5,2.08483692824787E-6,10.004817,10.004817,48476.96875,48486.98828125,56.8228300910445,20.561016575809,12.278775,0,0,0,40,4449,10.01115,48481.978515625,,,,,,,,,,,,,0,,,,-0.0049,,,,,,10.004817,,,,
,33061136.415,10.0044012,43796.6328125,-3.36292409495776E-5,7.52200550139602E-7,1,0.999253354069792,40.0298881530762,1.99354903567862,20.1999992132187,-0.00038161669905204,-5.1270918340539E-5,0.25,1.50128751864745E-6,-3.35823055621923E-5,1.25459052210675E-6,10.0044012,10.0044012,43793.78515625,43799.48046875,56.6000659630637,20.5624820716994,11.899124,0,0,0,40,4449,10.0082,43796.6328125,,,,,,,,,,,,,0,,,,0.0049,,,,,,10.0044012,,,,
,33061228.345,10.00352,39201.306640625,-1.8746892310307E-5,6.41746185048916E-7,1,0.999253354069792,40.0298881530762,1.99353018396432,20.1999992132187,-0.000213790643796701,-2.21104751137965E-5,0.25,1.40839734646285E-6,-1.87156159729929E-5,1.27159404120912E-6,10.00352,10.00352,39191.3046875,39211.30859375,57.0299616486406,20.5636422365667,11.899124,0,0,0,40,4449,10.00525,39201.306640625,,,,,,,,,,,,,0,,,,0,,,,,,10.00352,,,,
,33061319.635,10.00288155,34638.83203125,-8.08918500111339E-6,5.52540240552075E-7,1,0.999253354069792,40.0298881530762,1.99336328702255,20.1999992132187,-9.18504285826467E-5,-1.14582242857056E-5,0.25,4.35401734269421E-7,-8.07047226559679E-6,3.77859862556887E-7,10.0027409,10.0030222,34633.70703125,34643.95703125,56.7626446950637,20.5653119902013,11.899124,0,0,0,40,4449,10.004,34638.83203125,,,,,,,,,,,,,0,,,,0,,,,,,10.00288155,,,,
,33061412.675,10.0027714,29988.9091796875,7.87677530893503E-6,6.70276145857164E-7,1,0.999253354069792,40.0298881530762,1.99342606511453,20.1999992132187,8.86095764861121E-5,1.55320843557397E-5,0.25,-3.27282989376117E-8,7.85195097880667E-6,2.06539728216334E-8,10.0027714,10.0027714,29981.396484375,29996.421875,57.3981086811984,20.5638299119241,11.899124,0,0,0,40,4449,10.0023,29988.9091796875,,,,,,,,,,,,,0,,,,0,,,,,,10.0027714,,,,
,33061504.57,10.001236,25393.4267578125,2.05845779548902E-5,5.66505060849835E-7,1,0.999253354069792,40.0298881530762,1.99351268458324,20.1999992132187,0.000229301838711326,5.26290129262103E-5,0.25,9.92325573154258E-7,2.05028344489299E-5,1.12298620189773E-6,10.001236,10.001236,25388.544921875,25398.30859375,57.2253687784484,20.5610040760901,11.519473,0,0,0,40,4449,10.00195,25393.4267578125,,,,,,,,,,,,,0,,,,-0.0049,,,,,,10.001236,,,,
,33061597.265,10.0013533,20763.3486328125,3.157349427349E-5,4.35718952637854E-7,1,0.999253354069792,40.0298881530762,1.9935291866206,20.1999992132187,0.000353512114911601,6.97611450993683E-5,0.25,5.57923326591945E-7,3.1439886246923E-5,7.52832239364094E-7,10.0013533,10.0013533,20755.64453125,20771.052734375,56.8165770628906,20.5662676135811,11.519473,0,0,0,40,4449,10.0016,20763.3486328125,,,,,,,,,,,,,0,,,,-0.0049,,,,,,10.0013533,,,,
,33061686.545,10.00069,16298.3598632812,4.56601730605254E-5,4.38476502258091E-7,1,0.999253354069792,40.0298881530762,1.99361587777993,20.1999992132187,0.000512861870490764,9.064178508098E-5,0.25,-8.85008964748695E-8,4.54530847575667E-5,1.8350939821281E-7,10.0005913,10.0007887,16293.408203125,16303.3115234375,57.1198489283522,20.5646961036968,11.519473,0,0,0,40,4449,10.0006,16298.3598632812,,,,,,,,,,,,,0,,,,-0.00245,,,,,,10.00069,,,,
,33061777.9,9.9997501,11735.5766601562,5.5219744378618E-5,4.19530135532416E-7,1,0.999253354069792,40.0298881530762,1.99342925537581,20.1999992132187,0.000615739664547435,0.000133039907170442,0.25,2.00264017464003E-6,5.49350935925917E-5,2.3031616281672E-6,9.9997501,9.9997501,11725.5537109375,11745.599609375,57.220679007333,20.5695557216879,11.519473,0,0,0,40,4449,10.00155,11735.5766601562,,,,,,,,,,,,,0,,,,-0.00245,,,,,,9.9997501,,,,
,33061866.655,9.9984226,7297.73217773437,6.47330951584952E-5,3.24200891670148E-7,1,0.999253354069792,40.0298881530762,1.99273767608698,20.1999992132187,0.000725206687939908,0.000134095532731112,0.25,4.28895589541184E-7,6.43874445401962E-5,7.69340128279887E-7,9.9984226,9.9984226,7287.79931640625,7307.6650390625,56.8306463762368,20.5773730656893,11.139823,0,0,0,40,4449,10.00315,7297.73217773437,,,,,,,,,,,,,0,,,,0,,,,,,9.9984226,,,,
,33061954.82,9.9997826,2889.32592773438,7.2205595825572E-5,2.78980543467658E-7,1,0.999253354069792,40.0298881530762,1.992704781655,20.1999992132187,0.00080803916401547,0.000153057045109737,0.25,8.15708064205712E-7,7.17969797584998E-5,1.17086594476607E-6,9.9997826,9.9997826,2884.1787109375,2894.47314453125,56.8134505488137,20.5777794017237,11.899124,0,0,0,40,4449,10.002,2889.32592773438,,,,,,,,,,,,,0,,,,0.00245,,,,,,9.9997826,,,,
,33062014.5,10.0044241,-0.304475456476212,7.47821902264735E-5,3.49293590263044E-7,1,0.999253354069792,40.0298881530762,1.99253927064691,20.1999992132187,0.000838693720065944,0.000147191544043278,0.25,-1.50276084803888E-7,7.4353321834429E-5,2.11032368241108E-7,10.0044241,10.0044241,-0.319699227809906,-0.289251685142517,57.115940785756,20.5802289481378,11.519473,0,0,0,40,4417,9.99875,-0.304475456476212,,,,,,,,,,,,,0,,,,0,,,,,,10.0044241,,,,