File: data/doubleLayers/dl_1-25/ppms/data/DD205_3_HYST_100OE_150K.DAT
[Header]
; VSM Data File (default extension .dat)
; Copyright (c) 2003-2013, Quantum Design, Inc. All rights reserved.
TITLE,
FILEOPENTIME,32557439.61,01/13/2019,3:46 am
BYAPP,VSM,2.0,2.0
INFO,PPMS VSM Option Release 1.4.10 Build 1,APPNAME
INFO,Quantum Design Linear Motor Servo Controller,MOTOR_MODULE_NAME
INFO,3101-100 M1,MOTOR_HW_VERSION
INFO,MMC1014,MOTOR_SERIAL_NUMBER
INFO,SRV No X-over 01.03.11,MOTOR_SOFTWARE_VERSION
INFO,Quantum Design VSM Detection Module,VSM_MODULE_NAME
INFO,3101-150 F0,VSM_HW_VERSION
INFO,VSM707,VSM_SERIAL_NUMBER
INFO,VSM No X-over 01.02.05 May 20 2008 13:51:47,VSM_SOFTWARE_VERSION
INFO,704,PREAMP_SERIAL_NUMBER
INFO,822,COIL_SERIAL_NUMBER
INFO,0,MOMENT_UNITS
INFO,DD205_4,SAMPLE_MATERIAL
INFO,Double Layer Blue 1.25,SAMPLE_COMMENT
INFO,26.73,SAMPLE_MASS
INFO,,SAMPLE_VOLUME
INFO,,SAMPLE_MOLECULAR_WEIGHT
INFO,,SAMPLE_SIZE
INFO,,SAMPLE_SHAPE
DATATYPE,COMMENT,1
DATATYPE,TIME,2
STARTUPAXIS,X,2
STARTUPAXIS,Y1,5
[Data]
Comment,Time Stamp (sec),Temperature (K),Magnetic Field (Oe),Moment (emu),M. Std. Err. (emu),Transport Action,Averaging Time (sec),Frequency (Hz),Peak Amplitude (mm),Center Position (mm),Coil Signal' (mV),Coil Signal" (mV),Range (mV),M. Quad. Signal (emu),M. Raw' (emu),M. Raw" (emu),Min. Temperature (K),Max. Temperature (K),Min. Field (Oe),Max. Field (Oe),Mass (grams),Motor Lag (deg),Pressure (Torr),VSM Status (code),Motor Status (code),Measure Status (code),Measure Count,PPMS Status (code),System Temp. (K),System Field (Oe),Sample Position (deg),Bridge 1 Resistance (ohms),Bridge 1 Excitation (에),Bridge 2 Resistance (ohms),Bridge 2 Excitation (에),Bridge 3 Resistance (ohms),Bridge 3 Excitation (에),Bridge 4 Resistance (ohms),Bridge 4 Excitation (에),Signal 1 Vin (V),Signal 2 Vin (V),Digital Inputs (code),Drive 1 Iout (mA),Drive 1 Ipower (W),Drive 2 Iout (mA),Drive 2 Ipower (W),Pressure (),Map 20 (),Map 21 (),Map 22 (),Map 23 (),Map 24 (),Map 25 (),Map 26 (),Map 27 (),Map 28 (),Map 29 ()
,32557454.34,149.9767761,-0.441489428281784,,,2,,,,20.4800007277727,,,,,,,149.9767761,149.9767761,-0.441489428281784,-0.441489428281784,,,21.01075,,,,-99999999,4369,149.8764,-0.441489428281784,,,,,,,,,,,,,,,,,,,,,,,149.9767761,,,,
,32557598.705,149.9798126,4425.876953125,4.47338041339321E-5,4.23982860614342E-7,1,0.999253354069792,40.0298881530762,1.9974777196278,20.4700008034706,0.000508454702345057,8.80859251360576E-5,0.25,-4.246338903466E-8,4.49530063998549E-5,2.90553944270981E-8,149.9798126,149.9798126,4415.896484375,4435.857421875,56.4077853473329,20.5820177338956,21.770052,0,0,0,40,4449,149.9061,4425.876953125,,,,,,,,,,,,,0,,,,0,,,,,,149.9798126,,,,
,32557693.46,149.9842987,9162.0869140625,4.24750311915791E-5,6.84004726289083E-7,1,0.999253354069792,40.0298881530762,1.99731638059843,20.4700008034706,0.000483834483472742,7.73728050481703E-5,0.25,-5.90961534189932E-7,4.26840743369589E-5,-5.25904764097643E-7,149.9842987,149.9842987,9156.99609375,9167.177734375,56.9846271945253,20.5875712118724,21.3904,0,0,0,40,4449,149.9161,9162.0869140625,,,,,,,,,,,,,0,,,,0,,,,,,149.9842987,,,,
,32557786.495,149.9908142,13812.337890625,3.46653130832751E-5,6.2924369894895E-7,1,0.999253354069792,40.0298881530762,1.99759843488757,20.4700008034706,0.000395677090756163,5.88505736529642E-5,0.25,-8.60923472138792E-7,3.48365458684465E-5,-8.09818139876184E-7,149.9908142,149.9908142,13779.9345703125,13844.7412109375,57.2417829773522,20.5864426347058,21.3904,0,0,0,40,4449,149.9239,13812.337890625,,,,,,,,,,,,,0,,,,-0.00245,,,,,,149.9908142,,,,
,32557881.325,149.9952545,18554.4677734375,2.28694729715429E-5,9.88209806790365E-7,1,0.999253354069792,40.0298881530762,1.99740046270642,20.4700008034706,0.00026080173044004,4.00306931062075E-5,0.25,-4.61459955840711E-7,2.29822849522385E-5,-4.27317169746661E-7,149.9952545,149.9952545,18551.818359375,18557.1171875,57.1675282680253,20.5874670264607,21.3904,0,0,0,40,4449,149.9263,18554.4677734375,,,,,,,,,,,,,0,,,,0,,,,,,149.9952545,,,,
,32557978.035,149.9985504,23387.3466796875,1.04643515136361E-5,1.41526341360337E-6,1,0.999253354069792,40.0298881530762,1.99757308026214,20.4700008034706,0.000120299998716059,1.28339570180721E-5,0.25,-6.93672167682925E-7,1.05167448268183E-5,-6.80460469961109E-7,149.9985504,149.9985504,23379.91796875,23394.775390625,57.4293738219676,20.5905253818719,21.770052,0,0,0,40,4449,149.9269,23387.3466796875,,,,,,,,,,,,,0,,,,-0.0049,,,,,,149.9985504,,,,
,32558073.815,149.9995422,28175.08984375,-6.66142497118625E-6,1.43055839531526E-6,1,0.999253354069792,40.0298881530762,1.99750223925913,20.4700008034706,-7.27289449612065E-5,-3.02673204302002E-5,0.25,-1.5028898068397E-6,-6.69170392562021E-6,-1.52080277387708E-6,149.9995422,149.9995422,28162.453125,28187.7265625,57.2159892362176,20.5912905988589,21.01075,0,0,0,40,4449,149.92735,28175.08984375,,,,,,,,,,,,,0,,,,0.0049,,,,,,149.9995422,,,,
,32558172.27,150.0020905,33092.955078125,-1.94267203730297E-5,1.37703698792893E-6,1,0.999253354069792,40.0298881530762,1.99732788213662,20.4700008034706,-0.000217881643224211,-5.49688214593894E-5,0.25,-1.45322558149416E-6,-1.9519685914728E-5,-1.49101226538392E-6,150.0020905,150.0020905,33085.16015625,33100.75,57.0315249056791,20.5931459928746,21.3904,0,0,0,40,4449,149.92635,33092.955078125,,,,,,,,,,,,,0,,,,0.00245,,,,,,150.0020905,,,,
,32558266.5,150.0037537,37805.294921875,-3.2710417715229E-5,1.87663517730798E-6,1,0.999253354069792,40.0298881530762,1.99739588795232,20.4700008034706,-0.000364687159599164,-0.000105137248726392,0.25,-3.5539336653389E-6,-3.28652514052196E-5,-3.62284127133057E-6,150.0037537,150.0037537,37802.48046875,37808.109375,57.393418910083,20.592290643594,22.149702,0,0,0,40,4449,149.92025,37805.294921875,,,,,,,,,,,,,0,,,,0,,,,,,150.0037537,,,,
,32558363.32,150.0068207,42642.4375,-4.77560229707024E-5,2.44518264000971E-6,1,0.999253354069792,40.0298881530762,1.99732864733578,20.4700008034706,-0.000534650279420935,-0.000140651525700019,0.25,-4.05889907141213E-6,-4.79839169516732E-5,-4.15373712464472E-6,150.0068207,150.0068207,42635.02734375,42649.84765625,57.5653771843138,20.5954501676518,22.149702,0,0,0,40,4449,149.9147,42642.4375,,,,,,,,,,,,,0,,,,-0.00245,,,,,,150.0068207,,,,
,32558457.215,150.0097046,47335.537109375,-6.43104752725597E-5,2.60586980676803E-6,1,0.999253354069792,40.0298881530762,1.99719376672424,20.4700008034706,-0.000723490057784355,-0.000169010913746018,0.25,-3.67221687525199E-6,-6.4620258378921E-5,-3.79083622108967E-6,150.0095673,150.0098419,47327.70703125,47343.3671875,57.566158812833,20.5944473548901,21.3904,0,0,0,40,4449,149.9051,47335.537109375,,,,,,,,,,,,,0,,,,0,,,,,,150.0097046,,,,
,32558553.365,150.0073547,52141.09375,-7.91851070446511E-5,2.53976273585734E-6,1,0.999253354069792,40.0298881530762,1.99742409381792,20.4700008034706,-0.000892346575487825,-0.000199982426852299,0.25,-3.8054231135718E-6,-7.95677670650313E-5,-3.94758750624138E-6,150.0073547,150.0073547,52136.328125,52145.859375,57.2238055214099,20.5920231836041,21.3904,0,0,0,40,4449,149.8947,52141.09375,,,,,,,,,,,,,0,,,,-0.00245,,,,,,150.0073547,,,,
,32558649.4,150.0110931,56940.705078125,-9.67824174508342E-5,2.77455777342608E-6,1,0.999253354069792,40.0298881530762,1.99745545391188,20.4700008034706,-0.00108765562671974,-0.000261737843858175,0.25,-6.17468870791709E-6,-9.72478605760353E-5,-6.3554589225299E-6,150.0110931,150.0110931,56933.59765625,56947.8125,57.4450063923522,20.5880780914074,21.3904,0,0,0,40,4449,149.88315,56940.705078125,,,,,,,,,,,,,0,,,,0.0049,,,,,,150.0110931,,,,
,32558747.445,150.0112305,61843.3671875,-0.000113466613724297,2.77894455930679E-6,1,0.999253354069792,40.0298881530762,1.9972565101093,20.4700008034706,-0.00128026122193654,-0.000276826728218292,0.25,-4.59938514066585E-6,-0.000114016544006491,-4.79778974723613E-6,150.0112305,150.0112305,61840.9609375,61845.7734375,57.6529195784676,20.5938221498197,21.3904,0,0,0,40,4449,149.8757,61843.3671875,,,,,,,,,,,,,0,,,,-0.0049,,,,,,150.0112305,,,,
,32558844.56,150.0091858,66696.484375,-0.00013048413303723,3.58492084976428E-6,1,0.999253354069792,40.0298881530762,1.99735033743559,20.4700008034706,-0.00146706314408323,-0.000348661010085571,0.25,-7.95632941893093E-6,-0.000131112596559883,-8.19693259756851E-6,150.0091858,150.0091858,66688.9921875,66703.9765625,57.3895107674868,20.5943158685241,21.3904,0,0,0,40,4449,149.86745,66696.484375,,,,,,,,,,,,,0,,,,0.00245,,,,,,150.0091858,,,,
,32558942.195,150.00736235,71574.26953125,-0.000146156422214113,3.4016548687656E-6,1,0.999253354069792,40.0298881530762,1.99739478043532,20.4700008034706,-0.00165369454789291,-0.000330904823284271,0.25,-3.66443291275673E-6,-0.000146868660667557,-3.90741776328668E-6,150.0072174,150.0075073,71566.84375,71581.6953125,57.190195495083,20.5920505268864,21.770052,0,0,0,40,4449,149.86025,71574.26953125,,,,,,,,,,,,,0,,,,-0.00245,,,,,,150.00736235,,,,
,32559040.335,150.0094147,76482.63671875,-0.000162280716542792,4.38816821888807E-6,1,0.999253354069792,40.0298881530762,1.99754259867811,20.4700008034706,-0.0018364656376593,-0.000366288379627108,0.25,-3.96844820310904E-6,-0.000163071875459014,-4.2369045461078E-6,150.0094147,150.0094147,76480.3828125,76484.890625,57.3363600281791,20.5868853033876,21.770052,0,0,0,40,4449,149.85285,76482.63671875,,,,,,,,,,,,,0,,,,0,,,,,,150.0094147,,,,
,32559138.39,150.0092316,81385.8125,-0.000174025141342901,3.93842818436545E-6,1,0.999253354069792,40.0298881530762,1.99745883264427,20.4700008034706,-0.00197258901626368,-0.00037387287987124,0.25,-2.59269857923902E-6,-0.000174876313054833,-2.87151376553922E-6,150.0092316,150.0092316,81383.4765625,81388.1484375,57.3230723433522,20.5925364341774,21.770052,0,0,0,40,4449,149.8413,81385.8125,,,,,,,,,,,,,0,,,,0,,,,,,150.0092316,,,,
,32559233.25,150.0096512,86123.81640625,-0.000197105452229238,4.41602158362141E-6,1,0.999253354069792,40.0298881530762,1.99749309131314,20.4700008034706,-0.00223236825987969,-0.000434244562209794,0.25,-3.88600883691855E-6,-0.000198068288940531,-4.20546530400101E-6,150.00914,150.0101624,86121.1953125,86126.4375,57.1956668947176,20.5918366444043,21.770052,0,0,0,40,4449,149.8348,86123.81640625,,,,,,,,,,,,,0,,,,0,,,,,,150.0096512,,,,
,32559343.86,150.0095215,89351.48046875,-0.00021904202148272,6.00815895666434E-6,1,0.999253354069792,40.0298881530762,1.99738603451302,20.4700008034706,-0.00248458949137582,-0.000460164117961732,0.25,-2.349478715928E-6,-0.000220115181045586,-2.69406748920449E-6,150.0095215,150.0095215,89341.71875,89361.2421875,57.2120810936214,20.593706435076,21.770052,0,0,0,40,4449,149.8239,89351.48046875,,,,,,,,,,,,,0,,,,-0.00245,,,,,,150.0095215,,,,
,32559434.875,150.0042114,84801.60546875,-0.00019420139872097,3.6569292101892E-6,1,0.999253354069792,40.0298881530762,1.99739874641029,20.4700008034706,-0.00219659625590975,-0.000443801579730577,0.25,-5.23410401422038E-6,-0.000195147862673346,-5.55607688499654E-6,150.0037994,150.0046234,84769.15625,84834.0546875,57.3199458292753,20.5940643987547,22.149702,0,0,0,40,4449,149.82205,84801.60546875,,,,,,,,,,,,,0,,,,0,,,,,,150.0042114,,,,
,32559530.4,149.9981384,80027.6171875,-0.000183185845839617,3.15682612902253E-6,1,0.999253354069792,40.0298881530762,1.99725113442787,20.4700008034706,-0.0020698586111895,-0.000430044453530555,0.25,-5.94356238203995E-6,-0.000184076890692689,-6.25315890125619E-6,149.9981384,149.9981384,80025.0625,80030.171875,57.1245386994676,20.5951422984375,21.770052,0,0,0,40,4449,149.8268,80027.6171875,,,,,,,,,,,,,0,,,,0,,,,,,149.9981384,,,,
,32559625.82,149.9949646,75258.875,-0.00016483565027492,3.8870958212721E-6,1,0.999253354069792,40.0298881530762,1.9973297749958,20.4700008034706,-0.00186603504717011,-0.000367160341606645,0.25,-3.60325766255123E-6,-0.000165639927854924,-3.87409907275355E-6,149.9949646,149.9949646,75251.4296875,75266.3203125,57.7177947455638,20.5947585288739,21.770052,0,0,0,40,4449,149.83585,75258.875,,,,,,,,,,,,,0,,,,-0.00245,,,,,,149.9949646,,,,
,32559724.875,149.9923935,70305.671875,-0.000146917410359583,3.77113846959262E-6,1,0.999253354069792,40.0298881530762,1.99727699932768,20.4700008034706,-0.00166324051044882,-0.000326699210101549,0.25,-3.16319775704644E-6,-0.000147634162320664,-3.40513959693974E-6,149.9923706,149.9924164,70298.8125,70312.53125,57.4450063923522,20.6005187726211,21.3904,0,0,0,40,4449,149.83845,70305.671875,,,,,,,,,,,,,0,,,,-0.00245,,,,,,149.9923935,,,,
,32559822.43,149.9944611,65427.91796875,-0.000124556525055428,3.07332147633799E-6,1,0.999253354069792,40.0298881530762,1.9973711031191,20.4700008034706,-0.00140647738827124,-0.000298111306380082,0.25,-4.53994753012937E-6,-0.00012516115737034,-4.75482603112419E-6,149.9944611,149.9944611,65425.28125,65430.5546875,57.5888260398907,20.5968245298686,22.149702,0,0,0,40,4449,149.84675,65427.91796875,,,,,,,,,,,,,0,,,,0,,,,,,149.9944611,,,,
,32559919.875,149.99340055,60556.146484375,-0.000109417671311108,2.71878309122836E-6,1,0.999253354069792,40.0298881530762,1.99740340425771,20.4700008034706,-0.00123877129418521,-0.000243379664999405,0.25,-2.35946875057391E-6,-0.000109951205342374,-2.54079024999761E-6,149.9933319,149.9934692,60545.94921875,60566.34375,57.3301070000253,20.5990663384063,21.770052,0,0,0,40,4449,149.852,60556.146484375,,,,,,,,,,,,,0,,,,-0.0049,,,,,,149.99340055,,,,
,32560019.215,149.9937897,55593.740234375,-9.08769322182843E-5,2.58874733525257E-6,1,0.999253354069792,40.0298881530762,1.99734134858608,20.4700008034706,-0.00102716786177422,-0.000211680161113703,0.25,-2.79933908884233E-6,-9.131864210057E-5,-2.95451950136956E-6,149.9937897,149.9937897,55588.3828125,55599.09765625,57.525514129833,20.5938629705224,22.149702,0,0,0,40,4449,149.861,55593.740234375,,,,,,,,,,,,,0,,,,-0.0049,,,,,,149.9937897,,,,
,32560114.68,149.9927063,50821.232421875,-7.64303771313839E-5,2.80740100472736E-6,1,0.999253354069792,40.0298881530762,1.99740188023838,20.4700008034706,-0.000862733810355103,-0.000184756954588378,0.25,-2.94549743234073E-6,-7.68008568351087E-5,-3.07928114313622E-6,149.9927063,149.9927063,50811.1640625,50831.30078125,57.3543374841214,20.5999996997128,21.770052,0,0,0,40,4449,149.86775,50821.232421875,,,,,,,,,,,,,0,,,,-0.00245,,,,,,149.9927063,,,,
,32560211.48,149.9902802,45983.693359375,-6.48857716939014E-5,2.35814453476035E-6,1,0.999253354069792,40.0298881530762,1.99735481199967,20.4700008034706,-0.000727908077677593,-0.000182651146869916,0.25,-4.77106545136593E-6,-6.51966593389397E-5,-4.89609636189908E-6,149.9902802,149.9902802,45979.0546875,45988.33203125,57.2871174314676,20.6002660920182,22.149702,0,0,0,40,4449,149.87435,45983.693359375,,,,,,,,,,,,,0,,,,0,,,,,,149.9902802,,,,
,32560305.9,149.9908447,41263.76171875,-4.50973705449009E-5,2.138634469534E-6,1,0.999253354069792,40.0298881530762,1.9973465795458,20.4700008034706,-0.00051075658450934,-9.91409937730168E-5,0.25,-8.6892578975631E-7,-4.53172280085816E-5,-9.44029429268536E-7,149.9908447,149.9908447,41256.2265625,41271.296875,57.4715817620061,20.6017759709277,21.3904,0,0,0,40,4449,149.8818,41263.76171875,,,,,,,,,,,,,0,,,,0,,,,,,149.9908447,,,,
,32560401.64,149.9919891,36478.576171875,-3.09557115281844E-5,1.46603489400163E-6,1,0.999253354069792,40.0298881530762,1.99733266874479,20.4700008034706,-0.000349027371237225,-7.70255063443709E-5,0.25,-1.38598833725691E-6,-3.11053468268167E-5,-1.4415574109078E-6,149.9919891,149.9919891,36468.515625,36488.63671875,57.4309370790061,20.5994508921467,21.770052,0,0,0,40,4449,149.88835,36478.576171875,,,,,,,,,,,,,0,,,,-0.00245,,,,,,149.9919891,,,,
,32560497.36,149.9906311,31693.736328125,-1.4214690880877E-5,2.06614912946946E-6,1,0.999253354069792,40.0298881530762,1.99726846900614,20.4700008034706,-0.000156648678936857,-5.61362207786391E-5,0.25,-2.46397941888831E-6,-1.4280498412395E-5,-2.49852196900279E-6,149.9906311,149.9906311,31691.203125,31696.26953125,57.8006473686023,20.5959600769255,21.770052,0,0,0,40,4449,149.89595,31693.736328125,,,,,,,,,,,,,0,,,,0.0049,,,,,,149.9906311,,,,
,32560594.145,149.9911041,26858.9765625,-9.40870682141381E-7,1.07238481082254E-6,1,0.999253354069792,40.0298881530762,1.99739765319288,20.4700008034706,-8.51956142863818E-6,-1.43337312856108E-5,0.25,-1.09742786380751E-6,-9.43744334629321E-7,-1.10429880575547E-6,149.9911041,149.9911041,26854.2109375,26863.7421875,57.4723633905253,20.6020581626447,21.3904,0,0,0,40,4449,149.90685,26858.9765625,,,,,,,,,,,,,0,,,,0.0049,,,,,,149.9911041,,,,
,32560691.26,149.9928589,22003.3466796875,1.329672230226E-5,1.10725767965591E-6,1,0.999253354069792,40.0298881530762,1.99743988472314,20.4700008034706,0.000152413117798095,1.88241979322954E-5,0.25,-6.59916141120033E-7,1.33629438688807E-5,-6.42022152570914E-7,149.9928589,149.9928589,22000.83203125,22005.861328125,57.4395349927176,20.6014712691573,21.770052,0,0,0,40,4449,149.9092,22003.3466796875,,,,,,,,,,,,,0,,,,0,,,,,,149.9928589,,,,
,32560787.33,149.9925919,17203.3935546875,2.61648877875167E-5,7.69825056452134E-7,1,0.999253354069792,40.0298881530762,1.99753965514149,20.4700008034706,0.000298972010197402,4.25310646412755E-5,0.25,-8.15806516792899E-7,2.62944090881538E-5,-7.7811889752917E-7,149.9925385,149.9926453,17198.447265625,17208.33984375,57.7873596837753,20.6005909636169,21.770052,0,0,0,40,4449,149.9151,17203.3935546875,,,,,,,,,,,,,0,,,,0,,,,,,149.9925919,,,,
,32560884.86,149.991745,12328.751953125,3.91137090512622E-5,8.52931938629413E-7,1,0.999253354069792,40.0298881530762,1.99761099588481,20.4700008034706,0.000445887939953425,6.96553888517922E-5,0.25,-6.85266983566391E-7,3.93064476506749E-5,-6.26152958410574E-7,149.991745,149.991745,12316.2626953125,12341.2412109375,57.9155467609292,20.5988337623618,22.149702,0,0,0,40,4449,149.9232,12328.751953125,,,,,,,,,,,,,0,,,,0.00245,,,,,,149.991745,,,,
,32560980.855,149.9919434,7530.98803710937,4.91735548052298E-5,5.5818935336276E-7,1,0.999253354069792,40.0298881530762,1.99754508263802,20.4700008034706,0.000560623606852703,8.71449019841331E-5,0.25,-8.98884843321918E-7,4.94158878644348E-5,-8.24569670608133E-7,149.9919434,149.9919434,7523.6318359375,7538.34423828125,57.6708970344099,20.601860270444,21.3904,0,0,0,40,4449,149.93,7530.98803710937,,,,,,,,,,,,,0,,,,0,,,,,,149.9919434,,,,
,32561075.705,149.9944153,2790.44189453125,5.25426382870546E-5,3.63185025832425E-7,1,0.999253354069792,40.0298881530762,1.99745165361866,20.4700008034706,0.000597857572201543,9.97093215835101E-5,0.25,-3.8004600616946E-7,5.28006055619232E-5,-2.97626100636249E-7,149.9944153,149.9944153,2780.48095703125,2800.40283203125,57.7615659426407,20.5983361044857,21.770052,0,0,0,40,4449,149.93225,2790.44189453125,,,,,,,,,,,,,0,,,,-0.00245,,,,,,149.9944153,,,,
,32561168.935,149.9963226,-1869.14624023438,3.91745934333591E-5,3.30433108037731E-7,1,0.999253354069792,40.0298881530762,1.9975669151186,20.4700008034706,0.000445747160736116,7.44960287091418E-5,0.25,-2.70089427922051E-7,3.93669007279155E-5,-2.08556074942012E-7,149.9963226,149.9963226,-1879.25952148438,-1859.03295898438,57.4473512779099,20.6007372267563,22.149702,0,0,0,40,4449,149.93775,-1869.14624023438,,,,,,,,,,,,,0,,,,-0.00245,,,,,,149.9963226,,,,
,32561265.22,150.0003052,-6679.79296875,7.77344898176938E-6,7.18085545831678E-7,1,0.999253354069792,40.0298881530762,1.99737214777477,20.4700008034706,8.77400878840956E-5,1.88088316779237E-5,0.25,3.00879879250663E-7,7.8110454276047E-6,3.14801829864839E-7,150.0003052,150.0003052,-6682.2265625,-6677.359375,57.637287008083,20.6027843719012,22.149702,0,0,0,40,4449,149.9364,-6679.79296875,,,,,,,,,,,,,0,,,,0,,,,,,150.0003052,,,,
,32561361.305,150.0024872,-11483.1987304688,-2.06264782027828E-5,9.41427907885928E-7,1,0.999253354069792,40.0298881530762,1.99773711729814,20.4700008034706,-0.000235124924113105,-3.68874122123328E-5,0.25,3.47950012198257E-7,-2.07280883511715E-5,3.16699690590371E-7,150.0024872,150.0024872,-11485.7978515625,-11480.599609375,57.6083667528715,20.5968642773257,21.770052,0,0,0,40,4449,149.9336,-11483.1987304688,,,,,,,,,,,,,0,,,,0,,,,,,150.0024872,,,,
,32561457.91,150.00551605,-16310.7998046875,-2.50799102465329E-5,1.06540489180097E-6,1,0.999253354069792,40.0298881530762,1.9974573800329,20.4700008034706,-0.000285463221190239,-4.70796583855925E-5,0.25,2.26404655517821E-7,-2.52031633678666E-5,1.87542532403831E-7,150.0048523,150.0061798,-16317.953125,-16303.646484375,57.6380686366023,20.6038945764597,22.149702,0,0,0,40,4449,149.92745,-16310.7998046875,,,,,,,,,,,,,0,,,,0,,,,,,150.00551605,,,,
,32561554.24,150.0088654,-21127.876953125,-1.46845134439886E-5,1.08180019416131E-6,1,0.999253354069792,40.0298881530762,1.99744586078845,20.4700008034706,-0.00016682094882472,-2.93997393132679E-5,0.25,-2.89089281044448E-8,-1.47564339609953E-5,-5.23935999800243E-8,150.0088654,150.0088654,-21130.326171875,-21125.427734375,57.5911709254484,20.6038416234345,21.770052,0,0,0,40,4449,149.9197,-21127.876953125,,,,,,,,,,,,,0,,,,0.00245,,,,,,150.0088654,,,,
,32561650.69,150.010376,-25947.212890625,-1.05797210948822E-6,1.43170512394469E-6,1,0.999253354069792,40.0298881530762,1.99751012424285,20.4700008034706,-1.31002557793426E-5,4.08700153658938E-6,0.25,5.43926425218597E-7,-1.06402033562671E-6,5.44915306911839E-7,150.010376,150.010376,-25957.2734375,-25937.15234375,57.5685036983907,20.6028271669991,21.770052,0,0,0,40,4449,149.9075,-25947.212890625,,,,,,,,,,,,,0,,,,-0.0049,,,,,,150.010376,,,,
,32561750.17,150.0103302,-30917.5556640625,1.5041067850109E-5,2.14483501051993E-6,1,0.999253354069792,40.0298881530762,1.99763351553742,20.4700008034706,0.000168081511307311,4.62225603806548E-5,0.25,1.44688355494303E-6,1.5112522849912E-5,1.47775435247004E-6,150.0103302,150.0103302,-30920.458984375,-30914.65234375,57.8256594812177,20.5996484470907,21.3904,0,0,0,40,4449,149.898,-30917.5556640625,,,,,,,,,,,,,0,,,,0,,,,,,150.0103302,,,,
,32561848.625,150.0093994,-35839.9140625,2.97408655739971E-5,1.89290856251684E-6,1,0.999253354069792,40.0298881530762,1.99752940598541,20.4700008034706,0.000335177043599823,7.50668945675438E-5,0.25,1.42461201245803E-6,2.98844624056345E-5,1.47847428547809E-6,150.0093994,150.0093994,-35847.15234375,-35832.67578125,57.6794949481215,20.5978942371745,21.3904,0,0,0,40,4449,149.88845,-35839.9140625,,,,,,,,,,,,,0,,,,0.00245,,,,,,150.0093994,,,,
,32561946.285,150.0125427,-40722.326171875,4.4993731534298E-5,2.13214342391182E-6,1,0.999253354069792,40.0298881530762,1.99758490508836,20.4700008034706,0.00050842544533325,0.000105899629399027,0.25,1.48064900151198E-6,4.52120852464913E-5,1.5586173567142E-6,150.0125427,150.0125427,-40724.92578125,-40719.7265625,57.9163283894484,20.6004190734404,22.149702,0,0,0,40,4449,149.8768,-40722.326171875,,,,,,,,,,,,,0,,,,0,,,,,,150.0125427,,,,
,32562043.475,150.0125275,-45577.646484375,5.97601966782741E-5,3.08555084604307E-6,1,0.999253354069792,40.0298881530762,1.99774130676181,20.4700008034706,0.000670650615825764,0.000167567711611129,0.25,4.33378570343182E-6,6.00465734351325E-5,4.44867450693378E-6,150.0125275,150.0125275,-45582.68359375,-45572.609375,57.8803734775638,20.6002451318695,22.149702,0,0,0,40,4449,149.8638,-45577.646484375,,,,,,,,,,,,,0,,,,0.0049,,,,,,150.0125275,,,,
,32562140.12,150.0103149,-50409.43359375,7.64235150254084E-5,2.28885085627993E-6,1,0.999253354069792,40.0298881530762,1.99768702474644,20.4700008034706,0.000859564456384236,0.00020318837396749,0.25,4.56611766405213E-6,7.6791380053307E-5,4.70788777223371E-6,150.0103149,150.0103149,-50414.171875,-50404.6953125,57.8194064530638,20.6063056996864,21.3904,0,0,0,40,4449,149.8551,-50409.43359375,,,,,,,,,,,,,0,,,,0,,,,,,150.0103149,,,,
,32562237.625,150.0106049,-55279.169921875,9.38819564669121E-5,1.86297636651695E-6,1,0.999253354069792,40.0298881530762,1.99764321618774,20.4700008034706,0.00105808518000812,0.000237086186567297,0.25,4.50859611462481E-6,9.43356983156802E-5,4.67689172270843E-6,150.0106049,150.0106049,-55286.7578125,-55271.58203125,57.7474966292946,20.6065973313579,21.3904,0,0,0,40,4449,149.8464,-55279.169921875,,,,,,,,,,,,,0,,,,0,,,,,,150.0106049,,,,
,32562336.345,150.0142517,-60213.62890625,0.000109070096757085,2.46364831369802E-6,1,0.999253354069792,40.0298881530762,1.99735757255932,20.4700008034706,0.00123411366142417,0.000246589243346702,0.25,2.70285197799149E-6,0.000109601310026884,2.88539201034446E-6,150.0142517,150.0142517,-60218.28125,-60208.9765625,57.4317187075253,20.6095815128743,22.149702,0,0,0,40,4449,149.8304,-60213.62890625,,,,,,,,,,,,,0,,,,-0.00245,,,,,,150.0142517,,,,
,32562436.835,150.0080719,-65236.26953125,0.000124217008948239,2.6615673622652E-6,1,0.999253354069792,40.0298881530762,1.99768249405472,20.4700008034706,0.00140208106464903,0.00030176709282434,0.25,4.91678049542623E-6,0.000124819328865703,5.13304121973596E-6,150.0080719,150.0080719,-65246.1875,-65226.3515625,57.677931691083,20.6062029698728,22.149702,0,0,0,40,4449,149.828,-65236.26953125,,,,,,,,,,,,,0,,,,-0.0049,,,,,,150.0080719,,,,
,32562534.99,150.009491,-70143.45703125,0.000140633746984282,2.64365057612491E-6,1,0.999253354069792,40.0298881530762,1.99772544547018,20.4700008034706,0.00159369121219966,0.000305630894813764,0.25,2.39769270063166E-6,0.000141320730878944,2.62625978484878E-6,150.009491,150.009491,-70153.3984375,-70133.515625,57.4903408464676,20.6047773153517,21.770052,0,0,0,40,4449,149.8159,-70143.45703125,,,,,,,,,,,,,0,,,,0.00245,,,,,,150.009491,,,,
,32562632.52,150.0121307,-75017.80078125,0.000155513669738134,2.36704992120888E-6,1,0.999253354069792,40.0298881530762,1.99774049057356,20.4700008034706,0.00176039884013608,0.000349050071349454,0.25,3.62690213787987E-6,0.000156272013924837,3.8836460983423E-6,150.0121307,150.0121307,-75025.25,-75010.3515625,57.5278590153907,20.6063135582103,21.3904,0,0,0,40,4449,149.807,-75017.80078125,,,,,,,,,,,,,0,,,,0.00245,,,,,,150.0121307,,,,
,32562731.38,150.0103149,-79954.73828125,0.000174218458546094,3.62612396505343E-6,1,0.999253354069792,40.0298881530762,1.9978663299878,20.4700008034706,0.0019753829781948,0.000373101940875624,0.25,2.48444132055513E-6,0.000175070654271437,2.76340201953952E-6,150.0103149,150.0103149,-79962.3671875,-79947.109375,57.8905346483138,20.603108522825,21.770052,0,0,0,40,4449,149.7964,-79954.73828125,,,,,,,,,,,,,0,,,,-0.00245,,,,,,150.0103149,,,,
,32562829.155,150.0128632,-84842.4609375,0.000188008642206638,3.31368312916698E-6,1,0.999253354069792,40.0298881530762,1.99764773643898,20.4700008034706,0.00212158321087006,0.000459673427189323,0.25,7.70427262428312E-6,0.000188920833865167,8.02902614317186E-6,150.0128632,150.0128632,-84845.03125,-84839.890625,57.7662557137561,20.6072627119971,21.770052,0,0,0,40,4449,149.7847,-84842.4609375,,,,,,,,,,,,,0,,,,0.00245,,,,,,150.0128632,,,,
,32562921.615,150.0124359,-89466.4921875,0.000204815413154318,3.57322453920372E-6,1,0.999253354069792,40.0298881530762,1.9977516570042,20.4700008034706,0.00231275309596636,0.000492772236476274,0.25,7.68851706352161E-6,0.000205810475293386,8.037840194493E-6,150.0124359,150.0124359,-89476.4375,-89456.546875,57.8194064530638,20.605542975811,21.770052,0,0,0,40,4449,149.77205,-89466.4921875,,,,,,,,,,,,,0,,,,0.0049,,,,,,150.0124359,,,,
,32563033.725,150.0058899,-85884.78515625,0.000196660612651385,2.9772586139145E-6,1,0.999253354069792,40.0298881530762,1.99771906451871,20.4700008034706,0.0022262469268835,0.000440910175970203,0.25,4.54556620474285E-6,0.000197620222570308,4.86782718194563E-6,150.0058899,150.0058899,-85894.6640625,-85874.90625,57.4332819645638,20.6062432684801,21.770052,0,0,0,40,4449,149.7659,-85884.78515625,,,,,,,,,,,,,0,,,,0.0049,,,,,,150.0058899,,,,
,32563134.485,150.0020294,-80850.546875,0.000177522845638685,2.97658685332116E-6,1,0.999253354069792,40.0298881530762,1.99792240989369,20.4700008034706,0.00200942887324996,0.000400147160137434,0.25,4.28745536027931E-6,0.000178388579559798,4.58024313733991E-6,150.0020294,150.0020294,-80858.1171875,-80842.9765625,57.9077304757369,20.60472449643,21.3904,0,0,0,40,4449,149.764,-80850.546875,,,,,,,,,,,,,0,,,,0,,,,,,150.0020294,,,,
,32563240.975,149.9967957,-75528.16015625,0.000160579849437629,2.8684922838522E-6,1,0.999253354069792,40.0298881530762,1.99779678796914,20.4700008034706,0.00181908411061208,0.000353040981051579,0.25,3.09489260256211E-6,0.00016136396577507,3.35681118749898E-6,149.9967957,149.9967957,-75540.703125,-75515.6171875,57.7983024830446,20.60583796682,21.770052,0,0,0,40,4449,149.7667,-75528.16015625,,,,,,,,,,,,,0,,,,0,,,,,,149.9967957,,,,
,32563349.425,149.9951172,-70111.2890625,0.00013846850659056,2.70408730155097E-6,1,0.999253354069792,40.0298881530762,1.99765414455015,20.4700008034706,0.00156617521669177,0.000317715987309818,0.25,3.83891318709529E-6,0.000139142669951981,4.07130898793284E-6,149.9951172,149.9951172,-70113.8359375,-70108.7421875,57.8420736801215,20.6064886070788,21.3904,0,0,0,40,4449,149.7744,-70111.2890625,,,,,,,,,,,,,0,,,,0,,,,,,149.9951172,,,,
,32563456.985,149.9965668,-64731.857421875,0.00012379637189813,2.54896471570269E-6,1,0.999253354069792,40.0298881530762,1.9973819141795,20.4700008034706,0.00139818338131327,0.000294668430951977,0.25,4.36904161975108E-6,0.000124397475719018,4.58211542785267E-6,149.9965668,149.9965668,-64741.984375,-64721.73046875,57.4793980471984,20.6100587358757,21.770052,0,0,0,40,4449,149.78,-64731.857421875,,,,,,,,,,,,,0,,,,0.00245,,,,,,149.9965668,,,,
,32563562.895,149.9930573,-59439.92578125,0.00010707665952708,2.14077131217833E-6,1,0.999253354069792,40.0298881530762,1.99742906503281,20.4700008034706,0.00121295963214359,0.000234283616330988,0.25,1.96630951417177E-6,0.000107599257848757,2.14229783508011E-6,149.9930573,149.9930573,-59449.27734375,-59430.57421875,57.7279559163138,20.6087299270159,22.149702,0,0,0,40,4449,149.78615,-59439.92578125,,,,,,,,,,,,,0,,,,0,,,,,,149.9930573,,,,
,32563670.66,149.9922943,-54055.705078125,8.98297849241364E-5,1.93565412473542E-6,1,0.999253354069792,40.0298881530762,1.99752160583358,20.4700008034706,0.00101125413428627,0.000233170814996081,0.25,4.8708864034108E-6,9.02630724736498E-5,5.03483372923378E-6,149.9922943,149.9922943,-54068.7265625,-54042.68359375,57.6669888918138,20.6039946894463,21.3904,0,0,0,40,4449,149.7957,-54055.705078125,,,,,,,,,,,,,0,,,,0,,,,,,149.9922943,,,,
,32563777.71,149.9922485,-48703.611328125,7.1489841440576E-5,2.64273112875578E-6,1,0.999253354069792,40.0298881530762,1.99749549069716,20.4700008034706,0.000806200079290273,0.000177421586513142,0.25,3.15962690341917E-6,7.1835682949409E-5,3.2869745502357E-6,149.9922485,149.9922485,-48710.84765625,-48696.375,57.5020652742561,20.6029155554556,22.149702,0,0,0,40,4449,149.79965,-48703.611328125,,,,,,,,,,,,,0,,,,0,,,,,,149.9922485,,,,
,32563881.15,149.9937286,-43533.630859375,5.32904756775257E-5,2.1365384543365E-6,1,0.999253354069792,40.0298881530762,1.99761210080219,20.4700008034706,0.000601183984135484,0.00013118374431008,0.25,2.26011489579684E-6,5.35483501035243E-5,2.35485215449508E-6,149.9937286,149.9937286,-43538.6015625,-43528.66015625,57.7412436011407,20.6030188683093,21.770052,0,0,0,40,4449,149.8049,-43533.630859375,,,,,,,,,,,,,0,,,,0,,,,,,149.9937286,,,,
,32563980.26,149.9928589,-38578.857421875,3.67478583142358E-5,2.11650763120089E-6,1,0.999253354069792,40.0298881530762,1.99762456078081,20.4700008034706,0.000414015107894391,9.36144108190451E-5,0.25,1.83574547158399E-6,3.69252002037876E-5,1.90261214174579E-6,149.9928589,149.9928589,-38586.28515625,-38571.4296875,57.5481813568907,20.6022982476721,21.770052,0,0,0,40,4449,149.8114,-38578.857421875,,,,,,,,,,,,,0,,,,0,,,,,,149.9928589,,,,
,32564075.83,149.9920502,-33804.6953125,2.33718680133721E-5,2.34877956124729E-6,1,0.999253354069792,40.0298881530762,1.99757261840309,20.4700008034706,0.000261219591296523,7.1534392171005E-5,0.25,2.2230119000698E-6,2.34829627383045E-5,2.27082409148086E-6,149.9920502,149.9920502,-33819.3828125,-33790.0078125,57.5473997283715,20.6026300093246,21.3904,0,0,0,40,4449,149.81195,-33804.6953125,,,,,,,,,,,,,0,,,,-0.00245,,,,,,149.9920502,,,,
,32564174.25,149.9922333,-28887.30859375,7.98038427532766E-6,1.33231331780315E-6,1,0.999253354069792,40.0298881530762,1.99760444765306,20.4700008034706,8.91819029225122E-5,2.45030092438366E-5,0.25,7.65797767347471E-7,8.01829569031029E-6,7.82192207269591E-7,149.9922333,149.9922333,-28892.392578125,-28882.224609375,57.4387533641984,20.6015215520687,21.3904,0,0,0,40,4449,149.8235,-28887.30859375,,,,,,,,,,,,,0,,,,-0.0049,,,,,,149.9922333,,,,
,32564270.875,149.9896088,-24057.6787109375,-6.34809621721602E-6,1.35738765455281E-6,1,0.999253354069792,40.0298881530762,1.99767148880992,20.4700008034706,-7.51117168527845E-5,4.43793822055661E-6,0.25,1.49634446611521E-6,-6.38158916717288E-6,1.49359654035095E-6,149.9896088,149.9896088,-24065.115234375,-24050.2421875,57.7482782578138,20.6010106061587,21.3904,0,0,0,40,4449,149.83365,-24057.6787109375,,,,,,,,,,,,,0,,,,-0.0049,,,,,,149.9896088,,,,
,32564369.4,149.9900055,-19132.7392578125,-2.20723199437334E-5,1.70245740039219E-6,1,0.999253354069792,40.0298881530762,1.99757319755615,20.4700008034706,-0.00025347950658446,-2.86065025354809E-5,0.25,1.32811233055345E-6,-2.21826054328396E-5,1.29946891237219E-6,149.9900055,149.9900055,-19137.560546875,-19127.91796875,57.8123717963907,20.6021397602355,21.770052,0,0,0,40,4449,149.8437,-19132.7392578125,,,,,,,,,,,,,0,,,,0,,,,,,149.9900055,,,,
,32564466.595,149.9906311,-14275.423828125,-3.40342063211528E-5,1.71988651941414E-6,1,0.999253354069792,40.0298881530762,1.99762844668754,20.4700008034706,-0.000388445892152602,-5.79701484310585E-5,0.25,8.28542578002803E-7,-3.42022901732431E-5,7.78259961074262E-7,149.9906311,149.9906311,-14280.5185546875,-14270.3291015625,57.3402681707753,20.6030416944529,21.770052,0,0,0,40,4449,149.85005,-14275.423828125,,,,,,,,,,,,,0,,,,-0.0049,,,,,,149.9906311,,,,
,32564563.365,149.9909668,-9438.0498046875,-4.49974283724927E-5,7.03650306247972E-7,1,0.999253354069792,40.0298881530762,1.99733626429169,20.4700008034706,-0.000511404784096293,-8.86675501078407E-5,0.25,3.65563605830001E-8,-4.52179274256413E-5,-3.52823160177427E-8,149.9909668,149.9909668,-9443.0849609375,-9433.0146484375,58.0640561795831,20.6054784251844,21.770052,0,0,0,40,4449,149.859,-9438.0498046875,,,,,,,,,,,,,0,,,,0,,,,,,149.9909668,,,,
,32564660.04,149.9919739,-4607.1416015625,-5.17427932192455E-5,4.52360106604914E-7,1,0.999253354069792,40.0298881530762,1.9976371403071,20.4700008034706,-0.000587512061568062,-0.000105642954250969,0.25,-2.80617985413306E-7,-5.19957877734807E-5,-3.64985759232438E-7,149.9919739,149.9919739,-4614.16943359375,-4600.11376953125,57.3871658819292,20.6038118354807,22.149702,0,0,0,40,4449,149.86345,-4607.1416015625,,,,,,,,,,,,,0,,,,-0.0049,,,,,,149.9919739,,,,
,32564754.46,149.9928436,114.546878814697,-4.70942901118714E-5,3.71485290194126E-7,1,0.999253354069792,40.0298881530762,1.99733526504736,20.4700008034706,-0.000534158816479224,-9.89766266148727E-5,0.25,-5.05073428496735E-7,-4.73241271868459E-5,-5.83201440073038E-7,149.9928436,149.9928436,109.621284484863,119.472473144531,57.8397287945638,20.6047219963129,22.149702,0,0,0,40,4449,149.869,114.546878814697,,,,,,,,,,,,,0,,,,0,,,,,,149.9928436,,,,
,32564849.35,149.996933,4853.68530273438,-2.13228534312108E-5,4.79540783487576E-7,1,0.999253354069792,40.0298881530762,1.99756269846284,20.4700008034706,-0.00024066938474715,-5.17510182229463E-5,0.25,-8.38741229219262E-7,-2.14259495747693E-5,-8.77044247625911E-7,149.996933,149.996933,4848.67333984375,4858.697265625,57.8194064530638,20.5990549038294,21.770052,0,0,0,40,4449,149.8712,4853.68530273438,,,,,,,,,,,,,0,,,,0.0049,,,,,,149.996933,,,,
,32564943.605,150.0000916,9564.626953125,1.20345123138833E-5,6.13598132238989E-7,1,0.999253354069792,40.0298881530762,1.99747623441138,20.4700008034706,0.000137744057322719,1.82035688564908E-5,0.25,-4.94803175610425E-7,1.20942584070935E-5,-4.7796981865089E-7,150.0000916,150.0000916,9557.09765625,9572.15625,57.677931691083,20.6003286384347,21.770052,0,0,0,40,4449,149.87285,9564.626953125,,,,,,,,,,,,,0,,,,-0.00245,,,,,,150.0000916,,,,
,32565040.095,150.0037994,14387.416015625,2.54980873756338E-5,9.73703651765446E-7,1,0.999253354069792,40.0298881530762,1.99748253558277,20.4700008034706,0.000290855054683834,4.42562024129698E-5,0.25,-5.47817008633082E-7,2.56238898420609E-5,-5.09796408005838E-7,150.0037994,150.0037994,14384.8056640625,14390.0263671875,57.4160861371407,20.6011593356705,21.3904,0,0,0,40,4449,149.8644,14387.416015625,,,,,,,,,,,,,0,,,,0,,,,,,150.0037994,,,,
,32565137.405,150.0075073,19252.26171875,1.94661385741388E-5,1.46924702681278E-6,1,0.999253354069792,40.0298881530762,1.99748759171647,20.4700008034706,0.000222376631501922,3.19101484731432E-5,0.25,-5.8328043168023E-7,1.9562457396387E-5,-5.55144054356422E-7,150.0075073,150.0075073,19247.11328125,19257.41015625,57.6099300099099,20.6008454572622,21.770052,0,0,0,40,4449,149.85985,19252.26171875,,,,,,,,,,,,,0,,,,-0.0049,,,,,,150.0075073,,,,
,32565236.2,150.0102081,24187.0126953125,5.79141201939724E-6,9.74752917889057E-7,1,0.999253354069792,40.0298881530762,1.99746699428629,20.4700008034706,6.80329104479739E-5,-1.26259706454301E-6,0.25,-1.11999145121111E-6,5.82157521571099E-6,-1.11628415984326E-6,150.0102081,150.0102081,24184.34765625,24189.677734375,58.1093906336985,20.601975321969,21.3904,0,0,0,40,4449,149.8461,24187.0126953125,,,,,,,,,,,,,0,,,,0,,,,,,150.0102081,,,,
,32565334.16,150.0097351,29085.173828125,-8.46243913714215E-6,1.13538417803285E-6,1,0.999253354069792,40.0298881530762,1.99744659114299,20.4700008034706,-9.2990067266656E-5,-3.50035482142255E-5,0.25,-1.60598770718024E-6,-8.5013805520064E-6,-1.62726012495014E-6,150.0097351,150.0097351,29077.8125,29092.53515625,57.5489629854099,20.6005350075076,22.149702,0,0,0,40,4449,149.84215,29085.173828125,,,,,,,,,,,,,0,,,,0,,,,,,150.0097351,,,,
,32565433.68,150.0106125,34060.291015625,-2.35992967697446E-5,1.93109324324643E-6,1,0.999253354069792,40.0298881530762,1.99735829975281,20.4700008034706,-0.000263032492604462,-7.62523957850325E-5,0.25,-2.59923185291063E-6,-2.37109040876375E-5,-2.64923512303353E-6,150.0104065,150.0108185,34050.05078125,34070.53125,57.8006473686023,20.602281600091,22.149702,0,0,0,40,4449,149.82855,34060.291015625,,,,,,,,,,,,,0,,,,0,,,,,,150.0106125,,,,
,32565532.19,150.008667,38982.724609375,-3.93708554923641E-5,1.56607321688003E-6,1,0.999253354069792,40.0298881530762,1.99728203742281,20.4700008034706,-0.000443734978609274,-9.88968982838057E-5,0.25,-1.84508411482886E-6,-3.9561035572864E-5,-1.91610437611306E-6,150.008667,150.008667,38977.890625,38987.55859375,57.4536043060638,20.6010782108367,21.770052,0,0,0,40,4449,149.8213,38982.724609375,,,,,,,,,,,,,0,,,,0.0049,,,,,,150.008667,,,,
,32565629.395,150.012207,43842.48828125,-5.44277992215857E-5,2.10362061941336E-6,1,0.999253354069792,40.0298881530762,1.99743517588892,20.4700008034706,-0.000611255685900513,-0.00014951066517458,0.25,-3.6756928501542E-6,-5.46890089720041E-5,-3.77913545848903E-6,150.012207,150.012207,43839.8203125,43845.15625,57.2738297466407,20.6019768540585,21.770052,0,0,0,40,4449,149.8116,43842.48828125,,,,,,,,,,,,,0,,,,0,,,,,,150.012207,,,,
,32565727.62,150.0106812,48750.791015625,-6.86790068163702E-5,1.88632367589045E-6,1,0.999253354069792,40.0298881530762,1.99732868626857,20.4700008034706,-0.000772078157351761,-0.000183990803924063,0.25,-4.22856285057903E-6,-6.90093493064223E-5,-4.35675199083312E-6,150.0106812,150.0106812,48743.15234375,48758.4296875,57.6818398336792,20.5981457918652,21.3904,0,0,0,40,4449,149.80015,48750.791015625,,,,,,,,,,,,,0,,,,0,,,,,,150.0106812,,,,
,32565826.34,150.0114136,53683.263671875,-8.58786939854949E-5,2.20288663117655E-6,1,0.999253354069792,40.0298881530762,1.99736972766503,20.4700008034706,-0.000965634480992049,-0.000229039939528107,0.25,-5.19702132007765E-6,-8.62920238550819E-5,-5.35644713624503E-6,150.0114136,150.0114136,53680.6953125,53685.83203125,57.5755383550638,20.5964959666171,21.770052,0,0,0,40,4449,149.7899,53683.263671875,,,,,,,,,,,,,0,,,,0,,,,,,150.0114136,,,,
,32565923.385,150.0125275,58536.294921875,-0.000104786390360022,2.15420111350629E-6,1,0.999253354069792,40.0298881530762,1.99738610174261,20.4700008034706,-0.00118227219297914,-0.000256356416129949,0.25,-4.30786359511896E-6,-0.000105294021447569,-4.49190002808759E-6,150.0125275,150.0125275,58529.046875,58543.54296875,57.2284952925253,20.6008365271911,21.770052,0,0,0,40,4449,149.777,58536.294921875,,,,,,,,,,,,,0,,,,0,,,,,,150.0125275,,,,
,32566023.64,150.0088348,63546.53515625,-0.000120427155910012,2.54083281838881E-6,1,0.999253354069792,40.0298881530762,1.99739718286513,20.4700008034706,-0.00135856297694706,-0.000295703778158766,0.25,-5.04660327011338E-6,-0.000121010582914108,-5.25795375596665E-6,150.0088348,150.0088348,63536.53125,63556.5390625,57.4270289364099,20.6009435396874,22.149702,0,0,0,40,4449,149.7712,63546.53515625,,,,,,,,,,,,,0,,,,0.00245,,,,,,150.0088348,,,,
,32566123.26,150.0132904,68526.4765625,-0.000138968056255738,2.77423009248867E-6,1,0.999253354069792,40.0298881530762,1.9973382563568,20.4700008034706,-0.00157124848031628,-0.000320755958569955,0.25,-4.02340209141933E-6,-0.000139644252156811,-4.25774147040244E-6,150.0132904,150.0132904,68518.90625,68534.046875,57.3246356003907,20.6025013952592,21.770052,0,0,0,40,4449,149.7578,68526.4765625,,,,,,,,,,,,,0,,,,0,,,,,,150.0132904,,,,
,32566221.245,150.0105591,73422.09765625,-0.00015714714010921,2.09041878917701E-6,1,0.999253354069792,40.0298881530762,1.9974052039693,20.4700008034706,-0.00177855054595097,-0.000352964606729679,0.25,-3.69142877790175E-6,-0.000157913321748091,-3.95139866237092E-6,150.0105591,150.0105591,73416.8125,73427.3828125,57.6294707228907,20.6021484397713,22.149702,0,0,0,40,4449,149.7496,73422.09765625,,,,,,,,,,,,,0,,,,0.00245,,,,,,150.0105591,,,,
,32566319.895,150.0096588,78355.0234375,-0.000170145636489088,3.10368719552572E-6,1,0.999253354069792,40.0298881530762,1.99736250780506,20.4700008034706,-0.00192611651495186,-0.000379343587866294,0.25,-3.75044747185808E-6,-0.000170975785857709,-4.02981890830922E-6,150.0096588,150.0096588,78349.8515625,78360.1953125,57.2394380917945,20.6015822929667,21.770052,0,0,0,40,4449,149.7421,78355.0234375,,,,,,,,,,,,,0,,,,0.0049,,,,,,150.0096588,,,,
,32566418.32,150.0101624,83273.546875,-0.000190169683001279,2.4415665962977E-6,1,0.999253354069792,40.0298881530762,1.99728979264528,20.4700008034706,-0.00214679010281253,-0.000458051038683735,0.25,-7.19165191420769E-6,-0.000191093176154558,-7.5176461313709E-6,150.0101624,150.0101624,83268.6171875,83278.4765625,57.444224763833,20.6002219031797,22.149702,0,0,0,40,4449,149.73325,83273.546875,,,,,,,,,,,,,0,,,,0,,,,,,150.0101624,,,,
,32566514.375,150.0106354,88076.4453125,-0.000208183903142413,2.30130654428382E-6,1,0.999253354069792,40.0298881530762,1.99734119140289,20.4700008034706,-0.00235212345926611,-0.000490465287143851,0.25,-6.90700249270999E-6,-0.000209196610714616,-7.25806419016692E-6,150.0106354,150.0106354,88071.40625,88081.484375,57.5833546402561,20.6011801387311,21.770052,0,0,0,40,4449,149.7239,88076.4453125,,,,,,,,,,,,,0,,,,0.0049,,,,,,150.0106354,,,,
,32566623.875,150.0074921,87453.421875,-0.00020558560567977,2.8384468006942E-6,1,0.999253354069792,40.0298881530762,1.99731058203359,20.4700008034706,-0.00232064676315112,-0.000496316536907879,0.25,-7.87483975804536E-6,-0.000206584045577297,-8.22686504506423E-6,150.0074921,150.0074921,87418.4375,87488.40625,57.3590272552368,20.5978331819596,21.770052,0,0,0,40,4449,149.71565,87453.421875,,,,,,,,,,,,,0,,,,0,,,,,,150.0074921,,,,
,32566720.405,149.9991302,82629.58984375,-0.000188942512389193,3.11526137541892E-6,1,0.999253354069792,40.0298881530762,1.99733837271647,20.4700008034706,-0.00213874147439669,-0.000422058647580799,0.25,-4.23699111982028E-6,-0.000189864509651884,-4.54676392191769E-6,149.9991302,149.9991302,82624.6484375,82634.53125,57.4074882234292,20.6016744980328,21.770052,0,0,0,40,4449,149.7186,82629.58984375,,,,,,,,,,,,,0,,,,0,,,,,,149.9991302,,,,
,32566818.36,149.9953918,77728.66015625,-0.000179497896270604,3.05695528659642E-6,1,0.999253354069792,40.0298881530762,1.99724386833252,20.4700008034706,-0.00203094095827545,-0.000405524073545148,0.25,-4.42741691513876E-6,-0.000180372986253412,-4.72462612427559E-6,149.9953918,149.9953918,77721.21875,77736.1015625,57.119067299833,20.5969888320644,22.529354,0,0,0,40,4449,149.7245,77728.66015625,,,,,,,,,,,,,0,,,,-0.00245,,,,,,149.9953918,,,,
,32566916.86,149.9933929,72807.2734375,-0.000157371385606356,2.49295070768444E-6,1,0.999253354069792,40.0298881530762,1.9973612448975,20.4700008034706,-0.00177599446810292,-0.000382499110817048,0.25,-6.25184621467905E-6,-0.000158134772277879,-6.52486698165463E-6,149.9933929,149.9933929,72802.171875,72812.375,57.2933704596215,20.6010680200751,22.149702,0,0,0,40,4449,149.73955,72807.2734375,,,,,,,,,,,,,0,,,,0,,,,,,149.9933929,,,,
,32567016.29,149.9905396,67837.1796875,-0.000139988144413036,2.9896785111628E-6,1,0.999253354069792,40.0298881530762,1.9973106837201,20.4700008034706,-0.00157691614356938,-0.000356671898168337,0.25,-7.00655479513506E-6,-0.000140664797090319,-7.25725735946155E-6,149.9905396,149.9905396,67829.859375,67844.5,57.6701154058907,20.5996002610278,22.149702,0,0,0,40,4449,149.74195,67837.1796875,,,,,,,,,,,,,0,,,,0,,,,,,149.9905396,,,,
,32567115.93,149.9901733,62856.4140625,-0.000120505046392968,2.82815285269158E-6,1,0.999253354069792,40.0298881530762,1.99723983467015,20.4700008034706,-0.00135894869060074,-0.000298118644308832,0.25,-5.24737939228355E-6,-0.000121088576510238,-5.4599607085665E-6,149.9901733,149.9901733,62851.27734375,62861.55078125,57.7091968318523,20.5952129652332,21.3904,0,0,0,40,4449,149.75185,62856.4140625,,,,,,,,,,,,,0,,,,0.0049,,,,,,149.9901733,,,,
,32567214.16,149.9922028,57945.76171875,-0.000103915705852234,2.25489648465395E-6,1,0.999253354069792,40.0298881530762,1.99728643473303,20.4700008034706,-0.00117609859844791,-0.000232939237690974,0.25,-2.39975200907241E-6,-0.000104422066913256,-2.57316318548375E-6,149.9922028,149.9922028,57938.22265625,57953.30078125,57.1753445532176,20.6003932843481,21.770052,0,0,0,40,4449,149.7586,57945.76171875,,,,,,,,,,,,,0,,,,0,,,,,,149.9922028,,,,
,32567313.325,149.9922333,52990.634765625,-8.53003488073326E-5,2.52947572837663E-6,1,0.999253354069792,40.0298881530762,1.99718493738902,20.4700008034706,-0.000965291541901467,-0.000191625721941988,0.25,-2.0067881806498E-6,-8.57158400312562E-5,-2.14974764123946E-6,149.9922333,149.9922333,52985.8828125,52995.38671875,57.5114448164869,20.5998491694411,22.149702,0,0,0,40,4449,149.7672,52990.634765625,,,,,,,,,,,,,0,,,,-0.0049,,,,,,149.9922333,,,,
,32567411.145,149.991806,48098.28125,-6.798937930775E-5,2.88110167521556E-6,1,0.999253354069792,40.0298881530762,1.99712285851263,20.4700008034706,-0.000771055620645332,-0.00014305614704147,0.25,-7.47614023215459E-7,-6.83218030833846E-5,-8.57721106877028E-7,149.991806,149.991806,48092.83203125,48103.73046875,57.9210181605638,20.5991448329362,21.770052,0,0,0,40,4449,149.7712,48098.28125,,,,,,,,,,,,,0,,,,0,,,,,,149.991806,,,,
,32567507.235,149.9923096,43297.974609375,-5.66682216779443E-5,1.76647573217319E-6,1,0.999253354069792,40.0298881530762,1.99722560700107,20.4700008034706,-0.000640700850659811,-0.000130690709014681,0.25,-1.6304710213114E-6,-5.69436486093791E-5,-1.72745406457296E-6,149.9923096,149.9923096,43295.24609375,43300.703125,57.6701154058907,20.6008245163534,21.770052,0,0,0,40,4449,149.78235,43297.974609375,,,,,,,,,,,,,0,,,,-0.0049,,,,,,149.9923096,,,,
,32567603.64,149.9890594,38479.947265625,-3.7421951409376E-5,1.89584570512641E-6,1,0.999253354069792,40.0298881530762,1.9973090078611,20.4700008034706,-0.000424374779632158,-7.90785033320079E-5,0.25,-4.40381726320567E-7,-3.76047968604355E-5,-5.01482414727672E-7,149.9890594,149.9890594,38472.76953125,38487.125,57.0463758475445,20.5976547055256,22.149702,0,0,0,40,4449,149.7891,38479.947265625,,,,,,,,,,,,,0,,,,0,,,,,,149.9890594,,,,
,32567698.655,149.9894867,33730.037109375,-2.06036617363012E-5,1.09703312314033E-6,1,0.999253354069792,40.0298881530762,1.99747049968897,20.4700008034706,-0.000233465233753034,-4.4710348089996E-5,0.25,-3.45169115150725E-7,-2.07041484112579E-5,-3.79406222704734E-7,149.9894867,149.9894867,33720.2109375,33739.86328125,57.7646924567176,20.5962461941258,22.149702,0,0,0,40,4449,149.80105,33730.037109375,,,,,,,,,,,,,0,,,,0.00245,,,,,,149.9894867,,,,
,32567797.265,149.991333,28800.404296875,-6.9506995328443E-6,1.40663964792013E-6,1,0.999253354069792,40.0298881530762,1.99740637568596,20.4700008034706,-7.78454334125016E-5,-2.03190298745375E-5,0.25,-5.77194398529402E-7,-6.98386115678962E-6,-5.91035251021984E-7,149.991333,149.991333,28792.873046875,28807.935546875,57.4567308201407,20.6008772958032,21.770052,0,0,0,40,4449,149.8102,28800.404296875,,,,,,,,,,,,,0,,,,-0.0049,,,,,,149.991333,,,,
,32567894.815,149.9896851,23927.6494140625,6.91977527254035E-6,1.05846151485039E-6,1,0.999253354069792,40.0298881530762,1.9972791064291,20.4700008034706,8.10754443762231E-5,-3.29793009619191E-7,0.25,-1.23448311782373E-6,6.95565438771489E-6,-1.22954107901686E-6,149.9896851,149.9896851,23920.177734375,23935.12109375,57.3613721407945,20.6007864937748,22.149702,0,0,0,40,4449,149.8182,23927.6494140625,,,,,,,,,,,,,0,,,,0,,,,,,149.9896851,,,,
,32567991.575,149.9904022,19090.28125,2.22496335285396E-5,1.02757529071529E-6,1,0.999253354069792,40.0298881530762,1.99735636731205,20.4700008034706,0.000254173343292891,3.63871957342857E-5,0.25,-6.74051747357807E-7,2.23597450013904E-5,-6.41914802773078E-7,149.9904022,149.9904022,19082.7578125,19097.8046875,57.6740235484869,20.6030184788559,22.149702,0,0,0,40,4449,149.82945,19090.28125,,,,,,,,,,,,,0,,,,0,,,,,,149.9904022,,,,
,32568085.345,149.99055485,14405.7133789062,3.39879055215733E-5,9.25799186220232E-7,1,0.999253354069792,40.0298881530762,1.99731591976595,20.4700008034706,0.000387104679904689,6.22154613877045E-5,0.25,-4.46125557004318E-7,3.41551513387153E-5,-3.94040005573288E-7,149.9904633,149.9906464,14400.671875,14410.7548828125,57.7029438036984,20.6010398239773,22.149702,0,0,0,40,4449,149.8371,14405.7133789062,,,,,,,,,,,,,0,,,,-0.0049,,,,,,149.99055485,,,,
,32568183.15,149.993576,9513.09716796875,4.50585485789599E-5,4.81111910972722E-7,1,0.999253354069792,40.0298881530762,1.99728989497856,20.4700008034706,0.000512540621919197,8.61881042014489E-5,0.25,-2.65236762232111E-7,4.52797077974405E-5,-1.94411451316423E-7,149.993576,149.993576,9507.9365234375,9518.2578125,57.9991810124869,20.6041171249251,22.149702,0,0,0,40,4449,149.8423,9513.09716796875,,,,,,,,,,,,,0,,,,0,,,,,,149.993576,,,,
,32568277.485,149.9918518,4800.37524414063,5.21127645837423E-5,5.04328126544822E-7,1,0.999253354069792,40.0298881530762,1.9972323493648,20.4700008034706,0.000592913202252109,9.88312913710275E-5,0.25,-3.81503244710791E-7,5.23686328060528E-5,-2.99781926226269E-7,149.9918518,149.9918518,4790.298828125,4810.45166015625,57.4020168237945,20.6043906872275,21.770052,0,0,0,40,4449,149.851,4800.37524414063,,,,,,,,,,,,,0,,,,-0.00245,,,,,,149.9918518,,,,
,32568372.29,149.9952393,61.3504257202148,4.80621672678392E-5,4.17668931655996E-7,1,0.999253354069792,40.0298881530762,1.99720275785386,20.4700008034706,0.00054597721484377,9.59820830418695E-5,0.25,7.3449256936502E-8,4.82974321641068E-5,1.51029752836156E-7,149.9952393,149.9952393,56.4731826782227,66.227668762207,57.6701154058907,20.6046787949219,22.149702,0,0,0,40,4449,149.8547,61.3504257202148,,,,,,,,,,,,,0,,,,0,,,,,,149.9952393,,,,
,32568374.425,149.9949951,-0.578503370285034,4.78347900578519E-5,3.55913056014733E-7,1,0.999253354069792,40.0298881530762,1.99716747919895,20.4700008034706,0.000544647983464899,8.82776999374291E-5,0.25,-5.64840864952022E-7,4.80699667644143E-5,-4.90749419804586E-7,149.9949951,149.9949951,-0.593727171421051,-0.563279569149017,57.7099784603715,20.6063015627452,22.529354,0,0,0,40,4417,149.8526,-0.578503370285034,,,,,,,,,,,,,0,,,,0,,,,,,149.9949951,,,,