File: data/doubleLayers/dl_1-25/ppms/data/DD205_3_FCC_100OE.DAT
[Header]
; VSM Data File (default extension .dat)
; Copyright (c) 2003-2013, Quantum Design, Inc. All rights reserved.
TITLE,
FILEOPENTIME,32472292.63,01/12/2019,4:07 am
BYAPP,VSM,2.0,2.0
INFO,PPMS VSM Option Release 1.4.10 Build 1,APPNAME
INFO,Quantum Design Linear Motor Servo Controller,MOTOR_MODULE_NAME
INFO,3101-100 M1,MOTOR_HW_VERSION
INFO,MMC1014,MOTOR_SERIAL_NUMBER
INFO,SRV No X-over 01.03.11,MOTOR_SOFTWARE_VERSION
INFO,Quantum Design VSM Detection Module,VSM_MODULE_NAME
INFO,3101-150 F0,VSM_HW_VERSION
INFO,VSM707,VSM_SERIAL_NUMBER
INFO,VSM No X-over 01.02.05 May 20 2008 13:51:47,VSM_SOFTWARE_VERSION
INFO,704,PREAMP_SERIAL_NUMBER
INFO,822,COIL_SERIAL_NUMBER
INFO,0,MOMENT_UNITS
INFO,DD205_4,SAMPLE_MATERIAL
INFO,Double Layer Blue 1.25,SAMPLE_COMMENT
INFO,26.73,SAMPLE_MASS
INFO,,SAMPLE_VOLUME
INFO,,SAMPLE_MOLECULAR_WEIGHT
INFO,,SAMPLE_SIZE
INFO,,SAMPLE_SHAPE
DATATYPE,COMMENT,1
DATATYPE,TIME,2
STARTUPAXIS,X,2
STARTUPAXIS,Y1,5
[Data]
Comment,Time Stamp (sec),Temperature (K),Magnetic Field (Oe),Moment (emu),M. Std. Err. (emu),Transport Action,Averaging Time (sec),Frequency (Hz),Peak Amplitude (mm),Center Position (mm),Coil Signal' (mV),Coil Signal" (mV),Range (mV),M. Quad. Signal (emu),M. Raw' (emu),M. Raw" (emu),Min. Temperature (K),Max. Temperature (K),Min. Field (Oe),Max. Field (Oe),Mass (grams),Motor Lag (deg),Pressure (Torr),VSM Status (code),Motor Status (code),Measure Status (code),Measure Count,PPMS Status (code),System Temp. (K),System Field (Oe),Sample Position (deg),Bridge 1 Resistance (ohms),Bridge 1 Excitation (에),Bridge 2 Resistance (ohms),Bridge 2 Excitation (에),Bridge 3 Resistance (ohms),Bridge 3 Excitation (에),Bridge 4 Resistance (ohms),Bridge 4 Excitation (에),Signal 1 Vin (V),Signal 2 Vin (V),Digital Inputs (code),Drive 1 Iout (mA),Drive 1 Ipower (W),Drive 2 Iout (mA),Drive 2 Ipower (W),Pressure (),Map 20 (),Map 21 (),Map 22 (),Map 23 (),Map 24 (),Map 25 (),Map 26 (),Map 27 (),Map 28 (),Map 29 ()
,32472430.98,349.5647278,99.7613830566406,1.34626378747545E-5,4.65948176066664E-7,1,0.999253354069792,40.0298881530762,1.9992726551914,19.4899998605251,0.000153034938409487,2.11640923137978E-5,0.25,-4.5827786112801E-7,1.34392225467206E-5,-4.4996976805633E-7,349.5647278,349.5647278,99.7613830566406,99.7613830566406,57.1722180391407,20.58079246068,23.288654,0,0,0,40,4369,350.317,99.7613830566406,,,,,,,,,,,,,0,,,,-0.0049,,,,,,349.5647278,,,,
,32472577.745,346.9953308,99.7613830566406,1.33256148642061E-5,5.75249603289514E-7,1,0.999253354069792,40.0298881530762,1.99929406908536,19.4899998605251,0.000151047522845561,2.35178546578061E-5,0.25,-2.26577257898178E-7,1.33034646302977E-5,-2.1866526601766E-7,346.9953308,346.9953308,99.7613830566406,99.7613830566406,57.3988903097176,20.5770716122828,22.909004,0,0,0,40,4374,345.39755,99.7613830566406,,,,,,,,,,,,,0,,,,0,,,,,,346.9953308,,,,
,32472729.265,343.4584045,99.7613830566406,1.33617240133812E-5,4.50921285421541E-7,1,0.999253354069792,40.0298881530762,1.99940148136269,19.4899998605251,0.000151413844102337,2.39838771238213E-5,0.25,-1.92049394856417E-7,1.33410980889315E-5,-1.84107309233695E-7,343.4584045,343.4584045,99.7613830566406,99.7613830566406,57.1862873524868,20.5796233734327,23.288654,0,0,0,40,4374,341.5036,99.7613830566406,,,,,,,,,,,,,0,,,,0,,,,,,343.4584045,,,,
,32472874.9,339.940155,99.7613830566406,1.41356779508722E-5,4.75482736822474E-7,1,0.999253354069792,40.0298881530762,1.99960328252417,19.4899998605251,0.000160495462050947,2.37817376997284E-5,0.25,-3.44509094347278E-7,1.41156376714861E-5,-3.35830062409263E-7,339.940155,339.940155,99.7613830566406,99.7613830566406,57.444224763833,20.5765602329177,23.288654,0,0,0,40,4374,337.6597,99.7613830566406,,,,,,,,,,,,,0,,,,-0.00245,,,,,,339.940155,,,,
,32473018.58,336.4997253,99.7613830566406,1.40977608718011E-5,5.16123743199143E-7,1,0.999253354069792,40.0298881530762,1.99956351356398,19.4600000977516,0.000159075530049954,2.95254438413479E-5,0.25,1.69714050002161E-7,1.40791405111607E-5,1.77753258664014E-7,336.4997253,336.4997253,99.7613830566406,99.7613830566406,57.1386080128137,20.5717067436787,22.909004,0,0,0,40,4374,333.9881,99.7613830566406,,,,,,,,,,,,,0,,,,-0.00245,,,,,,336.4997253,,,,
,32473139.43,333.4918213,99.7613830566406,1.39093380092377E-5,4.33233832538203E-7,1,0.999253354069792,40.0298881530762,1.99965436505057,19.4600000977516,0.00015783941875688,2.41295276333435E-5,0.25,-2.75258349286626E-7,1.38926708251522E-5,-2.66689264653106E-7,333.4918213,333.4918213,99.7613830566406,99.7613830566406,57.3269804859484,20.5724700034666,22.909004,0,0,0,40,4374,330.915,99.7613830566406,,,,,,,,,,,,,0,,,,-0.0049,,,,,,333.4918213,,,,
,32473283.445,329.9971924,99.7613830566406,1.48985252199398E-5,4.25797365125948E-7,1,0.999253354069792,40.0298881530762,1.9996797346081,19.4600000977516,0.000169199589136443,2.51990230417026E-5,0.25,-3.52410013725467E-7,1.48825134933618E-5,-3.43093599036102E-7,329.9971924,329.9971924,99.7613830566406,99.7613830566406,57.1753445532176,20.5721807609298,22.909004,0,0,0,40,4374,327.267,99.7613830566406,,,,,,,,,,,,,0,,,,0,,,,,,329.9971924,,,,
,32473427.155,326.4467468,99.7613830566406,1.44662626075238E-5,4.60899845733965E-7,1,0.999253354069792,40.0298881530762,2.00020146249729,19.4799993187189,0.000164406443606246,2.41611679022917E-5,0.25,-3.70211165927679E-7,1.44525232567865E-5,-3.6106953195477E-7,326.4467468,326.4467468,99.7613830566406,99.7613830566406,56.9588334533906,20.5583912609361,23.288654,0,0,0,40,4374,323.6494,99.7613830566406,,,,,,,,,,,,,0,,,,-0.00245,,,,,,326.4467468,,,,
,32473569.395,322.9414063,99.7613830566406,1.46825787465806E-5,4.94422525217719E-7,1,0.999253354069792,40.0298881530762,2.00063596616509,19.4799993187189,0.000165944170611087,3.01639314111638E-5,0.25,1.21857383412886E-7,1.46701302736974E-5,1.30786417990514E-7,322.9414063,322.9414063,99.7613830566406,99.7613830566406,57.0362146767945,20.5677588935425,23.288654,0,0,0,40,4374,320.04005,99.7613830566406,,,,,,,,,,,,,0,,,,0,,,,,,322.9414063,,,,
,32473710.47,319.4370117,99.7613830566406,1.51821263487722E-5,4.21736947642484E-7,1,0.999253354069792,40.0298881530762,2.00070190006891,19.4799993187189,0.00017146310581961,3.20813015884362E-5,0.25,2.04175125869567E-7,1.51710722380601E-5,2.13488862883683E-7,319.4370117,319.4370117,99.7613830566406,99.7613830566406,57.1980117802753,20.5584945613721,23.668306,0,0,0,40,4374,316.5017,99.7613830566406,,,,,,,,,,,,,0,,,,0,,,,,,319.4370117,,,,
,32473848.97,315.9908142,99.7613830566406,1.50557394788064E-5,5.38823591798343E-7,1,0.999253354069792,40.0298881530762,1.97455832472604,19.4899998605251,0.000168852382947136,2.61165274250728E-5,0.25,-2.72092045276976E-7,1.50469030556795E-5,-2.62424798635089E-7,315.9610901,316.0205383,99.7613830566406,99.7613830566406,57.0307432771599,20.5556241686109,23.668306,0,0,0,40,4374,313.02015,99.7613830566406,,,,,,,,,,,,,0,,,,0,,,,,,315.9908142,,,,
,32473991.555,312.4739075,99.7613830566406,1.49351448182835E-5,3.94217475214044E-7,1,0.999253354069792,40.0298881530762,1.97458690371943,19.4899998605251,0.000168186288644012,2.2082507296611E-5,0.25,-6.12423281689475E-7,1.4928456764127E-5,-6.02575704327069E-7,312.4739075,312.4739075,99.7613830566406,99.7613830566406,57.0369963053137,20.549855050155,23.288654,0,0,0,40,4374,309.4385,99.7613830566406,,,,,,,,,,,,,0,,,,0,,,,,,312.4739075,,,,
,32474131.11,308.9812927,99.7613830566406,1.5558404922288E-5,4.89145404723205E-7,1,0.999253354069792,40.0298881530762,1.97471362014239,19.4899998605251,0.00017348426963211,3.31276609076636E-5,0.25,2.66712950422021E-7,1.55527823002128E-5,2.76711585790835E-7,308.9812927,308.9812927,99.7613830566406,99.7613830566406,57.1690915250637,20.5518289686036,23.288654,0,0,0,40,4374,305.9217,99.7613830566406,,,,,,,,,,,,,0,,,,0,,,,,,308.9812927,,,,
,32474252.18,305.986084,99.7613830566406,1.60223281649155E-5,3.78861950686991E-7,1,0.999253354069792,40.0298881530762,1.97464796923026,19.5000004023314,0.000179008538458383,3.21672737993442E-5,0.25,1.00129561278415E-7,1.60183550271823E-5,1.10622042476966E-7,305.986084,305.986084,99.7613830566406,99.7613830566406,56.946327397083,20.554837182022,23.288654,0,0,0,40,4374,302.8932,99.7613830566406,,,,,,,,,,,,,0,,,,-0.0049,,,,,,305.986084,,,,
,32474393.73,302.4827271,99.7613830566406,1.59590776361117E-5,4.61729997534935E-7,1,0.999253354069792,40.0298881530762,1.97433911120377,19.5000004023314,0.000180218684093986,2.09508625338693E-5,0.25,-8.91863976060059E-7,1.59577693777976E-5,-8.81132574117014E-7,302.4827271,302.4827271,99.7613830566406,99.7613830566406,57.1346998702176,20.5606995641266,23.668306,0,0,0,40,4374,299.3177,99.7613830566406,,,,,,,,,,,,,0,,,,0,,,,,,302.4827271,,,,
,32474535.555,298.972641,99.7613830566406,1.62827429900994E-5,4.76230648743863E-7,1,0.999253354069792,40.0298881530762,1.97439476779871,19.5000004023314,0.000183328890396746,2.46852356159752E-5,0.25,-6.14539333076011E-7,1.62832555300208E-5,-6.03546026599281E-7,298.9454041,298.9998779,99.7613830566406,99.7613830566406,57.6888744903523,20.5564156941552,22.909004,0,0,0,40,4374,295.7619,99.7613830566406,,,,,,,,,,,,,0,,,,0,,,,,,298.972641,,,,
,32474656.005,295.9677429,99.7613830566406,1.6224919684441E-5,3.1005009384329E-7,1,0.999253354069792,40.0298881530762,1.97415922761341,19.5099990814924,0.000182543826533853,2.53641007079032E-5,0.25,-5.43951117473984E-7,1.62271299292178E-5,-5.32919016845909E-7,295.9677429,295.9677429,99.7613830566406,99.7613830566406,56.7259081546598,20.55233557752,22.909004,0,0,0,40,4374,292.7442,99.7613830566406,,,,,,,,,,,,,0,,,,0,,,,,,295.9677429,,,,
,32474796.245,292.475769,99.7613830566406,1.68693313422132E-5,3.96770277920888E-7,1,0.999253354069792,40.0298881530762,1.97425031283149,19.5099990814924,0.000188721027020135,3.2753068794249E-5,0.25,4.28671053872194E-9,1.68733458102389E-5,1.59908454871384E-8,292.475769,292.475769,99.7613830566406,99.7613830566406,57.5036285312945,20.5508419992728,23.668306,0,0,0,40,4374,289.22965,99.7613830566406,,,,,,,,,,,,,0,,,,0,,,,,,292.475769,,,,
,32474939.265,288.9396667,99.7613830566406,1.63845746720565E-5,3.95453909925179E-7,1,0.999253354069792,40.0298881530762,1.97348790419588,19.5099990814924,0.000183917269968126,2.79737293592223E-5,0.25,-3.38468908030922E-7,1.63907881626514E-5,-3.27053084223737E-7,288.9396667,288.9396667,99.7613830566406,99.7613830566406,57.2011382943522,20.5759138073632,23.668306,0,0,0,40,4374,285.63465,99.7613830566406,,,,,,,,,,,,,0,,,,0,,,,,,288.9396667,,,,
,32475077.4,285.4847717,99.7613830566406,1.69352042753324E-5,4.1436947400075E-7,1,0.999253354069792,40.0298881530762,1.99905385699173,19.5300001651049,0.000191046081165598,3.75106050054564E-5,0.25,3.77195323293348E-7,1.69432055787636E-5,3.89483048719627E-7,285.4847717,285.4847717,99.7613830566406,99.7613830566406,57.5919525539676,20.5800705580914,23.288654,0,0,0,40,4374,282.17375,99.7613830566406,,,,,,,,,,,,,0,,,,-0.0049,,,,,,285.4847717,,,,
,32475219.42,281.9960022,99.7613830566406,1.71024631159683E-5,4.15035648362467E-7,1,0.999253354069792,40.0298881530762,1.99903377897041,19.5300001651049,0.000193939538190146,3.22058050334018E-5,0.25,-1.2073401304402E-7,1.71130398224691E-5,-1.08396806484953E-7,281.9960022,281.9960022,99.7613830566406,99.7613830566406,57.2902439455445,20.5827465291145,22.909004,0,0,0,40,4374,278.6179,99.7613830566406,,,,,,,,,,,,,0,,,,0,,,,,,281.9960022,,,,
,32475341.24,278.9593506,99.7613830566406,1.74039451060343E-5,4.11444906257617E-7,1,0.999253354069792,40.0298881530762,1.99917395623879,19.5300001651049,0.000196838598583369,3.59775840306011E-5,0.25,1.59306746300451E-7,1.74163943736271E-5,1.72220593816038E-7,278.9593506,278.9593506,99.7613830566406,99.7613830566406,57.0776409883137,20.5808108769347,22.909004,0,0,0,40,4374,275.5655,99.7613830566406,,,,,,,,,,,,,0,,,,0,,,,,,278.9593506,,,,
touchdown = 14.7799998521805 mm,32475489.465,275.2219849,99.7613830566406,1.70595385287297E-5,3.72431530784024E-7,1,0.999253354069792,40.0298881530762,1.99900559297501,19.5599999278784,0.000194356523865758,2.71744527628755E-5,0.25,-5.58444547273108E-7,1.70745559748735E-5,-5.46170121935596E-7,275.2219849,275.2219849,99.7613830566406,99.7613830566406,56.983845566006,20.5803618694275,23.668306,0,0,0,40,4374,271.8516,99.7613830566406,,,,,,,,,,,,,0,,,,0,,,,,,275.2219849,,,,
,32475620.59,271.964447,99.7613830566406,1.73410698105965E-5,4.84226186980764E-7,1,0.999253354069792,40.0298881530762,1.99909142958941,19.5599999278784,0.000196693650161059,3.28273895639576E-5,0.25,-1.08892967669355E-7,1.73580136100612E-5,-9.58454070321905E-8,271.964447,271.964447,99.7613830566406,99.7613830566406,57.3058765159291,20.5813833396783,23.668306,0,0,0,40,4374,268.57655,99.7613830566406,,,,,,,,,,,,,0,,,,-0.00245,,,,,,271.964447,,,,
,32475762.075,268.4728394,99.7613830566406,1.7198550260288E-5,3.65304448741915E-7,1,0.999253354069792,40.0298881530762,1.99925943487436,19.5599999278784,0.000194557231003776,3.57934386148134E-5,0.25,1.76739112372707E-7,1.72172817664193E-5,1.9018831742121E-7,268.4728394,268.4728394,99.7613830566406,99.7613830566406,57.0119841926983,20.5825531845117,23.288654,0,0,0,40,4374,265.03815,99.7613830566406,,,,,,,,,,,,,0,,,,-0.00245,,,,,,268.4728394,,,,
touchdown = 14.8000000044703 mm,32475907.985,264.811676,99.7613830566406,1.73976189562363E-5,3.66655048347267E-7,1,0.999253354069792,40.0298881530762,1.99921123794787,19.5799991488457,0.000196751316014728,3.6667189638662E-5,0.25,2.18756057418733E-7,1.74188058045891E-5,2.3265938327892E-7,264.811676,264.811676,99.7613830566406,99.7613830566406,57.0971817012945,20.5847250868948,23.288654,0,0,0,40,4374,261.3828,99.7613830566406,,,,,,,,,,,,,0,,,,-0.0049,,,,,,264.811676,,,,
,32476042.39,261.467804,99.7613830566406,1.82460905457041E-5,4.74801929973191E-7,1,0.999253354069792,40.0298881530762,1.99926139353499,19.5799991488457,0.000206586954296919,3.72455211576997E-5,0.25,1.21982339799353E-7,1.82705658068618E-5,1.36669531652219E-7,261.467804,261.467804,99.7613830566406,99.7613830566406,57.2144259791791,20.5875901232463,23.668306,0,0,0,40,4374,258.0401,99.7613830566406,,,,,,,,,,,,,0,,,,0.0049,,,,,,261.467804,,,,
,32476180.895,257.9921265,99.7613830566406,1.81918656623663E-5,3.6603660005033E-7,1,0.999253354069792,40.0298881530762,1.99934108049148,19.5799991488457,0.000206628925288801,3.35498933336755E-5,0.25,-1.95354871015537E-7,1.82187695315339E-5,-1.80924015730511E-7,257.9921265,257.9921265,99.7613830566406,99.7613830566406,57.2277136640061,20.5871118587879,23.288654,0,0,0,40,4374,254.56225,99.7613830566406,,,,,,,,,,,,,0,,,,-0.00245,,,,,,257.9921265,,,,
touchdown = 14.8299997672439 mm,32476323.97,254.4420776,99.7613830566406,1.85701995124101E-5,3.45106875503117E-7,1,0.999253354069792,40.0298881530762,1.99932960776218,19.6100007742643,0.00021144580324996,3.14016614503218E-5,0.25,-4.51035764947125E-7,1.86002087896951E-5,-4.36473685810787E-7,254.4420776,254.4420776,99.7613830566406,99.7613830566406,57.0002597649099,20.5802507713354,23.288654,0,0,0,40,4374,250.9874,99.7613830566406,,,,,,,,,,,,,0,,,,0,,,,,,254.4420776,,,,
,32476462.57,250.9729309,99.7613830566406,1.86569642170228E-5,4.16669018750837E-7,1,0.999253354069792,40.0298881530762,1.99936764176195,19.6100007742643,0.000212699839541849,3.01910676783136E-5,0.25,-5.73482924105497E-7,1.86895076545399E-5,-5.58856309295619E-7,250.9729309,250.9729309,99.7613830566406,99.7613830566406,57.1761261817368,20.5807045212098,24.047956,0,0,0,40,4374,247.5237,99.7613830566406,,,,,,,,,,,,,0,,,,0,,,,,,250.9729309,,,,
,32476603.865,247.4509125,99.7613830566406,1.87901929241748E-5,3.95054961811686E-7,1,0.999253354069792,40.0298881530762,1.99929597877842,19.6100007742643,0.00021316509453676,3.65950828616051E-5,0.25,-3.24288781633786E-8,1.88248434559588E-5,-1.64898118339815E-8,247.4509125,247.4509125,99.7613830566406,99.7613830566406,57.2011382943522,20.5839717583533,23.668306,0,0,0,40,4374,243.9818,99.7613830566406,,,,,,,,,,,,,0,,,,0,,,,,,247.4509125,,,,
touchdown = 14.8700000718236 mm,32476741.14,243.9888306,99.7613830566406,1.83699468630681E-5,3.65219983955818E-7,1,0.999253354069792,40.0298881530762,1.99925272711301,19.6499992161989,0.000208747823607238,3.388229848192E-5,0.25,-1.99303074402109E-7,1.84061998046163E-5,-1.83785051902206E-7,243.9888306,243.9888306,99.7613830566406,99.7613830566406,57.139389641333,20.5800489751482,23.668306,0,0,0,40,4374,240.5591,99.7613830566406,,,,,,,,,,,,,0,,,,0.00245,,,,,,243.9888306,,,,
,32476880.77,240.4976654,99.7613830566406,1.83965120476628E-5,4.73636368410318E-7,1,0.999253354069792,40.0298881530762,1.99924998237479,19.6499992161989,0.000208513273150426,3.71728314944277E-5,0.25,8.55268974213684E-8,1.84348133139353E-5,1.01921733634329E-7,240.4976654,240.4976654,99.7613830566406,99.7613830566406,57.65057469291,20.586583464386,23.288654,0,0,0,40,4374,237.0607,99.7613830566406,,,,,,,,,,,,,0,,,,0,,,,,,240.4976654,,,,
,32477021.055,236.9903717,99.7613830566406,1.82041981174279E-5,3.94523572880602E-7,1,0.999253354069792,40.0298881530762,1.99932230875712,19.6499992161989,0.000207121378323863,3.24347136459794E-5,0.25,-2.99539792548537E-7,1.82446633453241E-5,-2.83862528852094E-7,236.9903717,236.9903717,99.7613830566406,99.7613830566406,57.3058765159291,20.5801213108605,23.668306,0,0,0,40,4374,233.5496,99.7613830566406,,,,,,,,,,,,,0,,,,0,,,,,,236.9903717,,,,
touchdown = 14.8999998345971 mm,32477158.55,233.5467682,99.7613830566406,1.87938868937333E-5,3.02783273903809E-7,1,0.999253354069792,40.0298881530762,1.99914512998166,19.6800008416176,0.000214206296040192,3.13643889155151E-5,0.25,-4.96590509443452E-7,1.88380794051214E-5,-4.80572709323453E-7,233.5467682,233.5467682,99.7613830566406,99.7613830566406,56.8626931455252,20.5798255358881,23.668306,0,0,0,40,4374,230.1095,99.7613830566406,,,,,,,,,,,,,0,,,,-0.00245,,,,,,233.5467682,,,,
,32477282.195,230.4816284,99.7613830566406,1.90798733335018E-5,4.05369230521082E-7,1,0.999253354069792,40.0298881530762,1.99912915491147,19.6800008416176,0.000216132904706289,3.9649143006962E-5,0.25,1.83374535710608E-7,1.91261213146476E-5,2.01543678997148E-7,230.4816284,230.4816284,99.7613830566406,99.7613830566406,57.0799858738714,20.5850593651425,22.909004,0,0,0,40,4374,227.019,99.7613830566406,,,,,,,,,,,,,0,,,,-0.0049,,,,,,230.4816284,,,,
,32477423.635,226.9446259,99.7613830566406,1.86417899354498E-5,3.86128960219085E-7,1,0.999253354069792,40.0298881530762,1.99900839612577,19.6800008416176,0.000211798244125922,3.52002025030657E-5,0.25,-1.33222280774985E-7,1.86895272407837E-5,-1.15912597355695E-7,226.9446259,226.9446259,99.7613830566406,99.7613830566406,57.1659650109868,20.5876604998327,23.288654,0,0,0,40,4374,223.481,99.7613830566406,,,,,,,,,,,,,0,,,,0.00245,,,,,,226.9446259,,,,
,32477561.89,223.5247345,99.7613830566406,,,2,,,,19.7300001391768,,,,,,,223.5247345,223.5247345,99.7613830566406,99.7613830566406,,,23.288654,,,,-99999999,4374,220.0287,99.7613830566406,,,,,,,,,,,,,,,,,,,,,,,223.5247345,,,,
,32477680.68,220.4994812,99.7613830566406,1.8929298532153E-5,3.84659432884795E-7,1,0.999253354069792,40.0298881530762,1.99875976850863,19.7199992835522,0.000214833458174455,3.72028443360777E-5,0.25,-7.60566912740278E-9,1.89817931736976E-5,1.09457210894739E-8,220.4994812,220.4994812,99.7613830566406,99.7613830566406,57.0971817012945,20.5878700091868,22.909004,0,0,0,40,4374,217.0551,99.7613830566406,,,,,,,,,,,,,0,,,,-0.00245,,,,,,220.4994812,,,,
,32477823.385,216.9453278,99.7613830566406,1.85675861017094E-5,3.24224736318071E-7,1,0.999253354069792,40.0298881530762,1.99881381276696,19.7199992835522,0.000211000739693891,3.5103832441035E-5,0.25,-1.30596382651019E-7,1.86214190011797E-5,-1.1238362472963E-7,216.9453278,216.9453278,99.7613830566406,99.7613830566406,57.1620568683907,20.5863773581386,22.909004,0,0,0,40,4374,213.5056,99.7613830566406,,,,,,,,,,,,,0,,,,0,,,,,,216.9453278,,,,
,32477976.11,213.1535645,99.7613830566406,,,2,,,,19.7599999019504,,,,,,,213.1535645,213.1535645,99.7613830566406,99.7613830566406,,,23.668306,,,,-99999999,4374,209.6979,99.7613830566406,,,,,,,,,,,,,,,,,,,,,,,213.1535645,,,,
,32478100.555,209.9671021,99.7613830566406,1.89326347326776E-5,3.37088282391258E-7,1,0.999253354069792,40.0298881530762,1.99839161478429,19.7500009089708,0.000215064117267201,3.63216151790821E-5,0.25,-8.75558005753026E-8,1.89918729631892E-5,-6.80836736545395E-8,209.9671021,209.9671021,99.7613830566406,99.7613830566406,57.2316218066022,20.5896771997837,23.288654,0,0,0,40,4374,206.5827,99.7613830566406,,,,,,,,,,,,,0,,,,0.00245,,,,,,209.9671021,,,,
,32478241.205,206.4670563,99.7613830566406,1.88518049837977E-5,3.56679632045481E-7,1,0.999253354069792,40.0298881530762,1.99837903664797,19.7500009089708,0.000214189992872613,3.60505893122954E-5,0.25,-9.81655561993625E-8,1.89129671222949E-5,-7.83957736215447E-8,206.4670563,206.4670563,99.7613830566406,99.7613830566406,57.190195495083,20.5929252621955,22.909004,0,0,0,40,4374,203.06405,99.7613830566406,,,,,,,,,,,,,0,,,,0,,,,,,206.4670563,,,,
,32478390.03,202.7747192,99.7613830566406,,,2,,,,19.8099998170137,,,,,,,202.7747192,202.7747192,99.7613830566406,99.7613830566406,,,23.288654,,,,-99999999,4374,199.3541,99.7613830566406,,,,,,,,,,,,,,,,,,,,,,,202.7747192,,,,
,32478520.905,199.4953308,99.7613830566406,1.90331449426613E-5,3.43821150589011E-7,1,0.999253354069792,40.0298881530762,1.99843610035782,19.7999998927116,0.000217519870128533,2.94124767029354E-5,0.25,-7.16003815669672E-7,1.90998754773329E-5,-6.97286984005671E-7,199.4953308,199.4953308,99.7613830566406,99.7613830566406,57.2167708647368,20.5922265751699,23.668306,0,0,0,40,4374,196.075,99.7613830566406,,,,,,,,,,,,,0,,,,0,,,,,,199.4953308,,,,
,32478660.205,195.9667511,99.7613830566406,1.84556938476478E-5,3.1528910235809E-7,1,0.999253354069792,40.0298881530762,1.99844712515313,19.7999998927116,0.000210712753158749,2.98625415010281E-5,0.25,-5.76833454218153E-7,1.85223564792729E-5,-5.57866477571143E-7,195.9667511,195.9667511,99.7613830566406,99.7613830566406,57.3160376866791,20.592018366596,23.288654,0,0,0,40,4374,192.5884,99.7613830566406,,,,,,,,,,,,,0,,,,0,,,,,,195.9667511,,,,
,32478806.41,192.3428955,99.7613830566406,,,2,,,,19.8500001215935,,,,,,,192.3428955,192.3428955,99.7613830566406,99.7613830566406,,,23.288654,,,,-99999999,4374,188.9292,99.7613830566406,,,,,,,,,,,,,,,,,,,,,,,192.3428955,,,,
,32478939.5,188.9994812,99.7613830566406,1.91129203841459E-5,3.36321547644877E-7,1,0.999253354069792,40.0298881530762,1.99843398128444,19.8400001972914,0.000217393329592055,3.59352809996354E-5,0.25,-1.57967864416762E-7,1.91856266278259E-5,-1.35722781792942E-7,188.9994812,188.9994812,99.7613830566406,99.7613830566406,56.9174071418714,20.5903545204832,22.909004,0,0,0,40,4374,185.5981,99.7613830566406,,,,,,,,,,,,,0,,,,0,,,,,,188.9994812,,,,
,32479079.175,185.4902802,99.7613830566406,1.86784565648294E-5,3.63308964413699E-7,1,0.999253354069792,40.0298881530762,1.99825308401543,19.8400001972914,0.000213222154928262,3.07126425609006E-5,0.25,-5.42898865178939E-7,1.87520008616996E-5,-5.22131132996925E-7,185.4902802,185.4902802,99.7613830566406,99.7613830566406,56.9134989992753,20.5927303591369,22.529354,0,0,0,40,4374,182.11545,99.7613830566406,,,,,,,,,,,,,0,,,,0,,,,,,185.4902802,,,,
,32479224.7,181.9587555,99.7613830566406,,,2,,,,19.9000000366569,,,,,,,181.9587555,181.9587555,99.7613830566406,99.7613830566406,,,23.288654,,,,-99999999,4374,178.4657,99.7613830566406,,,,,,,,,,,,,,,,,,,,,,,181.9587555,,,,
,32479360.135,178.4698944,99.7613830566406,1.90985996896419E-5,3.93278893696417E-7,1,0.999253354069792,40.0298881530762,1.99834876335267,19.8899991810322,0.000217750817962372,3.32721538888682E-5,0.25,-3.92587814727518E-7,1.91776458642503E-5,-3.69541893525664E-7,178.4698944,178.4698944,99.7613830566406,99.7613830566406,57.1675282680253,20.5933846632783,22.909004,0,0,0,40,4374,175.0749,99.7613830566406,,,,,,,,,,,,,0,,,,-0.00245,,,,,,178.4698944,,,,
,32479481.185,175.4392853,99.7613830566406,1.84893918484758E-5,3.26733604171913E-7,1,0.999253354069792,40.0298881530762,1.99791855948792,19.8899991810322,0.000210022613714356,3.65643422686141E-5,0.25,2.95640515317212E-9,1.85670654003272E-5,2.74062892354232E-8,175.4392853,175.4392853,99.7613830566406,99.7613830566406,57.0260535060445,20.5987179417958,22.909004,0,0,0,40,4374,172.0748,99.7613830566406,,,,,,,,,,,,,0,,,,0.0049,,,,,,175.4392853,,,,
,32479618.125,171.9812012,99.7613830566406,1.87852457729667E-5,4.23268614374407E-7,1,0.999253354069792,40.0298881530762,1.99818283319808,19.8899991810322,0.000213081641717597,3.91683070616458E-5,0.25,1.79275857327614E-7,1.88657982784865E-5,2.05560064658642E-7,171.9812012,171.9812012,99.7613830566406,99.7613830566406,57.3871658819292,20.5923935895989,22.529354,0,0,0,40,4374,168.6778,99.7613830566406,,,,,,,,,,,,,0,,,,-0.0049,,,,,,171.9812012,,,,
,32479738.29,168.9530792,99.7613830566406,1.85768985615598E-5,3.43130888877629E-7,1,0.999253354069792,40.0298881530762,1.99823039052192,19.9400000274181,0.000211304454370976,3.5500494390845E-5,0.25,-1.08259569424188E-7,1.86585446433139E-5,-8.28737795411146E-8,168.9530792,168.9530792,99.7613830566406,99.7613830566406,57.0315249056791,20.5942638081694,22.909004,0,0,0,40,4374,165.68485,99.7613830566406,,,,,,,,,,,,,0,,,,0,,,,,,168.9530792,,,,
,32479877.165,165.4417725,99.7613830566406,1.83146582171447E-5,3.38994597555907E-7,1,0.999253354069792,40.0298881530762,1.99818312797031,19.9400000274181,0.000208919850324114,3.16544032478782E-5,0.25,-4.02067291384771E-7,1.83973699341108E-5,-3.77614701743805E-7,165.4417725,165.4417725,99.7613830566406,99.7613830566406,57.4567308201407,20.5988391139668,22.529354,0,0,0,40,4374,162.2304,99.7613830566406,,,,,,,,,,,,,0,,,,-0.0049,,,,,,165.4417725,,,,
,32480018.075,161.9412384,99.7613830566406,1.849579589614E-5,3.26198914719255E-7,1,0.999253354069792,40.0298881530762,1.9983910305566,19.9400000274181,0.000210380324110092,3.56899566444322E-5,0.25,-7.99045994721715E-8,1.85806220118525E-5,-5.29254262073067E-8,161.9412384,161.9412384,99.7613830566406,99.7613830566406,57.2253687784484,20.5973965594009,22.529354,0,0,0,40,4374,158.7273,99.7613830566406,,,,,,,,,,,,,0,,,,0,,,,,,161.9412384,,,,
,32480156.67,158.4845886,99.7613830566406,1.86279742314687E-5,3.01427913979965E-7,1,0.999253354069792,40.0298881530762,1.99839231546967,19.9999995529652,0.000212211317134917,3.41796573613562E-5,0.25,-2.36948683312491E-7,1.87153576660416E-5,-2.09633515616089E-7,158.4845886,158.4845886,99.7613830566406,99.7613830566406,57.139389641333,20.5927530049978,22.909004,0,0,0,40,4374,155.26715,99.7613830566406,,,,,,,,,,,,,0,,,,-0.00245,,,,,,158.4845886,,,,
,32480293.41,154.9887695,99.7613830566406,1.84993111952948E-5,2.9837411658855E-7,1,0.999253354069792,40.0298881530762,1.9984381894647,19.9999995529652,0.000210833959650087,3.35765248031452E-5,0.25,-2.68850344597198E-7,1.85878321973328E-5,-2.4098491643905E-7,154.9887695,154.9887695,99.7613830566406,99.7613830566406,57.2183341217753,20.5929981740875,22.149702,0,0,0,40,4374,151.8661,99.7613830566406,,,,,,,,,,,,,0,,,,0,,,,,,154.9887695,,,,
,32480435.39,151.4438477,99.7613830566406,1.85026382584413E-5,3.49433580755642E-7,1,0.999253354069792,40.0298881530762,1.99843488533987,19.9999995529652,0.000210071031783415,3.82878304978118E-5,0.25,1.43695511568496E-7,1.85921632822105E-5,1.74566895993357E-7,151.4438477,151.4438477,99.7613830566406,99.7613830566406,57.1346998702176,20.594329900807,22.149702,0,0,0,40,4374,148.337,99.7613830566406,,,,,,,,,,,,,0,,,,-0.0049,,,,,,151.4438477,,,,
,32480571.865,147.9980621,99.7613830566406,1.8461685886981E-5,4.15895713468746E-7,1,0.999253354069792,40.0298881530762,1.9982787480131,20.0599990785122,0.000210319517058834,3.41205528929437E-5,0.25,-2.16796325253132E-7,1.85531589570427E-5,-1.86700889634237E-7,147.9980621,147.9980621,99.7613830566406,99.7613830566406,57.0127658212176,20.5883425291666,22.149702,0,0,0,40,4374,144.93285,99.7613830566406,,,,,,,,,,,,,0,,,,0.00245,,,,,,147.9980621,,,,
,32480713.07,144.4761047,99.7613830566406,1.86486419723616E-5,3.69912743241102E-7,1,0.999253354069792,40.0298881530762,1.9984856050612,20.0599990785122,0.000212032463677039,3.70843916552992E-5,0.25,9.54068204410192E-9,1.87421899846794E-5,4.22596354586044E-8,144.4761047,144.4761047,99.7613830566406,99.7613830566406,57.4067065949099,20.5953333531967,21.770052,0,0,0,40,4374,141.40955,99.7613830566406,,,,,,,,,,,,,0,,,,0,,,,,,144.4761047,,,,
,32480852.165,140.9558716,99.7613830566406,1.86461001906864E-5,2.82534474128159E-7,1,0.999253354069792,40.0298881530762,1.99845405914899,20.0599990785122,0.00021159885447808,3.94791377221084E-5,0.25,2.19113168224746E-7,1.87407277655964E-5,2.54160998312888E-7,140.9558716,140.9558716,99.7613830566406,99.7613830566406,57.1839424669291,20.5976192641344,22.149702,0,0,0,40,4374,137.94075,99.7613830566406,,,,,,,,,,,,,0,,,,-0.0049,,,,,,140.9558716,,,,
,32480992.405,137.4554901,99.7613830566406,1.83809899627806E-5,3.29256388016511E-7,1,0.999253354069792,40.0298881530762,1.99829501136483,20.1099999248981,0.000209149144250238,3.57128799748841E-5,0.25,-6.71858568755646E-8,1.84761647572153E-5,-3.27282613558935E-8,137.4554901,137.4554901,99.7613830566406,99.7613830566406,57.4481329064291,20.5942777740701,22.149702,0,0,0,40,4374,134.4503,99.7613830566406,,,,,,,,,,,,,0,,,,0.0049,,,,,,137.4554901,,,,
,32481129.64,133.9862976,99.7613830566406,1.78880475147983E-5,3.59099873724052E-7,1,0.999253354069792,40.0298881530762,1.99831956122037,20.1099999248981,0.000203732251172722,3.37533975049544E-5,0.25,-1.55111198641876E-7,1.79821070795189E-5,-1.20653298583311E-7,133.9862976,133.9862976,99.7613830566406,99.7613830566406,57.9092937327753,20.6019313236436,22.149702,0,0,0,40,4374,131.03405,99.7613830566406,,,,,,,,,,,,,0,,,,0,,,,,,133.9862976,,,,
,32481269.515,130.4652252,99.7613830566406,1.82959705119027E-5,2.8124858428204E-7,1,0.999253354069792,40.0298881530762,1.99831132926041,20.1099999248981,0.000207943992594795,3.70864594983582E-5,0.25,6.49896333781694E-8,1.83929474875578E-5,1.029862107611E-7,130.4652252,130.4652252,99.7613830566406,99.7613830566406,57.1370447557753,20.5911791176684,21.3904,0,0,0,40,4374,127.5669,99.7613830566406,,,,,,,,,,,,,0,,,,-0.0049,,,,,,130.4652252,,,,
,32481408.805,126.9802628,99.7613830566406,1.86491159766797E-5,3.49315860889765E-7,1,0.999253354069792,40.0298881530762,1.99841802793024,20.1799999922514,0.000212248693441545,3.62762049124568E-5,0.25,-7.0039459506736E-8,1.87493808833367E-5,-3.02881788808777E-8,126.9802628,126.9802628,99.7613830566406,99.7613830566406,57.2191157502945,20.6038075713662,21.3904,0,0,0,40,4374,124.1003,99.7613830566406,,,,,,,,,,,,,0,,,,0.0049,,,,,,126.9802628,,,,
,32481546.53,123.4858322,99.7613830566406,1.85802874679625E-5,3.14912133921303E-7,1,0.999253354069792,40.0298881530762,1.99823862074165,20.1799999922514,0.000211446423886156,3.62132036208735E-5,0.25,-6.53151445459786E-8,1.86812089562133E-5,-2.38160082973587E-8,123.4858322,123.4858322,99.7613830566406,99.7613830566406,57.5997688391599,20.6079380688168,21.770052,0,0,0,40,4374,120.68135,99.7613830566406,,,,,,,,,,,,,0,,,,-0.00245,,,,,,123.4858322,,,,
,32481685.345,119.9960632,99.7613830566406,1.83978192512023E-5,3.44920844522963E-7,1,0.999253354069792,40.0298881530762,1.99826020714431,20.1799999922514,0.000209025732561579,3.78973379894298E-5,0.25,1.12454922838518E-7,1.84982317425756E-5,1.56552429080714E-7,119.9960632,119.9960632,99.7613830566406,99.7613830566406,57.5106631879676,20.605748008585,21.3904,0,0,0,40,4374,117.24285,99.7613830566406,,,,,,,,,,,,,0,,,,0,,,,,,119.9960632,,,,
,32481804.195,116.9870758,99.7613830566406,1.87513779099596E-5,3.22275755550285E-7,1,0.999253354069792,40.0298881530762,1.99821180921075,20.2399995177984,0.000213568011025667,3.56408750859817E-5,0.25,-1.49788928803643E-7,1.88550349394939E-5,-1.04350128941897E-7,116.9870758,116.9870758,99.7613830566406,99.7613830566406,57.6216544376984,20.6078747547913,21.770052,0,0,0,40,4374,114.28615,99.7613830566406,,,,,,,,,,,,,0,,,,0,,,,,,116.9870758,,,,
,32481943.105,113.470787,99.7613830566406,1.8676490782676E-5,3.12996280001197E-7,1,0.999253354069792,40.0298881530762,1.99785723925101,20.2399995177984,0.000212881593684742,3.43807378073682E-5,0.25,-2.49524115555915E-7,1.87806487283076E-5,-2.02356765771582E-7,113.470787,113.470787,99.7613830566406,99.7613830566406,57.1941036376791,20.606378643706,21.3904,0,0,0,40,4374,110.83275,99.7613830566406,,,,,,,,,,,,,0,,,,0.0049,,,,,,113.470787,,,,
,32482083.14,109.9830322,99.7613830566406,1.86121296442324E-5,3.20754625940436E-7,1,0.999253354069792,40.0298881530762,1.99784144278829,20.2399995177984,0.000212322413226763,3.32897161675885E-5,0.25,-3.36946051886692E-7,1.87166358053911E-5,-2.87717528573013E-7,109.9830322,109.9830322,99.7613830566406,99.7613830566406,57.2878990599868,20.6135363212889,21.01075,0,0,0,40,4374,107.3692,99.7613830566406,,,,,,,,,,,,,0,,,,0,,,,,,109.9830322,,,,
,32482222.575,106.4501343,99.7613830566406,1.86978967858909E-5,3.59616562108685E-7,1,0.999253354069792,40.0298881530762,1.99746491272511,20.3099995851517,0.00021238281536283,3.84670430770087E-5,0.25,1.00870439823638E-7,1.88018895136032E-5,1.55783566438716E-7,106.4501343,106.4501343,99.7613830566406,99.7613830566406,57.2433462343907,20.618777156413,21.01075,0,0,0,40,4374,103.9138,99.7613830566406,,,,,,,,,,,,,0,,,,-0.0049,,,,,,106.4501343,,,,
,32482360.005,102.9557495,99.7613830566406,1.88185826293965E-5,3.05734366396199E-7,1,0.999253354069792,40.0298881530762,1.99722887138769,20.3099995851517,0.000214125340538727,3.64558501857877E-5,0.25,-1.00138502372546E-7,1.89238153252925E-5,-4.26873864783958E-8,102.9557495,102.9557495,99.7613830566406,99.7613830566406,57.9397772450254,20.6127822504989,21.01075,0,0,0,40,4374,100.5035,99.7613830566406,,,,,,,,,,,,,0,,,,0,,,,,,102.9557495,,,,
,32482498.61,99.4520187,99.7613830566406,1.82464757300572E-5,3.33172883230583E-7,1,0.999253354069792,40.0298881530762,1.9971801131836,20.3099995851517,0.000208126819179211,3.23922312808487E-5,0.25,-3.60538936993073E-7,1.83490329050698E-5,-3.02697971552981E-7,99.4520187,99.4520187,99.7613830566406,99.7613830566406,57.2769562607176,20.6129393411253,20.631098,0,0,0,40,4374,97.0477,99.7613830566406,,,,,,,,,,,,,0,,,,-0.00245,,,,,,99.4520187,,,,
,32482637.285,95.964653,99.7613830566406,1.86392168366313E-5,3.57112452859925E-7,1,0.999253354069792,40.0298881530762,1.99684199662487,20.3799996525049,0.000212157301056862,3.53964976296268E-5,0.25,-1.68746453545498E-7,1.87426190104775E-5,-1.04497593278762E-7,95.9216156,96.0076904,99.7613830566406,99.7613830566406,57.6255625802946,20.6085012095173,20.631098,0,0,0,40,4374,93.6182,99.7613830566406,,,,,,,,,,,,,0,,,,0.00245,,,,,,95.964653,,,,
,32482775.895,92.46383285,99.7613830566406,1.85113367462225E-5,3.56463552530766E-7,1,0.999253354069792,40.0298881530762,1.99720228204098,20.3799996525049,0.000210457677089096,3.66734721061277E-5,0.25,-3.86402135884204E-8,1.8612390078885E-5,3.03388888282962E-8,92.420578,92.5070877,99.7613830566406,99.7613830566406,57.8240962241792,20.6167960799393,20.251448,0,0,0,40,4374,90.19345,99.7613830566406,,,,,,,,,,,,,0,,,,0,,,,,,92.46383285,,,,
,32482915.76,88.9375534,99.7613830566406,1.85307113108248E-5,3.17874070210891E-7,1,0.999253354069792,40.0298881530762,1.99668354635205,20.3799996525049,0.000210621141130503,3.66115609311531E-5,0.25,-5.13957909914623E-8,1.86301253593871E-5,2.26070604505334E-8,88.9375534,88.9375534,99.7613830566406,99.7613830566406,57.3793495967368,20.6087235742647,20.631098,0,0,0,40,4374,86.72785,99.7613830566406,,,,,,,,,,,,,0,,,,0,,,,,,88.9375534,,,,
,32483053.5,85.4005051,99.7613830566406,1.891053430579E-5,2.95328396252627E-7,1,0.999253354069792,40.0298881530762,1.99706661231648,20.4499997198582,0.000215129652577495,3.63467447062012E-5,0.25,-1.47540696043379E-7,1.9009897649651E-5,-6.69402088209506E-8,85.4005051,85.4005051,99.7613830566406,99.7613830566406,57.6427584077176,20.6209024192856,20.251448,0,0,0,40,4374,83.3257,99.7613830566406,,,,,,,,,,,,,0,,,,-0.00245,,,,,,85.4005051,,,,
,32483191.195,81.9214554,99.7613830566406,1.85133155991878E-5,3.05021216980285E-7,1,0.999253354069792,40.0298881530762,1.99707386390673,20.4499997198582,0.000209800998364186,3.99404256861923E-5,0.25,2.33761516604937E-7,1.86055576918224E-5,3.205752567152E-7,81.9214554,81.9214554,99.7613830566406,99.7613830566406,57.5880444113715,20.6146760346192,20.251448,0,0,0,40,4374,79.9452,99.7613830566406,,,,,,,,,,,,,0,,,,-0.00245,,,,,,81.9214554,,,,
,32483328.555,78.44275665,99.7613830566406,1.89641625715902E-5,2.70151977288181E-7,1,0.999253354069792,40.0298881530762,1.9972085728333,20.4499997198582,0.000215764396162826,3.58818573318243E-5,0.25,-2.09732066011061E-7,1.90562162134949E-5,-1.16253604889802E-7,78.4150085,78.4705048,99.7613830566406,99.7613830566406,57.5192611016792,20.6202377714632,19.492144,0,0,0,40,4374,76.53015,99.7613830566406,,,,,,,,,,,,,0,,,,0.00245,,,,,,78.44275665,,,,
,32483464.545,74.9877968,99.7613830566406,1.86846464415215E-5,2.90111456659836E-7,1,0.999253354069792,40.0298881530762,1.99738803970748,20.5199997872114,0.0002118628357559,3.91434201541321E-5,0.25,1.20919486652968E-7,1.87679616255775E-5,2.21558726078657E-7,74.9552994,75.0202942,99.7613830566406,99.7613830566406,57.4410982497561,20.6190825445108,19.871798,0,0,0,40,4374,73.206,99.7613830566406,,,,,,,,,,,,,0,,,,0.00245,,,,,,74.9877968,,,,
,32483602.935,71.4629593,99.7613830566406,1.86652237681657E-5,3.47592678197563E-7,1,0.999253354069792,40.0298881530762,1.99708324123681,20.5199997872114,0.000211995626388403,3.64548311371643E-5,0.25,-1.18331754728592E-7,1.87422585591327E-5,-1.12206953697824E-8,71.4629593,71.4629593,99.7613830566406,99.7613830566406,57.3105662870445,20.6131278356935,19.492144,0,0,0,40,4374,69.7915,99.7613830566406,,,,,,,,,,,,,0,,,,0.0049,,,,,,71.4629593,,,,
,32483740.93,67.9651566,99.7613830566406,1.88024745555385E-5,3.3880712385793E-7,1,0.999253354069792,40.0298881530762,1.9972568009311,20.5199997872114,0.000213336366391408,3.7431479689259E-5,0.25,-6.31758938711254E-8,1.88702817771413E-5,5.27641399936525E-8,67.9651566,67.9651566,99.7613830566406,99.7613830566406,57.7529680289292,20.6064798305056,19.492144,0,0,0,40,4374,66.40965,99.7613830566406,,,,,,,,,,,,,0,,,,-0.00245,,,,,,67.9651566,,,,
,32483877.8,64.4483337,99.7613830566406,1.82981926529373E-5,3.85156593186335E-7,1,0.999253354069792,40.0298881530762,1.99698821413421,20.5799993127584,0.000207232675434353,3.76675137563234E-5,0.25,4.29355185215879E-8,1.83521108138779E-5,1.6348376567958E-7,64.4483337,64.4483337,99.7613830566406,99.7613830566406,57.3879475104484,20.6010864379248,19.112494,0,0,0,40,4374,63.0388,99.7613830566406,,,,,,,,,,,,,0,,,,0.00245,,,,,,64.4483337,,,,
,32484016.075,60.9653778,99.7613830566406,1.89008271988745E-5,3.76326529796192E-7,1,0.999253354069792,40.0298881530762,1.99778007911391,20.5799993127584,0.000214155705641653,3.78983419104423E-5,0.25,-5.05163872331977E-8,1.89428056189034E-5,8.06861466091749E-8,60.9653778,60.9653778,99.7613830566406,99.7613830566406,57.4199942797368,20.6004535529492,19.112494,0,0,0,40,4374,59.644,99.7613830566406,,,,,,,,,,,,,0,,,,-0.0049,,,,,,60.9653778,,,,
,32484151.565,57.4925156,99.7613830566406,1.84496091358585E-5,3.47903600270283E-7,1,0.999253354069792,40.0298881530762,1.99786729593117,20.5799993127584,0.000208327663781735,3.99834736729851E-5,0.25,2.12257469013578E-7,1.84726892282094E-5,3.45971535937016E-7,57.4925156,57.4925156,99.7613830566406,99.7613830566406,57.4496961634676,20.6002091334702,19.112494,0,0,0,40,4374,56.3175,99.7613830566406,,,,,,,,,,,,,0,,,,0,,,,,,57.4925156,,,,
,32484288.175,53.9874229,99.7613830566406,1.86097416530504E-5,2.91302577062897E-7,1,0.999253354069792,40.0298881530762,1.9977117017248,20.6499993801117,0.000210167580707287,3.88829457923338E-5,0.25,8.64295787952699E-8,1.86156891622751E-5,2.24278672754444E-7,53.9874229,53.9874229,99.7613830566406,99.7613830566406,57.3746598256215,20.5953813867134,17.973541,0,0,0,40,4374,52.9605,99.7613830566406,,,,,,,,,,,,,0,,,,0,,,,,,53.9874229,,,,
,32484424.82,50.4957771,99.7613830566406,1.91925547831501E-5,3.65385996639612E-7,1,0.999253354069792,40.0298881530762,1.99792261481139,20.6499993801117,0.000216845427062945,3.84018539827354E-5,0.25,-5.86488315128465E-8,1.91798224052959E-5,8.40560871190969E-8,50.4957771,50.4957771,99.7613830566406,99.7613830566406,57.4911224749868,20.5985317983093,18.732843,0,0,0,40,4370,49.6104,99.7613830566406,,,,,,,,,,,,,0,,,,0,,,,,,50.4957771,,,,
,32484565.215,46.975071,99.7613830566406,1.89454203667206E-5,3.03522044311066E-7,1,0.999253354069792,40.0298881530762,1.99802795439622,20.6499993801117,0.000213463531858935,3.99186834605126E-5,0.25,1.26319336696393E-7,1.89110821725031E-5,2.64317895194938E-7,46.975071,46.975071,99.7613830566406,99.7613830566406,57.4668919908907,20.6052464577081,18.353191,0,0,0,40,4370,46.1469,99.7613830566406,,,,,,,,,,,,,0,,,,0,,,,,,46.975071,,,,
,32484702.485,43.4531517,99.7613830566406,1.88974531525942E-5,2.91526893795118E-7,1,0.999253354069792,40.0298881530762,1.99795685141416,20.7000002264977,0.00021273395874763,3.96247376790834E-5,0.25,1.17653822481109E-7,1.88447552130591E-5,2.49905000860263E-7,43.4531517,43.4531517,99.7613830566406,99.7613830566406,57.667770520333,20.6013090718569,17.593889,0,0,0,40,4370,42.779,99.7613830566406,,,,,,,,,,,,,0,,,,-0.00245,,,,,,43.4531517,,,,
,32484838.95,39.9624672,99.7613830566406,1.89947290278127E-5,3.42545253160699E-7,1,0.999253354069792,40.0298881530762,1.99793528849184,20.7000002264977,0.000213355601376881,4.13909782592671E-5,0.25,2.67275059903173E-7,1.89244629585405E-5,3.9228898027575E-7,39.9624672,39.9624672,99.7613830566406,99.7613830566406,57.5434915857753,20.6028216130314,16.834587,0,0,0,40,4370,39.4117,99.7613830566406,,,,,,,,,,,,,0,,,,0,,,,,,39.9624672,,,,
,32484975.795,36.4840851,99.7613830566406,1.87798441670147E-5,3.3136587942617E-7,1,0.999253354069792,40.0298881530762,1.99785200898422,20.7000002264977,0.000211932547764387,3.4471484122531E-5,0.25,-2.98214522673763E-7,1.87005839997701E-5,-1.80511216664149E-7,36.4840851,36.4840851,99.7613830566406,99.7613830566406,57.1737812961791,20.6001310446544,16.454937,0,0,0,40,4370,36.0209,99.7613830566406,,,,,,,,,,,,,0,,,,-0.00245,,,,,,36.4840851,,,,
,32485115.685,32.9868927,99.7613830566406,1.87124324782364E-5,3.85023391411872E-7,1,0.999253354069792,40.0298881530762,1.99802254733572,20.7499992102385,0.000210433550300573,3.78875867191193E-5,0.25,2.70817037782103E-8,1.86210090977355E-5,1.34882266887413E-7,32.9868927,32.9868927,99.7613830566406,99.7613830566406,57.119067299833,20.6010939289295,16.834587,0,0,0,40,4370,32.573,99.7613830566406,,,,,,,,,,,,,0,,,,0,,,,,,32.9868927,,,,
,32485254.795,29.4615955,99.7613830566406,1.84517535882786E-5,3.35340175875388E-7,1,0.999253354069792,40.0298881530762,1.99782647963084,20.7499992102385,0.000207185439257837,3.85372586424614E-5,0.25,1.39991452886363E-7,1.83535902967459E-5,2.3876834090766E-7,29.4615955,29.4615955,99.7613830566406,99.7613830566406,57.4520410490253,20.6044695428367,16.075285,0,0,0,40,4370,29.1223,99.7613830566406,,,,,,,,,,,,,0,,,,0.0049,,,,,,29.4615955,,,,
,32485393.18,25.9818649,99.7613830566406,1.88601320525216E-5,3.52634763259661E-7,1,0.999253354069792,40.0298881530762,1.99765527966595,20.7499992102385,0.00021182980410062,3.86316300087475E-5,0.25,8.22334457591075E-8,1.87551486981603E-5,1.78089116672717E-7,25.9818649,25.9818649,99.7613830566406,99.7613830566406,57.2628869473714,20.6068763488573,15.695635,0,0,0,40,4370,25.6936,99.7613830566406,,,,,,,,,,,,,0,,,,0,,,,,,25.9818649,,,,
,32485512.2,22.9876881,99.7613830566406,1.86433422353205E-5,3.22903537481168E-7,1,0.999253354069792,40.0298881530762,1.99757362400096,20.7899995148182,0.000209956309189917,3.48109862962866E-5,0.25,-2.15406465660202E-7,1.8538459194564E-5,-1.2211600504447E-7,22.9876881,22.9876881,99.7613830566406,99.7613830566406,57.0964000727753,20.6064474196477,14.936333,0,0,0,40,4370,22.73635,99.7613830566406,,,,,,,,,,,,,0,,,,0,,,,,,22.9876881,,,,
,32485653.19,19.4494781,99.7613830566406,1.88224041978053E-5,3.69616012143412E-7,1,0.999253354069792,40.0298881530762,1.99752759748283,20.7899995148182,0.000211393653944939,3.82854218465199E-5,0.25,6.42060012985571E-8,1.87137237616881E-5,1.54841933230115E-7,19.4494781,19.4494781,99.7613830566406,99.7613830566406,57.4207759082561,20.6078716974535,14.556682,0,0,0,40,4370,19.2427,99.7613830566406,,,,,,,,,,,,,0,,,,0.0049,,,,,,19.4494781,,,,
,32485790.51,15.97861385,99.7613830566406,1.87594661964842E-5,3.11862464058876E-7,1,0.999253354069792,40.0298881530762,1.99739351892737,20.7899995148182,0.000211368537726787,3.42417982820963E-5,0.25,-2.84020161561611E-7,1.86528587335017E-5,-1.91912806832381E-7,15.951561,16.0056667,99.7613830566406,99.7613830566406,57.2519441481022,20.6084374972257,13.797379,0,0,0,40,4370,15.8154,99.7613830566406,,,,,,,,,,,,,0,,,,0,,,,,,15.97861385,,,,
,32485909.87,12.9662247,99.7613830566406,1.86348776846113E-5,3.02439447643406E-7,1,0.999253354069792,40.0298881530762,1.99745454108069,20.8199992775917,0.000209704123516837,3.55274628354231E-5,0.25,-1.47601419413271E-7,1.85284795402695E-5,-5.68805969630968E-8,12.9662247,12.9662247,99.7613830566406,99.7613830566406,57.3332335141022,20.605786465971,13.417728,0,0,0,40,4370,12.83885,99.7613830566406,,,,,,,,,,,,,0,,,,0.0049,,,,,,12.9662247,,,,
,32486209.085,6.9840951,99.7613830566406,1.88267292589155E-5,4.09217715029541E-7,1,0.999253354069792,40.0298881530762,1.99721539037831,20.8199992775917,0.000212239535598254,3.36442985191809E-5,0.25,-3.48933808272166E-7,1.8720373285562E-5,-2.56132878870323E-7,6.9840951,6.9840951,99.7613830566406,99.7613830566406,57.2847725459099,20.6140950993807,10.760172,0,0,0,40,4374,6.83205,99.7613830566406,,,,,,,,,,,,,0,,,,0.00245,,,,,,6.9840951,,,,
,32486760.865,5.0116715,99.7613830566406,1.89015418041689E-5,4.08775205599547E-7,1,0.999253354069792,40.0298881530762,1.99700492300989,20.8199992775917,0.000212939107617364,3.44650749793657E-5,0.25,-2.88866753631502E-7,1.87944866157408E-5,-1.9604992089648E-7,5.0116715,5.0116715,99.7613830566406,99.7613830566406,57.2347483206791,20.6163537407587,8.482265,0,0,0,40,4369,4.9376,99.7613830566406,,,,,,,,,,,,,0,,,,0.0049,,,,,,5.0116715,,,,