File: data/doubleLayers/dl_1-25/ppms/data/DD205_3_HYST_100OE_300K.DAT
[Header]
; VSM Data File (default extension .dat)
; Copyright (c) 2003-2013, Quantum Design, Inc. All rights reserved.
TITLE,
FILEOPENTIME,22263310.88,09/16/2018,1:13 am
BYAPP,VSM,2.0,2.0
INFO,PPMS VSM Option Release 1.4.10 Build 1,APPNAME
INFO,Quantum Design Linear Motor Servo Controller,MOTOR_MODULE_NAME
INFO,3101-100 M1,MOTOR_HW_VERSION
INFO,MMC1014,MOTOR_SERIAL_NUMBER
INFO,SRV No X-over 01.03.11,MOTOR_SOFTWARE_VERSION
INFO,Quantum Design VSM Detection Module,VSM_MODULE_NAME
INFO,3101-150 F0,VSM_HW_VERSION
INFO,VSM707,VSM_SERIAL_NUMBER
INFO,VSM No X-over 01.02.05 May 20 2008 13:51:47,VSM_SOFTWARE_VERSION
INFO,704,PREAMP_SERIAL_NUMBER
INFO,822,COIL_SERIAL_NUMBER
INFO,0,MOMENT_UNITS
INFO,CoFe2O4,SAMPLE_MATERIAL
INFO,Double Layer blue,SAMPLE_COMMENT
INFO,,SAMPLE_MASS
INFO,,SAMPLE_VOLUME
INFO,,SAMPLE_MOLECULAR_WEIGHT
INFO,,SAMPLE_SIZE
INFO,,SAMPLE_SHAPE
DATATYPE,COMMENT,1
DATATYPE,TIME,2
STARTUPAXIS,X,2
STARTUPAXIS,Y1,5
[Data]
Comment,Time Stamp (sec),Temperature (K),Magnetic Field (Oe),Moment (emu),M. Std. Err. (emu),Transport Action,Averaging Time (sec),Frequency (Hz),Peak Amplitude (mm),Center Position (mm),Coil Signal' (mV),Coil Signal" (mV),Range (mV),M. Quad. Signal (emu),M. Raw' (emu),M. Raw" (emu),Min. Temperature (K),Max. Temperature (K),Min. Field (Oe),Max. Field (Oe),Mass (grams),Motor Lag (deg),Pressure (Torr),VSM Status (code),Motor Status (code),Measure Status (code),Measure Count,PPMS Status (code),System Temp. (K),System Field (Oe),Sample Position (deg),Bridge 1 Resistance (ohms),Bridge 1 Excitation (에),Bridge 2 Resistance (ohms),Bridge 2 Excitation (에),Bridge 3 Resistance (ohms),Bridge 3 Excitation (에),Bridge 4 Resistance (ohms),Bridge 4 Excitation (에),Signal 1 Vin (V),Signal 2 Vin (V),Digital Inputs (code),Drive 1 Iout (mA),Drive 1 Ipower (W),Drive 2 Iout (mA),Drive 2 Ipower (W),Pressure (),Map 20 (),Map 21 (),Map 22 (),Map 23 (),Map 24 (),Map 25 (),Map 26 (),Map 27 (),Map 28 (),Map 29 ()
,22263326.92,300.3561401,-0.274027913808823,,,2,,,,15.7899998614192,,,,,,,300.3561401,300.3561401,-0.274027913808823,-0.274027913808823,,,29.363071,,,,-99999999,4369,301.4139,-0.274027913808823,,,,,,,,,,,,,,,,,,,,,,,300.3561401,,,,
,22263484.715,300.28125,4375.5615234375,5.99317832476857E-5,5.80473760489221E-7,1,0.999253354069792,40.0298881530762,1.99829428012571,15.7800000160933,0.000677007546307548,0.000123865793641308,0.25,5.63657146062832E-7,5.99290292946934E-5,6.03254165319188E-7,300.28125,300.28125,4365.56201171875,4385.56103515625,55.9997752602944,20.5183619168188,29.363071,0,0,0,40,4449,300.99645,4375.5615234375,,,,,,,,,,,,,0,,,,0,,,,,,300.28125,,,,
,22263576.35,300.1949158,8951.89990234375,5.34735903334256E-5,6.77393753212592E-7,1,0.999253354069792,40.0298881530762,1.99845329110121,15.7800000160933,0.000602954033950352,0.000117150341305378,0.25,1.08826470936147E-6,5.34709129431411E-5,1.12356647233236E-6,300.1949158,300.1949158,8941.830078125,8961.9697265625,56.211596589006,20.5191737475735,28.983419,0,0,0,40,4449,300.87345,8951.89990234375,,,,,,,,,,,,,0,,,,0.00245,,,,,,300.1949158,,,,
,22263671.97,300.1209412,13732.2124023437,4.23308149829184E-5,1.21248033902026E-6,1,0.999253354069792,40.0298881530762,1.99843416261301,15.7800000160933,0.000472310244508791,0.000121583861501139,0.25,3.41072427888284E-6,4.23271260213908E-5,3.43856892002253E-6,300.1209412,300.1209412,13724.611328125,13739.8134765625,56.6196066760444,20.5201070409833,29.363071,0,0,0,40,4449,300.8121,13732.2124023437,,,,,,,,,,,,,0,,,,0,,,,,,300.1209412,,,,
,22263764.195,300.0736389,18342.1005859375,2.87298645813839E-5,1.5182420190527E-6,1,0.999253354069792,40.0298881530762,1.99840081941733,15.7800000160933,0.000319005102885454,9.14446387346566E-5,0.25,3.10379339286882E-6,2.87268913634314E-5,3.12265616159137E-6,300.0736389,300.0736389,18337.11328125,18347.087890625,56.4312342029098,20.5282181788769,29.363071,0,0,0,40,4449,300.77805,18342.1005859375,,,,,,,,,,,,,0,,,,0,,,,,,300.0736389,,,,
,22263861.775,300.0358887,23217.09375,1.3188310683599E-5,1.47369470514604E-6,1,0.999253354069792,40.0298881530762,1.99827792370105,15.7800000160933,0.000135620746047581,0.000104360477349438,0.25,6.93844318346546E-6,1.31833292139781E-5,6.94692676220258E-6,300.0358887,300.0358887,23204.41796875,23229.76953125,56.4664074862752,20.5248896425412,29.742722,0,0,0,40,4449,300.7536,23217.09375,,,,,,,,,,,,,0,,,,0.00245,,,,,,300.0358887,,,,
,22263958.96,300.0169067,28077.162109375,-1.08894927394522E-6,1.78421413378266E-6,1,0.999253354069792,40.0298881530762,1.9982982165414,15.7800000160933,-2.69886398397161E-5,8.25225167951048E-5,0.25,7.48194309422303E-6,-1.09384568368306E-6,7.48100097548577E-6,300.0169067,300.0169067,28072.06640625,28082.2578125,56.3765202065637,20.5288708269891,29.742722,0,0,0,40,4449,300.74945,28077.162109375,,,,,,,,,,,,,0,,,,0.00245,,,,,,300.0169067,,,,
,22264054.11,300.010437,32832.392578125,-1.70034562518096E-5,1.79325702040936E-6,1,0.999253354069792,40.0298881530762,1.99840936195048,15.7800000160933,-0.000214021465963484,9.14482189712079E-5,0.25,1.1027618368548E-5,-1.70102083290163E-5,1.10160995409994E-5,300.010437,300.010437,32830,32834.78515625,56.6633778731214,20.5310260717441,29.363071,0,0,0,40,4449,300.74135,32832.392578125,,,,,,,,,,,,,0,,,,-0.0049,,,,,,300.010437,,,,
,22264152.035,300.0097046,37727.099609375,-3.33149180895935E-5,1.44946839262312E-6,1,0.999253354069792,40.0298881530762,1.99833186737736,15.7800000160933,-0.000392286861106394,2.31524477867414E-5,0.25,7.81809999675848E-6,-3.33190701167522E-5,7.7959654553526E-6,300.0097046,300.0097046,37722.13671875,37732.0625,56.4679707433137,20.5307650753244,29.363071,0,0,0,40,4449,300.73905,37727.099609375,,,,,,,,,,,,,0,,,,0.00245,,,,,,300.0097046,,,,
,22264247.745,300.01194765,42509.44921875,-4.86262684329279E-5,1.53983722735226E-6,1,0.999253354069792,40.0298881530762,1.99832616914852,15.7800000160933,-0.000567229596978961,2.92234334727173E-6,0.25,8.68292589751722E-6,-4.8630528104176E-5,8.65073235559736E-6,300.0113831,300.0125122,42504.65625,42514.2421875,56.5883415352752,20.5302313479723,28.983419,0,0,0,40,4449,300.72745,42509.44921875,,,,,,,,,,,,,0,,,,0,,,,,,300.01194765,,,,
,22264343.665,300.01089475,47305.013671875,-6.81373253941525E-5,2.10986619275401E-6,1,0.999253354069792,40.0298881530762,1.99839808651364,15.7800000160933,-0.000790809118198153,-1.92576364394586E-5,0.25,1.01030658200767E-5,-6.81419385366597E-5,1.00580648487284E-5,300.0101013,300.0116882,47297.64453125,47312.3828125,56.6594697305252,20.5293734189066,29.742722,0,0,0,40,4449,300.71695,47305.013671875,,,,,,,,,,,,,0,,,,-0.00245,,,,,,300.01089475,,,,
,22264439.085,300.015686,52072.3984375,-7.96028779165306E-5,2.57016625074284E-6,1,0.999253354069792,40.0298881530762,1.99835045754783,15.7800000160933,-0.000919367433043827,-4.84189156793182E-5,0.25,9.5122196062911E-6,-7.96067489435322E-5,9.45976902008942E-6,300.015686,300.015686,52064.9921875,52079.8046875,56.6102271338137,20.5304048775534,29.742722,0,0,0,40,4449,300.70375,52072.3984375,,,,,,,,,,,,,0,,,,0,,,,,,300.015686,,,,
,22264533.08,300.0138245,56770.009765625,-9.81736722936067E-5,2.38743624140298E-6,1,0.999253354069792,40.0298881530762,1.99836621365517,15.7800000160933,-0.00113330639130631,-6.28990547769841E-5,0.25,1.14499025043799E-5,-9.81782665888618E-5,1.13852952283699E-5,300.0138245,300.0138245,56767.4609375,56772.55859375,56.5305010248521,20.5301590591655,29.363071,0,0,0,40,4449,300.693,56770.009765625,,,,,,,,,,,,,0,,,,-0.00245,,,,,,300.0138245,,,,
,22264626.415,300.0129395,61435.087890625,-0.000116730804865335,1.86738004540213E-6,1,0.999253354069792,40.0298881530762,1.99838723328222,15.7800000160933,-0.00134213736679078,-0.000105981793204184,0.25,1.08574614196782E-5,-0.000116734466264874,1.07808092791467E-5,300.0129395,300.0129395,61430.10546875,61440.0703125,56.7220000120637,20.5310373955473,29.363071,0,0,0,40,4449,300.68645,61435.087890625,,,,,,,,,,,,,0,,,,-0.00245,,,,,,300.0129395,,,,
,22264721.75,300.0198059,66200.52734375,-0.000134005537623035,2.18718213485565E-6,1,0.999253354069792,40.0298881530762,1.99832830871687,15.7800000160933,-0.00153574168481889,-0.00015036010351566,0.25,9.92788897786881E-6,-0.000134008050685992,9.84006376606896E-6,300.0198059,300.0198059,66187.9140625,66213.140625,56.5312826533714,20.5274126866845,29.742722,0,0,0,40,4449,300.6699,66200.52734375,,,,,,,,,,,,,0,,,,-0.0049,,,,,,300.0198059,,,,
,22264815.585,300.0154419,70888.5234375,-0.000150055286919196,3.18174708134119E-6,1,0.999253354069792,40.0298881530762,1.99814840457177,15.7800000160933,-0.00172608728566015,-0.000130499043217351,0.25,1.44626768467088E-5,-0.00015006030904147,1.43643473044619E-5,300.0154419,300.0154419,70880.9375,70896.109375,56.7368509539291,20.5275265311571,29.742722,0,0,0,40,4449,300.6576,70888.5234375,,,,,,,,,,,,,0,,,,0,,,,,,300.0154419,,,,
,22264910.975,300.0176697,75658.5390625,-0.000161497211430963,3.11789596840085E-6,1,0.999253354069792,40.0298881530762,1.99842923583512,15.7800000160933,-0.0018676737743606,-8.43587083131824E-5,0.25,2.05239836645352E-5,-0.000161505834091386,2.04181317150109E-5,300.0176697,300.0176697,75653.75,75663.328125,56.6915164998137,20.5302086780452,29.363071,0,0,0,40,4449,300.64305,75658.5390625,,,,,,,,,,,,,0,,,,-0.0049,,,,,,300.0176697,,,,
,22265005.095,300.0193787,80362.2421875,-0.000182407845205035,3.37478626365664E-6,1,0.999253354069792,40.0298881530762,1.99816393479791,15.7800000160933,-0.00208470672151876,-0.000236834251360952,0.25,1.06691128830599E-5,-0.000182409422977873,1.05500615415182E-5,300.0193787,300.0193787,80352.3359375,80372.1484375,56.8079791491791,20.527058666326,29.742722,0,0,0,40,4449,300.63135,80362.2421875,,,,,,,,,,,,,0,,,,0,,,,,,300.0193787,,,,
,22265100.695,300.019043,85140.64453125,-0.000202066934723595,3.32214813043377E-6,1,0.999253354069792,40.0298881530762,1.998275907641,15.7800000160933,-0.00231245063163044,-0.000245402575523017,0.25,1.3318692567241E-5,-0.000202069664642951,1.31869202005748E-5,300.019043,300.019043,85130.71875,85150.5703125,56.5703640793329,20.5245207636155,29.742722,0,0,0,40,4449,300.6116,85140.64453125,,,,,,,,,,,,,0,,,,0.00245,,,,,,300.019043,,,,
,22265189.04,300.0148315,89558.828125,-0.000218372660374004,4.38992964529225E-6,1,0.999253354069792,40.0298881530762,1.99821223676552,15.7800000160933,-0.00249570278690874,-0.000284099436814312,0.25,1.27226552378283E-5,-0.000218374562034802,1.25804591023214E-5,300.0148315,300.0148315,89553.6875,89563.96875,56.5688008222944,20.5287592399886,29.742722,0,0,0,40,4449,300.6,89558.828125,,,,,,,,,,,,,0,,,,0,,,,,,300.0148315,,,,
,22265298.14,300.01419065,85998.45703125,-0.000205475554662933,2.70421908305842E-6,1,0.999253354069792,40.0298881530762,1.9983064416242,15.7800000160933,-0.00235584755993621,-0.000224413848605243,0.25,1.57644812116691E-5,-0.000205479810808744,1.56304420897489E-5,300.0134277,300.0149536,85993.3203125,86003.59375,56.8071975206598,20.5268299072776,29.742722,0,0,0,40,4449,300.5893,85998.45703125,,,,,,,,,,,,,0,,,,-0.00245,,,,,,300.01419065,,,,
,22265390.195,300.0078735,81394.9453125,-0.00019187972948451,3.34473485241084E-6,1,0.999253354069792,40.0298881530762,1.9983961801253,15.7800000160933,-0.00220074547973986,-0.000205626137527893,0.25,1.50704227096266E-5,-0.000191883972979029,1.49450936256157E-5,300.0078735,300.0078735,81389.9375,81399.953125,56.8791073444291,20.5290617721043,28.983419,0,0,0,40,4449,300.58545,81394.9453125,,,,,,,,,,,,,0,,,,-0.0049,,,,,,300.0078735,,,,
,22265488.565,299.9965515,76478.921875,-0.000171351261929799,2.84846825763021E-6,1,0.999253354069792,40.0298881530762,1.9983311420807,15.7800000160933,-0.00196531613253503,-0.000183158878712594,0.25,1.34991079745192E-5,-0.000171355146487585,1.33870536781775E-5,299.9965515,299.9965515,76466.3828125,76491.4609375,56.9885353371214,20.5269570812158,29.742722,0,0,0,40,4449,300.59495,76478.921875,,,,,,,,,,,,,0,,,,0.00245,,,,,,299.9965515,,,,
,22265589.52,299.9965515,71432.90625,-0.000151887245114871,2.81541285369091E-6,1,0.999253354069792,40.0298881530762,1.99838173506776,15.7800000160933,-0.00173447448430795,-0.00020646094987508,0.25,8.06819287350439E-6,-0.000151888143962711,7.96885160265631E-6,299.9965515,299.9965515,71422.953125,71442.859375,56.7165286124291,20.5289011649034,29.363071,0,0,0,40,4449,300.59625,71432.90625,,,,,,,,,,,,,0,,,,0.00245,,,,,,299.9965515,,,,
,22265685.5,299.9966431,66632.65234375,-0.000138408415490849,2.35063820622251E-6,1,0.999253354069792,40.0298881530762,1.99833805359357,15.7800000160933,-0.00158682336515726,-0.00015175285877769,0.25,1.05676851762661E-5,-0.000138411330951026,1.0476958781427E-5,299.9966431,299.9966431,66620.1328125,66645.171875,56.6868267286983,20.5278664706035,29.363071,0,0,0,40,4449,300.59955,66632.65234375,,,,,,,,,,,,,0,,,,0,,,,,,299.9966431,,,,
,22265778.98,299.9959106,61961.55859375,-0.000123011844982144,2.43533271551841E-6,1,0.999253354069792,40.0298881530762,1.99838366096398,15.7800000160933,-0.00141341117102521,-0.000117122988081375,0.25,1.09610506720714E-5,-0.000123015464359291,1.08802789515532E-5,299.9959106,299.9959106,61956.5078125,61966.609375,56.5219031111406,20.5315337879707,29.363071,0,0,0,40,4449,300.6026,61961.55859375,,,,,,,,,,,,,0,,,,-0.00245,,,,,,299.9959106,,,,
,22265876.075,299.993927,57108.640625,-0.000104894014104674,3.29071394817845E-6,1,0.999253354069792,40.0298881530762,1.9983539222582,15.7800000160933,-0.00120652752423694,-9.23213154560302E-5,0.25,1.00139530907871E-5,-0.000104897544839496,9.94497981937536E-6,299.993927,299.993927,57103.73046875,57113.55078125,56.7431039820829,20.5305629361779,29.363071,0,0,0,40,4449,300.6121,57108.640625,,,,,,,,,,,,,0,,,,-0.00245,,,,,,299.993927,,,,
,22265970.915,299.9910583,52368.7734375,-8.58189438517727E-5,2.91507556967643E-6,1,0.999253354069792,40.0298881530762,1.99823533347097,15.7800000160933,-0.00098706997033727,-7.54916701740903E-5,0.25,8.19620923021656E-6,-8.58218439260687E-5,8.1397173905686E-6,299.9910583,299.9910583,52361.2421875,52376.3046875,56.709493955756,20.5310442958395,29.742722,0,0,0,40,4449,300.6232,52368.7734375,,,,,,,,,,,,,0,,,,-0.0049,,,,,,299.9910583,,,,
,22266065.055,299.9916534,47663.681640625,-7.02780331080096E-5,1.95583972972929E-6,1,0.999253354069792,40.0298881530762,1.99840332200759,15.7800000160933,-0.000814597865174382,-2.59760467140041E-5,0.25,9.88022988014576E-6,-7.02824859812941E-5,9.83382500277186E-6,299.9910583,299.9922485,47653.62109375,47673.7421875,56.7212183835445,20.5313920199,28.983419,0,0,0,40,4449,300.62475,47663.681640625,,,,,,,,,,,,,0,,,,0,,,,,,299.9916534,,,,
,22266164.365,299.9910889,42698.37890625,-5.48447997841289E-5,1.62531627877184E-6,1,0.999253354069792,40.0298881530762,1.99839918382163,15.7800000160933,-0.000636346284807816,-1.65926889939094E-5,0.25,8.03567133183207E-6,-5.48484916218083E-5,7.99940669523132E-6,299.9910889,299.9910889,42690.9375,42705.8203125,56.7454488676406,20.5310167437014,29.363071,0,0,0,40,4449,300.6307,42698.37890625,,,,,,,,,,,,,0,,,,0,,,,,,299.9910889,,,,
,22266259.33,299.9901733,37953.65625,-3.96222145476853E-5,1.61980021128702E-6,1,0.999253354069792,40.0298881530762,1.9984740453738,15.7800000160933,-0.0004606902542489,-6.50336816327219E-6,0.25,6.28999760285766E-6,-3.96252033206116E-5,6.2637569369623E-6,299.9901733,299.9901733,37948.71484375,37958.59765625,56.9486722826406,20.531017681252,29.363071,0,0,0,40,4449,300.63755,37953.65625,,,,,,,,,,,,,0,,,,0,,,,,,299.9901733,,,,
,22266355.235,299.988739,33161.232421875,-2.30389413394676E-5,1.75629350105167E-6,1,0.999253354069792,40.0298881530762,1.99844960232458,15.7800000160933,-0.000270238580178081,9.87648875220698E-6,0.25,4.86441942250373E-6,-2.30414760779794E-5,4.84911100934654E-6,299.988739,299.988739,33156.23828125,33166.2265625,56.8290831191983,20.5318458097618,29.742722,0,0,0,40,4449,300.64975,33161.232421875,,,,,,,,,,,,,0,,,,-0.00245,,,,,,299.988739,,,,
,22266451.76,299.9955444,28336.5751953125,-6.57599609576986E-6,1.37678998516105E-6,1,0.999253354069792,40.0298881530762,1.99848910195578,15.7800000160933,-8.25297696691829E-5,3.39536530470677E-5,0.25,4.13984981221625E-6,-6.57853181752858E-6,4.13539472463905E-6,299.9955444,299.9955444,28329.01171875,28344.138671875,57.0369963053137,20.5295586376531,29.742722,0,0,0,40,4449,300.64365,28336.5751953125,,,,,,,,,,,,,0,,,,0.0049,,,,,,299.9955444,,,,
,22266547.15,299.9953003,23568.740234375,1.01647199825814E-5,1.22432852552877E-6,1,0.999253354069792,40.0298881530762,1.99854561902785,15.7800000160933,0.000108289368370689,5.88125867817263E-5,0.25,3.43609443313632E-6,1.01621552429642E-5,3.44269866751449E-6,299.9953003,299.9953003,23561.203125,23576.27734375,56.8384626614291,20.532579367798,29.363071,0,0,0,40,4449,300.66565,23568.740234375,,,,,,,,,,,,,0,,,,0,,,,,,299.9953003,,,,
,22266644.755,299.991272,18689.33203125,2.57039727541213E-5,1.19919658960139E-6,1,0.999253354069792,40.0298881530762,1.9985482625728,15.7800000160933,0.000284685745622542,8.6101984562745E-5,0.25,3.15532676282015E-6,2.57011375520897E-5,3.17220657780851E-6,299.991272,299.991272,18684.333984375,18694.330078125,56.8025077495445,20.5316514058709,29.742722,0,0,0,40,4449,300.66205,18689.33203125,,,,,,,,,,,,,0,,,,-0.00245,,,,,,299.991272,,,,
,22266740.305,299.9941101,13914.419921875,4.13720883169358E-5,1.17403978924035E-6,1,0.999253354069792,40.0298881530762,1.99850413727344,15.7800000160933,0.000463370118911766,0.000108794922088965,0.25,2.44624235860838E-6,4.13692551216534E-5,2.47351308989099E-6,299.9941101,299.9941101,13906.7109375,13922.12890625,56.8783257159099,20.5331652892306,29.742722,0,0,0,40,4449,300.65985,13914.419921875,,,,,,,,,,,,,0,,,,0.00245,,,,,,299.9941101,,,,
,22266835.93,299.9911194,9136.93408203125,5.25956816995532E-5,6.13606180401266E-7,1,0.999253354069792,40.0298881530762,1.99863516811133,15.7800000160933,0.000591886127591978,0.000122306263460274,0.25,1.69497127357348E-6,5.25930172688938E-5,1.72970956681951E-6,299.9911194,299.9911194,9124.2177734375,9149.650390625,56.9041194570445,20.5328860035825,29.363071,0,0,0,40,4449,300.6726,9136.93408203125,,,,,,,,,,,,,0,,,,-0.00245,,,,,,299.9911194,,,,
,22266928.07,299.9894409,4529.20654296875,5.8564173997037E-5,4.37427575981985E-7,1,0.999253354069792,40.0298881530762,1.99857903217031,15.7800000160933,0.000661763493514866,0.000120433453491625,0.25,4.95649213576745E-7,5.85621285207551E-5,5.3439786918088E-7,299.9894409,299.9894409,4526.662109375,4531.7509765625,56.6907348712945,20.5327789555332,29.363071,0,0,0,40,4449,300.67945,4529.20654296875,,,,,,,,,,,,,0,,,,-0.0049,,,,,,299.9894409,,,,
,22267018.53,299.9996643,7.39568984508514,1.60448465905224E-5,4.06350683247588E-7,1,0.999253354069792,40.0298881530762,1.9986812549589,15.7800000160933,0.000182047022054959,2.87564459354841E-5,0.25,-2.38902906019503E-7,1.60445278528216E-5,-2.28269797295796E-7,299.9996643,299.9996643,2.36732459068298,12.4240550994873,56.7548284098714,20.5353415555908,29.742722,0,0,0,40,4449,300.6763,7.39568984508514,,,,,,,,,,,,,0,,,,0,,,,,,299.9996643,,,,
,22267110.76,299.9983521,-4596.20947265625,-5.81376667929952E-5,4.81260019027249E-7,1,0.999253354069792,40.0298881530762,1.99873659240527,15.7800000160933,-0.000656243328140077,-0.000123893734760018,0.25,-8.74501683111877E-7,-5.81353645228435E-5,-9.1295598168739E-7,299.9983521,299.9983521,-4600.98388671875,-4591.43505859375,56.9822823089676,20.5351633470031,29.363071,0,0,0,40,4449,300.68125,-4596.20947265625,,,,,,,,,,,,,0,,,,-0.0049,,,,,,299.9983521,,,,
,22267205.77,300.0059204,-9347.4638671875,-5.11306491776112E-5,5.71880173607002E-7,1,0.999253354069792,40.0298881530762,1.99857742008378,15.7800000160933,-0.000573009175480243,-0.000132598357403188,0.25,-2.85859049974185E-6,-5.11272309848251E-5,-2.89232356749953E-6,300.0059204,300.0059204,-9355.142578125,-9339.78515625,56.8040710065829,20.5343509019011,29.363071,0,0,0,40,4449,300.66755,-9347.4638671875,,,,,,,,,,,,,0,,,,-0.00245,,,,,,300.0059204,,,,
,22267301.265,300.005127,-14120.1484375,-3.93721293013952E-5,8.46191732535559E-7,1,0.999253354069792,40.0298881530762,1.99866743140637,15.7800000160933,-0.000438791595568658,-0.000116316987784242,0.25,-3.45668285411864E-6,-3.93686717657786E-5,-3.48259944091809E-6,300.005127,300.005127,-14122.79296875,-14117.50390625,56.7485753817175,20.5356377924705,29.363071,0,0,0,40,4449,300.6629,-14120.1484375,,,,,,,,,,,,,0,,,,0.0049,,,,,,300.005127,,,,
,22267398.25,300.0075073,-18967.345703125,-2.55657123504981E-5,1.0049204023932E-6,1,0.999253354069792,40.0298881530762,1.99874197928226,15.7800000160933,-0.000283057107076128,-8.63586959712382E-5,0.25,-3.20126545745481E-6,-2.55628360145973E-5,-3.21805046462462E-6,300.0075073,300.0075073,-18974.693359375,-18959.998046875,56.8103240347368,20.5380011066332,29.742722,0,0,0,40,4449,300.6527,-18967.345703125,,,,,,,,,,,,,0,,,,-0.00245,,,,,,300.0075073,,,,
,22267495.66,300.0097961,-23834.408203125,-9.14696895270631E-6,1.4280195691206E-6,1,0.999253354069792,40.0298881530762,1.99878877412705,15.7800000160933,-9.61928898343106E-5,-6.02324019545773E-5,0.25,-3.73727804426729E-6,-9.14423055993122E-6,-3.74320029054586E-6,300.0097961,300.0097961,-23846.8125,-23822.00390625,56.943200883006,20.5341104269408,29.742722,0,0,0,40,4449,300.64555,-23834.408203125,,,,,,,,,,,,,0,,,,0,,,,,,300.0097961,,,,
,22267597.62,300.0101318,-28931.9150390625,8.15323441108081E-6,1.23412489146299E-6,1,0.999253354069792,40.0298881530762,1.99883025009626,15.7800000160933,0.000100840036522608,-3.34410967742514E-5,0.25,-4.36733935921316E-6,8.15586929812919E-6,-4.36183654384984E-6,300.0101318,300.0101318,-28939.3828125,-28924.447265625,56.8173586914099,20.5344496317211,29.363071,0,0,0,40,4449,300.6423,-28931.9150390625,,,,,,,,,,,,,0,,,,-0.0049,,,,,,300.0101318,,,,
,22267697.19,300.0120239,-33906.3984375,2.53268989745999E-5,1.361543740138E-6,1,0.999253354069792,40.0298881530762,1.99874862535929,15.7800000160933,0.000297790122387356,-1.47400929131583E-5,0.25,-5.69044313911066E-6,2.53298898816421E-5,-5.6736008409539E-6,300.0120239,300.0120239,-33911.390625,-33901.40625,56.8431524325445,20.5388602739563,29.363071,0,0,0,40,4449,300.62385,-33906.3984375,,,,,,,,,,,,,0,,,,0.00245,,,,,,300.0120239,,,,
,22267793.78,300.0144653,-38736.0703125,4.06737891330217E-5,1.50017988864914E-6,1,0.999253354069792,40.0298881530762,1.99876586316167,15.7800000160933,0.000476078579984769,-1.119345336594E-5,0.25,-8.0359460178304E-6,4.06778599413469E-5,-8.00895864259402E-6,300.0144653,300.0144653,-38743.40625,-38728.734375,56.9267866841022,20.5382408943383,30.122374,0,0,0,40,4449,300.61565,-38736.0703125,,,,,,,,,,,,,0,,,,-0.00245,,,,,,300.0144653,,,,
,22267892.615,300.017395,-43675.556640625,5.90413594852135E-5,1.95767450178531E-6,1,0.999253354069792,40.0298881530762,1.99882193571865,15.7800000160933,0.00068330163002371,2.8680174921021E-5,0.25,-7.69501496629373E-6,5.9044650091709E-5,-7.65599987372952E-6,300.017395,300.017395,-43685.4453125,-43665.66796875,56.8759808303522,20.5377974579724,29.742722,0,0,0,40,4449,300.59915,-43675.556640625,,,,,,,,,,,,,0,,,,0,,,,,,300.017395,,,,
,22267990.645,300.0185547,-48572.908203125,7.78759066403864E-5,1.83449550534773E-6,1,0.999253354069792,40.0298881530762,1.99884732815091,15.7800000160933,0.000900524882099464,4.22448368021708E-5,0.25,-9.7596166593501E-6,7.78799853964321E-5,-9.70822364144868E-6,300.0185547,300.0185547,-48582.95703125,-48562.859375,56.8454973181022,20.538522775756,29.363071,0,0,0,40,4449,300.58885,-48572.908203125,,,,,,,,,,,,,0,,,,-0.00245,,,,,,300.0185547,,,,
,22268086.535,300.0151062,-53365.068359375,9.48394471235326E-5,2.15201928625129E-6,1,0.999253354069792,40.0298881530762,1.99894109579272,15.7800000160933,0.00108952047165761,9.30822881461314E-5,0.25,-8.20710063524532E-6,9.48420125091254E-5,-8.14469168712779E-6,300.0151062,300.0151062,-53369.86328125,-53360.2734375,56.9854088230445,20.5398237322433,29.363071,0,0,0,40,4449,300.5757,-53365.068359375,,,,,,,,,,,,,0,,,,-0.00245,,,,,,300.0151062,,,,
,22268182.56,300.0156555,-58164.974609375,0.00011266857663789,2.82216918621741E-6,1,0.999253354069792,40.0298881530762,1.99880220833458,15.7800000160933,0.00129621841746942,9.92501345758863E-5,0.25,-1.07504227930764E-5,0.00011267227731369,-1.06763355272759E-5,300.0156555,300.0156555,-58172.296875,-58157.65234375,56.9088092281599,20.5376808935491,30.122374,0,0,0,40,4449,300.5681,-58164.974609375,,,,,,,,,,,,,0,,,,-0.0049,,,,,,300.0156555,,,,
,22268280.08,300.0152588,-63040.193359375,0.000129033143723943,2.14906346001637E-6,1,0.999253354069792,40.0298881530762,1.99883842802745,15.7800000160933,0.00148355395761884,0.000119206590532934,0.25,-1.18223768293074E-5,0.000129037062990651,-1.17376406838837E-5,300.0141602,300.0163574,-63050.23828125,-63030.1484375,57.1315733561406,20.5397313130432,29.742722,0,0,0,40,4449,300.5547,-63040.193359375,,,,,,,,,,,,,0,,,,0.00245,,,,,,300.0152588,,,,
,22268377.86,300.0127258,-67924.640625,0.000146370115232202,2.27709569130559E-6,1,0.999253354069792,40.0298881530762,1.99890312034391,15.7800000160933,0.00168374343012082,0.000130574408866732,0.25,-1.38218382376585E-5,0.000146374842573603,-1.37258189891556E-5,300.0127258,300.0127258,-67927.078125,-67922.203125,56.9815006804483,20.5388468049189,30.122374,0,0,0,40,4449,300.5436,-67924.640625,,,,,,,,,,,,,0,,,,0,,,,,,300.0127258,,,,
,22268474.785,300.0123291,-72768.6796875,0.000165953441413342,2.33518087887682E-6,1,0.999253354069792,40.0298881530762,1.99884846574962,15.7800000160933,0.00190388202035473,0.000177391604913837,0.25,-1.30776367238972E-5,0.000165957110742732,-1.2968975757093E-5,300.0123291,300.0123291,-72778.7734375,-72758.5859375,56.9893169656406,20.5405576645491,30.122374,0,0,0,40,4449,300.5329,-72768.6796875,,,,,,,,,,,,,0,,,,-0.0049,,,,,,300.0123291,,,,
,22268572.6,300.017395,-77655.86328125,0.000176172591200029,3.13401836349648E-6,1,0.999253354069792,40.0298881530762,1.99893885047723,15.7800000160933,0.00202906610416219,0.000142959375141945,0.25,-1.78907840128308E-5,0.000176179067587449,-1.77754502140358E-5,300.017395,300.017395,-77665.859375,-77645.8671875,57.0283983916022,20.5411906364451,29.363071,0,0,0,40,4449,300.5208,-77655.86328125,,,,,,,,,,,,,0,,,,0,,,,,,300.017395,,,,
,22268671.955,300.0158844,-82622.7734375,0.000201907590881104,2.58768477941295E-6,1,0.999253354069792,40.0298881530762,1.99883438660877,15.7800000160933,0.00231810127162076,0.000205691274259847,0.25,-1.6805761242052E-5,0.000201912614916505,-1.66738509590534E-5,300.0155029,300.0162659,-82632.6953125,-82612.8515625,56.8368994043906,20.5414478212083,30.122374,0,0,0,40,4449,300.5049,-82622.7734375,,,,,,,,,,,,,0,,,,0,,,,,,300.0158844,,,,
,22268765.75,300.0158081,-87309.94140625,0.000214209083842679,3.64580540373365E-6,1,0.999253354069792,40.0298881530762,1.99888129691436,15.7800000160933,0.0024595020226907,0.000217580534948161,0.25,-1.78867332509855E-5,0.000214214452494679,-1.77469487874446E-5,300.0158081,300.0158081,-87314.78125,-87305.1015625,56.9916618511983,20.542815925415,29.363071,0,0,0,40,4449,300.4915,-87309.94140625,,,,,,,,,,,,,0,,,,0,,,,,,300.0158081,,,,
,22268875.445,300.0134277,-88173.16015625,0.000221071941709064,3.34793273851465E-6,1,0.999253354069792,40.0298881530762,1.99894150510506,15.7800000160933,0.00253786301101552,0.000227501838643197,0.25,-1.81996587617067E-5,0.000221077332315398,-1.80554328078186E-5,300.0134277,300.0134277,-88183.1953125,-88163.125,56.7446672391214,20.5407899380782,30.122374,0,0,0,40,4449,300.4826,-88173.16015625,,,,,,,,,,,,,0,,,,0.00245,,,,,,300.0134277,,,,
,22268967.935,300.0081482,-83551.75,0.000200376921070341,2.96362124681958E-6,1,0.999253354069792,40.0298881530762,1.99899726702021,15.7800000160933,0.00230095355200287,0.000202725792343211,0.25,-1.68039751036575E-5,0.000200382044555958,-1.66730849573232E-5,300.0081482,300.0081482,-83556.59375,-83546.90625,57.1198489283522,20.540663593072,29.742722,0,0,0,40,4449,300.4802,-83551.75,,,,,,,,,,,,,0,,,,-0.00245,,,,,,300.0081482,,,,
,22269064.895,299.9926758,-78704.2578125,0.000184256036582198,3.38598342824966E-6,1,0.999253354069792,40.0298881530762,1.99886379162656,15.7800000160933,0.0021161901858483,0.000183584842973227,0.25,-1.57012988437252E-5,0.00018426101201015,-1.55807910061277E-5,299.9926758,299.9926758,-78714.5078125,-78694.0078125,57.0088576786214,20.5399186890727,30.122374,0,0,0,40,4449,300.4843,-78704.2578125,,,,,,,,,,,,,0,,,,0,,,,,,299.9926758,,,,
,22269159.87,299.9921875,-73957.15625,0.000166621348465548,3.00755707141636E-6,1,0.999253354069792,40.0298881530762,1.99885115104715,15.7800000160933,0.00191621892648825,0.000151147060292123,0.25,-1.55122197988397E-5,0.000166626707174021,-1.54030797976252E-5,299.9921875,299.9921875,-73966.9921875,-73947.3203125,57.0745144742368,20.5391951022547,29.363071,0,0,0,40,4449,300.4949,-73957.15625,,,,,,,,,,,,,0,,,,0,,,,,,299.9921875,,,,
,22269256.45,299.9931335,-69132.35546875,0.000147769201492619,2.59052614700327E-6,1,0.999253354069792,40.0298881530762,1.99883977228009,15.7800000160933,0.00169828083388119,0.000140514356012718,0.25,-1.31856192339248E-5,0.00014777357612128,-1.30887274604576E-5,299.9931335,299.9931335,-69144.8203125,-69119.890625,57.126101956506,20.5422493375143,29.742722,0,0,0,40,4449,300.50125,-69132.35546875,,,,,,,,,,,,,0,,,,-0.00245,,,,,,299.9931335,,,,
,22269352.05,299.9926758,-64355.341796875,0.000132542587559148,3.04999156795579E-6,1,0.999253354069792,40.0298881530762,1.998928274768,15.7800000160933,0.0015239307581663,0.000122682161720305,0.25,-1.21237621121283E-5,0.000132546707735379,-1.20367436845406E-5,299.9926758,299.9926758,-64357.90234375,-64352.78125,57.0252718775253,20.5419592058305,30.122374,0,0,0,40,4449,300.5063,-64355.341796875,,,,,,,,,,,,,0,,,,-0.0049,,,,,,299.9926758,,,,
,22269450.93,299.9916382,-59413.142578125,0.000113553357273146,2.01837244794602E-6,1,0.999253354069792,40.0298881530762,1.99886002998077,15.7800000160933,0.00130519215945714,0.000107204562345702,0.25,-1.02011363380317E-5,0.000113556770061102,-1.0126503798515E-5,299.9916382,299.9916382,-59415.68359375,-59410.6015625,57.0643533034868,20.5393679488337,30.122374,0,0,0,40,4449,300.5208,-59413.142578125,,,,,,,,,,,,,0,,,,-0.00245,,,,,,299.9916382,,,,
,22269543.155,299.9852905,-54803.1328125,9.85759987605499E-5,1.93726631555617E-6,1,0.999253354069792,40.0298881530762,1.99883554267909,15.7800000160933,0.00113546135736752,7.90189626569768E-5,0.25,-1.00966347646313E-5,9.85797972860548E-5,-1.0031740556703E-5,299.9852905,299.9852905,-54808.21484375,-54798.05078125,56.8306463762368,20.5394521317503,29.742722,0,0,0,40,4449,300.5237,-54803.1328125,,,,,,,,,,,,,0,,,,0,,,,,,299.9852905,,,,
,22269637.11,299.9861145,-50109.189453125,8.32084029356051E-5,1.79241293679515E-6,1,0.999253354069792,40.0298881530762,1.99878770328332,15.7800000160933,0.000956921835476561,7.53786470291135E-5,0.25,-7.75572364432989E-6,8.3211104455411E-5,-7.70090895384248E-6,299.9861145,299.9861145,-50116.703125,-50101.67578125,56.976810909333,20.5391229765023,29.742722,0,0,0,40,4449,300.53625,-50109.189453125,,,,,,,,,,,,,0,,,,-0.0049,,,,,,299.9861145,,,,
,22269735.805,299.9896851,-45176.98046875,6.42803541765705E-5,1.81605403320217E-6,1,0.999253354069792,40.0298881530762,1.99885513836337,15.7800000160933,0.000746819026130762,1.46454803557926E-5,0.25,-9.84276920878605E-6,6.42849627545117E-5,-9.80026369456521E-6,299.9896851,299.9896851,-45184.4296875,-45169.53125,56.709493955756,20.5388183965876,29.742722,0,0,0,40,4449,300.5436,-45176.98046875,,,,,,,,,,,,,0,,,,-0.00245,,,,,,299.9896851,,,,
,22269831.165,299.9936218,-40409.40234375,4.62217357000567E-5,1.43604883060292E-6,1,0.999253354069792,40.0298881530762,1.99889453392048,15.7800000160933,0.000537323782632588,8.78519705297236E-6,0.25,-7.23189280199204E-6,4.62251466300235E-5,-7.20128915352001E-6,299.9936218,299.9936218,-40416.81640625,-40401.98828125,56.9799374234099,20.5387255529608,29.742722,0,0,0,40,4449,300.54155,-40409.40234375,,,,,,,,,,,,,0,,,,-0.00245,,,,,,299.9936218,,,,
,22269926.365,299.9916687,-35654.541015625,3.22674429292321E-5,1.51296920506706E-6,1,0.999253354069792,40.0298881530762,1.99886929121762,15.7800000160933,0.000377927337685038,-1.01755399494699E-5,0.25,-6.48954509882186E-6,3.22707762339409E-5,-6.46811768079116E-6,299.9916687,299.9916687,-35664.60546875,-35644.4765625,56.9095908566791,20.5370864099867,29.742722,0,0,0,40,4449,300.5598,-35654.541015625,,,,,,,,,,,,,0,,,,-0.00245,,,,,,299.9916687,,,,
,22270021.4,299.991394,-30902.359375,1.63343480769943E-5,1.45727097541134E-6,1,0.999253354069792,40.0298881530762,1.99889747771862,15.7800000160933,0.000195141350445936,-2.72299757569765E-5,0.25,-5.2358874300406E-6,1.63373222657081E-5,-5.22497208333385E-6,299.991394,299.991394,-30912.25,-30892.46875,57.0198004778906,20.5368567192576,29.742722,0,0,0,40,4449,300.55425,-30902.359375,,,,,,,,,,,,,0,,,,0,,,,,,299.991394,,,,
,22270115.86,299.9875183,-26182.3447265625,-3.32756316372861E-7,9.34251274238689E-7,1,0.999253354069792,40.0298881530762,1.99892956543236,15.7800000160933,5.43642295003167E-6,-5.37684684933466E-5,0.25,-4.6929276468032E-6,-3.2965150353858E-7,-4.69301080734448E-6,299.9875183,299.9875183,-26189.779296875,-26174.91015625,56.9580518248714,20.5383475315544,29.363071,0,0,0,40,4449,300.5676,-26182.3447265625,,,,,,,,,,,,,0,,,,0.00245,,,,,,299.9875183,,,,
,22270211.155,299.9908752,-21417.8642578125,-1.65874947348857E-5,1.25255505859366E-6,1,0.999253354069792,40.0298881530762,1.99880991065312,15.7800000160933,-0.000180943013184986,-7.17068375070826E-5,0.25,-3.46194970376547E-6,-1.65847246702452E-5,-3.47279867201105E-6,299.9906921,299.9910583,-21422.9609375,-21412.767578125,56.9072459711214,20.5382604840301,29.742722,0,0,0,40,4449,300.58125,-21417.8642578125,,,,,,,,,,,,,0,,,,-0.00245,,,,,,299.9908752,,,,
,22270308.495,299.9902649,-16555.7060546875,-3.17404452922509E-5,9.5800733467559E-7,1,0.999253354069792,40.0298881530762,1.99881515437787,15.7800000160933,-0.00035345704373835,-9.55474127305026E-5,0.25,-2.94305601219302E-6,-3.17375721456956E-5,-2.96394266293687E-6,299.9902649,299.9902649,-16565.263671875,-16546.1484375,57.1651833824676,20.5354765236624,29.363071,0,0,0,40,4449,300.5871,-16555.7060546875,,,,,,,,,,,,,0,,,,-0.00245,,,,,,299.9902649,,,,
,22270403.03,299.9913635,-11830.6606445313,-4.51762623210618E-5,8.36081850089332E-7,1,0.999253354069792,40.0298881530762,1.99887273897399,15.7800000160933,-0.000508054371107964,-0.000107344308742912,0.25,-1.65726101638769E-6,-4.51738407990071E-5,-1.68708789265796E-6,299.9913635,299.9913635,-11838.4345703125,-11822.88671875,56.6860451001791,20.538850142904,30.122374,0,0,0,40,4449,300.59705,-11830.6606445313,,,,,,,,,,,,,0,,,,0,,,,,,299.9913635,,,,
,22270501.915,299.9964447,-6887.8232421875,-5.64514095187761E-5,6.36777628949667E-7,1,0.999253354069792,40.0298881530762,1.99883562078923,15.7800000160933,-0.000637283955246802,-0.000120049098123464,0.25,-8.26443811120952E-7,-5.64491930235364E-5,-8.63782437487281E-7,299.995697,299.9971924,-6890.49755859375,-6885.14892578125,56.9088092281599,20.5361854269803,29.363071,0,0,0,40,4449,300.5985,-6887.8232421875,,,,,,,,,,,,,0,,,,-0.0049,,,,,,299.9964447,,,,
,22270598.61,299.9943237,-2054.47875976562,-5.42197635949103E-5,3.93386155240303E-7,1,0.999253354069792,40.0298881530762,1.99888925105381,15.7800000160933,-0.000612703982174558,-0.000111857384920528,0.25,-4.89024358713725E-7,-5.42178379891373E-5,-5.24921862214158E-7,299.9943237,299.9943237,-2056.51098632813,-2052.44653320313,56.8963031718522,20.5358376219018,29.363071,0,0,0,40,4449,300.5943,-2054.47875976562,,,,,,,,,,,,,0,,,,-0.0049,,,,,,299.9943237,,,,
,22270688.595,299.9952393,2438.86047363281,5.50800001258691E-5,3.19948785958867E-7,1,0.999253354069792,40.0298881530762,1.998809797769,15.7800000160933,0.000623303289955826,0.000108422065123327,0.25,3.68215109693959E-8,5.50783470296842E-5,7.32997013182785E-8,299.9952393,299.9952393,2431.29418945313,2446.4267578125,57.0033862789868,20.535388080779,29.363071,0,0,0,40,4449,300.59875,2438.86047363281,,,,,,,,,,,,,0,,,,0.00245,,,,,,299.9952393,,,,
,22270780.85,299.9986877,7053.43896484375,5.65871007709296E-5,4.95759367980921E-7,1,0.999253354069792,40.0298881530762,1.99885724660207,15.7800000160933,0.000638237339962183,0.000123715295506484,0.25,1.12675713784358E-6,5.65846772007352E-5,1.16417420346121E-6,299.9986877,299.9986877,7050.9013671875,7055.9765625,56.811105663256,20.5356485289705,30.122374,0,0,0,40,4449,300.608,7053.43896484375,,,,,,,,,,,,,0,,,,0,,,,,,299.9986877,,,,
,22270875.385,299.9979248,11776.0776367188,4.63550086121088E-5,7.10312957550988E-7,1,0.999253354069792,40.0298881530762,1.99883291892995,15.7800000160933,0.000520669397081849,0.000113786028781952,0.25,2.02238578885671E-6,4.63523001644132E-5,2.05298063306219E-6,299.9979248,299.9979248,11763.423828125,11788.7314453125,56.7673344661791,20.5357838603817,29.363071,0,0,0,40,4449,300.60245,11776.0776367188,,,,,,,,,,,,,0,,,,0,,,,,,299.9979248,,,,
,22270970.22,300.0074768,16519.4541015625,3.15357446539708E-5,8.19622775880435E-7,1,0.999253354069792,40.0298881530762,1.99880600888693,15.7800000160933,0.000353018930731965,8.42924915877264E-5,0.25,1.98410435196008E-6,3.1533491745831E-5,2.00488182151888E-6,300.0074768,300.0074768,16511.81640625,16527.091796875,57.0315249056791,20.5349033078211,29.742722,0,0,0,40,4449,300.5979,16519.4541015625,,,,,,,,,,,,,0,,,,0,,,,,,300.0074768,,,,
,22271063.36,300.0067444,21173.8212890625,1.75328013384293E-5,1.45352167035953E-6,1,0.999253354069792,40.0298881530762,1.99874120488352,15.7800000160933,0.00019369406246614,6.16750519798048E-5,0.25,2.41196649349993E-6,1.75306867956981E-5,2.42346880803921E-6,300.0067444,300.0067444,21163.83203125,21183.810546875,56.8478422036599,20.5350682051054,29.363071,0,0,0,40,4449,300.5935,21173.8212890625,,,,,,,,,,,,,0,,,,-0.00245,,,,,,300.0067444,,,,
,22271158.82,300.0099487,25946.3798828125,3.99970099201992E-6,1.10439918792516E-6,1,0.999253354069792,40.0298881530762,1.99877190935897,15.7800000160933,3.43790064489383E-5,7.06823393553398E-5,0.25,5.55246562253564E-6,3.99591961015157E-6,5.5549377891848E-6,300.0099487,300.0099487,25941.3046875,25951.455078125,56.8454973181022,20.5343590121366,29.742722,0,0,0,40,4449,300.58345,25946.3798828125,,,,,,,,,,,,,0,,,,0.00245,,,,,,300.0099487,,,,
,22271252.36,300.0097656,30619.3505859375,-1.35335229485044E-5,9.94496224701429E-7,1,0.999253354069792,40.0298881530762,1.99875945211062,15.7800000160933,-0.000163099278454885,3.08089018432778E-5,0.25,5.06702227144704E-6,-1.35364584409265E-5,5.05795427319298E-6,300.0095825,300.0099487,30609.392578125,30629.30859375,56.8071975206598,20.5347208359789,29.742722,0,0,0,40,4449,300.5776,30619.3505859375,,,,,,,,,,,,,0,,,,-0.00245,,,,,,300.0097656,,,,
,22271349.78,300.0135956,35486.7890625,-3.16764645757942E-5,1.53694165991216E-6,1,0.999253354069792,40.0298881530762,1.99870585103626,15.7800000160933,-0.000370998017127541,1.01134113191621E-5,0.25,6.38173700297548E-6,-3.1679719214147E-5,6.36069610703263E-6,300.0130005,300.0141907,35481.8671875,35491.7109375,56.9142806277945,20.5328788232845,29.742722,0,0,0,40,4449,300.5622,35486.7890625,,,,,,,,,,,,,0,,,,0,,,,,,300.0135956,,,,
,22271446.695,300.0093079,40332.24609375,-4.68018979410155E-5,1.35781346245215E-6,1,0.999253354069792,40.0298881530762,1.99859558897322,15.7800000160933,-0.000542093395356483,-1.98420957660788E-5,0.25,6.35523547246789E-6,-4.68046891443583E-5,6.32427287560376E-6,300.0093079,300.0093079,40324.8671875,40339.625,57.004167907506,20.5336175220618,30.122374,0,0,0,40,4449,300.551,40332.24609375,,,,,,,,,,,,,0,,,,0.00245,,,,,,300.0093079,,,,
,22271544.175,300.0100403,45204.7734375,-6.48954097154694E-5,1.62124498709227E-6,1,0.999253354069792,40.0298881530762,1.99865550874194,15.7800000160933,-0.000755963169582124,-2.83206623092655E-6,0.25,1.09930856747224E-5,-6.49007085420459E-5,1.09501361273194E-5,300.0100403,300.0100403,45196.99609375,45212.55078125,56.533627538929,20.5340433684014,29.742722,0,0,0,40,4449,300.54895,45204.7734375,,,,,,,,,,,,,0,,,,0.00245,,,,,,300.0100403,,,,
,22271640.95,300.009613,50039.994140625,-7.73180801033441E-5,2.74861261267154E-6,1,0.999253354069792,40.0298881530762,1.99866402228962,15.7800000160933,-0.000889516418892329,-6.77969468344934E-5,0.25,7.40475814912375E-6,-7.73206550547381E-5,7.35381261904645E-6,300.009613,300.009613,50034.734375,50045.25390625,56.8673829166406,20.5343734405019,29.742722,0,0,0,40,4449,300.54405,50039.994140625,,,,,,,,,,,,,0,,,,0,,,,,,300.009613,,,,
,22271737.615,300.01272585,54874.744140625,-9.89878841135917E-5,2.30924535362206E-6,1,0.999253354069792,40.0298881530762,1.99866559043071,15.7800000160933,-0.00114844105317533,-3.12681907282222E-5,0.25,1.43868508178978E-5,-9.89943849199555E-5,1.43215522357386E-5,300.0126648,300.0127869,54867.3671875,54882.12109375,57.0932735586983,20.5324571845463,29.742722,0,0,0,40,4449,300.5285,54874.744140625,,,,,,,,,,,,,0,,,,0,,,,,,300.01272585,,,,
,22271837.6,300.0132751,59869.9140625,-0.000113034646774917,2.4572153661495E-6,1,0.999253354069792,40.0298881530762,1.99855699958404,15.7800000160933,-0.00130443547849251,-7.55630107216902E-5,0.25,1.29059911946627E-5,-0.000113039757205131,1.28316177174992E-5,300.0132751,300.0132751,59860.05078125,59879.77734375,56.6766655579483,20.531462714768,30.122374,0,0,0,40,4449,300.517,59869.9140625,,,,,,,,,,,,,0,,,,0,,,,,,300.0132751,,,,
,22271934.675,300.0116272,64720.3671875,-0.000135103652481936,2.55597105277605E-6,1,0.999253354069792,40.0298881530762,1.99857979124566,15.7800000160933,-0.00155120691339567,-0.00013605997049416,0.25,1.13834877232524E-5,-0.00013510712307618,1.12948168602735E-5,300.0116272,300.0116272,64712.86328125,64727.87109375,56.946327397083,20.533372950493,29.742722,0,0,0,40,4449,300.5081,64720.3671875,,,,,,,,,,,,,0,,,,0.00245,,,,,,300.0116272,,,,
,22272029.775,300.0123291,69475.2890625,-0.000145369704828518,2.42402697157239E-6,1,0.999253354069792,40.0298881530762,1.99845693481205,15.7800000160933,-0.00166341305080304,-0.000178521124374443,0.25,9.40887326944607E-6,-0.000145371581460446,9.31365791689978E-6,300.0123291,300.0123291,69470.28125,69480.296875,56.5836517641598,20.5332743529961,29.742722,0,0,0,40,4449,300.49885,69475.2890625,,,,,,,,,,,,,0,,,,0.00245,,,,,,300.0123291,,,,
,22272127.75,300.01651,74370.73828125,-0.000164574381896047,3.04441694448909E-6,1,0.999253354069792,40.0298881530762,1.99848667547563,15.7800000160933,-0.00188560518116573,-0.000188177701358403,0.25,1.18828030549019E-5,-0.000164577287729466,1.17750988625611E-5,300.01651,300.01651,74363.4765625,74378,56.6930797568522,20.5336995017299,30.122374,0,0,0,40,4449,300.48455,74370.73828125,,,,,,,,,,,,,0,,,,-0.00245,,,,,,300.01651,,,,
,22272227.475,300.0140991,79356.23046875,-0.000180099426619865,3.57000273704752E-6,1,0.999253354069792,40.0298881530762,1.99844382012515,15.7800000160933,-0.0020662082738938,-0.000189951141610249,0.25,1.4415288670067E-5,-0.000180103544148999,1.42975275866531E-5,300.0140991,300.0140991,79346.1796875,79366.28125,56.5688008222944,20.5337418244521,30.122374,0,0,0,40,4449,300.4686,79356.23046875,,,,,,,,,,,,,0,,,,0,,,,,,300.0140991,,,,
,22272324.395,300.0166016,84202.1875,-0.000204817335723807,3.32670111427287E-6,1,0.999253354069792,40.0298881530762,1.99843340854155,15.7800000160933,-0.00234040757442619,-0.000270089981940364,0.25,1.16152245624067E-5,-0.000204818891833872,1.14816042585133E-5,300.0166016,300.0166016,84189.2890625,84215.0859375,56.9119357422368,20.5315123970431,29.742722,0,0,0,40,4449,300.4607,84202.1875,,,,,,,,,,,,,0,,,,0,,,,,,300.0166016,,,,
,22272415.505,300.0115662,88757.546875,-0.00021065505752767,3.27169942032911E-6,1,0.999253354069792,40.0298881530762,1.99846764296908,15.7800000160933,-0.00241422932293407,-0.00023695254298365,0.25,1.55552488856588E-5,-0.000210659046790665,1.54178730190096E-5,300.0115662,300.0115662,88747.6171875,88767.4765625,56.7102755842752,20.5327980594025,30.122374,0,0,0,40,4449,300.44485,88757.546875,,,,,,,,,,,,,0,,,,0,,,,,,300.0115662,,,,
,22272526.06,300.0107117,86703.74609375,-0.000205621850251505,3.09849466689046E-6,1,0.999253354069792,40.0298881530762,1.99836173345121,15.7800000160933,-0.00235147567129386,-0.000259857381211164,0.25,1.26580363135292E-5,-0.00020562410690946,1.2523940799072E-5,300.0107117,300.0107117,86698.9765625,86708.515625,56.5617661656214,20.534094138582,30.122374,0,0,0,40,4449,300.43835,86703.74609375,,,,,,,,,,,,,0,,,,0.0049,,,,,,300.0107117,,,,
,22272619.16,299.9981689,82047.7421875,-0.00019514629514331,3.55991041109544E-6,1,0.999253354069792,40.0298881530762,1.99830208704392,15.7800000160933,-0.00223006683764518,-0.000255550406093414,0.25,1.12233347847193E-5,-0.000195148006428801,1.10959471098202E-5,299.9981689,299.9981689,82040.3359375,82055.1484375,56.6563432164483,20.5340886828193,29.363071,0,0,0,40,4449,300.44455,82047.7421875,,,,,,,,,,,,,0,,,,0,,,,,,299.9981689,,,,
,22272715.46,299.9938202,77233.9765625,-0.000173623870219483,2.76673852731097E-6,1,0.999253354069792,40.0298881530762,1.99839163553553,15.7800000160933,-0.00199184908037373,-0.000183229756480457,0.25,1.38870784823935E-5,-0.000173627959148251,1.37734929094498E-5,299.9932251,299.9944153,77221.5859375,77246.3671875,56.9322580837368,20.5349993310791,29.363071,0,0,0,40,4449,300.4531,77233.9765625,,,,,,,,,,,,,0,,,,-0.0049,,,,,,299.9938202,,,,
,22272814.695,299.9920959,72273.0625,-0.00015814144286794,2.89167220491003E-6,1,0.999253354069792,40.0298881530762,1.99842281599594,15.7800000160933,-0.00181169751528398,-0.000181675778187621,0.25,1.13424774180432E-5,-0.000158144323239256,1.12389299352127E-5,299.9920959,299.9920959,72268.0078125,72278.1171875,56.6368025034675,20.5375806018181,29.363071,0,0,0,40,4449,300.45955,72273.0625,,,,,,,,,,,,,0,,,,-0.00245,,,,,,299.9920959,,,,
,22272913.735,299.98927305,67325.43359375,-0.000136728161312045,3.0771033999823E-6,1,0.999253354069792,40.0298881530762,1.9984218053617,15.7800000160933,-0.00156084486521104,-0.000189038450980205,0.25,6.98208175937676E-6,-0.000136728817805616,6.8925284114793E-6,299.9881897,299.9903564,67320.359375,67330.5078125,56.5617661656214,20.5357300894712,29.742722,0,0,0,40,4449,300.4693,67325.43359375,,,,,,,,,,,,,0,,,,0,,,,,,299.98927305,,,,
,22273008.025,299.9869385,62609.8359375,-0.000122625733284131,2.69839790947622E-6,1,0.999253354069792,40.0298881530762,1.99851615360157,15.7800000160933,-0.00140480998484826,-0.000141318824390171,0.25,8.75665977009025E-6,-0.000122627961085493,8.67618002467441E-6,299.9869385,299.9869385,62607.1796875,62612.4921875,56.8329912617945,20.5355562470519,29.742722,0,0,0,40,4449,300.47545,62609.8359375,,,,,,,,,,,,,0,,,,-0.00245,,,,,,299.9869385,,,,
,22273101.255,299.987793,57949.060546875,-0.0001093176076694,2.38201890178898E-6,1,0.999253354069792,40.0298881530762,1.99849973594815,15.7800000160933,-0.00125049739881867,-0.000136623280004659,0.25,6.86594790776694E-6,-0.000109318973008675,6.7941492822418E-6,299.987793,299.987793,57939.171875,57958.94921875,56.8798889729483,20.5357708823176,30.122374,0,0,0,40,4449,300.4842,57949.060546875,,,,,,,,,,,,,0,,,,0,,,,,,299.987793,,,,
,22273197.69,299.9840088,53128.759765625,-9.36899362872228E-5,2.31319949270661E-6,1,0.999253354069792,40.0298881530762,1.9984323729811,15.7800000160933,-0.00107719603321512,-8.53437507196282E-5,0.25,8.68986291453192E-6,-9.36929569812115E-5,8.62817778686721E-6,299.9840088,299.9840088,53116.1953125,53141.32421875,56.9416376259676,20.5364122312584,29.742722,0,0,0,40,4449,300.48665,53128.759765625,,,,,,,,,,,,,0,,,,0.00245,,,,,,299.9840088,,,,
,22273298.47,299.9841614,48091.462890625,-6.989311895722E-5,1.79101013004897E-6,1,0.999253354069792,40.0298881530762,1.99850542919936,15.7800000160933,-0.000804478503028996,-5.87206388815435E-5,0.25,6.92002121979459E-6,-6.98956593146587E-5,6.87393987467857E-6,299.9841614,299.9841614,48083.88671875,48099.0390625,56.7626446950637,20.5346185241343,30.122374,0,0,0,40,4449,300.5078,48091.462890625,,,,,,,,,,,,,0,,,,0.00245,,,,,,299.9841614,,,,
,22273393.875,299.987915,43323.619140625,-5.62440703993695E-5,2.34188302467608E-6,1,0.999253354069792,40.0298881530762,1.99837555734545,15.7800000160933,-0.000650404062116012,-2.95421027360646E-5,0.25,7.13367938347595E-6,-5.62471359740615E-5,7.09651112466505E-6,299.987915,299.987915,43316.19140625,43331.046875,56.618043419006,20.5343143077723,29.742722,0,0,0,40,4449,300.51685,43323.619140625,,,,,,,,,,,,,0,,,,0.00245,,,,,,299.987915,,,,
,22273490.23,299.9908752,38508.654296875,-3.75235204503011E-5,1.59313069136942E-6,1,0.999253354069792,40.0298881530762,1.99856137682988,15.7800000160933,-0.000434892339799326,-1.43231189718145E-5,0.25,5.2354068071177E-6,-3.75258759263353E-5,5.21056837154401E-6,299.9908752,299.9908752,38498.62109375,38518.6875,56.9361662263329,20.5376142815161,29.742722,0,0,0,40,4449,300.5192,38508.654296875,,,,,,,,,,,,,0,,,,0.00245,,,,,,299.9908752,,,,
,22273582.84,299.9862366,33881.4609375,-2.19036754752234E-5,1.25250557687621E-6,1,0.999253354069792,40.0298881530762,1.99829630385948,15.7800000160933,-0.000255782746870857,2.92010790394526E-6,0.25,4.05299803461775E-6,-2.19057113074861E-5,4.03845649275286E-6,299.9862366,299.9862366,33876.54296875,33886.37890625,56.7876568076791,20.534610681128,29.742722,0,0,0,40,4449,300.5328,33881.4609375,,,,,,,,,,,,,0,,,,-0.00245,,,,,,299.9862366,,,,
,22273678.86,299.9892883,29081.533203125,-5.35076793466763E-6,1.57648332999762E-6,1,0.999253354069792,40.0298881530762,1.99839458528375,15.7800000160933,-7.03839056355034E-5,4.62919881766154E-5,0.25,5.01810955720564E-6,-5.35392031165602E-6,5.01443637623108E-6,299.9892883,299.9892883,29074.26953125,29088.796875,56.7415407250445,20.5374075290016,30.122374,0,0,0,40,4449,300.53845,29081.533203125,,,,,,,,,,,,,0,,,,0,,,,,,299.9892883,,,,
,22273770.75,299.9913635,24488.728515625,8.95123901814105E-6,1.31126137900422E-6,1,0.999253354069792,40.0298881530762,1.99840970675177,15.7800000160933,9.4804774994602E-5,5.49663117448457E-5,0.25,3.30676003340931E-6,8.9487956858895E-6,3.31256968915194E-6,299.9913635,299.9913635,24475.931640625,24501.525390625,56.6508718168137,20.5383017252025,29.742722,0,0,0,40,4449,300.54535,24488.728515625,,,,,,,,,,,,,0,,,,0,,,,,,299.9913635,,,,
,22273865.315,299.986084,19763.615234375,2.49379622682758E-5,1.19037185232519E-6,1,0.999253354069792,40.0298881530762,1.99830841679875,15.7800000160933,0.000275718600204666,8.61328251031117E-5,0.25,3.29163628742534E-6,2.49350634730275E-5,3.3080097952393E-6,299.986084,299.986084,19753.806640625,19773.423828125,56.7204367550252,20.5399026058435,29.742722,0,0,0,40,4449,300.56365,19763.615234375,,,,,,,,,,,,,0,,,,-0.0049,,,,,,299.986084,,,,
,22273962.62,299.98965455,14899.2216796875,3.72430652980872E-5,6.72708021639187E-7,1,0.999253354069792,40.0298881530762,1.99834892488564,15.7800000160933,0.000417379389375401,9.62821253252509E-5,0.25,2.05648916445412E-6,3.72406164541176E-5,2.08104697286347E-6,299.9891968,299.9901123,14886.849609375,14911.59375,56.9799374234099,20.5387940309174,30.122374,0,0,0,40,4449,300.57035,14899.2216796875,,,,,,,,,,,,,0,,,,-0.00245,,,,,,299.98965455,,,,
,22274057.61,299.9886475,10151.8198242187,5.0632036149749E-5,6.23794923945437E-7,1,0.999253354069792,40.0298881530762,1.998284007605,15.7800000160933,0.000570053551096806,0.000115637640998443,0.25,1.4476210114322E-6,5.06295965360703E-5,1.48107548865182E-6,299.9886475,299.9886475,10144.2353515625,10159.404296875,56.6985511564868,20.5366316010984,29.742722,0,0,0,40,4449,300.5706,10151.8198242187,,,,,,,,,,,,,0,,,,0.0049,,,,,,299.9886475,,,,
,22274153.615,299.9914856,5354.32861328125,5.94530225991879E-5,5.36292215608496E-7,1,0.999253354069792,40.0298881530762,1.99836605894129,15.7800000160933,0.000670726291512237,0.000128093506976487,0.25,1.01968901143096E-6,5.94505986857872E-5,1.05902123277761E-6,299.9914856,299.9914856,5351.64990234375,5357.00732421875,56.6493085597752,20.5401246899855,30.122374,0,0,0,40,4449,300.57895,5354.32861328125,,,,,,,,,,,,,0,,,,-0.0049,,,,,,299.9914856,,,,
,22274247.595,299.9920654,657.896240234375,4.39446524581421E-5,3.70813382303041E-7,1,0.999253354069792,40.0298881530762,1.99831807843441,15.7800000160933,0.000497161970886179,8.65596810926496E-5,0.25,3.61979885308458E-8,4.39433333870842E-5,6.53086716184449E-8,299.9920654,299.9920654,652.813171386719,662.979309082031,56.7485753817175,20.5406711665395,29.742722,0,0,0,40,4449,300.58785,657.896240234375,,,,,,,,,,,,,0,,,,-0.0049,,,,,,299.9920654,,,,
,22274261.775,299.9962463,-0.380594313144684,9.81575424233992E-6,4.68452986521238E-7,1,0.999253354069792,40.0298881530762,1.9983382587597,15.7800000160933,0.000111918783949181,1.43219576510201E-5,0.25,-4.34928807006407E-7,9.81575159615669E-6,-4.28412970236748E-7,299.9962463,299.9962463,-0.380594313144684,-0.380594313144684,57.0440309619868,20.541640616249,30.122374,0,0,0,40,4417,300.5874,-0.380594313144684,,,,,,,,,,,,,0,,,,0.00245,,,,,,299.9962463,,,,