File: data/doubleLayers/dl_1-25/ppms/data/DD205_3_HYST_100OE_350K.DAT
[Header]
; VSM Data File (default extension .dat)
; Copyright (c) 2003-2013, Quantum Design, Inc. All rights reserved.
TITLE,
FILEOPENTIME,32606454.52,01/13/2019,5:23 pm
BYAPP,VSM,2.0,2.0
INFO,PPMS VSM Option Release 1.4.10 Build 1,APPNAME
INFO,Quantum Design Linear Motor Servo Controller,MOTOR_MODULE_NAME
INFO,3101-100 M1,MOTOR_HW_VERSION
INFO,MMC1014,MOTOR_SERIAL_NUMBER
INFO,SRV No X-over 01.03.11,MOTOR_SOFTWARE_VERSION
INFO,Quantum Design VSM Detection Module,VSM_MODULE_NAME
INFO,3101-150 F0,VSM_HW_VERSION
INFO,VSM707,VSM_SERIAL_NUMBER
INFO,VSM No X-over 01.02.05 May 20 2008 13:51:47,VSM_SOFTWARE_VERSION
INFO,704,PREAMP_SERIAL_NUMBER
INFO,822,COIL_SERIAL_NUMBER
INFO,0,MOMENT_UNITS
INFO,DD205_4,SAMPLE_MATERIAL
INFO,Double Layer Blue 1.25,SAMPLE_COMMENT
INFO,26.73,SAMPLE_MASS
INFO,,SAMPLE_VOLUME
INFO,,SAMPLE_MOLECULAR_WEIGHT
INFO,,SAMPLE_SIZE
INFO,,SAMPLE_SHAPE
DATATYPE,COMMENT,1
DATATYPE,TIME,2
STARTUPAXIS,X,2
STARTUPAXIS,Y1,5
[Data]
Comment,Time Stamp (sec),Temperature (K),Magnetic Field (Oe),Moment (emu),M. Std. Err. (emu),Transport Action,Averaging Time (sec),Frequency (Hz),Peak Amplitude (mm),Center Position (mm),Coil Signal' (mV),Coil Signal" (mV),Range (mV),M. Quad. Signal (emu),M. Raw' (emu),M. Raw" (emu),Min. Temperature (K),Max. Temperature (K),Min. Field (Oe),Max. Field (Oe),Mass (grams),Motor Lag (deg),Pressure (Torr),VSM Status (code),Motor Status (code),Measure Status (code),Measure Count,PPMS Status (code),System Temp. (K),System Field (Oe),Sample Position (deg),Bridge 1 Resistance (ohms),Bridge 1 Excitation (에),Bridge 2 Resistance (ohms),Bridge 2 Excitation (에),Bridge 3 Resistance (ohms),Bridge 3 Excitation (에),Bridge 4 Resistance (ohms),Bridge 4 Excitation (에),Signal 1 Vin (V),Signal 2 Vin (V),Digital Inputs (code),Drive 1 Iout (mA),Drive 1 Ipower (W),Drive 2 Iout (mA),Drive 2 Ipower (W),Pressure (),Map 20 (),Map 21 (),Map 22 (),Map 23 (),Map 24 (),Map 25 (),Map 26 (),Map 27 (),Map 28 (),Map 29 ()
,32606470.36,349.9832458,-0.258804142475128,,,2,,,,19.3099997350574,,,,,,,349.9832458,349.9832458,-0.258804142475128,-0.258804142475128,,,26.325863,,,,-99999999,4369,350.4291,-0.258804142475128,,,,,,,,,,,,,,,,,,,,,,,349.9832458,,,,
,32606589.525,349.9728088,3104.32727050781,4.59395263894368E-5,4.61527211722889E-7,1,0.999253354069792,40.0298881530762,1.99900096755419,19.3000007420778,0.000518809584637802,9.14273260915718E-5,0.25,1.37033377506717E-7,4.58580450837501E-5,1.62372960955155E-7,349.9728088,349.9728088,3099.3388671875,3109.31567382812,56.3858997487944,20.568506701383,25.946213,0,0,0,40,4449,350.46535,3104.32727050781,,,,,,,,,,,,,0,,,,0.00245,,,,,,349.9728088,,,,
,32606655.43,349.9643555,6393.20458984375,4.54704355045832E-5,5.84287559440358E-7,1,0.999253354069792,40.0298881530762,1.99902773263042,19.3000007420778,0.00051449518090806,8.485553218452E-5,0.25,-3.63447529181827E-7,4.53900779173978E-5,-3.37494371724437E-7,349.9643555,349.9643555,6388.1591796875,6398.25,56.5711457078521,20.5707259851112,25.566563,0,0,0,40,4449,350.4918,6393.20458984375,,,,,,,,,,,,,0,,,,-0.00245,,,,,,349.9643555,,,,
,32606720.99,349.9558716,9672.06982421875,4.02699956064517E-5,5.77255825578905E-7,1,0.999253354069792,40.0298881530762,1.99891472889694,19.3000007420778,0.000456276637005886,7.14009929808756E-5,0.25,-6.53376708098484E-7,4.01990252125586E-5,-6.29816021356581E-7,349.9558716,349.9558716,9662.0830078125,9682.056640625,56.8540952318137,20.5732591313906,26.325863,0,0,0,40,4449,350.51475,9672.06982421875,,,,,,,,,,,,,0,,,,-0.0049,,,,,,349.9558716,,,,
,32606789.73,349.9671631,13107.4521484375,3.14212159552437E-5,9.0992237472377E-7,1,0.999253354069792,40.0298881530762,1.99925138062839,19.3000007420778,0.00035435838632382,6.56240631738193E-5,0.25,3.66581472537473E-7,3.13653415511398E-5,3.8340382660392E-7,349.9671631,349.9671631,13099.98046875,13114.923828125,56.9854088230445,20.56969991107,26.325863,0,0,0,40,4449,350.5141,13107.4521484375,,,,,,,,,,,,,0,,,,-0.00245,,,,,,349.9671631,,,,
,32606856.255,349.970459,16431.064453125,2.20632173776677E-5,9.24875872210891E-7,1,0.999253354069792,40.0298881530762,1.99931532253354,19.3000007420778,0.000247182528193082,5.55925947328173E-5,0.25,1.09907992379258E-6,2.20235141861091E-5,1.10939339864941E-6,349.970459,349.970459,16423.5,16438.62890625,57.0596635323714,20.5694683648349,26.325863,0,0,0,40,4449,350.5503,16431.064453125,,,,,,,,,,,,,0,,,,0,,,,,,349.970459,,,,
,32606924.91,349.9729309,19861.703125,1.30487457434469E-5,1.37997352576735E-6,1,0.999253354069792,40.0298881530762,1.99937712848907,19.3000007420778,0.000146650361531258,3.02460140876514E-5,0.25,4.16970467065204E-7,1.30253931235306E-5,4.23479013768195E-7,349.9725952,349.9732666,19851.611328125,19871.794921875,57.0518472471791,20.5699293550042,26.325863,0,0,0,40,4449,350.55395,19861.703125,,,,,,,,,,,,,0,,,,0,,,,,,349.9729309,,,,
,32606993.33,349.9802551,23282.646484375,3.41753520621296E-6,1.06014531653255E-6,1,0.999253354069792,40.0298881530762,1.99929555522032,19.3000007420778,3.91578033394471E-5,3.58511158898299E-6,0.25,-2.74498619670134E-7,3.41163129468155E-6,-2.7211517396417E-7,349.9802551,349.9802551,23275.302734375,23289.990234375,57.0080760501022,20.5747840694071,25.946213,0,0,0,40,4449,350.5654,23282.646484375,,,,,,,,,,,,,0,,,,-0.00245,,,,,,349.9802551,,,,
,32607063.7,349.978302,26803.58203125,-9.18971698068667E-6,1.42085303709524E-6,1,0.999253354069792,40.0298881530762,1.99936683059686,19.3000007420778,-0.000103564903115018,-1.96529292730643E-5,0.25,-1.47832525073901E-7,-9.17335054409901E-6,-1.52668404952951E-7,349.978302,349.978302,26798.5546875,26808.609375,57.1034347294484,20.5734791455237,25.946213,0,0,0,40,4449,350.5757,26803.58203125,,,,,,,,,,,,,0,,,,-0.0049,,,,,,349.978302,,,,
,32607131.09,349.9826965,30169.0224609375,-1.90240291341336E-5,1.82855376821899E-6,1,0.999253354069792,40.0298881530762,1.99933534514616,19.3000007420778,-0.000213401235952058,-4.63995746166516E-5,0.25,-8.11822497906165E-7,-1.89898656458131E-5,-8.20930511135062E-7,349.9826965,349.9826965,30166.44140625,30171.603515625,57.2066096939868,20.5733014915021,25.946213,0,0,0,40,4449,350.5906,30169.0224609375,,,,,,,,,,,,,0,,,,-0.0049,,,,,,349.9826965,,,,
,32607198.13,349.9827576,33520.06640625,-2.7105598770936E-5,1.79825038326899E-6,1,0.999253354069792,40.0298881530762,1.99929163397102,19.3000007420778,-0.000305690894636105,-5.66298163089113E-5,0.25,-3.17876648453948E-7,-2.70573880807363E-5,-3.32331535004086E-7,349.9827576,349.9827576,33510.03125,33530.1015625,57.2675767184868,20.5741055637169,25.946213,0,0,0,40,4449,350.58835,33520.06640625,,,,,,,,,,,,,0,,,,-0.0049,,,,,,349.9827576,,,,
,32607267.04,349.9913635,36962.7890625,-3.9988666670047E-5,2.08888347703973E-6,1,0.999253354069792,40.0298881530762,1.99937868558439,19.3000007420778,-0.000452032930310327,-7.75942172266043E-5,0.25,5.79376375055016E-8,-3.99178231585826E-5,3.5692322294026E-8,349.9913635,349.9913635,36952.85546875,36972.72265625,57.0088576786214,20.5761339187956,26.325863,0,0,0,40,4449,350.58605,36962.7890625,,,,,,,,,,,,,0,,,,0,,,,,,349.9913635,,,,
,32607336.505,349.9941711,40436.244140625,-5.07723458496191E-5,2.24156040124733E-6,1,0.999253354069792,40.0298881530762,1.99936087005774,19.3000007420778,-0.000571902401556953,-0.000110210995630435,0.25,-9.61128771531121E-7,-5.06818221573746E-5,-9.87519703512938E-7,349.9941711,349.9941711,40431.4453125,40441.04296875,57.281646031833,20.577903764799,25.946213,0,0,0,40,4449,350.6037,40436.244140625,,,,,,,,,,,,,0,,,,0,,,,,,349.9941711,,,,
,32607407.36,349.9961243,43974.48046875,-6.13650609675575E-5,2.44110457135661E-6,1,0.999253354069792,40.0298881530762,1.99954114897006,19.3000007420778,-0.000694173329194398,-0.000116498557579984,0.25,3.17472770332258E-7,-6.12564670596119E-5,2.82975151921835E-7,349.9961243,349.9961243,43969.5625,43979.3984375,57.3668435404292,20.5768327332691,25.946213,0,0,0,40,4449,350.5887,43974.48046875,,,,,,,,,,,,,0,,,,0,,,,,,349.9961243,,,,
,32607476.175,349.9891968,47418.228515625,-6.98961140292004E-5,2.80792924402065E-6,1,0.999253354069792,40.0298881530762,1.9994230876403,19.3000007420778,-0.000787644120020339,-0.000149954156703206,0.25,-1.16629856739579E-6,-6.97715969593838E-5,-1.20285917420363E-6,349.9891968,349.9891968,47408.24609375,47428.2109375,57.2269320354868,20.5771322278956,25.946213,0,0,0,40,4449,350.5869,47418.228515625,,,,,,,,,,,,,0,,,,0,,,,,,349.9891968,,,,
,32607544.865,349.9966125,50851.673828125,-8.35959948705215E-5,2.59968623635938E-6,1,0.999253354069792,40.0298881530762,1.99921702455901,19.3000007420778,-0.000945283564434939,-0.000159972653766887,0.25,3.17886203330604E-7,-8.34479999169872E-5,2.71155801674734E-7,349.9966125,349.9966125,50847.0546875,50856.29296875,57.200356665833,20.577654223478,26.325863,0,0,0,40,4449,350.59675,50851.673828125,,,,,,,,,,,,,0,,,,0.00245,,,,,,349.9966125,,,,
,32607613.165,350.0059814,54262.333984375,-9.51580826458968E-5,2.34652305048796E-6,1,0.999253354069792,40.0298881530762,1.9992812766817,19.3000007420778,-0.00107568246889271,-0.000184270313060525,0.25,1.70107663764536E-7,-9.49894852130654E-5,1.17288758201324E-7,350.0059814,350.0059814,54259.96875,54264.69921875,57.2746113751599,20.5787875044921,26.325863,0,0,0,40,4449,350.59705,54262.333984375,,,,,,,,,,,,,0,,,,-0.0049,,,,,,350.0059814,,,,
,32607681.47,350.0010986,57675.322265625,-0.000107271531184469,2.65932109373192E-6,1,0.999253354069792,40.0298881530762,1.99933594408197,19.3000007420778,-0.00120215693583563,-0.000268316696133803,0.25,-5.16920633147265E-6,-0.000107078535522926,-5.21920632475415E-6,350.0010986,350.0010986,57672.953125,57677.69140625,57.2808644033138,20.5768272698793,26.325863,0,0,0,40,4449,350.59855,57675.322265625,,,,,,,,,,,,,0,,,,-0.0049,,,,,,350.0010986,,,,
,32607750.07,349.9978333,61106.525390625,-0.000118873439318068,2.72635719407523E-6,1,0.999253354069792,40.0298881530762,1.99959980184759,19.3000007420778,-0.00133762032354127,-0.000266898756054166,0.25,-3.03198251984875E-6,-0.000118661075021546,-3.09212461660125E-6,349.9978333,349.9978333,61096.73046875,61116.3203125,57.1425161554099,20.5765958496363,26.325863,0,0,0,40,4449,350.6019,61106.525390625,,,,,,,,,,,,,0,,,,0.0049,,,,,,349.9978333,,,,
,32607820.375,350.0043335,64620.466796875,-0.000129233659658868,3.36395051056843E-6,1,0.999253354069792,40.0298881530762,1.9992278474674,19.3000007420778,-0.00145464760191389,-0.000286021812185702,0.25,-2.93465206410904E-6,-0.000129002962699076,-3.0006281498017E-6,350.0043335,350.0043335,64615.48046875,64625.453125,57.0862389020253,20.5778680321282,25.946213,0,0,0,40,4449,350.5894,64620.466796875,,,,,,,,,,,,,0,,,,-0.0049,,,,,,350.0043335,,,,
,32607891.335,350.0022888,68168.5234375,-0.000138115654454342,4.12483132470859E-6,1,0.999253354069792,40.0298881530762,1.99924305978379,19.3000007420778,-0.00156382318027789,-0.000252611521829505,0.25,1.55989488252243E-6,-0.000137871701591557,1.48111339368558E-6,350.0022888,350.0022888,68158.4453125,68178.6015625,57.3191642007561,20.5776587403693,26.325863,0,0,0,40,4449,350.58275,68168.5234375,,,,,,,,,,,,,0,,,,-0.00245,,,,,,350.0022888,,,,
,32607962.315,350.0117798,71714.71875,-0.000150859419078299,3.44680701393206E-6,1,0.999253354069792,40.0298881530762,1.99926551935482,19.3000007420778,-0.00170449294171791,-0.000296946206204341,0.25,-1.56641110272419E-7,-0.000150591889361047,-2.39332195801778E-7,350.0117798,350.0117798,71707.15625,71722.28125,57.3160376866791,20.5718102409794,26.325863,0,0,0,40,4449,350.5883,71714.71875,,,,,,,,,,,,,0,,,,0.00245,,,,,,350.0117798,,,,
,32608033.39,350.0091858,75265.30078125,-0.000165434222901134,4.06557115388059E-6,1,0.999253354069792,40.0298881530762,1.99908561449175,19.3000007420778,-0.00186796451375091,-0.000331626744357033,0.25,-7.04597715091396E-7,-0.000165140573330031,-7.94266979052805E-7,350.0091858,350.0091858,75260.515625,75270.0859375,57.2988418592561,20.5792288090249,25.946213,0,0,0,40,4449,350.5857,75265.30078125,,,,,,,,,,,,,0,,,,0.00245,,,,,,350.0091858,,,,
,32608103.65,350.0040894,78778.91015625,-0.000175169922797204,3.30390076282055E-6,1,0.999253354069792,40.0298881530762,1.99904717116398,19.3000007420778,-0.00196951549108429,-0.000399314167790251,0.25,-5.00987078959661E-6,-0.000174856685793467,-5.09719380508417E-6,350.0040894,350.0040894,78768.8984375,78788.921875,57.2245871499291,20.5789089372577,26.705515,0,0,0,40,4449,350.56765,78778.91015625,,,,,,,,,,,,,0,,,,-0.00245,,,,,,350.0040894,,,,
,32608173.205,350.0151978,82255.546875,-0.000188328832438953,3.6947463883412E-6,1,0.999253354069792,40.0298881530762,1.99908904785494,19.3000007420778,-0.00213243722180804,-0.000343098888333092,0.25,2.24409259040596E-6,-0.000187996189363026,2.13675808034094E-6,350.0151978,350.0151978,82252.8671875,82258.2265625,57.4160861371407,20.5797922124726,25.946213,0,0,0,40,4449,350.56015,82255.546875,,,,,,,,,,,,,0,,,,-0.00245,,,,,,350.0151978,,,,
,32608241.93,350.01359555,85691.765625,-0.000197490596307434,3.12241226299774E-6,1,0.999253354069792,40.0298881530762,1.99885840479121,19.3000007420778,-0.00222583392403295,-0.000418057329243429,0.25,-2.80746844135773E-6,-0.000197138956424029,-2.9107960050201E-6,350.0130615,350.0141296,85681.5078125,85702.0234375,57.180034324333,20.5752976846468,25.946213,0,0,0,40,4449,350.5622,85691.765625,,,,,,,,,,,,,0,,,,0,,,,,,350.01359555,,,,
,32608308.125,350.0211792,89000.1328125,-0.000205758084876128,3.3482749308116E-6,1,0.999253354069792,40.0298881530762,1.99904662416172,19.3000007420778,-0.00232343643059793,-0.000411251875458142,0.25,-7.7049434527811E-7,-0.000205392859552879,-8.81886354581166E-7,350.0211792,350.0211792,88990.0859375,89010.1796875,57.2214606358522,20.5748327909397,26.325863,0,0,0,40,4449,350.56375,89000.1328125,,,,,,,,,,,,,0,,,,-0.00245,,,,,,350.0211792,,,,
,32608393.155,350.0152893,87685.5234375,-0.000205204285800286,3.91379358420889E-6,1,0.999253354069792,40.0298881530762,1.99898312082848,19.3000007420778,-0.0023085720090322,-0.000459462334679458,0.25,-5.13420201593806E-6,-0.00020483768771638,-5.23759553578484E-6,350.0152893,350.0152893,87673.078125,87697.96875,57.0502839901407,20.575516034048,26.705515,0,0,0,40,4449,350.53455,87685.5234375,,,,,,,,,,,,,0,,,,0,,,,,,350.0152893,,,,
,32608459.225,350.0004883,84384.0859375,-0.000193245491639804,3.55486098132495E-6,1,0.999253354069792,40.0298881530762,1.99870697762528,19.3000007420778,-0.00217858971317205,-0.000404668893351431,0.25,-2.3600257343015E-6,-0.00019290170472507,-2.4618585778409E-6,350.0004883,350.0004883,84379.1171875,84389.0546875,57.1151591572368,20.5774053599805,26.705515,0,0,0,40,4449,350.5296,84384.0859375,,,,,,,,,,,,,0,,,,0,,,,,,350.0004883,,,,
,32608528.725,349.9988403,80908.015625,-0.000184051096127577,3.2967171771119E-6,1,0.999253354069792,40.0298881530762,1.99913599495441,19.3000007420778,-0.00207849135338734,-0.000367408902315837,0.25,-6.47184045483831E-7,-0.000183724548833853,-7.47081107353083E-7,349.9988403,349.9988403,80900.484375,80915.546875,57.3043132588907,20.5796045112598,27.085165,0,0,0,40,4449,350.5359,80908.015625,,,,,,,,,,,,,0,,,,-0.00245,,,,,,349.9988403,,,,
,32608598.18,349.9987793,77435.984375,-0.000173595759247123,4.64458663889247E-6,1,0.999253354069792,40.0298881530762,1.99886265805365,19.3000007420778,-0.00196574388551685,-0.000314261166020118,0.25,2.24236889958657E-6,-0.000173289324350891,2.14302232053277E-6,349.9987793,349.9987793,77426.1015625,77445.8671875,57.4113963660253,20.577907213322,27.085165,0,0,0,40,4449,350.5406,77435.984375,,,,,,,,,,,,,0,,,,0.00245,,,,,,349.9987793,,,,
,32608667.55,349.9907837,73969.3046875,-0.000159225234222032,3.84710414360822E-6,1,0.999253354069792,40.0298881530762,1.99872299828302,19.3000007420778,-0.00179546973418399,-0.000331122283102387,0.25,-1.74002107372827E-6,-0.000158942118016305,-1.82447940029122E-6,349.9907837,349.9907837,73961.84375,73976.765625,57.3332335141022,20.5771216157174,26.705515,0,0,0,40,4449,350.53555,73969.3046875,,,,,,,,,,,,,0,,,,0.00245,,,,,,349.9907837,,,,
,32608738.01,349.9882813,70445.78515625,-0.000152248472377711,4.34750455885689E-6,1,0.999253354069792,40.0298881530762,1.99897041646369,19.3000007420778,-0.00172213975358794,-0.000286969901209241,0.25,9.63148374472753E-7,-0.000151979214896149,8.7768160813496E-7,349.9882813,349.9882813,70433.5390625,70458.03125,57.474708276083,20.5792221468148,26.325863,0,0,0,40,4449,350.56515,70445.78515625,,,,,,,,,,,,,0,,,,-0.0049,,,,,,349.9882813,,,,
,32608807.585,349.9818115,66969.38671875,-0.00013441480981177,3.50049160926946E-6,1,0.999253354069792,40.0298881530762,1.99913517269644,19.3000007420778,-0.00150873632709368,-0.000321526858039755,0.25,-5.18076219474712E-6,-0.000134173797232815,-5.24558420069352E-6,349.9818115,349.9818115,66964.1953125,66974.578125,57.4465696493907,20.5832738156155,27.085165,0,0,0,40,4449,350.56515,66969.38671875,,,,,,,,,,,,,0,,,,-0.0049,,,,,,349.9818115,,,,
,32608876.54,349.9963074,63521.03125,-0.00012866505073419,3.09083892764618E-6,1,0.999253354069792,40.0298881530762,1.99903677549229,19.3000007420778,-0.00144595473794977,-0.000297217837392447,0.25,-4.02624067240943E-6,-0.000128434793136196,-4.0899904166623E-6,349.9963074,349.9963074,63516.08984375,63525.97265625,57.3981086811984,20.5812160747543,26.325863,0,0,0,40,4449,350.56405,63521.03125,,,,,,,,,,,,,0,,,,0,,,,,,349.9963074,,,,
,32608946.4,349.9828186,60029.859375,-0.000113113180321275,2.98802632550391E-6,1,0.999253354069792,40.0298881530762,1.99899221225111,19.3000007420778,-0.0012757426690344,-0.00023478710136428,0.25,-1.19420331594617E-6,-0.000112912094323539,-1.25444597215715E-6,349.9828186,349.9828186,60022.2734375,60037.4453125,57.5372385576215,20.5846666434374,26.705515,0,0,0,40,4449,350.57925,60029.859375,,,,,,,,,,,,,0,,,,0,,,,,,349.9828186,,,,
,32609015.505,349.9861603,56576.2265625,-0.00010450078581989,3.3400078762648E-6,1,0.999253354069792,40.0298881530762,1.99911846310979,19.3000007420778,-0.00117966419435024,-0.000211233411277283,0.25,-5.99677878820339E-7,-0.000104315273161206,-6.5626453793474E-7,349.9858704,349.9864502,56573.55078125,56578.90234375,57.4668919908907,20.5848167914006,26.705515,0,0,0,40,4449,350.5848,56576.2265625,,,,,,,,,,,,,0,,,,0.00245,,,,,,349.9861603,,,,
,32609087.305,349.988678,52988.044921875,-9.37502812451337E-5,4.09851678958632E-6,1,0.999253354069792,40.0298881530762,1.99881561754105,19.3000007420778,-0.00105434565392265,-0.000211466195311344,0.25,-2.48435787241479E-6,-9.35827679548183E-5,-2.53170839771816E-6,349.988678,349.988678,52980.8125,52995.27734375,57.5208243587176,20.5851059104131,26.325863,0,0,0,40,4449,350.59745,52988.044921875,,,,,,,,,,,,,0,,,,0,,,,,,349.988678,,,,
,32609156.155,349.9949951,49547.53515625,-7.89604486342955E-5,2.80926743353019E-6,1,0.999253354069792,40.0298881530762,1.99882363690638,19.3000007420778,-0.000886512548672105,-0.000186798999986047,0.25,-2.8617814650256E-6,-7.88189171369634E-5,-2.90032654353056E-6,349.9949951,349.9949951,49537.46875,49557.6015625,57.4293738219676,20.584921020673,26.705515,0,0,0,40,4449,350.6013,49547.53515625,,,,,,,,,,,,,0,,,,0,,,,,,349.9949951,,,,
,32609226.295,349.9928284,46041.234375,-6.99003143586399E-5,2.43312181337149E-6,1,0.999253354069792,40.0298881530762,1.99862373357014,19.3000007420778,-0.000794012765072466,-0.000111661354878307,0.25,2.21897973770212E-6,-6.97776517008763E-5,2.17640723380026E-6,349.9928284,349.9928284,46038.9140625,46043.5546875,57.5098815594484,20.585291892175,26.325863,0,0,0,40,4449,350.5902,46041.234375,,,,,,,,,,,,,0,,,,0,,,,,,349.9928284,,,,
,32609297.015,349.9826965,42505.41796875,-6.07879106286236E-5,2.8736448303395E-6,1,0.999253354069792,40.0298881530762,1.9987549440994,19.3000007420778,-0.000681647255522968,-0.000148507838194862,0.25,-2.61953877792529E-6,-6.06787421161985E-5,-2.64852089483017E-6,349.9826965,349.9826965,42495.1015625,42515.734375,57.2456911199484,20.5825450768314,27.085165,0,0,0,40,4449,350.59855,42505.41796875,,,,,,,,,,,,,0,,,,0,,,,,,349.9826965,,,,
,32609365.38,349.9838257,39086.947265625,-4.85650464512126E-5,3.17308387833221E-6,1,0.999253354069792,40.0298881530762,1.99871980398838,19.3000007420778,-0.000543781469595254,-0.000123236890759134,0.25,-2.49926744867554E-6,-4.84776001353409E-5,-2.52171795984007E-6,349.9838257,349.9838257,39081.70703125,39092.1875,57.2488176340253,20.5890377365885,27.085165,0,0,0,40,4449,350.60755,39086.947265625,,,,,,,,,,,,,0,,,,-0.0049,,,,,,349.9838257,,,,
,32609434.57,349.98651125,35628.900390625,-3.75736272818653E-5,2.79849133044106E-6,1,0.999253354069792,40.0298881530762,1.99875798121264,19.3000007420778,-0.000422340161220331,-8.59812663356544E-5,0.25,-1.10461061515632E-6,-3.75064262765296E-5,-1.12346136556641E-6,349.9860535,349.986969,35623.9296875,35633.87109375,57.5583425276407,20.5912220607697,26.705515,0,0,0,40,4449,350.6208,35628.900390625,,,,,,,,,,,,,0,,,,0.0049,,,,,,349.98651125,,,,
,32609503,349.9884338,32210.73046875,-2.803519120483E-5,2.2188992904091E-6,1,0.999253354069792,40.0298881530762,1.99866780692675,19.3000007420778,-0.000315062383370769,-6.44340780074591E-5,0.25,-8.49215163386849E-7,-2.79850331967613E-5,-8.63245184193826E-7,349.9884338,349.9884338,32205.576171875,32215.884765625,57.3465211989291,20.5925035617281,26.325863,0,0,0,40,4449,350.629,32210.73046875,,,,,,,,,,,,,0,,,,0,,,,,,349.9884338,,,,
,32609570.695,349.9898071,28827.6220703125,-1.58691200538331E-5,2.1214863521449E-6,1,0.999253354069792,40.0298881530762,1.99857783307195,19.3000007420778,-0.000180946107102453,-2.13684489051344E-5,0.25,8.56182063934411E-7,-1.58414684175011E-5,8.45865506910472E-7,349.9898071,349.9898071,28822.7265625,28832.517578125,57.1401712698522,20.5911380334884,27.464817,0,0,0,40,4449,350.61625,28827.6220703125,,,,,,,,,,,,,0,,,,0,,,,,,349.9898071,,,,
,32609639.58,349.9880676,25384.1240234375,-5.02726613100872E-6,1.36164981428482E-6,1,0.999253354069792,40.0298881530762,1.99836315778911,19.3000007420778,-5.5009297925749E-5,-2.00968160934445E-5,0.25,-9.08687927503406E-7,-5.0178519156425E-6,-9.09866300600878E-7,349.9880676,349.9880676,25379.1484375,25389.099609375,57.0674798175637,20.5896240741451,27.085165,0,0,0,40,4449,350.6488,25384.1240234375,,,,,,,,,,,,,0,,,,0,,,,,,349.9880676,,,,
,32609709.11,349.9888611,21908.076171875,5.1998823176636E-6,1.25769881686147E-6,1,0.999253354069792,40.0298881530762,1.99826545055357,19.3000007420778,5.78903615258557E-5,1.50398351231251E-5,0.25,4.31169759036131E-7,5.19042665941055E-6,4.33291912400174E-7,349.9888611,349.9888611,21905.556640625,21910.595703125,57.3926372815638,20.5893492789716,27.085165,0,0,0,40,4449,350.6441,21908.076171875,,,,,,,,,,,,,0,,,,0,,,,,,349.9888611,,,,
,32609777.97,349.9872437,18468.23046875,1.45556264306754E-5,1.11978545510173E-6,1,0.999253354069792,40.0298881530762,1.99837827576623,19.3000007420778,0.000164695878506661,2.68600660286898E-5,0.25,-1.42420390296507E-7,1.45299074567322E-5,-1.34084049831302E-7,349.9872437,349.9872437,18458.421875,18478.0390625,57.4168677656599,20.5899906485691,26.705515,0,0,0,40,4449,350.65055,18468.23046875,,,,,,,,,,,,,0,,,,0,,,,,,349.9872437,,,,
,32609847.375,349.9961548,14997.5947265625,2.51815426164858E-5,8.90243931786677E-7,1,0.999253354069792,40.0298881530762,1.99843937061894,19.3000007420778,0.000286833759775413,3.55072338968587E-5,0.25,-1.21687161952454E-6,2.51375794672533E-5,-1.20072211486639E-6,349.9960022,349.9963074,14995.1064453125,15000.0830078125,57.4528226775445,20.5940113999028,26.705515,0,0,0,40,4449,350.6645,14997.5947265625,,,,,,,,,,,,,0,,,,-0.00245,,,,,,349.9961548,,,,
,32609916.185,349.9878082,11559.2875976563,3.43533767277E-5,7.62475561515471E-7,1,0.999253354069792,40.0298881530762,1.99806707502033,19.3000007420778,0.000389134746490961,6.05743925210641E-5,0.25,-5.84937186114834E-7,3.42928126545967E-5,-5.64802179599431E-7,349.9873962,349.9882202,11551.65234375,11566.9228515625,57.3355783996599,20.5935403625085,27.085165,0,0,0,40,4449,350.67005,11559.2875976563,,,,,,,,,,,,,0,,,,-0.00245,,,,,,349.9878082,,,,
,32609984.19,349.98104855,8160.60180664062,4.24340272846537E-5,6.53335839259006E-7,1,0.999253354069792,40.0298881530762,1.99814086184097,19.3000007420778,0.000480245167553121,7.73634328665008E-5,0.25,-4.97828029967072E-7,4.23591012884022E-5,-4.73343937762039E-7,349.9801025,349.9819946,8153.22705078125,8167.9765625,57.4622022197753,20.5919602678575,27.085165,0,0,0,40,4449,350.66965,8160.60180664062,,,,,,,,,,,,,0,,,,-0.0049,,,,,,349.98104855,,,,
,32610050.415,349.9917297,4852.54443359375,4.67160002574466E-5,5.99148862506917E-7,1,0.999253354069792,40.0298881530762,1.99820112826283,19.3000007420778,0.000529222813139713,8.22756588269524E-5,0.25,-8.04551361464357E-7,4.66336386861772E-5,-7.77129990459012E-7,349.9917297,349.9917297,4845.0888671875,4860,57.4926857320253,20.5882109616765,27.085165,0,0,0,40,4449,350.6603,4852.54443359375,,,,,,,,,,,,,0,,,,0,,,,,,349.9917297,,,,
,32610117.335,349.9919739,1505.72924804687,4.17778868784968E-5,4.25194890575918E-7,1,0.999253354069792,40.0298881530762,1.99809479348674,19.3000007420778,0.000472723306642814,7.66588767409108E-5,0.25,-4.4646316555538E-7,4.17040785795455E-5,-4.22417045203872E-7,349.9919739,349.9919739,1500.92370605469,1510.53479003906,57.169873153583,20.5857997441271,27.464817,0,0,0,40,4449,350.6806,1505.72924804687,,,,,,,,,,,,,0,,,,0.00245,,,,,,349.9919739,,,,
,32610182.125,349.995697,-1729.48876953125,-4.26844332578958E-5,4.2951654133195E-7,1,0.999253354069792,40.0298881530762,1.9988667702122,19.3000007420778,-0.000481814291063592,-8.61174866818887E-5,0.25,-2.31228353754693E-7,-4.26086353614898E-5,-2.54578230646996E-7,349.995697,349.995697,-1734.34985351562,-1724.62768554687,57.3856026248907,20.58151656575,26.705515,0,0,0,40,4449,350.66565,-1729.48876953125,,,,,,,,,,,,,0,,,,0,,,,,,349.995697,,,,
,32610247.77,349.996582,-5010.0947265625,-4.70032816276385E-5,4.41780614370931E-7,1,0.999253354069792,40.0298881530762,1.99894932177281,19.3000007420778,-0.000530983236401444,-9.25381147335819E-5,0.25,-5.13792403801802E-8,-4.69199269296908E-5,-7.74419987588307E-8,349.996582,349.996582,-5017.43212890625,-5002.75732421875,57.5192611016792,20.5812083778075,27.085165,0,0,0,40,4449,350.67015,-5010.0947265625,,,,,,,,,,,,,0,,,,0,,,,,,349.996582,,,,
,32610314.79,350.0040894,-8361.3603515625,-4.16892068569138E-5,6.93298706603558E-7,1,0.999253354069792,40.0298881530762,1.99890115956912,19.3000007420778,-0.000470066859252791,-8.71204750071499E-5,0.25,-4.9221951654799E-7,-4.16150178228662E-5,-5.14533699741508E-7,350.0040894,350.0040894,-8371.2587890625,-8351.4619140625,57.4145228801022,20.5813033667169,26.705515,0,0,0,40,4449,350.6699,-8361.3603515625,,,,,,,,,,,,,0,,,,-0.00245,,,,,,350.0040894,,,,
,32610383.89,350.0079956,-11812.7387695313,-3.30297570373775E-5,7.56105463749398E-7,1,0.999253354069792,40.0298881530762,1.99892060976758,19.3000007420778,-0.00037283470801863,-6.66911137508406E-5,0.25,-1.83431188640796E-7,-3.29710893628543E-5,-2.0146791567971E-7,350.0079956,350.0079956,-11825.2099609375,-11800.267578125,57.677931691083,20.5843333334855,27.085165,0,0,0,40,4449,350.6649,-11812.7387695313,,,,,,,,,,,,,0,,,,-0.00245,,,,,,350.0079956,,,,
,32610453.88,349.9958191,-15313.6611328125,-2.32549128055974E-5,9.41435053266128E-7,1,0.999253354069792,40.0298881530762,1.99893037260204,19.3000007420778,-0.000261452205315946,-5.30011469045106E-5,0.25,-6.64290700377151E-7,-2.32133199868162E-5,-6.76034774627805E-7,349.9958191,349.9958191,-15323.9541015625,-15303.3681640625,57.7342089444676,20.5845147592416,27.464817,0,0,0,40,4449,350.6515,-15313.6611328125,,,,,,,,,,,,,0,,,,0,,,,,,349.9958191,,,,
,32610523.455,350.0091858,-18791.919921875,-1.43000751932303E-5,1.17747697404261E-6,1,0.999253354069792,40.0298881530762,1.99889146390669,19.3000007420778,-0.000161890698908958,-2.61244665885308E-5,0.25,1.63857724978082E-7,-1.42748104999985E-5,1.55625713990448E-7,350.0091858,350.0091858,-18796.94140625,-18786.8984375,57.6482298073523,20.584373338857,27.085165,0,0,0,40,4449,350.65515,-18791.919921875,,,,,,,,,,,,,0,,,,-0.00245,,,,,,350.0091858,,,,
,32610591.49,350.0098572,-22189.21875,-3.4075689607489E-6,1.13224571501476E-6,1,0.999253354069792,40.0298881530762,1.99886528942022,19.3000007420778,-4.05120473325398E-5,4.95336311893829E-6,0.25,1.02843087841657E-6,-3.40209777249758E-6,1.024715991834E-6,350.0098572,350.0098572,-22193.99609375,-22184.44140625,57.7506231433715,20.585573110501,27.464817,0,0,0,40,4449,350.6504,-22189.21875,,,,,,,,,,,,,0,,,,0.00245,,,,,,350.0098572,,,,
,32610661.375,350.0119629,-25682.6435546875,7.29775866629648E-6,1.24043749036988E-6,1,0.999253354069792,40.0298881530762,1.99877734896258,19.3000007420778,8.17040184279898E-5,1.85821740964515E-5,0.25,3.81140390458635E-7,7.28460712104852E-6,3.84512834363311E-7,350.0119629,350.0119629,-25687.759765625,-25677.52734375,57.5427099572561,20.58323469549,27.085165,0,0,0,40,4449,350.6472,-25682.6435546875,,,,,,,,,,,,,0,,,,-0.0049,,,,,,350.0119629,,,,
,32610729.72,350.0111084,-29098.5849609375,1.8752083029148E-5,1.68498889734548E-6,1,0.999253354069792,40.0298881530762,1.99876737433234,19.3000007420778,0.000211178717806164,4.0611181689427E-5,0.25,3.47683123279304E-7,1.87186407324638E-5,3.57463266285353E-7,350.0111084,350.0111084,-29106.080078125,-29091.08984375,57.6435400362369,20.5853405844206,27.085165,0,0,0,40,4449,350.63275,-29098.5849609375,,,,,,,,,,,,,0,,,,0,,,,,,350.0111084,,,,
,32610801.885,350.0088196,-32704.3642578125,2.90520502661315E-5,1.78399717770113E-6,1,0.999253354069792,40.0298881530762,1.9987470708094,19.3000007420778,0.00032385818839473,8.20431712167994E-5,0.25,2.23157077666939E-6,2.89993043033507E-5,2.24371115999713E-6,350.0088196,350.0088196,-32714.607421875,-32694.12109375,57.7865780552561,20.5867163348235,27.844467,0,0,0,40,4449,350.633,-32704.3642578125,,,,,,,,,,,,,0,,,,-0.00245,,,,,,350.0088196,,,,
,32610875.065,350.005249,-36363.900390625,4.06617506311037E-5,2.32450831244881E-6,1,0.999253354069792,40.0298881530762,1.99869511548873,19.3000007420778,0.000453751747906851,0.000112022799152324,0.25,2.87521609486299E-6,4.05880710978724E-5,2.89263298215928E-6,350.005249,350.005249,-36366.02734375,-36361.7734375,57.8311308808523,20.5883489999325,27.844467,0,0,0,40,4449,350.64215,-36363.900390625,,,,,,,,,,,,,0,,,,0,,,,,,350.005249,,,,
,32610945.535,349.99978635,-39884.765625,5.15391128626548E-5,2.0991108983074E-6,1,0.999253354069792,40.0298881530762,1.99850396137794,19.3000007420778,0.000577074164622962,0.000130470299772544,0.25,2.62577488487661E-6,5.14462990799113E-5,2.64964019060393E-6,349.9992065,350.0003662,-39890.09765625,-39879.43359375,57.6974724040638,20.5930125581739,27.085165,0,0,0,40,4449,350.62625,-39884.765625,,,,,,,,,,,,,0,,,,0,,,,,,349.99978635,,,,
,32611016.96,350.0124207,-43455.3984375,6.4426728120582E-5,2.00996051485137E-6,1,0.999253354069792,40.0298881530762,1.99785806004501,19.3000007420778,0.000726255113827178,0.000133570273222558,0.25,6.72409798451438E-7,6.43121245205506E-5,7.06846122590306E-7,350.0124207,350.0124207,-43467.71875,-43443.078125,57.5841362687753,20.5972791473323,27.085165,0,0,0,40,4449,350.61805,-43455.3984375,,,,,,,,,,,,,0,,,,0,,,,,,350.0124207,,,,
,32611087.625,350.01205445,-46985.939453125,7.36119833422809E-5,1.97412251132948E-6,1,0.999253354069792,40.0298881530762,1.99778127581398,19.3000007420778,0.000828373079599173,0.000160653499979907,0.25,1.48079144759487E-6,7.34806503173264E-5,1.51884660469098E-6,350.0108643,350.0132446,-46990.69921875,-46981.1796875,57.5645955557946,20.5979405804963,27.085165,0,0,0,40,4449,350.6206,-46985.939453125,,,,,,,,,,,,,0,,,,-0.00245,,,,,,350.01205445,,,,
,32611157.93,350.010376,-50499.3359375,8.74845510966721E-5,2.02511115019515E-6,1,0.999253354069792,40.0298881530762,1.99793153902358,19.3000007420778,0.000983254802404886,0.000198453184196494,0.25,2.42487281258482E-6,8.73281082612047E-5,2.46889015524898E-6,350.010376,350.010376,-50509.140625,-50489.53125,57.5935158110061,20.5999220273347,27.085165,0,0,0,40,4449,350.6062,-50499.3359375,,,,,,,,,,,,,0,,,,0,,,,,,350.010376,,,,
,32611227.575,350.0108337,-53981.9453125,9.65266903853666E-5,1.81642131154234E-6,1,0.999253354069792,40.0298881530762,1.99798275962672,19.3000007420778,0.00108405124877568,0.000223916014828072,0.25,3.1134764703365E-6,9.63538385678232E-5,3.16123091425067E-6,350.0108337,350.0108337,-53987.078125,-53976.8125,57.6669888918138,20.5972809750222,27.464817,0,0,0,40,4449,350.6053,-53981.9453125,,,,,,,,,,,,,0,,,,-0.00245,,,,,,350.0108337,,,,
,32611297.305,350.0174866,-57465.20703125,0.00010753591497518,2.43548791267306E-6,1,0.999253354069792,40.0298881530762,1.99805013720945,19.3000007420778,0.0012091363977824,0.000241339413332462,0.25,2.74938651821487E-6,0.000107343725501038,2.80382281930411E-6,350.0174866,350.0174866,-57470.23828125,-57460.17578125,57.6044586102753,20.5989723938866,27.085165,0,0,0,40,4449,350.5966,-57465.20703125,,,,,,,,,,,,,0,,,,-0.00245,,,,,,350.0174866,,,,
,32611366.445,350.015686,-60920.193359375,0.000120965226969153,1.99630843690898E-6,1,0.999253354069792,40.0298881530762,1.99794256788701,19.3000007420778,0.00135721877078007,0.000287909494863384,0.25,4.54893684580825E-6,0.00012074824557614,4.60754593852698E-6,350.015686,350.015686,-60922.6015625,-60917.78515625,57.8069003967561,20.6011909604307,27.085165,0,0,0,40,4449,350.5851,-60920.193359375,,,,,,,,,,,,,0,,,,-0.0049,,,,,,350.015686,,,,
,32611437.21,350.0137024,-64456.267578125,0.000130517449123613,2.65207971323848E-6,1,0.999253354069792,40.0298881530762,1.99801397099174,19.3000007420778,0.00146579688667879,0.000302841404289308,0.25,4.21632136436463E-6,0.000130283728865833,4.2807355824694E-6,350.0137024,350.0137024,-64466.1796875,-64446.35546875,57.7686005993138,20.6022564244876,27.085165,0,0,0,40,4449,350.5797,-64456.267578125,,,,,,,,,,,,,0,,,,0.0049,,,,,,350.0137024,,,,
,32611507.86,350.0096436,-67986.80078125,0.000141734114593194,2.38115759866316E-6,1,0.999253354069792,40.0298881530762,1.99802883330049,19.3000007420778,0.00159992352461338,0.000281831196654882,0.25,4.13762887816666E-7,0.000141482626464288,4.91038166337234E-7,350.0096436,350.0096436,-67994.1953125,-67979.40625,57.4708001334869,20.6035844162478,27.464817,0,0,0,40,4449,350.5929,-67986.80078125,,,,,,,,,,,,,0,,,,-0.00245,,,,,,350.0096436,,,,
,32611578.7,350.0110779,-71529.484375,0.000151564558996969,2.62339969111365E-6,1,0.999253354069792,40.0298881530762,1.9979734665868,19.3000007420778,0.00171103591996994,0.000300275408295632,0.25,3.45542908635903E-7,0.000151295678196536,4.28296152211772E-7,350.0110779,350.0110779,-71537.0390625,-71521.9296875,57.5903892969292,20.6041795000546,27.085165,0,0,0,40,4449,350.56215,-71529.484375,,,,,,,,,,,,,0,,,,0,,,,,,350.0110779,,,,
,32611648.475,350.0098267,-75014.84375,0.000166310254592589,2.61758008253722E-6,1,0.999253354069792,40.0298881530762,1.99800981778365,19.3000007420778,0.00187110561178021,0.000366628775412159,0.25,3.6672106865918E-6,0.000166013419300685,3.75212009577783E-6,350.0098267,350.0098267,-75019.921875,-75009.765625,57.5708485839484,20.603639683056,27.844467,0,0,0,40,4449,350.56275,-75014.84375,,,,,,,,,,,,,0,,,,0,,,,,,350.0098267,,,,
,32611719.56,350.0145264,-78567.671875,0.000179622175349746,2.40472137731036E-6,1,0.999253354069792,40.0298881530762,1.99800434568361,19.3000007420778,0.00203220399801249,0.000330504337755819,0.25,-1.83611935333488E-6,0.000179304742803119,-1.73420797507454E-6,350.0145264,350.0145264,-78572.6328125,-78562.7109375,57.7435884866984,20.6054370894143,27.844467,0,0,0,40,4449,350.5537,-78567.671875,,,,,,,,,,,,,0,,,,0,,,,,,350.0145264,,,,
,32611790.585,350.0181274,-82118.72265625,0.000188931898647933,2.69445251282414E-6,1,0.999253354069792,40.0298881530762,1.99800986506202,19.3000007420778,0.00213918086464837,0.000338143692095881,0.25,-2.77161673521243E-6,0.000188598456781636,-2.6630077006386E-6,350.0181274,350.0181274,-82120.984375,-82116.4609375,57.6052402387946,20.6043038559961,27.844467,0,0,0,40,4449,350.54245,-82118.72265625,,,,,,,,,,,,,0,,,,0.00245,,,,,,350.0181274,,,,
,32611860.845,350.0188599,-85628.9765625,0.000206014578154491,3.38307163105703E-6,1,0.999253354069792,40.0298881530762,1.99782718855761,19.3000007420778,0.00231981913965169,0.000441323767430532,0.25,3.41011221386275E-6,0.000205647459400578,3.51705565179903E-6,350.0188599,350.0188599,-85638.8515625,-85619.1015625,57.759221057083,20.6071464719858,27.085165,0,0,0,40,4449,350.53415,-85628.9765625,,,,,,,,,,,,,0,,,,0,,,,,,350.0188599,,,,
,32611926.255,350.0160828,-88896.48046875,0.000210445544996031,2.63175299345022E-6,1,0.999253354069792,40.0298881530762,1.9978994684231,19.3000007420778,0.00238192070081597,0.000380803941963921,0.25,-2.7173050884626E-6,0.000210073955654291,-2.59714718749926E-6,350.0160828,350.0160828,-88901.5546875,-88891.40625,57.6849663477561,20.6097546516357,27.085165,0,0,0,40,4449,350.52855,-88896.48046875,,,,,,,,,,,,,0,,,,-0.00245,,,,,,350.0160828,,,,
,32612008.955,350.0163879,-87891.08203125,0.000212207176844314,2.29415465358422E-6,1,0.999253354069792,40.0298881530762,1.99811736215826,19.3000007420778,0.00239726122252721,0.000412033939333636,0.25,-2.60769289625745E-7,0.000211831113622557,-1.43969539961658E-7,350.0163879,350.0163879,-87898.4921875,-87883.671875,57.5692853269099,20.6071018431292,27.085165,0,0,0,40,4449,350.5092,-87891.08203125,,,,,,,,,,,,,0,,,,0.00245,,,,,,350.0163879,,,,
,32612076.305,350.006134,-84525.5859375,0.000198782222575997,2.60975743840364E-6,1,0.999253354069792,40.0298881530762,1.99796211532448,19.3000007420778,0.00224736352551769,0.000374808810625923,0.25,-1.22986378501736E-6,0.000198430554178329,-1.11862797097729E-6,350.006134,350.006134,-84530.390625,-84520.78125,57.4997203886984,20.6093456510384,27.844467,0,0,0,40,4449,350.50925,-84525.5859375,,,,,,,,,,,,,0,,,,-0.0049,,,,,,350.006134,,,,
,32612144.235,349.9992676,-81130.421875,0.000190589215312501,3.09799860482938E-6,1,0.999253354069792,40.0298881530762,1.99767295168298,19.3000007420778,0.00215275415753904,0.00036904218327679,0.25,-3.1748238630844E-7,0.000190251607328039,-2.12284882621607E-7,349.9992676,349.9992676,-81133.125,-81127.71875,57.5927341824868,20.6114490690353,27.464817,0,0,0,40,4449,350.5143,-81130.421875,,,,,,,,,,,,,0,,,,0.00245,,,,,,349.9992676,,,,
,32612216.765,349.9981995,-77504.2890625,0.000177037940685377,2.68371509622971E-6,1,0.999253354069792,40.0298881530762,1.99764537405442,19.3000007420778,0.00200332735707095,0.000321632583301815,0.25,-2.16938206768839E-6,0.000176725368236567,-2.06826928833515E-6,349.9981995,349.9981995,-77514.1875,-77494.390625,57.6787133196022,20.6112205319477,27.844467,0,0,0,40,4449,350.5188,-77504.2890625,,,,,,,,,,,,,0,,,,0.0049,,,,,,349.9981995,,,,
,32612287.595,349.9901428,-73966.30078125,0.000166340697823419,2.77380616420571E-6,1,0.999253354069792,40.0298881530762,1.9975807501,19.3000007420778,0.00187524314272022,0.000342494479544273,0.25,1.53115864432393E-6,0.000166045090706907,1.61990139402898E-6,349.9901428,349.9901428,-73971.25,-73961.3515625,57.434063593083,20.6125569534447,27.464817,0,0,0,40,4449,350.5271,-73966.30078125,,,,,,,,,,,,,0,,,,0,,,,,,349.9901428,,,,
,32612356.195,349.9885559,-70538.6953125,0.000157300335716025,2.15948609650957E-6,1,0.999253354069792,40.0298881530762,1.99760378486488,19.3000007420778,0.00177212120336966,0.000330958453933336,0.25,2.07440465201794E-6,0.000157020453127131,2.15727405380514E-6,349.9880676,349.9890442,-70548.578125,-70528.8125,57.5747567265446,20.6076600232452,27.844467,0,0,0,40,4449,350.5334,-70538.6953125,,,,,,,,,,,,,0,,,,0,,,,,,349.9885559,,,,
,32612427.58,349.9914856,-66970.9140625,0.000140937432082663,2.81028094219215E-6,1,0.999253354069792,40.0298881530762,1.99750104161319,19.3000007420778,0.00158547034418273,0.000309400322313997,0.25,2.99963031542512E-6,0.000140686016896494,3.0719111884209E-6,349.9914856,349.9914856,-66970.9140625,-66970.9140625,57.5466180998522,20.6023479320061,27.464817,0,0,0,40,4449,350.54515,-66970.9140625,,,,,,,,,,,,,0,,,,0,,,,,,349.9914856,,,,
,32612498.765,349.9921875,-63413.33203125,0.000128352305531487,2.30949163215773E-6,1,0.999253354069792,40.0298881530762,1.99744681284446,19.3000007420778,0.00143858660632646,0.00031220362332507,0.25,5.42762173152844E-6,0.000128121847309699,5.48872216827175E-6,349.9921875,349.9921875,-63423.28125,-63403.3828125,57.4371901071599,20.5999590894112,27.844467,0,0,0,40,4449,350.5414,-63413.33203125,,,,,,,,,,,,,0,,,,0,,,,,,349.9921875,,,,
,32612570.065,349.9854431,-59849.7578125,0.000110919699864484,2.36041653124005E-6,1,0.999253354069792,40.0298881530762,1.99735721047218,19.3000007420778,0.00124136396608622,0.000280087396944884,0.25,5.6025417559945E-6,0.000110720059309925,5.65377225558826E-6,349.9854431,349.9854431,-59854.8984375,-59844.6171875,57.5059734168522,20.6048999665683,28.224119,0,0,0,40,4449,350.54005,-59849.7578125,,,,,,,,,,,,,0,,,,0,,,,,,349.9854431,,,,
,32612640.195,349.990448,-56344.095703125,0.000100781812645183,2.22565215224615E-6,1,0.999253354069792,40.0298881530762,1.9972448871512,19.3000007420778,0.00112990106507721,0.000242596277214643,0.25,4.03834383613067E-6,0.000100600977850227,4.0867917840949E-6,349.990448,349.990448,-56356.68359375,-56331.5078125,57.606803495833,20.6044436180653,27.844467,0,0,0,40,4449,350.55565,-56344.095703125,,,,,,,,,,,,,0,,,,-0.00245,,,,,,349.990448,,,,
,32612710.495,349.9814758,-52831.1015625,8.98229464159222E-5,2.36556593173019E-6,1,0.999253354069792,40.0298881530762,1.99719930563292,19.3000007420778,0.00100462010840789,0.000230047205809578,0.25,4.82468207647474E-6,8.96611222826707E-5,4.86572345267434E-6,349.9814758,349.9814758,-52833.62109375,-52828.58203125,57.5583425276407,20.6061062319979,27.844467,0,0,0,40,4449,350.571,-52831.1015625,,,,,,,,,,,,,0,,,,0,,,,,,349.9814758,,,,
,32612782.035,349.9868774,-49258.650390625,7.81456046942625E-5,1.66769916806686E-6,1,0.999253354069792,40.0298881530762,1.99717538029481,19.3000007420778,0.000875070166745031,0.000193987662633306,0.25,3.65264780432584E-6,7.80051012827621E-5,3.68934774034901E-6,349.9868774,349.9868774,-49266.09375,-49251.20703125,57.5810097546984,20.6055148293509,27.464817,0,0,0,40,4449,350.57365,-49258.650390625,,,,,,,,,,,,,0,,,,0,,,,,,349.9868774,,,,
,32612853.635,349.9889221,-45675.783203125,6.61145939555907E-5,1.99821020498146E-6,1,0.999253354069792,40.0298881530762,1.99753727874008,19.3000007420778,0.000740568100643297,0.000163615724844076,0.25,3.04292238117438E-6,6.59957406077086E-5,3.0740800391816E-6,349.9889221,349.9889221,-45677.84375,-45673.72265625,57.6021137247176,20.6036649490267,28.224119,0,0,0,40,4449,350.5809,-45675.783203125,,,,,,,,,,,,,0,,,,0,,,,,,349.9889221,,,,
,32612924.9,349.9930725,-42114.73828125,5.5106681934558E-5,2.0564083153673E-6,1,0.999253354069792,40.0298881530762,1.99732473436581,19.3000007420778,0.000614773303750148,0.0001503904345866,0.25,3.77896008633862E-6,5.50069197521488E-5,3.80274728531451E-6,349.9930725,349.9930725,-42124.6796875,-42104.796875,57.5325487865061,20.6036464021749,27.464817,0,0,0,40,4449,350.5836,-42114.73828125,,,,,,,,,,,,,0,,,,-0.00245,,,,,,349.9930725,,,,
,32612994.74,349.9894104,-38624.11328125,4.57064842374898E-5,1.22720344883654E-6,1,0.999253354069792,40.0298881530762,1.99731632035555,19.3000007420778,0.000509227007671759,0.000128635276834866,0.25,3.47968855309342E-6,4.56235518863803E-5,3.49882208047495E-6,349.9894104,349.9894104,-38631.42578125,-38616.80078125,57.4692368764484,20.6014008348383,27.844467,0,0,0,40,4449,350.59185,-38624.11328125,,,,,,,,,,,,,0,,,,-0.00245,,,,,,349.9894104,,,,
,32613063.945,349.9872131,-35168.25390625,3.27164438534547E-5,1.49124117512253E-6,1,0.999253354069792,40.0298881530762,1.99713764407452,19.3000007420778,0.000361014905874687,0.000112027196781416,0.25,4.25868728359731E-6,3.26561028392933E-5,4.26926096721307E-6,349.9872131,349.9872131,-35178.30859375,-35158.19921875,57.4457880208715,20.6023339415548,27.844467,0,0,0,40,4449,350.5963,-35168.25390625,,,,,,,,,,,,,0,,,,0.00245,,,,,,349.9872131,,,,
,32613134.495,349.9916382,-31641.2021484375,2.37249127579043E-5,1.20231628522487E-6,1,0.999253354069792,40.0298881530762,1.99720400244226,19.3000007420778,0.000264207648022483,6.73627876674811E-5,0.25,1.85894069617634E-6,2.36818315122183E-5,1.86879484764737E-6,349.9916382,349.9916382,-31646.259765625,-31636.14453125,57.393418910083,20.5984854443684,27.464817,0,0,0,40,4449,350.6009,-31641.2021484375,,,,,,,,,,,,,0,,,,0,,,,,,349.9916382,,,,
,32613204.99,349.9880981,-28117.9013671875,1.32259844217866E-5,1.54862525193909E-6,1,0.999253354069792,40.0298881530762,1.99733350541744,19.3000007420778,0.000146704931301927,4.09781091578473E-5,0.25,1.3394779293999E-6,1.32018005590371E-5,1.34443871860932E-6,349.9880981,349.9880981,-28128.033203125,-28107.76953125,57.5239508727946,20.5943822306892,27.844467,0,0,0,40,4449,350.59665,-28117.9013671875,,,,,,,,,,,,,0,,,,-0.00245,,,,,,349.9880981,,,,
,32613274.765,349.9867249,-24629.7890625,4.13558391670989E-6,1.04414743676066E-6,1,0.999253354069792,40.0298881530762,1.99724252933353,19.3000007420778,4.30418272854842E-5,2.91500782536237E-5,0.25,1.86594101583823E-6,4.12721897321052E-6,1.86492868453998E-6,349.9867249,349.9867249,-24639.724609375,-24619.853515625,57.6193095521407,20.5961575225293,28.224119,0,0,0,40,4449,350.6184,-24629.7890625,,,,,,,,,,,,,0,,,,0.00245,,,,,,349.9867249,,,,
,32613345.375,349.9880981,-21101.8662109375,-7.93456096393529E-6,9.40056417439135E-7,1,0.999253354069792,40.0298881530762,1.99727892398174,19.3000007420778,-9.1090545143191E-5,-6.78735753836414E-6,0.25,7.72675056475732E-7,-7.92092678891484E-6,7.66900431604018E-7,349.9880981,349.9880981,-21106.87890625,-21096.853515625,57.7639108281984,20.5975552694532,28.224119,0,0,0,40,4449,350.6258,-21101.8662109375,,,,,,,,,,,,,0,,,,-0.0049,,,,,,349.9880981,,,,
,32613416.15,349.99020385,-17563.6416015625,-1.80430575406211E-5,8.36076124234727E-7,1,0.999253354069792,40.0298881530762,1.9974223535151,19.3000007420778,-0.000205531845218385,-2.47954840369706E-5,0.25,9.28041588468029E-7,-1.80115919947698E-5,9.16374134677067E-7,349.9900513,349.9903564,-17568.802734375,-17558.48046875,57.5481813568907,20.6007068426077,27.464817,0,0,0,40,4449,350.63945,-17563.6416015625,,,,,,,,,,,,,0,,,,0.00245,,,,,,349.99020385,,,,
,32613485.86,349.9840393,-14078.4291992187,-2.8398931213039E-5,5.58593647247159E-7,1,0.999253354069792,40.0298881530762,1.99742661215087,19.3000007420778,-0.00032251781527167,-4.46894405997503E-5,0.25,9.5918918807146E-7,-2.83491328913533E-5,9.41705756999366E-7,349.9840393,349.9840393,-14085.9013671875,-14070.95703125,57.7217028881599,20.5959485120737,28.224119,0,0,0,40,4449,350.639,-14078.4291992187,,,,,,,,,,,,,0,,,,0,,,,,,349.9840393,,,,
,32613555.25,349.9867554,-10612.3735351562,-3.71525647862912E-5,6.87653033975424E-7,1,0.999253354069792,40.0298881530762,1.99733173899049,19.3000007420778,-0.000421447624770438,-6.11375395482755E-5,0.25,1.01785818283828E-6,-3.70872811026784E-5,9.95395207205167E-7,349.9867554,349.9867554,-10622.306640625,-10602.4404296875,57.5677220698715,20.5974845299359,27.844467,0,0,0,40,4449,350.6408,-10612.3735351562,,,,,,,,,,,,,0,,,,-0.00245,,,,,,349.9867554,,,,
,32613624.655,349.994751,-7140.72290039063,-4.47449809675567E-5,4.11633139074681E-7,1,0.999253354069792,40.0298881530762,1.99730272962535,19.3000007420778,-0.000504876047021675,-8.91689466843636E-5,0.25,-1.50432377497287E-7,-4.46655777336582E-5,-1.7505839297617E-7,349.994751,349.994751,-7148.1142578125,-7133.33154296875,57.6263442088138,20.5982155816394,28.224119,0,0,0,40,4449,350.6391,-7140.72290039063,,,,,,,,,,,,,0,,,,0.0049,,,,,,349.994751,,,,
,32613691.135,349.988739,-3819.67395019531,-4.7706782188946E-5,5.29502400313207E-7,1,0.999253354069792,40.0298881530762,1.99731482702201,19.3000007420778,-0.000539964123795371,-8.54522652930057E-5,0.25,6.91664516583221E-7,-4.76226059852652E-5,6.63886068431895E-7,349.988739,349.988739,-3824.78002929687,-3814.56787109375,57.3308886285445,20.5974184403041,27.844467,0,0,0,40,4449,350.6247,-3819.67395019531,,,,,,,,,,,,,0,,,,0.0049,,,,,,349.988739,,,,
,32613756.225,349.9896545,-564.932037353516,-3.38639224463063E-5,4.86379536565244E-7,1,0.999253354069792,40.0298881530762,1.9974466982121,19.3000007420778,-0.000382314802300559,-6.64044867737753E-5,0.25,-1.77358216327635E-8,-3.38038867538318E-5,-3.65566448533774E-8,349.9896545,349.9896545,-569.778259277344,-560.085815429687,57.5161345876022,20.5974233129836,27.844467,0,0,0,40,4449,350.65975,-564.932037353516,,,,,,,,,,,,,0,,,,0,,,,,,349.9896545,,,,
,32613819.575,349.9916992,2597.85192871094,4.58414975137269E-5,4.91267847807849E-7,1,0.999253354069792,40.0298881530762,1.99732706084262,19.3000007420778,0.000518796441771442,8.24502889963772E-5,0.25,-6.34627578830206E-7,4.57605911592149E-5,-6.0798709555315E-7,349.9916992,349.9916992,2592.80932617187,2602.89453125,57.5317671579869,20.5938416280035,27.464817,0,0,0,40,4449,350.65605,2597.85192871094,,,,,,,,,,,,,0,,,,-0.00245,,,,,,349.9916992,,,,
,32613886.115,349.9971619,5922.8857421875,4.68016927220852E-5,6.11966332319169E-7,1,0.999253354069792,40.0298881530762,1.99730591105672,19.3000007420778,0.000529831566744606,8.31722869151015E-5,0.25,-7.36851115348585E-7,4.67191331685813E-5,-7.09504790608522E-7,349.9971619,349.9971619,5917.67578125,5928.095703125,57.738898715583,20.5965628993902,28.224119,0,0,0,40,4449,350.6519,5922.8857421875,,,,,,,,,,,,,0,,,,0.00245,,,,,,349.9971619,,,,
,32613952.875,350.0010681,9262.41064453125,4.02147947228398E-5,7.41464806723221E-7,1,0.999253354069792,40.0298881530762,1.99738410020726,19.3000007420778,0.000456401760956291,6.49890469191659E-5,0.25,-1.2070906736396E-6,4.01441691303386E-5,-1.18258523460157E-6,350.0010681,350.0010681,9247.5810546875,9277.240234375,57.6122748954676,20.5990315339352,28.224119,0,0,0,40,4449,350.6492,9262.41064453125,,,,,,,,,,,,,0,,,,0,,,,,,350.0010681,,,,
,32614019.755,350.0008545,12603.0122070312,3.28883479517502E-5,6.92879422824429E-7,1,0.999253354069792,40.0298881530762,1.99728757158855,19.3000007420778,0.000375654590444456,3.91783675720552E-5,0.25,-2.22441322955939E-6,3.28312775185234E-5,-2.20218681137525E-6,350.0008545,350.0008545,12595.60546875,12610.4189453125,57.434063593083,20.5982639316259,28.224119,0,0,0,40,4449,350.63455,12603.0122070312,,,,,,,,,,,,,0,,,,-0.00245,,,,,,350.0008545,,,,
,32614089.195,350.0133057,16074.4194335938,2.34018045931659E-5,7.6453661836607E-7,1,0.999253354069792,40.0298881530762,1.99712152084494,19.3000007420778,0.000268166619808393,2.2736550251805E-5,0.25,-2.03797706875197E-6,2.33614390731619E-5,-2.02136136783308E-6,350.0133057,350.0133057,16069.77734375,16079.0615234375,57.596642325083,20.5989455209681,28.224119,0,0,0,40,4449,350.64975,16074.4194335938,,,,,,,,,,,,,0,,,,-0.0049,,,,,,350.0133057,,,,
,32614156.43,350.0054626,19434.4716796875,1.34058913304136E-5,8.48842140469331E-7,1,0.999253354069792,40.0298881530762,1.99715095050898,19.3000007420778,0.000155349599040587,3.05539884821855E-6,0.25,-2.05057666317185E-6,1.33832615446567E-5,-2.03949675226566E-6,350.0054626,350.0054626,19426.84765625,19442.095703125,57.3981086811984,20.5969146843641,28.224119,0,0,0,40,4449,350.64855,19434.4716796875,,,,,,,,,,,,,0,,,,-0.00245,,,,,,350.0054626,,,,
,32614224.14,350.0135803,22820.3984375,3.11613679094512E-6,8.71830435541431E-7,1,0.999253354069792,40.0298881530762,1.99708534087705,19.3000007420778,4.07442577407168E-5,-2.60592517977486E-5,0.25,-2.84797202625503E-6,3.11219183393405E-6,-2.84119234652589E-6,350.0135803,350.0135803,22815.70703125,22825.08984375,57.5106631879676,20.5991584518959,28.224119,0,0,0,40,4449,350.6255,22820.3984375,,,,,,,,,,,,,0,,,,-0.0049,,,,,,350.0135803,,,,
,32614255.735,350.0080261,24396.8134765625,-1.10489073655605E-6,8.18978066957135E-7,1,0.999253354069792,40.0298881530762,1.99711286516408,19.3000007420778,-5.27703976034039E-6,-4.37193841938626E-5,0.25,-3.68144515076622E-6,-1.10088901075835E-6,-3.67553086545532E-6,350.0080261,350.0080261,24394.318359375,24399.30859375,57.2824276603522,20.5948043631828,27.844467,0,0,0,40,4449,350.6354,24396.8134765625,,,,,,,,,,,,,0,,,,-0.0049,,,,,,350.0080261,,,,