File: data/doubleLayers/dl_1-25/ppms/data/DD205_3_HYST_100OE_5K.DAT
[Header]
; VSM Data File (default extension .dat)
; Copyright (c) 2003-2013, Quantum Design, Inc. All rights reserved.
TITLE,
FILEOPENTIME,32508341.22,01/12/2019,2:08 pm
BYAPP,VSM,2.0,2.0
INFO,PPMS VSM Option Release 1.4.10 Build 1,APPNAME
INFO,Quantum Design Linear Motor Servo Controller,MOTOR_MODULE_NAME
INFO,3101-100 M1,MOTOR_HW_VERSION
INFO,MMC1014,MOTOR_SERIAL_NUMBER
INFO,SRV No X-over 01.03.11,MOTOR_SOFTWARE_VERSION
INFO,Quantum Design VSM Detection Module,VSM_MODULE_NAME
INFO,3101-150 F0,VSM_HW_VERSION
INFO,VSM707,VSM_SERIAL_NUMBER
INFO,VSM No X-over 01.02.05 May 20 2008 13:51:47,VSM_SOFTWARE_VERSION
INFO,704,PREAMP_SERIAL_NUMBER
INFO,822,COIL_SERIAL_NUMBER
INFO,0,MOMENT_UNITS
INFO,DD205_4,SAMPLE_MATERIAL
INFO,Double Layer Blue 1.25,SAMPLE_COMMENT
INFO,26.73,SAMPLE_MASS
INFO,,SAMPLE_VOLUME
INFO,,SAMPLE_MOLECULAR_WEIGHT
INFO,,SAMPLE_SIZE
INFO,,SAMPLE_SHAPE
DATATYPE,COMMENT,1
DATATYPE,TIME,2
STARTUPAXIS,X,2
STARTUPAXIS,Y1,5
[Data]
Comment,Time Stamp (sec),Temperature (K),Magnetic Field (Oe),Moment (emu),M. Std. Err. (emu),Transport Action,Averaging Time (sec),Frequency (Hz),Peak Amplitude (mm),Center Position (mm),Coil Signal' (mV),Coil Signal" (mV),Range (mV),M. Quad. Signal (emu),M. Raw' (emu),M. Raw" (emu),Min. Temperature (K),Max. Temperature (K),Min. Field (Oe),Max. Field (Oe),Mass (grams),Motor Lag (deg),Pressure (Torr),VSM Status (code),Motor Status (code),Measure Status (code),Measure Count,PPMS Status (code),System Temp. (K),System Field (Oe),Sample Position (deg),Bridge 1 Resistance (ohms),Bridge 1 Excitation (에),Bridge 2 Resistance (ohms),Bridge 2 Excitation (에),Bridge 3 Resistance (ohms),Bridge 3 Excitation (에),Bridge 4 Resistance (ohms),Bridge 4 Excitation (에),Signal 1 Vin (V),Signal 2 Vin (V),Digital Inputs (code),Drive 1 Iout (mA),Drive 1 Ipower (W),Drive 2 Iout (mA),Drive 2 Ipower (W),Pressure (),Map 20 (),Map 21 (),Map 22 (),Map 23 (),Map 24 (),Map 25 (),Map 26 (),Map 27 (),Map 28 (),Map 29 ()
,32508355.05,5.0000038,0.1674614995718,,,2,,,,21.0200001829863,,,,,,,5.0000038,5.0000038,0.1674614995718,0.1674614995718,,,7.722963,,,,-99999999,4369,5.0109,0.1674614995718,,,,,,,,,,,,,,,,,,,,,,,5.0000038,,,,
,32508498.805,5.0131617,4471.27905273438,-8.74853515147655E-6,3.44372693629875E-7,1,0.999253354069792,40.0298881530762,1.99722122110095,21.0100002586842,-9.62662602879084E-5,-2.90387994893748E-5,0.25,-1.02791008281524E-6,-8.69519652427325E-6,-1.06678983097176E-6,5.0131617,5.0131617,4468.73828125,4473.81982421875,56.4367056025444,20.5842713466868,8.102614,0,0,0,40,4449,4.9794,4471.27905273438,,,,,,,,,,,,,0,,,,0,,,,,,5.0131617,,,,
,32508590.57,5.00815485,9057.31396484375,-1.83934615803392E-5,5.22264265288064E-7,1,0.999253354069792,40.0298881530762,1.99721556266491,21.0100002586842,-0.000203323258680446,-5.62036577765729E-5,0.25,-1.7219379622515E-6,-1.8289116045878E-5,-1.81281549964134E-6,5.0079288,5.0083809,9027.3955078125,9087.232421875,56.4703156288714,20.5842281981558,8.102614,0,0,0,40,4449,4.97475,9057.31396484375,,,,,,,,,,,,,0,,,,-0.00245,,,,,,5.00815485,,,,
,32508681.445,5.0053658,13597.9482421875,-2.56715411112388E-5,7.22858850535461E-7,1,0.999253354069792,40.0298881530762,1.99722411670069,21.0100002586842,-0.000283645828376008,-7.97654315773364E-5,0.25,-2.50981095433237E-6,-2.55342312672795E-5,-2.64559761312377E-6,5.0053658,5.0053658,13565.7548828125,13630.1416015625,56.9205336559483,20.5911738272292,8.102614,0,0,0,40,4449,4.9716,13597.9482421875,,,,,,,,,,,,,0,,,,0.0049,,,,,,5.0053658,,,,
,32508774.67,5.0010228,18257.7607421875,-3.11152061204093E-5,7.6564961147293E-7,1,0.999253354069792,40.0298881530762,1.99712498529904,21.0100002586842,-0.000342151934330278,-0.000106565295588677,0.25,-3.9076125673387E-6,-3.09558148659411E-5,-4.07983119625568E-6,5.0010228,5.0010228,18247.779296875,18267.7421875,57.0416860764291,20.5884756683753,8.102614,0,0,0,40,4449,4.9718,18257.7607421875,,,,,,,,,,,,,0,,,,0,,,,,,5.0010228,,,,
,32508866.845,5.0068684,22865.7109375,-2.9580798098877E-5,9.69027995900534E-7,1,0.999253354069792,40.0298881530762,1.99711548648708,21.0100002586842,-0.000324543510968047,-0.00010620766969483,0.25,-4.13760597326638E-6,-2.94388085509872E-5,-4.31005396405756E-6,5.0068684,5.0068684,22865.7109375,22865.7109375,56.8322096332752,20.5935266058172,8.482265,0,0,0,40,4449,4.9729,22865.7109375,,,,,,,,,,,,,0,,,,0.0049,,,,,,5.0068684,,,,
,32508956.345,5.0017757,27338.63671875,-2.55664056917746E-5,1.26183366461173E-6,1,0.999253354069792,40.0298881530762,1.99706003229183,21.0100002586842,-0.00027990611708063,-9.57626618562948E-5,0.25,-3.91878906028141E-6,-2.54521783581715E-5,-4.07476725219744E-6,5.0017757,5.0017757,27308.642578125,27368.630859375,57.1065612435253,20.5938138575949,8.482265,0,0,0,40,4449,4.9703,27338.63671875,,,,,,,,,,,,,0,,,,0,,,,,,5.0017757,,,,
,32509047.85,4.99967505,31913.71875,-2.23811396649554E-5,1.1647885742708E-6,1,0.999253354069792,40.0298881530762,1.99693228114819,21.0100002586842,-0.000241242025016009,-0.000105494111947247,0.25,-5.34607573082977E-6,-2.22779746355934E-5,-5.48357385493467E-6,4.9994102,4.9999399,31876.33203125,31951.10546875,56.8071975206598,20.5977306097938,8.102614,0,0,0,40,4449,4.96875,31913.71875,,,,,,,,,,,,,0,,,,-0.00245,,,,,,4.99967505,,,,
,32509139.855,5.0010467,36511.3046875,-3.04499243384575E-5,1.38838320193989E-6,1,0.999253354069792,40.0298881530762,1.99696988217681,21.0100002586842,-0.000331085711678285,-0.000128472891285665,0.25,-5.92557121704456E-6,-3.03325393667487E-5,-6.1252196894685E-6,5.0010467,5.0010467,36508.828125,36513.78125,56.8423708040252,20.596303909321,8.102614,0,0,0,40,4449,4.9688,36511.3046875,,,,,,,,,,,,,0,,,,0.0049,,,,,,5.0010467,,,,
,32509234.86,5.000082,41261.298828125,-3.90532571531424E-5,1.4294093564174E-6,1,0.999253354069792,40.0298881530762,1.99695191376629,21.0100002586842,-0.000430204789709991,-0.000134987216100433,0.25,-4.94471163666693E-6,-3.89402971515879E-5,-5.21583705753524E-6,5.000082,5.000082,41256.359375,41266.23828125,56.7884384361983,20.595534862705,7.722963,0,0,0,40,4449,4.9689,41261.298828125,,,,,,,,,,,,,0,,,,0,,,,,,5.000082,,,,
,32509326.5,4.9974971,45839.560546875,-4.88182941070208E-5,1.55006872162809E-6,1,0.999253354069792,40.0298881530762,1.99675101382871,21.0100002586842,-0.000538076691583064,-0.000168237068850196,0.25,-6.12562045173043E-6,-4.87002210975385E-5,-6.47299424247483E-6,4.9974971,4.9974971,45834.78515625,45844.3359375,57.1941036376791,20.6004784414557,8.102614,0,0,0,40,4449,4.9726,45839.560546875,,,,,,,,,,,,,0,,,,-0.0049,,,,,,4.9974971,,,,
,32509418.415,4.9996791,50434.69921875,-6.36467104747159E-5,1.75337988319962E-6,1,0.999253354069792,40.0298881530762,1.99681647470141,21.0100002586842,-0.000706623962538503,-0.000193026173938426,0.25,-5.6397249846171E-6,-6.35394853696561E-5,-6.10369530559833E-6,4.9996791,4.9996791,50432.2265625,50437.171875,57.2675767184868,20.5995549926821,8.482265,0,0,0,40,4449,4.97185,50434.69921875,,,,,,,,,,,,,0,,,,-0.0049,,,,,,4.9996791,,,,
,32509509.535,4.9968393,54987.046875,-7.40843475088562E-5,1.87853655564118E-6,1,0.999253354069792,40.0298881530762,1.99709463876572,21.0100002586842,-0.000828145976853179,-0.000196183282209144,0.25,-4.02545874423789E-6,-7.40117241597799E-5,-4.5733044570791E-6,4.9968181,4.9968605,54954.33984375,55019.75390625,57.3043132588907,20.6006749431482,8.102614,0,0,0,40,4449,4.97315,54987.046875,,,,,,,,,,,,,0,,,,0.00245,,,,,,4.9968393,,,,
,32509599.515,4.99796555,59484.8828125,-8.54527166960181E-5,1.82672799965494E-6,1,0.999253354069792,40.0298881530762,1.99721293955481,21.0100002586842,-0.000949522432157824,-0.000260634959342683,0.25,-7.67323157834344E-6,-8.53833154413602E-5,-8.30817635978286E-6,4.9973235,4.9986076,59452.6484375,59517.1171875,57.4012351952753,20.5957166251091,7.722963,0,0,0,40,4449,4.97595,59484.8828125,,,,,,,,,,,,,0,,,,-0.00245,,,,,,4.99796555,,,,
,32509690.41,4.9952502,64028.33203125,-9.47522180652611E-5,2.18253718150409E-6,1,0.999253354069792,40.0298881530762,1.9969557543986,21.0100002586842,-0.00106650178797631,-0.000215113224092418,0.25,-1.96188550468065E-6,-9.47637866154519E-5,-2.66697887529552E-6,4.995018,4.9954824,63995.8359375,64060.828125,57.423902422333,20.5998141650508,8.102614,0,0,0,40,4449,4.9834,64028.33203125,,,,,,,,,,,,,0,,,,0,,,,,,4.9952502,,,,
,32509784.62,4.9937985,68736.11328125,-0.000115209999703615,1.92251745447458E-6,1,0.999253354069792,40.0298881530762,1.99675898001672,21.0100002586842,-0.00128767126986727,-0.000314435118917134,0.25,-7.06069903236175E-6,-0.000115237339122877,-7.91869707926611E-6,4.9937239,4.9938731,68708.734375,68763.4921875,57.0033862789868,20.6017281740317,8.102614,0,0,0,40,4449,4.9852,68736.11328125,,,,,,,,,,,,,0,,,,0,,,,,,4.9937985,,,,
,32509880.215,4.9940915,73516.5703125,-0.000132281412895199,2.5406808881791E-6,1,0.999253354069792,40.0298881530762,1.99670073905935,21.0100002586842,-0.00148623442280559,-0.000321158666367075,0.25,-4.57590121096376E-6,-0.000132392074958857,-5.55355285491281E-6,4.9940915,4.9940915,73511.6640625,73521.4765625,56.9947883652753,20.6040484332435,8.861917,0,0,0,40,4449,4.9886,73516.5703125,,,,,,,,,,,,,0,,,,-0.00245,,,,,,4.9940915,,,,
,32509976.975,4.9982195,78352.12890625,-0.000142933862282895,2.8663286029395E-6,1,0.999253354069792,40.0298881530762,1.99652743952261,21.0100002586842,-0.00160415651421838,-0.000359592985493234,0.25,-6.05726169410615E-6,-0.000143100257195403,-7.10710480371824E-6,4.9982195,4.9982195,78349.5,78354.7578125,56.963523224506,20.6048674178957,8.102614,0,0,0,40,4449,4.9926,78352.12890625,,,,,,,,,,,,,0,,,,0,,,,,,4.9982195,,,,
,32510069.77,4.9926188,82990.44140625,-0.000158544487472244,3.90412615352491E-6,1,0.999253354069792,40.0298881530762,1.99648491108489,21.0100002586842,-0.00177373095251865,-0.000433480697727683,0.25,-9.78026684591769E-6,-0.000158762254918938,-1.09397151626383E-5,4.9923778,4.9928598,82957.8515625,83023.03125,57.2136443506599,20.604343119352,8.482265,0,0,0,40,4449,5.00095,82990.44140625,,,,,,,,,,,,,0,,,,0,,,,,,4.9926188,,,,
,32510157.615,4.9957209,87381.37890625,-0.00017757079164149,3.86536743661498E-6,1,0.999253354069792,40.0298881530762,1.99656234923878,21.0100002586842,-0.00199135153005084,-0.000463054311674821,0.25,-8.97156742737812E-6,-0.000177884397294606,-1.02537448651375E-5,4.9957209,4.9957209,87371.2265625,87391.53125,56.7204367550252,20.6019909278297,8.102614,0,0,0,40,4449,5.00485,87381.37890625,,,,,,,,,,,,,0,,,,0,,,,,,4.9957209,,,,
,32510259.735,5.00366665,88350.734375,-0.000175003596896578,3.2673814605245E-6,1,0.999253354069792,40.0298881530762,1.99654884072747,21.0100002586842,-0.00196524064876463,-0.000442147711845394,0.25,-7.58741725891495E-6,-0.000175333211619411,-8.84529606839832E-6,5.0028663,5.004467,88318.234375,88383.234375,56.9494539111599,20.6088724727903,8.102614,0,0,0,40,4449,5.0056,88350.734375,,,,,,,,,,,,,0,,,,-0.0049,,,,,,5.00366665,,,,
,32510349.265,4.9969811,83874.33984375,-0.00016315706616162,3.1711126648701E-6,1,0.999253354069792,40.0298881530762,1.99629105926116,21.0100002586842,-0.00183242329661666,-0.000406402658795206,0.25,-6.56043444565537E-6,-0.000163416859847901,-7.74490343795071E-6,4.9969811,4.9969811,83844.2890625,83904.390625,57.4770531616407,20.606752908217,8.102614,0,0,0,40,4449,5.00735,83874.33984375,,,,,,,,,,,,,0,,,,0.00245,,,,,,4.9969811,,,,
,32510442.195,4.9997902,79227.93359375,-0.000151061344791443,3.25485902543517E-6,1,0.999253354069792,40.0298881530762,1.99656347557049,21.0100002586842,-0.00169633349572128,-0.000375525717375204,0.25,-6.00196991724015E-6,-0.000151250278908486,-7.10914041959473E-6,4.9997902,4.9997902,79225.6875,79230.1796875,57.2019199228714,20.6079579843784,8.102614,0,0,0,40,4449,5.0052,79227.93359375,,,,,,,,,,,,,0,,,,0,,,,,,4.9997902,,,,
,32510539.275,5.0021405,74377.140625,-0.00013334390373112,2.79113678140345E-6,1,0.999253354069792,40.0298881530762,1.99663824029225,21.0100002586842,-0.00149147918124909,-0.000361237217004104,0.25,-7.9297239147329E-6,-0.000133440437009881,-8.91789104169925E-6,5.0021405,5.0021405,74366.90625,74387.375,57.3199458292753,20.6059561437071,8.102614,0,0,0,40,4449,5.0033,74377.140625,,,,,,,,,,,,,0,,,,0.00245,,,,,,5.0021405,,,,
,32510633.235,5.0010247,69678.98046875,-0.000120722811288776,2.8829077850721E-6,1,0.999253354069792,40.0298881530762,1.99648250886571,21.0100002586842,-0.00134952259274661,-0.000327771007792139,0.25,-7.24986791566243E-6,-0.000120762353210829,-8.14835227957905E-6,5.0010247,5.0010247,69673.9921875,69683.96875,57.5567792706022,20.6105167138003,8.102614,0,0,0,40,4449,5.0012,69678.98046875,,,,,,,,,,,,,0,,,,-0.0049,,,,,,5.0010247,,,,
,32510723.125,5.0007157,65185.55859375,-0.000101631388544716,2.74208885416291E-6,1,0.999253354069792,40.0298881530762,1.99613616408404,21.0100002586842,-0.00113971538566978,-0.000252230952290479,0.25,-4.01441584488157E-6,-0.000101640180840886,-4.77108244774643E-6,5.0007157,5.0007157,65150.640625,65220.4765625,57.187068981006,20.6182586423417,7.722963,0,0,0,40,4449,4.9987,65185.55859375,,,,,,,,,,,,,0,,,,0,,,,,,5.0007157,,,,
,32510817.945,5.0077906,60444.7265625,-8.8890863952128E-5,2.43590833446181E-6,1,0.999253354069792,40.0298881530762,1.9964944816196,21.0100002586842,-0.000989665367358018,-0.000258906621102115,0.25,-6.90630153426017E-6,-8.88346932510383E-5,-7.5676041919501E-6,5.0077906,5.0077906,60442.22265625,60447.23046875,57.0838940164676,20.6130337559899,8.102614,0,0,0,40,4449,4.9943,60444.7265625,,,,,,,,,,,,,0,,,,0,,,,,,5.0077906,,,,
,32510915.47,5.0013132,55571.962890625,-7.70107378296642E-5,2.25463768780091E-6,1,0.999253354069792,40.0298881530762,1.99668830877444,21.0100002586842,-0.000861128597290709,-0.000201750828771438,0.25,-3.99339230499766E-6,-7.69410566506398E-5,-4.56350216337001E-6,5.0013132,5.0013132,55569.5625,55574.36328125,57.1386080128137,20.6122354917926,8.482265,0,0,0,40,4449,4.99405,55571.962890625,,,,,,,,,,,,,0,,,,0,,,,,,5.0013132,,,,
,32511009.84,5.0016336,50854.421875,-5.94153047892398E-5,1.94636519384308E-6,1,0.999253354069792,40.0298881530762,1.99642369258594,21.0100002586842,-0.000664719729211999,-0.000151475994900293,0.25,-2.72112125044135E-6,-5.9336490317508E-5,-3.15730435232668E-6,5.0016336,5.0016336,50851.33984375,50857.50390625,57.1628384969099,20.6149694184353,8.482265,0,0,0,40,4449,4.9906,50854.421875,,,,,,,,,,,,,0,,,,-0.0049,,,,,,5.0016336,,,,
,32511103.035,5.0035291,46196.5703125,-4.33987187012583E-5,1.64187081936145E-6,1,0.999253354069792,40.0298881530762,1.99628761545671,21.0100002586842,-0.000481264649403878,-0.000132814842140816,0.25,-3.9625351926732E-6,-4.33061646671452E-5,-4.27403106423444E-6,5.0035291,5.0035291,46194.03125,46199.109375,56.9322580837368,20.6145962110061,8.102614,0,0,0,40,4449,4.9897,46196.5703125,,,,,,,,,,,,,0,,,,0.0049,,,,,,5.0035291,,,,
,32511194.435,5.0040107,41628.5,-3.35067923805029E-5,1.6296511179821E-6,1,0.999253354069792,40.0298881530762,1.99631229404511,21.0100002586842,-0.000369701452467422,-0.000111926157439783,0.25,-3.89971512359335E-6,-3.34135986131797E-5,-4.13350625117318E-6,5.0040107,5.0040107,41620.96484375,41636.03515625,57.268358347006,20.6170037644303,8.102614,0,0,0,40,4449,4.98695,41628.5,,,,,,,,,,,,,0,,,,0.00245,,,,,,5.0040107,,,,
,32511292.01,5.0047164,36753.8125,-1.65699224302953E-5,1.50609334573242E-6,1,0.999253354069792,40.0298881530762,1.99651948925107,21.0100002586842,-0.000175167131621314,-9.75033082748232E-5,0.25,-5.67486220113329E-6,-1.64891710126742E-5,-5.77770753677435E-6,5.0047164,5.0047164,36748.8203125,36758.8046875,57.1073428720445,20.6183616134061,8.102614,0,0,0,40,4449,4.98455,36753.8125,,,,,,,,,,,,,0,,,,0,,,,,,5.0047164,,,,
,32511385.165,5.0040503,32096.2705078125,-6.31308891634247E-6,1.12330284298032E-6,1,0.999253354069792,40.0298881530762,1.99629714399841,21.0100002586842,-6.77446438187803E-5,-3.13260911569234E-5,0.25,-1.64805165219448E-6,-6.28313728783116E-6,-1.68650281853018E-6,5.0040503,5.0040503,32091.24609375,32101.294921875,57.4637654768138,20.6176261231313,8.482265,0,0,0,40,4449,4.9833,32096.2705078125,,,,,,,,,,,,,0,,,,-0.0049,,,,,,5.0040503,,,,
,32511476.74,5.0031085,27521.3212890625,8.55509938403026E-6,6.58468967384332E-7,1,0.999253354069792,40.0298881530762,1.99655736934003,21.0100002586842,0.000104708295134138,-2.96316763624238E-5,0.25,-4.16785567317284E-6,8.55340526771519E-6,-4.09674625742247E-6,5.0031085,5.0031085,27493.84765625,27548.794921875,57.3598088837561,20.6153246284648,7.722963,0,0,0,40,4449,4.97655,27521.3212890625,,,,,,,,,,,,,0,,,,0,,,,,,5.0031085,,,,
,32511571.72,5.0083961,22773.515625,1.93380974165792E-5,6.96182040692264E-7,1,0.999253354069792,40.0298881530762,1.99624480922203,21.0100002586842,0.000225415971385433,-5.04938717815436E-6,0.25,-3.91370106382173E-6,1.92872757725028E-5,-3.77517022054433E-6,5.0083961,5.0083961,22771.05859375,22775.97265625,57.3074397729676,20.6182003935449,7.722963,0,0,0,40,4449,4.9694,22773.515625,,,,,,,,,,,,,0,,,,0,,,,,,5.0083961,,,,
,32511665.15,5.0058646,18103.591796875,3.10878748937176E-5,5.87895931489389E-7,1,0.999253354069792,40.0298881530762,1.99629362127832,21.0100002586842,0.000358305222562575,1.36519067006566E-5,0.25,-4.34637892787882E-6,3.09783056402969E-5,-4.13860751999313E-6,5.0058646,5.0058646,18103.591796875,18103.591796875,56.973684395256,20.6216030902402,7.722963,0,0,0,40,4449,4.9691,18103.591796875,,,,,,,,,,,,,0,,,,0.0049,,,,,,5.0058646,,,,
,32511758.095,5.0040584,13458.6000976563,4.50263912759078E-5,5.19462407856914E-7,1,0.999253354069792,40.0298881530762,1.99635843136777,21.0100002586842,0.000511811287095547,5.84884774310312E-5,0.25,-2.83520069670339E-6,4.48266454553058E-5,-2.56282003075033E-6,5.0040584,5.0040584,13456.2001953125,13461,57.4997203886984,20.6203968510496,8.102614,0,0,0,40,4449,4.9666,13458.6000976563,,,,,,,,,,,,,0,,,,0,,,,,,5.0040584,,,,
,32511849.715,4.9951634,8877.82421875,5.74737590099745E-5,4.36544625559089E-7,1,0.999253354069792,40.0298881530762,1.99623354665298,21.0100002586842,0.000648736816919514,9.85219924839636E-5,0.25,-1.47261659058065E-6,5.71840560768768E-5,-1.1539980420104E-6,4.9951634,4.9951634,8872.830078125,8882.818359375,57.3449579418907,20.6218881890725,8.482265,0,0,0,40,4449,4.96985,8877.82421875,,,,,,,,,,,,,0,,,,0,,,,,,4.9951634,,,,
,32511942.02,4.9986105,4262.21069335937,6.75364724632201E-5,3.96609488850816E-7,1,0.999253354069792,40.0298881530762,1.99637466154599,21.0100002586842,0.000759697532418927,0.000129295017168485,0.25,-5.01104769381671E-7,6.71667225935333E-5,-1.55556092170274E-7,4.9975686,4.9996524,4259.6298828125,4264.79150390625,57.2222422643714,20.6194100621706,7.722963,0,0,0,40,4449,4.9672,4262.21069335937,,,,,,,,,,,,,0,,,,0,,,,,,4.9986105,,,,
,32512035.11,4.9951324,-388.197860717773,7.66174028382732E-5,3.95425713244427E-7,1,0.999253354069792,40.0298881530762,1.99649997464585,21.0100002586842,0.000859676760637411,0.000158100307709647,0.25,4.68781159285491E-7,7.61763191449076E-5,8.36523596810867E-7,4.9951324,4.9951324,-393.075256347656,-383.320465087891,57.5067550453715,20.627081898325,7.722963,0,0,0,40,4449,4.9724,-388.197860717773,,,,,,,,,,,,,0,,,,0,,,,,,4.9951324,,,,
,32512127.275,4.99678255,-4993.21264648438,8.50112699018401E-5,3.66464748402275E-7,1,0.999253354069792,40.0298881530762,1.9963377681888,21.0100002586842,0.000953464424430493,0.000178676359090909,0.25,7.82099945110498E-7,8.45427639829572E-5,1.21369249420979E-6,4.9958673,4.9976978,-5023.13671875,-4963.28857421875,57.271484861083,20.6233671809368,8.102614,0,0,0,40,4449,4.9772,-4993.21264648438,,,,,,,,,,,,,0,,,,-0.00245,,,,,,4.99678255,,,,
,32512219.035,4.9978662,-9581.4521484375,9.22140659898141E-5,4.55013574370909E-7,1,0.999253354069792,40.0298881530762,1.99627406663028,21.0100002586842,0.0010319987326576,0.000208303026656009,0.25,2.10133577433418E-6,9.1730120698214E-5,2.59434247944882E-6,4.9978662,4.9978662,-9586.509765625,-9576.39453125,56.9861904515637,20.6255029422651,8.482265,0,0,0,40,4449,4.97755,-9581.4521484375,,,,,,,,,,,,,0,,,,0.00245,,,,,,4.9978662,,,,
,32512311.945,4.9978809,-14224.7587890625,9.32116998107302E-5,6.24401544471637E-7,1,0.999253354069792,40.0298881530762,1.99635753382047,21.0100002586842,0.00104438266480859,0.000206328803080358,0.25,1.70834996907759E-6,9.27608584920489E-5,2.24110870671167E-6,4.9978809,4.9978809,-14229.73828125,-14219.779296875,57.5317671579869,20.6223878484475,7.722963,0,0,0,40,4449,4.9789,-14224.7587890625,,,,,,,,,,,,,0,,,,0,,,,,,4.9978809,,,,
,32512403.82,4.9974914,-18817.107421875,8.5885077803398E-5,6.8578189103282E-7,1,0.999253354069792,40.0298881530762,1.9963183368142,21.0100002586842,0.000959588814499536,0.000207472829388965,0.25,3.08400839878876E-6,8.54964352999568E-5,3.59631057159202E-6,4.9974914,4.9974914,-18822.130859375,-18812.083984375,57.2269320354868,20.6205154735935,8.482265,0,0,0,40,4449,4.9802,-18817.107421875,,,,,,,,,,,,,0,,,,0,,,,,,4.9974914,,,,
,32512494.78,4.9986973,-23362.1181640625,6.7902025741134E-5,1.00274808869609E-6,1,0.999253354069792,40.0298881530762,1.9962302884703,21.0100002586842,0.000759667678404569,0.000160189953910203,0.25,2.07161964636065E-6,6.76267688384862E-5,2.49861753641538E-6,4.9986973,4.9986973,-23364.599609375,-23359.63671875,57.0377779338329,20.6246122368561,8.102614,0,0,0,40,4449,4.9798,-23362.1181640625,,,,,,,,,,,,,0,,,,0.0049,,,,,,4.9986973,,,,
,32512589.595,4.9999871,-28099.626953125,4.61171361756537E-5,1.08599471094167E-6,1,0.999253354069792,40.0298881530762,1.99626951271603,21.0100002586842,0.000514522587178858,0.000118212872001572,0.25,2.22677398240992E-6,4.5946749656861E-5,2.52685224974972E-6,4.9999871,4.9999871,-28112.087890625,-28087.166015625,56.9361662263329,20.6263600719077,8.102614,0,0,0,40,4449,4.97935,-28099.626953125,,,,,,,,,,,,,0,,,,0,,,,,,4.9999871,,,,
,32512684.25,5.0007906,-32832.033203125,3.69959796376021E-5,1.11021333202702E-6,1,0.999253354069792,40.0298881530762,1.9962432811905,21.0100002586842,0.000411869713999737,0.000100922997528249,0.25,2.31505552517027E-6,3.68736450468668E-5,2.56344303900555E-6,5.0007906,5.0007906,-32834.765625,-32829.30078125,57.0706063316407,20.6255156267345,8.482265,0,0,0,40,4449,4.9823,-32832.033203125,,,,,,,,,,,,,0,,,,-0.0049,,,,,,5.0007906,,,,
,32512776.57,4.9987073,-37446.14453125,3.53949793311427E-5,1.64345610243275E-6,1,0.999253354069792,40.0298881530762,1.99644860676532,21.0100002586842,0.000392221927814087,0.000108021125190128,0.25,3.2213656030472E-6,3.52877503447188E-5,3.46404682019378E-6,4.9987073,4.9987073,-37451.09375,-37441.1953125,57.241001348833,20.6275161774245,7.722963,0,0,0,40,4449,4.98195,-37446.14453125,,,,,,,,,,,,,0,,,,0,,,,,,4.9987073,,,,
,32512869.195,5.0049267,-42071.4765625,3.92847944711841E-5,1.93562593645521E-6,1,0.999253354069792,40.0298881530762,1.99626541565428,21.0100002586842,0.000436743357592377,0.000113013222368675,0.25,2.95532884197179E-6,3.91889752687059E-5,3.2331859270365E-6,5.0049267,5.0049267,-42074.1171875,-42068.8359375,57.4559491916215,20.627446249256,8.482265,0,0,0,40,4449,4.9741,-42071.4765625,,,,,,,,,,,,,0,,,,0.0049,,,,,,5.0049267,,,,
,32512960.785,4.9992833,-46649.197265625,5.06436349363043E-5,1.55631026842571E-6,1,0.999253354069792,40.0298881530762,1.99628426967304,21.0100002586842,0.000564544348009638,0.000138822203482418,0.25,3.18936440671359E-6,5.0548464674885E-5,3.55555806289475E-6,4.9992833,4.9992833,-46651.734375,-46646.66015625,57.4231207938138,20.6297577783568,8.482265,0,0,0,40,4449,4.9776,-46649.197265625,,,,,,,,,,,,,0,,,,0,,,,,,4.9992833,,,,
,32513056.43,4.9951737,-51428.822265625,6.77462599743037E-5,2.10431412611745E-6,1,0.999253354069792,40.0298881530762,1.99625832392087,21.0100002586842,0.00075959286865125,0.000163360026397398,0.25,2.27321752995769E-6,6.76664278432704E-5,2.7719848835687E-6,4.9950161,4.9953313,-51458.8203125,-51398.82421875,57.054973761256,20.6309649102253,8.482265,0,0,0,40,4449,4.984,-51428.822265625,,,,,,,,,,,,,0,,,,0,,,,,,4.9951737,,,,
,32513153.785,4.99698165,-56296.26171875,6.99633659196555E-5,3.37768299272789E-6,1,0.999253354069792,40.0298881530762,1.99621172085082,21.0100002586842,0.000777743048013924,0.000207998798645462,0.25,5.81981914157206E-6,6.98886847056334E-5,6.33730534908335E-6,4.9969411,4.9970222,-56301.3203125,-56291.203125,57.1049979864868,20.6298397494726,7.722963,0,0,0,40,4449,4.98525,-56296.26171875,,,,,,,,,,,,,0,,,,0,,,,,,4.99698165,,,,
,32513247.695,4.996006,-60991.138671875,9.09177264779847E-5,3.52550215413395E-6,1,0.999253354069792,40.0298881530762,1.9962213949286,21.0100002586842,0.00101921676803033,0.000225589265036883,0.25,3.59197689588965E-6,9.08907558763343E-5,4.26870297127591E-6,4.996006,4.996006,-60994.15625,-60988.12109375,57.413741251583,20.6351991958822,8.102614,0,0,0,40,4449,4.9908,-60991.138671875,,,,,,,,,,,,,0,,,,0.00245,,,,,,4.996006,,,,
,32513341.65,4.996707,-65685.9453125,0.000100412095515579,3.76612178239584E-6,1,0.999253354069792,40.0298881530762,1.99620301352878,21.0100002586842,0.0011214566367905,0.000275144009740094,0.25,6.26129548509115E-6,0.000100408222233037,7.00975232183127E-6,4.996707,4.996707,-65691.0390625,-65680.8515625,57.3566823696791,20.6319629480589,8.482265,0,0,0,40,4449,4.99335,-65685.9453125,,,,,,,,,,,,,0,,,,-0.00245,,,,,,4.996707,,,,
,32513434.93,4.9958701,-70345.37890625,0.000116644611881116,3.43399744734467E-6,1,0.999253354069792,40.0298881530762,1.99630964309405,21.0100002586842,0.00131300690640503,0.00026614930063072,0.25,2.53340924113433E-6,0.000116722492235007,3.39746099750539E-6,4.9958701,4.9958701,-70347.921875,-70342.8359375,57.515352959083,20.6338670174732,7.722963,0,0,0,40,4449,4.9961,-70345.37890625,,,,,,,,,,,,,0,,,,0,,,,,,4.9958701,,,,
,32513531.125,4.9972191,-75152.5703125,0.000139528283240836,4.17832523355235E-6,1,0.999253354069792,40.0298881530762,1.9962059631204,21.0100002586842,0.0015565306901162,0.000399572980276793,0.25,1.02129732616811E-5,0.000139624006627811,1.12483405934543E-5,4.9972191,4.9972191,-75155.046875,-75150.09375,57.4817429327561,20.6341686061458,8.482265,0,0,0,40,4449,5.00035,-75152.5703125,,,,,,,,,,,,,0,,,,-0.0049,,,,,,4.9972191,,,,
,32513623.13,4.9956851,-79752.4375,0.000147341750176185,4.93520352523343E-6,1,0.999253354069792,40.0298881530762,1.99630097777513,21.0100002586842,0.00165102950961771,0.000385094397303444,0.25,7.52199161016145E-6,0.000147519813070132,8.6034585911812E-6,4.9952068,4.9961634,-79787.453125,-79717.421875,57.4199942797368,20.6316044260083,7.722963,0,0,0,40,4449,5.00465,-79752.4375,,,,,,,,,,,,,0,,,,0,,,,,,4.9956851,,,,
,32513716.655,4.9957168,-84427.2265625,0.000160098836915758,3.91456908951618E-6,1,0.999253354069792,40.0298881530762,1.99616593444374,21.0100002586842,0.00178820521741492,0.000453426035199895,0.25,1.12700113744762E-5,0.000160325454667319,1.24400875370485E-5,4.9948225,4.9966111,-84454.796875,-84399.65625,57.4457880208715,20.6353507721191,8.102614,0,0,0,40,4449,5.0083,-84427.2265625,,,,,,,,,,,,,0,,,,0.0049,,,,,,4.9957168,,,,
,32513803.57,4.996285,-88769.25390625,0.000172720748859852,4.81501112633971E-6,1,0.999253354069792,40.0298881530762,1.996220086568,21.0100002586842,0.00194078671977606,0.000428363532319408,0.25,6.78660477306994E-6,0.000173055942153635,8.02517607084541E-6,4.996285,4.996285,-88801.9375,-88736.5703125,57.4801796757176,20.6326138533626,8.102614,0,0,0,40,4449,5.01165,-88769.25390625,,,,,,,,,,,,,0,,,,-0.00245,,,,,,4.996285,,,,
,32513909.36,4.9980943,-86751.6484375,0.000172238670145945,4.69605401126713E-6,1,0.999253354069792,40.0298881530762,1.99637427384189,21.0100002586842,0.00193140692568144,0.000448480002826662,0.25,8.6459715716373E-6,0.000172535734681425,9.89141632586415E-6,4.9980669,4.9981217,-86784.34375,-86718.953125,57.5513078709676,20.6296955914829,7.722963,0,0,0,40,4449,5.01305,-86751.6484375,,,,,,,,,,,,,0,,,,0,,,,,,4.9980943,,,,
,32514000.375,5.00038245,-82204.5390625,0.000152021554164587,3.99855060004297E-6,1,0.999253354069792,40.0298881530762,1.99637221710327,21.0100002586842,0.00170587453984802,0.000386104288455276,0.25,6.76811136095832E-6,0.000152240389780651,7.87695943361946E-6,5.0003076,5.0004573,-82236.890625,-82172.1875,57.6763684340446,20.6300340334669,8.482265,0,0,0,40,4449,5.01215,-82204.5390625,,,,,,,,,,,,,0,,,,0,,,,,,5.00038245,,,,
,32514092.97,5.0019641,-77574.21484375,0.000136198460428995,3.39467180090421E-6,1,0.999253354069792,40.0298881530762,1.99634845025179,21.0100002586842,0.00152845573648161,0.000341965125280979,0.25,5.71410086706353E-6,0.000136349206296938,6.71573589810947E-6,5.0019641,5.0019641,-77579.40625,-77569.0234375,57.5278590153907,20.6286493987505,7.722963,0,0,0,40,4449,5.0108,-77574.21484375,,,,,,,,,,,,,0,,,,0,,,,,,5.0019641,,,,
,32514188.595,5.0015416,-72797.44140625,0.000124546348486901,3.31438322705105E-6,1,0.999253354069792,40.0298881530762,1.99610368439341,21.0100002586842,0.00138985429885528,0.000352185104697963,0.25,8.72321296929808E-6,0.000124610683837932,9.64912362538817E-6,5.0015416,5.0015416,-72827.5703125,-72767.3125,57.6247809517753,20.6285173301451,8.102614,0,0,0,40,4449,5.00825,-72797.44140625,,,,,,,,,,,,,0,,,,-0.00245,,,,,,5.0015416,,,,
,32514284.25,5.0043716,-68015.359375,0.000110048106062083,3.07766985088633E-6,1,0.999253354069792,40.0298881530762,1.99639956200571,21.0100002586842,0.00122745473140466,0.000312680161756251,0.25,7.84138142521826E-6,0.00011005920526518,8.66188024301268E-6,5.0043716,5.0043716,-68020.25,-68010.46875,57.9866749561792,20.6271467366953,8.102614,0,0,0,40,4449,5.00445,-68015.359375,,,,,,,,,,,,,0,,,,0,,,,,,5.0043716,,,,
,32514378.985,5.0030584,-63280.47265625,9.93109080585899E-5,2.69188037759155E-6,1,0.999253354069792,40.0298881530762,1.99624401526876,21.0100002586842,0.00111248524540116,0.000252398726818419,0.25,4.44923751649902E-6,9.92984903217416E-5,5.18889344829288E-6,5.0030584,5.0030584,-63283.14453125,-63277.80078125,56.9689946241406,20.6281454151255,7.722963,0,0,0,40,4449,5.00225,-63280.47265625,,,,,,,,,,,,,0,,,,0,,,,,,5.0030584,,,,
,32514472.85,5.0030956,-58590.51953125,8.25536585251862E-5,2.17823880486674E-6,1,0.999253354069792,40.0298881530762,1.99609678142384,21.0100002586842,0.000922950654847134,0.000217193211977205,0.25,4.36146657716721E-6,8.25023321934288E-5,4.97482784506956E-6,5.0030956,5.0030956,-58595.5625,-58585.4765625,57.6107116384292,20.6268351285929,8.102614,0,0,0,40,4449,4.9992,-58590.51953125,,,,,,,,,,,,,0,,,,0,,,,,,5.0030956,,,,
,32514567.93,5.00278235,-53837.923828125,7.03895386967495E-5,2.3208240939046E-6,1,0.999253354069792,40.0298881530762,1.99632433879649,21.0100002586842,0.000788571253036291,0.000174625156614164,0.25,2.78973842829952E-6,7.0320280716603E-5,3.30993536597833E-6,5.0024142,5.0031505,-53842.94140625,-53832.90625,57.3879475104484,20.62908355483,8.102614,0,0,0,40,4449,4.9956,-53837.923828125,,,,,,,,,,,,,0,,,,0,,,,,,5.00278235,,,,
,32514662.765,5.0022464,-49098.173828125,4.99029878359066E-5,1.659111445322E-6,1,0.999253354069792,40.0298881530762,1.99624268250852,21.0100002586842,0.000558142070034727,0.00012724333784635,0.25,2.29124643690354E-6,4.98279055322367E-5,2.65596426996138E-6,5.0022464,5.0022464,-49100.796875,-49095.55078125,57.4418798782753,20.6287721819625,8.102614,0,0,0,40,4449,4.99295,-49098.173828125,,,,,,,,,,,,,0,,,,-0.0049,,,,,,5.0022464,,,,
,32514756.73,5.0038142,-44400.6484375,3.81887190987473E-5,2.19520253740455E-6,1,0.999253354069792,40.0298881530762,1.9962185337129,21.0100002586842,0.000423144893275613,0.00011824545204526,0.25,3.61248366197888E-6,3.80993586271757E-5,3.88426619897154E-6,5.0038142,5.0038142,-44428.02734375,-44373.26953125,57.5388018146599,20.624949430877,8.102614,0,0,0,40,4449,4.9931,-44400.6484375,,,,,,,,,,,,,0,,,,0.00245,,,,,,5.0038142,,,,
,32514851.5,5.0021329,-39665.48828125,2.82610338059837E-5,1.43624521738521E-6,1,0.999253354069792,40.0298881530762,1.99613779675611,21.0100002586842,0.000307165667163993,0.000119754733865961,0.25,5.54332540229673E-6,2.81606475145391E-5,5.73336819520824E-6,5.0021329,5.0021329,-39670.265625,-39660.7109375,57.3605905122753,20.6289622266849,8.102614,0,0,0,40,4449,4.993,-39665.48828125,,,,,,,,,,,,,0,,,,0,,,,,,5.0021329,,,,
,32514948.405,5.0029955,-34823.5,1.27637578159211E-5,1.58973713826212E-6,1,0.999253354069792,40.0298881530762,1.99619073111965,21.0100002586842,0.000137429477058927,6.09283956105595E-5,0.25,3.1156070054146E-6,1.2708017800849E-5,3.19634747938807E-6,5.0029955,5.0029955,-34828.4375,-34818.5625,57.3269804859484,20.6308032545066,8.102614,0,0,0,40,4449,4.98845,-34823.5,,,,,,,,,,,,,0,,,,0.00245,,,,,,5.0029955,,,,
,32515044.155,5.0021949,-30039.048828125,-1.11346554699522E-6,1.03806661286027E-6,1,0.999253354069792,40.0298881530762,1.99605426442988,21.0100002586842,-1.59407829756106E-5,1.67295762496317E-5,0.25,1.68631857316902E-6,-1.12134636344334E-6,1.67343905681889E-6,5.0021949,5.0021949,-30041.673828125,-30036.423828125,57.3676251689484,20.6297606652977,8.102614,0,0,0,40,4449,4.9891,-30039.048828125,,,,,,,,,,,,,0,,,,0.00245,,,,,,5.0021949,,,,
,32515135.76,5.0032945,-25459.21875,-1.29608463068748E-5,8.06175443083373E-7,1,0.999253354069792,40.0298881530762,1.99616388643029,21.0100002586842,-0.000150309269154411,-1.13242295436294E-6,0.25,2.22362938641323E-6,-1.29281150045927E-5,2.13092165945181E-6,5.0032945,5.0032945,-25459.21875,-25459.21875,57.0901470446214,20.6283000893705,7.722963,0,0,0,40,4449,4.9871,-25459.21875,,,,,,,,,,,,,0,,,,-0.00245,,,,,,5.0032945,,,,
,32515231.875,5.0014787,-20656.744140625,-2.67502532397278E-5,8.32216188724058E-7,1,0.999253354069792,40.0298881530762,1.99612673068062,21.0100002586842,-0.000305760160108178,-2.63313114210702E-5,0.25,2.44783625952868E-6,-2.6655123672946E-5,2.27083219203758E-6,5.0014787,5.0014787,-20661.873046875,-20651.615234375,57.7232661451984,20.6292353595038,8.102614,0,0,0,40,4449,4.9834,-20656.744140625,,,,,,,,,,,,,0,,,,-0.00245,,,,,,5.0014787,,,,
,32515326.155,5.0005527,-15944.4125976562,-3.91792574551876E-5,5.77087698096501E-7,1,0.999253354069792,40.0298881530762,1.99599541954762,21.0100002586842,-0.000443379260441466,-6.20656721960281E-5,0.25,1.48030623707728E-6,-3.9008783531531E-5,1.24144197623769E-6,5.0005527,5.0005527,-15949.4375,-15939.3876953125,58.0632745510638,20.6270509931711,8.482265,0,0,0,40,4449,4.98525,-15944.4125976562,,,,,,,,,,,,,0,,,,-0.0049,,,,,,5.0005527,,,,
,32515421.375,5.0004978,-11186.6435546875,-5.19916260384464E-5,5.99146657427646E-7,1,0.999253354069792,40.0298881530762,1.99626908564224,21.0100002586842,-0.000587351002471866,-8.70651159885007E-5,0.25,1.52592718556466E-6,-5.17405765139471E-5,1.22811467255606E-6,5.0004978,5.0004978,-11191.64453125,-11181.642578125,57.5817913832176,20.6231512498091,7.722963,0,0,0,40,4449,4.9843,-11186.6435546875,,,,,,,,,,,,,0,,,,0,,,,,,5.0004978,,,,
,32515514.615,5.0006642,-6523.58740234375,-6.36640555155434E-5,3.94389671813048E-7,1,0.999253354069792,40.0298881530762,1.9962977698424,21.0100002586842,-0.000715119818974073,-0.0001281058963269,0.25,-7.00074221610314E-8,-6.33226555565392E-5,-4.03081937702621E-7,5.0006642,5.0006642,-6533.56103515625,-6513.61376953125,57.4629838482945,20.6237845954366,7.722963,0,0,0,40,4449,4.98515,-6523.58740234375,,,,,,,,,,,,,0,,,,0.00245,,,,,,5.0006642,,,,
,32515607.78,5.0006428,-1864.80157470703,-7.44073067560887E-5,3.59456798775012E-7,1,0.999253354069792,40.0298881530762,1.99622848263753,21.0100002586842,-0.000834712685272752,-0.000154189191464768,0.25,-5.07791091186434E-7,-7.3983922261106E-5,-8.70741625017256E-7,5.0006428,5.0006428,-1899.65869140625,-1829.94445800781,57.3410497992945,20.627262156336,8.102614,0,0,0,40,4449,4.9832,-1864.80157470703,,,,,,,,,,,,,0,,,,-0.0049,,,,,,5.0006428,,,,
,32515700.42,5.00093745,2758.04467773438,-8.06806140325738E-5,3.95052821472147E-7,1,0.999253354069792,40.0298881530762,1.9962486746392,21.0100002586842,-0.000904720285136481,-0.000169573384065242,0.25,-7.57392922496375E-7,-8.02245531217477E-5,-1.15440196988841E-6,5.0006819,5.001193,2728.06323242187,2788.02612304687,57.3809128537753,20.6245379210573,8.102614,0,0,0,40,4449,4.98245,2758.04467773438,,,,,,,,,,,,,0,,,,0,,,,,,5.00093745,,,,
,32515793.23,4.9995565,7400.5126953125,-8.87434793107744E-5,4.28953318651924E-7,1,0.999253354069792,40.0298881530762,1.99613104063085,21.0100002586842,-0.000994129048339159,-0.000193652631385206,0.25,-1.43452594954642E-6,-8.82662151844609E-5,-1.89744604923553E-6,4.9995565,4.9995565,7398.013671875,7403.01171875,57.5958606965638,20.6258343115345,8.102614,0,0,0,40,4449,4.9818,7400.5126953125,,,,,,,,,,,,,0,,,,0,,,,,,4.9995565,,,,
,32515888.515,4.99999975,12163.45703125,-9.32728621359736E-5,6.43764288628833E-7,1,0.999253354069792,40.0298881530762,1.99627635526569,21.0100002586842,-0.00104466293583013,-0.000207415445534772,0.25,-1.81198633009585E-6,-9.280463994225E-5,-2.33037700146963E-6,4.999588,5.0004115,12155.642578125,12171.271484375,57.8905346483138,20.6226468358251,8.102614,0,0,0,40,4449,4.9819,12163.45703125,,,,,,,,,,,,,0,,,,0,,,,,,4.99999975,,,,
,32515983,5.0000119,16886.0009765625,-9.10700561143728E-5,7.17150869155224E-7,1,0.999253354069792,40.0298881530762,1.99611754637963,21.0100002586842,-0.0010182632456341,-0.000214214478336894,0.25,-2.77297010339001E-6,-9.06447369263747E-5,-3.30595254226084E-6,5.0000119,5.0000119,16883.8203125,16888.181640625,57.6161830380638,20.6241155041914,8.102614,0,0,0,40,4449,4.98415,16886.0009765625,,,,,,,,,,,,,0,,,,-0.0049,,,,,,5.0000119,,,,
,32516075.34,4.998508,21498.451171875,-7.46491011491313E-5,9.94226239382898E-7,1,0.999253354069792,40.0298881530762,1.99610908561248,21.0100002586842,-0.000835480335763982,-0.000173102766913465,0.25,-2.02255953105871E-6,-7.43344712664881E-5,-2.48410004770397E-6,4.998508,4.998508,21491.26171875,21505.640625,57.8037738826792,20.6249856483129,8.102614,0,0,0,40,4449,4.98375,21498.451171875,,,,,,,,,,,,,0,,,,0.0049,,,,,,4.998508,,,,
,32516168.755,4.9992552,26168.69140625,-5.34985108631364E-5,1.04213814031086E-6,1,0.999253354069792,40.0298881530762,1.99607641448013,21.0100002586842,-0.000595683678565047,-0.000142778616443078,0.25,-3.09387813709683E-6,-5.32870722675789E-5,-3.43414436764915E-6,4.9992552,4.9992552,26163.3203125,26174.0625,57.1081245005637,20.6244465122466,8.102614,0,0,0,40,4449,4.98505,26168.69140625,,,,,,,,,,,,,0,,,,-0.00245,,,,,,4.9992552,,,,
,32516259.99,4.9997163,30729.8388671875,-4.03115030012581E-5,1.09711353160069E-6,1,0.999253354069792,40.0298881530762,1.99614761104368,21.0100002586842,-0.000448635530241787,-0.000110090376597173,0.25,-2.53978563863115E-6,-4.01693806399165E-5,-2.80600651482825E-6,4.9997163,4.9997163,30727.71484375,30731.962890625,57.1948852661984,20.6245530026677,7.722963,0,0,0,40,4449,4.9845,30729.8388671875,,,,,,,,,,,,,0,,,,-0.0049,,,,,,4.9997163,,,,
,32516353.775,4.9985251,35414.39453125,-3.54871453749118E-5,1.16947932681835E-6,1,0.999253354069792,40.0298881530762,1.99594847236842,21.0100002586842,-0.00039378193653495,-0.000104275538171758,0.25,-2.87908533514249E-6,-3.53746753787805E-5,-3.11997410300563E-6,4.9985251,4.9985251,35409.1953125,35419.59375,57.1323549846599,20.6285510021146,8.482265,0,0,0,40,4449,4.985,35414.39453125,,,,,,,,,,,,,0,,,,-0.0049,,,,,,4.9985251,,,,
,32516449.235,4.9976687,40189.939453125,-3.87214423483279E-5,1.3533844729669E-6,1,0.999253354069792,40.0298881530762,1.99594058927719,21.0100002586842,-0.00042748008451048,-0.000127185029820573,0.25,-4.32020424319788E-6,-3.86093834569211E-5,-4.58848798944436E-6,4.9976687,4.9976687,40182.40625,40197.47265625,57.2941520881407,20.6274350396856,7.722963,0,0,0,40,4449,4.9872,40189.939453125,,,,,,,,,,,,,0,,,,0,,,,,,4.9976687,,,,
,32516544.4,4.9991579,44945.392578125,-4.53519640163958E-5,1.68276934709738E-6,1,0.999253354069792,40.0298881530762,1.99614441398642,21.0100002586842,-0.000506851951235465,-0.000116411518713062,0.25,-2.15902337189108E-6,-4.52638927819056E-5,-2.48597966063736E-6,4.9991579,4.9991579,44940.48828125,44950.296875,57.301968373333,20.6253388520271,8.102614,0,0,0,40,4449,4.98715,44945.392578125,,,,,,,,,,,,,0,,,,0.00245,,,,,,4.9991579,,,,
,32516635.735,4.9980779,49510.81640625,-5.98373697938412E-5,2.11707098667368E-6,1,0.999253354069792,40.0298881530762,1.99598000155727,21.0100002586842,-0.000667211983700627,-0.000163581205282414,0.25,-3.72422623572393E-6,-5.97426434363078E-5,-4.16093544303011E-6,4.9980779,4.9980779,49508.25390625,49513.37890625,56.8798889729483,20.6292651711123,7.722963,0,0,0,40,4449,4.9903,49510.81640625,,,,,,,,,,,,,0,,,,-0.00245,,,,,,4.9980779,,,,
,32516729.205,4.9978423,54183.53125,-7.28256874343904E-5,1.99432328397667E-6,1,0.999253354069792,40.0298881530762,1.99607981964053,21.0100002586842,-0.000815997272675219,-0.000179535806414715,0.25,-2.78700758054853E-6,-7.27572476689724E-5,-3.32557480042753E-6,4.9978423,4.9978423,54181.08984375,54185.97265625,57.6208728091792,20.6256290480749,8.102614,0,0,0,40,4449,4.9926,54183.53125,,,,,,,,,,,,,0,,,,0,,,,,,4.9978423,,,,
,32516824.12,4.9962311,58923.4921875,-8.53092110814501E-5,2.33890791384056E-6,1,0.999253354069792,40.0298881530762,1.99601291427955,21.0100002586842,-0.000958484005987447,-0.000198175973485655,0.25,-2.18008382718281E-6,-8.52761865541766E-5,-2.81457191279187E-6,4.9962311,4.9962311,58918.50390625,58928.48046875,57.3191642007561,20.6263647057147,7.722963,0,0,0,40,4449,4.9965,58923.4921875,,,,,,,,,,,,,0,,,,-0.00245,,,,,,4.9962311,,,,
,32516917.525,4.99695805,63594.19921875,-9.86464067176193E-5,2.24361015334885E-6,1,0.999253354069792,40.0298881530762,1.99594211871328,21.0100002586842,-0.00110528273563382,-0.000248632453086452,0.25,-4.23819291133344E-6,-9.86382386266705E-5,-4.97287313249039E-6,4.9960237,4.9978924,63561.8515625,63626.546875,56.8267382336406,20.6265025755283,8.102614,0,0,0,40,4449,4.9971,63594.19921875,,,,,,,,,,,,,0,,,,0,,,,,,4.99695805,,,,
,32517012.57,4.9977219,68346.98046875,-0.00011414637890673,3.51197204821767E-6,1,0.999253354069792,40.0298881530762,1.99611130080074,21.0100002586842,-0.001278104662868,-0.000296114696829524,0.25,-5.63989992761861E-6,-0.000114179659613151,-6.48923423165657E-6,4.9976759,4.9977679,68314.6015625,68379.359375,57.3621537693137,20.6287969930482,8.482265,0,0,0,40,4449,5.00125,68346.98046875,,,,,,,,,,,,,0,,,,0,,,,,,4.9977219,,,,
,32517107.89,4.996419,73109.53515625,-0.000132058528859023,2.42783472568598E-6,1,0.999253354069792,40.0298881530762,1.99596232705262,21.0100002586842,-0.00148346144496744,-0.00031880454668535,0.25,-4.41801575787325E-6,-0.000132165704214438,-5.39438995177465E-6,4.996419,4.996419,73106.9296875,73112.140625,57.3191642007561,20.6229532952836,8.482265,0,0,0,40,4449,5.00325,73109.53515625,,,,,,,,,,,,,0,,,,-0.0049,,,,,,4.996419,,,,
,32517202.325,4.9972889,77830.54296875,-0.000149281523595509,3.92297992234113E-6,1,0.999253354069792,40.0298881530762,1.99618711610349,21.0100002586842,-0.00168305799226692,-0.000331054631187818,0.25,-2.39543118457417E-6,-0.000149477929310667,-3.48726114755655E-6,4.9962811,4.9982967,77800.765625,77860.3203125,57.4098331089868,20.6230002247802,8.102614,0,0,0,40,4449,5.0081,77830.54296875,,,,,,,,,,,,,0,,,,0,,,,,,4.9972889,,,,
,32517300.885,4.9969296,82756.57421875,-0.000167359183965627,3.93613419290627E-6,1,0.999253354069792,40.0298881530762,1.99622821291022,21.0100002586842,-0.00187801661840031,-0.000424558840005011,0.25,-7.40959266616062E-6,-0.000167607184119859,-8.62881760636854E-6,4.9969296,4.9969296,82754.1328125,82759.015625,57.6451032932753,20.6226568517381,7.722963,0,0,0,40,4449,5.00745,82756.57421875,,,,,,,,,,,,,0,,,,-0.00245,,,,,,4.9969296,,,,
,32517391.805,4.9962263,87302.00390625,-0.000168847347655172,3.51399878131598E-6,1,0.999253354069792,40.0298881530762,1.99616529546405,21.0100002586842,-0.00190472533960574,-0.000375895276149078,0.25,-2.84565512805971E-6,-0.000169185070091617,-4.05302537406107E-6,4.9962263,4.9962263,87272.2265625,87331.78125,57.139389641333,20.6212873254213,8.102614,0,0,0,40,4449,5.01225,87302.00390625,,,,,,,,,,,,,0,,,,0,,,,,,4.9962263,,,,
,32517498.64,4.9972219,88190.3125,-0.000177916495394663,3.11280889097897E-6,1,0.999253354069792,40.0298881530762,1.99621997774592,21.0100002586842,-0.00200648355274717,-0.000400132848967814,0.25,-3.35655977765108E-6,-0.000178280571215228,-4.62640231324766E-6,4.9972219,4.9972219,88187.8125,88192.8125,57.7201396311215,20.6213584226477,8.102614,0,0,0,40,4449,5.0167,88190.3125,,,,,,,,,,,,,0,,,,0.0049,,,,,,4.9972219,,,,
,32517586.525,4.9992309,83799.2265625,-0.000169855172752537,2.8604189461894E-6,1,0.999253354069792,40.0298881530762,1.99625551757523,21.0100002586842,-0.00190062826009019,-0.000461855709022414,0.25,-1.02573900120095E-5,-0.000170100082216083,-1.14971246531549E-5,4.9992309,4.9992309,83794.2109375,83804.2421875,57.1972301517561,20.6205523421024,7.722963,0,0,0,40,4449,5.0162,83799.2265625,,,,,,,,,,,,,0,,,,0,,,,,,4.9992309,,,,
,32517681.855,5.0003757,79032.94921875,-0.000151770591992463,2.6551357435891E-6,1,0.999253354069792,40.0298881530762,1.9961610294831,21.0100002586842,-0.00171009864631609,-0.000343033954958325,0.25,-3.00729325709792E-6,-0.000151980128840151,-4.11545789591994E-6,5.0003757,5.0003757,79030.6484375,79035.25,57.3770047111791,20.62084533984,8.482265,0,0,0,40,4449,5.0127,79032.94921875,,,,,,,,,,,,,0,,,,0.0049,,,,,,5.0003757,,,,
,32517778.98,5.0018821,74177.16796875,-0.000131290447190785,2.76616688236005E-6,1,0.999253354069792,40.0298881530762,1.9962290456933,21.0100002586842,-0.00146707011435797,-0.000361869771971487,0.25,-8.36199018769469E-6,-0.00013137928591363,-9.33579998166383E-6,5.0018821,5.0018821,74142.3359375,74212,57.3488660844868,20.6216808982599,7.722963,0,0,0,40,4449,5.01215,74177.16796875,,,,,,,,,,,,,0,,,,0.00245,,,,,,5.0018821,,,,
,32517874.89,5.0026436,69381.62109375,-0.000120023137253006,2.79372836532829E-6,1,0.999253354069792,40.0298881530762,1.99617671112417,21.0100002586842,-0.00134033229294808,-0.000332133661315744,0.25,-7.76667196506179E-6,-0.00012005525488026,-8.66052320780325E-6,5.0026436,5.0026436,69379.2109375,69384.03125,57.5849178972945,20.6211768224049,8.482265,0,0,0,40,4449,5.00985,69381.62109375,,,,,,,,,,,,,0,,,,0.00245,,,,,,5.0026436,,,,
,32517968.805,5.0059125,64685.984375,-0.000102448075661911,2.2216336150308E-6,1,0.999253354069792,40.0298881530762,1.99619343072373,21.0100002586842,-0.0011490070046703,-0.000253403773109222,0.25,-3.97115329952469E-6,-0.00010245290756495,-4.73395617682408E-6,5.005444,5.006381,64655.85546875,64716.11328125,57.5184794731599,20.6226852442932,8.102614,0,0,0,40,4449,5.0026,64685.984375,,,,,,,,,,,,,0,,,,0,,,,,,5.0059125,,,,
,32518064.665,5.0071807,59897.896484375,-8.74150620025321E-5,2.19240122395497E-6,1,0.999253354069792,40.0298881530762,1.99622940740415,21.0100002586842,-0.000978425695340882,-0.000224802236047318,0.25,-4.15551042392944E-6,-8.73749623692078E-5,-4.80575493097804E-6,5.0071807,5.0071807,59893.4453125,59902.34765625,57.4410982497561,20.6198820118159,7.722963,0,0,0,40,4449,4.99515,59897.896484375,,,,,,,,,,,,,0,,,,0,,,,,,5.0071807,,,,
,32518160.86,5.0016389,55089.794921875,-6.8791779881768E-5,1.9266598610124E-6,1,0.999253354069792,40.0298881530762,1.99610680619777,21.0100002586842,-0.000764197696297968,-0.000206664617763947,0.25,-5.91626089268069E-6,-6.87088562377298E-5,-6.42381882833984E-6,5.0016389,5.0016389,55084.82421875,55094.765625,57.7279559163138,20.6233449340269,8.482265,0,0,0,40,4449,4.9953,55089.794921875,,,,,,,,,,,,,0,,,,0,,,,,,5.0016389,,,,
,32518255.99,5.001606,50332.298828125,-5.63150537856728E-5,1.50455128435842E-6,1,0.999253354069792,40.0298881530762,1.99617541320575,21.0100002586842,-0.0006274806416022,-0.000157124641242258,0.25,-3.78326591646889E-6,-5.62285088121395E-5,-4.19491801996318E-6,5.001606,5.001606,50302.328125,50362.26953125,57.5130080735253,20.6237591125808,8.102614,0,0,0,40,4449,4.99295,50332.298828125,,,,,,,,,,,,,0,,,,0.00245,,,,,,5.001606,,,,
,32518350.415,5.0030394,45614.6953125,-4.35376120325176E-5,1.51483102963057E-6,1,0.999253354069792,40.0298881530762,1.99613222577449,21.0100002586842,-0.000476147665890784,-0.000169824415864296,0.25,-7.22253091449854E-6,-4.34184756870935E-5,-7.52931611871967E-6,5.0030394,5.0030394,45609.6875,45619.703125,57.4113963660253,20.6244870507888,8.102614,0,0,0,40,4449,4.99245,45614.6953125,,,,,,,,,,,,,0,,,,-0.00245,,,,,,5.0030394,,,,
,32518445.46,5.0010343,40864.185546875,-3.06392778443388E-5,1.41973357927328E-6,1,0.999253354069792,40.0298881530762,1.99629900029537,21.0100002586842,-0.000332817824688445,-0.000131316241194056,0.25,-6.13809994737613E-6,-3.05331918855512E-5,-6.34573250299857E-6,5.0010343,5.0010343,40856.6640625,40871.70703125,57.3160376866791,20.6243543910439,8.102614,0,0,0,40,4449,4.9915,40864.185546875,,,,,,,,,,,,,0,,,,0.0049,,,,,,5.0010343,,,,
,32518539.835,5.0015416,36146.349609375,-1.94805039332925E-5,1.33353261159427E-6,1,0.999253354069792,40.0298881530762,1.99619649003685,21.0100002586842,-0.000213835347124214,-7.04392750974981E-5,0.25,-2.75072430571353E-6,-1.94120113204667E-5,-2.8806671673271E-6,5.0013013,5.0017819,36113.828125,36178.87109375,56.9744660237753,20.6253082105889,8.102614,0,0,0,40,4449,4.98885,36146.349609375,,,,,,,,,,,,,0,,,,0.00245,,,,,,5.0015416,,,,
,32518634.125,5.0023756,31433.9814453125,-3.83795685254786E-6,1.06791274756976E-6,1,0.999253354069792,40.0298881530762,1.99621249329908,21.0100002586842,-3.8226904457085E-5,-3.54821825351831E-5,0.25,-2.46235089073698E-6,-3.80953226797536E-6,-2.48112728027495E-6,5.0023756,5.0023756,31431.564453125,31436.3984375,57.667770520333,20.6283836291028,8.482265,0,0,0,40,4449,4.9876,31433.9814453125,,,,,,,,,,,,,0,,,,-0.0049,,,,,,5.0023756,,,,
,32518727.92,5.0007377,26746.380859375,1.10931558986989E-5,9.40205416609375E-7,1,0.999253354069792,40.0298881530762,1.99621692697685,21.0100002586842,0.000128483906623222,2.01390029618565E-6,0.25,-1.81117838934171E-6,1.10661373998254E-5,-1.73161955468063E-6,5.0007377,5.0007377,26743.87890625,26748.8828125,57.5192611016792,20.6273522726188,8.102614,0,0,0,40,4449,4.9844,26746.380859375,,,,,,,,,,,,,0,,,,0.0049,,,,,,5.0007377,,,,
,32518820.29,5.00092195,22130.91796875,2.29003020793357E-5,7.01754296739813E-7,1,0.999253354069792,40.0298881530762,1.99623508106889,21.0100002586842,0.000262019217840321,2.13711818327287E-5,0.25,-2.20213400800903E-6,2.28230662962799E-5,-2.04837063382889E-6,5.000844,5.0009999,22100.86328125,22160.97265625,57.5997688391599,20.624443478274,8.102614,0,0,0,40,4449,4.98515,22130.91796875,,,,,,,,,,,,,0,,,,0.00245,,,,,,5.00092195,,,,
,32518913.525,4.9997213,17469.0458984375,3.51779073719982E-5,6.2852796859991E-7,1,0.999253354069792,40.0298881530762,1.99613940645921,21.0100002586842,0.000399210217674072,4.99952543321336E-5,0.25,-1.8436863529485E-6,3.50330678776557E-5,-1.62342578928985E-6,4.9992304,5.0002122,17438.9609375,17499.130859375,57.044812590506,20.6245392674532,7.722963,0,0,0,40,4449,4.98385,17469.0458984375,,,,,,,,,,,,,0,,,,0,,,,,,4.9997213,,,,
,32519010.805,5.0046368,12608.9838867188,4.81452850329514E-5,4.6003919200264E-7,1,0.999253354069792,40.0298881530762,1.99608919468634,21.0100002586842,0.000544050724171178,7.98939118926372E-5,0.25,-1.48329226537792E-6,4.79191588072076E-5,-1.20232812996898E-6,5.0046368,5.0046368,12606.53515625,12611.4326171875,57.6794949481215,20.6257708952108,8.102614,0,0,0,40,4449,4.9793,12608.9838867188,,,,,,,,,,,,,0,,,,-0.00245,,,,,,5.0046368,,,,
,32519104.015,4.9995766,7948.51416015625,5.95765618133908E-5,4.00172671222034E-7,1,0.999253354069792,40.0298881530762,1.99628350391098,21.0100002586842,0.00067104504068389,0.000109944387644759,0.25,-8.26156081435291E-7,5.92681383579234E-5,-5.03540697608452E-7,4.9995766,4.9995766,7943.388671875,7953.6396484375,57.5520894994869,20.6237942898922,8.102614,0,0,0,40,4449,4.9827,7948.51416015625,,,,,,,,,,,,,0,,,,0.0049,,,,,,4.9995766,,,,
,32519196.39,4.9996622,3333.1298828125,7.12523439856246E-5,3.66468960423093E-7,1,0.999253354069792,40.0298881530762,1.99620414980109,21.0100002586842,0.000800626212750729,0.000140645755389393,0.25,-1.45198109502512E-7,7.0856100481785E-5,2.12704964776329E-7,4.9993978,4.9999266,3300.57983398438,3365.67993164063,57.1206305568714,20.6264556830688,8.102614,0,0,0,40,4449,4.9833,3333.1298828125,,,,,,,,,,,,,0,,,,-0.00245,,,,,,4.9996622,,,,
,32519265.045,5.0004101,-0.296863585710526,7.74496824214801E-5,3.96349816383863E-7,1,0.999253354069792,40.0298881530762,1.99635584332077,21.0100002586842,0.000869632929951236,0.000155927046092166,0.25,1.29782171192273E-7,7.70044953715822E-5,5.02341248760203E-7,5.0004101,5.0004101,-0.304475486278534,-0.289251685142517,57.7209212596407,20.6257071227435,8.482265,0,0,0,40,4417,4.98225,-0.296863585710526,,,,,,,,,,,,,0,,,,-0.0049,,,,,,5.0004101,,,,