File: data/doubleLayers/dl_1-25/ppms/data/DD205_3_HYST_FC40000OE_10KREPEAT.DAT
[Header]
; VSM Data File (default extension .dat)
; Copyright (c) 2003-2013, Quantum Design, Inc. All rights reserved.
TITLE,
FILEOPENTIME,33070216.92,01/19/2019,2:12 am
BYAPP,VSM,2.0,2.0
INFO,PPMS VSM Option Release 1.4.10 Build 1,APPNAME
INFO,Quantum Design Linear Motor Servo Controller,MOTOR_MODULE_NAME
INFO,3101-100 M1,MOTOR_HW_VERSION
INFO,MMC1014,MOTOR_SERIAL_NUMBER
INFO,SRV No X-over 01.03.11,MOTOR_SOFTWARE_VERSION
INFO,Quantum Design VSM Detection Module,VSM_MODULE_NAME
INFO,3101-150 F0,VSM_HW_VERSION
INFO,VSM707,VSM_SERIAL_NUMBER
INFO,VSM No X-over 01.02.05 May 20 2008 13:51:47,VSM_SOFTWARE_VERSION
INFO,704,PREAMP_SERIAL_NUMBER
INFO,822,COIL_SERIAL_NUMBER
INFO,0,MOMENT_UNITS
INFO,DD205_4,SAMPLE_MATERIAL
INFO,Double Layer Blue 1.25,SAMPLE_COMMENT
INFO,26.73,SAMPLE_MASS
INFO,,SAMPLE_VOLUME
INFO,,SAMPLE_MOLECULAR_WEIGHT
INFO,,SAMPLE_SIZE
INFO,,SAMPLE_SHAPE
DATATYPE,COMMENT,1
DATATYPE,TIME,2
STARTUPAXIS,X,2
STARTUPAXIS,Y1,5
[Data]
Comment,Time Stamp (sec),Temperature (K),Magnetic Field (Oe),Moment (emu),M. Std. Err. (emu),Transport Action,Averaging Time (sec),Frequency (Hz),Peak Amplitude (mm),Center Position (mm),Coil Signal' (mV),Coil Signal" (mV),Range (mV),M. Quad. Signal (emu),M. Raw' (emu),M. Raw" (emu),Min. Temperature (K),Max. Temperature (K),Min. Field (Oe),Max. Field (Oe),Mass (grams),Motor Lag (deg),Pressure (Torr),VSM Status (code),Motor Status (code),Measure Status (code),Measure Count,PPMS Status (code),System Temp. (K),System Field (Oe),Sample Position (deg),Bridge 1 Resistance (ohms),Bridge 1 Excitation (에),Bridge 2 Resistance (ohms),Bridge 2 Excitation (에),Bridge 3 Resistance (ohms),Bridge 3 Excitation (에),Bridge 4 Resistance (ohms),Bridge 4 Excitation (에),Signal 1 Vin (V),Signal 2 Vin (V),Digital Inputs (code),Drive 1 Iout (mA),Drive 1 Ipower (W),Drive 2 Iout (mA),Drive 2 Ipower (W),Pressure (),Map 20 (),Map 21 (),Map 22 (),Map 23 (),Map 24 (),Map 25 (),Map 26 (),Map 27 (),Map 28 (),Map 29 ()
,33070232.17,10.0015802,39999.47265625,,,2,,,,20.2999995064735,,,,,,,10.0015802,10.0015802,39999.47265625,39999.47265625,,,12.658426,,,,-99999999,4369,9.9949,39999.47265625,,,,,,,,,,,,,,,,,,,,,,,10.0015802,,,,
,33070584.085,9.9993439,4646.24243164063,7.11443024458138E-5,3.64035958222677E-7,1,0.999253354069792,40.0298881530762,1.98266097571809,20.2799998223782,0.000793309710304054,0.000145081728912753,0.25,3.45661111471457E-7,7.07518298196315E-5,7.06778530582556E-7,9.9993439,9.9993439,4641.19091796875,4651.2939453125,56.3601060076598,20.5392272542972,13.038077,0,0,0,40,4449,9.992,4646.24243164063,,,,,,,,,,,,,0,,,,0,,,,,,9.9993439,,,,
,33070683.175,9.9991894,9595.228515625,6.01265337420495E-5,3.8178331545602E-7,1,0.999253354069792,40.0298881530762,1.98257815185125,20.2799998223782,0.000669648625166599,0.00012840099385402,0.25,7.85227488558394E-7,5.98139715210826E-5,1.10973757268309E-6,9.9991894,9.9991894,9582.75,9607.70703125,56.1686070204483,20.5409297488267,12.658426,0,0,0,40,4449,9.99105,9595.228515625,,,,,,,,,,,,,0,,,,0,,,,,,9.9991894,,,,
,33070780.375,10.0007906,14455.1533203125,4.66113634237086E-5,4.25655001167229E-7,1,0.999253354069792,40.0298881530762,1.98219784756927,20.2900003641844,0.000519211172347721,9.97491641611499E-5,0.25,6.08988582348603E-7,4.63880735456724E-5,8.77335149835284E-7,10.0007906,10.0007906,14450.267578125,14460.0390625,56.3483815798714,20.5472787665796,12.658426,0,0,0,40,4449,9.992,14455.1533203125,,,,,,,,,,,,,0,,,,0,,,,,,10.0007906,,,,
,33070877.025,10.0008202,19285.0283203125,3.3988778004644E-5,5.13978545564492E-7,1,0.999253354069792,40.0298881530762,1.98277928157136,20.2799998223782,0.000377619618619778,7.98469624094168E-5,0.25,1.06448881346178E-6,3.38372677380955E-5,1.26899442062139E-6,10.0008202,10.0008202,19277.466796875,19292.58984375,55.9755447761982,20.5445219863369,12.658426,0,0,0,40,4449,9.9917,19285.0283203125,,,,,,,,,,,,,0,,,,-0.0049,,,,,,10.0008202,,,,
,33070977.5,10.0006618,24307.6513671875,2.2642441357854E-5,6.68468375994575E-7,1,0.999253354069792,40.0298881530762,1.98272206520752,20.2799998223782,0.000254001881716837,4.02490828077423E-5,0.25,-4.58037713844042E-7,2.25601005767994E-5,-3.10002719654826E-7,10.0006618,10.0006618,24295.3671875,24319.935546875,56.3194613246598,20.5415529677396,12.658426,0,0,0,40,4449,9.9929,24307.6513671875,,,,,,,,,,,,,0,,,,0.00245,,,,,,10.0006618,,,,
,33071073.76,10.0000696,29118.083984375,6.13410849113092E-6,5.07883997842888E-7,1,0.999253354069792,40.0298881530762,1.98289850302487,20.2799998223782,6.95932361757389E-5,6.78588046306179E-6,0.25,-4.94471401251596E-7,6.11736776236387E-6,-4.51624874244724E-7,10.0000696,10.0000696,29108.076171875,29128.091796875,56.2295740449483,20.5420336072053,12.278775,0,0,0,40,4449,9.99275,29118.083984375,,,,,,,,,,,,,0,,,,-0.00245,,,,,,10.0000696,,,,
,33071174.005,9.9989395,34128.017578125,-5.37481012365023E-6,5.0561903752503E-7,1,0.999253354069792,40.0298881530762,1.98279128699084,20.2799998223782,-6.04315657945986E-5,-9.16191816075336E-6,0.25,1.47297279486486E-7,-5.36109271013438E-6,1.09548353021934E-7,9.9987516,9.9991274,34120.77734375,34135.2578125,56.7180918694675,20.543641520458,12.278775,0,0,0,40,4449,9.99145,34128.017578125,,,,,,,,,,,,,0,,,,-0.0049,,,,,,9.9989395,,,,
,33071272.42,9.9992237,39048.0625,-2.14678683371174E-5,7.44963501217139E-7,1,0.999253354069792,40.0298881530762,1.98262950419308,20.2799998223782,-0.000240471220440744,-4.22311383665158E-5,0.25,8.99642449541325E-8,-2.14208428634739E-5,-6.32353051621521E-8,9.9992237,9.9992237,39043.25390625,39052.87109375,56.3976241765829,20.5443009639412,12.658426,0,0,0,40,4449,9.99265,39048.0625,,,,,,,,,,,,,0,,,,-0.00245,,,,,,9.9992237,,,,
,33071371.03,9.9978428,43975.509765625,-3.7464319089848E-5,7.6129519599511E-7,1,0.999253354069792,40.0298881530762,1.98271738339646,20.2799998223782,-0.00041935415260085,-7.67245756378285E-5,0.25,-1.04471391850915E-7,-3.73998334757203E-5,-3.76405999406464E-7,9.9978428,9.9978428,43970.453125,43980.56640625,56.9830639374868,20.5477491680609,12.658426,0,0,0,40,4449,9.9954,43975.509765625,,,,,,,,,,,,,0,,,,0,,,,,,9.9978428,,,,
,33071466.89,9.9972248,48768.435546875,-5.15485315275491E-5,8.3139045114371E-7,1,0.999253354069792,40.0298881530762,1.98257987224704,20.2799998223782,-0.000577062588638916,-0.000106673508869661,0.25,-2.33692588033873E-7,-5.14847053603653E-5,-6.12651300419748E-7,9.9972248,9.9972248,48758.3671875,48778.50390625,56.6821369575829,20.5437918079901,12.278775,0,0,0,40,4449,9.997,48768.435546875,,,,,,,,,,,,,0,,,,0.00245,,,,,,9.9972248,,,,
,33071565.75,9.9967117,53708.375,-6.45676914453418E-5,7.97900835624574E-7,1,0.999253354069792,40.0298881530762,1.98265212168755,20.2799998223782,-0.000723972770447339,-0.000129351560949745,0.25,9.7597425468912E-8,-6.45227429050093E-5,-3.8133678045626E-7,9.9967117,9.9967117,53700.984375,53715.765625,56.3452550657944,20.5491367230089,12.658426,0,0,0,40,4449,9.9994,53708.375,,,,,,,,,,,,,0,,,,0,,,,,,9.9967117,,,,
,33071666.61,9.9962106,58749.185546875,-8.11096186262499E-5,7.31858482530669E-7,1,0.999253354069792,40.0298881530762,1.98253208111632,20.2799998223782,-0.000907112376894376,-0.000177714933222539,0.25,-1.22690494211223E-6,-8.10828003901712E-5,-1.83027154583622E-6,9.9961739,9.9962473,58739.4609375,58758.91015625,56.7376325824483,20.5478616998225,12.278775,0,0,0,40,4449,10.00365,58749.185546875,,,,,,,,,,,,,0,,,,0,,,,,,9.9962106,,,,
,33071767.26,9.9957609,63781.921875,-9.82412716936751E-5,9.41923743419738E-7,1,0.999253354069792,40.0298881530762,1.98254415811683,20.2799998223782,-0.00110101256374784,-0.000205457712093811,0.25,-6.04968447717589E-7,-9.82612506684512E-5,-1.33570919971619E-6,9.9957609,9.9957609,63776.953125,63786.890625,56.5172133400252,20.5510698150504,12.278775,0,0,0,40,4449,10.0092,63781.921875,,,,,,,,,,,,,0,,,,0,,,,,,9.9957609,,,,
,33071868.335,9.9953012,68832.35546875,-0.000112921049385219,9.2503304559573E-7,1,0.999253354069792,40.0298881530762,1.98248689296008,20.2799998223782,-0.00126697521107648,-0.00023118405597596,0.25,-2.474664019509E-7,-0.000112997672524176,-1.08370718559307E-6,9.9953012,9.9953012,68829.9140625,68834.796875,56.2991389831598,20.5503160203316,11.899124,0,0,0,40,4449,10.01155,68832.35546875,,,,,,,,,,,,,0,,,,0,,,,,,9.9953012,,,,
,33071966.875,9.9954338,73759.66015625,-0.000129678356999327,8.80970929451109E-7,1,0.999253354069792,40.0298881530762,1.98265441573151,20.2799998223782,-0.00145341710255185,-0.00027833553321091,0.25,-1.42371509732493E-6,-0.000129811324778046,-2.37839814755253E-6,9.9954338,9.9954338,73751.984375,73767.3359375,56.2428617297752,20.5494117157832,12.658426,0,0,0,40,4449,10.01695,73759.66015625,,,,,,,,,,,,,0,,,,0,,,,,,9.9954338,,,,
,33072066.035,9.9951496,78715.515625,-0.000144397398311377,8.58533052198993E-7,1,0.999253354069792,40.0298881530762,1.98271244712704,20.2799998223782,-0.00161866245228329,-0.000312276596153001,0.25,-1.79382157276142E-6,-0.000144600354596501,-2.84722430651798E-6,9.9951496,9.9951496,78705.5234375,78725.5078125,57.2761746321984,20.5438938284352,12.278775,0,0,0,40,4449,10.0204,78715.515625,,,,,,,,,,,,,0,,,,0,,,,,,9.9951496,,,,
,33072166.115,9.9942236,83718.8046875,-0.000159994480481393,1.08486171535615E-6,1,0.999253354069792,40.0298881530762,1.9827188476406,20.2799998223782,-0.00179562042766716,-0.000338079055214577,0.25,-1.2854538224316E-6,-0.000160283703969643,-2.43773453950998E-6,9.994154,9.9942932,83713.7265625,83723.8828125,56.5859966497175,20.5454376836773,12.278775,0,0,0,40,4449,10.027,83718.8046875,,,,,,,,,,,,,0,,,,0.00245,,,,,,9.9942236,,,,
,33072261.24,9.9949913,88472.265625,-0.000176583525041131,1.23931993821829E-6,1,0.999253354069792,40.0298881530762,1.98279010594968,20.2799998223782,-0.0019821200093025,-0.0003754849708609,0.25,-1.6333843746425E-6,-0.000176959462836746,-2.88896474679885E-6,9.9949913,9.9949913,88467.1328125,88477.3984375,56.8751992018329,20.5384748137938,12.278775,0,0,0,40,4449,10.0298,88472.265625,,,,,,,,,,,,,0,,,,-0.0049,,,,,,9.9949913,,,,
,33072370.235,9.9983206,87050.75390625,-0.000170290810269648,8.94761309861454E-7,1,0.999253354069792,40.0298881530762,1.98292303353654,20.2799998223782,-0.00191403240223592,-0.000347594449849111,0.25,-2.80440929299306E-7,-0.000170646139111281,-1.49352479261403E-6,9.9983206,9.9983206,87048.1953125,87053.3125,56.4742237714675,20.5417753621091,12.278775,0,0,0,40,4449,10.0353,87050.75390625,,,,,,,,,,,,,0,,,,0,,,,,,9.9983206,,,,
,33072463.265,10.0009623,82399.94140625,-0.000154763466081123,8.07907030505435E-7,1,0.999253354069792,40.0298881530762,1.98288754379222,20.2799998223782,-0.00173834650757642,-0.000318923575931475,0.25,-5.1898357162985E-7,-0.000155033711098602,-1.63605272671374E-6,10.0009623,10.0009623,82394.890625,82404.9921875,56.3780834636021,20.5404325969036,12.658426,0,0,0,40,4449,10.031,82399.94140625,,,,,,,,,,,,,0,,,,0,,,,,,10.0009623,,,,
,33072554.275,10.0027561,77853.47265625,-0.000139959093163308,9.30305131594154E-7,1,0.999253354069792,40.0298881530762,1.98302014156234,20.2799998223782,-0.0015674051078937,-0.000311775765916512,0.25,-2.54414920833467E-6,-0.000140140661501453,-3.56816034558769E-6,10.0027561,10.0027561,77846.03125,77860.9140625,56.4578095725637,20.5426863264931,11.899124,0,0,0,40,4449,10.0279,77853.47265625,,,,,,,,,,,,,0,,,,0,,,,,,10.0027561,,,,
,33072645.195,10.0029287,73307.03125,-0.000122642623256565,8.23326212879667E-7,1,0.999253354069792,40.0298881530762,1.98299966182394,20.2799998223782,-0.00137551559676612,-0.00025896132828335,0.25,-9.62239781040216E-7,-0.000122766680703451,-1.86537775883727E-6,10.0029287,10.0029287,73296.859375,73317.203125,56.6414922745829,20.5386725933553,12.278775,0,0,0,40,4449,10.02585,73307.03125,,,,,,,,,,,,,0,,,,0,,,,,,10.0029287,,,,
,33072738.51,10.0033178,68643.88671875,-0.000108893970205693,8.30880653016239E-7,1,0.999253354069792,40.0298881530762,1.98286021362659,20.2799998223782,-0.0012175734741381,-0.000247491434757389,0.25,-2.42221250214571E-6,-0.000108949924518908,-3.23028918883176E-6,10.0033178,10.0033178,68638.8984375,68648.875,56.5523866233906,20.5409069029792,12.278775,0,0,0,40,4449,10.0224,68643.88671875,,,,,,,,,,,,,0,,,,0,,,,,,10.0033178,,,,
,33072826.89,10.0034819,64223.244140625,-9.66287259883272E-5,7.16164809887444E-7,1,0.999253354069792,40.0298881530762,1.98283096595776,20.2799998223782,-0.00108356564092643,-0.00019972224809151,0.25,-3.81457932190453E-7,-9.66538193099012E-5,-1.09998927579496E-6,10.0034819,10.0034819,64215.6796875,64230.80859375,56.4382688595829,20.5405264926339,11.899124,0,0,0,40,4449,10.0195,64223.244140625,,,,,,,,,,,,,0,,,,0.0049,,,,,,10.0034819,,,,
,33072920.315,10.0033579,59554.9140625,-8.16076493111469E-5,8.71363676356949E-7,1,0.999253354069792,40.0298881530762,1.98285721054482,20.2799998223782,-0.000913293455793562,-0.000176636574662095,0.25,-1.0372625953563E-6,-8.15883576740206E-5,-1.64454622918328E-6,10.0033579,10.0033579,59547.43359375,59562.39453125,56.5250296252175,20.5412741608749,12.278775,0,0,0,40,4449,10.01715,59554.9140625,,,,,,,,,,,,,0,,,,-0.0049,,,,,,10.0033579,,,,
,33073017.26,10.0031109,54708.94921875,-6.59229114132393E-5,6.37048301559445E-7,1,0.999253354069792,40.0298881530762,1.98297446145191,20.2799998223782,-0.000740617434162944,-0.000125102410822813,0.25,7.2421468479563E-7,-6.58881629443586E-5,2.3434408842128E-7,10.0031109,10.0031109,54698.73046875,54719.16796875,56.7876568076791,20.540302664385,11.899124,0,0,0,40,4449,10.01345,54708.94921875,,,,,,,,,,,,,0,,,,0,,,,,,10.0031109,,,,
,33073119.395,10.0034904,49604.0390625,-5.01937335453309E-5,8.05061084494098E-7,1,0.999253354069792,40.0298881530762,1.98288283806159,20.2799998223782,-0.000557447663055467,-0.000129304550391261,0.25,-2.49448240732956E-6,-5.01191542876051E-5,-2.86159615745102E-6,10.0034904,10.0034904,49596.46484375,49611.61328125,56.4124751184483,20.5442613423728,11.899124,0,0,0,40,4449,10.01085,49604.0390625,,,,,,,,,,,,,0,,,,0.00245,,,,,,10.0034904,,,,
,33073216.66,10.0037136,44741.8203125,-3.56310094184954E-5,5.71778623258225E-7,1,0.999253354069792,40.0298881530762,1.98302157946268,20.2799998223782,-0.000398678132832934,-7.43496274655785E-5,0.25,-2.2043543486645E-7,-3.55716482504143E-5,-4.79497862233417E-7,10.0037136,10.0037136,44734.2734375,44749.3671875,56.506270540756,20.5434744530693,12.278775,0,0,0,40,4449,10.0078,44741.8203125,,,,,,,,,,,,,0,,,,-0.0049,,,,,,10.0037136,,,,
,33073318.11,10.0027399,39670.755859375,-2.02377191810303E-5,5.14382241081537E-7,1,0.999253354069792,40.0298881530762,1.9830785838261,20.2799998223782,-0.000224462455105118,-5.25663617528028E-5,0.25,-1.05304432878614E-6,-2.01865932571232E-5,-1.19540392584418E-6,10.0027399,10.0027399,39660.91015625,39680.6015625,56.2983573546406,20.5400269525136,11.519473,0,0,0,40,4449,10.005,39670.755859375,,,,,,,,,,,,,0,,,,0,,,,,,10.0027399,,,,
,33073417.08,10.001771,34726.23828125,-5.82527932655806E-6,6.21162684857979E-7,1,0.999253354069792,40.0298881530762,1.98308220416457,20.2799998223782,-6.47788557418152E-5,-1.39975393721855E-5,0.25,-2.03535109331207E-7,-5.80825362440335E-6,-2.43604852873098E-7,10.001771,10.001771,34723.83984375,34728.63671875,56.7313795542945,20.5423969037951,11.899124,0,0,0,40,4449,10.00305,34726.23828125,,,,,,,,,,,,,0,,,,0.00245,,,,,,10.001771,,,,
,33073517.65,10.0019341,29698.80859375,8.28573130041068E-6,4.04587215006519E-7,1,0.999253354069792,40.0298881530762,1.98300418902506,20.2799998223782,9.41919662834552E-5,8.18034355886227E-6,0.25,-7.56380386776174E-7,8.26423859757385E-6,-6.98024475729666E-7,10.0019341,10.0019341,29686.23828125,29711.37890625,56.6805737005445,20.5424378894797,11.899124,0,0,0,40,4449,10.00285,29698.80859375,,,,,,,,,,,,,0,,,,0.00245,,,,,,10.0019341,,,,
,33073617.885,10.0011311,24688.529296875,2.21631004971807E-5,4.88999922699924E-7,1,0.999253354069792,40.0298881530762,1.9831545742114,20.2799998223782,0.000247588017556504,4.55325179184035E-5,0.25,9.90881245397986E-8,2.20798214405299E-5,2.42418030472954E-7,10.0011311,10.0011311,24678.53515625,24698.5234375,56.3890262628713,20.5453851924545,11.899124,0,0,0,40,4449,10.003,24688.529296875,,,,,,,,,,,,,0,,,,-0.0049,,,,,,10.0011311,,,,
,33073719.26,9.999917,19621.4384765625,3.53778432117658E-5,4.2687432380916E-7,1,0.999253354069792,40.0298881530762,1.98297163630292,20.2799998223782,0.000394898155494332,7.30806382786323E-5,0.25,2.0871876207311E-7,3.5226816628671E-5,4.26203437795538E-7,9.999917,9.999917,19611.5390625,19631.337890625,56.5312826533714,20.543549926593,11.899124,0,0,0,40,4449,10.0022,19621.4384765625,,,,,,,,,,,,,0,,,,-0.00245,,,,,,9.999917,,,,
,33073816.095,10.0002804,14781.5009765625,4.85047117067475E-5,4.38745716603094E-7,1,0.999253354069792,40.0298881530762,1.982900486559,20.2799998223782,0.00054225831005213,9.39970195121768E-5,0.25,-2.48577055110235E-7,4.82789106008043E-5,3.59483806389116E-8,10.0002804,10.0002804,14778.8759765625,14784.1259765625,56.7024592990829,20.5454846148499,12.278775,0,0,0,40,4449,10.00325,14781.5009765625,,,,,,,,,,,,,0,,,,-0.0049,,,,,,10.0002804,,,,
,33073916.36,9.9984322,9769.349609375,6.14059823780246E-5,3.39849397046552E-7,1,0.999253354069792,40.0298881530762,1.98304477589722,20.2799998223782,0.000686253987078073,0.000118864946568646,0.25,-3.00384686753306E-7,6.10936532680717E-5,3.74690761465367E-8,9.9984322,9.9984322,9761.8896484375,9776.8095703125,57.0924919301791,20.5433980065301,11.899124,0,0,0,40,4449,10.0038,9769.349609375,,,,,,,,,,,,,0,,,,0.00245,,,,,,9.9984322,,,,
,33074013.14,9.9989386,4933.86889648438,7.17595509978286E-5,2.91178337916727E-7,1,0.999253354069792,40.0298881530762,1.98313114440406,20.2799998223782,0.000800946807582218,0.000143112657610573,0.25,5.51782591124954E-8,7.13665628859887E-5,4.22493894853288E-7,9.9989386,9.9989386,4928.86279296875,4938.875,56.6899532427752,20.5448940827107,11.899124,0,0,0,40,4449,10.00595,4933.86889648438,,,,,,,,,,,,,0,,,,0,,,,,,9.9989386,,,,
,33074111.595,10.0020885,9.71210639178753,7.69969649229876E-5,3.03565822822506E-7,1,0.999253354069792,40.0298881530762,1.98310293562998,20.2799998223782,0.000859203413281212,0.000153250397838824,0.25,5.89658945902345E-8,7.65543767375656E-5,4.297608713055E-7,10.0020885,10.0020885,-0.102863937616348,19.5270767211914,56.7782772654483,20.5455066547903,11.899124,0,0,0,40,4449,10.0019,9.71210639178753,,,,,,,,,,,,,0,,,,0.00245,,,,,,10.0020885,,,,
,33074210.435,10.0002441,-4926.90209960937,8.05730053699067E-5,2.83975411219922E-7,1,0.999253354069792,40.0298881530762,1.98310640906098,20.2799998223782,0.000899138349796649,0.000161637711673461,0.25,1.47103280138232E-7,8.01312766003088E-5,5.59026393582212E-7,10.0002441,10.0002441,-4934.3525390625,-4919.45166015625,56.516431711506,20.5481393950718,11.519473,0,0,0,40,4449,10.00525,-4926.90209960937,,,,,,,,,,,,,0,,,,-0.00245,,,,,,10.0002441,,,,
,33074300.345,10.0008621,-9420.7119140625,8.62545554838598E-5,3.44849969034697E-7,1,0.999253354069792,40.0298881530762,1.98321705301707,20.2799998223782,0.000961706280079737,0.000179880691152498,0.25,7.3611087163645E-7,8.58071104820685E-5,1.20251433236214E-6,10.0008621,10.0008621,-9428.353515625,-9413.0703125,56.9564885678329,20.5465311075241,12.278775,0,0,0,40,4449,10.0043,-9420.7119140625,,,,,,,,,,,,,0,,,,0.00245,,,,,,10.0008621,,,,
,33074392.34,10.0016966,-14018.7397460938,8.80498251231991E-5,4.26818748107924E-7,1,0.999253354069792,40.0298881530762,1.9828259122643,20.2799998223782,0.000982960457709484,0.000177832071964962,0.25,1.99902884960973E-7,8.7630142289778E-5,7.08540718864399E-7,10.0016966,10.0016966,-14026.23828125,-14011.2412109375,56.6876083572175,20.556418150552,12.278775,0,0,0,40,4449,10.00395,-14018.7397460938,,,,,,,,,,,,,0,,,,-0.00245,,,,,,10.0016966,,,,
,33074483.17,10.000762,-18558.5185546875,8.01001902952534E-5,4.83321950775097E-7,1,0.999253354069792,40.0298881530762,1.98292242506977,20.2799998223782,0.000893747494631518,0.000166796476744589,0.25,5.9925297821411E-7,7.97493225032214E-5,1.08545480563184E-6,10.000762,10.000762,-18568.765625,-18548.271484375,56.7798405224868,20.5523374583054,11.899124,0,0,0,40,4449,10.0014,-18558.5185546875,,,,,,,,,,,,,0,,,,-0.0049,,,,,,10.000762,,,,
,33074574.055,10.0012217,-23099.1435546875,6.03906737306451E-5,4.2853125895437E-7,1,0.999253354069792,40.0298881530762,1.98292694762823,20.2799998223782,0.000673724442431136,0.000128096256850407,0.25,6.38967094604432E-7,6.01517115765863E-5,1.02240255274045E-6,10.0012217,10.0012217,-23101.875,-23096.412109375,56.9385111118906,20.5515380241329,12.278775,0,0,0,40,4449,10.0014,-23099.1435546875,,,,,,,,,,,,,0,,,,0.0049,,,,,,10.0012217,,,,
,33074668.065,10.0004673,-27798.61328125,4.0580903781391E-5,4.92801767859881E-7,1,0.999253354069792,40.0298881530762,1.98296703635162,20.2799998223782,0.000453719773381392,8.18391962768914E-5,0.25,3.59084086992959E-8,4.04423453752221E-5,3.0581477694958E-7,10.0004673,10.0004673,-27804.140625,-27793.0859375,56.9056827140829,20.5530773034776,12.278775,0,0,0,40,4449,10.0013,-27798.61328125,,,,,,,,,,,,,0,,,,-0.0049,,,,,,10.0004673,,,,
,33074761.265,10.0000458,-32456.6044921875,3.02515430093982E-5,5.49373048063087E-7,1,0.999253354069792,40.0298881530762,1.98298576018639,20.2799998223782,0.00033664314945147,7.08186407383903E-5,0.25,8.94277527112118E-7,3.0157069678086E-5,1.09972123459442E-6,10.0000458,10.0000458,-32466.61328125,-32446.595703125,56.6352392464291,20.5504779098226,12.278775,0,0,0,40,4449,10.0008,-32456.6044921875,,,,,,,,,,,,,0,,,,0.00245,,,,,,10.0000458,,,,
,33074851.055,9.9989576,-36943.447265625,2.91370142100778E-5,6.35373496100316E-7,1,0.999253354069792,40.0298881530762,1.98230199138994,20.2900003641844,0.000325560711649531,6.11388780846041E-5,0.25,2.2340197820686E-7,2.90642361776337E-5,4.28439696868417E-7,9.9989576,9.9989576,-36978.83203125,-36908.0625,56.861911517006,20.5718273936292,11.519473,0,0,0,40,4449,10.00165,-36943.447265625,,,,,,,,,,,,,0,,,,0,,,,,,9.9989576,,,,
,33074943.02,9.9987698,-41540.84375,3.53538168707335E-5,6.525915585159E-7,1,0.999253354069792,40.0298881530762,1.98144441048741,20.2900003641844,0.000394367001845542,7.8001273119731E-5,0.25,6.06720091703703E-7,3.52802682062119E-5,8.60119635181392E-7,9.9987698,9.9987698,-41546.03515625,-41535.65234375,56.4124751184483,20.588721823849,11.899124,0,0,0,40,4449,10.0023,-41540.84375,,,,,,,,,,,,,0,,,,0,,,,,,9.9987698,,,,
,33075033.545,9.9971638,-46066.671875,4.54933676109855E-5,7.50917545695972E-7,1,0.999253354069792,40.0298881530762,1.9807476038387,20.2799998223782,0.000508456433530289,9.53094405784639E-5,0.25,3.22344741158682E-7,4.54235386720567E-5,6.54363370769024E-7,9.9971638,9.9971638,-46074.40234375,-46058.94140625,56.6266413327175,20.6010844370014,12.278775,0,0,0,40,4449,10.0051,-46066.671875,,,,,,,,,,,,,0,,,,-0.00245,,,,,,9.9971638,,,,
,33075123.025,9.9971857,-50538.814453125,5.65613561492839E-5,7.69997299990054E-7,1,0.999253354069792,40.0298881530762,1.98033850499148,20.2900003641844,0.000632838049273163,0.000115670928867316,0.25,1.41531328074282E-7,5.65023524779388E-5,5.58946917476675E-7,9.9971857,9.9971857,-50541.3671875,-50536.26171875,56.5664559367368,20.5981404539514,11.899124,0,0,0,40,4449,10.0084,-50538.814453125,,,,,,,,,,,,,0,,,,0.00245,,,,,,9.9971857,,,,
,33075214.26,9.9960308,-55096.26171875,6.82320781297967E-5,8.13512750916072E-7,1,0.999253354069792,40.0298881530762,1.98066678381371,20.2799998223782,0.000759229972724051,0.000165446835175436,0.25,2.47348875698224E-6,6.81747707218008E-5,2.97883162706676E-6,9.9960308,9.9960308,-55103.7421875,-55088.78125,57.085457273506,20.6005393856472,11.899124,0,0,0,40,4449,10.011,-55096.26171875,,,,,,,,,,,,,0,,,,-0.00245,,,,,,9.9960308,,,,
,33075305.39,9.996151,-59651.2734375,8.35129712156911E-5,7.26572023648805E-7,1,0.999253354069792,40.0298881530762,1.9811778593393,20.2799998223782,0.000934435598663166,0.000177470799715051,0.25,7.80862406434692E-7,8.34960776319118E-5,1.40237803083864E-6,9.996151,9.996151,-59661.1953125,-59641.3515625,57.0948368157368,20.5969928082244,12.278775,0,0,0,40,4449,10.01435,-59651.2734375,,,,,,,,,,,,,0,,,,0,,,,,,9.996151,,,,
,33075394.735,9.9960957,-64116.68359375,9.6342679109338E-5,8.22811187230213E-7,1,0.999253354069792,40.0298881530762,1.98138303530188,20.2799998223782,0.00107806177973042,0.000207490648944316,0.25,1.13831725018441E-6,9.63611368507247E-5,1.85497412155135E-6,9.9960957,9.9960957,-64124.2109375,-64109.15625,56.8259566051214,20.5891436471906,11.899124,0,0,0,40,4449,10.0172,-64116.68359375,,,,,,,,,,,,,0,,,,-0.0049,,,,,,9.9960957,,,,
,33075484.655,9.9964275,-68609.171875,0.00010977221139737,6.70097448416974E-7,1,0.999253354069792,40.0298881530762,1.98129233122774,20.2900003641844,0.00122868862113509,0.000236944907263251,0.25,1.34048053292552E-6,0.000109836445506738,2.15435634535151E-6,9.9964275,9.9964275,-68616.78125,-68601.5625,56.9994781363906,20.5877390320525,11.519473,0,0,0,40,4449,10.02025,-68609.171875,,,,,,,,,,,,,0,,,,0,,,,,,9.9964275,,,,
,33075574.225,9.9955044,-73086.21875,0.000121996704524465,8.60298592199914E-7,1,0.999253354069792,40.0298881530762,1.98146023122262,20.2799998223782,0.00136693277789216,0.000259061497877016,0.25,1.10470363517796E-6,0.000122116822840243,2.00356141370846E-6,9.9953661,9.9956427,-73093.46875,-73078.96875,56.9705578811791,20.5929779242058,11.519473,0,0,0,40,4449,10.02395,-73086.21875,,,,,,,,,,,,,0,,,,-0.00245,,,,,,9.9955044,,,,
,33075663.07,9.9954472,-77526.4765625,0.000137299695811347,1.15422283062969E-6,1,0.999253354069792,40.0298881530762,1.98169999648378,20.2900003641844,0.00154320283267771,0.000269016518369628,0.25,-7.67455030123081E-7,0.000137498141915726,2.33160481844042E-7,9.9954472,9.9954472,-77531.5859375,-77521.3671875,56.9064643426022,20.5879580114982,11.519473,0,0,0,40,4449,10.02885,-77526.4765625,,,,,,,,,,,,,0,,,,0,,,,,,9.9954472,,,,
,33075751.08,9.9951124,-81924.203125,0.000151177884240549,9.71336414068053E-7,1,0.999253354069792,40.0298881530762,1.98071956160313,20.2799998223782,0.00169687570878458,0.00030766561906634,0.25,1.90916694348324E-7,0.000151438900893464,1.28286623817487E-6,9.9951124,9.9951124,-81929.09375,-81919.3125,56.9775925378522,20.601160950975,12.278775,0,0,0,40,4449,10.0328,-81924.203125,,,,,,,,,,,,,0,,,,0,,,,,,9.9951124,,,,
,33075842.18,9.994833,-86478.96484375,0.000167487332409387,1.10377049379717E-6,1,0.999253354069792,40.0298881530762,1.98070739550566,20.2799998223782,0.00187817008960252,0.000354103426005191,0.25,1.39659092665704E-6,0.000167822246188102,2.59398387072769E-6,9.994833,9.994833,-86486.328125,-86471.6015625,56.9893169656406,20.6011753540879,11.899124,0,0,0,40,4449,10.03655,-86478.96484375,,,,,,,,,,,,,0,,,,-0.00245,,,,,,9.994833,,,,
,33075957.415,9.9964743,-88862.1328125,0.000173720662795389,8.65803157218978E-7,1,0.999253354069792,40.0298881530762,1.98095416850549,20.2900003641844,0.00194917985070023,0.000364246872427591,0.25,1.17814053390248E-6,0.000174098082261637,2.41099804489475E-6,9.9964743,9.9964743,-88872.1484375,-88852.1171875,56.8032893780637,20.5981443201983,11.899124,0,0,0,40,4449,10.04105,-88862.1328125,,,,,,,,,,,,,0,,,,0.00245,,,,,,9.9964743,,,,
,33076051.32,10.0001125,-84170.4765625,0.00016055940185863,1.15697796001553E-6,1,0.999253354069792,40.0298881530762,1.98101008794911,20.2799998223782,0.00180369307886061,0.00032145398490271,0.25,-2.71320056793892E-7,0.0001608660308453,8.80702478898728E-7,10.0001125,10.0001125,-84180.5546875,-84160.3984375,56.9916618511983,20.5963909686689,11.519473,0,0,0,40,4449,10.0408,-84170.4765625,,,,,,,,,,,,,0,,,,0,,,,,,10.0001125,,,,
,33076153.985,10.0021315,-79038.2421875,0.000144656014961175,1.04122960246485E-6,1,0.999253354069792,40.0298881530762,1.98146342377235,20.2799998223782,0.00162142097178011,0.000308236518754415,0.25,1.4042979442601E-6,0.000144865751438593,2.45826232245E-6,10.0021315,10.0021315,-79043.3046875,-79033.1796875,57.044812590506,20.5895776225141,12.278775,0,0,0,40,4449,10.039,-79038.2421875,,,,,,,,,,,,,0,,,,-0.00245,,,,,,10.0021315,,,,
,33076254.635,10.0028057,-74008.4140625,0.000128324984286501,8.55534864078114E-7,1,0.999253354069792,40.0298881530762,1.98009208209192,20.2799998223782,0.00143559293041238,0.000280140535962469,0.25,1.85902458166023E-6,0.00012845584463621,2.80386158436387E-6,10.0028057,10.0028057,-74016.1640625,-74000.6640625,56.7321611828137,20.6092170541596,11.899124,0,0,0,40,4449,10.0353,-74008.4140625,,,,,,,,,,,,,0,,,,-0.00245,,,,,,10.0028057,,,,
,33076355.22,10.0033102,-68981.7734375,0.000112167253203215,8.47341381950312E-7,1,0.999253354069792,40.0298881530762,1.98088852776361,20.2799998223782,0.00125511353378433,0.000243066551077992,0.25,1.45850859097208E-6,0.000112235824143998,2.28987815950597E-6,10.0033102,10.0033102,-68994.421875,-68969.125,56.9994781363906,20.5988947282391,11.899124,0,0,0,40,4449,10.0321,-68981.7734375,,,,,,,,,,,,,0,,,,-0.00245,,,,,,10.0033102,,,,
,33076454.175,10.0030632,-64036.9765625,9.59997945058699E-5,7.70963549145505E-7,1,0.999253354069792,40.0298881530762,1.98130415698765,20.2799998223782,0.00107158435108231,0.000221123490958008,0.25,2.41669973910554E-6,9.60079582977599E-5,3.13117929374527E-6,10.0030632,10.0030632,-64042.28515625,-64031.66796875,56.7696793517368,20.5928545447991,11.899124,0,0,0,40,4449,10.0289,-64036.9765625,,,,,,,,,,,,,0,,,,0.00245,,,,,,10.0030632,,,,
,33076554.165,10.0039492,-59039.384765625,8.11520747814794E-5,7.90395612187979E-7,1,0.999253354069792,40.0298881530762,1.98140764072922,20.2900003641844,0.000908227808698012,0.000171572700978786,0.25,6.79391090484525E-7,8.11315557024713E-5,1.2832514235767E-6,10.0039492,10.0039492,-59044.31640625,-59034.453125,56.6618146160829,20.5928017867265,12.278775,0,0,0,40,4449,10.0246,-59039.384765625,,,,,,,,,,,,,0,,,,0,,,,,,10.0039492,,,,
,33076654.75,10.00352045,-54014.666015625,6.43229787264005E-5,7.0358384757593E-7,1,0.999253354069792,40.0298881530762,1.98120639680832,20.2900003641844,0.000717646702131656,0.000145984394611724,0.25,1.43885062529898E-6,6.42687523723885E-5,1.91508953454189E-6,10.003396,10.0036449,-54022.1484375,-54007.18359375,56.882233858506,20.5969054662808,11.899124,0,0,0,40,4449,10.02095,-54014.666015625,,,,,,,,,,,,,0,,,,0,,,,,,10.00352045,,,,
,33076756.835,10.0039454,-48910.125,4.94609422788564E-5,7.58001705846875E-7,1,0.999253354069792,40.0298881530762,1.98123497059322,20.2799998223782,0.000549669280635173,0.000122673725307252,0.25,2.04477414403247E-6,4.93870186319246E-5,2.40633168965158E-6,10.0039454,10.0039454,-48920.31640625,-48899.93359375,56.8994296859291,20.5942434407388,11.899124,0,0,0,40,4449,10.0175,-48910.125,,,,,,,,,,,,,0,,,,0,,,,,,10.0039454,,,,
,33076857.96,10.0033951,-43854.70703125,3.51317854240754E-5,6.67554262370482E-7,1,0.999253354069792,40.0298881530762,1.97995461771567,20.2799998223782,0.000388458069619214,9.54994344426041E-5,0.25,2.21255150465015E-6,3.5055517832663E-5,2.4638305242621E-6,10.0033951,10.0033951,-43857.12890625,-43852.28515625,56.7767140084099,20.6077240317324,11.519473,0,0,0,40,4449,10.0145,-43854.70703125,,,,,,,,,,,,,0,,,,-0.0049,,,,,,10.0033951,,,,
,33076959.055,10.0025768,-38805.533203125,1.96396388246683E-5,7.72472789658783E-7,1,0.999253354069792,40.0298881530762,1.98034202436411,20.2900003641844,0.000216871332116305,5.45574417288401E-5,0.25,1.34591322200628E-6,1.95859447883757E-5,1.48270714730481E-6,10.0025768,10.0025768,-38810.89453125,-38800.171875,56.597721077506,20.6014404174883,12.278775,0,0,0,40,4449,10.0112,-38805.533203125,,,,,,,,,,,,,0,,,,0,,,,,,10.0025768,,,,
,33077059.065,10.0022602,-33803.279296875,5.07160816216578E-6,6.63377165688295E-7,1,0.999253354069792,40.0298881530762,1.98048898597676,20.2900003641844,5.53116612823312E-5,1.77903354780508E-5,0.25,6.80288206571984E-7,5.05280653034382E-6,7.13569677501647E-7,10.0022602,10.0022602,-33813.1484375,-33793.41015625,56.5430070811598,20.5980387662357,11.899124,0,0,0,40,4449,10.00845,-33803.279296875,,,,,,,,,,,,,0,,,,0.00245,,,,,,10.0022602,,,,
,33077161.235,10.001955,-28701.3701171875,-8.35926774448139E-6,5.31961371727408E-7,1,0.999253354069792,40.0298881530762,1.9811515356127,20.2900003641844,-9.50204884394636E-5,-7.75568456547328E-6,0.25,8.06443832752793E-7,-8.33696471197596E-6,7.47760463214179E-7,10.001955,10.001955,-28711.31640625,-28691.423828125,56.7149653553906,20.5811039582755,11.899124,0,0,0,40,4449,10.00815,-28701.3701171875,,,,,,,,,,,,,0,,,,0,,,,,,10.001955,,,,
,33077262.79,10.001483,-23623.794921875,-2.20613770824924E-5,3.63729132266581E-7,1,0.999253354069792,40.0298881530762,1.98120076666523,20.2900003641844,-0.000248138532949086,-3.44203868422311E-5,0.25,8.71986852080114E-7,-2.19823382223967E-5,7.26970824742695E-7,10.001483,10.001483,-23628.623046875,-23618.966796875,56.6969878994483,20.5894150193132,11.899124,0,0,0,40,4449,10.00805,-23623.794921875,,,,,,,,,,,,,0,,,,-0.0049,,,,,,10.001483,,,,
,33077365.125,10.0010281,-18509.2783203125,-3.63723354042635E-5,4.07140202259348E-7,1,0.999253354069792,40.0298881530762,1.98154477761656,20.2799998223782,-0.000405715407082735,-7.48568099328067E-5,0.25,-1.97676966541125E-7,-3.62132954070725E-5,-4.18656435441748E-7,10.0010281,10.0010281,-18521.99609375,-18496.560546875,56.6024108486214,20.5811550619871,11.519473,0,0,0,40,4449,10.00805,-18509.2783203125,,,,,,,,,,,,,0,,,,-0.0049,,,,,,10.0010281,,,,
,33077463.82,10.0004272,-13577.0224609375,-4.94826948918896E-5,3.9322116615042E-7,1,0.999253354069792,40.0298881530762,1.9818020435122,20.2799998223782,-0.000551900613378718,-0.000101086453685422,0.25,-2.21476521708641E-7,-4.92442857777728E-5,-5.0522493562273E-7,10.0004272,10.0004272,-13579.3310546875,-13574.7138671875,56.7665528376599,20.578570189955,11.899124,0,0,0,40,4449,10.0073,-13577.0224609375,,,,,,,,,,,,,0,,,,-0.00245,,,,,,10.0004272,,,,
,33077553.76,9.99935915,-9081.583984375,-6.04132430974492E-5,3.52572432493579E-7,1,0.999253354069792,40.0298881530762,1.98192242520978,20.2799998223782,-0.000673867514349067,-0.000121864528290597,0.25,-1.54787503847921E-7,-6.01001981017937E-5,-4.81794052576361E-7,9.9993372,9.9993811,-9086.6201171875,-9076.5478515625,56.2553677860829,20.5775543904187,11.519473,0,0,0,40,4449,10.00795,-9081.583984375,,,,,,,,,,,,,0,,,,0.0049,,,,,,9.99935915,,,,
,33077641.815,9.9991894,-4680.47583007812,-6.98169650892043E-5,3.33932275764667E-7,1,0.999253354069792,40.0298881530762,1.98182408122574,20.2799998223782,-0.000777255417585279,-0.000147610383953943,0.25,-8.1345947717785E-7,-6.9429552034441E-5,-1.16540576562594E-6,9.9991894,9.9991894,-4682.9775390625,-4677.97412109375,56.7720242372945,20.5790709280647,11.899124,0,0,0,40,4449,10.0079,-4680.47583007812,,,,,,,,,,,,,0,,,,-0.0049,,,,,,9.9991894,,,,
,33077730.595,10.0025358,-240.899192810059,-7.50431881833327E-5,3.7062964774619E-7,1,0.999253354069792,40.0298881530762,1.98195245376087,20.2799998223782,-0.000835189029500721,-0.000159157688051233,0.25,-9.42404511378914E-7,-7.46080800109228E-5,-1.29932799637147E-6,10.0025358,10.0025358,-243.341613769531,-238.456771850586,56.5007991411214,20.575542576439,11.899124,0,0,0,40,4449,10.00565,-240.899192810059,,,,,,,,,,,,,0,,,,0,,,,,,10.0025358,,,,
,33077820.18,9.9985809,4232.62036132812,-7.66745826754943E-5,3.70927662332102E-7,1,0.999253354069792,40.0298881530762,1.9820498819301,20.2799998223782,-0.000853026639622976,-0.000165725136032704,0.25,-1.2187309112132E-6,-7.62452342198976E-5,-1.60101203882072E-6,9.9985809,9.9985809,4230.0712890625,4235.16943359375,56.472660514429,20.574818453646,11.899124,0,0,0,40,4449,10.0074,4232.62036132812,,,,,,,,,,,,,0,,,,0,,,,,,9.9985809,,,,
,33077908.665,9.9997616,8656.5947265625,-8.28379556055004E-5,4.5331178419727E-7,1,0.999253354069792,40.0298881530762,1.9821831659835,20.2799998223782,-0.000922372784728798,-0.0001767229250876,0.25,-1.07576425008228E-6,-8.24013034477327E-5,-1.51704883183367E-6,9.9997616,9.9997616,8643.7744140625,8669.4150390625,57.1237570709483,20.5763259342581,11.519473,0,0,0,40,4449,10.0071,8656.5947265625,,,,,,,,,,,,,0,,,,0.00245,,,,,,9.9997616,,,,
,33077996.655,10.0005312,13054.9213867188,-8.5118067259982E-5,4.13049058676291E-7,1,0.999253354069792,40.0298881530762,1.98206675346029,20.2799998223782,-0.000948432936567699,-0.000179506960876685,0.25,-8.86543876868413E-7,-8.4701204858583E-5,-1.36896132335562E-6,10.0005312,10.0005312,13047.548828125,13062.2939453125,57.014329078256,20.5756862450638,11.519473,0,0,0,40,4449,10.0071,13054.9213867188,,,,,,,,,,,,,0,,,,-0.0049,,,,,,10.0005312,,,,
,33078085.985,10.0011015,17520.18359375,-7.76203616200148E-5,3.83481384050173E-7,1,0.999253354069792,40.0298881530762,1.98208906203315,20.2799998223782,-0.000864907409263245,-0.000165674713658693,0.25,-9.5530128488289E-7,-7.72705001371877E-5,-1.41930581676547E-6,10.0011015,10.0011015,17515.28125,17525.0859375,56.8939582862945,20.5743546695798,11.899124,0,0,0,40,4449,10.007,17520.18359375,,,,,,,,,,,,,0,,,,-0.00245,,,,,,10.0011015,,,,
,33078178.05,10.0002456,22122.501953125,-6.08806824363738E-5,3.92861035577587E-7,1,0.999253354069792,40.0298881530762,1.98224060781683,20.2799998223782,-0.000677806426103345,-0.000135185506398458,0.25,-1.19418505636528E-6,-6.06303922078105E-5,-1.57486244573672E-6,10.0001574,10.0003338,22117.62890625,22127.375,56.4515565444098,20.5745230539037,11.519473,0,0,0,40,4449,10.0055,22122.501953125,,,,,,,,,,,,,0,,,,0.00245,,,,,,10.0002456,,,,
,33078268.72,10.0000668,26652.8896484375,-4.07250118528376E-5,4.88818851222053E-7,1,0.999253354069792,40.0298881530762,1.982273913707,20.2799998223782,-0.000452081500602218,-9.90553465102092E-5,0.25,-1.55607711366105E-6,-4.0571109120139E-5,-1.81909889848655E-6,10.0000668,10.0000668,26650.400390625,26655.37890625,56.6821369575829,20.5758620393319,11.899124,0,0,0,40,4449,10.0061,26652.8896484375,,,,,,,,,,,,,0,,,,-0.00245,,,,,,10.0000668,,,,
,33078358.5,9.99973535,31138.775390625,-3.00181570001915E-5,6.65176150535346E-7,1,0.999253354069792,40.0298881530762,1.98228543677701,20.2799998223782,-0.000334655453383079,-6.5961626673918E-5,0.25,-5.06635589822787E-7,-2.99228847271832E-5,-7.09756452367206E-7,9.9997005,9.9997702,31133.654296875,31143.896484375,56.5211214826214,20.5732196430068,12.278775,0,0,0,40,4449,10.0057,31138.775390625,,,,,,,,,,,,,0,,,,0,,,,,,9.99973535,,,,
,33078449.565,9.9992599,35691.73046875,-2.90411429733426E-5,6.17602012466749E-7,1,0.999253354069792,40.0298881530762,1.98243631316353,20.2900003641844,-0.000321329963074887,-7.83802272964156E-5,0.25,-1.78336557032983E-6,-2.89538142911145E-5,-1.98233948888651E-6,9.9992599,9.9992599,35686.66015625,35696.80078125,56.780622151006,20.5740816896029,11.519473,0,0,0,40,4449,10.0073,35691.73046875,,,,,,,,,,,,,0,,,,-0.0049,,,,,,9.9992599,,,,
,33078540.29,9.9993401,40226.71875,-3.34016969408936E-5,5.69982874349557E-7,1,0.999253354069792,40.0298881530762,1.9823805832667,20.2799998223782,-0.000372305306725342,-7.59539810866778E-5,0.25,-7.74274569542963E-7,-3.33261549375185E-5,-1.01192013973715E-6,9.9993401,9.9993401,40219.3828125,40234.0546875,56.4648442292367,20.567318733399,12.278775,0,0,0,40,4449,10.0084,40226.71875,,,,,,,,,,,,,0,,,,0,,,,,,9.9993401,,,,
,33078631.015,9.9975882,44762.77734375,-4.36317083429069E-5,7.4868380539414E-7,1,0.999253354069792,40.0298881530762,1.98202886281465,20.2799998223782,-0.000484951148364626,-0.000107742095202834,0.25,-1.76515916427545E-6,-4.35482266634436E-5,-2.07999274171522E-6,9.9974604,9.997716,44757.78515625,44767.76953125,56.6438371601406,20.571454067516,11.899124,0,0,0,40,4449,10.0096,44762.77734375,,,,,,,,,,,,,0,,,,-0.0049,,,,,,9.9975882,,,,
,33078725.495,9.9971647,49483.033203125,-5.53507054846526E-5,7.70656898007667E-7,1,0.999253354069792,40.0298881530762,1.98220039746674,20.2799998223782,-0.000616749717944001,-0.000130115765639536,0.25,-1.64172226227026E-6,-5.52759585919689E-5,-2.04767774289327E-6,9.9971647,9.9971647,49475.41015625,49490.65625,56.8368994043906,20.5732699852055,11.899124,0,0,0,40,4449,10.0124,49483.033203125,,,,,,,,,,,,,0,,,,0,,,,,,9.9971647,,,,
,33078824.79,9.9964466,54448.1328125,-6.91999616393955E-5,6.54166108372088E-7,1,0.999253354069792,40.0298881530762,1.980547221382,20.2799998223782,-0.000771248248552484,-0.000160328463328346,0.25,-1.8440739033265E-6,-6.91423797397333E-5,-2.35653233039451E-6,9.9964466,9.9964466,54443.0625,54453.203125,56.8150138058522,20.5968456044615,11.139823,0,0,0,40,4449,10.0149,54448.1328125,,,,,,,,,,,,,0,,,,0,,,,,,9.9964466,,,,
,33078921.2,9.9968653,59265.53125,-8.32582657702342E-5,9.16380680595978E-7,1,0.999253354069792,40.0298881530762,1.98137138740958,20.2799998223782,-0.000928165617633122,-0.000196207331159378,0.25,-2.49749816159285E-6,-8.32255967099898E-5,-3.11676709603673E-6,9.9968653,9.9968653,59255.7421875,59275.3203125,56.5531682519098,20.5804326369,11.899124,0,0,0,40,4449,10.01875,59265.53125,,,,,,,,,,,,,0,,,,0,,,,,,9.9968653,,,,
,33079021.43,9.9960976,64276.267578125,-9.9381201070746E-5,7.76437567647162E-7,1,0.999253354069792,40.0298881530762,1.98174164439518,20.2799998223782,-0.0011065279156003,-0.000245936772349983,0.25,-4.01510341707716E-6,-9.93805514902675E-5,-4.75514530382296E-6,9.9960976,9.9960976,64263.84765625,64288.6875,56.8134505488137,20.5770371906184,11.519473,0,0,0,40,4449,10.02405,64276.267578125,,,,,,,,,,,,,0,,,,-0.0049,,,,,,9.9960976,,,,
,33079119.835,9.9963989,69196.67578125,-0.000112802310270818,7.17211376969317E-7,1,0.999253354069792,40.0298881530762,1.98197571990388,20.2799998223782,-0.00125800678898559,-0.00027175557848358,0.25,-3.88903949657595E-6,-0.000112855422028568,-4.7266803922347E-6,9.9963989,9.9963989,69191.8203125,69201.53125,56.7063674416791,20.5778244542491,11.899124,0,0,0,40,4449,10.02575,69196.67578125,,,,,,,,,,,,,0,,,,0,,,,,,9.9963989,,,,
,33079219.645,9.99603655,74181.73046875,-0.000128869496195212,1.33455021787816E-6,1,0.999253354069792,40.0298881530762,1.98195446758007,20.2799998223782,-0.00144062619622629,-0.000294764744067863,0.25,-3.04109998439748E-6,-0.000128994097620442,-3.99101511887907E-6,9.995842,9.9962311,74169.3046875,74194.15625,57.0643533034868,20.5741090652807,11.899124,0,0,0,40,4449,10.0301,74181.73046875,,,,,,,,,,,,,0,,,,-0.00245,,,,,,9.99603655,,,,
,33079316.64,9.9953108,79033.03515625,-0.000146363518468386,9.58372758922592E-7,1,0.999253354069792,40.0298881530762,1.98121052298047,20.2900003641844,-0.00164040824954004,-0.000311565228064196,0.25,-1.3966758042799E-6,-0.000146575850157236,-2.46305641892251E-6,9.9953108,9.9953108,79022.921875,79043.1484375,56.4992358840829,20.5851660273632,12.278775,0,0,0,40,4449,10.0356,79033.03515625,,,,,,,,,,,,,0,,,,-0.00245,,,,,,9.9953108,,,,
,33079413.85,9.9955206,83891.28125,-0.000161613533612398,9.86970165119429E-7,1,0.999253354069792,40.0298881530762,1.98135564490208,20.2799998223782,-0.0018109885397448,-0.000350356025739075,0.25,-2.10705361368957E-6,-0.000161901868915199,-3.27199081904717E-6,9.9955206,9.9955206,83891.28125,83891.28125,57.0010413934291,20.5868782293047,11.519473,0,0,0,40,4449,10.0398,83891.28125,,,,,,,,,,,,,0,,,,0,,,,,,9.9955206,,,,
,33079507.93,9.9950495,88594.375,-0.000173830501810934,1.03231951129181E-6,1,0.999253354069792,40.0298881530762,1.98135702433714,20.2799998223782,-0.00194521000954125,-0.000395377530015999,0.25,-3.92229195682445E-6,-0.000174185601095458,-5.16295292335562E-6,9.9950495,9.9950495,88589.2421875,88599.5078125,57.0096393071407,20.5867785513503,11.899124,0,0,0,40,4449,10.044,88594.375,,,,,,,,,,,,,0,,,,0,,,,,,9.9950495,,,,
,33079619.775,9.9976025,86861.00390625,-0.000172333305506237,1.05994279790551E-6,1,0.999253354069792,40.0298881530762,1.98131418343384,20.2799998223782,-0.00193390454473565,-0.000360149514750975,0.25,-1.05425037522375E-6,-0.000172685169128485,-2.28416696001753E-6,9.9976025,9.9976025,86853.4609375,86868.546875,56.6469636742175,20.5867743741654,11.519473,0,0,0,40,4449,10.0462,86861.00390625,,,,,,,,,,,,,0,,,,0,,,,,,9.9976025,,,,
,33079714.385,10.000782,82132.390625,-0.00015528966995231,1.19581959051647E-6,1,0.999253354069792,40.0298881530762,1.98044556418851,20.2900003641844,-0.00173815154639256,-0.000341953564038408,0.25,-2.50901549646371E-6,-0.000155543455523707,-3.63412270384414E-6,10.000782,10.000782,82125.0390625,82139.7421875,57.0158923352945,20.5945097389098,11.899124,0,0,0,40,4449,10.04415,82132.390625,,,,,,,,,,,,,0,,,,0.0049,,,,,,10.000782,,,,
,33079815.03,10.00240565,77098.5234375,-0.000140057845591947,1.03970674020798E-6,1,0.999253354069792,40.0298881530762,1.98124667380963,20.2799998223782,-0.00157014937011727,-0.000294663076423147,0.25,-1.02556490294922E-6,-0.000140242423442054,-2.0497180545514E-6,10.0021744,10.0026369,77091.1953125,77105.8515625,56.8642564025637,20.5859591609014,11.899124,0,0,0,40,4449,10.04055,77098.5234375,,,,,,,,,,,,,0,,,,0,,,,,,10.00240565,,,,
,33079916.82,10.0032606,72012.76171875,-0.000121795645651397,1.04675076640519E-6,1,0.999253354069792,40.0298881530762,1.98155408436897,20.2799998223782,-0.00136205294999365,-0.000272878634076808,0.25,-2.3714673961701E-6,-0.000121895444695299,-3.27154394302927E-6,10.0032606,10.0032606,72007.71875,72017.8046875,56.7579549239483,20.5807244869969,11.139823,0,0,0,40,4449,10.0377,72012.76171875,,,,,,,,,,,,,0,,,,0,,,,,,10.0032606,,,,
,33080015.53,10.0037956,67077.3515625,-0.00010982693169994,8.57474779819579E-7,1,0.999253354069792,40.0298881530762,1.98146845444604,20.2799998223782,-0.00122822060959531,-0.000242719556032028,0.25,-1.8449872632105E-6,-0.000109872841726887,-2.6607059750773E-6,10.0037956,10.0037956,67070.203125,67084.5,56.6922981283329,20.5831417847709,11.139823,0,0,0,40,4449,10.03425,67077.3515625,,,,,,,,,,,,,0,,,,0,,,,,,10.0037956,,,,
,33080110.01,10.0046043,62353.68359375,-9.33754402692786E-5,9.4283061589516E-7,1,0.999253354069792,40.0298881530762,1.98187287134687,20.2799998223782,-0.0010469757594866,-0.000189808630356361,0.25,-9.43811506540746E-8,-9.33858345767324E-5,-7.89215746921829E-7,10.0046043,10.0046043,62346.19140625,62361.17578125,56.7423223535637,20.5818176633814,11.519473,0,0,0,40,4449,10.03075,62353.68359375,,,,,,,,,,,,,0,,,,0,,,,,,10.0046043,,,,
,33080204.78,10.0045319,57618.11328125,-7.81760841033228E-5,9.48315267139735E-7,1,0.999253354069792,40.0298881530762,1.98184508778238,20.2799998223782,-0.000874430680595245,-0.000168381758985295,0.25,-9.30188198965773E-7,-7.81436711781062E-5,-1.51146021504763E-6,10.0045319,10.0045319,57613.05078125,57623.17578125,56.8728543162753,20.5747364930014,11.519473,0,0,0,40,4449,10.02575,57618.11328125,,,,,,,,,,,,,0,,,,0.00245,,,,,,10.0045319,,,,
,33080295.16,10.0049,53099.875,-6.45299318794005E-5,1.07195622459531E-6,1,0.999253354069792,40.0298881530762,1.98198335460929,20.2799998223782,-0.00072166145803125,-0.000138165384720931,0.25,-7.00524495684893E-7,-6.44751972781657E-5,-1.17822209501616E-6,10.0049,10.0049,53084.78125,53114.96875,56.5891231637945,20.5790593975438,11.899124,0,0,0,40,4449,10.0221,53099.875,,,,,,,,,,,,,0,,,,0,,,,,,10.0049,,,,
,33080385.855,10.0046291,48567.466796875,-5.01457594173055E-5,6.49866835518493E-7,1,0.999253354069792,40.0298881530762,1.98204384109388,20.2799998223782,-0.00056102024242285,-0.000104753956769686,0.25,-3.17861600020448E-7,-5.00819733029182E-5,-6.86231985748593E-7,10.0046291,10.0046291,48562.515625,48572.41796875,56.5219031111406,20.5754710951113,11.519473,0,0,0,40,4449,10.01915,48567.466796875,,,,,,,,,,,,,0,,,,-0.0049,,,,,,10.0046291,,,,
,33080478.38,10.0039606,43941.583984375,-3.59232295379259E-5,7.79870277751267E-7,1,0.999253354069792,40.0298881530762,1.9818308343783,20.2799998223782,-0.000398403322442387,-9.31258721541372E-5,0.25,-1.85012489939555E-6,-3.58485598358968E-5,-2.10786163222967E-6,10.0039606,10.0039606,43934.2890625,43948.87890625,56.4413953736598,20.5795811140187,11.899124,0,0,0,40,4449,10.01405,43941.583984375,,,,,,,,,,,,,0,,,,0,,,,,,10.0039606,,,,
,33080566.205,10.00437495,39553.80078125,-2.16549467586162E-5,6.29848703380599E-7,1,0.999253354069792,40.0298881530762,1.98214886402899,20.2900003641844,-0.000240675948288962,-5.28590444039204E-5,0.25,-8.26390329187618E-7,-2.1602122068142E-5,-9.7927778000251E-7,10.0043697,10.0043802,39541.03515625,39566.56640625,56.4742237714675,20.5789985931316,11.519473,0,0,0,40,4449,10.01225,39553.80078125,,,,,,,,,,,,,0,,,,0.0049,,,,,,10.00437495,,,,
,33080658.11,10.0029469,34959.0625,-8.29506091513783E-6,5.09817515669362E-7,1,0.999253354069792,40.0298881530762,1.98233888601033,20.2799998223782,-9.05646858731255E-5,-2.9092194597168E-5,0.25,-1.10916956700411E-6,-8.26529887905943E-6,-1.16413646620089E-6,10.0029469,10.0029469,34954.046875,34964.078125,56.7868751791599,20.5749233891792,11.519473,0,0,0,40,4449,10.0102,34959.0625,,,,,,,,,,,,,0,,,,0,,,,,,10.0029469,,,,
,33080749.795,10.0017891,30376.083984375,4.17074193518659E-6,4.15632054410891E-7,1,0.999253354069792,40.0298881530762,1.98240889942648,20.2799998223782,4.99419736261075E-5,-1.00217160331988E-5,0.25,-1.64525262659473E-6,4.16880880982309E-6,-1.61180009807211E-6,10.0017891,10.0017891,30370.970703125,30381.197265625,56.5547315089483,20.5723237540136,11.899124,0,0,0,40,4449,10.0077,30376.083984375,,,,,,,,,,,,,0,,,,0,,,,,,10.0017891,,,,
,33080840.495,10.0016422,25842.908203125,1.74606992194704E-5,6.12744571815828E-7,1,0.999253354069792,40.0298881530762,1.98225952417363,20.2900003641844,0.000191552283064087,5.50594681960117E-5,0.25,1.79472570487453E-6,1.73859032992446E-5,1.90259382648262E-6,10.0016422,10.0016422,25832.90625,25852.91015625,56.7220000120637,20.574244208445,11.519473,0,0,0,40,4449,10.00795,25842.908203125,,,,,,,,,,,,,0,,,,-0.00245,,,,,,10.0016422,,,,
,33080932.27,10.0012283,21255.1630859375,2.94008364107013E-5,4.14156621839616E-7,1,0.999253354069792,40.0298881530762,1.98220987305334,20.2799998223782,0.000330831819157214,4.55395786780306E-5,0.25,-1.18855982852144E-6,2.92885502361906E-5,-9.99166910742227E-7,10.0012283,10.0012283,21245.419921875,21264.90625,56.6837002146214,20.5759312395372,11.139823,0,0,0,40,4449,10.0072,21255.1630859375,,,,,,,,,,,,,0,,,,-0.0049,,,,,,10.0012283,,,,
,33081020.615,10.0013866,16840.544921875,4.11308118031916E-5,3.87016324122786E-7,1,0.999253354069792,40.0298881530762,1.98229165953102,20.2799998223782,0.000461376118958801,7.07414062526728E-5,0.25,-1.01878190398782E-6,4.09519573594955E-5,-7.6799415217677E-7,10.0013866,10.0013866,16827.912109375,16853.177734375,56.3647957787752,20.5732183792615,11.519473,0,0,0,40,4449,10.0064,16840.544921875,,,,,,,,,,,,,0,,,,-0.0049,,,,,,10.0013866,,,,
,33081110.68,9.9997711,12340.3359375,5.29013500033266E-5,4.01604532443901E-7,1,0.999253354069792,40.0298881530762,1.98239504604583,20.2799998223782,0.00059276114697459,9.33741313326566E-5,0.25,-1.0765417139629E-6,5.26482563864448E-5,-7.71524938451917E-7,9.9997711,9.9997711,12335.3359375,12345.3359375,56.9760292808137,20.5731493333333,11.519473,0,0,0,40,4449,10.0074,12340.3359375,,,,,,,,,,,,,0,,,,0,,,,,,9.9997711,,,,
,33081199.765,9.9992504,7884.68334960937,6.38701633005745E-5,3.59188951492423E-7,1,0.999253354069792,40.0298881530762,1.98246235207433,20.2799998223782,0.000713687186799838,0.00012245169310582,0.25,-4.04788658211881E-7,6.35363390257021E-5,-6.17466886044439E-8,9.9992504,9.9992504,7881.9697265625,7887.39697265625,56.5953761919483,20.5737826499557,11.519473,0,0,0,40,4449,10.0087,7884.68334960937,,,,,,,,,,,,,0,,,,0,,,,,,9.9992504,,,,
,33081288.29,9.9987288,3461.53930664063,7.2914543135989E-5,3.704188789254E-7,1,0.999253354069792,40.0298881530762,1.98245397071214,20.2900003641844,0.000813057777765472,0.000147810351135872,0.25,2.83623542108677E-7,7.25071321986911E-5,6.48101287591246E-7,9.9987288,9.9987288,3454.06591796875,3469.0126953125,56.7743691228522,20.5721274072034,11.899124,0,0,0,40,4449,10.0069,3461.53930664063,,,,,,,,,,,,,0,,,,0,,,,,,9.9987288,,,,
,33081359.23,10.0030031,-0.28163979947567,7.61673149769544E-5,3.12923366696276E-7,1,0.999253354069792,40.0298881530762,1.98249194843472,20.2799998223782,0.000849372488870243,0.000153371319224831,0.25,2.21185867669501E-7,7.57286993469727E-5,5.87036617045917E-7,10.0030031,10.0030031,-0.289251685142517,-0.274027913808823,56.9142806277945,20.5705415730276,11.139823,0,0,0,40,4417,10.00355,-0.28163979947567,,,,,,,,,,,,,0,,,,0.00245,,,,,,10.0030031,,,,