File: data/doubleLayers/dl_1-25/ppms/data/DD205_3_FCW_100OE.DAT
[Header]
; VSM Data File (default extension .dat)
; Copyright (c) 2003-2013, Quantum Design, Inc. All rights reserved.
TITLE,
FILEOPENTIME,32486767.02,01/12/2019,8:08 am
BYAPP,VSM,2.0,2.0
INFO,PPMS VSM Option Release 1.4.10 Build 1,APPNAME
INFO,Quantum Design Linear Motor Servo Controller,MOTOR_MODULE_NAME
INFO,3101-100 M1,MOTOR_HW_VERSION
INFO,MMC1014,MOTOR_SERIAL_NUMBER
INFO,SRV No X-over 01.03.11,MOTOR_SOFTWARE_VERSION
INFO,Quantum Design VSM Detection Module,VSM_MODULE_NAME
INFO,3101-150 F0,VSM_HW_VERSION
INFO,VSM707,VSM_SERIAL_NUMBER
INFO,VSM No X-over 01.02.05 May 20 2008 13:51:47,VSM_SOFTWARE_VERSION
INFO,704,PREAMP_SERIAL_NUMBER
INFO,822,COIL_SERIAL_NUMBER
INFO,0,MOMENT_UNITS
INFO,DD205_4,SAMPLE_MATERIAL
INFO,Double Layer Blue 1.25,SAMPLE_COMMENT
INFO,26.73,SAMPLE_MASS
INFO,,SAMPLE_VOLUME
INFO,,SAMPLE_MOLECULAR_WEIGHT
INFO,,SAMPLE_SIZE
INFO,,SAMPLE_SHAPE
DATATYPE,COMMENT,1
DATATYPE,TIME,2
STARTUPAXIS,X,2
STARTUPAXIS,Y1,5
[Data]
Comment,Time Stamp (sec),Temperature (K),Magnetic Field (Oe),Moment (emu),M. Std. Err. (emu),Transport Action,Averaging Time (sec),Frequency (Hz),Peak Amplitude (mm),Center Position (mm),Coil Signal' (mV),Coil Signal" (mV),Range (mV),M. Quad. Signal (emu),M. Raw' (emu),M. Raw" (emu),Min. Temperature (K),Max. Temperature (K),Min. Field (Oe),Max. Field (Oe),Mass (grams),Motor Lag (deg),Pressure (Torr),VSM Status (code),Motor Status (code),Measure Status (code),Measure Count,PPMS Status (code),System Temp. (K),System Field (Oe),Sample Position (deg),Bridge 1 Resistance (ohms),Bridge 1 Excitation (에),Bridge 2 Resistance (ohms),Bridge 2 Excitation (에),Bridge 3 Resistance (ohms),Bridge 3 Excitation (에),Bridge 4 Resistance (ohms),Bridge 4 Excitation (에),Signal 1 Vin (V),Signal 2 Vin (V),Digital Inputs (code),Drive 1 Iout (mA),Drive 1 Ipower (W),Drive 2 Iout (mA),Drive 2 Ipower (W),Pressure (),Map 20 (),Map 21 (),Map 22 (),Map 23 (),Map 24 (),Map 25 (),Map 26 (),Map 27 (),Map 28 (),Map 29 ()
,32486921.915,5.0209017,99.7613830566406,1.86256553593995E-5,3.29617544068755E-7,1,0.999253354069792,40.0298881530762,1.9970424295699,20.8199992775917,0.000209311533959659,3.69094272062656E-5,0.25,-2.23730167323518E-8,1.85188977711974E-5,6.75842362690952E-8,5.0209017,5.0209017,99.7613830566406,99.7613830566406,57.3152560581599,20.6135024809651,8.861917,0,0,0,40,4369,4.9523,99.7613830566406,,,,,,,,,,,,,0,,,,-0.00245,,,,,,5.0209017,,,,
,32487049.425,8.0508604,99.7613830566406,1.86052654681423E-5,3.50787630983696E-7,1,0.999253354069792,40.0298881530762,1.99684075543372,20.8199992775917,0.000209089754680002,3.67080715811571E-5,0.25,-3.63521868446591E-8,1.8498654581421E-5,5.35868254679772E-8,8.0508604,8.0508604,99.7613830566406,99.7613830566406,57.4496961634676,20.6171994112588,10.38052,0,0,0,40,4370,8.06405,99.7613830566406,,,,,,,,,,,,,0,,,,0,,,,,,8.0508604,,,,
,32487190.37,11.5464754,99.7613830566406,1.87084040190078E-5,3.84169663848442E-7,1,0.999253354069792,40.0298881530762,1.99653176577296,20.8199992775917,0.000210157855177824,3.72372195127856E-5,0.25,-7.05896005721832E-9,1.86009617702486E-5,8.3208904401469E-8,11.5464754,11.5464754,99.7613830566406,99.7613830566406,57.6161830380638,20.6175784459516,11.139823,0,0,0,40,4370,11.613,99.7613830566406,,,,,,,,,,,,,0,,,,0,,,,,,11.5464754,,,,
,32487330.15,15.001091,99.7613830566406,1.87701269590521E-5,3.25700589330211E-7,1,0.999253354069792,40.0298881530762,1.99660266752447,20.8199992775917,0.000210922040696023,3.69926024426191E-5,0.25,-3.98813717224589E-8,1.86623344187796E-5,5.08723103583418E-8,15.001091,15.001091,99.7613830566406,99.7613830566406,57.268358347006,20.6196638783906,12.278775,0,0,0,40,4370,15.12615,99.7613830566406,,,,,,,,,,,,,0,,,,0,,,,,,15.001091,,,,
,32487472.44,18.5175591,99.7613830566406,1.87680445251125E-5,2.86709743760002E-7,1,0.999253354069792,40.0298881530762,1.99635265796237,20.8199992775917,0.000211112584766324,3.56286494823541E-5,0.25,-1.60629558040265E-7,1.86607135323695E-5,-6.90968150665605E-8,18.5175591,18.5175591,99.7613830566406,99.7613830566406,56.9564885678329,20.6215302741748,13.038077,0,0,0,40,4370,18.6904,99.7613830566406,,,,,,,,,,,,,0,,,,-0.00245,,,,,,18.5175591,,,,
,32487612.155,22.005825,99.7613830566406,1.86584916598693E-5,3.64181553525643E-7,1,0.999253354069792,40.0298881530762,1.99644178653846,20.8199992775917,0.000209827662611636,3.58466142934455E-5,0.25,-1.23765918711623E-7,1.85527909801829E-5,-3.13282824765222E-8,22.005825,22.005825,99.7613830566406,99.7613830566406,56.8290831191983,20.6186815712353,13.417728,0,0,0,40,4370,22.2149,99.7613830566406,,,,,,,,,,,,,0,,,,0,,,,,,22.005825,,,,
touchdown = 16.160000115633 mm,32487763.405,25.755291,99.7613830566406,1.88877303136133E-5,3.67716630007601E-7,1,0.999253354069792,40.0298881530762,2.00934987852699,20.9400001913309,0.000213663961019409,3.70251450691529E-5,0.25,-8.44219294530108E-8,1.87839000134635E-5,1.2950325944845E-8,25.755291,25.755291,99.7613830566406,99.7613830566406,57.434063593083,20.6105327175589,13.797379,0,0,0,40,4370,26.0318,99.7613830566406,,,,,,,,,,,,,0,,,,-0.0049,,,,,,25.755291,,,,
,32487894.83,29.0165977,99.7613830566406,1.87322388936919E-5,2.74950289124466E-7,1,0.999253354069792,40.0298881530762,1.996297710848,20.9400001913309,0.000211107668536345,3.39275687362401E-5,0.25,-3.18254437212606E-7,1.86355661707924E-5,-2.15136545982836E-7,29.0165977,29.0165977,99.7613830566406,99.7613830566406,56.8361177758714,20.6173001408879,14.556682,0,0,0,40,4370,29.34975,99.7613830566406,,,,,,,,,,,,,0,,,,0.0049,,,,,,29.0165977,,,,
,32488037.375,32.54146385,99.7613830566406,1.85714870637593E-5,3.56967205910462E-7,1,0.999253354069792,40.0298881530762,1.99657581927068,20.9400001913309,0.00020938105276807,3.38539677733577E-5,0.25,-3.0521726957926E-7,1.848371341129E-5,-1.95838473904655E-7,32.5096626,32.5732651,99.7613830566406,99.7613830566406,57.7943943404484,20.6128940998009,14.556682,0,0,0,40,4370,32.9275,99.7613830566406,,,,,,,,,,,,,0,,,,-0.00245,,,,,,32.54146385,,,,
touchdown = 16.1499995738268 mm,32488182.405,36.13157845,99.7613830566406,1.86788771966874E-5,3.67708514823799E-7,1,0.999253354069792,40.0298881530762,1.99679820911344,20.9299996495247,0.000211022587826021,3.25397411872556E-5,0.25,-4.52084623915317E-7,1.86032348524173E-5,-3.33000259278295E-7,36.1026764,36.1604805,99.7613830566406,99.7613830566406,56.7657712091406,20.6072396632782,14.556682,0,0,0,40,4370,36.59875,99.7613830566406,,,,,,,,,,,,,0,,,,0.00245,,,,,,36.13157845,,,,
,32488320.245,39.5119667,99.7613830566406,1.86634008058129E-5,2.99473598068377E-7,1,0.999253354069792,40.0298881530762,1.99663929850567,20.9299996495247,0.000210496509441565,3.53177942022948E-5,0.25,-2.12665646980819E-7,1.860064165061E-5,-8.66525869621199E-8,39.5119667,39.5119667,99.7613830566406,99.7613830566406,57.6943458899869,20.6092248157198,15.695635,0,0,0,40,4370,40.0694,99.7613830566406,,,,,,,,,,,,,0,,,,-0.0049,,,,,,39.5119667,,,,
,32488462.21,43.0316734,99.7613830566406,1.88047665146445E-5,3.8389880370377E-7,1,0.999253354069792,40.0298881530762,1.99660196093665,20.9299996495247,0.000211867639654629,3.7977614643643E-5,0.25,-1.21181692929037E-8,1.87581479946383E-5,1.21450905993951E-7,43.0316734,43.0316734,99.7613830566406,99.7613830566406,56.8572217458906,20.615510285294,16.075285,0,0,0,40,4370,43.6651,99.7613830566406,,,,,,,,,,,,,0,,,,0,,,,,,43.0316734,,,,
touchdown = 16.1300003528595 mm,32488605.2,46.5055428,99.7613830566406,1.88849334554293E-5,3.24492941368151E-7,1,0.999253354069792,40.0298881530762,1.9966216743419,20.9100004285574,0.000213560972116913,3.50998357251035E-5,0.25,-2.90183687609841E-7,1.88607429118057E-5,-1.50789372597845E-7,46.5055428,46.5055428,99.7613830566406,99.7613830566406,56.8697278021983,20.6112716430532,16.075285,0,0,0,40,4370,47.29435,99.7613830566406,,,,,,,,,,,,,0,,,,-0.00245,,,,,,46.5055428,,,,
,32488747.225,50.0314178,99.7613830566406,1.86763586429549E-5,3.29658596913325E-7,1,0.999253354069792,40.0298881530762,1.99667179895532,20.9100004285574,0.000210820510126259,3.82292475321089E-5,0.25,1.96018809640305E-8,1.86713261729559E-5,1.58575421418973E-7,50.0314178,50.0314178,99.7613830566406,99.7613830566406,56.9916618511983,20.6141241157048,16.454937,0,0,0,40,4370,50.9002,99.7613830566406,,,,,,,,,,,,,0,,,,0,,,,,,50.0314178,,,,
,32488890.555,53.5174789,99.7613830566406,1.84841880654814E-5,3.27785344296153E-7,1,0.999253354069792,40.0298881530762,1.99677739693514,20.9100004285574,0.000209746936111509,3.31483896176044E-5,0.25,-3.97172592342432E-7,1.85028955892416E-5,-2.61832165151496E-7,53.5174789,53.5174789,99.7613830566406,99.7613830566406,56.9760292808137,20.6143000015387,17.214239,0,0,0,40,4374,54.5497,99.7613830566406,,,,,,,,,,,,,0,,,,0,,,,,,53.5174789,,,,
touchdown = 16.1199998110533 mm,32489028.21,56.9164238,99.7613830566406,1.85956976673133E-5,3.19557713010611E-7,1,0.999253354069792,40.0298881530762,1.99678034173352,20.8999998867512,0.000210514667878897,3.72786934471171E-5,0.25,-5.0418383041094E-8,1.86300069226186E-5,8.14726557450408E-8,56.9164238,56.9164238,99.7613830566406,99.7613830566406,57.4074882234292,20.6083058563933,17.214239,0,0,0,40,4374,58.0296,99.7613830566406,,,,,,,,,,,,,0,,,,0,,,,,,56.9164238,,,,
,32489154.79,60.0222054,99.7613830566406,1.86199393661959E-5,3.37076053942027E-7,1,0.999253354069792,40.0298881530762,1.99672305683429,20.8999998867512,0.000210729523669041,3.8570306643636E-5,0.25,6.27462498665714E-8,1.86681097326272E-5,1.89208571439019E-7,60.0222054,60.0222054,99.7613830566406,99.7613830566406,57.3668435404292,20.6122241045068,17.593889,0,0,0,40,4374,61.23645,99.7613830566406,,,,,,,,,,,,,0,,,,-0.00245,,,,,,60.0222054,,,,
,32489297.025,63.541172,99.7613830566406,1.85542059954991E-5,2.73513751553107E-7,1,0.999253354069792,40.0298881530762,1.99671013993909,20.8999998867512,0.000210996352036741,3.36753917851888E-5,0.25,-3.52100164282978E-7,1.86185955346841E-5,-2.35100344327757E-7,63.541172,63.541172,99.7613830566406,99.7613830566406,56.8564401173714,20.6154846430965,17.214239,0,0,0,40,4374,64.8351,99.7613830566406,,,,,,,,,,,,,0,,,,0.0049,,,,,,63.541172,,,,
,32489436.25,66.9769516,99.7613830566406,,,2,,,,20.8800000482798,,,,,,,66.9769516,66.9769516,99.7613830566406,99.7613830566406,,,17.593889,,,,-99999999,4374,68.3602,99.7613830566406,,,,,,,,,,,,,,,,,,,,,,,66.9769516,,,,
,32489559.82,70.0370102,99.7613830566406,1.85459941327016E-5,3.39329448231003E-7,1,0.999253354069792,40.0298881530762,1.99686917056427,20.8700001239777,0.000210655148344926,3.63370924566685E-5,0.25,-1.04105819609396E-7,1.86273252852364E-5,-1.46735962547463E-9,70.0370102,70.0370102,99.7613830566406,99.7613830566406,57.5005020172176,20.6129550060693,17.973541,0,0,0,40,4374,71.49975,99.7613830566406,,,,,,,,,,,,,0,,,,-0.0049,,,,,,70.0370102,,,,
,32489701.485,73.5356522,99.7613830566406,1.92890634631664E-5,2.66063783281725E-7,1,0.999253354069792,40.0298881530762,1.99664989062663,20.8700001239777,0.000219132596463147,3.79205201877677E-5,0.25,-8.99017093939141E-8,1.93807753358315E-5,8.87373801303879E-9,73.5356522,73.5356522,99.7613830566406,99.7613830566406,57.3762230826599,20.6152121781361,18.353191,0,0,0,40,4374,75.0811,99.7613830566406,,,,,,,,,,,,,0,,,,0,,,,,,73.5356522,,,,
,32489842.33,77.0284958,99.7613830566406,1.87171508639253E-5,3.78735007095117E-7,1,0.999253354069792,40.0298881530762,1.99706103231065,20.8700001239777,0.000212516277149677,3.80564176541411E-5,0.25,2.93477659565165E-8,1.88108932331971E-5,1.18579087041205E-7,77.0284958,77.0284958,99.7613830566406,99.7613830566406,57.0948368157368,20.6099181045785,17.973541,0,0,0,40,4374,78.63155,99.7613830566406,,,,,,,,,,,,,0,,,,0,,,,,,77.0284958,,,,
,32489966.565,80.0200119,99.7613830566406,1.86479452118523E-5,3.39604895018845E-7,1,0.999253354069792,40.0298881530762,1.99687676430545,20.8500009030104,0.000212345259931245,3.45776951632849E-5,0.25,-2.59122223960587E-7,1.87463135759213E-5,-1.77591091122171E-7,80.0200119,80.0200119,99.7613830566406,99.7613830566406,57.0901470446214,20.6095311509093,18.732843,0,0,0,40,4374,81.8056,99.7613830566406,,,,,,,,,,,,,0,,,,0,,,,,,80.0200119,,,,
,32490110.86,83.5970383,99.7613830566406,1.87279827273785E-5,3.3029803080913E-7,1,0.999253354069792,40.0298881530762,1.99685690000241,20.8500009030104,0.000213096046835566,3.58237072785292E-5,0.25,-1.57951370749259E-7,1.88294264535173E-5,-8.17237957065675E-8,83.5970383,83.5970383,99.7613830566406,99.7613830566406,57.210517836583,20.6081321086502,18.732843,0,0,0,40,4374,85.4524,99.7613830566406,,,,,,,,,,,,,0,,,,0,,,,,,83.5970383,,,,
,32490246.79,87.0331497,99.7613830566406,1.86882020448994E-5,2.98895785354919E-7,1,0.999253354069792,40.0298881530762,1.99718416542843,20.8500009030104,0.00021287459205974,3.47669875011234E-5,0.25,-2.39572471707834E-7,1.87918110710164E-5,-1.69156049394239E-7,87.0331497,87.0331497,99.7613830566406,99.7613830566406,57.6701154058907,20.6085074327316,19.112494,0,0,0,40,4374,88.86485,99.7613830566406,,,,,,,,,,,,,0,,,,0.00245,,,,,,87.0331497,,,,
,32490387.76,90.5131607,99.7613830566406,1.83647739085099E-5,3.33213938373673E-7,1,0.999253354069792,40.0298881530762,1.99718616190587,20.8100005984306,0.000209022081481507,3.52178766555148E-5,0.25,-1.38331528755944E-7,1.84677110084666E-5,-7.3362163290614E-8,90.5131607,90.5131607,99.7613830566406,99.7613830566406,56.9924434797176,20.6121378284152,19.112494,0,0,0,40,4374,92.40345,99.7613830566406,,,,,,,,,,,,,0,,,,0,,,,,,90.5131607,,,,
,32490531.055,94.0656586,99.7613830566406,1.86477348570876E-5,3.29509121864176E-7,1,0.999253354069792,40.0298881530762,1.99712410354615,20.8100005984306,0.000211861551707203,3.79530558543129E-5,0.25,5.67100786808008E-8,1.87525806442443E-5,1.19402213897509E-7,94.0656586,94.0656586,99.7613830566406,99.7613830566406,57.1558038402368,20.6096870414307,18.732843,0,0,0,40,4374,95.9873,99.7613830566406,,,,,,,,,,,,,0,,,,-0.00245,,,,,,94.0656586,,,,
,32490669.6,97.5287399,99.7613830566406,1.86680623267404E-5,3.65405443819199E-7,1,0.999253354069792,40.0298881530762,1.99680037862595,20.8100005984306,0.000212954623586854,3.29346684983959E-5,0.25,-3.84151376850694E-7,1.87749765275676E-5,-3.27718523086941E-7,97.5287399,97.5287399,99.7613830566406,99.7613830566406,57.3285437429868,20.6139642404014,18.732843,0,0,0,40,4374,99.47405,99.7613830566406,,,,,,,,,,,,,0,,,,-0.00245,,,,,,97.5287399,,,,
,32490810.81,101.0297623,99.7613830566406,1.85093798090633E-5,3.70298816992641E-7,1,0.999253354069792,40.0298881530762,1.99656623634475,20.7700002938509,0.000211062536604545,3.29921994908918E-5,0.25,-3.4743450051299E-7,1.86154346440804E-5,-2.94771300197079E-7,101.0297623,101.0297623,99.7613830566406,99.7613830566406,57.1042163579676,20.6131638379656,19.112494,0,0,0,40,4374,103.01395,99.7613830566406,,,,,,,,,,,,,0,,,,-0.00245,,,,,,101.0297623,,,,
,32490951.265,104.5404129,99.7613830566406,1.81695125257403E-5,3.50939190116322E-7,1,0.999253354069792,40.0298881530762,1.99652664783558,20.7700002938509,0.000206790106106971,3.46167773290245E-5,0.25,-1.41683800873118E-7,1.82729342633091E-5,-9.1928597741387E-8,104.5404129,104.5404129,99.7613830566406,99.7613830566406,57.3551191126407,20.615371186473,18.732843,0,0,0,40,4374,106.5529,99.7613830566406,,,,,,,,,,,,,0,,,,0,,,,,,104.5404129,,,,
,32491092.485,108.0669556,99.7613830566406,1.89364361543346E-5,2.96943468818721E-7,1,0.999253354069792,40.0298881530762,1.99666051323101,20.7700002938509,0.000216096895669966,3.2835769995585E-5,0.25,-4.30159706780222E-7,1.90446181512377E-5,-3.82803841413234E-7,108.0669556,108.0669556,99.7613830566406,99.7613830566406,57.7990841115638,20.6137781193357,19.492144,0,0,0,40,4374,110.1088,99.7613830566406,,,,,,,,,,,,,0,,,,-0.00245,,,,,,108.0669556,,,,
,32491232.915,111.5162354,99.7613830566406,1.84197202434366E-5,3.29286394949547E-7,1,0.999253354069792,40.0298881530762,1.99670564388012,20.7299999892712,0.000209363762412944,3.67058710668515E-5,0.25,3.43065825516419E-9,1.8523347405582E-5,4.93404568647282E-8,111.5162354,111.5162354,99.7613830566406,99.7613830566406,57.1534589546791,20.610555467542,19.492144,0,0,0,40,4374,113.63815,99.7613830566406,,,,,,,,,,,,,0,,,,-0.00245,,,,,,111.5162354,,,,
,32491375.05,115.0351868,99.7613830566406,1.83651955626839E-5,3.67123267099976E-7,1,0.999253354069792,40.0298881530762,1.99673031698703,20.7299999892712,0.000208909048156636,3.5622876778884E-5,0.25,-7.990902018452E-8,1.84680302545876E-5,-3.69235387657298E-8,115.0351868,115.0351868,99.7613830566406,99.7613830566406,57.3238539718714,20.611339902479,19.492144,0,0,0,40,4374,117.20725,99.7613830566406,,,,,,,,,,,,,0,,,,-0.00245,,,,,,115.0351868,,,,
,32491516.195,118.5370255,99.7613830566406,1.84640442927841E-5,3.26724075368503E-7,1,0.999253354069792,40.0298881530762,1.99668681240227,20.7299999892712,0.000209627887422735,3.80518800546746E-5,0.25,1.18811036747767E-7,1.85661447356389E-5,1.61017608808118E-7,118.5370255,118.5370255,99.7613830566406,99.7613830566406,57.555997642083,20.6096239202501,19.492144,0,0,0,40,4374,120.76705,99.7613830566406,,,,,,,,,,,,,0,,,,0,,,,,,118.5370255,,,,
,32491654.465,122.0109558,99.7613830566406,1.85022380849933E-5,3.48024352606623E-7,1,0.999253354069792,40.0298881530762,1.99655813512094,20.6899996846914,0.000210395131525226,3.60819297841121E-5,0.25,-5.89479172525594E-8,1.86039822463141E-5,-1.9527735023265E-8,122.0109558,122.0109558,99.7613830566406,99.7613830566406,57.5669404413522,20.6091541055207,20.251448,0,0,0,40,4374,124.2389,99.7613830566406,,,,,,,,,,,,,0,,,,-0.00245,,,,,,122.0109558,,,,
,32491797.165,125.5204697,99.7613830566406,1.86147624752898E-5,3.0515028274979E-7,1,0.999253354069792,40.0298881530762,1.99661595370255,20.6899996846914,0.000211774628877924,3.56912507111619E-5,0.25,-1.11106961786E-7,1.87161488788386E-5,-7.3524000838351E-8,125.5204697,125.5204697,99.7613830566406,99.7613830566406,56.9072459711214,20.6064908133457,20.251448,0,0,0,40,4374,127.8288,99.7613830566406,,,,,,,,,,,,,0,,,,-0.00245,,,,,,125.5204697,,,,
,32491936.98,129.0246124,99.7613830566406,1.8410854840374E-5,3.20601736759009E-7,1,0.999253354069792,40.0298881530762,1.99661423694948,20.6899996846914,0.000209633725932875,3.41955301874626E-5,0.25,-2.05319184347486E-7,1.85101357697214E-5,-1.70246362045518E-7,129.0246124,129.0246124,99.7613830566406,99.7613830566406,57.1972301517561,20.6132889863071,20.251448,0,0,0,40,4374,131.33385,99.7613830566406,,,,,,,,,,,,,0,,,,-0.0049,,,,,,129.0246124,,,,
,32492057.77,132.0167084,99.7613830566406,1.85165828762639E-5,3.11587388846885E-7,1,0.999253354069792,40.0298881530762,1.99667837423012,20.6400007009506,0.000210590212040132,3.57748688852055E-5,0.25,-8.34417791057772E-8,1.86151151822781E-5,-4.87873459986548E-8,132.0167084,132.0167084,99.7613830566406,99.7613830566406,57.1307917276214,20.6079790193643,20.251448,0,0,0,40,4374,134.37405,99.7613830566406,,,,,,,,,,,,,0,,,,0.0049,,,,,,132.0167084,,,,
,32492197.865,135.5271606,99.7613830566406,1.82806090637134E-5,3.64180823914841E-7,1,0.999253354069792,40.0298881530762,1.99663935285722,20.6400007009506,0.000208230526499945,3.33497240182752E-5,0.25,-2.54044357082261E-7,1.83768728884319E-5,-2.22084816144399E-7,135.5271606,135.5271606,99.7613830566406,99.7613830566406,57.3168193151984,20.6078683284484,20.631098,0,0,0,40,4374,137.8867,99.7613830566406,,,,,,,,,,,,,0,,,,-0.00245,,,,,,135.5271606,,,,
,32492339.455,139.0426025,99.7613830566406,1.85297519168905E-5,3.67950797243931E-7,1,0.999253354069792,40.0298881530762,1.99651737135927,20.6400007009506,0.000210559554192127,3.65548234683782E-5,0.25,-1.37360610287551E-8,1.86254750695925E-5,1.86488366008487E-8,139.0426025,139.0426025,99.7613830566406,99.7613830566406,57.5145713305638,20.6128561240512,19.871798,0,0,0,40,4374,141.44325,99.7613830566406,,,,,,,,,,,,,0,,,,0,,,,,,139.0426025,,,,
,32492458.745,142.0248108,99.7613830566406,1.88602449835006E-5,2.73705895076888E-7,1,0.999253354069792,40.0298881530762,1.99663780501333,20.6000003963709,0.00021509032558569,3.27471834328938E-5,0.25,-4.05437414559662E-7,1.8957068778029E-5,-3.75497634026175E-7,141.996521,142.0531006,99.7613830566406,99.7613830566406,57.6411951506792,20.6078959948312,20.631098,0,0,0,40,4374,144.4384,99.7613830566406,,,,,,,,,,,,,0,,,,0.00245,,,,,,142.0248108,,,,
,32492599.595,145.513916,99.7613830566406,1.83603964688671E-5,3.37985481748007E-7,1,0.999253354069792,40.0298881530762,1.99692504122889,20.6000003963709,0.000209029453283018,3.40148670926607E-5,0.25,-2.05803642083643E-7,1.84528217486744E-5,-1.7677957918773E-7,145.513916,145.513916,99.7613830566406,99.7613830566406,57.3738781971022,20.6100078426204,19.871798,0,0,0,40,4374,147.9718,99.7613830566406,,,,,,,,,,,,,0,,,,-0.0049,,,,,,145.513916,,,,
,32492740.43,149.0513916,99.7613830566406,1.84884119734269E-5,3.89026586881947E-7,1,0.999253354069792,40.0298881530762,1.99709656758373,20.6000003963709,0.000210744623578903,3.27670893999961E-5,0.25,-3.36886636042966E-7,1.85800849676979E-5,-3.09313907426795E-7,149.0513916,149.0513916,99.7613830566406,99.7613830566406,57.1980117802753,20.6051957507545,20.631098,0,0,0,40,4374,151.5087,99.7613830566406,,,,,,,,,,,,,0,,,,0.00245,,,,,,149.0513916,,,,
,32492880.11,152.51319125,99.7613830566406,1.83793970920631E-5,3.04399061029939E-7,1,0.999253354069792,40.0298881530762,1.99703112657429,20.5499995499849,0.000208885612379269,3.59667753467535E-5,0.25,-3.49878566636125E-8,1.84684588389328E-5,-7.04286319265321E-9,152.4821625,152.54422,99.7613830566406,99.7613830566406,56.6571248449675,20.6048182763712,20.631098,0,0,0,40,4374,155.0099,99.7613830566406,,,,,,,,,,,,,0,,,,-0.00245,,,,,,152.51319125,,,,
,32493021.27,156.0518494,99.7613830566406,1.84832270704788E-5,3.68410547634582E-7,1,0.999253354069792,40.0298881530762,1.9971237384701,20.5499995499849,0.000209904256285403,3.70388083222655E-5,0.25,4.2330529466116E-8,1.8570985815349E-5,6.99076186771171E-8,156.0518494,156.0518494,99.7613830566406,99.7613830566406,57.0846756449868,20.6065304241391,21.01075,0,0,0,40,4374,158.5441,99.7613830566406,,,,,,,,,,,,,0,,,,-0.0049,,,,,,156.0518494,,,,
,32493161.38,159.5483856,99.7613830566406,1.84631677868244E-5,4.02748226894804E-7,1,0.999253354069792,40.0298881530762,1.99713019506023,20.5499995499849,0.000209362020638122,3.86945616415877E-5,0.25,1.92692340958013E-7,1.85489065081731E-5,2.20102733286951E-7,159.5483856,159.5483856,99.7613830566406,99.7613830566406,57.1378263842945,20.6064205839004,21.01075,0,0,0,40,4374,162.0577,99.7613830566406,,,,,,,,,,,,,0,,,,0,,,,,,159.5483856,,,,
,32493300.25,163.0181274,99.7613830566406,1.85528384927982E-5,4.21373897557135E-7,1,0.999253354069792,40.0298881530762,1.99710899441353,20.5000005662441,0.000211625656539036,3.15879730808732E-5,0.25,-4.47427091418403E-7,1.86381483711248E-5,-4.23605139084159E-7,163.0181274,163.0181274,99.7613830566406,99.7613830566406,57.95540981541,20.5998460317266,20.631098,0,0,0,40,4374,165.5342,99.7613830566406,,,,,,,,,,,,,0,,,,0.00245,,,,,,163.0181274,,,,
,32493441.12,166.521347,99.7613830566406,1.8220450424733E-5,3.48788049444979E-7,1,0.999253354069792,40.0298881530762,1.99710537944991,20.5000005662441,0.000207110116869977,3.50625649994848E-5,0.25,-8.26733617256248E-8,1.83019618133478E-5,-5.83696750993441E-8,166.521347,166.521347,99.7613830566406,99.7613830566406,57.1808159528522,20.6052267562004,21.01075,0,0,0,40,4374,169.06365,99.7613830566406,,,,,,,,,,,,,0,,,,0,,,,,,166.521347,,,,
,32493581.5,170.0578461,99.7613830566406,1.85239786411797E-5,3.99519755284831E-7,1,0.999253354069792,40.0298881530762,1.99690689779626,20.5000005662441,0.000210198339990249,3.74850150882962E-5,0.25,7.91348269769446E-8,1.86047750667192E-5,1.03871736780181E-7,170.0578461,170.0578461,99.7613830566406,99.7613830566406,57.6849663477561,20.6056303691355,21.3904,0,0,0,40,4374,172.57565,99.7613830566406,,,,,,,,,,,,,0,,,,-0.00245,,,,,,170.0578461,,,,
,32493721.745,173.5447083,99.7613830566406,1.85767978016013E-5,3.29460595791508E-7,1,0.999253354069792,40.0298881530762,1.99696177248454,20.4499997198582,0.000211521752401563,3.33359261679129E-5,0.25,-2.94556308691454E-7,1.86564398803981E-5,-2.72006109511177E-7,173.5447083,173.5447083,99.7613830566406,99.7613830566406,57.190195495083,20.6022759693835,21.01075,0,0,0,40,4374,176.0823,99.7613830566406,,,,,,,,,,,,,0,,,,-0.00245,,,,,,173.5447083,,,,
,32493860.565,177.0432587,99.7613830566406,1.84313967444386E-5,3.70429452899652E-7,1,0.999253354069792,40.0298881530762,1.99702090507796,20.4499997198582,0.000209344590465479,3.59826251262391E-5,0.25,-3.53501951552953E-8,1.85081932608276E-5,-1.248312032374E-8,177.0432587,177.0432587,99.7613830566406,99.7613830566406,57.2863358029484,20.6018610874863,20.631098,0,0,0,40,4374,179.5526,99.7613830566406,,,,,,,,,,,,,0,,,,0,,,,,,177.0432587,,,,
,32494000.8,180.5359039,99.7613830566406,1.87356492070486E-5,3.71043724181807E-7,1,0.999253354069792,40.0298881530762,1.99673576465545,20.4499997198582,0.000213732568859588,3.09108285951413E-5,0.25,-5.33691953018336E-7,1.88123690491364E-5,-5.13054922952468E-7,180.5359039,180.5359039,99.7613830566406,99.7613830566406,57.413741251583,20.6089860339957,21.3904,0,0,0,40,4374,183.06525,99.7613830566406,,,,,,,,,,,,,0,,,,-0.00245,,,,,,180.5359039,,,,
,32494141.685,184.0158691,99.7613830566406,1.90713679880582E-5,4.06158725737817E-7,1,0.999253354069792,40.0298881530762,1.99661540037829,20.4000007361174,0.000217385458912913,3.22733581519123E-5,0.25,-4.70986349426935E-7,1.91473550666222E-5,-4.5020958258501E-7,184.0158691,184.0158691,99.7613830566406,99.7613830566406,57.4864327038715,20.610151541207,21.3904,0,0,0,40,4374,186.6023,99.7613830566406,,,,,,,,,,,,,0,,,,0,,,,,,184.0158691,,,,
,32494281.32,187.5299683,99.7613830566406,1.85486085882653E-5,3.85657167054867E-7,1,0.999253354069792,40.0298881530762,1.99640099604948,20.4000007361174,0.000211245332957609,3.21700925108462E-5,0.25,-3.88117664356736E-7,1.86204197787898E-5,-3.68113746054759E-7,187.5299683,187.5299683,99.7613830566406,99.7613830566406,57.4973755031407,20.612091015617,21.3904,0,0,0,40,4374,190.0928,99.7613830566406,,,,,,,,,,,,,0,,,,0.0049,,,,,,187.5299683,,,,
,32494422.955,191.0325928,99.7613830566406,1.8964119238581E-5,4.08403079573031E-7,1,0.999253354069792,40.0298881530762,1.99653217716819,20.4000007361174,0.00021458406838102,4.08519744233771E-5,0.25,3.05450616705411E-7,1.9034671809809E-5,3.28052996973477E-7,191.0325928,191.0325928,99.7613830566406,99.7613830566406,57.6138381525061,20.6133249727809,21.3904,0,0,0,40,4374,193.6616,99.7613830566406,,,,,,,,,,,,,0,,,,0.00245,,,,,,191.0325928,,,,
,32494542.725,194.0230255,99.7613830566406,1.89091740850656E-5,3.34780348911084E-7,1,0.999253354069792,40.0298881530762,2.00901007608109,20.3399993479252,0.000216519172344792,3.34814891984473E-5,0.25,-3.51356007735599E-7,1.89784805526193E-5,-3.31652398432511E-7,194.0230255,194.0230255,99.7613830566406,99.7613830566406,57.2191157502945,20.6109864036436,21.3904,0,0,0,40,4374,196.6568,99.7613830566406,,,,,,,,,,,,,0,,,,0,,,,,,194.0230255,,,,
,32494683.42,197.5166931,99.7613830566406,1.83343852706881E-5,3.32816323176262E-7,1,0.999253354069792,40.0298881530762,2.00918625312322,20.3399993479252,0.000209397272011858,3.55404673466231E-5,0.25,-7.05764461969199E-8,1.839925071423E-5,-5.09328906751335E-8,197.5166931,197.5166931,99.7613830566406,99.7613830566406,57.4833061897945,20.6055322319509,21.770052,0,0,0,40,4374,200.1934,99.7613830566406,,,,,,,,,,,,,0,,,,-0.0049,,,,,,197.5166931,,,,
,32494825.385,201.0542755,99.7613830566406,1.86802514351809E-5,3.78900530306488E-7,1,0.999253354069792,40.0298881530762,1.99681461522473,20.3399993479252,0.000212475204673116,3.36604660987705E-5,0.25,-2.7716330179064E-7,1.87444361811737E-5,-2.58286093155872E-7,201.0542755,201.0542755,99.7613830566406,99.7613830566406,57.6255625802946,20.6019795184932,21.770052,0,0,0,40,4374,203.7493,99.7613830566406,,,,,,,,,,,,,0,,,,0.0049,,,,,,201.0542755,,,,
,32494944.75,204.0316162,99.7613830566406,1.93241968943835E-5,3.86404411861995E-7,1,0.999253354069792,40.0298881530762,1.99702146146532,20.2900003641844,0.000219311493852844,3.76351871674329E-5,0.25,-3.82893217960912E-8,1.93884662878049E-5,-1.82783464993245E-8,204.0316162,204.0316162,99.7613830566406,99.7613830566406,57.4958122461022,20.5992206770086,21.3904,0,0,0,40,4374,206.7468,99.7613830566406,,,,,,,,,,,,,0,,,,-0.0049,,,,,,204.0316162,,,,
,32495084.01,207.5349426,99.7613830566406,1.85821640681389E-5,4.64286571308586E-7,1,0.999253354069792,40.0298881530762,1.99701753389948,20.2900003641844,0.000211178217122728,3.43855222853254E-5,0.25,-1.95127538954225E-7,1.86419985385863E-5,-1.76786489164354E-7,207.5349426,207.5349426,99.7613830566406,99.7613830566406,57.5481813568907,20.6020509087643,21.770052,0,0,0,40,4374,210.23265,99.7613830566406,,,,,,,,,,,,,0,,,,-0.00245,,,,,,207.5349426,,,,
,32495223.38,211.0052948,99.7613830566406,1.86984813965105E-5,4.24376506358907E-7,1,0.999253354069792,40.0298881530762,1.99684782603742,20.2900003641844,0.00021206793011424,3.68443222675467E-5,0.25,2.44202563202389E-9,1.87563481124931E-5,2.11522903176029E-8,211.0052948,211.0052948,99.7613830566406,99.7613830566406,57.7482782578138,20.6057195099462,21.3904,0,0,0,40,4374,213.71635,99.7613830566406,,,,,,,,,,,,,0,,,,0,,,,,,211.0052948,,,,
,32495364.98,214.5041962,99.7613830566406,1.89456383154076E-5,3.7597870216052E-7,1,0.999253354069792,40.0298881530762,1.99690794768956,20.2300008386374,0.000215244761753028,3.50671803316032E-5,0.25,-1.96508864140305E-7,1.90022617958728E-5,-1.78524526880258E-7,214.5041962,214.5041962,99.7613830566406,99.7613830566406,57.5919525539676,20.6006366810693,21.770052,0,0,0,40,4374,217.27255,99.7613830566406,,,,,,,,,,,,,0,,,,0,,,,,,214.5041962,,,,
,32495505.215,218.0141907,99.7613830566406,1.83080481249664E-5,4.10089987519889E-7,1,0.999253354069792,40.0298881530762,1.99698719621934,20.2300008386374,0.000207745373161461,3.52616699471152E-5,0.25,-6.80915912092354E-8,1.83604919731094E-5,-5.06902801309998E-8,218.0141907,218.0141907,99.7613830566406,99.7613830566406,57.4246840508522,20.6043037503274,21.770052,0,0,0,40,4374,220.7852,99.7613830566406,,,,,,,,,,,,,0,,,,0.00245,,,,,,218.0141907,,,,
,32495645.99,221.5297089,99.7613830566406,1.93441234835731E-5,3.87638246950852E-7,1,0.999253354069792,40.0298881530762,1.99681755517955,20.2300008386374,0.000219711112367845,3.5792163946783E-5,0.25,-2.00153822348188E-7,1.93973592010818E-5,-1.82465557915376E-7,221.5297089,221.5297089,99.7613830566406,99.7613830566406,57.3066581444484,20.605450431283,21.3904,0,0,0,40,4374,224.3033,99.7613830566406,,,,,,,,,,,,,0,,,,0,,,,,,221.5297089,,,,
,32495785.985,225.0251312,99.7613830566406,1.88214184992089E-5,3.85079009542511E-7,1,0.999253354069792,40.0298881530762,1.99684736836947,20.1799999922514,0.00021313141732688,3.83970477616262E-5,0.25,1.20995413524322E-7,1.88706844274262E-5,1.38725322500873E-7,225.0251312,225.0251312,99.7613830566406,99.7613830566406,57.3605905122753,20.5983356913948,21.770052,0,0,0,40,4374,227.81665,99.7613830566406,,,,,,,,,,,,,0,,,,0,,,,,,225.0251312,,,,
,32495924.815,228.5273438,99.7613830566406,1.87172059976444E-5,3.40131703275588E-7,1,0.999253354069792,40.0298881530762,1.9967930341765,20.1799999922514,0.000212540747250635,3.46042914216425E-5,0.25,-1.94725466609079E-7,1.87642449694894E-5,-1.7821135516223E-7,228.5273438,228.5273438,99.7613830566406,99.7613830566406,57.6451032932753,20.6068350434207,22.149702,0,0,0,40,4374,231.28825,99.7613830566406,,,,,,,,,,,,,0,,,,0,,,,,,228.5273438,,,,
,32496066.295,232.0000916,99.7613830566406,1.86176948723242E-5,3.58060288228084E-7,1,0.999253354069792,40.0298881530762,1.99687076616042,20.1799999922514,0.000210732151892657,3.82288179920541E-5,0.25,1.42889744600355E-7,1.86619569225883E-5,1.59832842785348E-7,232.0000916,232.0000916,99.7613830566406,99.7613830566406,57.5614690417176,20.6029506359136,22.149702,0,0,0,40,4374,234.842,99.7613830566406,,,,,,,,,,,,,0,,,,-0.0049,,,,,,232.0000916,,,,
,32496207.63,235.5446472,99.7613830566406,1.86300722048833E-5,4.3872490788104E-7,1,0.999253354069792,40.0298881530762,1.99699024438323,20.1200004667044,0.000211915269066583,3.21601504326853E-5,0.25,-3.94214736134871E-7,1.86725522245153E-5,-3.78791004802916E-7,235.515625,235.5736694,99.7613830566406,99.7613830566406,57.5505262424484,20.6063828824039,22.149702,0,0,0,40,4374,238.3925,99.7613830566406,,,,,,,,,,,,,0,,,,0,,,,,,235.5446472,,,,
,32496347.35,239.0494537,99.7613830566406,1.87413990584273E-5,3.47415616022658E-7,1,0.999253354069792,40.0298881530762,1.99704552136387,20.1200004667044,0.000212893992760502,3.38899358094112E-5,0.25,-2.60330275518248E-7,1.87817259860226E-5,-2.44760339254328E-7,239.0494537,239.0494537,99.7613830566406,99.7613830566406,57.2652318329291,20.6022624219888,22.149702,0,0,0,40,4374,241.89275,99.7613830566406,,,,,,,,,,,,,0,,,,-0.00245,,,,,,239.0494537,,,,
,32496488.785,242.5301666,99.7613830566406,1.87232686524994E-5,3.87826860503638E-7,1,0.999253354069792,40.0298881530762,1.99699662891463,20.1200004667044,0.000212657699708155,3.3849542762127E-5,0.25,-2.60039009531758E-7,1.87612771828594E-5,-2.44732945867165E-7,242.5301666,242.5301666,99.7613830566406,99.7613830566406,57.6458849217946,20.604333545471,21.770052,0,0,0,40,4374,245.4475,99.7613830566406,,,,,,,,,,,,,0,,,,-0.00245,,,,,,242.5301666,,,,
,32496608.235,245.5397339,99.7613830566406,1.87789384741834E-5,4.18023856406367E-7,1,0.999253354069792,40.0298881530762,1.99677415245119,20.0599990785122,0.000212949532514374,3.56455693629677E-5,0.25,-1.10291002699126E-7,1.88149495558926E-5,-9.48530240577104E-8,245.5397339,245.5397339,99.7613830566406,99.7613830566406,57.3371416566984,20.6014475801944,22.149702,0,0,0,40,4374,248.4287,99.7613830566406,,,,,,,,,,,,,0,,,,0.00245,,,,,,245.5397339,,,,
,32496749.445,249.0323334,99.7613830566406,1.82734122571867E-5,3.61300264828121E-7,1,0.999253354069792,40.0298881530762,1.99686903088173,20.0599990785122,0.000207486523981592,3.30364547769709E-5,0.25,-2.52453337808498E-7,1.83063260655331E-5,-2.37935270329587E-7,249.0323334,249.0323334,99.7613830566406,99.7613830566406,57.5950790680446,20.5964504629333,22.149702,0,0,0,40,4374,251.9795,99.7613830566406,,,,,,,,,,,,,0,,,,0,,,,,,249.0323334,,,,
,32496887.285,252.5115509,99.7613830566406,1.87473891354147E-5,3.55677171377761E-7,1,0.999253354069792,40.0298881530762,1.99674124862843,20.0599990785122,0.000212783929070077,3.41480562290229E-5,0.25,-2.3571429665565E-7,1.87788312135758E-5,-2.20998779573878E-7,252.5115509,252.5115509,99.7613830566406,99.7613830566406,57.6544828355061,20.598420412945,22.149702,0,0,0,40,4374,255.43745,99.7613830566406,,,,,,,,,,,,,0,,,,0,,,,,,252.5115509,,,,
,32497007.555,255.511673,99.7613830566406,1.8366605584095E-5,3.51541484293586E-7,1,0.999253354069792,40.0298881530762,1.99658812443913,20.0100000947714,0.000208373892780948,3.37410098128552E-5,0.25,-2.04885763472249E-7,1.83954346270601E-5,-1.90611082477054E-7,255.511673,255.511673,99.7613830566406,99.7613830566406,57.6114932669484,20.6011683345223,22.149702,0,0,0,40,4374,258.4473,99.7613830566406,,,,,,,,,,,,,0,,,,0.00245,,,,,,255.511673,,,,
,32497151.255,259.0577087,99.7613830566406,1.83327116968954E-5,3.61469712024837E-7,1,0.999253354069792,40.0298881530762,1.99666895510037,20.0100000947714,0.000207902482400131,3.40722781253438E-5,0.25,-1.69252796885926E-7,1.83591497924649E-5,-1.5516863207886E-7,259.0577087,259.0577087,99.7613830566406,99.7613830566406,57.454385934583,20.5981805219895,22.529354,0,0,0,40,4374,262.04815,99.7613830566406,,,,,,,,,,,,,0,,,,-0.0049,,,,,,259.0577087,,,,
,32497290.28,262.5248413,99.7613830566406,1.79960816175828E-5,4.42884808044745E-7,1,0.999253354069792,40.0298881530762,1.99700228524863,20.0100000947714,0.000205445069739623,2.56447626534115E-5,0.25,-8.55070740589107E-7,1.80203417548245E-5,-8.42349797224489E-7,262.5248413,262.5248413,99.7613830566406,99.7613830566406,57.7154498600061,20.5976498878033,22.909004,0,0,0,40,4374,265.528,99.7613830566406,,,,,,,,,,,,,0,,,,0,,,,,,262.5248413,,,,
,32497432.275,266.0115967,99.7613830566406,1.77632848144065E-5,4.37541774055131E-7,1,0.999253354069792,40.0298881530762,1.99685579659732,19.9400000274181,0.00020166608881493,3.1548800522551E-5,0.25,-2.92525691140301E-7,1.77845952605989E-5,-2.79427657506694E-7,266.0115967,266.0115967,99.7613830566406,99.7613830566406,57.8694306782946,20.5934854416046,22.529354,0,0,0,40,4374,269.0991,99.7613830566406,,,,,,,,,,,,,0,,,,0,,,,,,266.0115967,,,,
,32497571.98,269.5278625,99.7613830566406,1.76242904985422E-5,3.86378311417558E-7,1,0.999253354069792,40.0298881530762,1.99676729240694,19.9400000274181,0.000199796535910635,3.27847607250812E-5,0.25,-1.58562427793474E-7,1.76431189751775E-5,-1.45596690155746E-7,269.5278625,269.5278625,99.7613830566406,99.7613830566406,57.6208728091792,20.5939134778794,22.529354,0,0,0,40,4374,272.5989,99.7613830566406,,,,,,,,,,,,,0,,,,0,,,,,,269.5278625,,,,
,32497713.695,273.0423584,99.7613830566406,1.73932527279769E-5,4.52210184747747E-7,1,0.999253354069792,40.0298881530762,1.99695907600023,19.9400000274181,0.00019713040610883,3.25862689776909E-5,0.25,-1.35753306072453E-7,1.74096311788594E-5,-1.23119119613817E-7,273.0423584,273.0423584,99.7613830566406,99.7613830566406,57.6568277210638,20.5936508370696,22.529354,0,0,0,40,4374,276.15165,99.7613830566406,,,,,,,,,,,,,0,,,,-0.0049,,,,,,273.0423584,,,,
,32497853.15,276.5175934,99.7613830566406,1.70065454957365E-5,4.67874040090276E-7,1,0.999253354069792,40.0298881530762,1.99679825292434,19.8899991810322,0.000193284354123729,2.85344990687779E-5,0.25,-4.2601155333654E-7,1.70206543449924E-5,-4.14066808473936E-7,276.4886475,276.5465393,99.7613830566406,99.7613830566406,57.3887291389676,20.5930004985962,22.909004,0,0,0,40,4374,279.63485,99.7613830566406,,,,,,,,,,,,,0,,,,-0.00245,,,,,,276.5175934,,,,
,32497993.19,280.0075989,99.7613830566406,1.69370120696444E-5,4.65139426155934E-7,1,0.999253354069792,40.0298881530762,1.99707561904074,19.8899991810322,0.000192623323498556,2.76805105104649E-5,0.25,-4.89263609351372E-7,1.69489873574928E-5,-4.77541326992736E-7,280.0075989,280.0075989,99.7613830566406,99.7613830566406,57.6208728091792,20.5953831076787,22.529354,0,0,0,40,4374,283.134,99.7613830566406,,,,,,,,,,,,,0,,,,-0.00245,,,,,,280.0075989,,,,
,32498132.135,283.5031128,99.7613830566406,1.74513690538255E-5,3.89568073940804E-7,1,0.999253354069792,40.0298881530762,1.99725489370877,19.8899991810322,0.00019860487811455,2.77137790348856E-5,0.25,-5.75189841699673E-7,1.74615664730978E-5,-5.63268942636901E-7,283.5031128,283.5031128,99.7613830566406,99.7613830566406,57.4786164186792,20.5942140310644,22.529354,0,0,0,40,4374,286.59725,99.7613830566406,,,,,,,,,,,,,0,,,,0.00245,,,,,,283.5031128,,,,
,32498275.34,287.0350952,99.7613830566406,1.7154334160634E-5,3.7712588977055E-7,1,0.999253354069792,40.0298881530762,1.99704782685991,19.8400001972914,0.000194089862586598,3.35291515518038E-5,0.25,-8.95411724089526E-9,1.71617966709275E-5,2.89819034687292E-9,287.0043335,287.0658569,99.7613830566406,99.7613830566406,57.6255625802946,20.5974127634665,22.529354,0,0,0,40,4374,290.18995,99.7613830566406,,,,,,,,,,,,,0,,,,-0.00245,,,,,,287.0350952,,,,
,32498415.52,290.5258484,99.7613830566406,1.67636186610162E-5,4.8259129774222E-7,1,0.999253354069792,40.0298881530762,1.99740463355982,19.8400001972914,0.000190276096894202,2.93142002484992E-5,0.25,-3.1376591494625E-7,1.67690228835365E-5,-3.02443274161274E-7,290.5258484,290.5258484,99.7613830566406,99.7613830566406,57.5755383550638,20.5960886300447,23.288654,0,0,0,40,4374,293.7021,99.7613830566406,,,,,,,,,,,,,0,,,,0,,,,,,290.5258484,,,,
,32498556.325,294.0054932,99.7613830566406,1.664927733489E-5,4.42774234237002E-7,1,0.999253354069792,40.0298881530762,1.99739236977255,19.8400001972914,0.000188002876905007,3.45974028258338E-5,0.25,1.73573257348441E-7,1.6652242365107E-5,1.84785865489653E-7,294.0054932,294.0054932,99.7613830566406,99.7613830566406,57.6560460925446,20.5972327289958,22.909004,0,0,0,40,4374,297.2312,99.7613830566406,,,,,,,,,,,,,0,,,,-0.0049,,,,,,294.0054932,,,,
,32498697.245,297.5406494,99.7613830566406,1.6296887947376E-5,3.62494177099816E-7,1,0.999253354069792,40.0298881530762,1.99726287375944,19.7700001299381,0.000183762981549603,3.51637727657019E-5,0.25,2.85434094800731E-7,1.62976552743672E-5,2.96241522756568E-7,297.5406494,297.5406494,99.7613830566406,99.7613830566406,57.271484861083,20.5923342836833,22.529354,0,0,0,40,4374,300.7502,99.7613830566406,,,,,,,,,,,,,0,,,,0,,,,,,297.5406494,,,,
,32498837.9,301.0073242,99.7613830566406,1.67842902314299E-5,4.40971987097575E-7,1,0.999253354069792,40.0298881530762,1.99747758270872,19.7700001299381,0.000190352726476125,2.9878161792529E-5,0.25,-2.6613213687246E-7,1.6783371590329E-5,-2.55154987824484E-7,301.0073242,301.0073242,99.7613830566406,99.7613830566406,57.5403650716984,20.5945899766661,22.909004,0,0,0,40,4374,304.2768,99.7613830566406,,,,,,,,,,,,,0,,,,-0.0049,,,,,,301.0073242,,,,
,32498979.38,304.54985045,99.7613830566406,1.60659443680497E-5,4.64957326456478E-7,1,0.999253354069792,40.0298881530762,1.99765002946966,19.7700001299381,0.000181913194186574,3.02412977829099E-5,0.25,-1.09311898589857E-7,1.60629405025611E-5,-9.89439316035183E-8,304.5205688,304.5791321,99.7613830566406,99.7613830566406,57.4457880208715,20.5922292073264,23.288654,0,0,0,40,4374,307.8266,99.7613830566406,,,,,,,,,,,,,0,,,,0,,,,,,304.54985045,,,,
,32499119.55,308.0580139,99.7613830566406,1.60803278863527E-5,4.56954829978904E-7,1,0.999253354069792,40.0298881530762,1.99740057876366,19.7199992835522,0.000182820657141406,2.57062021750686E-5,0.25,-5.12107724294731E-7,1.60755697574609E-5,-5.0172738513012E-7,308.0580139,308.0580139,99.7613830566406,99.7613830566406,57.210517836583,20.5993269469626,22.909004,0,0,0,40,4374,311.3319,99.7613830566406,,,,,,,,,,,,,0,,,,0,,,,,,308.0580139,,,,
,32499262.125,311.5556641,99.7613830566406,1.56924375617676E-5,4.09222001117596E-7,1,0.999253354069792,40.0298881530762,1.9978184456079,19.7199992835522,0.000177668659464481,2.94489352538911E-5,0.25,-1.13962103580253E-7,1.56856008317817E-5,-1.04073316049514E-7,311.5556641,311.5556641,99.7613830566406,99.7613830566406,57.4199942797368,20.5923994189925,22.909004,0,0,0,40,4374,314.91455,99.7613830566406,,,,,,,,,,,,,0,,,,-0.0049,,,,,,311.5556641,,,,
,32499400.92,315.042572,99.7613830566406,1.55892264828878E-5,3.87105900744299E-7,1,0.999253354069792,40.0298881530762,1.99780256699425,19.7199992835522,0.000177041499085519,2.59923069006524E-5,0.25,-4.0134561957141E-7,1.55806887207426E-5,-3.91470763136872E-7,315.042572,315.042572,99.7613830566406,99.7613830566406,57.5098815594484,20.5939090598533,22.909004,0,0,0,40,4374,318.4095,99.7613830566406,,,,,,,,,,,,,0,,,,-0.00245,,,,,,315.042572,,,,
,32499522.2,318.0259094,99.7613830566406,1.49797195217292E-5,4.75048127488959E-7,1,0.999253354069792,40.0298881530762,1.99783458813681,19.6599997580051,0.000169576936855106,2.80178804956805E-5,0.25,-1.16291341268286E-7,1.49697713768168E-5,-1.07043219922004E-7,318.0259094,318.0259094,99.7613830566406,99.7613830566406,57.4770531616407,20.5872933402341,23.668306,0,0,0,40,4374,321.4333,99.7613830566406,,,,,,,,,,,,,0,,,,-0.0049,,,,,,318.0259094,,,,
,32499661.04,321.506012,99.7613830566406,1.51513995741976E-5,4.92193839948074E-7,1,0.999253354069792,40.0298881530762,1.9974105588776,19.6599997580051,0.000171099186779049,3.0439965440475E-5,0.25,6.92053880645756E-8,1.51393690025338E-5,7.83119151248704E-8,321.506012,321.506012,99.7613830566406,99.7613830566406,57.4668919908907,20.5938384470953,23.288654,0,0,0,40,4374,324.9137,99.7613830566406,,,,,,,,,,,,,0,,,,0,,,,,,321.506012,,,,
,32499805.075,325.0336914,99.7613830566406,1.47306513454286E-5,3.54879286202205E-7,1,0.999253354069792,40.0298881530762,1.9975166632767,19.6599997580051,0.000166248333684287,3.00969099707533E-5,0.25,1.12029360049455E-7,1.47171080632908E-5,1.20721972846475E-7,325.0336914,325.0336914,99.7613830566406,99.7613830566406,57.2933704596215,20.5942874690413,23.668306,0,0,0,40,4374,328.543,99.7613830566406,,,,,,,,,,,,,0,,,,-0.0049,,,,,,325.0336914,,,,
,32499946.415,328.5495911,99.7613830566406,1.51924544490888E-5,4.41732848165771E-7,1,0.999253354069792,40.0298881530762,1.9975300756716,19.6000002324581,0.000172286870023752,2.61482421735833E-5,0.25,-3.16989635082158E-7,1.51768787417471E-5,-3.07698938820467E-7,328.5495911,328.5495911,99.7613830566406,99.7613830566406,57.4934673605446,20.5953501458878,23.288654,0,0,0,40,4374,332.1011,99.7613830566406,,,,,,,,,,,,,0,,,,-0.00245,,,,,,328.5495911,,,,
,32500087.12,332.0615234,99.7613830566406,1.38142393391283E-5,4.05818250875945E-7,1,0.999253354069792,40.0298881530762,1.99738859815792,19.6000002324581,0.000156658474569012,2.35943096656147E-5,0.25,-3.03836037706973E-7,1.3798398421542E-5,-2.95429274443043E-7,332.0615234,332.0615234,99.7613830566406,99.7613830566406,57.2980602307368,20.5989665999902,23.288654,0,0,0,40,4374,335.616,99.7613830566406,,,,,,,,,,,,,0,,,,-0.00245,,,,,,332.0615234,,,,
,32500226.94,335.5363464,99.7613830566406,1.43590237921766E-5,5.47346646315979E-7,1,0.999253354069792,40.0298881530762,1.99760877075457,19.6000002324581,0.000162278065551782,2.77350095574255E-5,0.25,-3.15303295100068E-8,1.43406673302898E-5,-2.32118813426085E-8,335.5363464,335.5363464,99.7613830566406,99.7613830566406,57.1323549846599,20.5943193212864,22.909004,0,0,0,40,4374,339.117,99.7613830566406,,,,,,,,,,,,,0,,,,0,,,,,,335.5363464,,,,
,32500367.705,339.0189819,99.7613830566406,1.3843097305479E-5,4.53931280198496E-7,1,0.999253354069792,40.0298881530762,1.99729310464448,19.5300001651049,0.000157485517083128,2.04913145872895E-5,0.25,-5.82803572675738E-7,1.38240571646881E-5,-5.74094801342715E-7,339.0189819,339.0189819,99.7613830566406,99.7613830566406,57.2793011462753,20.5937089878706,22.909004,0,0,0,40,4374,342.637,99.7613830566406,,,,,,,,,,,,,0,,,,0,,,,,,339.0189819,,,,
,32500508.25,342.5255432,99.7613830566406,1.36055312501339E-5,4.35062958273475E-7,1,0.999253354069792,40.0298881530762,1.99741032904667,19.5300001651049,0.000154330957833892,2.26905724206034E-5,0.25,-3.46729295493723E-7,1.35850551458257E-5,-3.38526848431193E-7,342.5255432,342.5255432,99.7613830566406,99.7613830566406,57.2542890336599,20.5947541660208,23.288654,0,0,0,40,4374,346.1437,99.7613830566406,,,,,,,,,,,,,0,,,,0,,,,,,342.5255432,,,,
,32500647.83,346.0032349,99.7613830566406,1.40531629923709E-5,4.62212274832015E-7,1,0.999253354069792,40.0298881530762,1.99812210246732,19.5300001651049,0.000159885381192784,2.08924196382359E-5,0.25,-5.83791034408523E-7,1.403047556515E-5,-5.7498789837238E-7,346.0032349,346.0032349,99.7613830566406,99.7613830566406,57.4223391652945,20.5860277844551,23.288654,0,0,0,40,4374,349.6517,99.7613830566406,,,,,,,,,,,,,0,,,,-0.00245,,,,,,346.0032349,,,,
,32500964.55,349.5031433,99.7613830566406,1.33593452316359E-5,5.14139900983596E-7,1,0.999253354069792,40.0298881530762,1.99755738546391,19.4799993187189,0.000150033765013595,3.08198240658455E-5,0.25,4.16274870944199E-7,1.33356527337963E-5,4.22981301039925E-7,349.5031433,349.5031433,99.7613830566406,99.7613830566406,57.2863358029484,20.5978136119105,23.288654,0,0,0,40,4374,350.6662,99.7613830566406,,,,,,,,,,,,,0,,,,0.0049,,,,,,349.5031433,,,,
,32501092.69,349.7926636,99.7613830566406,1.30846809874893E-5,6.0365036423107E-7,1,0.999253354069792,40.0298881530762,1.99746527712726,19.4799993187189,0.00014830189238641,2.23262017719477E-5,0.25,-2.88268291687695E-7,1.3061735265196E-5,-2.80477652743026E-7,349.7926636,349.7926636,99.7613830566406,99.7613830566406,57.3848209963715,20.5982969952955,23.288654,0,0,0,40,4369,350.8076,99.7613830566406,,,,,,,,,,,,,0,,,,0.00245,,,,,,349.7926636,,,,