File: data/doubleLayers/dl_1-25/ppms/data/DD205_3_HYST_100OE_250K.DAT
[Header]
; VSM Data File (default extension .dat)
; Copyright (c) 2003-2013, Quantum Design, Inc. All rights reserved.
TITLE,
FILEOPENTIME,22251552.97,09/15/2018,9:57 pm
BYAPP,VSM,2.0,2.0
INFO,PPMS VSM Option Release 1.4.10 Build 1,APPNAME
INFO,Quantum Design Linear Motor Servo Controller,MOTOR_MODULE_NAME
INFO,3101-100 M1,MOTOR_HW_VERSION
INFO,MMC1014,MOTOR_SERIAL_NUMBER
INFO,SRV No X-over 01.03.11,MOTOR_SOFTWARE_VERSION
INFO,Quantum Design VSM Detection Module,VSM_MODULE_NAME
INFO,3101-150 F0,VSM_HW_VERSION
INFO,VSM707,VSM_SERIAL_NUMBER
INFO,VSM No X-over 01.02.05 May 20 2008 13:51:47,VSM_SOFTWARE_VERSION
INFO,704,PREAMP_SERIAL_NUMBER
INFO,822,COIL_SERIAL_NUMBER
INFO,0,MOMENT_UNITS
INFO,CoFe2O4,SAMPLE_MATERIAL
INFO,Double Layer blue,SAMPLE_COMMENT
INFO,,SAMPLE_MASS
INFO,,SAMPLE_VOLUME
INFO,,SAMPLE_MOLECULAR_WEIGHT
INFO,,SAMPLE_SIZE
INFO,,SAMPLE_SHAPE
DATATYPE,COMMENT,1
DATATYPE,TIME,2
STARTUPAXIS,X,2
STARTUPAXIS,Y1,5
[Data]
Comment,Time Stamp (sec),Temperature (K),Magnetic Field (Oe),Moment (emu),M. Std. Err. (emu),Transport Action,Averaging Time (sec),Frequency (Hz),Peak Amplitude (mm),Center Position (mm),Coil Signal' (mV),Coil Signal" (mV),Range (mV),M. Quad. Signal (emu),M. Raw' (emu),M. Raw" (emu),Min. Temperature (K),Max. Temperature (K),Min. Field (Oe),Max. Field (Oe),Mass (grams),Motor Lag (deg),Pressure (Torr),VSM Status (code),Motor Status (code),Measure Status (code),Measure Count,PPMS Status (code),System Temp. (K),System Field (Oe),Sample Position (deg),Bridge 1 Resistance (ohms),Bridge 1 Excitation (에),Bridge 2 Resistance (ohms),Bridge 2 Excitation (에),Bridge 3 Resistance (ohms),Bridge 3 Excitation (에),Bridge 4 Resistance (ohms),Bridge 4 Excitation (에),Signal 1 Vin (V),Signal 2 Vin (V),Digital Inputs (code),Drive 1 Iout (mA),Drive 1 Ipower (W),Drive 2 Iout (mA),Drive 2 Ipower (W),Pressure (),Map 20 (),Map 21 (),Map 22 (),Map 23 (),Map 24 (),Map 25 (),Map 26 (),Map 27 (),Map 28 (),Map 29 ()
,22251569.67,250.4357605,-0.289251685142517,,,2,,,,16.0900002831221,,,,,,,250.4357605,250.4357605,-0.289251685142517,-0.289251685142517,,,28.224119,,,,-99999999,4369,250.8177,-0.289251685142517,,,,,,,,,,,,,,,,,,,,,,,250.4357605,,,,
,22251719.415,250.3015137,4605.66845703125,6.01327495718201E-5,4.01573523346509E-7,1,0.999253354069792,40.0298881530762,1.99844324594231,16.0799995064735,0.000681217673310571,0.000120585714998964,0.25,2.09462489360214E-7,6.02374445561962E-5,2.59421133053251E-7,250.3015137,250.3015137,4600.58837890625,4610.74853515625,56.2850696698137,20.5150301753263,28.603769,0,0,0,40,4449,250.4055,4605.66845703125,,,,,,,,,,,,,0,,,,-0.00245,,,,,,250.3015137,,,,
,22251816.42,250.1841278,9451.67724609375,5.61079037175837E-5,6.21067956994225E-7,1,0.999253354069792,40.0298881530762,1.99840562829845,16.0799995064735,0.000635856595900701,0.000111109706992713,0.25,7.16622312765596E-8,5.62059310789448E-5,1.18039012966813E-7,250.1841278,250.1841278,9441.5439453125,9461.810546875,56.3530713509867,20.5201833327463,27.844467,0,0,0,40,4449,250.29615,9451.67724609375,,,,,,,,,,,,,0,,,,-0.0049,,,,,,250.1841278,,,,
,22251916.35,250.0950928,14446.5424804687,4.40711102926394E-5,8.04985106171718E-7,1,0.999253354069792,40.0298881530762,1.99835016316594,16.0799995064735,0.000497847686476103,9.64246559942045E-5,0.25,8.63845829646025E-7,4.4147586826217E-5,9.01654076176993E-7,250.0950928,250.0950928,14444.1435546875,14448.94140625,56.4335790884675,20.5220285065686,28.224119,0,0,0,40,4449,250.24955,14446.5424804687,,,,,,,,,,,,,0,,,,0,,,,,,250.0950928,,,,
,22252012.18,250.0416412,19236.34375,3.10156302340441E-5,1.31080924723698E-6,1,0.999253354069792,40.0298881530762,1.99839395846641,16.0799995064735,0.000348570338056882,7.82676864930329E-5,0.25,1.52599249223805E-6,3.1068759458664E-5,1.55418231487221E-6,250.0416412,250.0416412,19231.404296875,19241.283203125,56.516431711506,20.5224288799139,28.224119,0,0,0,40,4449,250.24035,19236.34375,,,,,,,,,,,,,0,,,,0,,,,,,250.0416412,,,,
,22252108.325,250.0141144,24041.5517578125,1.7651185318679E-5,1.50979551159617E-6,1,0.999253354069792,40.0298881530762,1.99828510836306,16.0799995064735,0.000195643945290929,6.02217291482024E-5,0.25,2.25195575436223E-6,1.76803050558129E-5,2.2704091131661E-6,250.0141144,250.0141144,24034,24049.103515625,56.6602513590445,20.5249329599225,28.224119,0,0,0,40,4449,250.23805,24041.5517578125,,,,,,,,,,,,,0,,,,-0.00245,,,,,,250.0141144,,,,
,22252205.47,250.0049438,28896.9453125,1.15256059205364E-6,1.05742453649344E-6,1,0.999253354069792,40.0298881530762,1.9982896728123,16.0799995064735,7.59295301203059E-6,3.38131280903707E-5,0.25,2.78327060786192E-6,1.15229963865958E-6,2.78910094020167E-6,250.0049438,250.0049438,28892.11328125,28901.77734375,56.668849272756,20.5233912430788,28.224119,0,0,0,40,4449,250.2399,28896.9453125,,,,,,,,,,,,,0,,,,0,,,,,,250.0049438,,,,
,22252304.565,250.00357055,33846.546875,-1.47310638750455E-5,1.49081418933678E-6,1,0.999253354069792,40.0298881530762,1.9983908465485,16.0799995064735,-0.000172340687871597,1.95113860155631E-6,0.25,2.72677893524604E-6,-1.47591537720302E-5,2.7194945052311E-6,250.0033417,250.0037994,33839.26953125,33853.82421875,56.6055373626983,20.5276299981275,28.603769,0,0,0,40,4449,250.23645,33846.546875,,,,,,,,,,,,,0,,,,0,,,,,,250.00357055,,,,
,22252399.675,250.0030365,38601.447265625,-3.19907280641719E-5,2.14349469266056E-6,1,0.999253354069792,40.0298881530762,1.99827378690848,16.0799995064735,-0.000368862455674825,-2.6788699007442E-5,0.25,3.18433134033027E-6,-3.20494876640295E-5,3.16374434296499E-6,250.0030365,250.0030365,38596.4453125,38606.44921875,56.6039741056598,20.5248847774202,28.224119,0,0,0,40,4449,250.2388,38601.447265625,,,,,,,,,,,,,0,,,,0.00245,,,,,,250.0030365,,,,
,22252496.945,250.0029755,43464.001953125,-4.70816467859792E-5,1.34027606892911E-6,1,0.999253354069792,40.0298881530762,1.99835890878074,16.0799995064735,-0.000542027182747944,-4.43867615338881E-5,0.25,4.2488828934035E-6,-4.71677680754481E-5,4.21786957239404E-6,250.0029755,250.0029755,43454.01953125,43473.984375,56.8056342636214,20.5261006106583,28.224119,0,0,0,40,4449,250.2248,43464.001953125,,,,,,,,,,,,,0,,,,0.00245,,,,,,250.0029755,,,,
,22252593.225,250.0042725,48276.5078125,-6.15852743460092E-5,2.87742895920058E-6,1,0.999253354069792,40.0298881530762,1.99831555435547,16.0799995064735,-0.000707722224140635,-6.53431998768517E-5,0.25,4.91505368794388E-6,-6.16973997955212E-5,4.87343252381291E-6,250.0042725,250.0042725,48271.4375,48281.578125,56.4796951711021,20.5216882804297,28.224119,0,0,0,40,4449,250.2281,48276.5078125,,,,,,,,,,,,,0,,,,0,,,,,,250.0042725,,,,
,22252687.33,250.0118332,52979.404296875,-7.87349152821463E-5,1.53448617399123E-6,1,0.999253354069792,40.0298881530762,1.99831568900614,16.0799995064735,-0.00089780338163136,-0.000123893347493203,0.25,2.7234885190053E-6,-7.88753449337771E-5,2.66411648944661E-6,250.0112152,250.0124512,52974.25,52984.55859375,56.7954730928714,20.5243601736373,28.224119,0,0,0,40,4449,250.21895,52979.404296875,,,,,,,,,,,,,0,,,,0.00245,,,,,,250.0118332,,,,
,22252783.43,250.0119019,57781.791015625,-9.51841642538729E-5,3.30767995961305E-6,1,0.999253354069792,40.0298881530762,1.99834273134355,16.0799995064735,-0.0010902611178318,-0.000121666353302288,0.25,5.77252549749701E-6,-9.53559585019034E-5,5.70521616001473E-6,250.0119019,250.0119019,57776.796875,57786.78515625,56.6774471864675,20.5224732224756,28.603769,0,0,0,40,4449,250.20885,57781.791015625,,,,,,,,,,,,,0,,,,0.0049,,,,,,250.0119019,,,,
,22252879.955,250.0131073,62607.6796875,-0.000112321593945853,2.56722704481205E-6,1,0.999253354069792,40.0298881530762,1.99843070236399,16.0799995064735,-0.00128199669046479,-0.000170187981188155,0.25,4.46419536669511E-6,-0.000112522413574065,4.38078208592034E-6,250.0131073,250.0131073,62595.09765625,62620.26171875,56.8494054606983,20.5252624433674,28.603769,0,0,0,40,4449,250.19965,62607.6796875,,,,,,,,,,,,,0,,,,-0.00245,,,,,,250.0131073,,,,
,22252973.94,250.01274105,67305.58203125,-0.000130049410700857,1.98334094860921E-6,1,0.999253354069792,40.0298881530762,1.99843549648742,16.0799995064735,-0.00148380022553646,-0.000200155749671088,0.25,4.89458970629291E-6,-0.000130281716042628,4.7976850233869E-6,250.0124969,250.0129852,67303.3671875,67307.796875,56.6477453027368,20.5226855911649,28.224119,0,0,0,40,4449,250.1898,67305.58203125,,,,,,,,,,,,,0,,,,0,,,,,,250.01274105,,,,
,22253070.085,250.0137634,72110.43359375,-0.000143281719077909,2.40778947003463E-6,1,0.999253354069792,40.0298881530762,1.99849379535526,16.0799995064735,-0.00163791319546915,-0.000202689842622895,0.25,6.96598658675015E-6,-0.000143538942882247,6.86215839522459E-6,250.0137634,250.0137634,72105.515625,72115.3515625,56.9611783389483,20.5224029587088,28.603769,0,0,0,40,4449,250.17445,72110.43359375,,,,,,,,,,,,,0,,,,0,,,,,,250.0137634,,,,
,22253165.33,250.0170898,76873.3515625,-0.000160776685261854,3.95199116748254E-6,1,0.999253354069792,40.0298881530762,1.99840026074285,16.0799995064735,-0.00182986398789493,-0.0002733277205164,0.25,3.76713264351862E-6,-0.000161062034710512,3.64371653509262E-6,250.0170898,250.0170898,76868.4296875,76878.2734375,56.8439340610637,20.5229798225908,28.224119,0,0,0,40,4449,250.16745,76873.3515625,,,,,,,,,,,,,0,,,,0,,,,,,250.0170898,,,,
,22253262.765,250.0140076,81744.01171875,-0.000181616780778695,3.71549673455218E-6,1,0.999253354069792,40.0298881530762,1.99848355566489,16.0799995064735,-0.00207107983842353,-0.000286026795718583,0.25,6.26144962018112E-6,-0.00018194077724328,6.12578876817793E-6,250.0140076,250.0140076,81736.109375,81751.9140625,56.7431039820829,20.5248064461156,28.224119,0,0,0,40,4449,250.15405,81744.01171875,,,,,,,,,,,,,0,,,,0,,,,,,250.0140076,,,,
,22253357.365,250.0180511,86472.328125,-0.000200686781257998,3.10268191834246E-6,1,0.999253354069792,40.0298881530762,1.99842707135118,16.0799995064735,-0.00229102373139816,-0.000301405791931044,0.25,8.21068092372004E-6,-0.000201045828813549,8.06328982987191E-6,250.0180511,250.0180511,86469.8046875,86474.8515625,56.6571248449675,20.5219038089829,27.844467,0,0,0,40,4449,250.13865,86472.328125,,,,,,,,,,,,,0,,,,0,,,,,,250.0180511,,,,
,22253468.555,250.0137329,88982.03125,-0.000203015540483375,2.78793346817236E-6,1,0.999253354069792,40.0298881530762,1.99848762993509,16.0799995064735,-0.00230935363405841,-0.000352906721805554,0.25,4.07194782650476E-6,-0.000203375383372143,3.91553998719181E-6,250.0137329,250.0137329,88976.8671875,88987.1953125,56.7618630665445,20.5209948227455,28.603769,0,0,0,40,4449,250.1241,88982.03125,,,,,,,,,,,,,0,,,,0,,,,,,250.0137329,,,,
,22253561.085,250.0074615,84356.27734375,-0.000193302340458632,3.45852245491041E-6,1,0.999253354069792,40.0298881530762,1.99847952063926,16.0799995064735,-0.00220598880146417,-0.000294882893624394,0.25,7.50640099734683E-6,-0.000193647916618372,7.36360522095268E-6,250.0074615,250.0074615,84348.609375,84363.9453125,56.7384142109675,20.5231619388306,28.224119,0,0,0,40,4449,250.1209,84356.27734375,,,,,,,,,,,,,0,,,,-0.00245,,,,,,250.0074615,,,,
,22253659.465,249.9981689,79437.75,-0.000170656049687201,3.4133896141994E-6,1,0.999253354069792,40.0298881530762,1.99844078282554,16.0799995064735,-0.00193904552610238,-0.000309150314634371,0.25,2.32049680568564E-6,-0.000170957700045249,2.18664273190953E-6,249.9981689,249.9981689,79435.40625,79440.09375,56.8048526351022,20.524172548213,28.224119,0,0,0,40,4449,250.1256,79437.75,,,,,,,,,,,,,0,,,,-0.00245,,,,,,249.9981689,,,,
,22253754.285,249.9958649,74699.16015625,-0.000157979955488555,2.93020629924723E-6,1,0.999253354069792,40.0298881530762,1.99843021052586,16.0799995064735,-0.0018024279117829,-0.00024339013141038,0.25,5.92367392704922E-6,-0.000158262250023504,5.80619839978574E-6,249.9958649,249.9958649,74691.9921875,74706.328125,56.9346029692945,20.5239867700272,28.603769,0,0,0,40,4449,250.1337,74699.16015625,,,,,,,,,,,,,0,,,,0,,,,,,249.9958649,,,,
,22253853.08,249.9954071,69761.31640625,-0.000140305118473802,2.74026355990992E-6,1,0.999253354069792,40.0298881530762,1.99839073339535,16.0799995064735,-0.00160139413727515,-0.0002123920763342,0.25,5.59312596609337E-6,-0.000140556087976546,5.48919069047168E-6,249.9954071,249.9954071,69758.890625,69763.7421875,56.5430070811598,20.5239269325078,28.224119,0,0,0,40,4449,250.13005,69761.31640625,,,,,,,,,,,,,0,,,,-0.00245,,,,,,249.9954071,,,,
,22253953.045,249.9917374,64760.7734375,-0.000122196872830887,2.14678762154734E-6,1,0.999253354069792,40.0298881530762,1.99838523834141,16.0799995064735,-0.0013936600455778,-0.000191030110268535,0.25,4.3376321640977E-6,-0.000122415023213359,4.2460198741148E-6,249.9911652,249.9923096,64750.8359375,64770.7109375,56.7274714116983,20.5249001162687,28.224119,0,0,0,40,4449,250.14385,64760.7734375,,,,,,,,,,,,,0,,,,0,,,,,,249.9917374,,,,
,22254048.74,249.9945068,59977.8203125,-0.000103251857194448,2.7993956715407E-6,1,0.999253354069792,40.0298881530762,1.99853591835723,16.0799995064735,-0.00117785240385252,-0.000160407303321565,0.25,3.75504036115392E-6,-0.000103436239644698,3.67766173950484E-6,249.9945068,249.9945068,59967.73046875,59987.91015625,56.7016776705637,20.5252096640473,28.224119,0,0,0,40,4449,250.14735,59977.8203125,,,,,,,,,,,,,0,,,,0.00245,,,,,,249.9945068,,,,
,22254144.32,249.9906921,55199.966796875,-8.9784207282772E-5,2.16239064339933E-6,1,0.999253354069792,40.0298881530762,1.99853497916243,16.0799995064735,-0.00102437251777151,-0.000138598605064176,0.25,3.34350942235258E-6,-8.99446078790106E-5,3.2762545914385E-6,249.9906921,249.9906921,55195.0390625,55204.89453125,56.8955215433329,20.5281884469082,28.224119,0,0,0,40,4449,250.1568,55199.966796875,,,,,,,,,,,,,0,,,,0.00245,,,,,,249.9906921,,,,
,22254243.295,249.989502,50255.05859375,-6.98799068383364E-5,2.12439004701708E-6,1,0.999253354069792,40.0298881530762,1.99854553901861,16.0799995064735,-0.000797283503585146,-0.000107869712439129,0.25,2.60267528438612E-6,-7.00047451186913E-5,2.55024464167689E-6,249.989502,249.989502,50252.48046875,50257.63671875,56.8736359447945,20.526706603255,28.983419,0,0,0,40,4449,250.161,50255.05859375,,,,,,,,,,,,,0,,,,0,,,,,,249.989502,,,,
,22254338.985,249.9935455,45472.583984375,-5.46479147603078E-5,1.9562277383152E-6,1,0.999253354069792,40.0298881530762,1.99853941355841,16.0799995064735,-0.000632201200561604,-3.41503120343531E-5,0.25,6.46432203360944E-6,-5.47491468446484E-5,6.43103270174042E-6,249.9935455,249.9935455,45469.96875,45475.19921875,56.7939098358329,20.5279237095435,28.224119,0,0,0,40,4449,250.16925,45472.583984375,,,,,,,,,,,,,0,,,,0,,,,,,249.9935455,,,,
,22254436.145,249.9907532,40617.470703125,-3.72041694652029E-5,1.69167997057093E-6,1,0.999253354069792,40.0298881530762,1.99859509595905,16.0799995064735,-0.000428187908705909,-3.60783104405836E-5,0.25,3.26934011104861E-6,-3.72721663997529E-5,3.24464607354901E-6,249.9907532,249.9907532,40612.52734375,40622.4140625,56.8400259184676,20.530588410472,28.603769,0,0,0,40,4449,250.1703,40617.470703125,,,,,,,,,,,,,0,,,,0,,,,,,249.9907532,,,,
,22254532.79,249.9893341,35787.357421875,-2.3293263595993E-5,1.4367433386654E-6,1,0.999253354069792,40.0298881530762,1.99859626032513,16.0799995064735,-0.000271825255924448,-1.02371307949866E-6,0.25,3.94918952056788E-6,-2.33373948049301E-5,3.93704263084847E-6,249.9893341,249.9893341,35779.91015625,35794.8046875,56.9166255133522,20.5280561052598,27.844467,0,0,0,40,4449,250.1813,35787.357421875,,,,,,,,,,,,,0,,,,0,,,,,,249.9893341,,,,
,22254629.215,249.9891663,30967.12109375,-4.2858457239974E-6,1.3014338990823E-6,1,0.999253354069792,40.0298881530762,1.99859994159473,16.0799995064735,-5.60695001232703E-5,3.47262976337212E-5,0.25,3.80650769611046E-6,-4.29649212991668E-6,3.80967504063591E-6,249.9891663,249.9891663,30962.322265625,30971.919921875,56.8439340610637,20.5326548031058,28.603769,0,0,0,40,4449,250.1921,30967.12109375,,,,,,,,,,,,,0,,,,-0.00245,,,,,,249.9891663,,,,
,22254725.495,249.9911346,26154.390625,9.54846443819321E-6,1.43923039349318E-6,1,0.999253354069792,40.0298881530762,1.99852636030164,16.0799995064735,0.000105496451062799,3.45993940483534E-5,0.25,1.39626448790668E-6,9.56407911350976E-6,1.40655770706784E-6,249.9911346,249.9911346,26149.513671875,26159.267578125,56.9353845978137,20.5296531317596,28.224119,0,0,0,40,4449,250.1936,26154.390625,,,,,,,,,,,,,0,,,,0,,,,,,249.9911346,,,,
,22254820.885,249.9949341,21387.2685546875,2.39914821738762E-5,1.37304342298177E-6,1,0.999253354069792,40.0298881530762,1.99851127934479,16.0799995064735,0.000264709699644073,8.90026538683842E-5,0.25,3.69073332943454E-6,2.40305558545447E-5,3.71694049560555E-6,249.9949341,249.9949341,21382.078125,21392.458984375,56.9049010855637,20.5308861460931,28.224119,0,0,0,40,4449,250.19325,21387.2685546875,,,,,,,,,,,,,0,,,,0.00245,,,,,,249.9949341,,,,
,22254918.46,249.993454,16510.7177734375,3.86372712104358E-5,9.20223001984357E-7,1,0.999253354069792,40.0298881530762,1.99850064741678,16.0799995064735,0.00043301361673009,0.000104630969353531,0.25,2.52949330568233E-6,3.87030007552354E-5,2.56574412491909E-6,249.993454,249.993454,16505.548828125,16515.88671875,57.0354330482753,20.5300039979083,28.603769,0,0,0,40,4449,250.2027,16510.7177734375,,,,,,,,,,,,,0,,,,0,,,,,,249.993454,,,,
,22255014.545,249.9925842,11710.341796875,5.11679909925293E-5,7.6442015898406E-7,1,0.999253354069792,40.0298881530762,1.9985649201382,16.0799995064735,0.000578082437452967,0.000111942368257147,0.25,1.00100554398943E-6,5.1256966918047E-5,1.04493841229679E-6,249.9925842,249.9925842,11702.732421875,11717.951171875,56.841589175506,20.5282392634366,28.603769,0,0,0,40,4449,250.2064,11710.341796875,,,,,,,,,,,,,0,,,,0.0049,,,,,,249.9925842,,,,
,22255107.24,249.9919891,7075.28295898438,5.97763350190587E-5,6.00307159109415E-7,1,0.999253354069792,40.0298881530762,1.99850021212183,16.0799995064735,0.000675989300171621,0.000126890562178623,0.25,8.27033527392118E-7,5.98805573020964E-5,8.77805477572087E-7,249.9919891,249.9919891,7070.37841796875,7080.1875,56.8243933480829,20.5293079807645,28.983419,0,0,0,40,4449,250.2135,7075.28295898438,,,,,,,,,,,,,0,,,,-0.00245,,,,,,249.9919891,,,,
,22255202.945,249.9945526,2292.248046875,5.57454555847004E-5,4.47542476847947E-7,1,0.999253354069792,40.0298881530762,1.99864956768116,16.0799995064735,0.000632384778973359,0.000107188265288398,0.25,-2.12677953124496E-7,5.58434521379795E-5,-1.67015166367145E-7,249.9945526,249.9945526,2282.52490234375,2301.97119140625,57.034651419756,20.5343680840706,28.603769,0,0,0,40,4449,250.2176,2292.248046875,,,,,,,,,,,,,0,,,,0,,,,,,249.9945526,,,,
,22255295.305,249.9989319,-2321.39990234375,-4.55075090357874E-5,3.99192809256428E-7,1,0.999253354069792,40.0298881530762,1.99863366292013,16.0799995064735,-0.000514742473697421,-9.6136760765077E-5,0.25,-5.88063879507134E-7,-4.55868718240587E-5,-6.26677330431613E-7,249.9989319,249.9989319,-2326.57836914062,-2316.22143554687,56.9885353371214,20.5337743414392,28.603769,0,0,0,40,4449,250.2144,-2321.39990234375,,,,,,,,,,,,,0,,,,-0.0049,,,,,,249.9989319,,,,
,22255391.52,249.9986877,-7130.52783203125,-5.8353234787021E-5,5.15565947389154E-7,1,0.999253354069792,40.0298881530762,1.9986030953715,16.0799995064735,-0.000658466874593715,-0.000132302164930909,0.25,-1.55065439064753E-6,-5.84543488162652E-5,-1.60152006946361E-6,249.9986877,249.9986877,-7140.53173828125,-7120.52392578125,57.0026046504676,20.5341335882222,28.983419,0,0,0,40,4449,250.2182,-7130.52783203125,,,,,,,,,,,,,0,,,,-0.00245,,,,,,249.9986877,,,,
,22255487,250.0031128,-11903.6728515625,-4.9795171307913E-5,6.62196475357231E-7,1,0.999253354069792,40.0298881530762,1.99863202009495,16.0799995064735,-0.000561381199580608,-0.000115915533341674,0.25,-1.5892497819076E-6,-4.988123475599E-5,-1.63307977076117E-6,250.0031128,250.0031128,-11913.607421875,-11893.73828125,57.0018230219483,20.5325183852976,28.224119,0,0,0,40,4449,250.2128,-11903.6728515625,,,,,,,,,,,,,0,,,,0.0049,,,,,,250.0031128,,,,
,22255584.165,250.0059052,-16760.9228515625,-3.7042392049486E-5,7.68648601638202E-7,1,0.999253354069792,40.0298881530762,1.99866045265949,16.0799995064735,-0.000414168740008088,-0.000106099264676296,0.25,-2.9349010466839E-6,-3.7104972561645E-5,-2.97054694202355E-6,250.0059052,250.0059052,-16765.734375,-16756.111328125,56.9439825115252,20.5358441080584,28.603769,0,0,0,40,4449,250.2037,-16760.9228515625,,,,,,,,,,,,,0,,,,0,,,,,,250.0059052,,,,
,22255680.02,250.0106659,-21548.111328125,-2.26264481658893E-5,1.06648102481242E-6,1,0.999253354069792,40.0298881530762,1.9986048261493,16.0799995064735,-0.000249996191439869,-8.20017025495543E-5,0.25,-3.30955205215692E-6,-2.26634270515034E-5,-3.33396465496533E-6,250.0106659,250.0106659,-21553.005859375,-21543.216796875,56.973684395256,20.5357079506763,28.603769,0,0,0,40,4449,250.1974,-21548.111328125,,,,,,,,,,,,,0,,,,0,,,,,,250.0106659,,,,
,22255777.07,250.0094299,-26400.173828125,-6.84467328177942E-6,1.13577881354213E-6,1,0.999253354069792,40.0298881530762,1.99862749416107,16.0799995064735,-6.73711649275001E-5,-7.24098145316966E-5,0.25,-5.20028453230478E-6,-6.85241329228127E-6,-5.21503097682779E-6,250.0094299,250.0094299,-26405.26171875,-26395.0859375,56.9603967104291,20.5349682162981,28.603769,0,0,0,40,4449,250.1933,-26400.173828125,,,,,,,,,,,,,0,,,,-0.00245,,,,,,250.0094299,,,,
,22255874.97,250.0137024,-31292.9677734375,8.20060438329212E-6,1.26796845241514E-6,1,0.999253354069792,40.0298881530762,1.99863384679631,16.0799995064735,0.00010069275896682,-2.84285084916966E-5,0.25,-3.92982984324025E-6,8.21821745849485E-6,-3.92999937682871E-6,250.0137024,250.0137024,-31302.94140625,-31282.994140625,57.0237086204868,20.5368961860694,28.983419,0,0,0,40,4449,250.17575,-31292.9677734375,,,,,,,,,,,,,0,,,,-0.00245,,,,,,250.0137024,,,,
,22255970.17,250.0118713,-36049.86328125,2.32521720424954E-5,1.0916304978681E-6,1,0.999253354069792,40.0298881530762,1.99877263396205,16.0799995064735,0.00027180429957509,-1.49178265914643E-6,0.25,-4.16394800746843E-6,2.32963882905861E-5,-4.15220876174944E-6,250.0118713,250.0118713,-36054.85546875,-36044.87109375,57.0573186468137,20.5366647436098,28.603769,0,0,0,40,4449,250.1682,-36049.86328125,,,,,,,,,,,,,0,,,,0,,,,,,250.0118713,,,,
,22256068.305,250.0129089,-40954.787109375,3.79532818240185E-5,1.52778224197234E-6,1,0.999253354069792,40.0298881530762,1.99875413386756,16.0799995064735,0.000437794994639308,3.13142932528469E-5,0.25,-3.81969820703549E-6,3.80230142233971E-5,-3.79535503682461E-6,250.0129089,250.0129089,-40957.25390625,-40952.3203125,57.0182372208522,20.5371973052946,28.983419,0,0,0,40,4449,250.1516,-40954.787109375,,,,,,,,,,,,,0,,,,0,,,,,,250.0129089,,,,
,22256166.12,250.0140533,-45844.7109375,5.40053449996715E-5,1.70622801786716E-6,1,0.999253354069792,40.0298881530762,1.99883057260875,16.0799995064735,0.000626124797765471,2.64251655110366E-5,0.25,-7.03467801234963E-6,5.41058752050512E-5,-7.00290932102555E-6,250.0140533,250.0140533,-45854.88671875,-45834.53515625,57.0846756449868,20.5397536455949,28.603769,0,0,0,40,4449,250.14275,-45844.7109375,,,,,,,,,,,,,0,,,,0,,,,,,250.0140533,,,,
,22256266.79,250.0129395,-50874.21484375,7.27182978732655E-5,1.91513886988132E-6,1,0.999253354069792,40.0298881530762,1.99876534745721,16.0799995064735,0.00084155859578757,4.41919652722746E-5,0.25,-8.71254247549086E-6,7.28530435545978E-5,-8.66852166830705E-6,250.0129395,250.0129395,-50881.515625,-50866.9140625,57.017455592333,20.538191695463,28.224119,0,0,0,40,4449,250.1308,-50874.21484375,,,,,,,,,,,,,0,,,,-0.00245,,,,,,250.0129395,,,,
,22256363.925,250.0102234,-55728.658203125,8.95204742149436E-5,2.3331659688968E-6,1,0.999253354069792,40.0298881530762,1.99868433357526,16.0799995064735,0.0010265778535741,0.000108548478280018,0.25,-5.9492917062067E-6,8.96824716023982E-5,-5.88682519977337E-6,250.0102234,250.0102234,-55738.96484375,-55718.3515625,57.0612267894099,20.5368922701071,28.224119,0,0,0,40,4449,250.12565,-55728.658203125,,,,,,,,,,,,,0,,,,0,,,,,,250.0102234,,,,
,22256460.57,250.0141602,-60558.216796875,0.000105749005203469,2.1633868998948E-6,1,0.999253354069792,40.0298881530762,1.99882302654909,16.0799995064735,0.00121066431946673,0.000140314429043893,0.25,-5.9622359380975E-6,0.000105939494064077,-5.88670075240437E-6,250.0141602,250.0141602,-60565.76171875,-60550.671875,56.9267866841022,20.5388549144934,28.603769,0,0,0,40,4449,250.11355,-60558.216796875,,,,,,,,,,,,,0,,,,-0.0049,,,,,,250.0141602,,,,
,22256559.85,250.0166779,-65520.779296875,0.000120709764123476,2.51037026882704E-6,1,0.999253354069792,40.0298881530762,1.99879534617211,16.0799995064735,0.00138554315201821,0.000139291869458227,0.25,-8.64650380643763E-6,0.000120928694197236,-8.56366296324378E-6,250.0166779,250.0166779,-65528.38671875,-65513.171875,57.0596635323714,20.5387434910265,28.224119,0,0,0,40,4449,250.0987,-65520.779296875,,,,,,,,,,,,,0,,,,-0.00245,,,,,,250.0166779,,,,
,22256657.42,250.0130463,-70394.73828125,0.00013895397751423,2.168476175216E-6,1,0.999253354069792,40.0298881530762,1.99886152082602,16.0799995064735,0.00158600564807512,0.000212254168078376,0.25,-5.37518525579118E-6,0.000139202309765933,-5.27196155055756E-6,250.0130463,250.0130463,-70399.734375,-70389.7421875,57.058100275333,20.5382353474352,28.603769,0,0,0,40,4449,250.08995,-70394.73828125,,,,,,,,,,,,,0,,,,0,,,,,,250.0130463,,,,
,22256756.44,250.0154266,-75344.09765625,0.000157352601388016,2.58689454872527E-6,1,0.999253354069792,40.0298881530762,1.99888511223089,16.0799995064735,0.00180343997288233,0.000197605536286846,0.25,-9.85770731223262E-6,0.000157636868136322,-9.74763499091491E-6,250.0154266,250.0154266,-75351.609375,-75336.5859375,57.0502839901407,20.5377904360475,28.983419,0,0,0,40,4449,250.0744,-75344.09765625,,,,,,,,,,,,,0,,,,0.00245,,,,,,250.0154266,,,,
,22256854.695,250.0127716,-80256.76171875,0.000172462013973143,3.34422495305463E-6,1,0.999253354069792,40.0298881530762,1.99889320817778,16.0799995064735,0.00197425701747005,0.000230201927682158,0.25,-9.60269928155414E-6,0.00017277263243767,-9.4801716095331E-6,250.0127716,250.0127716,-80269.4921875,-80244.03125,57.004167907506,20.538750736933,28.983419,0,0,0,40,4449,250.0654,-80256.76171875,,,,,,,,,,,,,0,,,,-0.00245,,,,,,250.0127716,,,,
,22256950.865,250.015152,-85061.12109375,0.000190539802647095,3.44326136292385E-6,1,0.999253354069792,40.0298881530762,1.99885897258843,16.0799995064735,0.00217027526176839,0.000317136219962321,0.25,-5.06932507013213E-6,0.000190878506980617,-4.92446690233411E-6,250.015152,250.015152,-85066.1484375,-85056.09375,56.9510171681983,20.5404849578299,28.603769,0,0,0,40,4449,250.0562,-85061.12109375,,,,,,,,,,,,,0,,,,-0.0049,,,,,,250.015152,,,,
,22257047.425,250.0196075,-89887.44921875,0.00021099708401992,3.27042465895931E-6,1,0.999253354069792,40.0298881530762,1.99877485790036,16.0799995064735,0.00240950514336357,0.000314752594365722,0.25,-8.82560654228204E-6,0.00021137472947372,-8.67109800807282E-6,250.0196075,250.0196075,-89897.40625,-89877.4921875,57.0299616486406,20.5386661230168,28.224119,0,0,0,40,4449,250.03545,-89887.44921875,,,,,,,,,,,,,0,,,,-0.00245,,,,,,250.0196075,,,,
,22257158.805,250.0112457,-85600.51953125,0.000192825943289986,2.3628003701353E-6,1,0.999253354069792,40.0298881530762,1.998853866946,16.0799995064735,0.00219509472356917,0.000327947013959921,0.25,-4.51216576310489E-6,0.000193168240500169,-4.36449443104658E-6,250.0112457,250.0112457,-85610.3984375,-85590.640625,57.0088576786214,20.5411364134897,28.603769,0,0,0,40,4449,250.03015,-85600.51953125,,,,,,,,,,,,,0,,,,0.0049,,,,,,250.0112457,,,,
,22257256.34,250.0025177,-80728.6328125,0.00018163228941801,2.5367657851413E-6,1,0.999253354069792,40.0298881530762,1.9987321860229,16.0799995064735,0.00207263927337669,0.000279534601296084,0.25,-6.8399261305654E-6,0.000181956845021523,-6.70513568763842E-6,250.0025177,250.0025177,-80733.1953125,-80724.0703125,56.9713395096983,20.5391900997302,28.224119,0,0,0,40,4449,250.0289,-80728.6328125,,,,,,,,,,,,,0,,,,0,,,,,,250.0025177,,,,
,22257356.725,249.9941406,-75708.43359375,0.000161194191013308,2.80468521461516E-6,1,0.999253354069792,40.0298881530762,1.99888511619283,16.0799995064735,0.00183959063262447,0.000247870154722382,0.25,-6.09059563373692E-6,0.000161482275520061,-5.9707974656727E-6,249.9941406,249.9941406,-75721.0390625,-75695.828125,57.0119841926983,20.5400892310988,28.603769,0,0,0,40,4449,250.03865,-75708.43359375,,,,,,,,,,,,,0,,,,0.00245,,,,,,249.9941406,,,,
,22257454.755,249.9905396,-70808.84375,0.000141752351148214,3.07584664061336E-6,1,0.999253354069792,40.0298881530762,1.99892365663773,16.0799995064735,0.0016220516501607,0.000193143516491076,0.25,-7.54654400724081E-6,0.000142007470696453,-7.44486109557153E-6,249.9905396,249.9905396,-70818.9140625,-70798.7734375,57.068261446083,20.5383434800219,28.603769,0,0,0,40,4449,250.04475,-70808.84375,,,,,,,,,,,,,0,,,,0,,,,,,249.9905396,,,,
,22257552.695,249.990448,-65914.17578125,0.000125620719399834,2.71295224347333E-6,1,0.999253354069792,40.0298881530762,1.99890697194004,16.0799995064735,0.00143246608427644,0.000199891964441917,0.25,-4.15396988206087E-6,0.000125844739732286,-4.05924998938676E-6,249.990448,249.990448,-65921.625,-65906.7265625,57.139389641333,20.5416735091446,28.224119,0,0,0,40,4449,250.05435,-65914.17578125,,,,,,,,,,,,,0,,,,-0.0049,,,,,,249.990448,,,,
,22257651.025,249.9908905,-61002.234375,0.00010828005252748,2.55131535504442E-6,1,0.999253354069792,40.0298881530762,1.998868822974,16.0799995064735,0.00123794178502879,0.000153636551088031,0.25,-5.22643062640045E-6,0.000108474475668203,-5.14754163831617E-6,249.9908905,249.9908905,-61009.75,-60994.71875,57.1284468420637,20.5384141824608,28.603769,0,0,0,40,4449,250.0642,-61002.234375,,,,,,,,,,,,,0,,,,0.00245,,,,,,249.9908905,,,,
,22257748.275,249.9892426,-56142.5546875,9.23879814151651E-5,2.22613839960611E-6,1,0.999253354069792,40.0298881530762,1.99899325331955,16.0799995064735,0.0010565157811702,0.000129931768116109,0.25,-4.56209295830843E-6,9.25539515248594E-5,-4.4948499913364E-6,249.9892426,249.9892426,-56147.48828125,-56137.62109375,57.1151591572368,20.5401812732534,28.603769,0,0,0,40,4449,250.07225,-56142.5546875,,,,,,,,,,,,,0,,,,0,,,,,,249.9892426,,,,
,22257849.585,249.98745725,-51080.70703125,7.34412203636817E-5,1.8113768957378E-6,1,0.999253354069792,40.0298881530762,1.99890248109588,16.0799995064735,0.000832352215579888,0.000146292313462828,0.25,1.66927902546842E-7,7.35700580918082E-5,2.27133601527197E-7,249.9869537,249.9879608,-51090.46875,-51070.9453125,56.9932251082368,20.5414663151552,28.603769,0,0,0,40,4449,250.0843,-51080.70703125,,,,,,,,,,,,,0,,,,-0.00245,,,,,,249.98745725,,,,
,22257949.71,249.9859619,-46076.10546875,5.6639399998401E-5,1.45600717712731E-6,1,0.999253354069792,40.0298881530762,1.99890982587034,16.0799995064735,0.000643403194671366,0.000104326514037962,0.25,-6.20799726078048E-7,5.67393699831491E-5,-5.75615625714956E-7,249.9859619,249.9859619,-46083.69921875,-46068.51171875,57.098744958333,20.5400902281892,28.603769,0,0,0,40,4449,250.09385,-46076.10546875,,,,,,,,,,,,,0,,,,0,,,,,,249.9859619,,,,
,22258047.695,249.9917297,-41178.75390625,3.95381710744505E-5,1.65482829492783E-6,1,0.999253354069792,40.0298881530762,1.99895437348048,16.0799995064735,0.000454997555878557,3.91021838834553E-5,0.25,-3.40795392467486E-6,3.96103778859654E-5,-3.38158824825149E-6,249.9917297,249.9917297,-41191.23046875,-41166.27734375,57.0026046504676,20.5389404262409,28.983419,0,0,0,40,4449,250.0988,-41178.75390625,,,,,,,,,,,,,0,,,,0,,,,,,249.9917297,,,,
,22258148.16,249.9878235,-36156.8359375,2.27100514997842E-5,1.57908877088145E-6,1,0.999253354069792,40.0298881530762,1.99894003790717,16.0799995064735,0.000265931703757332,-4.01178483890885E-6,0.25,-4.29218495233615E-6,2.27534412794391E-5,-4.28111381993459E-6,249.9878235,249.9878235,-36159.3125,-36154.359375,57.1307917276214,20.5410282783375,28.603769,0,0,0,40,4449,250.10965,-36156.8359375,,,,,,,,,,,,,0,,,,0,,,,,,249.9878235,,,,
,22258245.305,249.9893341,-31305.1083984375,7.99955357828073E-6,1.42667614273511E-6,1,0.999253354069792,40.0298881530762,1.99891035491544,16.0799995064735,9.09823264197471E-5,1.40987065921871E-5,0.25,-1.4380197046551E-7,8.01371530875447E-6,-1.37491220645902E-7,249.9893341,249.9893341,-31312.5234375,-31297.693359375,57.0237086204868,20.5402086100614,28.224119,0,0,0,40,4449,250.11465,-31305.1083984375,,,,,,,,,,,,,0,,,,0,,,,,,249.9893341,,,,
,22258340.93,249.9885864,-26522.4609375,-6.23500431599627E-6,1.46435854908571E-6,1,0.999253354069792,40.0298881530762,1.99881368813381,16.0799995064735,-6.32023949047127E-5,-5.5433134364657E-5,0.25,-3.80805551577803E-6,-6.24282141918147E-6,-3.8198624916314E-6,249.9885864,249.9885864,-26529.951171875,-26514.970703125,57.1894138665637,20.5361436149025,28.983419,0,0,0,40,4449,250.1239,-26522.4609375,,,,,,,,,,,,,0,,,,0,,,,,,249.9885864,,,,
,22258438.82,249.9898529,-21630.3427734375,-2.26084814388391E-5,1.05015580700377E-6,1,0.999253354069792,40.0298881530762,1.99886215980338,16.0799995064735,-0.000254263802120033,-5.63718230968051E-5,0.25,-1.05120218226755E-6,-2.26473017960408E-5,-1.07164360199167E-6,249.9898529,249.9898529,-21637.8984375,-21622.787109375,56.9729027667368,20.538498509791,28.224119,0,0,0,40,4449,250.1326,-21630.3427734375,,,,,,,,,,,,,0,,,,-0.0049,,,,,,249.9898529,,,,
,22258534.205,249.9898834,-16862.951171875,-3.59705035389774E-5,1.06323862767209E-6,1,0.999253354069792,40.0298881530762,1.9987386880703,16.0799995064735,-0.000404474564079419,-8.99130317097492E-5,0.25,-1.69271117404327E-6,-3.60322451966644E-5,-1.72530411991523E-6,249.9898834,249.9898834,-16865.453125,-16860.44921875,56.9807190519291,20.5349437914883,28.603769,0,0,0,40,4449,250.1402,-16862.951171875,,,,,,,,,,,,,0,,,,0,,,,,,249.9898834,,,,
,22258631.905,249.99140165,-11980.6196289062,-5.03320900137181E-5,5.82158632780611E-7,1,0.999253354069792,40.0298881530762,1.99885636134646,16.0799995064735,-0.000565814593278882,-0.000126869384914119,0.25,-2.46116157391365E-6,-5.04183960064456E-5,-2.50697725879726E-6,249.9910736,249.9917297,-11988.046875,-11973.1923828125,57.2527257766214,20.5355905293181,28.603769,0,0,0,40,4449,250.14685,-11980.6196289062,,,,,,,,,,,,,0,,,,-0.00245,,,,,,249.99140165,,,,
,22258729.055,249.9949036,-7125.037109375,-5.91298842193851E-5,5.36111885609914E-7,1,0.999253354069792,40.0298881530762,1.99878308397007,16.0799995064735,-0.000667604587729565,-0.000132249729098028,0.25,-1.41031909014802E-6,-5.92324826756595E-5,-1.46159524247255E-6,249.9949036,249.9949036,-7129.87353515625,-7120.20068359375,56.9611783389483,20.5344543214705,28.603769,0,0,0,40,4449,250.15055,-7125.037109375,,,,,,,,,,,,,0,,,,0,,,,,,249.9949036,,,,
,22258825.235,249.9932556,-2316.97229003906,-5.54965979675257E-5,4.90170873901627E-7,1,0.999253354069792,40.0298881530762,1.99881987352515,16.0799995064735,-0.000627256195234948,-0.000120307580660071,0.25,-9.86851811850085E-7,-5.55931680195206E-5,-1.03442770125744E-6,249.9928589,249.9936523,-2321.82373046875,-2312.12084960938,57.0112025641791,20.5321454502291,28.603769,0,0,0,40,4449,250.15415,-2316.97229003906,,,,,,,,,,,,,0,,,,0.0049,,,,,,249.9932556,,,,
,22258921.965,249.9972076,2513.76037597656,4.78581497044196E-5,3.45731886385611E-7,1,0.999253354069792,40.0298881530762,1.99877052828192,16.0799995064735,0.000543058084458404,9.13543004730442E-5,0.25,-2.41996280164951E-7,4.79423243573976E-5,-2.02888180592205E-7,249.9972076,249.9972076,2511.15966796875,2516.36108398438,56.8744175733137,20.5318468955925,28.983419,0,0,0,40,4449,250.1553,2513.76037597656,,,,,,,,,,,,,0,,,,-0.0049,,,,,,249.9972076,,,,
,22259019.545,249.9994507,7390.63037109375,5.85811720453195E-5,4.51080728832648E-7,1,0.999253354069792,40.0298881530762,1.99877517264118,16.0799995064735,0.000662864069272449,0.000122618900849761,0.25,6.56049697229208E-7,5.86834210724308E-5,7.05545547231521E-7,249.9994507,249.9994507,7380.47119140625,7400.78955078125,56.9588334533906,20.5319685370938,28.603769,0,0,0,40,4449,250.15495,7390.63037109375,,,,,,,,,,,,,0,,,,-0.00245,,,,,,249.9994507,,,,
,22259118.74,250.0011139,12348.2749023437,4.90796214667301E-5,8.10292265505127E-7,1,0.999253354069792,40.0298881530762,1.99877508427981,16.0799995064735,0.000556339770838709,9.70298557690849E-5,0.25,4.68412909653515E-8,4.91657033082617E-5,8.73824529844194E-8,250.0011139,250.0011139,12338.525390625,12358.0244140625,56.9611783389483,20.5383717606368,28.983419,0,0,0,40,4449,250.153,12348.2749023437,,,,,,,,,,,,,0,,,,0.00245,,,,,,250.0011139,,,,
,22259217.47,250.0073853,17285.9248046875,3.4643853266102E-5,8.18956102827917E-7,1,0.999253354069792,40.0298881530762,1.99865455707579,16.0799995064735,0.000387843867720959,9.63794593688126E-5,0.25,2.49350949915452E-6,3.47025859885201E-5,2.52641004440594E-6,250.0073853,250.0073853,17275.904296875,17295.9453125,57.0057311645445,20.5295176329227,28.983419,0,0,0,40,4449,250.1469,17285.9248046875,,,,,,,,,,,,,0,,,,-0.0049,,,,,,250.0073853,,,,
,22259317.055,250.0071869,22263.421875,2.04101596526772E-5,1.18243204751705E-6,1,0.999253354069792,40.0298881530762,1.99880551258084,16.0799995064735,0.000229869188678506,4.89579285053515E-5,0.25,7.78654442634895E-7,2.04453333206223E-5,7.96805371363523E-7,250.0071869,250.0071869,22253.423828125,22273.419921875,56.983845566006,20.5329071746669,28.983419,0,0,0,40,4449,250.1405,22263.421875,,,,,,,,,,,,,0,,,,0,,,,,,250.0071869,,,,
,22259415.065,250.0066986,27161.5947265625,5.93898742785015E-6,1.27611739775765E-6,1,0.999253354069792,40.0298881530762,1.9988872819305,16.0799995064735,6.43248808374236E-5,2.90400113303457E-5,0.25,1.5313656786375E-6,5.94815174518365E-6,1.53893071651842E-6,250.0066986,250.0066986,27156.599609375,27166.58984375,57.0510656186599,20.5333100499548,28.603769,0,0,0,40,4449,250.13585,27161.5947265625,,,,,,,,,,,,,0,,,,-0.0049,,,,,,250.0066986,,,,
,22259513.13,250.0083618,32061.4609375,-1.11571732666639E-5,1.03828527914088E-6,1,0.999253354069792,40.0298881530762,1.99888490992246,16.0799995064735,-0.000131246438594299,5.43610540457713E-6,0.25,2.41433912491732E-6,-1.1178733419389E-5,2.40942470618653E-6,250.0083618,250.0083618,32059.01953125,32063.90234375,57.1386080128137,20.5318522795827,28.603769,0,0,0,40,4449,250.12705,32061.4609375,,,,,,,,,,,,,0,,,,0,,,,,,250.0083618,,,,
,22259610.28,250.0103912,36916.138671875,-2.70122227310545E-5,1.3314633901125E-6,1,0.999253354069792,40.0298881530762,1.99887458499696,16.0799995064735,-0.000308018387094955,-4.29799788017205E-5,0.25,8.936004300274E-7,-2.70603601292753E-5,8.73042404968051E-7,250.0103912,250.0103912,36911.16796875,36921.109375,56.9517987967176,20.533838615199,28.603769,0,0,0,40,4449,250.1182,36916.138671875,,,,,,,,,,,,,0,,,,0.0049,,,,,,250.0103912,,,,
,22259705.49,250.0102844,41676.408203125,-4.22390031215642E-5,1.45338981131771E-6,1,0.999253354069792,40.0298881530762,1.99891942795232,16.0799995064735,-0.000483179967353008,-5.84363603546097E-5,0.25,2.17102475516556E-6,-4.23149122640619E-5,2.14028293990519E-6,250.0102844,250.0102844,41664.0390625,41688.77734375,56.9674313671022,20.5313959856348,28.983419,0,0,0,40,4449,250.10875,41676.408203125,,,,,,,,,,,,,0,,,,-0.00245,,,,,,250.0102844,,,,
,22259802.66,250.0103302,46531.666015625,-5.78454987011947E-5,1.94413258208393E-6,1,0.999253354069792,40.0298881530762,1.99905147659593,16.0799995064735,-0.000661056193847857,-8.40182612061037E-5,0.25,2.62159669908795E-6,-5.79491715439382E-5,2.57894701254512E-6,250.0103302,250.0103302,46521.6171875,46541.71484375,56.9572701963522,20.5326073000991,28.224119,0,0,0,40,4449,250.1026,46531.666015625,,,,,,,,,,,,,0,,,,0,,,,,,250.0103302,,,,
,22259898.33,250.0146942,51314.314453125,-7.42788600921746E-5,1.60071577579144E-6,1,0.999253354069792,40.0298881530762,1.99890648472865,16.0799995064735,-0.000852636549850178,-8.57400254988559E-5,0.25,5.31895889494731E-6,-7.44135721159122E-5,5.2677038583566E-6,250.0146942,250.0146942,51304.4921875,51324.13671875,56.9650864815445,20.5315549962914,28.224119,0,0,0,40,4449,250.08665,51314.314453125,,,,,,,,,,,,,0,,,,0.00245,,,,,,250.0146942,,,,
,22259997.41,250.0127106,56266.73046875,-8.9919356798867E-5,1.92629117610441E-6,1,0.999253354069792,40.0298881530762,1.9989038700863,16.0799995064735,-0.00102832101372559,-0.000125991574238014,0.25,4.48101550889721E-6,-9.00808502743612E-5,4.41564103126562E-6,250.0127106,250.0127106,56256.23828125,56277.22265625,56.9854088230445,20.5319296947406,28.603769,0,0,0,40,4449,250.0748,56266.73046875,,,,,,,,,,,,,0,,,,0.00245,,,,,,250.0127106,,,,
,22260098.015,250.0161591,61293.958984375,-0.000108214167483034,2.3377649198919E-6,1,0.999253354069792,40.0298881530762,1.9989281847146,16.0799995064735,-0.00123788273975704,-0.000149739885979282,0.25,5.55904654934274E-6,-0.000108408648188843,5.48079720700929E-6,250.0161591,250.0161591,61289.09765625,61298.8203125,57.0291800201214,20.5317544227833,28.983419,0,0,0,40,4449,250.06085,61293.958984375,,,,,,,,,,,,,0,,,,0,,,,,,250.0161591,,,,
,22260196.045,250.0123291,66196.95703125,-0.000126696769855383,2.45108219478694E-6,1,0.999253354069792,40.0298881530762,1.99869272140765,16.0799995064735,-0.00145959085178069,-0.000115064738484957,0.25,1.18211315052795E-5,-0.000126928807837439,1.17390043832031E-5,250.0123291,250.0123291,66186.734375,66207.1796875,56.9299131981791,20.52881419566,28.603769,0,0,0,40,4449,250.0529,66196.95703125,,,,,,,,,,,,,0,,,,0,,,,,,250.0123291,,,,
,22260295.235,250.0104218,71152.14453125,-0.000145214935895476,2.29687434273939E-6,1,0.999253354069792,40.0298881530762,1.99869633204207,16.0799995064735,-0.00166414858429459,-0.000182520190890539,0.25,9.08217285788476E-6,-0.000145477280406011,8.98038567414607E-6,250.0104218,250.0104218,71144.6796875,71159.609375,56.8290831191983,20.5277555312846,28.603769,0,0,0,40,4449,250.04285,71152.14453125,,,,,,,,,,,,,0,,,,0.00245,,,,,,250.0104218,,,,
,22260394.69,250.0106659,76122.109375,-0.000163465247323985,2.45230149262604E-6,1,0.999253354069792,40.0298881530762,1.99870496550327,16.0799995064735,-0.00187150828824752,-0.000215810198446951,0.25,9.31041528921849E-6,-0.00016375983214949,9.19444427705781E-6,250.0106659,250.0106659,76107.59375,76136.625,56.8955215433329,20.5275296729064,28.983419,0,0,0,40,4449,250.0338,76122.109375,,,,,,,,,,,,,0,,,,0,,,,,,250.0106659,,,,
,22260493.83,250.0124969,81081.22265625,-0.000184313900705655,3.08618025685709E-6,1,0.999253354069792,40.0298881530762,1.99876624869004,16.0799995064735,-0.00211393797234034,-0.000222164404609006,0.25,1.23656084813728E-5,-0.000184647567461301,1.22383659240155E-5,250.0124969,250.0124969,81071.25,81091.1953125,56.851750346256,20.5302234331432,28.224119,0,0,0,40,4449,250.02375,81081.22265625,,,,,,,,,,,,,0,,,,0,,,,,,250.0124969,,,,
,22260592.335,250.0121155,86001.38671875,-0.000198351423948904,2.63467747235761E-6,1,0.999253354069792,40.0298881530762,1.99884318080137,16.0799995064735,-0.0022623216764165,-0.000312329262882403,0.25,6.84766078566234E-6,-0.000198705304616748,6.69964257687525E-6,250.0121155,250.0121155,85993.9453125,86008.828125,56.8056342636214,20.5290090155245,28.603769,0,0,0,40,4449,250.01465,86001.38671875,,,,,,,,,,,,,0,,,,-0.00245,,,,,,250.0121155,,,,
,22260703.285,250.0123138,89349.3671875,-0.000209431054963318,3.29539628785721E-6,1,0.999253354069792,40.0298881530762,1.99878955180311,16.0799995064735,-0.0024022631391422,-0.000251151435377205,0.25,1.41641297322155E-5,-0.000209810303916785,1.40202050535886E-5,250.0123138,250.0123138,89341.984375,89356.75,56.8634747740445,20.5309548403875,28.603769,0,0,0,40,4449,250.00305,89349.3671875,,,,,,,,,,,,,0,,,,0.00245,,,,,,250.0123138,,,,
,22260798.515,250.0074768,84589.2421875,-0.000191575873033686,2.1617271212948E-6,1,0.999253354069792,40.0298881530762,1.99874750899628,16.0799995064735,-0.00219028528185736,-0.000270837472961395,0.25,9.33135198300571E-6,-0.000191919884489385,9.19307553560074E-6,250.0070801,250.0078735,84578.8671875,84599.6171875,56.8079791491791,20.5307767316705,28.603769,0,0,0,40,4449,249.99425,84589.2421875,,,,,,,,,,,,,0,,,,-0.00245,,,,,,250.0074768,,,,
,22260898.93,249.9957581,79568.09375,-0.000179676368789803,2.56671604286415E-6,1,0.999253354069792,40.0298881530762,1.99868800744673,16.0799995064735,-0.00204596528918177,-0.000301383699320057,0.25,4.57305832003163E-6,-0.000179995694023061,4.43579599820687E-6,249.9957581,249.9957581,79565.9140625,79570.2734375,56.926005055583,20.5270694665945,28.983419,0,0,0,40,4449,250.0056,79568.09375,,,,,,,,,,,,,0,,,,-0.00245,,,,,,249.9957581,,,,
,22261000.19,249.9909515,74509.69140625,-0.000159850524564691,3.03615015504814E-6,1,0.999253354069792,40.0298881530762,1.99878828192061,16.0799995064735,-0.00183064806144927,-0.000208448173178993,0.25,9.33379421555869E-6,-0.00016013888921442,9.22071658477844E-6,249.9909515,249.9909515,74501.9296875,74517.453125,56.8368994043906,20.5263654102863,28.603769,0,0,0,40,4449,250.01595,74509.69140625,,,,,,,,,,,,,0,,,,-0.0049,,,,,,249.9909515,,,,
,22261097.06,249.9900665,69666.7890625,-0.00013927782721975,2.31328209317184E-6,1,0.999253354069792,40.0298881530762,1.99876378290348,16.0799995064735,-0.00159734912614047,-0.000168220415502501,0.25,9.31451422311604E-6,-0.000139530033610837,9.21788914246604E-6,249.9900665,249.9900665,69664.28125,69669.296875,56.8666012881214,20.5291187287674,28.983419,0,0,0,40,4449,250.02215,69666.7890625,,,,,,,,,,,,,0,,,,-0.00245,,,,,,249.9900665,,,,
,22261195.21,249.9898224,64759.017578125,-0.000120730199084635,2.15629385439395E-6,1,0.999253354069792,40.0298881530762,1.9988190272427,16.0799995064735,-0.00138520773306164,-0.000142701860354151,0.25,8.3494841795525E-6,-0.000120949037401571,8.26605871350565E-6,249.9898224,249.9898224,64746.59765625,64771.4375,56.9072459711214,20.5282903915624,28.603769,0,0,0,40,4449,250.0331,64759.017578125,,,,,,,,,,,,,0,,,,-0.00245,,,,,,249.9898224,,,,
,22261294.075,249.987442,59818.322265625,-0.000107770734262871,1.60086590900865E-6,1,0.999253354069792,40.0298881530762,1.99889646341286,16.0799995064735,-0.00123265132892667,-0.000149939879986967,0.25,5.46437208468385E-6,-0.00010796446718227,5.38627383930172E-6,249.987442,249.987442,59813.4765625,59823.16796875,56.9205336559483,20.5299695617176,28.983419,0,0,0,40,4449,250.04255,59818.322265625,,,,,,,,,,,,,0,,,,0.00245,,,,,,249.987442,,,,
,22261392.81,249.99149325,54882.955078125,-8.95617947496323E-5,2.28104053466166E-6,1,0.999253354069792,40.0298881530762,1.99889236563958,16.0799995064735,-0.00102448454377138,-0.000124005090716675,0.25,4.59420187564794E-6,-8.97228182543052E-5,4.52928076559404E-6,249.9911957,249.9917908,54875.44140625,54890.46875,56.9072459711214,20.5301430770643,28.983419,0,0,0,40,4449,250.05085,54882.955078125,,,,,,,,,,,,,0,,,,-0.0049,,,,,,249.99149325,,,,
,22261489.14,249.9908142,50068.3203125,-7.07096485332943E-5,2.24829179023663E-6,1,0.999253354069792,40.0298881530762,1.99904023439128,16.0799995064735,-0.000809927099625259,-9.19559046924862E-5,0.25,4.15232632151241E-6,-7.08372030044988E-5,4.10190818995881E-6,249.9908142,249.9908142,50063.33984375,50073.30078125,57.0229269919676,20.5328575047659,28.603769,0,0,0,40,4449,250.0567,50068.3203125,,,,,,,,,,,,,0,,,,-0.00245,,,,,,249.9908142,,,,
,22261588.81,249.9844666,45088.162109375,-5.58148877821985E-5,2.49990231221397E-6,1,0.999253354069792,40.0298881530762,1.99904512753482,16.0799995064735,-0.000637667664079184,-8.21148538907323E-5,0.25,2.43733181944034E-6,-5.59148957352726E-5,2.39599334348827E-6,249.9844666,249.9844666,45075.92578125,45100.3984375,56.9846271945253,20.5341768235227,28.603769,0,0,0,40,4449,250.07325,45088.162109375,,,,,,,,,,,,,0,,,,0.00245,,,,,,249.9844666,,,,
,22261685.975,249.9915466,40230.599609375,-3.923889404088E-5,1.87087163747913E-6,1,0.999253354069792,40.0298881530762,1.99887469907017,16.0799995064735,-0.000451739486966692,-3.76334099000095E-5,0.25,3.48548037255565E-6,-3.93106388201326E-5,3.45948360595333E-6,249.9915466,249.9915466,40223.02734375,40238.171875,57.0588819038522,20.5298820926981,28.603769,0,0,0,40,4449,250.07905,40230.599609375,,,,,,,,,,,,,0,,,,-0.00245,,,,,,249.9915466,,,,
,22261783.35,249.9888611,35363.03125,-2.33810764817076E-5,9.55664664675323E-7,1,0.999253354069792,40.0298881530762,1.99900988267469,16.0799995064735,-0.000272233173857229,-4.89545406982696E-6,0.25,3.62298231905675E-6,-2.34250955342877E-5,3.61017950939671E-6,249.9888611,249.9888611,35355.44140625,35370.62109375,56.9486722826406,20.5327363815098,28.603769,0,0,0,40,4449,250.08415,35363.03125,,,,,,,,,,,,,0,,,,0,,,,,,249.9888611,,,,
,22261880.7,249.9896088,30498.107421875,-6.98832050973018E-6,1.23779268498374E-6,1,0.999253354069792,40.0298881530762,1.99904246210142,16.0799995064735,-7.66009813719331E-5,-2.89540964637664E-5,0.25,-1.34162460884083E-6,-6.9994876149782E-6,-1.34971524432464E-6,249.9896088,249.9896088,30488.275390625,30507.939453125,56.994006736756,20.5342163842738,28.603769,0,0,0,40,4449,250.09475,30498.107421875,,,,,,,,,,,,,0,,,,0.00245,,,,,,249.9896088,,,,
,22261975.765,249.9916229,25748.1552734375,8.70151864012348E-6,1.07795281793248E-6,1,0.999253354069792,40.0298881530762,1.99898374440334,16.0799995064735,9.47403533706252E-5,3.97230336242005E-5,0.25,1.99435374976589E-6,8.71515388397079E-6,2.00500502904098E-6,249.9916229,249.9916229,25745.376953125,25750.93359375,57.0260535060445,20.5331227895301,28.983419,0,0,0,40,4449,250.1015,25748.1552734375,,,,,,,,,,,,,0,,,,0,,,,,,249.9916229,,,,
,22262071.99,249.9868469,20938.380859375,2.43795072723504E-5,1.09079170565324E-6,1,0.999253354069792,40.0298881530762,1.9988917372259,16.0799995064735,0.000270007213585229,8.48807140415981E-5,0.25,3.25845160612019E-6,2.44196220542771E-5,3.28422999686633E-6,249.9868469,249.9868469,20933.234375,20943.52734375,57.1761261817368,20.5329885583297,28.603769,0,0,0,40,4449,250.1122,20938.380859375,,,,,,,,,,,,,0,,,,-0.00245,,,,,,249.9868469,,,,
,22262170.09,249.9925842,16036.0883789062,3.81923316452752E-5,7.21329062500926E-7,1,0.999253354069792,40.0298881530762,1.99898257246856,16.0799995064735,0.000432208255762943,7.99082918169022E-5,0.25,4.24089441379959E-7,3.82590128343902E-5,4.56295610422834E-7,249.9925842,249.9925842,16030.9453125,16041.2314453125,56.973684395256,20.5346696281944,28.603769,0,0,0,40,4449,250.1145,16036.0883789062,,,,,,,,,,,,,0,,,,0,,,,,,249.9925842,,,,
,22262267.04,249.9882355,11188.7836914062,5.13548847939931E-5,6.51981937817793E-7,1,0.999253354069792,40.0298881530762,1.99882200461565,16.0799995064735,0.000580389770178154,0.000111646722956364,0.25,9.4128302890349E-7,5.14442431815692E-5,9.85286278066256E-7,249.9882355,249.9882355,11183.6669921875,11193.900390625,57.0565370182945,20.5296486366084,28.983419,0,0,0,40,4449,250.1273,11188.7836914062,,,,,,,,,,,,,0,,,,0,,,,,,249.9882355,,,,
,22262363.37,249.9917145,6376.37939453125,5.98733246298168E-5,4.92720617791291E-7,1,0.999253354069792,40.0298881530762,1.99873574120289,16.0799995064735,0.000676548518741186,0.000130649557860453,0.25,1.14049397807757E-6,5.99774556335504E-5,1.19192228323434E-6,249.9917145,249.9917145,6366.517578125,6386.2412109375,57.0596635323714,20.5289599670507,28.983419,0,0,0,40,4449,250.1324,6376.37939453125,,,,,,,,,,,,,0,,,,-0.00245,,,,,,249.9917145,,,,
,22262460.84,249.9908295,1502.708984375,5.20634448427881E-5,3.48201725073407E-7,1,0.999253354069792,40.0298881530762,1.99895342391446,16.0799995064735,0.00059108633122435,9.79024662182257E-5,0.25,-3.94493149346205E-7,5.21551350719665E-5,-3.52168350436828E-7,249.9908295,249.9908295,1497.83129882813,1507.58666992187,56.9869720800829,20.5353711688777,28.983419,0,0,0,40,4449,250.1381,1502.708984375,,,,,,,,,,,,,0,,,,-0.0049,,,,,,249.9908295,,,,
,22262491.16,249.9932098,-0.365370556712151,2.60231374973589E-5,4.06574623719512E-7,1,0.999253354069792,40.0298881530762,1.99906862032588,16.0799995064735,0.000296193198821149,4.47211075581171E-5,0.25,-5.6906115967023E-7,2.60692721963503E-5,-5.48554439425431E-7,249.9932098,249.9932098,-0.380594313144684,-0.350146800279617,56.8658196596022,20.5344062191162,28.224119,0,0,0,40,4417,250.14105,-0.365370556712151,,,,,,,,,,,,,0,,,,0.00245,,,,,,249.9932098,,,,