File: data/doubleLayers/dl_1-25/ppms/data/DD205_3_FCC_100OE_2_00001.dat
[Header]
; VSM Data File (default extension .dat)
; Copyright (c) 2003-2013, Quantum Design, Inc. All rights reserved.
TITLE,
FILEOPENTIME,22756307.67,09/21/2018,6:10 pm
BYAPP,VSM,2.0,2.0
INFO,PPMS VSM Option Release 1.4.10 Build 1,APPNAME
INFO,Quantum Design Linear Motor Servo Controller,MOTOR_MODULE_NAME
INFO,3101-100 M1,MOTOR_HW_VERSION
INFO,MMC1014,MOTOR_SERIAL_NUMBER
INFO,SRV No X-over 01.03.11,MOTOR_SOFTWARE_VERSION
INFO,Quantum Design VSM Detection Module,VSM_MODULE_NAME
INFO,3101-150 F0,VSM_HW_VERSION
INFO,VSM707,VSM_SERIAL_NUMBER
INFO,VSM No X-over 01.02.05 May 20 2008 13:51:47,VSM_SOFTWARE_VERSION
INFO,704,PREAMP_SERIAL_NUMBER
INFO,822,COIL_SERIAL_NUMBER
INFO,0,MOMENT_UNITS
INFO,,SAMPLE_MATERIAL
INFO,,SAMPLE_COMMENT
INFO,,SAMPLE_MASS
INFO,,SAMPLE_VOLUME
INFO,,SAMPLE_MOLECULAR_WEIGHT
INFO,,SAMPLE_SIZE
INFO,,SAMPLE_SHAPE
DATATYPE,COMMENT,1
DATATYPE,TIME,2
STARTUPAXIS,X,2
STARTUPAXIS,Y1,5
[Data]
Comment,Time Stamp (sec),Temperature (K),Magnetic Field (Oe),Moment (emu),M. Std. Err. (emu),Transport Action,Averaging Time (sec),Frequency (Hz),Peak Amplitude (mm),Center Position (mm),Coil Signal' (mV),Coil Signal" (mV),Range (mV),M. Quad. Signal (emu),M. Raw' (emu),M. Raw" (emu),Min. Temperature (K),Max. Temperature (K),Min. Field (Oe),Max. Field (Oe),Mass (grams),Motor Lag (deg),Pressure (Torr),VSM Status (code),Motor Status (code),Measure Status (code),Measure Count,PPMS Status (code),System Temp. (K),System Field (Oe),Sample Position (deg),Bridge 1 Resistance (ohms),Bridge 1 Excitation (에),Bridge 2 Resistance (ohms),Bridge 2 Excitation (에),Bridge 3 Resistance (ohms),Bridge 3 Excitation (에),Bridge 4 Resistance (ohms),Bridge 4 Excitation (에),Signal 1 Vin (V),Signal 2 Vin (V),Digital Inputs (code),Drive 1 Iout (mA),Drive 1 Ipower (W),Drive 2 Iout (mA),Drive 2 Ipower (W),Pressure (),Map 20 (),Map 21 (),Map 22 (),Map 23 (),Map 24 (),Map 25 (),Map 26 (),Map 27 (),Map 28 (),Map 29 ()
,22757247.86,350.1017761,99.5330276489258,,,2,,,,15.0100003564358,,,,,,,350.1017761,350.1017761,99.5330276489258,99.5330276489258,,,24.427608,,,,-99999999,4373,350.6824,99.5330276489258,,,,,,,,,,,,,,,,,,,,,,,350.1017761,,,,
,22757825.4,347.4783325,99.5330276489258,1.55311669856022E-5,4.2788436243214E-7,1,0.999253354069792,40.0298881530762,1.97650881993193,14.9999996647239,0.000173970822532063,2.80210144752215E-5,0.25,-1.82712266997546E-7,1.55050503082078E-5,-1.736280037293E-7,347.4783325,347.4783325,99.5330276489258,99.5330276489258,56.8236117195637,20.5942409447604,24.807261,0,0,0,40,4374,345.554,99.5330276489258,,,,,,,,,,,,,0,,,,0.0049,,,,,,347.4783325,,,,
,22757968.805,343.9654846,99.5330276489258,1.54670621179145E-5,4.23393133696787E-7,1,0.999253354069792,40.0298881530762,1.97652560785378,14.9999996647239,0.000173263877699024,2.7972249958068E-5,0.25,-1.76385663507524E-7,1.54428931153381E-5,-1.67275903641833E-7,343.9654846,343.9654846,99.5330276489258,99.5330276489258,56.8118872917752,20.5970095113101,24.807261,0,0,0,40,4374,342.0683,99.5330276489258,,,,,,,,,,,,,0,,,,-0.0049,,,,,,343.9654846,,,,
,22758119.115,340.4881134,99.5330276489258,1.60217919830023E-5,3.96148212872818E-7,1,0.999253354069792,40.0298881530762,1.97660347292374,14.9999996647239,0.000179671578035982,2.80244996607017E-5,0.25,-2.68280326520737E-7,1.59987059799358E-5,-2.58624815233501E-7,340.462677,340.5135498,99.5330276489258,99.5330276489258,56.9158438848329,20.5985459749805,24.807261,0,0,0,40,4374,338.0485,99.5330276489258,,,,,,,,,,,,,0,,,,0.00245,,,,,,340.4881134,,,,
,22758267.955,336.9470825,99.5330276489258,1.61631635779322E-5,4.18626943571747E-7,1,0.999253354069792,40.0298881530762,1.99127030677271,14.9800004437566,0.000182610184005405,2.8207434861812E-5,0.25,-2.94577256546262E-7,1.61418523116756E-5,-2.84718411138446E-7,336.9470825,336.9470825,99.5330276489258,99.5330276489258,56.7509202672752,20.6021290925118,25.186911,0,0,0,40,4374,334.1552,99.5330276489258,,,,,,,,,,,,,0,,,,0,,,,,,336.9470825,,,,
,22758414.205,333.4701233,99.5330276489258,1.57252399116349E-5,4.30012265580777E-7,1,0.999253354069792,40.0298881530762,1.99106088374904,14.9800004437566,0.000178710224929996,2.14146629694917E-5,0.25,-8.22031400526127E-7,1.57067106055131E-5,-8.11708157707792E-7,333.4701233,333.4701233,99.5330276489258,99.5330276489258,56.7532651528329,20.606501871932,25.566563,0,0,0,40,4374,330.3438,99.5330276489258,,,,,,,,,,,,,0,,,,0,,,,,,333.4701233,,,,
,22758564.525,329.9548035,99.5330276489258,1.65110091203796E-5,3.99883719451518E-7,1,0.999253354069792,40.0298881530762,1.99094488643674,14.9800004437566,0.000186404700182389,2.96916127105859E-5,0.25,-2.23520492922883E-7,1.64931865548514E-5,-2.1334623102846E-7,329.9548035,329.9548035,99.5330276489258,99.5330276489258,56.7892200647175,20.6088236166646,26.325863,0,0,0,40,4374,326.3392,99.5330276489258,,,,,,,,,,,,,0,,,,0,,,,,,329.9548035,,,,
,22758702.845,326.4857483,99.5330276489258,1.64610503954957E-5,3.8434206147571E-7,1,0.999253354069792,40.0298881530762,1.97572561463211,15.0100002065301,0.000185161962005237,2.55999812411788E-5,0.25,-5.61812248980731E-7,1.64454780841652E-5,-5.51248019625338E-7,326.4857483,326.4857483,99.5330276489258,99.5330276489258,57.0104209356599,20.6091634137319,25.946213,0,0,0,40,4374,322.9247,99.5330276489258,,,,,,,,,,,,,0,,,,0,,,,,,326.4857483,,,,
,22758842.86,322.9976501,99.5330276489258,1.66939710018598E-5,4.35362711714302E-7,1,0.999253354069792,40.0298881530762,1.97641035975466,15.0100002065301,0.000188018922601129,2.50977890442358E-5,0.25,-6.48210601808173E-7,1.6680267034521E-5,-6.37370660034236E-7,322.9976501,322.9976501,99.5330276489258,99.5330276489258,56.9166255133522,20.6042386985768,25.566563,0,0,0,40,4374,319.4086,99.5330276489258,,,,,,,,,,,,,0,,,,0.00245,,,,,,322.9976501,,,,
,22758986.22,319.4647217,99.5330276489258,1.68791825554938E-5,4.18518884672926E-7,1,0.999253354069792,40.0298881530762,1.97645717726918,15.0100002065301,0.000190229487019451,2.48221413194753E-5,0.25,-7.05394909433251E-7,1.68674561197256E-5,-6.94340923836937E-7,319.4647217,319.4647217,99.5330276489258,99.5330276489258,56.8298647477175,20.6056685643894,26.325863,0,0,0,40,4374,315.7939,99.5330276489258,,,,,,,,,,,,,0,,,,0,,,,,,319.4647217,,,,
,22759107.39,316.4760132,99.5330276489258,1.70769997087216E-5,3.13366436714761E-7,1,0.999253354069792,40.0298881530762,2.00240228376837,15.03000035882,0.00019412568457434,2.98498838433391E-5,0.25,-3.23733882506665E-7,1.70666917377609E-5,-3.12742265751494E-7,316.4760132,316.4760132,99.5330276489258,99.5330276489258,56.7470121246791,20.6071275263167,25.946213,0,0,0,40,4374,312.7198,99.5330276489258,,,,,,,,,,,,,0,,,,-0.00245,,,,,,316.4760132,,,,
,22759250.405,312.98146055,99.5330276489258,1.68696826993391E-5,4.0781082663058E-7,1,0.999253354069792,40.0298881530762,2.00240977993313,15.03000035882,0.000191948424242101,2.85962279713042E-5,0.25,-3.98932645903984E-7,1.68616353294456E-5,-3.87927863823544E-7,312.9546814,313.0082397,99.5330276489258,99.5330276489258,56.8087607776983,20.6085701368685,25.946213,0,0,0,40,4374,309.11085,99.5330276489258,,,,,,,,,,,,,0,,,,0,,,,,,312.98146055,,,,
,22759391.64,309.493515,99.5330276489258,1.7985796392645E-5,3.96598346523972E-7,1,0.999253354069792,40.0298881530762,2.00236358747766,15.03000035882,0.000204299724517369,3.26213110710258E-5,0.25,-2.37536061363534E-7,1.79793204487379E-5,-2.25765276112674E-7,309.4661865,309.5208435,99.5330276489258,99.5330276489258,56.8595666314483,20.6091254866671,25.946213,0,0,0,40,4374,305.5477,99.5330276489258,,,,,,,,,,,,,0,,,,0,,,,,,309.493515,,,,
,22759515.05,306.4534302,99.5330276489258,1.83310679707581E-5,4.3788707950773E-7,1,0.999253354069792,40.0298881530762,2.00236041955251,15.0499995797873,0.000208215720422033,3.34133712116156E-5,0.25,-2.27922976327565E-7,1.83264388851255E-5,-2.15809391326546E-7,306.4534302,306.4534302,99.5330276489258,99.5330276489258,56.9299131981791,20.6046006347672,26.325863,0,0,0,40,4374,302.4251,99.5330276489258,,,,,,,,,,,,,0,,,,0,,,,,,306.4534302,,,,
,22759655.04,302.9994812,99.5330276489258,1.8526590832432E-5,3.85547424033286E-7,1,0.999253354069792,40.0298881530762,2.00236161487604,15.0499995797873,0.000210513730211067,3.34788577441295E-5,0.25,-2.56555898299299E-7,1.85242086775476E-5,-2.44165925578406E-7,302.9994812,302.9994812,99.5330276489258,99.5330276489258,57.0135474497368,20.6063005497597,26.705515,0,0,0,40,4374,298.902,99.5330276489258,,,,,,,,,,,,,0,,,,0,,,,,,302.9994812,,,,
,22759798.75,299.450592,99.5330276489258,1.87395667740587E-5,3.95123473723206E-7,1,0.999253354069792,40.0298881530762,2.00137479845722,15.0499995797873,0.000212103478898512,3.82213960417719E-5,0.25,1.25895570565044E-7,1.87392695840277E-5,1.38575491684551E-7,299.450592,299.450592,99.5330276489258,99.5330276489258,56.9572701963522,20.6206917078066,26.325863,0,0,0,40,4374,295.2659,99.5330276489258,,,,,,,,,,,,,0,,,,0.0049,,,,,,299.450592,,,,
,22759919.005,296.4840393,99.5330276489258,1.88099824580208E-5,4.11156028662069E-7,1,0.999253354069792,40.0298881530762,1.9755076439407,15.0800002738833,0.00021131400020781,3.20102041442707E-5,0.25,-3.99580815220531E-7,1.88120354457688E-5,-3.8673079887597E-7,296.4840393,296.4840393,99.5330276489258,99.5330276489258,56.6829185861022,20.6191559370303,26.705515,0,0,0,40,4374,292.23335,99.5330276489258,,,,,,,,,,,,,0,,,,0,,,,,,296.4840393,,,,
,22760059.15,292.99394225,99.5330276489258,1.84536299466123E-5,3.68892052171646E-7,1,0.999253354069792,40.0298881530762,1.97544007778202,15.0800002738833,0.000207365674043385,3.1199726571637E-5,0.25,-4.10682164693824E-7,1.84579630178799E-5,-3.97943002755678E-7,292.9690552,293.0188293,99.5330276489258,99.5330276489258,56.9541436822753,20.6172464050946,27.085165,0,0,0,40,4374,288.71455,99.5330276489258,,,,,,,,,,,,,0,,,,-0.00245,,,,,,292.99394225,,,,
,22760201.895,289.4878845,99.5330276489258,1.93604228797621E-5,3.98054516823934E-7,1,0.999253354069792,40.0298881530762,1.97530858401112,15.0800002738833,0.00021653100075169,3.87238149917687E-5,0.25,1.03917796413091E-7,1.93670241512571E-5,1.17617774703919E-7,289.4878845,289.4878845,99.5330276489258,99.5330276489258,56.9095908566791,20.6214743662649,26.705515,0,0,0,40,4374,285.12085,99.5330276489258,,,,,,,,,,,,,0,,,,0,,,,,,289.4878845,,,,
,22760343.815,285.9591064,99.5330276489258,1.90019485319211E-5,3.87910916611924E-7,1,0.999253354069792,40.0298881530762,1.97519861033128,15.1100000366569,0.00021216656220302,4.01484769953348E-5,0.25,2.92840687814258E-7,1.90106900024395E-5,3.06595132899919E-7,285.9591064,285.9591064,99.5330276489258,99.5330276489258,56.8884868866599,20.6210971622737,26.325863,0,0,0,40,4374,281.54705,99.5330276489258,,,,,,,,,,,,,0,,,,0.00245,,,,,,285.9591064,,,,
,22760484.23,282.4879456,99.5330276489258,1.92360470016985E-5,3.97712345748719E-7,1,0.999253354069792,40.0298881530762,1.97533301926593,15.1100000366569,0.000215129263437464,3.88723289922234E-5,0.25,1.37414160222071E-7,1.9247399374922E-5,1.51490668135869E-7,282.4879456,282.4879456,99.5330276489258,99.5330276489258,56.872072687756,20.6305327267287,27.085165,0,0,0,40,4374,278.0289,99.5330276489258,,,,,,,,,,,,,0,,,,-0.0049,,,,,,282.4879456,,,,
,22760624.055,278.9813538,99.5330276489258,1.99987372416413E-5,4.66687577423601E-7,1,0.999253354069792,40.0298881530762,1.97563883567835,15.1100000366569,0.000224925093875652,3.34727600023547E-5,0.25,-4.78031317313278E-7,2.00135077749857E-5,-4.63602178451745E-7,278.9813538,278.9813538,99.5330276489258,99.5330276489258,57.0924919301791,20.6272048030822,26.325863,0,0,0,40,4374,274.5234,99.5330276489258,,,,,,,,,,,,,0,,,,-0.00245,,,,,,278.9813538,,,,
,22760766.39,275.4549866,99.5330276489258,1.97317915234748E-5,3.78593558240833E-7,1,0.999253354069792,40.0298881530762,2.00155392442648,15.1399997994304,0.00022409839710382,3.70888060815032E-5,0.25,-1.50510682896179E-7,1.97486195233625E-5,-1.35830512643326E-7,275.4549866,275.4549866,99.5330276489258,99.5330276489258,56.8032893780637,20.6260817697328,27.085165,0,0,0,40,4374,270.96215,99.5330276489258,,,,,,,,,,,,,0,,,,-0.0049,,,,,,275.4549866,,,,
,22760905.61,271.9474487,99.5330276489258,1.9678650326732E-5,3.61008081407549E-7,1,0.999253354069792,40.0298881530762,2.00152974915916,15.1399997994304,0.000224178511553978,3.31964843991077E-5,0.25,-4.85031668536709E-7,1.96981587864705E-5,-4.70505504933855E-7,271.9474487,271.9474487,99.5330276489258,99.5330276489258,57.0455942190253,20.6273139701783,26.325863,0,0,0,40,4374,267.50655,99.5330276489258,,,,,,,,,,,,,0,,,,0,,,,,,271.9474487,,,,
,22761043.495,268.4806519,99.5330276489258,1.97645916075495E-5,3.94012383060446E-7,1,0.999253354069792,40.0298881530762,2.00130105068804,15.1399997994304,0.000225079489386021,3.38116949871217E-5,0.25,-4.45974809984582E-7,1.97866070718528E-5,-4.3116408756919E-7,268.4806519,268.4806519,99.5330276489258,99.5330276489258,56.7438856106022,20.6306610923994,26.325863,0,0,0,40,4374,264.0706,99.5330276489258,,,,,,,,,,,,,0,,,,0,,,,,,268.4806519,,,,
,22761162.775,265.4911499,99.5330276489258,2.00563762408344E-5,4.45206639242181E-7,1,0.999253354069792,40.0298881530762,1.97502310966835,15.1699995622039,0.000224752806788891,3.85485317680427E-5,0.25,-3.63967761106542E-8,2.00805340895962E-5,-2.07028623978974E-8,265.4911499,265.4911499,99.5330276489258,99.5330276489258,57.4473512779099,20.6300910817176,26.325863,0,0,0,40,4374,261.11,99.5330276489258,,,,,,,,,,,,,0,,,,0,,,,,,265.4911499,,,,
,22761303.78,261.9701843,99.5330276489258,2.04485701425487E-5,4.48734134793811E-7,1,0.999253354069792,40.0298881530762,1.97473538538622,15.1699995622039,0.000230305071812784,3.26088927617583E-5,0.25,-6.3482370319531E-7,2.04762417825155E-5,-6.19358273226097E-7,261.9701843,261.9701843,99.5330276489258,99.5330276489258,57.0057311645445,20.6426938214728,25.946213,0,0,0,40,4374,257.6014,99.5330276489258,,,,,,,,,,,,,0,,,,0.00245,,,,,,261.9701843,,,,
,22761444.04,258.4427795,99.5330276489258,2.04548974875545E-5,4.03900545467567E-7,1,0.999253354069792,40.0298881530762,1.97507771247365,15.1699995622039,0.000228890539582106,4.15836119736341E-5,0.25,1.63877502723424E-7,2.04845025517041E-5,1.80700787014097E-7,258.4427795,258.4427795,99.5330276489258,99.5330276489258,56.7212183835445,20.6385369895285,26.325863,0,0,0,40,4374,254.095,99.5330276489258,,,,,,,,,,,,,0,,,,0,,,,,,258.4427795,,,,
,22761584.93,254.9477081,99.5330276489258,2.0726557227244E-5,3.29249169552333E-7,1,0.999253354069792,40.0298881530762,1.97513993422057,15.2200004085898,0.000232946233244424,3.64905281648439E-5,0.25,-3.38527621259611E-7,2.0759536775282E-5,-3.21972303143834E-7,254.9477081,254.9477081,99.5330276489258,99.5330276489258,56.8103240347368,20.6291699709219,26.325863,0,0,0,40,4374,250.5782,99.5330276489258,,,,,,,,,,,,,0,,,,0,,,,,,254.9477081,,,,
,22761723.625,251.4883728,99.5330276489258,2.07375157404178E-5,3.48304086655492E-7,1,0.999253354069792,40.0298881530762,1.9751699448742,15.2200004085898,0.000233170740429031,3.61143725214823E-5,0.25,-3.74719195028321E-7,2.07730830578144E-5,-3.5796864192154E-7,251.4883728,251.4883728,99.5330276489258,99.5330276489258,57.8092452823138,20.6317963779355,26.325863,0,0,0,40,4374,247.11035,99.5330276489258,,,,,,,,,,,,,0,,,,0,,,,,,251.4883728,,,,
,22761863.585,247.9763947,99.5330276489258,2.0494254382496E-5,3.29229442827341E-7,1,0.999253354069792,40.0298881530762,1.97557120719811,15.2200004085898,0.000231302657749261,3.11253768290482E-5,0.25,-7.78804171672488E-7,2.05322939847449E-5,-7.6274334917319E-7,247.9763947,247.9763947,99.5330276489258,99.5330276489258,56.9744660237753,20.633720881635,25.946213,0,0,0,40,4374,243.61145,99.5330276489258,,,,,,,,,,,,,0,,,,0,,,,,,247.9763947,,,,
,22762002.26,244.4731293,99.5330276489258,2.04707013323363E-5,3.14470991988013E-7,1,0.999253354069792,40.0298881530762,2.00148425780892,15.259999781847,0.000233494129118626,3.41614957624612E-5,0.25,-5.42286786862646E-7,2.05110218516377E-5,-5.25578080043472E-7,244.4731293,244.4731293,99.5330276489258,99.5330276489258,56.7837486650829,20.6336274743438,26.325863,0,0,0,40,4374,240.1537,99.5330276489258,,,,,,,,,,,,,0,,,,0.0049,,,,,,244.4731293,,,,
,22762141.805,240.9817352,99.5330276489258,2.0597414803198E-5,3.476138472714E-7,1,0.999253354069792,40.0298881530762,2.00152529566476,15.259999781847,0.000234356522919827,3.79300075643862E-5,0.25,-2.33146706164504E-7,2.06402313608781E-5,-2.15437636413884E-7,240.9817352,240.9817352,99.5330276489258,99.5330276489258,57.0776409883137,20.6407552162372,25.946213,0,0,0,40,4374,236.6779,99.5330276489258,,,,,,,,,,,,,0,,,,0.00245,,,,,,240.9817352,,,,
,22762281.79,237.4749451,99.5330276489258,2.06100335603651E-5,3.59707423071095E-7,1,0.999253354069792,40.0298881530762,2.00189598165236,15.259999781847,0.000234764121443925,3.68465704216671E-5,0.25,-3.32042149533255E-7,2.06554841965505E-5,-3.14236555187442E-7,237.4749451,237.4749451,99.5330276489258,99.5330276489258,57.027616763083,20.6368536655902,25.566563,0,0,0,40,4374,233.1782,99.5330276489258,,,,,,,,,,,,,0,,,,-0.0049,,,,,,237.4749451,,,,
,22762423.185,233.9319,99.5330276489258,2.08851901832812E-5,3.06137207712778E-7,1,0.999253354069792,40.0298881530762,1.97610713339116,15.3099996969104,0.000235359082987425,3.48130565088425E-5,0.25,-5.21349616743065E-7,2.09339852136795E-5,-5.03425260108239E-7,233.9319,233.9319,99.5330276489258,99.5330276489258,56.9619599674676,20.6314578564447,25.566563,0,0,0,40,4374,229.64715,99.5330276489258,,,,,,,,,,,,,0,,,,0,,,,,,233.9319,,,,
,22762560.755,230.493988,99.5330276489258,2.12321197410646E-5,3.98068844849745E-7,1,0.999253354069792,40.0298881530762,1.97604727359874,15.3099996969104,0.000238173654866188,4.1828286855998E-5,0.25,4.29741535255626E-8,2.12837140470976E-5,6.28862330569419E-8,230.493988,230.493988,99.5330276489258,99.5330276489258,56.9861904515637,20.6307521749108,25.566563,0,0,0,40,4374,226.2077,99.5330276489258,,,,,,,,,,,,,0,,,,0,,,,,,230.493988,,,,
,22762702.02,226.9776611,99.5330276489258,2.07528598664585E-5,3.20545561345362E-7,1,0.999253354069792,40.0298881530762,1.97588411571236,15.3099996969104,0.000233211769860853,3.8554075105791E-5,0.25,-1.66149342789633E-7,2.08059857276731E-5,-1.46838645336212E-7,226.9776611,226.9776611,99.5330276489258,99.5330276489258,57.068261446083,20.6336766183662,25.946213,0,0,0,40,4374,222.6751,99.5330276489258,,,,,,,,,,,,,0,,,,-0.0049,,,,,,226.9776611,,,,
,22762820.77,223.9941864,99.5330276489258,2.0954220739856E-5,3.43807328966985E-7,1,0.999253354069792,40.0298881530762,1.97588495420474,15.3500000014901,0.000236431437436036,3.35575246330743E-5,0.25,-6.46974268809007E-7,2.10104569500098E-5,-6.2843696903783E-7,223.9941864,223.9941864,99.5330276489258,99.5330276489258,56.7110572127945,20.6276486701887,25.186911,0,0,0,40,4374,219.7155,99.5330276489258,,,,,,,,,,,,,0,,,,0,,,,,,223.9941864,,,,
,22762960.13,220.4750595,99.5330276489258,2.07196169097152E-5,3.96173427212428E-7,1,0.999253354069792,40.0298881530762,1.97569067289075,15.3500000014901,0.000233358395197971,3.56706875646303E-5,0.25,-4.18436430337786E-7,2.077748593472E-5,-3.99176751908322E-7,220.4473572,220.5027618,99.5330276489258,99.5330276489258,57.0760777312753,20.6344258970747,25.186911,0,0,0,40,4374,216.2618,99.5330276489258,,,,,,,,,,,,,0,,,,0,,,,,,220.4750595,,,,
,22763100.065,216.9558105,99.5330276489258,2.06522017465008E-5,3.56365868898457E-7,1,0.999253354069792,40.0298881530762,1.97570731843976,15.3500000014901,0.000232731835931117,3.49640242511503E-5,0.25,-4.70499682991269E-7,2.07123868303401E-5,-4.51094967799467E-7,216.9558105,216.9558105,99.5330276489258,99.5330276489258,57.047939104583,20.6379049829101,25.186911,0,0,0,40,4374,212.7716,99.5330276489258,,,,,,,,,,,,,0,,,,0,,,,,,216.9558105,,,,
,22763217.115,213.9919891,99.5330276489258,2.03325077301861E-5,3.97215349299296E-7,1,0.999253354069792,40.0298881530762,2.00156119978468,15.3999999165535,0.000230741088539109,4.2191059155967E-5,0.25,1.81761613603331E-7,2.03931208022969E-5,2.0309922353006E-7,213.9919891,213.9919891,99.5330276489258,99.5330276489258,57.088583787583,20.6311098999832,24.807261,0,0,0,40,4374,209.8651,99.5330276489258,,,,,,,,,,,,,0,,,,-0.0049,,,,,,213.9919891,,,,
,22763359.515,210.4320984,99.5330276489258,2.07492187688849E-5,2.71473121636849E-7,1,0.999253354069792,40.0298881530762,2.00144867981992,15.3999999165535,0.000236052806928453,3.97891229932639E-5,0.25,-1.0259252530042E-7,2.08138163566152E-5,-8.12353255897806E-8,210.4320984,210.4320984,99.5330276489258,99.5330276489258,57.0088576786214,20.6363940218714,24.807261,0,0,0,40,4374,206.3044,99.5330276489258,,,,,,,,,,,,,0,,,,0,,,,,,210.4320984,,,,
,22763498.975,206.9299469,99.5330276489258,2.08414447873593E-5,3.02112760719306E-7,1,0.999253354069792,40.0298881530762,2.00141191586783,15.3999999165535,0.000237398696359235,3.83942596594497E-5,0.25,-2.42115158856707E-7,2.09088757978266E-5,-2.20655091428468E-7,206.9299469,206.9299469,99.5330276489258,99.5330276489258,56.9174071418714,20.6386538468347,24.807261,0,0,0,40,4374,202.8226,99.5330276489258,,,,,,,,,,,,,0,,,,0,,,,,,206.9299469,,,,
,22763637.385,203.4640045,99.5330276489258,2.05127407398353E-5,3.47224519707915E-7,1,0.999253354069792,40.0298881530762,2.0013680020014,15.4499998316169,0.000234023150027387,3.5793288365897E-5,0.25,-4.14593941377463E-7,2.05816177019268E-5,-3.93609432428628E-7,203.4640045,203.4640045,99.5330276489258,99.5330276489258,57.1425161554099,20.6342698766477,24.047956,0,0,0,40,4374,199.3697,99.5330276489258,,,,,,,,,,,,,0,,,,0,,,,,,203.4640045,,,,
,22763777.025,199.9850464,99.5330276489258,2.04806935409503E-5,2.85110291760401E-7,1,0.999253354069792,40.0298881530762,2.00133635535051,15.4499998316169,0.000233318508212771,3.78228971769743E-5,0.25,-2.31325474680245E-7,2.05515627533931E-5,-2.09285313149234E-7,199.9850464,199.9850464,99.5330276489258,99.5330276489258,56.8150138058522,20.6425539036015,23.668306,0,0,0,40,4374,195.87955,99.5330276489258,,,,,,,,,,,,,0,,,,0.00245,,,,,,199.9850464,,,,
,22763917.92,196.457016,99.5330276489258,2.06026442609042E-5,3.5752553307871E-7,1,0.999253354069792,40.0298881530762,2.00129601092777,15.4499998316169,0.000234766173170955,3.78413249219186E-5,0.25,-2.51732332615362E-7,2.06762783481553E-5,-2.29118063209441E-7,196.457016,196.457016,99.5330276489258,99.5330276489258,56.7798405224868,20.6424018599879,23.668306,0,0,0,40,4374,192.3671,99.5330276489258,,,,,,,,,,,,,0,,,,0.00245,,,,,,196.457016,,,,
,22764057.08,192.9535675,99.5330276489258,2.03099391292493E-5,3.33444344003351E-7,1,0.999253354069792,40.0298881530762,2.00113612561073,15.4999997466803,0.000231960924203447,3.42997836532751E-5,0.25,-5.12983765404271E-7,2.0385083960452E-5,-4.91140336301296E-7,192.9535675,192.9535675,99.5330276489258,99.5330276489258,57.0323065341983,20.6404353279492,24.047956,0,0,0,40,4374,188.8942,99.5330276489258,,,,,,,,,,,,,0,,,,0.0049,,,,,,192.9535675,,,,
,22764196.165,189.4894714,99.5330276489258,2.05110295100507E-5,3.15000056557025E-7,1,0.999253354069792,40.0298881530762,2.00117504365118,15.4999997466803,0.000233624725422057,3.84556699736601E-5,0.25,-1.83458705524317E-7,2.05887419576109E-5,-1.59605662509719E-7,189.4894714,189.4894714,99.5330276489258,99.5330276489258,56.9900985941599,20.6441096312545,23.288654,0,0,0,40,4374,185.4172,99.5330276489258,,,,,,,,,,,,,0,,,,-0.0049,,,,,,189.4894714,,,,
,22764336.2,185.9759216,99.5330276489258,2.06814267157402E-5,3.37066574493322E-7,1,0.999253354069792,40.0298881530762,2.00119406837723,15.4999997466803,0.000235541272306536,3.9077862210989E-5,0.25,-1.59384815659655E-7,2.07619899172211E-5,-1.3462996537476E-7,185.9759216,185.9759216,99.5330276489258,99.5330276489258,56.7900016932368,20.646049012918,23.288654,0,0,0,40,4374,181.9268,99.5330276489258,,,,,,,,,,,,,0,,,,-0.00245,,,,,,185.9759216,,,,
,22764455.01,182.9822235,99.5330276489258,2.03274062124507E-5,3.11957596802366E-7,1,0.999253354069792,40.0298881530762,1.97536883664546,15.5600002035499,0.000229305385963031,3.43195267149607E-5,0.25,-4.79362318619674E-7,2.04088438024014E-5,-4.55782151297268E-7,182.9822235,182.9822235,99.5330276489258,99.5330276489258,56.946327397083,20.6349501966111,22.909004,0,0,0,40,4374,178.9687,99.5330276489258,,,,,,,,,,,,,0,,,,-0.00245,,,,,,182.9822235,,,,
,22764597.985,179.4832535,99.5330276489258,2.02419111987659E-5,3.96325580766014E-7,1,0.999253354069792,40.0298881530762,1.97523762910311,15.5600002035499,0.000227961924478589,3.6410284231284E-5,0.25,-2.79232567368893E-7,2.03248780795459E-5,-2.54284401133857E-7,179.4548798,179.5116272,99.5330276489258,99.5330276489258,56.7384142109675,20.6378540273445,22.909004,0,0,0,40,4374,175.31605,99.5330276489258,,,,,,,,,,,,,0,,,,0.00245,,,,,,179.4832535,,,,
,22764733.33,175.9947205,99.5330276489258,2.02714279954506E-5,3.02413516748721E-7,1,0.999253354069792,40.0298881530762,1.97534341274966,15.5600002035499,0.000228508811151576,3.54382858104897E-5,0.25,-3.72039326012383E-7,2.03567331686471E-5,-3.46793550174568E-7,175.9947205,175.9947205,99.5330276489258,99.5330276489258,57.2785195177561,20.6435376519454,22.529354,0,0,0,40,4374,172.0272,99.5330276489258,,,,,,,,,,,,,0,,,,0.0049,,,,,,175.9947205,,,,
,22764851.9,172.9901276,99.5330276489258,2.047776550291E-5,3.67387183750864E-7,1,0.999253354069792,40.0298881530762,2.00088927355536,15.6199997290969,0.000233679225657124,3.63934079012363E-5,0.25,-3.6334563252956E-7,2.05657163519552E-5,-3.37179288186988E-7,172.9901276,172.9901276,99.5330276489258,99.5330276489258,57.1589303543137,20.635565488233,22.529354,0,0,0,40,4374,169.09115,99.5330276489258,,,,,,,,,,,,,0,,,,0.0049,,,,,,172.9901276,,,,
,22764991.265,169.4696045,99.5330276489258,2.03777232562159E-5,3.26774097798129E-7,1,0.999253354069792,40.0298881530762,2.00087252970271,15.6299993395805,0.000232875528314946,3.4400634416249E-5,0.25,-5.22181119592954E-7,2.04675246170718E-5,-4.96086312201966E-7,169.4696045,169.4696045,99.5330276489258,99.5330276489258,56.9877537086022,20.6409750273423,22.529354,0,0,0,40,4374,165.6419,99.5330276489258,,,,,,,,,,,,,0,,,,0.0049,,,,,,169.4696045,,,,
,22765130.155,165.949173,99.5330276489258,2.06906967141734E-5,3.01965320965318E-7,1,0.999253354069792,40.0298881530762,2.00072869674922,15.6199997290969,0.000236580877212738,3.4231750102866E-5,0.25,-5.92427014358202E-7,2.07840210294404E-5,-5.65404391974442E-7,165.949173,165.949173,99.5330276489258,99.5330276489258,57.2363115777176,20.6408868364732,22.149702,0,0,0,40,4374,162.19575,99.5330276489258,,,,,,,,,,,,,0,,,,0,,,,,,165.949173,,,,
touchdown = 9.89999994635582 mm,22765262.785,162.6243591,99.5330276489258,2.00694742152437E-5,3.53418414432514E-7,1,0.999253354069792,40.0298881530762,2.00074280115845,15.6800001859665,0.000229407817351603,3.37383096386655E-5,0.25,-5.28805648086005E-7,2.01617737230991E-5,-5.01592080559616E-7,162.6243591,162.6243591,99.5330276489258,99.5330276489258,56.7141837268714,20.6361382834611,21.770052,0,0,0,40,4374,158.902,99.5330276489258,,,,,,,,,,,,,0,,,,0,,,,,,162.6243591,,,,
,22765388.47,159.47424315,99.5330276489258,2.02411223595331E-5,3.21772494615139E-7,1,0.999253354069792,40.0298881530762,2.00076081289162,15.6800001859665,0.000231112976225926,3.56294381950749E-5,0.25,-3.93633458024482E-7,2.0335722558198E-5,-3.64720993068192E-7,159.4447021,159.5037842,99.5330276489258,99.5330276489258,56.9822823089676,20.650424852228,22.149702,0,0,0,40,4374,155.7672,99.5330276489258,,,,,,,,,,,,,0,,,,0,,,,,,159.47424315,,,,
,22765528.535,155.9658813,99.5330276489258,2.02892181362488E-5,3.33861260905052E-7,1,0.999253354069792,40.0298881530762,2.00078717710643,15.6800001859665,0.000231693229494312,3.56782464878537E-5,0.25,-3.99065910878517E-7,2.03859217383674E-5,-3.69115843606845E-7,155.9658813,155.9658813,99.5330276489258,99.5330276489258,57.3637170263522,20.6541314316065,21.3904,0,0,0,40,4374,152.2767,99.5330276489258,,,,,,,,,,,,,0,,,,0.00245,,,,,,155.9658813,,,,
,22765664.77,152.5275879,99.5330276489258,,,2,,,,15.7500004032254,,,,,,,152.5275879,152.5275879,99.5330276489258,99.5330276489258,,,21.770052,,,,-99999999,4374,148.8898,99.5330276489258,,,,,,,,,,,,,,,,,,,,,,,152.5275879,,,,
,22765785.205,149.4964981,99.5330276489258,2.04608211869325E-5,2.44891846452805E-7,1,0.999253354069792,40.0298881530762,2.00076752961989,15.7399997115135,0.000233834264579409,3.51504381259839E-5,0.25,-4.7788577603874E-7,2.05618133268997E-5,-4.46026800186841E-7,149.4694061,149.5235901,99.5330276489258,99.5330276489258,57.1175040427945,20.6490572623264,21.01075,0,0,0,40,4374,145.8967,99.5330276489258,,,,,,,,,,,,,0,,,,0,,,,,,149.4964981,,,,
,22765924.01,145.9831085,99.5330276489258,2.07708515450347E-5,2.61686545425928E-7,1,0.999253354069792,40.0298881530762,2.00076354670644,15.7399997115135,0.000237604312809281,3.44972747248367E-5,0.25,-5.90820702958196E-7,2.08753217325859E-5,-5.57775086121541E-7,145.9831085,145.9831085,99.5330276489258,99.5330276489258,56.8095424062176,20.6504099397491,21.3904,0,0,0,40,4374,142.446,99.5330276489258,,,,,,,,,,,,,0,,,,0,,,,,,145.9831085,,,,
,22766076.67,142.2000122,99.5330276489258,,,2,,,,15.8199995392561,,,,,,,142.2000122,142.2000122,99.5330276489258,99.5330276489258,,,21.3904,,,,-99999999,4374,138.6318,99.5330276489258,,,,,,,,,,,,,,,,,,,,,,,142.2000122,,,,
,22766203.065,138.9997253,99.5330276489258,2.06041036572443E-5,3.28298297287151E-7,1,0.999253354069792,40.0298881530762,2.00054230725837,15.8099997788668,0.000235365933067999,3.61904250744096E-5,0.25,-4.15997439108166E-7,2.07106998153594E-5,-3.79586210980229E-7,138.9997253,138.9997253,99.5330276489258,99.5330276489258,56.7212183835445,20.6556695054738,21.3904,0,0,0,40,4374,135.4917,99.5330276489258,,,,,,,,,,,,,0,,,,0.0049,,,,,,138.9997253,,,,
,22766343.21,135.4705353,99.5330276489258,2.05949681819053E-5,2.64275761499553E-7,1,0.999253354069792,40.0298881530762,2.00065235213336,15.8099997788668,0.000234105331223679,4.29728795665112E-5,0.25,1.79366080275195E-7,2.07018892823965E-5,2.20435612032432E-7,135.4705353,135.4705353,99.5330276489258,99.5330276489258,56.7571732954291,20.6593157588108,20.631098,0,0,0,40,4374,132.0078,99.5330276489258,,,,,,,,,,,,,0,,,,-0.0049,,,,,,135.4705353,,,,
,22766488.84,131.775528,99.5330276489258,,,2,,,,15.8899996066093,,,,,,,131.775528,131.775528,99.5330276489258,99.5330276489258,,,21.01075,,,,-99999999,4374,128.4041,99.5330276489258,,,,,,,,,,,,,,,,,,,,,,,131.775528,,,,
,22766620.195,128.4758606,99.5330276489258,2.01324906651471E-5,3.2242583116797E-7,1,0.999253354069792,40.0298881530762,1.97471793860414,15.87999984622,0.00022715062373543,3.51576682402038E-5,0.25,-3.91550853012129E-7,2.02408175989624E-5,-3.50910471128859E-7,128.4758606,128.4758606,99.5330276489258,99.5330276489258,57.2480360055061,20.6521010889952,20.631098,0,0,0,40,4374,125.1474,99.5330276489258,,,,,,,,,,,,,0,,,,0.0049,,,,,,128.4758606,,,,
,22766758.57,124.9780807,99.5330276489258,2.03843944414637E-5,2.9443588447798E-7,1,0.999253354069792,40.0298881530762,1.97465833158758,15.87999984622,0.000229979607034137,3.57141588819554E-5,0.25,-3.88171412473779E-7,2.04952693550394E-5,-3.44994985353766E-7,124.9780807,124.9780807,99.5330276489258,99.5330276489258,56.9650864815445,20.6540929516455,20.631098,0,0,0,40,4374,121.7227,99.5330276489258,,,,,,,,,,,,,0,,,,0,,,,,,124.9780807,,,,
,22766899.23,121.4420319,99.5330276489258,,,2,,,,15.9500000634789,,,,,,,121.4420319,121.4420319,99.5330276489258,99.5330276489258,,,20.631098,,,,-99999999,4374,118.2311,99.5330276489258,,,,,,,,,,,,,,,,,,,,,,,121.4420319,,,,
,22767015.04,118.4750786,99.5330276489258,2.06428977914022E-5,3.03158377885436E-7,1,0.999253354069792,40.0298881530762,2.00013882376321,15.939999371767,0.000235359493871801,3.90606845572351E-5,0.25,-1.82599524025201E-7,2.07566024932759E-5,-1.3348088767224E-7,118.4481354,118.5020218,99.5330276489258,99.5330276489258,57.0620084179291,20.6528610711295,20.631098,0,0,0,40,4374,115.3761,99.5330276489258,,,,,,,,,,,,,0,,,,0,,,,,,118.4750786,,,,
,22767151.755,114.9874649,99.5330276489258,2.05068798987363E-5,3.43280053355817E-7,1,0.999253354069792,40.0298881530762,2.00028306978347,15.9499999135733,0.000233766140102944,3.91939157840068E-5,0.25,-1.50005988226007E-7,2.06205478027255E-5,-9.84762788013195E-8,114.9874649,114.9874649,99.5330276489258,99.5330276489258,56.6274229612368,20.6572390560662,20.631098,0,0,0,40,4374,112.0043,99.5330276489258,,,,,,,,,,,,,0,,,,0,,,,,,114.9874649,,,,
,22767289.76,111.4976959,99.5330276489258,2.05668967428791E-5,2.80249180032123E-7,1,0.999253354069792,40.0298881530762,2.00021441019162,15.939999371767,0.000234718588555502,3.77732185942143E-5,0.25,-2.88146794303095E-7,2.06818590890659E-5,-2.3437116165106E-7,111.4729843,111.5224075,99.5330276489258,99.5330276489258,57.1511140691214,20.6582560785077,20.631098,0,0,0,40,4374,108.59185,99.5330276489258,,,,,,,,,,,,,0,,,,-0.00245,,,,,,111.4976959,,,,
,22767408.635,108.4740791,99.5330276489258,2.05613444823155E-5,3.13336178580336E-7,1,0.999253354069792,40.0298881530762,2.00030089481721,16.0199999809265,0.000234886934308927,3.65236662223312E-5,0.25,-3.99799873607721E-7,2.06769510498171E-5,-3.43974842958484E-7,108.447731,108.5004272,99.5330276489258,99.5330276489258,56.5727089648906,20.6623288592909,19.871798,0,0,0,40,4374,105.661,99.5330276489258,,,,,,,,,,,,,0,,,,-0.00245,,,,,,108.4740791,,,,
,22767546.445,104.98192975,99.5330276489258,2.05340446396547E-5,3.34497242685298E-7,1,0.999253354069792,40.0298881530762,2.00007458127562,16.0199999809265,0.000234803460952536,3.50403378363408E-5,0.25,-5.28384127237341E-7,2.06500787639679E-5,-4.69954665793629E-7,104.9560623,105.0077972,99.5330276489258,99.5330276489258,57.0721695886791,20.6648029906745,20.251448,0,0,0,40,4374,102.2769,99.5330276489258,,,,,,,,,,,,,0,,,,0,,,,,,104.98192975,,,,
,22767683.98,101.4941483,99.5330276489258,2.07755927613275E-5,3.03713742238371E-7,1,0.999253354069792,40.0298881530762,2.00001487066237,16.0099994391203,0.000236736740958525,4.01205787649395E-5,0.25,-1.28217135386782E-7,2.08915990128662E-5,-6.29917422323861E-8,101.4941483,101.4941483,99.5330276489258,99.5330276489258,56.9697762526599,20.6653094654143,19.871798,0,0,0,40,4374,98.8589,99.5330276489258,,,,,,,,,,,,,0,,,,0,,,,,,101.4941483,,,,
,22767824.03,97.9472427,99.5330276489258,2.04053008226663E-5,2.80042455698749E-7,1,0.999253354069792,40.0298881530762,1.99959496466204,16.0799995064735,0.000232773425602297,3.76418476381217E-5,0.25,-2.84360794348433E-7,2.05192156269622E-5,-2.16918510298216E-7,97.9472427,97.9472427,99.5330276489258,99.5330276489258,56.7759323798906,20.6659212985864,19.492144,0,0,0,40,4374,95.38375,99.5330276489258,,,,,,,,,,,,,0,,,,0.0049,,,,,,97.9472427,,,,
,22767963.42,94.4472427,99.5330276489258,2.06421355915984E-5,3.30569146327327E-7,1,0.999253354069792,40.0298881530762,1.99925528733343,16.0799995064735,0.000235185307713805,3.94342876066996E-5,0.25,-1.72539617196543E-7,2.07559455245896E-5,-9.89142904009381E-8,94.4472427,94.4472427,99.5330276489258,99.5330276489258,57.0932735586983,20.6663562170868,19.492144,0,0,0,40,4374,91.9279,99.5330276489258,,,,,,,,,,,,,0,,,,0,,,,,,94.4472427,,,,
,22768098.655,90.998703,99.5330276489258,2.04159592755968E-5,2.98200936914323E-7,1,0.999253354069792,40.0298881530762,1.99914916539925,16.0799995064735,0.000232767295990116,3.79350834073826E-5,0.25,-2.69052143449672E-7,2.05273969419108E-5,-1.91721343173806E-7,90.998703,90.998703,99.5330276489258,99.5330276489258,56.9596150819099,20.6667731468083,19.492144,0,0,0,40,4374,88.5946,99.5330276489258,,,,,,,,,,,,,0,,,,0,,,,,,90.998703,,,,
,22768238.1,87.4426727,99.5330276489258,2.01505911225647E-5,3.14864420918477E-7,1,0.999253354069792,40.0298881530762,1.99927000773659,16.160000115633,0.0002290756450479,4.1145813981043E-5,0.25,5.46512619726808E-8,2.02571016967199E-5,1.38321578651812E-7,87.4426727,87.4426727,99.5330276489258,99.5330276489258,56.7681160946983,20.6634184827264,19.871798,0,0,0,40,4374,85.1896,99.5330276489258,,,,,,,,,,,,,0,,,,-0.0049,,,,,,87.4426727,,,,
,22768373.465,83.977272,99.5330276489258,2.07689811397848E-5,2.61662331463205E-7,1,0.999253354069792,40.0298881530762,1.99948661658374,16.160000115633,0.000236822375809934,3.83024328799517E-5,0.25,-3.10760499364164E-7,2.08773004685879E-5,-2.20203219719505E-7,83.977272,83.977272,99.5330276489258,99.5330276489258,56.9486722826406,20.6722950263338,19.492144,0,0,0,40,4374,81.8794,99.5330276489258,,,,,,,,,,,,,0,,,,0,,,,,,83.977272,,,,
,22768508.4,80.49491885,99.5330276489258,2.02604694070305E-5,3.40945616937561E-7,1,0.999253354069792,40.0298881530762,1.99930124813379,16.160000115633,0.000231014348156501,3.70475297935985E-5,0.25,-3.36748096908268E-7,2.03624194982944E-5,-2.41885791386262E-7,80.4648285,80.5250092,99.5330276489258,99.5330276489258,56.8283014906791,20.6675152368393,19.112494,0,0,0,40,4374,78.58085,99.5330276489258,,,,,,,,,,,,,0,,,,0.00245,,,,,,80.49491885,,,,
,22768645.38,76.99610135,99.5330276489258,2.05575635514393E-5,3.03047951143083E-7,1,0.999253354069792,40.0298881530762,1.99937195069036,16.2400007247925,0.000234630677834022,3.60053339633265E-5,0.25,-4.87897334178333E-7,2.0656467735419E-5,-3.84790133159905E-7,76.9686508,77.0235519,99.5330276489258,99.5330276489258,56.3468183228329,20.6643686085468,18.353191,0,0,0,40,4374,75.22145,99.5330276489258,,,,,,,,,,,,,0,,,,-0.00245,,,,,,76.99610135,,,,
,22768783.085,73.4780502,99.5330276489258,2.0468838484717E-5,2.86344619995834E-7,1,0.999253354069792,40.0298881530762,1.99932960568088,16.2300001829863,0.000233146301332427,3.80248378438233E-5,0.25,-3.01243204170207E-7,2.05594643390994E-5,-1.89616629627645E-7,73.4780502,73.4780502,99.5330276489258,99.5330276489258,57.1534589546791,20.6689338923803,19.112494,0,0,0,40,4374,71.8437,99.5330276489258,,,,,,,,,,,,,0,,,,0,,,,,,73.4780502,,,,
,22768922.06,69.9554672,99.5330276489258,2.0748569732136E-5,3.12264731172682E-7,1,0.999253354069792,40.0298881530762,1.99936123613337,16.2300001829863,0.000236264224420968,3.83514497698082E-5,0.25,-3.29589997041327E-7,2.08314041697249E-5,-2.07750903674394E-7,69.9554672,69.9554672,99.5330276489258,99.5330276489258,56.8486238321791,20.6736105769121,18.353191,0,0,0,40,4374,68.4028,99.5330276489258,,,,,,,,,,,,,0,,,,-0.00245,,,,,,69.9554672,,,,
,22769040.62,66.9659958,99.5330276489258,2.06603987378974E-5,3.19408536607231E-7,1,0.999253354069792,40.0298881530762,1.99905705632553,16.3000002503395,0.000234773173555325,4.00882933188323E-5,0.25,-1.66135089375479E-7,2.07322384662229E-5,-3.67221276568635E-8,66.9659958,66.9659958,99.5330276489258,99.5330276489258,56.8861420011022,20.6628428737042,18.353191,0,0,0,40,4374,65.48,99.5330276489258,,,,,,,,,,,,,0,,,,0,,,,,,66.9659958,,,,
,22769176.665,63.4789696,99.5330276489258,2.05679909486497E-5,3.3007268852156E-7,1,0.999253354069792,40.0298881530762,1.99918925131294,16.3000002503395,0.000233633521558208,3.9626424855809E-5,0.25,-1.96398922496632E-7,2.06263404557956E-5,-5.94663989850427E-8,63.4789696,63.4789696,99.5330276489258,99.5330276489258,56.9392927404099,20.6668856891174,18.353191,0,0,0,40,4374,62.1336,99.5330276489258,,,,,,,,,,,,,0,,,,0,,,,,,63.4789696,,,,
,22769314.045,59.9978638,99.5330276489258,2.0938301379029E-5,2.73648325512396E-7,1,0.999253354069792,40.0298881530762,1.99918725630548,16.3000002503395,0.00023699243457345,4.39870714729624E-5,0.25,1.17375803228262E-7,2.09790181865504E-5,2.64844649097755E-7,59.9978638,59.9978638,99.5330276489258,99.5330276489258,56.7055858131598,20.6715446835081,17.973541,0,0,0,40,4374,58.7608,99.5330276489258,,,,,,,,,,,,,0,,,,0,,,,,,59.9978638,,,,
,22769431.805,56.9978714,99.5330276489258,2.0256173275472E-5,3.39700798197978E-7,1,0.999253354069792,40.0298881530762,1.99900498766716,16.3700003176928,0.000229833411584983,3.83052238572313E-5,0.25,-2.63338320856104E-7,2.02826151486629E-5,-1.16550078402726E-7,56.9978714,56.9978714,99.5330276489258,99.5330276489258,56.8353361473522,20.6712296909546,17.214239,0,0,0,40,4374,55.876,99.5330276489258,,,,,,,,,,,,,0,,,,-0.0049,,,,,,56.9978714,,,,
,22769568.985,53.4710464,99.5330276489258,2.07231458679952E-5,2.83437345927137E-7,1,0.999253354069792,40.0298881530762,1.99919502290026,16.380000859499,0.000235129012986376,3.79912075278776E-5,0.25,-3.75521812983964E-7,2.07303525894421E-5,-2.21862744569908E-7,53.4710464,53.4710464,99.5330276489258,99.5330276489258,56.8814522299868,20.6719700945961,17.593889,0,0,0,40,4374,52.4982,99.5330276489258,,,,,,,,,,,,,0,,,,0,,,,,,53.4710464,,,,
,22769707.045,49.9917107,99.5330276489258,2.08043680870143E-5,3.05510771519478E-7,1,0.999253354069792,40.0298881530762,1.99910941707915,16.3700003176928,0.000235720121662362,3.84933730183373E-5,0.25,-3.42283714419686E-7,2.07893372714706E-5,-1.87547563070528E-7,49.9917107,49.9917107,99.5330276489258,99.5330276489258,57.014329078256,20.6697644919331,17.214239,0,0,0,40,4370,49.1064,99.5330276489258,,,,,,,,,,,,,0,,,,0,,,,,,49.9917107,,,,
,22769824.045,46.9752808,99.5330276489258,2.09419237031853E-5,2.4559462953487E-7,1,0.999253354069792,40.0298881530762,1.99900387661987,16.4299998432398,0.000237804630465661,3.45440366539696E-5,0.25,-7.11331264546488E-7,2.09107320502695E-5,-5.57197761628667E-7,46.9752808,46.9752808,99.5330276489258,99.5330276489258,56.1310888515252,20.669499759188,17.214239,0,0,0,40,4370,46.2307,99.5330276489258,,,,,,,,,,,,,0,,,,0,,,,,,46.9752808,,,,
,22769963.175,43.4800301,99.5330276489258,2.04368450849571E-5,2.69602513692165E-7,1,0.999253354069792,40.0298881530762,1.9992524319487,16.4299998432398,0.000231393491985135,3.62815540794941E-5,0.25,-4.5787325577306E-7,2.03840756510672E-5,-3.13202684418672E-7,43.4800301,43.4800301,99.5330276489258,99.5330276489258,56.8830154870253,20.6667394374423,16.454937,0,0,0,40,4370,42.7997,99.5330276489258,,,,,,,,,,,,,0,,,,0,,,,,,43.4800301,,,,
,22770100.965,39.9561195,99.5330276489258,2.07300593475741E-5,2.85300799197028E-7,1,0.999253354069792,40.0298881530762,1.99926354036129,16.4299998432398,0.000233411014556019,4.28774280354372E-5,0.25,8.55431988571156E-8,2.06546461381499E-5,2.22672092614896E-7,39.9561195,39.9561195,99.5330276489258,99.5330276489258,56.7532651528329,20.6668767722243,16.454937,0,0,0,40,4370,39.3926,99.5330276489258,,,,,,,,,,,,,0,,,,0,,,,,,39.9561195,,,,
,22770238.57,36.4850464,99.5330276489258,2.02684732305732E-5,3.02079561270782E-7,1,0.999253354069792,40.0298881530762,1.99911443834754,16.4800006896257,0.000228824030502001,3.74801443071662E-5,0.25,-2.99291228703698E-7,2.01827595501752E-5,-1.7237512303982E-7,36.4850464,36.4850464,99.5330276489258,99.5330276489258,57.0104209356599,20.6614814011258,16.075285,0,0,0,40,4370,36.0132,99.5330276489258,,,,,,,,,,,,,0,,,,0,,,,,,36.4850464,,,,
,22770375.825,32.9793358,99.5330276489258,2.08845688059901E-5,3.85011877190709E-7,1,0.999253354069792,40.0298881530762,1.99906000527016,16.4800006896257,0.00023545924183885,3.96162205574185E-5,0.25,-2.08979162168202E-7,2.0784071611331E-5,-8.73725709134479E-8,32.9793358,32.9793358,99.5330276489258,99.5330276489258,56.6407106460637,20.6621664933297,15.695635,0,0,0,40,4370,32.6244,99.5330276489258,,,,,,,,,,,,,0,,,,0,,,,,,32.9793358,,,,
,22770515.54,29.4752979,99.5330276489258,2.10045965983284E-5,2.72766529729579E-7,1,0.999253354069792,40.0298881530762,1.99934291998455,16.4800006896257,0.00023704406542063,3.81634613067943E-5,0.25,-3.50635354437207E-7,2.089568920399E-5,-2.35418999510125E-7,29.4752979,29.4752979,99.5330276489258,99.5330276489258,56.9689946241406,20.6655896893717,15.315984,0,0,0,40,4370,29.1628,99.5330276489258,,,,,,,,,,,,,0,,,,-0.0049,,,,,,29.4752979,,,,
,22770653.395,25.9768791,99.5330276489258,2.05913176102689E-5,3.60618854553967E-7,1,0.999253354069792,40.0298881530762,1.99897103142695,16.5199991315603,0.000232683263685629,3.5101953509498E-5,0.25,-5.41753260550998E-7,2.04799917593815E-5,-4.33528813189153E-7,25.9768791,25.9768791,99.5330276489258,99.5330276489258,56.7118388413137,20.6663071175343,15.315984,0,0,0,40,4370,25.7428,99.5330276489258,,,,,,,,,,,,,0,,,,0,,,,,,25.9768791,,,,
,22770792.175,22.4904003,99.5330276489258,2.07621056177204E-5,2.98015945714174E-7,1,0.999253354069792,40.0298881530762,1.99891154787726,16.5199991315603,0.00023427574354525,3.70324532496702E-5,0.25,-3.95898514026391E-7,2.06457656954142E-5,-2.91507868017723E-7,22.4904003,22.4904003,99.5330276489258,99.5330276489258,56.5758354789675,20.6737813981774,14.556682,0,0,0,40,4370,22.2879,99.5330276489258,,,,,,,,,,,,,0,,,,0.00245,,,,,,22.4904003,,,,
,22770931.375,18.9794121,99.5330276489258,2.07853901879599E-5,3.1036504961119E-7,1,0.999253354069792,40.0298881530762,1.99890356372649,16.5199991315603,0.0002345428307239,3.69550110190491E-5,0.25,-4.04817415270296E-7,2.06676102372544E-5,-3.02106581906087E-7,18.9794121,18.9794121,99.5330276489258,99.5330276489258,56.5211214826214,20.6742201880912,13.797379,0,0,0,40,4370,18.8269,99.5330276489258,,,,,,,,,,,,,0,,,,0,,,,,,18.9794121,,,,
,22771071.6,15.4761391,99.5330276489258,2.07093188251781E-5,2.92836555036674E-7,1,0.999253354069792,40.0298881530762,1.9988421325129,16.5599994361401,0.0002337015377878,3.66919483697927E-5,0.25,-4.14489147207334E-7,2.05921483996808E-5,-3.1222777376845E-7,15.4761391,15.4761391,99.5330276489258,99.5330276489258,57.0846756449868,20.6746253587501,13.417728,0,0,0,40,4370,15.34635,99.5330276489258,,,,,,,,,,,,,0,,,,0,,,,,,15.4761391,,,,
,22771210.155,11.995307,99.5330276489258,2.09282440716534E-5,2.78276903199265E-7,1,0.999253354069792,40.0298881530762,1.9988864043924,16.5599994361401,0.000235327740725718,4.18754263753497E-5,0.25,7.48703801234791E-9,2.08079601883285E-5,1.08376968271478E-7,11.995307,11.995307,99.5330276489258,99.5330276489258,56.872072687756,20.6719004081784,13.038077,0,0,0,40,4370,11.8829,99.5330276489258,,,,,,,,,,,,,0,,,,-0.0049,,,,,,11.995307,,,,
,22771448.405,10.0040598,99.5330276489258,2.05183428045566E-5,2.91704666695513E-7,1,0.999253354069792,40.0298881530762,1.99887003033865,16.5599994361401,0.000231367042350058,3.73980095828412E-5,0.25,-3.17872128021892E-7,2.04020569621603E-5,-2.17090436379443E-7,10.0040598,10.0040598,99.5330276489258,99.5330276489258,56.7759323798906,20.6745281196661,11.519473,0,0,0,40,4369,9.98765,99.5330276489258,,,,,,,,,,,,,0,,,,0.0049,,,,,,10.0040598,,,,