File: data/doubleLayers/dl_1-25/ppms/data/DD205_3_HYST_100OE_250K.DAT
[Header]
; VSM Data File (default extension .dat)
; Copyright (c) 2003-2013, Quantum Design, Inc. All rights reserved.
TITLE,
FILEOPENTIME,32581859.83,01/13/2019,10:33 am
BYAPP,VSM,2.0,2.0
INFO,PPMS VSM Option Release 1.4.10 Build 1,APPNAME
INFO,Quantum Design Linear Motor Servo Controller,MOTOR_MODULE_NAME
INFO,3101-100 M1,MOTOR_HW_VERSION
INFO,MMC1014,MOTOR_SERIAL_NUMBER
INFO,SRV No X-over 01.03.11,MOTOR_SOFTWARE_VERSION
INFO,Quantum Design VSM Detection Module,VSM_MODULE_NAME
INFO,3101-150 F0,VSM_HW_VERSION
INFO,VSM707,VSM_SERIAL_NUMBER
INFO,VSM No X-over 01.02.05 May 20 2008 13:51:47,VSM_SOFTWARE_VERSION
INFO,704,PREAMP_SERIAL_NUMBER
INFO,822,COIL_SERIAL_NUMBER
INFO,0,MOMENT_UNITS
INFO,DD205_4,SAMPLE_MATERIAL
INFO,Double Layer Blue 1.25,SAMPLE_COMMENT
INFO,26.73,SAMPLE_MASS
INFO,,SAMPLE_VOLUME
INFO,,SAMPLE_MOLECULAR_WEIGHT
INFO,,SAMPLE_SIZE
INFO,,SAMPLE_SHAPE
DATATYPE,COMMENT,1
DATATYPE,TIME,2
STARTUPAXIS,X,2
STARTUPAXIS,Y1,5
[Data]
Comment,Time Stamp (sec),Temperature (K),Magnetic Field (Oe),Moment (emu),M. Std. Err. (emu),Transport Action,Averaging Time (sec),Frequency (Hz),Peak Amplitude (mm),Center Position (mm),Coil Signal' (mV),Coil Signal" (mV),Range (mV),M. Quad. Signal (emu),M. Raw' (emu),M. Raw" (emu),Min. Temperature (K),Max. Temperature (K),Min. Field (Oe),Max. Field (Oe),Mass (grams),Motor Lag (deg),Pressure (Torr),VSM Status (code),Motor Status (code),Measure Status (code),Measure Count,PPMS Status (code),System Temp. (K),System Field (Oe),Sample Position (deg),Bridge 1 Resistance (ohms),Bridge 1 Excitation (에),Bridge 2 Resistance (ohms),Bridge 2 Excitation (에),Bridge 3 Resistance (ohms),Bridge 3 Excitation (에),Bridge 4 Resistance (ohms),Bridge 4 Excitation (에),Signal 1 Vin (V),Signal 2 Vin (V),Digital Inputs (code),Drive 1 Iout (mA),Drive 1 Ipower (W),Drive 2 Iout (mA),Drive 2 Ipower (W),Pressure (),Map 20 (),Map 21 (),Map 22 (),Map 23 (),Map 24 (),Map 25 (),Map 26 (),Map 27 (),Map 28 (),Map 29 ()
,32581875.02,249.9820557,-0.121790185570717,,,2,,,,19.9000000366569,,,,,,,249.9820557,249.9820557,-0.121790185570717,-0.121790185570717,,,24.047956,,,,-99999999,4369,250.0378,-0.121790185570717,,,,,,,,,,,,,,,,,,,,,,,249.9820557,,,,
,32582028.145,249.9768066,4538.7197265625,4.92532897829402E-5,4.60133385621291E-7,1,0.999253354069792,40.0298881530762,1.99780376215908,19.8899991810322,0.00055908596973537,9.13535796437417E-5,0.25,-4.80298699423225E-7,4.93401451059854E-5,-4.40456082213324E-7,249.9768066,249.9768066,4536.18994140625,4541.24951171875,56.6016292201021,20.5654442489234,23.668306,0,0,0,40,4449,250.07525,4538.7197265625,,,,,,,,,,,,,0,,,,0,,,,,,249.9768066,,,,
,32582123.545,249.9801636,9304.9326171875,4.46337300633084E-5,4.83574165807769E-7,1,0.999253354069792,40.0298881530762,1.99783584530399,19.8899991810322,0.000506818221891095,8.18511244875926E-5,0.25,-5.17762516848119E-7,4.47125058657962E-5,-4.81841367444884E-7,249.9801636,249.9801636,9292.6455078125,9317.2197265625,56.861911517006,20.5665340781899,23.668306,0,0,0,40,4449,250.0933,9304.9326171875,,,,,,,,,,,,,0,,,,0,,,,,,249.9801636,,,,
,32582222.695,249.9851227,14262.19921875,3.375700890298E-5,8.20080750846407E-7,1,0.999253354069792,40.0298881530762,1.99787927696399,19.8899991810322,0.000382229559984129,6.81964519774483E-5,0.25,1.63503614668612E-7,3.38161278039355E-5,1.91612523379305E-7,249.9851227,249.9851227,14259.525390625,14264.873046875,57.0190188493714,20.5707972447129,23.668306,0,0,0,40,4449,250.10145,14262.19921875,,,,,,,,,,,,,0,,,,0.0049,,,,,,249.9851227,,,,
,32582316.93,249.9876862,18972.462890625,2.12387612525735E-5,1.22247949042751E-6,1,0.999253354069792,40.0298881530762,1.99786297909837,19.8899991810322,0.000242224005269703,3.28730581637112E-5,0.25,-7.82489099308922E-7,2.12766862014877E-5,-7.66379251224153E-7,249.9876862,249.9876862,18967.61328125,18977.3125,57.4536043060638,20.569824238807,23.288654,0,0,0,40,4449,250.111,18972.462890625,,,,,,,,,,,,,0,,,,-0.0049,,,,,,249.9876862,,,,
,32582410.945,249.9918518,23669.9755859375,7.18391188937048E-6,1.22455244077332E-6,1,0.999253354069792,40.0298881530762,1.9978619632584,19.8899991810322,8.18807351983355E-5,1.14095344772862E-5,0.25,-2.39041802541045E-7,7.19671824104016E-6,-2.33555141105605E-7,249.9918518,249.9918518,23665.08984375,23674.861328125,57.210517836583,20.571682869879,23.668306,0,0,0,40,4449,250.1177,23669.9755859375,,,,,,,,,,,,,0,,,,0.0049,,,,,,249.9918518,,,,
,32582504.18,249.996933,28330.3515625,-7.40337535260081E-6,1.08199178952501E-6,1,0.999253354069792,40.0298881530762,1.99785166298432,19.8899991810322,-8.26213150923288E-5,-2.19090229990806E-5,0.25,-6.49417398606257E-7,-7.41583664517414E-6,-6.56636379775101E-7,249.996933,249.996933,28322.818359375,28337.884765625,57.2159892362176,20.5727541156923,23.668306,0,0,0,40,4449,250.11405,28330.3515625,,,,,,,,,,,,,0,,,,0,,,,,,249.996933,,,,
,32582598.51,249.9985962,33045.59765625,-2.26947719413807E-5,1.99656207647367E-6,1,0.999253354069792,40.0298881530762,1.99785499975238,19.8899991810322,-0.000255053703792154,-5.68933235074281E-5,0.25,-1.08470424840784E-6,-2.27337181283576E-5,-1.10521892755363E-6,249.9985962,249.9985962,33035.55078125,33055.64453125,57.2214606358522,20.5715496791796,23.288654,0,0,0,40,4449,250.1144,33045.59765625,,,,,,,,,,,,,0,,,,0,,,,,,249.9985962,,,,
,32582691.345,250.0027924,37683.09375,-3.68274076202913E-5,1.74234164975564E-6,1,0.999253354069792,40.0298881530762,1.99798498067634,19.8899991810322,-0.000417038015804098,-7.42797758641286E-5,0.25,-1.67687832371176E-7,-3.68919116839936E-5,-1.9814207623543E-7,250.0027924,250.0027924,37673.2109375,37692.9765625,57.3910740245253,20.5736688519231,23.668306,0,0,0,40,4449,250.11445,37683.09375,,,,,,,,,,,,,0,,,,0.0049,,,,,,250.0027924,,,,
,32582787.115,250.0026398,42470.60546875,-5.27493595125966E-5,2.22757101761295E-6,1,0.999253354069792,40.0298881530762,1.99789293456725,19.8899991810322,-0.000595439312378136,-0.000117199127279735,0.25,-1.19412541219228E-6,-5.28409782913846E-5,-1.23936112392819E-6,250.0022736,250.003006,42465.671875,42475.5390625,57.1823792098907,20.5713641254564,23.668306,0,0,0,40,4449,250.1091,42470.60546875,,,,,,,,,,,,,0,,,,0,,,,,,250.0026398,,,,
,32582881.48,250.0076294,47188.56640625,-6.75950663496508E-5,2.07513727302163E-6,1,0.999253354069792,40.0298881530762,1.99780872476198,19.8899991810322,-0.000762911839232862,-0.000150617866979266,0.25,-1.56914029094726E-6,-6.77124366152695E-5,-1.62709853171659E-6,250.0076294,250.0076294,47178.45703125,47198.67578125,57.2675767184868,20.5720806306001,23.668306,0,0,0,40,4449,250.10355,47188.56640625,,,,,,,,,,,,,0,,,,-0.00245,,,,,,250.0076294,,,,
,32582975.47,250.006485,51886.353515625,-8.43606808658886E-5,1.80332207420227E-6,1,0.999253354069792,40.0298881530762,1.99780677206105,19.8899991810322,-0.00095109508322077,-0.000193979538296233,0.25,-2.48825657285862E-6,-8.45067468228459E-5,-2.56142354661853E-6,250.006485,250.006485,51876.2890625,51896.41796875,57.4911224749868,20.5721454698297,23.288654,0,0,0,40,4449,250.0984,51886.353515625,,,,,,,,,,,,,0,,,,0,,,,,,250.006485,,,,
,32583072.86,250.0071106,56753.947265625,-9.9593708828599E-5,2.46686880620791E-6,1,0.999253354069792,40.0298881530762,1.99779929610443,19.8899991810322,-0.00112416937321022,-0.000221286168335958,0.25,-2.25647358620752E-6,-9.97667193602712E-5,-2.34153561896758E-6,250.0071106,250.0071106,56744.31640625,56763.578125,57.3340151426215,20.5724012239516,23.668306,0,0,0,40,4449,250.0942,56753.947265625,,,,,,,,,,,,,0,,,,-0.00245,,,,,,250.0071106,,,,
,32583167.82,250.0061798,61501.3671875,-0.000115916290682923,2.15125423397039E-6,1,0.999253354069792,40.0298881530762,1.99779998283682,19.8899991810322,-0.00130623118388625,-0.000270129613377544,0.25,-3.73623169331732E-6,-0.000116116776401318,-3.83704262132078E-6,250.0061798,250.0061798,61495.875,61506.859375,57.2691399755253,20.5740298156867,24.047956,0,0,0,40,4449,250.0938,61501.3671875,,,,,,,,,,,,,0,,,,-0.00735,,,,,,250.0061798,,,,
,32583264.89,250.0143585,66352.26171875,-0.00012955349119062,2.76788953778704E-6,1,0.999253354069792,40.0298881530762,1.99775603239265,19.8899991810322,-0.00146932762647072,-0.000247390454673254,0.25,6.34633233441075E-7,-0.00012978145323495,5.30562627135665E-7,250.0143585,250.0143585,66344.8203125,66359.703125,57.3074397729676,20.5726660809933,23.288654,0,0,0,40,4449,250.0751,66352.26171875,,,,,,,,,,,,,0,,,,-0.0049,,,,,,250.0143585,,,,
,32583357.985,250.0121765,71004.8359375,-0.000146219874955392,2.7685857049342E-6,1,0.999253354069792,40.0298881530762,1.99770584023726,19.8899991810322,-0.00165125460924903,-0.000319892924413437,0.25,-2.87418297041676E-6,-0.000146474281946307,-2.99777246122073E-6,250.0121765,250.0121765,71002.3984375,71007.2734375,57.4965938746215,20.5734912399493,23.668306,0,0,0,40,4449,250.06455,71004.8359375,,,,,,,,,,,,,0,,,,-0.0049,,,,,,250.0121765,,,,
,32583453.735,250.0121918,75790.64453125,-0.000163711307644635,3.46862109456042E-6,1,0.999253354069792,40.0298881530762,1.9977091157933,19.8899991810322,-0.00184851062215095,-0.000359758748653688,0.25,-3.35925509621426E-6,-0.00016399605998237,-3.49767276184613E-6,250.0121918,250.0121918,75785.65625,75795.6328125,57.2910255740638,20.5744712153637,23.668306,0,0,0,40,4449,250.0582,75790.64453125,,,,,,,,,,,,,0,,,,0,,,,,,250.0121918,,,,
,32583550.3,250.01097865,80616.546875,-0.000181686748695205,3.09979760115591E-6,1,0.999253354069792,40.0298881530762,1.99782936831266,19.8899991810322,-0.00204447628728049,-0.00044033318506119,0.25,-7.35073373085761E-6,-0.000181999876501521,-7.51048408664453E-6,250.0099792,250.0119781,80609.0859375,80624.0078125,57.1644017539484,20.5771114362954,24.047956,0,0,0,40,4449,250.0472,80616.546875,,,,,,,,,,,,,0,,,,0,,,,,,250.01097865,,,,
,32583647.36,250.0132446,85469.67578125,-0.000199318676237793,2.93557474860752E-6,1,0.999253354069792,40.0298881530762,1.99770212238816,19.8899991810322,-0.00225046878995471,-0.00043851179411122,0.25,-4.13510387015708E-6,-0.000199665384968269,-4.30319809796641E-6,250.0132446,250.0132446,85462.3046875,85477.046875,57.4160861371407,20.5728666127099,23.668306,0,0,0,40,4449,250.04365,85469.67578125,,,,,,,,,,,,,0,,,,0,,,,,,250.0132446,,,,
,32583757.805,250.0067596,89953.63671875,-0.000214240777712912,2.57682932907013E-6,1,0.999253354069792,40.0298881530762,1.99772686045854,19.8899991810322,-0.00241899180475738,-0.000471283956488509,0.25,-4.43937106051916E-6,-0.000214613529647984,-4.61979058528754E-6,250.0067596,250.0067596,89949.3984375,89957.875,57.169873153583,20.5742217511316,23.288654,0,0,0,40,4449,250.0299,89953.63671875,,,,,,,,,,,,,0,,,,0.0049,,,,,,250.0067596,,,,
,32583852.385,250.0025635,85239.30078125,-0.000195677515869921,2.91676936795099E-6,1,0.999253354069792,40.0298881530762,1.99765845466952,19.8899991810322,-0.00220693045017619,-0.000444225384050393,0.25,-5.27150499461926E-6,-0.000196016984709771,-5.43868021901403E-6,250.0025635,250.0025635,85229.4453125,85249.15625,57.4754899046022,20.5744724830019,23.668306,0,0,0,40,4449,250.0313,85239.30078125,,,,,,,,,,,,,0,,,,-0.00245,,,,,,250.0025635,,,,
,32583947.595,249.9983826,80478.09765625,-0.000178638612314444,3.16792690065498E-6,1,0.999253354069792,40.0298881530762,1.99759778463654,19.8899991810322,-0.00201086961434928,-0.00042762285464831,0.25,-6.76184033515327E-6,-0.00017894694106133,-6.91811214447407E-6,249.9983826,249.9983826,80470.7109375,80485.484375,57.3168193151984,20.5758396822207,23.668306,0,0,0,40,4449,250.0331,80478.09765625,,,,,,,,,,,,,0,,,,0,,,,,,249.9983826,,,,
,32584043.765,249.9990082,75674.03125,-0.00016468420814447,3.15346283673076E-6,1,0.999253354069792,40.0298881530762,1.9977487289513,19.8899991810322,-0.00184895208292772,-0.000422914748847059,0.25,-8.7632405654956E-6,-0.000164966368630331,-8.91195994936153E-6,249.9990082,249.9990082,75671.4453125,75676.6171875,57.200356665833,20.574676530715,23.668306,0,0,0,40,4449,250.0328,75674.03125,,,,,,,,,,,,,0,,,,0,,,,,,249.9990082,,,,
,32584141.025,249.996521,70810.90625,-0.000146769404125328,2.33902193321507E-6,1,0.999253354069792,40.0298881530762,1.99769462059449,19.8899991810322,-0.0016596399110969,-0.000308479126016997,0.25,-1.77174339207208E-6,-0.000147025749216705,-1.8938649773293E-6,249.996521,249.996521,70803.3984375,70818.4140625,57.2800827747945,20.5763601414569,23.668306,0,0,0,40,4449,250.03985,70810.90625,,,,,,,,,,,,,0,,,,-0.00245,,,,,,249.996521,,,,
,32584238.305,249.9905548,65947.83203125,-0.000132617326433987,3.02490026744508E-6,1,0.999253354069792,40.0298881530762,1.99765728943246,19.8899991810322,-0.00149480590416512,-0.000306284698712022,0.25,-4.03251990929748E-6,-0.000132846987003327,-4.14730266268485E-6,249.9905548,249.9905548,65940.3984375,65955.265625,57.034651419756,20.5773409507281,24.047956,0,0,0,40,4449,250.0485,65947.83203125,,,,,,,,,,,,,0,,,,0.0049,,,,,,249.9905548,,,,
,32584335.91,249.9889526,61067.041015625,-0.000113291662740822,2.10709632470567E-6,1,0.999253354069792,40.0298881530762,1.99770808768684,19.8899991810322,-0.00127948820596767,-0.000247344479743411,0.25,-2.18161801635794E-6,-0.000113488870192197,-2.2775954477002E-6,249.9889526,249.9889526,61062.0703125,61072.01171875,57.3519925985638,20.5776905537539,24.047956,0,0,0,40,4449,250.05655,61067.041015625,,,,,,,,,,,,,0,,,,0,,,,,,249.9889526,,,,
,32584431.91,249.990097,56269.236328125,-9.75603884510731E-5,2.98419877640044E-6,1,0.999253354069792,40.0298881530762,1.99776087833133,19.8899991810322,-0.001101822562178,-0.000213166287419357,0.25,-1.89285007086925E-6,-9.7730181426032E-5,-1.97564377579698E-6,249.990097,249.990097,56259.23046875,56279.2421875,57.4723633905253,20.579349823126,23.288654,0,0,0,40,4449,250.0604,56269.236328125,,,,,,,,,,,,,0,,,,0,,,,,,249.990097,,,,
,32584528.02,249.9913483,51463.857421875,-8.39923668547582E-5,2.19872484897998E-6,1,0.999253354069792,40.0298881530762,1.99768414079411,19.8899991810322,-0.00094386217656285,-0.000210567895912092,0.25,-4.01702524916696E-6,-8.41365820544638E-5,-4.09259549673838E-6,249.9913483,249.9913483,51461.46484375,51466.25,57.4793980471984,20.5783903103594,23.668306,0,0,0,40,4449,250.0709,51463.857421875,,,,,,,,,,,,,0,,,,-0.0049,,,,,,249.9913483,,,,
,32584626.345,249.9908905,46553.97265625,-6.5806166795289E-5,2.88324655427454E-6,1,0.999253354069792,40.0298881530762,1.99761671803068,19.8899991810322,-0.000741485955259956,-0.00015335222830103,0.25,-2.12187335091664E-6,-6.5919982256554E-5,-2.17936036350765E-6,249.9908905,249.9908905,46543.92578125,46564.01953125,57.3762230826599,20.5800294157736,23.288654,0,0,0,40,4449,250.07215,46553.97265625,,,,,,,,,,,,,0,,,,0,,,,,,249.9908905,,,,
,32584722.64,249.9925232,41738.3984375,-5.22951763916738E-5,2.05175100405946E-6,1,0.999253354069792,40.0298881530762,1.99761738165227,19.8899991810322,-0.000591329394598032,-0.000109863701767423,0.25,-6.26860688074508E-7,-5.23864789425204E-5,-6.70743833499939E-7,249.9925232,249.9925232,41731.0625,41745.734375,57.5677220698715,20.580089835494,23.668306,0,0,0,40,4449,250.0837,41738.3984375,,,,,,,,,,,,,0,,,,-0.00245,,,,,,249.9925232,,,,
,32584818.39,249.9878845,36954.025390625,-3.42502067290254E-5,1.84450989195137E-6,1,0.999253354069792,40.0298881530762,1.99779699195586,19.8899991810322,-0.000386137381342826,-7.87714550310902E-5,0.25,-1.01156870665616E-6,-3.43095130746288E-5,-1.04140271692039E-6,249.9878845,249.9878845,36943.93359375,36964.1171875,57.3543374841214,20.581553813817,24.047956,0,0,0,40,4449,250.09415,36954.025390625,,,,,,,,,,,,,0,,,,-0.00245,,,,,,249.9878845,,,,
,32584913.925,249.9862671,32178.328125,-1.92668248180918E-5,1.66769042702677E-6,1,0.999253354069792,40.0298881530762,1.99786648230048,19.8899991810322,-0.000214877382629675,-5.7830945925295E-5,0.25,-1.76188218950263E-6,-1.92992062286042E-5,-1.7807797734063E-6,249.9862671,249.9862671,32170.908203125,32185.748046875,57.5302039009484,20.5824652308929,23.668306,0,0,0,40,4449,250.1047,32178.328125,,,,,,,,,,,,,0,,,,0,,,,,,249.9862671,,,,
,32585011.21,249.9854431,27316.2275390625,-6.1934362367701E-6,1.24676151416049E-6,1,0.999253354069792,40.0298881530762,1.99797478232963,19.8899991810322,-6.73169548476834E-5,-2.8741075908532E-5,0.25,-1.46197565270294E-6,-6.20310868348661E-6,-1.4696292412451E-6,249.9854431,249.9854431,27308.822265625,27323.6328125,57.6834030907176,20.5816823804806,23.668306,0,0,0,40,4449,250.1173,27316.2275390625,,,,,,,,,,,,,0,,,,0,,,,,,249.9854431,,,,
,32585107.065,249.9911652,22526.0615234375,9.43354670376137E-6,1.22460495620094E-6,1,0.999253354069792,40.0298881530762,1.99783564683928,19.8899991810322,0.000107817650954366,1.32673608990591E-5,0.25,-4.65226227269773E-7,9.45048785387324E-6,-4.58284743515986E-7,249.9911652,249.9911652,22520.98828125,22531.134765625,57.3011867448138,20.5864602328869,23.668306,0,0,0,40,4449,250.1189,22526.0615234375,,,,,,,,,,,,,0,,,,0.0049,,,,,,249.9911652,,,,
,32585203,249.9927979,17731.1943359375,2.3595027804416E-5,9.69748369795577E-7,1,0.999253354069792,40.0298881530762,1.99795421145313,19.8899991810322,0.000268647965961236,3.91768870818903E-5,0.25,-6.35009482142588E-7,2.36369625915602E-5,-6.16695661209587E-7,249.9927979,249.9927979,17723.744140625,17738.64453125,57.6755868055253,20.5851484484521,24.047956,0,0,0,40,4449,250.1193,17731.1943359375,,,,,,,,,,,,,0,,,,0.00245,,,,,,249.9927979,,,,
,32585298.72,249.9933472,12946.203125,3.64637980593681E-5,8.91473665032571E-7,1,0.999253354069792,40.0298881530762,1.99802382557354,19.8899991810322,0.000413229752940427,7.1807769714294E-5,0.25,1.23094065020895E-8,3.65277814534656E-5,4.23894434418276E-8,249.9933472,249.9933472,12941.072265625,12951.333984375,57.3230723433522,20.5830256936971,23.668306,0,0,0,40,4449,250.12795,12946.203125,,,,,,,,,,,,,0,,,,0,,,,,,249.9933472,,,,
,32585397.115,249.99352265,8028.16015625,4.70150303577681E-5,4.75344672872344E-7,1,0.999253354069792,40.0298881530762,1.99813001550964,19.8899991810322,0.000533742973996135,8.73244939771602E-5,0.25,-4.48831597638447E-7,4.70979065687707E-5,-4.10820990467007E-7,249.9931793,249.993866,8023.166015625,8033.154296875,57.6161830380638,20.5824901520894,24.047956,0,0,0,40,4449,250.1339,8028.16015625,,,,,,,,,,,,,0,,,,-0.00245,,,,,,249.99352265,,,,
,32585495.38,249.9910583,3115.6611328125,4.84375375594389E-5,4.37986361824544E-7,1,0.999253354069792,40.0298881530762,1.99806066204783,19.8899991810322,0.00054927927846911,9.33924531347766E-5,0.25,-1.59910700022898E-7,4.8522671820171E-5,-1.20181363079259E-7,249.9910583,249.9910583,3105.7353515625,3125.5869140625,57.566158812833,20.5847980154307,23.668306,0,0,0,40,4449,250.14045,3115.6611328125,,,,,,,,,,,,,0,,,,-0.0049,,,,,,249.9910583,,,,
,32585589.15,249.9949341,-1567.53308105469,-2.62964941910529E-5,4.25031253548359E-7,1,0.999253354069792,40.0298881530762,1.99797611722577,19.8899991810322,-0.000297106119531795,-5.69434281931659E-5,0.25,-4.64065954518061E-7,-2.63422537682101E-5,-4.86606920889294E-7,249.9949341,249.9949341,-1574.99401855469,-1560.07214355469,57.5802281261792,20.5863348601661,24.047956,0,0,0,40,4449,250.1422,-1567.53308105469,,,,,,,,,,,,,0,,,,0.00245,,,,,,249.9949341,,,,
,32585682.465,249.9978943,-6229.62426757812,-4.70731712756115E-5,5.75264524682063E-7,1,0.999253354069792,40.0298881530762,1.99782035018073,19.8899991810322,-0.000533082009278647,-9.45804225232923E-5,0.25,-1.8251069959828E-7,-4.71556198857132E-5,-2.21688201736802E-7,249.9978943,249.9978943,-6237.013671875,-6222.23486328125,57.3160376866791,20.586575706871,24.047956,0,0,0,40,4449,250.15355,-6229.62426757812,,,,,,,,,,,,,0,,,,0.00245,,,,,,249.9978943,,,,
,32585777.085,249.9986267,-10960.7866210938,-4.03432507922567E-5,6.03641784504727E-7,1,0.999253354069792,40.0298881530762,1.99778737393138,19.8899991810322,-0.00045659590805684,-8.25892244859858E-5,0.25,-2.91640832105862E-7,-4.04138032161313E-5,-3.25421531013862E-7,249.9986267,249.9986267,-10965.7138671875,-10955.859375,57.6060218673138,20.5876942280674,23.668306,0,0,0,40,4449,250.14575,-10960.7866210938,,,,,,,,,,,,,0,,,,0,,,,,,249.9986267,,,,
,32585874.295,250.0025482,-15820.5688476562,-2.8111172759162E-5,8.18672715324804E-7,1,0.999253354069792,40.0298881530762,1.99775561329205,19.8899991810322,-0.000318726777046149,-5.42280475429007E-5,0.25,8.96720390398247E-8,-2.81605741170006E-5,6.66737340722414E-8,250.0025482,250.0025482,-15828.013671875,-15813.1240234375,57.4708001334869,20.587797171088,24.047956,0,0,0,40,4449,250.14015,-15820.5688476562,,,,,,,,,,,,,0,,,,0,,,,,,250.0025482,,,,
,32585970.375,250.0078278,-20620.3017578125,-1.49972896938781E-5,1.1669802048569E-6,1,0.999253354069792,40.0298881530762,1.99791600658697,19.8899991810322,-0.000171174315318934,-2.24699959936936E-5,0.25,6.18108888150657E-7,-1.50241132231988E-5,6.06854488133443E-7,250.0078278,250.0078278,-20630.158203125,-20610.4453125,57.8045555111984,20.5883371896032,24.047956,0,0,0,40,4449,250.13325,-20620.3017578125,,,,,,,,,,,,,0,,,,0.00245,,,,,,250.0078278,,,,
,32586067.295,250.0095978,-25465.259765625,2.7049957477109E-7,1.10009207317164E-6,1,0.999253354069792,40.0298881530762,1.99782769004823,19.8899991810322,6.67456229414712E-8,1.78224769004332E-5,0.25,1.52581736284704E-6,2.69720413827045E-7,1.52871699133356E-6,250.0095978,250.0095978,-25477.486328125,-25453.033203125,57.5536527565253,20.5877292019636,24.047956,0,0,0,40,4449,250.12435,-25465.259765625,,,,,,,,,,,,,0,,,,0,,,,,,250.0095978,,,,
,32586165.18,250.0070038,-30357.59375,1.5660194434858E-5,1.30856785256069E-6,1,0.999253354069792,40.0298881530762,1.99783312181934,19.8899991810322,0.000176620452436579,3.5646551895517E-5,0.25,4.29788647696491E-7,1.5687323976632E-5,4.43394625285636E-7,250.0070038,250.0070038,-30370.095703125,-30345.091796875,57.5020652742561,20.5896994060691,24.047956,0,0,0,40,4449,250.1148,-30357.59375,,,,,,,,,,,,,0,,,,0,,,,,,250.0070038,,,,
,32586262.755,250.0137634,-35234.966796875,3.18996668246909E-5,1.55217563515645E-6,1,0.999253354069792,40.0298881530762,1.99778483654253,19.8899991810322,0.000358272466023458,8.12214008136961E-5,0.25,1.63543065478443E-6,3.19543038624438E-5,1.66444380149069E-6,250.0137634,250.0137634,-35242.2578125,-35227.67578125,57.698254032583,20.5905629425636,23.668306,0,0,0,40,4449,250.1103,-35234.966796875,,,,,,,,,,,,,0,,,,0.00245,,,,,,250.0137634,,,,
,32586361.14,250.0101166,-40152.00390625,4.40627364560154E-5,1.8520120288621E-6,1,0.999253354069792,40.0298881530762,1.99765327500543,19.8899991810322,0.000498891375943772,8.88661523705324E-5,0.25,2.01276981199272E-7,4.41399040310009E-5,2.37692079158249E-7,250.0101166,250.0101166,-40159.546875,-40144.4609375,57.6959091470253,20.5923019806111,23.668306,0,0,0,40,4449,250.0992,-40152.00390625,,,,,,,,,,,,,0,,,,-0.00245,,,,,,250.0101166,,,,
,32586461.635,250.0140076,-45175.29296875,6.11784408472476E-5,1.83704778370111E-6,1,0.999253354069792,40.0298881530762,1.99788234871253,19.8899991810322,0.000692721845427999,0.000123597228993793,0.25,2.97044175324698E-7,6.12855687290764E-5,3.47563910000452E-7,250.0140076,250.0140076,-45177.984375,-45172.6015625,57.5911709254484,20.5914935615012,23.668306,0,0,0,40,4449,250.08435,-45175.29296875,,,,,,,,,,,,,0,,,,-0.0049,,,,,,250.0140076,,,,
,32586557.74,250.0097656,-49977.333984375,8.02816813392027E-5,1.97777521274057E-6,1,0.999253354069792,40.0298881530762,1.99775053742676,19.8899991810322,0.000907682386201205,0.000169607874506886,0.25,1.04530621530367E-6,8.0421748569649E-5,1.11265699125755E-6,250.0097656,250.0097656,-49984.8828125,-49969.78515625,57.6286890943715,20.59294126651,24.047956,0,0,0,40,4449,250.0815,-49977.333984375,,,,,,,,,,,,,0,,,,0.0049,,,,,,250.0097656,,,,
,32586657.025,250.0140839,-54938.85546875,9.74133495866262E-5,2.64970567540075E-6,1,0.999253354069792,40.0298881530762,1.99809431041861,19.8899991810322,0.0011017240341772,0.00020487570200179,0.25,1.1838386047561E-6,9.75833746620167E-5,1.26529690744247E-6,250.0140839,250.0140839,-54941.46875,-54936.2421875,57.6841847192369,20.5890000541892,24.427608,0,0,0,40,4449,250.0667,-54938.85546875,,,,,,,,,,,,,0,,,,-0.0049,,,,,,250.0140839,,,,
,32586757.685,250.0158386,-59968.6640625,0.000110917602819873,2.84510340790038E-6,1,0.999253354069792,40.0298881530762,1.99797331831865,19.8899991810322,0.00125390353279997,0.000236022076447614,0.25,1.59147072293973E-6,0.000111111009908901,1.68451220144861E-6,250.0158386,250.0158386,-59973.625,-59963.703125,57.5528711280061,20.5888043944698,23.668306,0,0,0,40,4449,250.0525,-59968.6640625,,,,,,,,,,,,,0,,,,-0.0049,,,,,,250.0158386,,,,
,32586856.42,250.012146,-64903.75390625,0.00012718636518467,2.36919125675386E-6,1,0.999253354069792,40.0298881530762,1.99787732748135,19.8899991810322,0.00143620897309929,0.000279534530475025,0.25,2.61097627587875E-6,0.00012740753835379,2.71888448856513E-6,250.012146,250.012146,-64911.33203125,-64896.17578125,57.6873112333138,20.5922086852974,24.047956,0,0,0,40,4449,250.04785,-64903.75390625,,,,,,,,,,,,,0,,,,0,,,,,,250.012146,,,,
,32586954.03,250.0107727,-69783.1484375,0.000143488663727001,2.93122549480099E-6,1,0.999253354069792,40.0298881530762,1.99784733476913,19.8899991810322,0.00162075295339054,0.0003125995235721,0.25,2.70224279254533E-6,0.000143738413897568,2.82337712915175E-6,250.0107727,250.0107727,-69788.0078125,-69778.2890625,57.5583425276407,20.5936713300855,23.668306,0,0,0,40,4449,250.03765,-69783.1484375,,,,,,,,,,,,,0,,,,-0.00245,,,,,,250.0107727,,,,
,32587053.9,250.0137329,-74774.91796875,0.000162239214917744,3.38352360979241E-6,1,0.999253354069792,40.0298881530762,1.99793774328545,19.8899991810322,0.00183287520462517,0.000352027134015884,0.25,2.92877149939962E-6,0.000162521713790007,3.06530422459325E-6,250.0137329,250.0137329,-74780.0546875,-74769.78125,57.4973755031407,20.5926113120633,23.668306,0,0,0,40,4449,250.0274,-74774.91796875,,,,,,,,,,,,,0,,,,-0.00245,,,,,,250.0137329,,,,
,32587154.845,250.013504,-79819.6484375,0.000177328241388278,2.05116449264757E-6,1,0.999253354069792,40.0298881530762,1.99786019446713,19.8899991810322,0.00200866871125597,0.000353605990020167,0.25,4.52889604669437E-7,0.00017763926695346,5.97065806480698E-7,250.013504,250.013504,-79822.171875,-79817.125,57.6028953532369,20.5922326033755,24.047956,0,0,0,40,4449,250.01115,-79819.6484375,,,,,,,,,,,,,0,,,,0,,,,,,250.013504,,,,
,32587252.95,250.0140381,-84719.28515625,0.000195595231075973,3.43137934557652E-6,1,0.999253354069792,40.0298881530762,1.99777067366285,19.8899991810322,0.00221174315911496,0.00041163285956085,0.25,2.40747415188263E-6,0.000195936780274528,2.56960243555752E-6,250.0140381,250.0140381,-84724.578125,-84713.9921875,57.6662072632946,20.5933798621417,23.668306,0,0,0,40,4449,249.9988,-84719.28515625,,,,,,,,,,,,,0,,,,-0.00245,,,,,,250.0140381,,,,
,32587343.805,250.0113983,-89261.33203125,0.000208767016038113,2.9168813760693E-6,1,0.999253354069792,40.0298881530762,1.99777828985011,19.8899991810322,0.00235436309216268,0.000475873525430873,0.25,5.79247545038774E-6,0.000209129018342143,5.97093129083989E-6,250.0113983,250.0113983,-89266.140625,-89256.5234375,57.6099300099099,20.5959730996649,24.047956,0,0,0,40,4449,249.9895,-89261.33203125,,,,,,,,,,,,,0,,,,0,,,,,,250.0113983,,,,
,32587455.58,250.0057678,-86142.11328125,0.000200453925771387,3.2326425183255E-6,1,0.999253354069792,40.0298881530762,1.99778423505623,19.8899991810322,0.00226315333784265,0.000442311158835997,0.25,4.27198639054431E-6,0.000200802570417391,4.44124501400276E-6,250.0057678,250.0057678,-86144.75,-86139.4765625,57.5098815594484,20.5957464959414,24.047956,0,0,0,40,4449,249.98565,-86142.11328125,,,,,,,,,,,,,0,,,,0,,,,,,250.0057678,,,,
,32587549.51,249.9975128,-81447.28125,0.000184668654327486,2.83331086775154E-6,1,0.999253354069792,40.0298881530762,1.99793408263786,19.8899991810322,0.00208622579413413,0.000400930160173423,0.25,3.35479831431384E-6,0.000184990337661656,3.50993902726178E-6,249.9975128,249.9975128,-81457.3203125,-81437.2421875,57.627125837333,20.5923805098339,24.427608,0,0,0,40,4449,249.99305,-81447.28125,,,,,,,,,,,,,0,,,,-0.00245,,,,,,249.9975128,,,,
,32587645.925,249.9943695,-76627.6796875,0.000168311328188465,2.3539734354932E-6,1,0.999253354069792,40.0298881530762,1.99780166891891,19.8899991810322,0.00190038779780787,0.000370738552870712,0.25,3.5290572542338E-6,0.000168604127698368,3.67149881849724E-6,249.9943695,249.9943695,-76630.1171875,-76625.2421875,57.6154014095446,20.5945889257848,23.668306,0,0,0,40,4449,249.999,-76627.6796875,,,,,,,,,,,,,0,,,,0.0049,,,,,,249.9943695,,,,
,32587745.265,249.9933167,-71662.70703125,0.000151215252676259,2.9784881236753E-6,1,0.999253354069792,40.0298881530762,1.99763398682386,19.8899991810322,0.001709909037704,0.000317550960076692,0.25,1.80219219689557E-6,0.000151479400583031,1.92795906647753E-6,249.9933167,249.9933167,-71672.59375,-71652.8203125,57.7045070607369,20.5953789152262,23.668306,0,0,0,40,4449,250.0036,-71662.70703125,,,,,,,,,,,,,0,,,,-0.00245,,,,,,249.9933167,,,,
,32587844.54,249.9894409,-66700.57421875,0.000133571729030871,2.42305261081453E-6,1,0.999253354069792,40.0298881530762,1.99765625318283,19.8899991810322,0.00150480279146028,0.000312871766679786,0.25,4.44835111125592E-6,0.000133802734785586,4.56463108847564E-6,249.9894409,249.9894409,-66710.421875,-66690.7265625,57.4496961634676,20.5941235260138,23.668306,0,0,0,40,4449,250.0132,-66700.57421875,,,,,,,,,,,,,0,,,,-0.00245,,,,,,249.9894409,,,,
,32587942.25,249.9893036,-61818.310546875,0.000116133713586792,2.1426639723745E-6,1,0.999253354069792,40.0298881530762,1.99770701405058,19.8899991810322,0.0013119956577973,0.000251180908768366,0.25,2.02735021778924E-6,0.000116336037879905,2.125359392774E-6,249.9893036,249.9893036,-61828.109375,-61808.51171875,57.444224763833,20.5917283685268,23.668306,0,0,0,40,4449,250.02555,-61818.310546875,,,,,,,,,,,,,0,,,,0,,,,,,249.9893036,,,,
,32588041.585,249.9910736,-56853.947265625,0.000100917745395494,2.3579860861573E-6,1,0.999253354069792,40.0298881530762,1.99783022338799,19.8899991810322,0.00114048402168712,0.000216434727116186,0.25,1.59843779497105E-6,0.000101093671402558,1.68344471210239E-6,249.9910736,249.9910736,-56861.875,-56846.01953125,57.6693337773715,20.5943286835194,24.047956,0,0,0,40,4449,250.03295,-56853.947265625,,,,,,,,,,,,,0,,,,-0.00245,,,,,,249.9910736,,,,
,32588140.53,249.9858093,-51909.31640625,8.53609295252159E-5,2.17774249186849E-6,1,0.999253354069792,40.0298881530762,1.99771299093968,19.8899991810322,0.000965447060973109,0.000178294047530597,0.25,9.31310354884344E-7,8.55100818824111E-5,1.00257945097931E-6,249.9858093,249.9858093,-51919.49609375,-51899.13671875,57.3715333115445,20.5926026206693,23.668306,0,0,0,40,4449,250.03915,-51909.31640625,,,,,,,,,,,,,0,,,,0,,,,,,249.9858093,,,,
,32588239.47,249.9907837,-46964.41796875,7.04845678321064E-5,2.33496707080681E-6,1,0.999253354069792,40.0298881530762,1.99785742207275,19.8899991810322,0.000795447028671257,0.000157614421663206,0.25,1.68511095309417E-6,7.06069551015416E-5,1.74565371340274E-6,249.9907837,249.9907837,-46971.87109375,-46956.96484375,57.5708485839484,20.5898046324518,23.668306,0,0,0,40,4449,250.04365,-46964.41796875,,,,,,,,,,,,,0,,,,0,,,,,,249.9907837,,,,
,32588338.085,249.9896545,-42034.5625,5.17800652178979E-5,2.15487184986813E-6,1,0.999253354069792,40.0298881530762,1.99775663105791,19.8899991810322,0.000585409922198414,0.000109560586657752,0.25,6.88792921167206E-7,5.18704177255518E-5,7.32365814926911E-7,249.9896545,249.9896545,-42039.57421875,-42029.55078125,57.6286890943715,20.5908595449818,23.668306,0,0,0,40,4449,250.0533,-42034.5625,,,,,,,,,,,,,0,,,,0.00245,,,,,,249.9896545,,,,
,32588435.66,249.9891968,-37159.81640625,3.71816410100155E-5,1.80548050878511E-6,1,0.999253354069792,40.0298881530762,1.99777551569102,19.8899991810322,0.000423155335162041,6.26013182282287E-5,0.25,-9.2368034793571E-7,3.7247677672099E-5,-8.94840450544164E-7,249.9891968,249.9891968,-37162.33984375,-37157.29296875,57.5747567265446,20.5905318917754,24.047956,0,0,0,40,4449,250.0661,-37159.81640625,,,,,,,,,,,,,0,,,,0,,,,,,249.9891968,,,,
,32588531.28,249.986557,-32380.4521484375,2.08822307627537E-5,1.42467089551819E-6,1,0.999253354069792,40.0298881530762,1.99787913142818,19.8899991810322,0.000234924496476346,5.09770031312666E-5,0.25,8.76901862111272E-7,2.09181738113194E-5,8.95572324986168E-7,249.9864044,249.9867096,-32390.30078125,-32370.603515625,57.708415203333,20.5907813854489,24.047956,0,0,0,40,4449,250.0734,-32380.4521484375,,,,,,,,,,,,,0,,,,0,,,,,,249.986557,,,,
,32588627.785,249.9847565,-27555.94921875,5.21089453969102E-6,1.42516016848309E-6,1,0.999253354069792,40.0298881530762,1.99785079412031,19.8899991810322,5.5747380117434E-5,2.92942012952664E-5,0.25,1.68132840967819E-6,5.21866180742232E-6,1.68856054830732E-6,249.9847565,249.9847565,-27558.4921875,-27553.40625,57.6951275185061,20.5901152504874,23.288654,0,0,0,40,4449,250.0822,-27555.94921875,,,,,,,,,,,,,0,,,,0,,,,,,249.9847565,,,,
,32588725.235,249.9894714,-22688.5048828125,-9.4645592500892E-6,1.274380015534E-6,1,0.999253354069792,40.0298881530762,1.9978782964437,19.8899991810322,-0.000108164384648065,-1.33684741684163E-5,0.25,4.6170648507135E-7,-9.48155248251663E-6,4.54732845363453E-7,249.9894714,249.9894714,-22696.025390625,-22680.984375,57.3363600281791,20.5895413935675,24.047956,0,0,0,40,4449,250.0964,-22688.5048828125,,,,,,,,,,,,,0,,,,0,,,,,,249.9894714,,,,
,32588821.485,249.99095155,-17876.044921875,-2.26757179999747E-5,1.07541407857913E-6,1,0.999253354069792,40.0298881530762,1.99781559707112,19.8899991810322,-0.000257229264409531,-4.30368617313518E-5,0.25,1.34730557231752E-7,-2.27156287202083E-5,1.16294374600804E-7,249.9908295,249.9910736,-17908.6640625,-17843.42578125,57.8819367346023,20.5913362890066,23.668306,0,0,0,40,4449,250.0971,-17876.044921875,,,,,,,,,,,,,0,,,,-0.00245,,,,,,249.99095155,,,,
,32588917.825,249.9922409,-13063.1489257813,-3.6143422411539E-5,6.76818273822177E-7,1,0.999253354069792,40.0298881530762,1.99780055833469,19.8899991810322,-0.000411276508259834,-6.12449751186046E-5,0.25,8.63573518049954E-7,-3.62075667126738E-5,8.35291506544692E-7,249.9921417,249.9923401,-13065.650390625,-13060.6474609375,57.5341120435445,20.5904410263247,24.047956,0,0,0,40,4449,250.09915,-13063.1489257813,,,,,,,,,,,,,0,,,,0.0049,,,,,,249.9922409,,,,
,32589014.73,249.9930573,-8220.26416015625,-4.59744934104255E-5,6.51381474262997E-7,1,0.999253354069792,40.0298881530762,1.99779156954095,19.8899991810322,-0.000520749220233784,-9.17011328267036E-5,0.25,-1.19085630484194E-7,-4.60550753677614E-5,-1.57237106779743E-7,249.9930573,249.9930573,-8227.8427734375,-8212.685546875,57.6036769817561,20.5895992686225,24.427608,0,0,0,40,4449,250.10905,-8220.26416015625,,,,,,,,,,,,,0,,,,0.00245,,,,,,249.9930573,,,,
,32589110.365,249.9942474,-3437.01501464844,-4.83122384601305E-5,3.94666243664311E-7,1,0.999253354069792,40.0298881530762,1.99789495890741,19.8899991810322,-0.000547224412854811,-9.65486981347194E-5,0.25,-1.40980970254723E-7,-4.83968984683215E-5,-1.8113764186265E-7,249.9942474,249.9942474,-3444.806640625,-3429.22338867188,57.7342089444676,20.5890149461547,24.047956,0,0,0,40,4449,250.1135,-3437.01501464844,,,,,,,,,,,,,0,,,,0,,,,,,249.9942474,,,,
,32589202.33,249.993454,1157.44390869141,1.87738641112643E-5,3.33871773393106E-7,1,0.999253354069792,40.0298881530762,1.99788565460122,19.8899991810322,0.000214173260324424,2.87196941029361E-5,0.25,-7.21608602848858E-7,1.8807403987714E-5,-7.07360732332483E-7,249.993454,249.993454,1147.46166992188,1167.42614746094,57.5403650716984,20.5891115309455,24.047956,0,0,0,40,4449,250.1174,1157.44390869141,,,,,,,,,,,,,0,,,,-0.00245,,,,,,249.993454,,,,
,32589297.07,249.9946594,5891.04077148438,4.82921047008839E-5,5.54647109391429E-7,1,0.999253354069792,40.0298881530762,1.99782712305298,19.8899991810322,0.000547832262812256,9.15832913989143E-5,0.25,-2.93399999306072E-7,4.83770895782938E-5,-2.54041797666109E-7,249.9946594,249.9946594,5883.5703125,5898.51123046875,57.7779801415446,20.5883470292454,24.047956,0,0,0,40,4449,250.1174,5891.04077148438,,,,,,,,,,,,,0,,,,0,,,,,,249.9946594,,,,
,32589393.67,249.99958805,10721.5747070312,4.15959188340839E-5,7.90135942780594E-7,1,0.999253354069792,40.0298881530762,1.99762739189715,19.8899991810322,0.000472566962429725,7.45970749979702E-5,0.25,-6.30378850957205E-7,4.16694277225099E-5,-5.97176994392219E-7,249.9988251,250.000351,10716.5439453125,10726.60546875,57.3176009437176,20.5906176866883,24.047956,0,0,0,40,4449,250.1202,10721.5747070312,,,,,,,,,,,,,0,,,,-0.0049,,,,,,249.99958805,,,,
,32589490.01,250.0074615,15537.0678710938,2.97285206316859E-5,7.56158842517424E-7,1,0.999253354069792,40.0298881530762,1.99773855935133,19.8899991810322,0.000338883213353816,4.68436380449167E-5,0.25,-1.02178088329228E-6,2.9781522265443E-5,-9.99081763464341E-7,250.0074615,250.0074615,15529.71484375,15544.4208984375,57.342613056333,20.5896937962178,23.668306,0,0,0,40,4449,250.12055,15537.0678710938,,,,,,,,,,,,,0,,,,-0.0049,,,,,,250.0074615,,,,
,32589588.83,250.0080872,20474.2177734375,1.54247810465594E-5,1.18674267734153E-6,1,0.999253354069792,40.0298881530762,1.99799114737536,19.8899991810322,0.000174966227218892,2.94176173241529E-5,0.25,-7.92798457877477E-8,1.54519110184366E-5,-6.67264687799774E-8,250.0080872,250.0080872,20471.58203125,20476.853515625,57.3918556530445,20.5865198825548,23.668306,0,0,0,40,4449,250.1113,20474.2177734375,,,,,,,,,,,,,0,,,,0,,,,,,250.0080872,,,,
,32589685.72,250.012146,25319.37890625,1.11147406013873E-6,1.03327846870733E-6,1,0.999253354069792,40.0298881530762,1.99785144375577,19.8899991810322,1.30720060741075E-5,-5.62773827750623E-7,0.25,-2.42414653469494E-7,1.11362347808931E-6,-2.41926504552413E-7,250.012146,250.012146,25314.482421875,25324.275390625,57.4528226775445,20.5887843853638,24.047956,0,0,0,40,4449,250.09595,25319.37890625,,,,,,,,,,,,,0,,,,-0.0049,,,,,,250.012146,,,,
,32589784.89,250.010498,30271.791015625,-1.45151447376707E-5,1.66592142246167E-6,1,0.999253354069792,40.0298881530762,1.99789642763273,19.8899991810322,-0.000160909176188586,-4.91982756869348E-5,0.25,-1.82408674141447E-6,-1.45391182869798E-5,-1.83920162323186E-6,250.010498,250.010498,30266.513671875,30277.068359375,57.3676251689484,20.5870562978103,23.668306,0,0,0,40,4449,250.08455,30271.791015625,,,,,,,,,,,,,0,,,,0.00245,,,,,,250.010498,,,,
,32589881.955,250.0110474,35126.890625,-2.96264931707094E-5,1.57511632437034E-6,1,0.999253354069792,40.0298881530762,1.99780323560129,19.8899991810322,-0.000334907483997427,-6.29638652359952E-5,0.25,-4.18437819656146E-7,-2.9678140953808E-5,-4.43456915979815E-7,250.0110474,250.0110474,35124.31640625,35129.46484375,57.6302523514099,20.5868440663428,24.427608,0,0,0,40,4449,250.078,35126.890625,,,,,,,,,,,,,0,,,,0,,,,,,250.0110474,,,,
,32589979.22,250.0091858,39986.94921875,-4.71713816141063E-5,1.51788214437721E-6,1,0.999253354069792,40.0298881530762,1.99782174140655,19.8899991810322,-0.000529806370061782,-0.000120083058630539,0.25,-2.41625477913955E-6,-4.72521925998883E-5,-2.45910888669811E-6,250.0091858,250.0091858,39982.03515625,39991.86328125,57.5685036983907,20.5855929357537,24.047956,0,0,0,40,4449,250.0689,39986.94921875,,,,,,,,,,,,,0,,,,0,,,,,,250.0091858,,,,
,32590076.715,250.0128479,44860.369140625,-6.20537340193112E-5,2.08198553385995E-6,1,0.999253354069792,40.0298881530762,1.99770307583903,19.8899991810322,-0.000702348247062105,-0.00012664860969179,0.25,-4.15458628220443E-7,-6.21623026161178E-5,-4.66912189242815E-7,250.0128479,250.0128479,44850.15625,44870.58203125,57.5403650716984,20.5843785857912,23.668306,0,0,0,40,4449,250.05985,44860.369140625,,,,,,,,,,,,,0,,,,-0.00245,,,,,,250.0128479,,,,
,32590173.7,250.0084534,49708.044921875,-7.7448749055396E-5,2.17153093749195E-6,1,0.999253354069792,40.0298881530762,1.99781762022836,19.8899991810322,-0.000873471472217365,-0.000176367653130328,0.25,-2.13260061976994E-6,-7.75829580869056E-5,-2.1995611417314E-6,250.0084534,250.0084534,49703.09765625,49712.9921875,57.5950790680446,20.5828472135963,24.047956,0,0,0,40,4449,250.05525,49708.044921875,,,,,,,,,,,,,0,,,,-0.00245,,,,,,250.0084534,,,,
,32590269.945,250.0092468,54520.8671875,-9.48597549404115E-5,1.91468688351063E-6,1,0.999253354069792,40.0298881530762,1.99769816053392,19.8899991810322,-0.00107428322693311,-0.000189995079188048,0.25,-3.16865121324593E-7,-9.50260186307002E-5,-3.94737667193175E-7,250.0092468,250.0092468,54516.25,54525.484375,57.5903892969292,20.5849464927593,24.047956,0,0,0,40,4449,250.048,54520.8671875,,,,,,,,,,,,,0,,,,0,,,,,,250.0092468,,,,
,32590367.025,250.0108643,59370.630859375,-0.000109877883194987,2.36787829237316E-6,1,0.999253354069792,40.0298881530762,1.99764335615073,19.8899991810322,-0.00124223385080644,-0.000232159620050126,0.25,-1.43415810712964E-6,-0.000110069609540358,-1.52610327348022E-6,250.0108643,250.0108643,59368.01953125,59373.2421875,57.4184310226984,20.5849817009752,24.047956,0,0,0,40,4449,250.0319,59370.630859375,,,,,,,,,,,,,0,,,,0.00245,,,,,,250.0108643,,,,
,32590467.5,250.012146,64393.87890625,-0.000127321462247576,2.41704376049429E-6,1,0.999253354069792,40.0298881530762,1.99754519285487,19.8899991810322,-0.00143729746202781,-0.000280991692484126,0.25,-2.72003866670491E-6,-0.000127542780308605,-2.82827603915224E-6,250.012146,250.012146,64386.40625,64401.3515625,57.3566823696791,20.5875696016622,24.047956,0,0,0,40,4449,250.025,64393.87890625,,,,,,,,,,,,,0,,,,0.00245,,,,,,250.012146,,,,
,32590566.395,250.0090027,69336.24609375,-0.000141743927315248,3.21450226929658E-6,1,0.999253354069792,40.0298881530762,1.9975816525829,19.8899991810322,-0.00159885576952418,-0.000320215689764558,0.25,-3.6804297248768E-6,-0.000141989825732131,-3.80189441740762E-6,250.0090027,250.0090027,69323.8203125,69348.671875,57.3301070000253,20.5887491882152,24.047956,0,0,0,40,4449,250.01685,69336.24609375,,,,,,,,,,,,,0,,,,0,,,,,,250.0090027,,,,
,32590664.695,250.0137634,74248.984375,-0.000161414041647648,3.42378837637178E-6,1,0.999253354069792,40.0298881530762,1.9977697045173,19.8899991810322,-0.00182810346649298,-0.000323122548471928,0.25,-5.23598939923286E-7,-0.000161697034856989,-6.55279317286602E-7,250.0137634,250.0137634,74241.578125,74256.390625,57.4364084786407,20.5817746464621,24.427608,0,0,0,40,4449,250.0004,74248.984375,,,,,,,,,,,,,0,,,,-0.00245,,,,,,250.0137634,,,,
,32590764.585,250.01415255,79244.60546875,-0.000179065065086838,2.91997511936442E-6,1,0.999253354069792,40.0298881530762,1.99769645963196,19.8899991810322,-0.00202527981883724,-0.000373787145967977,0.25,-1.93508336895386E-6,-0.000179377932881011,-2.08330859242484E-6,250.0137024,250.0146027,79239.4609375,79249.75,57.4012351952753,20.5829688894014,23.668306,0,0,0,40,4449,249.98995,79244.60546875,,,,,,,,,,,,,0,,,,-0.00245,,,,,,250.01415255,,,,
,32590861.615,250.0110168,84093.09375,-0.000195253756920592,3.24634973724811E-6,1,0.999253354069792,40.0298881530762,1.99760120556752,19.8899991810322,-0.00220674432997504,-0.000416411053279046,0.25,-2.89127089774181E-6,-0.000195594331145558,-3.05401998135273E-6,250.0110168,250.0110168,84088.1953125,84097.9921875,57.4043617093522,20.5872473678544,24.427608,0,0,0,40,4449,249.98055,84093.09375,,,,,,,,,,,,,0,,,,-0.0049,,,,,,250.0110168,,,,
,32590953.75,250.0111847,88698.81640625,-0.00021035244990352,3.00783319711532E-6,1,0.999253354069792,40.0298881530762,1.99806517460863,19.8899991810322,-0.00237914251576859,-0.000441638069736562,0.25,-2.49103450845929E-6,-0.000210719894224463,-2.66501426591107E-6,250.0111847,250.0111847,88696.0546875,88701.578125,57.2996234877753,20.5774118210259,24.047956,0,0,0,40,4449,249.9741,88698.81640625,,,,,,,,,,,,,0,,,,0,,,,,,250.0111847,,,,
,32591067.045,250.0097656,86601.47265625,-0.000200775966435119,2.38365161677186E-6,1,0.999253354069792,40.0298881530762,1.99768029922478,19.8899991810322,-0.00227005909442894,-0.000423492185669551,0.25,-2.55732488604693E-6,-0.000201126533146731,-2.723819500384E-6,250.0097656,250.0097656,86593.875,86609.0703125,57.4153045086215,20.5840103515517,24.047956,0,0,0,40,4449,249.9678,86601.47265625,,,,,,,,,,,,,0,,,,0.00245,,,,,,250.0097656,,,,
,32591162.17,250.0014801,81847.8046875,-0.000187997860910902,2.81947143851462E-6,1,0.999253354069792,40.0298881530762,1.99757879921806,19.8899991810322,-0.00212141076860959,-0.000419995844018453,0.25,-4.46612756810599E-6,-0.000188324467991247,-4.62590777354888E-6,250.0014801,250.0014801,81840.265625,81855.34375,57.3402681707753,20.5854196448261,24.427608,0,0,0,40,4449,249.968,81847.8046875,,,,,,,,,,,,,0,,,,0.00245,,,,,,250.0014801,,,,
,32591260.41,249.992691,76934.0625,-0.000170274323115838,2.22826708814644E-6,1,0.999253354069792,40.0298881530762,1.99761737510658,19.8899991810322,-0.00192578678927065,-0.000355398733197948,0.25,-1.83775579444963E-6,-0.000170571950024522,-1.97881602366094E-6,249.992691,249.992691,76926.75,76941.375,57.5184794731599,20.584485449747,24.047956,0,0,0,40,4449,249.9764,76934.0625,,,,,,,,,,,,,0,,,,0.0049,,,,,,249.992691,,,,
,32591359.11,249.9902649,71998.3515625,-0.000151180131605886,2.19109884978389E-6,1,0.999253354069792,40.0298881530762,1.99777442010442,19.8899991810322,-0.00171034612724506,-0.000313350284423382,0.25,-1.43570726180352E-6,-0.000151444531503357,-1.56080152063374E-6,249.9902649,249.9902649,71988.3828125,72008.3203125,57.4879959609099,20.5830586732264,23.668306,0,0,0,40,4449,249.98105,71998.3515625,,,,,,,,,,,,,0,,,,0,,,,,,249.9902649,,,,
,32591459.795,249.9882355,66967.7265625,-0.000137800517616145,2.3531765038429E-6,1,0.999253354069792,40.0298881530762,1.99776023624995,19.8899991810322,-0.00155980583519249,-0.000280784146784924,0.25,-8.82030948760479E-7,-0.000138041852818566,-9.954836855878E-7,249.9882355,249.9882355,66965.09375,66970.359375,57.3371416566984,20.5834049988852,24.427608,0,0,0,40,4449,249.98905,66967.7265625,,,,,,,,,,,,,0,,,,0,,,,,,249.9882355,,,,
,32591558.485,249.9906921,62034.3359375,-0.00011907885267281,2.46225209588443E-6,1,0.999253354069792,40.0298881530762,1.99771765121883,19.8899991810322,-0.00135232022477946,-0.000216922345555052,0.25,1.50675629412514E-6,-0.00011928921746127,1.4125536023573E-6,249.9906921,249.9906921,62031.46875,62037.203125,57.3816944822945,20.5836828952694,23.668306,0,0,0,40,4449,249.9989,62034.3359375,,,,,,,,,,,,,0,,,,0,,,,,,249.9906921,,,,
,32591657.375,249.9874725,57091.248046875,-0.000103474912255148,1.97099913830664E-6,1,0.999253354069792,40.0298881530762,1.99762361693977,19.8899991810322,-0.0011676182199361,-0.000231408426387096,0.25,-2.47833406944479E-6,-0.000103654625305434,-2.56697215448072E-6,249.9874725,249.9874725,57083.64453125,57098.8515625,57.3590272552368,20.5878112746163,24.427608,0,0,0,40,4449,250.01015,57091.248046875,,,,,,,,,,,,,0,,,,0.00245,,,,,,249.9874725,,,,
,32591755.17,249.9880219,52204.103515625,-8.51027551802225E-5,1.92513223379552E-6,1,0.999253354069792,40.0298881530762,1.99772821040529,19.8899991810322,-0.000959711726678681,-0.000194030645483642,0.25,-2.36469391785378E-6,-8.52502783067673E-5,-2.4382681697559E-6,249.9880219,249.9880219,52196.6640625,52211.54296875,57.5771016121022,20.5908772471991,24.047956,0,0,0,40,4449,250.024,52204.103515625,,,,,,,,,,,,,0,,,,0,,,,,,249.9880219,,,,
,32591851.595,249.9861298,47385.99609375,-7.05998064608786E-5,2.24217146220955E-6,1,0.999253354069792,40.0298881530762,1.99765340999748,19.8899991810322,-0.000797026516791827,-0.000155801109225931,0.25,-1.50645618180534E-6,-7.07225542162051E-5,-1.5667762603784E-6,249.9861298,249.9861298,47378.171875,47393.8203125,57.3066581444484,20.5901346239265,23.668306,0,0,0,40,4449,250.029,47385.99609375,,,,,,,,,,,,,0,,,,0,,,,,,249.9861298,,,,
,32591949.72,249.9850616,42480.884765625,-5.21561827227523E-5,1.68404846948149E-6,1,0.999253354069792,40.0298881530762,1.99765930353225,19.8899991810322,-0.000588142514981629,-0.000118956885332742,0.25,-1.45325065278074E-6,-5.22465791029609E-5,-1.49847115237676E-6,249.9850616,249.9850616,42475.69921875,42486.0703125,57.6638623777369,20.5913914730475,24.047956,0,0,0,40,4449,250.03815,42480.884765625,,,,,,,,,,,,,0,,,,0.0049,,,,,,249.9850616,,,,
,32592045.17,249.9895477,37708.14453125,-3.86746433340038E-5,2.13378763435751E-6,1,0.999253354069792,40.0298881530762,1.99799810024998,19.8899991810322,-0.000437293956668189,-8.1842599274156E-5,0.25,-5.14608119078544E-7,-3.87421227632867E-5,-5.4719380265944E-7,249.9895477,249.9895477,37697.890625,37718.3984375,57.3785679682176,20.5860104401279,23.668306,0,0,0,40,4449,250.04965,37708.14453125,,,,,,,,,,,,,0,,,,-0.0049,,,,,,249.9895477,,,,
,32592140.095,249.9938965,32965.904296875,-2.29940565630289E-5,1.54773770273192E-6,1,0.999253354069792,40.0298881530762,1.99744094459436,19.8899991810322,-0.000256557285550877,-6.8062530659187E-5,0.25,-2.0195865499765E-6,-2.30327641387647E-5,-2.04199370954847E-6,249.9938965,249.9938965,32955.828125,32975.98046875,57.6583909781023,20.5905484741954,24.427608,0,0,0,40,4449,250.0543,32965.904296875,,,,,,,,,,,,,0,,,,-0.0049,,,,,,249.9938965,,,,
,32592232.86,249.9918213,28328.4541015625,-8.59018023644992E-6,1.19092086190966E-6,1,0.999253354069792,40.0298881530762,1.99757217315409,19.8899991810322,-9.38670476671275E-5,-3.68706339237634E-5,0.25,-1.76429024329139E-6,-8.60381019736655E-6,-1.77444260674198E-6,249.9918213,249.9918213,28323.484375,28333.423828125,57.5599057846792,20.5930810266103,24.047956,0,0,0,40,4449,250.06225,28328.4541015625,,,,,,,,,,,,,0,,,,0.0049,,,,,,249.9918213,,,,
,32592329.89,249.9835663,23480.720703125,6.16520554914024E-6,1.30936791181028E-6,1,0.999253354069792,40.0298881530762,1.99753547626609,19.8899991810322,7.02151226109649E-5,1.00419053943134E-5,0.25,-1.82922095076132E-7,6.17617936064137E-6,-1.7817323708706E-7,249.9835663,249.9835663,23475.841796875,23485.599609375,57.4012351952753,20.5910767059098,24.427608,0,0,0,40,4449,250.0756,23480.720703125,,,,,,,,,,,,,0,,,,-0.0049,,,,,,249.9835663,,,,
,32592427.805,249.9885864,18586.2490234375,2.03632163637854E-5,1.05064229000635E-6,1,0.999253354069792,40.0298881530762,1.99772691894166,19.8899991810322,0.000233321593813066,2.51838562942921E-5,0.25,-1.3090237464398E-6,2.04000370344644E-5,-1.29455467735235E-6,249.9885864,249.9885864,18578.619140625,18593.87890625,57.2722664896022,20.5936852027358,23.668306,0,0,0,40,4449,250.07995,18586.2490234375,,,,,,,,,,,,,0,,,,0,,,,,,249.9885864,,,,
,32592524.69,249.9916077,13743.8046875,3.44145423841323E-5,6.72181990160719E-7,1,0.999253354069792,40.0298881530762,1.99787458383505,19.8899991810322,0.000389774501824782,6.89440916100097E-5,0.25,1.15454746976706E-7,3.44748465091208E-5,1.44026193990213E-7,249.9916077,249.9916077,13741.1494140625,13746.4599609375,57.5114448164869,20.5927477126189,24.047956,0,0,0,40,4449,250.09065,13743.8046875,,,,,,,,,,,,,0,,,,0,,,,,,249.9916077,,,,
,32592623.58,249.9930267,8800.82568359375,4.53442043499472E-5,6.43017589324741E-7,1,0.999253354069792,40.0298881530762,1.99784032949463,19.8899991810322,0.000515167742783331,8.15327846272806E-5,0.25,-6.69083783158096E-7,4.54243309769408E-5,-6.32838070361044E-7,249.9930267,249.9930267,8798.462890625,8803.1884765625,57.3246356003907,20.5939239495753,23.668306,0,0,0,40,4449,250.0962,8800.82568359375,,,,,,,,,,,,,0,,,,-0.00245,,,,,,249.9930267,,,,
,32592718.545,249.9945068,4055.53991699219,4.90096250359664E-5,4.01758655566718E-7,1,0.999253354069792,40.0298881530762,1.99770177973517,19.8899991810322,0.00055683837948533,8.77502238389722E-5,0.25,-7.55635892657781E-7,4.90962492225796E-5,-7.16478716912429E-7,249.9945068,249.9945068,4050.74194335937,4060.337890625,57.4958122461022,20.5941186565643,24.047956,0,0,0,40,4449,250.10115,4055.53991699219,,,,,,,,,,,,,0,,,,-0.00245,,,,,,249.9945068,,,,
,32592800.455,249.9935913,-0.517608284950256,2.45178879241445E-5,4.20273684719141E-7,1,0.999253354069792,40.0298881530762,1.9976907821492,19.8899991810322,0.000278361567630275,4.50786991550363E-5,0.25,-2.73861523748298E-7,2.45611365923834E-5,-2.54076854790722E-7,249.9935913,249.9935913,-0.532832026481628,-0.502384543418884,57.3488660844868,20.5966131177995,24.047956,0,0,0,40,4417,250.10115,-0.517608284950256,,,,,,,,,,,,,0,,,,0,,,,,,249.9935913,,,,