File: data/doubleLayers/dl_1-25/ppms/data/DD205_3_ZFCW_100OE.DAT
[Header]
; VSM Data File (default extension .dat)
; Copyright (c) 2003-2013, Quantum Design, Inc. All rights reserved.
TITLE,
FILEOPENTIME,32445182.67,01/11/2019,8:35 pm
BYAPP,VSM,2.0,2.0
INFO,PPMS VSM Option Release 1.4.10 Build 1,APPNAME
INFO,Quantum Design Linear Motor Servo Controller,MOTOR_MODULE_NAME
INFO,3101-100 M1,MOTOR_HW_VERSION
INFO,MMC1014,MOTOR_SERIAL_NUMBER
INFO,SRV No X-over 01.03.11,MOTOR_SOFTWARE_VERSION
INFO,Quantum Design VSM Detection Module,VSM_MODULE_NAME
INFO,3101-150 F0,VSM_HW_VERSION
INFO,VSM707,VSM_SERIAL_NUMBER
INFO,VSM No X-over 01.02.05 May 20 2008 13:51:47,VSM_SOFTWARE_VERSION
INFO,704,PREAMP_SERIAL_NUMBER
INFO,822,COIL_SERIAL_NUMBER
INFO,0,MOMENT_UNITS
INFO,DD205_4,SAMPLE_MATERIAL
INFO,Double Layer Blue 1.25,SAMPLE_COMMENT
INFO,26.73,SAMPLE_MASS
INFO,,SAMPLE_VOLUME
INFO,,SAMPLE_MOLECULAR_WEIGHT
INFO,,SAMPLE_SIZE
INFO,,SAMPLE_SHAPE
DATATYPE,COMMENT,1
DATATYPE,TIME,2
STARTUPAXIS,X,2
STARTUPAXIS,Y1,5
[Data]
Comment,Time Stamp (sec),Temperature (K),Magnetic Field (Oe),Moment (emu),M. Std. Err. (emu),Transport Action,Averaging Time (sec),Frequency (Hz),Peak Amplitude (mm),Center Position (mm),Coil Signal' (mV),Coil Signal" (mV),Range (mV),M. Quad. Signal (emu),M. Raw' (emu),M. Raw" (emu),Min. Temperature (K),Max. Temperature (K),Min. Field (Oe),Max. Field (Oe),Mass (grams),Motor Lag (deg),Pressure (Torr),VSM Status (code),Motor Status (code),Measure Status (code),Measure Count,PPMS Status (code),System Temp. (K),System Field (Oe),Sample Position (deg),Bridge 1 Resistance (ohms),Bridge 1 Excitation (에),Bridge 2 Resistance (ohms),Bridge 2 Excitation (에),Bridge 3 Resistance (ohms),Bridge 3 Excitation (에),Bridge 4 Resistance (ohms),Bridge 4 Excitation (에),Signal 1 Vin (V),Signal 2 Vin (V),Digital Inputs (code),Drive 1 Iout (mA),Drive 1 Ipower (W),Drive 2 Iout (mA),Drive 2 Ipower (W),Pressure (),Map 20 (),Map 21 (),Map 22 (),Map 23 (),Map 24 (),Map 25 (),Map 26 (),Map 27 (),Map 28 (),Map 29 ()
,32457992.56,4.9905596,99.7613830566406,,,2,,,,20.9799998784065,,,,,,,4.9905596,4.9905596,99.7613830566406,99.7613830566406,,,8.482265,,,,-99999999,4369,5.0039,99.7613830566406,,,,,,,,,,,,,,,,,,,,,,,4.9905596,,,,
,32458223.535,7.5048714,99.7613830566406,1.00317880878431E-8,2.88360259221951E-7,1,0.999253354069792,40.0298881530762,1.99903919229326,20.9699999541044,6.27087971522644E-7,-2.87601663322586E-6,0.25,-2.57515641303905E-7,1.12161748077606E-8,-2.55989369417747E-7,7.5048714,7.5048714,99.7613830566406,99.7613830566406,56.7165286124291,20.5574580616938,10.00087,0,0,0,40,4370,7.56,99.7613830566406,,,,,,,,,,,,,0,,,,-0.00245,,,,,,7.5048714,,,,
,32458364.67,11.0089874,99.7613830566406,5.0262784212722E-9,2.88748599843689E-7,1,0.999253354069792,40.0298881530762,1.99911510305374,20.9699999541044,1.08820179499481E-6,-5.79971889609064E-6,0.25,-5.1658499483857E-7,7.48880871920687E-9,-5.13593589930326E-7,11.0089874,11.0089874,99.7613830566406,99.7613830566406,56.6758839294291,20.5649802168981,11.139823,0,0,0,40,4370,11.1178,99.7613830566406,,,,,,,,,,,,,0,,,,0,,,,,,11.0089874,,,,
,32458507.35,14.5567837,99.7613830566406,-2.12674395014078E-7,2.76193869041501E-7,1,0.999253354069792,40.0298881530762,1.99902256655684,20.9699999541044,-1.55584885376972E-6,-5.13177552484098E-6,0.25,-4.18558996744107E-7,-2.0943251372504E-7,-4.17177214478794E-7,14.5567837,14.5567837,99.7613830566406,99.7613830566406,56.946327397083,20.5641652302652,11.519473,0,0,0,40,4370,14.6988,99.7613830566406,,,,,,,,,,,,,0,,,,0.00245,,,,,,14.5567837,,,,
,32458626.68,17.5475273,99.7613830566406,-1.50760039761842E-7,2.66277711224842E-7,1,0.999253354069792,40.0298881530762,1.99909879764179,20.9699999541044,-1.06239219932022E-6,-3.86623892465264E-6,0.25,-3.17011599352543E-7,-1.48363024652341E-7,-3.15911550394684E-7,17.5475273,17.5475273,99.7613830566406,99.7613830566406,56.8204852054868,20.5658452448866,12.658426,0,0,0,40,4370,17.7006,99.7613830566406,,,,,,,,,,,,,0,,,,-0.0049,,,,,,17.5475273,,,,
,32458769.48,21.0598259,99.7613830566406,-2.53253419962734E-7,2.96944914274518E-7,1,0.999253354069792,40.0298881530762,1.99905972320181,20.9699999541044,-2.02522589428582E-6,-5.13858984458975E-6,0.25,-4.11926510811052E-7,-2.49792676301735E-7,-4.10805887089042E-7,21.0598259,21.0598259,99.7613830566406,99.7613830566406,57.0205821064099,20.5687834620798,13.417728,0,0,0,40,4370,21.2871,99.7613830566406,,,,,,,,,,,,,0,,,,-0.0049,,,,,,21.0598259,,,,
,32458907.305,24.5110989,99.7613830566406,-1.29751282324867E-7,3.02635992795308E-7,1,0.999253354069792,40.0298881530762,1.99849694197283,20.9699999541044,-1.362117272486E-6,-8.04166242146517E-7,0.25,-4.84463710420091E-8,-1.28781083570482E-7,-4.88300180300925E-8,24.5110989,24.5110989,99.7613830566406,99.7613830566406,57.0166739638137,20.5748527586874,13.417728,0,0,0,40,4370,24.75835,99.7613830566406,,,,,,,,,,,,,0,,,,0.00245,,,,,,24.5110989,,,,
,32459051.72,28.0530891,99.7613830566406,-2.33880719023895E-7,2.45127945228392E-7,1,0.999253354069792,40.0298881530762,1.9985491144011,20.9800004959106,-2.18786707120534E-6,-2.95360949487139E-6,0.25,-2.20959767697033E-7,-2.31454879184231E-7,-2.21025228873571E-7,28.0530891,28.0530891,99.7613830566406,99.7613830566406,57.2589788047753,20.5769506508574,14.177031,0,0,0,40,4370,28.4045,99.7613830566406,,,,,,,,,,,,,0,,,,0,,,,,,28.0530891,,,,
,32459190.275,31.5294514,99.7613830566406,-3.54872285344446E-7,2.75737324156699E-7,1,0.999253354069792,40.0298881530762,1.99844059129682,20.9800004959106,-3.81298498844002E-6,-1.7172841143383E-6,0.25,-8.93140502675034E-8,-3.52602697862521E-7,-9.08890974094573E-8,31.5294514,31.5294514,99.7613830566406,99.7613830566406,57.1339182416984,20.5768409809764,14.177031,0,0,0,40,4370,31.88615,99.7613830566406,,,,,,,,,,,,,0,,,,0,,,,,,31.5294514,,,,
,32459333.745,35.0608673,99.7613830566406,-2.27402114042809E-7,3.07788063734074E-7,1,0.999253354069792,40.0298881530762,1.99847698941509,20.9800004959106,-2.34215477666603E-6,-1.67299185362899E-6,0.25,-1.07947525805896E-7,-2.25738286306162E-7,-1.08866688419888E-7,35.0608673,35.0608673,99.7613830566406,99.7613830566406,57.139389641333,20.580145495002,14.936333,0,0,0,40,4370,35.50975,99.7613830566406,,,,,,,,,,,,,0,,,,0.0049,,,,,,35.0608673,,,,
,32459476.095,38.5481491,99.7613830566406,-1.0430972426094E-7,2.64405188950937E-7,1,0.999253354069792,40.0298881530762,1.99851713175568,20.9599994122982,-8.62029101239031E-7,-1.95459335049632E-6,0.25,-1.54823662289285E-7,-1.02906182009466E-7,-1.54943366631666E-7,38.5481491,38.5481491,99.7613830566406,99.7613830566406,57.1456426694868,20.5772017874117,14.936333,0,0,0,40,4370,39.0992,99.7613830566406,,,,,,,,,,,,,0,,,,0,,,,,,38.5481491,,,,
,32459617.165,42.0127373,99.7613830566406,-3.70509196045053E-7,2.98119677027951E-7,1,0.999253354069792,40.0298881530762,1.99831228837448,20.9599994122982,-3.70616086392026E-6,-3.36515720258456E-6,0.25,-2.31926936607298E-7,-3.67860814134053E-7,-2.33881050670524E-7,42.0127373,42.0127373,99.7613830566406,99.7613830566406,57.749059886333,20.5786729184241,15.695635,0,0,0,40,4370,42.66615,99.7613830566406,,,,,,,,,,,,,0,,,,0,,,,,,42.0127373,,,,
,32459759.255,45.5519676,99.7613830566406,-1.86302378543658E-7,2.94049722521576E-7,1,0.999253354069792,40.0298881530762,1.9981276265246,20.9599994122982,-1.53548275315391E-6,-3.52298151443976E-6,0.25,-2.78710859627535E-7,-1.83947751020406E-7,-2.7959391928858E-7,45.5519676,45.5519676,99.7613830566406,99.7613830566406,57.2089545795445,20.5800128810567,15.695635,0,0,0,40,4370,46.26135,99.7613830566406,,,,,,,,,,,,,0,,,,-0.00245,,,,,,45.5519676,,,,
,32459901.305,49.0361824,99.7613830566406,-4.37412819546088E-7,2.94544433031604E-7,1,0.999253354069792,40.0298881530762,1.9980770984384,20.9400001913309,-4.01747300986887E-6,-6.00971891968054E-6,0.25,-4.53264522733702E-7,-4.33786256609191E-7,-4.5625268455462E-7,49.0361824,49.0361824,99.7613830566406,99.7613830566406,57.2542890336599,20.5805204028262,16.454937,0,0,0,40,4370,49.8738,99.7613830566406,,,,,,,,,,,,,0,,,,0,,,,,,49.0361824,,,,
,32460043.04,52.5560188,99.7613830566406,-3.95141190981857E-8,3.23457284452842E-7,1,0.999253354069792,40.0298881530762,1.99757331662267,20.9400001913309,4.1763858402205E-7,-4.877110937393E-6,0.25,-4.24325649273153E-7,-3.63996087213936E-8,-4.24840910019155E-7,52.5560188,52.5560188,99.7613830566406,99.7613830566406,57.2824276603522,20.5866054949739,16.075285,0,0,0,40,4370,53.4544,99.7613830566406,,,,,,,,,,,,,0,,,,0,,,,,,52.5560188,,,,
,32460187.125,56.075346,99.7613830566406,-2.06429119556583E-7,2.80919118745425E-7,1,0.999253354069792,40.0298881530762,1.99733491088778,20.9400001913309,-2.10756735467937E-6,-1.68847836199468E-6,0.25,-1.12073336422247E-7,-2.05951502805649E-7,-1.13731212391759E-7,56.0412254,56.1094666,99.7613830566406,99.7613830566406,57.1042163579676,20.5900948327737,16.454937,0,0,0,40,4374,57.1136,99.7613830566406,,,,,,,,,,,,,0,,,,-0.00245,,,,,,56.075346,,,,
,32460307.5,59.0349884,99.7613830566406,-1.42257251760938E-8,2.8916749696954E-7,1,0.999253354069792,40.0298881530762,1.99761984724496,20.9199991077185,-7.9595633293492E-8,-4.82699886513865E-7,0.25,-4.00626302677905E-8,-1.39829813368669E-8,-4.0255201241713E-8,59.0349884,59.0349884,99.7613830566406,99.7613830566406,56.9643048530253,20.5858120208241,16.454937,0,0,0,40,4374,60.1562,99.7613830566406,,,,,,,,,,,,,0,,,,0,,,,,,59.0349884,,,,
,32460448.96,62.5197792,99.7613830566406,-2.59557285586862E-7,2.8358018895676E-7,1,0.999253354069792,40.0298881530762,1.99768060935145,20.9199991077185,-2.40236988033036E-6,-3.53974258395789E-6,0.25,-2.65729438466972E-7,-2.5864559026479E-7,-2.68250850729269E-7,62.5197792,62.5197792,99.7613830566406,99.7613830566406,57.86395927866,20.5861636658304,16.834587,0,0,0,40,4374,63.7468,99.7613830566406,,,,,,,,,,,,,0,,,,-0.00245,,,,,,62.5197792,,,,
,32460592.24,66.0604019,99.7613830566406,-1.26818219431432E-7,3.10984714895636E-7,1,0.999253354069792,40.0298881530762,1.99776236867711,20.9199991077185,-9.33696825246842E-7,-3.08162404046753E-6,0.25,-2.4896326480184E-7,-1.25789149303273E-7,-2.50673853192649E-7,66.0604019,66.0604019,99.7613830566406,99.7613830566406,57.1307917276214,20.5886337864654,17.214239,0,0,0,40,4374,67.3719,99.7613830566406,,,,,,,,,,,,,0,,,,0.00245,,,,,,66.0604019,,,,
,32460712.71,69.027832,99.7613830566406,5.52886346433108E-8,3.32656486118233E-7,1,0.999253354069792,40.0298881530762,1.99789810333127,20.8999998867512,9.85155707674147E-7,-1.89219703366212E-6,0.25,-1.76563626066167E-7,5.65263848015072E-8,-1.76993986825717E-7,69.027832,69.027832,99.7613830566406,99.7613830566406,57.1612752398714,20.5844326380469,17.593889,0,0,0,40,4374,70.4149,99.7613830566406,,,,,,,,,,,,,0,,,,-0.00245,,,,,,69.027832,,,,
,32460855.345,72.5556793,99.7613830566406,7.98484570161999E-8,3.16435383110942E-7,1,0.999253354069792,40.0298881530762,1.99791722842572,20.8999998867512,1.54581116404651E-6,-3.42905898427505E-6,0.25,-3.16156075037E-7,8.18814799256821E-8,-3.17200034832743E-7,72.5556793,72.5556793,99.7613830566406,99.7613830566406,57.0862389020253,20.5880318757513,17.973541,0,0,0,40,4374,74.0411,99.7613830566406,,,,,,,,,,,,,0,,,,-0.00245,,,,,,72.5556793,,,,
,32460997.905,76.0728607,99.7613830566406,-1.2567586244262E-8,2.4936592868241E-7,1,0.999253354069792,40.0298881530762,1.997847962869,20.8999998867512,-9.54002349185611E-8,-2.92150455905591E-7,0.25,-2.34847674851422E-8,-1.25155102495861E-8,-2.36619891333959E-8,76.0728607,76.0728607,99.7613830566406,99.7613830566406,57.3058765159291,20.590501831319,17.214239,0,0,0,40,4374,77.64255,99.7613830566406,,,,,,,,,,,,,0,,,,0,,,,,,76.0728607,,,,
,32461140.555,79.57766725,99.7613830566406,-1.65007781152819E-7,2.96595349683436E-7,1,0.999253354069792,40.0298881530762,1.99805605748194,20.8599995821714,-7.95715087164131E-7,-6.42538092373242E-6,0.25,-5.3612569015978E-7,-1.63453085419625E-7,-5.3964610033081E-7,79.544899,79.6104355,99.7613830566406,99.7613830566406,57.0283983916022,20.5867117385793,17.593889,0,0,0,40,4374,81.2779,99.7613830566406,,,,,,,,,,,,,0,,,,0,,,,,,79.57766725,,,,
,32461282.81,83.0861473,99.7613830566406,-2.93838109227152E-7,2.65235324354674E-7,1,0.999253354069792,40.0298881530762,1.99806415085843,20.8599995821714,-2.970850821809E-6,-2.67962028013499E-6,0.25,-1.83757401396279E-7,-2.94646555603684E-7,-1.85966079283439E-7,83.04599,83.1263046,99.7613830566406,99.7613830566406,57.3871658819292,20.5878642849106,18.353191,0,0,0,40,4374,84.8618,99.7613830566406,,,,,,,,,,,,,0,,,,-0.00245,,,,,,83.0861473,,,,
,32461423.975,86.5824089,99.7613830566406,1.37919540528487E-7,2.91262598726776E-7,1,0.999253354069792,40.0298881530762,1.99805781006972,20.8599995821714,1.90294533283541E-6,-1.61980467506368E-6,0.25,-1.66816303472726E-7,1.39321734458904E-7,-1.67196649787726E-7,86.5373611,86.6274567,99.7613830566406,99.7613830566406,56.9252234270637,20.5896452095498,18.353191,0,0,0,40,4374,88.4183,99.7613830566406,,,,,,,,,,,,,0,,,,-0.00245,,,,,,86.5824089,,,,
,32461562.97,90.0232544,99.7613830566406,3.67266701795075E-9,2.92441248231821E-7,1,0.999253354069792,40.0298881530762,1.9981392990662,20.8299998193979,3.94386709023446E-7,-1.99297508272047E-6,0.25,-1.7590663631478E-7,4.32910392367766E-9,-1.7687276662571E-7,90.0232544,90.0232544,99.7613830566406,99.7613830566406,57.0776409883137,20.5893041722998,17.973541,0,0,0,40,4374,91.8909,99.7613830566406,,,,,,,,,,,,,0,,,,0.00245,,,,,,90.0232544,,,,
,32461700.65,93.5162506,99.7613830566406,-3.72196467081837E-8,3.03674532520927E-7,1,0.999253354069792,40.0298881530762,1.99803086012795,20.8299998193979,-8.70019585528175E-7,2.46322241008061E-6,0.25,2.2315505041333E-7,-3.81842397458065E-8,2.24283930332372E-7,93.5162506,93.5162506,99.7613830566406,99.7613830566406,57.3535558556022,20.5906111054684,18.353191,0,0,0,40,4374,95.35115,99.7613830566406,,,,,,,,,,,,,0,,,,-0.0049,,,,,,93.5162506,,,,
,32461845.305,97.0730591,99.7613830566406,1.3915515874045E-7,2.98006499948102E-7,1,0.999253354069792,40.0298881530762,1.99770469993077,20.8299998193979,1.81132798135823E-6,-1.02411038826279E-6,0.25,-1.1452885949105E-7,1.40305357208125E-7,-1.14736185043639E-7,97.0730591,97.0730591,99.7613830566406,99.7613830566406,57.2894623170253,20.5911725794062,19.112494,0,0,0,40,4374,98.9778,99.7613830566406,,,,,,,,,,,,,0,,,,-0.00245,,,,,,97.0730591,,,,
,32461981.885,100.5098343,99.7613830566406,2.39685216209112E-7,3.2685413681162E-7,1,0.999253354069792,40.0298881530762,1.99759344336369,20.7899995148182,3.37911221359868E-6,-3.24297659672034E-6,0.25,-3.27292783785891E-7,2.42020851424248E-7,-3.28434256742442E-7,100.5098343,100.5098343,99.7613830566406,99.7613830566406,57.1151591572368,20.5927604816892,19.112494,0,0,0,40,4374,102.40605,99.7613830566406,,,,,,,,,,,,,0,,,,-0.0049,,,,,,100.5098343,,,,
,32462123.705,104.0109787,99.7613830566406,1.82115671913233E-7,3.21793653150634E-7,1,0.999253354069792,40.0298881530762,1.99750871943375,20.7899995148182,2.29862328923774E-6,-9.35029062655449E-7,0.25,-1.1418295224902E-7,1.83469191241326E-7,-1.14318958299364E-7,104.0109787,104.0109787,99.7613830566406,99.7613830566406,57.1761261817368,20.593467200493,19.112494,0,0,0,40,4374,105.9791,99.7613830566406,,,,,,,,,,,,,0,,,,0,,,,,,104.0109787,,,,
,32462266.715,107.5304565,99.7613830566406,9.48209480875932E-8,3.04725846178828E-7,1,0.999253354069792,40.0298881530762,1.99748493166573,20.7899995148182,1.32017416126664E-6,-1.19139207650676E-6,0.25,-1.21396759579582E-7,9.5679155927401E-8,-1.21832091873425E-7,107.5304565,107.5304565,99.7613830566406,99.7613830566406,57.5309855294676,20.5932067092585,19.112494,0,0,0,40,4374,109.5794,99.7613830566406,,,,,,,,,,,,,0,,,,0,,,,,,107.5304565,,,,
,32462407.555,111.0758286,99.7613830566406,-7.41958553368685E-9,2.82481872278956E-7,1,0.999253354069792,40.0298881530762,1.99770230745145,20.7499992102385,5.08484092338052E-7,-3.3996753656682E-6,0.25,-2.97650096104721E-7,-6.71410682318042E-9,-2.99344345957191E-7,111.0758286,111.0758286,99.7613830566406,99.7613830566406,57.3027500018522,20.5918356971905,19.112494,0,0,0,40,4374,113.1276,99.7613830566406,,,,,,,,,,,,,0,,,,0,,,,,,111.0758286,,,,
,32462549.055,114.5536957,99.7613830566406,-9.37382367187179E-9,3.08598591894739E-7,1,0.999253354069792,40.0298881530762,1.99760917789916,20.7499992102385,2.7605229338753E-7,-2.20498539823641E-6,0.25,-1.9226540306767E-7,-8.96820446189885E-9,-1.93363349890518E-7,114.5536957,114.5536957,99.7613830566406,99.7613830566406,57.1948852661984,20.5938254851194,18.732843,0,0,0,40,4374,116.6917,99.7613830566406,,,,,,,,,,,,,0,,,,0.00245,,,,,,114.5536957,,,,
,32462689.03,118.0525131,99.7613830566406,-8.55755061057888E-8,3.17800810217612E-7,1,0.999253354069792,40.0298881530762,1.99761862797353,20.7499992102385,-7.47567797055963E-8,-5.3064929864289E-6,0.25,-4.51694073083239E-7,-8.50261687826648E-8,-4.54395085027845E-7,118.0525131,118.0525131,99.7613830566406,99.7613830566406,57.0557553897753,20.5940121919328,19.492144,0,0,0,40,4374,120.20315,99.7613830566406,,,,,,,,,,,,,0,,,,-0.00245,,,,,,118.0525131,,,,
,32462809.615,121.0454788,99.7613830566406,7.35404651176113E-8,3.37708184260582E-7,1,0.999253354069792,40.0298881530762,1.99774675658188,20.7000002264977,8.48664341695597E-7,7.52874062260363E-8,0.25,-6.23471013552695E-9,7.39590153060102E-8,-6.10896681757245E-9,121.0454788,121.0454788,99.7613830566406,99.7613830566406,57.2910255740638,20.5903779274481,19.492144,0,0,0,40,4374,123.23325,99.7613830566406,,,,,,,,,,,,,0,,,,0.0049,,,,,,121.0454788,,,,
,32462949.155,124.5288086,99.7613830566406,2.57496760100528E-7,3.31915234773033E-7,1,0.999253354069792,40.0298881530762,1.99762425739149,20.7000002264977,3.62864303135049E-6,-3.4996754582195E-6,0.25,-3.52773201522575E-7,2.59633967964328E-7,-3.54160542760953E-7,124.5288086,124.5288086,99.7613830566406,99.7613830566406,57.2050464369484,20.5921380324638,19.492144,0,0,0,40,4374,126.7441,99.7613830566406,,,,,,,,,,,,,0,,,,0,,,,,,124.5288086,,,,
,32463090.085,128.0322876,99.7613830566406,5.2707620570324E-7,2.79762393375468E-7,1,0.999253354069792,40.0298881530762,1.99763604917335,20.7000002264977,6.32048099434344E-6,-8.29811589424924E-7,0.25,-1.6501837219461E-7,5.30244889730579E-7,-1.64858708431774E-7,128.0322876,128.0322876,99.7613830566406,99.7613830566406,57.1409528983714,20.594680961251,19.492144,0,0,0,40,4374,130.2841,99.7613830566406,,,,,,,,,,,,,0,,,,0,,,,,,128.0322876,,,,
,32463212.15,131.0496216,99.7613830566406,2.74425970923259E-7,2.3621742335344E-7,1,0.999253354069792,40.0298881530762,1.99771894010507,20.6599999219179,3.44894605510908E-6,-1.33882203049445E-6,0.25,-1.65649901633186E-7,2.76206848698856E-7,-1.66006679142776E-7,131.0496216,131.0496216,99.7613830566406,99.7613830566406,57.3402681707753,20.5905972946937,19.112494,0,0,0,40,4374,133.35525,99.7613830566406,,,,,,,,,,,,,0,,,,0.00245,,,,,,131.0496216,,,,
,32463351.36,134.52485655,99.7613830566406,4.66753284871492E-8,3.06212937244267E-7,1,0.999253354069792,40.0298881530762,1.99775227714457,20.6599999219179,9.34053658967925E-7,-2.2195108642501E-6,0.25,-2.0335981009893E-7,4.72956279371389E-8,-2.04343754602021E-7,134.4920807,134.5576324,99.7613830566406,99.7613830566406,57.1878506095253,20.5901577465647,19.871798,0,0,0,40,4374,136.8392,99.7613830566406,,,,,,,,,,,,,0,,,,-0.00245,,,,,,134.52485655,,,,
,32463492.485,138.0379639,99.7613830566406,6.7194190154247E-7,2.76943076985372E-7,1,0.999253354069792,40.0298881530762,1.99811878140299,20.6599999219179,7.98347546210361E-6,-6.34301958350501E-7,0.25,-1.7296514202747E-7,6.75733374380091E-7,-1.7267173720408E-7,138.0379639,138.0379639,99.7613830566406,99.7613830566406,57.3465211989291,20.5885739623055,20.251448,0,0,0,40,4374,140.3831,99.7613830566406,,,,,,,,,,,,,0,,,,0.0049,,,,,,138.0379639,,,,
,32463632.375,141.5300751,99.7613830566406,1.98225698389361E-7,3.07628929093877E-7,1,0.999253354069792,40.0298881530762,1.99829003329869,20.609999075532,2.10190807920768E-6,1.26545600910995E-6,0.25,7.67328360394918E-8,1.99107382496507E-7,7.74630914540746E-8,141.5300751,141.5300751,99.7613830566406,99.7613830566406,57.1112510146407,20.5878722895629,20.251448,0,0,0,40,4374,143.90495,99.7613830566406,,,,,,,,,,,,,0,,,,-0.0049,,,,,,141.5300751,,,,
,32463772.885,145.0401459,99.7613830566406,3.23849377712667E-7,3.4300395124894E-7,1,0.999253354069792,40.0298881530762,1.99827932315568,20.609999075532,3.86838985765489E-6,-4.26824973689527E-7,0.25,-9.39745792257363E-8,3.25631928944831E-7,-9.39138828839181E-8,145.0401459,145.0401459,99.7613830566406,99.7613830566406,57.3762230826599,20.5831078548797,19.871798,0,0,0,40,4374,147.42325,99.7613830566406,,,,,,,,,,,,,0,,,,0.00245,,,,,,145.0401459,,,,
,32463914.275,148.5261993,99.7613830566406,1.53707103877186E-7,3.00791041722755E-7,1,0.999253354069792,40.0298881530762,1.9982291561252,20.609999075532,2.48686216417356E-6,-3.93982561898908E-6,0.25,-3.7331916394617E-7,1.5506016079224E-7,-3.74919988926326E-7,148.5261993,148.5261993,99.7613830566406,99.7613830566406,57.1995750373137,20.5846831738441,19.871798,0,0,0,40,4374,150.9705,99.7613830566406,,,,,,,,,,,,,0,,,,-0.00245,,,,,,148.5261993,,,,
,32464056.11,152.0544434,99.7613830566406,2.36341871028384E-7,3.46612826738575E-7,1,0.999253354069792,40.0298881530762,1.99837709985106,20.5600000917912,2.80483190894742E-6,-2.09021901313933E-7,0.25,-5.95447873436054E-8,2.37580664977123E-7,-5.94707436389952E-8,152.0544434,152.0544434,99.7613830566406,99.7613830566406,57.2363115777176,20.5869656321746,20.631098,0,0,0,40,4374,154.54265,99.7613830566406,,,,,,,,,,,,,0,,,,0.00245,,,,,,152.0544434,,,,
,32464193.28,155.5137787,99.7613830566406,3.30009289362173E-7,2.91809740882213E-7,1,0.999253354069792,40.0298881530762,1.99836200578308,20.5600000917912,4.15182440422342E-6,-1.64619582309057E-6,0.25,-2.02266887313266E-7,3.3188302868109E-7,-2.02739479172272E-7,155.5137787,155.5137787,99.7613830566406,99.7613830566406,57.1440794124484,20.5892348601454,19.871798,0,0,0,40,4374,157.9757,99.7613830566406,,,,,,,,,,,,,0,,,,-0.00245,,,,,,155.5137787,,,,
,32464335.22,159.027832,99.7613830566406,5.14376153810773E-7,2.93227089641414E-7,1,0.999253354069792,40.0298881530762,1.99837126086542,20.5600000917912,6.4111148264765E-6,-2.22393176707048E-6,0.25,-2.85178911189678E-7,5.17191063122509E-7,-2.85769435555032E-7,159.027832,159.027832,99.7613830566406,99.7613830566406,57.4231207938138,20.5898051526796,19.871798,0,0,0,40,4374,161.5296,99.7613830566406,,,,,,,,,,,,,0,,,,0,,,,,,159.027832,,,,
,32464475.845,162.5145264,99.7613830566406,4.48669017735729E-7,3.14865492237038E-7,1,0.999253354069792,40.0298881530762,1.99823510657219,20.5199997872114,5.80412913070789E-6,-3.1635394401957E-6,0.25,-3.56426048081758E-7,4.51222135171036E-7,-3.5742988507305E-7,162.5145264,162.5145264,99.7613830566406,99.7613830566406,57.1550222117176,20.5866053752919,20.251448,0,0,0,40,4374,165.0492,99.7613830566406,,,,,,,,,,,,,0,,,,0,,,,,,162.5145264,,,,
,32464614.225,166.0142059,99.7613830566406,7.01923623398547E-7,3.49202283851162E-7,1,0.999253354069792,40.0298881530762,1.99814069725967,20.5199997872114,8.77387345403719E-6,-3.19594597783388E-6,0.25,-4.03356254714976E-7,7.05617996119119E-7,-4.0420917013412E-7,166.0142059,166.0142059,99.7613830566406,99.7613830566406,57.1432977839291,20.5894497776334,21.01075,0,0,0,40,4374,168.5136,99.7613830566406,,,,,,,,,,,,,0,,,,0,,,,,,166.0142059,,,,
,32464757.285,169.5415649,99.7613830566406,7.26761069130595E-7,3.14786100974672E-7,1,0.999253354069792,40.0298881530762,1.99808359517945,20.5199997872114,9.06808661886898E-6,-3.22286522691007E-6,0.25,-4.10051525800981E-7,7.30487823754263E-7,-4.10887831674666E-7,169.5415649,169.5415649,99.7613830566406,99.7613830566406,57.2456911199484,20.5941693941351,20.251448,0,0,0,40,4374,172.093,99.7613830566406,,,,,,,,,,,,,0,,,,-0.0049,,,,,,169.5415649,,,,
,32464873.905,172.5116425,99.7613830566406,8.75997213735993E-8,3.61031098161867E-7,1,0.999253354069792,40.0298881530762,1.99788563904911,20.4600002616644,2.11993433679469E-6,-6.29477985581507E-6,0.25,-5.69333958043699E-7,8.87117198362583E-8,-5.71667070993048E-7,172.5116425,172.5116425,99.7613830566406,99.7613830566406,57.2855541744291,20.5886825922041,20.251448,0,0,0,40,4374,175.0151,99.7613830566406,,,,,,,,,,,,,0,,,,0.00245,,,,,,172.5116425,,,,
,32465016.065,176.0383453,99.7613830566406,8.12047220657431E-7,3.71305471016003E-7,1,0.999253354069792,40.0298881530762,1.99763570866376,20.4600002616644,1.03722477756256E-5,-5.00540935147786E-6,0.25,-5.8188618808698E-7,8.16184751307545E-7,-5.83305170752419E-7,176.0383453,176.0383453,99.7613830566406,99.7613830566406,57.1964485232368,20.5916512070047,21.01075,0,0,0,40,4374,178.5684,99.7613830566406,,,,,,,,,,,,,0,,,,-0.00245,,,,,,176.0383453,,,,
,32465155.37,179.5344086,99.7613830566406,3.31402588108809E-7,3.38123658374754E-7,1,0.999253354069792,40.0298881530762,1.99755021282831,20.4600002616644,3.77405391662711E-6,5.93625444129628E-7,0.25,-5.33655159581201E-9,3.32764625815004E-7,-4.95206936336954E-9,179.5344086,179.5344086,99.7613830566406,99.7613830566406,57.2847725459099,20.5866790844584,20.631098,0,0,0,40,4374,182.0544,99.7613830566406,,,,,,,,,,,,,0,,,,0.00245,,,,,,179.5344086,,,,
,32465295.24,183.0062103,99.7613830566406,7.29167219278192E-7,3.02380183407434E-7,1,0.999253354069792,40.0298881530762,1.99763465467394,20.4099994152784,9.0178810992044E-6,-2.80531446473817E-6,0.25,-3.7377269828825E-7,7.3252040398574E-7,-3.74390485895306E-7,183.0062103,183.0062103,99.7613830566406,99.7613830566406,56.9596150819099,20.5860286976971,21.01075,0,0,0,40,4374,185.5562,99.7613830566406,,,,,,,,,,,,,0,,,,0,,,,,,183.0062103,,,,
,32465416.97,186.0286407,99.7613830566406,9.94566083494539E-7,2.51454443218404E-7,1,0.999253354069792,40.0298881530762,1.99797287962874,20.4099994152784,1.16710025906611E-5,-2.02055352586467E-7,0.25,-1.9062568226979E-7,9.98661594495933E-7,-1.90203477032944E-7,186.0286407,186.0286407,99.7613830566406,99.7613830566406,57.1018714724099,20.5877793142342,20.251448,0,0,0,40,4374,188.6063,99.7613830566406,,,,,,,,,,,,,0,,,,0,,,,,,186.0286407,,,,
,32465556.695,189.5220795,99.7613830566406,7.77927815375034E-7,3.3661869239591E-7,1,0.999253354069792,40.0298881530762,1.99783548844086,20.4099994152784,9.92261228294679E-6,-4.73607824298744E-6,0.25,-5.52271444885309E-7,7.81504121141605E-7,-5.53472758470259E-7,189.5220795,189.5220795,99.7613830566406,99.7613830566406,57.4418798782753,20.591114660369,20.631098,0,0,0,40,4374,192.12255,99.7613830566406,,,,,,,,,,,,,0,,,,0,,,,,,189.5220795,,,,
,32465698.045,193.037674,99.7613830566406,1.10646960117727E-6,3.16038173040286E-7,1,0.999253354069792,40.0298881530762,1.99788966275769,20.3499998897314,1.24254410646138E-5,2.97148911144468E-6,0.25,6.9500801447349E-8,1.11045899052032E-6,7.09920293328107E-8,193.037674,193.037674,99.7613830566406,99.7613830566406,56.943200883006,20.5844687695722,21.01075,0,0,0,40,4374,195.6692,99.7613830566406,,,,,,,,,,,,,0,,,,0,,,,,,193.037674,,,,
,32465837.275,196.530426,99.7613830566406,9.30117252112655E-7,3.11545758511755E-7,1,0.999253354069792,40.0298881530762,1.99798873082036,20.3499998897314,1.13678558682449E-5,-2.81873898425654E-6,0.25,-4.09839783560726E-7,9.33880824477974E-7,-4.10285126795069E-7,196.530426,196.530426,99.7613830566406,99.7613830566406,57.596642325083,20.5874825816913,20.631098,0,0,0,40,4374,199.16065,99.7613830566406,,,,,,,,,,,,,0,,,,-0.00245,,,,,,196.530426,,,,
,32465979.125,200.0405273,99.7613830566406,1.32064469000881E-6,3.56800512962239E-7,1,0.999253354069792,40.0298881530762,1.99799762797576,20.3499998897314,1.60731277953558E-5,-3.62271175844619E-6,0.25,-5.48489694209678E-7,1.32579050355019E-6,-5.48973052754116E-7,200.0405273,200.0405273,99.7613830566406,99.7613830566406,57.1042163579676,20.5872479788631,21.770052,0,0,0,40,4374,202.7204,99.7613830566406,,,,,,,,,,,,,0,,,,-0.0049,,,,,,200.0405273,,,,
,32466118.59,203.5394135,99.7613830566406,1.92193442214463E-6,3.48562442370179E-7,1,0.999253354069792,40.0298881530762,1.99817377698292,20.3000009059906,2.25122830204111E-5,-2.15464385391637E-7,0.25,-3.52724931888717E-7,1.92872197136818E-6,-3.51893540196502E-7,203.5394135,203.5394135,99.7613830566406,99.7613830566406,57.3090030300061,20.5824771706957,21.01075,0,0,0,40,4374,206.20875,99.7613830566406,,,,,,,,,,,,,0,,,,0.00245,,,,,,203.5394135,,,,
,32466258.555,207.0363159,99.7613830566406,2.29638096430549E-6,3.56584764992972E-7,1,0.999253354069792,40.0298881530762,1.99835499503374,20.3000009059906,2.57678154917986E-5,6.2487280266793E-6,0.25,1.51769387750544E-7,2.3036328471427E-6,1.5460998631901E-7,207.0363159,207.0363159,99.7613830566406,99.7613830566406,57.0979633298137,20.5855990523029,21.770052,0,0,0,40,4374,209.7214,99.7613830566406,,,,,,,,,,,,,0,,,,0,,,,,,207.0363159,,,,
,32466399.205,210.5131531,99.7613830566406,1.7582202327035E-6,3.39982375911795E-7,1,0.999253354069792,40.0298881530762,1.99841969440043,20.3000009059906,2.00064885472781E-5,3.17674631291834E-6,0.25,-2.53590316031874E-8,1.76371577957709E-6,-2.36745648524842E-8,210.5131531,210.5131531,99.7613830566406,99.7613830566406,57.2722664896022,20.5853276801311,21.3904,0,0,0,40,4374,213.24945,99.7613830566406,,,,,,,,,,,,,0,,,,0.0049,,,,,,210.5131531,,,,
,32466539.62,214.0417633,99.7613830566406,2.54614039122114E-6,3.13451340892498E-7,1,0.999253354069792,40.0298881530762,1.99844380657067,20.2500000596046,2.94594750958782E-5,1.77454473722194E-6,0.25,-2.85616995709784E-7,2.55404419142003E-6,-2.83969181326601E-7,214.0417633,214.0417633,99.7613830566406,99.7613830566406,57.2691399755253,20.58034390402,21.770052,0,0,0,40,4374,216.75325,99.7613830566406,,,,,,,,,,,,,0,,,,0,,,,,,214.0417633,,,,
,32466679.195,217.5330505,99.7613830566406,2.51589690543154E-6,3.05334550338413E-7,1,0.999253354069792,40.0298881530762,1.99844059035309,20.2500000596046,2.90653069191254E-5,1.98800607891926E-6,0.25,-2.61489460307312E-7,2.52338743221154E-6,-2.59816740572717E-7,217.5330505,217.5330505,99.7613830566406,99.7613830566406,57.1565854687561,20.5807983641653,21.3904,0,0,0,40,4374,220.2639,99.7613830566406,,,,,,,,,,,,,0,,,,0,,,,,,217.5330505,,,,
,32466818.395,221.010498,99.7613830566406,2.62372599682984E-6,3.67272990025078E-7,1,0.999253354069792,40.0298881530762,1.99842611540317,20.2500000596046,2.97095286803531E-5,5.51683835498572E-6,0.25,3.08690912496796E-8,2.63093785134154E-6,3.34353976158822E-8,221.010498,221.010498,99.7613830566406,99.7613830566406,57.3152560581599,20.5834750867998,21.770052,0,0,0,40,4374,223.7434,99.7613830566406,,,,,,,,,,,,,0,,,,0.0049,,,,,,221.010498,,,,
,32466940.695,224.0442352,99.7613830566406,3.13190730888958E-6,3.60324426479875E-7,1,0.999253354069792,40.0298881530762,1.99845447826564,20.1900005340576,3.54969079524546E-5,6.37625633332187E-6,0.25,1.85159266794573E-8,3.14021123246222E-6,2.14781702649395E-8,224.0442352,224.0442352,99.7613830566406,99.7613830566406,57.098744958333,20.5853583716876,21.770052,0,0,0,40,4374,226.8113,99.7613830566406,,,,,,,,,,,,,0,,,,-0.00245,,,,,,224.0442352,,,,
,32467079.48,227.5153046,99.7613830566406,3.95977600352317E-6,4.38443833299811E-7,1,0.999253354069792,40.0298881530762,1.99848866830551,20.1900005340576,4.5574788273308E-5,4.03000707214439E-6,0.25,-3.31840371790006E-7,3.97013045156309E-6,-3.29066844551649E-7,227.5153046,227.5153046,99.7613830566406,99.7613830566406,57.4457880208715,20.5893675596226,21.770052,0,0,0,40,4374,230.2823,99.7613830566406,,,,,,,,,,,,,0,,,,-0.0049,,,,,,227.5153046,,,,
,32467218.645,231.0007935,99.7613830566406,4.28345632728706E-6,3.80250631258018E-7,1,0.999253354069792,40.0298881530762,1.99851586716829,20.1900005340576,4.92412986611007E-5,4.66762368084336E-6,0.25,-3.31683931820968E-7,4.2941140197167E-6,-3.28645387579846E-7,231.0007935,231.0007935,99.7613830566406,99.7613830566406,57.2183341217753,20.5886054994891,21.770052,0,0,0,40,4374,233.7788,99.7613830566406,,,,,,,,,,,,,0,,,,0,,,,,,231.0007935,,,,
touchdown = 15.3599996119738 mm,32467353.37,234.3350449,99.7613830566406,4.8600274332578E-6,4.2148460987011E-7,1,0.999253354069792,40.0298881530762,1.99848006747702,20.1399996876717,5.6041984743217E-5,4.25740304928072E-6,0.25,-4.67756736416432E-7,4.87163499563694E-6,-4.64551656738979E-7,234.3094788,234.360611,99.7613830566406,99.7613830566406,57.1386080128137,20.5833651433864,22.149702,0,0,0,40,4374,237.1729,99.7613830566406,,,,,,,,,,,,,0,,,,0,,,,,,234.3350449,,,,
,32467480.585,237.5141449,99.7613830566406,5.08215947338694E-6,3.42219050628717E-7,1,0.999253354069792,40.0298881530762,1.99853440335003,20.1399996876717,5.87957694777588E-5,3.31397829313395E-6,0.25,-5.89376884133948E-7,5.0938169954436E-6,-5.86262636123836E-7,237.5141449,237.5141449,99.7613830566406,99.7613830566406,57.1581487257945,20.5864435987525,21.3904,0,0,0,40,4374,240.3566,99.7613830566406,,,,,,,,,,,,,0,,,,0,,,,,,237.5141449,,,,
,32467622.02,241.0352173,99.7613830566406,5.23369785642079E-6,4.25531767744539E-7,1,0.999253354069792,40.0298881530762,1.99833548036792,20.1399996876717,5.96566418855417E-5,8.47978470119635E-6,0.25,-1.5992014762451E-7,5.24467061628636E-6,-1.55792372325328E-7,241.0352173,241.0352173,99.7613830566406,99.7613830566406,57.2034831799099,20.5834579290685,21.770052,0,0,0,40,4374,243.9052,99.7613830566406,,,,,,,,,,,,,0,,,,0,,,,,,241.0352173,,,,
touchdown = 15.3000000864267 mm,32467772.305,244.7825546,99.7613830566406,5.84833695897962E-6,3.76630687337534E-7,1,0.999253354069792,40.0298881530762,1.99821613050833,20.0800001621246,6.62283469403668E-5,1.19055139673892E-5,0.25,3.58900359868496E-8,5.85964873936584E-6,4.08510968272602E-8,244.7585449,244.8065643,99.7613830566406,99.7613830566406,57.0846756449868,20.5825414207335,21.3904,0,0,0,40,4374,247.6729,99.7613830566406,,,,,,,,,,,,,0,,,,-0.00245,,,,,,244.7825546,,,,
,32467903.405,248.0533752,99.7613830566406,6.70047164858014E-6,3.75437178355142E-7,1,0.999253354069792,40.0298881530762,1.9982243710116,20.0800001621246,7.58809077883158E-5,1.357450977588E-5,0.25,3.55434157144587E-8,6.71266630607187E-6,4.1124530885485E-8,248.0533752,248.0533752,99.7613830566406,99.7613830566406,57.1573670972753,20.5862718879158,21.770052,0,0,0,40,4374,250.9489,99.7613830566406,,,,,,,,,,,,,0,,,,0,,,,,,248.0533752,,,,
,32468042.155,251.5003662,99.7613830566406,7.2582736214075E-6,3.28519179233287E-7,1,0.999253354069792,40.0298881530762,1.99822004901291,20.0800001621246,8.31403552045171E-5,9.20915077298217E-6,0.25,-4.46110894086776E-7,7.27099394454962E-6,-4.40993399928163E-7,251.4672241,251.5335083,99.7613830566406,99.7613830566406,57.1894138665637,20.586068321385,22.149702,0,0,0,40,4374,254.4364,99.7613830566406,,,,,,,,,,,,,0,,,,0,,,,,,251.5003662,,,,
touchdown = 15.2399996295571 mm,32468190.275,255.1785126,99.7613830566406,7.82758363942729E-6,4.35701815265864E-7,1,0.999253354069792,40.0298881530762,1.99842574009345,20.0100000947714,8.90308104017858E-5,1.35519167035625E-5,0.25,-1.6151712043764E-7,7.84002185690056E-6,-1.55542528147665E-7,255.1785126,255.1785126,99.7613830566406,99.7613830566406,57.0409044479099,20.5822798277069,22.149702,0,0,0,40,4374,258.1494,99.7613830566406,,,,,,,,,,,,,0,,,,-0.0049,,,,,,255.1785126,,,,
,32468325.215,258.5480042,99.7613830566406,8.61742876416336E-6,4.29419599406175E-7,1,0.999253354069792,40.0298881530762,1.9985169936173,20.0100000947714,9.78191751196159E-5,1.60017664455145E-5,0.25,-8.20980104037885E-8,8.63001442879386E-6,-7.54669468349197E-8,258.5480042,258.5480042,99.7613830566406,99.7613830566406,57.1722180391407,20.5834330391559,22.149702,0,0,0,40,4374,261.5375,99.7613830566406,,,,,,,,,,,,,0,,,,-0.00245,,,,,,258.5480042,,,,
,32468466.435,262.0478516,99.7613830566406,8.90316549541751E-6,3.89450532697117E-7,1,0.999253354069792,40.0298881530762,1.99837478788212,20.0100000947714,0.000101124035529782,1.60630573478997E-5,0.25,-1.25847703039844E-7,8.91509062374727E-6,-1.19152587788966E-7,262.0478516,262.0478516,99.7613830566406,99.7613830566406,57.1472059265253,20.5864392262123,22.149702,0,0,0,40,4374,265.07535,99.7613830566406,,,,,,,,,,,,,0,,,,-0.0049,,,,,,262.0478516,,,,
touchdown = 15.1800001040101 mm,32468609.695,265.649231,99.7613830566406,9.76360626073513E-6,4.49308232947588E-7,1,0.999253354069792,40.0298881530762,1.99846106057134,19.9599992483854,0.000110398130176129,2.04364298870876E-5,0.25,1.11238293893064E-7,9.77523946092483E-6,1.18776960376095E-7,265.649231,265.649231,99.7613830566406,99.7613830566406,57.0198004778906,20.5831389950514,22.149702,0,0,0,40,4374,268.64785,99.7613830566406,,,,,,,,,,,,,0,,,,0,,,,,,265.649231,,,,
,32468747.295,269.0621033,99.7613830566406,1.00709017205865E-5,4.14869272805005E-7,1,0.999253354069792,40.0298881530762,1.99850804040057,19.9599992483854,0.000114722728779442,1.61090223171322E-5,0.25,-3.23736488059118E-7,1.00820024961867E-5,-3.16563402975224E-7,269.0621033,269.0621033,99.7613830566406,99.7613830566406,57.058100275333,20.5852963852935,22.149702,0,0,0,40,4374,272.0852,99.7613830566406,,,,,,,,,,,,,0,,,,0,,,,,,269.0621033,,,,
,32468885.865,272.5013123,99.7613830566406,1.11935711109505E-5,4.36243221844973E-7,1,0.999253354069792,40.0298881530762,1.9984316285869,19.9599992483854,0.000126725726141451,2.23184759117059E-5,0.25,3.02267668392287E-8,1.12042418480216E-5,3.8489038438666E-8,272.5013123,272.5013123,99.7613830566406,99.7613830566406,57.373096568583,20.5859859387286,22.529354,0,0,0,40,4374,275.57245,99.7613830566406,,,,,,,,,,,,,0,,,,-0.00245,,,,,,272.5013123,,,,
touchdown = 15.1300001889467 mm,32469027.73,276.0202942,99.7613830566406,1.18424394723597E-5,4.21591278655796E-7,1,0.999253354069792,40.0298881530762,1.99836845328841,19.9100002646446,0.000134504789269773,2.09894599025167E-5,0.25,-1.99158269192371E-7,1.18524048233187E-5,-1.9074592150877E-7,276.0202942,276.0202942,99.7613830566406,99.7613830566406,56.7438856106022,20.5856640586443,22.529354,0,0,0,40,4374,279.11785,99.7613830566406,,,,,,,,,,,,,0,,,,0,,,,,,276.0202942,,,,
,32469166.695,279.5267334,99.7613830566406,1.235954716852E-5,3.87626512100829E-7,1,0.999253354069792,40.0298881530762,1.998471801559,19.9100002646446,0.000140886425064214,1.8909020560732E-5,0.25,-4.72230516766735E-7,1.23685815103576E-5,-4.63743519600804E-7,279.5267334,279.5267334,99.7613830566406,99.7613830566406,57.0979633298137,20.585436520002,22.149702,0,0,0,40,4374,282.5996,99.7613830566406,,,,,,,,,,,,,0,,,,0.0049,,,,,,279.5267334,,,,
,32469307.61,283.041748,99.7613830566406,1.26119557809608E-5,4.27294068592288E-7,1,0.999253354069792,40.0298881530762,1.99866301399987,19.9100002646446,0.000143063310459335,2.33065611460895E-5,0.25,-1.27434720635606E-7,1.26193317702234E-5,-1.18641999946453E-7,283.041748,283.041748,99.7613830566406,99.7613830566406,57.3902923960061,20.586307251395,22.529354,0,0,0,40,4374,286.11585,99.7613830566406,,,,,,,,,,,,,0,,,,0,,,,,,283.041748,,,,
touchdown = 15.0699997320771 mm,32469446.93,286.4528198,99.7613830566406,1.27680469726987E-5,4.3512249634716E-7,1,0.999253354069792,40.0298881530762,1.9986367399993,19.8500007390976,0.000145474093038398,1.97849737761005E-5,0.25,-4.65115059052461E-7,1.27741853388636E-5,-4.5648045605249E-7,286.4528198,286.4528198,99.7613830566406,99.7613830566406,57.1683098965445,20.5803259592156,22.529354,0,0,0,40,4374,289.594,99.7613830566406,,,,,,,,,,,,,0,,,,0.00245,,,,,,286.4528198,,,,
,32469568.27,289.504425,99.7613830566406,1.32824273339191E-5,4.14091743629309E-7,1,0.999253354069792,40.0298881530762,1.99871882323701,19.8500007390976,0.000150880728715789,2.31391881947122E-5,0.25,-2.57741970181754E-7,1.32872019809709E-5,-2.48742936268607E-7,289.504425,289.504425,99.7613830566406,99.7613830566406,57.1659650109868,20.5822275852778,22.909004,0,0,0,40,4374,292.627,99.7613830566406,,,,,,,,,,,,,0,,,,0,,,,,,289.504425,,,,
,32469708.39,293.0037537,99.7613830566406,1.34296800368091E-5,4.19650393945542E-7,1,0.999253354069792,40.0298881530762,1.99878307126875,19.8500007390976,0.000152700647625538,2.24604574436461E-5,0.25,-3.42891841045363E-7,1.34328780721481E-5,-3.3390914953928E-7,293.0037537,293.0037537,99.7613830566406,99.7613830566406,57.230840178083,20.5816108207075,22.529354,0,0,0,40,4374,296.1353,99.7613830566406,,,,,,,,,,,,,0,,,,0.0049,,,,,,293.0037537,,,,
touchdown = 15.0100002065301 mm,32469863.275,296.845459,99.7613830566406,1.35178854654152E-5,4.04404033820557E-7,1,0.999253354069792,40.0298881530762,1.99867135966043,19.7899993509054,0.000153680397955481,2.25680384659328E-5,0.25,-3.4815056461071E-7,1.35192456694077E-5,-3.39203481556521E-7,296.845459,296.845459,99.7613830566406,99.7613830566406,56.9713395096983,20.5828133665793,22.909004,0,0,0,40,4374,300.03425,99.7613830566406,,,,,,,,,,,,,0,,,,0,,,,,,296.845459,,,,
,32469992.7,300.0446777,99.7613830566406,1.4305930596939E-5,4.31972793489498E-7,1,0.999253354069792,40.0298881530762,1.99884191326971,19.7899993509054,0.000161361492973272,3.12280027342802E-5,0.25,2.80660867369818E-7,1.43053068002674E-5,2.90030656001169E-7,300.0446777,300.0446777,99.7613830566406,99.7613830566406,57.1956668947176,20.5840416924428,22.529354,0,0,0,40,4374,303.2717,99.7613830566406,,,,,,,,,,,,,0,,,,0.0049,,,,,,300.0446777,,,,
,32470132.82,303.5429993,99.7613830566406,1.38161604901331E-5,3.74018806841747E-7,1,0.999253354069792,40.0298881530762,1.99899544888623,19.7899993509054,0.000158173945780641,1.66229832282611E-5,0.25,-9.24731537370956E-7,1.38146100741734E-5,-9.15654051083693E-7,303.5429993,303.5429993,99.7613830566406,99.7613830566406,57.2902439455445,20.5854384185764,22.529354,0,0,0,40,4374,306.79335,99.7613830566406,,,,,,,,,,,,,0,,,,0.0049,,,,,,303.5429993,,,,
touchdown = 14.9499997496605 mm,32470282.695,307.2790222,99.7613830566406,1.51155224881688E-5,4.70668567966242E-7,1,0.999253354069792,40.0298881530762,1.99880889801977,19.7299998253584,0.000171453938375213,2.71712467600505E-5,0.25,-2.17112036784122E-7,1.51113007724932E-5,-2.07415730861776E-7,307.2790222,307.2790222,99.7613830566406,99.7613830566406,57.2402197203138,20.5798107387158,22.149702,0,0,0,40,4374,310.55655,99.7613830566406,,,,,,,,,,,,,0,,,,-0.00245,,,,,,307.2790222,,,,
,32470413.63,310.5377502,99.7613830566406,1.46388294993114E-5,5.15900338036691E-7,1,0.999253354069792,40.0298881530762,1.99886447670352,19.7299998253584,0.000166092854247057,2.59608428700076E-5,0.25,-2.41190113927194E-7,1.46330650147343E-5,-2.31877330375338E-7,310.5377502,310.5377502,99.7613830566406,99.7613830566406,57.2058280654676,20.5816233772725,22.149702,0,0,0,40,4374,313.829,99.7613830566406,,,,,,,,,,,,,0,,,,-0.00245,,,,,,310.5377502,,,,
,32470554.385,314.021698,99.7613830566406,1.46970601379448E-5,4.20647071184734E-7,1,0.999253354069792,40.0298881530762,1.99876015295349,19.7299998253584,0.000166048506633529,2.9962943856349E-5,0.25,1.03038699948068E-7,1.46892430704784E-5,1.12115663491026E-7,314.021698,314.021698,99.7613830566406,99.7613830566406,57.2746113751599,20.5836716798062,22.529354,0,0,0,40,4374,317.3663,99.7613830566406,,,,,,,,,,,,,0,,,,0.0049,,,,,,314.021698,,,,
touchdown = 14.8900002241135 mm,32470702.585,317.6977539,99.7613830566406,1.42992836405124E-5,3.55277334142805E-7,1,0.999253354069792,40.0298881530762,1.99873562234335,19.6700002998114,0.000162065568329099,2.60647004728677E-5,0.25,-1.72231736267989E-7,1.42899903030777E-5,-1.63353896635141E-7,317.6977539,317.6977539,99.7613830566406,99.7613830566406,57.1010898438907,20.586688113379,22.529354,0,0,0,40,4374,321.08905,99.7613830566406,,,,,,,,,,,,,0,,,,0,,,,,,317.6977539,,,,
,32470836.535,321.0309448,99.7613830566406,1.40596865291522E-5,3.93678998668866E-7,1,0.999253354069792,40.0298881530762,1.9986782928411,19.6700002998114,0.000159497278741558,2.46407774667235E-5,0.25,-2.56211599821165E-7,1.4048951352694E-5,-2.47497448565366E-7,321.0309448,321.0309448,99.7613830566406,99.7613830566406,57.3441763133715,20.5874733354009,22.529354,0,0,0,40,4374,324.4299,99.7613830566406,,,,,,,,,,,,,0,,,,0,,,,,,321.0309448,,,,
,32470977.5,324.5190735,99.7613830566406,1.35876452244733E-5,4.11172690586751E-7,1,0.999253354069792,40.0298881530762,1.99887560449248,19.6700002998114,0.000153849631823797,2.54774491749325E-5,0.25,-1.0030450516682E-7,1.35755189715135E-5,-9.20857056332403E-8,324.4843445,324.5538025,99.7613830566406,99.7613830566406,57.2112994651022,20.5883912753124,22.909004,0,0,0,40,4374,327.9642,99.7613830566406,,,,,,,,,,,,,0,,,,-0.0049,,,,,,324.5190735,,,,
touchdown = 14.8299997672439 mm,32471123.43,328.153183,99.7613830566406,1.48047542459522E-5,4.52173131588141E-7,1,0.999253354069792,40.0298881530762,1.99920500417626,19.6100007742643,0.000167399715321441,2.91231729170074E-5,0.25,1.13252568969888E-8,1.47895913577676E-5,2.0060258864614E-8,328.1288147,328.1775513,99.7613830566406,99.7613830566406,57.1722180391407,20.5770865443067,22.909004,0,0,0,40,4374,331.6415,99.7613830566406,,,,,,,,,,,,,0,,,,0.00245,,,,,,328.153183,,,,
,32471258.69,331.535553,99.7613830566406,1.40001119214615E-5,4.37565095907315E-7,1,0.999253354069792,40.0298881530762,1.99908886512807,19.6100007742643,0.000158923134793665,2.37877366480744E-5,0.25,-3.20666812413863E-7,1.3984320806573E-5,-3.12122206732992E-7,331.535553,331.535553,99.7613830566406,99.7613830566406,57.2230238928907,20.5811098482412,22.909004,0,0,0,40,4374,335.02545,99.7613830566406,,,,,,,,,,,,,0,,,,0.00245,,,,,,331.535553,,,,
,32471400.47,335.0486755,99.7613830566406,1.39448530075299E-5,4.96087521243952E-7,1,0.999253354069792,40.0298881530762,1.99912792548282,19.6100007742643,0.000158696596522988,2.12829868820645E-5,0.25,-5.32337854424638E-7,1.39275502813996E-5,-5.23612498465127E-7,335.0486755,335.0486755,99.7613830566406,99.7613830566406,57.281646031833,20.5787552591476,23.288654,0,0,0,40,4374,338.5794,99.7613830566406,,,,,,,,,,,,,0,,,,0,,,,,,335.0486755,,,,
touchdown = 14.7700002416968 mm,32471540.9,338.5229187,99.7613830566406,1.35520290122334E-5,3.81136025519663E-7,1,0.999253354069792,40.0298881530762,1.99942675741699,19.5499993860722,0.000153304268173737,2.60277489012786E-5,0.25,-4.45947951262762E-8,1.35333199782488E-5,-3.67933132186172E-8,338.5229187,338.5229187,99.7613830566406,99.7613830566406,57.1909771236022,20.5766056246564,22.909004,0,0,0,40,4374,342.1087,99.7613830566406,,,,,,,,,,,,,0,,,,0.0049,,,,,,338.5229187,,,,
,32471681.655,342.0377502,99.7613830566406,1.38582576382258E-5,4.34085119750555E-7,1,0.999253354069792,40.0298881530762,1.99928353862007,19.5499993860722,0.000157255488371419,2.36270041550996E-5,0.25,-3.09490194946492E-7,1.38376073851046E-5,-3.01194819543873E-7,342.0377502,342.0377502,99.7613830566406,99.7613830566406,57.2769562607176,20.5830418813176,22.909004,0,0,0,40,4374,345.627,99.7613830566406,,,,,,,,,,,,,0,,,,-0.0049,,,,,,342.0377502,,,,
,32471821.56,345.51297,99.7613830566406,1.31672189065278E-5,4.65821431609226E-7,1,0.999253354069792,40.0298881530762,1.99920890019684,19.5499993860722,0.000148546742941277,2.73208303900456E-5,0.25,1.3739744605257E-7,1.31457983130587E-5,1.44538410531572E-7,345.51297,345.51297,99.7613830566406,99.7613830566406,57.2230238928907,20.581281484784,22.909004,0,0,0,40,4374,349.12055,99.7613830566406,,,,,,,,,,,,,0,,,,0,,,,,,345.51297,,,,
touchdown = 14.7099997848272 mm,32471960.625,348.8404846,99.7613830566406,1.34912240525668E-5,4.6834992261488E-7,1,0.999253354069792,40.0298881530762,1.99950184425659,19.4899998605251,0.000152288997170435,2.75152972438368E-5,0.25,9.84811527218941E-8,1.34677801799149E-5,1.05808934280598E-7,348.8404846,348.8404846,99.7613830566406,99.7613830566406,57.1659650109868,20.5731325357741,23.288654,0,0,0,40,4374,351.26275,99.7613830566406,,,,,,,,,,,,,0,,,,-0.00245,,,,,,348.8404846,,,,
,32472286.5,349.782074,99.7613830566406,1.36736122479073E-5,3.66042498072449E-7,1,0.999253354069792,40.0298881530762,1.99926651532915,19.4899998605251,0.000154178765875287,2.87308772748757E-5,0.25,1.74809924416968E-7,1.36493737795494E-5,1.82109993857455E-7,349.782074,349.782074,99.7613830566406,99.7613830566406,57.3801312252561,20.5788076650702,22.909004,0,0,0,40,4369,350.837,99.7613830566406,,,,,,,,,,,,,0,,,,-0.0049,,,,,,349.782074,,,,