File: data/doubleLayers/dl_1-25/ppms/data/DD205_3_HYST_100OE_100K.DAT
[Header]
; VSM Data File (default extension .dat)
; Copyright (c) 2003-2013, Quantum Design, Inc. All rights reserved.
TITLE,
FILEOPENTIME,32545248.52,01/13/2019,12:23 am
BYAPP,VSM,2.0,2.0
INFO,PPMS VSM Option Release 1.4.10 Build 1,APPNAME
INFO,Quantum Design Linear Motor Servo Controller,MOTOR_MODULE_NAME
INFO,3101-100 M1,MOTOR_HW_VERSION
INFO,MMC1014,MOTOR_SERIAL_NUMBER
INFO,SRV No X-over 01.03.11,MOTOR_SOFTWARE_VERSION
INFO,Quantum Design VSM Detection Module,VSM_MODULE_NAME
INFO,3101-150 F0,VSM_HW_VERSION
INFO,VSM707,VSM_SERIAL_NUMBER
INFO,VSM No X-over 01.02.05 May 20 2008 13:51:47,VSM_SOFTWARE_VERSION
INFO,704,PREAMP_SERIAL_NUMBER
INFO,822,COIL_SERIAL_NUMBER
INFO,0,MOMENT_UNITS
INFO,DD205_4,SAMPLE_MATERIAL
INFO,Double Layer Blue 1.25,SAMPLE_COMMENT
INFO,26.73,SAMPLE_MASS
INFO,,SAMPLE_VOLUME
INFO,,SAMPLE_MOLECULAR_WEIGHT
INFO,,SAMPLE_SIZE
INFO,,SAMPLE_SHAPE
DATATYPE,COMMENT,1
DATATYPE,TIME,2
STARTUPAXIS,X,2
STARTUPAXIS,Y1,5
[Data]
Comment,Time Stamp (sec),Temperature (K),Magnetic Field (Oe),Moment (emu),M. Std. Err. (emu),Transport Action,Averaging Time (sec),Frequency (Hz),Peak Amplitude (mm),Center Position (mm),Coil Signal' (mV),Coil Signal" (mV),Range (mV),M. Quad. Signal (emu),M. Raw' (emu),M. Raw" (emu),Min. Temperature (K),Max. Temperature (K),Min. Field (Oe),Max. Field (Oe),Mass (grams),Motor Lag (deg),Pressure (Torr),VSM Status (code),Motor Status (code),Measure Status (code),Measure Count,PPMS Status (code),System Temp. (K),System Field (Oe),Sample Position (deg),Bridge 1 Resistance (ohms),Bridge 1 Excitation (에),Bridge 2 Resistance (ohms),Bridge 2 Excitation (에),Bridge 3 Resistance (ohms),Bridge 3 Excitation (에),Bridge 4 Resistance (ohms),Bridge 4 Excitation (에),Signal 1 Vin (V),Signal 2 Vin (V),Digital Inputs (code),Drive 1 Iout (mA),Drive 1 Ipower (W),Drive 2 Iout (mA),Drive 2 Ipower (W),Pressure (),Map 20 (),Map 21 (),Map 22 (),Map 23 (),Map 24 (),Map 25 (),Map 26 (),Map 27 (),Map 28 (),Map 29 ()
,32545264.39,99.9974823,-0.137013956904411,,,2,,,,20.7699996763468,,,,,,,99.9974823,99.9974823,-0.137013956904411,-0.137013956904411,,,19.871798,,,,-99999999,4369,99.9132,-0.137013956904411,,,,,,,,,,,,,,,,,,,,,,,99.9974823,,,,
,32545436.245,99.9991837,4942.67749023438,5.29835488668378E-5,5.13891042242469E-7,1,0.999253354069792,40.0298881530762,1.99671111606788,20.7599997520447,0.000601840573084466,0.000107798552677888,0.25,1.72514296247321E-7,5.32812230593555E-5,3.37910078120395E-7,99.9991837,99.9991837,4930.03515625,4955.31982421875,57.0737328457176,20.5946416062198,19.871798,0,0,0,40,4449,99.9136,4942.67749023438,,,,,,,,,,,,,0,,,,-0.0049,,,,,,99.9991837,,,,
,32545541.685,100.0001144,10214.076171875,4.19920743044072E-5,6.43830870231051E-7,1,0.999253354069792,40.0298881530762,1.99683171430697,20.7599997520447,0.0004775605290066,8.23615793115575E-5,0.25,-1.33544406823733E-7,4.22291417038192E-5,-4.65973461744735E-9,100.0001144,100.0001144,10201.53125,10226.62109375,57.3660619119099,20.6002128210633,19.871798,0,0,0,40,4449,99.91235,10214.076171875,,,,,,,,,,,,,0,,,,0,,,,,,100.0001144,,,,
,32545644.59,100.0021973,15356.7607421875,3.0510572821911E-5,7.5385045317868E-7,1,0.999253354069792,40.0298881530762,1.9968241707346,20.7599997520447,0.000349070127310936,4.7987874912921E-5,0.25,-1.13945870097706E-6,3.0686258218463E-5,-1.05222513812816E-6,100.0021973,100.0021973,15349.1787109375,15364.3427734375,57.2628869473714,20.6009007761935,19.871798,0,0,0,40,4449,99.9102,15356.7607421875,,,,,,,,,,,,,0,,,,0,,,,,,100.0021973,,,,
,32545732.195,100.002327,19734.43359375,1.88106463194125E-5,9.11867169110958E-7,1,0.999253354069792,40.0298881530762,1.9968320698432,20.7599997520447,0.000215567371313848,2.7574821907229E-5,0.25,-8.79174950047041E-7,1.89196219838158E-5,-8.2668802227481E-7,100.002327,100.002327,19727.041015625,19741.826171875,57.3183825722368,20.6027285550351,20.251448,0,0,0,40,4449,99.9079,19734.43359375,,,,,,,,,,,,,0,,,,0.00245,,,,,,100.002327,,,,
,32545821.61,100.0024948,24202.412109375,6.04232248298594E-6,9.97246832219109E-7,1,0.999253354069792,40.0298881530762,1.99667650234658,20.7599997520447,7.10009851027618E-5,-1.16937111389563E-6,0.25,-1.16445600841008E-6,6.08004697553471E-6,-1.15268811020913E-6,100.0024948,100.0024948,24194.830078125,24209.994140625,57.4403166212368,20.6032774990035,20.251448,0,0,0,40,4449,99.90575,24202.412109375,,,,,,,,,,,,,0,,,,0.00245,,,,,,100.0024948,,,,
,32545911.405,100.0056152,28692.943359375,-6.74316730180164E-6,1.2476085221068E-6,1,0.999253354069792,40.0298881530762,1.99678058379089,20.7599997520447,-7.39210100943904E-5,-2.89763941555845E-5,0.25,-1.36470262355756E-6,-6.77724725350499E-6,-1.39280545977989E-6,100.0056152,100.0056152,28682.787109375,28703.099609375,57.4997203886984,20.6075760098195,20.251448,0,0,0,40,4449,99.9031,28692.943359375,,,,,,,,,,,,,0,,,,0.0049,,,,,,100.0056152,,,,
,32545988.495,100.0049057,32543.099609375,-1.74942276377177E-5,1.60574471424527E-6,1,0.999253354069792,40.0298881530762,1.99675348009177,20.7599997520447,-0.000192293024128029,-7.22389602031767E-5,0.25,-3.28248853741407E-6,-1.75835842890816E-5,-3.35370162801052E-6,100.0049057,100.0049057,32540.609375,32545.58984375,57.2027015513907,20.6103571861676,19.871798,0,0,0,40,4449,99.8966,32543.099609375,,,,,,,,,,,,,0,,,,0,,,,,,100.0049057,,,,
,32546058.22,100.0054398,36028.9375,-2.88292216743214E-5,1.27708911885739E-6,1,0.999253354069792,40.0298881530762,1.99658152395925,20.7599997520447,-0.000326709154325129,-6.29701413703035E-5,0.25,-4.76773997045192E-7,-2.89914827637072E-5,-5.65763234197809E-7,100.0054398,100.0054398,36019.16796875,36038.70703125,57.1558038402368,20.6101516584584,19.871798,0,0,0,40,4449,99.89385,36028.9375,,,,,,,,,,,,,0,,,,0.0049,,,,,,100.0054398,,,,
,32546124.2,100.0072327,39327.1953125,-3.84302536067992E-5,1.46216478362482E-6,1,0.999253354069792,40.0298881530762,1.99685989938682,20.7599997520447,-0.00043442268496823,-9.05079590485924E-5,0.25,-1.21271758740338E-6,-3.86450554631272E-5,-1.33413427849086E-6,100.0072098,100.0072556,39317.09765625,39337.29296875,57.4090514804676,20.6054065477503,19.492144,0,0,0,40,4449,99.88825,39327.1953125,,,,,,,,,,,,,0,,,,-0.00245,,,,,,100.0072327,,,,
,32546192.195,100.0067825,42725.130859375,-4.80244687438756E-5,1.91816217729079E-6,1,0.999253354069792,40.0298881530762,1.99681217327949,20.7599997520447,-0.000540800297699107,-0.000124878160841482,0.25,-2.55214253935841E-6,-4.82901221355743E-5,-2.70913526665835E-6,100.0067825,100.0067825,42710.30859375,42739.953125,57.5802281261792,20.6069446514455,19.871798,0,0,0,40,4449,99.88365,42725.130859375,,,,,,,,,,,,,0,,,,0,,,,,,100.0067825,,,,
,32546258.58,100.0077209,46044.07421875,-6.02241485634691E-5,1.41631894219157E-6,1,0.999253354069792,40.0298881530762,1.99683154464668,20.7599997520447,-0.000680882461669868,-0.000141274571011745,0.25,-1.85274432474348E-6,-6.05616547187304E-5,-2.04116136655286E-6,100.0077209,100.0077209,46038.96875,46049.1796875,57.6349421225253,20.6073440983045,19.871798,0,0,0,40,4449,99.88135,46044.07421875,,,,,,,,,,,,,0,,,,0.00245,,,,,,100.0077209,,,,
,32546321.745,100.0077057,49202.88671875,-6.86571994616326E-5,2.11716983597929E-6,1,0.999253354069792,40.0298881530762,1.99688365997031,20.7599997520447,-0.000770521148685325,-0.000193680367006147,0.25,-4.98246155502372E-6,-6.90339181974724E-5,-5.21278368758634E-6,100.0077057,100.0077057,49197.92578125,49207.84765625,57.4074882234292,20.6063159116848,19.871798,0,0,0,40,4449,99.8728,49202.88671875,,,,,,,,,,,,,0,,,,-0.0049,,,,,,100.0077057,,,,
,32546385.505,100.0073624,52388.373046875,-8.31956409817219E-5,1.77236499263263E-6,1,0.999253354069792,40.0298881530762,1.99685588264466,20.7599997520447,-0.000936032404261644,-0.000221268720382126,0.25,-4.8577992119635E-6,-8.36561230964347E-5,-5.12912611478967E-6,100.0073624,100.0073624,52380.9609375,52395.78515625,57.4309370790061,20.6096870406387,19.492144,0,0,0,40,4449,99.86985,52388.373046875,,,,,,,,,,,,,0,,,,0,,,,,,100.0073624,,,,
,32546447.82,100.0058289,55501.99609375,-8.88343071526148E-5,2.0657947232317E-6,1,0.999253354069792,40.0298881530762,1.99686830091382,20.7599997520447,-0.00100347906338963,-0.000213518019482563,0.25,-3.18685189160177E-6,-8.93323787569044E-5,-3.46404961156646E-6,100.0058289,100.0058289,55494.35546875,55509.63671875,57.3090030300061,20.6075249055075,20.251448,0,0,0,40,4449,99.8677,55501.99609375,,,,,,,,,,,,,0,,,,0,,,,,,100.0058289,,,,
,32546512.23,100.00624465,58723.01953125,-0.000102641146027241,2.05591732358534E-6,1,0.999253354069792,40.0298881530762,1.99683074507145,20.7599997520447,-0.00116398018638905,-0.000220770773864621,0.25,-1.40245987928981E-6,-0.000103223860855651,-1.70839196087791E-6,100.0061493,100.00634,58713.2109375,58732.828125,57.1690915250637,20.6069818101153,19.871798,0,0,0,40,4449,99.8633,58723.01953125,,,,,,,,,,,,,0,,,,0.00245,,,,,,100.00624465,,,,
,32546577.105,100.0089188,61963.83203125,-0.000112103312218918,2.38418300962886E-6,1,0.999253354069792,40.0298881530762,1.99685113690023,20.7599997520447,-0.00126693183505486,-0.000266030427192787,0.25,-3.72394732475742E-6,-0.000112734045031404,-4.06916965834623E-6,100.0089188,100.0089188,61956.1015625,61971.5625,57.3207274577945,20.6067691113153,19.871798,0,0,0,40,4449,99.85765,61963.83203125,,,,,,,,,,,,,0,,,,0,,,,,,100.0089188,,,,
,32546640.62,100.00754165,65140.240234375,-0.000122312582800538,1.98403166578696E-6,1,0.999253354069792,40.0298881530762,1.99675579543994,20.7599997520447,-0.00138585687391797,-0.000269734625050647,0.25,-2.26021167590765E-6,-0.000123006660258147,-2.62499559702965E-6,100.007225,100.0078583,65135.18359375,65145.296875,57.373096568583,20.6079585893247,20.251448,0,0,0,40,4449,99.85265,65140.240234375,,,,,,,,,,,,,0,,,,-0.00245,,,,,,100.00754165,,,,
,32546709.63,100.0067596,68588.35546875,-0.000131263096003114,2.24813097562004E-6,1,0.999253354069792,40.0298881530762,1.99679310227218,20.7599997520447,-0.0014787321382605,-0.000338330317018995,0.25,-6.72476723244942E-6,-0.000131996466793665,-7.13906255099416E-6,100.0067596,100.0067596,68583.2421875,68593.46875,57.3871658819292,20.6098528701382,19.492144,0,0,0,40,4449,99.84905,68588.35546875,,,,,,,,,,,,,0,,,,0,,,,,,100.0067596,,,,
,32546779.5,100.0076447,72082.12890625,-0.000144892441205184,1.92847841234623E-6,1,0.999253354069792,40.0298881530762,1.99690338495976,20.7599997520447,-0.00163833070626665,-0.000339511269725247,0.25,-4.43687908516085E-6,-0.000145711427981392,-4.87502839574807E-6,100.0076447,100.0076447,72076.921875,72087.3359375,57.4942489890638,20.6073254390666,19.871798,0,0,0,40,4449,99.8455,72082.12890625,,,,,,,,,,,,,0,,,,0,,,,,,100.0076447,,,,
,32546844.465,100.0073624,75327.8203125,-0.000159210118906191,1.94985651203375E-6,1,0.999253354069792,40.0298881530762,1.9968697282452,20.7599997520447,-0.00179396150476292,-0.000408637165704845,0.25,-8.00722456320468E-6,-0.000160102081975634,-8.50460505309906E-6,100.0073624,100.0073624,75325.3359375,75330.3046875,57.2011382943522,20.6089748760318,19.492144,0,0,0,40,4449,99.8384,75327.8203125,,,,,,,,,,,,,0,,,,0,,,,,,100.0073624,,,,
,32546908.75,100.0069427,78539.58203125,-0.000167020833513136,2.52811116892365E-6,1,0.999253354069792,40.0298881530762,1.9968972034965,20.7599997520447,-0.00188174474943056,-0.000430191554149484,0.25,-8.53407618020136E-6,-0.000167957189896599,-9.05448343677731E-6,100.0069427,100.0069427,78534.703125,78544.4609375,57.3379232852176,20.6092832008568,19.871798,0,0,0,40,4449,99.83495,78539.58203125,,,,,,,,,,,,,0,,,,0,,,,,,100.0069427,,,,
,32546974.15,100.0072479,81811.1953125,-0.000180162666720011,2.12392026904379E-6,1,0.999253354069792,40.0298881530762,1.99684686346901,20.7599997520447,-0.00204033567863394,-0.000403819020479023,0.25,-3.9113554200677E-6,-0.000181188672662186,-4.43988656083606E-6,100.0072479,100.0072479,81803.8203125,81818.5703125,57.2324034351214,20.6082020292459,19.871798,0,0,0,40,4449,99.8309,81811.1953125,,,,,,,,,,,,,0,,,,-0.0049,,,,,,100.0072479,,,,
,32547042.455,100.0059814,85224.703125,-0.000188431225506558,2.40747630404992E-6,1,0.999253354069792,40.0298881530762,1.99686024177238,20.7599997520447,-0.00213065146309207,-0.000441462056069594,0.25,-5.77398713603634E-6,-0.000189500751826762,-6.333857200045E-6,100.0059814,100.0059814,85217.3125,85232.09375,57.1253203279868,20.6047231670795,19.871798,0,0,0,40,4449,99.82925,85224.703125,,,,,,,,,,,,,0,,,,0,,,,,,100.0059814,,,,
,32547114.14,100.0042877,88807.95703125,-0.000201175934100104,2.50208401584321E-6,1,0.999253354069792,40.0298881530762,1.99688712732365,20.7599997520447,-0.00227283790954769,-0.000482534566608191,0.25,-7.15303057002865E-6,-0.000202316336225746,-7.75356665781646E-6,100.0042877,100.0042877,88800.5078125,88815.40625,57.1909771236022,20.6002528293943,19.871798,0,0,0,40,4449,99.82595,88807.95703125,,,,,,,,,,,,,0,,,,0,,,,,,100.0042877,,,,
,32547210.4,100.0026321,87443.15625,-0.00019979646568572,2.73637126321597E-6,1,0.999253354069792,40.0298881530762,1.99694564365985,20.7599997520447,-0.00225880086600124,-0.000470743254226557,0.25,-6.35565349667565E-6,-0.000200930638832827,-6.9488815759429E-6,100.0026321,100.0026321,87428.2734375,87458.0390625,57.4801796757176,20.6015309505257,19.871798,0,0,0,40,4449,99.82385,87443.15625,,,,,,,,,,,,,0,,,,0,,,,,,100.0026321,,,,
,32547277.805,100.00107195,84071.84765625,-0.000189475287187803,2.20374532573408E-6,1,0.999253354069792,40.0298881530762,1.99670317220913,20.7599997520447,-0.00214977109550718,-0.000401243423557447,0.25,-2.05485728535333E-6,-0.000190560852012385,-2.59714886925705E-6,100.0010605,100.0010834,84064.3046875,84079.390625,57.5552160135638,20.6042341448958,20.251448,0,0,0,40,4449,99.825,84071.84765625,,,,,,,,,,,,,0,,,,0,,,,,,100.00107195,,,,
,32547342.805,99.9989204,80823.203125,-0.000178182525790743,2.67742046806377E-6,1,0.999253354069792,40.0298881530762,1.99676332402509,20.7599997520447,-0.00200463578712572,-0.000474544695988023,0.25,-1.04810977517383E-5,-0.000179178364106176,-1.10426125152307E-5,99.9986877,99.9991531,80815.640625,80830.765625,57.3988903097176,20.61058351916,20.251448,0,0,0,40,4449,99.82835,80823.203125,,,,,,,,,,,,,0,,,,0.00245,,,,,,99.9989204,,,,
,32547418.77,99.99897,77026.1796875,-0.000161702307978242,2.0987352505213E-6,1,0.999253354069792,40.0298881530762,1.99676523119807,20.7599997520447,-0.00182678168942614,-0.000387524730926146,0.25,-5.7154002249581E-6,-0.000162615587964332,-6.20563761432977E-6,99.99897,99.99897,77015.8046875,77036.5546875,57.2472543769868,20.6078622589801,20.251448,0,0,0,40,4449,99.8279,77026.1796875,,,,,,,,,,,,,0,,,,0.00245,,,,,,99.99897,,,,
,32547510.795,99.9962311,72423.00390625,-0.000149490837169408,2.06002696511847E-6,1,0.999253354069792,40.0298881530762,1.99685064994877,20.7599997520447,-0.00169569549976386,-0.000319442263982802,0.25,-1.86533753187534E-6,-0.000150343621310193,-2.30172086154005E-6,99.9962311,99.9962311,72407.5,72438.5078125,57.2753930036791,20.6103081041505,20.251448,0,0,0,40,4449,99.8299,72423.00390625,,,,,,,,,,,,,0,,,,0,,,,,,99.9962311,,,,
,32547589.805,99.9955826,68476.7578125,-0.000135824020167263,1.61830580487191E-6,1,0.999253354069792,40.0298881530762,1.99690124167051,20.7599997520447,-0.00154029513918351,-0.000292536186346679,0.25,-1.89432394713317E-6,-0.000136597328860991,-2.29414413728939E-6,99.9955826,99.9955826,68469.2578125,68484.2578125,57.5989872106407,20.6052181727785,19.871798,0,0,0,40,4449,99.8325,68476.7578125,,,,,,,,,,,,,0,,,,-0.00245,,,,,,99.9955826,,,,
,32547685.55,99.9941559,63691.33984375,-0.000118587673553233,2.31502618666759E-6,1,0.999253354069792,40.0298881530762,1.99695898149033,20.7599997520447,-0.00133569016551502,-0.000307626846917017,0.25,-6.2441157584192E-6,-0.000119248615384378,-6.62177769733191E-6,99.9941559,99.9941559,63676.31640625,63706.36328125,57.5239508727946,20.6072043170804,19.871798,0,0,0,40,4449,99.83805,63691.33984375,,,,,,,,,,,,,0,,,,-0.00245,,,,,,99.9941559,,,,
,32547769.15,99.9958954,59510.349609375,-0.0001060471810758,1.85148268092168E-6,1,0.999253354069792,40.0298881530762,1.99686837114438,20.7599997520447,-0.00119227622530327,-0.000287072652082598,0.25,-6.63681645826761E-6,-0.000106634303618866,-6.98234853151745E-6,99.9958954,99.9958954,59497.7109375,59522.98828125,57.80299225416,20.6103580646303,19.871798,0,0,0,40,4449,99.83815,59510.349609375,,,,,,,,,,,,,0,,,,0,,,,,,99.9958954,,,,
,32547869.16,99.9957886,54510.103515625,-8.79172982305585E-5,1.62690652173999E-6,1,0.999253354069792,40.0298881530762,1.99688300292262,20.7599997520447,-0.000988773616713324,-0.000236101306019713,0.25,-5.3339203690878E-6,-8.84036717819766E-5,-5.6211466422581E-6,99.9957886,99.9957886,54500.25390625,54519.953125,57.6239993232561,20.6074028259675,20.251448,0,0,0,40,4449,99.84575,54510.103515625,,,,,,,,,,,,,0,,,,0.0049,,,,,,99.9957886,,,,
,32547967.21,99.9941711,49609.984375,-7.09320375083396E-5,1.63544457364494E-6,1,0.999253354069792,40.0298881530762,1.9969405675146,20.7599997520447,-0.000800315744910191,-0.000175941109632636,0.25,-3.02212264062448E-6,-7.13275287407885E-5,-3.2479202855573E-6,99.9941711,99.9941711,49597.4375,49622.53125,57.7482782578138,20.6084133522642,19.492144,0,0,0,40,4449,99.85085,49609.984375,,,,,,,,,,,,,0,,,,-0.0049,,,,,,99.9941711,,,,
,32548060.68,99.993187,44940.0859375,-5.77612648271653E-5,1.86266943510714E-6,1,0.999253354069792,40.0298881530762,1.99689746222081,20.7599997520447,-0.000652888122567367,-0.000136460689835084,0.25,-1.86106555151678E-6,-5.80845842086945E-5,-2.04258179597942E-6,99.993187,99.993187,44924.921875,44955.25,57.3996719382368,20.6086518770586,20.251448,0,0,0,40,4449,99.85615,44940.0859375,,,,,,,,,,,,,0,,,,0,,,,,,99.993187,,,,
,32548163.235,99.9938812,39814.384765625,-3.99792886842029E-5,1.22176299047361E-6,1,0.999253354069792,40.0298881530762,1.99709189285854,20.7599997520447,-0.00044785336967891,-0.00011768367432047,0.25,-3.3302511864636E-6,-4.01966097479953E-5,-3.46829280984709E-6,99.9938812,99.9938812,39801.890625,39826.87890625,57.5028469027753,20.6111161370804,19.871798,0,0,0,40,4449,99.86345,39814.384765625,,,,,,,,,,,,,0,,,,0,,,,,,99.9938812,,,,
,32548265.425,99.9915619,34707.05078125,-2.40411267612326E-5,2.46922912877488E-6,1,0.999253354069792,40.0298881530762,1.99720150795381,20.7599997520447,-0.000272477641726285,-5.28125925181753E-5,0.25,-4.2254026594688E-7,-2.41763006899734E-5,-4.97043971207256E-7,99.9915619,99.9915619,34694.58984375,34719.51171875,57.3011867448138,20.6048749560922,20.251448,0,0,0,40,4449,99.8707,34707.05078125,,,,,,,,,,,,,0,,,,0,,,,,,99.9915619,,,,
,32548365.785,99.9916229,29690.025390625,-8.4830144477542E-6,1.12334466180421E-6,1,0.999253354069792,40.0298881530762,1.99717180005395,20.7599997520447,-9.35245822904157E-5,-3.35383764863984E-5,0.25,-1.45987976063418E-6,-8.52667943588314E-6,-1.49375863017683E-6,99.9916229,99.9916229,29677.30078125,29702.75,57.8569246219869,20.6134127004087,20.251448,0,0,0,40,4449,99.8774,29690.025390625,,,,,,,,,,,,,0,,,,0,,,,,,99.9916229,,,,
,32548469.215,99.992897,24519.87109375,6.48602782548591E-6,6.87062857727915E-7,1,0.999253354069792,40.0298881530762,1.9972144775439,20.7599997520447,7.71484539442537E-5,-6.45817542468418E-6,0.25,-1.70758912872814E-6,6.52791435630344E-6,-1.69754833827552E-6,99.992897,99.992897,24509.89453125,24529.84765625,57.9108569898138,20.6098191029198,19.492144,0,0,0,40,4449,99.88745,24519.87109375,,,,,,,,,,,,,0,,,,0.00245,,,,,,99.992897,,,,
,32548576.735,99.9916153,19147.7958984375,2.17562593119123E-5,7.23426308777669E-7,1,0.999253354069792,40.0298881530762,1.99722131611278,20.7599997520447,0.000248026571483387,3.95436135890265E-5,0.25,-3.44455035792635E-7,2.18802241685368E-5,-2.7988782622985E-7,99.9916153,99.9916153,19137.70703125,19157.884765625,57.5935158110061,20.6081450195126,20.251448,0,0,0,40,4449,99.8948,19147.7958984375,,,,,,,,,,,,,0,,,,0.0049,,,,,,99.9916153,,,,
,32548678.905,99.9898758,14043.41796875,3.59508374896034E-5,5.77466319826142E-7,1,0.999253354069792,40.0298881530762,1.99706752250874,20.7599997520447,0.000409965547506112,6.4481059159849E-5,0.25,-6.45204271340313E-7,3.61556409338018E-5,-5.38304296821714E-7,99.9898758,99.9898758,14035.8603515625,14050.9755859375,57.8225329671407,20.6124826112308,20.251448,0,0,0,40,4449,99.90455,14043.41796875,,,,,,,,,,,,,0,,,,0,,,,,,99.9898758,,,,
,32548781.135,99.9940414,8931.0390625,4.93930935126352E-5,7.01181262186428E-7,1,0.999253354069792,40.0298881530762,1.99731917096116,20.7599997520447,0.000561242858257614,0.000100408866440277,0.25,1.51346775293453E-7,4.96709029044033E-5,3.04891080259382E-7,99.9940414,99.9940414,8923.6064453125,8938.4716796875,57.3207274577945,20.609867915635,19.871798,0,0,0,40,4449,99.9116,8931.0390625,,,,,,,,,,,,,0,,,,0,,,,,,99.9940414,,,,
,32548884.005,99.9917831,3790.07971191406,6.06824884598642E-5,3.69407123638354E-7,1,0.999253354069792,40.0298881530762,1.9971999583991,20.7599997520447,0.000690077462572423,0.000119939093484831,0.25,-1.15061348269631E-7,6.10243154162522E-5,7.27858926394009E-8,99.9917831,99.9917831,3780.10888671875,3800.05053710937,57.6935642614676,20.6134815380772,19.871798,0,0,0,40,4449,99.9186,3790.07971191406,,,,,,,,,,,,,0,,,,0,,,,,,99.9917831,,,,
,32548988.23,99.9932556,-1415.36047363281,6.35888172968268E-5,2.85155738395034E-7,1,0.999253354069792,40.0298881530762,1.99707203403777,20.7599997520447,0.000722453702670999,0.000129250038337954,0.25,1.93531890914198E-7,6.39458729589287E-5,3.92499299115936E-7,99.9932556,99.9932556,-1425.29577636719,-1405.42517089844,57.5098815594484,20.6116026401586,19.871798,0,0,0,40,4449,99.9245,-1415.36047363281,,,,,,,,,,,,,0,,,,-0.0049,,,,,,99.9932556,,,,
,32549093.415,99.9975586,-6674.47436523437,5.78215442338477E-5,4.46673601749234E-7,1,0.999253354069792,40.0298881530762,1.9969329151603,20.7599997520447,0.000656540007140963,0.000119513820419219,0.25,3.52166335154324E-7,5.81460465692742E-5,5.33257146951419E-7,99.9975586,99.9975586,-6686.8095703125,-6662.13916015625,57.5348936720638,20.6118230841291,20.251448,0,0,0,40,4449,99.92545,-6674.47436523437,,,,,,,,,,,,,0,,,,-0.00245,,,,,,99.9975586,,,,
,32549195.14,100.0034866,-11760.2778320312,3.50159283847077E-5,6.08309950867559E-7,1,0.999253354069792,40.0298881530762,1.99692897726581,20.7599997520447,0.000398266103510926,6.85496057767826E-5,0.25,-1.22837500338091E-7,3.52137291862866E-5,-1.56160916051154E-8,100.0034866,100.0034866,-11770.3564453125,-11750.19921875,57.6810582051599,20.6158944636728,20.251448,0,0,0,40,4449,99.9166,-11760.2778320312,,,,,,,,,,,,,0,,,,-0.0049,,,,,,100.0034866,,,,
,32549286.13,100.0085983,-16307.8129882812,1.0514040802183E-5,6.3687591150187E-7,1,0.999253354069792,40.0298881530762,1.99701622503724,20.7599997520447,0.000118191671678156,2.85472782036114E-5,0.25,6.63809972222649E-7,1.05713558800932E-5,6.99799233569393E-7,100.0085983,100.0085983,-16313.0126953125,-16302.61328125,57.7740719989484,20.6116202049368,19.871798,0,0,0,40,4449,99.90965,-16307.8129882812,,,,,,,,,,,,,0,,,,0.0049,,,,,,100.0085983,,,,
,32549389.355,100.0108948,-21464.94140625,-6.36857079477212E-7,8.44474260664118E-7,1,0.999253354069792,40.0298881530762,1.99703347937214,20.7599997520447,-1.03748492763605E-5,1.65725175612111E-5,0.25,1.56976251083712E-6,-6.45242678337357E-7,1.57669490755994E-6,100.0108948,100.0108948,-21469.794921875,-21460.087890625,57.7076335748138,20.6139078426208,20.251448,0,0,0,40,4449,99.89865,-21464.94140625,,,,,,,,,,,,,0,,,,-0.0049,,,,,,100.0108948,,,,
,32549490.455,100.0113297,-26519.6552734375,4.48888760285246E-6,1.06888298076026E-6,1,0.999253354069792,40.0298881530762,1.99694376071817,20.7599997520447,5.20456632183423E-5,3.16313806908618E-6,0.25,-5.10346317268404E-7,4.51584664106374E-6,-4.99633659509595E-7,100.0113297,100.0113297,-26527.283203125,-26512.02734375,57.8295676238138,20.6139716910072,20.251448,0,0,0,40,4449,99.888,-26519.6552734375,,,,,,,,,,,,,0,,,,-0.00245,,,,,,100.0113297,,,,
,32549595.365,100.0113525,-31762.3115234375,1.88937287266164E-5,1.38165946218546E-6,1,0.999253354069792,40.0298881530762,1.99701888787212,20.7599997520447,0.000209312513204608,6.88585514358104E-5,0.25,2.73842424736826E-6,1.89926126974727E-5,2.81082814844878E-6,100.0113525,100.0113525,-31769.921875,-31754.701171875,57.4520410490253,20.6117650406822,19.871798,0,0,0,40,4449,99.87925,-31762.3115234375,,,,,,,,,,,,,0,,,,0.0049,,,,,,100.0113525,,,,
,32549697.43,100.0100937,-36863.8203125,3.27794231056357E-5,1.33798335202967E-6,1,0.999253354069792,40.0298881530762,1.99708876788216,20.7599997520447,0.000369925548286743,8.09526446666809E-5,0.25,1.36347497825424E-6,3.29614896501218E-5,1.46925219764117E-6,100.0100937,100.0100937,-36866.28515625,-36861.35546875,57.7678189707946,20.6155310156594,19.871798,0,0,0,40,4449,99.8708,-36863.8203125,,,,,,,,,,,,,0,,,,0.0049,,,,,,100.0100937,,,,
,32549800.415,100.0104218,-42010.8828125,4.73665174020413E-5,1.65603256468371E-6,1,0.999253354069792,40.0298881530762,1.99699928809064,20.7599997520447,0.0005345879647926,0.000116628563045831,0.25,1.94084721017531E-6,4.76301434300139E-5,2.09260384440678E-6,100.0104218,100.0104218,-42018.5703125,-42003.1953125,57.66073586366,20.6184591276573,20.251448,0,0,0,40,4449,99.8576,-42010.8828125,,,,,,,,,,,,,0,,,,-0.00245,,,,,,100.0104218,,,,
,32549906.43,100.0116806,-47308.568359375,6.33863557338757E-5,1.77299810080454E-6,1,0.999253354069792,40.0298881530762,1.99696578837372,20.7599997520447,0.000715959795964548,0.000152808290983811,0.25,2.31143512993765E-6,6.37406128144599E-5,2.51158941650005E-6,100.0116806,100.0116806,-47315.703125,-47301.43359375,57.6341604940061,20.6179053392695,20.631098,0,0,0,40,4449,99.8468,-47308.568359375,,,,,,,,,,,,,0,,,,-0.0049,,,,,,100.0116806,,,,
,32550012.04,100.0093918,-52585.166015625,8.02135157392868E-5,1.97384098057341E-6,1,0.999253354069792,40.0298881530762,1.997062929408,20.7599997520447,0.000907434128546847,0.000185651887928235,0.25,2.24650415186351E-6,8.06645948142074E-5,2.49426437383807E-6,100.0093918,100.0093918,-52597.6640625,-52572.66796875,57.6357237510446,20.617465208496,20.251448,0,0,0,40,4449,99.8361,-52585.166015625,,,,,,,,,,,,,0,,,,0.00245,,,,,,100.0093918,,,,
,32550117.43,100.0094299,-57854.794921875,9.89355090632953E-5,1.65503951944187E-6,1,0.999253354069792,40.0298881530762,1.99709670322798,20.7599997520447,0.00111652892997379,0.00024454486987077,0.25,4.14118672034723E-6,9.94888420710523E-5,4.45252867664566E-6,100.0094299,100.0094299,-57859.83984375,-57849.75,57.5755383550638,20.6191762011483,20.251448,0,0,0,40,4449,99.8282,-57854.794921875,,,,,,,,,,,,,0,,,,0,,,,,,100.0094299,,,,
,32550221.835,100.0089035,-63072.5,0.00011685538562593,1.71671572259502E-6,1,0.999253354069792,40.0298881530762,1.99714721299748,20.7599997520447,0.00132233328121445,0.000268758975968459,0.25,3.12676002897327E-6,0.000117515183345035,3.48197285573359E-6,100.0089035,100.0089035,-63087.48046875,-63057.51953125,57.5481813568907,20.6152967134723,20.251448,0,0,0,40,4449,99.8197,-63072.5,,,,,,,,,,,,,0,,,,0,,,,,,100.0089035,,,,
,32550326.97,100.0084763,-68323.95703125,0.000133943883272867,2.26340570708232E-6,1,0.999253354069792,40.0298881530762,1.99704540000536,20.7599997520447,0.00151524509986006,0.000310338527799089,0.25,3.78821751801699E-6,0.000134700857813844,4.19372180265474E-6,100.0084763,100.0084763,-68334.0234375,-68313.890625,57.5645955557946,20.6200716888249,20.251448,0,0,0,40,4449,99.8116,-68323.95703125,,,,,,,,,,,,,0,,,,0,,,,,,100.0084763,,,,
,32550432.465,100.007782,-73595.65234375,0.000149361618538316,1.68585499449966E-6,1,0.999253354069792,40.0298881530762,1.99735000735783,20.7599997520447,0.00169379113582753,0.000324058851468434,0.25,2.28782077388982E-6,0.000150212656263045,2.72571884570658E-6,100.007782,100.007782,-73605.78125,-73585.5234375,57.3269804859484,20.6174743913044,20.251448,0,0,0,40,4449,99.80345,-73595.65234375,,,,,,,,,,,,,0,,,,-0.00245,,,,,,100.007782,,,,
,32550538.665,100.0063858,-78905.13671875,0.000168573318602516,2.14959348446167E-6,1,0.999253354069792,40.0298881530762,1.99732424031633,20.7599997520447,0.00190262110195713,0.000417194893459525,0.25,7.11093779019242E-6,0.000169522611822722,7.62756139327554E-6,100.0063858,100.0063858,-78917.8046875,-78892.46875,57.6740235484869,20.6182968812246,20.251448,0,0,0,40,4449,99.7985,-78905.13671875,,,,,,,,,,,,,0,,,,-0.00245,,,,,,100.0063858,,,,
,32550644.38,100.0051956,-84186.98046875,0.000193638615171092,2.93189554313382E-6,1,0.999253354069792,40.0298881530762,1.99733843564548,20.7599997520447,0.00219549832012663,0.00042258497671479,0.25,3.19039024061404E-6,0.000194744888610952,3.75105407346847E-6,100.0051956,100.0051956,-84204.4921875,-84169.46875,57.5982055821215,20.6148535791086,20.631098,0,0,0,40,4449,99.7932,-84186.98046875,,,,,,,,,,,,,0,,,,0,,,,,,100.0051956,,,,
,32550748.64,100.0062256,-89398.73828125,0.000203646012670141,2.4125267365795E-6,1,0.999253354069792,40.0298881530762,1.99724316752782,20.7599997520447,0.00230107857264739,0.000488871985955624,0.25,7.26997650842804E-6,0.000204800389321755,7.87791535975676E-6,100.0062256,100.0062256,-89411.15625,-89386.3203125,57.6662072632946,20.6211176286713,19.871798,0,0,0,40,4449,99.78555,-89398.73828125,,,,,,,,,,,,,0,,,,0,,,,,,100.0062256,,,,
,32550876.11,100.0012169,-85647.6640625,0.000189934493526479,1.8866539675626E-6,1,0.999253354069792,40.0298881530762,1.99710356227001,20.7599997520447,0.00214765119474618,0.000446449051366747,0.25,5.94431493737481E-6,0.000191012204769195,6.50941126927106E-6,100.0011368,100.001297,-85660.0078125,-85635.3203125,57.8858448771984,20.6192136112593,20.251448,0,0,0,40,4449,99.784,-85647.6640625,,,,,,,,,,,,,0,,,,-0.00245,,,,,,100.0012169,,,,
,32550980.17,99.9987183,-80448.28515625,0.000173064909142576,2.1370498816283E-6,1,0.999253354069792,40.0298881530762,1.99730850180691,20.7599997520447,0.00195699217271586,0.000407304390431511,0.25,5.45417803835098E-6,0.000174045183612408,5.97294526774024E-6,99.9987183,99.9987183,-80453.1640625,-80443.40625,57.4684552479292,20.614882477655,20.251448,0,0,0,40,4449,99.78745,-80448.28515625,,,,,,,,,,,,,0,,,,0.0049,,,,,,99.9987183,,,,
,32551085.37,99.9970055,-75188.23828125,0.000157083825912774,1.63749905143024E-6,1,0.999253354069792,40.0298881530762,1.99717359124187,20.7599997520447,0.00177764910999185,0.000361118887717722,0.25,4.19541755671501E-6,0.000157974226439772,4.66529432772401E-6,99.9969559,99.9970551,-75200.4296875,-75176.046875,57.8545797364292,20.6198041998921,20.631098,0,0,0,40,4449,99.79085,-75188.23828125,,,,,,,,,,,,,0,,,,0,,,,,,99.9970055,,,,
,32551190.325,99.9959564,-69946.6640625,0.000138601056913496,1.51067701244199E-6,1,0.999253354069792,40.0298881530762,1.99724063189614,20.7599997520447,0.00156672761652898,0.000328867444568129,0.25,4.59864825264606E-6,0.000139382814742477,5.02132847058469E-6,99.9959564,99.9959564,-69954.1796875,-69939.1484375,57.4043617093522,20.6185160273518,20.631098,0,0,0,40,4449,99.7953,-69946.6640625,,,,,,,,,,,,,0,,,,-0.0049,,,,,,99.9959564,,,,
,32551294.345,99.9961624,-64744.775390625,0.000122927656703997,2.55262932908873E-6,1,0.999253354069792,40.0298881530762,1.99729640145578,20.7599997520447,0.0013900550812787,0.000288984671082761,0.25,3.83867604674667E-6,0.000123620517695045,4.21477019293249E-6,99.9959717,99.9963531,-64752.265625,-64737.28515625,57.5700669554292,20.6159410894475,20.251448,0,0,0,40,4449,99.79935,-64744.775390625,,,,,,,,,,,,,0,,,,0.00245,,,,,,99.9961624,,,,
,32551397.505,99.9960938,-59589.865234375,0.000105024204031083,1.27934695347454E-6,1,0.999253354069792,40.0298881530762,1.99716870307217,20.7599997520447,0.00118744528664524,0.000247309075941784,0.25,3.31524151677821E-6,0.000105615053460253,3.63893822330669E-6,99.9960938,99.9960938,-59604.82421875,-59574.90625,57.6787133196022,20.6150026754732,19.871798,0,0,0,40,4449,99.80585,-59589.865234375,,,,,,,,,,,,,0,,,,0.00245,,,,,,99.9960938,,,,
,32551498.045,99.994751,-54565.46875,8.85946960723917E-5,1.83073135074002E-6,1,0.999253354069792,40.0298881530762,1.99721889492745,20.7599997520447,0.000999259781728854,0.000222531844055863,0.25,4.01804534204815E-6,8.9088719473317E-5,4.299867509859E-6,99.994751,99.994751,-54582.93359375,-54548.00390625,57.5481813568907,20.6178006360196,19.871798,0,0,0,40,4449,99.8098,-54565.46875,,,,,,,,,,,,,0,,,,0,,,,,,99.994751,,,,
,32551602.96,99.9944229,-49323.220703125,6.88851537909327E-5,1.47152764296546E-6,1,0.999253354069792,40.0298881530762,1.99721183623547,20.7599997520447,0.000777103319129258,0.000172123948585399,0.25,3.04359881717265E-6,6.92688129313499E-5,3.26370565633073E-6,99.9944229,99.9944229,-49335.69140625,-49310.75,57.4715817620061,20.6138046104431,20.251448,0,0,0,40,4449,99.81245,-49323.220703125,,,,,,,,,,,,,0,,,,0.00245,,,,,,99.9944229,,,,
,32551705.525,99.9929886,-44195.982421875,5.56098672746145E-5,1.69177469532306E-6,1,0.999253354069792,40.0298881530762,1.99716037456144,20.7599997520447,0.000625648040200129,0.000148477188747914,0.25,3.29408470003972E-6,5.59165693678887E-5,3.47764837237528E-6,99.9929886,99.9929886,-44198.33984375,-44193.625,57.5575608991215,20.6167569269195,19.871798,0,0,0,40,4449,99.82155,-44195.982421875,,,,,,,,,,,,,0,,,,0,,,,,,99.9929886,,,,
,32551809.265,99.9927521,-39011.294921875,3.78837713018474E-5,1.32621435384139E-6,1,0.999253354069792,40.0298881530762,1.99714826193786,20.7599997520447,0.000426794535654454,9.78242716629533E-5,0.25,1.95099742522124E-6,3.80931988062395E-5,2.07514144671934E-6,99.9927521,99.9927521,-39021.51953125,-39001.0703125,57.6357237510446,20.613997381456,20.631098,0,0,0,40,4449,99.82765,-39011.294921875,,,,,,,,,,,,,0,,,,0.0049,,,,,,99.9927521,,,,
,32551912.85,99.9908905,-33836.78515625,2.1376040568783E-5,1.48074323681091E-6,1,0.999253354069792,40.0298881530762,1.99727688325716,20.7599997520447,0.000238323090557153,6.94874253983532E-5,0.25,2.35705054063522E-6,2.14902259304418E-5,2.43464609309779E-6,99.9908905,99.9908905,-33849.3359375,-33824.234375,57.6646440062561,20.6144235198219,19.871798,0,0,0,40,4449,99.83545,-33836.78515625,,,,,,,,,,,,,0,,,,0.0049,,,,,,99.9908905,,,,
,32552013.885,99.9907837,-28784.6455078125,6.90648888908233E-6,9.81471618544922E-7,1,0.999253354069792,40.0298881530762,1.9971701427849,20.7599997520447,7.6333017465143E-5,2.62248874164973E-5,0.25,1.09349425891272E-6,6.94230463738929E-6,1.12057119171916E-6,99.9907837,99.9907837,-28801.9609375,-28767.330078125,58.1297129751985,20.6138982793413,20.251448,0,0,0,40,4449,99.8454,-28784.6455078125,,,,,,,,,,,,,0,,,,-0.00245,,,,,,99.9907837,,,,
,32552116.92,99.9912796,-23634.90234375,-9.18885188038555E-6,8.18261834171649E-7,1,0.999253354069792,40.0298881530762,1.9973368521862,20.7599997520447,-0.000105320289677184,-1.35222179430466E-5,0.25,4.25070273220895E-7,-9.24211699069122E-6,3.99514117212378E-7,99.9912796,99.9912796,-23644.990234375,-23624.814453125,57.9843300706215,20.6140723577496,19.871798,0,0,0,40,4449,99.85275,-23634.90234375,,,,,,,,,,,,,0,,,,0,,,,,,99.9912796,,,,
,32552220.745,99.9905777,-18445.904296875,-2.45672704953564E-5,8.51677362922199E-7,1,0.999253354069792,40.0298881530762,1.99728731346199,20.7599997520447,-0.000279367741332059,-4.8713933658801E-5,0.25,3.19715216338301E-8,-2.47061141320318E-5,-4.30598228824295E-8,99.9905777,99.9905777,-18463.408203125,-18428.400390625,57.6286890943715,20.6097402939935,20.251448,0,0,0,40,4449,99.86215,-18445.904296875,,,,,,,,,,,,,0,,,,0.00245,,,,,,99.9905777,,,,
,32552322.745,99.9898224,-13350.9765625,-3.82899355147494E-5,7.62706507383445E-7,1,0.999253354069792,40.0298881530762,1.99725790386147,20.7599997520447,-0.000435859848080298,-7.33405299340394E-5,0.25,2.77624435055787E-7,-3.85067329247708E-5,1.61296912901112E-7,99.9898224,99.9898224,-13361.0673828125,-13340.8857421875,57.6286890943715,20.6112760646421,20.251448,0,0,0,40,4449,99.8704,-13350.9765625,,,,,,,,,,,,,0,,,,-0.00245,,,,,,99.9898224,,,,
,32552425.355,99.9907074,-8220.1923828125,-5.01952877383187E-5,5.44604544010773E-7,1,0.999253354069792,40.0298881530762,1.99729630521425,20.7599997520447,-0.000570157991242543,-0.00010313548587643,0.25,-2.50117958929163E-7,-5.04772247215105E-5,-4.06892924369602E-7,99.9907074,99.9907074,-8227.791015625,-8212.59375,57.9608812150446,20.6109896260219,20.631098,0,0,0,40,4449,99.88145,-8220.1923828125,,,,,,,,,,,,,0,,,,0,,,,,,99.9907074,,,,
,32552527.195,99.990387,-3129.77917480469,-6.09941657342028E-5,3.62817232587232E-7,1,0.999253354069792,40.0298881530762,1.99742231726687,20.7599997520447,-0.000692699792575222,-0.000126226709532542,0.25,-3.81868905327928E-7,-6.13361023920001E-5,-5.7369941109227E-7,99.990387,99.990387,-3144.73779296875,-3114.82055664063,57.7131049744484,20.6112266935048,19.871798,0,0,0,40,4449,99.88495,-3129.77917480469,,,,,,,,,,,,,0,,,,0,,,,,,99.990387,,,,
,32552629.845,99.9951172,1997.37158203125,-6.35179557176445E-5,3.3225335714994E-7,1,0.999253354069792,40.0298881530762,1.99754964774532,20.7599997520447,-0.000720479655676278,-0.000136722437082759,0.25,-8.60574163540105E-7,-6.38725235721396E-5,-1.06309597634316E-6,99.9951172,99.9951172,1985.06982421875,2009.67333984375,57.6005504676792,20.6069306622666,20.631098,0,0,0,40,4449,99.89335,1997.37158203125,,,,,,,,,,,,,0,,,,0.00245,,,,,,99.9951172,,,,
,32552734.725,99.9994583,7240.09033203125,-5.54377711567933E-5,5.07069675405453E-7,1,0.999253354069792,40.0298881530762,1.99727108250806,20.7599997520447,-0.000628290089141619,-0.000121915725021039,0.25,-9.80686520849543E-7,-5.57468983729848E-5,-1.15793877065411E-6,99.9994583,99.9994583,7227.60986328125,7252.57080078125,57.5700669554292,20.6083078250131,19.871798,0,0,0,40,4449,99.8918,7240.09033203125,,,,,,,,,,,,,0,,,,-0.0049,,,,,,99.9994583,,,,
,32552836,100.0049973,12300.71484375,-3.08629755319599E-5,4.78994838056712E-7,1,0.999253354069792,40.0298881530762,1.99723471574887,20.7599997520447,-0.000349582975517025,-6.89602664123635E-5,0.25,-6.42225080920772E-7,-3.10350053995516E-5,-7.40955984735812E-7,100.0049973,100.0049973,12285.546875,12315.8828125,57.5880444113715,20.6117125892273,20.631098,0,0,0,40,4449,99.88605,12300.71484375,,,,,,,,,,,,,0,,,,0.00245,,,,,,100.0049973,,,,
,32552938.92,100.0064621,17445.775390625,-4.66961522145225E-6,5.78015228638599E-7,1,0.999253354069792,40.0298881530762,1.99743437671667,20.7599997520447,-5.02001578017751E-5,-2.57878106790634E-5,0.25,-1.44758682952064E-6,-4.69154437228731E-6,-1.47006844739641E-6,100.0064621,100.0064621,17433.24609375,17458.3046875,57.7428068581792,20.6096791091504,19.871798,0,0,0,40,4449,99.8789,17445.775390625,,,,,,,,,,,,,0,,,,0,,,,,,100.0064621,,,,
,32553044.63,100.0092354,22730.8623046875,1.56267210368068E-6,7.38893691550658E-7,1,0.999253354069792,40.0298881530762,1.99719042694487,20.7599997520447,2.17715807197002E-5,-1.96810685531773E-5,0.25,-2.00574590937899E-6,1.57761642160933E-6,-2.01232831554441E-6,100.0092163,100.0092545,22720.7421875,22740.982421875,57.6052402387946,20.6128225690148,20.251448,0,0,0,40,4449,99.8687,22730.8623046875,,,,,,,,,,,,,0,,,,0,,,,,,100.0092354,,,,
,32553147.445,100.01017,27868.12109375,-7.81277453562894E-6,1.19491411676068E-6,1,0.999253354069792,40.0298881530762,1.99728549606032,20.7599997520447,-8.35550512664884E-5,-4.56011095130652E-5,0.25,-2.63841426974057E-6,-7.849031222361E-6,-2.67700155212421E-6,100.01017,100.01017,27863.1796875,27873.0625,57.4098331089868,20.6106897358686,20.251448,0,0,0,40,4449,99.85565,27868.12109375,,,,,,,,,,,,,0,,,,0.00245,,,,,,100.01017,,,,
,32553250.54,100.0091553,33020.708984375,-2.0711579058421E-5,1.20675644746698E-6,1,0.999253354069792,40.0298881530762,1.99728186611061,20.7599997520447,-0.000230582176513111,-6.9222805370973E-5,0.25,-2.45043485636925E-6,-2.08216771082832E-5,-2.52661253793411E-6,100.0091553,100.0091553,33015.80078125,33025.6171875,57.6052402387946,20.6093441922181,20.251448,0,0,0,40,4449,99.84865,33020.708984375,,,,,,,,,,,,,0,,,,0.00245,,,,,,100.0091553,,,,
,32553354.525,100.0103836,38217.90234375,-3.42488530481515E-5,1.58416748926986E-6,1,0.999253354069792,40.0298881530762,1.99724186887893,20.7599997520447,-0.000382530779680402,-0.000107400290126285,0.25,-3.4312303798085E-6,-3.44331495244424E-5,-3.55302064096648E-6,100.0103836,100.0103836,38212.66015625,38223.14453125,57.2957153451791,20.6113741712033,20.251448,0,0,0,40,4449,99.839,38217.90234375,,,,,,,,,,,,,0,,,,0.00245,,,,,,100.0103836,,,,
,32553458.93,100.0094528,43437.572265625,-5.16871238767631E-5,1.57503648991617E-6,1,0.999253354069792,40.0298881530762,1.99733808346742,20.7599997520447,-0.000581053753939173,-0.000140914766412494,0.25,-3.31661680250238E-6,-5.19713490691167E-5,-3.48881532618562E-6,100.0094528,100.0094528,43425.00390625,43450.140625,57.4231207938138,20.6105041869898,20.251448,0,0,0,40,4449,99.8295,43437.572265625,,,,,,,,,,,,,0,,,,-0.0049,,,,,,100.0094528,,,,
,32553562.535,100.009697,48615.34375,-6.92096612802972E-5,1.61736701289183E-6,1,0.999253354069792,40.0298881530762,1.99737624767704,20.7599997520447,-0.000782018878044038,-0.000166145200732664,0.25,-2.45945466024988E-6,-6.95967872808021E-5,-2.67735544901204E-6,100.009697,100.009697,48607.90234375,48622.78515625,57.5208243587176,20.6106368238618,20.631098,0,0,0,40,4449,99.82075,48615.34375,,,,,,,,,,,,,0,,,,0.0049,,,,,,100.009697,,,,
,32553665.09,100.0092163,53740.69140625,-8.47465937221403E-5,1.56166350824976E-6,1,0.999253354069792,40.0298881530762,1.99732917663385,20.7599997520447,-0.000954262432043227,-0.000222235935946434,0.25,-4.66635446788885E-6,-8.52165920164913E-5,-4.94090942217846E-6,100.0092163,100.0092163,53725.8203125,53755.5625,57.1573670972753,20.6081926363951,20.631098,0,0,0,40,4449,99.81035,53740.69140625,,,,,,,,,,,,,0,,,,0.00245,,,,,,100.0092163,,,,
,32553768.2,100.0102768,58893.2890625,-0.000103138334187973,1.7613632309327E-6,1,0.999253354069792,40.0298881530762,1.99734730594189,20.7599997520447,-0.00116320434189416,-0.000260069305526665,0.25,-4.76640542575081E-6,-0.000103714010414793,-5.09323754982618E-6,100.0102768,100.0102768,58883.45703125,58903.12109375,57.5309855294676,20.6067969347844,19.871798,0,0,0,40,4449,99.8013,58893.2890625,,,,,,,,,,,,,0,,,,0,,,,,,100.0102768,,,,
,32553870.605,100.0087891,64013.55859375,-0.000119249867706383,2.39093445351209E-6,1,0.999253354069792,40.0298881530762,1.99764572300235,20.7599997520447,-0.00134722231322919,-0.000288744698967213,0.25,-4.45853573255137E-6,-0.000119919669881848,-4.82797453297768E-6,100.0084763,100.0091019,64006.18359375,64020.93359375,57.2589788047753,20.6033978464207,20.631098,0,0,0,40,4449,99.79275,64013.55859375,,,,,,,,,,,,,0,,,,0,,,,,,100.0087891,,,,
,32553976.37,100.0072556,69301.31640625,-0.000136699174284362,2.23016864466635E-6,1,0.999253354069792,40.0298881530762,1.99746798098594,20.7599997520447,-0.00154730518085725,-0.000313502230567768,0.25,-3.57769369813416E-6,-0.00013747272407387,-3.98949804828982E-6,100.0072556,100.0072556,69288.625,69314.0078125,57.4739266475638,20.6068214833951,20.251448,0,0,0,40,4449,99.78605,69301.31640625,,,,,,,,,,,,,0,,,,0.00245,,,,,,100.0072556,,,,
,32554079.935,100.0069733,74476.3203125,-0.000154369486545365,2.76020721258701E-6,1,0.999253354069792,40.0298881530762,1.997378096696,20.7599997520447,-0.0017442809788039,-0.00037097577340908,0.25,-5.53499831911687E-6,-0.000155240217432965,-6.00540252855005E-6,100.006691,100.0072556,74466.1796875,74486.4609375,57.5208243587176,20.6046473099104,20.251448,0,0,0,40,4449,99.77795,74476.3203125,,,,,,,,,,,,,0,,,,0.00245,,,,,,100.0069733,,,,
,32554185.22,100.007782,79739.203125,-0.000171091897408334,2.984823401511E-6,1,0.999253354069792,40.0298881530762,1.9975421375158,20.7599997520447,-0.0019371101468848,-0.000390076469059355,0.25,-4.28087176925401E-6,-0.000172063826043417,-4.78794036715423E-6,100.007782,100.007782,79724.4609375,79753.9453125,57.2027015513907,20.5981661054337,19.871798,0,0,0,40,4449,99.77255,79739.203125,,,,,,,,,,,,,0,,,,-0.00245,,,,,,100.007782,,,,
,32554289.93,100.0066757,84975.3203125,-0.000187629050941737,3.03223055341951E-6,1,0.999253354069792,40.0298881530762,1.99739132676924,20.7599997520447,-0.00212338656070525,-0.000432451254360537,0.25,-5.11178700998295E-6,-0.000188695486862523,-5.66632252457748E-6,100.0066757,100.0066757,84962.90625,84987.734375,57.0182372208522,20.6072792926244,19.871798,0,0,0,40,4449,99.76365,84975.3203125,,,,,,,,,,,,,0,,,,-0.00245,,,,,,100.0066757,,,,
,32554390.77,100.00813295,89999.65625,-0.000205912402923114,2.29006794605526E-6,1,0.999253354069792,40.0298881530762,1.99722040719834,20.7599997520447,-0.0023271835144139,-0.000491341409147627,0.25,-7.090259055857E-6,-0.000207080446147874,-7.70322740460754E-6,100.0079727,100.0082932,89999.65625,89999.65625,57.0424677049483,20.6062878227563,20.631098,0,0,0,40,4417,99.7547,89999.65625,,,,,,,,,,,,,0,,,,-0.00245,,,,,,100.00813295,,,,
,32554512.58,100.001152,85134.21875,-0.000190452682016293,2.22078458511465E-6,1,0.999253354069792,40.0298881530762,1.99723037823359,20.7599997520447,-0.00214541616185011,-0.000494557090558711,0.25,-1.00814491086497E-5,-0.000191521534828788,-1.06724303664303E-5,100.001152,100.001152,85129.1796875,85139.2578125,57.5341120435445,20.6065821640404,20.251448,0,0,0,40,4449,99.7588,85134.21875,,,,,,,,,,,,,0,,,,0.00245,,,,,,100.001152,,,,
,32554615.635,99.9978027,79980.28125,-0.000177060291928111,2.18069127840402E-6,1,0.999253354069792,40.0298881530762,1.99744064532971,20.7599997520447,-0.00199302544128761,-0.000469562227335371,0.25,-1.02253103629287E-5,-0.000178049858374016,-1.07833212484531E-5,99.9978027,99.9978027,79970.390625,79990.171875,57.5520894994869,20.6046485894974,20.251448,0,0,0,40,4449,99.76025,79980.28125,,,,,,,,,,,,,0,,,,0.0049,,,,,,99.9978027,,,,
,32554718.405,99.9967651,74844.3203125,-0.000152859994752702,1.84116354372704E-6,1,0.999253354069792,40.0298881530762,1.99739129656026,20.7599997520447,-0.00173146911063287,-0.000343231945054357,0.25,-3.3599334068185E-6,-0.000153728329407109,-3.81342415199324E-6,99.9967651,99.9967651,74826.796875,74861.84375,57.2628869473714,20.6060722033892,20.251448,0,0,0,40,4449,99.76395,74844.3203125,,,,,,,,,,,,,0,,,,0.00245,,,,,,99.9967651,,,,
,32554823.785,99.9975052,69576.390625,-0.000139669394776361,2.423328644562E-6,1,0.999253354069792,40.0298881530762,1.99738529053274,20.7599997520447,-0.00157668918308614,-0.000344085028455916,0.25,-5.7471079153862E-6,-0.000140453818704433,-6.17980003986517E-6,99.9975052,99.9975052,69569.03125,69583.75,57.6341604940061,20.6039815524196,21.01075,0,0,0,40,4449,99.76985,69576.390625,,,,,,,,,,,,,0,,,,-0.00245,,,,,,99.9975052,,,,
,32554927.775,99.9955978,64378.640625,-0.000119382264311358,1.90380140331255E-6,1,0.999253354069792,40.0298881530762,1.99735801748384,20.7599997520447,-0.0013444922297152,-0.000312047940631492,0.25,-6.48827031109363E-6,-0.000120047031066114,-6.86965539292149E-6,99.9955978,99.9955978,64365.89453125,64391.38671875,57.2112994651022,20.6055251145905,20.251448,0,0,0,40,4449,99.77085,64378.640625,,,,,,,,,,,,,0,,,,0,,,,,,99.9955978,,,,
,32555031.95,99.9955063,59170.658203125,-0.000101525986115846,2.63343694749559E-6,1,0.999253354069792,40.0298881530762,1.99731174032558,20.7599997520447,-0.00114289301035764,-0.000268007297006218,0.25,-5.74798377453198E-6,-0.000102089627603798,-6.07574240361878E-6,99.9955063,99.9955063,59158.109375,59183.20703125,57.8272227382561,20.6039765134963,20.251448,0,0,0,40,4449,99.7777,59170.658203125,,,,,,,,,,,,,0,,,,-0.00245,,,,,,99.9955063,,,,
,32555134.265,99.9927521,54057.82421875,-8.5893722838308E-5,1.62373072839528E-6,1,0.999253354069792,40.0298881530762,1.99736294256226,20.7599997520447,-0.000968719362529838,-0.000216566856652468,0.25,-3.96603295323836E-6,-8.63723423245873E-5,-4.23995605388313E-6,99.9927521,99.9927521,54045.5859375,54070.0625,57.4864327038715,20.6050555175662,20.631098,0,0,0,40,4449,99.78145,54057.82421875,,,,,,,,,,,,,0,,,,-0.00245,,,,,,99.9927521,,,,
,32555237.98,99.9932632,48872.8828125,-7.14717603220361E-5,1.57033998962235E-6,1,0.999253354069792,40.0298881530762,1.99720941391999,20.7599997520447,-0.00080387084805464,-0.00019231318335081,0.25,-4.36500181354012E-6,-7.18661696523368E-5,-4.60046075482487E-6,99.9932632,99.9932632,48862.70703125,48883.05859375,57.4496961634676,20.6085584037265,20.251448,0,0,0,40,4449,99.78915,48872.8828125,,,,,,,,,,,,,0,,,,-0.00245,,,,,,99.9932632,,,,
,32555340.96,99.9932175,43727.38671875,-5.21110253707245E-5,1.32614073754026E-6,1,0.999253354069792,40.0298881530762,1.99699954628653,20.7599997520447,-0.000586333799763704,-0.000138577769434618,0.25,-3.03857895462371E-6,-5.23984940603112E-5,-3.21047512663884E-6,99.9932175,99.9932175,43719.79296875,43734.98046875,57.8342573949292,20.6128836387269,20.631098,0,0,0,40,4449,99.7976,43727.38671875,,,,,,,,,,,,,0,,,,0,,,,,,99.9932175,,,,
,32555444.23,99.9937439,38565.23828125,-3.74568676761188E-5,1.13853226250917E-6,1,0.999253354069792,40.0298881530762,1.99710766732958,20.7599997520447,-0.000419252553299718,-0.000112227662251696,0.25,-3.29300441509122E-6,-3.76598062408981E-5,-3.42360451119493E-6,99.9937439,99.9937439,38552.84375,38577.6328125,57.6177462951023,20.6133977306419,20.251448,0,0,0,40,4449,99.80505,38565.23828125,,,,,,,,,,,,,0,,,,0.00245,,,,,,99.9937439,,,,
,32555547.875,99.9925385,33386.03125,-2.00577085448475E-5,1.22304301477835E-6,1,0.999253354069792,40.0298881530762,1.99721185593294,20.7599997520447,-0.000222232488925719,-7.30849751239014E-5,0.25,-2.90519949630261E-6,-2.0162732370764E-5,-2.9819995354906E-6,99.9925385,99.9925385,33371.47265625,33400.58984375,57.6662072632946,20.6100757432182,20.251448,0,0,0,40,4449,99.8119,33386.03125,,,,,,,,,,,,,0,,,,-0.00245,,,,,,99.9925385,,,,
,32555649.05,99.9901505,28331.02734375,-5.32609551028131E-6,1.08110955326587E-6,1,0.999253354069792,40.0298881530762,1.9972041016329,20.7599997520447,-5.54582175232072E-5,-3.96266681942015E-5,0.25,-2.54990773576574E-6,-5.34854129725332E-6,-2.5804681079596E-6,99.9901505,99.9901505,28318.720703125,28343.333984375,57.4004535667561,20.6101740182439,20.631098,0,0,0,40,4449,99.8236,28331.02734375,,,,,,,,,,,,,0,,,,0,,,,,,99.9901505,,,,
,32555749.055,99.9909286,23330.453125,1.0414829330049E-5,9.40065710358754E-7,1,0.999253354069792,40.0298881530762,1.99726333226226,20.7599997520447,0.000122511994351244,-2.56964267604718E-6,0.25,-2.05587505697424E-6,1.04799844545023E-5,-2.03578434741121E-6,99.9909286,99.9909286,23315.392578125,23345.513671875,57.2628869473714,20.6121272557619,20.251448,0,0,0,40,4449,99.82765,23330.453125,,,,,,,,,,,,,0,,,,0,,,,,,99.9909286,,,,
,32555852.445,99.9921074,18163.7392578125,2.48589649403053E-5,8.9456893919188E-7,1,0.999253354069792,40.0298881530762,1.99738964773415,20.7599997520447,0.00028495226805405,3.64672555395175E-5,0.25,-1.16064064035115E-6,2.50028878243181E-5,-1.09103327472683E-6,99.9917603,99.9924545,18153.84765625,18173.630859375,57.5020652742561,20.6106000367667,20.631098,0,0,0,40,4449,99.83885,18163.7392578125,,,,,,,,,,,,,0,,,,0,,,,,,99.9921074,,,,
,32555955.4,99.9882431,13016.361328125,3.85490266204133E-5,7.63002934581304E-7,1,0.999253354069792,40.0298881530762,1.9973891152639,20.7599997520447,0.000439225226387945,7.16276270295539E-5,0.25,-4.74300813220861E-7,3.87678528230418E-5,-3.58195693393105E-7,99.9882431,99.9882431,13006.392578125,13026.330078125,57.2527257766214,20.6132015414625,20.631098,0,0,0,40,4449,99.8489,13016.361328125,,,,,,,,,,,,,0,,,,-0.0049,,,,,,99.9882431,,,,
,32556052.485,99.989357,8163.62670898438,5.11790280791464E-5,5.75877317133938E-7,1,0.999253354069792,40.0298881530762,1.99747143252828,20.7599997520447,0.000583508974068117,9.30537183324423E-5,0.25,-8.10329701911394E-7,5.14697533224563E-5,-6.56400148822572E-7,99.989357,99.989357,8158.64501953125,8168.6083984375,57.5247325013138,20.6113105819797,21.01075,0,0,0,40,4449,99.8553,8163.62670898438,,,,,,,,,,,,,0,,,,0,,,,,,99.989357,,,,
,32556152.32,99.9924393,3175.88024902344,6.12404052236351E-5,3.06841959789421E-7,1,0.999253354069792,40.0298881530762,1.99737527729631,20.7599997520447,0.000695866766544468,0.000124534767155316,0.25,1.89966906865829E-7,6.15842946364307E-5,3.81541001820954E-7,99.9924393,99.9924393,3165.91015625,3185.85034179687,57.3129111726022,20.611242801663,21.01075,0,0,0,40,4449,99.86565,3175.88024902344,,,,,,,,,,,,,0,,,,0.0049,,,,,,99.9924393,,,,
,32556216.705,99.9926071,-0.509996384382248,6.50161107502163E-5,2.60778233933511E-7,1,0.999253354069792,40.0298881530762,1.99732314374975,20.7599997520447,0.000739432969485751,0.000128317543722669,0.25,-1.4105854149321E-7,6.53820685279556E-5,6.08343746899793E-8,99.9925995,99.9926147,-0.532832026481628,-0.487160742282867,57.3074397729676,20.6120555339054,20.631098,0,0,0,40,4417,99.87015,-0.509996384382248,,,,,,,,,,,,,0,,,,0.00245,,,,,,99.9926071,,,,