File: data/doubleLayers/dl_5/ppms/data/DD205_6_HYST_100OE_300K.DAT
[Header]
; VSM Data File (default extension .dat)
; Copyright (c) 2003-2013, Quantum Design, Inc. All rights reserved.
TITLE,
FILEOPENTIME,31023035.73,12/26/2018,9:32 am
BYAPP,VSM,2.0,2.0
INFO,PPMS VSM Option Release 1.4.10 Build 1,APPNAME
INFO,Quantum Design Linear Motor Servo Controller,MOTOR_MODULE_NAME
INFO,3101-100 M1,MOTOR_HW_VERSION
INFO,MMC1014,MOTOR_SERIAL_NUMBER
INFO,SRV No X-over 01.03.11,MOTOR_SOFTWARE_VERSION
INFO,Quantum Design VSM Detection Module,VSM_MODULE_NAME
INFO,3101-150 F0,VSM_HW_VERSION
INFO,VSM707,VSM_SERIAL_NUMBER
INFO,VSM No X-over 01.02.05 May 20 2008 13:51:47,VSM_SOFTWARE_VERSION
INFO,704,PREAMP_SERIAL_NUMBER
INFO,822,COIL_SERIAL_NUMBER
INFO,0,MOMENT_UNITS
INFO,CoFe2O4,SAMPLE_MATERIAL
INFO,AH11 DL,SAMPLE_COMMENT
INFO,30.27,SAMPLE_MASS
INFO,,SAMPLE_VOLUME
INFO,,SAMPLE_MOLECULAR_WEIGHT
INFO,,SAMPLE_SIZE
INFO,,SAMPLE_SHAPE
DATATYPE,COMMENT,1
DATATYPE,TIME,2
STARTUPAXIS,X,2
STARTUPAXIS,Y1,5
[Data]
Comment,Time Stamp (sec),Temperature (K),Magnetic Field (Oe),Moment (emu),M. Std. Err. (emu),Transport Action,Averaging Time (sec),Frequency (Hz),Peak Amplitude (mm),Center Position (mm),Coil Signal' (mV),Coil Signal" (mV),Range (mV),M. Quad. Signal (emu),M. Raw' (emu),M. Raw" (emu),Min. Temperature (K),Max. Temperature (K),Min. Field (Oe),Max. Field (Oe),Mass (grams),Motor Lag (deg),Pressure (Torr),VSM Status (code),Motor Status (code),Measure Status (code),Measure Count,PPMS Status (code),System Temp. (K),System Field (Oe),Sample Position (deg),Bridge 1 Resistance (ohms),Bridge 1 Excitation (에),Bridge 2 Resistance (ohms),Bridge 2 Excitation (에),Bridge 3 Resistance (ohms),Bridge 3 Excitation (에),Bridge 4 Resistance (ohms),Bridge 4 Excitation (에),Signal 1 Vin (V),Signal 2 Vin (V),Digital Inputs (code),Drive 1 Iout (mA),Drive 1 Ipower (W),Drive 2 Iout (mA),Drive 2 Ipower (W),Pressure (),Map 20 (),Map 21 (),Map 22 (),Map 23 (),Map 24 (),Map 25 (),Map 26 (),Map 27 (),Map 28 (),Map 29 ()
,31023051.73,300.0021973,-0.19790905714035,,,2,,,,14.8800001162291,,,,,,,300.0021973,300.0021973,-0.19790905714035,-0.19790905714035,,,25.566563,,,,-99999999,4369,300.1976,-0.19790905714035,,,,,,,,,,,,,,,,,,,,,,,300.0021973,,,,
,31023195.41,299.9900818,4376.19702148438,4.89205894689508E-5,3.78598847650818E-7,1,0.999253354069792,40.0298881530762,1.99701754364465,14.8700000718236,0.000553185706307426,9.58804247929424E-5,0.25,3.05821624440895E-9,4.89191462569961E-5,3.5498823832455E-8,299.9900818,299.9900818,4366.24951171875,4386.14453125,56.0826278833329,20.6026445588715,25.186911,0,0,0,40,4449,300.2115,4376.19702148438,,,,,,,,,,,,,0,,,,0,,,,,,299.9900818,,,,
,31023287.08,299.987915,8954.95849609375,4.00695515864144E-5,4.49888819332819E-7,1,0.999253354069792,40.0298881530762,1.99665572095507,14.8700000718236,0.000452414246331004,8.20237234607087E-5,0.25,3.12466881290754E-7,4.0068169121334E-5,3.39008005317135E-7,299.987915,299.987915,8952.50390625,8957.4130859375,56.4054404617752,20.6077081534969,25.566563,0,0,0,40,4449,300.2274,8954.95849609375,,,,,,,,,,,,,0,,,,0,,,,,,299.987915,,,,
,31023383.02,299.98168945,13750.1899414062,2.64588674000113E-5,8.23318059209835E-7,1,0.999253354069792,40.0298881530762,1.9966816841246,14.8700000718236,0.000299295122965703,5.09794210774337E-5,0.25,-7.52228124943162E-8,2.64581484845139E-5,-5.77058669740089E-8,299.9812012,299.9821777,13745.091796875,13755.2880859375,56.6344576179098,20.6110790062442,25.566563,0,0,0,40,4449,300.25825,13750.1899414062,,,,,,,,,,,,,0,,,,0.00245,,,,,,299.98168945,,,,
,31023477.245,299.9837036,18460.10546875,1.0083522599362E-5,1.24504535988772E-6,1,0.999253354069792,40.0298881530762,1.99631332552698,14.8700000718236,0.000113262878217726,2.39208383504999E-5,0.25,3.69060123842361E-7,1.00829853426763E-5,3.7571850302633E-7,299.9837036,299.9837036,18452.658203125,18467.552734375,56.9166255133522,20.6175391278601,25.566563,0,0,0,40,4449,300.2516,18460.10546875,,,,,,,,,,,,,0,,,,0.0049,,,,,,299.9837036,,,,
,31023573.525,299.9914856,23273.03125,-8.35023323897146E-6,1.21629605675732E-6,1,0.999253354069792,40.0298881530762,1.99624694238539,14.8700000718236,-9.41267321677662E-5,-1.7869222586655E-5,0.25,-1.34077840121988E-7,-8.34990003619152E-6,-1.39591159088093E-7,299.9914856,299.9914856,23265.517578125,23280.544921875,56.4343607169867,20.6183436911964,25.566563,0,0,0,40,4449,300.25955,23273.03125,,,,,,,,,,,,,0,,,,0.00245,,,,,,299.9914856,,,,
,31023669.08,299.9899597,28048.0185546875,-2.57903532357952E-5,1.31997692991964E-6,1,0.999253354069792,40.0298881530762,1.99628344102281,14.8700000718236,-0.000287160065494462,-7.5755606154788E-5,0.25,-2.23331862665847E-6,-2.5788126475528E-5,-2.25027715356238E-6,299.9899597,299.9899597,28038.072265625,28057.96484375,56.401532319179,20.6156867613803,25.186911,0,0,0,40,4449,300.2568,28048.0185546875,,,,,,,,,,,,,0,,,,0,,,,,,299.9899597,,,,
,31023764.53,299.9967957,32820.583984375,-4.3029357260919E-5,1.521260776712E-6,1,0.999253354069792,40.0298881530762,1.99616175212107,14.8700000718236,-0.000483637606665332,-0.000100068639898127,0.25,-1.39792928806774E-6,-4.30271718966235E-5,-1.42626164161626E-6,299.9967957,299.9967957,32810.78125,32830.38671875,56.3382204091213,20.6209490395116,25.946213,0,0,0,40,4449,300.25895,32820.583984375,,,,,,,,,,,,,0,,,,-0.00245,,,,,,299.9967957,,,,
,31023863.945,299.9947205,37787.935546875,-6.53553462479515E-5,2.02519999687494E-6,1,0.999253354069792,40.0298881530762,1.99597488979165,14.8700000718236,-0.00073613118934303,-0.000142617748437339,0.25,-1.29529151688795E-6,-6.53525831800495E-5,-1.33829976208871E-6,299.9947205,299.9947205,37783.01171875,37792.859375,56.5688008222944,20.6204720972289,25.566563,0,0,0,40,4449,300.26835,37787.935546875,,,,,,,,,,,,,0,,,,0,,,,,,299.9947205,,,,
,31023960.565,300.0011292,42618.076171875,-7.99325752147721E-5,2.2438729262726E-6,1,0.999253354069792,40.0298881530762,1.99602234768964,14.8700000718236,-0.000899519421027823,-0.000179181954038721,0.25,-2.00451424785712E-6,-7.99289070056091E-5,-2.05704688002462E-6,300.0011292,300.0011292,42605.453125,42630.69921875,56.4460851447752,20.6223725559504,25.186911,0,0,0,40,4449,300.2589,42618.076171875,,,,,,,,,,,,,0,,,,0,,,,,,300.0011292,,,,
,31024056.15,300.0019531,47396.017578125,-0.000101011057616528,1.77819151103512E-6,1,0.999253354069792,40.0298881530762,1.99604313748122,14.8700000718236,-0.00113401052975963,-0.000242171977890742,0.25,-3.92549621307602E-6,-0.000101005512235056,-3.99176890208775E-6,300.0019531,300.0019531,47393.12109375,47398.9140625,56.5281561392944,20.6193821385591,25.186911,0,0,0,40,4449,300.2532,47396.017578125,,,,,,,,,,,,,0,,,,0.00245,,,,,,300.0019531,,,,
,31024153.815,299.9999695,52276.29296875,-0.000118756703637168,2.09797901503571E-6,1,0.999253354069792,40.0298881530762,1.99614665211592,14.8700000718236,-0.00133828584416025,-0.000255952994483404,0.25,-2.06923287693186E-6,-0.000118751875480185,-2.14713221896735E-6,299.9999695,299.9999695,52266.359375,52286.2265625,56.750138638756,20.6175915189068,25.566563,0,0,0,40,4449,300.25685,52276.29296875,,,,,,,,,,,,,0,,,,-0.00245,,,,,,299.9999695,,,,
,31024249.025,300.0039063,57035.734375,-0.000135727036184383,2.70885010374223E-6,1,0.999253354069792,40.0298881530762,1.99608482220705,14.8700000718236,-0.00153317902145547,-0.000271178555221726,0.25,-4.76890446701391E-7,-0.000135722747514161,-5.65877512092614E-7,300.0039063,300.0039063,57028.25390625,57043.21484375,56.658688102006,20.6206868164869,25.946213,0,0,0,40,4449,300.2487,57035.734375,,,,,,,,,,,,,0,,,,-0.00245,,,,,,300.0039063,,,,
,31024343.975,300.013855,61781.611328125,-0.000155248518851122,2.52386427134921E-6,1,0.999253354069792,40.0298881530762,1.9965846268037,14.8700000718236,-0.00174187557806245,-0.000380891070804713,0.25,-6.79337942565985E-6,-0.000155239475817337,-6.89486800580304E-6,300.0138245,300.0138855,61776.24609375,61786.9765625,56.922878541506,20.6145862998031,25.566563,0,0,0,40,4449,300.23425,61781.611328125,,,,,,,,,,,,,0,,,,0,,,,,,300.013855,,,,
,31024437.5,300.0055237,66457.140625,-0.00017501417303395,2.90617925111035E-6,1,0.999253354069792,40.0298881530762,1.99645271457714,14.8700000718236,-0.00196381769847005,-0.000427648403815074,0.25,-7.50721500791901E-6,-0.000175004147675718,-7.62149796099843E-6,300.0055237,300.0055237,66449.6328125,66464.6484375,56.5680191937752,20.6151915941343,25.946213,0,0,0,40,4449,300.2369,66457.140625,,,,,,,,,,,,,0,,,,-0.0049,,,,,,300.0055237,,,,
,31024529.61,300.0134583,71060.19921875,-0.000196228589028167,3.39721536785845E-6,1,0.999253354069792,40.0298881530762,1.99633283134599,14.8700000718236,-0.00221061524210783,-0.000428207710290618,0.25,-3.88360133542707E-6,-0.000196220274094652,-4.01172612358758E-6,300.0134583,300.0134583,71052.6875,71067.7109375,56.5953761919483,20.6169867192349,25.566563,0,0,0,40,4449,300.2253,71060.19921875,,,,,,,,,,,,,0,,,,0,,,,,,300.0134583,,,,
,31024623.945,300.01763915,75775.65625,-0.000214001134452852,3.45862040027789E-6,1,0.999253354069792,40.0298881530762,1.996183830863,14.8700000718236,-0.00241073558650445,-0.000466521900710776,0.25,-4.19696819448091E-6,-0.000213992076581417,-4.33653922448212E-6,300.0171509,300.0181274,75770.609375,75780.703125,56.7243448976214,20.6194950124896,25.946213,0,0,0,40,4449,300.2092,75775.65625,,,,,,,,,,,,,0,,,,0,,,,,,300.01763915,,,,
,31024719.96,300.0118408,80574.171875,-0.00023104606229253,2.61869887925333E-6,1,0.999253354069792,40.0298881530762,1.99623993759492,14.8700000718236,-0.00259763353440488,-0.000533620300591656,0.25,-7.17894417189533E-6,-0.000231034624723125,-7.329372115935E-6,300.0118408,300.0118408,80569.421875,80578.921875,56.7243448976214,20.6201411729705,25.566563,0,0,0,40,4449,300.2051,80574.171875,,,,,,,,,,,,,0,,,,-0.0049,,,,,,300.0118408,,,,
,31024814.39,300.0137634,85294.75,-0.000250603980469445,3.22720461179278E-6,1,0.999253354069792,40.0298881530762,1.9961681520796,14.8700000718236,-0.00281922446489708,-0.000568384971487373,0.25,-6.86797627356379E-6,-0.000250592178336779,-7.03097513463001E-6,300.0137634,300.0137634,85287.21875,85302.28125,56.6000659630637,20.619591224165,25.186911,0,0,0,40,4449,300.188,85294.75,,,,,,,,,,,,,0,,,,-0.0049,,,,,,300.0137634,,,,
,31024904.95,300.0151062,89822.92578125,-0.000267567284027077,2.95074398569941E-6,1,0.999253354069792,40.0298881530762,1.996078763271,14.8700000718236,-0.00300999019080123,-0.000606475813715394,0.25,-7.30148218754771E-6,-0.000267554714041319,-7.47531237646916E-6,300.0151062,300.0151062,89815.546875,89830.3046875,56.7118388413137,20.6214779845151,25.566563,0,0,0,40,4449,300.1822,89822.92578125,,,,,,,,,,,,,0,,,,0,,,,,,300.0151062,,,,
,31025016.215,300.0095825,85701.5234375,-0.000256796852400808,3.32977074248263E-6,1,0.999253354069792,40.0298881530762,1.9960528270075,14.8700000718236,-0.00288023026399253,-0.00063148124149281,0.25,-1.13802244449744E-5,-0.00025678197028297,-1.15471180292696E-5,300.0095825,300.0095825,85699.1484375,85703.8984375,56.6743206723906,20.6197326666904,25.946213,0,0,0,40,4449,300.1729,85701.5234375,,,,,,,,,,,,,0,,,,-0.0049,,,,,,300.0095825,,,,
,31025111.055,299.9970703,80957.75,-0.000236898939625517,3.12820083399327E-6,1,0.999253354069792,40.0298881530762,1.99588761591259,14.8700000718236,-0.00266025904917854,-0.000562807721945982,0.25,-8.75539131932993E-6,-0.000236886427504924,-8.90960385386684E-6,299.9970703,299.9970703,80950.4921875,80965.0078125,56.8869236296214,20.6193526282231,25.186911,0,0,0,40,4449,300.16265,80957.75,,,,,,,,,,,,,0,,,,0.00245,,,,,,299.9970703,,,,
,31025205.22,299.9966125,76249.01953125,-0.000217331355684766,3.29183386675764E-6,1,0.999253354069792,40.0298881530762,1.99580815126595,14.8700000718236,-0.00244063543363211,-0.00051512499120929,0.25,-7.92800125741374E-6,-0.000217319927848454,-8.06964421138519E-6,299.9966125,299.9966125,76241.8046875,76256.234375,56.7227816405829,20.6222202569571,25.186911,0,0,0,40,4449,300.1741,76249.01953125,,,,,,,,,,,,,0,,,,-0.00245,,,,,,299.9966125,,,,
,31025301.395,299.9923401,71440.69140625,-0.000196314367983929,3.12376913451386E-6,1,0.999253354069792,40.0298881530762,1.99606246962267,14.8700000718236,-0.0022079227126304,-0.0004478184839251,0.25,-5.60863838461409E-6,-0.000196305071611261,-5.73677698627381E-6,299.9923401,299.9923401,71433.0703125,71448.3125,56.8611298884868,20.6204876931996,25.566563,0,0,0,40,4449,300.19205,71440.69140625,,,,,,,,,,,,,0,,,,0.00245,,,,,,299.9923401,,,,
,31025398.415,299.9810791,66592.74609375,-0.000176547748233203,3.20579124133117E-6,1,0.999253354069792,40.0298881530762,1.99600435536844,14.8700000718236,-0.00197819300737209,-0.000445213397214583,0.25,-8.80366656623817E-6,-0.000176536983141712,-8.91893534569908E-6,299.9810791,299.9810791,66585.265625,66600.2265625,56.8595666314483,20.6206017114173,25.566563,0,0,0,40,4449,300.2001,66592.74609375,,,,,,,,,,,,,0,,,,-0.00245,,,,,,299.9810791,,,,
,31025495.18,299.9875183,61756.541015625,-0.000159097307792509,2.59337424597266E-6,1,0.999253354069792,40.0298881530762,1.99604814387917,14.8700000718236,-0.00179128611842126,-0.000351656732321157,0.25,-3.54868837774343E-6,-0.000159090425459885,-3.65280863433458E-6,299.9875183,299.9875183,61751.6015625,61761.48046875,56.5516049948714,20.6211049229332,25.946213,0,0,0,40,4449,300.2081,61756.541015625,,,,,,,,,,,,,0,,,,0,,,,,,299.9875183,,,,
,31025592.315,299.9941406,56900.642578125,-0.000137775887485624,2.55798920445781E-6,1,0.999253354069792,40.0298881530762,1.99604439526608,14.8700000718236,-0.00154473910032309,-0.000341957439117698,0.25,-6.38447887116951E-6,-0.000137767711424529,-6.47465253877834E-6,299.9941406,299.9941406,56893.06640625,56908.21875,56.7446672391214,20.6224415101423,25.186911,0,0,0,40,4449,300.2175,56900.642578125,,,,,,,,,,,,,0,,,,0.00245,,,,,,299.9941406,,,,
,31025688.04,299.9951477,52116.140625,-0.000121580935747781,2.28318626440581E-6,1,0.999253354069792,40.0298881530762,1.99591742818292,14.8700000718236,-0.00135919390053046,-0.000324166993080548,0.25,-7.61794747114751E-6,-0.000121572401532626,-7.69755349043308E-6,299.9951477,299.9951477,52111.15234375,52121.12890625,56.946327397083,20.6261349646069,25.566563,0,0,0,40,4449,300.2232,52116.140625,,,,,,,,,,,,,0,,,,-0.00245,,,,,,299.9951477,,,,
,31025783.17,299.9956665,47360.615234375,-0.000103121534964867,2.34994749443622E-6,1,0.999253354069792,40.0298881530762,1.99593731461142,14.8700000718236,-0.00115545715539056,-0.000259851246478164,0.25,-5.1251633004041E-6,-0.00010311516149275,-5.19279587847895E-6,299.9956665,299.9956665,47353.1796875,47368.05078125,56.9205336559483,20.6273698719722,25.566563,0,0,0,40,4449,300.2293,47360.615234375,,,,,,,,,,,,,0,,,,0.00245,,,,,,299.9956665,,,,
,31025879.08,299.98602295,42567.6640625,-8.0959348630568E-5,2.0293907321006E-6,1,0.999253354069792,40.0298881530762,1.99584511159571,14.8700000718236,-0.000904194012235772,-0.00022073689509106,0.25,-5.5048476500605E-6,-8.09533901936641E-5,-5.55796191597625E-6,299.9859314,299.9861145,42555.375,42579.953125,57.0088576786214,20.6289933472573,25.946213,0,0,0,40,4449,300.2332,42567.6640625,,,,,,,,,,,,,0,,,,0,,,,,,299.98602295,,,,
,31025976.055,299.9845886,37720.595703125,-6.36394605565537E-5,1.57248298113325E-6,1,0.999253354069792,40.0298881530762,1.99596796462867,14.8700000718236,-0.000710769915424155,-0.000173690077236194,0.25,-4.34181724235445E-6,-6.36347637901735E-5,-4.38361053325629E-6,299.9845886,299.9845886,37718.00390625,37723.1875,56.8361177758714,20.6287261198369,25.566563,0,0,0,40,4449,300.256,37720.595703125,,,,,,,,,,,,,0,,,,0,,,,,,299.9845886,,,,
,31026070.21,299.986908,33015.75,-4.46535538286751E-5,1.61522720151407E-6,1,0.999253354069792,40.0298881530762,1.99584733091989,14.8700000718236,-0.000497209075018342,-0.00013043115462113,0.25,-3.80441467705584E-6,-4.4649749933744E-5,-3.83374796011233E-6,299.986908,299.986908,33005.578125,33025.921875,56.6414922745829,20.6277443869157,25.566563,0,0,0,40,4449,300.25465,33015.75,,,,,,,,,,,,,0,,,,0,,,,,,299.986908,,,,
,31026165.085,299.9916992,28270.6328125,-2.8118348908242E-5,1.66608090536987E-6,1,0.999253354069792,40.0298881530762,1.9959021246809,14.8700000718236,-0.000311158950393573,-9.33422109203954E-5,0.25,-3.38727145421904E-6,-2.8115290833368E-5,-3.40573239561014E-6,299.9916992,299.9916992,28263.388671875,28277.876953125,56.9752476522945,20.6271632557044,25.566563,0,0,0,40,4449,300.2498,28270.6328125,,,,,,,,,,,,,0,,,,0,,,,,,299.9916992,,,,
,31026260.235,299.9883118,23517.783203125,-9.96443823381944E-6,1.5232851891803E-6,1,0.999253354069792,40.0298881530762,1.99601485498728,14.8700000718236,-0.000108088581658592,-4.5687175050679E-5,0.25,-2.31579314852972E-6,-9.96261755268809E-6,-2.32230877611501E-6,299.9883118,299.9883118,23510.30078125,23525.265625,56.5781803645252,20.6273675016846,25.566563,0,0,0,40,4449,300.2704,23517.783203125,,,,,,,,,,,,,0,,,,-0.0049,,,,,,299.9883118,,,,
,31026354.755,299.983429,18795.6005859375,7.52060090198028E-6,1.00006035616245E-6,1,0.999253354069792,40.0298881530762,1.99609660142089,14.8700000718236,8.90150442120954E-5,-8.41582211238688E-6,0.25,-2.04756939599488E-6,7.52173641804164E-6,-2.04253665680458E-6,299.983429,299.983429,18788.1015625,18803.099609375,56.9049010855637,20.6297254607619,25.566563,0,0,0,40,4449,300.2747,18795.6005859375,,,,,,,,,,,,,0,,,,0.0049,,,,,,299.983429,,,,
,31026448.56,299.9904175,14105.9555664062,2.42688552078497E-5,7.97994285378206E-7,1,0.999253354069792,40.0298881530762,1.99604489485449,14.8700000718236,0.000276866279208535,3.27341762884705E-5,0.25,-1.30864535757511E-6,2.4269008884351E-5,-1.29254456171794E-6,299.9904175,299.9904175,14096.2529296875,14115.658203125,56.8157954343714,20.628492631241,25.946213,0,0,0,40,4449,300.2838,14105.9555664062,,,,,,,,,,,,,0,,,,0,,,,,,299.9904175,,,,
,31026543.145,299.9949036,9378.2685546875,3.90075071358109E-5,7.26875985296147E-7,1,0.999253354069792,40.0298881530762,1.99623399453939,14.8700000718236,0.000443329700381846,6.25438796734313E-5,0.25,-1.2253640212973E-6,3.90071655107468E-5,-1.19948981931515E-6,299.9949036,299.9949036,9373.474609375,9383.0625,56.8587850029291,20.6294985342445,25.566563,0,0,0,40,4449,300.2935,9378.2685546875,,,,,,,,,,,,,0,,,,-0.0049,,,,,,299.9949036,,,,
,31026637.065,299.9941101,4685.09692382812,4.87802978979349E-5,5.15100403839053E-7,1,0.999253354069792,40.0298881530762,1.99617184049292,14.8700000718236,0.000553575642443807,8.28728511674434E-5,0.25,-1.11996156175648E-6,4.87795972848529E-5,-1.08759294034304E-6,299.9941101,299.9941101,4680.1328125,4690.06103515625,57.068261446083,20.6315868876081,25.566563,0,0,0,40,4449,300.2953,4685.09692382812,,,,,,,,,,,,,0,,,,0,,,,,,299.9941101,,,,
,31026728.78,299.9955444,98.7673683166504,2.28905398874758E-5,5.18808462917869E-7,1,0.999253354069792,40.0298881530762,1.99614223848709,14.8700000718236,0.000260345840169492,3.55417875681563E-5,0.25,-8.21616782912922E-7,2.28904057167632E-5,-8.06409880779071E-7,299.9955444,299.9955444,96.1666488647461,101.368087768555,57.3660619119099,20.6287570189864,25.946213,0,0,0,40,4449,300.2935,98.7673683166504,,,,,,,,,,,,,0,,,,-0.00245,,,,,,299.9955444,,,,
,31026820.705,300.0007019,-4492.6240234375,-4.82177989141332E-5,5.010548220399E-7,1,0.999253354069792,40.0298881530762,1.99610693196719,14.8700000718236,-0.000545721533370433,-9.03041804584315E-5,0.25,3.64810952048926E-7,-4.82166029011867E-5,3.3283688208657E-7,300.0007019,300.0007019,-4497.72705078125,-4487.52099609375,56.6665043871983,20.6281239345261,25.946213,0,0,0,40,4449,300.29795,-4492.6240234375,,,,,,,,,,,,,0,,,,0,,,,,,300.0007019,,,,
,31026916.08,299.9959717,-9259.2470703125,-3.95862220792786E-5,7.13195266695527E-7,1,0.999253354069792,40.0298881530762,1.99625439176083,14.8700000718236,-0.000447897463889437,-7.5095699746885E-5,0.25,2.1528098169362E-7,-3.95851927568765E-5,1.89053247348959E-7,299.9959717,299.9959717,-9261.88671875,-9256.607421875,56.7993812354675,20.6274118038052,25.186911,0,0,0,40,4449,300.2981,-9259.2470703125,,,,,,,,,,,,,0,,,,0.00245,,,,,,299.9959717,,,,
,31027012.7,300.0010681,-14089.6181640625,-2.38693330322214E-5,8.9803453717217E-7,1,0.999253354069792,40.0298881530762,1.9962789437082,14.8700000718236,-0.000273749830920951,-2.40547085702497E-5,0.25,2.00757328704964E-6,-2.38699518904205E-5,1.99171551821508E-6,300.0010681,300.0010681,-14099.6875,-14079.548828125,57.2363115777176,20.628905012328,25.946213,0,0,0,40,4449,300.2827,-14089.6181640625,,,,,,,,,,,,,0,,,,-0.00245,,,,,,300.0010681,,,,
,31027107.99,300.0070801,-18851.7236328125,-7.76020791008218E-6,9.94025578287646E-7,1,0.999253354069792,40.0298881530762,1.99598635308568,14.8700000718236,-9.08536702000579E-5,2.95513911868598E-6,0.25,1.60597838158946E-6,-7.76103784497414E-6,1.60079874043164E-6,300.0070801,300.0070801,-18856.990234375,-18846.45703125,57.1370447557753,20.6308858048206,25.566563,0,0,0,40,4449,300.2756,-18851.7236328125,,,,,,,,,,,,,0,,,,-0.0049,,,,,,300.0070801,,,,
,31027201.7,300.0090637,-23534.0654296875,8.95783538274653E-6,9.45521003839898E-7,1,0.999253354069792,40.0298881530762,1.99605723957959,14.8700000718236,9.72266184857077E-5,4.0754093194662E-5,0.25,2.05366616940369E-6,8.95621056614814E-6,2.05952289434533E-6,300.0090637,300.0090637,-23538.9609375,-23529.169921875,56.8454973181022,20.6281033011459,25.946213,0,0,0,40,4449,300.26885,-23534.0654296875,,,,,,,,,,,,,0,,,,0,,,,,,300.0090637,,,,
,31027297.325,300.013092,-28313.951171875,2.67938320520941E-5,1.36626617777243E-6,1,0.999253354069792,40.0298881530762,1.99591070739922,14.8700000718236,0.000302583256067871,5.3850386675997E-5,0.25,1.22484730984739E-7,2.67929472920917E-5,1.4016469473795E-7,300.013092,300.013092,-28326.5546875,-28301.34765625,56.8025077495445,20.6326449472492,25.566563,0,0,0,40,4449,300.2773,-28313.951171875,,,,,,,,,,,,,0,,,,0,,,,,,300.013092,,,,
,31027391.155,300.0112305,-33004.046875,4.37428981674729E-5,1.10612589421517E-6,1,0.999253354069792,40.0298881530762,1.9958392082117,14.8700000718236,0.000486958981151681,0.000128392745352204,0.25,3.7818828782285E-6,4.37390976461071E-5,3.8106112343165E-6,300.0112305,300.0112305,-33009.05078125,-32999.04296875,57.1925403806407,20.6342734841833,25.566563,0,0,0,40,4449,300.2712,-33004.046875,,,,,,,,,,,,,0,,,,-0.0049,,,,,,300.0112305,,,,
,31027484.02,300.0184631,-37643.541015625,6.09963245775205E-5,1.39531751366434E-6,1,0.999253354069792,40.0298881530762,1.9958091409622,14.8700000718236,0.000682377159175175,0.000159651417453856,0.25,3.55873521983444E-6,6.09921453684779E-5,3.5988078835396E-6,300.0184631,300.0184631,-37645.8203125,-37641.26171875,56.8290831191983,20.6338360645368,25.946213,0,0,0,40,4449,300.24665,-37643.541015625,,,,,,,,,,,,,0,,,,0,,,,,,300.0184631,,,,
,31027577.265,300.0092468,-42303.546875,7.94348109617138E-5,2.15959929384679E-6,1,0.999253354069792,40.0298881530762,1.99580750743828,14.8700000718236,0.000887359114338152,0.000215372195037833,0.25,5.29465411235726E-6,7.94289683230651E-5,5.34676832679994E-6,300.0092468,300.0092468,-42313.609375,-42293.484375,56.8126689202945,20.6335172931139,25.946213,0,0,0,40,4449,300.2412,-42303.546875,,,,,,,,,,,,,0,,,,0,,,,,,300.0092468,,,,
,31027672.14,300.0083008,-47046.17578125,9.72452268714045E-5,1.76876412210084E-6,1,0.999253354069792,40.0298881530762,1.99578121062629,14.8700000718236,0.00108959199716253,0.000244681430344601,0.25,4.802670315583E-6,9.72391920853612E-5,4.86645027604446E-6,300.0083008,300.0083008,-47051.15625,-47041.1953125,57.0291800201214,20.6360670255628,25.946213,0,0,0,40,4449,300.2373,-47046.17578125,,,,,,,,,,,,,0,,,,0,,,,,,300.0083008,,,,
,31027765.86,300.0136414,-51728.53125,0.000115846551775893,1.91204608895229E-6,1,0.999253354069792,40.0298881530762,1.99580420771234,14.8700000718236,0.00129884565343556,0.000286758088455899,0.25,5.30290121758356E-6,0.000115839626327508,5.37881243001392E-6,300.0136414,300.0136414,-51733.5625,-51723.5,56.8884868866599,20.6345476287662,25.566563,0,0,0,40,4449,300.22465,-51728.53125,,,,,,,,,,,,,0,,,,-0.0049,,,,,,300.0136414,,,,
,31027864.68,300.0113525,-56670.84375,0.000136212296008615,2.57773446795411E-6,1,0.999253354069792,40.0298881530762,1.99590942510553,14.8700000718236,0.00153141953301868,0.000313172411074148,0.25,4.11043661478098E-6,0.000136205571509906,4.19965550936251E-6,300.0113525,300.0113525,-56675.79296875,-56665.89453125,57.014329078256,20.6348875423579,25.566563,0,0,0,40,4449,300.21035,-56670.84375,,,,,,,,,,,,,0,,,,-0.00245,,,,,,300.0113525,,,,
,31027963.225,300.0113831,-61592.671875,0.000154440444923073,2.39357540458165E-6,1,0.999253354069792,40.0298881530762,1.99582217707911,14.8700000718236,0.00173661342788558,0.000353167019309844,0.25,4.49251924499965E-6,0.000154432945060036,4.59356002447627E-6,300.0113831,300.0113831,-61597.70703125,-61587.63671875,57.0541921327368,20.6352474728432,25.946213,0,0,0,40,4449,300.21305,-61592.671875,,,,,,,,,,,,,0,,,,-0.0049,,,,,,300.0113831,,,,
,31028062.305,300.0151062,-66547.73046875,0.000176461712016075,2.60252102192775E-6,1,0.999253354069792,40.0298881530762,1.99571909562437,14.8700000718236,0.00197858799827671,0.00043552022547293,0.25,7.96626311585585E-6,0.000176451281486587,8.08149032881287E-6,300.0151062,300.0151062,-66555.109375,-66540.3515625,56.9174071418714,20.6346431064874,25.946213,0,0,0,40,4449,300.20105,-66547.73046875,,,,,,,,,,,,,0,,,,0,,,,,,300.0151062,,,,
,31028157.845,300.01651,-71322.25390625,0.000196537982133659,3.32833276268135E-6,1,0.999253354069792,40.0298881530762,1.99582788274575,14.8700000718236,0.00220811581135843,0.000460237353084304,0.25,6.67323366482777E-6,0.000196527811939659,6.80149019890437E-6,300.01651,300.01651,-71327.375,-71317.1328125,57.0268351345637,20.6356630095631,25.566563,0,0,0,40,4449,300.1832,-71322.25390625,,,,,,,,,,,,,0,,,,0,,,,,,300.01651,,,,
,31028253.5,300.0148315,-76101.91796875,0.00021345008915493,3.49945504822654E-6,1,0.999253354069792,40.0298881530762,1.99578877780452,14.8700000718236,0.00239273654802774,0.000530673275712018,0.25,9.97666581016075E-6,0.000213437295164986,1.01157153278589E-5,300.0148315,300.0148315,-76114.5859375,-76089.25,56.8900501436983,20.6341384726641,25.566563,0,0,0,40,4449,300.1731,-76101.91796875,,,,,,,,,,,,,0,,,,-0.00245,,,,,,300.0148315,,,,
,31028349.28,300.0136108,-80886.89453125,0.000231619185226567,3.06834168572877E-6,1,0.999253354069792,40.0298881530762,1.99582449907847,14.8700000718236,0.00259868891492735,0.000562951977764919,0.25,9.68439702939353E-6,0.000231606081419368,9.83513421414427E-6,300.0136108,300.0136108,-80896.78125,-80877.0078125,57.0635716749676,20.6363761114618,26.325863,0,0,0,40,4449,300.1679,-80886.89453125,,,,,,,,,,,,,0,,,,0,,,,,,300.0136108,,,,
,31028444.095,300.0149841,-85626.5546875,0.000256749984357948,3.95016648054508E-6,1,0.999253354069792,40.0298881530762,1.995766614958,14.8700000718236,0.00287744872688232,0.000642022171052693,0.25,1.23287057154506E-5,0.000256734433049329,1.2495561311366E-5,300.0149841,300.0149841,-85634.28125,-85618.828125,56.8947399148137,20.6363235653245,25.566563,0,0,0,40,4449,300.1429,-85626.5546875,,,,,,,,,,,,,0,,,,0,,,,,,300.0149841,,,,
,31028553.525,300.0127869,-89840.55859375,0.000269917562542205,3.49100839879054E-6,1,0.999253354069792,40.0298881530762,1.99578404981552,14.8700000718236,0.00303255794958868,0.000631595632512575,0.25,9.1245697404021E-6,0.000269903757111388,9.29990377103701E-6,300.0127869,300.0127869,-89850.4921875,-89830.625,56.9392927404099,20.639846914803,26.325863,0,0,0,40,4449,300.14015,-89840.55859375,,,,,,,,,,,,,0,,,,0,,,,,,300.0127869,,,,
,31028647.08,300.00654605,-85170.48828125,0.000250548357607324,3.34842514348424E-6,1,0.999253354069792,40.0298881530762,1.99581116884613,14.8700000718236,0.00281457329290806,0.000588624061885901,0.25,8.67699699572407E-6,0.000250535440714118,8.83993543758333E-6,300.0065308,300.0065613,-85180.5703125,-85160.40625,56.7876568076791,20.6348161212411,25.946213,0,0,0,40,4449,300.15435,-85170.48828125,,,,,,,,,,,,,0,,,,-0.00245,,,,,,300.00654605,,,,
,31028745,299.9984131,-80278.046875,0.000235586589480018,3.51654318846134E-6,1,0.999253354069792,40.0298881530762,1.99575673069599,14.8700000718236,0.00263808212185599,0.000601641344550077,0.25,1.24220772554875E-5,0.000235571706405641,1.25753740379059E-5,299.9984131,299.9984131,-80283.578125,-80272.515625,57.1034347294484,20.637055780223,25.946213,0,0,0,40,4449,300.1306,-80278.046875,,,,,,,,,,,,,0,,,,-0.00245,,,,,,299.9984131,,,,
,31028843.165,299.9909973,-75372.98046875,0.00021635318662421,2.57498234741998E-6,1,0.999253354069792,40.0298881530762,1.995898330725,14.8700000718236,0.00242825250071292,0.000521505692116856,0.25,8.66001185451409E-6,0.000216341346305095,8.80104665996654E-6,299.9909973,299.9909973,-75380.171875,-75365.7890625,56.7993812354675,20.6341097539676,26.325863,0,0,0,40,4449,300.14085,-75372.98046875,,,,,,,,,,,,,0,,,,0.00245,,,,,,299.9909973,,,,
,31028939.65,299.9888611,-70550.953125,0.000194455866922763,3.00668380056318E-6,1,0.999253354069792,40.0298881530762,1.99597120810659,14.8700000718236,0.00218100306723916,0.000477742019198534,0.25,8.57985735804298E-6,0.00019444470012059,8.70674386257807E-6,299.9888611,299.9888611,-70558.3828125,-70543.5234375,57.0643533034868,20.633751647958,25.946213,0,0,0,40,4449,300.15505,-70550.953125,,,,,,,,,,,,,0,,,,-0.0049,,,,,,299.9888611,,,,
,31029036.685,299.9908447,-65701.72265625,0.000178794370722709,2.40896543162101E-6,1,0.999253354069792,40.0298881530762,1.99581951710065,14.8700000718236,0.00200685003270841,0.000429703144648576,0.25,7.04548443903782E-6,0.000178784623969347,7.16231454549146E-6,299.9908447,299.9908447,-65706.7890625,-65696.65625,56.8306463762368,20.6357827054621,25.566563,0,0,0,40,4449,300.1602,-65701.72265625,,,,,,,,,,,,,0,,,,0,,,,,,299.9908447,,,,
,31029133.5,299.98849485,-60861.494140625,0.000155554716888374,2.41786477832299E-6,1,0.999253354069792,40.0298881530762,1.99598200796648,14.8700000718236,0.00174622662314023,0.000373355007952844,0.25,6.0831948953019E-6,0.000155546265737558,6.18495690267682E-6,299.9880676,299.9889221,-60869.078125,-60853.91015625,57.0127658212176,20.6333222796019,26.325863,0,0,0,40,4449,300.17545,-60861.494140625,,,,,,,,,,,,,0,,,,0,,,,,,299.98849485,,,,
,31029229.955,299.98791505,-56041.546875,0.000136368251151721,2.39318661983215E-6,1,0.999253354069792,40.0298881530762,1.99609774616164,14.8700000718236,0.00152999995572396,0.000332677799020918,0.25,5.80655755869551E-6,0.000136360521304294,5.89585679451056E-6,299.9869385,299.9888916,-56051.671875,-56031.421875,56.9056827140829,20.6329397378975,25.946213,0,0,0,40,4449,300.1825,-56041.546875,,,,,,,,,,,,,0,,,,-0.00245,,,,,,299.98791505,,,,
,31029325.83,299.9909363,-51249.693359375,0.00011766857172696,1.75931630560289E-6,1,0.999253354069792,40.0298881530762,1.99603004955785,14.8700000718236,0.0013217073591013,0.000278081725139932,0.25,4.21681047753629E-6,0.000117662398881885,4.29397279980538E-6,299.9909363,299.9909363,-51254.6875,-51244.69921875,57.0401228193907,20.6300607345025,26.325863,0,0,0,40,4449,300.1909,-51249.693359375,,,,,,,,,,,,,0,,,,0.0049,,,,,,299.9909363,,,,
,31029423.235,299.9848938,-46382.736328125,9.99398305293522E-5,2.13641487114422E-6,1,0.999253354069792,40.0298881530762,1.99586943848269,14.8700000718236,0.00111794655154202,0.000262355147810185,0.25,5.89867121128262E-6,9.99330767672443E-5,5.96421396215557E-6,299.9848938,299.9848938,-46392.625,-46372.84765625,57.1018714724099,20.6347621526048,25.566563,0,0,0,40,4449,300.2027,-46382.736328125,,,,,,,,,,,,,0,,,,-0.00245,,,,,,299.9848938,,,,
,31029518.83,299.9891357,-41605.1640625,7.91238626706653E-5,1.57790606769987E-6,1,0.999253354069792,40.0298881530762,1.9959199503247,14.8700000718236,0.00088315451559105,0.000219038041095955,0.25,5.67182724390749E-6,7.9117835849117E-5,5.72374444916925E-6,299.9891357,299.9891357,-41610.21875,-41600.109375,56.8611298884868,20.6333787530652,26.325863,0,0,0,40,4449,300.2096,-41605.1640625,,,,,,,,,,,,,0,,,,0,,,,,,299.9891357,,,,
,31029613.685,299.993988,-36862.42578125,5.94489049260358E-5,1.60342041142787E-6,1,0.999253354069792,40.0298881530762,1.99587825418016,14.8700000718236,0.000662979008169359,0.00016778173135805,0.25,4.54572373692331E-6,5.94441722419685E-5,4.58476421510706E-6,299.993988,299.993988,-36872.42578125,-36852.42578125,56.9525804252368,20.6320449936551,26.325863,0,0,0,40,4449,300.2073,-36862.42578125,,,,,,,,,,,,,0,,,,-0.00245,,,,,,299.993988,,,,
,31029712.09,299.9954529,-31945.89453125,4.11877092066867E-5,1.35259581112676E-6,1,0.999253354069792,40.0298881530762,1.99599724955977,14.8700000718236,0.000461677213185054,0.000102845166381657,0.25,1.96335098588287E-6,4.11852059781691E-5,1.99046039512627E-6,299.9954529,299.9954529,-31951.021484375,-31940.767578125,56.8986480574099,20.6291720209375,25.946213,0,0,0,40,4449,300.2327,-31945.89453125,,,,,,,,,,,,,0,,,,0.00245,,,,,,299.9954529,,,,
,31029808.175,299.9848633,-27143.7421875,2.41921309011494E-5,1.49434478623724E-6,1,0.999253354069792,40.0298881530762,1.99582633851204,14.8700000718236,0.000267363025151449,8.22598960514755E-5,0.25,3.08720338983334E-6,2.41893904977207E-5,3.10308751376944E-6,299.9848633,299.9848633,-27148.814453125,-27138.669921875,56.9603967104291,20.6329718239173,26.325863,0,0,0,40,4449,300.2264,-27143.7421875,,,,,,,,,,,,,0,,,,0,,,,,,299.9848633,,,,
,31029906.285,299.9873047,-22238.330078125,5.01385652386184E-6,8.57130200503582E-7,1,0.999253354069792,40.0298881530762,1.99586524534303,14.8700000718236,5.27155327920401E-5,3.26145767283824E-5,0.25,2.01711531081799E-6,5.01237717247678E-6,2.02037022772269E-6,299.9873047,299.9873047,-22250.869140625,-22225.791015625,56.7305979257752,20.6326847428732,25.946213,0,0,0,40,4449,300.24145,-22238.330078125,,,,,,,,,,,,,0,,,,0.00245,,,,,,299.9873047,,,,
,31030001.15,299.9893341,-17501.3828125,-1.1944936677257E-5,8.25203443781811E-7,1,0.999253354069792,40.0298881530762,1.99592618257759,14.8700000718236,-0.000138523990658806,-3.06445014902857E-6,0.25,1.79841574622413E-6,-1.19457765200207E-5,1.79046130611785E-6,299.9891357,299.9895325,-17508.896484375,-17493.869140625,56.7384142109675,20.6305616349696,25.566563,0,0,0,40,4449,300.2492,-17501.3828125,,,,,,,,,,,,,0,,,,0.0049,,,,,,299.9893341,,,,
,31030097.96,299.9955139,-12661.119140625,-2.93841658756471E-5,8.22743485678513E-7,1,0.999253354069792,40.0298881530762,1.99585948011038,14.8700000718236,-0.000334221268848102,-4.52415269457543E-5,0.25,1.08798768527404E-6,-2.93840175231982E-5,1.06849928627646E-6,299.9955139,299.9955139,-12665.818359375,-12656.419921875,56.6500901882945,20.6286223261768,25.946213,0,0,0,40,4449,300.24295,-12661.119140625,,,,,,,,,,,,,0,,,,-0.00245,,,,,,299.9955139,,,,
,31030193.39,299.9937439,-7890.5107421875,-4.20416773844549E-5,5.63704149279491E-7,1,0.999253354069792,40.0298881530762,1.99572622372939,14.8700000718236,-0.000477143039508415,-7.05942459669556E-5,0.25,1.03736837276186E-6,-4.20411225525939E-5,1.00947886114524E-6,299.9937439,299.9937439,-7898.22216796875,-7882.79931640625,56.9197520274291,20.6304080747571,26.325863,0,0,0,40,4449,300.25585,-7890.5107421875,,,,,,,,,,,,,0,,,,0,,,,,,299.9937439,,,,
,31030286.735,299.9919739,-3227.49291992188,-4.7900538115453E-5,4.94544234998552E-7,1,0.999253354069792,40.0298881530762,1.99578908024482,14.8700000718236,-0.000541472701242086,-9.30202255977089E-5,0.25,6.83115428722462E-8,-4.78991690396202E-5,3.65454155071051E-8,299.9919739,299.9919739,-3234.92919921875,-3220.056640625,56.800944492506,20.6282367530859,26.325863,0,0,0,40,4449,300.2543,-3227.49291992188,,,,,,,,,,,,,0,,,,0,,,,,,299.9919739,,,,
,31030378.25,299.9931946,1348.8935546875,4.13701284939858E-5,4.40512536066796E-7,1,0.999253354069792,40.0298881530762,1.99579151257543,14.8700000718236,0.000468478949866822,7.55702633776163E-5,0.25,-4.80931541838361E-7,4.13692237023746E-5,-4.5347927943663E-7,299.9931946,299.9931946,1341.626953125,1356.16015625,56.597721077506,20.6264113598857,26.325863,0,0,0,40,4449,300.27465,1348.8935546875,,,,,,,,,,,,,0,,,,0,,,,,,299.9931946,,,,
,31030473.11,299.9936218,6088.06469726563,4.71588290854325E-5,4.33692681480502E-7,1,0.999253354069792,40.0298881530762,1.99574948237694,14.8700000718236,0.000535773339765576,7.60228010138712E-5,0.25,-1.44368227406704E-6,4.71583920838806E-5,-1.41238282260416E-6,299.9936218,299.9936218,6083.13916015625,6092.990234375,56.6751023009098,20.6254595133303,25.566563,0,0,0,40,4449,300.2723,6088.06469726563,,,,,,,,,,,,,0,,,,-0.00245,,,,,,299.9936218,,,,
,31030566.08,300.0010681,10733.8823242187,3.54027171492556E-5,4.81300573620722E-7,1,0.999253354069792,40.0298881530762,1.99582541913606,14.8700000718236,0.000403439899013477,5.00681632425313E-5,0.25,-1.70361580824147E-6,3.54027911400146E-5,-1.68011702642919E-6,300.0010681,300.0010681,10731.484375,10736.2802734375,56.7134020983521,20.6244799480701,26.325863,0,0,0,40,4449,300.25735,10733.8823242187,,,,,,,,,,,,,0,,,,-0.0049,,,,,,300.0010681,,,,
,31030659.93,300.0046692,15424.3178710938,1.99173748501221E-5,8.10057950466184E-7,1,0.999253354069792,40.0298881530762,1.99593502360036,14.8700000718236,0.000229066904864097,1.61530790582355E-5,0.25,-2.0216405449959E-6,1.99181179513941E-5,-2.00839953531225E-6,300.0046692,300.0046692,15414.40234375,15434.2333984375,57.0432493334676,20.6203652434306,25.946213,0,0,0,40,4449,300.2539,15424.3178710938,,,,,,,,,,,,,0,,,,-0.00245,,,,,,300.0046692,,,,
,31030755.765,300.00248715,20216.4267578125,2.86601922684788E-6,7.27917664928583E-7,1,0.999253354069792,40.0298881530762,1.99608227368434,14.8700000718236,3.76350407370172E-5,-2.46355372772363E-5,0.25,-2.67613677151358E-6,2.86770332434516E-6,-2.67416238946853E-6,300.0018005,300.0031738,20211.478515625,20221.375,56.658688102006,20.6218623411453,25.946213,0,0,0,40,4449,300.2595,20216.4267578125,,,,,,,,,,,,,0,,,,0.00245,,,,,,300.00248715,,,,
,31030850.095,300.0080872,24929.171875,-1.37820895069148E-5,1.32210520244807E-6,1,0.999253354069792,40.0298881530762,1.99606601421606,14.8700000718236,-0.00015095795853903,-5.47999618467799E-5,0.25,-2.46050425648712E-6,-1.37800525755036E-5,-2.46953418792358E-6,300.0080872,300.0080872,24913.98046875,24944.36328125,56.6665043871983,20.6188827968826,25.946213,0,0,0,40,4449,300.251,24929.171875,,,,,,,,,,,,,0,,,,0,,,,,,300.0080872,,,,
,31030946.165,300.0091248,29732.2177734375,-3.16590022716473E-5,1.36984391422313E-6,1,0.999253354069792,40.0298881530762,1.99586519255175,14.8700000718236,-0.000349989656911347,-0.000107079030288035,0.25,-3.98944867693635E-6,-3.16554246248336E-5,-4.01022079851259E-6,300.0091248,300.0091248,29722.2109375,29742.224609375,56.790783321756,20.6185746996378,25.946213,0,0,0,40,4449,300.2415,29732.2177734375,,,,,,,,,,,,,0,,,,-0.00245,,,,,,300.0091248,,,,
,31031042.29,300.0093384,34537.287109375,-4.97447160793592E-5,1.84847853157005E-6,1,0.999253354069792,40.0298881530762,1.9957986681674,14.8700000718236,-0.000551533238953059,-0.000158872114025995,0.25,-5.43922074297262E-6,-4.97396480297076E-5,-5.4718513869962E-6,300.0093384,300.0093384,34525.00390625,34549.5703125,56.7173102409483,20.6176679399264,25.566563,0,0,0,40,4449,300.23075,34537.287109375,,,,,,,,,,,,,0,,,,0.00245,,,,,,300.0093384,,,,
,31031138.925,300.0112,39364.556640625,-6.79851136202455E-5,1.58990827568816E-6,1,0.999253354069792,40.0298881530762,1.99591209275875,14.8700000718236,-0.000763286244317069,-0.000162446348636284,0.25,-2.59450036315918E-6,-6.79813787212328E-5,-2.63919347467933E-6,300.0112,300.0112,39357.03515625,39372.078125,56.6782288149868,20.6196458375618,25.946213,0,0,0,40,4449,300.2216,39364.556640625,,,,,,,,,,,,,0,,,,-0.00245,,,,,,300.0112,,,,
,31031235.785,300.0180054,44207.248046875,-8.82495064585782E-5,2.13674387066845E-6,1,0.999253354069792,40.0298881530762,1.99669220391867,14.8700000718236,-0.000988949757924503,-0.000223755981769041,0.25,-4.50095362410176E-6,-8.82438990965604E-5,-4.55887286422068E-6,300.0180054,300.0180054,44199.73828125,44214.7578125,56.8853603725829,20.6029692439004,25.946213,0,0,0,40,4449,300.20665,44207.248046875,,,,,,,,,,,,,0,,,,0.0049,,,,,,300.0180054,,,,
,31031331.045,300.0108032,48968.078125,-0.000105752959429072,2.18447600719087E-6,1,0.999253354069792,40.0298881530762,1.99620671324664,14.8700000718236,-0.00118492441730238,-0.000267493933030341,0.25,-5.34245933467045E-6,-0.000105746311743607,-5.41179241917135E-6,300.0108032,300.0108032,48962.828125,48973.328125,56.6547799594098,20.6130295568672,25.566563,0,0,0,40,4449,300.206,48968.078125,,,,,,,,,,,,,0,,,,0.00245,,,,,,300.0108032,,,,
,31031427.865,300.01046755,53807.912109375,-0.000124579795779565,2.05031300331433E-6,1,0.999253354069792,40.0298881530762,1.99590360407247,14.8700000718236,-0.00139470552240261,-0.000320637969058918,0.25,-6.78636953581188E-6,-0.000124571655931431,-6.86793681709026E-6,300.0096741,300.011261,53800.51171875,53815.3125,56.5070521692752,20.6159660643358,25.566563,0,0,0,40,4449,300.2079,53807.912109375,,,,,,,,,,,,,0,,,,0.0049,,,,,,300.01046755,,,,
,31031525.55,300.0144043,58690.99609375,-0.000139929779974346,3.06901001806401E-6,1,0.999253354069792,40.0298881530762,1.99587477547499,14.8700000718236,-0.00157367602308803,-0.000318900736523435,0.25,-3.97372753136624E-6,-0.000139923024665593,-4.06534746649795E-6,300.0144043,300.0144043,58683.38671875,58698.60546875,56.658688102006,20.6125315588251,25.566563,0,0,0,40,4449,300.1987,58690.99609375,,,,,,,,,,,,,0,,,,0.00245,,,,,,300.0144043,,,,
,31031623.445,300.011322,63583.798828125,-0.000157291588897566,2.71732853907623E-6,1,0.999253354069792,40.0298881530762,1.99575055738522,14.8700000718236,-0.00176369704313196,-0.000388047782455483,0.25,-7.08614968418243E-6,-0.000157282311371186,-7.18894314118456E-6,300.011322,300.011322,63576.3046875,63591.29296875,56.3765202065637,20.6145310544404,25.566563,0,0,0,40,4449,300.1833,63583.798828125,,,,,,,,,,,,,0,,,,0,,,,,,300.011322,,,,
,31031717.955,300.0089722,68309.109375,-0.000178201823316401,2.19079473064211E-6,1,0.999253354069792,40.0298881530762,1.99583177206801,14.8700000718236,-0.00200738987679927,-0.000386836881274274,0.25,-3.35507466502837E-6,-0.000178194401883665,-3.47153972967694E-6,300.0089722,300.0089722,68304.09375,68314.125,57.044812590506,20.6128752389464,25.946213,0,0,0,40,4449,300.17125,68309.109375,,,,,,,,,,,,,0,,,,0.0049,,,,,,300.0089722,,,,
,31031815.925,300.0134277,73204.36328125,-0.00021220195910468,2.48538880633236E-6,1,0.999253354069792,40.0298881530762,1.99597042939275,14.8700000718236,-0.00240950741866108,-0.000351248710976385,0.25,5.6863149936222E-6,-0.000212199430796034,5.54751035194316E-6,300.0134277,300.0134277,73196.8359375,73211.890625,56.5234663681791,20.6165460046686,25.946213,0,0,0,40,4449,300.1608,73204.36328125,,,,,,,,,,,,,0,,,,0.0049,,,,,,300.0134277,,,,
,31031912.655,300.0134583,78039.9921875,-0.000222148568748186,3.60173760044049E-6,1,0.999253354069792,40.0298881530762,1.99603128556115,14.8700000718236,-0.0024923085988748,-0.000542119885910481,0.25,-9.47700898990714E-6,-0.000222135863639723,-9.62169371324302E-6,300.0134583,300.0134583,78030.0703125,78049.9140625,56.2631840712752,20.6106443720769,25.946213,0,0,0,40,4449,300.1492,78039.9921875,,,,,,,,,,,,,0,,,,0.0049,,,,,,300.0134583,,,,
,31032006.68,300.0123901,82740.94921875,-0.000240631750158076,3.06554289720333E-6,1,0.999253354069792,40.0298881530762,1.9958302428121,14.8700000718236,-0.0027075981564371,-0.000539930702490815,0.25,-6.085903660837E-6,-0.000240620745652078,-6.24256489859603E-6,300.0123901,300.0123901,82733.640625,82748.2578125,56.3429101802367,20.6169283657765,26.325863,0,0,0,40,4449,300.13955,82740.94921875,,,,,,,,,,,,,0,,,,0,,,,,,300.0123901,,,,
,31032100.18,300.01390075,87411.60546875,-0.000249627596624166,3.1628634984721E-6,1,0.999253354069792,40.0298881530762,1.99563725128445,14.8700000718236,-0.00281154969510895,-0.000542810799818922,0.25,-4.78685960808964E-6,-0.00024961718325754,-4.94922629271467E-6,300.0125732,300.0152283,87401.9375,87421.2734375,56.3952792910252,20.6141750542778,25.946213,0,0,0,40,4449,300.1357,87411.60546875,,,,,,,,,,,,,0,,,,-0.00245,,,,,,300.01390075,,,,
,31032210.43,300.013031,88112.97265625,-0.00025393529543384,3.42453932844284E-6,1,0.999253354069792,40.0298881530762,1.99587944281606,14.8700000718236,-0.0028555824985873,-0.000580040920512599,0.25,-7.32918316608071E-6,-0.000253923111124727,-7.49426229151631E-6,300.013031,300.013031,88103.03125,88122.9140625,56.4460851447752,20.6110991243546,25.946213,0,0,0,40,4449,300.1159,88112.97265625,,,,,,,,,,,,,0,,,,0,,,,,,300.013031,,,,
,31032304.665,300.0078125,83402.2109375,-0.000239277683577419,3.1884029160042E-6,1,0.999253354069792,40.0298881530762,1.99592693767421,14.8700000718236,-0.0026894926531972,-0.000554201568972462,0.25,-7.580964426159E-6,-0.000239265785142907,-7.73668758428521E-6,300.0078125,300.0078125,83399.7421875,83404.6796875,56.4273260603137,20.615725050335,26.325863,0,0,0,40,4449,300.1168,83402.2109375,,,,,,,,,,,,,0,,,,0,,,,,,300.0078125,,,,
,31032400.765,299.9969788,78598.56640625,-0.000217761802395626,3.02872479252608E-6,1,0.999253354069792,40.0298881530762,1.99608704287192,14.8700000718236,-0.00244599392047679,-0.000515069228878161,0.25,-7.84246891233846E-6,-0.000217750421990941,-7.98434047912367E-6,299.9969788,299.9969788,78591.1015625,78606.03125,56.3374387806021,20.6200303408222,25.946213,0,0,0,40,4449,300.11805,78598.56640625,,,,,,,,,,,,,0,,,,0,,,,,,299.9969788,,,,
,31032499.32,299.98947145,73669.57421875,-0.000200154527519917,2.95802600997182E-6,1,0.999253354069792,40.0298881530762,1.99581788975316,14.8700000718236,-0.00224569249919448,-0.000486291374468758,0.25,-8.35222904517277E-6,-0.000200143353681073,-8.48276055637687E-6,299.9889832,299.9899597,73662.3125,73676.8359375,56.5344091674483,20.6177254253771,26.325863,0,0,0,40,4449,300.1233,73669.57421875,,,,,,,,,,,,,0,,,,-0.00245,,,,,,299.98947145,,,,
,31032599.11,299.989624,68684.5390625,-0.000183251583500408,2.61983028772253E-6,1,0.999253354069792,40.0298881530762,1.99606600805467,14.8700000718236,-0.00205589320002359,-0.000447559930661854,0.25,-7.84871054926427E-6,-0.000183241201197218,-7.9683584078086E-6,299.989624,299.989624,68674.625,68694.453125,56.6837002146214,20.6151409761633,26.325863,0,0,0,40,4449,300.1341,68684.5390625,,,,,,,,,,,,,0,,,,0.00245,,,,,,299.989624,,,,
,31032695.68,299.9898682,63856.265625,-0.000158744980350947,1.74580477849464E-6,1,0.999253354069792,40.0298881530762,1.99597819165029,14.8700000718236,-0.00178864156052745,-0.000342888056083259,0.25,-2.83496824397789E-6,-0.000158738564691804,-2.93885514525409E-6,299.9898682,299.9898682,63851.1015625,63861.4296875,56.8259566051214,20.6137658142565,26.325863,0,0,0,40,4449,300.131,63856.265625,,,,,,,,,,,,,0,,,,-0.0049,,,,,,299.9898682,,,,
,31032794.305,299.9887085,58925.62890625,-0.000144934344215536,2.89955840028794E-6,1,0.999253354069792,40.0298881530762,1.99602516786792,14.8700000718236,-0.00163018925061009,-0.000329682256464516,0.25,-4.05850543672966E-6,-0.000144927517178539,-4.15342043995902E-6,299.9887085,299.9887085,58918.0390625,58933.21875,56.9361662263329,20.615678859017,25.946213,0,0,0,40,4449,300.1494,58925.62890625,,,,,,,,,,,,,0,,,,-0.00245,,,,,,299.9887085,,,,
,31032891.24,299.9835815,54080.357421875,-0.000126454048125658,2.70139182761097E-6,1,0.999253354069792,40.0298881530762,1.99593701968849,14.8700000718236,-0.00142815137576435,-0.000253669966299115,0.25,-5.3590993672965E-7,-0.000126450076760732,-6.18900308730894E-7,299.9835815,299.9835815,54070.2578125,54090.45703125,56.9619599674676,20.6172815719193,25.946213,0,0,0,40,4449,300.1682,54080.357421875,,,,,,,,,,,,,0,,,,0.00245,,,,,,299.9835815,,,,
,31032987.415,299.9885864,49275.423828125,-0.000105413704204273,1.70670138128446E-6,1,0.999253354069792,40.0298881530762,1.99582803161,14.8700000718236,-0.00118464492096205,-0.000245031702156691,0.25,-3.41796284189808E-6,-0.000105408414876027,-3.48713650021702E-6,299.9885864,299.9885864,49262.828125,49288.01953125,56.6821369575829,20.6198792287207,25.566563,0,0,0,40,4449,300.17395,49275.423828125,,,,,,,,,,,,,0,,,,0,,,,,,299.9885864,,,,
,31033083.89,299.9894714,44452.171875,-8.90246283296466E-5,2.31457031034097E-6,1,0.999253354069792,40.0298881530762,1.99592833127442,14.8700000718236,-0.000997424240145109,-0.000224764642842219,0.25,-4.46311359465013E-6,-8.901911367978E-5,-4.52154982088976E-6,299.9894714,299.9894714,44449.7265625,44454.6171875,56.7423223535637,20.6229348093097,26.325863,0,0,0,40,4449,300.1864,44452.171875,,,,,,,,,,,,,0,,,,0,,,,,,299.9894714,,,,
,31033179.75,299.98484805,39659.62890625,-7.02733123339808E-5,1.39902404544086E-6,1,0.999253354069792,40.0298881530762,1.99598410712106,14.8700000718236,-0.000781618127279978,-0.000210551904906099,0.25,-6.45378014722174E-6,-7.02670340811633E-5,-6.49987237449032E-6,299.9846802,299.9850159,39652.16015625,39667.09765625,56.7814037795252,20.6210489361292,25.946213,0,0,0,40,4449,300.1982,39659.62890625,,,,,,,,,,,,,0,,,,0,,,,,,299.98484805,,,,
,31033274.85,299.9898682,34907.05859375,-5.18700709281429E-5,1.72552509288834E-6,1,0.999253354069792,40.0298881530762,1.99604257267467,14.8700000718236,-0.000577157287539779,-0.000154180924889402,0.25,-4.6542899642797E-6,-5.18654930713711E-5,-4.68834940653169E-6,299.9898682,299.9898682,34899.58984375,34914.52734375,56.7462304961599,20.6175510736876,25.946213,0,0,0,40,4449,300.202,34907.05859375,,,,,,,,,,,,,0,,,,0,,,,,,299.9898682,,,,
,31033369.02,299.9890442,30202.0693359375,-3.31953986474005E-5,1.57716595044785E-6,1,0.999253354069792,40.0298881530762,1.99600224366715,14.8700000718236,-0.000369135235154561,-9.99519417116544E-5,0.25,-3.09205312045029E-6,-3.31923913255061E-5,-3.11386773745163E-6,299.9886475,299.9894409,30192.095703125,30212.04296875,56.6313311038329,20.6184875011565,25.946213,0,0,0,40,4449,300.22025,30202.0693359375,,,,,,,,,,,,,0,,,,0,,,,,,299.9890442,,,,
,31033464.195,299.9925079,25444.4189453125,-1.6863230535079E-5,9.69157409933321E-7,1,0.999253354069792,40.0298881530762,1.99627079796253,14.8700000718236,-0.000183507714631216,-7.40807013760314E-5,0.25,-3.63186529305853E-6,-1.68603372623275E-5,-3.64289751613877E-6,299.9922485,299.9927673,25434.62890625,25454.208984375,56.9064643426022,20.6144597491756,25.946213,0,0,0,40,4449,300.22215,25444.4189453125,,,,,,,,,,,,,0,,,,-0.00245,,,,,,299.9925079,,,,
,31033561.07,299.9924927,20602.111328125,3.65958434224624E-7,8.04073954540722E-7,1,0.999253354069792,40.0298881530762,1.99604008840806,14.8700000718236,1.09143983597868E-5,-3.84047819297183E-5,0.25,-3.4612541531111E-6,3.6823616864228E-7,-3.46091053449543E-6,299.9924927,299.9924927,20597.1796875,20607.04296875,56.8837971155445,20.6191883934053,26.325863,0,0,0,40,4449,300.22675,20602.111328125,,,,,,,,,,,,,0,,,,0,,,,,,299.9924927,,,,
,31033656.09,299.9911194,15854.7280273438,1.76175964001658E-5,8.17351791763458E-7,1,0.999253354069792,40.0298881530762,1.99610310513684,14.8700000718236,0.000204363214059963,4.30776234544543E-6,0.25,-2.67127901470908E-6,1.7618846663738E-5,-2.65954174943389E-6,299.9911194,299.9911194,15844.626953125,15864.8291015625,56.7305979257752,20.6181074875873,25.946213,0,0,0,40,4449,300.2318,15854.7280273438,,,,,,,,,,,,,0,,,,0,,,,,,299.9911194,,,,
,31033752.65,299.9909363,11027.5927734375,3.47395181215412E-5,5.95248291004291E-7,1,0.999253354069792,40.0298881530762,1.99595424871182,14.8700000718236,0.000396753505078278,4.42463168402704E-5,0.25,-2.10409255464714E-6,3.47398897430992E-5,-2.08102152423717E-6,299.9909363,299.9909363,11022.623046875,11032.5625,56.496109370006,20.6217444051052,26.325863,0,0,0,40,4449,300.2406,11027.5927734375,,,,,,,,,,,,,0,,,,0,,,,,,299.9909363,,,,
,31033848.26,299.9905701,6249.572265625,4.70714001603977E-5,5.13612095465566E-7,1,0.999253354069792,40.0298881530762,1.9960696651061,14.8700000718236,0.000533009728697044,8.65842484913221E-5,0.25,-4.95159930058557E-7,4.70703420490537E-5,-4.63944306111567E-7,299.9905701,299.9905701,6239.39990234375,6259.74462890625,56.9682129956214,20.6178397959337,25.566563,0,0,0,40,4449,300.24795,6249.572265625,,,,,,,,,,,,,0,,,,-0.00245,,,,,,299.9905701,,,,
,31033941.03,299.9940186,1611.17150878906,4.49423795929568E-5,4.96754872057052E-7,1,0.999253354069792,40.0298881530762,1.99607470935728,14.8700000718236,0.000508228506154384,8.65615662941336E-5,0.25,-1.28330555093408E-7,4.49411337637182E-5,-9.85174141350313E-8,299.9940186,299.9940186,1606.19787597656,1616.14514160156,56.7149653553906,20.6191380375958,26.325863,0,0,0,40,4449,300.2492,1611.17150878906,,,,,,,,,,,,,0,,,,0,,,,,,299.9940186,,,,
,31033973.03,299.9945374,-0.502384543418884,1.49725672965988E-5,5.15520925283986E-7,1,0.999253354069792,40.0298881530762,1.99613309959572,14.8700000718236,0.00017128091634425,1.75279892717537E-5,0.25,-1.04343247050827E-6,1.4972815664372E-5,-1.03346887072181E-6,299.9945374,299.9945374,-0.502384543418884,-0.502384543418884,56.6313311038329,20.6200264616078,25.566563,0,0,0,40,4417,300.2473,-0.502384543418884,,,,,,,,,,,,,0,,,,-0.0049,,,,,,299.9945374,,,,