File: data/doubleLayers/dl_5/ppms/data/DD205_6_FCC_100OE.DAT
[Header]
; VSM Data File (default extension .dat)
; Copyright (c) 2003-2013, Quantum Design, Inc. All rights reserved.
TITLE,
FILEOPENTIME,30904407.53,12/25/2018,12:35 am
BYAPP,VSM,2.0,2.0
INFO,PPMS VSM Option Release 1.4.10 Build 1,APPNAME
INFO,Quantum Design Linear Motor Servo Controller,MOTOR_MODULE_NAME
INFO,3101-100 M1,MOTOR_HW_VERSION
INFO,MMC1014,MOTOR_SERIAL_NUMBER
INFO,SRV No X-over 01.03.11,MOTOR_SOFTWARE_VERSION
INFO,Quantum Design VSM Detection Module,VSM_MODULE_NAME
INFO,3101-150 F0,VSM_HW_VERSION
INFO,VSM707,VSM_SERIAL_NUMBER
INFO,VSM No X-over 01.02.05 May 20 2008 13:51:47,VSM_SOFTWARE_VERSION
INFO,704,PREAMP_SERIAL_NUMBER
INFO,822,COIL_SERIAL_NUMBER
INFO,0,MOMENT_UNITS
INFO,CoFe2O4,SAMPLE_MATERIAL
INFO,AH11 DL,SAMPLE_COMMENT
INFO,30.27,SAMPLE_MASS
INFO,,SAMPLE_VOLUME
INFO,,SAMPLE_MOLECULAR_WEIGHT
INFO,,SAMPLE_SIZE
INFO,,SAMPLE_SHAPE
DATATYPE,COMMENT,1
DATATYPE,TIME,2
STARTUPAXIS,X,2
STARTUPAXIS,Y1,5
[Data]
Comment,Time Stamp (sec),Temperature (K),Magnetic Field (Oe),Moment (emu),M. Std. Err. (emu),Transport Action,Averaging Time (sec),Frequency (Hz),Peak Amplitude (mm),Center Position (mm),Coil Signal' (mV),Coil Signal" (mV),Range (mV),M. Quad. Signal (emu),M. Raw' (emu),M. Raw" (emu),Min. Temperature (K),Max. Temperature (K),Min. Field (Oe),Max. Field (Oe),Mass (grams),Motor Lag (deg),Pressure (Torr),VSM Status (code),Motor Status (code),Measure Status (code),Measure Count,PPMS Status (code),System Temp. (K),System Field (Oe),Sample Position (deg),Bridge 1 Resistance (ohms),Bridge 1 Excitation (에),Bridge 2 Resistance (ohms),Bridge 2 Excitation (에),Bridge 3 Resistance (ohms),Bridge 3 Excitation (에),Bridge 4 Resistance (ohms),Bridge 4 Excitation (에),Signal 1 Vin (V),Signal 2 Vin (V),Digital Inputs (code),Drive 1 Iout (mA),Drive 1 Ipower (W),Drive 2 Iout (mA),Drive 2 Ipower (W),Pressure (),Map 20 (),Map 21 (),Map 22 (),Map 23 (),Map 24 (),Map 25 (),Map 26 (),Map 27 (),Map 28 (),Map 29 ()
,30904547.485,349.584259,99.3960113525391,1.27300907016448E-5,4.319565307808E-7,1,0.999253354069792,40.0298881530762,1.99625181297462,14.7700002416968,0.00014508733339733,1.65859481985391E-5,0.25,-7.34434100821819E-7,1.27081088571432E-5,-7.26047483259241E-7,349.584259,349.584259,99.3960113525391,99.3960113525391,56.9158438848329,20.6245149873089,23.668306,0,0,0,40,4369,350.28125,99.3960113525391,,,,,,,,,,,,,0,,,,0,,,,,,349.584259,,,,
,30904696.305,346.9865723,99.3960113525391,1.31961082672828E-5,4.53694878808051E-7,1,0.999253354069792,40.0298881530762,1.99659705337037,14.7700002416968,0.000149882089263039,2.0400279184678E-5,0.25,-4.77673253709793E-7,1.31743203710844E-5,-4.69413594050838E-7,346.9865723,346.9865723,99.3960113525391,99.3960113525391,57.2425646058714,20.6333749487802,23.288654,0,0,0,40,4374,345.34235,99.3960113525391,,,,,,,,,,,,,0,,,,0,,,,,,346.9865723,,,,
,30904846.885,343.4554443,99.3960113525391,1.40836548591005E-5,4.64170796483784E-7,1,0.999253354069792,40.0298881530762,1.99661193122718,14.7700002416968,0.000160407850213838,1.9323209505837E-5,0.25,-7.27097046292735E-7,1.40622160634167E-5,-7.17910205444776E-7,343.4554443,343.4554443,99.3960113525391,99.3960113525391,57.115940785756,20.6304507597881,24.047956,0,0,0,40,4374,341.44375,99.3960113525391,,,,,,,,,,,,,0,,,,0.00245,,,,,,343.4554443,,,,
,30904992.67,339.95462035,99.3960113525391,1.4006344335123E-5,4.67333774293714E-7,1,0.999253354069792,40.0298881530762,1.99658430909119,14.7700002416968,0.000158514827444362,2.51641952453241E-5,0.25,-1.96626326527046E-7,1.39863965461826E-5,-1.88232449300063E-7,339.9241638,339.9850769,99.3960113525391,99.3960113525391,56.9721211382176,20.6291317009477,24.427608,0,0,0,40,4374,337.606,99.3960113525391,,,,,,,,,,,,,0,,,,0,,,,,,339.95462035,,,,
,30905134.735,336.4851379,99.3960113525391,1.42729028050297E-5,4.27386250713361E-7,1,0.999253354069792,40.0298881530762,1.99675591229247,14.7700002416968,0.000161728235547645,2.47004821356131E-5,0.25,-2.84398527721464E-7,1.4254325691362E-5,-2.75660261761808E-7,336.4851379,336.4851379,99.3960113525391,99.3960113525391,57.1206305568714,20.6274443237102,24.047956,0,0,0,40,4374,333.98945,99.3960113525391,,,,,,,,,,,,,0,,,,-0.00245,,,,,,336.4851379,,,,
,30905292.08,332.6773682,99.3960113525391,,,2,,,,14.7399999815226,,,,,,,332.6773682,332.6773682,99.3960113525391,99.3960113525391,,,24.427608,,,,-99999999,4374,329.9832,99.3960113525391,,,,,,,,,,,,,,,,,,,,,,,332.6773682,,,,
,30905421.58,329.4828796,99.3960113525391,1.42231323703172E-5,5.10408563422849E-7,1,0.999253354069792,40.0298881530762,1.99703878882662,14.7299999371171,0.000160731827669046,2.74723499366466E-5,0.25,-3.1437295301558E-8,1.42079177362764E-5,-2.28588621275832E-8,329.4828796,329.4828796,99.3960113525391,99.3960113525391,57.0799858738714,20.6225877833504,23.668306,0,0,0,40,4374,326.69225,99.3960113525391,,,,,,,,,,,,,0,,,,-0.00245,,,,,,329.4828796,,,,
,30905562.315,325.9899902,99.3960113525391,1.51919930349592E-5,4.84146108406665E-7,1,0.999253354069792,40.0298881530762,1.99694539647585,14.7299999371171,0.000172192188206346,2.64692031429746E-5,0.25,-2.88337103979721E-7,1.5177745839962E-5,-2.78822134023347E-7,325.9899902,325.9899902,99.3960113525391,99.3960113525391,57.007294421583,20.6227117915041,23.668306,0,0,0,40,4374,323.1527,99.3960113525391,,,,,,,,,,,,,0,,,,-0.00245,,,,,,325.9899902,,,,
,30905713.34,322.2730713,99.3960113525391,,,2,,,,14.7499995920062,,,,,,,322.2730713,322.2730713,99.3960113525391,99.3960113525391,,,24.047956,,,,-99999999,4374,319.3479,99.3960113525391,,,,,,,,,,,,,,,,,,,,,,,322.2730713,,,,
,30905845,318.9962158,99.3960113525391,1.51220223780153E-5,4.01149128984258E-7,1,0.999253354069792,40.0298881530762,1.9967552674416,14.7299999371171,0.000172116060933441,2.23655829285723E-5,0.25,-6.40004508750622E-7,1.51117726562399E-5,-6.30114102310384E-7,318.9962158,318.9962158,99.3960113525391,99.3960113525391,56.9455457685637,20.6268902534822,24.047956,0,0,0,40,4374,316.0292,99.3960113525391,,,,,,,,,,,,,0,,,,0.0049,,,,,,318.9962158,,,,
,30905987.885,315.4658813,99.3960113525391,1.50566488297473E-5,2.98596686811702E-7,1,0.999253354069792,40.0298881530762,1.9972552361035,14.7299999371171,0.000169830806589106,3.15337814935611E-5,0.25,1.81597928018023E-7,1.50478039818312E-5,1.91018540186066E-7,315.4658813,315.4658813,99.3960113525391,99.3960113525391,57.047939104583,20.6172987919355,24.427608,0,0,0,40,4374,312.4368,99.3960113525391,,,,,,,,,,,,,0,,,,0,,,,,,315.4658813,,,,
,30906132.31,311.8974304,99.3960113525391,,,2,,,,14.7600001338124,,,,,,,311.8974304,311.8974304,99.3960113525391,99.3960113525391,,,23.668306,,,,-99999999,4374,308.8109,99.3960113525391,,,,,,,,,,,,,,,,,,,,,,,311.8974304,,,,
,30906270.43,308.4711914,99.3960113525391,1.60079131870266E-5,3.65841519573254E-7,1,0.999253354069792,40.0298881530762,1.99699731590407,14.750000089407,0.000182015555225667,2.5261303845156E-5,0.25,-5.3868085434081E-7,1.60029459120463E-5,-5.28094786546211E-7,308.4711914,308.4711914,99.3960113525391,99.3960113525391,56.8697278021983,20.6325428211919,24.047956,0,0,0,40,4374,305.34045,99.3960113525391,,,,,,,,,,,,,0,,,,0,,,,,,308.4711914,,,,
,30906413.365,304.9338989,99.3960113525391,1.57819548092828E-5,4.50584286197856E-7,1,0.999253354069792,40.0298881530762,1.99667995896085,14.750000089407,0.000177961737304599,3.34463298384795E-5,0.25,2.24451831994322E-7,1.57785483439134E-5,2.348116646845E-7,304.9338989,304.9338989,99.3960113525391,99.3960113525391,57.0440309619868,20.635576984619,24.047956,0,0,0,40,4374,301.7449,99.3960113525391,,,,,,,,,,,,,0,,,,0.00245,,,,,,304.9338989,,,,
,30906531.915,301.98278805,99.3960113525391,1.59841238966416E-5,5.20481420046939E-7,1,0.999253354069792,40.0298881530762,1.99671585323955,14.750000089407,0.000180889973701228,3.02630394592005E-5,0.25,-9.26314644960881E-8,1.59825652561833E-5,-8.19567398144496E-8,301.9524841,302.013092,99.3960113525391,99.3960113525391,56.780622151006,20.6334199930246,24.047956,0,0,0,40,4374,298.76515,99.3960113525391,,,,,,,,,,,,,0,,,,-0.00245,,,,,,301.98278805,,,,
,30906654.38,298.9292603,99.3960113525391,1.56573544314679E-5,3.49837641503018E-7,1,0.999253354069792,40.0298881530762,1.99707798919397,14.7700002416968,0.000176964868404236,3.12518639245488E-5,0.25,5.05412410747431E-8,1.56574381601309E-5,6.11194036134465E-8,298.9292603,298.9292603,99.3960113525391,99.3960113525391,56.9822823089676,20.6272750939399,24.047956,0,0,0,40,4374,295.6878,99.3960113525391,,,,,,,,,,,,,0,,,,0,,,,,,298.9292603,,,,
,30906793.44,295.4880371,99.3960113525391,1.63470839386439E-5,4.37023886961426E-7,1,0.999253354069792,40.0298881530762,1.99694376364758,14.7700002416968,0.0001844097374396,3.47169116287023E-5,0.25,2.37099543304351E-7,1.63490536340288E-5,2.48332367528532E-7,295.4880371,295.4880371,99.3960113525391,99.3960113525391,57.0495023616214,20.6270344863728,23.668306,0,0,0,40,4374,292.20795,99.3960113525391,,,,,,,,,,,,,0,,,,-0.00245,,,,,,295.4880371,,,,
,30906936.11,291.9544373,99.3960113525391,1.6641181465648E-5,4.88218940827235E-7,1,0.999253354069792,40.0298881530762,1.99649826258744,14.7700002416968,0.000188872228581376,2.86382388028301E-5,0.25,-3.51305183876914E-7,1.66456988868754E-5,-3.39821337289253E-7,291.9544373,291.9544373,99.3960113525391,99.3960113525391,57.3762230826599,20.626038496117,23.668306,0,0,0,40,4374,288.6221,99.3960113525391,,,,,,,,,,,,,0,,,,-0.00245,,,,,,291.9544373,,,,
,30907055.44,288.9774475,99.3960113525391,1.67547443084672E-5,4.87278217331518E-7,1,0.999253354069792,40.0298881530762,1.99654630118273,14.7900003939867,0.000190044086108129,2.96550771912251E-5,0.25,-2.81551059999052E-7,1.67610298519703E-5,-2.69853217242192E-7,288.9774475,288.9774475,99.3960113525391,99.3960113525391,57.3605905122753,20.6260496247647,24.427608,0,0,0,40,4374,285.63075,99.3960113525391,,,,,,,,,,,,,0,,,,-0.0049,,,,,,288.9774475,,,,
,30907197.46,285.447998,99.3960113525391,1.70366716620666E-5,4.06642717721666E-7,1,0.999253354069792,40.0298881530762,1.99657262355215,14.7900003939867,0.000191872323082719,3.82157195450832E-5,0.25,4.25865328974029E-7,1.70447096755378E-5,4.38255483782926E-7,285.447998,285.447998,99.3960113525391,99.3960113525391,57.0502839901407,20.6268911287953,24.047956,0,0,0,40,4374,282.0657,99.3960113525391,,,,,,,,,,,,,0,,,,0.00245,,,,,,285.447998,,,,
,30907337.315,281.9768372,99.3960113525391,1.70053048273541E-5,4.19633132943771E-7,1,0.999253354069792,40.0298881530762,1.99670803933375,14.7900003939867,0.000192365616205633,3.34768500451431E-5,0.25,1.1610280834957E-8,1.7015737402412E-5,2.39609121299568E-8,281.9768372,281.9768372,99.3960113525391,99.3960113525391,57.3215090863138,20.622221260961,23.668306,0,0,0,40,4374,278.566,99.3960113525391,,,,,,,,,,,,,0,,,,0,,,,,,281.9768372,,,,
,30907477.595,278.4806519,99.3960113525391,1.71871265688789E-5,4.58006654930591E-7,1,0.999253354069792,40.0298881530762,1.99651869313328,14.8000000044703,0.000194557316912792,3.30964073509514E-5,0.25,-5.38226451312198E-8,1.71998705406943E-5,-4.11952120217353E-8,278.4806519,278.4806519,99.3960113525391,99.3960113525391,56.9088092281599,20.6251488833295,24.047956,0,0,0,40,4374,275.06255,99.3960113525391,,,,,,,,,,,,,0,,,,0,,,,,,278.4806519,,,,
,30907618.455,274.9680786,99.3960113525391,1.71527987566036E-5,3.86820940330526E-7,1,0.999253354069792,40.0298881530762,1.9963026261637,14.8000000044703,0.000193647424371417,3.60633749875396E-5,0.25,2.14104060623812E-7,1.71674738140192E-5,2.27128857510796E-7,274.9680786,274.9680786,99.3960113525391,99.3960113525391,56.7055858131598,20.627272726065,23.668306,0,0,0,40,4374,271.5427,99.3960113525391,,,,,,,,,,,,,0,,,,0,,,,,,274.9680786,,,,
,30907758.08,271.4800415,99.3960113525391,1.7840089202532E-5,3.35942483980843E-7,1,0.999253354069792,40.0298881530762,1.99637651226393,14.8000000044703,0.000202016346776519,3.41829605105721E-5,0.25,-7.19294149753633E-8,1.78577989092836E-5,-5.84362404493978E-8,271.4800415,271.4800415,99.3960113525391,99.3960113525391,57.4168677656599,20.6255057849034,24.427608,0,0,0,40,4374,268.0433,99.3960113525391,,,,,,,,,,,,,0,,,,0,,,,,,271.4800415,,,,
,30907898.095,267.9770813,99.3960113525391,1.82633849818792E-5,3.4293723140114E-7,1,0.999253354069792,40.0298881530762,2.00896501057887,14.8400003090501,0.00020810830234472,3.50434256365329E-5,0.25,-8.83916912039216E-8,1.82838123512735E-5,-7.43821462708849E-8,267.9770813,267.9770813,99.3960113525391,99.3960113525391,57.2769562607176,20.6274294223043,24.427608,0,0,0,40,4374,264.5375,99.3960113525391,,,,,,,,,,,,,0,,,,-0.00245,,,,,,267.9770813,,,,
,30908040.53,264.4736328,99.3960113525391,1.7959408191561E-5,4.82140187548326E-7,1,0.999253354069792,40.0298881530762,1.99646056629634,14.8400003090501,0.000203309408501611,3.50967929666438E-5,0.25,-1.31999862660166E-8,1.79816823082519E-5,8.86015494547699E-10,264.4736328,264.4736328,99.3960113525391,99.3960113525391,57.4059249663907,20.6305545027785,24.427608,0,0,0,40,4374,260.9614,99.3960113525391,,,,,,,,,,,,,0,,,,0,,,,,,264.4736328,,,,
,30908182.475,260.9441833,99.3960113525391,1.8056887888051E-5,3.3451267191589E-7,1,0.999253354069792,40.0298881530762,1.99647886794364,14.8400003090501,0.000205550637569573,2.88890104729058E-5,0.25,-5.79114861378539E-7,1.80820032739E-5,-5.65491500115195E-7,260.9441833,260.9441833,99.3960113525391,99.3960113525391,57.0252718775253,20.6263466923541,24.807261,0,0,0,40,4374,257.4186,99.3960113525391,,,,,,,,,,,,,0,,,,0.0049,,,,,,260.9441833,,,,
,30908321.68,257.4507751,99.3960113525391,1.85656663918965E-5,3.45884256094037E-7,1,0.999253354069792,40.0298881530762,1.99652735937858,14.8499999195337,0.000210551301667665,3.44486832987835E-5,0.25,-1.76913283945319E-7,1.85934612391376E-5,-1.62111602901242E-7,257.4507751,257.4507751,99.3960113525391,99.3960113525391,57.2027015513907,20.6221383604423,24.047956,0,0,0,40,4374,253.9338,99.3960113525391,,,,,,,,,,,,,0,,,,0,,,,,,257.4507751,,,,
,30908460.11,253.9705048,99.3960113525391,1.8738733788537E-5,4.58401585304272E-7,1,0.999253354069792,40.0298881530762,1.99662449984113,14.8499999195337,0.000212058602469307,3.76097907598608E-5,0.25,7.14570598790494E-8,1.87688942366925E-5,8.70308434023039E-8,253.9705048,253.9705048,99.3960113525391,99.3960113525391,57.1135959001984,20.6224070046405,24.427608,0,0,0,40,4374,250.4752,99.3960113525391,,,,,,,,,,,,,0,,,,0.00245,,,,,,253.9705048,,,,
,30908601.53,250.4374084,99.3960113525391,1.8823515145704E-5,3.30379330461128E-7,1,0.999253354069792,40.0298881530762,1.99648313710592,14.8499999195337,0.000213762735898055,3.35583535236449E-5,0.25,-3.01452764561343E-7,1.88564730329304E-5,-2.86180530820925E-7,250.4374084,250.4374084,99.3960113525391,99.3960113525391,56.9080275996406,20.6241859244045,24.427608,0,0,0,40,4374,246.9447,99.3960113525391,,,,,,,,,,,,,0,,,,-0.00245,,,,,,250.4374084,,,,
,30908719.125,247.4803162,99.3960113525391,1.89737200720086E-5,4.72228730832111E-7,1,0.999253354069792,40.0298881530762,1.99640244949752,14.8900002241135,0.000215361735072146,3.45252561712236E-5,0.25,-2.42552537167301E-7,1.90088680527289E-5,-2.26846609649636E-7,247.4803162,247.4803162,99.3960113525391,99.3960113525391,56.8204852054868,20.6264831260348,24.427608,0,0,0,40,4374,244.0129,99.3960113525391,,,,,,,,,,,,,0,,,,0,,,,,,247.4803162,,,,
,30908859.52,243.9788818,99.3960113525391,1.90036268898177E-5,3.966513657268E-7,1,0.999253354069792,40.0298881530762,1.99629403241159,14.8900002241135,0.000215217690233622,3.74576917415212E-5,0.25,1.06696617690924E-8,1.90409488552588E-5,2.71527212733112E-8,243.9788818,243.9788818,99.3960113525391,99.3960113525391,57.0268351345637,20.6292007938414,24.047956,0,0,0,40,4374,240.5125,99.3960113525391,,,,,,,,,,,,,0,,,,-0.00245,,,,,,243.9788818,,,,
,30908999.195,240.4688873,99.3960113525391,1.91634837847746E-5,3.57623441350531E-7,1,0.999253354069792,40.0298881530762,1.99632693328427,14.8900002241135,0.000217532154181647,3.50452279486308E-5,0.25,-2.30780794295105E-7,1.92036828825758E-5,-2.14365465209871E-7,240.4688873,240.4688873,99.3960113525391,99.3960113525391,57.1214121853907,20.6279606196039,24.047956,0,0,0,40,4374,237.0084,99.3960113525391,,,,,,,,,,,,,0,,,,-0.0049,,,,,,240.4688873,,,,
,30909140.65,236.9566193,99.3960113525391,1.88575509516374E-5,3.33334347846986E-7,1,0.999253354069792,40.0298881530762,1.99634729368826,14.919999986887,0.000214052394829388,3.46932893505686E-5,0.25,-2.09481622455662E-7,1.88993996429858E-5,-1.93012025294305E-7,236.9566193,236.9566193,99.3960113525391,99.3960113525391,57.1815975813714,20.6289982225306,24.427608,0,0,0,40,4374,233.46575,99.3960113525391,,,,,,,,,,,,,0,,,,0.0049,,,,,,236.9566193,,,,
,30909280.03,233.482193,99.3960113525391,1.92974511491081E-5,3.70163416869995E-7,1,0.999253354069792,40.0298881530762,1.99619299093902,14.919999986887,0.000219477302076081,3.3075484920355E-5,0.25,-4.29056317552251E-7,1.934279633782E-5,-4.12409247694583E-7,233.482193,233.482193,99.3960113525391,99.3960113525391,57.2871174314676,20.6327622653598,24.047956,0,0,0,40,4374,229.97025,99.3960113525391,,,,,,,,,,,,,0,,,,0.0049,,,,,,233.482193,,,,
,30909417.985,229.9985504,99.3960113525391,1.89757131654942E-5,4.12710494163576E-7,1,0.999253354069792,40.0298881530762,1.99654274514453,14.919999986887,0.000215371956361984,3.5461360722052E-5,0.25,-1.638592902256E-7,1.90223453606306E-5,-1.46587555940238E-7,229.9985504,229.9985504,99.3960113525391,99.3960113525391,56.9893169656406,20.6305366211663,24.047956,0,0,0,40,4374,226.5234,99.3960113525391,,,,,,,,,,,,,0,,,,-0.00245,,,,,,229.9985504,,,,
,30909558.455,226.4815369,99.3960113525391,1.89593350218199E-5,3.89769029872351E-7,1,0.999253354069792,40.0298881530762,1.99640862960043,14.9699999019504,0.000215656920710036,3.2789299638524E-5,0.25,-3.97295223341317E-7,1.90084339719525E-5,-3.80319745436012E-7,226.4815369,226.4815369,99.3960113525391,99.3960113525391,56.9517987967176,20.626789233823,24.427608,0,0,0,40,4374,223.0132,99.3960113525391,,,,,,,,,,,,,0,,,,-0.00245,,,,,,226.4815369,,,,
,30909699.015,222.9964142,99.3960113525391,1.98196740281581E-5,3.8746555390415E-7,1,0.999253354069792,40.0298881530762,1.99616377170043,14.9699999019504,0.000224706442618755,3.85229745773776E-5,0.25,-4.10724832184228E-8,1.98729954522257E-5,-2.20014050154318E-8,222.9964142,222.9964142,99.3960113525391,99.3960113525391,56.8634747740445,20.6307289748445,23.668306,0,0,0,40,4374,219.49705,99.3960113525391,,,,,,,,,,,,,0,,,,-0.0049,,,,,,222.9964142,,,,
,30909839.795,219.4601593,99.3960113525391,1.92941584118556E-5,2.99897918582994E-7,1,0.999253354069792,40.0298881530762,1.9961392328065,14.9699999019504,0.000218879996646313,3.68828550228625E-5,0.25,-9.52914580794865E-8,1.93484267274803E-5,-7.6514337079233E-8,219.4601593,219.4601593,99.3960113525391,99.3960113525391,57.1862873524868,20.6275080314008,23.668306,0,0,0,40,4374,215.99335,99.3960113525391,,,,,,,,,,,,,0,,,,0,,,,,,219.4601593,,,,
,30909979.485,215.9883728,99.3960113525391,1.89456783228162E-5,3.84088385657781E-7,1,0.999253354069792,40.0298881530762,2.00901151603495,14.9900000542402,0.000215752329078857,3.94481170641969E-5,0.25,1.69466834711815E-7,1.90009088860325E-5,1.89042643441058E-7,215.9883728,215.9883728,99.3960113525391,99.3960113525391,57.1761261817368,20.6287428756407,24.427608,0,0,0,40,4374,212.4951,99.3960113525391,,,,,,,,,,,,,0,,,,0,,,,,,215.9883728,,,,
,30910119.25,212.4881744,99.3960113525391,1.93663319939958E-5,4.12708516576485E-7,1,0.999253354069792,40.0298881530762,2.00902613855454,14.9900000542402,0.000220869888840499,3.86007601560746E-5,0.25,2.13285663531988E-8,1.94251973112148E-5,4.12997450942414E-8,212.4881744,212.4881744,99.3960113525391,99.3960113525391,57.108906129083,20.6296865895893,24.047956,0,0,0,40,4374,209.0148,99.3960113525391,,,,,,,,,,,,,0,,,,0.0049,,,,,,212.4881744,,,,
,30910258.33,208.9868927,99.3960113525391,1.89104278396781E-5,3.68373300071257E-7,1,0.999253354069792,40.0298881530762,2.00892149462689,14.9900000542402,0.000215520401138533,3.8639556319207E-5,0.25,1.03262336210348E-7,1.89700057942171E-5,1.2343477835251E-7,208.9868927,208.9868927,99.3960113525391,99.3960113525391,57.3074397729676,20.6290445821619,24.047956,0,0,0,40,4374,205.54575,99.3960113525391,,,,,,,,,,,,,0,,,,-0.0049,,,,,,208.9868927,,,,
,30910399.265,205.4691925,99.3960113525391,1.92854674216392E-5,4.1202372850384E-7,1,0.999253354069792,40.0298881530762,2.00896507577775,15.0399999693036,0.000220384359229195,3.61872009163635E-5,0.25,-1.77707332213106E-7,1.93487464849653E-5,-1.57605673476623E-7,205.4691925,205.4691925,99.3960113525391,99.3960113525391,57.1151591572368,20.6252145795512,24.047956,0,0,0,40,4374,202.0205,99.3960113525391,,,,,,,,,,,,,0,,,,0,,,,,,205.4691925,,,,
,30910539.21,201.9527893,99.3960113525391,1.92731976538336E-5,3.09796472441772E-7,1,0.999253354069792,40.0298881530762,2.00901047256997,15.0399999693036,0.000220763434315374,3.33511493472561E-5,0.25,-4.25003002661682E-7,1.93389075110329E-5,-4.05313351776555E-7,201.9527893,201.9527893,99.3960113525391,99.3960113525391,56.9893169656406,20.6251123442706,24.047956,0,0,0,40,4374,198.5321,99.3960113525391,,,,,,,,,,,,,0,,,,0.0049,,,,,,201.9527893,,,,
,30910676.485,198.4985352,99.3960113525391,1.95324961455134E-5,3.89984365160988E-7,1,0.999253354069792,40.0298881530762,2.00901904028306,15.0399999693036,0.000223319808642799,3.63334268483261E-5,0.25,-2.09526793890479E-7,1.96010162156972E-5,-1.88367369497678E-7,198.4985352,198.4985352,99.3960113525391,99.3960113525391,57.393418910083,20.627884703996,23.668306,0,0,0,40,4374,195.0983,99.3960113525391,,,,,,,,,,,,,0,,,,-0.00245,,,,,,198.4985352,,,,
,30910819.335,194.935379,99.3960113525391,1.94014154410164E-5,4.56454189774415E-7,1,0.999253354069792,40.0298881530762,2.0089474990879,15.0800002738833,0.000221694396721118,3.69225911865411E-5,0.25,-1.35899170590557E-7,1.94715900864241E-5,-1.14123851024643E-7,194.935379,194.935379,99.3960113525391,99.3960113525391,57.2238055214099,20.6272414272997,23.288654,0,0,0,40,4374,191.5207,99.3960113525391,,,,,,,,,,,,,0,,,,-0.00245,,,,,,194.935379,,,,
,30910959.6,191.4288635,99.3960113525391,1.94681771300541E-5,3.7892098851883E-7,1,0.999253354069792,40.0298881530762,2.00907460868021,15.0800002738833,0.000221584264976781,4.22971240021569E-5,0.25,3.22259201412708E-7,1.95401970713079E-5,3.46338649547679E-7,191.4288635,191.4288635,99.3960113525391,99.3960113525391,57.3347967711407,20.6258605816193,23.668306,0,0,0,40,4374,188.01555,99.3960113525391,,,,,,,,,,,,,0,,,,0,,,,,,191.4288635,,,,
,30911097.5,187.9519958,99.3960113525391,1.93796985723298E-5,3.3358777121844E-7,1,0.999253354069792,40.0298881530762,2.00897652011969,15.0800002738833,0.000222541491563604,3.08826887699715E-5,0.25,-6.63060394190254E-7,1.94546520879027E-5,-6.4226402360266E-7,187.9519958,187.9519958,99.3960113525391,99.3960113525391,56.9564885678329,20.6311384323608,23.668306,0,0,0,40,4374,184.56,99.3960113525391,,,,,,,,,,,,,0,,,,0,,,,,,187.9519958,,,,
,30911220.585,184.9533539,99.3960113525391,1.9206224361609E-5,3.0899199621915E-7,1,0.999253354069792,40.0298881530762,2.00879207577579,15.1300001889467,0.000219392344196638,3.72681833378701E-5,0.25,-7.40667173103804E-8,1.92815626202746E-5,-5.07034404577979E-8,184.9533539,184.9533539,99.3960113525391,99.3960113525391,57.3183825722368,20.6259364619627,23.668306,0,0,0,40,4374,181.40825,99.3960113525391,,,,,,,,,,,,,0,,,,0,,,,,,184.9533539,,,,
,30911356.97,181.4858093,99.3960113525391,1.93645357777751E-5,3.18583416537923E-7,1,0.999253354069792,40.0298881530762,2.00867748997738,15.1300001889467,0.000221051647797739,3.84984277468412E-5,0.25,5.4245116291683E-9,1.94424246542344E-5,2.98902511912805E-8,181.4858093,181.4858093,99.3960113525391,99.3960113525391,57.268358347006,20.6321461538554,24.047956,0,0,0,40,4374,178.06365,99.3960113525391,,,,,,,,,,,,,0,,,,0.00245,,,,,,181.4858093,,,,
,30911496.585,177.9904785,99.3960113525391,1.93640234102058E-5,3.76174364943326E-7,1,0.999253354069792,40.0298881530762,2.00836506020113,15.1300001889467,0.000221516759106845,3.5730519697473E-5,0.25,-2.37454918397823E-7,1.94442359390812E-5,-2.1334082826018E-7,177.9904785,177.9904785,99.3960113525391,99.3960113525391,57.268358347006,20.630160219104,23.668306,0,0,0,40,4374,174.60335,99.3960113525391,,,,,,,,,,,,,0,,,,-0.0049,,,,,,177.9904785,,,,
,30911635.21,174.4743805,99.3960113525391,1.90430042162484E-5,3.02972135204006E-7,1,0.999253354069792,40.0298881530762,1.98424838769442,15.1800001040101,0.000214469156127776,3.99129206011004E-5,0.25,2.24276880750892E-7,1.91232436937657E-5,2.50579417108185E-7,174.4743805,174.4743805,99.3960113525391,99.3960113525391,57.1534589546791,20.6321890815447,23.668306,0,0,0,40,4374,171.15075,99.3960113525391,,,,,,,,,,,,,0,,,,0,,,,,,174.4743805,,,,
,30911775.31,170.9438629,99.3960113525391,1.94584531791121E-5,3.47949390950074E-7,1,0.999253354069792,40.0298881530762,1.98395372018839,15.1800001040101,0.000219394734381095,3.93123192631719E-5,0.25,9.82039185999852E-8,1.95425866079755E-5,1.25274978514646E-7,170.9438629,170.9438629,99.3960113525391,99.3960113525391,57.0760777312753,20.6367580429835,23.288654,0,0,0,40,4374,167.671,99.3960113525391,,,,,,,,,,,,,0,,,,0.0049,,,,,,170.9438629,,,,
,30911913.04,167.4996185,99.3960113525391,1.94242915698543E-5,3.56365729351913E-7,1,0.999253354069792,40.0298881530762,1.9838429465482,15.1800001040101,0.00021952101778219,3.63601143303787E-5,0.25,-1.58365393922193E-7,1.95105176782484E-5,-1.31694853615693E-7,167.4996185,167.4996185,99.3960113525391,99.3960113525391,57.0846756449868,20.6379242902259,23.288654,0,0,0,40,4374,164.23865,99.3960113525391,,,,,,,,,,,,,0,,,,0.0049,,,,,,167.4996185,,,,
,30912051.89,163.9957275,99.3960113525391,1.94218577848782E-5,3.5956699622543E-7,1,0.999253354069792,40.0298881530762,2.00819104370062,15.2300000190735,0.000222014348970838,3.71936553996736E-5,0.25,-1.23368024803777E-7,1.9509906376923E-5,-9.5729812672021E-8,163.9957275,163.9957275,99.3960113525391,99.3960113525391,57.1808159528522,20.6305738737758,23.288654,0,0,0,40,4374,160.782,99.3960113525391,,,,,,,,,,,,,0,,,,-0.00245,,,,,,163.9957275,,,,
,30912195.545,160.4285736,99.3960113525391,1.94844413811418E-5,3.79123854928577E-7,1,0.999253354069792,40.0298881530762,2.00789554979857,15.2300000190735,0.000223149750133491,3.48428007795931E-5,0.25,-3.40921097148864E-7,1.95749750615786E-5,-3.13289528798328E-7,160.4285736,160.4285736,99.3960113525391,99.3960113525391,57.3074397729676,20.6329214972874,22.909004,0,0,0,40,4374,157.1983,99.3960113525391,,,,,,,,,,,,,0,,,,0.00245,,,,,,160.4285736,,,,
,30912331.97,156.9667053,99.3960113525391,1.94118129658645E-5,3.08189846494074E-7,1,0.999253354069792,40.0298881530762,2.00800329459689,15.2300000190735,0.000221943211294989,3.70517387257636E-5,0.25,-1.36195522328712E-7,1.95034778860202E-5,-1.06811564665025E-7,156.9667053,156.9667053,99.3960113525391,99.3960113525391,57.0401228193907,20.631365922689,22.909004,0,0,0,40,4374,153.8034,99.3960113525391,,,,,,,,,,,,,0,,,,-0.00245,,,,,,156.9667053,,,,
,30912470.885,153.49928285,99.3960113525391,1.918296055392E-5,3.20517284663917E-7,1,0.999253354069792,40.0298881530762,1.98351992786546,15.3000000864267,0.000216806348709319,3.6112994103331E-5,0.25,-1.42573010785838E-7,1.92752623085557E-5,-1.12584408494799E-7,153.4680481,153.5305176,99.3960113525391,99.3960113525391,57.1479875550445,20.6394699366813,22.909004,0,0,0,40,4374,150.33785,99.3960113525391,,,,,,,,,,,,,0,,,,-0.00245,,,,,,153.49928285,,,,
,30912609.615,149.9981842,99.3960113525391,1.94740005635703E-5,3.64992536112133E-7,1,0.999253354069792,40.0298881530762,1.98329790214329,15.3000000864267,0.000220568206373602,3.39234906048048E-5,0.25,-3.88273970596964E-7,1.95698042536238E-5,-3.57947611451763E-7,149.9981842,149.9981842,99.3960113525391,99.3960113525391,56.7517018957945,20.642840905654,22.529354,0,0,0,40,4374,146.8879,99.3960113525391,,,,,,,,,,,,,0,,,,0,,,,,,149.9981842,,,,
,30912750.14,146.49102785,99.3960113525391,1.90122707829561E-5,3.68046629736712E-7,1,0.999253354069792,40.0298881530762,1.98353554890948,15.3000000864267,0.000215164700556558,3.43687594442592E-5,0.25,-2.70116242583365E-7,1.91072313547761E-5,-2.38837433510734E-7,146.4609833,146.5210724,99.3960113525391,99.3960113525391,56.7352876968906,20.6448581246966,22.529354,0,0,0,40,4374,143.3707,99.3960113525391,,,,,,,,,,,,,0,,,,-0.0049,,,,,,146.49102785,,,,
,30912892.42,142.911438,99.3960113525391,1.94419231581613E-5,3.33943237735448E-7,1,0.999253354069792,40.0298881530762,2.0079017666991,15.3500000014901,0.000222172712423964,3.81523657871185E-5,0.25,-5.05760379593581E-8,1.95402469712454E-5,-1.6185130015371E-8,142.911438,142.911438,99.3960113525391,99.3960113525391,56.9494539111599,20.6431015460633,22.909004,0,0,0,40,4374,139.8359,99.3960113525391,,,,,,,,,,,,,0,,,,0,,,,,,142.911438,,,,
,30913027.625,139.4950104,99.3960113525391,1.93618334972706E-5,3.23226664541892E-7,1,0.999253354069792,40.0298881530762,2.00773214557813,15.3500000014901,0.000221287386129906,3.7816679891181E-5,0.25,-6.72895984302602E-8,1.94612424935591E-5,-3.18108038222246E-8,139.4950104,139.4950104,99.3960113525391,99.3960113525391,56.7931282073137,20.6377981404588,22.149702,0,0,0,40,4374,136.4649,99.3960113525391,,,,,,,,,,,,,0,,,,0,,,,,,139.4950104,,,,
,30913168.25,135.9915619,99.3960113525391,1.94113502519486E-5,3.26838903724564E-7,1,0.999253354069792,40.0298881530762,2.00793834978104,15.3500000014901,0.000222394693720333,3.50356522012701E-5,0.25,-3.21409208055675E-7,1.95129247412833E-5,-2.85679842108665E-7,135.9915619,135.9915619,99.3960113525391,99.3960113525391,57.2667950899676,20.6339737000618,22.909004,0,0,0,40,4374,132.96565,99.3960113525391,,,,,,,,,,,,,0,,,,0,,,,,,135.9915619,,,,
,30913306.77,132.4754028,99.3960113525391,1.93973352765059E-5,4.05232946875604E-7,1,0.999253354069792,40.0298881530762,1.98377531251438,15.4200000688434,0.000219544906737641,3.54775576090253E-5,0.25,-2.45979871998434E-7,1.95000562750449E-5,-2.08317608160386E-7,132.4754028,132.4754028,99.3960113525391,99.3960113525391,57.1776894387753,20.6372214706757,22.529354,0,0,0,40,4374,129.5218,99.3960113525391,,,,,,,,,,,,,0,,,,0,,,,,,132.4754028,,,,
,30913448.24,128.9406128,99.3960113525391,1.91853719598691E-5,3.31481760187061E-7,1,0.999253354069792,40.0298881530762,1.98372117379342,15.4200000688434,0.000217432153214882,3.35015984366081E-5,0.25,-3.85775338254641E-7,1.92885285066581E-5,-3.47564072644488E-7,128.9406128,128.9406128,99.3960113525391,99.3960113525391,57.2230238928907,20.6414510206606,21.770052,0,0,0,40,4374,126.0131,99.3960113525391,,,,,,,,,,,,,0,,,,0.0049,,,,,,128.9406128,,,,
,30913585.465,125.4711685,99.3960113525391,1.93326753567308E-5,3.24128294349658E-7,1,0.999253354069792,40.0298881530762,1.98379795785432,15.4200000688434,0.000218872985934792,3.51911052039424E-5,0.25,-2.64056741418163E-7,1.94375115539402E-5,-2.23047701274108E-7,125.4711685,125.4711685,99.3960113525391,99.3960113525391,56.9713395096983,20.6393389651078,21.770052,0,0,0,40,4374,122.59975,99.3960113525391,,,,,,,,,,,,,0,,,,0,,,,,,125.4711685,,,,
,30913724.235,121.9556046,99.3960113525391,1.94039056881086E-5,3.30225780106912E-7,1,0.999253354069792,40.0298881530762,2.00787106903188,15.4699999839067,0.000221735848645048,3.85863583737091E-5,0.25,-1.72206925413222E-8,1.95096125003294E-5,2.73265678275914E-8,121.9556046,121.9556046,99.3960113525391,99.3960113525391,57.5841362687753,20.6283048064939,22.149702,0,0,0,40,4374,119.1528,99.3960113525391,,,,,,,,,,,,,0,,,,0.00245,,,,,,121.9556046,,,,
,30913863.225,118.4968491,99.3960113525391,1.93720310468081E-5,3.37664265966341E-7,1,0.999253354069792,40.0298881530762,2.00785036396196,15.4699999839067,0.000221967877673233,3.516205601565E-5,0.25,-3.13691721295739E-7,1.94791444329048E-5,-2.68602187030215E-7,118.4968491,118.4968491,99.3960113525391,99.3960113525391,57.2370932062368,20.6348064492736,22.149702,0,0,0,40,4374,115.70285,99.3960113525391,,,,,,,,,,,,,0,,,,0,,,,,,118.4968491,,,,
,30914002.425,114.9715462,99.3960113525391,1.91924926692693E-5,3.76611184213159E-7,1,0.999253354069792,40.0298881530762,2.00766098250327,15.4699999839067,0.000219553138697304,3.68128329953245E-5,0.25,-1.40050052560486E-7,1.92989455253668E-5,-9.20014240275825E-8,114.9394684,115.003624,99.3960113525391,99.3960113525391,57.4575124486599,20.6330809919069,21.3904,0,0,0,40,4374,112.2462,99.3960113525391,,,,,,,,,,,,,0,,,,0.00245,,,,,,114.9715462,,,,
,30914119.105,111.99366,99.3960113525391,1.90677716065651E-5,3.3054884242113E-7,1,0.999253354069792,40.0298881530762,1.99543646226015,15.54000005126,0.000216466370587293,3.86338462580708E-5,0.25,5.86535878661356E-8,1.91734979042652E-5,1.09711856073026E-7,111.99366,111.99366,99.3960113525391,99.3960113525391,57.1362631272561,20.6219465399772,21.3904,0,0,0,40,4374,109.3434,99.3960113525391,,,,,,,,,,,,,0,,,,0,,,,,,111.99366,,,,
,30914259.68,108.4663391,99.3960113525391,1.92179520811467E-5,3.28236647362815E-7,1,0.999253354069792,40.0298881530762,1.99540675107979,15.54000005126,0.000218716932669027,3.5834053014546E-5,0.25,-2.17108499565037E-7,1.93256407755545E-5,-1.642460559785E-7,108.4663391,108.4663391,99.3960113525391,99.3960113525391,56.8353361473522,20.6334867804607,21.770052,0,0,0,40,4374,105.86985,99.3960113525391,,,,,,,,,,,,,0,,,,0,,,,,,108.4663391,,,,
,30914398.11,104.987648,99.3960113525391,1.86852443459909E-5,3.24793026772058E-7,1,0.999253354069792,40.0298881530762,1.99529996948243,15.54000005126,0.000212223315018794,3.72407704760225E-5,0.25,-2.74660125388148E-9,1.87894678933285E-5,5.29319093999827E-8,104.987648,104.987648,99.3960113525391,99.3960113525391,57.545836471333,20.6342902186009,21.770052,0,0,0,40,4374,102.4387,99.3960113525391,,,,,,,,,,,,,0,,,,0.0049,,,,,,104.987648,,,,
,30914536.42,101.47779085,99.3960113525391,1.9168888450046E-5,3.54360544091424E-7,1,0.999253354069792,40.0298881530762,1.98392351704349,15.6100001186132,0.000217100536781079,3.47462414969199E-5,0.25,-2.94096002952993E-7,1.92765554877833E-5,-2.35042716198663E-7,101.4373703,101.5182114,99.3960113525391,99.3960113525391,56.8994296859291,20.6283937114745,21.3904,0,0,0,40,4374,98.99555,99.3960113525391,,,,,,,,,,,,,0,,,,0,,,,,,101.47779085,,,,
,30914677.545,97.91225815,99.3960113525391,1.9275466073308E-5,3.01170381002887E-7,1,0.999253354069792,40.0298881530762,1.98379607692501,15.6100001186132,0.000217596457886998,3.8870511054682E-5,0.25,4.86140656870917E-8,1.93820931772987E-5,1.13924421400578E-7,97.8686829,97.9558334,99.3960113525391,99.3960113525391,57.1604936113522,20.6338022109278,20.631098,0,0,0,40,4374,95.51055,99.3960113525391,,,,,,,,,,,,,0,,,,0.00245,,,,,,97.91225815,,,,
,30914814.35,94.4648895,99.3960113525391,1.931346052584E-5,3.4213470919422E-7,1,0.999253354069792,40.0298881530762,1.98385827191731,15.6100001186132,0.00021836120527261,3.70169176738553E-5,0.25,-1.26467929585743E-7,1.94199518126369E-5,-5.76464430108591E-8,94.4648895,94.4648895,99.3960113525391,99.3960113525391,57.4184310226984,20.6350259780215,21.3904,0,0,0,40,4374,92.1171,99.3960113525391,,,,,,,,,,,,,0,,,,-0.0049,,,,,,94.4648895,,,,
,30914953.49,90.9277267,99.3960113525391,1.94789403017603E-5,3.69090363620987E-7,1,0.999253354069792,40.0298881530762,2.00818454888573,15.6800001859665,0.000222292930371706,4.059738458609E-5,0.25,1.15195863413733E-7,1.9583928494225E-5,1.90868750525601E-7,90.9277267,90.9277267,99.3960113525391,99.3960113525391,57.2073913225061,20.6189582036632,21.01075,0,0,0,40,4374,88.6743,99.3960113525391,,,,,,,,,,,,,0,,,,0,,,,,,90.9277267,,,,
,30915091.775,87.433876,99.3960113525391,1.93083449473388E-5,3.54153465966976E-7,1,0.999253354069792,40.0298881530762,1.99545913100038,15.6800001859665,0.000219081160119379,3.9474788088635E-5,0.25,6.30844782782481E-8,1.94104423706998E-5,1.43195699588872E-7,87.433876,87.433876,99.3960113525391,99.3960113525391,57.352774227083,20.6216741733912,20.631098,0,0,0,40,4374,85.26125,99.3960113525391,,,,,,,,,,,,,0,,,,0,,,,,,87.433876,,,,
,30915229.595,83.9418564,99.3960113525391,1.95902203903168E-5,3.42579240026093E-7,1,0.999253354069792,40.0298881530762,1.99551285326899,15.6800001859665,0.000222591373751407,3.81265001460785E-5,0.25,-1.11108451501133E-7,1.96915659241982E-5,-2.4711694471014E-8,83.9418564,83.9418564,99.3960113525391,99.3960113525391,57.383257739333,20.624043190783,21.01075,0,0,0,40,4374,81.8569,99.3960113525391,,,,,,,,,,,,,0,,,,0.00245,,,,,,83.9418564,,,,
,30915365.22,80.4598846,99.3960113525391,1.92588737922317E-5,3.30120179349444E-7,1,0.999253354069792,40.0298881530762,1.99572417139619,15.7500002533197,0.000218940644340795,3.67181938046434E-5,0.25,-1.82556103054545E-7,1.93550367034966E-5,-9.15758724472521E-8,80.4598846,80.4598846,99.3960113525391,99.3960113525391,57.4168677656599,20.6225571113276,20.631098,0,0,0,40,4374,78.518,99.3960113525391,,,,,,,,,,,,,0,,,,0,,,,,,80.4598846,,,,
,30915503.845,76.9871292,99.3960113525391,1.93009411149292E-5,2.90659117499319E-7,1,0.999253354069792,40.0298881530762,1.99571255762369,15.7500002533197,0.000219471039644001,3.61620889533881E-5,0.25,-2.45283211781757E-7,1.93924686454827E-5,-1.47219530881146E-7,76.9871292,76.9871292,99.3960113525391,99.3960113525391,57.2769562607176,20.6294824762574,20.631098,0,0,0,40,4374,75.1021,99.3960113525391,,,,,,,,,,,,,0,,,,0.00245,,,,,,76.9871292,,,,
,30915640.195,73.4702454,99.3960113525391,1.94660887337966E-5,3.82869836123113E-7,1,0.999253354069792,40.0298881530762,1.99566634127947,15.760000795126,0.000220975677572633,3.81080517369904E-5,0.25,-1.0951427485631E-7,1.95510280261031E-5,-2.33805520730428E-9,73.4702454,73.4702454,99.3960113525391,99.3960113525391,57.1925403806407,20.6312034444217,20.631098,0,0,0,40,4374,71.7368,99.3960113525391,,,,,,,,,,,,,0,,,,-0.00245,,,,,,73.4702454,,,,
,30915780.315,69.91934965,99.3960113525391,1.96167423442831E-5,3.64365738226249E-7,1,0.999253354069792,40.0298881530762,1.99556472806052,15.820000320673,0.000222884568056196,3.66591100206281E-5,0.25,-2.70738409953667E-7,1.96945105458431E-5,-1.55141266605932E-7,69.8930969,69.9456024,99.3960113525391,99.3960113525391,57.444224763833,20.6375482950252,20.251448,0,0,0,40,4374,68.3026,99.3960113525391,,,,,,,,,,,,,0,,,,0,,,,,,69.91934965,,,,
,30915915.59,66.4943771,99.3960113525391,1.94718780575494E-5,3.50789154130721E-7,1,0.999253354069792,40.0298881530762,1.99530183792209,15.820000320673,0.000220915838073122,3.73493941443282E-5,0.25,-1.89693909321646E-7,1.95380438638012E-5,-6.66453898612804E-8,66.4943771,66.4943771,99.3960113525391,99.3960113525391,57.075296102756,20.6473965492985,19.871798,0,0,0,40,4374,64.9795,99.3960113525391,,,,,,,,,,,,,0,,,,0,,,,,,66.4943771,,,,
,30916053.59,62.992981,99.3960113525391,1.92798460756686E-5,3.26784687383555E-7,1,0.999253354069792,40.0298881530762,1.99499926129021,15.820000320673,0.000218515911543643,3.71848210909525E-5,0.25,-1.74778020513578E-7,1.93321666478423E-5,-4.52029792135173E-8,62.992981,62.992981,99.3960113525391,99.3960113525391,56.8830154870253,20.6426660098913,19.112494,0,0,0,40,4374,61.5853,99.3960113525391,,,,,,,,,,,,,0,,,,-0.0049,,,,,,62.992981,,,,
,30916171.545,59.9459152,99.3960113525391,1.94289391614861E-5,3.39518340578821E-7,1,0.999253354069792,40.0298881530762,1.98339763919249,15.87999984622,0.000218726370898854,3.7836558825952E-5,0.25,-1.287607848032E-7,1.94680452366273E-5,7.73279769086717E-9,59.9459152,59.9459152,99.3960113525391,99.3960113525391,57.8037738826792,20.6438659380678,19.112494,0,0,0,40,4374,58.6912,99.3960113525391,,,,,,,,,,,,,0,,,,0,,,,,,59.9459152,,,,
,30916307.35,56.4701004,99.3960113525391,1.95878741926226E-5,3.68510110267619E-7,1,0.999253354069792,40.0298881530762,1.98358537275979,15.87999984622,0.000220296148972688,3.83459239644625E-5,0.25,-1.14434068700261E-7,1.96095394913477E-5,2.83392681707119E-8,56.4701004,56.4701004,99.3960113525391,99.3960113525391,57.383257739333,20.6510111384806,18.732843,0,0,0,40,4374,55.35785,99.3960113525391,,,,,,,,,,,,,0,,,,0,,,,,,56.4701004,,,,
,30916445.09,52.9969864,99.3960113525391,1.92396347923316E-5,3.48642809744842E-7,1,0.999253354069792,40.0298881530762,1.98336619783873,15.87999984622,0.000216662335708388,3.47169950974541E-5,0.25,-3.74026979935555E-7,1.92434209534259E-5,-2.31097562880977E-7,52.9969864,52.9969864,99.3960113525391,99.3960113525391,57.342613056333,20.6531159292488,19.112494,0,0,0,40,4374,51.9774,99.3960113525391,,,,,,,,,,,,,0,,,,0,,,,,,52.9969864,,,,
,30916564.845,49.9417953,99.3960113525391,1.95286521386249E-5,3.45375853328047E-7,1,0.999253354069792,40.0298881530762,2.00747202837549,15.939999371767,0.000221695177322242,3.87586007174778E-5,0.25,-1.02379071521469E-7,1.95123758325533E-5,4.26472392040541E-8,49.9417953,49.9417953,99.3960113525391,99.3960113525391,57.187068981006,20.645480826238,18.732843,0,0,0,40,4370,49.01945,99.3960113525391,,,,,,,,,,,,,0,,,,0,,,,,,49.9417953,,,,
,30916700.46,46.4480209,99.3960113525391,1.97592112759452E-5,3.37288401158942E-7,1,0.999253354069792,40.0298881530762,2.00745945036996,15.939999371767,0.000224242532890424,3.82726462594595E-5,0.25,-1.80338658295213E-7,1.9722966238612E-5,-3.64305209922112E-8,46.4480209,46.4480209,99.3960113525391,99.3960113525391,56.7774956369291,20.6536552885634,18.353191,0,0,0,40,4370,45.6933,99.3960113525391,,,,,,,,,,,,,0,,,,-0.0049,,,,,,46.4480209,,,,
,30916837.09,42.9904175,99.3960113525391,1.90991474964976E-5,3.68441131090031E-7,1,0.999253354069792,40.0298881530762,2.00766901438288,15.939999371767,0.000216386384389294,3.79418473660619E-5,0.25,-8.22172365490413E-8,1.90449852446113E-5,5.11366449459522E-8,42.9556961,43.0251389,99.3960113525391,99.3960113525391,57.2183341217753,20.6554874803391,17.593889,0,0,0,40,4370,42.3366,99.3960113525391,,,,,,,,,,,,,0,,,,0.0049,,,,,,42.9904175,,,,
,30916977.095,39.4534225,99.3960113525391,1.94501398729446E-5,2.80725735286176E-7,1,0.999253354069792,40.0298881530762,2.0078586412421,15.990000218153,0.000220239074819139,3.83416277149862E-5,0.25,-9.95903909587053E-8,1.93782639938517E-5,2.84865501858969E-8,39.4534225,39.4534225,99.3960113525391,99.3960113525391,56.7423223535637,20.652097060629,17.593889,0,0,0,40,4370,38.87895,99.3960113525391,,,,,,,,,,,,,0,,,,0.00245,,,,,,39.4534225,,,,
,30917116.01,35.9449883,99.3960113525391,1.97345340721061E-5,3.22921628886823E-7,1,0.999253354069792,40.0298881530762,2.00804468806465,15.990000218153,0.000223663695471438,3.69743650899854E-5,0.25,-2.60859309220048E-7,1.96489064556748E-5,-1.38778801051922E-7,35.9449883,35.9449883,99.3960113525391,99.3960113525391,57.1440794124484,20.6490530026248,16.454937,0,0,0,40,4370,35.4675,99.3960113525391,,,,,,,,,,,,,0,,,,0,,,,,,35.9449883,,,,
,30917254.01,32.4040031,99.3960113525391,1.97280358886441E-5,3.21265375788076E-7,1,0.999253354069792,40.0298881530762,2.00804218671728,15.990000218153,0.000223499404444856,3.6772904174373E-5,0.25,-2.67443819985618E-7,1.96319275027164E-5,-1.53564745820342E-7,32.4040031,32.4040031,99.3960113525391,99.3960113525391,56.8595666314483,20.6440692261565,16.075285,0,0,0,40,4370,32.0394,99.3960113525391,,,,,,,,,,,,,0,,,,0.00245,,,,,,32.4040031,,,,
,30917392.975,28.9494724,99.3960113525391,1.96405740572825E-5,2.92196493031674E-7,1,0.999253354069792,40.0298881530762,2.00799386091667,16.0199999809265,0.000222280725063987,3.73610584235802E-5,0.25,-1.91333078848973E-7,1.95369537855051E-5,-8.53665399190613E-8,28.9494724,28.9494724,99.3960113525391,99.3960113525391,56.9049010855637,20.6516188250788,16.075285,0,0,0,40,4370,28.5975,99.3960113525391,,,,,,,,,,,,,0,,,,-0.00245,,,,,,28.9494724,,,,
,30917528.63,25.4652061,99.3960113525391,1.93374284341645E-5,3.49088027044586E-7,1,0.999253354069792,40.0298881530762,2.00807568510203,16.0199999809265,0.000218373488512727,3.91985068968145E-5,0.25,3.11938831794294E-8,1.92295531712347E-5,1.29170594546405E-7,25.4652061,25.4652061,99.3960113525391,99.3960113525391,56.9306948266983,20.6449467616723,16.075285,0,0,0,40,4370,25.236,99.3960113525391,,,,,,,,,,,,,0,,,,-0.0049,,,,,,25.4652061,,,,
,30917667.5,21.9713802,99.3960113525391,1.9587004464813E-5,3.14640978327124E-7,1,0.999253354069792,40.0298881530762,2.00800938266405,16.0199999809265,0.000221774369843736,3.62022378084345E-5,0.25,-2.74433665013661E-7,1.94764777433489E-5,-1.7688245760931E-7,21.9713802,21.9713802,99.3960113525391,99.3960113525391,56.9189703989099,20.6501705481002,14.936333,0,0,0,40,4370,21.79435,99.3960113525391,,,,,,,,,,,,,0,,,,-0.00245,,,,,,21.9713802,,,,
,30917806.095,18.4871521,99.3960113525391,1.94487823308635E-5,3.09735677922058E-7,1,0.999253354069792,40.0298881530762,1.99546661565855,16.0700008273125,0.000218581381299,3.74412964277846E-5,0.25,-1.18637940231995E-7,1.93372736761689E-5,-2.41255530584799E-8,18.4871521,18.4871521,99.3960113525391,99.3960113525391,57.1964485232368,20.6436733003742,14.556682,0,0,0,40,4370,18.3402,99.3960113525391,,,,,,,,,,,,,0,,,,-0.00245,,,,,,18.4871521,,,,
,30917947.285,14.9595432,99.3960113525391,1.96298876954579E-5,3.60666459297361E-7,1,0.999253354069792,40.0298881530762,1.99567599812083,16.0700008273125,0.000220505404683657,3.85582397452545E-5,0.25,-5.16532003428953E-8,1.95172077797058E-5,4.33143996852025E-8,14.9595432,14.9595432,99.3960113525391,99.3960113525391,57.2550706621791,20.646611122974,13.797379,0,0,0,40,4370,14.827,99.3960113525391,,,,,,,,,,,,,0,,,,0.0049,,,,,,14.9595432,,,,
,30918086.305,11.47391555,99.3960113525391,1.9451805314291E-5,3.39081362673778E-7,1,0.999253354069792,40.0298881530762,1.99598833847993,16.0700008273125,0.000218844925481519,3.64940943878434E-5,0.25,-2.04383128624541E-7,1.93410465377807E-5,-1.09396642494045E-7,11.4441013,11.5037298,99.3960113525391,99.3960113525391,57.8381655375254,20.6384169264418,13.417728,0,0,0,40,4370,11.3613,99.3960113525391,,,,,,,,,,,,,0,,,,0.00245,,,,,,11.47391555,,,,
,30918274.58,10.003397,99.3960113525391,1.96823513009587E-5,3.23060598265311E-7,1,0.999253354069792,40.0298881530762,1.98397864722517,16.0900000482798,0.00022055667886177,3.45193342255873E-5,0.25,-4.03417222648709E-7,1.95712783335896E-5,-3.0617625612747E-7,10.003397,10.003397,99.3960113525391,99.3960113525391,57.0409044479099,20.6471261535042,12.278775,0,0,0,40,4369,9.99425,99.3960113525391,,,,,,,,,,,,,0,,,,0.00245,,,,,,10.003397,,,,