File: data/doubleLayers/dl_5/ppms/data/DD205_6_HYST_100OE_50K.DAT
[Header]
; VSM Data File (default extension .dat)
; Copyright (c) 2003-2013, Quantum Design, Inc. All rights reserved.
TITLE,
FILEOPENTIME,30962005.33,12/25/2018,4:35 pm
BYAPP,VSM,2.0,2.0
INFO,PPMS VSM Option Release 1.4.10 Build 1,APPNAME
INFO,Quantum Design Linear Motor Servo Controller,MOTOR_MODULE_NAME
INFO,3101-100 M1,MOTOR_HW_VERSION
INFO,MMC1014,MOTOR_SERIAL_NUMBER
INFO,SRV No X-over 01.03.11,MOTOR_SOFTWARE_VERSION
INFO,Quantum Design VSM Detection Module,VSM_MODULE_NAME
INFO,3101-150 F0,VSM_HW_VERSION
INFO,VSM707,VSM_SERIAL_NUMBER
INFO,VSM No X-over 01.02.05 May 20 2008 13:51:47,VSM_SOFTWARE_VERSION
INFO,704,PREAMP_SERIAL_NUMBER
INFO,822,COIL_SERIAL_NUMBER
INFO,0,MOMENT_UNITS
INFO,CoFe2O4,SAMPLE_MATERIAL
INFO,AH11 DL,SAMPLE_COMMENT
INFO,30.27,SAMPLE_MASS
INFO,,SAMPLE_VOLUME
INFO,,SAMPLE_MOLECULAR_WEIGHT
INFO,,SAMPLE_SIZE
INFO,,SAMPLE_SHAPE
DATATYPE,COMMENT,1
DATATYPE,TIME,2
STARTUPAXIS,X,2
STARTUPAXIS,Y1,5
[Data]
Comment,Time Stamp (sec),Temperature (K),Magnetic Field (Oe),Moment (emu),M. Std. Err. (emu),Transport Action,Averaging Time (sec),Frequency (Hz),Peak Amplitude (mm),Center Position (mm),Coil Signal' (mV),Coil Signal" (mV),Range (mV),M. Quad. Signal (emu),M. Raw' (emu),M. Raw" (emu),Min. Temperature (K),Max. Temperature (K),Min. Field (Oe),Max. Field (Oe),Mass (grams),Motor Lag (deg),Pressure (Torr),VSM Status (code),Motor Status (code),Measure Status (code),Measure Count,PPMS Status (code),System Temp. (K),System Field (Oe),Sample Position (deg),Bridge 1 Resistance (ohms),Bridge 1 Excitation (에),Bridge 2 Resistance (ohms),Bridge 2 Excitation (에),Bridge 3 Resistance (ohms),Bridge 3 Excitation (에),Bridge 4 Resistance (ohms),Bridge 4 Excitation (에),Signal 1 Vin (V),Signal 2 Vin (V),Digital Inputs (code),Drive 1 Iout (mA),Drive 1 Ipower (W),Drive 2 Iout (mA),Drive 2 Ipower (W),Pressure (),Map 20 (),Map 21 (),Map 22 (),Map 23 (),Map 24 (),Map 25 (),Map 26 (),Map 27 (),Map 28 (),Map 29 ()
,30962020.34,49.9997597,-0.137013956904411,,,2,,,,16.2200000751018,,,,,,,49.9997597,49.9997597,-0.137013956904411,-0.137013956904411,,,17.214239,,,,-99999999,4369,50.0374,-0.137013956904411,,,,,,,,,,,,,,,,,,,,,,,49.9997597,,,,
,30962171.07,50.0011177,4551.27856445313,6.06440712055242E-5,3.76783902473395E-7,1,0.999253354069792,40.0298881530762,1.98378192854479,16.2099990993738,0.000681051834511176,0.000118987973299881,0.25,-3.25746774232489E-7,6.06242814742255E-5,1.25663163958934E-7,50.0011177,50.0011177,4541.09375,4561.46337890625,56.3061736398329,20.6304500161844,17.214239,0,0,0,40,4449,50.0367,4551.27856445313,,,,,,,,,,,,,0,,,,0,,,,,,50.0011177,,,,
,30962264.575,50.0008163,9222.66162109375,4.66558044009463E-5,3.87287087068747E-7,1,0.999253354069792,40.0298881530762,1.98383268694946,16.2099990993738,0.000524028978806666,9.19168153365997E-5,0.25,-2.19092531679287E-7,4.66510550973904E-5,1.28022149392886E-7,50.0008163,50.0008163,9217.6318359375,9227.69140625,56.7290346687368,20.6385343988477,16.834587,0,0,0,40,4449,50.0344,9222.66162109375,,,,,,,,,,,,,0,,,,0,,,,,,50.0008163,,,,
,30962360.395,50.0000992,14012.6103515625,2.96766179140738E-5,4.52082818337021E-7,1,0.999253354069792,40.0298881530762,1.98393801987263,16.2099990993738,0.000335492651879694,4.70036211221133E-5,0.25,-1.16164913011381E-6,2.96887219226386E-5,-9.41335634730698E-7,50.0000992,50.0000992,14004.703125,14020.517578125,56.9549253107945,20.6371072274323,17.593889,0,0,0,40,4449,50.0343,14012.6103515625,,,,,,,,,,,,,0,,,,0,,,,,,50.0000992,,,,
,30962455.61,50.0006714,18770.0537109375,1.6920875944752E-5,5.66650134033958E-7,1,0.999253354069792,40.0298881530762,1.98385965734065,16.2099990993738,0.000191923174531983,2.3525317502186E-5,0.25,-9.5417032137648E-7,1.6934321844021E-5,-8.29175909718018E-7,50.0003281,50.0010147,18762.634765625,18777.47265625,56.8408075469868,20.6369883328295,17.214239,0,0,0,40,4449,50.03375,18770.0537109375,,,,,,,,,,,,,0,,,,-0.00245,,,,,,50.0006714,,,,
,30962549.805,50.0018158,23480.4169921875,3.47294510717291E-6,6.34960856237633E-7,1,0.999253354069792,40.0298881530762,1.98383528165541,16.2099990993738,4.06888705244817E-5,-2.31710667377439E-6,0.25,-8.32067669610004E-7,3.48129390223914E-6,-8.06970094677033E-7,50.0018158,50.0018158,23475.326171875,23485.5078125,57.2644502044099,20.6368285448004,17.593889,0,0,0,40,4449,50.0317,23480.4169921875,,,,,,,,,,,,,0,,,,0,,,,,,50.0018158,,,,
,30962645.67,50.0016136,28270.6337890625,-1.53279042733434E-5,7.5997253025602E-7,1,0.999253354069792,40.0298881530762,1.98381727869874,16.2099990993738,-0.000168804536740883,-4.98379838352004E-5,0.25,-1.67519205604025E-6,-1.53293917878585E-5,-1.78920216975577E-6,50.0016136,50.0016136,28263.091796875,28278.17578125,56.9815006804483,20.6414650167633,17.593889,0,0,0,40,4449,50.0323,28270.6337890625,,,,,,,,,,,,,0,,,,0,,,,,,50.0016136,,,,
,30962739.665,50.0012474,32968.263671875,-3.06345350492836E-5,8.33166552307792E-7,1,0.999253354069792,40.0298881530762,1.98393077605292,16.2099990993738,-0.000341455344368673,-7.75665783990002E-5,0.25,-1.38550562939669E-6,-3.06597610907017E-5,-1.61051399246833E-6,50.0012474,50.0012474,32960.84375,32975.68359375,57.5200427301984,20.6414939773773,17.593889,0,0,0,40,4449,50.0309,32968.263671875,,,,,,,,,,,,,0,,,,0.0049,,,,,,50.0012474,,,,
,30962836.76,50.0022621,37820.5390625,-4.71538760933967E-5,8.18392765649093E-7,1,0.999253354069792,40.0298881530762,1.98393443759778,16.2099990993738,-0.000525630275584202,-0.000119913802306445,0.25,-2.17891741464106E-6,-4.72045996796855E-5,-2.52318846961458E-6,50.0022621,50.0022621,37818.01171875,37823.06640625,57.065134932006,20.6426829068213,17.214239,0,0,0,40,4449,50.0286,37820.5390625,,,,,,,,,,,,,0,,,,-0.0049,,,,,,50.0022621,,,,
,30962931.13,50.0009499,42538.50390625,-6.38686084752986E-5,8.88846945575627E-7,1,0.999253354069792,40.0298881530762,1.98404651007413,16.2099990993738,-0.000714498002799545,-0.00014950379148197,0.25,-1.80238288653914E-6,-6.39612898082833E-5,-2.26349253616132E-6,50.0009499,50.0009499,42526.203125,42550.8046875,56.966649738583,20.6358831530488,17.214239,0,0,0,40,4449,50.028,42538.50390625,,,,,,,,,,,,,0,,,,0,,,,,,50.0009499,,,,
,30963027.155,50.0018044,47336.2265625,-8.15740839356355E-5,7.2927558525983E-7,1,0.999253354069792,40.0298881530762,1.98430613105386,16.2099990993738,-0.000911740628127568,-0.000197481107957101,0.25,-2.88245009446253E-6,-8.17080633380913E-5,-3.46727720548866E-6,50.0018044,50.0018044,47328.85546875,47343.59765625,57.0971817012945,20.635044410146,17.214239,0,0,0,40,4449,50.0267,47336.2265625,,,,,,,,,,,,,0,,,,0,,,,,,50.0018044,,,,
,30963125.685,50.0021706,52261.330078125,-9.91895112325076E-5,1.06891999012412E-6,1,0.999253354069792,40.0298881530762,1.9842632990451,16.2099990993738,-0.00111225045410216,-0.000221365793892202,0.25,-1.84076325935471E-6,-9.9387940183945E-5,-2.54136188432133E-6,50.0021706,50.0021706,52256.3359375,52266.32421875,56.8970848003714,20.6319552436033,17.214239,0,0,0,40,4449,50.02465,52261.330078125,,,,,,,,,,,,,0,,,,0.00245,,,,,,50.0021706,,,,
,30963220.395,50.0013657,56993.556640625,-0.000117465494354539,1.2230021898905E-6,1,0.999253354069792,40.0298881530762,1.98434478897751,16.2099990993738,-0.00131699322699416,-0.000265197061840698,0.25,-2.45401833543583E-6,-0.000117724581973273,-3.27532823586739E-6,50.0013657,50.0013657,56988.5859375,56998.52734375,57.1175040427945,20.6291881013316,17.214239,0,0,0,40,4449,50.0245,56993.556640625,,,,,,,,,,,,,0,,,,-0.00245,,,,,,50.0013657,,,,
,30963315.83,50.0014305,61766.39453125,-0.00013085127185434,1.05660113001223E-6,1,0.999253354069792,40.0298881530762,1.98439704589213,16.2099990993738,-0.00146328154764836,-0.00031853229690003,0.25,-4.79219577705283E-6,-0.000131153814562484,-5.70172920963493E-6,50.0014305,50.0014305,61756.25390625,61776.53515625,57.1245386994676,20.6319356247312,17.214239,0,0,0,40,4449,50.0223,61766.39453125,,,,,,,,,,,,,0,,,,0.0049,,,,,,50.0014305,,,,
,30963414.4,50.0007973,66692.0859375,-0.000148445454680837,1.14212888028782E-6,1,0.999253354069792,40.0298881530762,1.98438407879447,16.2099990993738,-0.00166270898555816,-0.000348441752152495,0.25,-4.29634530770889E-6,-0.000148828112888484,-5.31241929499414E-6,50.0007973,50.0007973,66689.6328125,66694.5390625,57.3566823696791,20.6283914225685,17.593889,0,0,0,40,4449,50.02225,66692.0859375,,,,,,,,,,,,,0,,,,0.0049,,,,,,50.0007973,,,,
,30963510.22,50.0015297,71479.94140625,-0.000169106919478073,9.73751260761941E-7,1,0.999253354069792,40.0298881530762,1.98449444695847,16.2099990993738,-0.00190099145254087,-0.000361456757943295,0.25,-1.75080994312365E-6,-0.000169597219343427,-2.88423546242414E-6,50.0015297,50.0015297,71472.3671875,71487.515625,57.3965454241599,20.6314634086732,17.593889,0,0,0,40,4449,50.0194,71479.94140625,,,,,,,,,,,,,0,,,,-0.0049,,,,,,50.0015297,,,,
,30963605.415,50.001133,76240.625,-0.000187858452555841,8.42092183141303E-7,1,0.999253354069792,40.0298881530762,1.98442253585766,16.2099990993738,-0.00210981067535277,-0.000414375672509538,0.25,-3.0973486355757E-6,-0.000188430559633912,-4.34262693806822E-6,50.001133,50.001133,76235.5,76245.75,57.1589303543137,20.628488314608,17.593889,0,0,0,40,4449,50.02,76240.625,,,,,,,,,,,,,0,,,,0,,,,,,50.001133,,,,
,30963704.485,50.0005455,81191.6328125,-0.000205373995361016,1.31295715174451E-6,1,0.999253354069792,40.0298881530762,1.98439163725439,16.2099990993738,-0.00231120429802447,-0.000429152753629249,0.25,-1.28244083850626E-6,-0.00020605103248435,-2.61682649150512E-6,50.0005455,50.0005455,81184.2109375,81199.0546875,57.0354330482753,20.630817517605,17.973541,0,0,0,40,4449,50.01665,81191.6328125,,,,,,,,,,,,,0,,,,0,,,,,,50.0005455,,,,
,30963799.43,50.00100515,85936.98046875,-0.000223165342117968,1.19736078146629E-6,1,0.999253354069792,40.0298881530762,1.9843960212453,16.2099990993738,-0.00251171517361882,-0.000467139649594325,0.25,-1.48037310894782E-6,-0.000223937986673749,-2.90909345536921E-6,50.0008392,50.0011711,85931.921875,85942.0390625,57.3707516830253,20.6310365027941,17.593889,0,0,0,40,4449,50.01695,85936.98046875,,,,,,,,,,,,,0,,,,-0.0049,,,,,,50.00100515,,,,
,30963911.08,49.9999313,89471.3125,-0.000238072053275126,1.53947588267558E-6,1,0.999253354069792,40.0298881530762,1.98429018561313,16.2099990993738,-0.0026784824628779,-0.000505018002114749,0.25,-2.18611438518962E-6,-0.00023892099861003,-3.69522702351827E-6,49.9999313,49.9999313,89461.4140625,89481.2109375,56.8189219484483,20.6283803424964,17.593889,0,0,0,40,4449,50.01555,89471.3125,,,,,,,,,,,,,0,,,,-0.0049,,,,,,49.9999313,,,,
,30964002.315,49.9992943,84914.61328125,-0.000217413588657028,1.07687396945106E-6,1,0.999253354069792,40.0298881530762,1.98436855745342,16.2099990993738,-0.00244467958149468,-0.000467251712941935,0.25,-2.51800545132809E-6,-0.000218151688932563,-3.91819229992739E-6,49.9992943,49.9992943,84904.6015625,84924.625,57.3488660844868,20.629985282029,17.593889,0,0,0,40,4449,50.01585,84914.61328125,,,,,,,,,,,,,0,,,,-0.0049,,,,,,49.9992943,,,,
,30964099.22,49.9990349,80067.73046875,-0.00020172111801246,1.18246550996714E-6,1,0.999253354069792,40.0298881530762,1.98452960556409,16.2099990993738,-0.00226860065714023,-0.000430199754495914,0.25,-2.02444216401761E-6,-0.000202372888609904,-3.34218595613116E-6,49.9990349,49.9990349,80055.140625,80080.3203125,57.4020168237945,20.6284646678245,17.593889,0,0,0,40,4449,50.01735,80067.73046875,,,,,,,,,,,,,0,,,,-0.00245,,,,,,49.9990349,,,,
,30964196.825,50.0003548,75188.53515625,-0.000180325701626578,8.24504820185401E-7,1,0.999253354069792,40.0298881530762,1.98455723116986,16.2099990993738,-0.00202590367249885,-0.000394183400658904,0.25,-2.65089951739813E-6,-0.000180869617772787,-3.84896490916844E-6,50.0003548,50.0003548,75180.890625,75196.1796875,57.3144744296407,20.6303488443248,17.593889,0,0,0,40,4449,50.01725,75188.53515625,,,,,,,,,,,,,0,,,,-0.0049,,,,,,50.0003548,,,,
,30964294.64,50.0007133,70300.85546875,-0.00016132061254881,8.39225996282386E-7,1,0.999253354069792,40.0298881530762,1.98465775328381,16.2099990993738,-0.00181621213643691,-0.000329818615639931,0.25,-3.34016189074532E-7,-0.000161789570309464,-1.4150309321434E-6,50.0007133,50.0007133,70293.234375,70308.4765625,57.0995265868522,20.6283480142444,17.973541,0,0,0,40,4449,50.01715,70300.85546875,,,,,,,,,,,,,0,,,,-0.0049,,,,,,50.0007133,,,,
,30964391.13,50.000412,65475.48828125,-0.000142194753594399,9.42119663643065E-7,1,0.999253354069792,40.0298881530762,1.98461924172338,16.2099990993738,-0.00159579056525383,-0.00031709712595225,0.25,-2.62954818612154E-6,-0.000142563922626546,-3.60192393492143E-6,50.000412,50.000412,65465.4609375,65485.515625,56.9009929429675,20.6304838790486,17.973541,0,0,0,40,4449,50.01725,65475.48828125,,,,,,,,,,,,,0,,,,0,,,,,,50.000412,,,,
,30964488.43,49.9991646,60611.923828125,-0.000124455844196808,1.08149982095165E-6,1,0.999253354069792,40.0298881530762,1.98472290066732,16.2099990993738,-0.00139603591453438,-0.000280024661605879,0.25,-2.51485124751711E-6,-0.000124751181525011,-3.3772262207037E-6,49.9991646,49.9991646,60606.93359375,60616.9140625,57.2034831799099,20.6284306282829,17.973541,0,0,0,40,4449,50.0188,60611.923828125,,,,,,,,,,,,,0,,,,0.0049,,,,,,49.9991646,,,,
,30964584.6,50.0002174,55804.146484375,-0.000106294188817489,9.76506861034965E-7,1,0.999253354069792,40.0298881530762,1.98457397003804,16.2099990993738,-0.00119319115593113,-0.000232294228446312,0.25,-1.53462341381215E-6,-0.000106527428272241,-2.27839053590635E-6,50.0002174,50.0002174,55799.3828125,55808.91015625,56.6735390438714,20.6290048334977,17.973541,0,0,0,40,4449,50.0162,55804.146484375,,,,,,,,,,,,,0,,,,0,,,,,,50.0002174,,,,
,30964680.28,49.9992943,51024.12890625,-9.04346182217451E-5,1.01915388336071E-6,1,0.999253354069792,40.0298881530762,1.98447101379057,16.2099990993738,-0.0010139751579541,-0.000202634174013811,0.25,-1.7473961591751E-6,-9.06095823621366E-5,-2.38807507555367E-6,49.9992943,49.9992943,51016.453125,51031.8046875,56.8173586914099,20.6306920650387,17.593889,0,0,0,40,4449,50.01835,51024.12890625,,,,,,,,,,,,,0,,,,0,,,,,,49.9992943,,,,
,30964777.32,49.9996567,46174.30859375,-7.15284389809394E-5,9.50919824269254E-7,1,0.999253354069792,40.0298881530762,1.98452679009846,16.2099990993738,-0.000799522725318294,-0.000173040184600476,0.25,-2.51462044256164E-6,-7.16417381845038E-5,-3.02855793712254E-6,49.9996567,49.9996567,46164.2421875,46184.375,57.3957637956407,20.6311890652547,17.593889,0,0,0,40,4449,50.0181,46174.30859375,,,,,,,,,,,,,0,,,,0,,,,,,49.9996567,,,,
,30964873.905,50.0004387,41346.26171875,-5.36161808728941E-5,9.45449729970697E-7,1,0.999253354069792,40.0298881530762,1.98449305900591,16.2099990993738,-0.000596501365661017,-0.000144379913173591,0.25,-3.18883381679486E-6,-5.36785252586089E-5,-3.57941324961905E-6,50.0004387,50.0004387,41336.31640625,41356.20703125,57.1346998702176,20.6320797917333,17.593889,0,0,0,40,4449,50.0174,41346.26171875,,,,,,,,,,,,,0,,,,-0.00245,,,,,,50.0004387,,,,
,30964969.595,49.9995766,36563.986328125,-3.74056405324166E-5,9.69208346248216E-7,1,0.999253354069792,40.0298881530762,1.98450487229778,16.2099990993738,-0.000413975576224061,-0.00011222538289199,0.25,-3.24720719474264E-6,-3.74322681938958E-5,-3.52282915364183E-6,49.9995766,49.9995766,36559.09765625,36568.875,57.0690430746022,20.6324386615828,17.973541,0,0,0,40,4449,50.0168,36563.986328125,,,,,,,,,,,,,0,,,,0,,,,,,49.9995766,,,,
,30965061.665,49.9996586,31961.4609375,-2.08156814853775E-5,7.1758763696136E-7,1,0.999253354069792,40.0298881530762,1.98453289080989,16.2099990993738,-0.000229610061783748,-6.6361275162133E-5,0.25,-2.15501934958129E-6,-2.08227480412656E-5,-2.30942317182751E-6,49.9993935,49.9999237,31951.48046875,31971.44140625,57.1964485232368,20.6342744522549,17.593889,0,0,0,40,4449,50.0163,31961.4609375,,,,,,,,,,,,,0,,,,-0.00245,,,,,,49.9996586,,,,
,30965157.785,49.9993477,27156.3134765625,-4.78879613215002E-6,6.85654427125586E-7,1,0.999253354069792,40.0298881530762,1.98458674668807,16.2099990993738,-5.03568797771374E-5,-2.8884765046928E-5,0.25,-1.70769807099365E-6,-4.78024127239171E-6,-1.7443225911156E-6,49.9993477,49.9993477,27148.693359375,27163.93359375,57.3379232852176,20.6314107581279,17.214239,0,0,0,40,4449,50.01805,27156.3134765625,,,,,,,,,,,,,0,,,,0.00245,,,,,,49.9993477,,,,
,30965254.43,50.0006104,22325.7236328125,1.09948407045677E-5,5.78964987079968E-7,1,0.999253354069792,40.0298881530762,1.98466539285771,16.2099990993738,0.000124860337832322,1.48486574222086E-5,0.25,-6.59494393980381E-7,1.10059648529964E-5,-5.78645197387453E-7,50.0006104,50.0006104,22320.388671875,22331.05859375,56.9916618511983,20.6328505843662,17.593889,0,0,0,40,4449,50.0177,22325.7236328125,,,,,,,,,,,,,0,,,,0,,,,,,50.0006104,,,,
,30965351.4,49.9998627,17481.298828125,2.63663089917884E-5,5.13527433549154E-7,1,0.999253354069792,40.0298881530762,1.9846836408566,16.2099990993738,0.000298217878569967,4.18593499648952E-5,0.25,-1.02490522229778E-6,2.63818613480463E-5,-8.29707515256196E-7,49.9998627,49.9998627,17468.873046875,17493.724609375,57.1432977839291,20.6319057346915,17.973541,0,0,0,40,4449,50.018,17481.298828125,,,,,,,,,,,,,0,,,,0.00245,,,,,,49.9998627,,,,
,30965443.51,50.0007935,12876.3276367188,4.07563640302494E-5,3.99296267320079E-7,1,0.999253354069792,40.0298881530762,1.98452584602273,16.2099990993738,0.000458945836604095,7.51234622544636E-5,0.25,-6.55290986320812E-7,4.07633111312317E-5,-3.52420670969142E-7,50.0007935,50.0007935,12871.1875,12881.4677734375,57.2019199228714,20.6350332468752,17.593889,0,0,0,40,4449,50.0176,12876.3276367188,,,,,,,,,,,,,0,,,,0,,,,,,50.0007935,,,,
,30965538.43,50.0002899,8130.81567382813,5.47852105360738E-5,3.58775197915043E-7,1,0.999253354069792,40.0298881530762,1.9844145363413,16.2099990993738,0.000615364131956255,0.000108553810239521,0.25,-2.04130173199249E-7,5.47759041689183E-5,2.03543854801024E-7,50.0002632,50.0003166,8123.287109375,8138.34423828125,57.1823792098907,20.6333159126736,17.214239,0,0,0,40,4449,50.01815,8130.81567382813,,,,,,,,,,,,,0,,,,-0.00245,,,,,,50.0002899,,,,
,30965636.305,50.0004921,3237.99182128906,6.89579258195912E-5,3.5884127118687E-7,1,0.999253354069792,40.0298881530762,1.98460441101245,16.2099990993738,0.000774293459354095,0.000137463653906081,0.25,-1.81631332712938E-7,6.89295349412971E-5,3.31563708451584E-7,50.0004921,50.0004921,3230.59423828125,3245.38940429687,57.0792042453522,20.6344255056047,17.593889,0,0,0,40,4449,50.018,3237.99182128906,,,,,,,,,,,,,0,,,,-0.0049,,,,,,50.0004921,,,,
,30965735.555,49.9999161,-1716.88287353516,8.00826638472301E-5,3.80487226309706E-7,1,0.999253354069792,40.0298881530762,1.98468791078908,16.2099990993738,0.000897957753980611,0.000166452419488685,0.25,3.96450245676458E-7,8.00400761242527E-5,9.92057570437083E-7,49.9999161,49.9999161,-1719.27783203125,-1714.48791503906,57.2644502044099,20.6306899490999,17.973541,0,0,0,40,4449,50.0157,-1716.88287353516,,,,,,,,,,,,,0,,,,0,,,,,,49.9999161,,,,
,30965836.235,49.9990997,-6749.37548828125,8.87595708720563E-5,3.46835338720162E-7,1,0.999253354069792,40.0298881530762,1.98456482695478,16.2099990993738,0.000994900899831748,0.000187394122875661,0.25,6.95585906611997E-7,8.87307197283826E-5,1.3559022098914E-6,49.9990997,49.9990997,-6756.75927734375,-6741.99169921875,57.3082214014868,20.6371525202764,17.973541,0,0,0,40,4449,50.0183,-6749.37548828125,,,,,,,,,,,,,0,,,,0,,,,,,49.9990997,,,,
,30965933.625,50.0011253,-11617.7866210938,8.75706707951814E-5,3.77855814899322E-7,1,0.999253354069792,40.0298881530762,1.98469817069883,16.2099990993738,0.000982543585960359,0.000181278371827585,0.25,3.60681216080487E-7,8.75665367833138E-5,1.01178045973519E-6,50.0011253,50.0011253,-11620.23046875,-11615.3427734375,57.3965454241599,20.6350022212856,17.973541,0,0,0,40,4449,50.01655,-11617.7866210938,,,,,,,,,,,,,0,,,,-0.00245,,,,,,50.0011253,,,,
,30966030.705,50.001503,-16470.146484375,7.13830587218989E-5,5.48967941026404E-7,1,0.999253354069792,40.0298881530762,1.98461348495756,16.2099990993738,0.000800800084071911,0.000149442126271306,0.25,4.41352136395358E-7,7.13973185499635E-5,9.71091859656908E-7,50.001503,50.001503,-16477.666015625,-16462.626953125,57.4434431353138,20.6374159807913,17.973541,0,0,0,40,4449,50.0162,-16470.146484375,,,,,,,,,,,,,0,,,,-0.00245,,,,,,50.001503,,,,
,30966129.49,50.0005951,-21404.7958984375,4.65134603782252E-5,4.4945597807971E-7,1,0.999253354069792,40.0298881530762,1.98454210282884,16.2099990993738,0.000519423510119077,0.000111298613148749,0.25,1.52611704944216E-6,4.65262342635443E-5,1.87080582071777E-6,50.0005951,50.0005951,-21409.82421875,-21399.767578125,57.2605420618137,20.6373830566109,17.973541,0,0,0,40,4449,50.01555,-21404.7958984375,,,,,,,,,,,,,0,,,,0,,,,,,50.0005951,,,,
,30966228.42,50.0011139,-26352.162109375,3.26521319592502E-5,6.28943221073629E-7,1,0.999253354069792,40.0298881530762,1.98453376054354,16.2099990993738,0.000364927352751584,7.70563699701732E-5,0.25,9.75077240235256E-7,3.26707456177529E-5,1.21607779280301E-6,50.0011139,50.0011139,-26357.248046875,-26347.076171875,57.0807675023906,20.6371243839418,17.214239,0,0,0,40,4449,50.0149,-26352.162109375,,,,,,,,,,,,,0,,,,0,,,,,,50.0011139,,,,
,30966326.17,50.0014229,-31237.5908203125,3.33757255544799E-5,5.73146434093014E-7,1,0.999253354069792,40.0298881530762,1.98468751543568,16.2099990993738,0.000374367066720072,7.19867478274548E-5,0.25,3.92949721009951E-7,3.34080934994344E-5,6.37403741667143E-7,50.0013466,50.0014992,-31245.302734375,-31229.87890625,57.2277136640061,20.6361091116148,17.973541,0,0,0,40,4449,50.0135,-31237.5908203125,,,,,,,,,,,,,0,,,,0.0049,,,,,,50.0014229,,,,
,30966423.51,50.0018768,-36101.623046875,4.40105704452667E-5,6.84940513350012E-7,1,0.999253354069792,40.0298881530762,1.98504905391176,16.2099990993738,0.000495000496617214,8.8685588855101E-5,0.25,-3.78437646904241E-8,4.40687626769525E-5,2.815268264257E-7,50.0018768,50.0018768,-36106.62890625,-36096.6171875,57.4809613042369,20.6331039495963,17.973541,0,0,0,40,4449,50.0125,-36101.623046875,,,,,,,,,,,,,0,,,,0,,,,,,50.0018768,,,,
,30966521.735,50.0011711,-41011.7578125,5.81355678589915E-5,9.63885526471443E-7,1,0.999253354069792,40.0298881530762,1.98472361793649,16.2099990993738,0.000649913938118533,0.000139491424839696,0.25,1.93930786278316E-6,5.82130066400572E-5,2.36064285291277E-6,50.0011711,50.0011711,-41019.1640625,-41004.3515625,57.3168193151984,20.6345214937821,17.593889,0,0,0,40,4449,50.0118,-41011.7578125,,,,,,,,,,,,,0,,,,-0.00245,,,,,,50.0011711,,,,
,30966623.675,50.0000648,-46104.076171875,7.50161363481984E-5,9.72164488504207E-7,1,0.999253354069792,40.0298881530762,1.98495206081535,16.2099990993738,0.000842036086628262,0.000162829847103782,0.25,9.76482486380513E-7,7.51464247765141E-5,1.51253725134502E-6,50.0000648,50.0000648,-46111.34765625,-46096.8046875,57.5114448164869,20.6348181396438,17.214239,0,0,0,40,4449,50.01155,-46104.076171875,,,,,,,,,,,,,0,,,,-0.00245,,,,,,50.0000648,,,,
,30966725.005,50.0007591,-51168.68359375,9.33710647231554E-5,9.04655344061748E-7,1,0.999253354069792,40.0298881530762,1.98493099567876,16.2099990993738,0.0010497957117509,0.000194475435874798,0.25,4.90473532201994E-7,9.35614787945787E-5,1.14906213750016E-6,50.0007591,50.0007591,-51173.796875,-51163.5703125,57.2793011462753,20.6337013681934,17.973541,0,0,0,40,4449,50.0108,-51168.68359375,,,,,,,,,,,,,0,,,,0,,,,,,50.0007591,,,,
,30966821.205,50.000885,-55975.568359375,0.000111699655728039,7.42701421026686E-7,1,0.999253354069792,40.0298881530762,1.98483026458611,16.2099990993738,0.00125397907522592,0.000244438245346882,0.25,1.63953923609549E-6,0.00011194534539382,2.42091125464623E-6,50.000885,50.000885,-55985.625,-55965.51171875,57.6732419199676,20.6375798784654,17.593889,0,0,0,40,4449,50.0106,-55975.568359375,,,,,,,,,,,,,0,,,,-0.00245,,,,,,50.000885,,,,
,30966918.49,50.0013733,-60837.814453125,0.000130486096164416,1.06171806133476E-6,1,0.999253354069792,40.0298881530762,1.98478200432287,16.2099990993738,0.00146651558266399,0.000278108324397454,0.25,1.26084335170726E-6,0.000130806306628719,2.16110303389603E-6,50.0013542,50.0013924,-60842.99609375,-60832.6328125,57.4387533641984,20.6370344942822,17.593889,0,0,0,40,4449,50.0092,-60837.814453125,,,,,,,,,,,,,0,,,,-0.00245,,,,,,50.0013733,,,,
,30967015.235,50.0018959,-65675.42578125,0.000148755926150926,1.15942244245419E-6,1,0.999253354069792,40.0298881530762,1.98471242813801,16.2099990993738,0.00167195791338698,0.000318113019682705,0.25,1.54067580744117E-6,0.000149151366215672,2.55417698121861E-6,50.0018959,50.0018959,-65680.640625,-65670.2109375,57.3519925985638,20.639785943813,17.593889,0,0,0,40,4449,50.0067,-65675.42578125,,,,,,,,,,,,,0,,,,-0.0049,,,,,,50.0018959,,,,
,30967113.5,50.001606,-70584.75,0.000166777326960184,1.01591897142551E-6,1,0.999253354069792,40.0298881530762,1.9847635469785,16.2099990993738,0.0018779346699421,0.000340022149164795,0.25,2.59701475651313E-7,0.000167264362179473,1.37623594299605E-6,50.001545,50.001667,-70592.15625,-70577.34375,57.3746598256215,20.6372112603036,17.593889,0,0,0,40,4449,50.00575,-70584.75,,,,,,,,,,,,,0,,,,0.00245,,,,,,50.001606,,,,
,30967209.405,50.0011826,-75376.7890625,0.000187756398380903,1.24278195338307E-6,1,0.999253354069792,40.0298881530762,1.98488307222175,16.2099990993738,0.00211336975956751,0.000390188444454508,0.25,9.58423905343395E-7,0.000188335677534249,2.19970035447131E-6,50.0011826,50.0011826,-75384.296875,-75369.28125,57.6302523514099,20.636823759053,17.973541,0,0,0,40,4449,50.00505,-75376.7890625,,,,,,,,,,,,,0,,,,0,,,,,,50.0011826,,,,
,30967309.46,50.00118065,-80379.40234375,0.000205601694122317,1.16569496187689E-6,1,0.999253354069792,40.0298881530762,1.98500367737226,16.2099990993738,0.00231301351778626,0.000437349217625001,0.25,1.95531427071841E-6,0.000206268746206689,3.29693421147205E-6,50.0009766,50.0013847,-80386.84375,-80371.9609375,57.3973270526791,20.6348104531167,17.214239,0,0,0,40,4449,50.00495,-80379.40234375,,,,,,,,,,,,,0,,,,-0.00245,,,,,,50.00118065,,,,
,30967406.63,50.0000725,-85236.3671875,0.000221183055958824,1.34032808567823E-6,1,0.999253354069792,40.0298881530762,1.98512487001542,16.2099990993738,0.00249130671588242,0.000457042988026615,0.25,9.22829824872108E-7,0.000221946620019125,2.34032412713915E-6,50.0000725,50.0000725,-85238.890625,-85233.84375,57.3559007411599,20.6373040082991,17.214239,0,0,0,40,4449,50.00375,-85236.3671875,,,,,,,,,,,,,0,,,,0.00245,,,,,,50.0000725,,,,
,30967500.17,50.0014114,-89908.3984375,0.000244927647341567,1.11023110962996E-6,1,0.999253354069792,40.0298881530762,1.98483603742649,16.2099990993738,0.00275633663105667,0.000519907991911422,0.25,2.2692040227391E-6,0.000245804156018179,3.81984784815321E-6,50.0014114,50.0014114,-89920.8671875,-89895.9296875,57.1409528983714,20.6421908490413,17.593889,0,0,0,40,4449,50.00315,-89908.3984375,,,,,,,,,,,,,0,,,,0.00245,,,,,,50.0014114,,,,
,30967611.29,49.9984779,-85515.25390625,0.000227885478548668,1.08320862402001E-6,1,0.999253354069792,40.0298881530762,1.98475493459895,16.2099990993738,0.00256081443807308,0.000501812866088756,0.25,3.70272460627653E-6,0.000228656817957324,5.17146514989879E-6,49.9984779,49.9984779,-85525.171875,-85505.3359375,57.281646031833,20.6425065215522,17.214239,0,0,0,40,4449,50.004,-85515.25390625,,,,,,,,,,,,,0,,,,-0.00245,,,,,,49.9984779,,,,
,30967706.635,49.9993629,-80751.015625,0.000209293268953951,1.20154573829065E-6,1,0.999253354069792,40.0298881530762,1.98463280378022,16.2099990993738,0.00235701952005588,0.000429147303099247,0.25,5.73661780954996E-7,0.000209984318890725,1.93311654879577E-6,49.9993629,49.9993629,-80754.078125,-80747.953125,57.047939104583,20.6420014920872,17.593889,0,0,0,40,4449,50.00415,-80751.015625,,,,,,,,,,,,,0,,,,-0.00245,,,,,,49.9993629,,,,
,30967806.855,49.9994278,-75740.5078125,0.000190333222008403,9.30654151450868E-7,1,0.999253354069792,40.0298881530762,1.98485812860236,16.2099990993738,0.00213760822388817,0.000422141316340166,0.25,3.33375111070986E-6,0.000190907553575597,4.5980869138292E-6,49.9994278,49.9994278,-75750.765625,-75730.25,56.8673829166406,20.6420094554387,17.214239,0,0,0,40,4449,50.0051,-75740.5078125,,,,,,,,,,,,,0,,,,-0.00245,,,,,,49.9994278,,,,
,30967904.425,49.9991112,-70866.078125,0.000171269444820254,7.71231175206105E-7,1,0.999253354069792,40.0298881530762,1.98459947840418,16.2099990993738,0.00192067350224005,0.000392135455479401,0.25,4.0837127424422E-6,0.000171746021145992,5.24061030553252E-6,49.9991112,49.9991112,-70873.609375,-70858.546875,57.2417829773522,20.6426691811773,17.973541,0,0,0,40,4449,50.0056,-70866.078125,,,,,,,,,,,,,0,,,,-0.0049,,,,,,49.9991112,,,,
,30968000.93,49.9998894,-66043.89453125,0.000151732525311291,9.98339022505192E-7,1,0.999253354069792,40.0298881530762,1.98475949769404,16.2099990993738,0.00170789576613667,0.000311028043971781,0.25,3.77051382430122E-7,0.000152146322237595,1.40652466086126E-6,49.9998894,49.9998894,-66056.53125,-66031.2578125,56.9041194570445,20.6403571084969,17.593889,0,0,0,40,4449,50.00585,-66043.89453125,,,,,,,,,,,,,0,,,,-0.00245,,,,,,49.9998894,,,,
,30968096.835,49.99936295,-61248.818359375,0.000135370991522043,8.42491231635702E-7,1,0.999253354069792,40.0298881530762,1.9846698261438,16.2099990993738,0.0015210686397271,0.000290136101257448,0.25,1.45356634715616E-6,0.000135704586130145,2.38692950408115E-6,49.9992752,49.9994507,-61258.80859375,-61238.828125,57.0807675023906,20.6391275612234,17.973541,0,0,0,40,4449,50.00625,-61248.818359375,,,,,,,,,,,,,0,,,,0,,,,,,49.99936295,,,,
,30968195.935,49.9996338,-56296.96484375,0.00011600511127236,6.64277684849032E-7,1,0.999253354069792,40.0298881530762,1.98465323130527,16.2099990993738,0.00130638791379554,0.000230658269525745,0.25,-3.56454538905607E-7,0.000116276240862876,4.4967107958102E-7,49.9996338,49.9996338,-56307.08984375,-56286.83984375,57.1855057239676,20.6413508944171,17.593889,0,0,0,40,4449,50.00675,-56296.96484375,,,,,,,,,,,,,0,,,,0.00245,,,,,,49.9996338,,,,
,30968289.94,49.998909,-51599.607421875,9.68767413326369E-5,8.50535279305453E-7,1,0.999253354069792,40.0298881530762,1.98479706123467,16.2099990993738,0.00109134842543715,0.000189611186073453,0.25,-5.70728975147154E-7,9.70838349116576E-5,1.09672118550205E-7,49.998909,49.998909,-51609.34765625,-51589.8671875,57.3105662870445,20.6380714118675,17.593889,0,0,0,40,4449,50.0072,-51599.607421875,,,,,,,,,,,,,0,,,,0,,,,,,49.998909,,,,
,30968387.455,49.9999523,-46724.89453125,7.89950739526194E-5,9.16520458516782E-7,1,0.999253354069792,40.0298881530762,1.98445041628408,16.2099990993738,0.000887291346347849,0.000167093409581528,0.25,6.43472813193214E-7,7.91373909858792E-5,1.20655191612102E-6,49.9998779,50.0000267,-46732.37890625,-46717.41015625,57.2112994651022,20.6417012203346,17.973541,0,0,0,40,4449,50.0077,-46724.89453125,,,,,,,,,,,,,0,,,,0,,,,,,49.9999523,,,,
,30968485.6,49.9999771,-41819.99609375,6.06109410493373E-5,7.10223415328953E-7,1,0.999253354069792,40.0298881530762,1.98441218764172,16.2099990993738,0.000680690399159188,0.000127760410533242,0.25,4.52645583224413E-7,6.07054447161085E-5,8.88812112623475E-7,49.9999771,49.9999771,-41819.99609375,-41819.99609375,57.301968373333,20.642256784786,17.973541,0,0,0,40,4449,50.00855,-41819.99609375,,,,,,,,,,,,,0,,,,0,,,,,,49.9999771,,,,
,30968581.76,49.999649,-37015.115234375,4.44340555851809E-5,6.0539086028465E-7,1,0.999253354069792,40.0298881530762,1.98436206232662,16.2099990993738,0.000496928677206055,0.000104472298258487,0.25,1.29285245045187E-6,4.44852560653884E-5,1.61662726958043E-6,49.999649,49.999649,-37022.7578125,-37007.47265625,57.2386564632753,20.642632813773,17.973541,0,0,0,40,4449,50.00765,-37015.115234375,,,,,,,,,,,,,0,,,,0,,,,,,49.999649,,,,
,30968679.44,50.0002441,-32133.87890625,2.58564618545003E-5,8.21441098493776E-7,1,0.999253354069792,40.0298881530762,1.98447480840373,16.2099990993738,0.000288033631217002,6.67360850615395E-5,0.25,1.28068205622795E-6,2.58756312797928E-5,1.47091893439237E-6,50.0002441,50.0002441,-32141.54296875,-32126.21484375,56.983845566006,20.6438927934166,17.593889,0,0,0,40,4449,50.0084,-32133.87890625,,,,,,,,,,,,,0,,,,0.00245,,,,,,50.0002441,,,,
,30968778.445,49.9991913,-27186.4140625,9.03977939205234E-6,6.42718155108654E-7,1,0.999253354069792,40.0298881530762,1.98452883269504,16.2099990993738,0.000100389735176475,2.49147430810776E-5,0.25,5.88664778637405E-7,9.0429922855636E-6,6.55601779889004E-7,49.9991913,49.9991913,-27188.82421875,-27184.00390625,57.3488660844868,20.6400079928375,17.973541,0,0,0,40,4449,50.009,-27186.4140625,,,,,,,,,,,,,0,,,,-0.0049,,,,,,49.9991913,,,,
,30968873.585,49.9994011,-22428.9033203125,-7.59722147577705E-6,5.44486703904278E-7,1,0.999253354069792,40.0298881530762,1.98436472124709,16.2099990993738,-8.59010509628904E-5,-1.22723013353989E-5,0.25,2.76439408340955E-7,-7.60361021491411E-6,2.20476432260435E-7,49.9994011,49.9994011,-22436.46875,-22421.337890625,57.3762230826599,20.6417137822437,17.973541,0,0,0,40,4449,50.0094,-22428.9033203125,,,,,,,,,,,,,0,,,,-0.0049,,,,,,49.9994011,,,,
,30968971.775,49.999218,-17521.2919921875,-2.42735906002383E-5,4.29590792143057E-7,1,0.999253354069792,40.0298881530762,1.98422396517399,16.2099990993738,-0.000272072618940306,-5.19267357351354E-5,0.25,-2.49590368169312E-7,-2.42790577962659E-5,-4.29655211275869E-7,49.999218,49.999218,-17533.92578125,-17508.658203125,57.2386564632753,20.6420365269802,17.973541,0,0,0,40,4449,50.00965,-17521.2919921875,,,,,,,,,,,,,0,,,,0,,,,,,49.999218,,,,
,30969067.57,49.999649,-12733.734375,-3.96978261932692E-5,4.35481556439083E-7,1,0.999253354069792,40.0298881530762,1.98432136951804,16.2099990993738,-0.000445177633839842,-8.31498897152271E-5,0.25,-2.51127024297092E-7,-3.969758040612E-5,-5.46194146741742E-7,49.999649,49.999649,-12741.3876953125,-12726.0810546875,57.3394865422561,20.6407342741884,17.593889,0,0,0,40,4449,50.00915,-12733.734375,,,,,,,,,,,,,0,,,,0,,,,,,49.999649,,,,
,30969165.61,49.9992752,-7833.18383789063,-5.46405129466929E-5,3.52053311625451E-7,1,0.999253354069792,40.0298881530762,1.98432828963883,16.2099990993738,-0.000612386011429226,-0.00011556530185289,0.25,-4.47180695718758E-7,-5.46254364963904E-5,-8.53657217503012E-7,49.9992752,49.9992752,-7843.28515625,-7823.08251953125,56.9721211382176,20.639077402905,17.973541,0,0,0,40,4449,50.01045,-7833.18383789063,,,,,,,,,,,,,0,,,,-0.00245,,,,,,49.9992752,,,,
,30969262.06,50.0001907,-3012.53515625,-6.90679497346054E-5,3.63885436070087E-7,1,0.999253354069792,40.0298881530762,1.98431640196921,16.2099990993738,-0.000773013397848582,-0.00015096862670553,0.25,-1.00388403897536E-6,-6.90298493409571E-5,-1.51736188142247E-6,50.0001907,50.0001907,-3024.96264648438,-3000.10766601562,57.1964485232368,20.6401777250867,17.593889,0,0,0,40,4449,50.01045,-3012.53515625,,,,,,,,,,,,,0,,,,-0.0049,,,,,,50.0001907,,,,
,30969355.455,50.0000916,1652.93438720703,-7.9090461250928E-5,2.79002968017636E-7,1,0.999253354069792,40.0298881530762,1.984429544626,16.2099990993738,-0.000885772377654622,-0.000169615868300361,0.25,-8.59122022208504E-7,-7.90445766602538E-5,-1.44710688687221E-6,50.0000916,50.0000916,1650.44018554687,1655.42858886719,57.2277136640061,20.6407751789076,17.973541,0,0,0,40,4449,50.0098,1652.93438720703,,,,,,,,,,,,,0,,,,0,,,,,,50.0000916,,,,
,30969450.37,50.00029185,6398.0205078125,-8.78659740836909E-5,3.86294173386041E-7,1,0.999253354069792,40.0298881530762,1.9843100948697,16.2099990993738,-0.000984888749648794,-0.00018467769474312,0.25,-6.16980749679987E-7,-8.7836169321697E-5,-1.27066811467067E-6,50.000248,50.0003357,6388.11767578125,6407.92333984375,57.0049495360253,20.638502869491,17.593889,0,0,0,40,4449,50.0089,6398.0205078125,,,,,,,,,,,,,0,,,,0.00245,,,,,,50.00029185,,,,
,30969544.63,50.0003662,11108.6958007813,-8.81603370619692E-5,4.59960387192441E-7,1,0.999253354069792,40.0298881530762,1.98425712073447,16.2099990993738,-0.000987179720189347,-0.000192116510564558,0.25,-1.22365201839036E-6,-8.81472327256476E-5,-1.87918761252977E-6,50.0003662,50.0003662,11101.3203125,11116.0712890625,57.2324034351214,20.6384261067482,17.593889,0,0,0,40,4449,50.0103,11108.6958007813,,,,,,,,,,,,,0,,,,-0.00245,,,,,,50.0003662,,,,
,30969640.555,50.00021935,15903.62890625,-7.47469957330422E-5,5.10660092179988E-7,1,0.999253354069792,40.0298881530762,1.98416716477368,16.2099990993738,-0.000836604750922552,-0.000166019781812339,0.25,-1.31462557603012E-6,-7.47531441723887E-5,-1.86968009326946E-6,50.000145,50.0002937,15893.716796875,15913.541015625,57.1221938139099,20.6408170034674,17.973541,0,0,0,40,4449,50.00965,15903.62890625,,,,,,,,,,,,,0,,,,0,,,,,,50.00021935,,,,
,30969736.68,50.0008774,20708.3759765625,-5.16977758446264E-5,5.35313335116903E-7,1,0.999253354069792,40.0298881530762,1.98417157904458,16.2099990993738,-0.000578065934068741,-0.000118823282278127,0.25,-1.26382566311582E-6,-5.17130815024814E-5,-1.64689076632262E-6,50.0008774,50.0008774,20701.181640625,20715.5703125,57.0213637349291,20.6391339198772,17.973541,0,0,0,40,4449,50.0088,20708.3759765625,,,,,,,,,,,,,0,,,,-0.0049,,,,,,50.0008774,,,,
,30969832.73,50.0013542,25508.990234375,-3.56051445860607E-5,6.35593789451164E-7,1,0.999253354069792,40.0298881530762,1.98409963553354,16.2099990993738,-0.000396985537391992,-8.86824031619976E-5,0.25,-1.47948689094114E-6,-3.56206527976071E-5,-1.74279560394202E-6,50.0013542,50.0013542,25503.986328125,25513.994140625,57.2112994651022,20.6391752091487,17.593889,0,0,0,40,4449,50.00775,25508.990234375,,,,,,,,,,,,,0,,,,-0.00245,,,,,,50.0013542,,,,
,30969928.805,50.0005951,30308.9208984375,-3.42491536686665E-5,6.19491832467887E-7,1,0.999253354069792,40.0298881530762,1.98407159184,16.2099990993738,-0.000381889412832499,-8.57311125595696E-5,0.25,-1.46069969397134E-6,-3.42728505027261E-5,-1.71292098216734E-6,50.0005951,50.0005951,30296.271484375,30321.5703125,57.2347483206791,20.6396034750138,18.353191,0,0,0,40,4449,50.00765,30308.9208984375,,,,,,,,,,,,,0,,,,-0.00245,,,,,,50.0005951,,,,
,30970028.28,50.0005226,35281.791015625,-4.3778987776588E-5,6.45324679322412E-7,1,0.999253354069792,40.0298881530762,1.98407094088028,16.2099990993738,-0.000489799390832696,-0.00010118373900217,0.25,-1.11942660410421E-6,-4.38264996902242E-5,-1.43902807211633E-6,50.0005226,50.0005226,35269.16796875,35294.4140625,57.0096393071407,20.6381667038211,17.973541,0,0,0,40,4449,50.0062,35281.791015625,,,,,,,,,,,,,0,,,,-0.0049,,,,,,50.0005226,,,,
,30970127.485,50.0015297,40239.01953125,-5.83076663204678E-5,8.81156829015816E-7,1,0.999253354069792,40.0298881530762,1.98409511151002,16.2099990993738,-0.000651339472596776,-0.000141379568146141,0.25,-2.07989620771071E-6,-5.83819359023751E-5,-2.50323261147937E-6,50.0015297,50.0015297,40236.71484375,40241.32421875,57.105779615006,20.6377051759853,17.593889,0,0,0,40,4449,50.00515,40239.01953125,,,,,,,,,,,,,0,,,,0,,,,,,50.0015297,,,,
,30970225.565,50.0006409,45142.1328125,-7.3857384954057E-5,7.84284288859868E-7,1,0.999253354069792,40.0298881530762,1.98399482000024,16.2099990993738,-0.000828465331650492,-0.00016101736741536,0.25,-1.03004223836722E-6,-7.39814993157992E-5,-1.55898537003489E-6,50.0006409,50.0006409,45139.671875,45144.59375,57.0104209356599,20.6415403767102,18.353191,0,0,0,40,4449,50.0038,45142.1328125,,,,,,,,,,,,,0,,,,0,,,,,,50.0006409,,,,
,30970320.89,50.0008049,49907.267578125,-9.13011800883545E-5,9.16529790601852E-7,1,0.999253354069792,40.0298881530762,1.98415426701439,16.2099990993738,-0.00102222703928477,-0.000211486687134311,0.25,-2.38053371224223E-6,-9.14683077117429E-5,-3.03021696037591E-6,50.0007324,50.0008774,49897.3828125,49917.15234375,57.0026046504676,20.6373671264195,17.593889,0,0,0,40,4449,50.00535,49907.267578125,,,,,,,,,,,,,0,,,,-0.00245,,,,,,50.0008049,,,,
,30970417.43,50.0007591,54732.041015625,-0.000111309492191628,9.33402909764859E-7,1,0.999253354069792,40.0298881530762,1.98405454002671,16.2099990993738,-0.00125013568677285,-0.000237491865864428,0.25,-1.0991873520848E-6,-0.000111551515182603,-1.87896217749402E-6,50.0007591,50.0007591,54729.37109375,54734.7109375,57.2027015513907,20.6397025054787,17.973541,0,0,0,40,4449,50.005,54732.041015625,,,,,,,,,,,,,0,,,,-0.0049,,,,,,50.0007591,,,,
,30970516.345,50.0009079,59675.01171875,-0.000128950295154346,1.02997300048842E-6,1,0.999253354069792,40.0298881530762,1.98407017834915,16.2099990993738,-0.00144386888250886,-0.000301518642721342,0.25,-3.62388795234754E-6,-0.000129243553851276,-4.52212516239846E-6,50.0006104,50.0012054,59667.72265625,59682.30078125,56.9822823089676,20.6386844826902,17.593889,0,0,0,40,4449,50.0037,59675.01171875,,,,,,,,,,,,,0,,,,0,,,,,,50.0009079,,,,
,30970614.705,50.0014839,64590.53125,-0.00014780639297848,9.2419957677062E-7,1,0.999253354069792,40.0298881530762,1.98411685933697,16.2099990993738,-0.00166066420241572,-0.000316353629699892,0.25,-1.56116861585548E-6,-0.00014819216385564,-2.57129370270846E-6,50.0014839,50.0014839,64585.671875,64595.390625,57.1120326431599,20.636628117116,17.593889,0,0,0,40,4449,50.0017,64590.53125,,,,,,,,,,,,,0,,,,0.00245,,,,,,50.0014839,,,,
,30970713.565,50.0016022,69533.0859375,-0.000167905833573723,1.10042254880491E-6,1,0.999253354069792,40.0298881530762,1.98416785924388,16.2099990993738,-0.00189035734289671,-0.00034032217762304,0.25,-9.02434054257898E-8,-0.000168390050015844,-1.21733381342213E-6,50.0016022,50.0016022,69528.1015625,69538.0703125,57.0385595623522,20.6369930844248,17.593889,0,0,0,40,4449,50.0008,69533.0859375,,,,,,,,,,,,,0,,,,0.0049,,,,,,50.0016022,,,,
,30970811.53,50.0016632,74430.8359375,-0.000188146471090412,1.1646188763439E-6,1,0.999253354069792,40.0298881530762,1.98414396104697,16.2099990993738,-0.0021170224253722,-0.000390323063232918,0.25,-9.10357404672147E-7,-0.000188720271957049,-2.15765293793913E-6,50.0011635,50.0021629,74420.9375,74440.734375,57.115940785756,20.6357466773271,17.973541,0,0,0,40,4449,49.99975,74430.8359375,,,,,,,,,,,,,0,,,,0.0049,,,,,,50.0016632,,,,
,30970908.76,50.0013275,79291.3828125,-0.000206749043329635,1.21869328599666E-6,1,0.999253354069792,40.0298881530762,1.984023987664,16.2099990993738,-0.00232121146591317,-0.000459194454338169,0.25,-3.70432772045262E-6,-0.000207400068806225,-5.06368556924921E-6,50.0013275,50.0013275,79283.875,79298.890625,57.1526773261599,20.6363929543305,18.353191,0,0,0,40,4449,49.99995,79291.3828125,,,,,,,,,,,,,0,,,,-0.00245,,,,,,50.0013275,,,,
,30971006.155,50.0011158,84159.9375,-0.000227501683656762,1.19131191428456E-6,1,0.999253354069792,40.0298881530762,1.98440132285725,16.2099990993738,-0.0025584666454034,-0.000486778628594938,0.25,-2.44040918562451E-6,-0.000228268795860431,-3.90862077963613E-6,50.0010338,50.0011978,84152.328125,84167.546875,57.1034347294484,20.6347836029374,17.973541,0,0,0,40,4449,49.9988,84159.9375,,,,,,,,,,,,,0,,,,0.00245,,,,,,50.0011158,,,,
,30971097.32,50.0006027,88718.21875,-0.000248239290191992,1.1076756945111E-6,1,0.999253354069792,40.0298881530762,1.98416201057993,16.2099990993738,-0.0027894038203142,-0.000544521042810338,0.25,-3.87110801915417E-6,-0.000249107711827147,-5.45449782390194E-6,50.0006027,50.0006027,88715.7265625,88720.7109375,57.0119841926983,20.6325396939726,18.353191,0,0,0,40,4449,49.9983,88718.21875,,,,,,,,,,,,,0,,,,0,,,,,,50.0006027,,,,
,30971210.695,49.9990082,86558.58984375,-0.000234103429512334,1.0835311839613E-6,1,0.999253354069792,40.0298881530762,1.98437104360745,16.2099990993738,-0.00263540261630378,-0.000486910453526167,0.25,-1.27802230194577E-6,-0.000234920262279524,-2.77309044953618E-6,49.9990082,49.9990082,86548.5390625,86568.640625,57.1268835850253,20.6354603923504,17.593889,0,0,0,40,4449,49.99935,86558.58984375,,,,,,,,,,,,,0,,,,-0.00245,,,,,,49.9990082,,,,
,30971303.485,49.99949075,81920.40234375,-0.000218216779015205,1.10144151971393E-6,1,0.999253354069792,40.0298881530762,1.98427920138136,16.2099990993738,-0.00245303460468692,-0.000470617639841628,0.25,-2.66534145577915E-6,-0.000218933042095707,-4.08457825144018E-6,49.9992752,49.9997063,81915.1484375,81925.65625,57.0510656186599,20.6353041272119,17.593889,0,0,0,40,4449,49.9993,81920.40234375,,,,,,,,,,,,,0,,,,0,,,,,,49.99949075,,,,
,30971399.845,49.9998131,77101.3984375,-0.0001979425383211,1.11643860062697E-6,1,0.999253354069792,40.0298881530762,1.98422558801927,16.2099990993738,-0.00222508777466119,-0.000424500986731053,0.25,-2.19344619923677E-6,-0.00019855838547348,-3.49909132202153E-6,49.9998131,49.9998131,77096.2578125,77106.5390625,57.1456426694868,20.6355689495353,17.973541,0,0,0,40,4449,50.0001,77101.3984375,,,,,,,,,,,,,0,,,,0.00245,,,,,,49.9998131,,,,
,30971499.055,49.9980621,72142.83203125,-0.000177730015424864,9.93892470282442E-7,1,0.999253354069792,40.0298881530762,1.98413768013799,16.2099990993738,-0.0019974969453625,-0.000380579677483268,0.25,-1.90860644395795E-6,-0.000178249108128677,-3.09798215813339E-6,49.9980621,49.9980621,72138.03125,72147.6328125,57.0495023616214,20.6375603936334,17.973541,0,0,0,40,4449,50.0003,72142.83203125,,,,,,,,,,,,,0,,,,0.00245,,,,,,49.9980621,,,,
,30971597.93,49.998909,67202.3984375,-0.000158608318913532,1.07093274173262E-6,1,0.999253354069792,40.0298881530762,1.98416792878894,16.2099990993738,-0.00178359008353463,-0.000332153575350294,0.25,-1.02903189017248E-6,-0.000159044178460373,-2.10347456360386E-6,49.998909,49.998909,67189.9375,67214.859375,57.004167907506,20.636988649728,17.973541,0,0,0,40,4449,50.00205,67202.3984375,,,,,,,,,,,,,0,,,,0.0049,,,,,,49.998909,,,,
,30971694.135,49.9987259,62391.82421875,-0.000139636244027556,1.05092921703701E-6,1,0.999253354069792,40.0298881530762,1.98419019517342,16.2099990993738,-0.0015646426321613,-0.000321865269637618,0.25,-3.51385313419413E-6,-0.000139973486881226,-4.47900293279489E-6,49.9987259,49.9987259,62381.90625,62401.7421875,57.0878021590637,20.6398970232343,17.593889,0,0,0,40,4449,50.00285,62391.82421875,,,,,,,,,,,,,0,,,,-0.0049,,,,,,49.9987259,,,,
,30971789.945,49.9998989,57603.662109375,-0.000121638102621354,1.06896109107097E-6,1,0.999253354069792,40.0298881530762,1.98409936147884,16.2099990993738,-0.00136674517029717,-0.000257352934723943,0.25,-1.01042187113542E-6,-0.000121919958017741,-1.85619775216396E-6,49.9997978,50,57593.953125,57613.37109375,56.811105663256,20.6418690788162,17.593889,0,0,0,40,4449,50.00275,57603.662109375,,,,,,,,,,,,,0,,,,0,,,,,,49.9998989,,,,
,30971887.53,49.9991798,52726.005859375,-0.000104104519798726,7.10049953435369E-7,1,0.999253354069792,40.0298881530762,1.98427571542073,16.2099990993738,-0.00116678781470997,-0.000235703933612433,0.25,-2.23159449562597E-6,-0.000104312580182408,-2.96692498441291E-6,49.9991798,49.9991798,52721.11328125,52730.8984375,57.1331366131791,20.6421853622465,17.593889,0,0,0,40,4449,50.0033,52726.005859375,,,,,,,,,,,,,0,,,,-0.00245,,,,,,49.9991798,,,,
,30971985.68,49.9985657,47821.07421875,-8.61471523031926E-5,8.54304906697077E-7,1,0.999253354069792,40.0298881530762,1.98422522945598,16.2099990993738,-0.000963708087221814,-0.000203690728031715,0.25,-2.61275522940602E-6,-8.62933909519446E-5,-3.22907830276959E-6,49.9985657,49.9985657,47818.3984375,47823.75,57.0065127930637,20.6426021223761,17.973541,0,0,0,40,4449,50.0036,47821.07421875,,,,,,,,,,,,,0,,,,-0.0049,,,,,,49.9985657,,,,
,30972082.235,49.9994316,42995.486328125,-6.74653397433143E-5,8.62301758386265E-7,1,0.999253354069792,40.0298881530762,1.98419385378868,16.2099990993738,-0.000752211672034611,-0.000172332318661893,0.25,-3.184362628537E-6,-6.75553161642376E-5,-3.67327032921622E-6,49.9994316,49.9994316,42985.53515625,43005.4375,56.926005055583,20.64213049691,17.973541,0,0,0,40,4449,50.00485,42995.486328125,,,,,,,,,,,,,0,,,,-0.0049,,,,,,49.9994316,,,,
,30972179.895,50.0002365,38112.9296875,-4.98591818537741E-5,7.01072299276842E-7,1,0.999253354069792,40.0298881530762,1.98416187421059,16.2099990993738,-0.000556351750033722,-0.000124038970410748,0.25,-2.05768078006036E-6,-4.99151016986403E-5,-2.42125663413203E-6,50.0002365,50.0002365,38103.125,38122.734375,57.0205821064099,20.6419836180635,17.973541,0,0,0,40,4449,50.00455,38112.9296875,,,,,,,,,,,,,0,,,,0,,,,,,50.0002365,,,,
,30972277.04,49.9992485,33255.8671875,-3.24583691742173E-5,7.23233515845345E-7,1,0.999253354069792,40.0298881530762,1.98430726075824,16.2099990993738,-0.000359824725790403,-9.34630710028741E-5,0.25,-2.47011195230446E-6,-3.2478101415252E-5,-2.70963280057322E-6,49.9992485,49.9992485,33245.63671875,33266.09765625,57.1354814987368,20.6406780719435,17.593889,0,0,0,40,4449,50.0055,33255.8671875,,,,,,,,,,,,,0,,,,0,,,,,,49.9992485,,,,
,30972373.25,49.9990425,28451.0322265625,-1.39687632101865E-5,5.57384445296316E-7,1,0.999253354069792,40.0298881530762,1.984215947649,16.2099990993738,-0.00015372735182483,-4.62000050617504E-5,0.25,-1.59539548912919E-6,-1.39696582858745E-5,-1.6993557933637E-6,49.9990425,49.9990425,28443.478515625,28458.5859375,56.8611298884868,20.6421347758926,17.593889,0,0,0,40,4449,50.00505,28451.0322265625,,,,,,,,,,,,,0,,,,-0.0049,,,,,,49.9990425,,,,
,30972468.065,49.9994659,23711.0908203125,1.90148083474291E-6,4.72727064450628E-7,1,0.999253354069792,40.0298881530762,1.98432394018309,16.2099990993738,2.50690172460974E-5,-1.67311971356872E-5,0.25,-1.83196525666171E-6,1.91621844374679E-6,-1.81911214497108E-6,49.9994659,49.9994659,23706.0234375,23716.158203125,57.139389641333,20.6442705108884,17.973541,0,0,0,40,4449,50.0064,23711.0908203125,,,,,,,,,,,,,0,,,,-0.0049,,,,,,49.9994659,,,,
,30972561.21,49.9987984,19053.2197265625,1.82106865675367E-5,4.97854814129039E-7,1,0.999253354069792,40.0298881530762,1.98424956895453,16.2099990993738,0.000206274131805513,2.70937535348026E-5,0.25,-8.69259773259458E-7,1.82241362462851E-5,-7.34699230237915E-7,49.9987984,49.9987984,19048.1640625,19058.275390625,57.2550706621791,20.6425930030419,17.973541,0,0,0,40,4449,50.0066,19053.2197265625,,,,,,,,,,,,,0,,,,0,,,,,,49.9987984,,,,
,30972658.155,49.9995651,14208.6821289062,3.36145003881237E-5,5.22379974180596E-7,1,0.999253354069792,40.0298881530762,1.98433169349309,16.2099990993738,0.000379276430029179,5.77280467219525E-5,0.25,-9.17036077946449E-7,3.36253477536E-5,-6.67450498293655E-7,49.9995651,49.9995651,14206.125,14211.2392578125,56.9525804252368,20.6412619871211,17.593889,0,0,0,40,4449,50.008,14208.6821289062,,,,,,,,,,,,,0,,,,0,,,,,,49.9995651,,,,
,30972752.82,49.9996338,9478.6220703125,4.98351607039611E-5,3.86442202294865E-7,1,0.999253354069792,40.0298881530762,1.98417723726329,16.2099990993738,0.000559640942285382,9.92718189562353E-5,0.25,-1.38279416187E-7,4.98296309327559E-5,2.32468927790638E-7,49.9996338,49.9996338,9468.5087890625,9488.7353515625,57.088583787583,20.6421457220348,18.353191,0,0,0,40,4449,50.0077,9478.6220703125,,,,,,,,,,,,,0,,,,-0.00245,,,,,,49.9996338,,,,
,30972848.89,49.9995937,4675.6083984375,6.47258940891527E-5,3.62543450071891E-7,1,0.999253354069792,40.0298881530762,1.98424383878961,16.2099990993738,0.000727277669012819,0.000125767159030122,0.25,-4.5972363370168E-7,6.47053711452191E-5,2.21111987464757E-8,49.9995651,49.9996223,4665.82177734375,4685.39501953125,57.2292769210445,20.6443896992782,17.973541,0,0,0,40,4449,50.00695,4675.6083984375,,,,,,,,,,,,,0,,,,-0.00245,,,,,,49.9995937,,,,
,30972943.125,50.0003853,-0.213132828474045,7.74502236649243E-5,3.68544547453145E-7,1,0.999253354069792,40.0298881530762,1.98422678067284,16.2099990993738,0.000869596115951591,0.000153176428096799,0.25,-3.08080026451098E-7,7.74096972449989E-5,2.68190950649388E-7,50.0003853,50.0003853,-0.213132828474045,-0.213132828474045,57.1612752398714,20.6477001547158,17.593889,0,0,0,40,4417,50.0086,-0.213132828474045,,,,,,,,,,,,,0,,,,0,,,,,,50.0003853,,,,