File: data/doubleLayers/dl_5/ppms/data/DD205_6_ZFCW_100OE.DAT
[Header]
; VSM Data File (default extension .dat)
; Copyright (c) 2003-2013, Quantum Design, Inc. All rights reserved.
TITLE,
FILEOPENTIME,30877852.91,12/24/2018,5:12 pm
BYAPP,VSM,2.0,2.0
INFO,PPMS VSM Option Release 1.4.10 Build 1,APPNAME
INFO,Quantum Design Linear Motor Servo Controller,MOTOR_MODULE_NAME
INFO,3101-100 M1,MOTOR_HW_VERSION
INFO,MMC1014,MOTOR_SERIAL_NUMBER
INFO,SRV No X-over 01.03.11,MOTOR_SOFTWARE_VERSION
INFO,Quantum Design VSM Detection Module,VSM_MODULE_NAME
INFO,3101-150 F0,VSM_HW_VERSION
INFO,VSM707,VSM_SERIAL_NUMBER
INFO,VSM No X-over 01.02.05 May 20 2008 13:51:47,VSM_SOFTWARE_VERSION
INFO,704,PREAMP_SERIAL_NUMBER
INFO,822,COIL_SERIAL_NUMBER
INFO,0,MOMENT_UNITS
INFO,CoFe2O4,SAMPLE_MATERIAL
INFO,AH11 DL,SAMPLE_COMMENT
INFO,30.27,SAMPLE_MASS
INFO,,SAMPLE_VOLUME
INFO,,SAMPLE_MOLECULAR_WEIGHT
INFO,,SAMPLE_SIZE
INFO,,SAMPLE_SHAPE
DATATYPE,COMMENT,1
DATATYPE,TIME,2
STARTUPAXIS,X,2
STARTUPAXIS,Y1,5
[Data]
Comment,Time Stamp (sec),Temperature (K),Magnetic Field (Oe),Moment (emu),M. Std. Err. (emu),Transport Action,Averaging Time (sec),Frequency (Hz),Peak Amplitude (mm),Center Position (mm),Coil Signal' (mV),Coil Signal" (mV),Range (mV),M. Quad. Signal (emu),M. Raw' (emu),M. Raw" (emu),Min. Temperature (K),Max. Temperature (K),Min. Field (Oe),Max. Field (Oe),Mass (grams),Motor Lag (deg),Pressure (Torr),VSM Status (code),Motor Status (code),Measure Status (code),Measure Count,PPMS Status (code),System Temp. (K),System Field (Oe),Sample Position (deg),Bridge 1 Resistance (ohms),Bridge 1 Excitation (에),Bridge 2 Resistance (ohms),Bridge 2 Excitation (에),Bridge 3 Resistance (ohms),Bridge 3 Excitation (에),Bridge 4 Resistance (ohms),Bridge 4 Excitation (에),Signal 1 Vin (V),Signal 2 Vin (V),Digital Inputs (code),Drive 1 Iout (mA),Drive 1 Ipower (W),Drive 2 Iout (mA),Drive 2 Ipower (W),Pressure (),Map 20 (),Map 21 (),Map 22 (),Map 23 (),Map 24 (),Map 25 (),Map 26 (),Map 27 (),Map 28 (),Map 29 ()
,30890342.89,10.0012102,99.3960113525391,,,2,,,,16.2799996006489,,,,,,,10.0012102,10.0012102,99.3960113525391,99.3960113525391,,,12.658426,,,,-99999999,4373,9.997,99.3960113525391,,,,,,,,,,,,,,,,,,,,,,,10.0012102,,,,
,30890548.615,12.5092049,99.3960113525391,-1.92010285799204E-7,2.99737086517782E-7,1,0.999253354069792,40.0298881530762,1.99669280979214,16.2599999457598,-1.33644797901894E-6,-5.00349568854935E-6,0.25,-4.11314812748347E-7,-1.88923149926914E-7,-4.09877091653844E-7,12.5092049,12.5092049,99.3960113525391,99.3960113525391,56.6321127323521,20.6073700833233,12.658426,0,0,0,40,4370,12.64305,99.3960113525391,,,,,,,,,,,,,0,,,,-0.0049,,,,,,12.5092049,,,,
,30890689.32,16.0155315,99.3960113525391,-2.70065552713721E-7,2.53752149786882E-7,1,0.999253354069792,40.0298881530762,1.99607875343651,16.2599999457598,-2.83459486988969E-6,-1.65497691459751E-6,0.25,-9.94135033149145E-8,-2.68031607548584E-7,-1.00143739025112E-7,16.0155315,16.0155315,99.3960113525391,99.3960113525391,56.3546346080252,20.620165572365,13.038077,0,0,0,40,4370,16.17475,99.3960113525391,,,,,,,,,,,,,0,,,,0.0049,,,,,,16.0155315,,,,
,30890830.415,19.5394936,99.3960113525391,-1.63509626350652E-7,3.10359252365723E-7,1,0.999253354069792,40.0298881530762,1.99625562800517,16.2599999457598,-1.26381198777341E-6,-3.55008427566327E-6,0.25,-2.87058224732259E-7,-1.6117907025086E-7,-2.86199219556378E-7,19.5394936,19.5394936,99.3960113525391,99.3960113525391,56.7032409276022,20.6217557105427,14.177031,0,0,0,40,4370,19.71005,99.3960113525391,,,,,,,,,,,,,0,,,,0,,,,,,19.5394936,,,,
,30890969.61,23.0119057,99.3960113525391,-3.79049488183551E-7,2.7537029692301E-7,1,0.999253354069792,40.0298881530762,2.00864904719899,16.2599999457598,-3.50744924608706E-6,-5.12280703132714E-6,0.25,-3.86050787469543E-7,-3.74987859317308E-7,-3.85744836077059E-7,23.0119057,23.0119057,99.3960113525391,99.3960113525391,56.831428004756,20.6197296769086,13.797379,0,0,0,40,4370,23.2172,99.3960113525391,,,,,,,,,,,,,0,,,,0.00245,,,,,,23.0119057,,,,
,30891112.965,26.5153847,99.3960113525391,-1.09584754783907E-7,2.89424737932359E-7,1,0.999253354069792,40.0298881530762,2.00864892354662,16.2599999457598,-5.7203162842282E-7,-3.96444131509688E-6,0.25,-3.31332246151608E-7,-1.07265781317432E-7,-3.30089968269721E-7,26.5153847,26.5153847,99.3960113525391,99.3960113525391,56.6000659630637,20.6264106682421,14.936333,0,0,0,40,4370,26.82935,99.3960113525391,,,,,,,,,,,,,0,,,,-0.00245,,,,,,26.5153847,,,,
,30891254.57,30.0590153,99.3960113525391,-1.82918467588232E-7,3.01345755144416E-7,1,0.999253354069792,40.0298881530762,2.00884141843236,16.2599999457598,-1.257236264172E-6,-4.9143795933185E-6,0.25,-4.02127888807173E-7,-1.79756694692279E-7,-4.01070276386988E-7,30.0590153,30.0590153,99.3960113525391,99.3960113525391,56.7712426087752,20.6236139144607,15.315984,0,0,0,40,4370,30.40225,99.3960113525391,,,,,,,,,,,,,0,,,,-0.00245,,,,,,30.0590153,,,,
,30891394.98,33.5239525,99.3960113525391,-2.54407768054895E-7,2.64479437154862E-7,1,0.999253354069792,40.0298881530762,2.00847466578035,16.2099990993738,-2.3391488161797E-6,-3.52082898095007E-6,0.25,-2.65923693576134E-7,-2.51641757731198E-7,-2.66191894651186E-7,33.5239525,33.5239525,99.3960113525391,99.3960113525391,56.9471090256022,20.6292865000147,15.315984,0,0,0,40,4370,33.9423,99.3960113525391,,,,,,,,,,,,,0,,,,0,,,,,,33.5239525,,,,
,30891535.655,37.0262833,99.3960113525391,-2.85219638060198E-7,2.90393494649075E-7,1,0.999253354069792,40.0298881530762,2.00842188027706,16.2099990993738,-2.97668594859042E-6,-1.97321458185241E-6,0.25,-1.23313601261432E-7,-2.83284230345083E-7,-1.24639284875817E-7,37.0262833,37.0262833,99.3960113525391,99.3960113525391,56.8580033744099,20.6284235039623,15.695635,0,0,0,40,4370,37.48165,99.3960113525391,,,,,,,,,,,,,0,,,,-0.0049,,,,,,37.0262833,,,,
,30891678.43,40.53752135,99.3960113525391,-3.5145536568653E-7,3.20026625451872E-7,1,0.999253354069792,40.0298881530762,2.00856163137096,16.2099990993738,-3.73883880115161E-6,-2.05335675245847E-6,0.25,-1.18217828375957E-7,-3.49528604249397E-7,-1.20242891395651E-7,40.5102501,40.5647926,99.3960113525391,99.3960113525391,57.3293253715061,20.6262724352248,16.075285,0,0,0,40,4370,41.0904,99.3960113525391,,,,,,,,,,,,,0,,,,0,,,,,,40.53752135,,,,
,30891819.875,44.0358734,99.3960113525391,-1.76641524931843E-7,3.05660108120002E-7,1,0.999253354069792,40.0298881530762,1.99612923741057,16.1799993366003,-1.83215877050709E-6,-1.23527831278399E-6,0.25,-7.78508206878271E-8,-1.7569429519312E-7,-7.89497081349036E-8,44.0358734,44.0358734,99.3960113525391,99.3960113525391,57.0330881627176,20.6257550791491,16.834587,0,0,0,40,4370,44.6624,99.3960113525391,,,,,,,,,,,,,0,,,,0,,,,,,44.0358734,,,,
,30891964.095,47.5673637,99.3960113525391,-7.90230449396173E-8,3.41234866618565E-7,1,0.999253354069792,40.0298881530762,1.99640794601738,16.1799993366003,-5.48147189060666E-7,-2.06507395880891E-6,0.25,-1.6883682351051E-7,-7.76887075697387E-8,-1.69241057152235E-7,47.5673637,47.5673637,99.3960113525391,99.3960113525391,56.6633778731214,20.6196172272649,16.834587,0,0,0,40,4370,48.3317,99.3960113525391,,,,,,,,,,,,,0,,,,-0.00245,,,,,,47.5673637,,,,
,30892105.75,51.0046692,99.3960113525391,-4.02810961503491E-7,2.86821663877387E-7,1,0.999253354069792,40.0298881530762,1.99618027613089,16.1799993366003,-3.73553585357416E-6,-5.32883804774081E-6,0.25,-3.99341742268243E-7,-3.9986853662224E-7,-4.02359743959508E-7,51.0046692,51.0046692,99.3960113525391,99.3960113525391,56.8955215433329,20.6230905603378,17.593889,0,0,0,40,4370,51.9368,99.3960113525391,,,,,,,,,,,,,0,,,,0.00245,,,,,,51.0046692,,,,
,30892248.115,54.5161057,99.3960113525391,-2.68670911765304E-7,3.15621369343525E-7,1,0.999253354069792,40.0298881530762,2.0087295706397,16.160000115633,-2.74389471817926E-6,-2.27890212661104E-6,0.25,-1.52022154201564E-7,-2.67870294058383E-7,-1.54152734127907E-7,54.5161057,54.5161057,99.3960113525391,99.3960113525391,56.9103724851983,20.6183895475837,17.593889,0,0,0,40,4374,55.5399,99.3960113525391,,,,,,,,,,,,,0,,,,0.00245,,,,,,54.5161057,,,,
,30892389.76,58.0543137,99.3960113525391,-1.76998488800118E-7,2.69349125953351E-7,1,0.999253354069792,40.0298881530762,2.00838162887463,16.160000115633,-1.12212279465291E-6,-5.32566595118594E-6,0.25,-4.36116469793764E-7,-1.74318823242955E-7,-4.38272914879719E-7,58.0543137,58.0543137,99.3960113525391,99.3960113525391,57.1456426694868,20.6284524192249,17.593889,0,0,0,40,4374,59.1204,99.3960113525391,,,,,,,,,,,,,0,,,,0,,,,,,58.0543137,,,,
,30892533.035,61.5442619,99.3960113525391,-2.91824622628333E-7,2.61922830201484E-7,1,0.999253354069792,40.0298881530762,2.00855687416254,16.160000115633,-2.41580491150595E-6,-5.66266423355717E-6,0.25,-4.44711330707346E-7,-2.8974158797286E-7,-4.47948912245649E-7,61.5442619,61.5442619,99.3960113525391,99.3960113525391,57.0557553897753,20.6234694590939,17.593889,0,0,0,40,4374,62.75845,99.3960113525391,,,,,,,,,,,,,0,,,,0.00245,,,,,,61.5442619,,,,
,30892652.495,64.5184555,99.3960113525391,-5.19889775686326E-7,3.25973809887698E-7,1,0.999253354069792,40.0298881530762,1.98429914473161,16.1400008946657,-5.22675551044694E-6,-4.57635794527474E-6,0.25,-3.13068213589252E-7,-5.19760505188419E-7,-3.17421845920881E-7,64.5184555,64.5184555,99.3960113525391,99.3960113525391,57.0510656186599,20.6274554301682,17.973541,0,0,0,40,4374,65.7778,99.3960113525391,,,,,,,,,,,,,0,,,,0,,,,,,64.5184555,,,,
,30892796.225,68.0302963,99.3960113525391,-2.39056425563893E-7,3.15913075042938E-7,1,0.999253354069792,40.0298881530762,1.98413293435969,16.1400008946657,-1.63182889560741E-6,-6.43738994026324E-6,0.25,-5.28284641764355E-7,-2.36963726708899E-7,-5.31832326146926E-7,68.0302963,68.0302963,99.3960113525391,99.3960113525391,56.9963516223137,20.6327031850188,18.353191,0,0,0,40,4374,69.41675,99.3960113525391,,,,,,,,,,,,,0,,,,0.0049,,,,,,68.0302963,,,,
,30892938.06,71.531929,99.3960113525391,-1.78643947819768E-7,3.07730975396149E-7,1,0.999253354069792,40.0298881530762,1.984180968424,16.1400008946657,-2.08061442428735E-6,8.36003364019501E-9,0.25,3.25572557111815E-8,-1.79627306002977E-7,3.17432613768874E-8,71.531929,71.531929,99.3960113525391,99.3960113525391,57.3035316303714,20.6323133426697,18.732843,0,0,0,40,4374,73.0037,99.3960113525391,,,,,,,,,,,,,0,,,,0,,,,,,71.531929,,,,
,30893058.935,74.5448303,99.3960113525391,7.95795513151566E-8,2.80959352646499E-7,1,0.999253354069792,40.0298881530762,2.00849692384294,16.1099992692471,9.41837264610194E-7,-2.59725132765593E-8,0.25,-1.64194264565714E-8,8.00455439736988E-8,-1.60979815626794E-8,74.5448303,74.5448303,99.3960113525391,99.3960113525391,57.0198004778906,20.6247180574413,18.732843,0,0,0,40,4374,76.06735,99.3960113525391,,,,,,,,,,,,,0,,,,-0.00245,,,,,,74.5448303,,,,
,30893199.765,78.0136337,99.3960113525391,-2.59333677627603E-7,3.4900405364633E-7,1,0.999253354069792,40.0298881530762,2.00845399002353,16.1099992692471,-2.76978210124266E-6,-1.60679169497073E-6,0.25,-9.4706122390879E-8,-2.60210810218399E-7,-9.63952682835053E-8,78.0136337,78.0136337,99.3960113525391,99.3960113525391,56.6641595016406,20.6254897027045,18.353191,0,0,0,40,4374,79.63385,99.3960113525391,,,,,,,,,,,,,0,,,,-0.0049,,,,,,78.0136337,,,,
,30893342.96,81.501152,99.3960113525391,-3.38874592569023E-7,2.51190438126418E-7,1,0.999253354069792,40.0298881530762,2.0084580489019,16.1099992692471,-3.2847320061322E-6,-3.99741219065699E-6,0.25,-2.89964230830463E-7,-3.39417061416453E-7,-2.9295710922864E-7,81.501152,81.501152,99.3960113525391,99.3960113525391,57.0831123879483,20.6252953268336,18.353191,0,0,0,40,4374,83.274,99.3960113525391,,,,,,,,,,,,,0,,,,-0.00245,,,,,,81.501152,,,,
,30893483.185,85.0008621,99.3960113525391,-1.50906194745086E-7,2.98006039566012E-7,1,0.999253354069792,40.0298881530762,2.00833638345349,16.0799995064735,-9.45416342686569E-7,-4.71167583371397E-6,0.25,-3.85752027443713E-7,-1.50182356956208E-7,-3.88450933263291E-7,85.0008621,85.0008621,99.3960113525391,99.3960113525391,57.0409044479099,20.6254479938295,18.353191,0,0,0,40,4374,86.8196,99.3960113525391,,,,,,,,,,,,,0,,,,0,,,,,,85.0008621,,,,
,30893627.235,88.5723953,99.3960113525391,-2.20810302532048E-7,2.83962399513188E-7,1,0.999253354069792,40.0298881530762,2.00834866812087,16.0799995064735,-1.85533134095243E-6,-4.23062561523805E-6,0.25,-3.31300330273596E-7,-2.20799413432876E-7,-3.33955879631464E-7,88.5723953,88.5723953,99.3960113525391,99.3960113525391,56.8861420011022,20.6277016999351,19.492144,0,0,0,40,4374,90.4118,99.3960113525391,,,,,,,,,,,,,0,,,,0,,,,,,88.5723953,,,,
,30893765.705,92.0105667,99.3960113525391,-1.09556048479989E-7,2.86694743180129E-7,1,0.999253354069792,40.0298881530762,2.00836517191122,16.0799995064735,-1.05586895003932E-6,-1.33390642955695E-6,0.25,-9.74275905303365E-8,-1.09830988838655E-7,-9.83546879004004E-8,92.0105667,92.0105667,99.3960113525391,99.3960113525391,56.9088092281599,20.6268576599881,19.112494,0,0,0,40,4374,93.89055,99.3960113525391,,,,,,,,,,,,,0,,,,0,,,,,,92.0105667,,,,
,30893908.57,95.5637283,99.3960113525391,-4.23070092112716E-7,2.73841271976392E-7,1,0.999253354069792,40.0298881530762,2.00832430503994,16.0499997437,-4.49114282007075E-6,-2.80556006295976E-6,0.25,-1.71065458887733E-7,-4.24902640918841E-7,-1.73408426724544E-7,95.5637283,95.5637283,99.3960113525391,99.3960113525391,56.7673344661791,20.6247255521889,19.492144,0,0,0,40,4374,97.4758,99.3960113525391,,,,,,,,,,,,,0,,,,0.00245,,,,,,95.5637283,,,,
,30894045.945,99.0141602,99.3960113525391,-1.42920365758437E-7,2.83783771994807E-7,1,0.999253354069792,40.0298881530762,2.00823399652808,16.0499997437,-7.57700622377549E-7,-5.27062431631072E-6,0.25,-4.36064853365688E-7,-1.42396021994177E-7,-4.38974004653309E-7,99.0141602,99.0141602,99.3960113525391,99.3960113525391,56.7845302936022,20.6287224573976,19.871798,0,0,0,40,4374,100.9228,99.3960113525391,,,,,,,,,,,,,0,,,,0.0049,,,,,,99.0141602,,,,
,30894188.15,102.5178604,99.3960113525391,-2.73963026102172E-7,3.22041345216501E-7,1,0.999253354069792,40.0298881530762,2.00832149006139,16.0499997437,-2.67684878186242E-6,-3.13850991663145E-6,0.25,-2.26509367093308E-7,-2.74865606169658E-7,-2.28583183574404E-7,102.5178604,102.5178604,99.3960113525391,99.3960113525391,56.7493570102368,20.6266072340936,19.871798,0,0,0,40,4374,104.50615,99.3960113525391,,,,,,,,,,,,,0,,,,-0.0049,,,,,,102.5178604,,,,
,30894328.005,106.0322647,99.3960113525391,-2.04882996407071E-7,3.01814020824456E-7,1,0.999253354069792,40.0298881530762,1.98440395193548,16.0099994391203,-1.54015843491358E-6,-4.82528970116628E-6,0.25,-3.91097345171169E-7,-2.04980817800444E-7,-3.9386922783773E-7,106.0322647,106.0322647,99.3960113525391,99.3960113525391,56.7993812354675,20.6254116347591,19.112494,0,0,0,40,4374,108.0276,99.3960113525391,,,,,,,,,,,,,0,,,,0.0049,,,,,,106.0322647,,,,
,30894470.09,109.5181427,99.3960113525391,-6.19038210346476E-7,2.71205111962632E-7,1,0.999253354069792,40.0298881530762,1.98446268809888,16.0099994391203,-5.92055814311681E-6,-7.35922302845124E-6,0.25,-5.42789927002642E-7,-6.21137243410264E-7,-5.47443351847224E-7,109.5181427,109.5181427,99.3960113525391,99.3960113525391,56.7595181809868,20.6263216032186,19.492144,0,0,0,40,4374,111.60915,99.3960113525391,,,,,,,,,,,,,0,,,,0.0049,,,,,,109.5181427,,,,
,30894610.45,113.0333633,99.3960113525391,-1.76263918857533E-7,2.99513005029401E-7,1,0.999253354069792,40.0298881530762,1.98432375831843,16.0099994391203,-1.81323869454152E-6,-1.36777697805562E-6,0.25,-9.01908998660461E-8,-1.77033133305895E-7,-9.11264734655577E-8,113.0333633,113.0333633,99.3960113525391,99.3960113525391,56.7118388413137,20.6268421902065,19.492144,0,0,0,40,4374,115.1357,99.3960113525391,,,,,,,,,,,,,0,,,,-0.00245,,,,,,113.0333633,,,,
,30894750.78,116.5076294,99.3960113525391,-3.42480233854435E-7,3.08278234710137E-7,1,0.999253354069792,40.0298881530762,1.98451655535669,15.9699991345406,-3.80101058437269E-6,-1.07176172429497E-6,0.25,-3.49283055951403E-8,-3.44307167035115E-7,-3.59163184968622E-8,116.5076294,116.5076294,99.3960113525391,99.3960113525391,56.8916134007368,20.6237412100074,19.871798,0,0,0,40,4374,118.6618,99.3960113525391,,,,,,,,,,,,,0,,,,0,,,,,,116.5076294,,,,
,30894893.075,120.0260544,99.3960113525391,-2.29955323741773E-8,2.78908684469412E-7,1,0.999253354069792,40.0298881530762,1.98448984593991,15.9699991345406,-1.08876399093878E-7,-9.0889106167898E-7,0.25,-7.64149938661858E-8,-2.29539692990044E-8,-7.68877190237054E-8,120.0260544,120.0260544,99.3960113525391,99.3960113525391,56.6477453027368,20.6256495252526,20.251448,0,0,0,40,4374,122.2388,99.3960113525391,,,,,,,,,,,,,0,,,,0,,,,,,120.0260544,,,,
,30895033.01,123.5351486,99.3960113525391,-1.2964484834913E-7,3.02676293430912E-7,1,0.999253354069792,40.0298881530762,1.98439997523087,15.9699991345406,-7.65940390926167E-7,-4.25562243323487E-6,0.25,-3.53993052492943E-7,-1.29608128360848E-7,-3.56201534136622E-7,123.5351486,123.5351486,99.3960113525391,99.3960113525391,56.9369478548522,20.6280182075761,19.871798,0,0,0,40,4374,125.7584,99.3960113525391,,,,,,,,,,,,,0,,,,0.0049,,,,,,123.5351486,,,,
,30895153.4,126.5270844,99.3960113525391,-9.60110779171996E-8,2.80616401160454E-7,1,0.999253354069792,40.0298881530762,2.00860906329024,15.9200001507998,-1.03508856807701E-7,-5.8822324346642E-6,0.25,-4.97870686023843E-7,-9.55217730998795E-8,-5.00761850808401E-7,126.5270844,126.5270844,99.3960113525391,99.3960113525391,56.5508233663521,20.6244806011753,19.871798,0,0,0,40,4374,128.7782,99.3960113525391,,,,,,,,,,,,,0,,,,0,,,,,,126.5270844,,,,
,30895294.48,130.0132446,99.3960113525391,-2.0962202055721E-7,2.45462691310899E-7,1,0.999253354069792,40.0298881530762,2.00859423983825,15.9200001507998,-2.08306705658808E-6,-2.20974227117506E-6,0.25,-1.56749366824601E-7,-2.10439478850701E-7,-1.57995305094515E-7,130.0132446,130.0132446,99.3960113525391,99.3960113525391,56.9846271945253,20.6236660091303,20.251448,0,0,0,40,4374,132.3191,99.3960113525391,,,,,,,,,,,,,0,,,,0.00245,,,,,,130.0132446,,,,
,30895435.275,133.5222626,99.3960113525391,-8.95018058597707E-8,3.06759103575313E-7,1,0.999253354069792,40.0298881530762,2.00851559320048,15.9200001507998,-1.02535376517806E-6,-1.64041441915299E-7,0.25,1.2626069923514E-9,-8.99769239724741E-8,1.10250764238756E-9,133.5222626,133.5222626,99.3960113525391,99.3960113525391,56.9893169656406,20.624742891902,20.631098,0,0,0,40,4374,135.8593,99.3960113525391,,,,,,,,,,,,,0,,,,0.0049,,,,,,133.5222626,,,,
,30895555.305,136.5441742,99.3960113525391,1.63324198376742E-7,2.8701647835322E-7,1,0.999253354069792,40.0298881530762,1.99603836732484,15.87999984622,1.81189101096807E-6,5.7262580703241E-7,0.25,2.19207841734424E-8,1.64137060481124E-7,2.2329391421894E-8,136.5441742,136.5441742,99.3960113525391,99.3960113525391,57.0878021590637,20.6251390794004,20.251448,0,0,0,40,4374,138.8673,99.3960113525391,,,,,,,,,,,,,0,,,,0.0049,,,,,,136.5441742,,,,
,30895695.96,140.0292816,99.3960113525391,7.40518909565334E-8,2.92222763626301E-7,1,0.999253354069792,40.0298881530762,1.99600244312256,15.87999984622,1.23536097278937E-6,-2.11436444851918E-6,0.25,-1.99053844908604E-7,7.47778364691519E-8,-1.99949065000719E-7,140.0292816,140.0292816,99.3960113525391,99.3960113525391,57.0862389020253,20.6257118470267,20.251448,0,0,0,40,4374,142.39185,99.3960113525391,,,,,,,,,,,,,0,,,,-0.00245,,,,,,140.0292816,,,,
,30895837.51,143.5463715,99.3960113525391,3.19069431605396E-7,3.04602389426528E-7,1,0.999253354069792,40.0298881530762,1.99600027297703,15.87999984622,3.43544093192242E-6,1.71352279976542E-6,0.25,9.52539356259923E-8,3.20525384621999E-7,9.62692090349495E-8,143.5463715,143.5463715,99.3960113525391,99.3960113525391,56.689171614256,20.6265177445617,20.631098,0,0,0,40,4374,145.9498,99.3960113525391,,,,,,,,,,,,,0,,,,0,,,,,,143.5463715,,,,
,30895977.125,147.0281219,99.3960113525391,6.78931395217932E-8,2.82373857385533E-7,1,0.999253354069792,40.0298881530762,2.00869756137502,15.8300008624792,1.35131163646019E-6,-3.16826002947698E-6,0.25,-2.89110873179464E-7,6.86975547002356E-8,-2.90440843837343E-7,147.0281219,147.0281219,99.3960113525391,99.3960113525391,56.9134989992753,20.6250964390217,20.251448,0,0,0,40,4374,149.45365,99.3960113525391,,,,,,,,,,,,,0,,,,0.0049,,,,,,147.0281219,,,,
,30896117.82,150.5259857,99.3960113525391,-9.36449222515789E-8,3.01761191109345E-7,1,0.999253354069792,40.0298881530762,2.00866732884256,15.8300008624792,-1.52959610044389E-6,2.45291366503656E-6,0.25,2.31005794520041E-7,-9.44632905571807E-8,2.31990069413435E-7,150.5259857,150.5259857,99.3960113525391,99.3960113525391,56.8150138058522,20.6259714471401,20.631098,0,0,0,40,4374,152.97555,99.3960113525391,,,,,,,,,,,,,0,,,,-0.0049,,,,,,150.5259857,,,,
,30896255.795,154.0163116,99.3960113525391,2.51221471255963E-7,3.35900481681409E-7,1,0.999253354069792,40.0298881530762,2.00859757594147,15.8300008624792,2.75739333420462E-6,1.14588113710957E-6,0.25,5.65626341981926E-8,2.52342969117379E-7,5.72136323496524E-8,154.0163116,154.0163116,99.3960113525391,99.3960113525391,57.1729996676599,20.6271527396046,20.631098,0,0,0,40,4374,156.4354,99.3960113525391,,,,,,,,,,,,,0,,,,0,,,,,,154.0163116,,,,
,30896398.04,157.5394592,99.3960113525391,5.49885533779139E-8,3.40574543180036E-7,1,0.999253354069792,40.0298881530762,1.98460186714005,15.7800000160933,7.36549693765094E-7,-5.55912343766417E-7,0.25,-5.88002923271274E-8,5.53336329590977E-8,-5.89969805542761E-8,157.5394592,157.5394592,99.3960113525391,99.3960113525391,57.0815491309099,20.6259178947197,21.01075,0,0,0,40,4374,160.0086,99.3960113525391,,,,,,,,,,,,,0,,,,0,,,,,,157.5394592,,,,
,30896537.85,161.0286942,99.3960113525391,5.81463698531092E-7,2.91729077401001E-7,1,0.999253354069792,40.0298881530762,1.98447496043488,15.7800000160933,6.82814927786923E-6,-3.68033295895555E-7,0.25,-1.33788058287474E-7,5.84339076426909E-7,-1.33581422378832E-7,160.9993134,161.058075,99.3960113525391,99.3960113525391,56.8470605751406,20.6303402425613,20.631098,0,0,0,40,4374,163.51455,99.3960113525391,,,,,,,,,,,,,0,,,,0.0049,,,,,,161.0286942,,,,
,30896677.92,164.5411072,99.3960113525391,3.24910805728885E-7,2.8182252758915E-7,1,0.999253354069792,40.0298881530762,1.98426734008253,15.7800000160933,3.61331774338253E-6,9.51586517639206E-7,0.25,2.77640186558138E-8,3.26341989240004E-7,2.83369778717566E-8,164.5411072,164.5411072,99.3960113525391,99.3960113525391,56.8259566051214,20.6339452969656,20.631098,0,0,0,40,4374,167.0186,99.3960113525391,,,,,,,,,,,,,0,,,,0,,,,,,164.5411072,,,,
,30896818.805,168.052887,99.3960113525391,4.86770346026483E-7,3.40098507257124E-7,1,0.999253354069792,40.0298881530762,2.0087513120558,15.7299991697073,5.52768933865546E-6,1.14838941663378E-6,0.25,1.58805155297443E-8,4.88902701937617E-7,1.66021159630958E-8,168.052887,168.052887,99.3960113525391,99.3960113525391,56.8697278021983,20.6235711793518,21.01075,0,0,0,40,4374,170.5453,99.3960113525391,,,,,,,,,,,,,0,,,,0,,,,,,168.052887,,,,
,30896959.68,171.5512543,99.3960113525391,5.49395405974542E-7,3.13067895900981E-7,1,0.999253354069792,40.0298881530762,2.00849481958627,15.7299991697073,6.30193929083434E-6,9.25192362532671E-7,0.25,-1.45183574152243E-8,5.51790170717308E-7,-1.38661177431193E-8,171.5512543,171.5512543,99.3960113525391,99.3960113525391,56.8689461736791,20.6297422898761,20.631098,0,0,0,40,4374,174.0717,99.3960113525391,,,,,,,,,,,,,0,,,,-0.00245,,,,,,171.5512543,,,,
,30897097.92,175.0364075,99.3960113525391,4.65034304491249E-7,2.58478359481224E-7,1,0.999253354069792,40.0298881530762,2.0084580255821,15.7299991697073,6.15547133320539E-6,-3.94357057093609E-6,0.25,-4.26273298552982E-7,4.6753861298028E-7,-4.27484065769266E-7,175.0364075,175.0364075,99.3960113525391,99.3960113525391,57.095618444256,20.6306316307924,21.3904,0,0,0,40,4374,177.5269,99.3960113525391,,,,,,,,,,,,,0,,,,-0.0049,,,,,,175.0364075,,,,
,30897238.82,178.5636292,99.3960113525391,5.97353265123613E-7,3.19392840048032E-7,1,0.999253354069792,40.0298881530762,2.00827086327424,15.6800001859665,7.30006960889155E-6,-1.58383487883675E-6,0.25,-2.4259897181828E-7,6.0011342541589E-7,-2.42860513056706E-7,178.5636292,178.5636292,99.3960113525391,99.3960113525391,57.0924919301791,20.6259462417781,21.3904,0,0,0,40,4374,181.048,99.3960113525391,,,,,,,,,,,,,0,,,,-0.0049,,,,,,178.5636292,,,,
,30897378.29,182.02308655,99.3960113525391,8.12283864185441E-7,2.68583657471217E-7,1,0.999253354069792,40.0298881530762,2.00835024159336,15.6800001859665,9.43644983557374E-6,6.62409505151958E-7,0.25,-8.31506177936307E-8,8.15645644541524E-7,-8.25061710607816E-8,181.989151,182.0570221,99.3960113525391,99.3960113525391,56.9650864815445,20.62634391227,21.01075,0,0,0,40,4374,184.53985,99.3960113525391,,,,,,,,,,,,,0,,,,-0.00245,,,,,,182.02308655,,,,
,30897520.575,185.5471191,99.3960113525391,8.73450885143708E-7,3.15962065218615E-7,1,0.999253354069792,40.0298881530762,2.00827876635072,15.6800001859665,1.06832805172241E-5,-2.38192022575534E-6,0.25,-3.60500666499682E-7,8.77288033516566E-7,-3.60883518440879E-7,185.5471191,185.5471191,99.3960113525391,99.3960113525391,56.9510171681983,20.6270569498457,21.770052,0,0,0,40,4374,188.11395,99.3960113525391,,,,,,,,,,,,,0,,,,0.0049,,,,,,185.5471191,,,,
,30897639.645,188.5530853,99.3960113525391,1.046193809044E-6,3.40261531756741E-7,1,0.999253354069792,40.0298881530762,2.00846751921463,15.6299993395805,1.21697711884863E-5,7.50851272361023E-7,0.25,-1.15992792385645E-7,1.05031919214682E-6,-1.15231075156341E-7,188.5530853,188.5530853,99.3960113525391,99.3960113525391,56.8454973181022,20.6247194608565,21.01075,0,0,0,40,4374,191.09745,99.3960113525391,,,,,,,,,,,,,0,,,,0,,,,,,188.5530853,,,,
,30897781.38,192.0489655,99.3960113525391,7.78777870914028E-7,3.45786884572067E-7,1,0.999253354069792,40.0298881530762,2.00867985448868,15.6299993395805,9.73677259162326E-6,-3.3424896168913E-6,0.25,-4.28176374586616E-7,7.82145952147993E-7,-4.28887935017794E-7,192.0489655,192.0489655,99.3960113525391,99.3960113525391,56.7884384361983,20.6253955324789,21.3904,0,0,0,40,4374,194.65425,99.3960113525391,,,,,,,,,,,,,0,,,,-0.00245,,,,,,192.0489655,,,,
,30897920.95,195.5621033,99.3960113525391,1.67658150149738E-6,3.17209150017349E-7,1,0.999253354069792,40.0298881530762,2.00865774464869,15.6299993395805,1.98078521200536E-5,-5.68648602105738E-7,0.25,-3.41062564763766E-7,1.6829851064203E-6,-3.40446340422018E-7,195.5621033,195.5621033,99.3960113525391,99.3960113525391,57.220679007333,20.6238453519857,21.770052,0,0,0,40,4374,198.1647,99.3960113525391,,,,,,,,,,,,,0,,,,-0.00245,,,,,,195.5621033,,,,
,30898040.61,198.5389252,99.3960113525391,1.67510241346374E-6,2.78229062609477E-7,1,0.999253354069792,40.0298881530762,1.98455075088345,15.5800003558397,1.94195965184565E-5,2.56543022178327E-7,0.25,-2.68193477160075E-7,1.68125617406507E-6,-2.67325994636144E-7,198.5389252,198.5389252,99.3960113525391,99.3960113525391,56.7532651528329,20.6233549490728,21.770052,0,0,0,40,4374,201.1674,99.3960113525391,,,,,,,,,,,,,0,,,,0.0049,,,,,,198.5389252,,,,
,30898180.485,202.0108337,99.3960113525391,1.41149830428371E-6,3.20312036911464E-7,1,0.999253354069792,40.0298881530762,1.98465752986201,15.5800003558397,1.61354673431982E-5,1.52391184863423E-6,0.25,-1.1000773682632E-7,1.41639837694567E-6,-1.08891076305676E-7,202.0108337,202.0108337,99.3960113525391,99.3960113525391,56.6579064734868,20.6228695826725,21.3904,0,0,0,40,4374,204.67875,99.3960113525391,,,,,,,,,,,,,0,,,,-0.0049,,,,,,202.0108337,,,,
,30898320.81,205.5087433,99.3960113525391,1.65152577090923E-6,2.94539645582016E-7,1,0.999253354069792,40.0298881530762,1.98484791197052,15.5800003558397,1.92581864416386E-5,-4.01423445311607E-7,0.25,-3.22358308743323E-7,1.65726857401882E-6,-3.2170789011938E-7,205.5087433,205.5087433,99.3960113525391,99.3960113525391,57.0901470446214,20.6208050788046,21.770052,0,0,0,40,4374,208.1841,99.3960113525391,,,,,,,,,,,,,0,,,,-0.0049,,,,,,205.5087433,,,,
,30898461.23,209.0338135,99.3960113525391,1.86844891623133E-6,3.33028668212028E-7,1,0.999253354069792,40.0298881530762,2.00896269865126,15.5199998989701,2.18704196273179E-5,5.03770558374233E-7,0.25,-2.80232976437765E-7,1.87463670974927E-6,-2.7922771725179E-7,209.0338135,209.0338135,99.3960113525391,99.3960113525391,57.0463758475445,20.6164619336869,21.770052,0,0,0,40,4374,211.7054,99.3960113525391,,,,,,,,,,,,,0,,,,0.0049,,,,,,209.0338135,,,,
,30898603.6,212.56053925,99.3960113525391,2.35756608367629E-6,3.64935610577093E-7,1,0.999253354069792,40.0298881530762,2.00881090370406,15.5199998989701,2.6111622697744E-5,9.15357918538483E-6,0.25,3.93265347039908E-7,2.36435092284958E-6,3.96799314499815E-7,212.5264893,212.5945892,99.3960113525391,99.3960113525391,56.9119357422368,20.617217039631,21.3904,0,0,0,40,4374,215.27195,99.3960113525391,,,,,,,,,,,,,0,,,,0,,,,,,212.56053925,,,,
,30898741.5,216.0012665,99.3960113525391,2.73664649636735E-6,3.59518040112828E-7,1,0.999253354069792,40.0298881530762,1.99632541321986,15.5199998989701,3.06769729495441E-5,7.39318823880282E-6,0.25,1.77112363427869E-7,2.74448850211631E-6,1.80291655007918E-7,216.0012665,216.0012665,99.3960113525391,99.3960113525391,56.7665528376599,20.6216380860478,21.770052,0,0,0,40,4374,218.7191,99.3960113525391,,,,,,,,,,,,,0,,,,0,,,,,,216.0012665,,,,
,30898883.98,219.5597229,99.3960113525391,2.97646371397208E-6,3.5607856135215E-7,1,0.999253354069792,40.0298881530762,2.00901727564126,15.4699999839067,3.40537490438607E-5,5.26490345746308E-6,0.25,-5.49300465285882E-8,2.98487653982328E-6,-5.22473554821528E-8,219.5597229,219.5597229,99.3960113525391,99.3960113525391,56.9385111118906,20.6222785731862,21.770052,0,0,0,40,4374,222.2983,99.3960113525391,,,,,,,,,,,,,0,,,,-0.00245,,,,,,219.5597229,,,,
,30899023.275,223.0314789,99.3960113525391,2.86920504117579E-6,2.80474091196907E-7,1,0.999253354069792,40.0298881530762,2.00897666568078,15.4699999839067,3.34651802677843E-5,1.36882791343267E-6,0.25,-3.77872943866519E-7,2.87728040661351E-6,-3.76206547252789E-7,223.0314789,223.0314789,99.3960113525391,99.3960113525391,56.8751992018329,20.6229269313571,22.149702,0,0,0,40,4374,225.7897,99.3960113525391,,,,,,,,,,,,,0,,,,0,,,,,,223.0314789,,,,
,30899164.805,226.5928192,99.3960113525391,3.80839475347198E-6,3.54825428216989E-7,1,0.999253354069792,40.0298881530762,2.00901816834158,15.4699999839067,4.34522006525147E-5,7.36467895083252E-6,0.25,-1.49104045941177E-8,3.8181957810292E-6,-1.14538247029165E-8,226.5928192,226.5928192,99.3960113525391,99.3960113525391,56.8595666314483,20.6238037429036,22.149702,0,0,0,40,4374,229.34255,99.3960113525391,,,,,,,,,,,,,0,,,,0,,,,,,226.5928192,,,,
,30899304.05,230.0172729,99.3960113525391,4.14159081636389E-6,4.17810057711821E-7,1,0.999253354069792,40.0298881530762,1.99645229759201,15.4200000688434,4.71891230466944E-5,6.67607636862855E-6,0.25,-1.29467387207717E-7,4.15186491422944E-6,-1.2605306451024E-7,230.0172729,230.0172729,99.3960113525391,99.3960113525391,56.9017745714868,20.6180746095493,22.149702,0,0,0,40,4374,232.8317,99.3960113525391,,,,,,,,,,,,,0,,,,-0.00245,,,,,,230.0172729,,,,
,30899444.29,233.5543365,99.3960113525391,4.70358995955848E-6,3.27925693954596E-7,1,0.999253354069792,40.0298881530762,1.99652078362021,15.4200000688434,5.38309848455612E-5,6.1791253110337E-6,0.25,-2.70703066282016E-7,4.71479145738365E-6,-2.67171581613456E-7,233.5543365,233.5543365,99.3960113525391,99.3960113525391,56.8666012881214,20.6218602977658,22.529354,0,0,0,40,4374,236.33955,99.3960113525391,,,,,,,,,,,,,0,,,,-0.00245,,,,,,233.5543365,,,,
,30899585.315,237.0566559,99.3960113525391,4.67013081047564E-6,3.8923148831899E-7,1,0.999253354069792,40.0298881530762,1.99640956888678,15.4200000688434,5.37743220055501E-5,4.19929799353021E-6,0.25,-4.39478380095013E-7,4.68082981450284E-6,-4.36389963805238E-7,237.0566559,237.0566559,99.3960113525391,99.3960113525391,56.8439340610637,20.6206250470452,22.149702,0,0,0,40,4374,239.8812,99.3960113525391,,,,,,,,,,,,,0,,,,-0.00245,,,,,,237.0566559,,,,
,30899725.22,240.5221863,99.3960113525391,5.66938645233492E-6,3.76341512759697E-7,1,0.999253354069792,40.0298881530762,1.98500040019528,15.37000015378,6.41394984950425E-5,9.54665921258935E-6,0.25,-1.3602575470584E-7,5.68134284624086E-6,-1.31467574464292E-7,240.5221863,240.5221863,99.3960113525391,99.3960113525391,56.6422739031022,20.6179540307713,22.529354,0,0,0,40,4374,243.3956,99.3960113525391,,,,,,,,,,,,,0,,,,0.00245,,,,,,240.5221863,,,,
,30899866.615,244.0518494,99.3960113525391,6.20282059787681E-6,3.90930375165491E-7,1,0.999253354069792,40.0298881530762,1.98480993404089,15.37000015378,6.99582189966632E-5,1.16020147672549E-5,0.25,-4.5808262057751E-8,6.21504728878572E-6,-4.06918267313298E-8,244.0518494,244.0518494,99.3960113525391,99.3960113525391,56.6954246424098,20.6186438680643,22.529354,0,0,0,40,4374,246.9412,99.3960113525391,,,,,,,,,,,,,0,,,,0,,,,,,244.0518494,,,,
,30900006.315,247.5529175,99.3960113525391,6.44818589495212E-6,4.44970468706681E-7,1,0.999253354069792,40.0298881530762,1.98468131917618,15.37000015378,7.21798506737604E-5,1.51279038859866E-5,0.25,2.24995336095306E-7,6.45987746415223E-6,2.30731323415553E-7,247.5529175,247.5529175,99.3960113525391,99.3960113525391,56.8329912617945,20.6207762773883,22.529354,0,0,0,40,4374,250.4398,99.3960113525391,,,,,,,,,,,,,0,,,,0,,,,,,247.5529175,,,,
,30900126.48,250.5119934,99.3960113525391,7.4123516818219E-6,3.49360971063118E-7,1,0.999253354069792,40.0298881530762,1.98488826317953,15.3000000864267,8.48705116638065E-5,6.44313955234316E-6,0.25,-7.13283409971628E-7,7.42581214172279E-6,-7.08492601294635E-7,250.5119934,250.5119934,99.3960113525391,99.3960113525391,56.8228300910445,20.6177251416156,22.529354,0,0,0,40,4374,253.4404,99.3960113525391,,,,,,,,,,,,,0,,,,0,,,,,,250.5119934,,,,
,30900267.34,254.0516052,99.3960113525391,7.9329727978293E-6,3.55949446190886E-7,1,0.999253354069792,40.0298881530762,1.98464297314137,15.3000000864267,9.00668638158485E-5,1.11760754525734E-5,0.25,-3.82958832595121E-7,7.94607121397061E-6,-3.77229389096461E-7,254.0218658,254.0813446,99.3960113525391,99.3960113525391,56.8298647477175,20.6244691878944,22.909004,0,0,0,40,4374,256.9817,99.3960113525391,,,,,,,,,,,,,0,,,,-0.0049,,,,,,254.0516052,,,,
,30900408.22,257.5557556,99.3960113525391,8.64367524199297E-6,4.84114972812405E-7,1,0.999253354069792,40.0298881530762,1.98486876642114,15.3000000864267,9.7495541545448E-5,1.58607984062885E-5,0.25,-8.9981956635186E-8,8.65661015243113E-6,-8.33133983954141E-8,257.5557556,257.5557556,99.3960113525391,99.3960113525391,56.8892685151791,20.6224536757416,22.529354,0,0,0,40,4374,260.5286,99.3960113525391,,,,,,,,,,,,,0,,,,-0.00245,,,,,,257.5557556,,,,
,30900527.44,260.51602175,99.3960113525391,8.61625216284877E-6,4.00733357309601E-7,1,0.999253354069792,40.0298881530762,2.0089512338916,15.2500001713634,9.81430651342892E-5,1.69026971050201E-5,0.25,-9.62218656278255E-9,8.62817631978815E-6,-2.94669484479664E-9,260.4852295,260.546814,99.3960113525391,99.3960113525391,56.7431039820829,20.616761120787,22.529354,0,0,0,40,4374,263.50585,99.3960113525391,,,,,,,,,,,,,0,,,,0,,,,,,260.51602175,,,,
,30900669.39,264.0469971,99.3960113525391,9.84152068634708E-6,3.6527079034498E-7,1,0.999253354069792,40.0298881530762,2.00897761882376,15.2500001713634,0.000111606020563062,2.20771689150749E-5,0.25,2.32655358254273E-7,9.85371650777655E-6,2.40465997477888E-7,264.0469971,264.0469971,99.3960113525391,99.3960113525391,56.9377294833714,20.6220049174412,22.149702,0,0,0,40,4374,267.04855,99.3960113525391,,,,,,,,,,,,,0,,,,-0.0049,,,,,,264.0469971,,,,
,30900808.71,267.5490417,99.3960113525391,1.021291235275E-5,3.87760660558056E-7,1,0.999253354069792,40.0298881530762,2.00876277795967,15.2500001713634,0.000116106459138115,2.10881378276047E-5,0.25,8.19535333051529E-8,1.02244147788232E-5,8.972720683486E-8,267.5490417,267.5490417,99.3960113525391,99.3960113525391,57.0565370182945,20.6233300261614,22.529354,0,0,0,40,4374,270.53575,99.3960113525391,,,,,,,,,,,,,0,,,,-0.0049,,,,,,267.5490417,,,,
,30900949.42,271.0234985,99.3960113525391,1.09735579257702E-5,4.04596870473395E-7,1,0.999253354069792,40.0298881530762,1.98487438571457,15.2099998667836,0.000123872559328296,1.92242079901086E-5,0.25,-1.93901171912824E-7,1.09847642511282E-5,-1.85970793983305E-7,271.0234985,271.0234985,99.3960113525391,99.3960113525391,56.5938129349098,20.6165430907642,22.909004,0,0,0,40,4374,274.0433,99.3960113525391,,,,,,,,,,,,,0,,,,-0.0049,,,,,,271.0234985,,,,
,30901090.84,274.5440979,99.3960113525391,1.12727844873229E-5,4.79980405484147E-7,1,0.999253354069792,40.0298881530762,1.98494651265403,15.2099998667836,0.000127801445996958,1.64998100529009E-5,0.25,-4.87593132377119E-7,1.12830843777672E-5,-4.79804727160775E-7,274.5440979,274.5440979,99.3960113525391,99.3960113525391,56.7876568076791,20.6171127805838,22.909004,0,0,0,40,4374,277.60535,99.3960113525391,,,,,,,,,,,,,0,,,,0,,,,,,274.5440979,,,,
,30901230.67,278.0474548,99.3960113525391,1.1845842326807E-5,3.87641609543146E-7,1,0.999253354069792,40.0298881530762,1.9847120501665,15.2099998667836,0.000134353814865512,1.68292066408106E-5,0.25,-5.5716181480111E-7,1.18552060797895E-5,-5.49076202541897E-7,278.0474548,278.0474548,99.3960113525391,99.3960113525391,56.8900501436983,20.6237591118571,22.909004,0,0,0,40,4374,281.0971,99.3960113525391,,,,,,,,,,,,,0,,,,0.0049,,,,,,278.0474548,,,,
,30901369.075,281.5172729,99.3960113525391,1.24007380862999E-5,4.61681538187727E-7,1,0.999253354069792,40.0298881530762,2.00902679610667,15.1399997994304,0.00014014674055141,3.00941060050568E-5,0.25,4.95301808167643E-7,1.24082292796818E-5,5.04390642133734E-7,281.5172729,281.5172729,99.3960113525391,99.3960113525391,56.6031924771406,20.6199496846393,23.288654,0,0,0,40,4374,284.55095,99.3960113525391,,,,,,,,,,,,,0,,,,-0.0049,,,,,,281.5172729,,,,
,30901511.99,285.0563049,99.3960113525391,1.22078042865239E-5,3.72273087943223E-7,1,0.999253354069792,40.0298881530762,2.00892125427629,15.1399997994304,0.000139886406904461,1.84001984031507E-5,0.25,-4.98407806037227E-7,1.22143233045939E-5,-4.9014976272706E-7,285.0563049,285.0563049,99.3960113525391,99.3960113525391,56.5719273363714,20.6201559871862,22.909004,0,0,0,40,4374,288.1307,99.3960113525391,,,,,,,,,,,,,0,,,,0.0049,,,,,,285.0563049,,,,
,30901650.6,288.5030823,99.3960113525391,1.36773124844063E-5,4.19309029916626E-7,1,0.999253354069792,40.0298881530762,2.00895050633381,15.1399997994304,0.000156252668383168,2.32401006218852E-5,0.25,-3.27341108618034E-7,1.3682762951024E-5,-3.18069052175732E-7,288.4761658,288.5299988,99.3960113525391,99.3960113525391,56.7493570102368,20.6244773262776,23.288654,0,0,0,40,4374,291.62515,99.3960113525391,,,,,,,,,,,,,0,,,,0,,,,,,288.5030823,,,,
,30901792.79,292.0108032,99.3960113525391,1.32592549466077E-5,3.35819697736233E-7,1,0.999253354069792,40.0298881530762,1.99648853812282,15.0800002738833,0.000149691526971652,2.7412414688542E-5,0.25,1.26612908552759E-7,1.32625696004567E-5,1.35624360583034E-7,292.0108032,292.0108032,99.3960113525391,99.3960113525391,56.5680191937752,20.6086442331953,22.529354,0,0,0,40,4374,295.1597,99.3960113525391,,,,,,,,,,,,,0,,,,-0.0049,,,,,,292.0108032,,,,
,30901935.815,295.572998,99.3960113525391,1.37300063641066E-5,3.86925057320957E-7,1,0.999253354069792,40.0298881530762,1.99653419271521,15.0800002738833,0.00015543001644672,2.5841720462496E-5,0.25,-9.34792994398997E-8,1.37318400703155E-5,-8.43275637110991E-8,295.572998,295.572998,99.3960113525391,99.3960113525391,56.926005055583,20.6139062966929,22.909004,0,0,0,40,4374,298.75415,99.3960113525391,,,,,,,,,,,,,0,,,,0.0049,,,,,,295.572998,,,,
,30902072.305,299.000061,99.3960113525391,1.41948552107488E-5,3.42789507146729E-7,1,0.999253354069792,40.0298881530762,1.99656139768293,15.0800002738833,0.000161234101728544,2.34850471596467E-5,0.25,-3.82089718216493E-7,1.41951996180539E-5,-3.72746309501273E-7,299.000061,299.000061,99.3960113525391,99.3960113525391,57.0518472471791,20.6156027835262,23.288654,0,0,0,40,4374,302.17505,99.3960113525391,,,,,,,,,,,,,0,,,,0.00245,,,,,,299.000061,,,,
,30902196.39,302.050354,99.3960113525391,1.36476172625659E-5,3.93328386747543E-7,1,0.999253354069792,40.0298881530762,1.97125645310947,15.0100002065301,0.000153706414310205,1.8942600126611E-5,0.25,-6.682211460666E-7,1.36466557710653E-5,-6.59275886770837E-7,302.050354,302.050354,99.3960113525391,99.3960113525391,56.933039712256,20.6145983780673,22.909004,0,0,0,40,4374,305.2758,99.3960113525391,,,,,,,,,,,,,0,,,,0,,,,,,302.050354,,,,
,30902337.38,305.5527954,99.3960113525391,1.40011437269646E-5,5.35334444984743E-7,1,0.999253354069792,40.0298881530762,1.98529296502072,15.0100002065301,0.000157901108725001,2.44113678376055E-5,0.25,-2.54154519648663E-7,1.39981277217222E-5,-2.45113870785296E-7,305.5527954,305.5527954,99.3960113525391,99.3960113525391,57.0635716749676,20.6128145167208,23.668306,0,0,0,40,4374,308.8175,99.3960113525391,,,,,,,,,,,,,0,,,,-0.0049,,,,,,305.5527954,,,,
,30902477.36,309.0354309,99.3960113525391,1.45985081733795E-5,4.30161482520138E-7,1,0.999253354069792,40.0298881530762,1.98517710115591,15.0100002065301,0.000163882382555022,2.96396047284002E-5,0.25,1.08002882907416E-7,1.45933179553675E-5,1.17207316986384E-7,309.0354309,309.0354309,99.3960113525391,99.3960113525391,56.9822823089676,20.6147229626551,23.288654,0,0,0,40,4374,312.31635,99.3960113525391,,,,,,,,,,,,,0,,,,0,,,,,,309.0354309,,,,
,30902615.49,312.5091248,99.3960113525391,1.46623940307107E-5,4.97859655469602E-7,1,0.999253354069792,40.0298881530762,2.00947350440648,14.9400001391768,0.000166483345391544,3.0216049553301E-5,0.25,1.1763683627184E-7,1.46553703606776E-5,1.26744019458959E-7,312.5091248,312.5091248,99.3960113525391,99.3960113525391,56.821266834006,20.6124027110333,23.288654,0,0,0,40,4374,315.7897,99.3960113525391,,,,,,,,,,,,,0,,,,0.00245,,,,,,312.5091248,,,,
,30902759.12,316.0579834,99.3960113525391,1.44156862477084E-5,4.24652601427383E-7,1,0.999253354069792,40.0298881530762,2.00935162729364,14.9400001391768,0.000163713813476765,2.93459903409912E-5,0.25,8.4441830481405E-8,1.44069924107993E-5,9.32813013833235E-8,316.0579834,316.0579834,99.3960113525391,99.3960113525391,56.7798405224868,20.6160432424442,22.909004,0,0,0,40,4374,319.4016,99.3960113525391,,,,,,,,,,,,,0,,,,0.0049,,,,,,316.0579834,,,,
,30902899.775,319.5439453,99.3960113525391,1.48131229269481E-5,3.60359491390151E-7,1,0.999253354069792,40.0298881530762,2.00922113662938,14.9400001391768,0.000168808923231535,2.66123230490776E-5,0.25,-2.24318592543935E-7,1.48025598384711E-5,-2.15136429962728E-7,319.5439453,319.5439453,99.3960113525391,99.3960113525391,57.1081245005637,20.6184419330355,23.288654,0,0,0,40,4374,322.92255,99.3960113525391,,,,,,,,,,,,,0,,,,0.00245,,,,,,319.5439453,,,,
,30903039.76,323.0322876,99.3960113525391,1.44801828123079E-5,4.63933887339137E-7,1,0.999253354069792,40.0298881530762,2.00942093884286,14.8900002241135,0.000164736657323742,2.7592655481117E-5,0.25,-8.02262813131966E-8,1.44679981580762E-5,-7.14496064398271E-8,323.0322876,323.0322876,99.3960113525391,99.3960113525391,56.790783321756,20.6107639207005,22.909004,0,0,0,40,4374,326.4345,99.3960113525391,,,,,,,,,,,,,0,,,,0,,,,,,323.0322876,,,,
,30903182.34,326.5666199,99.3960113525391,1.43223337761193E-5,4.22141617818144E-7,1,0.999253354069792,40.0298881530762,1.99649550073271,14.8900002241135,0.000161821341699505,2.76950083909143E-5,0.25,-2.84258066929659E-8,1.4308480650693E-5,-1.98902937290382E-8,326.5666199,326.5666199,99.3960113525391,99.3960113525391,56.729816297256,20.6128491386274,23.288654,0,0,0,40,4374,330.0265,99.3960113525391,,,,,,,,,,,,,0,,,,0,,,,,,326.5666199,,,,
,30903321.505,330.039917,99.3960113525391,1.43493199534382E-5,4.06885139834759E-7,1,0.999253354069792,40.0298881530762,1.99659729922163,14.8900002241135,0.000162544419760309,2.52627135548026E-5,0.25,-2.48187766787307E-7,1.4333833709707E-5,-2.39493045814834E-7,330.039917,330.039917,99.3960113525391,99.3960113525391,56.7829670365637,20.613502878721,23.288654,0,0,0,40,4374,333.5226,99.3960113525391,,,,,,,,,,,,,0,,,,-0.00245,,,,,,330.039917,,,,
,30903463.72,333.5324402,99.3960113525391,1.40923738427279E-5,5.66420001426627E-7,1,0.999253354069792,40.0298881530762,1.99672190899306,14.8200001567602,0.00015887499974595,2.91336739330452E-5,0.25,1.39313715208469E-7,1.40752347292163E-5,1.47323110707935E-7,333.5324402,333.5324402,99.3960113525391,99.3960113525391,56.7939098358329,20.610873312078,24.047956,0,0,0,40,4374,337.0636,99.3960113525391,,,,,,,,,,,,,0,,,,0,,,,,,333.5324402,,,,
,30903603.65,337.0070801,99.3960113525391,1.42702828372434E-5,4.84184098253394E-7,1,0.999253354069792,40.0298881530762,1.99656769886319,14.8200001567602,0.000160712078735302,3.02896801303172E-5,0.25,2.11478560083328E-7,1.42511774448028E-5,2.19386172750505E-7,337.0070801,337.0070801,99.3960113525391,99.3960113525391,56.8689461736791,20.616413793691,22.909004,0,0,0,40,4374,340.58185,99.3960113525391,,,,,,,,,,,,,0,,,,0,,,,,,337.0070801,,,,
,30903744.58,340.5596008,99.3960113525391,1.34717207765672E-5,4.24654533858815E-7,1,0.999253354069792,40.0298881530762,1.99653866123501,14.8200001567602,0.000152042182755906,2.6603465838951E-5,0.25,2.36936816081342E-8,1.3452143475747E-5,3.13060962727094E-8,340.5596008,340.5596008,99.3960113525391,99.3960113525391,56.9815006804483,20.6187650183894,23.288654,0,0,0,40,4374,344.1104,99.3960113525391,,,,,,,,,,,,,0,,,,0.00245,,,,,,340.5596008,,,,
,30903884.28,344.0048523,99.3960113525391,1.39430927937816E-5,4.00249912517902E-7,1,0.999253354069792,40.0298881530762,1.99656707714183,14.7700002416968,0.000157804496728299,2.48819270773656E-5,0.25,-2.10109843826579E-7,1.39213236818087E-5,-2.01947752537655E-7,344.0048523,344.0048523,99.3960113525391,99.3960113525391,56.7712426087752,20.6118481190864,23.288654,0,0,0,40,4374,347.5981,99.3960113525391,,,,,,,,,,,,,0,,,,0,,,,,,344.0048523,,,,
,30904027.305,347.5525513,99.3960113525391,1.30935120659977E-5,5.59569422588264E-7,1,0.999253354069792,40.0298881530762,1.99642498756422,14.7700002416968,0.000148538450878072,2.11827817232352E-5,0.25,-3.90267890094879E-7,1.3071600518285E-5,-3.82329169296249E-7,347.5525513,347.5525513,99.3960113525391,99.3960113525391,56.8751992018329,20.6175653197139,23.668306,0,0,0,40,4374,351.1952,99.3960113525391,,,,,,,,,,,,,0,,,,0,,,,,,347.5525513,,,,
,30904400.43,349.788208,99.3960113525391,1.35089304761566E-5,3.69664292801803E-7,1,0.999253354069792,40.0298881530762,1.99625353848068,14.7700002416968,0.000152759167957069,2.45530252556847E-5,0.25,-1.63246515859893E-7,1.34851679874474E-5,-1.55439863686663E-7,349.788208,349.788208,99.3960113525391,99.3960113525391,56.9682129956214,20.6214894754197,23.668306,0,0,0,40,4369,350.7736,99.3960113525391,,,,,,,,,,,,,0,,,,0,,,,,,349.788208,,,,