File: data/doubleLayers/dl_5/ppms/data/DD205_6_HYST_100OE_200K.DAT
[Header]
; VSM Data File (default extension .dat)
; Copyright (c) 2003-2013, Quantum Design, Inc. All rights reserved.
TITLE,
FILEOPENTIME,30998510.84,12/26/2018,2:43 am
BYAPP,VSM,2.0,2.0
INFO,PPMS VSM Option Release 1.4.10 Build 1,APPNAME
INFO,Quantum Design Linear Motor Servo Controller,MOTOR_MODULE_NAME
INFO,3101-100 M1,MOTOR_HW_VERSION
INFO,MMC1014,MOTOR_SERIAL_NUMBER
INFO,SRV No X-over 01.03.11,MOTOR_SOFTWARE_VERSION
INFO,Quantum Design VSM Detection Module,VSM_MODULE_NAME
INFO,3101-150 F0,VSM_HW_VERSION
INFO,VSM707,VSM_SERIAL_NUMBER
INFO,VSM No X-over 01.02.05 May 20 2008 13:51:47,VSM_SOFTWARE_VERSION
INFO,704,PREAMP_SERIAL_NUMBER
INFO,822,COIL_SERIAL_NUMBER
INFO,0,MOMENT_UNITS
INFO,CoFe2O4,SAMPLE_MATERIAL
INFO,AH11 DL,SAMPLE_COMMENT
INFO,30.27,SAMPLE_MASS
INFO,,SAMPLE_VOLUME
INFO,,SAMPLE_MOLECULAR_WEIGHT
INFO,,SAMPLE_SIZE
INFO,,SAMPLE_SHAPE
DATATYPE,COMMENT,1
DATATYPE,TIME,2
STARTUPAXIS,X,2
STARTUPAXIS,Y1,5
[Data]
Comment,Time Stamp (sec),Temperature (K),Magnetic Field (Oe),Moment (emu),M. Std. Err. (emu),Transport Action,Averaging Time (sec),Frequency (Hz),Peak Amplitude (mm),Center Position (mm),Coil Signal' (mV),Coil Signal" (mV),Range (mV),M. Quad. Signal (emu),M. Raw' (emu),M. Raw" (emu),Min. Temperature (K),Max. Temperature (K),Min. Field (Oe),Max. Field (Oe),Mass (grams),Motor Lag (deg),Pressure (Torr),VSM Status (code),Motor Status (code),Measure Status (code),Measure Count,PPMS Status (code),System Temp. (K),System Field (Oe),Sample Position (deg),Bridge 1 Resistance (ohms),Bridge 1 Excitation (에),Bridge 2 Resistance (ohms),Bridge 2 Excitation (에),Bridge 3 Resistance (ohms),Bridge 3 Excitation (에),Bridge 4 Resistance (ohms),Bridge 4 Excitation (에),Signal 1 Vin (V),Signal 2 Vin (V),Digital Inputs (code),Drive 1 Iout (mA),Drive 1 Ipower (W),Drive 2 Iout (mA),Drive 2 Ipower (W),Pressure (),Map 20 (),Map 21 (),Map 22 (),Map 23 (),Map 24 (),Map 25 (),Map 26 (),Map 27 (),Map 28 (),Map 29 ()
,30998526.03,199.9894714,-0.228356599807739,,,2,,,,15.4599998760223,,,,,,,199.9894714,199.9894714,-0.228356599807739,-0.228356599807739,,,22.909004,,,,-99999999,4369,199.9152,-0.228356599807739,,,,,,,,,,,,,,,,,,,,,,,199.9894714,,,,
,30998684.74,199.9837036,4548.638671875,4.62725870966585E-5,4.42091329337534E-7,1,0.999253354069792,40.0298881530762,2.00851705649599,15.4499998316169,0.000529231181915091,8.41225655899241E-5,0.25,-6.63669709384662E-7,4.64330486308245E-5,-6.15729769599624E-7,199.9837036,199.9837036,4536.20947265625,4561.06787109375,56.6938613853714,20.6100104323622,23.668306,0,0,0,40,4449,199.94215,4548.638671875,,,,,,,,,,,,,0,,,,0.00245,,,,,,199.9837036,,,,
,30998782.13,199.9850922,9415.04150390625,4.21732407377212E-5,5.10543175273717E-7,1,0.999253354069792,40.0298881530762,2.00841018561827,15.4499998316169,0.000480009868167575,8.99753648002977E-5,0.25,5.61822163804118E-7,4.23182292875314E-5,6.09474885166434E-7,199.9850922,199.9850922,9407.4501953125,9422.6328125,56.4695340003521,20.6157569204079,22.909004,0,0,0,40,4449,199.9553,9415.04150390625,,,,,,,,,,,,,0,,,,-0.0049,,,,,,199.9850922,,,,
,30998877.49,199.9902802,14182.4111328125,2.64379792885117E-5,7.91382864036639E-7,1,0.999253354069792,40.0298881530762,2.00845331012195,15.4499998316169,0.000298373450539029,7.10648100732083E-5,0.25,1.63716535773879E-6,2.65274832005521E-5,1.67142974112501E-6,199.9902802,199.9902802,14179.8095703125,14185.0126953125,56.9791557948906,20.6192200436046,23.288654,0,0,0,40,4449,199.96205,14182.4111328125,,,,,,,,,,,,,0,,,,0,,,,,,199.9902802,,,,
,30998976.44,199.9897461,19127.314453125,1.19221903730475E-5,6.39021715317482E-7,1,0.999253354069792,40.0298881530762,2.00896951815918,15.4499998316169,0.000141067046600507,-5.26976837645078E-6,0.25,-2.532516571496E-6,1.196609065478E-5,-2.52838017178566E-6,199.9897461,199.9897461,19117.427734375,19137.201171875,56.7180918694675,20.6124693750613,23.288654,0,0,0,40,4449,199.96545,19127.314453125,,,,,,,,,,,,,0,,,,0.00245,,,,,,199.9897461,,,,
,30999074.505,199.9959412,24027.560546875,-4.10956717367938E-6,9.96525765001148E-7,1,0.999253354069792,40.0298881530762,2.00867605529806,15.4499998316169,-5.00276858630829E-5,9.92755579840897E-6,0.25,1.58386180298883E-6,-4.12546486750488E-6,1.58489864508708E-6,199.9959412,199.9959412,24025.48828125,24029.6328125,56.6024108486214,20.6172581584531,23.288654,0,0,0,40,4449,199.9699,24027.560546875,,,,,,,,,,,,,0,,,,0,,,,,,199.9959412,,,,
,30999173.2,199.9995728,28960.2685546875,-2.83636160740465E-5,1.54872730407726E-6,1,0.999253354069792,40.0298881530762,2.00888899487922,15.4499998316169,-0.000328088898121692,-3.06755604644183E-5,0.25,2.23796505860998E-6,-2.84639643856039E-5,2.21516018804052E-6,199.9995728,199.9995728,28952.603515625,28967.93359375,56.6336759893906,20.6199409362546,23.668306,0,0,0,40,4449,199.9676,28960.2685546875,,,,,,,,,,,,,0,,,,0,,,,,,199.9995728,,,,
,30999270.875,200.00304415,33842.71484375,-4.22475922518551E-5,1.65152586360438E-6,1,0.999253354069792,40.0298881530762,2.00881587692813,15.4499998316169,-0.000485708912565339,-6.27462688909137E-5,0.25,1.83854231830148E-6,-4.23954556692613E-5,1.79949764409112E-6,200.0027466,200.0033417,33835.046875,33850.3828125,56.7016776705637,20.6173816405915,23.288654,0,0,0,40,4449,199.9635,33842.71484375,,,,,,,,,,,,,0,,,,0,,,,,,200.00304415,,,,
,30999368.9,200.0042725,38742.560546875,-6.03267769282033E-5,1.76713616321802E-6,1,0.999253354069792,40.0298881530762,2.00894496520836,15.4499998316169,-0.000696550316541766,-7.26325844903457E-5,0.25,4.11237005869456E-6,-6.0539521200129E-5,4.06187748620747E-6,200.0042725,200.0042725,38732.63671875,38752.484375,56.7423223535637,20.6139587098176,23.668306,0,0,0,40,4449,199.9593,38742.560546875,,,,,,,,,,,,,0,,,,0.00245,,,,,,200.0042725,,,,
,30999467.43,200.0074463,43667.5859375,-8.16410936859665E-5,2.10920269090685E-6,1,0.999253354069792,40.0298881530762,2.00927594114973,15.4499998316169,-0.000930918945773289,-0.000166718001036874,0.25,-4.28701000835347E-7,-8.192259288045E-5,-5.17562217131534E-7,200.0074463,200.0074463,43660.03515625,43675.13671875,56.953362053756,20.6128836969272,23.288654,0,0,0,40,4449,199.95135,43667.5859375,,,,,,,,,,,,,0,,,,-0.00245,,,,,,200.0074463,,,,
,30999565.505,200.0080566,48567.587890625,-0.000101284082990358,2.18468333985822E-6,1,0.999253354069792,40.0298881530762,2.00906481296143,15.4499998316169,-0.00116055587400194,-0.000173577506442858,0.25,2.38003937459242E-6,-0.000101636452351917,2.28007143002821E-6,200.0080566,200.0080566,48562.44921875,48572.7265625,56.8329912617945,20.6163725178713,23.288654,0,0,0,40,4449,199.9447,48567.587890625,,,,,,,,,,,,,0,,,,-0.0049,,,,,,200.0080566,,,,
,30999662.48,200.0081635,53415.41796875,-0.000118861781714227,2.27235542192371E-6,1,0.999253354069792,40.0298881530762,2.00917787041503,15.4499998316169,-0.00136814703610313,-0.000168559814888077,0.25,5.87304507455858E-6,-0.000119278618271058,5.76662318984046E-6,200.0081635,200.0081635,53410.515625,53420.3203125,56.5703640793329,20.6162147454104,23.288654,0,0,0,40,4449,199.9387,53415.41796875,,,,,,,,,,,,,0,,,,0,,,,,,200.0081635,,,,
,30999759.985,200.0106812,58288.361328125,-0.000141938495796617,2.78115671747719E-6,1,0.999253354069792,40.0298881530762,1.99676843715731,15.4499998316169,-0.00160709452167921,-0.000298256282728543,0.25,-1.638881072893E-6,-0.000142427073324055,-1.7955424778749E-6,200.0104218,200.0109406,58278.453125,58298.26953125,56.7454488676406,20.612635192011,23.668306,0,0,0,40,4449,199.9301,58288.361328125,,,,,,,,,,,,,0,,,,-0.00245,,,,,,200.0106812,,,,
,30999855.305,200.0105896,63054,-0.000158861021500435,2.07146694562951E-6,1,0.999253354069792,40.0298881530762,1.99688041525003,15.4499998316169,-0.00180125977723023,-0.000319648052590376,0.25,-5.84324329611022E-7,-0.000159409230546965,-7.55002774280614E-7,200.0105896,200.0105896,63046.76171875,63061.23828125,56.8126689202945,20.6106647910765,23.288654,0,0,0,40,4449,199.9222,63054,,,,,,,,,,,,,0,,,,-0.0049,,,,,,200.0105896,,,,
,30999948.64,200.0110016,67719.296875,-0.000180062345270654,2.43216562844168E-6,1,0.999253354069792,40.0298881530762,1.99685474502119,15.4499998316169,-0.00204295410316596,-0.000354669873111158,0.25,1.01205266949881E-8,-0.000180684484587453,-1.80627227921332E-7,200.0110016,200.0110016,67714.34375,67724.25,56.7415407250445,20.6115630473319,23.668306,0,0,0,40,4449,199.91535,67719.296875,,,,,,,,,,,,,0,,,,-0.0049,,,,,,200.0110016,,,,
,31000043.555,200.0108337,72464.31640625,-0.000198051293568735,2.82082286569693E-6,1,0.999253354069792,40.0298881530762,1.99672449020322,15.4499998316169,-0.0022386144498396,-0.000437871202275205,0.25,-4.20194969952339E-6,-0.000198731195654727,-4.42588030309943E-6,200.0108337,200.0108337,72461.90625,72466.7265625,56.7735874943329,20.6147139184687,23.288654,0,0,0,40,4449,199.9046,72464.31640625,,,,,,,,,,,,,0,,,,-0.0049,,,,,,200.0108337,,,,
,31000137.685,200.0121918,77167.50390625,-0.000215393171392055,3.08223514563605E-6,1,0.999253354069792,40.0298881530762,1.99674297499706,15.4499998316169,-0.00243230064906164,-0.000489776982041364,0.25,-5.76560677950623E-6,-0.00021613141369934,-6.01280836721629E-6,200.0121918,200.0121918,77159.953125,77175.0546875,56.7743691228522,20.6112270511353,23.288654,0,0,0,40,4449,199.89445,77167.50390625,,,,,,,,,,,,,0,,,,0.00245,,,,,,200.0121918,,,,
,31000234.36,200.0130768,82000.93359375,-0.000235432598105522,3.51998718116917E-6,1,0.999253354069792,40.0298881530762,1.9967005792068,15.4499998316169,-0.00266383272114374,-0.000504858150603675,0.25,-3.61629552726666E-6,-0.000236242436196203,-3.87667943422287E-6,200.0130768,200.0130768,81998.296875,82003.5703125,56.9549253107945,20.6130258718475,23.668306,0,0,0,40,4449,199.8866,82000.93359375,,,,,,,,,,,,,0,,,,0,,,,,,200.0130768,,,,
,31000325.985,200.0110321,86581.67578125,-0.000255864079489338,3.63672688451094E-6,1,0.999253354069792,40.0298881530762,1.99667617429858,15.4499998316169,-0.00289625274817485,-0.000541305620569845,0.25,-3.2819744644597E-6,-0.000256744982447967,-3.56217103933286E-6,200.0110321,200.0110321,86571.5703125,86591.78125,56.8298647477175,20.615332311679,23.668306,0,0,0,40,4449,199.8721,86581.67578125,,,,,,,,,,,,,0,,,,-0.00245,,,,,,200.0110321,,,,
,31000434.965,200.011673,88954.890625,-0.000265204309957664,2.14146128255655E-6,1,0.999253354069792,40.0298881530762,1.99736900177311,15.4499998316169,-0.00299991664295673,-0.000578858076391148,0.25,-4.9534968156543E-6,-0.000266115780924905,-5.24899480680811E-6,200.011673,200.011673,88947.328125,88962.453125,56.9189703989099,20.6085686163701,23.288654,0,0,0,40,4449,199.8625,88954.890625,,,,,,,,,,,,,0,,,,0.00245,,,,,,200.011673,,,,
,31000525.975,200.0046082,84406.703125,-0.000248461333271107,2.84358340056508E-6,1,0.999253354069792,40.0298881530762,1.99680297782112,15.4499998316169,-0.00281159300928874,-0.000531636057490588,0.25,-3.7120451983591E-6,-0.000249316206979948,-3.98622717765634E-6,200.0046082,200.0046082,84394.4375,84418.96875,56.8197035769676,20.6106160652282,23.288654,0,0,0,40,4449,199.86295,84406.703125,,,,,,,,,,,,,0,,,,0.00245,,,,,,200.0046082,,,,
,31000621.02,199.9958496,79652.75390625,-0.000227712761556495,2.68083975003544E-6,1,0.999253354069792,40.0298881530762,1.99679471018037,15.4499998316169,-0.00257748197392293,-0.000483261726552235,0.25,-3.05106334565685E-6,-0.000228496600950025,-3.30164926258086E-6,199.9958496,199.9958496,79640.1328125,79665.375,56.831428004756,20.6099561166922,23.288654,0,0,0,40,4449,199.87,79652.75390625,,,,,,,,,,,,,0,,,,0.00245,,,,,,199.9958496,,,,
,31000715.615,199.9929657,74923.796875,-0.000205489777657824,2.56791054660243E-6,1,0.999253354069792,40.0298881530762,1.99683647811461,15.4499998316169,-0.00233059435632764,-0.000409569700710054,0.25,-4.137785207233E-7,-0.000206199537774535,-6.32292700498314E-7,199.9929657,199.9929657,74921.4453125,74926.1484375,56.9932251082368,20.6126957167863,23.668306,0,0,0,40,4449,199.8676,74923.796875,,,,,,,,,,,,,0,,,,0,,,,,,199.9929657,,,,
,31000811.02,199.9910431,70155.89453125,-0.000187272971620159,2.45748003647788E-6,1,0.999253354069792,40.0298881530762,1.9969679653931,15.4499998316169,-0.00212101751978353,-0.000391141058042307,0.25,-1.95046951184597E-6,-0.000187918097748017,-2.15545768802038E-6,199.9910126,199.9910736,70143.4453125,70168.34375,56.8329912617945,20.610629971064,23.288654,0,0,0,40,4449,199.88175,70155.89453125,,,,,,,,,,,,,0,,,,-0.00245,,,,,,199.9910431,,,,
,31000907.35,199.9863586,65340.416015625,-0.000169664398464002,2.66317322450965E-6,1,0.999253354069792,40.0298881530762,1.99677888417501,15.4499998316169,-0.00191505134616031,-0.000390958576471832,0.25,-4.99509910421302E-6,-0.00017024540999049,-5.19234146221392E-6,199.9863586,199.9863586,65335.00390625,65345.828125,57.058100275333,20.613344719278,23.668306,0,0,0,40,4449,199.89245,65340.416015625,,,,,,,,,,,,,0,,,,-0.0049,,,,,,199.9863586,,,,
,31001002.635,199.9898376,60579.6484375,-0.00015063359621857,2.52833358473917E-6,1,0.999253354069792,40.0298881530762,1.99678687448435,15.4499998316169,-0.00170024778838927,-0.000347124364655369,0.25,-4.43601914701055E-6,-0.000151149361384128,-4.61146814907193E-6,199.9898376,199.9898376,60572.14453125,60587.15234375,57.0440309619868,20.6120013158378,23.288654,0,0,0,40,4449,199.8987,60579.6484375,,,,,,,,,,,,,0,,,,0,,,,,,199.9898376,,,,
,31001098.435,199.9890442,55789.490234375,-0.000130676615702043,2.60920430640793E-6,1,0.999253354069792,40.0298881530762,1.99670775792938,15.4499998316169,-0.00148046536126942,-0.000269255832306901,0.25,-1.03904141673264E-6,-0.000131126995203827,-1.18182088493143E-6,199.9890442,199.9890442,55784.66015625,55794.3203125,57.3496477130061,20.6165464842603,23.288654,0,0,0,40,4449,199.9063,55789.490234375,,,,,,,,,,,,,0,,,,0,,,,,,199.9890442,,,,
,31001194.07,199.9902649,51009.169921875,-0.000107755146695947,2.30419216061327E-6,1,0.999253354069792,40.0298881530762,1.99671588429118,15.4499998316169,-0.00122000629282804,-0.000226523273121119,0.25,-1.25283951381252E-6,-0.000108126064968631,-1.37217021122931E-6,199.9902649,199.9902649,51006.8515625,51011.48828125,56.9713395096983,20.6128040336774,23.668306,0,0,0,40,4449,199.9159,51009.169921875,,,,,,,,,,,,,0,,,,0,,,,,,199.9902649,,,,
,31001288.445,199.9901123,46291.07421875,-9.08906924894015E-5,2.01324018587494E-6,1,0.999253354069792,40.0298881530762,1.99669845380378,15.4499998316169,-0.00102957140839436,-0.000188110909615171,0.25,-7.95820570699815E-7,-9.12038092115941E-5,-8.95762187183773E-7,199.9901123,199.9901123,46288.90625,46293.2421875,57.0205821064099,20.6152635876311,23.288654,0,0,0,40,4449,199.92195,46291.07421875,,,,,,,,,,,,,0,,,,0,,,,,,199.9901123,,,,
,31001383.52,199.988205,41541.40234375,-7.13008400516731E-5,1.6814620500059E-6,1,0.999253354069792,40.0298881530762,1.99681203147498,15.4499998316169,-0.000809685520355378,-0.000136197207960638,0.25,3.78698834698402E-7,-7.15475265349362E-5,3.03615822037723E-7,199.988205,199.988205,41536.390625,41546.4140625,56.8916134007368,20.6152125782702,23.668306,0,0,0,40,4449,199.92785,41541.40234375,,,,,,,,,,,,,0,,,,0,,,,,,199.988205,,,,
,31001478.455,199.9910126,36796.029296875,-5.39099450412E-5,1.3151152869412E-6,1,0.999253354069792,40.0298881530762,1.99683340522643,15.4499998316169,-0.000609994900477401,-0.000115687715657359,0.25,-8.33754872835984E-7,-5.40952404548578E-5,-8.94498423526145E-7,199.9910126,199.9910126,36793.6328125,36798.42578125,57.0033862789868,20.61575480689,23.288654,0,0,0,40,4449,199.9428,36796.029296875,,,,,,,,,,,,,0,,,,0,,,,,,199.9910126,,,,
,31001573.415,199.9889221,32049.0078125,-3.68938427436941E-5,1.68810403723834E-6,1,0.999253354069792,40.0298881530762,1.99685169712605,15.4499998316169,-0.000415242258143964,-9.19420338246684E-5,0.25,-1.6959923565828E-6,-3.7019432199858E-5,-1.74152225693272E-6,199.9889221,199.9889221,32041.48828125,32056.52734375,57.1206305568714,20.6178396153806,23.668306,0,0,0,40,4449,199.9476,32049.0078125,,,,,,,,,,,,,0,,,,0.00245,,,,,,199.9889221,,,,
,31001668.3,199.9926758,27309.09765625,-1.79978033991277E-5,1.23263859249019E-6,1,0.999253354069792,40.0298881530762,1.99685757484162,15.4499998316169,-0.000202021540357718,-4.799100889408E-5,0.25,-1.10399610866446E-6,-1.80587623625785E-5,-1.12719642642066E-6,199.9926758,199.9926758,27303.919921875,27314.275390625,56.9103724851983,20.6145090397961,23.668306,0,0,0,40,4449,199.9518,27309.09765625,,,,,,,,,,,,,0,,,,0,,,,,,199.9926758,,,,
,31001762.86,199.9915924,22581.2568359375,-4.33317146809645E-6,1.09455246380892E-6,1,0.999253354069792,40.0298881530762,1.99658300120645,15.4499998316169,-5.53951476489676E-5,2.73833784871837E-5,0.25,3.16647690159733E-6,-4.35155022101808E-6,3.1727344885044E-6,199.9915924,199.9915924,22571.259765625,22591.25390625,56.9791557948906,20.6209033144997,23.288654,0,0,0,40,4449,199.96035,22581.2568359375,,,,,,,,,,,,,0,,,,-0.0049,,,,,,199.9915924,,,,
,31001857.725,199.9899445,17838.5087890625,1.70276314825857E-5,8.14061239538262E-7,1,0.999253354069792,40.0298881530762,1.99674156630336,15.4499998316169,0.000195526322503606,2.00369080443103E-5,0.25,-1.19132299279346E-6,1.70877097894952E-5,-1.17703198181804E-6,199.9899445,199.9899445,17828.576171875,17848.44140625,57.0534105042176,20.62098023761,23.668306,0,0,0,40,4449,199.96885,17838.5087890625,,,,,,,,,,,,,0,,,,0.00245,,,,,,199.9899445,,,,
,31001951.57,199.9909515,13150.9423828125,3.0839607245905E-5,7.70572826516728E-7,1,0.999253354069792,40.0298881530762,1.99714399687495,15.4499998316169,0.000353600475453869,3.97238375758649E-5,0.25,-1.85570366638058E-6,3.09480862485431E-5,-1.82872625423978E-6,199.9909515,199.9909515,13146.013671875,13155.87109375,57.2089545795445,20.6149057368932,24.047956,0,0,0,40,4449,199.97695,13150.9423828125,,,,,,,,,,,,,0,,,,0,,,,,,199.9909515,,,,
,31002046.4,199.9916382,8410.814453125,4.32836910108659E-5,5.89124707249716E-7,1,0.999253354069792,40.0298881530762,1.99672708256035,15.4499998316169,0.000489381895726306,9.48970743176318E-5,0.25,8.46790094645929E-7,4.34321940297794E-5,8.96635714271202E-7,199.9916382,199.9916382,8408.29296875,8413.3359375,57.095618444256,20.6220028328811,24.047956,0,0,0,40,4449,199.9848,8410.814453125,,,,,,,,,,,,,0,,,,0,,,,,,199.9916382,,,,
,31002138.165,199.993927,3822.58422851562,4.82625227337861E-5,3.6927683790446E-7,1,0.999253354069792,40.0298881530762,1.99686631400345,15.4499998316169,0.000549311098606206,8.50906256274757E-5,0.25,-8.82934098762454E-7,4.84300762360722E-5,-8.33595907593613E-7,199.993927,199.993927,3820.08740234375,3825.0810546875,57.3050948874099,20.6213144633253,23.668306,0,0,0,40,4449,199.9884,3822.58422851562,,,,,,,,,,,,,0,,,,-0.00245,,,,,,199.993927,,,,
,31002233.37,199.99741365,-934.372344970703,2.25717648820003E-5,4.09625851683262E-7,1,0.999253354069792,40.0298881530762,1.99710917934924,15.4499998316169,0.000256182656880557,4.41350415030888E-5,0.25,-3.09460145719994E-8,2.26497079009645E-5,-6.53637510650459E-9,199.9973297,199.9974976,-941.867431640625,-926.877258300781,57.3183825722368,20.6177772095688,24.047956,0,0,0,40,4449,199.98915,-934.372344970703,,,,,,,,,,,,,0,,,,0.0049,,,,,,199.99741365,,,,
,31002332.6,199.9958954,-5892.27661132813,-3.30016182706324E-5,4.32840754269728E-7,1,0.999253354069792,40.0298881530762,1.9968706149103,15.4499998316169,-0.000373932728770411,-6.78778255797026E-5,0.25,-2.50630470637799E-7,-3.3115264062762E-5,-2.87295890795004E-7,199.9958954,199.9958954,-5897.1220703125,-5887.43115234375,57.1003082153714,20.6183498551476,23.668306,0,0,0,40,4449,199.9929,-5892.27661132813,,,,,,,,,,,,,0,,,,-0.00245,,,,,,199.9958954,,,,
,31002430.58,200.003006,-10790.6870117187,-3.62744127524934E-5,6.53098284760024E-7,1,0.999253354069792,40.0298881530762,1.99698634580518,15.4499998316169,-0.000414285851498343,-5.59178906123834E-5,0.25,1.37217565472425E-6,-3.64011139189486E-5,1.33761794965807E-6,200.003006,200.003006,-10800.732421875,-10780.6416015625,57.1229754424291,20.619152468811,24.047956,0,0,0,40,4449,199.988,-10790.6870117187,,,,,,,,,,,,,0,,,,0,,,,,,200.003006,,,,
,31002528.41,200.0073547,-15680.8159179687,-2.33306195223937E-5,7.33437478930094E-7,1,0.999253354069792,40.0298881530762,1.9968809777734,15.4499998316169,-0.000265116236206798,-4.36010763694226E-5,0.25,2.09285720908422E-7,-2.34113827342582E-5,1.84774732248904E-7,200.0073547,200.0073547,-15683.455078125,-15678.1767578125,57.1440794124484,20.6247340133198,23.668306,0,0,0,40,4449,199.9818,-15680.8159179687,,,,,,,,,,,,,0,,,,0,,,,,,200.0073547,,,,
,31002626.93,200.0088348,-20602.953125,-6.4037276446645E-6,8.71418339738426E-7,1,0.999253354069792,40.0298881530762,1.99691413652699,15.4499998316169,-7.68199219011649E-5,1.1352328067645E-5,0.25,2.11279357668833E-6,-6.42811589999977E-6,2.11317277712399E-6,200.0088348,200.0088348,-20610.361328125,-20595.544921875,57.1049979864868,20.6209790295937,23.288654,0,0,0,40,4449,199.9717,-20602.953125,,,,,,,,,,,,,0,,,,0.00245,,,,,,200.0088348,,,,
,31002726.14,200.0080566,-25562.7890625,1.04714613960334E-5,1.04442330014133E-6,1,0.999253354069792,40.0298881530762,1.99684338909505,15.4499998316169,0.00011772622460748,2.68443021303099E-5,0.25,5.4734256864328E-7,1.05070241511088E-5,5.6051918821071E-7,200.0080566,200.0080566,-25572.8125,-25552.765625,56.9869720800829,20.6221595269881,24.047956,0,0,0,40,4449,199.9636,-25562.7890625,,,,,,,,,,,,,0,,,,0.00245,,,,,,200.0080566,,,,
,31002825.61,200.0087891,-30532.17578125,2.95261219105055E-5,8.38724809832121E-7,1,0.999253354069792,40.0298881530762,1.99679919179733,15.4499998316169,0.000335576454526984,5.47695013365608E-5,0.25,-3.00641658811084E-7,2.9628392244954E-5,-2.6991324657781E-7,200.0087891,200.0087891,-30539.642578125,-30524.708984375,56.882233858506,20.6222566734374,23.288654,0,0,0,40,4449,199.9591,-30532.17578125,,,,,,,,,,,,,0,,,,-0.00245,,,,,,200.0087891,,,,
,31002925.085,200.009201,-35504.638671875,4.7994118226341E-5,1.35324716655487E-6,1,0.999253354069792,40.0298881530762,1.99693580686827,15.4499998316169,0.000543105118316104,0.000102870900235684,0.25,7.31066235351882E-7,4.81590592916119E-5,7.85129626771272E-7,200.009201,200.009201,-35507.1328125,-35502.14453125,57.098744958333,20.6213882528046,23.668306,0,0,0,40,4449,199.94815,-35504.638671875,,,,,,,,,,,,,0,,,,0,,,,,,200.009201,,,,
,31003026.575,200.0108337,-40577.025390625,6.90917199324295E-5,1.47132106236082E-6,1,0.999253354069792,40.0298881530762,1.99699498672584,15.4499998316169,0.000778540396414604,0.000167264430205356,0.25,2.74197241605682E-6,6.93273761047766E-5,2.82548990874637E-6,200.0108337,200.0108337,-40584.53515625,-40569.515625,57.1980117802753,20.6229675342633,24.047956,0,0,0,40,4449,199.938,-40577.025390625,,,,,,,,,,,,,0,,,,-0.00245,,,,,,200.0108337,,,,
,31003123.9,200.0115967,-45442.404296875,8.6826110214294E-5,1.35348314857216E-6,1,0.999253354069792,40.0298881530762,1.99694845873756,15.4499998316169,0.000986091281779959,0.000165642238566863,0.25,-4.80546548387354E-7,8.71264858503986E-5,-3.89333622608315E-7,200.0115967,200.0115967,-45452.3828125,-45432.42578125,57.108906129083,20.6213137800535,24.047956,0,0,0,40,4449,199.933,-45442.404296875,,,,,,,,,,,,,0,,,,-0.00245,,,,,,200.0115967,,,,
,31003220.525,200.0127563,-50271.8046875,0.000105215689348732,1.59404173381925E-6,1,0.999253354069792,40.0298881530762,1.99695320500118,15.4499998316169,0.00118575447556367,0.000253651300272569,0.25,4.08252254294804E-6,0.000105574729970308,4.20894974230632E-6,200.0127563,200.0127563,-50279,-50264.609375,57.3582456267176,20.622073826324,23.668306,0,0,0,40,4449,199.9166,-50271.8046875,,,,,,,,,,,,,0,,,,0,,,,,,200.0127563,,,,
,31003318.395,200.0146942,-55161.064453125,0.000123650046380048,2.18114567018752E-6,1,0.999253354069792,40.0298881530762,1.99722823471017,15.4499998316169,0.00139323249648742,0.000300758465986921,0.25,5.02955369987999E-6,0.000124071787393897,5.17866512678748E-6,200.0146942,200.0146942,-55166.17578125,-55155.953125,57.3973270526791,20.6241252804045,23.288654,0,0,0,40,4449,199.90865,-55161.064453125,,,,,,,,,,,,,0,,,,0.00245,,,,,,200.0146942,,,,
,31003414.32,200.0100403,-59955.990234375,0.000147966153273483,2.60143069553887E-6,1,0.999253354069792,40.0298881530762,1.99706365268598,15.4499998316169,0.00167453945872791,0.000316952387128661,0.25,2.23612922377095E-6,0.000148474933787486,2.40118580545713E-6,200.0100403,200.0100403,-59963.48046875,-59948.5,57.187068981006,20.6244735431766,23.288654,0,0,0,40,4449,199.8954,-59955.990234375,,,,,,,,,,,,,0,,,,0,,,,,,200.0100403,,,,
,31003511.555,200.0117493,-64816.283203125,0.000167050325663888,2.52239814488513E-6,1,0.999253354069792,40.0298881530762,1.99693980568484,15.4499998316169,0.00189311929790654,0.000342178636649788,0.25,1.14715803737111E-6,0.00016762623769604,1.32837817976055E-6,200.0117493,200.0117493,-64821.1171875,-64811.44921875,57.1636201254291,20.6274609672614,23.288654,0,0,0,40,4449,199.8848,-64816.283203125,,,,,,,,,,,,,0,,,,-0.00245,,,,,,200.0117493,,,,
,31003607.14,200.0131073,-69593.08984375,0.000187064890577667,2.02259344256512E-6,1,0.999253354069792,40.0298881530762,1.99713676376123,15.4499998316169,0.00211978747317604,0.00038522494008785,0.25,1.46242390055281E-6,0.000187709668911365,1.6655607580865E-6,200.0131073,200.0131073,-69598.1171875,-69588.0625,57.2722664896022,20.6256482614173,23.668306,0,0,0,40,4449,199.87595,-69593.08984375,,,,,,,,,,,,,0,,,,0,,,,,,200.0131073,,,,
,31003705.845,200.0128937,-74525.26171875,0.000203088309209695,2.44442574545044E-6,1,0.999253354069792,40.0298881530762,1.99701960598291,15.4499998316169,0.00229539256645385,0.000451836290134003,0.25,4.55268711380489E-6,0.000203785256396618,4.78300587231613E-6,200.0128937,200.0128937,-74535.40625,-74515.1171875,57.1503324406022,20.6290385114752,23.288654,0,0,0,40,4449,199.8664,-74525.26171875,,,,,,,,,,,,,0,,,,0,,,,,,200.0128937,,,,
,31003807.125,200.0119629,-79587,0.000227937054091274,2.61109276534343E-6,1,0.999253354069792,40.0298881530762,1.99722428691065,15.4499998316169,0.002581212185302,0.000480018226669323,0.25,2.71753504698254E-6,0.00022872189410654,2.96723229295769E-6,200.0119629,200.0119629,-79597.0859375,-79576.9140625,57.1573670972753,20.6279114969494,23.668306,0,0,0,40,4449,199.8548,-79587,,,,,,,,,,,,,0,,,,0.0049,,,,,,200.0119629,,,,
,31003905.57,200.0116425,-84506.703125,0.00024776396431685,3.50695394097823E-6,1,0.999253354069792,40.0298881530762,1.99708193685123,15.4499998316169,0.00280666464303016,0.000515300441897116,0.25,2.38725584467414E-6,0.000248617761971807,2.65613432069644E-6,200.0116425,200.0116425,-84514.0625,-84499.34375,57.0964000727753,20.6267701862738,24.047956,0,0,0,40,4449,199.84915,-84506.703125,,,,,,,,,,,,,0,,,,-0.00245,,,,,,200.0116425,,,,
,31004001.44,200.0139313,-89296.0234375,0.000267752121499851,3.10927019690154E-6,1,0.999253354069792,40.0298881530762,1.99711694147664,15.4499998316169,0.00303130482888532,0.000567458418672138,0.25,3.51257861195805E-6,0.000268673891096762,3.80577185762247E-6,200.0139313,200.0139313,-89300.9140625,-89291.1328125,57.352774227083,20.628011027636,24.047956,0,0,0,40,4449,199.8351,-89296.0234375,,,,,,,,,,,,,0,,,,-0.0049,,,,,,200.0139313,,,,
,31004113.085,200.0094147,-86154.46875,0.000253384027218718,3.16429696399377E-6,1,0.999253354069792,40.0298881530762,1.99708655187766,15.4499998316169,0.00286505015636047,0.000557425595079978,0.25,5.12380514915127E-6,0.000254254415972937,5.4078874941549E-6,200.0094147,200.0094147,-86159.3671875,-86149.5703125,57.1386080128137,20.6286169609552,23.288654,0,0,0,40,4449,199.82655,-86154.46875,,,,,,,,,,,,,0,,,,-0.00245,,,,,,200.0094147,,,,
,31004210.955,200.000885,-81265.23046875,0.000230054240765166,2.93299544271853E-6,1,0.999253354069792,40.0298881530762,1.99689899836737,15.4499998316169,0.00259014756818365,0.000568684487316432,0.25,1.01713544250488E-5,0.000230838651790519,1.0448896567941E-5,200.000885,200.000885,-81277.375,-81253.0859375,57.0057311645445,20.6264087644184,24.047956,0,0,0,40,4449,199.83055,-81265.23046875,,,,,,,,,,,,,0,,,,0,,,,,,200.000885,,,,
,31004310.53,199.9946442,-76287.51953125,0.000212516559519475,2.97294541078969E-6,1,0.999253354069792,40.0298881530762,1.99675351920467,15.4499998316169,0.00241237521228805,0.000410998938404465,0.25,-6.78994303417842E-7,0.000213251761343151,-4.56930950597819E-7,199.9946442,199.9946442,-76294.90625,-76280.1328125,57.1018714724099,20.6291843598528,24.047956,0,0,0,40,4449,199.8371,-76287.51953125,,,,,,,,,,,,,0,,,,0.00245,,,,,,199.9946442,,,,
,31004409.005,199.9893188,-71365.40234375,0.000194576215143987,2.400463047702E-6,1,0.999253354069792,40.0298881530762,1.99691384500272,15.4499998316169,0.00220479144875988,0.00039996052557174,0.25,1.46043536566817E-6,0.00019524712030025,1.67139480015598E-6,199.9893188,199.9893188,-71373,-71357.8046875,57.1307917276214,20.6267637295451,23.668306,0,0,0,40,4449,199.84575,-71365.40234375,,,,,,,,,,,,,0,,,,0,,,,,,199.9893188,,,,
,31004509.55,199.9889069,-66340.67578125,0.000174014218337522,2.76275630390757E-6,1,0.999253354069792,40.0298881530762,1.99674917406581,15.4499998316169,0.00197473867620696,0.000339837753894208,0.25,-2.6574963002299E-7,0.000174615833692874,-8.21154452764005E-8,199.9889069,199.9889069,-66350.640625,-66330.7109375,57.088583787583,20.6282608938988,23.668306,0,0,0,40,4449,199.85755,-66340.67578125,,,,,,,,,,,,,0,,,,0.00245,,,,,,199.9889069,,,,
,31004607.56,199.990509,-61443.349609375,0.000153659156498087,2.62133203756447E-6,1,0.999253354069792,40.0298881530762,1.99688564479585,15.4499998316169,0.00173965838236426,0.000324296140881455,0.25,1.89712786617245E-6,0.000154188075212997,2.06699487182937E-6,199.990509,199.990509,-61448.3515625,-61438.34765625,57.1300100991022,20.6270317485351,24.047956,0,0,0,40,4449,199.8625,-61443.349609375,,,,,,,,,,,,,0,,,,0.0049,,,,,,199.990509,,,,
,31004706.39,199.9904785,-56503.416015625,0.000133015394492309,2.40007409463528E-6,1,0.999253354069792,40.0298881530762,1.99693747274249,15.4499998316169,0.00150756143941575,0.00027160535333984,0.25,8.37349638854089E-7,0.00013347406483095,9.81911021839299E-7,199.9904785,199.9904785,-56510.60546875,-56496.2265625,57.1112510146407,20.6252733025255,23.668306,0,0,0,40,4449,199.8703,-56503.416015625,,,,,,,,,,,,,0,,,,0.0049,,,,,,199.9904785,,,,
,31004806.265,199.9910126,-51511.564453125,0.000113719448601696,1.9413780490756E-6,1,0.999253354069792,40.0298881530762,1.99687175887858,15.4499998316169,0.00128780345763759,0.000238081392930501,0.25,1.23423390811241E-6,0.000114110988333815,1.35986641928897E-6,199.9910126,199.9910126,-51519.15234375,-51503.9765625,57.078422616833,20.6274393808919,24.047956,0,0,0,40,4449,199.8803,-51511.564453125,,,,,,,,,,,,,0,,,,-0.0049,,,,,,199.9910126,,,,
,31004905.37,199.9913635,-46559.935546875,9.2997415062145E-5,1.37517349487694E-6,1,0.999253354069792,40.0298881530762,1.99688233504894,15.4499998316169,0.00105219993877697,0.000200134829937907,0.25,1.48823614785941E-6,9.33170631588327E-5,1.59283277202509E-6,199.9913635,199.9913635,-46567.34375,-46552.52734375,57.0948368157368,20.6261483358081,23.288654,0,0,0,40,4449,199.88665,-46559.935546875,,,,,,,,,,,,,0,,,,-0.00245,,,,,,199.9913635,,,,
,31005005.41,199.98999025,-41559.74609375,7.48850512531345E-5,1.48225759360415E-6,1,0.999253354069792,40.0298881530762,1.99692707436587,15.4499998316169,0.000848826775012332,0.000152306617233209,0.25,4.17957877492531E-7,7.51432577335618E-5,4.99647811847766E-7,199.9898682,199.9901123,-41564.45703125,-41555.03515625,57.190195495083,20.6241795831064,24.047956,0,0,0,40,4449,199.89605,-41559.74609375,,,,,,,,,,,,,0,,,,-0.00245,,,,,,199.98999025,,,,
,31005103.93,199.9886169,-36635.025390625,5.37146715787772E-5,1.57270104328172E-6,1,0.999253354069792,40.0298881530762,1.99691511413034,15.4499998316169,0.000611092622718349,9.63675780605209E-5,0.25,-8.35561776687986E-7,5.39010864242458E-5,-7.80776680695145E-7,199.9886169,199.9886169,-36647.5859375,-36622.46484375,57.2722664896022,20.6239377949576,23.288654,0,0,0,40,4449,199.9068,-36635.025390625,,,,,,,,,,,,,0,,,,-0.00245,,,,,,199.9886169,,,,
,31005201.405,199.9894867,-31765.642578125,3.69263040507844E-5,1.5535664592657E-6,1,0.999253354069792,40.0298881530762,1.99724357601004,15.4499998316169,0.00041779092371919,7.99173339609877E-5,0.25,6.29171779226073E-7,3.70531501269108E-5,6.71064315911003E-7,199.9894867,199.9894867,-31770.5390625,-31760.74609375,57.1323549846599,20.6188861743471,23.668306,0,0,0,40,4449,199.9164,-31765.642578125,,,,,,,,,,,,,0,,,,-0.0049,,,,,,199.9894867,,,,
,31005298.665,199.9878998,-26906.0556640625,1.76065405501864E-5,1.18726658623529E-6,1,0.999253354069792,40.0298881530762,1.99714285741906,15.4499998316169,0.000199155723350676,3.83230855572357E-5,0.25,3.19359667313566E-7,1.76669954719408E-5,3.39435194289686E-7,199.9878998,199.9878998,-26913.509765625,-26898.6015625,57.1401712698522,20.6195293890753,23.668306,0,0,0,40,4449,199.92455,-26906.0556640625,,,,,,,,,,,,,0,,,,0,,,,,,199.9878998,,,,
,31005396.48,199.988327,-22016.12890625,-9.24065803584739E-8,9.4437601073078E-7,1,0.999253354069792,40.0298881530762,1.99703783111295,15.4499998316169,-9.31673469204555E-7,-8.54765536399125E-7,0.25,-5.92824639221105E-8,-9.26616575892454E-8,-5.95869133964656E-8,199.988327,199.988327,-22021.234375,-22011.0234375,57.0917103016599,20.6193585974015,23.668306,0,0,0,40,4449,199.9321,-22016.12890625,,,,,,,,,,,,,0,,,,0.0049,,,,,,199.988327,,,,
,31005492.9,199.9878387,-17196.068359375,-1.75737277809303E-5,8.90419113001322E-7,1,0.999253354069792,40.0298881530762,1.99706456172102,15.4499998316169,-0.000198346317250302,-4.07299060121669E-5,0.25,-5.37238236924607E-7,-1.76338232725647E-5,-5.58094490090044E-7,199.9878387,199.9878387,-17203.79296875,-17188.34375,57.1714364106214,20.6165212642549,23.288654,0,0,0,40,4449,199.9467,-17196.068359375,,,,,,,,,,,,,0,,,,0.0049,,,,,,199.9878387,,,,
,31005588.87,199.9887543,-12400.8383789062,-3.26067385409343E-5,6.55160188521931E-7,1,0.999253354069792,40.0298881530762,1.99704669647668,15.4499998316169,-0.000370382339563083,-6.19321897003273E-5,0.25,2.05228384667559E-7,-3.27195318994541E-5,1.7062448812828E-7,199.9887543,199.9887543,-12410.720703125,-12390.9560546875,57.1237570709483,20.6167323619654,24.047956,0,0,0,40,4449,199.94585,-12400.8383789062,,,,,,,,,,,,,0,,,,0,,,,,,199.9887543,,,,
,31005688.46,199.9923401,-7422.91943359375,-4.52638125170527E-5,4.33814352866114E-7,1,0.999253354069792,40.0298881530762,1.99700849013678,15.4499998316169,-0.000514636963208576,-8.31409681574295E-5,0.25,5.34386853543365E-7,-4.54206443172191E-5,4.87139857673813E-7,199.9923401,199.9923401,-7427.7626953125,-7418.076171875,56.9142806277945,20.6181021677849,23.668306,0,0,0,40,4449,199.9575,-7422.91943359375,,,,,,,,,,,,,0,,,,0,,,,,,199.9923401,,,,
,31005783.57,199.9942932,-2667.16967773438,-4.70011681425315E-5,3.51772911375991E-7,1,0.999253354069792,40.0298881530762,1.99709329938453,15.4499998316169,-0.00053274409530918,-9.59368376183391E-5,0.25,-2.91189438200372E-7,-4.716308907542E-5,-3.43234413420339E-7,199.9942932,199.9942932,-2669.54248046875,-2664.796875,57.0440309619868,20.618091126392,23.668306,0,0,0,40,4449,199.9621,-2667.16967773438,,,,,,,,,,,,,0,,,,0,,,,,,199.9942932,,,,
,31005878.265,199.9957581,2062.22705078125,-5.61731943261189E-6,3.68739363023112E-7,1,0.999253354069792,40.0298881530762,1.99703269909473,15.4499998316169,-6.3562088485381E-5,-1.20797468567914E-5,0.25,-8.89349279997141E-8,-5.63661213795875E-6,-9.53427020712301E-8,199.9957581,199.9957581,2059.75756835938,2064.69653320313,57.0026046504676,20.6156940069724,23.668306,0,0,0,40,4449,199.96375,2062.22705078125,,,,,,,,,,,,,0,,,,0,,,,,,199.9957581,,,,
,31005974.6,199.9995728,6878.0234375,3.68570691652389E-5,4.35087862889301E-7,1,0.999253354069792,40.0298881530762,1.99714225440304,15.4499998316169,0.000418504424211171,7.10250672625757E-5,0.25,-1.42435417142716E-7,3.69844461904546E-5,-1.02949694340603E-7,199.9995728,199.9995728,6878.0234375,6878.0234375,56.9283499411406,20.6145591468548,23.288654,0,0,0,40,4449,199.96935,6878.0234375,,,,,,,,,,,,,0,,,,-0.0049,,,,,,199.9995728,,,,
,31006069.18,200.0020294,11603.8857421875,3.45818321068003E-5,7.14245152983327E-7,1,0.999253354069792,40.0298881530762,1.99692164499636,15.4499998316169,0.000394690030014232,5.47629081649124E-5,0.25,-1.17983450452479E-6,3.47024838616034E-5,-1.14644993871017E-6,200.0020294,200.0020294,11596.3896484375,11611.3818359375,57.1128142716791,20.6177733991769,23.668306,0,0,0,40,4449,199.9618,11603.8857421875,,,,,,,,,,,,,0,,,,0.0049,,,,,,200.0020294,,,,
,31006165.28,200.0044098,16409.171875,2.01254460068745E-5,8.80067704561023E-7,1,0.999253354069792,40.0298881530762,1.99698667277968,15.4499998316169,0.000229020845824699,3.58003061967892E-5,0.25,-3.40295912004942E-7,2.01952889072757E-5,-3.19705539824134E-7,200.0044098,200.0044098,16404.21484375,16414.12890625,56.9830639374868,20.6191288401903,23.668306,0,0,0,40,4449,199.95495,16409.171875,,,,,,,,,,,,,0,,,,0,,,,,,200.0044098,,,,
,31006264.57,200.0085907,21371.0791015625,3.0167971255894E-6,8.64368243264306E-7,1,0.999253354069792,40.0298881530762,1.9972268883772,15.4499998316169,3.55100061809848E-5,-1.40334573137809E-6,0.25,-6.4764055855507E-7,3.02791099919152E-6,-6.46619315730847E-7,200.0085907,200.0085907,21366.08984375,21376.068359375,56.9650864815445,20.6135343987014,23.668306,0,0,0,40,4449,199.9479,21371.0791015625,,,,,,,,,,,,,0,,,,0.00245,,,,,,200.0085907,,,,
,31006363.095,200.0080719,26293.7138671875,-1.66411523654487E-5,1.16524903677955E-6,1,0.999253354069792,40.0298881530762,1.99698887307306,15.4499998316169,-0.000186849078976893,-4.41226383984435E-5,0.25,-9.98417110383538E-7,-1.66975302831635E-5,-1.01979875338781E-6,200.0080719,200.0080719,26283.66015625,26303.767578125,56.9619599674676,20.6148770834245,23.288654,0,0,0,40,4449,199.94195,26293.7138671875,,,,,,,,,,,,,0,,,,0,,,,,,200.0080719,,,,
,31006458.155,200.0117493,31046.8583984375,-3.39845082223308E-5,1.60085973107637E-6,1,0.999253354069792,40.0298881530762,1.99693537564357,15.4499998316169,-0.000385333078030363,-6.84551415414651E-5,0.25,-1.30908360260843E-7,-3.41017049321142E-5,-1.67921989392042E-7,200.0117493,200.0117493,31041.9609375,31051.755859375,57.0033862789868,20.6129823426937,24.047956,0,0,0,40,4449,199.9336,31046.8583984375,,,,,,,,,,,,,0,,,,0,,,,,,200.0117493,,,,
,31006552.17,200.0118256,35746.859375,-5.19088599191008E-5,1.38568247019134E-6,1,0.999253354069792,40.0298881530762,1.99694756878558,15.4499998316169,-0.000590759937831113,-9.19620954204023E-5,0.25,9.10349871625278E-7,-5.20890764322099E-5,8.57746571611794E-7,200.0118256,200.0118256,35744.2578125,35749.4609375,56.8095424062176,20.6143398728883,24.047956,0,0,0,40,4449,199.9215,35746.859375,,,,,,,,,,,,,0,,,,-0.0049,,,,,,200.0118256,,,,
,31006651.64,200.012146,40717.083984375,-7.01271077525364E-5,2.07418992795794E-6,1,0.999253354069792,40.0298881530762,1.99699250530161,15.4499998316169,-0.000795347873224375,-0.000140167044562227,0.25,-1.73970992616179E-7,-7.03690877307339E-5,-2.49736086157261E-7,200.012146,200.012146,40707.0078125,40727.16015625,57.0776409883137,20.6105588459659,23.288654,0,0,0,40,4449,199.91575,40717.083984375,,,,,,,,,,,,,0,,,,0.00245,,,,,,200.012146,,,,
,31006752.485,200.0110321,45757.193359375,-9.06442043961119E-5,1.86478745663267E-6,1,0.999253354069792,40.0298881530762,1.99702305356171,15.4499998316169,-0.00102575530547951,-0.000194438645928643,0.25,-1.39371384653333E-6,-9.09557621362235E-5,-1.49548949233128E-6,200.0110321,200.0110321,45749.5234375,45764.86328125,56.8447156895829,20.6138120720715,23.668306,0,0,0,40,4449,199.90205,45757.193359375,,,,,,,,,,,,,0,,,,0.00245,,,,,,200.0110321,,,,
,31006851.35,200.01420595,50699.67578125,-0.000110768999382424,2.06096917300223E-6,1,0.999253354069792,40.0298881530762,1.99706464022614,15.4499998316169,-0.00125642384582355,-0.000220882922683303,0.25,-2.28986672004871E-7,-0.000111151329543326,-3.48028998906188E-7,200.0135956,200.0148163,50692.3984375,50706.953125,56.9166255133522,20.6128553666659,23.288654,0,0,0,40,4449,199.8926,50699.67578125,,,,,,,,,,,,,0,,,,-0.0049,,,,,,200.01420595,,,,
,31006951.425,200.0115814,55699.6796875,-0.000129284973375969,2.10451709948985E-6,1,0.999253354069792,40.0298881530762,1.99696474902239,15.4499998316169,-0.00146705168693605,-0.000253904263614969,0.25,7.51979217701236E-8,-0.000129731631530952,-6.22741924566862E-8,200.0115814,200.0115814,55694.69921875,55704.66015625,57.0135474497368,20.613085586926,23.668306,0,0,0,40,4449,199.88335,55699.6796875,,,,,,,,,,,,,0,,,,-0.0049,,,,,,200.0115814,,,,
,31007051.19,200.0131378,60687.47265625,-0.000151986037168698,2.1191868577623E-6,1,0.999253354069792,40.0298881530762,1.99690287549065,15.4499998316169,-0.00172633166139879,-0.000288506082071095,0.25,9.66997652832594E-7,-0.000152512098641877,8.08759121665802E-7,200.0131378,200.0131378,60677.4765625,60697.46875,56.7204367550252,20.6130389147752,23.668306,0,0,0,40,4449,199.87055,60687.47265625,,,,,,,,,,,,,0,,,,-0.00245,,,,,,200.0131378,,,,
,31007150.695,200.010437,65663.1328125,-0.0001740109140099,2.68857434143907E-6,1,0.999253354069792,40.0298881530762,1.9968428077712,15.4499998316169,-0.00197391737570413,-0.00034485993566568,0.25,-1.7611281789718E-7,-0.000174611918467403,-3.61316752221719E-7,200.010437,200.010437,65655.6015625,65670.6640625,56.922878541506,20.612760792431,23.288654,0,0,0,40,4449,199.8654,65663.1328125,,,,,,,,,,,,,0,,,,0,,,,,,200.010437,,,,
,31007249.44,200.0124207,70597.99609375,-0.000193328476072008,1.93350364488146E-6,1,0.999253354069792,40.0298881530762,1.99695215679569,15.4499998316169,-0.00219490311557295,-0.000373150160992528,0.25,6.86489773812261E-7,-0.000193997184124921,4.84205847332873E-7,200.0124207,200.0124207,70588.0546875,70607.9375,56.7946914643522,20.6112408863318,23.668306,0,0,0,40,4449,199.85075,70597.99609375,,,,,,,,,,,,,0,,,,0,,,,,,200.0124207,,,,
,31007346.825,200.0114594,75465.90234375,-0.000213831502355806,2.39341465309912E-6,1,0.999253354069792,40.0298881530762,1.99692435028462,15.4499998316169,-0.00242594373691037,-0.000422528288848146,0.25,-1.0579590323102E-7,-0.000214570290641742,-3.32031676782441E-7,200.0114594,200.0114594,75455.9765625,75475.828125,56.6868267286983,20.6118789681764,23.668306,0,0,0,40,4449,199.8462,75465.90234375,,,,,,,,,,,,,0,,,,-0.0049,,,,,,200.0114594,,,,
,31007445.525,200.0094147,80399.59375,-0.000233027505369269,2.99578106788375E-6,1,0.999253354069792,40.0298881530762,1.99688099329302,15.4499998316169,-0.0026481768855125,-0.000434502820593006,0.25,2.17109312165113E-6,-0.000233835119611655,1.93299109156441E-6,200.0094147,200.0094147,80394.8203125,80404.3671875,56.8462789466214,20.6108449242552,23.668306,0,0,0,40,4449,199.83875,80399.59375,,,,,,,,,,,,,0,,,,0,,,,,,200.0094147,,,,
,31007542.575,200.0126648,85250.3984375,-0.000254098358755114,3.53340635406602E-6,1,0.999253354069792,40.0298881530762,1.99688594381658,15.4499998316169,-0.00288205784578439,-0.000505927079287704,0.25,-4.65405705750965E-7,-0.000254976069232814,-7.34255693285202E-7,200.0126648,200.0126648,85242.9765625,85257.8203125,56.8869236296214,20.6118055806382,23.668306,0,0,0,40,4449,199.8229,85250.3984375,,,,,,,,,,,,,0,,,,0,,,,,,200.0126648,,,,
,31007639.11,200.0162659,89999.6796875,-0.000272715231923525,2.83970055930193E-6,1,0.999253354069792,40.0298881530762,1.99687937588417,15.4499998316169,-0.00309473665814117,-0.000534183042833485,0.25,2.76368250467455E-7,-0.000273658119911236,-8.88319908923632E-9,200.0162659,200.0162659,89999.671875,89999.6875,56.8650380310829,20.6108769951542,23.668306,0,0,0,40,4417,199.8127,89999.6796875,,,,,,,,,,,,,0,,,,0,,,,,,200.0162659,,,,
,31007753.695,200.0065002,85249.234375,-0.000248316315839008,3.74590773903514E-6,1,0.999253354069792,40.0298881530762,1.99740236833673,15.4499998316169,-0.00280548814698479,-0.000561817796053778,0.25,-6.3833138180584E-6,-0.000249167865560407,-6.66656006923075E-6,200.0065002,200.0065002,85239.2109375,85259.2578125,56.8071975206598,20.613949986209,24.047956,0,0,0,40,4449,199.8084,85249.234375,,,,,,,,,,,,,0,,,,0.00245,,,,,,200.0065002,,,,
,31007849.3,199.999649,80470.61328125,-0.000234816310855505,3.58838489197157E-6,1,0.999253354069792,40.0298881530762,1.99705774400239,15.4499998316169,-0.00266445705744302,-0.000462489489689719,0.25,1.85361636124959E-8,-0.000235627909972806,-2.28920407646089E-7,199.999649,199.999649,80460.46875,80480.7578125,57.1425161554099,20.6127470827157,23.288654,0,0,0,40,4449,199.8133,80470.61328125,,,,,,,,,,,,,0,,,,-0.00245,,,,,,199.999649,,,,
,31007947.155,199.9963684,75576.76171875,-0.000213327590925579,2.53534574836542E-6,1,0.999253354069792,40.0298881530762,1.99712271268037,15.4499998316169,-0.00241475968785887,-0.000454382192449922,0.25,-2.99694155981679E-6,-0.000214061686478059,-3.2326633434037E-6,199.9963684,199.9963684,75571.7109375,75581.8125,56.9752476522945,20.6119126502373,23.668306,0,0,0,40,4449,199.81865,75576.76171875,,,,,,,,,,,,,0,,,,-0.0049,,,,,,199.9963684,,,,
,31008046.415,199.99367525,70616.16796875,-0.000192243641280906,2.64831149424109E-6,1,0.999253354069792,40.0298881530762,1.99699681559327,15.4499998316169,-0.0021743126596814,-0.000418984443672014,0.25,-3.54066607064438E-6,-0.000192904240224458,-3.75644220444758E-6,199.9934235,199.993927,70608.53125,70623.8046875,56.9494539111599,20.6149777270268,23.288654,0,0,0,40,4449,199.82285,70616.16796875,,,,,,,,,,,,,0,,,,0.00245,,,,,,199.99367525,,,,
,31008143.285,199.9898987,65775.63671875,-0.000173278904080987,2.45660535308347E-6,1,0.999253354069792,40.0298881530762,1.99692377920968,15.4499998316169,-0.00196332414218338,-0.000357052002495142,0.25,-1.37657757519629E-6,-0.000173876219939783,-1.56517940006956E-6,199.9898987,199.9898987,65770.609375,65780.6640625,56.9213152844676,20.6183149696316,23.668306,0,0,0,40,4449,199.8341,65775.63671875,,,,,,,,,,,,,0,,,,0,,,,,,199.9898987,,,,
,31008242.11,199.9886017,60832.67578125,-0.000153721965417043,2.19189388239603E-6,1,0.999253354069792,40.0298881530762,1.99699529886273,15.4499998316169,-0.00174254577824849,-0.000312439509913447,0.25,-8.39696488970954E-7,-0.000154252225258524,-1.00603950393233E-6,199.9886017,199.9886017,60822.70703125,60842.64453125,56.9244417985445,20.6164356942799,23.668306,0,0,0,40,4449,199.84315,60832.67578125,,,,,,,,,,,,,0,,,,0.00245,,,,,,199.9886017,,,,
,31008339.78,199.98996735,55951.732421875,-0.00013204275661216,1.9481617218557E-6,1,0.999253354069792,40.0298881530762,1.9969539005646,15.4499998316169,-0.00149962292744889,-0.000251924573527119,0.25,7.28533914132333E-7,-0.000132499729679179,5.90369521027691E-7,199.9896698,199.9902649,55944.015625,55959.44921875,57.2120810936214,20.6156291075034,24.047956,0,0,0,40,4449,199.8523,55951.732421875,,,,,,,,,,,,,0,,,,0.0049,,,,,,199.98996735,,,,
,31008439.14,199.9858856,50987.130859375,-0.00010965780338284,1.95143842792502E-6,1,0.999253354069792,40.0298881530762,1.99674836831338,15.4499998316169,-0.00124149807901711,-0.000230926971134185,0.25,-1.31020832331222E-6,-0.000110035243155582,-1.43180718596851E-6,199.9858856,199.9858856,50976.9140625,50997.34765625,56.9291315696599,20.6167878705476,23.288654,0,0,0,40,4449,199.86285,50987.130859375,,,,,,,,,,,,,0,,,,-0.00245,,,,,,199.9858856,,,,
,31008536.025,199.9874115,46144.310546875,-9.20094710302879E-5,2.12785897977175E-6,1,0.999253354069792,40.0298881530762,1.99690203351568,15.4499998316169,-0.00103902605103505,-0.000209560309145391,0.25,-2.49036028368893E-6,-9.2324642426271E-5,-2.59738757158799E-6,199.9874115,199.9874115,46139.37890625,46149.2421875,57.1276652135445,20.6188420776391,23.668306,0,0,0,40,4449,199.8729,46144.310546875,,,,,,,,,,,,,0,,,,-0.0049,,,,,,199.9874115,,,,
,31008632.255,199.9883575,41334.05859375,-7.52943877480758E-5,1.70058884455074E-6,1,0.999253354069792,40.0298881530762,1.9968989073317,15.4499998316169,-0.000854592060443518,-0.000146591051882966,0.25,1.56722841398478E-7,-7.55546260681422E-5,7.65659466410002E-8,199.9883575,199.9883575,41331.48828125,41336.62890625,57.1065612435253,20.6173409476409,24.047956,0,0,0,40,4449,199.8843,41334.05859375,,,,,,,,,,,,,0,,,,0,,,,,,199.9883575,,,,
,31008726.47,199.9917297,36627.009765625,-5.5568522608849E-5,1.88424292051965E-6,1,0.999253354069792,40.0298881530762,1.99703075462027,15.4499998316169,-0.000631951943479603,-0.000101231404136493,0.25,7.29352689157802E-7,-5.57612195609556E-5,6.72203578027365E-7,199.9917297,199.9917297,36619.7890625,36634.23046875,57.1620568683907,20.6151668685043,24.047956,0,0,0,40,4449,199.8891,36627.009765625,,,,,,,,,,,,,0,,,,-0.0049,,,,,,199.9917297,,,,
,31008822.29,199.9893799,31836.392578125,-3.81801590242022E-5,1.41654218727797E-6,1,0.999253354069792,40.0298881530762,1.99706971274041,15.4499998316169,-0.000434053593462372,-7.04626118292349E-5,0.25,4.21265129846874E-7,-3.83124648509103E-5,3.8164854947167E-7,199.9893799,199.9893799,31831.10546875,31841.6796875,56.973684395256,20.6132811344119,23.668306,0,0,0,40,4449,199.90035,31836.392578125,,,,,,,,,,,,,0,,,,0,,,,,,199.9893799,,,,
,31008916.655,199.9909973,27119.212890625,-1.85940227666388E-5,1.17360508751513E-6,1,0.999253354069792,40.0298881530762,1.99704227493728,15.4499998316169,-0.000211655216053865,-3.27567138711222E-5,0.25,3.42560599834171E-7,-1.86585989342784E-5,3.23705819446866E-7,199.9909973,199.9909973,27114.361328125,27124.064453125,57.0455942190253,20.6148506917071,23.288654,0,0,0,40,4449,199.9047,27119.212890625,,,,,,,,,,,,,0,,,,-0.00245,,,,,,199.9909973,,,,
,31009011.97,199.9896088,22356.7783203125,-1.47512130391853E-6,8.8410239153841E-7,1,0.999253354069792,40.0298881530762,1.99697870130475,15.4499998316169,-1.58117002887788E-5,-8.23554167521488E-6,0.25,-4.69628059866681E-7,-1.47970774533047E-6,-4.72842019640316E-7,199.9896088,199.9896088,22346.640625,22366.916015625,57.085457273506,20.6142761151759,23.668306,0,0,0,40,4449,199.9109,22356.7783203125,,,,,,,,,,,,,0,,,,-0.00245,,,,,,199.9896088,,,,
,31009106.33,199.9919739,17641.5439453125,1.62258664116636E-5,7.87506643138458E-7,1,0.999253354069792,40.0298881530762,1.99720906021247,15.4499998316169,0.000184429966689815,3.02177190058417E-5,0.25,-1.55287400942819E-7,1.62820547060091E-5,-1.38279323666644E-7,199.9919739,199.9919739,17638.978515625,17644.109375,57.1511140691214,20.6142145624451,23.668306,0,0,0,40,4449,199.9199,17641.5439453125,,,,,,,,,,,,,0,,,,-0.0049,,,,,,199.9919739,,,,
,31009199.39,199.9894714,12988.63671875,3.18738362165581E-5,6.10220916818479E-7,1,0.999253354069792,40.0298881530762,1.99720303257652,15.4499998316169,0.000362987864493772,5.53424118303115E-5,0.25,-6.59060868002403E-7,3.19845904080039E-5,-6.26820337487103E-7,199.9894714,199.9894714,12981.515625,12995.7578125,57.2652318329291,20.6163385524117,23.668306,0,0,0,40,4449,199.92845,12988.63671875,,,,,,,,,,,,,0,,,,0.0049,,,,,,199.9894714,,,,
,31009291.96,199.9920654,8363.59375,4.35439647188312E-5,4.45966691555352E-7,1,0.999253354069792,40.0298881530762,1.99741914813604,15.4499998316169,0.000493461925148222,8.98889681953758E-5,0.25,3.57507756897325E-7,4.36938935284267E-5,4.05962505798554E-7,199.9920654,199.9920654,8348.6298828125,8378.5576171875,57.1995750373137,20.6145982616588,24.047956,0,0,0,40,4449,199.93265,8363.59375,,,,,,,,,,,,,0,,,,0,,,,,,199.9920654,,,,
,31009387.275,199.9922943,3598.28369140625,4.818184237047E-5,4.33930538671091E-7,1,0.999253354069792,40.0298881530762,1.99698503593605,15.4499998316169,0.000546460996572777,9.62545119507281E-5,0.25,1.1455577582302E-7,4.83480343943686E-5,1.6726869606434E-7,199.9922943,199.9922943,3590.66796875,3605.8994140625,57.129228470583,20.6158375407882,24.047956,0,0,0,40,4449,199.9392,3598.28369140625,,,,,,,,,,,,,0,,,,0,,,,,,199.9922943,,,,
,31009459.175,199.9967804,-0.487160742282867,3.77772853266363E-5,3.90233219465624E-7,1,0.999253354069792,40.0298881530762,1.99701129760201,15.4499998316169,0.000429273204780695,7.0796915329073E-5,0.25,-3.22056928287445E-7,3.79080266746603E-5,-2.82118582586718E-7,199.9967804,199.9967804,-0.517608284950256,-0.456713199615479,57.2097362080637,20.6159268231154,24.047956,0,0,0,40,4417,199.9435,-0.487160742282867,,,,,,,,,,,,,0,,,,-0.00245,,,,,,199.9967804,,,,