File: data/doubleLayers/dl_5/ppms/data/DD205_6_FCW_100OE.DAT
[Header]
; VSM Data File (default extension .dat)
; Copyright (c) 2003-2013, Quantum Design, Inc. All rights reserved.
TITLE,
FILEOPENTIME,30918283.42,12/25/2018,4:26 am
BYAPP,VSM,2.0,2.0
INFO,PPMS VSM Option Release 1.4.10 Build 1,APPNAME
INFO,Quantum Design Linear Motor Servo Controller,MOTOR_MODULE_NAME
INFO,3101-100 M1,MOTOR_HW_VERSION
INFO,MMC1014,MOTOR_SERIAL_NUMBER
INFO,SRV No X-over 01.03.11,MOTOR_SOFTWARE_VERSION
INFO,Quantum Design VSM Detection Module,VSM_MODULE_NAME
INFO,3101-150 F0,VSM_HW_VERSION
INFO,VSM707,VSM_SERIAL_NUMBER
INFO,VSM No X-over 01.02.05 May 20 2008 13:51:47,VSM_SOFTWARE_VERSION
INFO,704,PREAMP_SERIAL_NUMBER
INFO,822,COIL_SERIAL_NUMBER
INFO,0,MOMENT_UNITS
INFO,CoFe2O4,SAMPLE_MATERIAL
INFO,AH11 DL,SAMPLE_COMMENT
INFO,30.27,SAMPLE_MASS
INFO,,SAMPLE_VOLUME
INFO,,SAMPLE_MOLECULAR_WEIGHT
INFO,,SAMPLE_SIZE
INFO,,SAMPLE_SHAPE
DATATYPE,COMMENT,1
DATATYPE,TIME,2
STARTUPAXIS,X,2
STARTUPAXIS,Y1,5
[Data]
Comment,Time Stamp (sec),Temperature (K),Magnetic Field (Oe),Moment (emu),M. Std. Err. (emu),Transport Action,Averaging Time (sec),Frequency (Hz),Peak Amplitude (mm),Center Position (mm),Coil Signal' (mV),Coil Signal" (mV),Range (mV),M. Quad. Signal (emu),M. Raw' (emu),M. Raw" (emu),Min. Temperature (K),Max. Temperature (K),Min. Field (Oe),Max. Field (Oe),Mass (grams),Motor Lag (deg),Pressure (Torr),VSM Status (code),Motor Status (code),Measure Status (code),Measure Count,PPMS Status (code),System Temp. (K),System Field (Oe),Sample Position (deg),Bridge 1 Resistance (ohms),Bridge 1 Excitation (에),Bridge 2 Resistance (ohms),Bridge 2 Excitation (에),Bridge 3 Resistance (ohms),Bridge 3 Excitation (에),Bridge 4 Resistance (ohms),Bridge 4 Excitation (에),Signal 1 Vin (V),Signal 2 Vin (V),Digital Inputs (code),Drive 1 Iout (mA),Drive 1 Ipower (W),Drive 2 Iout (mA),Drive 2 Ipower (W),Pressure (),Map 20 (),Map 21 (),Map 22 (),Map 23 (),Map 24 (),Map 25 (),Map 26 (),Map 27 (),Map 28 (),Map 29 ()
,30918417.925,10.0024176,99.3960113525391,1.95827716546228E-5,3.32150456500429E-7,1,0.999253354069792,40.0298881530762,1.98437456393688,16.0900000482798,0.000218217380209407,4.14764026851841E-5,0.25,2.36662201411314E-7,1.94691835264248E-5,3.29747495570591E-7,10.0024176,10.0024176,99.3960113525391,99.3960113525391,57.3238539718714,20.6483157390379,12.658426,0,0,0,40,4369,9.99415,99.3960113525391,,,,,,,,,,,,,0,,,,0.0049,,,,,,10.0024176,,,,
,30918546.72,13.0049372,99.3960113525391,1.92646076773025E-5,2.87602703090286E-7,1,0.999253354069792,40.0298881530762,1.98375830272952,16.0900000482798,0.000215140011417157,3.77887975608096E-5,0.25,-3.60301449493795E-8,1.91540499416561E-5,5.70862017255445E-8,13.0049372,13.0049372,99.3960113525391,99.3960113525391,57.2433462343907,20.6582190178107,13.038077,0,0,0,40,4370,13.1037,99.3960113525391,,,,,,,,,,,,,0,,,,0,,,,,,13.0049372,,,,
,30918689.98,16.5375118,99.3960113525391,1.97132794783401E-5,3.61240109562406E-7,1,0.999253354069792,40.0298881530762,1.98358780830231,16.0900000482798,0.000220092155674866,3.8880645279148E-5,0.25,-1.75821110252517E-8,1.9599862450368E-5,7.75912920761155E-8,16.5375118,16.5375118,99.3960113525391,99.3960113525391,57.484869446833,20.6577187927372,13.797379,0,0,0,40,4370,16.6959,99.3960113525391,,,,,,,,,,,,,0,,,,0,,,,,,16.5375118,,,,
,30918843.92,20.3917561,99.3960113525391,,,2,,,,16.1299998554587,,,,,,,20.3917561,20.3917561,99.3960113525391,99.3960113525391,,,14.177031,,,,-99999999,4370,20.5653,99.3960113525391,,,,,,,,,,,,,,,,,,,,,,,20.3917561,,,,
,30918969.415,23.5079689,99.3960113525391,1.98921839388316E-5,3.54735904831619E-7,1,0.999253354069792,40.0298881530762,1.98356504270874,16.1199998110533,0.000221790127947563,4.10550667017215E-5,0.25,1.41784936297336E-7,1.97792441794259E-5,2.40180649932066E-7,23.5079689,23.5079689,99.3960113525391,99.3960113525391,57.1612752398714,20.6573411217829,14.556682,0,0,0,40,4370,23.7333,99.3960113525391,,,,,,,,,,,,,0,,,,-0.0049,,,,,,23.5079689,,,,
,30919112.47,27.0540848,99.3960113525391,1.93985989802876E-5,3.81973655069592E-7,1,0.999253354069792,40.0298881530762,1.98386428295344,16.1199998110533,0.000216827528531902,3.74484794685497E-5,0.25,-9.95281806837499E-8,1.92938107811672E-5,2.51352751553853E-9,27.0540848,27.0540848,99.3960113525391,99.3960113525391,57.0026046504676,20.6515220358236,15.315984,0,0,0,40,4370,27.33925,99.3960113525391,,,,,,,,,,,,,0,,,,0,,,,,,27.0540848,,,,
,30919264.58,30.8341541,99.3960113525391,,,2,,,,16.1299998554587,,,,,,,30.8341541,30.8341541,99.3960113525391,99.3960113525391,,,15.315984,,,,-99999999,4370,31.1573,99.3960113525391,,,,,,,,,,,,,,,,,,,,,,,30.8341541,,,,
,30919393.18,34.0036736,99.3960113525391,1.94770478001693E-5,3.09676228370953E-7,1,0.999253354069792,40.0298881530762,1.99532457689854,16.1199998110533,0.000218798062955471,3.94743822566522E-5,0.25,3.07985091038507E-8,1.93873583889126E-5,1.4736837923437E-7,34.0036736,34.0036736,99.3960113525391,99.3960113525391,56.8361177758714,20.6464499891609,15.695635,0,0,0,40,4370,34.40255,99.3960113525391,,,,,,,,,,,,,0,,,,0.0049,,,,,,34.0036736,,,,
,30919537.375,37.5407219,99.3960113525391,1.93381772789961E-5,2.9858616285853E-7,1,0.999253354069792,40.0298881530762,1.99516504496457,16.1199998110533,0.000217821432331762,3.67129797386636E-5,0.25,-2.01148989105891E-7,1.9263952196824E-5,-7.54492579507404E-8,37.5407219,37.5407219,99.3960113525391,99.3960113525391,57.3746598256215,20.65005849133,16.075285,0,0,0,40,4370,38.0405,99.3960113525391,,,,,,,,,,,,,0,,,,-0.0049,,,,,,37.5407219,,,,
,30919685.38,41.2291565,99.3960113525391,,,2,,,,16.1200002449751,,,,,,,41.2291565,41.2291565,99.3960113525391,99.3960113525391,,,16.454937,,,,-99999999,4370,41.7841,99.3960113525391,,,,,,,,,,,,,,,,,,,,,,,41.2291565,,,,
,30919819.6,44.5202408,99.3960113525391,1.9556013058732E-5,3.04309592129984E-7,1,0.999253354069792,40.0298881530762,1.99526837682431,16.1099992692471,0.000220390682304056,3.89234431862336E-5,0.25,-6.50890615659354E-8,1.95165710548841E-5,7.6408062212345E-8,44.5202408,44.5202408,99.3960113525391,99.3960113525391,57.3949821671215,20.6501858386742,16.454937,0,0,0,40,4370,45.179,99.3960113525391,,,,,,,,,,,,,0,,,,-0.00245,,,,,,44.5202408,,,,
,30919961.9,48.0076408,99.3960113525391,1.98027736717336E-5,2.9282687751518E-7,1,0.999253354069792,40.0298881530762,1.99483218915075,16.1099992692471,0.000224122399338934,3.53059637254384E-5,0.25,-4.37131498257232E-7,1.97877373838845E-5,-2.89864219332474E-7,48.0076408,48.0076408,99.3960113525391,99.3960113525391,57.2284952925253,20.6583599334697,17.214239,0,0,0,40,4370,48.7997,99.3960113525391,,,,,,,,,,,,,0,,,,0,,,,,,48.0076408,,,,
,30920109.77,51.6348686,99.3960113525391,,,2,,,,16.1000000926852,,,,,,,51.6348686,51.6348686,99.3960113525391,99.3960113525391,,,17.593889,,,,-99999999,4370,52.5614,99.3960113525391,,,,,,,,,,,,,,,,,,,,,,,51.6348686,,,,
,30920250.16,55.0546227,99.3960113525391,1.95188544079794E-5,4.11142994110745E-7,1,0.999253354069792,40.0298881530762,1.98340117721299,16.0900000482798,0.00021940167034662,3.90647739331991E-5,0.25,-3.75611388291998E-8,1.95446945835074E-5,1.03810480320597E-7,55.0546227,55.0546227,99.3960113525391,99.3960113525391,57.1003082153714,20.6527700106759,18.353191,0,0,0,40,4374,56.1313,99.3960113525391,,,,,,,,,,,,,0,,,,0,,,,,,55.0546227,,,,
,30920391.82,58.5480156,99.3960113525391,1.92509450210071E-5,2.76146349420195E-7,1,0.999253354069792,40.0298881530762,1.98346444194088,16.0900000482798,0.000216773755404785,3.76007316864566E-5,0.25,-1.16864274127831E-7,1.92951497201362E-5,1.64741903975635E-8,58.5480156,58.5480156,99.3960113525391,99.3960113525391,56.7798405224868,20.6522486168698,17.973541,0,0,0,40,4374,59.72215,99.3960113525391,,,,,,,,,,,,,0,,,,-0.00245,,,,,,58.5480156,,,,
,30920532.69,62.0127487,99.3960113525391,,,2,,,,16.0799999403954,,,,,,,62.0127487,62.0127487,99.3960113525391,99.3960113525391,,,18.732843,,,,-99999999,4374,63.2837,99.3960113525391,,,,,,,,,,,,,,,,,,,,,,,62.0127487,,,,
,30920656.08,65.0664215,99.3960113525391,1.94417777849279E-5,3.55454524794615E-7,1,0.999253354069792,40.0298881530762,1.99501753960626,16.0700008273125,0.000220833815680859,3.6033313842417E-5,0.25,-2.97598580829663E-7,1.95141316833477E-5,-1.7854909619227E-7,65.0664215,65.0664215,99.3960113525391,99.3960113525391,56.8603482599676,20.651263551477,18.353191,0,0,0,40,4374,66.4065,99.3960113525391,,,,,,,,,,,,,0,,,,-0.00245,,,,,,65.0664215,,,,
,30920797.32,68.5419083,99.3960113525391,1.94217444202986E-5,3.30336759244249E-7,1,0.999253354069792,40.0298881530762,1.9949286703632,16.0700008273125,0.000220910626078848,3.49036659363306E-5,0.25,-3.86703163081597E-7,1.95048073877626E-5,-2.7678831572752E-7,68.5419083,68.5419083,99.3960113525391,99.3960113525391,57.2019199228714,20.6493258884611,18.732843,0,0,0,40,4374,69.9766,99.3960113525391,,,,,,,,,,,,,0,,,,-0.0049,,,,,,68.5419083,,,,
,30920937.355,72.0409393,99.3960113525391,1.94041622663766E-5,3.09911904058521E-7,1,0.999253354069792,40.0298881530762,1.99511203170201,16.0700008273125,0.00021963862123154,4.15209137430142E-5,0.25,2.06628410893903E-7,1.94919220023928E-5,3.10798873251511E-7,72.0409393,72.0409393,99.3960113525391,99.3960113525391,57.1823792098907,20.651493843999,18.732843,0,0,0,40,4374,73.5308,99.3960113525391,,,,,,,,,,,,,0,,,,0,,,,,,72.0409393,,,,
,30921060.415,75.0565605,99.3960113525391,1.91085106342493E-5,3.43400339411239E-7,1,0.999253354069792,40.0298881530762,1.98367857843479,16.0499997437,0.00021626987399685,3.4485994894665E-5,0.25,-3.38509913194689E-7,1.92031667326493E-5,-2.45171745390293E-7,75.0301056,75.0830154,99.3960113525391,99.3960113525391,57.1792526958137,20.6514370759729,19.112494,0,0,0,40,4374,76.6382,99.3960113525391,,,,,,,,,,,,,0,,,,-0.0049,,,,,,75.0565605,,,,
,30921203.365,78.5799179,99.3960113525391,1.92906304785088E-5,3.28291917674907E-7,1,0.999253354069792,40.0298881530762,1.9835686441436,16.0499997437,0.000218142511515597,3.61251129945587E-5,0.25,-2.1897724896223E-7,1.93904608909879E-5,-1.31461912125979E-7,78.5799179,78.5799179,99.3960113525391,99.3960113525391,57.4246840508522,20.6519844223275,19.112494,0,0,0,40,4374,80.25735,99.3960113525391,,,,,,,,,,,,,0,,,,0,,,,,,78.5799179,,,,
,30921344.275,82.0067139,99.3960113525391,1.91949069564883E-5,2.99204541763656E-7,1,0.999253354069792,40.0298881530762,1.98360215521781,16.0499997437,0.000216768910478824,3.78452185738211E-5,0.25,-4.3801730445524E-8,1.92970975562215E-5,3.76733646789611E-8,82.0067139,82.0067139,99.3960113525391,99.3960113525391,57.2316218066022,20.6499931342624,18.732843,0,0,0,40,4374,83.8405,99.3960113525391,,,,,,,,,,,,,0,,,,0.00245,,,,,,82.0067139,,,,
,30921483.515,85.5220642,99.3960113525391,1.96133677460541E-5,3.53986459753383E-7,1,0.999253354069792,40.0298881530762,1.98376509129896,16.0199999809265,0.000222000966869211,3.60750607120955E-5,0.25,-2.69500992393352E-7,1.972129311604E-5,-1.93313864125888E-7,85.5220642,85.5220642,99.3960113525391,99.3960113525391,57.1104693861214,20.6487531102975,19.871798,0,0,0,40,4374,87.33325,99.3960113525391,,,,,,,,,,,,,0,,,,0,,,,,,85.5220642,,,,
,30921628.625,89.1459885,99.3960113525391,1.92738307080031E-5,3.6047890616393E-7,1,0.999253354069792,40.0298881530762,1.98386052120157,16.0199999809265,0.000219023725452943,3.07183499851211E-5,0.25,-6.78944140748648E-7,1.938325392521E-5,-6.11766221448482E-7,89.1459885,89.1459885,99.3960113525391,99.3960113525391,57.6021137247176,20.647416468707,19.871798,0,0,0,40,4374,90.97395,99.3960113525391,,,,,,,,,,,,,0,,,,0.0049,,,,,,89.1459885,,,,
,30921767.985,92.5645828,99.3960113525391,1.93335061362253E-5,3.41701607597523E-7,1,0.999253354069792,40.0298881530762,1.98383677690877,16.0199999809265,0.000218766817261836,3.61795470069749E-5,0.25,-2.01447145981183E-7,1.94427140560673E-5,-1.36051059358205E-7,92.5645828,92.5645828,99.3960113525391,99.3960113525391,57.0635716749676,20.6479692196179,19.871798,0,0,0,40,4374,94.47185,99.3960113525391,,,,,,,,,,,,,0,,,,0,,,,,,92.5645828,,,,
,30921906.9,96.0696869,99.3960113525391,1.92887315788023E-5,3.11358848656657E-7,1,0.999253354069792,40.0298881530762,1.98379481700424,15.990000218153,0.000218580862886702,3.42917146003637E-5,0.25,-3.56613860494603E-7,1.93988866769944E-5,-2.96407925852605E-7,96.0696869,96.0696869,99.3960113525391,99.3960113525391,57.0510656186599,20.6459736306869,19.871798,0,0,0,40,4374,97.9635,99.3960113525391,,,,,,,,,,,,,0,,,,0,,,,,,96.0696869,,,,
,30922045.555,99.5212708,99.3960113525391,1.94103867067657E-5,3.88542316171382E-7,1,0.999253354069792,40.0298881530762,1.98376054951804,15.990000218153,0.000219076441383352,3.95320405415579E-5,0.25,8.96459189903252E-8,1.95201769786297E-5,1.4901956908494E-7,99.5212708,99.5212708,99.3960113525391,99.3960113525391,56.8400259184676,20.6482487926064,19.492144,0,0,0,40,4374,101.4421,99.3960113525391,,,,,,,,,,,,,0,,,,-0.00245,,,,,,99.5212708,,,,
,30922188.97,103.029541,99.3960113525391,1.90525846392519E-5,3.45931714739971E-7,1,0.999253354069792,40.0298881530762,1.98372350947727,15.990000218153,0.000215584053383061,3.56754279137436E-5,0.25,-1.85440205058755E-7,1.916122542306E-5,-1.32156777363011E-7,103.029541,103.029541,99.3960113525391,99.3960113525391,56.7626446950637,20.651873364943,20.251448,0,0,0,40,4374,105.05895,99.3960113525391,,,,,,,,,,,,,0,,,,0,,,,,,103.029541,,,,
,30922327.28,106.5032501,99.3960113525391,1.93574529626734E-5,3.02008968397894E-7,1,0.999253354069792,40.0298881530762,1.98390801265664,15.9499999135733,0.000219522590491209,3.35543515315718E-5,0.25,-4.23916095245043E-7,1.94682041765147E-5,-3.74146228726848E-7,106.5032501,106.5032501,99.3960113525391,99.3960113525391,57.098744958333,20.6453249897678,20.631098,0,0,0,40,4374,108.537,99.3960113525391,,,,,,,,,,,,,0,,,,0,,,,,,106.5032501,,,,
,30922470.345,110.0376511,99.3960113525391,1.91288338462724E-5,3.50700411815966E-7,1,0.999253354069792,40.0298881530762,1.98398984312478,15.9499999135733,0.000216461735973384,3.5846968022855E-5,0.25,-1.78148992323089E-7,1.92371592978889E-5,-1.30405533199123E-7,110.0376511,110.0376511,99.3960113525391,99.3960113525391,57.2644502044099,20.6478670355147,19.871798,0,0,0,40,4374,112.1356,99.3960113525391,,,,,,,,,,,,,0,,,,0,,,,,,110.0376511,,,,
,30922612.24,113.5474167,99.3960113525391,1.93281747727754E-5,2.94743562317487E-7,1,0.999253354069792,40.0298881530762,1.98374965693106,15.9499999135733,0.000218939590136941,3.47586769221141E-5,0.25,-3.06401390600946E-7,1.94372703837135E-5,-2.61412966129896E-7,113.5474167,113.5474167,99.3960113525391,99.3960113525391,56.821266834006,20.6534376847798,20.251448,0,0,0,40,4374,115.71025,99.3960113525391,,,,,,,,,,,,,0,,,,0,,,,,,113.5474167,,,,
,30922733.265,116.5470886,99.3960113525391,1.90546551315219E-5,3.26116070895312E-7,1,0.999253354069792,40.0298881530762,1.98384560866151,15.9200001507998,0.000215528554646652,3.60661451734852E-5,0.25,-1.40863553593057E-7,1.91611297086706E-5,-9.75604577863775E-8,116.5470886,116.5470886,99.3960113525391,99.3960113525391,56.9400743689291,20.6437248158563,20.631098,0,0,0,40,4374,118.7539,99.3960113525391,,,,,,,,,,,,,0,,,,-0.0049,,,,,,116.5470886,,,,
,30922873.36,120.0178909,99.3960113525391,1.90047213210013E-5,3.32239033920878E-7,1,0.999253354069792,40.0298881530762,1.98377275759828,15.9200001507998,0.000215389783248995,3.34291250932664E-5,0.25,-3.63254093906181E-7,1.91104860741058E-5,-3.23361123794928E-7,120.0178909,120.0178909,99.3960113525391,99.3960113525391,57.2402197203138,20.6441459225544,20.251448,0,0,0,40,4374,122.27675,99.3960113525391,,,,,,,,,,,,,0,,,,0,,,,,,120.0178909,,,,
,30923012.795,123.5172539,99.3960113525391,1.94409913366414E-5,3.60616970119882E-7,1,0.999253354069792,40.0298881530762,1.98408378031442,15.9200001507998,0.000220394049695074,3.39745630404812E-5,0.25,-3.89612508022959E-7,1.954811423442E-5,-3.50802911821589E-7,123.4822388,123.552269,99.3960113525391,99.3960113525391,57.2402197203138,20.6416707135464,20.631098,0,0,0,40,4374,125.76745,99.3960113525391,,,,,,,,,,,,,0,,,,-0.0049,,,,,,123.5172539,,,,
,30923134.255,126.5398369,99.3960113525391,1.89398174528142E-5,3.30810408561458E-7,1,0.999253354069792,40.0298881530762,2.00819763826312,15.8699993044138,0.000217266742440895,3.30466401378307E-5,0.25,-4.16057913702587E-7,1.90432410959745E-5,-3.79938282322946E-7,126.5036316,126.5760422,99.3960113525391,99.3960113525391,57.0870205305445,20.6312280648145,20.251448,0,0,0,40,4374,128.8262,99.3960113525391,,,,,,,,,,,,,0,,,,0,,,,,,126.5398369,,,,
,30923274.41,130.0604095,99.3960113525391,1.90460306884502E-5,3.13504364209701E-7,1,0.999253354069792,40.0298881530762,2.00830382042539,15.8699993044138,0.000217954831444942,3.62485374933075E-5,0.25,-1.52764123441046E-7,1.91482370918618E-5,-1.16609086651993E-7,130.0604095,130.0604095,99.3960113525391,99.3960113525391,56.8587850029291,20.638963857258,21.01075,0,0,0,40,4374,132.34685,99.3960113525391,,,,,,,,,,,,,0,,,,0,,,,,,130.0604095,,,,
,30923415.01,133.5062561,99.3960113525391,1.88639532336232E-5,3.16833574913868E-7,1,0.999253354069792,40.0298881530762,2.0081238817975,15.8699993044138,0.000215900877674556,3.55360481806187E-5,0.25,-1.81386272259748E-7,1.89639427214801E-5,-1.47198025612354E-7,133.5062561,133.5062561,99.3960113525391,99.3960113525391,57.3066581444484,20.6433582391384,20.631098,0,0,0,40,4374,135.8662,99.3960113525391,,,,,,,,,,,,,0,,,,0.00245,,,,,,133.5062561,,,,
,30923556.385,137.0443573,99.3960113525391,1.9298058608773E-5,2.92908002516567E-7,1,0.999253354069792,40.0298881530762,2.00832289188367,15.8300008624792,0.000221612758863379,3.21166747177319E-5,0.25,-5.55051986342144E-7,1.93995614756087E-5,-5.23390215335689E-7,137.0443573,137.0443573,99.3960113525391,99.3960113525391,57.3090030300061,20.6425694079106,21.01075,0,0,0,40,4374,139.4187,99.3960113525391,,,,,,,,,,,,,0,,,,0,,,,,,137.0443573,,,,
,30923696.16,140.5401154,99.3960113525391,1.91829215029549E-5,3.52214315250087E-7,1,0.999253354069792,40.0298881530762,2.00824745332239,15.8300008624792,0.000220203621501885,3.22752018644729E-5,0.25,-5.19507615078493E-7,1.92822452610578E-5,-4.8910070023968E-7,140.5401154,140.5401154,99.3960113525391,99.3960113525391,57.2925888311022,20.6391134688368,20.631098,0,0,0,40,4374,142.9293,99.3960113525391,,,,,,,,,,,,,0,,,,0,,,,,,140.5401154,,,,
,30923836.685,144.0314331,99.3960113525391,1.91912453764589E-5,3.71644114467674E-7,1,0.999253354069792,40.0298881530762,2.00826478898778,15.8300008624792,0.000219611198366792,3.61413968406787E-5,0.25,-1.81160189972609E-7,1.92884741197768E-5,-1.50174467177731E-7,144.0314331,144.0314331,99.3960113525391,99.3960113525391,56.9596150819099,20.6388345063998,21.01075,0,0,0,40,4374,146.454,99.3960113525391,,,,,,,,,,,,,0,,,,-0.00245,,,,,,144.0314331,,,,
,30923976.32,147.51589965,99.3960113525391,1.94084335653676E-5,3.60930262850124E-7,1,0.999253354069792,40.0298881530762,1.9957101646823,15.7800000160933,0.000220845480530451,3.57997989329214E-5,0.25,-2.28742720414939E-7,1.95052069741549E-5,-1.9872581869607E-7,147.4866943,147.545105,99.3960113525391,99.3960113525391,57.180034324333,20.6376232698827,20.631098,0,0,0,40,4374,149.96,99.3960113525391,,,,,,,,,,,,,0,,,,-0.0049,,,,,,147.51589965,,,,
,30924115.775,151.0108032,99.3960113525391,1.90620217633354E-5,3.53174794233109E-7,1,0.999253354069792,40.0298881530762,1.99574513495884,15.7800000160933,0.000216729013356241,3.60741723855823E-5,0.25,-1.43000292962767E-7,1.91552800766397E-5,-1.14114515525119E-7,151.0108032,151.0108032,99.3960113525391,99.3960113525391,57.0604451608906,20.6374536055921,21.01075,0,0,0,40,4374,153.46405,99.3960113525391,,,,,,,,,,,,,0,,,,-0.00245,,,,,,151.0108032,,,,
,30924256.4,154.5048828,99.3960113525391,1.91495322863495E-5,3.42767472650126E-7,1,0.999253354069792,40.0298881530762,1.99564321672736,15.7800000160933,0.000217625206636194,3.66297159294873E-5,0.25,-1.07924959515792E-7,1.92414520452852E-5,-7.9676424553531E-8,154.5048828,154.5048828,99.3960113525391,99.3960113525391,57.2699216040445,20.6379576865084,21.01075,0,0,0,40,4374,156.9831,99.3960113525391,,,,,,,,,,,,,0,,,,0.00245,,,,,,154.5048828,,,,
,30924398.84,158.0449066,99.3960113525391,1.91802193641292E-5,3.32747138806952E-7,1,0.999253354069792,40.0298881530762,1.98427733672435,15.7399997115135,0.000217387193355459,3.29300897188572E-5,0.25,-4.22095048220633E-7,1.92709595106495E-5,-3.96173168997204E-7,158.0449066,158.0449066,99.3960113525391,99.3960113525391,57.1042163579676,20.6371340558836,21.01075,0,0,0,40,4374,160.5571,99.3960113525391,,,,,,,,,,,,,0,,,,0,,,,,,158.0449066,,,,
,30924538.825,161.5402832,99.3960113525391,1.92028014109469E-5,3.85339811741604E-7,1,0.999253354069792,40.0298881530762,1.98433949559706,15.7399997115135,0.000217053085666196,3.62765811318502E-5,0.25,-1.28600657591032E-7,1.92914111308802E-5,-1.02086635539918E-7,161.5402832,161.5402832,99.3960113525391,99.3960113525391,57.0807675023906,20.6377196935847,21.01075,0,0,0,40,4374,164.05605,99.3960113525391,,,,,,,,,,,,,0,,,,-0.00245,,,,,,161.5402832,,,,
,30924677.195,165.0317383,99.3960113525391,1.91704632987678E-5,3.8888073744181E-7,1,0.999253354069792,40.0298881530762,1.98405058356875,15.7399997115135,0.000217193818469862,3.30045344490599E-5,0.25,-4.11332938176938E-7,1.92574659531352E-5,-3.86901149804858E-7,165.0317383,165.0317383,99.3960113525391,99.3960113525391,57.6622991206984,20.6384322649796,21.3904,0,0,0,40,4374,167.52965,99.3960113525391,,,,,,,,,,,,,0,,,,0.00245,,,,,,165.0317383,,,,
,30924798.235,168.0388184,99.3960113525391,1.89634859985771E-5,3.26541904970208E-7,1,0.999253354069792,40.0298881530762,1.99578396782676,15.6900007277727,0.000215277375286092,3.72349121542542E-5,0.25,-1.81585106285743E-8,1.90474182740939E-5,7.13451837053449E-9,168.0388184,168.0388184,99.3960113525391,99.3960113525391,56.8048526351022,20.637238527717,21.3904,0,0,0,40,4374,170.5523,99.3960113525391,,,,,,,,,,,,,0,,,,-0.0049,,,,,,168.0388184,,,,
,30924938.31,171.555954,99.3960113525391,1.9189272618891E-5,3.55990310534094E-7,1,0.999253354069792,40.0298881530762,1.99566317060247,15.6900007277727,0.000218136789445771,3.57712839381274E-5,0.25,-1.85194062059989E-7,1.92724945846903E-5,-1.61016824889294E-7,171.555954,171.555954,99.3960113525391,99.3960113525391,57.0385595623522,20.6360120729541,21.3904,0,0,0,40,4374,174.0524,99.3960113525391,,,,,,,,,,,,,0,,,,0,,,,,,171.555954,,,,
,30925079.04,175.0557861,99.3960113525391,1.94137418504989E-5,4.62633712942571E-7,1,0.999253354069792,40.0298881530762,1.99555803143903,15.6900007277727,0.000221044673661059,3.39429522701726E-5,0.25,-3.84218150508533E-7,1.94962076416157E-5,-3.61240392010657E-7,175.0557861,175.0557861,99.3960113525391,99.3960113525391,56.9525804252368,20.6440578650343,21.770052,0,0,0,40,4374,177.5765,99.3960113525391,,,,,,,,,,,,,0,,,,-0.0049,,,,,,175.0557861,,,,
,30925200.14,178.0607452,99.3960113525391,1.8950122077908E-5,3.34978765215828E-7,1,0.999253354069792,40.0298881530762,2.00823728050808,15.6399998813868,0.000216843825678048,3.45415636146601E-5,0.25,-2.68392398080283E-7,1.90287968397476E-5,-2.46022837130566E-7,178.0607452,178.0607452,99.3960113525391,99.3960113525391,57.0706063316407,20.6392209697836,21.3904,0,0,0,40,4374,180.6082,99.3960113525391,,,,,,,,,,,,,0,,,,0.0049,,,,,,178.0607452,,,,
,30925338.255,181.5030975,99.3960113525391,1.90725059369855E-5,3.81012318800722E-7,1,0.999253354069792,40.0298881530762,2.0082085088139,15.6399998813868,0.00021755213503466,3.85959276615592E-5,0.25,6.64871971852793E-8,1.91493094907647E-5,8.98041912822031E-8,181.5030975,181.5030975,99.3960113525391,99.3960113525391,57.0401228193907,20.6409494011671,22.149702,0,0,0,40,4374,184.0641,99.3960113525391,,,,,,,,,,,,,0,,,,0.0049,,,,,,181.5030975,,,,
,30925479.39,185.062912,99.3960113525391,1.94218943706559E-5,3.95971135684104E-7,1,0.999253354069792,40.0298881530762,2.00806281534377,15.6399998813868,0.000221525752848252,3.9138022662818E-5,0.25,5.44295751153594E-8,1.9498022642775E-5,7.75400946293451E-8,185.062912,185.062912,99.3960113525391,99.3960113525391,57.0135474497368,20.6352005975739,21.770052,0,0,0,40,4374,187.59715,99.3960113525391,,,,,,,,,,,,,0,,,,0,,,,,,185.062912,,,,
,30925598.17,188.0211487,99.3960113525391,1.94281217216907E-5,3.21208452538588E-7,1,0.999253354069792,40.0298881530762,2.00805279166219,15.5899999663234,0.000221991319309921,3.67547439422618E-5,0.25,-1.54734864517459E-7,1.95027506612509E-5,-1.32885436100948E-7,188.0211487,188.0211487,99.3960113525391,99.3960113525391,57.1784710672945,20.6366512857588,22.529354,0,0,0,40,4374,190.57965,99.3960113525391,,,,,,,,,,,,,0,,,,-0.00245,,,,,,188.0211487,,,,
,30925741.065,191.56436155,99.3960113525391,1.94485419783846E-5,3.61127379544496E-7,1,0.999253354069792,40.0298881530762,1.99536778732188,15.5899999663234,0.000221160397329904,3.48429455164289E-5,0.25,-3.06446522507379E-7,1.95212728119139E-5,-2.85651983131874E-7,191.5372467,191.5914764,99.3960113525391,99.3960113525391,56.7712426087752,20.6452966064423,22.149702,0,0,0,40,4374,194.16975,99.3960113525391,,,,,,,,,,,,,0,,,,-0.00245,,,,,,191.56436155,,,,
,30925879.945,195.036026,99.3960113525391,1.96930916319417E-5,3.7405191697354E-7,1,0.999253354069792,40.0298881530762,1.99553009619997,15.5899999663234,0.000223617465760078,3.71033783594592E-5,0.25,-1.49013588610212E-7,1.97643984845321E-5,-1.27838141768034E-7,195.036026,195.036026,99.3960113525391,99.3960113525391,57.2558522906984,20.643356039934,21.770052,0,0,0,40,4374,197.6587,99.3960113525391,,,,,,,,,,,,,0,,,,-0.00245,,,,,,195.036026,,,,
,30926021.585,198.5215302,99.3960113525391,1.95195181896101E-5,4.25430832740506E-7,1,0.999253354069792,40.0298881530762,1.98406556727596,15.54000005126,0.000220941039665596,3.34901068583611E-5,0.25,-4.20390563931327E-7,1.95883213332452E-5,-4.00818091723684E-7,198.5215302,198.5215302,99.3960113525391,99.3960113525391,56.9041194570445,20.6425107760184,21.770052,0,0,0,40,4374,201.2081,99.3960113525391,,,,,,,,,,,,,0,,,,-0.00245,,,,,,198.5215302,,,,
,30926160.52,202.01420595,99.3960113525391,1.92455663767973E-5,3.26721661846995E-7,1,0.999253354069792,40.0298881530762,1.98417908402029,15.54000005126,0.000217899254674576,3.26053904438894E-5,0.25,-4.50659204140168E-7,1.93112688376053E-5,-4.31878507808509E-7,201.9862671,202.0421448,99.3960113525391,99.3960113525391,56.9674313671022,20.6381271761899,22.529354,0,0,0,40,4374,204.6882,99.3960113525391,,,,,,,,,,,,,0,,,,-0.00245,,,,,,202.01420595,,,,
,30926301.86,205.5322876,99.3960113525391,1.96666180899855E-5,3.21170435541586E-7,1,0.999253354069792,40.0298881530762,1.98432912654788,15.54000005126,0.000222814354668315,3.24111716328267E-5,0.25,-5.40444449394264E-7,1.97315818195413E-5,-5.21902057085604E-7,205.5322876,205.5322876,99.3960113525391,99.3960113525391,57.0369963053137,20.6427446355921,22.149702,0,0,0,40,4374,208.24245,99.3960113525391,,,,,,,,,,,,,0,,,,0.00245,,,,,,205.5322876,,,,
,30926442.025,209.0173035,99.3960113525391,1.95074973753433E-5,3.69099533600527E-7,1,0.999253354069792,40.0298881530762,2.0085333162461,15.4900001361966,0.000222882086941689,3.64141905700393E-5,0.25,-1.94185846844133E-7,1.95693481101706E-5,-1.75063415579705E-7,209.0173035,209.0173035,99.3960113525391,99.3960113525391,56.7915649502752,20.6423267119718,21.770052,0,0,0,40,4374,211.74485,99.3960113525391,,,,,,,,,,,,,0,,,,0,,,,,,209.0173035,,,,
,30926580.805,212.5214539,99.3960113525391,1.91043226300832E-5,3.70922216605078E-7,1,0.999253354069792,40.0298881530762,2.00863371788175,15.4900001361966,0.000218552375115725,3.3979253844855E-5,0.25,-3.3708679501444E-7,1.91628211741477E-5,-3.19169542391761E-7,212.5214539,212.5214539,99.3960113525391,99.3960113525391,57.0604451608906,20.6409970959079,22.149702,0,0,0,40,4374,215.2294,99.3960113525391,,,,,,,,,,,,,0,,,,-0.0049,,,,,,212.5214539,,,,
,30926721.015,216.0098419,99.3960113525391,1.91795337770844E-5,3.74752502550963E-7,1,0.999253354069792,40.0298881530762,2.00876480416009,15.4900001361966,0.00021900352536125,3.64005739343015E-5,0.25,-1.37296947609489E-7,1.92358287301069E-5,-1.19054906896154E-7,216.0098419,216.0098419,99.3960113525391,99.3960113525391,57.0917103016599,20.6417305694719,22.529354,0,0,0,40,4374,218.74465,99.3960113525391,,,,,,,,,,,,,0,,,,0.0049,,,,,,216.0098419,,,,
,30926863.555,219.5363464,99.3960113525391,1.95040102019092E-5,3.93968986854477E-7,1,0.999253354069792,40.0298881530762,2.00884421978742,15.4200000688434,0.000223641871280048,3.1532538763212E-5,0.25,-6.19880283872954E-7,1.95594009003377E-5,-6.03033347798527E-7,219.5363464,219.5363464,99.3960113525391,99.3960113525391,56.9400743689291,20.6428919737433,22.529354,0,0,0,40,4374,222.3125,99.3960113525391,,,,,,,,,,,,,0,,,,0,,,,,,219.5363464,,,,
,30927004.05,223.0496521,99.3960113525391,1.93987868095713E-5,3.86905637558209E-7,1,0.999253354069792,40.0298881530762,2.00883082876908,15.4200000688434,0.000221075884596588,3.90312889472463E-5,0.25,5.67353692423401E-8,1.94509303877938E-5,7.50274824006698E-8,223.0496521,223.0496521,99.3960113525391,99.3960113525391,57.0299616486406,20.6302142677676,22.529354,0,0,0,40,4374,225.81985,99.3960113525391,,,,,,,,,,,,,0,,,,-0.0049,,,,,,223.0496521,,,,
,30927142.885,226.52352905,99.3960113525391,1.96390126281516E-5,3.75610876333647E-7,1,0.999253354069792,40.0298881530762,2.00893505109274,15.4200000688434,0.000224113677295045,3.7694067643967E-5,0.25,-1.01667923932258E-7,1.9689623979049E-5,-8.3903938466222E-8,226.4954834,226.5515747,99.3960113525391,99.3960113525391,57.0354330482753,20.6352239297502,22.149702,0,0,0,40,4374,229.31,99.3960113525391,,,,,,,,,,,,,0,,,,-0.00245,,,,,,226.52352905,,,,
,30927262.135,229.5035324,99.3960113525391,1.92799333604197E-5,3.64123504542324E-7,1,0.999253354069792,40.0298881530762,2.00875183573918,15.37000015378,0.000220078607587841,3.63973899508437E-5,0.25,-1.52215538426101E-7,1.93276959067869E-5,-1.35169301186955E-7,229.4719696,229.5350952,99.3960113525391,99.3960113525391,56.8626931455252,20.6309462571516,22.529354,0,0,0,40,4374,232.2816,99.3960113525391,,,,,,,,,,,,,0,,,,0,,,,,,229.5035324,,,,
,30927405.485,233.0699158,99.3960113525391,1.94935218826124E-5,2.98767283927483E-7,1,0.999253354069792,40.0298881530762,2.00850979636771,15.37000015378,0.000222310729196545,3.76743449660471E-5,0.25,-7.61460929729867E-8,1.95393468332951E-5,-5.90348232969512E-8,233.0699158,233.0699158,99.3960113525391,99.3960113525391,57.1237570709483,20.638066191663,22.909004,0,0,0,40,4374,235.8923,99.3960113525391,,,,,,,,,,,,,0,,,,0,,,,,,233.0699158,,,,
,30927543.82,236.5257721,99.3960113525391,1.92254900965924E-5,3.16721678696655E-7,1,0.999253354069792,40.0298881530762,2.00843330231872,15.37000015378,0.000219595376982997,3.49857055326143E-5,0.25,-2.64787966596091E-7,1.92685474496843E-5,-2.48622660270855E-7,236.5257721,236.5257721,99.3960113525391,99.3960113525391,56.8384626614291,20.6408013842963,22.529354,0,0,0,40,4374,239.3549,99.3960113525391,,,,,,,,,,,,,0,,,,-0.0049,,,,,,236.5257721,,,,
,30927663.35,239.5105896,99.3960113525391,1.90365020305133E-5,3.60563791267021E-7,1,0.999253354069792,40.0298881530762,2.00853276889056,15.3299998492002,0.000216549049214834,3.96864565920765E-5,0.25,1.80970195952892E-7,1.90767751404561E-5,1.97697066086927E-7,239.5105896,239.5105896,99.3960113525391,99.3960113525391,56.9447641400445,20.630484776005,22.909004,0,0,0,40,4374,242.3645,99.3960113525391,,,,,,,,,,,,,0,,,,0,,,,,,239.5105896,,,,
,30927804.315,243.0279083,99.3960113525391,1.94221261724107E-5,4.37856966712689E-7,1,0.999253354069792,40.0298881530762,2.00852614580388,15.3299998492002,0.000221595880486396,3.65189336656681E-5,0.25,-1.63223976430651E-7,1.9461124103894E-5,-1.47164751926712E-7,243.0279083,243.0279083,99.3960113525391,99.3960113525391,56.9549253107945,20.6357538805396,22.909004,0,0,0,40,4374,245.8949,99.3960113525391,,,,,,,,,,,,,0,,,,-0.0049,,,,,,243.0279083,,,,
,30927945.235,246.52416995,99.3960113525391,1.91176393604762E-5,3.53453634067478E-7,1,0.999253354069792,40.0298881530762,2.00833142475628,15.3299998492002,0.000217963057296007,3.6583887254391E-5,0.25,-1.03749718257615E-7,1.91536311066933E-5,-8.80893100824924E-8,246.4922028,246.5561371,99.3960113525391,99.3960113525391,57.0948368157368,20.6388162355718,22.909004,0,0,0,40,4374,249.41705,99.3960113525391,,,,,,,,,,,,,0,,,,0,,,,,,246.52416995,,,,
,30928085.1,250.0197144,99.3960113525391,1.9197675498975E-5,3.75326104007032E-7,1,0.999253354069792,40.0298881530762,2.00854443966611,15.2700003236532,0.000218599111016732,3.83028407167847E-5,0.25,3.36180713168531E-8,1.9231340574518E-5,4.93330779449497E-8,250.0197144,250.0197144,99.3960113525391,99.3960113525391,56.9525804252368,20.6318419438452,22.909004,0,0,0,40,4374,252.9301,99.3960113525391,,,,,,,,,,,,,0,,,,0,,,,,,250.0197144,,,,
,30928226.575,253.5180359,99.3960113525391,1.87827910908002E-5,4.21235471229325E-7,1,0.999253354069792,40.0298881530762,1.99596331605659,15.2700003236532,0.000213523975010566,3.17471169247138E-5,0.25,-4.52633594353351E-7,1.88137966511469E-5,-4.38309194882139E-7,253.5180359,253.5180359,99.3960113525391,99.3960113525391,57.3637170263522,20.6363252663006,22.529354,0,0,0,40,4374,256.48265,99.3960113525391,,,,,,,,,,,,,0,,,,-0.00245,,,,,,253.5180359,,,,
,30928365.835,257.0100403,99.3960113525391,1.93375347757899E-5,4.11584012555893E-7,1,0.999253354069792,40.0298881530762,1.99601171961529,15.2700003236532,0.000218540811721379,3.99909372895748E-5,0.25,1.79978981651958E-7,1.93665467144737E-5,1.95508229129728E-7,257.0100403,257.0100403,99.3960113525391,99.3960113525391,57.2621053188522,20.6366649508135,22.909004,0,0,0,40,4374,259.9681,99.3960113525391,,,,,,,,,,,,,0,,,,0,,,,,,257.0100403,,,,
,30928505.57,260.5032654,99.3960113525391,1.90152522929554E-5,3.39590352180632E-7,1,0.999253354069792,40.0298881530762,2.00876727021157,15.2200004085898,0.000216879535067071,3.55349965587174E-5,0.25,-1.76184224360965E-7,1.90416965224784E-5,-1.61663686404109E-7,260.5032654,260.5032654,99.3960113525391,99.3960113525391,56.7688977232175,20.6314690022142,23.288654,0,0,0,40,4374,263.465,99.3960113525391,,,,,,,,,,,,,0,,,,0,,,,,,260.5032654,,,,
,30928647.955,264.0065613,99.3960113525391,1.82383900903946E-5,3.99359917665463E-7,1,0.999253354069792,40.0298881530762,2.00871680729655,15.2200004085898,0.000208836248322061,2.91856156236939E-5,0.25,-5.98473727203345E-7,1.82618045676657E-5,-5.85293856147857E-7,264.0065613,264.0065613,99.3960113525391,99.3960113525391,56.9744660237753,20.6380477895672,23.288654,0,0,0,40,4374,267.0403,99.3960113525391,,,,,,,,,,,,,0,,,,0,,,,,,264.0065613,,,,
,30928788.545,267.5111084,99.3960113525391,1.84093214941174E-5,3.80671760303852E-7,1,0.999253354069792,40.0298881530762,2.00874846601929,15.2200004085898,0.000211263990640326,2.66075653350589E-5,0.25,-8.54060438136019E-7,1.84308339486332E-5,-8.41185564245578E-7,267.5111084,267.5111084,99.3960113525391,99.3960113525391,57.0823307594291,20.6395770752077,23.668306,0,0,0,40,4374,270.57025,99.3960113525391,,,,,,,,,,,,,0,,,,0.00245,,,,,,267.5111084,,,,
,30928930.385,271.039505,99.3960113525391,1.86647051979582E-5,3.63781323909147E-7,1,0.999253354069792,40.0298881530762,2.00860611386983,15.1599999517202,0.0002133921553844,3.13618710290525E-5,0.25,-4.79962292098445E-7,1.86838666534315E-5,-4.66630547308268E-7,271.0135498,271.0654602,99.3960113525391,99.3960113525391,56.8681645451599,20.636321033073,23.288654,0,0,0,40,4374,274.13875,99.3960113525391,,,,,,,,,,,,,0,,,,0.00245,,,,,,271.039505,,,,
,30929072.865,274.56260685,99.3960113525391,1.79569801041833E-5,4.17089272212974E-7,1,0.999253354069792,40.0298881530762,2.0087032809784,15.1599999517202,0.000205186417252478,3.07352590960689E-5,0.25,-4.11918276308977E-7,1.79731097989977E-5,-3.9919552325027E-7,274.5261536,274.5990601,99.3960113525391,99.3960113525391,57.0510656186599,20.6334823730908,22.909004,0,0,0,40,4374,277.7091,99.3960113525391,,,,,,,,,,,,,0,,,,0,,,,,,274.56260685,,,,
,30929211.68,278.0230103,99.3960113525391,1.78675257689639E-5,4.86898794685479E-7,1,0.999253354069792,40.0298881530762,2.00865414706047,15.1599999517202,0.000203887415986845,3.2001362029738E-5,0.25,-2.84563740520283E-7,1.78812664073914E-5,-2.71951665362828E-7,278.0230103,278.0230103,99.3960113525391,99.3960113525391,57.0565370182945,20.6331762270233,23.288654,0,0,0,40,4374,281.1722,99.3960113525391,,,,,,,,,,,,,0,,,,-0.00245,,,,,,278.0230103,,,,
,30929351.945,281.5434265,99.3960113525391,1.77382662176836E-5,3.61627133746215E-7,1,0.999253354069792,40.0298881530762,2.00876819566658,15.1100000366569,0.000202722493095072,2.98942377501656E-5,0.25,-4.46949780442015E-7,1.77497831950144E-5,-4.34686393808094E-7,281.5434265,281.5434265,99.3960113525391,99.3960113525391,57.139389641333,20.6281710545973,22.909004,0,0,0,40,4374,284.6878,99.3960113525391,,,,,,,,,,,,,0,,,,0.0049,,,,,,281.5434265,,,,
,30929492.245,285.0021362,99.3960113525391,1.77818625428789E-5,4.65293635397679E-7,1,0.999253354069792,40.0298881530762,2.0089549107957,15.1100000366569,0.000202639647810005,3.32782098670352E-5,0.25,-1.56828383131811E-7,1.77909964208507E-5,-1.44515342521559E-7,285.0021362,285.0021362,99.3960113525391,99.3960113525391,57.1784710672945,20.6313541197309,22.909004,0,0,0,40,4374,288.1902,99.3960113525391,,,,,,,,,,,,,0,,,,-0.0049,,,,,,285.0021362,,,,
,30929632.7,288.5380859,99.3960113525391,1.69891042759025E-5,4.04307875064106E-7,1,0.999253354069792,40.0298881530762,1.99662404357088,15.1100000366569,0.000193130214606226,2.76628780451562E-5,0.25,-4.9815011542294E-7,1.69959161943654E-5,-4.86671212375458E-7,288.5380859,288.5380859,99.3960113525391,99.3960113525391,57.1206305568714,20.6274998879342,23.668306,0,0,0,40,4374,291.7068,99.3960113525391,,,,,,,,,,,,,0,,,,0,,,,,,288.5380859,,,,
,30929753.19,291.5370789,99.3960113525391,1.69996313016454E-5,3.63090318148039E-7,1,0.999253354069792,40.0298881530762,2.00887070722229,15.0399999693036,0.0001940688139096,2.95174879582908E-5,0.25,-3.50760362071125E-7,1.70045173231778E-5,-3.39323647922966E-7,291.5370789,291.5370789,99.3960113525391,99.3960113525391,57.312129544083,20.6248489367386,23.668306,0,0,0,40,4374,294.7185,99.3960113525391,,,,,,,,,,,,,0,,,,-0.0049,,,,,,291.5370789,,,,
,30929894.485,295.0303955,99.3960113525391,1.63616375225837E-5,4.37956091192938E-7,1,0.999253354069792,40.0298881530762,2.00891278320797,15.0399999693036,0.000186743632201475,2.85345974979663E-5,0.25,-3.26196159242256E-7,1.63642841935762E-5,-3.15302903452362E-7,295.0303955,295.0303955,99.3960113525391,99.3960113525391,57.1948852661984,20.630324255144,23.668306,0,0,0,40,4374,298.2656,99.3960113525391,,,,,,,,,,,,,0,,,,-0.0049,,,,,,295.0303955,,,,
,30930035.57,298.5516357,99.3960113525391,1.69785107816658E-5,4.55682757295563E-7,1,0.999253354069792,40.0298881530762,2.00877420928627,15.0399999693036,0.000194431254965657,2.56562161759971E-5,0.25,-6.85550429928112E-7,1.69793460477873E-5,-6.74370222326251E-7,298.5516357,298.5516357,99.3960113525391,99.3960113525391,56.9994781363906,20.6351112792036,23.668306,0,0,0,40,4374,301.7912,99.3960113525391,,,,,,,,,,,,,0,,,,-0.00245,,,,,,298.5516357,,,,
touchdown = 9.92000009864569 mm,30930169.82,301.8849792,99.3960113525391,1.61474082727986E-5,4.20214793785667E-7,1,0.999253354069792,40.0298881530762,2.00878717704309,14.9900000542402,0.000183652407630856,3.1557661530181E-5,0.25,-2.21622184840583E-8,1.61458662585884E-5,-1.16526054388052E-8,301.8849792,301.8849792,99.3960113525391,99.3960113525391,56.9877537086022,20.63109536769,23.668306,0,0,0,40,4374,305.1635,99.3960113525391,,,,,,,,,,,,,0,,,,0,,,,,,301.8849792,,,,
,30930298.34,305.0550232,99.3960113525391,1.68506120801918E-5,3.93142575400457E-7,1,0.999253354069792,40.0298881530762,2.00886204356764,14.9900000542402,0.000192521279282367,2.78160802885549E-5,0.25,-4.72717196056676E-7,1.68473885990013E-5,-4.6178937924776E-7,305.0550232,305.0550232,99.3960113525391,99.3960113525391,57.0354330482753,20.6307455638625,23.288654,0,0,0,40,4374,308.3912,99.3960113525391,,,,,,,,,,,,,0,,,,0.0049,,,,,,305.0550232,,,,
,30930439.105,308.5528259,99.3960113525391,1.6613603313645E-5,4.1861263857647E-7,1,0.999253354069792,40.0298881530762,1.99642383401986,14.9900000542402,0.00018754449923958,3.37478162591396E-5,0.25,1.08198222337732E-7,1.66079908283544E-5,1.18696532501808E-7,308.5528259,308.5528259,99.3960113525391,99.3960113525391,57.4551675631022,20.6358518674833,24.047956,0,0,0,40,4374,311.9063,99.3960113525391,,,,,,,,,,,,,0,,,,0.0049,,,,,,308.5528259,,,,
,30930574.03,311.9251099,99.3960113525391,,,2,,,,14.9399996417761,,,,,,,311.9251099,311.9251099,99.3960113525391,99.3960113525391,,,23.288654,,,,-99999999,4374,315.2796,99.3960113525391,,,,,,,,,,,,,,,,,,,,,,,311.9251099,,,,
,30930699.29,315.0412903,99.3960113525391,1.60821476392672E-5,4.73444525519427E-7,1,0.999253354069792,40.0298881530762,1.99638187030096,14.919999986887,0.000181882915490514,3.04479085644486E-5,0.25,-9.08133173716533E-8,1.60731406786017E-5,-8.08094216198248E-8,315.0412903,315.0412903,99.3960113525391,99.3960113525391,56.9682129956214,20.6264970663592,23.288654,0,0,0,40,4374,318.4379,99.3960113525391,,,,,,,,,,,,,0,,,,0.00245,,,,,,315.0412903,,,,
,30930839.425,318.517395,99.3960113525391,1.57829575133728E-5,4.15036759283746E-7,1,0.999253354069792,40.0298881530762,1.99640629703985,14.919999986887,0.000178327588228068,3.07544282927697E-5,0.25,-1.14356690967297E-8,1.57721347381678E-5,-1.78366173497936E-9,318.517395,318.517395,99.3960113525391,99.3960113525391,56.851750346256,20.6262423340205,23.668306,0,0,0,40,4374,321.9504,99.3960113525391,,,,,,,,,,,,,0,,,,0,,,,,,318.517395,,,,
,30930992.95,322.3178406,99.3960113525391,,,2,,,,14.8800001162291,,,,,,,322.3178406,322.3178406,99.3960113525391,99.3960113525391,,,24.047956,,,,-99999999,4374,325.799,99.3960113525391,,,,,,,,,,,,,,,,,,,,,,,322.3178406,,,,
,30931121.15,325.5265503,99.3960113525391,1.50799070624539E-5,4.39013630566055E-7,1,0.999253354069792,40.0298881530762,1.99659370497825,14.8700000718236,0.000170354195920806,2.9397976425475E-5,0.25,-9.10012287192854E-9,1.50658567136827E-5,-1.02793244200788E-10,325.5265503,325.5265503,99.3960113525391,99.3960113525391,57.0198004778906,20.6249052530529,23.668306,0,0,0,40,4374,329.0213,99.3960113525391,,,,,,,,,,,,,0,,,,0,,,,,,325.5265503,,,,
,30931262.415,329.0293274,99.3960113525391,1.4651883420816E-5,5.04586872349202E-7,1,0.999253354069792,40.0298881530762,1.99654692657654,14.8700000718236,0.00016552454725206,2.83886553595161E-5,0.25,-2.38589679485741E-8,1.46364509165732E-5,-1.52040632633694E-8,329.0293274,329.0293274,99.3960113525391,99.3960113525391,57.0205821064099,20.6279326755554,24.047956,0,0,0,40,4374,332.5563,99.3960113525391,,,,,,,,,,,,,0,,,,0,,,,,,329.0293274,,,,
,30931412.98,332.7463989,99.3960113525391,,,2,,,,14.8199996593595,,,,,,,332.7463989,332.7463989,99.3960113525391,99.3960113525391,,,24.047956,,,,-99999999,4374,336.3128,99.3960113525391,,,,,,,,,,,,,,,,,,,,,,,332.7463989,,,,
,30931544.51,336.0454102,99.3960113525391,1.4065834786615E-5,4.35559556789337E-7,1,0.999253354069792,40.0298881530762,1.99693451127827,14.8000000044703,0.000158964167809525,2.68501221383705E-5,0.25,-5.82661582928256E-8,1.40476220289075E-5,-5.0094435869668E-8,336.0454102,336.0454102,99.3960113525391,99.3960113525391,57.1440794124484,20.6183854916901,24.047956,0,0,0,40,4374,339.6201,99.3960113525391,,,,,,,,,,,,,0,,,,0.0049,,,,,,336.0454102,,,,
,30931683.25,339.5054626,99.3960113525391,1.46441427775584E-5,3.99321307136774E-7,1,0.999253354069792,40.0298881530762,1.99673308164204,14.8000000044703,0.000165134708204348,2.9851029616414E-5,0.25,1.07970936330669E-7,1.46233435322419E-5,1.16156170784766E-7,339.5054626,339.5054626,99.3960113525391,99.3960113525391,56.8947399148137,20.6226836484843,24.047956,0,0,0,40,4374,343.096,99.3960113525391,,,,,,,,,,,,,0,,,,0.0049,,,,,,339.5054626,,,,
,30931832.86,343.1784668,99.3960113525391,,,2,,,,14.7600001338124,,,,,,,343.1784668,343.1784668,99.3960113525391,99.3960113525391,,,24.047956,,,,-99999999,4374,346.8446,99.3960113525391,,,,,,,,,,,,,,,,,,,,,,,343.1784668,,,,
,30931965.085,346.5084229,99.3960113525391,1.38710786782829E-5,4.50951268930248E-7,1,0.999253354069792,40.0298881530762,1.99653900024146,14.750000089407,0.000158113016107714,1.81727419016094E-5,0.25,-7.91772565936941E-7,1.38485675182841E-5,-7.82728177414728E-7,346.5084229,346.5084229,99.3960113525391,99.3960113525391,56.9142806277945,20.6279013293677,24.047956,0,0,0,40,4374,350.15695,99.3960113525391,,,,,,,,,,,,,0,,,,0.0049,,,,,,346.5084229,,,,
,30932380.025,349.79652405,99.3960113525391,1.34957620246727E-5,4.7649037891538E-7,1,0.999253354069792,40.0298881530762,1.99647233282181,14.750000089407,0.000152133077722971,2.73794689528196E-5,0.25,8.92536917995425E-8,1.34718784423857E-5,9.66074621468462E-8,349.795166,349.7978821,99.3960113525391,99.3960113525391,57.0862389020253,20.6339659845569,24.427608,0,0,0,40,4369,350.75815,99.3960113525391,,,,,,,,,,,,,0,,,,0,,,,,,349.79652405,,,,