File: data/doubleLayers/dl_5/ppms/data/DD205_6_HYST_INIT_300K.DAT
[Header]
; VSM Data File (default extension .dat)
; Copyright (c) 2003-2013, Quantum Design, Inc. All rights reserved.
TITLE,
FILEOPENTIME,30867245.45,12/24/2018,2:15 pm
BYAPP,VSM,2.0,2.0
INFO,PPMS VSM Option Release 1.4.10 Build 1,APPNAME
INFO,Quantum Design Linear Motor Servo Controller,MOTOR_MODULE_NAME
INFO,3101-100 M1,MOTOR_HW_VERSION
INFO,MMC1014,MOTOR_SERIAL_NUMBER
INFO,SRV No X-over 01.03.11,MOTOR_SOFTWARE_VERSION
INFO,Quantum Design VSM Detection Module,VSM_MODULE_NAME
INFO,3101-150 F0,VSM_HW_VERSION
INFO,VSM707,VSM_SERIAL_NUMBER
INFO,VSM No X-over 01.02.05 May 20 2008 13:51:47,VSM_SOFTWARE_VERSION
INFO,704,PREAMP_SERIAL_NUMBER
INFO,822,COIL_SERIAL_NUMBER
INFO,0,MOMENT_UNITS
INFO,CoFe2O4,SAMPLE_MATERIAL
INFO,AH11 DL,SAMPLE_COMMENT
INFO,30.27,SAMPLE_MASS
INFO,,SAMPLE_VOLUME
INFO,,SAMPLE_MOLECULAR_WEIGHT
INFO,,SAMPLE_SIZE
INFO,,SAMPLE_SHAPE
DATATYPE,COMMENT,1
DATATYPE,TIME,2
STARTUPAXIS,X,2
STARTUPAXIS,Y1,5
[Data]
Comment,Time Stamp (sec),Temperature (K),Magnetic Field (Oe),Moment (emu),M. Std. Err. (emu),Transport Action,Averaging Time (sec),Frequency (Hz),Peak Amplitude (mm),Center Position (mm),Coil Signal' (mV),Coil Signal" (mV),Range (mV),M. Quad. Signal (emu),M. Raw' (emu),M. Raw" (emu),Min. Temperature (K),Max. Temperature (K),Min. Field (Oe),Max. Field (Oe),Mass (grams),Motor Lag (deg),Pressure (Torr),VSM Status (code),Motor Status (code),Measure Status (code),Measure Count,PPMS Status (code),System Temp. (K),System Field (Oe),Sample Position (deg),Bridge 1 Resistance (ohms),Bridge 1 Excitation (에),Bridge 2 Resistance (ohms),Bridge 2 Excitation (에),Bridge 3 Resistance (ohms),Bridge 3 Excitation (에),Bridge 4 Resistance (ohms),Bridge 4 Excitation (에),Signal 1 Vin (V),Signal 2 Vin (V),Digital Inputs (code),Drive 1 Iout (mA),Drive 1 Ipower (W),Drive 2 Iout (mA),Drive 2 Ipower (W),Pressure (),Map 20 (),Map 21 (),Map 22 (),Map 23 (),Map 24 (),Map 25 (),Map 26 (),Map 27 (),Map 28 (),Map 29 ()
,30867261.06,300.0243225,0.1674614995718,,,2,,,,14.9500001835823,,,,,,,300.0243225,300.0243225,0.1674614995718,0.1674614995718,,,22.909004,,,,-99999999,4369,300.2405,0.1674614995718,,,,,,,,,,,,,,,,,,,,,,,300.0243225,,,,
,30867399.42,300.0190125,3913.73022460937,4.68311604838529E-5,4.092467556549E-7,1,0.999253354069792,40.0298881530762,1.97434236953723,14.9400001391768,0.000524490972590579,8.68797505920036E-5,0.25,-3.46620088755393E-7,4.68299619508773E-5,-3.15553356872053E-7,300.0190125,300.0190125,3903.81494140625,3923.6455078125,55.9692917480444,20.5442488341165,23.288654,0,0,0,40,4449,300.2199,3913.73022460937,,,,,,,,,,,,,0,,,,0,,,,,,300.0190125,,,,
,30867474.875,300.0131531,7685.0673828125,4.15324749505903E-5,6.76097598154283E-7,1,0.999253354069792,40.0298881530762,1.97418060420712,14.9400001391768,0.000466223946177956,7.06225630646254E-5,0.25,-8.81509212224955E-7,4.15318025054912E-5,-8.53954995846128E-7,300.0131531,300.0131531,7677.6826171875,7692.4521484375,56.1764233056406,20.5517039203882,22.909004,0,0,0,40,4449,300.208,7685.0673828125,,,,,,,,,,,,,0,,,,0,,,,,,300.0131531,,,,
,30867555.97,300.0094299,11741,2.98679009836086E-5,6.78585048438299E-7,1,0.999253354069792,40.0298881530762,1.97408142072398,14.9400001391768,0.000336448492394098,4.39656762389657E-5,0.25,-1.24370939225933E-6,2.9867826222062E-5,-1.22388956721934E-6,300.0094299,300.0094299,11735.958984375,11746.041015625,56.5242479966983,20.5530141350686,23.668306,0,0,0,40,4449,300.2094,11741,,,,,,,,,,,,,0,,,,0,,,,,,300.0094299,,,,
,30867635.555,300.0070496,15716.2973632812,1.45426660287109E-5,7.93517891836244E-7,1,0.999253354069792,40.0298881530762,1.97396889915213,14.9400001391768,0.000162640549520179,2.81421346873094E-5,0.25,-3.18696323127545E-9,1.45422325087884E-5,6.43839592129187E-9,300.0070496,300.0070496,15708.7412109375,15723.853515625,56.4710972573906,20.5569677585433,23.668306,0,0,0,40,4449,300.20235,15716.2973632812,,,,,,,,,,,,,0,,,,0,,,,,,300.0070496,,,,
,30867720.065,300.0089111,19941.751953125,-2.07808781874035E-6,8.62609699165665E-7,1,0.999253354069792,40.0298881530762,1.97391432506048,14.9400001391768,-2.24591590401599E-5,-8.52843979252074E-6,0.25,-4.02582876235877E-7,-2.07775928836985E-6,-4.03945115602921E-7,300.0089111,300.0089111,19936.693359375,19946.810546875,56.2553677860829,20.5578186654995,23.288654,0,0,0,40,4449,300.1982,19941.751953125,,,,,,,,,,,,,0,,,,0,,,,,,300.0089111,,,,
,30867803.1,300.0071106,24089.580078125,-1.66232972621472E-5,1.26784892455168E-6,1,0.999253354069792,40.0298881530762,1.97386040568023,14.9400001391768,-0.000184367307727551,-4.10126153216116E-5,0.25,-7.87406709268451E-7,-1.66222805644449E-5,-7.98367702681691E-7,300.0071106,300.0071106,24079.71484375,24099.4453125,56.6563432164483,20.5574392290809,23.668306,0,0,0,40,4449,300.1936,24089.580078125,,,,,,,,,,,,,0,,,,0.00245,,,,,,300.0071106,,,,
,30867885.27,300.0050049,28197.7958984375,-3.2778751295874E-5,1.47880789482921E-6,1,0.999253354069792,40.0298881530762,1.9738061807094,14.9400001391768,-0.000363864727555501,-7.89733752567965E-5,0.25,-1.38316425437044E-6,-3.27768634192719E-5,-1.40476458184945E-6,300.0050049,300.0050049,28187.921875,28207.669921875,56.6266413327175,20.5613816442666,23.668306,0,0,0,40,4449,300.1914,28197.7958984375,,,,,,,,,,,,,0,,,,0,,,,,,300.0050049,,,,
,30867967.58,300.006073,32310.619140625,-4.96572193187295E-5,1.28402820705502E-6,1,0.999253354069792,40.0298881530762,1.97381395942583,14.9400001391768,-0.000556023381556215,-9.19633219573945E-5,0.25,3.79502953773169E-7,-4.96559937273209E-5,3.46734706870047E-7,300.006073,300.006073,32300.732421875,32320.505859375,56.3655774072944,20.561461410085,23.288654,0,0,0,40,4449,300.18465,32310.619140625,,,,,,,,,,,,,0,,,,0,,,,,,300.006073,,,,
,30868046.905,300.007019,36276.388671875,-6.60093270212478E-5,1.58298188231336E-6,1,0.999253354069792,40.0298881530762,1.97387252283928,14.9400001391768,-0.000740004820739557,-0.00011727423436954,0.25,9.49411591343085E-7,-6.60079919283236E-5,9.05877054018066E-7,300.007019,300.007019,36268.7109375,36284.06640625,56.8494054606983,20.5644067952677,23.668306,0,0,0,40,4449,300.1814,36276.388671875,,,,,,,,,,,,,0,,,,-0.00245,,,,,,300.007019,,,,
,30868128.275,300.0048523,40344.28125,-8.14665713111866E-5,1.6175663920613E-6,1,0.999253354069792,40.0298881530762,1.97367693087514,14.9400001391768,-0.000911306696580343,-0.000155670702087708,0.25,1.92552202267106E-7,-8.14642888757082E-5,1.38902013685607E-7,300.0048523,300.0048523,40336.66015625,40351.90234375,56.6516534453329,20.5643359322635,23.288654,0,0,0,40,4449,300.1836,40344.28125,,,,,,,,,,,,,0,,,,0,,,,,,300.0048523,,,,
,30868211.62,300.009552,44506.955078125,-0.000101033441422437,1.54810601933759E-6,1,0.999253354069792,40.0298881530762,1.9737287525885,14.9400001391768,-0.00112564192613276,-0.00021946089578875,0.25,-2.12184089796907E-6,-0.000101029045847227,-2.18824742609353E-6,300.009552,300.009552,44499.4453125,44514.46484375,56.8525319747752,20.5648286322892,24.047956,0,0,0,40,4449,300.1678,44506.955078125,,,,,,,,,,,,,0,,,,0.00245,,,,,,300.009552,,,,
,30868292.87,300.0065002,48567.755859375,-0.000115762252652952,2.14566236039767E-6,1,0.999253354069792,40.0298881530762,1.97359677035827,14.9400001391768,-0.00128810305856079,-0.000260410379168737,0.25,-3.23366617169225E-6,-0.000115756709311598,-3.30965949918834E-6,300.0065002,300.0065002,48562.59375,48572.91796875,56.6532167023714,20.5661330883674,23.668306,0,0,0,40,4449,300.16285,48567.755859375,,,,,,,,,,,,,0,,,,0.0049,,,,,,300.0065002,,,,
,30868373.61,300.0094299,52605.45703125,-0.000132646744176661,1.90507034218893E-6,1,0.999253354069792,40.0298881530762,1.97359020996026,14.9400001391768,-0.00147685075721261,-0.000293333634920294,0.25,-3.25303553640551E-6,-0.000132640684877974,-3.34004474259341E-6,300.0094299,300.0094299,52595.3359375,52615.578125,56.668849272756,20.5656648779658,23.668306,0,0,0,40,4449,300.1563,52605.45703125,,,,,,,,,,,,,0,,,,0,,,,,,300.0094299,,,,
,30868454.635,300.0128479,56656.09765625,-0.000148978825075039,3.21281305313809E-6,1,0.999253354069792,40.0298881530762,1.97351421220558,14.9400001391768,-0.00166143876419085,-0.0003132047913672,0.25,-2.20177101920171E-6,-0.000148972964716478,-2.29944047787425E-6,300.0128479,300.0128479,56643.4453125,56668.75,56.9041194570445,20.5658236311315,24.047956,0,0,0,40,4449,300.1566,56656.09765625,,,,,,,,,,,,,0,,,,-0.00245,,,,,,300.0128479,,,,
,30868537.975,300.0117493,60821.478515625,-0.000163935906520038,3.23355402493903E-6,1,0.999253354069792,40.0298881530762,1.97345319231134,14.9400001391768,-0.00182772787497624,-0.000347301059276846,0.25,-2.66097195563502E-6,-0.000163929318719654,-2.76833890630847E-6,300.0117493,300.0117493,60816.296875,60826.66015625,56.8650380310829,20.568087134614,23.668306,0,0,0,40,4449,300.13785,60821.478515625,,,,,,,,,,,,,0,,,,0,,,,,,300.0117493,,,,
,30868617.705,300.0148621,64805.189453125,-0.000183387431202709,2.89591326881812E-6,1,0.999253354069792,40.0298881530762,1.97353619494305,14.9400001391768,-0.00204268246416708,-0.000400030591745757,0.25,-4.00585166443676E-6,-0.000183379379440512,-4.125812629493E-6,300.0148621,300.0148621,64800.2265625,64810.15234375,56.6782288149868,20.5680663748375,24.047956,0,0,0,40,4449,300.1303,64805.189453125,,,,,,,,,,,,,0,,,,0.00245,,,,,,300.0148621,,,,
,30868700.155,300.008667,68928.3125,-0.000202787838427578,2.02504315473316E-6,1,0.999253354069792,40.0298881530762,1.97338899570449,14.9400001391768,-0.00226363186156862,-0.000413365286725737,0.25,-1.84009822835703E-6,-0.000202780688803497,-1.97269215112796E-6,300.0081482,300.0091858,68918.3359375,68938.2890625,56.7876568076791,20.5696811764226,24.047956,0,0,0,40,4449,300.1264,68928.3125,,,,,,,,,,,,,0,,,,-0.0049,,,,,,300.008667,,,,
,30868782.39,300.0109863,73038.86328125,-0.000215456130850716,3.52560631460839E-6,1,0.999253354069792,40.0298881530762,1.97336952311355,14.9400001391768,-0.00240535942184921,-0.000437223639156897,0.25,-1.77981932788721E-6,-0.000215448645269664,-1.92055723490875E-6,300.0109863,300.0109863,73031.5390625,73046.1875,56.9682129956214,20.5718194320104,23.288654,0,0,0,40,4449,300.12265,73038.86328125,,,,,,,,,,,,,0,,,,-0.00245,,,,,,300.0109863,,,,
,30868862.79,300.009613,77054.76171875,-0.000237806313196464,3.33953635495301E-6,1,0.999253354069792,40.0298881530762,1.97322994691076,14.9400001391768,-0.00264543237002684,-0.000536029803766431,0.25,-6.74878213868675E-6,-0.00023779495476539,-6.90382380569555E-6,300.009613,300.009613,77049.84375,77059.6796875,56.8384626614291,20.5728913044589,24.047956,0,0,0,40,4449,300.11705,77054.76171875,,,,,,,,,,,,,0,,,,0,,,,,,300.009613,,,,
,30868942.91,300.0107117,81061.11328125,-0.000253440920532567,3.32882753841814E-6,1,0.999253354069792,40.0298881530762,1.97325128301248,14.9400001391768,-0.00282331366318925,-0.000548605910170971,0.25,-5.16470555929821E-6,-0.000253430147137623,-5.32983403846073E-6,300.0107117,300.0107117,81053.4765625,81068.75,56.966649738583,20.5724831615432,23.288654,0,0,0,40,4449,300.10925,81061.11328125,,,,,,,,,,,,,0,,,,0,,,,,,300.0107117,,,,
,30869026.005,300.0152283,85214.4140625,-0.000269143924421856,3.75848669829676E-6,1,0.999253354069792,40.0298881530762,1.97315448128871,14.9400001391768,-0.00299889992431378,-0.0005779704435802,0.25,-5.07346436034505E-6,-0.00026913272784132,-5.24865115902325E-6,300.0152283,300.0152283,85211.9921875,85216.8359375,56.8705094307176,20.5724807268203,24.047956,0,0,0,40,4449,300.10165,85214.4140625,,,,,,,,,,,,,0,,,,-0.0049,,,,,,300.0152283,,,,
,30869101.68,300.0114136,88997.77734375,-0.000287064789271545,3.50364805708356E-6,1,0.999253354069792,40.0298881530762,1.97310579652798,14.9400001391768,-0.00320497765486616,-0.000579084600712123,0.25,-2.0697711969685E-6,-0.000287055080312456,-2.2565439041608E-6,300.0114136,300.0114136,88965.3671875,89030.1875,56.9799374234099,20.5740336854062,23.288654,0,0,0,40,4449,300.0902,88997.77734375,,,,,,,,,,,,,0,,,,-0.00245,,,,,,300.0114136,,,,
,30869198.21,300.0143127,87235.82421875,-0.00027892727860041,3.10165255830521E-6,1,0.999253354069792,40.0298881530762,1.97309825116281,14.9400001391768,-0.00310933690126947,-0.00059023736295758,0.25,-4.47736892883259E-6,-0.000278916201274936,-4.6588646020285E-6,300.0143127,300.0143127,87228.3125,87243.3359375,56.5852150211983,20.5755283758464,23.668306,0,0,0,40,4449,300.0819,87235.82421875,,,,,,,,,,,,,0,,,,-0.00245,,,,,,300.0143127,,,,
,30869279.97,300.0020752,83147.35546875,-0.000261906908561409,2.6563143226107E-6,1,0.999253354069792,40.0298881530762,1.97308392733024,14.9400001391768,-0.00292126190506137,-0.000544528725980013,0.25,-3.33729159749063E-6,-0.000261897168556412,-3.50791897869125E-6,300.0020752,300.0020752,83134.953125,83159.7578125,56.7008960420445,20.5765478979858,23.668306,0,0,0,40,4449,300.08535,83147.35546875,,,,,,,,,,,,,0,,,,-0.00245,,,,,,300.0020752,,,,
,30869360.96,299.9927368,79097.61328125,-0.000244236380179175,3.92137949412651E-6,1,0.999253354069792,40.0298881530762,1.97297126892561,14.9400001391768,-0.00272077115037976,-0.000526515390613222,0.25,-4.78964834662044E-6,-0.000244226268428698,-4.94887679700315E-6,299.9927368,299.9927368,79090.21875,79105.0078125,56.7696793517368,20.5771215914344,23.668306,0,0,0,40,4449,300.0966,79097.61328125,,,,,,,,,,,,,0,,,,0,,,,,,299.9927368,,,,
,30869441.94,299.9860535,75049.04296875,-0.000226643488213948,2.47763127860851E-6,1,0.999253354069792,40.0298881530762,1.97295222870507,14.9400001391768,-0.00252187467158288,-0.000505268276908197,0.25,-5.93704032885385E-6,-0.000226633168453796,-6.08490553909146E-6,299.9860535,299.9860535,75041.4609375,75056.625,56.8533136032945,20.5814597195164,23.668306,0,0,0,40,4449,300.10675,75049.04296875,,,,,,,,,,,,,0,,,,0,,,,,,299.9860535,,,,
,30869521.345,299.99028015,71080.30078125,-0.000209029397298424,2.78316275589557E-6,1,0.999253354069792,40.0298881530762,1.97289099439157,14.9400001391768,-0.00233357301402251,-0.000421190654055627,0.25,-1.4678130752446E-6,-0.000209022452667243,-1.60443478488796E-6,299.9901428,299.9904175,71072.8515625,71087.75,56.9517987967176,20.5802396440574,23.668306,0,0,0,40,4449,300.1128,71080.30078125,,,,,,,,,,,,,0,,,,-0.0049,,,,,,299.99028015,,,,
,30869604.68,299.9951782,66914.64453125,-0.000191882534358861,2.75106944514332E-6,1,0.999253354069792,40.0298881530762,1.972968325623,14.9400001391768,-0.00214379045298908,-0.000377634592616349,0.25,-5.40342181510452E-7,-0.000191876641506185,-6.65908282955676E-7,299.9951782,299.9951782,66904.421875,66924.8671875,56.9557069393137,20.5829704396382,24.047956,0,0,0,40,4449,300.1187,66914.64453125,,,,,,,,,,,,,0,,,,-0.00245,,,,,,299.9951782,,,,
,30869685.115,299.9854431,62894.017578125,-0.000174864829099034,2.25059164208128E-6,1,0.999253354069792,40.0298881530762,1.97318612047943,14.9400001391768,-0.0019488985580621,-0.000372865185172822,0.25,-3.05834794841274E-6,-0.000174857828728223,-3.17281711086155E-6,299.9854431,299.9854431,62891.6953125,62896.33984375,56.8806706014676,20.5810539995448,23.668306,0,0,0,40,4449,300.12335,62894.017578125,,,,,,,,,,,,,0,,,,-0.0049,,,,,,299.9854431,,,,
,30869766.635,299.9873657,58820.505859375,-0.000157917348227213,2.07692855628693E-6,1,0.999253354069792,40.0298881530762,1.97291569257328,14.9400001391768,-0.00175545468901975,-0.000361678705474852,0.25,-4.9980039539632E-6,-0.000157909538510171,-5.10141409790795E-6,299.9873657,299.9873657,58808.02734375,58832.984375,56.8329912617945,20.5855765542948,23.668306,0,0,0,40,4449,300.13335,58820.505859375,,,,,,,,,,,,,0,,,,-0.0049,,,,,,299.9873657,,,,
,30869847.74,299.9863586,54767.09765625,-0.000140941293222997,2.37167522261468E-6,1,0.999253354069792,40.0298881530762,1.97276248063178,14.9400001391768,-0.0015724425711098,-0.000289210788521957,0.25,-1.45764593960757E-6,-0.000140936288589647,-1.55011424943612E-6,299.9863586,299.9863586,54759.5625,54774.6328125,56.821266834006,20.5881743159301,23.288654,0,0,0,40,4449,300.13995,54767.09765625,,,,,,,,,,,,,0,,,,-0.00245,,,,,,299.9863586,,,,
,30869930.27,299.9885864,50639.255859375,-0.000123238033493984,2.26485800268504E-6,1,0.999253354069792,40.0298881530762,1.97272910393499,14.9400001391768,-0.0013732133009019,-0.000262671804959086,0.25,-2.15061194568518E-6,-0.000123233064665363,-2.2315144476276E-6,299.9885864,299.9885864,50631.91796875,50646.59375,56.872072687756,20.5873068522128,23.668306,0,0,0,40,4449,300.1576,50639.255859375,,,,,,,,,,,,,0,,,,-0.00245,,,,,,299.9885864,,,,
,30870011.93,299.98506165,46558.396484375,-0.000109343265345114,1.80983929731123E-6,1,0.999253354069792,40.0298881530762,1.97266303389569,14.9400001391768,-0.00121379559045982,-0.000259325441974089,0.25,-4.25919252336262E-6,-0.000109337317273007,-4.33097394251615E-6,299.9849854,299.9851379,46553.0859375,46563.70703125,56.6594697305252,20.5902228319174,24.047956,0,0,0,40,4449,300.16155,46558.396484375,,,,,,,,,,,,,0,,,,0,,,,,,299.98506165,,,,
,30870095.88,299.9859314,42360.2421875,-9.18406709649055E-5,1.89382803989647E-6,1,0.999253354069792,40.0298881530762,1.97257201794079,14.9400001391768,-0.0010197803999526,-0.000215944946206309,0.25,-3.41087993027833E-6,-9.18357744277257E-5,-3.47123286667552E-6,299.9859314,299.9859314,42355.171875,42365.3125,56.7649895806214,20.5929526492302,24.047956,0,0,0,40,4449,300.16865,42360.2421875,,,,,,,,,,,,,0,,,,0.00245,,,,,,299.9859314,,,,
,30870176.2,299.9849854,38347.439453125,-7.33966121992351E-5,1.71827841221889E-6,1,0.999253354069792,40.0298881530762,1.97256106337306,14.9400001391768,-0.00081951609690327,-0.000146377089993305,0.25,-3.81510052156291E-7,-7.3394240562003E-5,-4.29853117650379E-7,299.9849854,299.9849854,38342.640625,38352.23828125,56.8572217458906,20.5944093827798,23.288654,0,0,0,40,4449,300.17485,38347.439453125,,,,,,,,,,,,,0,,,,0,,,,,,299.9849854,,,,
,30870256.195,299.9889832,34349.24609375,-5.7933168965207E-5,1.65801805875451E-6,1,0.999253354069792,40.0298881530762,1.97242452457758,14.9400001391768,-0.000642168709746423,-0.000142346393225612,0.25,-2.70077854949271E-6,-5.79297033377898E-5,-2.73889925520925E-6,299.9889832,299.9889832,34344.4921875,34354,56.8267382336406,20.596445402409,23.668306,0,0,0,40,4449,300.1846,34349.24609375,,,,,,,,,,,,,0,,,,0,,,,,,299.9889832,,,,
,30870336.065,299.9878235,30359.0068359375,-4.13080619990146E-5,1.26730249922337E-6,1,0.999253354069792,40.0298881530762,1.97234846776316,14.9400001391768,-0.000460337289719143,-8.72433794219086E-5,0.25,-6.50480854999457E-7,-4.13064310690528E-5,-6.77722066110376E-7,299.9878235,299.9878235,30351.451171875,30366.5625,56.8533136032945,20.5974865815225,24.047956,0,0,0,40,4449,300.1917,30359.0068359375,,,,,,,,,,,,,0,,,,-0.0049,,,,,,299.9878235,,,,
,30870416.555,299.9839783,26336.0634765625,-2.55429840152787E-5,1.24967889367893E-6,1,0.999253354069792,40.0298881530762,1.97239501772026,14.9400001391768,-0.000283116543451704,-6.28431771469857E-5,0.25,-1.19817861301496E-6,-2.55414519236136E-5,-1.21501389641985E-6,299.9839783,299.9839783,26323.607421875,26348.51953125,56.7993812354675,20.5968322585021,24.047956,0,0,0,40,4449,300.2035,26336.0634765625,,,,,,,,,,,,,0,,,,0,,,,,,299.9839783,,,,
,30870497.835,299.985321,22273.357421875,-9.29772793281363E-6,1.1330815768842E-6,1,0.999253354069792,40.0298881530762,1.97226124227896,14.9400001391768,-0.000103317291708181,-2.13229946892431E-5,0.25,-2.97364315611831E-7,-9.29726085736929E-6,-3.03501308241603E-7,299.985321,299.985321,22270.779296875,22275.935546875,56.9088092281599,20.5985110577349,23.668306,0,0,0,40,4449,300.21365,22273.357421875,,,,,,,,,,,,,0,,,,0.0049,,,,,,299.985321,,,,
,30870576.86,299.9927368,18326.021484375,4.88794945888208E-6,9.8275056722924E-7,1,0.999253354069792,40.0298881530762,1.97230322457562,14.9400001391768,5.84184527940319E-5,-1.24655064499597E-5,0.25,-1.96243385375519E-6,4.88910385763465E-6,-1.95914277853588E-6,299.9927368,299.9927368,18318.7421875,18333.30078125,57.0487207331022,20.6011455426914,23.668306,0,0,0,40,4449,300.21585,18326.021484375,,,,,,,,,,,,,0,,,,0,,,,,,299.9927368,,,,
,30870656.85,299.9884949,14328.1030273437,2.09670684552204E-5,9.50931307766939E-7,1,0.999253354069792,40.0298881530762,1.9722225837095,14.9400001391768,0.000235511686005504,3.34935465591733E-5,0.25,-6.35217763886585E-7,2.09668746403384E-5,-6.21319385978223E-7,299.9884949,299.9884949,14325.80078125,14330.4052734375,57.1229754424291,20.6028068336387,23.668306,0,0,0,40,4449,300.2243,14328.1030273437,,,,,,,,,,,,,0,,,,0,,,,,,299.9884949,,,,
,30870738.11,299.9882813,10264.8803710938,3.49645748978478E-5,6.37206251081848E-7,1,0.999253354069792,40.0298881530762,1.97221867575047,14.9400001391768,0.000391879112240322,6.08068630400592E-5,0.25,-6.16005587682978E-7,3.49639573042323E-5,-5.92824902716706E-7,299.9882813,299.9882813,10262.12109375,10267.6396484375,56.9830639374868,20.603744876404,23.668306,0,0,0,40,4449,300.2261,10264.8803710938,,,,,,,,,,,,,0,,,,0,,,,,,299.9882813,,,,
,30870817.905,299.9912109,6276.7578125,4.46440979573528E-5,4.5624923031923E-7,1,0.999253354069792,40.0298881530762,1.97214310266041,14.9400001391768,0.000499941058661702,7.99849084462731E-5,0.25,-5.76482112772278E-7,4.46431641379724E-5,-5.4687206975727E-7,299.9912109,299.9912109,6274.41162109375,6279.10400390625,56.9346029692945,20.6061224762524,23.288654,0,0,0,40,4449,300.23885,6276.7578125,,,,,,,,,,,,,0,,,,0.0049,,,,,,299.9912109,,,,
,30870896.035,299.99421695,2370.47985839844,4.57900735313226E-5,4.99940434278066E-7,1,0.999253354069792,40.0298881530762,1.9720879724653,14.9400001391768,0.000512684200764479,8.24752954183004E-5,0.25,-5.51965564107366E-7,4.57890834430745E-5,-5.21579963714539E-7,299.9938965,299.9945374,2365.39282226562,2375.56689453125,56.9979148793522,20.606212245528,23.668306,0,0,0,40,4449,300.24465,2370.47985839844,,,,,,,,,,,,,0,,,,0.00245,,,,,,299.99421695,,,,
,30870968.985,299.9921875,-1273.40942382812,-3.90541252395835E-5,4.31704629425226E-7,1,0.999253354069792,40.0298881530762,1.98638377479164,14.9400001391768,-0.00043971043958927,-7.42001478733467E-5,0.25,1.71212931499947E-7,-3.90530846803989E-5,1.45302688443837E-7,299.9921875,299.9921875,-1275.95629882812,-1270.86254882812,56.9916618511983,20.6019466612459,23.668306,0,0,0,40,4449,300.2456,-1273.40942382812,,,,,,,,,,,,,0,,,,0,,,,,,299.9921875,,,,
,30871046.735,299.9945679,-5160.37426757812,-4.60807023847078E-5,5.495663464546E-7,1,0.999253354069792,40.0298881530762,1.98632816625516,14.9400001391768,-0.000519630805481415,-8.28033336037416E-5,0.25,6.23726602588007E-7,-4.60797516681109E-5,5.93158751296578E-7,299.9945679,299.9945679,-5167.97802734375,-5152.7705078125,56.9815006804483,20.601901261172,24.047956,0,0,0,40,4449,300.24895,-5160.37426757812,,,,,,,,,,,,,0,,,,0.00245,,,,,,299.9945679,,,,
,30871123.29,300.0027161,-8984.05859375,-3.82423579842987E-5,6.46333067934054E-7,1,0.999253354069792,40.0298881530762,1.98620649568964,14.9400001391768,-0.000431500124281297,-6.7074952742803E-5,0.25,6.63352076622926E-7,-3.82416555010336E-5,6.37994522039284E-7,300.0027161,300.0027161,-8996.7587890625,-8971.3583984375,57.0182372208522,20.6031875870375,24.047956,0,0,0,40,4449,300.2444,-8984.05859375,,,,,,,,,,,,,0,,,,-0.00245,,,,,,300.0027161,,,,
,30871204.665,300.0091248,-13052.1040039062,-2.46177838061291E-5,7.98414372419463E-7,1,0.999253354069792,40.0298881530762,1.98635583501266,14.9400001391768,-0.000277573562516664,-4.44294496663123E-5,0.25,3.16065287057845E-7,-2.46172533167334E-5,2.99756797123616E-7,300.0091248,300.0091248,-13059.748046875,-13044.4599609375,57.1690915250637,20.6019428799137,23.288654,0,0,0,40,4449,300.2444,-13052.1040039062,,,,,,,,,,,,,0,,,,0.0049,,,,,,300.0091248,,,,
,30871286.765,300.0031433,-17155.1376953125,-1.0490534568191E-5,5.92052820555243E-7,1,0.999253354069792,40.0298881530762,1.98633354398748,14.9400001391768,-0.000118685482834735,-1.66096111066691E-5,0.25,3.41184697081237E-7,-1.04904477859695E-5,3.34234269005727E-7,300.0031433,300.0031433,-17157.5703125,-17152.705078125,56.9486722826406,20.605264870997,23.668306,0,0,0,40,4449,300.24385,-17155.1376953125,,,,,,,,,,,,,0,,,,0,,,,,,300.0031433,,,,
,30871370.065,300.0036011,-21317.5205078125,6.49330905537268E-6,1.03357211842668E-6,1,0.999253354069792,40.0298881530762,1.98607375616568,14.9400001391768,6.97898532588103E-5,3.14245332447487E-5,0.25,1.66857958187556E-6,6.49201280733156E-6,1.67282234146898E-6,300.0036011,300.0036011,-21324.966796875,-21310.07421875,57.1987934087945,20.6035562163827,23.668306,0,0,0,40,4449,300.23625,-21317.5205078125,,,,,,,,,,,,,0,,,,-0.00245,,,,,,300.0036011,,,,
,30871452.93,300.0066833,-25463.140625,2.35507324178192E-5,1.29427145238594E-6,1,0.999253354069792,40.0298881530762,1.98610337472467,14.9400001391768,0.000259803961072346,7.54326414275216E-5,0.25,2.62542491557239E-6,2.35482960134057E-5,2.64090207442931E-6,300.0066833,300.0066833,-25468.2265625,-25458.0546875,57.2425646058714,20.6049103344659,23.288654,0,0,0,40,4449,300.2298,-25463.140625,,,,,,,,,,,,,0,,,,0.00245,,,,,,300.0066833,,,,
,30871536.545,300.0122986,-29640.9013671875,3.7449436092907E-5,1.31947532282929E-6,1,0.999253354069792,40.0298881530762,1.98612902081046,14.9400001391768,0.00041867473000833,8.79770745821121E-5,0.25,1.33246849774988E-6,3.74474343587249E-5,1.35714282810792E-6,300.0122986,300.0122986,-29650.736328125,-29631.06640625,57.0205821064099,20.6037706334357,23.668306,0,0,0,40,4449,300.22535,-29640.9013671875,,,,,,,,,,,,,0,,,,0,,,,,,300.0122986,,,,
,30871618.24,300.0102844,-33723.35546875,5.41031086486332E-5,1.64708907791483E-6,1,0.999253354069792,40.0298881530762,1.98591820437872,14.9400001391768,0.000605121635869369,0.000125214363581043,0.25,1.75852166171606E-6,5.41003341948773E-5,1.79414386457065E-6,300.0102844,300.0102844,-33733.2578125,-33713.453125,57.1534589546791,20.6078522323532,23.668306,0,0,0,40,4449,300.2134,-33723.35546875,,,,,,,,,,,,,0,,,,0,,,,,,300.0102844,,,,
,30871701.97,300.012207,-37908.505859375,7.23548720233914E-5,2.21071544628866E-6,1,0.999253354069792,40.0298881530762,1.98584502034759,14.9400001391768,0.000808712382533897,0.000170447866397837,0.25,2.61836339603796E-6,7.23509860621151E-5,2.66595305591295E-6,300.012207,300.012207,-37910.96875,-37906.04296875,57.1331366131791,20.6092727483723,24.047956,0,0,0,40,4449,300.1994,-37908.505859375,,,,,,,,,,,,,0,,,,0.0049,,,,,,300.012207,,,,
,30871783.32,300.0131836,-41971.271484375,8.90348225746837E-5,1.44244926753932E-6,1,0.999253354069792,40.0298881530762,1.9859135570574,14.9400001391768,0.00099677575334593,0.000200523164016883,0.25,2.40188359593844E-6,8.90305843347648E-5,2.46041372373062E-6,300.0131836,300.0131836,-41983.62109375,-41958.921875,56.8814522299868,20.6095671822916,23.668306,0,0,0,40,4449,300.2031,-41971.271484375,,,,,,,,,,,,,0,,,,-0.0049,,,,,,300.0131836,,,,
,30871866.74,300.0165863,-46141.763671875,0.000106462768185943,1.99991828531118E-6,1,0.999253354069792,40.0298881530762,1.98592520887209,14.9400001391768,0.00119128920614619,0.000243267875740724,0.25,3.18258884623458E-6,0.000106457490640889,3.25250165298837E-6,300.0161438,300.0170288,-46176.9609375,-46106.56640625,56.9861904515637,20.6080867302028,23.668306,0,0,0,40,4449,300.1927,-46141.763671875,,,,,,,,,,,,,0,,,,0,,,,,,300.0165863,,,,
,30871952.355,300.0113831,-50419.54296875,0.000123918902469195,2.20750060966783E-6,1,0.999253354069792,40.0298881530762,1.98582002838689,14.9400001391768,0.00138629550400036,0.000284602873664494,0.25,3.83447628158661E-6,0.000123912706616988,3.91577133128056E-6,300.0113831,300.0113831,-50429.39453125,-50409.69140625,56.9596150819099,20.6091727780243,23.668306,0,0,0,40,4449,300.18035,-50419.54296875,,,,,,,,,,,,,0,,,,-0.00245,,,,,,300.0113831,,,,
,30872036.735,300.00959775,-54639.310546875,0.000142156532067213,1.89924760014364E-6,1,0.999253354069792,40.0298881530762,1.98582378425878,14.9400001391768,0.00159466466058585,0.000301442246224234,0.25,2.17196280507898E-6,0.000142150906036903,2.26519646137868E-6,300.0095825,300.009613,-54646.92578125,-54631.6953125,57.1651833824676,20.6117961620935,23.668306,0,0,0,40,4449,300.1751,-54639.310546875,,,,,,,,,,,,,0,,,,0.00245,,,,,,300.00959775,,,,
,30872118.155,300.01828,-58707.322265625,0.00015680118296557,2.54559237257852E-6,1,0.999253354069792,40.0298881530762,1.98583322771897,14.9400001391768,0.00175679107101333,0.000344964741180619,0.25,3.50424784038473E-6,0.000156794211534857,3.60695727770744E-6,300.01828,300.01828,-58714.90625,-58699.73828125,57.0080760501022,20.6125498885868,23.288654,0,0,0,40,4449,300.1596,-58707.322265625,,,,,,,,,,,,,0,,,,-0.0049,,,,,,300.01828,,,,
,30872200.025,300.0110474,-62797.91015625,0.000175813424199582,2.24434789299854E-6,1,0.999253354069792,40.0298881530762,1.98583788171178,14.9400001391768,0.00196995965496316,0.000385918434295837,0.25,3.85150563564066E-6,0.00017580571684127,3.9665570312908E-6,300.0110474,300.0110474,-62802.93359375,-62792.88671875,57.0213637349291,20.6111287288598,23.668306,0,0,0,40,4449,300.1583,-62797.91015625,,,,,,,,,,,,,0,,,,-0.00245,,,,,,300.0110474,,,,
,30872279.535,300.0136108,-66772.44921875,0.00019354186637634,2.394261066157E-6,1,0.999253354069792,40.0298881530762,1.98586272935583,14.9400001391768,0.00216921612732652,0.000421453473375321,0.25,3.93906896730064E-6,0.000193533574249751,4.06560976510716E-6,300.0136108,300.0136108,-66779.9453125,-66764.953125,57.2034831799099,20.6106606764589,23.668306,0,0,0,40,4449,300.1492,-66772.44921875,,,,,,,,,,,,,0,,,,0.0049,,,,,,300.0136108,,,,
,30872362.37,300.0118103,-70912.359375,0.000208421814310658,2.20816971661199E-6,1,0.999253354069792,40.0298881530762,1.98591527273801,14.9400001391768,0.00234022985128077,0.000429740362418751,0.25,2.09704180617411E-6,0.000208414315591506,2.23323541234326E-6,300.0118103,300.0118103,-70922.390625,-70902.328125,56.8454973181022,20.6099821564507,23.668306,0,0,0,40,4449,300.1448,-70912.359375,,,,,,,,,,,,,0,,,,0.00245,,,,,,300.0118103,,,,
,30872444.98,300.0134277,-75039.8984375,0.000223603524250411,2.82802122155505E-6,1,0.999253354069792,40.0298881530762,1.98598057845664,14.9400001391768,0.00250569698571589,0.000490362546477019,0.25,4.85520601568241E-6,0.000223593778653704,5.00110221914862E-6,300.0134277,300.0134277,-75045.0703125,-75034.7265625,57.0674798175637,20.6100286862271,23.668306,0,0,0,40,4449,300.12375,-75039.8984375,,,,,,,,,,,,,0,,,,-0.0049,,,,,,300.0134277,,,,
,30872529.535,300.0108643,-79267.35546875,0.00024577711400983,2.77048590534922E-6,1,0.999253354069792,40.0298881530762,1.98603445434773,14.9400001391768,0.00275712794159417,0.000522366618861201,0.25,3.85784950936856E-6,0.000245767409093126,4.01807912953976E-6,300.0108643,300.0108643,-79277.296875,-79257.4140625,57.2425646058714,20.6097748433545,23.288654,0,0,0,40,4449,300.1308,-79267.35546875,,,,,,,,,,,,,0,,,,-0.00245,,,,,,300.0108643,,,,
,30872611.94,300.0066833,-83385.1484375,0.000260472077473583,3.23333819343328E-6,1,0.999253354069792,40.0298881530762,1.98603994200864,14.9400001391768,0.00291841789368069,0.000574186601681938,0.25,5.91879364513546E-6,0.000260460656860866,6.08837593951365E-6,300.0066833,300.0066833,-83390.4609375,-83379.8359375,57.0940551872176,20.6105475262699,23.288654,0,0,0,40,4449,300.1216,-83385.1484375,,,,,,,,,,,,,0,,,,0.0049,,,,,,300.0066833,,,,
,30872692.12,300.0046997,-87390.15625,0.000278469962835829,2.59380426259746E-6,1,0.999253354069792,40.0298881530762,1.98598237062962,14.9400001391768,0.00311935263232869,0.000617502517832628,0.25,6.65316700856568E-6,0.000278457581510824,6.83427467648894E-6,300.0046997,300.0046997,-87397.6796875,-87382.6328125,57.3269804859484,20.6116902731585,24.047956,0,0,0,40,4449,300.1128,-87390.15625,,,,,,,,,,,,,0,,,,0,,,,,,300.0046997,,,,
,30872789.475,300.0109558,-88660.24609375,0.000282617104260937,2.52182110873289E-6,1,0.999253354069792,40.0298881530762,1.98603258811869,14.9400001391768,0.00317112000413171,0.000596489362521216,0.25,4.06535812004527E-6,0.000282606230296231,4.2491819572422E-6,300.0109558,300.0109558,-88667.5859375,-88652.90625,57.2159892362176,20.6103058148629,23.288654,0,0,0,40,4449,300.1077,-88660.24609375,,,,,,,,,,,,,0,,,,0,,,,,,300.0109558,,,,
,30872869.235,300.0075073,-84675.51171875,0.000265219645070662,2.97430889497993E-6,1,0.999253354069792,40.0298881530762,1.98600848776934,14.9400001391768,0.00296884622666137,0.000600343639265957,0.25,7.42249199067854E-6,0.000265207103707987,7.59508217897476E-6,300.0075073,300.0075073,-84680.59375,-84670.4296875,57.0924919301791,20.6101667979362,24.047956,0,0,0,40,4449,300.09805,-84675.51171875,,,,,,,,,,,,,0,,,,-0.0049,,,,,,300.0075073,,,,
,30872951.785,300.0038757,-80551.0234375,0.000250638833227153,2.91697697847708E-6,1,0.999253354069792,40.0298881530762,1.98604795543023,14.9400001391768,0.00281261241548539,0.000527354159190135,0.25,3.45866852706797E-6,0.000250629312500596,3.62205286880191E-6,300.0038757,300.0038757,-80553.5078125,-80548.5390625,57.0057311645445,20.6121489124552,24.047956,0,0,0,40,4449,300.09195,-80551.0234375,,,,,,,,,,,,,0,,,,0,,,,,,300.0038757,,,,
,30873034.23,299.9979248,-76427.82421875,0.000231097833336358,2.5605207126094E-6,1,0.999253354069792,40.0298881530762,1.98597619365199,14.9400001391768,0.00259833654640294,0.000456796886332809,0.25,5.728532062147E-7,0.000231090796201728,7.237347802611E-7,299.9979248,299.9979248,-76429.9375,-76425.7109375,57.0065127930637,20.6088324884624,23.288654,0,0,0,40,4449,300.093,-76427.82421875,,,,,,,,,,,,,0,,,,0,,,,,,299.9979248,,,,
,30873118.145,299.9927979,-72235.16796875,0.000217464266265834,2.50657306607457E-6,1,0.999253354069792,40.0298881530762,1.98584341366159,14.9400001391768,0.00243914994356589,0.000462966425503975,0.25,3.48583054634366E-6,0.000217455745639345,3.62786540395291E-6,299.9927979,299.9927979,-72237.6796875,-72232.65625,57.2277136640061,20.6107030735297,24.047956,0,0,0,40,4449,300.11635,-72235.16796875,,,,,,,,,,,,,0,,,,-0.0049,,,,,,299.9927979,,,,
,30873200.025,299.98599245,-68145.3125,0.000198958386627802,2.63562959422377E-6,1,0.999253354069792,40.0298881530762,1.98584579145394,14.9400001391768,0.00222667276690016,0.000451922135631863,0.25,5.70986082341926E-6,0.000198948976774115,5.83986886347482E-6,299.9855957,299.9863892,-68150.1328125,-68140.4921875,57.4184310226984,20.611090669223,24.047956,0,0,0,40,4449,300.122,-68145.3125,,,,,,,,,,,,,0,,,,0,,,,,,299.98599245,,,,
,30873284.58,299.9871826,-63917.791015625,0.000181600159069457,2.00707826979253E-6,1,0.999253354069792,40.0298881530762,1.98584964372786,14.9400001391768,0.00203878659347419,0.000375683820168451,0.25,1.93880349164066E-6,0.00018159369162325,2.05768379989575E-6,299.9871826,299.9871826,-63927.60546875,-63907.9765625,57.0409044479099,20.6094320361938,23.668306,0,0,0,40,4449,300.12985,-63917.791015625,,,,,,,,,,,,,0,,,,0.00245,,,,,,299.9871826,,,,
,30873366.1,299.9894409,-59842.19140625,0.000165646676375531,2.18369378697925E-6,1,0.999253354069792,40.0298881530762,1.98607605592182,14.9400001391768,0.00185734010785697,0.000357391766600086,0.25,3.07289708758059E-6,0.00016563989812472,3.18140039252763E-6,299.9894409,299.9894409,-59849.7109375,-59834.671875,57.0838940164676,20.6085500904907,23.288654,0,0,0,40,4449,300.141,-59842.19140625,,,,,,,,,,,,,0,,,,-0.00245,,,,,,299.9894409,,,,
,30873447.09,299.9848633,-55796.8125,0.000148446018936329,2.87314219768737E-6,1,0.999253354069792,40.0298881530762,1.98596574123011,14.9400001391768,0.00166332032102782,0.000326419191359677,0.25,3.30098116645842E-6,0.000148439600006063,3.39829409778744E-6,299.9848633,299.9848633,-55801.5546875,-55792.0703125,56.8759808303522,20.6092030951532,23.668306,0,0,0,40,4449,300.15145,-55796.8125,,,,,,,,,,,,,0,,,,0,,,,,,299.9848633,,,,
,30873530.46,299.9849854,-51629.40625,0.000129693385994796,2.26368380518504E-6,1,0.999253354069792,40.0298881530762,1.98599937735508,14.9400001391768,0.00145053532204871,0.000300699502099371,0.25,4.26285570343762E-6,0.00012968686280117,4.3479158328186E-6,299.9849854,299.9849854,-51639.5078125,-51619.3046875,56.9049010855637,20.6122718471893,23.668306,0,0,0,40,4449,300.16665,-51629.40625,,,,,,,,,,,,,0,,,,0,,,,,,299.9849854,,,,
,30873614.025,299.9896851,-47451.666015625,0.000114954202921852,2.23346131770185E-6,1,0.999253354069792,40.0298881530762,1.98577390843474,14.9400001391768,0.00128277627463774,0.000282492361528106,0.25,5.20047948553809E-6,0.000114947457712178,5.27590460038714E-6,299.9896851,299.9896851,-47456.5234375,-47446.80859375,57.1573670972753,20.6112919340991,23.668306,0,0,0,40,4449,300.1695,-47451.666015625,,,,,,,,,,,,,0,,,,0,,,,,,299.9896851,,,,
,30873697.165,299.9926758,-43299.0703125,9.31482702942075E-5,2.04429435117754E-6,1,0.999253354069792,40.0298881530762,1.986005782311,14.9400001391768,0.0010425343061892,0.00021175907829576,0.25,2.68730317877641E-6,9.3143791207764E-5,2.74852442013322E-6,299.9926758,299.9926758,-43309.03515625,-43289.10546875,57.0416860764291,20.6089138167515,24.427608,0,0,0,40,4449,300.16615,-43299.0703125,,,,,,,,,,,,,0,,,,-0.00245,,,,,,299.9926758,,,,
,30873780.03,299.9830933,-39156.318359375,7.73743158870291E-5,1.9465442879767E-6,1,0.999253354069792,40.0298881530762,1.98590685930263,14.9400001391768,0.000866712613226504,0.000171478047559776,0.25,1.83985110732116E-6,7.73708750469928E-5,1.89076204731863E-6,299.9830933,299.9830933,-39161.43359375,-39151.203125,57.1620568683907,20.6066690510218,23.668306,0,0,0,40,4449,300.18175,-39156.318359375,,,,,,,,,,,,,0,,,,-0.0049,,,,,,299.9830933,,,,
,30873863.155,299.9855652,-35001.125,6.0306401675288E-5,1.60221623356185E-6,1,0.999253354069792,40.0298881530762,1.98602146641586,14.9400001391768,0.000671106897694837,0.000159376584825208,0.25,3.72025460580149E-6,6.03022033941829E-5,3.75990326449339E-6,299.9855652,299.9855652,-35008.61328125,-34993.63671875,57.119067299833,20.6089641167648,23.668306,0,0,0,40,4449,300.1975,-35001.125,,,,,,,,,,,,,0,,,,0,,,,,,299.9855652,,,,
,30873947.08,299.9872437,-30808.5498046875,4.31949153292322E-5,1.67842021936907E-6,1,0.999253354069792,40.0298881530762,1.98594848919692,14.9400001391768,0.000482533222167288,0.000103387518080034,0.25,1.70775198237842E-6,4.31925333715152E-5,1.7362024135293E-6,299.9872437,299.9872437,-30811.44921875,-30805.650390625,57.0909286731407,20.6098532482246,23.288654,0,0,0,40,4449,300.214,-30808.5498046875,,,,,,,,,,,,,0,,,,-0.0049,,,,,,299.9872437,,,,
,30874027.85,299.9916992,-26768.8095703125,2.78237033886225E-5,1.10912701290459E-6,1,0.999253354069792,40.0298881530762,1.98596035866681,14.9400001391768,0.000309805862711032,7.24622653506963E-5,0.25,1.6214872573377E-6,2.78218181466837E-5,1.63981421544258E-6,299.9916992,299.9916992,-26773.9375,-26763.681640625,56.9619599674676,20.6092982368894,23.668306,0,0,0,40,4449,300.207,-26768.8095703125,,,,,,,,,,,,,0,,,,0,,,,,,299.9916992,,,,
,30874111.325,299.9848633,-22600.8603515625,1.14190775199943E-5,1.17394805487556E-6,1,0.999253354069792,40.0298881530762,1.98585834789649,14.9400001391768,0.000126662982933158,3.24947302612698E-5,0.25,9.10590508798961E-7,1.14181436933124E-5,9.18111176546055E-7,299.9848633,299.9848633,-22611.15234375,-22590.568359375,57.0737328457176,20.6095819545184,23.288654,0,0,0,40,4449,300.21965,-22600.8603515625,,,,,,,,,,,,,0,,,,-0.00245,,,,,,299.9848633,,,,
,30874192.085,299.9900208,-18563.2236328125,-4.17041258783634E-6,8.36661949505829E-7,1,0.999253354069792,40.0298881530762,1.98585767174206,14.9400001391768,-4.85091233375276E-5,1.1188404337885E-6,0.25,8.22030934439864E-7,-4.17083410505515E-6,8.19248284055761E-7,299.9900208,299.9900208,-18568.06640625,-18558.380859375,56.9705578811791,20.6098134408849,24.047956,0,0,0,40,4449,300.2185,-18563.2236328125,,,,,,,,,,,,,0,,,,-0.00245,,,,,,299.9900208,,,,
,30874272.98,299.9866638,-14518.1840820313,-1.92956988567407E-5,8.26296413388261E-7,1,0.999253354069792,40.0298881530762,1.98588425402005,14.9400001391768,-0.000218118052957551,-3.13424705003383E-5,0.25,5.56591508984421E-7,-1.92955032827135E-5,5.43802718962368E-7,299.9866638,299.9866638,-14525.7060546875,-14510.662109375,56.9041194570445,20.608384078698,24.047956,0,0,0,40,4449,300.2319,-14518.1840820313,,,,,,,,,,,,,0,,,,-0.00245,,,,,,299.9866638,,,,
,30874355.335,299.9925842,-10402.498046875,-3.41124748017019E-5,6.5375216897969E-7,1,0.999253354069792,40.0298881530762,1.98597116680719,14.9400001391768,-0.000385339183849245,-5.7047290719246E-5,0.25,8.38623339100568E-7,-3.41120244806979E-5,8.16001615986404E-7,299.9925842,299.9925842,-10412.423828125,-10392.572265625,57.2996234877753,20.6046064568833,23.288654,0,0,0,40,4449,300.23275,-10402.498046875,,,,,,,,,,,,,0,,,,-0.00245,,,,,,299.9925842,,,,
,30874436.705,299.9910583,-6336.6396484375,-4.44258989353741E-5,5.69311502314198E-7,1,0.999253354069792,40.0298881530762,1.98596312459371,14.9400001391768,-0.000500459077901344,-8.22595514466803E-5,0.25,3.8406383828633E-7,-4.44248443416137E-5,3.54605308592809E-7,299.9910583,299.9910583,-6339.3701171875,-6333.9091796875,57.1229754424291,20.6055920515743,24.047956,0,0,0,40,4449,300.2468,-6336.6396484375,,,,,,,,,,,,,0,,,,-0.0049,,,,,,299.9910583,,,,
,30874514.78,299.9980774,-2435.03637695313,-4.57034305017188E-5,4.66577016925112E-7,1,0.999253354069792,40.0298881530762,1.98581324314301,14.9400001391768,-0.000514614192606955,-8.57678178984329E-5,0.25,2.92978120548064E-7,-4.57022648506639E-5,2.62657340579249E-7,299.9980774,299.9980774,-2440.03955078125,-2430.033203125,57.1042163579676,20.6077140738445,24.047956,0,0,0,40,4449,300.2402,-2435.03637695313,,,,,,,,,,,,,0,,,,-0.00245,,,,,,299.9980774,,,,
,30874588.89,299.9954224,1271.71270751953,3.9792780833786E-5,3.75867592291293E-7,1,0.999253354069792,40.0298881530762,1.9859137438975,14.9400001391768,0.000448400111431347,7.28480386261762E-5,0.25,-4.17910280447123E-7,3.97918774742574E-5,-3.91502922832137E-7,299.9954224,299.9954224,1266.78161621094,1276.64379882812,57.2425646058714,20.607988810421,23.668306,0,0,0,40,4449,300.2474,1271.71270751953,,,,,,,,,,,,,0,,,,0,,,,,,299.9954224,,,,
,30874665.935,299.9962769,5118.47290039063,4.61036782788826E-5,4.71615276376111E-7,1,0.999253354069792,40.0298881530762,1.98594121787199,14.9400001391768,0.000519401126397389,8.50917210841681E-5,0.25,-4.2289028031241E-7,4.6102590879048E-5,-3.9231277957625E-7,299.9962769,299.9962769,5113.48388671875,5123.4619140625,56.8751992018329,20.6048394526652,23.668306,0,0,0,40,4449,300.24775,5118.47290039063,,,,,,,,,,,,,0,,,,-0.00245,,,,,,299.9962769,,,,
,30874748,300.0007324,9222.119140625,3.79794148033624E-5,6.09324607335969E-7,1,0.999253354069792,40.0298881530762,1.98592276727735,14.9400001391768,0.000428799274936775,6.47320209293028E-5,0.25,-8.25279031803862E-7,3.79788302267386E-5,-8.00091828852447E-7,300.0007324,300.0007324,9217.1533203125,9227.0849609375,56.9869720800829,20.605124099279,23.668306,0,0,0,40,4449,300.24335,9222.119140625,,,,,,,,,,,,,0,,,,-0.0049,,,,,,300.0007324,,,,
,30874830.28,299.9989014,13332.4213867188,2.42166184251171E-5,7.00072482552322E-7,1,0.999253354069792,40.0298881530762,1.98603623716857,14.9400001391768,0.00027324554601931,4.23301805309069E-5,0.25,-4.32579046398536E-7,2.42161860733739E-5,-4.16533474349977E-7,299.9989014,299.9989014,13325.0244140625,13339.818359375,57.0057311645445,20.6051921382158,23.668306,0,0,0,40,4449,300.24185,13332.4213867188,,,,,,,,,,,,,0,,,,0.00245,,,,,,299.9989014,,,,
,30874912,300.0032349,17417.9052734375,9.2298578448485E-6,7.99286820017482E-7,1,0.999253354069792,40.0298881530762,1.98602418218088,14.9400001391768,0.000106907791760699,1.78570107262879E-7,0.25,-1.58327262720884E-6,9.23063030073453E-6,-1.57711945688048E-6,300.0032349,300.0032349,17412.99609375,17422.814453125,56.9306948266983,20.6047166584804,24.047956,0,0,0,40,4449,300.2405,17417.9052734375,,,,,,,,,,,,,0,,,,0,,,,,,300.0032349,,,,
,30874992.715,300.0040588,21453.2255859375,-5.79258815641141E-6,1.14192208392175E-6,1,0.999253354069792,40.0298881530762,1.98586247946809,14.9400001391768,-6.11500584395161E-5,-3.43918393819057E-5,0.25,-2.05408476753116E-6,-5.79105788003132E-6,-2.05785269198661E-6,300.0040588,300.0040588,21445.58203125,21460.869140625,56.933039712256,20.6032243348477,24.047956,0,0,0,40,4449,300.2373,21453.2255859375,,,,,,,,,,,,,0,,,,0,,,,,,300.0040588,,,,
,30875076.06,300.0082092,25618.748046875,-2.11326860189462E-5,1.19426284201067E-6,1,0.999253354069792,40.0298881530762,1.98592070120083,14.9400001391768,-0.000233801226223021,-6.36827450077901E-5,0.25,-2.00033339982304E-6,-2.11307335978027E-5,-2.01423110707509E-6,300.0082092,300.0082092,25613.71484375,25623.78125,56.8376810329099,20.604613729014,24.047956,0,0,0,40,4449,300.23705,25618.748046875,,,,,,,,,,,,,0,,,,-0.00245,,,,,,300.0082092,,,,
,30875156.635,300.0059509,29644.4794921875,-3.84166583393742E-5,1.63077437228879E-6,1,0.999253354069792,40.0298881530762,1.98584118793046,14.9400001391768,-0.000427522907531025,-0.000101236474486402,0.25,-2.34484553189548E-6,-3.84139684128934E-5,-2.37012743221832E-6,300.0059509,300.0059509,29636.93359375,29652.025390625,56.6133536478906,20.6039458195344,23.668306,0,0,0,40,4449,300.2346,29644.4794921875,,,,,,,,,,,,,0,,,,0,,,,,,300.0059509,,,,
,30875240.28,300.0140991,33827.470703125,-5.52151655019436E-5,1.39147676950068E-6,1,0.999253354069792,40.0298881530762,1.98572014562015,14.9400001391768,-0.000617508815682925,-0.000127728683810465,0.25,-1.79047301546576E-6,-5.52123295100505E-5,-1.82682491887324E-6,300.0140991,300.0140991,33820.0625,33834.87890625,56.9377294833714,20.6042446365117,23.668306,0,0,0,40,4449,300.2242,33827.470703125,,,,,,,,,,,,,0,,,,0.00245,,,,,,300.0140991,,,,
,30875320.735,300.0124817,37845.373046875,-7.23498825700238E-5,1.91330660118734E-6,1,0.999253354069792,40.0298881530762,1.98594367531691,14.9400001391768,-0.000806826795063786,-0.000181227052698388,0.25,-3.57682454716095E-6,-7.23453649088388E-5,-3.62438007021587E-6,300.0124817,300.0124817,37842.875,37847.87109375,56.8494054606983,20.6032199907014,23.668306,0,0,0,40,4449,300.2148,37845.373046875,,,,,,,,,,,,,0,,,,-0.0049,,,,,,300.0124817,,,,
,30875401.695,300.0134583,41893.25390625,-8.86259210303887E-5,1.65817980087699E-6,1,0.999253354069792,40.0298881530762,1.98593197067773,14.9400001391768,-0.000992803071518415,-0.000196162064420975,0.25,-2.08485088503764E-6,-8.86219030771956E-5,-2.14311876214084E-6,300.0134583,300.0134583,41885.90625,41900.6015625,56.7517018957945,20.6032697809356,23.668306,0,0,0,40,4449,300.2189,41893.25390625,,,,,,,,,,,,,0,,,,0,,,,,,300.0134583,,,,
,30875479.8,300.01367185,45799.337890625,-0.00010260969684811,2.9225979542645E-6,1,0.999253354069792,40.0298881530762,1.98572403265164,14.9400001391768,-0.00115197633932662,-0.000211856038038514,0.25,-1.05930126967645E-6,-0.000102605941139461,-1.12674803757318E-6,300.0132141,300.0141296,45794.30078125,45804.375,57.0495023616214,20.6042888259994,23.668306,0,0,0,40,4449,300.1978,45799.337890625,,,,,,,,,,,,,0,,,,0.00245,,,,,,300.01367185,,,,
,30875559.705,300.0097046,49792.552734375,-0.000119370598070163,2.53715163029558E-6,1,0.999253354069792,40.0298881530762,1.98578235082012,14.9400001391768,-0.00134114346378497,-0.000240937461072407,0.25,-7.40602034096064E-7,-0.00011936657603914,-8.19009879305953E-7,300.0097046,300.0097046,49787.69140625,49797.4140625,56.9236601700253,20.6056074313735,23.668306,0,0,0,40,4449,300.1891,49792.552734375,,,,,,,,,,,,,0,,,,0,,,,,,300.0097046,,,,
,30875641.165,300.0098267,53862.94921875,-0.000134956008576219,2.28166663089569E-6,1,0.999253354069792,40.0298881530762,1.98572871481754,14.9400001391768,-0.00151139523967398,-0.00030016943636024,0.25,-3.30751499467945E-6,-0.000134949847295463,-3.39600374137133E-6,300.0098267,300.0098267,53855.23046875,53870.66796875,56.7868751791599,20.6050391202369,23.668306,0,0,0,40,4449,300.1812,53862.94921875,,,,,,,,,,,,,0,,,,0,,,,,,300.0098267,,,,
,30875720.8,300.0050964,57843.11328125,-0.000152702958711625,2.995969716569E-6,1,0.999253354069792,40.0298881530762,1.98575027013901,14.9400001391768,-0.00171009310416606,-0.000340057867197314,0.25,-3.77918862638505E-6,-0.000152695999937785,-3.87921797732342E-6,300.0050964,300.0050964,57833.0703125,57853.15625,57.0416860764291,20.6042889937122,23.668306,0,0,0,40,4449,300.1791,57843.11328125,,,,,,,,,,,,,0,,,,0,,,,,,300.0050964,,,,
,30875800.805,300.0117493,61841.2109375,-0.000170968522691921,3.00450565636941E-6,1,0.999253354069792,40.0298881530762,1.98578927242859,14.9400001391768,-0.00191796394693255,-0.000361794745991169,0.25,-2.54682625453239E-6,-0.000170961806665054,-2.65876017875318E-6,300.0117493,300.0117493,61836.3203125,61846.1015625,56.6235148186406,20.6035094813735,24.047956,0,0,0,40,4449,300.17825,61841.2109375,,,,,,,,,,,,,0,,,,0,,,,,,300.0117493,,,,
,30875880.885,300.0121765,65842.34765625,-0.000186967617957618,3.00798339266261E-6,1,0.999253354069792,40.0298881530762,1.9858303744786,14.9400001391768,-0.00209706582328593,-0.000398090225618531,0.25,-3.00143139059647E-6,-0.000186960141694576,-3.12371181617748E-6,300.0121765,300.0121765,65839.7109375,65844.984375,56.8353361473522,20.605823211991,23.668306,0,0,0,40,4449,300.1793,65842.34765625,,,,,,,,,,,,,0,,,,0,,,,,,300.0121765,,,,
,30875962.93,300.0172119,69945.40234375,-0.000206841417873944,4.10030121537779E-6,1,0.999253354069792,40.0298881530762,1.9857414488335,14.9400001391768,-0.00232070439605372,-0.000435598056799078,0.25,-2.89484178823931E-6,-0.000206833400944275,-3.03000712871164E-6,300.0172119,300.0172119,69937.78125,69953.0234375,56.7517018957945,20.6027127172539,24.047956,0,0,0,40,4449,300.15245,69945.40234375,,,,,,,,,,,,,0,,,,0,,,,,,300.0172119,,,,
,30876043.875,300.0115051,73991.09375,-0.000223043165692148,2.50911717044797E-6,1,0.999253354069792,40.0298881530762,1.98583225360163,14.9400001391768,-0.00250185037908075,-0.000474028547091551,0.25,-3.50313396830016E-6,-0.000223034332229618,-3.64873102081003E-6,300.0115051,300.0115051,73991.09375,73991.09375,56.6907348712945,20.6025564034568,23.668306,0,0,0,40,4449,300.1452,73991.09375,,,,,,,,,,,,,0,,,,0,,,,,,300.0115051,,,,
,30876125.64,300.0153503,78079.54296875,-0.000239750351274756,3.50115680348189E-6,1,0.999253354069792,40.0298881530762,1.98587984373614,14.9400001391768,-0.00268936404082417,-0.000509260993609132,0.25,-3.74021864434144E-6,-0.000239740856166173,-3.89656295770116E-6,300.0153503,300.0153503,78069.375,78089.7109375,56.7540467813522,20.6009893742486,24.427608,0,0,0,40,4449,300.1376,78079.54296875,,,,,,,,,,,,,0,,,,0.00245,,,,,,300.0153503,,,,
,30876206.32,300.0169678,82110.84375,-0.000252754993250416,3.72257814767813E-6,1,0.999253354069792,40.0298881530762,1.98580732395424,14.9400001391768,-0.00282704337510943,-0.000583616350595498,0.25,-8.09983748869028E-6,-0.000252742275511925,-8.26437699240885E-6,300.0169678,300.0169678,82103.3203125,82118.3671875,56.9166255133522,20.6034092141746,24.047956,0,0,0,40,4449,300.1239,82110.84375,,,,,,,,,,,,,0,,,,0.0049,,,,,,300.0169678,,,,
,30876286.025,300.0055847,86096.734375,-0.000269044784221981,4.1129056634885E-6,1,0.999253354069792,40.0298881530762,1.98576568898709,14.9400001391768,-0.00300894032046912,-0.00062262728054751,0.25,-8.74737655207943E-6,-0.000269031297086077,-8.92233866314795E-6,300.0055847,300.0055847,86091.578125,86101.890625,56.8376810329099,20.6021392877924,23.668306,0,0,0,40,4449,300.1241,86096.734375,,,,,,,,,,,,,0,,,,0,,,,,,300.0055847,,,,
,30876362.84,300.0079041,89935.3515625,-0.000289132175506075,3.92046822404342E-6,1,0.999253354069792,40.0298881530762,1.98572827926293,14.9400001391768,-0.00324596833527647,-0.000597336792656722,0.25,-3.01981695565321E-6,-0.000289121831334083,-3.20783834912211E-6,300.0079041,300.0079041,89925.3515625,89945.3515625,56.7782772654483,20.6030117407265,24.047956,0,0,0,40,4449,300.1221,89935.3515625,,,,,,,,,,,,,0,,,,0,,,,,,300.0079041,,,,
,30876365.565,300.0091858,89999.63671875,-0.00028472694659042,3.24434981514172E-6,1,0.999253354069792,40.0298881530762,1.98576215413206,14.9400001391768,-0.00319061003284589,-0.000622615615481701,0.25,-6.0297320553492E-6,-0.000284714759289342,-6.21479483535235E-6,300.0091858,300.0091858,89999.6328125,89999.640625,56.8197035769676,20.6039304153677,23.668306,0,0,0,40,4417,300.1248,89999.63671875,,,,,,,,,,,,,0,,,,-0.00245,,,,,,300.0091858,,,,