File: data/doubleLayers/dl_5/ppms/data/DD205_6_HYST_100OE_20K.DAT
[Header]
; VSM Data File (default extension .dat)
; Copyright (c) 2003-2013, Quantum Design, Inc. All rights reserved.
TITLE,
FILEOPENTIME,30950036.84,12/25/2018,1:15 pm
BYAPP,VSM,2.0,2.0
INFO,PPMS VSM Option Release 1.4.10 Build 1,APPNAME
INFO,Quantum Design Linear Motor Servo Controller,MOTOR_MODULE_NAME
INFO,3101-100 M1,MOTOR_HW_VERSION
INFO,MMC1014,MOTOR_SERIAL_NUMBER
INFO,SRV No X-over 01.03.11,MOTOR_SOFTWARE_VERSION
INFO,Quantum Design VSM Detection Module,VSM_MODULE_NAME
INFO,3101-150 F0,VSM_HW_VERSION
INFO,VSM707,VSM_SERIAL_NUMBER
INFO,VSM No X-over 01.02.05 May 20 2008 13:51:47,VSM_SOFTWARE_VERSION
INFO,704,PREAMP_SERIAL_NUMBER
INFO,822,COIL_SERIAL_NUMBER
INFO,0,MOMENT_UNITS
INFO,CoFe2O4,SAMPLE_MATERIAL
INFO,AH11 DL,SAMPLE_COMMENT
INFO,30.27,SAMPLE_MASS
INFO,,SAMPLE_VOLUME
INFO,,SAMPLE_MOLECULAR_WEIGHT
INFO,,SAMPLE_SIZE
INFO,,SAMPLE_SHAPE
DATATYPE,COMMENT,1
DATATYPE,TIME,2
STARTUPAXIS,X,2
STARTUPAXIS,Y1,5
[Data]
Comment,Time Stamp (sec),Temperature (K),Magnetic Field (Oe),Moment (emu),M. Std. Err. (emu),Transport Action,Averaging Time (sec),Frequency (Hz),Peak Amplitude (mm),Center Position (mm),Coil Signal' (mV),Coil Signal" (mV),Range (mV),M. Quad. Signal (emu),M. Raw' (emu),M. Raw" (emu),Min. Temperature (K),Max. Temperature (K),Min. Field (Oe),Max. Field (Oe),Mass (grams),Motor Lag (deg),Pressure (Torr),VSM Status (code),Motor Status (code),Measure Status (code),Measure Count,PPMS Status (code),System Temp. (K),System Field (Oe),Sample Position (deg),Bridge 1 Resistance (ohms),Bridge 1 Excitation (에),Bridge 2 Resistance (ohms),Bridge 2 Excitation (에),Bridge 3 Resistance (ohms),Bridge 3 Excitation (에),Bridge 4 Resistance (ohms),Bridge 4 Excitation (에),Signal 1 Vin (V),Signal 2 Vin (V),Digital Inputs (code),Drive 1 Iout (mA),Drive 1 Ipower (W),Drive 2 Iout (mA),Drive 2 Ipower (W),Pressure (),Map 20 (),Map 21 (),Map 22 (),Map 23 (),Map 24 (),Map 25 (),Map 26 (),Map 27 (),Map 28 (),Map 29 ()
,30950051.73,20.0005226,-0.365370541810989,,,2,,,,16.2499998378754,,,,,,,20.0005226,20.0005226,-0.365370541810989,-0.365370541810989,,,13.797379,,,,-99999999,4369,20.0111,-0.365370541810989,,,,,,,,,,,,,,,,,,,,,,,20.0005226,,,,
,30950214.165,20.0007286,4675.38818359375,6.36940747886111E-5,3.28198888416577E-7,1,0.999253354069792,40.0298881530762,1.98410630344729,16.2400007247925,0.000711546272377456,0.000125371792541058,0.25,-1.04732491045183E-7,6.33446185088492E-5,2.22510609937269E-7,20.0007286,20.0007286,4665.49853515625,4685.27783203125,56.5899047923137,20.630504331935,13.417728,0,0,0,40,4449,20.0088,4675.38818359375,,,,,,,,,,,,,0,,,,-0.0049,,,,,,20.0007286,,,,
,30950310.71,20.0010052,9498.92822265625,4.78051483890467E-5,3.32536977528515E-7,1,0.999253354069792,40.0298881530762,1.98394784966866,16.2400007247925,0.000533365274760216,9.87930186458684E-5,0.25,3.22691947125048E-7,4.75576883950767E-5,5.82926766014537E-7,20.0010052,20.0010052,9491.390625,9506.4658203125,56.8986480574099,20.6365423054277,13.797379,0,0,0,40,4449,20.0085,9498.92822265625,,,,,,,,,,,,,0,,,,-0.00245,,,,,,20.0010052,,,,
,30950406.93,20.0014992,14309.240234375,3.01703238917015E-5,3.55271270909207E-7,1,0.999253354069792,40.0298881530762,1.9840478868748,16.2400007247925,0.000337901323191122,5.60230299389793E-5,0.25,-3.75503927237412E-7,3.0029742664144E-5,-1.97930421630077E-7,20.0014992,20.0014992,14304.3271484375,14314.1533203125,56.821266834006,20.6362231627139,13.417728,0,0,0,40,4449,20.0076,14309.240234375,,,,,,,,,,,,,0,,,,0,,,,,,20.0014992,,,,
,30950498.905,20.0022926,18903.9697265625,1.38156538334508E-5,4.17951785094108E-7,1,0.999253354069792,40.0298881530762,1.98396055640828,16.2400007247925,0.000155410276920357,2.2214405137883E-5,0.25,-4.84884665489981E-7,1.37591333675157E-5,-3.97953859554921E-7,20.0022926,20.0022926,18901.609375,18906.330078125,56.9314764552176,20.6368915404295,13.797379,0,0,0,40,4449,20.0054,18903.9697265625,,,,,,,,,,,,,0,,,,-0.0049,,,,,,20.0022926,,,,
,30950596.45,20.0020237,23779.4541015625,-1.16611226377368E-6,3.42053189645784E-7,1,0.999253354069792,40.0298881530762,1.98375963885135,16.2400007247925,-1.14984134635043E-5,-1.09372760765555E-5,0.25,-7.69060947513666E-7,-1.15669472823943E-6,-7.73632453185641E-7,20.0020237,20.0020237,23774.74609375,23784.162109375,56.9822823089676,20.6423588889262,13.797379,0,0,0,40,4449,20.0031,23779.4541015625,,,,,,,,,,,,,0,,,,0,,,,,,20.0020237,,,,
,30950690.365,20.00243475,28472.25390625,-1.84022701978944E-5,5.73303509162404E-7,1,0.999253354069792,40.0298881530762,1.9838545500974,16.2400007247925,-0.000202794492833535,-5.41518558107959E-5,0.25,-1.53692625697197E-6,-1.83304237900889E-5,-1.65506562446237E-6,20.0023804,20.0024891,28462.376953125,28482.130859375,56.7415407250445,20.6451230950057,13.797379,0,0,0,40,4449,20.0021,28472.25390625,,,,,,,,,,,,,0,,,,0.00245,,,,,,20.00243475,,,,
,30950786.82,20.0022202,33295.18359375,-3.62495605628333E-5,5.05286989264313E-7,1,0.999253354069792,40.0298881530762,1.98383861548923,16.2400007247925,-0.000401889419837394,-9.43529249871299E-5,0.25,-1.91439511732277E-6,-3.61334229330112E-5,-2.15986599917132E-6,20.0022202,20.0022202,33290.05078125,33300.31640625,57.2073913225061,20.6454933278405,13.417728,0,0,0,40,4449,20.0007,33295.18359375,,,,,,,,,,,,,0,,,,0.00245,,,,,,20.0022202,,,,
,30950880.195,20.0025978,37959.81640625,-5.37028703239293E-5,5.24211213262145E-7,1,0.999253354069792,40.0298881530762,1.98389947218692,16.2400007247925,-0.000598634818076371,-0.000123526465348502,0.25,-1.36884792987823E-6,-5.35672512922414E-5,-1.74677274010867E-6,20.0025978,20.0025978,37947.29296875,37972.33984375,56.9447641400445,20.6430688489424,13.417728,0,0,0,40,4449,19.99935,37959.81640625,,,,,,,,,,,,,0,,,,0,,,,,,20.0025978,,,,
,30950977.69,20.0022497,42835.0625,-6.94413293645066E-5,6.33706185131085E-7,1,0.999253354069792,40.0298881530762,1.98386617487232,16.2400007247925,-0.000776943629489697,-0.000146004017848758,0.25,-5.28353191599639E-7,-6.93103814759893E-5,-1.03010811728414E-6,20.0021057,20.0023937,42829.91015625,42840.21484375,57.058100275333,20.6429381394361,13.797379,0,0,0,40,4449,19.9975,42835.0625,,,,,,,,,,,,,0,,,,-0.00245,,,,,,20.0022497,,,,
,30951072.015,20.0015049,47547.912109375,-8.83181180549423E-5,6.07232635279698E-7,1,0.999253354069792,40.0298881530762,1.98373828222598,16.2400007247925,-0.000985908869865399,-0.000200542320478674,0.25,-1.98117420130109E-6,-8.81850903719078E-5,-2.62670089979708E-6,20.0015049,20.0015049,47543.01171875,47552.8125,57.0260535060445,20.6473818006853,14.177031,0,0,0,40,4449,19.99605,47547.912109375,,,,,,,,,,,,,0,,,,0.00245,,,,,,20.0015049,,,,
,30951166.36,20.0005322,52263.146484375,-0.000106960587050919,5.47432536890356E-7,1,0.999253354069792,40.0298881530762,1.98387793331983,16.2400007247925,-0.00119635504734868,-0.000233642824561058,0.25,-1.55789843724402E-6,-0.000106856619760718,-2.34850224966641E-6,20.0005322,20.0005322,52255.578125,52270.71484375,57.0838940164676,20.6428727486206,13.417728,0,0,0,40,4449,19.99615,52263.146484375,,,,,,,,,,,,,0,,,,-0.00245,,,,,,20.0005322,,,,
,30951262.875,20.0004673,57087.865234375,-0.000123803697221934,6.24626837280087E-7,1,0.999253354069792,40.0298881530762,1.98383158322994,16.2400007247925,-0.00138533758719177,-0.000270731750281481,0.25,-1.81511862923124E-6,-0.00012374172161142,-2.73522569240618E-6,20.0004673,20.0004673,57082.85546875,57092.875,56.8478422036599,20.6451007543095,13.417728,0,0,0,40,4449,19.99475,57087.865234375,,,,,,,,,,,,,0,,,,0.00245,,,,,,20.0004673,,,,
,30951357.345,20.00085165,61808.115234375,-0.000144947222471278,8.89213041981521E-7,1,0.999253354069792,40.0298881530762,1.98391904962244,16.2400007247925,-0.00162139807690509,-0.000324447321961328,0.25,-2.77756300478629E-6,-0.000144934193644923,-3.85638446104812E-6,20.0007229,20.0009804,61800.8046875,61815.42578125,57.0831123879483,20.6416399462805,13.797379,0,0,0,40,4449,19.9946,61808.115234375,,,,,,,,,,,,,0,,,,-0.00245,,,,,,20.00085165,,,,
,30951456.17,20.0012131,66748.921875,-0.000163976626938386,7.3996079641626E-7,1,0.999253354069792,40.0298881530762,1.98363467734364,16.2400007247925,-0.00183837747460781,-0.000347453487688419,0.25,-1.39180163337365E-6,-0.000164047724951437,-2.60910851516892E-6,20.0012131,20.0012131,66738.75,66759.09375,57.0846756449868,20.6471056768747,14.177031,0,0,0,40,4449,19.9926,66748.921875,,,,,,,,,,,,,0,,,,-0.00245,,,,,,20.0012131,,,,
,30951554.65,20.0020676,71671.765625,-0.000183461882372217,6.12934635594706E-7,1,0.999253354069792,40.0298881530762,1.98369605688292,16.2400007247925,-0.00205653167158509,-0.000395700817754136,0.25,-2.17015027370613E-6,-0.000183613935848902,-3.52493085502271E-6,20.0020676,20.0020676,71666.859375,71676.671875,56.976810909333,20.6448481175739,13.417728,0,0,0,40,4449,19.9914,71671.765625,,,,,,,,,,,,,0,,,,0,,,,,,20.0020676,,,,
,30951653.555,20.0008717,76614.765625,-0.00020185828425721,8.52591315028395E-7,1,0.999253354069792,40.0298881530762,1.98388851537284,16.2400007247925,-0.00226576133444706,-0.00042502058963339,0.25,-1.46097477130866E-6,-0.000202112793371417,-2.93804643361166E-6,20.0008717,20.0008717,76609.6796875,76619.8515625,56.9994781363906,20.6425902182901,13.797379,0,0,0,40,4449,19.9897,76614.765625,,,,,,,,,,,,,0,,,,0,,,,,,20.0008717,,,,
,30951748.305,20.0014648,81352.9609375,-0.000222098807253523,6.88900782894184E-7,1,0.999253354069792,40.0298881530762,1.98397168132402,16.2400007247925,-0.00249260213930196,-0.000475284639906958,0.25,-2.28901709004339E-6,-0.000222453777750667,-3.89842975315893E-6,20.0014648,20.0014648,81343.03125,81362.890625,57.0596635323714,20.6443562864185,13.797379,0,0,0,40,4449,19.98835,81352.9609375,,,,,,,,,,,,,0,,,,0,,,,,,20.0014648,,,,
,30951842.425,20.002079,86056.22265625,-0.000242711656912592,7.96852354242152E-7,1,0.999253354069792,40.0298881530762,1.98375173278691,16.2400007247925,-0.00272008134564793,-0.00054442187782298,0.25,-4.73865364881057E-6,-0.000243165185669198,-6.48078638426981E-6,20.002079,20.002079,86046.171875,86066.2734375,57.1182856713137,20.6439111124471,13.797379,0,0,0,40,4449,19.9871,86056.22265625,,,,,,,,,,,,,0,,,,0,,,,,,20.002079,,,,
,30951947.205,20.0017662,89647.16015625,-0.000257955529527915,7.60158846185847E-7,1,0.999253354069792,40.0298881530762,1.98363844117812,16.2400007247925,-0.00289310041264175,-0.000569622116835053,0.25,-4.24715081926583E-6,-0.000258505934845519,-6.07854138563748E-6,20.0017662,20.0017662,89639.765625,89654.5546875,57.0917103016599,20.6462809579602,14.177031,0,0,0,40,4449,19.9857,89647.16015625,,,,,,,,,,,,,0,,,,-0.00245,,,,,,20.0017662,,,,
,30952036.21,20.0010872,85204.203125,-0.000238446310562979,7.88417230438208E-7,1,0.999253354069792,40.0298881530762,1.98377652692534,16.2400007247925,-0.00267461242646564,-0.000521160275704106,0.25,-3.4357448847004E-6,-0.000238886402492489,-5.14871483156998E-6,20.0010872,20.0010872,85194.46875,85213.9375,57.0252718775253,20.646895662765,13.417728,0,0,0,40,4449,19.9844,85204.203125,,,,,,,,,,,,,0,,,,-0.00245,,,,,,20.0010872,,,,
,30952133.28,19.999876,80350.671875,-0.000218735577689246,8.86814957561765E-7,1,0.999253354069792,40.0298881530762,1.98429477750842,16.2400007247925,-0.00245537980866952,-0.000466331272253816,0.25,-2.09078477930519E-6,-0.000219070095913794,-3.67928881460194E-6,19.999876,19.999876,80340.3359375,80361.0078125,56.3327490094867,20.638969224409,14.177031,0,0,0,40,4449,19.98515,80350.671875,,,,,,,,,,,,,0,,,,0,,,,,,19.999876,,,,
,30952228.775,19.9989948,75576.34375,-0.000200471402724172,8.270658568978E-7,1,0.999253354069792,40.0298881530762,1.98390288564404,16.2400007247925,-0.00224558619367645,-0.000446720925423317,0.25,-3.64131660046093E-6,-0.000200691742093591,-5.11389151253615E-6,19.9989948,19.9989948,75571.1953125,75581.4921875,56.7477937531983,20.6458498617122,13.038077,0,0,0,40,4449,19.9867,75576.34375,,,,,,,,,,,,,0,,,,0.0049,,,,,,19.9989948,,,,
,30952322.835,19.9989166,70872.90234375,-0.000180824783709363,9.56955989807587E-7,1,0.999253354069792,40.0298881530762,1.98400063769122,16.2400007247925,-0.00202458050033643,-0.000404212592382662,0.25,-3.39842256595007E-6,-0.000180953307267851,-4.73626003473908E-6,19.9989166,19.9989166,70867.71875,70878.0859375,57.1104693861214,20.646517121991,14.177031,0,0,0,40,4449,19.9874,70872.90234375,,,,,,,,,,,,,0,,,,0.00245,,,,,,19.9989166,,,,
,30952419.32,19.9983482,66050.09765625,-0.000161583881998687,6.45239036811261E-7,1,0.999253354069792,40.0298881530762,1.98394994730405,16.2400007247925,-0.00180909519436283,-0.000356954143655389,0.25,-2.66545415860222E-6,-0.000161634402846626,-3.86623437827076E-6,19.9983482,19.9983482,66040.2109375,66059.984375,57.2128627221407,20.6448190238736,14.177031,0,0,0,40,4449,19.98885,66050.09765625,,,,,,,,,,,,,0,,,,0,,,,,,19.9983482,,,,
,30952516.7,19.999361,61184.103515625,-0.000141095572450134,7.11835765265383E-7,1,0.999253354069792,40.0298881530762,1.98394369985114,16.2400007247925,-0.00157839121936715,-0.000314976501027741,0.25,-2.62917735964296E-6,-0.000141075306267028,-3.67931186412425E-6,19.999361,19.999361,61176.44921875,61191.7578125,57.1198489283522,20.6440960226368,13.797379,0,0,0,40,4449,19.9909,61184.103515625,,,,,,,,,,,,,0,,,,0,,,,,,19.999361,,,,
,30952615.345,19.9992199,56254.01171875,-0.000121975809549919,5.84457148444033E-7,1,0.999253354069792,40.0298881530762,1.98375891861867,16.2400007247925,-0.00136478256360588,-0.000266391893916392,0.25,-1.76088322498136E-6,-0.000121905147881017,-2.66683727401608E-6,19.9992199,19.9992199,56243.84375,56264.1796875,57.0940551872176,20.6486510419697,14.177031,0,0,0,40,4449,19.99195,56254.01171875,,,,,,,,,,,,,0,,,,0,,,,,,19.9992199,,,,
,30952709.735,19.9989338,51536.513671875,-0.000102773468334086,5.67249709219966E-7,1,0.999253354069792,40.0298881530762,1.98370665882609,16.2400007247925,-0.00114901253929071,-0.000226299464924587,0.25,-1.66156384118525E-6,-0.000102664893959336,-2.42014744715138E-6,19.9989338,19.9989338,51531.6328125,51541.39453125,56.9729027667368,20.6507284779094,13.797379,0,0,0,40,4449,19.99215,51536.513671875,,,,,,,,,,,,,0,,,,-0.00245,,,,,,19.9989338,,,,
,30952805.755,19.99995895,46736.408203125,-8.44164711588686E-5,7.16834382269074E-7,1,0.999253354069792,40.0298881530762,1.9836838971108,16.2400007247925,-0.000943011723639715,-0.000187438378110355,0.25,-1.51797804677833E-6,-8.42850496839069E-5,-2.13413069591187E-6,19.9998569,20.000061,46728.93359375,46743.8828125,57.2535074051407,20.6486617981646,13.797379,0,0,0,40,4449,19.99275,46736.408203125,,,,,,,,,,,,,0,,,,0,,,,,,19.99995895,,,,
,30952899.585,20.00012395,42046.029296875,-6.60861267829937E-5,6.42801190914702E-7,1,0.999253354069792,40.0298881530762,1.98385124034058,16.2400007247925,-0.000739979454645134,-0.000135370219534865,0.25,-1.85747965368275E-7,-6.59583313210622E-5,-6.62483029899575E-7,20.0000839,20.000164,42041.07421875,42050.984375,57.4981571316599,20.6485016665282,13.797379,0,0,0,40,4449,19.9918,42046.029296875,,,,,,,,,,,,,0,,,,-0.00245,,,,,,20.00012395,,,,
,30952995.275,19.9989204,37263.45703125,-4.94248086028916E-5,4.51923349657066E-7,1,0.999253354069792,40.0298881530762,1.98385714415809,16.2400007247925,-0.000553228844665912,-0.000100700406336845,0.25,-1.0221097573914E-7,-4.93045628478379E-5,-4.51561275001307E-7,19.9989204,19.9989204,37253.41015625,37273.50390625,56.7993812354675,20.6511214345897,13.797379,0,0,0,40,4449,19.99305,37263.45703125,,,,,,,,,,,,,0,,,,0.00245,,,,,,19.9989204,,,,
,30953090.165,19.9986057,32520.8642578125,-3.01092744133894E-5,5.15529375963782E-7,1,0.999253354069792,40.0298881530762,1.98400156639777,16.2400007247925,-0.000335198925572894,-7.06576667217158E-5,0.25,-9.02031827289855E-7,-3.00151367068853E-5,-1.10680958626966E-6,19.9986057,19.9986057,32510.857421875,32530.87109375,57.2988418592561,20.6453775930183,13.797379,0,0,0,40,4449,19.9946,32520.8642578125,,,,,,,,,,,,,0,,,,-0.0049,,,,,,19.9986057,,,,
,30953183.74,19.9984322,27845.6796875,-1.38868156090826E-5,5.64529443197561E-7,1,0.999253354069792,40.0298881530762,1.98389216344261,16.2400007247925,-0.000152509546256805,-4.37454161370646E-5,0.25,-1.41793877013142E-6,-1.38300089573148E-5,-1.50568969898188E-6,19.9984322,19.9984322,27837.904296875,27853.455078125,57.0534105042176,20.6462387932131,13.797379,0,0,0,40,4449,19.99515,27845.6796875,,,,,,,,,,,,,0,,,,0.0049,,,,,,19.9984322,,,,
,30953276.455,19.9976482,23210.4677734375,3.64436234132637E-6,4.19847039188496E-7,1,0.999253354069792,40.0298881530762,1.98373171963945,16.2400007247925,4.23746526802337E-5,-1.76281089866731E-6,0.25,-8.10761967760757E-7,3.63540604056355E-6,-7.84251999846496E-7,19.9976482,19.9976482,23205.419921875,23215.515625,57.0964000727753,20.649046431069,13.797379,0,0,0,40,4449,19.9969,23210.4677734375,,,,,,,,,,,,,0,,,,-0.0049,,,,,,19.9976482,,,,
,30953371.81,19.9990158,18445.9619140625,2.04383799516821E-5,3.96280005006391E-7,1,0.999253354069792,40.0298881530762,1.98383808692999,16.2400007247925,0.000227098548368934,4.84314648757504E-5,0.25,6.76418158023554E-7,2.03453302370083E-5,7.98369335968795E-7,19.9990158,19.9990158,18433.189453125,18458.734375,57.0495023616214,20.6498074781425,13.797379,0,0,0,40,4449,19.99765,18445.9619140625,,,,,,,,,,,,,0,,,,0,,,,,,19.9990158,,,,
,30953465.61,19.9984074,13758.16015625,3.65976019724308E-5,4.0164542685878E-7,1,0.999253354069792,40.0298881530762,1.98391963610042,16.2400007247925,0.000407591041916015,8.05427994203182E-5,0.25,6.72912711537706E-7,3.64187308952478E-5,8.8150468429336E-7,19.9984074,19.9984074,13750.7958984375,13765.5244140625,57.1729996676599,20.6477683393541,13.417728,0,0,0,40,4449,20.00005,13758.16015625,,,,,,,,,,,,,0,,,,0,,,,,,19.9984074,,,,
,30953560.105,19.9990597,9035.90185546875,5.27988466472963E-5,3.08812117705986E-7,1,0.999253354069792,40.0298881530762,1.98379362827025,16.2400007247925,0.00058945316068798,0.000106640870908124,0.25,1.37966581696586E-7,5.25247928577912E-5,4.24700762640883E-7,19.9990597,19.9990597,9028.3984375,9043.4052734375,57.2691399755253,20.6501883735809,13.417728,0,0,0,40,4449,20.0006,9035.90185546875,,,,,,,,,,,,,0,,,,-0.00245,,,,,,19.9990597,,,,
,30953656.515,19.9984608,4215.048828125,6.83669814750526E-5,3.58062370215325E-7,1,0.999253354069792,40.0298881530762,1.98362773129213,16.2400007247925,0.000762606850088807,0.000139833008997602,0.25,3.64343568939593E-7,6.79873716336234E-5,7.1075991743058E-7,19.9984608,19.9984608,4209.98486328125,4220.11279296875,57.1581487257945,20.6498931864199,14.177031,0,0,0,40,4449,20.0012,4215.048828125,,,,,,,,,,,,,0,,,,-0.00245,,,,,,19.9984608,,,,
,30953751.855,19.9998207,-550.203002929687,8.08666046712087E-5,3.28959930246942E-7,1,0.999253354069792,40.0298881530762,1.98376218300213,16.2400007247925,0.000902681114409842,0.000161018209299847,0.25,5.91433163981163E-8,8.04028675996131E-5,4.52486322224656E-7,19.9998207,19.9998207,-562.613952636719,-537.792053222656,57.0799858738714,20.6488914679613,13.417728,0,0,0,40,4449,20.0011,-550.203002929687,,,,,,,,,,,,,0,,,,0,,,,,,19.9998207,,,,
,30953848.14,19.9993553,-5359.9765625,9.36340916978317E-5,3.21750210396129E-7,1,0.999253354069792,40.0298881530762,1.98412466311751,16.2400007247925,0.00104526749009323,0.000188845435658113,0.25,2.47222540490738E-7,9.3122634982532E-5,7.30614071419532E-7,19.9993553,19.9993553,-5367.55810546875,-5352.39501953125,57.2597604332945,20.6446286906706,13.797379,0,0,0,40,4449,20.0013,-5359.9765625,,,,,,,,,,,,,0,,,,0,,,,,,19.9993553,,,,
,30953943.66,19.99938105,-10136.0810546875,0.000102540961548975,3.52410363226647E-7,1,0.999253354069792,40.0298881530762,1.98379524400939,16.2400007247925,0.00114622336070745,0.00019960926484924,0.25,-4.13296488984883E-7,0.000102021489855293,1.55344249147634E-7,19.999279,19.9994831,-10141.26171875,-10130.900390625,57.2519441481022,20.6523232434755,14.177031,0,0,0,40,4449,20.0027,-10136.0810546875,,,,,,,,,,,,,0,,,,-0.0049,,,,,,19.99938105,,,,
,30954038.285,20.0010204,-14863.6665039062,0.000100982055434143,4.63567734360348E-7,1,0.999253354069792,40.0298881530762,1.98399446636815,16.2400007247925,0.00112808314589191,0.000203877604776671,0.25,2.03213890371606E-7,0.000100508007673283,7.94606656011597E-7,20.0010204,20.0010204,-14873.6630859375,-14853.669921875,57.1010898438907,20.649080451754,14.177031,0,0,0,40,4449,20.0008,-14863.6665039062,,,,,,,,,,,,,0,,,,0,,,,,,20.0010204,,,,
,30954136.75,20.0024529,-19786.08203125,8.70034065490252E-5,4.2309778652092E-7,1,0.999253354069792,40.0298881530762,1.98388241574076,16.2400007247925,0.000972547475284916,0.000174483835799895,0.25,3.50186652719614E-8,8.66358881503672E-5,5.74147319037543E-7,20.0024529,20.0024529,-19791.23046875,-19780.93359375,57.1862873524868,20.6489773116885,13.797379,0,0,0,40,4449,20.00015,-19786.08203125,,,,,,,,,,,,,0,,,,-0.0049,,,,,,20.0024529,,,,
,30954231.585,20.0013733,-24525.6826171875,6.67000611650405E-5,3.76497266523464E-7,1,0.999253354069792,40.0298881530762,1.98375996166594,16.2400007247925,0.000745118853101006,0.000138184305312783,0.25,3.97861865409366E-7,6.64472973120868E-5,8.29039071533635E-7,20.0013733,20.0013733,-24557.93359375,-24493.431640625,57.4090514804676,20.6538075169086,13.797379,0,0,0,40,4449,19.9971,-24525.6826171875,,,,,,,,,,,,,0,,,,-0.0049,,,,,,20.0013733,,,,
,30954328.175,20.0010929,-29350.7333984375,5.42660249317548E-5,4.35254791903085E-7,1,0.999253354069792,40.0298881530762,1.98392657598848,16.2400007247925,0.000605568211759607,0.000118055242845193,0.25,8.07352185791159E-7,5.40840436160208E-5,1.17062658145053E-6,20.0010929,20.0010929,-29360.779296875,-29340.6875,57.2707032325638,20.652527207613,13.417728,0,0,0,40,4449,19.9971,-29350.7333984375,,,,,,,,,,,,,0,,,,-0.0049,,,,,,20.0010929,,,,
,30954422.325,20.0010414,-34057.95703125,5.40006890450655E-5,5.52923852218715E-7,1,0.999253354069792,40.0298881530762,1.98404354134022,16.2400007247925,0.000603751587077624,0.000113026914473234,0.25,3.88812516559473E-7,5.38490675504469E-5,7.6320292238983E-7,20.0010414,20.0010414,-34067.7578125,-34048.15625,57.3144744296407,20.6514839961954,13.797379,0,0,0,40,4449,19.99615,-34057.95703125,,,,,,,,,,,,,0,,,,0.00245,,,,,,20.0010414,,,,
,30954521.49,20.0013008,-39014.642578125,6.23828836153817E-5,4.58142254200657E-7,1,0.999253354069792,40.0298881530762,1.98394842191076,16.2400007247925,0.000699448262608286,0.000121492562438751,0.25,-3.77975455213255E-7,6.22462811362441E-5,6.77449863224098E-8,20.0013008,20.0013008,-39019.42578125,-39009.859375,57.1894138665637,20.6523464334976,13.797379,0,0,0,40,4449,19.9941,-39014.642578125,,,,,,,,,,,,,0,,,,0,,,,,,20.0013008,,,,
,30954619.65,20.0019875,-43919.87109375,7.71919833212762E-5,5.69164604439701E-7,1,0.999253354069792,40.0298881530762,1.98389292748438,16.2400007247925,0.000864903266173087,0.000156032797199966,0.25,2.42079145430904E-8,7.70592451057527E-5,5.85018487379545E-7,20.0019875,20.0019875,-43927.4296875,-43912.3125,57.261323690333,20.6555517926667,13.417728,0,0,0,40,4449,19.9924,-43919.87109375,,,,,,,,,,,,,0,,,,-0.0049,,,,,,20.0019875,,,,
,30954718.915,20.0008774,-48879.697265625,9.40661427840325E-5,6.6826445931883E-7,1,0.999253354069792,40.0298881530762,1.98387924486313,16.2400007247925,0.00105268012320798,0.0002003672436919,0.25,9.24421063947961E-7,9.39459468750682E-5,1.61572147586455E-6,20.0008774,20.0008774,-48885.265625,-48874.12890625,57.217552493256,20.6576949916186,13.797379,0,0,0,40,4449,19.9915,-48879.697265625,,,,,,,,,,,,,0,,,,0,,,,,,20.0008774,,,,
,30954816.705,20.0010738,-53766.82421875,0.000112237110859081,7.85138119014045E-7,1,0.999253354069792,40.0298881530762,1.98399590203797,16.2400007247925,0.00125567102070549,0.000245000298534091,0.25,1.61379696843317E-6,0.000112144882380551,2.44521755948109E-6,20.0010738,20.0010738,-53771.828125,-53761.8203125,57.1784710672945,20.6549494835809,13.797379,0,0,0,40,4449,19.991,-53766.82421875,,,,,,,,,,,,,0,,,,0.0049,,,,,,20.0010738,,,,
,30954912.49,20.0010681,-58553.744140625,0.000131672095037081,5.96444526519663E-7,1,0.999253354069792,40.0298881530762,1.98379602543369,16.2400007247925,0.00147245040675075,0.000294153336612012,0.25,2.48080744290554E-6,0.000131620502829825,3.46007183122862E-6,20.0010681,20.0010681,-58563.9765625,-58543.51171875,57.1808159528522,20.6587078949511,13.417728,0,0,0,40,4449,19.99025,-58553.744140625,,,,,,,,,,,,,0,,,,0.0049,,,,,,20.0010681,,,,
,30955009.565,20.0007362,-63406.951171875,0.000149987554991936,9.05639369392208E-7,1,0.999253354069792,40.0298881530762,1.983711289935,16.2400007247925,0.00168187651059006,0.00031344519731303,0.25,8.884362222746E-7,0.000150010756742361,2.00413153219075E-6,20.0007362,20.0007362,-63417.0234375,-63396.87890625,57.3058765159291,20.6578772864021,13.797379,0,0,0,40,4449,19.9896,-63406.951171875,,,,,,,,,,,,,0,,,,0,,,,,,20.0007362,,,,
,30955106.92,20.0017681,-68271.71484375,0.000169807210449251,8.32073879129218E-7,1,0.999253354069792,40.0298881530762,1.98362561619371,16.2400007247925,0.00190775180377463,0.000338971952859734,0.25,-4.16049548288835E-7,0.000169917058133644,8.41556804068794E-7,20.0017681,20.0017681,-68279.3671875,-68264.0625,57.3488660844868,20.6601369102261,13.417728,0,0,0,40,4449,19.9882,-68271.71484375,,,,,,,,,,,,,0,,,,0,,,,,,20.0017681,,,,
,30955204.695,20.0019035,-73155.90625,0.000190377940060466,6.82446317802142E-7,1,0.999253354069792,40.0298881530762,1.98359845171628,16.2400007247925,0.00213491322074234,0.000406786570029562,0.25,1.91176322284135E-6,0.00019056146713177,3.31414342516471E-6,20.0019035,20.0019035,-73160.7265625,-73151.0859375,57.2972786022176,20.6602616574678,13.797379,0,0,0,40,4449,19.9861,-73155.90625,,,,,,,,,,,,,0,,,,0.00245,,,,,,20.0019035,,,,
,30955302.015,20.0030746,-78023.0703125,0.000208243543825238,6.13997768076641E-7,1,0.999253354069792,40.0298881530762,1.98369968905664,16.2400007247925,0.00233932874324579,0.000428176033473167,0.25,5.95779926382257E-7,0.000208535461361288,2.11387665039078E-6,20.0030746,20.0030746,-78033.1171875,-78013.0234375,57.2621053188522,20.65890148077,14.177031,0,0,0,40,4449,19.9839,-78023.0703125,,,,,,,,,,,,,0,,,,0,,,,,,20.0030746,,,,
,30955400.905,20.0003757,-82965.0859375,0.000230326789081585,8.56093717125079E-7,1,0.999253354069792,40.0298881530762,1.98368300502529,16.2400007247925,0.00258510983478561,0.000491647440916057,0.25,2.27110026906153E-6,0.000230722719722904,3.93337530824767E-6,20.0003757,20.0003757,-82970.1640625,-82960.0078125,57.1526773261599,20.6564521359474,13.797379,0,0,0,40,4449,19.98195,-82965.0859375,,,,,,,,,,,,,0,,,,-0.00245,,,,,,20.0003757,,,,
,30955490.79,20.0011692,-87457.3046875,0.000251119080605375,8.37841318970083E-7,1,0.999253354069792,40.0298881530762,1.98375920594326,16.2400007247925,0.00281920692796729,0.000537638405929217,0.25,2.62550239417037E-6,0.00025162871534173,4.41637775031088E-6,20.0011692,20.0011692,-87467.328125,-87447.28125,57.6177462951023,20.6571365681629,13.417728,0,0,0,40,4449,19.98085,-87457.3046875,,,,,,,,,,,,,0,,,,-0.00245,,,,,,20.0011692,,,,
,30955596.06,20.0006189,-88195.49609375,0.000252268220803303,9.73601052725867E-7,1,0.999253354069792,40.0298881530762,1.98372021586204,16.2400007247925,0.00283280793395423,0.000536710524073717,0.25,2.3388323878546E-6,0.000252794904269221,4.13344999465172E-6,20.0006046,20.0006332,-88227.9140625,-88163.078125,57.190195495083,20.6588343264992,13.797379,0,0,0,40,4449,19.9807,-88195.49609375,,,,,,,,,,,,,0,,,,0.00245,,,,,,20.0006189,,,,
,30955685.575,20.0000305,-83720.671875,0.000233803432372792,8.11291874140901E-7,1,0.999253354069792,40.0298881530762,1.98371185402306,16.2400007247925,0.00262965886426394,0.00046937500133455,0.25,-3.34917636540328E-7,0.000234236991862476,1.34433217313621E-6,20.0000305,20.0000305,-83725.5234375,-83715.8203125,57.2581971762561,20.6562612708227,13.797379,0,0,0,40,4449,19.98035,-83720.671875,,,,,,,,,,,,,0,,,,-0.00245,,,,,,20.0000305,,,,
,30955779.93,19.999979,-79008.58203125,0.000214572309996154,7.75559833680892E-7,1,0.999253354069792,40.0298881530762,1.98366625249028,16.2400007247925,0.0024126143845865,0.000429836017435407,0.25,-3.94880814530433E-7,0.000214896560995625,1.16443222118004E-6,19.999979,19.999979,-79013.453125,-79003.7109375,57.2214606358522,20.6584579012053,14.177031,0,0,0,40,4449,19.9812,-79008.58203125,,,,,,,,,,,,,0,,,,0,,,,,,19.999979,,,,
,30955877.24,19.9989796,-74143.6953125,0.000194375387921154,9.24465327895545E-7,1,0.999253354069792,40.0298881530762,1.98406777405682,16.2400007247925,0.00218601230072898,0.000384342811459471,0.25,-8.14015899941342E-7,0.000194598641176813,6.12384456902311E-7,19.9989796,19.9989796,-74151.2265625,-74136.1640625,57.4575124486599,20.6538286123649,13.797379,0,0,0,40,4449,19.9824,-74143.6953125,,,,,,,,,,,,,0,,,,-0.0049,,,,,,19.9989796,,,,
,30955972.01,19.9986305,-69406.6796875,0.000174091037447146,6.40763220122144E-7,1,0.999253354069792,40.0298881530762,1.98366101579374,16.2400007247925,0.00195525429213664,0.000352271151074753,0.25,-5.44236132429489E-9,0.000174217438738634,1.28237924649936E-6,19.9986305,19.9986305,-69414.1171875,-69399.2421875,57.068261446083,20.6577053684569,13.797379,0,0,0,40,4449,19.98275,-69406.6796875,,,,,,,,,,,,,0,,,,-0.0049,,,,,,19.9986305,,,,
,30956067.95,19.997818,-64611.986328125,0.000155484872111473,6.97338449548743E-7,1,0.999253354069792,40.0298881530762,1.98360852944185,16.2400007247925,0.00174651026300961,0.000308934854157584,0.25,-5.0491451988327E-7,0.000155536402217544,6.50532848556286E-7,19.997818,19.997818,-64617.08984375,-64606.8828125,57.3590272552368,20.6586523112611,13.797379,0,0,0,40,4449,19.985,-64611.986328125,,,,,,,,,,,,,0,,,,0,,,,,,19.997818,,,,
,30956166.68,19.9983177,-59679.814453125,0.000135514549333164,5.63427826049245E-7,1,0.999253354069792,40.0298881530762,1.983653660432,16.2400007247925,0.0015205538607037,0.000274581582934466,0.25,4.2953882436603E-8,0.000135494536596622,1.05162116597718E-6,19.9983177,19.9983177,-59684.6796875,-59674.94921875,56.9564885678329,20.6555996621866,13.797379,0,0,0,40,4449,19.9865,-59679.814453125,,,,,,,,,,,,,0,,,,-0.00245,,,,,,19.9983177,,,,
,30956266.94,19.9990826,-54667.78515625,0.00011495166267002,6.12320206989036E-7,1,0.999253354069792,40.0298881530762,1.98349323614381,16.2400007247925,0.00128886806507676,0.000234104373066214,0.25,1.55645910411789E-7,0.000114878489094087,1.00904191381624E-6,19.9990826,19.9990826,-54672.421875,-54663.1484375,57.5012836457369,20.656417408601,13.797379,0,0,0,40,4449,19.988,-54667.78515625,,,,,,,,,,,,,0,,,,-0.00245,,,,,,19.9990826,,,,
,30956362.375,19.9999657,-49898.43359375,9.81812971742711E-5,7.54076228142736E-7,1,0.999253354069792,40.0298881530762,1.98382657754288,16.2400007247925,0.00109992191346911,0.000203023366479831,0.25,4.17101681006828E-7,9.80700266171125E-5,1.14080021884505E-6,19.9999657,19.9999657,-49905.7109375,-49891.15625,57.0893654161022,20.6528596821863,13.797379,0,0,0,40,4449,19.9881,-49898.43359375,,,,,,,,,,,,,0,,,,0,,,,,,19.9999657,,,,
,30956460.21,19.9999599,-45008.5625,7.96166758618499E-5,5.5621587000083E-7,1,0.999253354069792,40.0298881530762,1.98385498028037,16.2400007247925,0.000892575817543366,0.000158618416647042,0.25,-1.84904013643941E-7,7.94903185925168E-5,3.95795619126991E-7,19.9999599,19.9999599,-45018.62890625,-44998.49609375,57.2417829773522,20.6514632484068,13.797379,0,0,0,40,4449,19.98805,-45008.5625,,,,,,,,,,,,,0,,,,0,,,,,,19.9999599,,,,
,30956557.265,19.999424,-40158.287109375,6.00507294929157E-5,4.50606517331303E-7,1,0.999253354069792,40.0298881530762,1.98346456078581,16.2400007247925,0.000672658913070734,0.000120080604291291,0.25,-8.52368358994964E-8,5.99244985401927E-5,3.45289146472966E-7,19.999424,19.999424,-40165.703125,-40150.87109375,57.1135959001984,20.6575098874275,13.417728,0,0,0,40,4449,19.9887,-40158.287109375,,,,,,,,,,,,,0,,,,0,,,,,,19.999424,,,,
,30956655.035,19.9990654,-35271.09375,4.28757126050124E-5,5.51964702173267E-7,1,0.999253354069792,40.0298881530762,1.98390485966033,16.2400007247925,0.00048262261124057,7.18202609363299E-5,0.25,-1.29455705304569E-6,4.27720393360788E-5,-9.90996509734445E-7,19.9990654,19.9990654,-35278.5078125,-35263.6796875,57.3074397729676,20.6527764808836,13.417728,0,0,0,40,4449,19.9904,-35271.09375,,,,,,,,,,,,,0,,,,0.00245,,,,,,19.9990654,,,,
,30956749.65,19.9985523,-30541.203125,2.57004476004228E-5,4.84003805690037E-7,1,0.999253354069792,40.0298881530762,1.98337153541599,16.2400007247925,0.000287395305826295,5.23482139681644E-5,0.25,6.31607906920739E-8,2.56196117222588E-5,2.37715563447607E-7,19.9985523,19.9985523,-30546.2265625,-30536.1796875,57.4254656793715,20.6586794850042,13.417728,0,0,0,40,4449,19.99165,-30541.203125,,,,,,,,,,,,,0,,,,-0.0049,,,,,,19.9985523,,,,
,30956847.745,19.9985504,-25638.7900390625,7.59804630124784E-6,3.66242355934423E-7,1,0.999253354069792,40.0298881530762,1.98360397615084,16.2400007247925,8.63235246673381E-5,7.70705357843016E-6,0.25,-6.73588209484285E-7,7.57482035052283E-6,-6.2137601928002E-7,19.9985504,19.9985504,-25644.03515625,-25633.544921875,57.1776894387753,20.6526613840484,13.797379,0,0,0,40,4449,19.9931,-25638.7900390625,,,,,,,,,,,,,0,,,,-0.0049,,,,,,19.9985504,,,,
,30956943.855,19.9986057,-20836.9326171875,-1.0390005453213E-5,4.75662198487126E-7,1,0.999253354069792,40.0298881530762,1.98369428620536,16.2400007247925,-0.000114527428868188,-2.98637391810746E-5,0.25,-8.10936972126961E-7,-1.03421246807368E-5,-8.72691536509009E-7,19.9986057,19.9986057,-20841.990234375,-20831.875,57.3238539718714,20.6513911854367,14.177031,0,0,0,40,4449,19.9941,-20836.9326171875,,,,,,,,,,,,,0,,,,0.0049,,,,,,19.9986057,,,,
,30957036.835,19.9994698,-16189.7260742187,-2.80180322875425E-5,3.75484244087424E-7,1,0.999253354069792,40.0298881530762,1.98376610712246,16.2400007247925,-0.000312845215844802,-5.74144757303882E-5,0.25,-1.29584176713526E-7,-2.7889445351739E-5,-2.95928570861721E-7,19.9994698,19.9994698,-16199.9736328125,-16179.478515625,57.2472543769868,20.6501880677349,13.417728,0,0,0,40,4449,19.9965,-16189.7260742187,,,,,,,,,,,,,0,,,,0,,,,,,19.9994698,,,,
,30957133.735,19.9977016,-11347.1450195312,-4.41644040128075E-5,2.97630402781157E-7,1,0.999253354069792,40.0298881530762,1.98362255544381,16.2400007247925,-0.000492478866621354,-9.27479477700044E-5,0.25,-4.24586163358079E-7,-4.39417075713974E-5,-6.70383214635741E-7,19.9977016,19.9977016,-11351.779296875,-11342.5107421875,57.1651833824676,20.6522107229958,13.797379,0,0,0,40,4449,19.99775,-11347.1450195312,,,,,,,,,,,,,0,,,,-0.0049,,,,,,19.9977016,,,,
,30957228.475,19.9990044,-6611.29248046875,-5.92389112051279E-5,3.60965837144602E-7,1,0.999253354069792,40.0298881530762,1.98372288997114,16.2400007247925,-0.000660000325955828,-0.000126393423907975,0.25,-7.71660640575546E-7,-5.89173226497492E-5,-1.07952961789848E-6,19.9990044,19.9990044,-6613.77392578125,-6608.81103515625,57.1769078102561,20.6458015921065,14.177031,0,0,0,40,4449,19.9989,-6611.29248046875,,,,,,,,,,,,,0,,,,0,,,,,,19.9990044,,,,
,30957322.37,19.9994221,-1917.59301757813,-7.46018842373896E-5,3.39316793477059E-7,1,0.999253354069792,40.0298881530762,1.98356749803029,16.2400007247925,-0.000831687311289886,-0.000154402942154933,0.25,-5.73984016453252E-7,-7.41765179259223E-5,-9.39640358199783E-7,19.9994221,19.9994221,-1930.20251464844,-1904.98352050781,57.3176009437176,20.6542103487289,13.797379,0,0,0,40,4449,20.0002,-1917.59301757813,,,,,,,,,,,,,0,,,,0,,,,,,19.9994221,,,,
,30957417.805,20.0000896,2847.61450195313,-8.62219814461407E-5,3.29911600137255E-7,1,0.999253354069792,40.0298881530762,1.98337906097014,16.2400007247925,-0.000960815897062415,-0.000180584808836925,0.25,-8.4986095724605E-7,-8.57339637772279E-5,-1.27655564522876E-6,20.0000896,20.0000896,2842.63818359375,2852.5908203125,57.2198973788137,20.6586508816002,13.797379,0,0,0,40,4449,19.9997,2847.61450195313,,,,,,,,,,,,,0,,,,-0.00245,,,,,,20.0000896,,,,
,30957514.37,19.9990711,7677.34130859375,-9.74192229573564E-5,3.11456294019882E-7,1,0.999253354069792,40.0298881530762,1.9834527639353,16.2400007247925,-0.00108575925438739,-0.000205402396561771,0.25,-1.04268244511475E-6,-9.68991719993366E-5,-1.55784367633819E-6,19.9990711,19.9990711,7672.27099609375,7682.41162109375,57.1761261817368,20.656479106879,13.797379,0,0,0,40,4449,20.001,7677.34130859375,,,,,,,,,,,,,0,,,,-0.0049,,,,,,19.9990711,,,,
,30957611.045,20.0006828,12510.5434570312,-0.000102256197841875,3.79084872655878E-7,1,0.999253354069792,40.0298881530762,1.98350132681837,16.2400007247925,-0.00114046598475803,-0.000213872068657599,0.25,-8.95582573838295E-7,-0.000101751089028313,-1.47385369522928E-6,20.0006828,20.0006828,12500.4541015625,12520.6328125,57.241001348833,20.6539427861508,14.177031,0,0,0,40,4449,20.0004,12510.5434570312,,,,,,,,,,,,,0,,,,-0.00245,,,,,,20.0006828,,,,
,30957707.675,20.0017033,17337.9140625,-9.53628191888128E-5,4.62725075196318E-7,1,0.999253354069792,40.0298881530762,1.98371145687128,16.2400007247925,-0.0010634779155297,-0.000203348570271144,0.25,-1.14187205242341E-6,-9.49310698573568E-5,-1.7124515199963E-6,20.0017033,20.0017033,17332.767578125,17343.060546875,57.2832092888714,20.6505787399086,14.177031,0,0,0,40,4449,19.9983,17337.9140625,,,,,,,,,,,,,0,,,,0,,,,,,20.0017033,,,,
,30957802.92,20.0015755,22097.568359375,-7.60092651200381E-5,4.42114523714948E-7,1,0.999253354069792,40.0298881530762,1.98398232613596,16.2400007247925,-0.000850066991926155,-0.000151473681022313,0.25,7.01308982352363E-8,-7.57060643154729E-5,-4.12299984616911E-7,20.0015755,20.0015755,22095.015625,22100.12109375,57.0971817012945,20.6452503263005,13.797379,0,0,0,40,4449,19.99725,22097.568359375,,,,,,,,,,,,,0,,,,-0.0049,,,,,,20.0015755,,,,
,30957893.865,20.0016594,26645.5107421875,-5.88812628325299E-5,4.56533168548769E-7,1,0.999253354069792,40.0298881530762,1.98388293651441,16.2400007247925,-0.000656303023363753,-0.000131231851043576,0.25,-1.16791648448406E-6,-5.86654618590163E-5,-1.5526489646101E-6,20.0016594,20.0016594,26643.1328125,26647.888671875,57.0643533034868,20.6509013942916,13.797379,0,0,0,40,4449,19.9954,26645.5107421875,,,,,,,,,,,,,0,,,,0,,,,,,20.0016594,,,,
,30957989.805,20.00169755,31438.81640625,-5.33470152867956E-5,5.66178032902955E-7,1,0.999253354069792,40.0298881530762,1.98355125625498,16.2400007247925,-0.000595416474427217,-0.000115609382704286,0.25,-7.48202851934979E-7,-5.31800296761794E-5,-1.11087086899698E-6,20.0015965,20.0017986,31431.220703125,31446.412109375,57.1409528983714,20.6513255167382,14.177031,0,0,0,40,4449,19.99365,31438.81640625,,,,,,,,,,,,,0,,,,0,,,,,,20.00169755,,,,
,30958086.75,20.0016785,36283.962890625,-5.71088521995738E-5,5.24666081459672E-7,1,0.999253354069792,40.0298881530762,1.98370687938148,16.2400007247925,-0.000637518178894153,-0.000125276035032292,0.25,-9.18613754021974E-7,-5.69583543556888E-5,-1.31825558907239E-6,20.0016785,20.0016785,36274.078125,36293.84765625,57.3856026248907,20.6465663856991,13.797379,0,0,0,40,4449,19.99155,36283.962890625,,,,,,,,,,,,,0,,,,0,,,,,,20.0016785,,,,
,30958183.77,20.0016422,41134.01171875,-6.89887139877587E-5,5.70560185960846E-7,1,0.999253354069792,40.0298881530762,1.98346311707729,16.2400007247925,-0.000770573933639434,-0.000150651455733094,0.25,-1.0326969154582E-6,-6.88426593201352E-5,-1.52695826230566E-6,20.0016422,20.0016422,41126.4140625,41141.609375,57.2574155477368,20.6538068324957,13.797379,0,0,0,40,4449,19.9911,41134.01171875,,,,,,,,,,,,,0,,,,0,,,,,,20.0016422,,,,
,30958279.54,20.0017776,45919.296875,-8.4946057357179E-5,5.24998800251433E-7,1,0.999253354069792,40.0298881530762,1.98331518468641,16.2400007247925,-0.000949697797363356,-0.000182909517311445,0.25,-1.024044605542E-6,-8.48103421752865E-5,-1.64335370118746E-6,20.0017776,20.0017776,45914.3671875,45924.2265625,57.2722664896022,20.6540100162844,13.417728,0,0,0,40,4449,19.98955,45919.296875,,,,,,,,,,,,,0,,,,-0.0049,,,,,,20.0017776,,,,
,30958377.16,20.0013695,50799.32421875,-0.000103856770363589,6.61557939478223E-7,1,0.999253354069792,40.0298881530762,1.98328901704903,16.2400007247925,-0.00116096260426955,-0.000227743653256189,0.25,-1.60158613898291E-6,-0.000103739941478065,-2.36721011288252E-6,20.0013695,20.0013695,50791.90234375,50806.74609375,57.1573670972753,20.6512623370245,13.797379,0,0,0,40,4449,19.9893,50799.32421875,,,,,,,,,,,,,0,,,,0,,,,,,20.0013695,,,,
,30958471.825,20.0005989,55529.201171875,-0.000119336267032802,7.40698870471171E-7,1,0.999253354069792,40.0298881530762,1.98321917885215,16.2400007247925,-0.00133666077630572,-0.000250260665177276,0.25,-8.06460546383921E-7,-0.000119265549998386,-1.69272585726582E-6,20.0005989,20.0005989,55519.46484375,55538.9375,57.4293738219676,20.6544924194482,13.797379,0,0,0,40,4449,19.98875,55529.201171875,,,,,,,,,,,,,0,,,,-0.00245,,,,,,20.0005989,,,,
,30958569.02,20.0009575,60389.31640625,-0.000138158342165359,6.50111755232494E-7,1,0.999253354069792,40.0298881530762,1.98330891738255,16.2400007247925,-0.0015471717711772,-0.000295958303523808,0.25,-1.47410745092517E-6,-0.000138136471601876,-2.50235765303629E-6,20.0009575,20.0009575,60381.8515625,60396.78125,57.1644017539484,20.6533734736533,14.177031,0,0,0,40,4449,19.98795,60389.31640625,,,,,,,,,,,,,0,,,,0,,,,,,20.0009575,,,,
,30958667.515,20.0004063,65312.71875,-0.000158920703878754,8.57925540192651E-7,1,0.999253354069792,40.0298881530762,1.98316936141171,16.2400007247925,-0.00178218462691168,-0.00033043495235588,0.25,-7.96054896983283E-7,-0.000158973559692898,-1.97690072167482E-6,20.0004063,20.0004063,65310.00390625,65315.43359375,56.997133250833,20.6583972978634,13.417728,0,0,0,40,4449,19.9866,65312.71875,,,,,,,,,,,,,0,,,,0.0049,,,,,,20.0004063,,,,
,30958765.825,20.0015411,70225.1875,-0.00017835494395987,7.12233197566835E-7,1,0.999253354069792,40.0298881530762,1.98321985871618,16.2400007247925,-0.00200289648977476,-0.000360623309764055,0.25,2.40019019056734E-8,-0.000178496934578777,-1.29390741045125E-6,20.0015411,20.0015411,70217.5625,70232.8125,57.1964485232368,20.6531287352201,14.177031,0,0,0,40,4449,19.98525,70225.1875,,,,,,,,,,,,,0,,,,0,,,,,,20.0015411,,,,
,30958861.08,20.0015945,74985.421875,-0.000197005970094566,8.0630087242617E-7,1,0.999253354069792,40.0298881530762,1.98320895426719,16.2400007247925,-0.00221363501150781,-0.00039603986480877,0.25,2.32458221827424E-7,-0.00019724116592281,-1.21162770148132E-6,20.0015945,20.0015945,74975.53125,74995.3125,57.2136443506599,20.6557005886792,13.797379,0,0,0,40,4449,19.9842,74985.421875,,,,,,,,,,,,,0,,,,-0.00245,,,,,,20.0015945,,,,
,30958956.415,20.0030613,79753.7578125,-0.000214872178662875,8.12441294244684E-7,1,0.999253354069792,40.0298881530762,1.98373961962274,16.2400007247925,-0.0024151282023766,-0.00043646584302337,0.25,-1.40200904754661E-7,-0.000215205061512886,-1.69980004888526E-6,20.0030613,20.0030613,79748.7890625,79758.7265625,57.1604936113522,20.644388781313,13.797379,0,0,0,40,4449,19.98245,79753.7578125,,,,,,,,,,,,,0,,,,-0.0049,,,,,,20.0030613,,,,
,30959052.72,20.0012836,84567.30859375,-0.000234105143063814,9.76454215644396E-7,1,0.999253354069792,40.0298881530762,1.98368966379311,16.2400007247925,-0.00262983139203334,-0.000488619902870496,0.25,-1.32411256987565E-6,-0.000234541404294825,-3.00480497140357E-6,20.0012836,20.0012836,84557.1953125,84577.421875,57.085457273506,20.6426879554211,13.797379,0,0,0,40,4449,19.98135,84567.30859375,,,,,,,,,,,,,0,,,,0,,,,,,20.0012836,,,,
,30959139.23,20.0016441,88890.375,-0.000255425714007645,9.22672556473244E-7,1,0.999253354069792,40.0298881530762,1.98382050760428,16.2400007247925,-0.00287303098334098,-0.000518487531183508,0.25,-1.50311230217706E-7,-0.000255986572994233,-1.95881426624649E-6,20.0016441,20.0016441,88880.5078125,88900.2421875,57.095618444256,20.640081492278,14.177031,0,0,0,40,4449,19.9794,88890.375,,,,,,,,,,,,,0,,,,-0.00245,,,,,,20.0016441,,,,
,30959245.49,20.000248,86828.37109375,-0.000245809480458411,8.13016844756183E-7,1,0.999253354069792,40.0298881530762,1.98345551298204,16.2400007247925,-0.00276230613239389,-0.000508220782418408,0.25,-9.7046913336097E-7,-0.000246309176204429,-2.72329998559954E-6,20.000248,20.000248,86818.5625,86838.1796875,57.1034347294484,20.6504414101874,13.417728,0,0,0,40,4449,19.97905,86828.37109375,,,,,,,,,,,,,0,,,,0.00245,,,,,,20.000248,,,,
,30959338.52,19.9991913,82179.91796875,-0.000224418314091199,8.75541441345146E-7,1,0.999253354069792,40.0298881530762,1.98349342616021,16.2400007247925,-0.00252353115170133,-0.000450582020851354,0.25,3.15239432557644E-7,-0.000224809545201166,-1.30318060326983E-6,19.9991913,19.9991913,82174.984375,82184.8515625,57.2628869473714,20.6531713669098,13.797379,0,0,0,40,4449,19.9802,82179.91796875,,,,,,,,,,,,,0,,,,0.00245,,,,,,19.9991913,,,,
,30959435.645,19.9994392,77323.91796875,-0.000206779781831691,7.40814661118872E-7,1,0.999253354069792,40.0298881530762,1.98357288330469,16.2400007247925,-0.00232473350972884,-0.000413374648740608,0.25,4.55689549579724E-7,-0.000207066144571331,-1.05255704419655E-6,19.9994392,19.9994392,77321.375,77326.4609375,57.1409528983714,20.6490091433063,13.417728,0,0,0,40,4449,19.98135,77323.91796875,,,,,,,,,,,,,0,,,,0,,,,,,19.9994392,,,,
,30959535.59,19.9983025,72327.734375,-0.000185012019772622,7.46825918634703E-7,1,0.999253354069792,40.0298881530762,1.98331619018868,16.2400007247925,-0.00207961993630933,-0.000365805749717471,0.25,7.64688666241831E-7,-0.00018519713459323,-5.97376078627493E-7,19.9983025,19.9983025,72322.6171875,72332.8515625,57.004167907506,20.6522417005924,13.797379,0,0,0,40,4449,19.9826,72327.734375,,,,,,,,,,,,,0,,,,0,,,,,,19.9983025,,,,
,30959633.19,19.9988422,67449.89453125,-0.00016510315832286,7.4334860242719E-7,1,0.999253354069792,40.0298881530762,1.98335754359432,16.2400007247925,-0.00184822155246648,-0.000364528786747308,0.25,-2.71277709376835E-6,-0.000165175111511749,-3.93841096978844E-6,19.9988422,19.9988422,67440.1484375,67459.640625,57.1221938139099,20.6516129348465,13.417728,0,0,0,40,4449,19.9836,67449.89453125,,,,,,,,,,,,,0,,,,0,,,,,,19.9988422,,,,
,30959732.49,19.9981556,62484.408203125,-0.000145793932621364,6.55667607962323E-7,1,0.999253354069792,40.0298881530762,1.98311070218267,16.2400007247925,-0.00163351523246735,-0.00030859645239977,0.25,-1.22211788295893E-6,-0.000145801563203908,-2.30701065233525E-6,19.9981556,19.9981556,62472.078125,62496.73828125,57.129228470583,20.6594669580555,13.797379,0,0,0,40,4449,19.9854,62484.408203125,,,,,,,,,,,,,0,,,,-0.00245,,,,,,19.9981556,,,,
,30959834.745,19.9975376,57373.37109375,-0.000126108853448135,7.99958108498504E-7,1,0.999253354069792,40.0298881530762,1.98341183191121,16.2400007247925,-0.00141386995363888,-0.000259165147141,0.25,-3.72609190472378E-7,-0.000126060150657103,-1.31056491847586E-6,19.9975376,19.9975376,57368.33203125,57378.41015625,57.2120810936214,20.6519658092114,14.177031,0,0,0,40,4449,19.9873,57373.37109375,,,,,,,,,,,,,0,,,,0,,,,,,19.9975376,,,,
,30959933.51,19.995018,52435.828125,-0.000106224800033145,6.65150660847726E-7,1,0.999253354069792,40.0298881530762,1.98319883544854,16.2400007247925,-0.00118830277548515,-0.000228935536613967,0.25,-1.27690505419494E-6,-0.000106125362375222,-2.06251059778511E-6,19.995018,19.995018,52430.8203125,52440.8359375,57.1331366131791,20.6554132884536,14.177031,0,0,0,40,4449,19.98465,52435.828125,,,,,,,,,,,,,0,,,,0,,,,,,19.995018,,,,
,30960030.965,19.9978065,47565.982421875,-8.68419294297208E-5,5.68807607704736E-7,1,0.999253354069792,40.0298881530762,1.98329954044069,16.2400007247925,-0.000972758899999638,-0.000177543378674511,0.25,-1.98481781031975E-7,-8.67241201166608E-5,-8.3559232964596E-7,19.9978065,19.9978065,47553.62890625,47578.3359375,57.1253203279868,20.6533578109002,13.797379,0,0,0,40,4449,19.98935,47565.982421875,,,,,,,,,,,,,0,,,,-0.0049,,,,,,19.9978065,,,,
,30960128.71,19.9975262,42680.740234375,-6.79934922820967E-5,5.5175211553291E-7,1,0.999253354069792,40.0298881530762,1.98355016113502,16.2400007247925,-0.00075887962313852,-0.000152581780569763,0.25,-1.37869365277293E-6,-6.78579408728195E-5,-1.86812256838129E-6,19.9975262,19.9975262,42675.890625,42685.58984375,57.0776409883137,20.6510853682529,14.177031,0,0,0,40,4449,19.9923,42680.740234375,,,,,,,,,,,,,0,,,,0.00245,,,,,,19.9975262,,,,
,30960227.75,19.9979,37731.021484375,-4.95669466473536E-5,6.39609675966262E-7,1,0.999253354069792,40.0298881530762,1.98311747065918,16.2400007247925,-0.000551051015971119,-0.000120963014736528,0.25,-1.88874396170575E-6,-4.94361441854259E-5,-2.23566745160996E-6,19.9979,19.9979,37723.2578125,37738.78515625,57.2433462343907,20.6584822104734,13.797379,0,0,0,40,4449,19.99275,37731.021484375,,,,,,,,,,,,,0,,,,-0.00245,,,,,,19.9979,,,,
,30960331.16,19.9984322,32561.2900390625,-3.03230895044313E-5,5.93664930750958E-7,1,0.999253354069792,40.0298881530762,1.98321687855027,16.2400007247925,-0.000339008477333418,-6.24778553261425E-5,0.25,-1.34846150918594E-7,-3.02337415696399E-5,-3.43390647856936E-7,19.9984322,19.9984322,32551.3828125,32571.197265625,57.0909286731407,20.6561516510058,13.797379,0,0,0,40,4449,19.99485,32561.2900390625,,,,,,,,,,,,,0,,,,0,,,,,,19.9984322,,,,
,30960435.53,19.9982643,27346.8115234375,-1.14658400383362E-5,5.40453323084183E-7,1,0.999253354069792,40.0298881530762,1.98360415760276,16.2400007247925,-0.000127393215841289,-2.77794174012307E-5,0.25,-4.26057895443023E-7,-1.14233201828631E-5,-5.00730883231356E-7,19.9982643,19.9982643,27334.32421875,27359.298828125,57.3895107674868,20.6481351588673,14.177031,0,0,0,40,4449,19.9949,27346.8115234375,,,,,,,,,,,,,0,,,,0,,,,,,19.9982643,,,,
,30960539.78,19.9975796,22136.15625,8.46911563750467E-6,3.68993870433525E-7,1,0.999253354069792,40.0298881530762,1.98368892614214,16.2400007247925,9.47493923923715E-5,1.66178005090537E-5,0.25,-3.08569460387317E-8,8.43551135991343E-6,2.30084930422444E-8,19.9975796,19.9975796,22131.15234375,22141.16015625,57.3254172289099,20.6495159101039,14.177031,0,0,0,40,4449,19.9982,22136.15625,,,,,,,,,,,,,0,,,,0.0049,,,,,,19.9975796,,,,
,30960645.305,19.9975071,16861.677734375,2.63698476667517E-5,3.70437625955973E-7,1,0.999253354069792,40.0298881530762,1.98345997839266,16.2400007247925,0.000292571032908395,6.43562012595519E-5,0.25,1.04465420171291E-6,2.62449215760526E-5,1.19828544132762E-6,19.9975071,19.9975071,16859,16864.35546875,57.4903408464676,20.6547573562791,13.417728,0,0,0,40,4449,19.9997,16861.677734375,,,,,,,,,,,,,0,,,,0,,,,,,19.9975071,,,,
,30960752.805,19.9987202,11489.478515625,4.41565813387261E-5,3.86626491930584E-7,1,0.999253354069792,40.0298881530762,1.98351091887172,16.2400007247925,0.000492790464752542,9.03769020731366E-5,0.25,2.13593403532744E-7,4.39356362940458E-5,4.60862493146946E-7,19.9987202,19.9987202,11481.9775390625,11496.9794921875,57.1182856713137,20.6535844221178,13.797379,0,0,0,40,4449,20.0018,11489.478515625,,,,,,,,,,,,,0,,,,0,,,,,,19.9987202,,,,
,30960857.3,19.9974899,6267.25634765625,6.18068779749275E-5,7.69283357963333E-7,1,0.999253354069792,40.0298881530762,1.98357907209931,16.2400007247925,0.000689687116595837,0.000125450957761844,0.25,2.32668241561464E-7,6.14728422323179E-5,5.55412924769596E-7,19.9974899,19.9974899,6259.7421875,6274.7705078125,57.2667950899676,20.652559021937,14.177031,0,0,0,40,4449,20.0042,6267.25634765625,,,,,,,,,,,,,0,,,,0,,,,,,19.9974899,,,,
,30960953.07,20.0013027,1478.50427246094,7.68306219624001E-5,3.23720615102839E-7,1,0.999253354069792,40.0298881530762,1.98343526890943,16.2400007247925,0.000856783824398733,0.000157176727079629,0.25,4.29645199997647E-7,7.63915715774997E-5,8.05111880486636E-7,20.0013027,20.0013027,1465.91979980469,1491.08874511719,57.1214121853907,20.6554606910359,13.797379,0,0,0,40,4449,20.00375,1478.50427246094,,,,,,,,,,,,,0,,,,0,,,,,,20.0013027,,,,
,30960983.76,20.0030098,-0.220744714140892,8.06023693647626E-5,3.35662490386093E-7,1,0.999253354069792,40.0298881530762,1.98330355053234,16.2400007247925,0.000899442510377234,0.000160863848287846,0.25,9.75136321119565E-8,8.01384133463025E-5,4.8755133335742E-7,20.0030098,20.0030098,-0.228356599807739,-0.213132828474045,56.7180918694675,20.6596592439696,14.177031,0,0,0,40,4417,20.00285,-0.220744714140892,,,,,,,,,,,,,0,,,,0,,,,,,20.0030098,,,,