File: data/doubleLayers/dl_5/ppms/data/DD205_6_HYST_100OE_100K.DAT
[Header]
; VSM Data File (default extension .dat)
; Copyright (c) 2003-2013, Quantum Design, Inc. All rights reserved.
TITLE,
FILEOPENTIME,30974119.94,12/25/2018,7:57 pm
BYAPP,VSM,2.0,2.0
INFO,PPMS VSM Option Release 1.4.10 Build 1,APPNAME
INFO,Quantum Design Linear Motor Servo Controller,MOTOR_MODULE_NAME
INFO,3101-100 M1,MOTOR_HW_VERSION
INFO,MMC1014,MOTOR_SERIAL_NUMBER
INFO,SRV No X-over 01.03.11,MOTOR_SOFTWARE_VERSION
INFO,Quantum Design VSM Detection Module,VSM_MODULE_NAME
INFO,3101-150 F0,VSM_HW_VERSION
INFO,VSM707,VSM_SERIAL_NUMBER
INFO,VSM No X-over 01.02.05 May 20 2008 13:51:47,VSM_SOFTWARE_VERSION
INFO,704,PREAMP_SERIAL_NUMBER
INFO,822,COIL_SERIAL_NUMBER
INFO,0,MOMENT_UNITS
INFO,CoFe2O4,SAMPLE_MATERIAL
INFO,AH11 DL,SAMPLE_COMMENT
INFO,30.27,SAMPLE_MASS
INFO,,SAMPLE_VOLUME
INFO,,SAMPLE_MOLECULAR_WEIGHT
INFO,,SAMPLE_SIZE
INFO,,SAMPLE_SHAPE
DATATYPE,COMMENT,1
DATATYPE,TIME,2
STARTUPAXIS,X,2
STARTUPAXIS,Y1,5
[Data]
Comment,Time Stamp (sec),Temperature (K),Magnetic Field (Oe),Moment (emu),M. Std. Err. (emu),Transport Action,Averaging Time (sec),Frequency (Hz),Peak Amplitude (mm),Center Position (mm),Coil Signal' (mV),Coil Signal" (mV),Range (mV),M. Quad. Signal (emu),M. Raw' (emu),M. Raw" (emu),Min. Temperature (K),Max. Temperature (K),Min. Field (Oe),Max. Field (Oe),Mass (grams),Motor Lag (deg),Pressure (Torr),VSM Status (code),Motor Status (code),Measure Status (code),Measure Count,PPMS Status (code),System Temp. (K),System Field (Oe),Sample Position (deg),Bridge 1 Resistance (ohms),Bridge 1 Excitation (에),Bridge 2 Resistance (ohms),Bridge 2 Excitation (에),Bridge 3 Resistance (ohms),Bridge 3 Excitation (에),Bridge 4 Resistance (ohms),Bridge 4 Excitation (에),Signal 1 Vin (V),Signal 2 Vin (V),Digital Inputs (code),Drive 1 Iout (mA),Drive 1 Ipower (W),Drive 2 Iout (mA),Drive 2 Ipower (W),Pressure (),Map 20 (),Map 21 (),Map 22 (),Map 23 (),Map 24 (),Map 25 (),Map 26 (),Map 27 (),Map 28 (),Map 29 ()
,30974136.61,99.9905396,-0.152237743139267,,,2,,,,16.0399996358156,,,,,,,99.9905396,99.9905396,-0.152237743139267,-0.152237743139267,,,20.251448,,,,-99999999,4369,99.927,-0.152237743139267,,,,,,,,,,,,,,,,,,,,,,,99.9905396,,,,
,30974295.32,99.9940948,4281.39916992188,5.42505416290225E-5,4.17131198097607E-7,1,0.999253354069792,40.0298881530762,1.98428483184258,16.0199999809265,0.000615158924574246,9.49899103880241E-5,0.25,-1.1271981153395E-6,5.45593751827645E-5,-9.65160760620531E-7,99.9940948,99.9940948,4271.1669921875,4291.63134765625,56.2444249868136,20.6209044330673,20.251448,0,0,0,40,4449,99.9392,4281.39916992188,,,,,,,,,,,,,0,,,,0,,,,,,99.9940948,,,,
,30974374.145,99.9958725,8217.14794921875,4.30026766343789E-5,4.98992413814426E-7,1,0.999253354069792,40.0298881530762,1.98414055883724,16.0199999809265,0.000487250427443235,7.71970637239663E-5,0.25,-7.24239491843107E-7,4.3247174844525E-5,-5.95353164431604E-7,99.9958725,99.9958725,8207.08984375,8227.2060546875,56.5539498804291,20.6270642794882,20.631098,0,0,0,40,4449,99.94035,8217.14794921875,,,,,,,,,,,,,0,,,,0,,,,,,99.9958725,,,,
,30974446.43,99.9979172,11830.9340820312,3.28234441452547E-5,4.63996669077269E-7,1,0.999253354069792,40.0298881530762,1.98415039972279,16.0199999809265,0.000374031195348947,4.68891394579025E-5,0.25,-1.61771398853113E-6,3.30135152491903E-5,-1.52573049545576E-6,99.9979172,99.9979172,11825.875,11835.9931640625,56.7845302936022,20.6284543344665,20.251448,0,0,0,40,4449,99.94135,11830.9340820312,,,,,,,,,,,,,0,,,,-0.00245,,,,,,99.9979172,,,,
,30974515.695,100.0022507,15291.708984375,2.32259291022901E-5,7.34067143472476E-7,1,0.999253354069792,40.0298881530762,1.98390044014738,16.0199999809265,0.000265576395304386,2.78149715147452E-5,0.25,-1.61892639563817E-6,2.33619874793327E-5,-1.55679463138852E-6,100.0022507,100.0022507,15284.1982421875,15299.2197265625,56.607882248256,20.6331896650817,20.251448,0,0,0,40,4449,99.94015,15291.708984375,,,,,,,,,,,,,0,,,,0.0049,,,,,,100.0022507,,,,
,30974584.88,100.0048218,18750.0673828125,1.18998008195567E-5,9.57635964770673E-7,1,0.999253354069792,40.0298881530762,1.98389153312849,16.0199999809265,0.000138977140602324,-2.30539502528569E-6,0.25,-2.29498007247562E-6,1.19740436416829E-5,-2.27157356027815E-6,100.0048218,100.0048218,18737.607421875,18762.52734375,56.7931282073137,20.6351443307328,20.251448,0,0,0,40,4449,99.9347,18750.0673828125,,,,,,,,,,,,,0,,,,-0.00245,,,,,,100.0048218,,,,
,30974653.485,100.0065918,22177.8271484375,1.72318573812074E-7,7.34964791596404E-7,1,0.999253354069792,40.0298881530762,1.98392608298667,16.0199999809265,6.2465305928314E-6,-2.41318117053887E-5,0.25,-2.16650944269041E-6,1.79888630056215E-7,-2.17823637440666E-6,100.0065918,100.0065918,22175.26171875,22180.392578125,56.5250296252175,20.6331536117157,19.871798,0,0,0,40,4449,99.9279,22177.8271484375,,,,,,,,,,,,,0,,,,0.0049,,,,,,100.0065918,,,,
,30974719.18,100.0056305,25463.80859375,-1.08416107073204E-5,1.0802816823755E-6,1,0.999253354069792,40.0298881530762,1.98410420540569,16.0199999809265,-0.000116970626057543,-5.289441747683E-5,0.25,-2.77727554241172E-6,-1.08945577309074E-5,-2.82586974138387E-6,100.0056305,100.0056305,25458.853515625,25468.763671875,56.8157954343714,20.6325318498442,19.871798,0,0,0,40,4449,99.9255,25463.80859375,,,,,,,,,,,,,0,,,,0,,,,,,100.0056305,,,,
,30974785.805,100.0088654,28792.9111328125,-2.22280954144257E-5,1.34513575590823E-6,1,0.999253354069792,40.0298881530762,1.98397945869493,16.0199999809265,-0.000241842193140795,-9.68595236234785E-5,0.25,-4.66917763018261E-6,-2.23399369768541E-5,-4.76275713544674E-6,100.0088654,100.0088654,28782.90625,28802.916015625,57.1042163579676,20.6333199638883,20.251448,0,0,0,40,4449,99.9192,28792.9111328125,,,,,,,,,,,,,0,,,,-0.00245,,,,,,100.0088654,,,,
,30974851.365,100.0079803,32068.724609375,-3.74789149225415E-5,1.08129471670792E-6,1,0.999253354069792,40.0298881530762,1.98410127804374,16.0199999809265,-0.000416076583868318,-0.000116201128429213,0.25,-3.70197381939954E-6,-3.76803411132412E-5,-3.83567989211092E-6,100.0079803,100.0079803,32060.927734375,32076.521484375,56.8017261210252,20.6351109885281,20.251448,0,0,0,40,4449,99.9157,32068.724609375,,,,,,,,,,,,,0,,,,-0.00245,,,,,,100.0079803,,,,
,30974917.4,100.0096741,35369.853515625,-4.95091472117096E-5,1.5067404644831E-6,1,0.999253354069792,40.0298881530762,1.98399080337073,16.0199999809265,-0.000553644759929661,-0.000130499200685522,0.25,-2.85550940493039E-6,-4.97816526565153E-5,-3.01999395218112E-6,100.0096741,100.0096741,35365.01171875,35374.6953125,56.7579549239483,20.634092346109,20.251448,0,0,0,40,4449,99.9055,35369.853515625,,,,,,,,,,,,,0,,,,-0.00245,,,,,,100.0096741,,,,
,30974983.92,100.0112228,38692.337890625,-5.94215389440762E-5,1.33012948563673E-6,1,0.999253354069792,40.0298881530762,1.98402913736866,16.0199999809265,-0.000658038393619233,-0.000193468471954561,0.25,-6.6887038609621E-6,-5.97392556101716E-5,-6.90390837554797E-6,100.0112228,100.0112228,38687.49609375,38697.1796875,56.9478906541214,20.6336423831881,19.871798,0,0,0,40,4449,99.8996,38692.337890625,,,,,,,,,,,,,0,,,,-0.00245,,,,,,100.0112228,,,,
,30975050.395,100.0095863,42018.798828125,-7.33262920651182E-5,1.38009931683063E-6,1,0.999253354069792,40.0298881530762,1.98404605619481,16.0199999809265,-0.000818221695764044,-0.000203504990371285,0.25,-5.13567433381098E-6,-7.37281434811894E-5,-5.38258555319409E-6,100.0095062,100.0096664,42011.35546875,42026.2421875,56.8994296859291,20.6355846068041,19.871798,0,0,0,40,4449,99.896,42018.798828125,,,,,,,,,,,,,0,,,,0,,,,,,100.0095863,,,,
,30975119.445,100.0092926,45466.65625,-8.3094818111709E-5,2.21250932635729E-6,1,0.999253354069792,40.0298881530762,1.98392229260909,16.0199999809265,-0.000923723663210298,-0.000250265071133116,0.25,-7.56138968348615E-6,-8.35456344079194E-5,-7.85000333877485E-6,100.0092926,100.0092926,45459.09375,45474.21875,57.0690430746022,20.6338496470855,20.251448,0,0,0,40,4449,99.8932,45466.65625,,,,,,,,,,,,,0,,,,-0.00245,,,,,,100.0092926,,,,
,30975183.29,100.0106506,48657.34765625,-9.87920229256905E-5,1.26996058226632E-6,1,0.999253354069792,40.0298881530762,1.98395034719344,16.0199999809265,-0.00110656001483806,-0.000250184961968922,0.25,-4.79859412880656E-6,-9.93409717786401E-5,-5.11666672259469E-6,100.0106506,100.0106506,48652.15625,48662.5390625,56.9385111118906,20.6371147825616,20.631098,0,0,0,40,4449,99.8817,48657.34765625,,,,,,,,,,,,,0,,,,0,,,,,,100.0106506,,,,
,30975249.72,100.0082092,51981.345703125,-0.000113064981048737,1.90296917979276E-6,1,0.999253354069792,40.0298881530762,1.98392679654678,16.0199999809265,-0.00126658842665276,-0.000285390752251782,0.25,-5.41031979611323E-6,-0.000113694201115524,-5.7724127275623E-6,100.0082092,100.0082092,51976.265625,51986.42578125,56.9377294833714,20.6371354892363,20.631098,0,0,0,40,4449,99.8759,51981.345703125,,,,,,,,,,,,,0,,,,-0.0049,,,,,,100.0082092,,,,
,30975316.555,100.0096207,55319.333984375,-0.000125526090646032,1.42088429959008E-6,1,0.999253354069792,40.0298881530762,1.98413241678368,16.0199999809265,-0.00141013995185803,-0.000295174333212841,0.25,-4.08737750034666E-6,-0.000126231053438885,-4.4767632103556E-6,100.0096207,100.0096207,55314.20703125,55324.4609375,57.0659165605253,20.6351935516109,19.871798,0,0,0,40,4449,99.8715,55319.333984375,,,,,,,,,,,,,0,,,,-0.00245,,,,,,100.0096207,,,,
,30975384.86,100.0073853,58735.185546875,-0.000140197115760876,1.64645732622329E-6,1,0.999253354069792,40.0298881530762,1.98396775097628,16.0199999809265,-0.00157096940330886,-0.000351680124012814,0.25,-6.51707648999058E-6,-0.00014097969906945,-6.96122332051537E-6,100.0073853,100.0073853,58728.18359375,58742.1875,56.6758839294291,20.6389083498189,19.871798,0,0,0,40,4449,99.8669,58735.185546875,,,,,,,,,,,,,0,,,,-0.00245,,,,,,100.0073853,,,,
,30975451.5,100.0080261,62063.439453125,-0.000153922437802563,2.10037334032788E-6,1,0.999253354069792,40.0298881530762,1.98395685817227,16.0199999809265,-0.00173016331272832,-0.000355380654092599,0.25,-4.4371719677867E-6,-0.000154790450399724,-4.90723243862511E-6,100.0080261,100.0080261,62051.1875,62075.69140625,56.9306948266983,20.6373014802924,19.871798,0,0,0,40,4449,99.85955,62063.439453125,,,,,,,,,,,,,0,,,,-0.00245,,,,,,100.0080261,,,,
,30975519.125,100.009697,65444.935546875,-0.000161355049158402,2.39686253327988E-6,1,0.999253354069792,40.0298881530762,1.98379413717941,16.0199999809265,-0.00181132374542083,-0.000385359574125103,0.25,-5.79069977739249E-6,-0.000162262689285816,-6.28779855620563E-6,100.009697,100.009697,65434.8984375,65454.97265625,56.6625962446021,20.634386193698,19.871798,0,0,0,40,4449,99.8546,65444.935546875,,,,,,,,,,,,,0,,,,0,,,,,,100.009697,,,,
,30975586.375,100.0082474,68805.984375,-0.000179181009957273,2.13489192255913E-6,1,0.999253354069792,40.0298881530762,1.9839583643679,16.0199999809265,-0.0020238953260592,-0.00035793735241518,0.25,-2.34185071924939E-7,-0.000180207772770197,-7.48256097565731E-7,100.0082474,100.0082474,68803.53125,68808.4375,56.9603967104291,20.6382765307278,20.251448,0,0,0,40,4449,99.85055,68805.984375,,,,,,,,,,,,,0,,,,-0.0049,,,,,,100.0082474,,,,
,30975651.985,100.0087814,72084.375,-0.000194524559844705,1.78782535155598E-6,1,0.999253354069792,40.0298881530762,1.98395673080803,16.0199999809265,-0.00218557279986078,-0.000454928908627435,0.25,-6.1285995345553E-6,-0.000195623591337579,-6.7178222147311E-6,100.0087814,100.0087814,72071.7890625,72096.9609375,56.7759323798906,20.6343709086583,20.631098,0,0,0,40,4449,99.84515,72084.375,,,,,,,,,,,,,0,,,,-0.00245,,,,,,100.0087814,,,,
,30975717.44,100.0086517,75357.66015625,-0.000206241227808365,1.75998826062841E-6,1,0.999253354069792,40.0298881530762,1.98388438771875,16.0199999809265,-0.00231440620930034,-0.000497939570257605,0.25,-7.88334759328481E-6,-0.00020740374911809,-8.51331509872502E-6,100.0086517,100.0086517,75355.1953125,75360.125,56.8001628639868,20.6355439429365,20.631098,0,0,0,40,4449,99.84,75357.66015625,,,,,,,,,,,,,0,,,,0,,,,,,100.0086517,,,,
,30975796.47,100.0066376,79308.6875,-0.00022364542690759,2.40395371853669E-6,1,0.999253354069792,40.0298881530762,1.98400039696061,16.0199999809265,-0.00251620267668607,-0.00050391154956747,0.25,-5.35863051253403E-6,-0.000224916668017701,-6.0198713462955E-6,100.0066376,100.0066376,79303.6171875,79313.7578125,57.0831123879483,20.6336753387633,21.01075,0,0,0,40,4449,99.8347,79308.6875,,,,,,,,,,,,,0,,,,-0.0049,,,,,,100.0066376,,,,
,30975865.93,100.0058823,82780.24609375,-0.000236628741092352,2.4899674230214E-6,1,0.999253354069792,40.0298881530762,1.98394832680832,16.0199999809265,-0.00265934572292373,-0.000549568539753993,0.25,-7.12580588797733E-6,-0.000237971148706487,-7.83050354606098E-6,100.0058823,100.0058823,82767.8046875,82792.6875,56.6508718168137,20.6344199962947,20.251448,0,0,0,40,4449,99.8305,82780.24609375,,,,,,,,,,,,,0,,,,-0.00245,,,,,,100.0058823,,,,
,30975937.5,100.0057373,86358.99609375,-0.000252200439300666,1.74908296522452E-6,1,0.999253354069792,40.0298881530762,1.98411393964712,16.0199999809265,-0.00285418401561613,-0.000474104857173561,0.25,2.28547280288578E-6,-0.000253660350616369,1.59496030746801E-6,100.0057373,100.0057373,86356.453125,86361.5390625,56.8478422036599,20.6353981597644,20.251448,0,0,0,40,4449,99.825,86358.99609375,,,,,,,,,,,,,0,,,,-0.0049,,,,,,100.0057373,,,,
,30976032.34,100.0041046,89947.12109375,-0.000267261382221936,2.18743786144415E-6,1,0.999253354069792,40.0298881530762,1.98388968604427,16.0199999809265,-0.00300888848087734,-0.000590343938039475,0.25,-5.36896336545293E-6,-0.000268788418640611,-6.1417024858256E-6,100.0041046,100.0041046,89944.90625,89949.3359375,56.8353361473522,20.6350319805416,20.631098,0,0,0,40,4449,99.8248,89947.12109375,,,,,,,,,,,,,0,,,,-0.00245,,,,,,100.0041046,,,,
,30976114.555,100.0020218,85851.38671875,-0.000249355006905222,2.40539938851568E-6,1,0.999253354069792,40.0298881530762,1.98381155904133,16.0199999809265,-0.00280169978604137,-0.000581942078527838,0.25,-7.76454539680815E-6,-0.000250770261253137,-8.50557474671911E-6,100.0020218,100.0020218,85843.8515625,85858.921875,56.7939098358329,20.6354586113119,20.251448,0,0,0,40,4449,99.8233,85851.38671875,,,,,,,,,,,,,0,,,,-0.0049,,,,,,100.0020218,,,,
,30976212.77,99.9992065,80938.33203125,-0.000230387197353295,2.16469510607918E-6,1,0.999253354069792,40.0298881530762,1.98392855990598,16.0199999809265,-0.00259194561638324,-0.000519231028432927,0.25,-5.53450859067431E-6,-0.000231697388935076,-6.21431691837541E-6,99.9992065,99.9992065,80930.9140625,80945.75,57.0299616486406,20.6343498588786,20.631098,0,0,0,40,4449,99.8262,80938.33203125,,,,,,,,,,,,,0,,,,0,,,,,,99.9992065,,,,
,30976307.065,99.998642,76224.16796875,-0.000210974217815532,2.20187847484617E-6,1,0.999253354069792,40.0298881530762,1.98391711636015,16.0199999809265,-0.00237302031576966,-0.000478258487081038,0.25,-5.31063203856648E-6,-0.000212171539533672,-5.93862311297437E-6,99.998642,99.998642,76211.546875,76236.7890625,57.1167224142753,20.6367643675259,20.251448,0,0,0,40,4449,99.82585,76224.16796875,,,,,,,,,,,,,0,,,,-0.0049,,,,,,99.998642,,,,
,30976395.235,99.9970016,71818.1875,-0.000194390636130727,2.29404487177793E-6,1,0.999253354069792,40.0298881530762,1.98401690533842,16.0199999809265,-0.00218998527886791,-0.000421264391348008,0.25,-3.17094779809519E-6,-0.000195497201911013,-3.74320285686012E-6,99.9970016,99.9970016,71808.328125,71828.046875,56.9916618511983,20.6360745258984,20.251448,0,0,0,40,4449,99.8251,71818.1875,,,,,,,,,,,,,0,,,,0,,,,,,99.9970016,,,,
,30976499.415,99.9970779,66610.18359375,-0.000170857478777965,2.51662375974238E-6,1,0.999253354069792,40.0298881530762,1.98390775039623,16.0199999809265,-0.00191479521685426,-0.000426927452616384,0.25,-7.80089599931384E-6,-0.000171814110049361,-8.33621412380251E-6,99.9970779,99.9970779,66600.453125,66619.9140625,57.3543374841214,20.6382439750065,20.251448,0,0,0,40,4449,99.8305,66610.18359375,,,,,,,,,,,,,0,,,,0.00245,,,,,,99.9970779,,,,
,30976600.535,99.9957352,61554.287109375,-0.000154147230304895,2.01852322460748E-6,1,0.999253354069792,40.0298881530762,1.98404074726332,16.0199999809265,-0.00173495680045327,-0.000343387515210265,0.25,-3.33445585225856E-6,-0.000155019529186341,-3.79935927528548E-6,99.9957352,99.9957352,61546.73828125,61561.8359375,56.8267382336406,20.6375901631835,20.631098,0,0,0,40,4449,99.8341,61554.287109375,,,,,,,,,,,,,0,,,,0,,,,,,99.9957352,,,,
,30976704.145,99.9952011,56376.732421875,-0.000129294466143054,1.78322303538983E-6,1,0.999253354069792,40.0298881530762,1.98399963469586,16.0199999809265,-0.00144968513042518,-0.000319382034625642,0.25,-5.57047923865214E-6,-0.000130016832825139,-5.9789726154369E-6,99.9952011,99.9952011,56359.421875,56394.04296875,56.8439340610637,20.6375535745657,19.871798,0,0,0,40,4449,99.8389,56376.732421875,,,,,,,,,,,,,0,,,,0.0049,,,,,,99.9952011,,,,
,30976809.775,99.9932709,51096.8984375,-0.000108915368403149,1.37379303205555E-6,1,0.999253354069792,40.0298881530762,1.9841991938087,16.0199999809265,-0.00121905138015115,-0.000281839426459205,0.25,-5.82077551891131E-6,-0.000109519478447912,-6.17359565162395E-6,99.9932709,99.9932709,51086.87109375,51106.92578125,57.1018714724099,20.6357915968583,20.631098,0,0,0,40,4449,99.8457,51096.8984375,,,,,,,,,,,,,0,,,,-0.00245,,,,,,99.9932709,,,,
,30976910.81,99.9942017,46046.98828125,-9.83083221176249E-5,1.92609025279691E-6,1,0.999253354069792,40.0298881530762,1.98397306936583,16.0199999809265,-0.00110648355594615,-0.000218578560772808,0.25,-2.08452235077298E-6,-9.8861994599715E-5,-2.3868839789746E-6,99.9942017,99.9942017,46034.4765625,46059.5,57.3246356003907,20.6356922962485,20.631098,0,0,0,40,4449,99.85055,46046.98828125,,,,,,,,,,,,,0,,,,0.00245,,,,,,99.9942017,,,,
,30977010.83,99.9952316,41046.59375,-7.10786370079946E-5,1.4383210205875E-6,1,0.999253354069792,40.0298881530762,1.98401082125618,16.0199999809265,-0.000800992252217976,-0.000152469347358135,0.25,-1.01286103749777E-6,-7.14797767959175E-5,-1.2300624718028E-6,99.9952316,99.9952316,41036.6484375,41056.5390625,57.1182856713137,20.6383331840691,20.631098,0,0,0,40,4449,99.8565,41046.59375,,,,,,,,,,,,,0,,,,-0.00245,,,,,,99.9952316,,,,
,30977113.92,99.99338535,35896.775390625,-5.60541135852827E-5,1.52977249898051E-6,1,0.999253354069792,40.0298881530762,1.98387387104234,16.0199999809265,-0.000631702066935632,-0.000119832912590385,0.25,-7.62345725338286E-7,-5.63700582710261E-5,-9.34557025500432E-7,99.9932404,99.9935303,35884.203125,35909.34765625,56.9947883652753,20.6334086974445,20.251448,0,0,0,40,4449,99.8617,35896.775390625,,,,,,,,,,,,,0,,,,0,,,,,,99.99338535,,,,
,30977215.93,99.9927902,30796.9443359375,-3.75836075517908E-5,1.2742004359112E-6,1,0.999253354069792,40.0298881530762,1.98405690002644,16.0199999809265,-0.000427724577751346,-5.67719879110962E-5,0.25,1.57688330207735E-6,-3.78014052755329E-5,1.47252400225066E-6,99.9927902,99.9927902,30781.546875,30812.341796875,57.1198489283522,20.6354979474463,20.251448,0,0,0,40,4449,99.87075,30796.9443359375,,,,,,,,,,,,,0,,,,0,,,,,,99.9927902,,,,
,30977317.115,99.9919662,25739.4697265625,-1.58770650621991E-5,8.75165137827285E-7,1,0.999253354069792,40.0298881530762,1.98408345342941,16.0199999809265,-0.000177046355767753,-4.4732714345235E-5,0.25,-1.17021440095541E-6,-1.5963381044682E-5,-1.22500160726816E-6,99.9919662,99.9919662,25729.408203125,25749.53125,57.3254172289099,20.6361177737718,20.631098,0,0,0,40,4449,99.8792,25739.4697265625,,,,,,,,,,,,,0,,,,-0.00245,,,,,,99.9919662,,,,
,30977418.735,99.9916229,20661.9755859375,6.54813912602661E-6,7.96877394212115E-7,1,0.999253354069792,40.0298881530762,1.98417165720849,16.0199999809265,7.82474228014508E-5,-1.12949220741587E-5,0.25,-2.15028494182222E-6,6.59171075223356E-6,-2.14245276355536E-6,99.9916229,99.9916229,20652.126953125,20671.82421875,57.1980117802753,20.6424308113816,20.631098,0,0,0,40,4449,99.88785,20661.9755859375,,,,,,,,,,,,,0,,,,0,,,,,,99.9916229,,,,
,30977520.09,99.9903984,15594.8745117188,2.4277589998081E-5,6.42277851967565E-7,1,0.999253354069792,40.0298881530762,1.98418611828704,16.0199999809265,0.000276443799744829,3.58841114512137E-5,0.25,-1.08986320360919E-6,2.44179540787374E-5,-1.02148711712727E-6,99.9897079,99.9910889,15584.955078125,15604.7939453125,57.0393411908714,20.641478952157,20.251448,0,0,0,40,4449,99.8965,15594.8745117188,,,,,,,,,,,,,0,,,,-0.00245,,,,,,99.9903984,,,,
,30977619.95,99.9925842,10605.0478515625,4.03155895110784E-5,5.24461257643784E-7,1,0.999253354069792,40.0298881530762,1.98435054966796,16.0199999809265,0.000458346062505694,6.38746843106768E-5,0.25,-1.43160853549845E-6,4.05472379921056E-5,-1.31525284405642E-6,99.9925842,99.9925842,10592.4384765625,10617.6572265625,57.3090030300061,20.6384987712766,21.01075,0,0,0,40,4449,99.9057,10605.0478515625,,,,,,,,,,,,,0,,,,-0.00245,,,,,,99.9925842,,,,
,30977721.405,99.9938889,5532.71337890625,5.59040191966686E-5,3.96511640136988E-7,1,0.999253354069792,40.0298881530762,1.98410421691295,16.0199999809265,0.000632999204337188,0.000102737103195107,0.25,-7.3120776797023E-7,5.62209753057984E-5,-5.61911630158646E-7,99.9938889,99.9938889,5525.35693359375,5540.06982421875,57.0393411908714,20.640786251474,20.631098,0,0,0,40,4449,99.90735,5532.71337890625,,,,,,,,,,,,,0,,,,-0.00245,,,,,,99.9938889,,,,
,30977822.595,99.9932632,476.296234130859,6.79212624549233E-5,3.28257463231034E-7,1,0.999253354069792,40.0298881530762,1.98423402095828,16.0199999809265,0.000766701641562966,0.00013855333939593,0.25,3.25604433082227E-7,6.83022035243663E-5,5.38950003000636E-7,99.9932632,99.9932632,471.004119873047,481.588348388672,57.3316702570638,20.6415574662357,20.251448,0,0,0,40,4449,99.9182,476.296234130859,,,,,,,,,,,,,0,,,,0.0049,,,,,,99.9932632,,,,
,30977923.87,99.9982605,-4585.09741210937,6.92017747668083E-5,4.00407519470859E-7,1,0.999253354069792,40.0298881530762,1.98424121190162,16.0199999809265,0.000780575884179179,0.000144503776348623,0.25,6.27820922092301E-7,6.95892949935872E-5,8.46160814739413E-7,99.9982605,99.9982605,-4592.6142578125,-4577.58056640625,57.1128142716791,20.6454868626455,20.631098,0,0,0,40,4449,99.9185,-4585.09741210937,,,,,,,,,,,,,0,,,,0,,,,,,99.9982605,,,,
,30978026.84,100.002037,-9731.1142578125,5.45276696649823E-5,5.09856514326435E-7,1,0.999253354069792,40.0298881530762,1.98428090980221,16.0199999809265,0.000615605436690729,0.000110831496496019,0.25,2.27030779346561E-7,5.48342315895584E-5,3.96727623370707E-7,100.002037,100.002037,-9741.09765625,-9721.130859375,57.2277136640061,20.6458053576734,20.631098,0,0,0,40,4449,99.914,-9731.1142578125,,,,,,,,,,,,,0,,,,0,,,,,,100.002037,,,,
,30978129.055,100.0047226,-14838.599609375,2.87065111769566E-5,6.96874826971711E-7,1,0.999253354069792,40.0298881530762,1.98411403045005,16.0199999809265,0.000324297573764715,5.70296905990747E-5,0.25,3.67892479835458E-9,2.88684797713834E-5,9.18800136486426E-8,100.0047226,100.0047226,-14848.5849609375,-14828.6142578125,57.2597604332945,20.6407475561452,21.01075,0,0,0,40,4449,99.9085,-14838.599609375,,,,,,,,,,,,,0,,,,-0.00245,,,,,,100.0047226,,,,
,30978230.42,100.0084915,-19905.8017578125,1.18246857820749E-5,7.38339940113601E-7,1,0.999253354069792,40.0298881530762,1.98415844259148,16.0199999809265,0.000129225891910471,4.83150328125992E-5,0.25,2.19889937197067E-6,1.18847850672853E-5,2.24743936247517E-6,100.0084915,100.0084915,-19920.65625,-19890.947265625,57.0158923352945,20.6463193556153,20.631098,0,0,0,40,4449,99.89905,-19905.8017578125,,,,,,,,,,,,,0,,,,-0.00245,,,,,,100.0084915,,,,
,30978337.335,100.011055,-25247.732421875,1.82214791741898E-5,8.27581119945037E-7,1,0.999253354069792,40.0298881530762,1.9842335241689,16.0199999809265,0.000201444579785286,6.13536399652557E-5,0.25,2.2291472508516E-6,1.83178310432821E-5,2.29706267983262E-6,100.011055,100.011055,-25262.650390625,-25232.814453125,57.1276652135445,20.6458739769557,20.631098,0,0,0,40,4449,99.88865,-25247.732421875,,,,,,,,,,,,,0,,,,0,,,,,,100.011055,,,,
,30978442.905,100.0118065,-30524.7353515625,3.35815300232697E-5,9.22077323639157E-7,1,0.999253354069792,40.0298881530762,1.98413637161755,16.0199999809265,0.000373995811361918,9.73910588262249E-5,0.25,2.7212443372632E-6,3.37636578261207E-5,2.83792743689089E-6,100.0117798,100.0118332,-30529.62890625,-30519.841796875,57.1221938139099,20.6458384880133,20.631098,0,0,0,40,4449,99.8761,-30524.7353515625,,,,,,,,,,,,,0,,,,0,,,,,,100.0118065,,,,
,30978549.37,100.0121307,-35844.1796875,5.20365576899399E-5,1.33810173272763E-6,1,0.999253354069792,40.0298881530762,1.98422065141855,16.0199999809265,0.000581168043879352,0.000141755106325179,0.25,3.40653889662674E-6,5.23217538511567E-5,3.58172867701004E-6,100.0121307,100.0121307,-35856.46484375,-35831.89453125,57.1675282680253,20.6448093299071,20.631098,0,0,0,40,4449,99.8654,-35844.1796875,,,,,,,,,,,,,0,,,,0,,,,,,100.0121307,,,,
,30978653,100.0111771,-41024.1171875,7.30661691224291E-5,1.43713366654967E-6,1,0.999253354069792,40.0298881530762,1.98425727858345,16.0199999809265,0.000822339085767947,0.000163289100187451,0.25,1.61979724309742E-6,7.34767714221126E-5,1.84638071207585E-6,100.0111771,100.0111771,-41039.2109375,-41009.0234375,56.912717370756,20.645624728556,21.01075,0,0,0,40,4449,99.853,-41024.1171875,,,,,,,,,,,,,0,,,,0,,,,,,100.0111771,,,,
,30978758.815,100.0114098,-46313.59375,9.12577531199253E-5,1.35346007925058E-6,1,0.999253354069792,40.0298881530762,1.98431626621016,16.0199999809265,0.00102218167427144,0.00023206841263821,0.25,4.51338406079783E-6,9.1764099626914E-5,4.80867230340017E-6,100.0112534,100.0115662,-46321.03125,-46306.15625,57.210517836583,20.6450491897555,21.01075,0,0,0,40,4449,99.8444,-46313.59375,,,,,,,,,,,,,0,,,,0.00245,,,,,,100.0114098,,,,
,30978864.935,100.0082397,-51618.10546875,0.00011346753951068,1.43751198614762E-6,1,0.999253354069792,40.0298881530762,1.98426631903459,16.0199999809265,0.00127626239843896,0.000258212267091507,0.25,2.92979453824916E-6,0.00011410615143628,3.27928761963676E-6,100.0082397,100.0082397,-51623.11328125,-51613.09765625,57.444224763833,20.6481527730586,20.251448,0,0,0,40,4449,99.83785,-51618.10546875,,,,,,,,,,,,,0,,,,0,,,,,,100.0082397,,,,
,30978971.63,100.0106812,-56947.62109375,0.000132548573088655,1.53638979559251E-6,1,0.999253354069792,40.0298881530762,1.98450323842028,16.0199999809265,0.00148709891056516,0.000324271587817257,0.25,5.42523565602795E-6,0.000133290018170033,5.84214847336201E-6,100.0106812,100.0106812,-56960.08984375,-56935.15234375,57.2277136640061,20.6447145131874,20.251448,0,0,0,40,4449,99.8266,-56947.62109375,,,,,,,,,,,,,0,,,,0,,,,,,100.0106812,,,,
,30979078.485,100.0094528,-62289.548828125,0.000155180148741765,1.89161185512084E-6,1,0.999253354069792,40.0298881530762,1.98446161667285,16.0199999809265,0.0017400481682507,0.00038500667812548,0.25,6.83028995132702E-6,0.000156048365280675,7.31783703198602E-6,100.0094528,100.0094528,-62302.1640625,-62276.93359375,57.0659165605253,20.6478798503155,20.631098,0,0,0,40,4449,99.81745,-62289.548828125,,,,,,,,,,,,,0,,,,-0.0049,,,,,,100.0094528,,,,
,30979186.455,100.0080566,-67686.9765625,0.00017629413495772,1.9948006048858E-6,1,0.999253354069792,40.0298881530762,1.98438295795069,16.0199999809265,0.001983435039505,0.000399268376855317,0.25,4.39087888331832E-6,0.000177291933130553,4.92168120351102E-6,100.0080566,100.0080566,-67694.3203125,-67679.6328125,57.2284952925253,20.6497104279719,21.01075,0,0,0,40,4449,99.8069,-67686.9765625,,,,,,,,,,,,,0,,,,0,,,,,,100.0080566,,,,
,30979293.235,100.0076828,-73020.8046875,0.000194048020670014,1.71281488672629E-6,1,0.999253354069792,40.0298881530762,1.98419677450183,16.0199999809265,0.00218280223874999,0.000440591932647228,0.25,4.93906373874516E-6,0.000195147871039861,5.51973857616466E-6,100.0076828,100.0076828,-73031.09375,-73010.515625,57.1589303543137,20.6469138896913,20.251448,0,0,0,40,4449,99.80155,-73020.8046875,,,,,,,,,,,,,0,,,,0,,,,,,100.0076828,,,,
,30979400.335,100.0065994,-78375.0078125,0.000222576962605077,1.84533901267476E-6,1,0.999253354069792,40.0298881530762,1.98422811015882,16.0199999809265,0.00250163220546395,0.000517617358000361,0.25,6.75304988028972E-6,0.000223837585923588,7.42051397457864E-6,100.0065994,100.0065994,-78387.453125,-78362.5625,57.1808159528522,20.6497640692349,20.631098,0,0,0,40,4449,99.79725,-78375.0078125,,,,,,,,,,,,,0,,,,0,,,,,,100.0065994,,,,
,30979504.075,100.0065765,-83559.60546875,0.000243940269275471,1.57400322322978E-6,1,0.999253354069792,40.0298881530762,1.98420188270568,16.0199999809265,0.00274689274788955,0.000537891071385119,0.25,4.80393404616871E-6,0.000245331429994389,5.51542543720986E-6,100.0065765,100.0065765,-83564.671875,-83554.5390625,57.1847240954484,20.6514050686175,21.01075,0,0,0,40,4449,99.7897,-83559.60546875,,,,,,,,,,,,,0,,,,0,,,,,,100.0065765,,,,
,30979604.425,100.0049362,-88573.95703125,0.000261320816893234,1.72989015045765E-6,1,0.999253354069792,40.0298881530762,1.9843769270955,16.0199999809265,0.00294210855585281,0.000580666905726957,0.25,5.54073350164374E-6,0.000262812288084178,6.29987046364148E-6,100.0049362,100.0049362,-88586.46875,-88561.4453125,57.4364084786407,20.6465152746061,21.01075,0,0,0,40,4449,99.78625,-88573.95703125,,,,,,,,,,,,,0,,,,0,,,,,,100.0049362,,,,
,30979733.235,100.0018692,-86314.59765625,0.000254455310177959,1.65142529000807E-6,1,0.999253354069792,40.0298881530762,1.98442140590274,16.0199999809265,0.00286381359199242,0.000571401139236061,0.25,5.92192365104745E-6,0.000255905121135828,6.66653141655418E-6,100.0018692,100.0018692,-86324.78125,-86304.4140625,57.2136443506599,20.6476295302256,20.631098,0,0,0,40,4449,99.78355,-86314.59765625,,,,,,,,,,,,,0,,,,0.00245,,,,,,100.0018692,,,,
,30979839.62,99.9998016,-81000.69140625,0.000233645754051582,1.77503440795004E-6,1,0.999253354069792,40.0298881530762,1.98439429365889,16.0199999809265,0.00262795534390266,0.000533748093460459,0.25,6.23676438962561E-6,0.000234972557865755,6.93014427995334E-6,99.9998016,99.9998016,-81008.1171875,-80993.265625,57.5388018146599,20.6469479499582,21.01075,0,0,0,40,4449,99.7846,-81000.69140625,,,,,,,,,,,,,0,,,,0,,,,,,99.9998016,,,,
,30979946.01,99.9975891,-75683.3125,0.000210250274859895,2.15175341924924E-6,1,0.999253354069792,40.0298881530762,1.98431117845806,16.0199999809265,0.00236879314444431,0.000456927702644546,0.25,3.5412003607555E-6,0.000211448099943775,4.15778819341532E-6,99.9975891,99.9975891,-75690.703125,-75675.921875,57.230840178083,20.6489447423552,20.631098,0,0,0,40,4449,99.7888,-75683.3125,,,,,,,,,,,,,0,,,,0,,,,,,99.9975891,,,,
,30980049.195,99.9972687,-70526.24609375,0.000189989880385677,2.07758956734343E-6,1,0.999253354069792,40.0298881530762,1.98443829713496,16.0199999809265,0.00213541355648612,0.000442699568595547,0.25,5.83135566241431E-6,0.00019106302734316,6.40761674667882E-6,99.9972687,99.9972687,-70534.0078125,-70518.484375,57.2550706621791,20.6466494428814,20.251448,0,0,0,40,4449,99.79255,-70526.24609375,,,,,,,,,,,,,0,,,,0.0049,,,,,,99.9972687,,,,
,30980155.61,99.9946556,-65209.0859375,0.000175402290712481,1.49925161309959E-6,1,0.999253354069792,40.0298881530762,1.98434235905656,16.0199999809265,0.00197587520425474,0.000382874354141762,0.25,3.09555960626016E-6,0.000176397918383647,3.61825229062721E-6,99.9946289,99.9946823,-65221.41015625,-65196.76171875,57.2386564632753,20.645857770021,20.631098,0,0,0,40,4449,99.7961,-65209.0859375,,,,,,,,,,,,,0,,,,0.00245,,,,,,99.9946556,,,,
,30980260.72,99.9961395,-59954.634765625,0.000145812966150187,1.73088412584047E-6,1,0.999253354069792,40.0298881530762,1.98429970681421,16.0199999809265,0.00163672394649667,0.000351222672088212,0.25,5.4859841776059E-6,0.000146630802579821,5.94027813151745E-6,99.9961395,99.9961395,-59969.65625,-59939.61328125,57.1456426694868,20.6472653128191,20.631098,0,0,0,40,4449,99.7988,-59954.634765625,,,,,,,,,,,,,0,,,,0.0049,,,,,,99.9961395,,,,
,30980366.89,99.9927444,-54647.732421875,0.000131252104648273,1.23511651134066E-6,1,0.999253354069792,40.0298881530762,1.98437725203339,16.0199999809265,0.00147450482353807,0.00030941889928188,0.25,4.33892320618661E-6,0.000131988729046938,4.74719982582792E-6,99.9927444,99.9927444,-54657.75,-54637.71484375,57.3457395704099,20.6465889820609,20.631098,0,0,0,40,4449,99.8072,-54647.732421875,,,,,,,,,,,,,0,,,,-0.00245,,,,,,99.9927444,,,,
,30980474.32,99.9945374,-49278.646484375,0.000102010059060453,1.6066475786371E-6,1,0.999253354069792,40.0298881530762,1.98438485755159,16.0199999809265,0.00114279030579816,0.000258693788500721,0.25,4.98183966411962E-6,0.000102576804566351,5.31050922551538E-6,99.9945374,99.9945374,-49286.15625,-49271.13671875,57.1690915250637,20.6455903668367,21.01075,0,0,0,40,4449,99.81325,-49278.646484375,,,,,,,,,,,,,0,,,,0.0049,,,,,,99.9945374,,,,
,30980578.75,99.9925995,-44058.3828125,8.14688916518312E-5,1.45020606753808E-6,1,0.999253354069792,40.0298881530762,1.98445678647528,16.0199999809265,0.000918353200662215,0.000174392978529828,0.25,1.12613321201158E-6,8.19291589201295E-5,1.37404463853675E-6,99.9925995,99.9925995,-44073.41796875,-44043.34765625,57.2144259791791,20.6415841224331,20.631098,0,0,0,40,4449,99.8219,-44058.3828125,,,,,,,,,,,,,0,,,,-0.00245,,,,,,99.9925995,,,,
,30980680.755,99.9924393,-38961.291015625,5.91361812465203E-5,1.76513448631968E-6,1,0.999253354069792,40.0298881530762,1.98444406860817,16.0199999809265,0.000657663166111615,0.000177462825759844,0.25,5.31879359049107E-6,5.94563038990694E-5,5.52551154369145E-6,99.9924393,99.9924393,-38971.5,-38951.08203125,57.1167224142753,20.6400820763007,20.631098,0,0,0,40,4449,99.8268,-38961.291015625,,,,,,,,,,,,,0,,,,0.00245,,,,,,99.9924393,,,,
,30980787.01,99.9913025,-33649.71875,4.13712633213242E-5,7.40182960478935E-7,1,0.999253354069792,40.0298881530762,1.98437746193729,16.0199999809265,0.000459782059584184,0.00012582479350224,0.25,3.86866986315791E-6,4.15943224172955E-5,4.01494823095556E-6,99.9913025,99.9913025,-33664.625,-33634.8125,57.3770047111791,20.6418896821884,21.01075,0,0,0,40,4449,99.834,-33649.71875,,,,,,,,,,,,,0,,,,0,,,,,,99.9913025,,,,
,30980887.175,99.9904175,-28645.2138671875,2.31005918706327E-5,1.0356998513229E-6,1,0.999253354069792,40.0298881530762,1.98446751823166,16.0199999809265,0.000257869350066822,6.38217273119147E-5,0.25,1.58998360696956E-6,2.322663233867E-5,1.66885028588531E-6,99.9904175,99.9904175,-28657.80859375,-28632.619140625,57.2980602307368,20.6410885749595,21.01075,0,0,0,40,4449,99.84535,-28645.2138671875,,,,,,,,,,,,,0,,,,0.00245,,,,,,99.9904175,,,,
,30980989.405,99.9905472,-23535.48046875,3.2053007547194E-6,9.16845351036923E-7,1,0.999253354069792,40.0298881530762,1.9848200515686,16.0199999809265,3.19833531880506E-5,3.05012685523779E-5,0.25,2.1357623837103E-6,3.21692998786305E-6,2.15759608543168E-6,99.9905472,99.9905472,-23545.3984375,-23525.5625,57.3684067974676,20.6362991058684,20.631098,0,0,0,40,4449,99.8544,-23535.48046875,,,,,,,,,,,,,0,,,,0,,,,,,99.9905472,,,,
,30981095.485,99.9926224,-18235.9296875,-1.57939198167163E-5,7.69175334874425E-7,1,0.999253354069792,40.0298881530762,1.98449686621165,16.0199999809265,-0.000181066953151532,-1.6533259506975E-5,0.25,1.31201845962169E-6,-1.58871287929609E-5,1.27106272373481E-6,99.9926224,99.9926224,-18242.978515625,-18228.880859375,57.2894623170253,20.6406627349,20.631098,0,0,0,40,4449,99.86165,-18235.9296875,,,,,,,,,,,,,0,,,,0.00245,,,,,,99.9926224,,,,
,30981199.145,99.990654,-13053.4243164062,-3.25175457037982E-5,5.3462827865845E-7,1,0.999253354069792,40.0298881530762,1.98453278819558,16.0199999809265,-0.000368826851102215,-5.66289094449611E-5,0.25,7.02745250144138E-7,-3.27030833998657E-5,6.06556285920786E-7,99.990654,99.990654,-13060.7861328125,-13046.0625,57.2152076076984,20.6401451878855,21.01075,0,0,0,40,4449,99.8712,-13053.4243164062,,,,,,,,,,,,,0,,,,0,,,,,,99.990654,,,,
,30981302.295,99.9892349,-7898.07250976563,-4.82267881804092E-5,4.67838223335204E-7,1,0.999253354069792,40.0298881530762,1.98413905868289,16.0199999809265,-0.000546225896129711,-8.78040637810086E-5,0.25,7.03641401933736E-7,-4.85005657341155E-5,5.58272210779965E-7,99.9892349,99.9892349,-7913.095703125,-7883.04931640625,57.2355299491984,20.6421876689966,21.01075,0,0,0,40,4449,99.8776,-7898.07250976563,,,,,,,,,,,,,0,,,,0,,,,,,99.9892349,,,,
,30981403.83,99.9911957,-2822.60888671875,-6.28528434440493E-5,3.54845592611588E-7,1,0.999253354069792,40.0298881530762,1.98421135015321,16.0199999809265,-0.000710205971907386,-0.000124095691803526,0.25,6.29170263751347E-8,-6.32065974572446E-5,-1.32236895950488E-7,99.9911957,99.9911957,-2835.27807617187,-2809.93969726562,56.8267382336406,20.6419971878188,20.631098,0,0,0,40,4449,99.88625,-2822.60888671875,,,,,,,,,,,,,0,,,,-0.0049,,,,,,99.9911957,,,,
,30981507.375,99.9951019,2348.40856933594,-6.92429407622626E-5,2.70550090189751E-7,1,0.999253354069792,40.0298881530762,1.98431566433341,16.0199999809265,-0.000780623129467463,-0.00014711157285232,0.25,-8.50471498921973E-7,-6.96297608155625E-5,-1.07070867263339E-6,99.9951019,99.9951019,2338.35229492187,2358.46484375,56.7368509539291,20.6395255157228,20.251448,0,0,0,40,4449,99.8898,2348.40856933594,,,,,,,,,,,,,0,,,,0,,,,,,99.9951019,,,,
,30981609.845,99.9995575,7472.4140625,-6.33123396837998E-5,4.927908854584E-7,1,0.999253354069792,40.0298881530762,1.9841311705087,16.0199999809265,-0.000713168747695252,-0.000137550348656436,0.25,-1.04850400049227E-6,-6.36656161707321E-5,-1.25049258678056E-6,99.9995575,99.9995575,7457.47314453125,7487.35498046875,57.0565370182945,20.6428914815891,20.631098,0,0,0,40,4449,99.89,7472.4140625,,,,,,,,,,,,,0,,,,0,,,,,,99.9995575,,,,
,30981715.355,100.00339125,12745.1411132812,-3.7103601859445E-5,4.50159941396052E-7,1,0.999253354069792,40.0298881530762,1.98413393818227,16.0199999809265,-0.000417235708538854,-8.46735903897544E-5,0.25,-9.7471235977331E-7,-3.73098201684469E-5,-1.09449526184404E-6,100.0033798,100.0034027,12730.140625,12760.1416015625,57.1214121853907,20.6417853909281,21.01075,0,0,0,40,4449,99.88565,12745.1411132812,,,,,,,,,,,,,0,,,,0,,,,,,100.00339125,,,,
,30981818.265,100.0067444,17890.4111328125,-1.52452020056188E-5,6.17786557427964E-7,1,0.999253354069792,40.0298881530762,1.98413606662799,16.0199999809265,-0.000171698019450973,-3.33012998831963E-5,0.25,-2.68880204201032E-7,-1.53304633765901E-5,-3.17090157641664E-7,100.0067444,100.0067444,17877.80859375,17903.013671875,57.3699700545061,20.6426027888382,21.01075,0,0,0,40,4449,99.87635,17890.4111328125,,,,,,,,,,,,,0,,,,0.00245,,,,,,100.0067444,,,,
,30981923.375,100.0094681,23142.939453125,-1.28646949098582E-5,1.18720191700913E-6,1,0.999253354069792,40.0298881530762,1.98414885690703,16.0199999809265,-0.000140990065046181,-5.02982011502398E-5,0.25,-2.19183081303416E-6,-1.29307745002805E-5,-2.24338446652801E-6,100.0094681,100.0094681,23130.326171875,23155.552734375,57.1761261817368,20.6418548508948,21.3904,0,0,0,40,4449,99.86825,23142.939453125,,,,,,,,,,,,,0,,,,-0.0049,,,,,,100.0094681,,,,
,30982027.11,100.0096664,28327.916015625,-2.61165377536579E-5,1.38729697259223E-6,1,0.999253354069792,40.0298881530762,1.98417078689828,16.0199999809265,-0.000292648002992289,-6.55758249201016E-5,0.25,-1.21621165997379E-6,-2.62607740308666E-5,-1.30209607551185E-6,100.0096664,100.0096664,28323.05859375,28332.7734375,56.8673829166406,20.6394735941844,20.631098,0,0,0,40,4449,99.8579,28327.916015625,,,,,,,,,,,,,0,,,,-0.0049,,,,,,100.0096664,,,,
,30982130.97,100.0107498,33517.51171875,-4.36568569555002E-5,1.07730681130807E-6,1,0.999253354069792,40.0298881530762,1.98434112939437,16.0199999809265,-0.000492191211919082,-9.28279146192466E-5,0.25,-5.47051038871205E-7,-4.39028497611634E-5,-6.81347882426966E-7,100.0107498,100.0107498,33505.24609375,33529.77734375,57.1362631272561,20.6357452037943,21.01075,0,0,0,40,4449,99.84765,33517.51171875,,,,,,,,,,,,,0,,,,-0.00245,,,,,,100.0107498,,,,
,30982234.175,100.0087204,38677.669921875,-6.12968143522259E-5,1.38028036596105E-6,1,0.999253354069792,40.0298881530762,1.9842295561077,16.0199999809265,-0.000695002743288647,-0.000107737535619462,0.25,1.23029643731974E-6,-6.16487243272329E-5,1.05430475597998E-6,100.0087204,100.0087204,38662.5,38692.83984375,57.0495023616214,20.6383930060467,21.01075,0,0,0,40,4449,99.83805,38677.669921875,,,,,,,,,,,,,0,,,,0.0049,,,,,,100.0087204,,,,
,30982339.305,100.0102615,43929.62109375,-8.92297305631957E-5,1.34032113453947E-6,1,0.999253354069792,40.0298881530762,1.98417991561003,16.0199999809265,-0.00100683865660082,-0.000184509498165026,0.25,-6.6066753140406E-7,-8.97355007571525E-5,-9.28953403573874E-7,100.0102615,100.0102615,43919.57421875,43939.66796875,57.5755383550638,20.6380151372828,21.01075,0,0,0,40,4449,99.8284,43929.62109375,,,,,,,,,,,,,0,,,,0.00245,,,,,,100.0102615,,,,
,30982443.26,100.0097427,49127.79296875,-9.5145827799433E-5,1.62759168594441E-6,1,0.999253354069792,40.0298881530762,1.98396960503738,16.0199999809265,-0.00106455851694513,-0.00024761729123657,0.25,-5.21125377968268E-6,-9.56727304403817E-5,-5.52105297151765E-6,100.0097427,100.0097427,49117.703125,49137.8828125,56.8329912617945,20.6369016480513,21.01075,0,0,0,40,4449,99.8194,49127.79296875,,,,,,,,,,,,,0,,,,0,,,,,,100.0097427,,,,
,30982547.43,100.0082855,54335.267578125,-0.00012982151646057,1.71114699061726E-6,1,0.999253354069792,40.0298881530762,1.98412095319254,16.0199999809265,-0.00146050288715283,-0.000293189656229327,0.25,-3.1569270323819E-6,-0.000130553323999576,-3.55440942911384E-6,100.0082855,100.0082855,54330.203125,54340.33203125,57.2746113751599,20.6363169075227,20.631098,0,0,0,40,4449,99.81205,54335.267578125,,,,,,,,,,,,,0,,,,-0.00245,,,,,,100.0082855,,,,
,30982651.36,100.0071335,59527.783203125,-0.000141426304149776,1.45921758428008E-6,1,0.999253354069792,40.0298881530762,1.98429475913249,16.0199999809265,-0.00158442682162875,-0.000358043140403069,0.25,-6.85956010923069E-6,-0.000142214942397725,-7.30918884808602E-6,100.0067978,100.0074692,59517.73046875,59537.8359375,56.8423708040252,20.6364774706152,21.01075,0,0,0,40,4449,99.8046,59527.783203125,,,,,,,,,,,,,0,,,,0,,,,,,100.0071335,,,,
,30982755.89,100.0075912,64753.05078125,-0.000165162619148846,2.03417794786789E-6,1,0.999253354069792,40.0298881530762,1.98401578536149,16.0199999809265,-0.00185558478758247,-0.000386945097302145,0.25,-5.25824910093288E-6,-0.000166093192843266,-5.76415328564076E-6,100.0075912,100.0075912,64740.61328125,64765.48828125,56.8384626614291,20.6338004499333,21.01075,0,0,0,40,4449,99.79625,64753.05078125,,,,,,,,,,,,,0,,,,0.00245,,,,,,100.0075912,,,,
,30982860.64,100.0084305,69988.05859375,-0.000184567284558512,2.02384516356014E-6,1,0.999253354069792,40.0298881530762,1.98434385705131,16.0199999809265,-0.00207935942197442,-0.000401607184799558,0.25,-3.14790330329283E-6,-0.00018561674922404,-3.69373981450674E-6,100.0084305,100.0084305,69978.046875,69998.0703125,57.3840393678522,20.633541849697,21.01075,0,0,0,40,4449,99.7862,69988.05859375,,,,,,,,,,,,,0,,,,-0.0049,,,,,,100.0084305,,,,
,30982963.625,100.0071411,75135.57421875,-0.000200774783271281,1.79647468199914E-6,1,0.999253354069792,40.0298881530762,1.98426506722479,16.0199999809265,-0.00225814322681899,-0.000458211263167844,0.25,-5.31799733872231E-6,-0.000201912862943752,-5.91844028014778E-6,100.0071411,100.0071411,75130.6484375,75140.5,57.200356665833,20.6341226518891,21.3904,0,0,0,40,4449,99.781,75135.57421875,,,,,,,,,,,,,0,,,,0,,,,,,100.0071411,,,,
,30983068.35,100.0059509,80371.62109375,-0.000227880973878971,1.74204262530205E-6,1,0.999253354069792,40.0298881530762,1.98412614092493,16.0199999809265,-0.00256601795804824,-0.000502062560300554,0.25,-4.44948479307652E-6,-0.000229179322912619,-5.11701908115801E-6,100.0059509,100.0059509,80359.1484375,80384.09375,56.9658681100637,20.6353960601682,20.631098,0,0,0,40,4449,99.7773,80371.62109375,,,,,,,,,,,,,0,,,,-0.0049,,,,,,100.0059509,,,,
,30983170.37,100.0044479,85469.890625,-0.000258918031193264,2.10354619001657E-6,1,0.999253354069792,40.0298881530762,1.98435984093875,16.0199999809265,-0.00291888377046024,-0.000553273311472158,0.25,-3.5353451637081E-6,-0.000260399756866487,-4.27973355440272E-6,100.0044479,100.0044479,85457.3046875,85482.4765625,56.7126204698329,20.6297563810175,21.01075,0,0,0,40,4449,99.7679,85469.890625,,,,,,,,,,,,,0,,,,0.0049,,,,,,100.0044479,,,,
,30983290.03,100.0044174,89745.70703125,-0.000277690487050809,2.33891222165058E-6,1,0.999253354069792,40.0298881530762,1.98426376040734,16.0199999809265,-0.00312475711886885,-0.000625478994083329,0.25,-6.63848875933271E-6,-0.000279273760590363,-7.44844307529103E-6,100.0044174,100.0044174,89733.4453125,89757.96875,57.3105662870445,20.6324302177291,21.01075,0,0,0,40,4449,99.76415,89745.70703125,,,,,,,,,,,,,0,,,,-0.00245,,,,,,100.0044174,,,,
,30983389.8,99.9990005,84761.80859375,-0.000257872468161929,2.40490902273128E-6,1,0.999253354069792,40.0298881530762,1.98409344586113,16.0199999809265,-0.00290328833028536,-0.000570532179688946,0.25,-5.25184205313051E-6,-0.000259343082703944,-6.0039331919628E-6,99.9990005,99.9990005,84749.234375,84774.3828125,56.6844818431406,20.6345689818516,21.3904,0,0,0,40,4449,99.76885,84761.80859375,,,,,,,,,,,,,0,,,,0.00245,,,,,,99.9990005,,,,
,30983491.26,99.9985886,79690.6640625,-0.00022514887223245,2.08214704435598E-6,1,0.999253354069792,40.0298881530762,1.98429825177532,16.0199999809265,-0.00253560831622292,-0.000495242319521453,0.25,-4.32097608593697E-6,-0.000226431600835454,-4.98077086001242E-6,99.9985886,99.9985886,79680.6796875,79700.6484375,56.7665528376599,20.6335025380859,21.01075,0,0,0,40,4449,99.77065,79690.6640625,,,,,,,,,,,,,0,,,,0,,,,,,99.9985886,,,,
,30983594.695,99.9978943,74519.375,-0.000211860471671395,2.25639053287299E-6,1,0.999253354069792,40.0298881530762,1.98426289374028,16.0199999809265,-0.00238399060635823,-0.000476842230941458,0.25,-5.02090145536537E-6,-0.000213062832694922,-5.65172824436701E-6,99.9978943,99.9978943,74506.7109375,74532.0390625,57.0792042453522,20.6346299595813,21.3904,0,0,0,40,4449,99.7718,74519.375,,,,,,,,,,,,,0,,,,-0.00245,,,,,,99.9978943,,,,
,30983696.86,99.9975357,69411.42578125,-0.000182855603456615,2.36443848000718E-6,1,0.999253354069792,40.0298881530762,1.98439554743054,16.0199999809265,-0.00205812935065207,-0.000409260717967294,0.25,-4.12424183158716E-6,-0.00018389227488586,-4.67129448805738E-6,99.9975357,99.9975357,69404.1015625,69418.75,57.0995265868522,20.6310490090515,20.631098,0,0,0,40,4449,99.7768,69411.42578125,,,,,,,,,,,,,0,,,,-0.00245,,,,,,99.9975357,,,,
,30983802.095,99.9981232,64151.373046875,-0.000163452406625698,1.51519791882333E-6,1,0.999253354069792,40.0298881530762,1.98441584487466,16.0199999809265,-0.00183528362831003,-0.000391206772790369,0.25,-5.92848945593657E-6,-0.00016437104581508,-6.43383022550636E-6,99.9981232,99.9981232,64136.5,64166.24609375,57.2378748347561,20.6315896668237,21.01075,0,0,0,40,4449,99.77975,64151.373046875,,,,,,,,,,,,,0,,,,0.00245,,,,,,99.9981232,,,,
,30983902.69,99.9944763,59125.484375,-0.000140365477623478,1.76375641215265E-6,1,0.999253354069792,40.0298881530762,1.9843275784463,16.0199999809265,-0.00157464691654487,-0.000343506426476239,0.25,-5.75846806743663E-6,-0.000141151112702913,-6.19908531214684E-6,99.9944763,99.9944763,59113.16015625,59137.80859375,57.3160376866791,20.6343643277708,21.01075,0,0,0,40,4449,99.78445,59125.484375,,,,,,,,,,,,,0,,,,0,,,,,,99.9944763,,,,
,30984006.44,99.9948807,53938.048828125,-0.000129352433468519,1.90193769295449E-6,1,0.999253354069792,40.0298881530762,1.98405410646802,16.0199999809265,-0.00145664564948534,-0.000283758518961669,0.25,-2.40503105211142E-6,-0.000130083641882677,-2.79719649968294E-6,99.9948807,99.9948807,53935.62109375,53940.4765625,57.2277136640061,20.6394055721117,20.631098,0,0,0,40,4449,99.79,53938.048828125,,,,,,,,,,,,,0,,,,0,,,,,,99.9948807,,,,
,30984112.04,99.9925919,48660.544921875,-0.000105539777332911,1.73497590988053E-6,1,0.999253354069792,40.0298881530762,1.98391051908336,16.0199999809265,-0.0011864648250114,-0.000242503986733293,0.25,-2.93385768422838E-6,-0.00010613251220102,-3.26159144113256E-6,99.9925919,99.9925919,48648.15234375,48672.9375,56.7321611828137,20.6413961274442,20.631098,0,0,0,40,4449,99.7968,48660.544921875,,,,,,,,,,,,,0,,,,-0.0049,,,,,,99.9925919,,,,
,30984215.94,99.992775,43467.71875,-8.43702090717975E-5,1.37382737050938E-6,1,0.999253354069792,40.0298881530762,1.9841940902098,16.0199999809265,-0.00094660634119836,-0.0002052368922491,0.25,-3.34824448712558E-6,-8.48402634931214E-5,-3.61768227574206E-6,99.992775,99.992775,43455.5625,43479.875,57.088583787583,20.6398049994721,20.631098,0,0,0,40,4449,99.80175,43467.71875,,,,,,,,,,,,,0,,,,-0.0049,,,,,,99.992775,,,,
,30984320.435,99.9906235,38243.12109375,-6.12808277636434E-5,1.44940981921023E-6,1,0.999253354069792,40.0298881530762,1.98422508401213,16.0199999809265,-0.000686833205220508,-0.000153178449683612,0.25,-2.7942243981602E-6,-6.16205643405066E-5,-2.99321916188707E-6,99.9906235,99.9906235,38223.19921875,38263.04296875,56.7079306987175,20.6405989856426,21.01075,0,0,0,40,4449,99.81105,38243.12109375,,,,,,,,,,,,,0,,,,0.00245,,,,,,99.9906235,,,,
,30984424.095,99.9909058,33066.353515625,-4.26209991034651E-5,1.1055389447844E-6,1,0.999253354069792,40.0298881530762,1.98390773808724,16.0199999809265,-0.000479295412763688,-9.69635213365434E-5,0.25,-1.09668372367828E-6,-4.28594171010186E-5,-1.23112312645959E-6,99.9909058,99.9909058,33051.18359375,33081.5234375,57.1604936113522,20.6419837470452,21.01075,0,0,0,40,4449,99.81855,33066.353515625,,,,,,,,,,,,,0,,,,0,,,,,,99.9909058,,,,
,30984526.82,99.9905243,27928.810546875,-2.39114317518976E-5,1.44139896807703E-6,1,0.999253354069792,40.0298881530762,1.98422417654907,16.0199999809265,-0.000269179930379363,-5.30130775246547E-5,0.25,-4.91452276928189E-7,-2.40453470165724E-5,-5.66634050514119E-7,99.9904175,99.9906311,27918.849609375,27938.771484375,56.8353361473522,20.6382344926465,21.01075,0,0,0,40,4449,99.82895,27928.810546875,,,,,,,,,,,,,0,,,,0,,,,,,99.9905243,,,,
,30984629.04,99.9911423,22821.345703125,-2.55130221033884E-6,8.56737613174635E-7,1,0.999253354069792,40.0298881530762,1.98415254586491,16.0199999809265,-2.44123673055345E-5,-3.01717926655809E-5,0.25,-2.22236708593764E-6,-2.55895701969799E-6,-2.24270587900857E-6,99.9911423,99.9911423,22811.17578125,22831.515625,57.0088576786214,20.6397841908714,21.3904,0,0,0,40,4449,99.83775,22821.345703125,,,,,,,,,,,,,0,,,,0.00245,,,,,,99.9911423,,,,
,30984731.485,99.9906082,17701.6064453125,1.59009823176791E-5,7.42310432435346E-7,1,0.999253354069792,40.0298881530762,1.98410537638348,16.0199999809265,0.000182663452441003,1.4345151076456E-5,0.25,-1.5242829308664E-6,1.59954307783408E-5,-1.48415186449341E-6,99.9906082,99.9906082,17693.90234375,17709.310546875,57.146424298006,20.6416270731896,21.3904,0,0,0,40,4449,99.84535,17701.6064453125,,,,,,,,,,,,,0,,,,-0.00245,,,,,,99.9906082,,,,
,30984836.33,99.9914322,12461.669921875,3.45033264000286E-5,5.94602996144854E-7,1,0.999253354069792,40.0298881530762,1.9841258790125,16.0199999809265,0.0003932472489274,4.88421490916591E-5,0.25,-1.74008974509514E-6,3.47032139737451E-5,-1.64352647848248E-6,99.9914322,99.9914322,12451.6796875,12471.66015625,57.2152076076984,20.643618553698,20.631098,0,0,0,40,4449,99.85165,12461.669921875,,,,,,,,,,,,,0,,,,0.0049,,,,,,99.9914322,,,,
,30984937.35,99.9914551,7411.71118164062,4.98905501178578E-5,4.43667365808617E-7,1,0.999253354069792,40.0298881530762,1.98402764499267,16.0199999809265,0.000564248183252359,9.5327989198087E-5,0.25,-3.29710896984875E-7,5.01724807262157E-5,-1.76958394316838E-7,99.9914551,99.9914551,7399.37158203125,7424.05078125,57.065134932006,20.6417130257649,21.01075,0,0,0,40,4449,99.8591,7411.71118164062,,,,,,,,,,,,,0,,,,-0.0049,,,,,,99.9914551,,,,
,30985040.865,99.99136735,2236.18090820313,6.49275784139158E-5,3.56090054209822E-7,1,0.999253354069792,40.0298881530762,1.98411141416555,16.0199999809265,0.000734447981419615,0.000123437338646334,0.25,-4.85466970177653E-7,6.52942491866446E-5,-2.86085554418229E-7,99.991066,99.9916687,2226.18408203125,2246.177734375,57.3887291389676,20.6423633283185,21.3904,0,0,0,40,4449,99.8708,2236.18090820313,,,,,,,,,,,,,0,,,,-0.00245,,,,,,99.99136735,,,,
,30985088.395,99.9929733,-0.334923014044762,6.84112997606161E-5,3.90827343856073E-7,1,0.999253354069792,40.0298881530762,1.98420846556858,16.0199999809265,0.000772593282261983,0.000137442240865268,0.25,1.41076719739367E-7,6.87954719080152E-5,3.55125507124918E-7,99.9929733,99.9929733,-0.350146800279617,-0.319699227809906,57.2097362080637,20.6454863243036,21.3904,0,0,0,40,4417,99.87405,-0.334923014044762,,,,,,,,,,,,,0,,,,-0.00245,,,,,,99.9929733,,,,