File: data/doubleLayers/dl_5/ppms/data/DD205_6_HYST_100OE_150K.DAT
[Header]
; VSM Data File (default extension .dat)
; Copyright (c) 2003-2013, Quantum Design, Inc. All rights reserved.
TITLE,
FILEOPENTIME,30986320.14,12/25/2018,11:20 pm
BYAPP,VSM,2.0,2.0
INFO,PPMS VSM Option Release 1.4.10 Build 1,APPNAME
INFO,Quantum Design Linear Motor Servo Controller,MOTOR_MODULE_NAME
INFO,3101-100 M1,MOTOR_HW_VERSION
INFO,MMC1014,MOTOR_SERIAL_NUMBER
INFO,SRV No X-over 01.03.11,MOTOR_SOFTWARE_VERSION
INFO,Quantum Design VSM Detection Module,VSM_MODULE_NAME
INFO,3101-150 F0,VSM_HW_VERSION
INFO,VSM707,VSM_SERIAL_NUMBER
INFO,VSM No X-over 01.02.05 May 20 2008 13:51:47,VSM_SOFTWARE_VERSION
INFO,704,PREAMP_SERIAL_NUMBER
INFO,822,COIL_SERIAL_NUMBER
INFO,0,MOMENT_UNITS
INFO,CoFe2O4,SAMPLE_MATERIAL
INFO,AH11 DL,SAMPLE_COMMENT
INFO,30.27,SAMPLE_MASS
INFO,,SAMPLE_VOLUME
INFO,,SAMPLE_MOLECULAR_WEIGHT
INFO,,SAMPLE_SIZE
INFO,,SAMPLE_SHAPE
DATATYPE,COMMENT,1
DATATYPE,TIME,2
STARTUPAXIS,X,2
STARTUPAXIS,Y1,5
[Data]
Comment,Time Stamp (sec),Temperature (K),Magnetic Field (Oe),Moment (emu),M. Std. Err. (emu),Transport Action,Averaging Time (sec),Frequency (Hz),Peak Amplitude (mm),Center Position (mm),Coil Signal' (mV),Coil Signal" (mV),Range (mV),M. Quad. Signal (emu),M. Raw' (emu),M. Raw" (emu),Min. Temperature (K),Max. Temperature (K),Min. Field (Oe),Max. Field (Oe),Mass (grams),Motor Lag (deg),Pressure (Torr),VSM Status (code),Motor Status (code),Measure Status (code),Measure Count,PPMS Status (code),System Temp. (K),System Field (Oe),Sample Position (deg),Bridge 1 Resistance (ohms),Bridge 1 Excitation (에),Bridge 2 Resistance (ohms),Bridge 2 Excitation (에),Bridge 3 Resistance (ohms),Bridge 3 Excitation (에),Bridge 4 Resistance (ohms),Bridge 4 Excitation (에),Signal 1 Vin (V),Signal 2 Vin (V),Digital Inputs (code),Drive 1 Iout (mA),Drive 1 Ipower (W),Drive 2 Iout (mA),Drive 2 Ipower (W),Pressure (),Map 20 (),Map 21 (),Map 22 (),Map 23 (),Map 24 (),Map 25 (),Map 26 (),Map 27 (),Map 28 (),Map 29 ()
,30986335.5,149.980484,-0.319699227809906,,,2,,,,15.749999755919,,,,,,,149.980484,149.980484,-0.319699227809906,-0.319699227809906,,,22.149702,,,,-99999999,4369,149.8696,-0.319699227809906,,,,,,,,,,,,,,,,,,,,,,,149.980484,,,,
,30986487.78,149.9816589,4688.40869140625,4.43000047742738E-5,4.56642052773705E-7,1,0.999253354069792,40.0298881530762,2.00852840625725,15.7399997115135,0.000506881531970175,8.36725160674269E-5,0.25,-3.93891537129551E-7,4.45176435171139E-5,-3.24791298651078E-7,149.9816589,149.9816589,4686.1484375,4690.6689453125,56.4437402592175,20.6132765920603,21.770052,0,0,0,40,4449,149.8969,4688.40869140625,,,,,,,,,,,,,0,,,,0.0049,,,,,,149.9816589,,,,
,30986586.47,149.9839325,9619.69873046875,3.87078421051837E-5,6.56389016497784E-7,1,0.999253354069792,40.0298881530762,2.00846459532594,15.7399997115135,0.000443662118506147,6.86348363281106E-5,0.25,-7.3558090346603E-7,3.88986631789553E-5,-6.77273104304217E-7,149.9839325,149.9839325,9617.2421875,9622.1552734375,56.6391473890252,20.6184339926572,22.149702,0,0,0,40,4449,149.9158,9619.69873046875,,,,,,,,,,,,,0,,,,0,,,,,,149.9839325,,,,
,30986684.615,149.9888,14527.1420898438,2.71209738206207E-5,7.43883360629805E-7,1,0.999253354069792,40.0298881530762,2.00852548277326,15.7399997115135,0.000310616183604615,4.95179388254999E-5,0.25,-3.90377809516267E-7,2.72544931342712E-5,-3.49021554287434E-7,149.9888,149.9888,14524.62109375,14529.6630859375,56.5922496778714,20.6191393655205,22.149702,0,0,0,40,4449,149.9193,14527.1420898438,,,,,,,,,,,,,0,,,,0,,,,,,149.9888,,,,
,30986783.975,149.9951935,19492.0087890625,1.13204791792261E-5,9.08127641552299E-7,1,0.999253354069792,40.0298881530762,2.00874121641219,15.7399997115135,0.000130934264197352,1.3394988793381E-5,0.25,-7.99739968194642E-7,1.13772323584805E-5,-7.85648235165145E-7,149.9951935,149.9951935,19482.291015625,19501.7265625,56.7204367550252,20.6209620458628,22.149702,0,0,0,40,4449,149.9244,19492.0087890625,,,,,,,,,,,,,0,,,,0,,,,,,149.9951935,,,,
,30986879.815,149.9999847,24281.947265625,-7.89631100115956E-6,9.7503569236694E-7,1,0.999253354069792,40.0298881530762,2.00871796088519,15.7399997115135,-8.69148122010087E-5,-3.46819015009551E-5,0.25,-1.65994126775347E-6,-7.93238287590419E-6,-1.68060673313235E-6,149.9999847,149.9999847,24269.41796875,24294.4765625,56.7368509539291,20.6205122930185,22.149702,0,0,0,40,4449,149.92485,24281.947265625,,,,,,,,,,,,,0,,,,-0.0049,,,,,,149.9999847,,,,
,30986978.875,150.0011444,29232.046875,-2.7614111153654E-5,1.686851703109E-6,1,0.999253354069792,40.0298881530762,2.00860721851693,15.7399997115135,-0.00031159236505799,-7.73134437279846E-5,0.25,-1.95680047331861E-6,-2.77463990471172E-5,-2.01008273587198E-6,150.0011444,150.0011444,29226.9296875,29237.1640625,56.6547799594098,20.6179296821979,22.529354,0,0,0,40,4449,149.91885,29232.046875,,,,,,,,,,,,,0,,,,0.00245,,,,,,150.0011444,,,,
,30987078.24,150.0015564,34197.388671875,-4.51222879505381E-5,1.46114192978055E-6,1,0.999253354069792,40.0298881530762,2.008616181995,15.7399997115135,-0.000516856811839931,-8.21142609133682E-5,0.25,6.72708191871759E-7,-4.53446172313409E-5,6.0483710773316E-7,150.0015564,150.0015564,34190.015625,34204.76171875,56.9103724851983,20.6220080306158,22.149702,0,0,0,40,4449,149.922,34197.388671875,,,,,,,,,,,,,0,,,,0.0049,,,,,,150.0015564,,,,
,30987177.59,150.00645445,39164.380859375,-6.45469271038927E-5,1.92351959338654E-6,1,0.999253354069792,40.0298881530762,2.00853651628138,15.7399997115135,-0.000739839158448652,-0.000114539110456185,0.25,1.21759128755393E-6,-6.48654216423065E-5,1.1220645080299E-6,150.0064087,150.0065002,39157.13671875,39171.625,56.8775440873906,20.6215497536152,22.149702,0,0,0,40,4449,149.9137,39164.380859375,,,,,,,,,,,,,0,,,,0,,,,,,150.00645445,,,,
,30987276.695,150.0065918,44116.654296875,-8.40447865445152E-5,1.68282817220809E-6,1,0.999253354069792,40.0298881530762,2.00857998531321,15.7399997115135,-0.000964891209907803,-0.000140265174039159,0.25,2.36191836606991E-6,-8.44607874884398E-5,2.24175674732509E-6,150.0065918,150.0065918,44108.7109375,44124.59765625,56.8243933480829,20.6249508332705,22.149702,0,0,0,40,4449,149.90605,44116.654296875,,,,,,,,,,,,,0,,,,0,,,,,,150.0065918,,,,
,30987375.68,150.0075378,49067.58984375,-0.000104827791794717,2.25624398639535E-6,1,0.999253354069792,40.0298881530762,2.00838148460409,15.7399997115135,-0.00119402799060078,-0.000228637142352477,0.25,-1.75553761254949E-6,-0.000105339411745613,-1.92795800240917E-6,150.0075378,150.0075378,49062.58984375,49072.58984375,56.8150138058522,20.6222529700759,22.149702,0,0,0,40,4449,149.8993,49067.58984375,,,,,,,,,,,,,0,,,,0,,,,,,150.0075378,,,,
,30987471.72,150.0090027,53865.041015625,-0.00012472549409168,1.60005034919368E-6,1,0.999253354069792,40.0298881530762,2.00850186935093,15.7399997115135,-0.0014177359248521,-0.000289373737741451,0.25,-3.60562835188082E-6,-0.00012533199759494,-3.81762091766508E-6,150.0090027,150.0090027,53855.0625,53875.01953125,56.994006736756,20.619705288456,21.770052,0,0,0,40,4449,149.8885,53865.041015625,,,,,,,,,,,,,0,,,,0,,,,,,150.0090027,,,,
,30987568.475,150.0085449,58700.474609375,-0.000147531518630601,2.29741730190928E-6,1,0.999253354069792,40.0298881530762,2.00878672110272,15.7399997115135,-0.00168571153579248,-0.00029344805978291,0.25,1.27040492175461E-8,-0.000148255745979014,-2.16313883232195E-7,150.0085449,150.0085449,58693.0078125,58707.94140625,56.9056827140829,20.6152387287523,22.529354,0,0,0,40,4449,149.8857,58700.474609375,,,,,,,,,,,,,0,,,,0,,,,,,150.0085449,,,,
,30987664.055,150.0100861,63478.396484375,-0.000165762515984785,2.04134428238737E-6,1,0.999253354069792,40.0298881530762,2.00849075350178,15.7399997115135,-0.0019004982416467,-0.000290956246442715,0.25,3.40168753243182E-6,-0.000166581647774033,3.16181158736639E-6,150.0100861,150.0100861,63465.8359375,63490.95703125,56.8931766577752,20.6232945611159,22.529354,0,0,0,40,4449,149.87315,63478.396484375,,,,,,,,,,,,,0,,,,0.00245,,,,,,150.0100861,,,,
,30987759.125,150.0105438,68228.59375,-0.000192240197214097,3.03571445819363E-6,1,0.999253354069792,40.0298881530762,2.00838250030736,15.7399997115135,-0.00219754120768276,-0.000374262160540885,0.25,7.18578724949405E-7,-0.000193185372193482,4.25492130353022E-7,150.0105438,150.0105438,68218.5703125,68238.6171875,56.8884868866599,20.61790715161,22.149702,0,0,0,40,4449,149.8615,68228.59375,,,,,,,,,,,,,0,,,,0,,,,,,150.0105438,,,,
,30987858.18,150.0105743,73180.9375,-0.000202952276608342,2.18554243889931E-6,1,0.999253354069792,40.0298881530762,2.00855748361321,15.7399997115135,-0.0023204378971918,-0.000393719088589838,0.25,8.82828172211825E-7,-0.000203950530435116,5.75080365612222E-7,150.0105743,150.0105743,73170.8515625,73191.0234375,56.8603482599676,20.6169592891204,21.770052,0,0,0,40,4449,149.8526,73180.9375,,,,,,,,,,,,,0,,,,0,,,,,,150.0105743,,,,
,30987955.72,150.0084686,78056.88671875,-0.000221317551905575,2.82817162068283E-6,1,0.999253354069792,40.0298881530762,2.00843314869021,15.7399997115135,-0.00252643134455769,-0.000451360135826435,0.25,-9.67517845904235E-7,-0.000222403433105472,-1.31143781205026E-6,150.0084686,150.0084686,78054.40625,78059.3671875,56.9283499411406,20.6195745251285,21.770052,0,0,0,40,4449,149.848,78056.88671875,,,,,,,,,,,,,0,,,,0,,,,,,150.0084686,,,,
,30988049,150.0095978,82720.03125,-0.000240382840273041,3.05501990260999E-6,1,0.999253354069792,40.0298881530762,2.00858731603053,15.7399997115135,-0.00274917584008054,-0.000462125322556173,0.25,1.41215994730456E-6,-0.000241566272464549,1.05189524601955E-6,150.0095978,150.0095978,82712.5859375,82727.4765625,56.9056827140829,20.6166427720268,21.770052,0,0,0,40,4449,149.83445,82720.03125,,,,,,,,,,,,,0,,,,0,,,,,,150.0095978,,,,
,30988144.12,150.0102997,87475.85546875,-0.000260514872385041,2.46284072050863E-6,1,0.999253354069792,40.0298881530762,2.00853445721733,15.7399997115135,-0.00297611321242737,-0.000519387769250955,0.25,-9.64665223588422E-8,-0.000261795207763947,-4.93560107062536E-7,150.0102997,150.0102997,87465.734375,87485.9765625,56.9041194570445,20.6190375914546,22.529354,0,0,0,40,4449,149.82815,87475.85546875,,,,,,,,,,,,,0,,,,0,,,,,,150.0102997,,,,
,30988255.25,150.0067902,87928.1953125,-0.000267922957819853,2.52057305109755E-6,1,0.999253354069792,40.0298881530762,2.00880974681747,15.7399997115135,-0.00306086795030598,-0.000535810136434221,0.25,-2.37878184334687E-7,-0.000269239544137327,-6.4681429027079E-7,150.0067902,150.0067902,87923.3203125,87933.0703125,57.0846756449868,20.617988707438,22.149702,0,0,0,40,4449,149.8275,87928.1953125,,,,,,,,,,,,,0,,,,0.00245,,,,,,150.0067902,,,,
,30988348.565,150.0025635,83262.265625,-0.000243286503196988,2.73907432240006E-6,1,0.999253354069792,40.0298881530762,2.00866480045976,15.7399997115135,-0.00277959633821351,-0.000484325455725881,0.25,-2.38550241743966E-8,-0.000244482082982659,-3.95497785593165E-7,150.0025635,150.0025635,83259.6875,83264.84375,56.9447641400445,20.6154970304959,21.770052,0,0,0,40,4449,149.8256,83262.265625,,,,,,,,,,,,,0,,,,0,,,,,,150.0025635,,,,
,30988445.455,149.9968109,78420.6640625,-0.000222696414388896,2.41110269038889E-6,1,0.999253354069792,40.0298881530762,2.00857320178552,15.7399997115135,-0.0025442239649926,-0.000443393382534272,0.25,-2.745704458798E-8,-0.0002237905885413,-3.68849262572472E-7,149.9968109,149.9968109,78410.6640625,78430.6640625,56.9517987967176,20.6180931145659,21.770052,0,0,0,40,4449,149.82705,78420.6640625,,,,,,,,,,,,,0,,,,-0.0049,,,,,,149.9968109,,,,
,30988539.455,149.99227145,73719.54296875,-0.000206150193801567,2.03820283307955E-6,1,0.999253354069792,40.0298881530762,2.00867649138832,15.7399997115135,-0.00235419352063876,-0.000416839183618392,0.25,-5.81910402810808E-7,-0.000207162023542756,-9.017057255051E-7,149.9921265,149.9924164,73711.9921875,73727.09375,57.0674798175637,20.6182761787293,22.149702,0,0,0,40,4449,149.83385,73719.54296875,,,,,,,,,,,,,0,,,,-0.00245,,,,,,149.99227145,,,,
,30988635.205,149.9950714,68931.96484375,-0.000187899347753794,1.72790721324698E-6,1,0.999253354069792,40.0298881530762,2.00848939249719,15.7399997115135,-0.00215028319254053,-0.000352893015708141,0.25,1.83466754811797E-6,-0.000188825026182873,1.55384386187577E-6,149.9950714,149.9950714,68919.5078125,68944.421875,57.0964000727753,20.622081051647,22.529354,0,0,0,40,4449,149.8397,68931.96484375,,,,,,,,,,,,,0,,,,0.00245,,,,,,149.9950714,,,,
,30988732.05,149.9917603,64093.537109375,-0.000163171665941364,2.32392035154091E-6,1,0.999253354069792,40.0298881530762,2.00855072862491,15.7399997115135,-0.00186841771089359,-0.000300370905872891,0.25,2.12709664441164E-6,-0.000163976195677442,1.88501060328839E-6,149.9917603,149.9917603,64086.1328125,64100.94140625,56.9572701963522,20.6212464081296,21.770052,0,0,0,40,4449,149.84325,64093.537109375,,,,,,,,,,,,,0,,,,-0.0049,,,,,,149.9917603,,,,
,30988830.29,149.9919586,59183.037109375,-0.000144281330771978,1.86172433751891E-6,1,0.999253354069792,40.0298881530762,2.00854962025237,15.7399997115135,-0.00165160874948916,-0.000268468991075632,0.25,1.6301523276831E-6,-0.000144992184359725,1.41413154455744E-6,149.9919586,149.9919586,59172.94140625,59193.1328125,57.0768593597945,20.6248408314509,22.909004,0,0,0,40,4449,149.8554,59183.037109375,,,,,,,,,,,,,0,,,,-0.0049,,,,,,149.9919586,,,,
,30988926.03,149.9916534,54395.13671875,-0.000125438079308432,2.11592408773037E-6,1,0.999253354069792,40.0298881530762,2.00843654754434,15.7399997115135,-0.00143161677916023,-0.000257577421738259,0.25,-6.99022601838381E-7,-0.000126052673667851,-8.97840298001359E-7,149.9916534,149.9916534,54385.2734375,54405,56.9979148793522,20.6251137714194,21.770052,0,0,0,40,4449,149.86185,54395.13671875,,,,,,,,,,,,,0,,,,-0.00245,,,,,,149.9916534,,,,
,30989022.28,149.990097,49587.455078125,-0.000107552903579986,2.18059177156831E-6,1,0.999253354069792,40.0298881530762,2.0085239948101,15.7399997115135,-0.00122685273796327,-0.000224829983924107,0.25,-9.46283463680584E-7,-0.000108079215005446,-1.11897992360029E-6,149.990097,149.990097,49577.42578125,49597.484375,56.9455457685637,20.6256210138449,22.149702,0,0,0,40,4449,149.8705,49587.455078125,,,,,,,,,,,,,0,,,,-0.00245,,,,,,149.990097,,,,
,30989117.265,149.9930725,44840.048828125,-8.94629399559664E-5,1.75919063021866E-6,1,0.999253354069792,40.0298881530762,2.00860405464451,15.7399997115135,-0.00102201148757035,-0.000178565952134488,0.25,-4.66081902282973E-8,-8.99017851530972E-5,-1.87051220270102E-7,149.9930725,149.9930725,44830.13671875,44849.9609375,56.9056827140829,20.6280587442164,22.529354,0,0,0,40,4449,149.8773,44840.048828125,,,,,,,,,,,,,0,,,,0.00245,,,,,,149.9930725,,,,
,30989214.935,149.9908447,39956.759765625,-6.79183484312739E-5,2.08456180123351E-6,1,0.999253354069792,40.0298881530762,2.00863034649676,15.7399997115135,-0.000776387028942401,-0.000132758491421303,0.25,2.10590236836487E-7,-6.82518299522616E-5,1.04846456798288E-7,149.9908447,149.9908447,39951.48828125,39962.03125,57.1432977839291,20.6289699935651,21.770052,0,0,0,40,4449,149.88375,39956.759765625,,,,,,,,,,,,,0,,,,-0.0049,,,,,,149.9908447,,,,
,30989312.565,149.9904938,35076.99609375,-4.88330844302469E-5,1.66726678726637E-6,1,0.999253354069792,40.0298881530762,2.00856138199364,15.7399997115135,-0.00055764056118501,-9.86674610651623E-5,0.25,-1.30006385302656E-7,-4.90723641850833E-5,-2.07646034670245E-7,149.9904938,149.9904938,35074.6328125,35079.359375,57.0291800201214,20.6294871155772,22.529354,0,0,0,40,4449,149.89295,35076.99609375,,,,,,,,,,,,,0,,,,-0.00245,,,,,,149.9904938,,,,
,30989407.715,149.9910126,30322.158203125,-2.91624971942922E-5,1.33362546492625E-6,1,0.999253354069792,40.0298881530762,2.00867334624972,15.7399997115135,-0.000337466089379209,-3.34787103802146E-5,0.25,2.14978892194357E-6,-2.93088850167053E-5,2.11421378748084E-6,149.9910126,149.9910126,30317.248046875,30327.068359375,56.8947399148137,20.6290914085893,22.149702,0,0,0,40,4449,149.90095,30322.158203125,,,,,,,,,,,,,0,,,,-0.0049,,,,,,149.9910126,,,,
,30989504.635,149.9923096,25479.671875,-1.08793007327502E-5,1.00476672833237E-6,1,0.999253354069792,40.0298881530762,2.00891978943635,15.7399997115135,-0.000126248574176851,-1.05418985985744E-5,0.25,9.72617103594342E-7,-1.09341750274407E-5,9.60132562524044E-7,149.9923096,149.9923096,25474.71484375,25484.62890625,57.075296102756,20.629909350753,22.149702,0,0,0,40,4449,149.9089,25479.671875,,,,,,,,,,,,,0,,,,-0.0049,,,,,,149.9923096,,,,
,30989599.555,149.9916687,20732.37890625,6.14918948538222E-6,8.65325460926977E-7,1,0.999253354069792,40.0298881530762,2.00862442019473,15.7399997115135,6.78183111680206E-5,2.62195733391833E-5,0.25,1.22372040277711E-6,6.17738229463454E-6,1.23949573633437E-6,149.9913025,149.9920349,20727.416015625,20737.341796875,56.7618630665445,20.6277873804025,22.909004,0,0,0,40,4449,149.915,20732.37890625,,,,,,,,,,,,,0,,,,0,,,,,,149.9916687,,,,
,30989694.615,149.9922485,15982.2348632812,2.2786500727325E-5,6.52256544331212E-7,1,0.999253354069792,40.0298881530762,2.00845618371766,15.7399997115135,0.000263768098294693,2.55122027936296E-5,0.25,-1.73643626593881E-6,2.29009301980979E-5,-1.70862187572918E-6,149.9922485,149.9922485,15974.6875,15989.7822265625,57.1182856713137,20.627982451231,22.149702,0,0,0,40,4449,149.92545,15982.2348632812,,,,,,,,,,,,,0,,,,0.0049,,,,,,149.9922485,,,,
,30989792.24,149.992157,11104.939453125,3.86212902876193E-5,6.46596842426862E-7,1,0.999253354069792,40.0298881530762,2.00839376562976,15.7399997115135,0.000443118978032317,6.58170089191205E-5,0.25,-9.66914847249002E-7,3.88120586693482E-5,-9.09931611303597E-7,149.992157,149.992157,11102.3896484375,11107.4892578125,57.6138381525061,20.6287254326711,22.149702,0,0,0,40,4449,149.9279,11104.939453125,,,,,,,,,,,,,0,,,,-0.00245,,,,,,149.992157,,,,
,30989888.55,149.9918518,6289.60668945313,4.89237408599749E-5,4.44426328377011E-7,1,0.999253354069792,40.0298881530762,2.00854427973533,15.7399997115135,0.00056028958578173,8.95425934996632E-5,0.25,-6.85598712471581E-7,4.91644992597275E-5,-6.10592281275154E-7,149.9918518,149.9918518,6279.8203125,6299.39306640625,57.2136443506599,20.6303339029071,22.529354,0,0,0,40,4449,149.92775,6289.60668945313,,,,,,,,,,,,,0,,,,0,,,,,,149.9918518,,,,
,30989984.325,149.9924011,1501.119140625,5.34181540337151E-5,3.0586196444906E-7,1,0.999253354069792,40.0298881530762,2.00866266367248,15.7399997115135,0.000611024321282906,0.000102197394367949,0.25,-3.61563524374691E-7,5.3680375696411E-5,-2.77614487882108E-7,149.9924011,149.9924011,1496.07873535156,1506.15954589844,56.9908802226791,20.6288900196283,22.529354,0,0,0,40,4449,149.93915,1501.119140625,,,,,,,,,,,,,0,,,,0,,,,,,149.9924011,,,,
,30990078.98,149.995697,-3224.12243652344,3.65456451751862E-5,3.48203108715675E-7,1,0.999253354069792,40.0298881530762,2.00860321510193,15.7399997115135,0.000417134539459583,7.4975961181486E-5,0.25,1.95606624154275E-7,3.67243373819416E-5,2.55168095779756E-7,149.995697,149.995697,-3231.69848632812,-3216.54638671875,57.0760777312753,20.6329075462749,22.529354,0,0,0,40,4449,149.9464,-3224.12243652344,,,,,,,,,,,,,0,,,,-0.00245,,,,,,149.995697,,,,
,30990174.695,149.9991608,-8011.30712890625,3.25186351994025E-6,4.09910594114339E-7,1,0.999253354069792,40.0298881530762,2.0086182688277,15.7399997115135,3.8316324294879E-5,-2.10960454290057E-7,0.25,-5.84995353062847E-7,3.26872981956853E-6,-5.82657226794045E-7,149.9991608,149.9991608,-8016.34228515625,-8006.27197265625,57.1456426694868,20.6342119858385,22.529354,0,0,0,40,4449,149.94255,-8011.30712890625,,,,,,,,,,,,,0,,,,-0.00245,,,,,,149.9991608,,,,
,30990271.46,150.0047607,-12846.7543945313,-1.81447225958522E-5,7.47683713197926E-7,1,0.999253354069792,40.0298881530762,2.00850040517649,15.7399997115135,-0.000204527618286325,-5.19620887203913E-5,0.25,-1.387373938977E-6,-1.82314067406507E-5,-1.42313953854315E-6,150.0047607,150.0047607,-12854.23046875,-12839.2783203125,57.0995265868522,20.6347785704835,22.529354,0,0,0,40,4449,149.9389,-12846.7543945313,,,,,,,,,,,,,0,,,,0,,,,,,150.0047607,,,,
,30990366.865,150.0098114,-17617.0859375,-1.30483806964953E-5,7.75874943152903E-7,1,0.999253354069792,40.0298881530762,2.00857632759797,15.7399997115135,-0.000146244887451949,-4.22027862091814E-5,0.25,-1.42087168430654E-6,-1.31100568884858E-5,-1.44861543937474E-6,150.0098114,150.0098114,-17627.04296875,-17607.12890625,56.8587850029291,20.6327330570684,21.770052,0,0,0,40,4449,149.92755,-17617.0859375,,,,,,,,,,,,,0,,,,-0.00245,,,,,,150.0098114,,,,
,30990463.64,150.011673,-22451.9130859375,5.17774618447773E-7,8.39562011006453E-7,1,0.999253354069792,40.0298881530762,2.00874339352837,15.7399997115135,8.61629003684801E-6,-1.4470892948556E-5,0.25,-1.35673734869544E-6,5.22467360669529E-7,-1.3625642832543E-6,150.011673,150.011673,-22454.36328125,-22449.462890625,56.9783741663714,20.6336165335513,21.770052,0,0,0,40,4449,149.9181,-22451.9130859375,,,,,,,,,,,,,0,,,,-0.0049,,,,,,150.011673,,,,
,30990559.97,150.0134277,-27266.9873046875,1.85665772107664E-5,1.39755102728631E-6,1,0.999253354069792,40.0298881530762,2.00873956343026,15.7399997115135,0.000209621461087055,5.13725904515201E-5,0.25,1.26198336807547E-6,1.86555893843694E-5,1.29758308262738E-6,150.0134277,150.0134277,-27276.97265625,-27257.001953125,57.1815975813714,20.6290706941313,22.149702,0,0,0,40,4449,149.90265,-27266.9873046875,,,,,,,,,,,,,0,,,,-0.00245,,,,,,150.0134277,,,,
,30990658.125,150.0130005,-32171.701171875,3.7256984671595E-5,1.32990002676456E-6,1,0.999253354069792,40.0298881530762,2.00859150817736,15.7399997115135,0.000424869439656601,7.86400341111176E-5,0.25,3.93280151959358E-7,3.74390303711689E-5,4.54063664155584E-7,150.0130005,150.0130005,-32179.212890625,-32164.189453125,57.1761261817368,20.6356585533415,21.770052,0,0,0,40,4449,149.8907,-32171.701171875,,,,,,,,,,,,,0,,,,0,,,,,,150.0130005,,,,
,30990756.22,150.01297,-37073.427734375,5.64368928104829E-5,1.40061027010325E-6,1,0.999253354069792,40.0298881530762,2.00877936380886,15.7399997115135,0.000648705580881714,9.01140606758732E-5,0.25,-1.94392246049707E-6,5.67167151531374E-5,-1.86456074305711E-6,150.01297,150.01297,-37081.05859375,-37065.796875,57.1276652135445,20.6324527032666,22.149702,0,0,0,40,4449,149.8768,-37073.427734375,,,,,,,,,,,,,0,,,,-0.00245,,,,,,150.01297,,,,
,30990853.19,150.0139008,-41923.326171875,7.68533979352055E-5,1.32763548016903E-6,1,0.999253354069792,40.0298881530762,2.00891315265639,15.7399997115135,0.000883564587842297,0.000121988567789265,0.25,-2.71093219086815E-6,7.72346119979102E-5,-2.60353592806693E-6,150.0139008,150.0139008,-41933.29296875,-41913.359375,57.0377779338329,20.6337679581538,22.529354,0,0,0,40,4449,149.8651,-41923.326171875,,,,,,,,,,,,,0,,,,0.00245,,,,,,150.0139008,,,,
,30990953.68,150.0152283,-46943.49609375,9.69836910283132E-5,1.39372143376183E-6,1,0.999253354069792,40.0298881530762,2.00886571112542,15.7399997115135,0.00110877953080892,0.000189497888928248,0.25,-3.08413494214637E-7,9.74599665349765E-5,-1.58096595040563E-7,150.0152283,150.0152283,-46950.859375,-46936.1328125,56.983845566006,20.6323646571908,22.149702,0,0,0,40,4449,149.8514,-46943.49609375,,,,,,,,,,,,,0,,,,-0.00245,,,,,,150.0152283,,,,
,30991051.585,150.0134583,-51835.455078125,0.000113918229406555,1.6687058877497E-6,1,0.999253354069792,40.0298881530762,2.00878523846837,15.7399997115135,0.00130278416763682,0.000220014638254127,0.25,-5.86081645872798E-7,0.000114478141721079,-4.11174024056834E-7,150.0134583,150.0134583,-51843.1640625,-51827.74609375,57.1722180391407,20.6351072634633,22.149702,0,0,0,40,4449,149.8403,-51835.455078125,,,,,,,,,,,,,0,,,,0,,,,,,150.0134583,,,,
,30991147.15,150.013443,-56610.46875,0.00013619454149707,1.75396545685176E-6,1,0.999253354069792,40.0298881530762,2.00883823248189,15.7399997115135,0.00155840976166564,0.000258279356866271,0.25,-1.11708554557874E-6,0.000136864727043809,-9.10671122131912E-7,150.013443,150.013443,-56620.34765625,-56600.58984375,57.1581487257945,20.6348759595003,22.149702,0,0,0,40,4449,149.82535,-56610.46875,,,,,,,,,,,,,0,,,,0,,,,,,150.013443,,,,
,30991247.055,150.0138245,-61604.82421875,0.000156169141135407,1.89630818590627E-6,1,0.999253354069792,40.0298881530762,2.00891057014799,15.7399997115135,0.00178802510081764,0.000290472699478619,0.25,-1.77868811735847E-6,0.000156938553454578,-1.54525083923398E-6,150.0138245,150.0138245,-61612.30078125,-61597.34765625,57.0706063316407,20.63533790791,22.149702,0,0,0,40,4449,149.81625,-61604.82421875,,,,,,,,,,,,,0,,,,0,,,,,,150.0138245,,,,
,30991344.93,150.0099487,-66497.37109375,0.000174015349540231,2.21477953990336E-6,1,0.999253354069792,40.0298881530762,2.00899743872162,15.7399997115135,0.00199184194259429,0.000327090166586426,0.25,-1.68264850704917E-6,0.000174872421809195,-1.42195545840321E-6,150.0099487,150.0099487,-66504.78125,-66489.9609375,57.166746639506,20.6376236950385,22.909004,0,0,0,40,4449,149.8072,-66497.37109375,,,,,,,,,,,,,0,,,,0,,,,,,150.0099487,,,,
,30991442.5,150.0105438,-71371.93359375,0.000196635097423127,2.30141073564256E-6,1,0.999253354069792,40.0298881530762,2.0090366792077,15.7399997115135,0.00225544686224385,0.000342931949236637,0.25,-4.23537561310128E-6,0.000197607374869948,-3.95327096815227E-6,150.0105438,150.0105438,-71376.9609375,-71366.90625,57.1198489283522,20.6388588031639,22.529354,0,0,0,40,4449,149.7989,-71371.93359375,,,,,,,,,,,,,0,,,,0,,,,,,150.0105438,,,,
,30991540.8,150.012619,-76284.01953125,0.000215797799614731,2.08674482118912E-6,1,0.999253354069792,40.0298881530762,2.00887837061466,15.7399997115135,0.0024743665726936,0.000380325252588621,0.25,-4.29682775606745E-6,0.000216864488075138,-3.98662267304696E-6,150.012619,150.012619,-76289.1171875,-76278.921875,56.9799374234099,20.640944568281,22.149702,0,0,0,40,4449,149.7864,-76284.01953125,,,,,,,,,,,,,0,,,,0,,,,,,150.012619,,,,
,30991641.27,150.0132065,-81306.4296875,0.000236661308614904,2.58529661275733E-6,1,0.999253354069792,40.0298881530762,2.00892504664842,15.7399997115135,0.00270988162644523,0.000438762404563329,0.25,-2.81569460696529E-6,0.000237828457650679,-2.46743085266347E-6,150.0131531,150.0132599,-81316.28125,-81296.578125,56.9557069393137,20.6423759440865,22.529354,0,0,0,40,4449,149.7706,-81306.4296875,,,,,,,,,,,,,0,,,,-0.0049,,,,,,150.0132065,,,,
,30991736.975,150.0121307,-86088.27734375,0.000256054016845476,1.90591730739481E-6,1,0.999253354069792,40.0298881530762,2.00915442684778,15.7399997115135,0.00293012364544872,0.000487032991028128,0.25,-1.9718544984225E-6,0.00025731544060728,-1.59111654719836E-6,150.0121307,150.0121307,-86098.0546875,-86078.5,56.9275683126214,20.641629999129,22.909004,0,0,0,40,4449,149.76955,-86088.27734375,,,,,,,,,,,,,0,,,,-0.00245,,,,,,150.0121307,,,,
,30991852.625,150.0092316,-89141.78125,0.000266510855844626,2.10431993919818E-6,1,0.999253354069792,40.0298881530762,2.00907627570005,15.7399997115135,0.00305512098780996,0.000475625776733511,0.25,-4.78862940062044E-6,0.000267828149028183,-4.40663390603406E-6,150.0092316,150.0092316,-89146.9296875,-89136.6328125,57.0995265868522,20.6440553536062,22.149702,0,0,0,40,4449,149.75415,-89141.78125,,,,,,,,,,,,,0,,,,0.00245,,,,,,150.0092316,,,,
,30991948.385,150.00191495,-84357.92578125,0.000257776872470666,2.90764377577249E-6,1,0.999253354069792,40.0298881530762,2.008841779969,15.7399997115135,0.00294767142916856,0.000500167847636691,0.25,-1.11656783830896E-6,0.000259045419880601,-7.28446741781793E-7,150.00177,150.0020599,-84365.5,-84350.3515625,56.9385111118906,20.6413376952882,22.529354,0,0,0,40,4449,149.7525,-84357.92578125,,,,,,,,,,,,,0,,,,0,,,,,,150.00191495,,,,
,30992047.185,149.9986267,-79418.14453125,0.000228618075929681,2.01746041781058E-6,1,0.999253354069792,40.0298881530762,2.00897292963551,15.7399997115135,0.00261600127213511,0.000434431734849682,0.25,-1.79537736785497E-6,0.000229744131737916,-1.45388717949161E-6,149.9986267,149.9986267,-79423.546875,-79412.7421875,57.1346998702176,20.6450749795673,22.529354,0,0,0,40,4449,149.7562,-79418.14453125,,,,,,,,,,,,,0,,,,0,,,,,,149.9986267,,,,
,30992145.395,149.9956055,-74510.98828125,0.000210364515456906,2.25684784272283E-6,1,0.999253354069792,40.0298881530762,2.00896081570761,15.7399997115135,0.00240528085349588,0.000410278016661359,0.25,-7.31163177322247E-7,0.00021139903980522,-4.1130331118625E-7,149.9956055,149.9956055,-74515.859375,-74506.1171875,56.9869720800829,20.6432032830619,22.529354,0,0,0,40,4449,149.7616,-74510.98828125,,,,,,,,,,,,,0,,,,0,,,,,,149.9956055,,,,
,30992242.655,149.9920502,-69651.6640625,0.0001866864290712,2.15902220732508E-6,1,0.999253354069792,40.0298881530762,2.00892054780198,15.7399997115135,0.00213908464944465,0.000337799576606307,0.25,-2.95068214669407E-6,0.000187607879817531,-2.67717056572073E-6,149.9920502,149.9920502,-69654.1875,-69649.140625,57.2058280654676,20.6496145240325,22.909004,0,0,0,40,4449,149.7707,-69651.6640625,,,,,,,,,,,,,0,,,,0,,,,,,149.9920502,,,,
,30992340.915,149.9911041,-64742.1640625,0.000169638383617246,2.45201034480734E-6,1,0.999253354069792,40.0298881530762,2.00873123691908,15.7399997115135,0.00194675044510337,0.000288655257485495,0.25,-4.28103684787251E-6,0.000170477995803445,-4.03947468692786E-6,149.9911041,149.9911041,-64752.19921875,-64732.12890625,57.1581487257945,20.6497781526147,22.529354,0,0,0,40,4449,149.77715,-64742.1640625,,,,,,,,,,,,,0,,,,0,,,,,,149.9911041,,,,
,30992437.015,149.9925232,-59936.919921875,0.000146901015635019,1.70706662497287E-6,1,0.999253354069792,40.0298881530762,2.00891072996733,15.7399997115135,0.00168725083178311,0.000242581299703207,0.25,-4.3560384933057E-6,0.000147628954119597,-4.14929913715652E-6,149.9925232,149.9925232,-59944.32421875,-59929.515625,57.1448610409676,20.6506647316995,22.149702,0,0,0,40,4449,149.78515,-59936.919921875,,,,,,,,,,,,,0,,,,0,,,,,,149.9925232,,,,
,30992534.235,149.9919128,-55077.1875,0.000125839222932144,1.37415341363903E-6,1,0.999253354069792,40.0298881530762,2.0086878375105,15.7399997115135,0.00144208445745659,0.000225601472468737,0.25,-2.17225307465459E-6,0.000126460249093186,-1.98685976551406E-6,149.9919128,149.9919128,-55087.1953125,-55067.1796875,57.0119841926983,20.6463002553852,22.529354,0,0,0,40,4449,149.7895,-55077.1875,,,,,,,,,,,,,0,,,,0,,,,,,149.9919128,,,,
,30992631.52,149.9913483,-50218.111328125,0.000106949979972525,1.90371408136947E-6,1,0.999253354069792,40.0298881530762,2.00886211081758,15.7399997115135,0.00122701476968674,0.00018431332600187,0.25,-2.49780737816378E-6,0.000107478702396278,-2.3429122203117E-6,149.9913483,149.9913483,-50225.5703125,-50210.65234375,56.9392927404099,20.6452975661325,22.529354,0,0,0,40,4449,149.8,-50218.111328125,,,,,,,,,,,,,0,,,,-0.00245,,,,,,149.9913483,,,,
,30992728.025,149.9927063,-45395.669921875,8.72574278557502E-5,1.9117574047954E-6,1,0.999253354069792,40.0298881530762,2.00860326618998,15.7399997115135,0.000996002370878615,0.000178832431179356,0.25,4.54064769221048E-7,8.76848062616225E-5,5.93088671610988E-7,149.9927063,149.9927063,-45403.1953125,-45388.14453125,57.0612267894099,20.6423181352719,22.529354,0,0,0,40,4449,149.80945,-45395.669921875,,,,,,,,,,,,,0,,,,0.0049,,,,,,149.9927063,,,,
,30992825.575,149.990097,-40517.74609375,6.71509129734573E-5,1.63574001599303E-6,1,0.999253354069792,40.0298881530762,2.00862315806968,15.7399997115135,0.000767546186381273,0.000131633814931229,0.25,-1.75341356018615E-7,6.74805697207947E-5,-7.06013779934517E-8,149.990097,149.990097,-40520.28515625,-40515.20703125,56.9697762526599,20.6462450549769,22.529354,0,0,0,40,4449,149.8165,-40517.74609375,,,,,,,,,,,,,0,,,,0.00245,,,,,,149.990097,,,,
,30992920.51,149.9920654,-35772.9921875,4.86967798006145E-5,1.3236225936814E-6,1,0.999253354069792,40.0298881530762,2.00866197485683,15.7399997115135,0.000559446558016271,7.92455453292266E-5,0.25,-1.54660468589432E-6,4.89380293342948E-5,-1.47738401864965E-6,149.9920654,149.9920654,-35778.16015625,-35767.82421875,57.2230238928907,20.6430498930503,22.909004,0,0,0,40,4449,149.8228,-35772.9921875,,,,,,,,,,,,,0,,,,0,,,,,,149.9920654,,,,
,30993015.865,149.9883423,-31006.1201171875,3.17852413889372E-5,1.22910631371621E-6,1,0.999253354069792,40.0298881530762,2.00852465126917,15.7399997115135,0.000366404190946749,4.4444260306341E-5,0.25,-1.64663265594552E-6,3.194369387504E-5,-1.60443225619904E-6,149.9883423,149.9883423,-31016.330078125,-30995.91015625,56.9564885678329,20.6454323629543,22.529354,0,0,0,40,4449,149.83525,-31006.1201171875,,,,,,,,,,,,,0,,,,-0.00245,,,,,,149.9883423,,,,
,30993111.63,149.9902954,-26223.5546875,1.43394987502607E-5,1.23815069869483E-6,1,0.999253354069792,40.0298881530762,2.00855118054331,15.7399997115135,0.000166164853735572,1.50885879648944E-5,0.25,-1.17725846456865E-6,1.44116601122102E-5,-1.16028504366433E-6,149.9902954,149.9902954,-26228.54296875,-26218.56640625,57.0104209356599,20.6424254459066,22.909004,0,0,0,40,4449,149.8412,-26223.5546875,,,,,,,,,,,,,0,,,,-0.0049,,,,,,149.9902954,,,,
,30993207.535,149.9911652,-21428.5693359375,-3.53573830371352E-6,9.10281020398134E-7,1,0.999253354069792,40.0298881530762,2.00847356553263,15.7399997115135,-3.84435620926657E-5,-1.82244805010344E-5,0.25,-9.79318653044782E-7,-3.55151003189131E-6,-9.89741745835966E-7,149.9911652,149.9911652,-21431.087890625,-21426.05078125,57.2238055214099,20.6375796979005,22.149702,0,0,0,40,4449,149.8512,-21428.5693359375,,,,,,,,,,,,,0,,,,0,,,,,,149.9911652,,,,
,30993304.765,149.9928284,-16571.9033203125,-1.97867297537494E-5,6.53850022669905E-7,1,0.999253354069792,40.0298881530762,2.00854268614614,15.7399997115135,-0.000223751454337647,-5.25876100191387E-5,0.25,-1.15600913847154E-6,-1.98818451061236E-5,-1.19322667845783E-6,149.9928284,149.9928284,-16579.451171875,-16564.35546875,57.0698247031214,20.6397949849233,22.149702,0,0,0,40,4449,149.85575,-16571.9033203125,,,,,,,,,,,,,0,,,,0.00245,,,,,,149.9928284,,,,
,30993401.585,149.990448,-11731.8129882812,-3.58259923961487E-5,7.37185409018623E-7,1,0.999253354069792,40.0298881530762,2.00868944130055,15.7399997115135,-0.000406339808255891,-8.8414211212408E-5,0.25,-1.49707904637765E-6,-3.59991251301512E-5,-1.56168344370404E-6,149.990448,149.990448,-11736.7470703125,-11726.87890625,57.1644017539484,20.6383581355804,22.149702,0,0,0,40,4449,149.86625,-11731.8129882812,,,,,,,,,,,,,0,,,,0.00245,,,,,,149.990448,,,,
,30993498.065,149.9908905,-6908.52978515625,-4.7402349429388E-5,4.71844341269787E-7,1,0.999253354069792,40.0298881530762,2.00862732709764,15.7399997115135,-0.000540707349186787,-9.92754579308404E-5,0.25,-4.31030090704093E-7,-4.76338632425229E-5,-5.09089173344604E-7,149.9908905,149.9908905,-6918.63232421875,-6898.42724609375,56.770460980256,20.6375611186894,22.529354,0,0,0,40,4449,149.8724,-6908.52978515625,,,,,,,,,,,,,0,,,,0.0049,,,,,,149.9908905,,,,
,30993594.575,149.9944916,-2082.68579101562,-5.30010781041687E-5,3.40708457444805E-7,1,0.999253354069792,40.0298881530762,2.00870626921885,15.7399997115135,-0.000604925689987093,-0.000109094782650478,0.25,-3.14578055879768E-7,-5.32601609865907E-5,-4.01203911494474E-7,149.9944916,149.9944916,-2085.24536132813,-2080.12622070313,57.2042648084291,20.6372689855875,22.909004,0,0,0,40,4449,149.87685,-2082.68579101562,,,,,,,,,,,,,0,,,,-0.0049,,,,,,149.9944916,,,,
,30993688.35,149.9933014,2597.89733886719,-3.93923702156473E-5,3.15425200827885E-7,1,0.999253354069792,40.0298881530762,2.00870700939769,15.7399997115135,-0.000449473915616058,-8.18269042092947E-5,0.25,-2.98903993142707E-7,-3.95848309146755E-5,-3.63589558526453E-7,149.9933014,149.9933014,2593.052734375,2602.74194335938,57.0940551872176,20.6338419981891,22.529354,0,0,0,40,4449,149.8847,2597.89733886719,,,,,,,,,,,,,0,,,,0.00245,,,,,,149.9933014,,,,
,30993783.905,149.9983673,7375.068359375,-7.6218565225074E-6,4.40638276507953E-7,1,0.999253354069792,40.0298881530762,2.00874281324466,15.7399997115135,-8.69100156656578E-5,-1.61669285876988E-5,0.25,-8.71190746905302E-8,-7.65905249935058E-6,-9.97538165165613E-8,149.9983673,149.9983673,7367.4619140625,7382.6748046875,57.1206305568714,20.6364767468816,22.909004,0,0,0,40,4449,149.8813,7375.068359375,,,,,,,,,,,,,0,,,,0.00245,,,,,,149.9983673,,,,
,30993879.945,150.00384525,12178.4614257813,1.6830105722604E-5,6.08572424799742E-7,1,0.999253354069792,40.0298881530762,2.00843370911931,15.7399997115135,0.00019060087005919,4.30428377362394E-5,0.25,8.35759602407448E-7,1.69112232360875E-5,8.66748841246262E-7,150.00383,150.0038605,12165.853515625,12191.0693359375,56.9119357422368,20.6372720477214,22.149702,0,0,0,40,4449,149.8773,12178.4614257813,,,,,,,,,,,,,0,,,,-0.00245,,,,,,150.00384525,,,,
,30993976.055,150.0048065,16980.9873046875,1.51826728984324E-5,9.14922087481642E-7,1,0.999253354069792,40.0298881530762,2.00853899944321,15.7399997115135,0.000172237761437745,3.71939248406713E-5,0.25,6.10668149079556E-7,1.52560943193153E-5,6.37862492003123E-7,150.0048065,150.0048065,16968.55078125,16993.423828125,57.0924919301791,20.6335046271065,22.529354,0,0,0,40,4449,149.8709,16980.9873046875,,,,,,,,,,,,,0,,,,-0.00245,,,,,,150.0048065,,,,
,30994072.57,150.00737,21805.564453125,1.63051424967787E-6,8.09692897527588E-7,1,0.999253354069792,40.0298881530762,2.00852828214895,15.7399997115135,1.57587779075256E-5,1.97130229033716E-5,0.25,1.44147716366557E-6,1.63621337405613E-6,1.45113389915231E-6,150.0071564,150.0075836,21800.52734375,21810.6015625,57.0721695886791,20.6325768816171,22.529354,0,0,0,40,4449,149.86465,21805.564453125,,,,,,,,,,,,,0,,,,0,,,,,,150.00737,,,,
,30994169.45,150.0112915,26645.767578125,-1.52911972375577E-5,8.12848753977144E-7,1,0.999253354069792,40.0298881530762,2.0086217488254,15.7399997115135,-0.000176757036747376,-1.86270239766839E-5,0.25,1.03336904626546E-6,-1.5367787986375E-5,1.01418890624681E-6,150.0112915,150.0112915,26643.19921875,26648.3359375,56.9049010855637,20.6333080122486,22.909004,0,0,0,40,4449,149.85225,26645.767578125,,,,,,,,,,,,,0,,,,-0.0049,,,,,,150.0112915,,,,
,30994267.34,150.0079346,31538.9609375,-3.16752912275182E-5,1.11756602803409E-6,1,0.999253354069792,40.0298881530762,2.00849522540746,15.7399997115135,-0.000364279696232655,-4.91796460256308E-5,0.25,1.2128983675884E-6,-3.18325049965107E-5,1.16876635935256E-6,150.0079346,150.0079346,31531.5859375,31546.3359375,57.027616763083,20.6329482963955,22.529354,0,0,0,40,4449,149.8463,31538.9609375,,,,,,,,,,,,,0,,,,0.00245,,,,,,150.0079346,,,,
,30994364.955,150.0106506,36418.951171875,-5.26055795837928E-5,1.64674915891992E-6,1,0.999253354069792,40.0298881530762,2.00851096839727,15.7399997115135,-0.000603095837836669,-9.25632498013251E-5,0.25,1.06121872520674E-6,-5.28652132868147E-5,9.83494966078754E-7,150.0106506,150.0106506,36409.11328125,36428.7890625,56.9674313671022,20.6283116360048,22.149702,0,0,0,40,4449,149.83415,36418.951171875,,,,,,,,,,,,,0,,,,0,,,,,,150.0106506,,,,
,30994462.55,150.013031,41296.205078125,-6.93716914060124E-5,1.70558765868598E-6,1,0.999253354069792,40.0298881530762,2.00859072378133,15.7399997115135,-0.000796522790418383,-0.000115287217864933,0.25,1.99272873658631E-6,-6.97150667184132E-5,1.89347526487554E-6,150.013031,150.013031,41291.2421875,41301.16796875,57.1128142716791,20.6345859813698,22.909004,0,0,0,40,4449,149.8269,41296.205078125,,,,,,,,,,,,,0,,,,-0.0049,,,,,,150.013031,,,,
,30994562.345,150.013504,46284.23046875,-8.94573593371646E-5,1.49524183190165E-6,1,0.999253354069792,40.0298881530762,2.00848574581935,15.7399997115135,-0.00102585399363707,-0.00015578620976208,0.25,1.94547197680331E-6,-8.98992566624424E-5,1.81485556265967E-6,150.013504,150.013504,46279.30078125,46289.16015625,57.1644017539484,20.6326740267982,22.149702,0,0,0,40,4449,149.81195,46284.23046875,,,,,,,,,,,,,0,,,,-0.0049,,,,,,150.013504,,,,
,30994658.16,150.0117035,51074.4453125,-0.000108146366121471,1.76147011603644E-6,1,0.999253354069792,40.0298881530762,2.00839265735835,15.7399997115135,-0.00124006347640193,-0.000188631058704151,0.25,2.32452976836208E-6,-0.000108680646031926,2.16701400251004E-6,150.0117035,150.0117035,51061.859375,51087.03125,57.1855057239676,20.6344806846009,22.529354,0,0,0,40,4449,149.80255,51074.4453125,,,,,,,,,,,,,0,,,,-0.00245,,,,,,150.0117035,,,,
,30994754.95,150.0101166,55911.921875,-0.000126280822157457,2.16629999081806E-6,1,0.999253354069792,40.0298881530762,2.00829697553032,15.7399997115135,-0.00144844827930999,-0.00021732429015458,0.25,2.96996471198505E-6,-0.000126905217299222,2.78792052191451E-6,150.0101166,150.0101166,55904.5859375,55919.2578125,57.1339182416984,20.6341221908999,22.149702,0,0,0,40,4449,149.79585,55911.921875,,,,,,,,,,,,,0,,,,0,,,,,,150.0101166,,,,
,30994852.6,150.0099792,60792.20703125,-0.000146625902679774,1.57555450171161E-6,1,0.999253354069792,40.0298881530762,2.00825411459064,15.7399997115135,-0.00167472401498378,-0.000292815642699696,0.25,-9.62612073313137E-8,-0.000147345532273206,-3.24301129426862E-7,150.0099792,150.0099792,60792.20703125,60792.20703125,57.2480360055061,20.6297837643075,22.149702,0,0,0,40,4449,149.7834,60792.20703125,,,,,,,,,,,,,0,,,,0.0049,,,,,,150.0099792,,,,
,30994947.575,150.0112915,65540.458984375,-0.000166398718858067,1.94336238232605E-6,1,0.999253354069792,40.0298881530762,2.00840349875626,15.7399997115135,-0.00190900900061664,-0.000284623046867914,0.25,4.06569009544556E-6,-0.000167222021192118,3.82822134216962E-6,150.0112915,150.0112915,65535.53515625,65545.3828125,57.0463758475445,20.6279668247918,22.529354,0,0,0,40,4449,149.77515,65540.458984375,,,,,,,,,,,,,0,,,,0,,,,,,150.0112915,,,,
,30995046.745,150.0101624,70495.62890625,-0.000190469553998189,2.47037077602328E-6,1,0.999253354069792,40.0298881530762,2.00835091349968,15.7399997115135,-0.00217408582033452,-0.000389083789296197,0.25,-8.87929208620227E-7,-0.000191403599919254,-1.18597499834115E-6,150.0101624,150.0101624,70488.03125,70503.2265625,56.8580033744099,20.6263948384945,22.529354,0,0,0,40,4449,149.76375,70495.62890625,,,,,,,,,,,,,0,,,,-0.00245,,,,,,150.0101624,,,,
,30995144.585,150.0097961,75385.671875,-0.000208865167775626,2.42170281723523E-6,1,0.999253354069792,40.0298881530762,2.0083554997543,15.7399997115135,-0.00239462245227327,-0.000366056061689493,0.25,4.33061855166638E-6,-0.00020989781268443,4.03092862001526E-6,150.0097961,150.0097961,75375.859375,75395.484375,56.6758839294291,20.6294743440758,22.909004,0,0,0,40,4449,149.7564,75385.671875,,,,,,,,,,,,,0,,,,0,,,,,,150.0097961,,,,
,30995242.22,150.0110321,80266.78515625,-0.000233466748943534,2.42414879940864E-6,1,0.999253354069792,40.0298881530762,2.00837714879531,15.7399997115135,-0.00267497997226006,-0.000419098103200164,0.25,3.97106476955743E-6,-0.000234619916982466,3.63302132208683E-6,150.0110321,150.0110321,80259.3046875,80274.265625,56.9134989992753,20.6290492422402,22.909004,0,0,0,40,4449,149.7471,80266.78515625,,,,,,,,,,,,,0,,,,0.0049,,,,,,150.0110321,,,,
,30995338.57,150.0102844,85082.66015625,-0.000252981731098288,2.73724041154707E-6,1,0.999253354069792,40.0298881530762,2.00834357479534,15.7399997115135,-0.00290041349488054,-0.000443321180249576,0.25,5.24725053779289E-6,-0.000254232988641395,4.88689962991738E-6,150.0102844,150.0102844,85077.78125,85087.5390625,56.7212183835445,20.6283196495795,22.529354,0,0,0,40,4449,149.73755,85082.66015625,,,,,,,,,,,,,0,,,,0,,,,,,150.0102844,,,,
,30995432.985,150.010849,89800.74609375,-0.000270049118845082,2.68430620496569E-6,1,0.999253354069792,40.0298881530762,2.00829907505185,15.7399997115135,-0.00307535169121897,-0.000591951373565804,0.25,-4.79375735864719E-6,-0.000271369233228098,-5.22813923044231E-6,150.010849,150.010849,89790.8984375,89810.59375,57.095618444256,20.6280362435374,22.149702,0,0,0,40,4449,149.7282,89800.74609375,,,,,,,,,,,,,0,,,,0,,,,,,150.010849,,,,
,30995543.955,150.0022125,85669.34375,-0.000248820593066073,2.65894914856095E-6,1,0.999253354069792,40.0298881530762,2.00848412545196,15.7399997115135,-0.00285775678856056,-0.000408155412512296,0.25,7.60322176605277E-6,-0.000250055076928149,7.26093195443797E-6,150.0022125,150.0022125,85659.4296875,85679.2578125,56.9752476522945,20.6267503792969,22.529354,0,0,0,40,4449,149.7285,85669.34375,,,,,,,,,,,,,0,,,,0,,,,,,150.0022125,,,,
,30995639.73,149.9999084,80883.328125,-0.000233546416577679,1.92052984104546E-6,1,0.999253354069792,40.0298881530762,2.008498018515,15.7399997115135,-0.00268417735303446,-0.000372580792294935,0.25,8.05867920556996E-6,-0.000234706327907163,7.74070579413413E-6,149.9999084,149.9999084,80875.9140625,80890.7421875,56.8994296859291,20.6288940009521,22.529354,0,0,0,40,4449,149.7312,80883.328125,,,,,,,,,,,,,0,,,,0,,,,,,149.9999084,,,,
,30995736.61,149.9928589,76037.11328125,-0.000211927050929259,2.50925392095398E-6,1,0.999253354069792,40.0298881530762,2.00842619260862,15.7399997115135,-0.00244127310117117,-0.000305610187331297,0.25,1.01559512370993E-5,-0.000212983804964883,9.88027298270352E-6,149.9928589,149.9928589,76032.5546875,76041.671875,56.9299131981791,20.6300051196794,22.909004,0,0,0,40,4449,149.73835,76037.11328125,,,,,,,,,,,,,0,,,,0.00245,,,,,,149.9928589,,,,
,30995836.15,149.9942627,71060.98828125,-0.000189394387214248,1.79443198556189E-6,1,0.999253354069792,40.0298881530762,2.00844841305783,15.7399997115135,-0.00217677991877464,-0.000301550205505627,0.25,6.588504314085E-6,-0.000190334776260604,6.32889740883373E-6,149.9941254,149.9944,71053.125,71068.8515625,56.841589175506,20.6273645958635,22.909004,0,0,0,40,4449,149.7433,71060.98828125,,,,,,,,,,,,,0,,,,0,,,,,,149.9942627,,,,
,30995933.555,149.9908142,66193.02734375,-0.000171506816552009,2.24988037791651E-6,1,0.999253354069792,40.0298881530762,2.00835744392904,15.7399997115135,-0.00195574889074139,-0.000361227538327783,0.25,-1.75104261593035E-6,-0.000172346312485689,-2.02491665450078E-6,149.9908142,149.9908142,66190.484375,66195.5703125,56.9275683126214,20.6275365967769,22.529354,0,0,0,40,4449,149.7503,66193.02734375,,,,,,,,,,,,,0,,,,0,,,,,,149.9908142,,,,
,30996030.61,149.9889069,61342.056640625,-0.00015479049337372,2.01958325867397E-6,1,0.999253354069792,40.0298881530762,2.00840836716641,15.7399997115135,-0.00176624080708612,-0.000319867166929797,0.25,-1.04037198158393E-6,-0.000155548836841134,-1.28568357484116E-6,149.9886475,149.9891663,61331.9609375,61352.15234375,57.0729512171983,20.6295134086486,22.529354,0,0,0,40,4449,149.7589,61342.056640625,,,,,,,,,,,,,0,,,,-0.00245,,,,,,149.9889069,,,,
,30996125.735,149.9898834,56586.791015625,-0.000133897728702509,1.919413136247E-6,1,0.999253354069792,40.0298881530762,2.00835866224597,15.7399997115135,-0.00152702169281477,-0.000281187551134446,0.25,-1.2933165325757E-6,-0.000134552954829861,-1.50810093967162E-6,149.9898834,149.9898834,56579.44921875,56594.1328125,57.3559007411599,20.632416565074,22.149702,0,0,0,40,4449,149.76975,56586.791015625,,,,,,,,,,,,,0,,,,0,,,,,,149.9898834,,,,
,30996221.375,149.9909973,51806.646484375,-0.000114478060431527,1.97479427725911E-6,1,0.999253354069792,40.0298881530762,2.00830552700085,15.7399997115135,-0.00130303444622307,-0.000254657468075339,0.25,-2.35332324753105E-6,-0.000115036178588091,-2.54364105827846E-6,149.9909973,149.9909973,51796.984375,51816.30859375,57.1354814987368,20.6312666176619,22.529354,0,0,0,40,4449,149.77615,51806.646484375,,,,,,,,,,,,,0,,,,0,,,,,,149.9909973,,,,
,30996317.465,149.9898376,47004.068359375,-9.92533926596506E-5,1.86343764640095E-6,1,0.999253354069792,40.0298881530762,2.00835254234005,15.7399997115135,-0.00113230544043144,-0.000206211318910464,0.25,-7.63262115070307E-7,-9.97391767180209E-5,-9.22478000770937E-7,149.9898376,149.9898376,46999.21484375,47008.921875,57.1432977839291,20.6326767209201,22.529354,0,0,0,40,4449,149.7877,47004.068359375,,,,,,,,,,,,,0,,,,0,,,,,,149.9898376,,,,
,30996415.415,149.990509,42108.888671875,-7.68937711081534E-5,1.46587143866296E-6,1,0.999253354069792,40.0298881530762,2.00847166086144,15.7399997115135,-0.000875893680134603,-0.000167669071388916,0.25,-1.28279585948903E-6,-7.72689476378801E-5,-1.40990634708379E-6,149.990509,149.990509,42106.33984375,42111.4375,57.2316218066022,20.6332668194253,22.529354,0,0,0,40,4449,149.79915,42108.888671875,,,,,,,,,,,,,0,,,,0.00245,,,,,,149.990509,,,,
,30996512.535,149.9883881,37253.974609375,-5.80522572683198E-5,1.18652137502609E-6,1,0.999253354069792,40.0298881530762,2.0083639052799,15.7399997115135,-0.00066052809209708,-0.000130643486535223,0.25,-1.32407688972842E-6,-5.83348809844779E-5,-1.42206336382706E-6,149.9883881,149.9883881,37248.859375,37259.08984375,57.0596635323714,20.6320513608665,22.529354,0,0,0,40,4449,149.80335,37253.974609375,,,,,,,,,,,,,0,,,,0.0049,,,,,,149.9883881,,,,
,30996608.475,149.9903412,32458.9833984375,-3.93552705640721E-5,1.77512505952257E-6,1,0.999253354069792,40.0298881530762,2.00818726035111,15.7399997115135,-0.000446183850645832,-9.75652696498591E-5,0.25,-1.68587937612845E-6,-3.95455781786465E-5,-1.75635006368093E-6,149.9903412,149.9903412,32451.173828125,32466.79296875,57.1550222117176,20.6401601158115,22.149702,0,0,0,40,4449,149.81485,32458.9833984375,,,,,,,,,,,,,0,,,,0,,,,,,149.9903412,,,,
,30996705.515,149.98825835,27609.328125,-2.03482423502851E-5,8.39365376489352E-7,1,0.999253354069792,40.0298881530762,2.00805956536769,15.7399997115135,-0.000229918789508683,-5.48150433450282E-5,0.25,-1.25444032720566E-6,-2.04460095529936E-5,-1.29284369544181E-6,149.9881744,149.9883423,27604.43359375,27614.22265625,57.3699700545061,20.6397024712884,22.529354,0,0,0,40,4449,149.8253,27609.328125,,,,,,,,,,,,,0,,,,0,,,,,,149.98825835,,,,
,30996799.455,149.9891205,22914.15625,-3.10944124795938E-6,9.045968913806E-7,1,0.999253354069792,40.0298881530762,2.00803707872952,15.7399997115135,-3.34460335833149E-5,-1.80644289776282E-5,0.25,-1.03990300261819E-6,-3.12302927738116E-6,-1.04994203691463E-6,149.9891205,149.9891205,22906.92578125,22921.38671875,57.2574155477368,20.6436534279956,22.529354,0,0,0,40,4449,149.83225,22914.15625,,,,,,,,,,,,,0,,,,-0.00245,,,,,,149.9891205,,,,
,30996896.185,149.9901276,18079.0771484375,1.39908180650373E-5,1.04732745266758E-6,1,0.999253354069792,40.0298881530762,2.00816468622297,15.7399997115135,0.000159970504402922,2.69108819836354E-5,0.25,-8.13675103688429E-8,1.4059509754564E-5,-5.94706566108619E-8,149.9901276,149.9901276,18074.287109375,18083.8671875,57.1206305568714,20.6405826301092,22.909004,0,0,0,40,4449,149.8393,18079.0771484375,,,,,,,,,,,,,0,,,,-0.0049,,,,,,149.9901276,,,,
,30996991.805,149.9897919,13299.0063476563,2.9677843005048E-5,5.60182825237324E-7,1,0.999253354069792,40.0298881530762,2.00821510324586,15.7399997115135,0.000338301930133908,6.30627627218808E-5,0.25,3.5055010006277E-7,2.9822693978976E-5,3.9967833709083E-7,149.9897919,149.9897919,13291.525390625,13306.4873046875,57.027616763083,20.637840180747,22.529354,0,0,0,40,4449,149.85025,13299.0063476563,,,,,,,,,,,,,0,,,,0.00245,,,,,,149.9897919,,,,
,30997087.685,149.9915314,8508.6650390625,4.39329948135271E-5,4.25374364528196E-7,1,0.999253354069792,40.0298881530762,2.00828001037261,15.7399997115135,0.000503269040118259,7.92612574955793E-5,0.25,-7.15171726187134E-7,4.41493572640686E-5,-6.48324824046536E-7,149.9915314,149.9915314,8503.890625,8513.439453125,57.187068981006,20.6425923525384,22.529354,0,0,0,40,4449,149.8521,8508.6650390625,,,,,,,,,,,,,0,,,,-0.00245,,,,,,149.9915314,,,,
,30997182.295,149.9906158,3778.12353515625,5.25851970128208E-5,3.61655714035158E-7,1,0.999253354069792,40.0298881530762,2.0083223093879,15.7399997115135,0.000600988077388474,0.000102948430345794,0.25,-1.49242187844655E-7,5.28430031634345E-5,-6.56007095329496E-8,149.9906158,149.9906158,3770.57983398438,3785.66723632812,57.220679007333,20.6411746634024,22.909004,0,0,0,40,4449,149.8646,3778.12353515625,,,,,,,,,,,,,0,,,,0,,,,,,149.9906158,,,,
,30997259.585,149.9919281,-0.28163979947567,5.03855721982863E-5,3.19947095982417E-7,1,0.999253354069792,40.0298881530762,2.00816380441636,15.7399997115135,0.000575577426499498,9.99425741133877E-5,0.25,-2.85927575145125E-8,5.06323870341448E-5,5.22096886751447E-8,149.9919281,149.9919281,-0.289251685142517,-0.274027913808823,56.6352392464291,20.6427928190628,22.909004,0,0,0,40,4417,149.8699,-0.28163979947567,,,,,,,,,,,,,0,,,,0,,,,,,149.9919281,,,,