File: data/doubleLayers/dl_5/ppms/data/DD205_6_HYST_100OE_250K.DAT
[Header]
; VSM Data File (default extension .dat)
; Copyright (c) 2003-2013, Quantum Design, Inc. All rights reserved.
TITLE,
FILEOPENTIME,31010759.08,12/26/2018,6:07 am
BYAPP,VSM,2.0,2.0
INFO,PPMS VSM Option Release 1.4.10 Build 1,APPNAME
INFO,Quantum Design Linear Motor Servo Controller,MOTOR_MODULE_NAME
INFO,3101-100 M1,MOTOR_HW_VERSION
INFO,MMC1014,MOTOR_SERIAL_NUMBER
INFO,SRV No X-over 01.03.11,MOTOR_SOFTWARE_VERSION
INFO,Quantum Design VSM Detection Module,VSM_MODULE_NAME
INFO,3101-150 F0,VSM_HW_VERSION
INFO,VSM707,VSM_SERIAL_NUMBER
INFO,VSM No X-over 01.02.05 May 20 2008 13:51:47,VSM_SOFTWARE_VERSION
INFO,704,PREAMP_SERIAL_NUMBER
INFO,822,COIL_SERIAL_NUMBER
INFO,0,MOMENT_UNITS
INFO,CoFe2O4,SAMPLE_MATERIAL
INFO,AH11 DL,SAMPLE_COMMENT
INFO,30.27,SAMPLE_MASS
INFO,,SAMPLE_VOLUME
INFO,,SAMPLE_MOLECULAR_WEIGHT
INFO,,SAMPLE_SIZE
INFO,,SAMPLE_SHAPE
DATATYPE,COMMENT,1
DATATYPE,TIME,2
STARTUPAXIS,X,2
STARTUPAXIS,Y1,5
[Data]
Comment,Time Stamp (sec),Temperature (K),Magnetic Field (Oe),Moment (emu),M. Std. Err. (emu),Transport Action,Averaging Time (sec),Frequency (Hz),Peak Amplitude (mm),Center Position (mm),Coil Signal' (mV),Coil Signal" (mV),Range (mV),M. Quad. Signal (emu),M. Raw' (emu),M. Raw" (emu),Min. Temperature (K),Max. Temperature (K),Min. Field (Oe),Max. Field (Oe),Mass (grams),Motor Lag (deg),Pressure (Torr),VSM Status (code),Motor Status (code),Measure Status (code),Measure Count,PPMS Status (code),System Temp. (K),System Field (Oe),Sample Position (deg),Bridge 1 Resistance (ohms),Bridge 1 Excitation (에),Bridge 2 Resistance (ohms),Bridge 2 Excitation (에),Bridge 3 Resistance (ohms),Bridge 3 Excitation (에),Bridge 4 Resistance (ohms),Bridge 4 Excitation (에),Signal 1 Vin (V),Signal 2 Vin (V),Digital Inputs (code),Drive 1 Iout (mA),Drive 1 Ipower (W),Drive 2 Iout (mA),Drive 2 Ipower (W),Pressure (),Map 20 (),Map 21 (),Map 22 (),Map 23 (),Map 24 (),Map 25 (),Map 26 (),Map 27 (),Map 28 (),Map 29 ()
,31010775.13,249.9869232,-0.304475486278534,,,2,,,,15.1699999961257,,,,,,,249.9869232,249.9869232,-0.304475486278534,-0.304475486278534,,,24.047956,,,,-99999999,4369,250.0381,-0.304475486278534,,,,,,,,,,,,,,,,,,,,,,,249.9869232,,,,
,31010923.265,249.9789581,4560.86865234375,4.89010577053785E-5,4.28424961864852E-7,1,0.999253354069792,40.0298881530762,1.99695316503755,15.1599999517202,0.000555974150729353,8.42511306666788E-5,0.25,-1.04294727700888E-6,4.89877556046832E-5,-1.00438167280945E-6,249.9789581,249.9789581,4560.86865234375,4560.86865234375,56.3937160339867,20.5956401212092,24.427608,0,0,0,40,4449,250.0664,4560.86865234375,,,,,,,,,,,,,0,,,,0,,,,,,249.9789581,,,,
,31011020.09,249.9811249,9399.6611328125,4.16365806339409E-5,6.76856902298104E-7,1,0.999253354069792,40.0298881530762,1.99688463332028,15.1599999517202,0.000472826157167877,7.48464646647215E-5,0.25,-6.13096976606479E-7,4.17101724701892E-5,-5.79815187259539E-7,249.9811249,249.9811249,9392.234375,9407.087890625,56.3483815798714,20.6011512257943,24.807261,0,0,0,40,4449,250.0822,9399.6611328125,,,,,,,,,,,,,0,,,,0.0049,,,,,,249.9811249,,,,
,31011116.35,249.9859924,14209.845703125,2.6119348940885E-5,1.09697844757161E-6,1,0.999253354069792,40.0298881530762,1.99685922464805,15.1599999517202,0.000298771084355082,3.44815385616733E-5,0.25,-1.48552652976882E-6,2.61664197065585E-5,-1.46660612296577E-6,249.9859924,249.9859924,14204.8447265625,14214.8466796875,56.5430070811598,20.6021086013347,24.427608,0,0,0,40,4449,250.0962,14209.845703125,,,,,,,,,,,,,0,,,,-0.0049,,,,,,249.9859924,,,,
,31011213.16,249.9945221,19049.3974609375,1.02837106362602E-5,9.28215283818468E-7,1,0.999253354069792,40.0298881530762,1.99687903437533,15.1599999517202,0.000118754617814016,7.11007203969974E-6,0.25,-1.15572700795608E-6,1.03027107003077E-5,-1.14928976475953E-6,249.9945221,249.9945221,19041.998046875,19056.796875,56.1256174518906,20.6037274850129,24.427608,0,0,0,40,4449,250.1003,19049.3974609375,,,,,,,,,,,,,0,,,,-0.00735,,,,,,249.9945221,,,,
,31011308.31,249.9927826,23804.8271484375,-7.57445174995667E-6,1.17068394756108E-6,1,0.999253354069792,40.0298881530762,1.99665801424409,15.1599999517202,-8.1526960173276E-5,-3.9443900258135E-5,0.25,-2.16905754121495E-6,-7.58596344158221E-6,-2.17909236093425E-6,249.9927826,249.9927826,23799.783203125,23809.87109375,56.4968909985252,20.6053755049324,24.427608,0,0,0,40,4449,250.1016,23804.8271484375,,,,,,,,,,,,,0,,,,-0.0049,,,,,,249.9927826,,,,
,31011403.815,249.9938965,28577.48828125,-2.50855421707466E-5,1.36157188005968E-6,1,0.999253354069792,40.0298881530762,1.99687825188605,15.1599999517202,-0.00027859376798796,-8.12917375333729E-5,0.25,-2.82640456766642E-6,-2.51272547454865E-5,-2.8519639604239E-6,249.9938965,249.9938965,28567.275390625,28587.701171875,56.7454488676406,20.6080606930074,24.047956,0,0,0,40,4449,250.1027,28577.48828125,,,,,,,,,,,,,0,,,,0,,,,,,249.9938965,,,,
,31011500.275,250.0003052,33397.37109375,-4.48798702815159E-5,1.62211276353868E-6,1,0.999253354069792,40.0298881530762,1.99693650629512,15.1599999517202,-0.000503193683700041,-0.000118020964090454,0.25,-2.63601785219301E-6,-4.49564829095829E-5,-2.67744664324494E-6,250.0003052,250.0003052,33385.1015625,33409.640625,56.7759323798906,20.6061404421664,24.427608,0,0,0,40,4449,250.10185,33397.37109375,,,,,,,,,,,,,0,,,,0.0049,,,,,,250.0003052,,,,
,31011597.155,250.0012512,38240.240234375,-6.15521519184218E-5,2.09021744880651E-6,1,0.999253354069792,40.0298881530762,1.99670438814081,15.1599999517202,-0.000695954999542809,-0.000127778816030835,0.25,-6.07472779032938E-7,-6.16596979793471E-5,-6.58942377304845E-7,250.0012512,250.0012512,38237.7734375,38242.70703125,56.8814522299868,20.6075247275301,24.807261,0,0,0,40,4449,250.1012,38240.240234375,,,,,,,,,,,,,0,,,,0,,,,,,250.0012512,,,,
,31011692.79,250.0052795,43022.546875,-8.36342953835441E-5,2.11255374839742E-6,1,0.999253354069792,40.0298881530762,1.99665825036346,15.1599999517202,-0.000940493588043101,-0.000203128284262879,0.25,-3.43121270909463E-6,-8.3778292638941E-5,-3.5056269372744E-6,250.0052795,250.0052795,43015.2109375,43029.8828125,56.8728543162753,20.6118856085385,24.427608,0,0,0,40,4449,250.0944,43022.546875,,,,,,,,,,,,,0,,,,0.0049,,,,,,250.0052795,,,,
,31011790.42,250.0108337,47900.44140625,-0.0001013112655656,2.72318052556275E-6,1,0.999253354069792,40.0298881530762,1.99673048906532,15.1599999517202,-0.00114250086765595,-0.000227704092718306,0.25,-2.53501990844751E-6,-0.000101487019964654,-2.62219829103867E-6,250.0108337,250.0108337,47892.97265625,47907.91015625,56.4671891147944,20.6087195332786,24.807261,0,0,0,40,4449,250.0847,47900.44140625,,,,,,,,,,,,,0,,,,-0.00245,,,,,,250.0108337,,,,
,31011886.095,250.0093842,52683.2109375,-0.000120509402228851,2.37878577783084E-6,1,0.999253354069792,40.0298881530762,1.99682532740083,15.1599999517202,-0.00136174460123621,-0.000255400606231839,0.25,-1.65019302017344E-6,-0.000120719599756356,-1.75135713336817E-6,250.0093842,250.0093842,52675.5703125,52690.8515625,56.7048041846406,20.6075208089489,24.427608,0,0,0,40,4449,250.0718,52683.2109375,,,,,,,,,,,,,0,,,,0,,,,,,250.0093842,,,,
,31011980.995,250.0074921,57425.75,-0.000138179463972819,2.63040747615838E-6,1,0.999253354069792,40.0298881530762,1.99685180983407,15.1599999517202,-0.0015568686100326,-0.000319183842546377,0.25,-4.21692026248106E-6,-0.00013841861974366,-4.33683161475898E-6,250.0074921,250.0074921,57413.203125,57438.296875,57.0416860764291,20.6086474750449,24.427608,0,0,0,40,4449,250.07455,57425.75,,,,,,,,,,,,,0,,,,0,,,,,,250.0074921,,,,
,31012077.195,250.0140533,62233.37109375,-0.000160321323853273,2.67315530986607E-6,1,0.999253354069792,40.0298881530762,1.99662316657376,15.1599999517202,-0.00180186990601588,-0.000394933531574861,0.25,-7.06878641581372E-6,-0.000160597022752169,-7.21153646333324E-6,250.0140533,250.0140533,62231.05859375,62235.68359375,56.6969878994483,20.6118713751956,24.047956,0,0,0,40,4449,250.06965,62233.37109375,,,,,,,,,,,,,0,,,,-0.0049,,,,,,250.0140533,,,,
,31012175.015,250.0100784,67124.08203125,-0.000181334548771597,2.84318979608342E-6,1,0.999253354069792,40.0298881530762,1.99659727893346,15.1599999517202,-0.00204472083173844,-0.000408024244509804,0.25,-4.58132787691385E-6,-0.000181649215170721,-4.73657116801175E-6,250.0097961,250.0103607,67119.203125,67128.9609375,57.0268351345637,20.6076315900621,24.427608,0,0,0,40,4449,250.0603,67124.08203125,,,,,,,,,,,,,0,,,,0,,,,,,250.0100784,,,,
,31012273.39,250.011734,72039.484375,-0.000197308364527092,3.5406543384538E-6,1,0.999253354069792,40.0298881530762,1.9968246638107,15.1599999517202,-0.00222983031522854,-0.000416639208600223,0.25,-2.56819489994564E-6,-0.000197652730324959,-2.73262532014579E-6,250.011734,250.011734,72031.8125,72047.15625,56.9713395096983,20.6111531323946,24.427608,0,0,0,40,4449,250.0459,72039.484375,,,,,,,,,,,,,0,,,,0,,,,,,250.011734,,,,
,31012370.44,250.0117645,76890.0234375,-0.000221724969819931,3.55895919516459E-6,1,0.999253354069792,40.0298881530762,1.9967577430218,15.1599999517202,-0.00250041482156764,-0.000498595154795624,0.25,-5.57135545175777E-6,-0.000222109810693762,-5.76057538723735E-6,250.0117645,250.0117645,76880.0390625,76900.0078125,56.7477937531983,20.6103714830241,24.427608,0,0,0,40,4449,250.0309,76890.0234375,,,,,,,,,,,,,0,,,,0,,,,,,250.0117645,,,,
,31012466.695,250.0139008,81703.171875,-0.000240178822287421,3.79493503093299E-6,1,0.999253354069792,40.0298881530762,1.99644003470081,15.1599999517202,-0.00270610073033248,-0.000551595860615521,0.25,-7.05836819574888E-6,-0.000240594889311065,-7.26482629658909E-6,250.0139008,250.0139008,81693.2890625,81713.0546875,56.719655126506,20.6120863159142,24.427608,0,0,0,40,4449,250.0269,81703.171875,,,,,,,,,,,,,0,,,,0,,,,,,250.0139008,,,,
,31012558.57,250.0077667,86296.54296875,-0.000255800838357045,3.25436050790395E-6,1,0.999253354069792,40.0298881530762,1.99645000252582,15.1599999517202,-0.00288651115007505,-0.000562206757059461,0.25,-5.28641695144345E-6,-0.000256245867174161,-5.50207547176843E-6,250.0077667,250.0077667,86286.7578125,86306.328125,56.7532651528329,20.6146543141426,24.427608,0,0,0,40,4449,250.0198,86296.54296875,,,,,,,,,,,,,0,,,,-0.00245,,,,,,250.0077667,,,,
,31012668.15,250.01252745,89200,-0.000269569361188938,2.95633428393248E-6,1,0.999253354069792,40.0298881530762,1.99638315304107,15.1599999517202,-0.00304029790239076,-0.000600999519957833,0.25,-6.32624948972809E-6,-0.000270037716459892,-6.55463236134936E-6,250.0119781,250.0130768,89192.453125,89207.546875,56.8454973181022,20.6115361188415,24.807261,0,0,0,40,4449,250.01545,89200,,,,,,,,,,,,,0,,,,-0.0049,,,,,,250.01252745,,,,
,31012761.23,250.0104218,84547.00390625,-0.00025392872448875,2.77940052504802E-6,1,0.999253354069792,40.0298881530762,1.99650890198872,15.1599999517202,-0.00286608694276466,-0.00055452716230408,0.25,-4.93142763780783E-6,-0.000254370710268931,-5.14508426256379E-6,250.0104218,250.0104218,84539.5,84554.5078125,56.6774471864675,20.6124431463547,24.047956,0,0,0,40,4449,250.0074,84547.00390625,,,,,,,,,,,,,0,,,,0,,,,,,250.0104218,,,,
,31012859.15,249.999649,79650.43359375,-0.000231633596256088,3.69318976930811E-6,1,0.999253354069792,40.0298881530762,1.99648781344554,15.1599999517202,-0.00261097910049164,-0.000525657510598602,0.25,-6.24853385238972E-6,-0.000232035409630328,-6.44681350732797E-6,249.999649,249.999649,79645.2578125,79655.609375,56.9056827140829,20.6148474029893,24.427608,0,0,0,40,4449,250.00745,79650.43359375,,,,,,,,,,,,,0,,,,0,,,,,,249.999649,,,,
,31012957.07,249.9972839,74754.4609375,-0.000209706479496733,3.60316825956635E-6,1,0.999253354069792,40.0298881530762,1.9965942094308,15.1599999517202,-0.00236962711236175,-0.000443103390562179,0.25,-2.75906688229899E-6,-0.000210072583541794,-2.93375891822938E-6,249.9972839,249.9972839,74752.171875,74756.75,56.6571248449675,20.6131213972955,24.807261,0,0,0,40,4449,250.01115,74754.4609375,,,,,,,,,,,,,0,,,,0,,,,,,249.9972839,,,,
,31013054.345,249.9940033,69893.8203125,-0.000193289296836947,2.99208782129834E-6,1,0.999253354069792,40.0298881530762,1.9964390779846,15.1599999517202,-0.00217594770118728,-0.000454561066272831,0.25,-6.62035982655697E-6,-0.00019362342483428,-6.78878243285401E-6,249.9940033,249.9940033,69893.8203125,69893.8203125,56.6766655579483,20.6173382479405,24.807261,0,0,0,40,4449,250.0172,69893.8203125,,,,,,,,,,,,,0,,,,0,,,,,,249.9940033,,,,
,31013151.2,249.9885406,65050.658203125,-0.000168791627826994,2.66592238748179E-6,1,0.999253354069792,40.0298881530762,1.99654070743748,15.1599999517202,-0.00190480606996037,-0.000370744073520666,0.25,-3.46548230846529E-6,-0.000169085292199991,-3.60870102178724E-6,249.9885406,249.9885406,65040.76953125,65060.546875,56.9064643426022,20.6152486468985,24.047956,0,0,0,40,4449,250.0256,65050.658203125,,,,,,,,,,,,,0,,,,0.0049,,,,,,249.9885406,,,,
,31013248.055,249.9940948,60212.470703125,-0.000152188005848664,2.83588856597697E-6,1,0.999253354069792,40.0298881530762,1.99634661855396,15.1599999517202,-0.00171228969374123,-0.000362991671784033,0.25,-5.66302901680594E-6,-0.000152450663306862,-5.79680178466776E-6,249.9940948,249.9940948,60207.6328125,60217.30859375,56.8001628639868,20.6179801862069,24.047956,0,0,0,40,4449,250.0358,60212.470703125,,,,,,,,,,,,,0,,,,0,,,,,,249.9940948,,,,
,31013345.19,249.9897919,55354.787109375,-0.000133250092090585,2.37940752033881E-6,1,0.999253354069792,40.0298881530762,1.99642714271733,15.1599999517202,-0.00150301721011835,-0.000296249381813254,0.25,-3.05217943430458E-6,-0.000133481614561191,-3.16612261366766E-6,249.9897919,249.9897919,55344.87109375,55364.703125,56.9478906541214,20.6179240315449,24.807261,0,0,0,40,4449,250.03915,55354.787109375,,,,,,,,,,,,,0,,,,-0.0049,,,,,,249.9897919,,,,
,31013441.315,249.9879913,50550.0234375,-0.000114521212462508,2.18964400420576E-6,1,0.999253354069792,40.0298881530762,1.9963960815426,15.1599999517202,-0.00128839079398411,-0.000273932925300282,0.25,-4.32966083140806E-6,-0.000114718790542987,-4.43071783560587E-6,249.9879913,249.9879913,50542.5859375,50557.4609375,56.9674313671022,20.6194894679855,24.427608,0,0,0,40,4449,250.0541,50550.0234375,,,,,,,,,,,,,0,,,,0,,,,,,249.9879913,,,,
,31013537.985,249.9803009,45719.61328125,-9.46534009429038E-5,2.10950477126931E-6,1,0.999253354069792,40.0298881530762,1.99644029335053,15.1599999517202,-0.00106621994194642,-0.000218778762559796,0.25,-2.90418426262657E-6,-9.48172626551058E-5,-2.98663596711929E-6,249.9803009,249.9803009,45714.53125,45724.6953125,56.9009929429675,20.6170034599225,24.427608,0,0,0,40,4449,250.0629,45719.61328125,,,,,,,,,,,,,0,,,,0.0049,,,,,,249.9803009,,,,
,31013635.84,249.9877777,40827.2109375,-7.39813924120103E-5,2.20069795783091E-6,1,0.999253354069792,40.0298881530762,1.99648066608184,15.1599999517202,-0.000830795015828711,-0.000185887564834853,0.25,-3.58429467763093E-6,-7.41083597738281E-5,-3.65113131170088E-6,249.9877777,249.9877777,40817.53515625,40836.88671875,56.8572217458906,20.6143507029683,24.047956,0,0,0,40,4449,250.07385,40827.2109375,,,,,,,,,,,,,0,,,,-0.00245,,,,,,249.9877777,,,,
,31013733.285,249.9879227,35959.47265625,-5.56250050917518E-5,1.86057856276108E-6,1,0.999253354069792,40.0298881530762,1.99655894656198,15.1599999517202,-0.000625737383424553,-0.0001336728930324,0.25,-2.15652783365681E-6,-5.57208999065469E-5,-2.20589865247969E-6,249.9876862,249.9881592,35954.4453125,35964.5,56.729816297256,20.6183595810766,24.807261,0,0,0,40,4449,250.0794,35959.47265625,,,,,,,,,,,,,0,,,,0,,,,,,249.9879227,,,,
,31013830.11,249.984848,31116.58203125,-3.71633898350683E-5,2.06353136308392E-6,1,0.999253354069792,40.0298881530762,1.99623037135255,15.1599999517202,-0.000416979743995863,-9.51369574060377E-5,0.25,-1.9567822675273E-6,-3.72270322414468E-5,-1.99071395946134E-6,249.984848,249.984848,31106.232421875,31126.931640625,57.024490249006,20.6193725937968,24.427608,0,0,0,40,4449,250.08715,31116.58203125,,,,,,,,,,,,,0,,,,-0.0049,,,,,,249.984848,,,,
,31013927.2,249.9895782,26264.134765625,-1.7485580791216E-5,1.22062572674733E-6,1,0.999253354069792,40.0298881530762,1.99646526803399,15.1599999517202,-0.000198497493747656,-3.15958316633328E-5,0.25,2.42417185768755E-7,-1.75164745822712E-5,2.2847580255106E-7,249.9895782,249.9895782,26258.96484375,26269.3046875,57.1456426694868,20.6160521133696,24.807261,0,0,0,40,4449,250.10035,26264.134765625,,,,,,,,,,,,,0,,,,0,,,,,,249.9895782,,,,
,31014024.5,249.991333,21404.0087890625,9.12375022095215E-7,8.85243241642959E-7,1,0.999253354069792,40.0298881530762,1.99664473683441,15.1599999517202,1.5457038562324E-5,-2.77522941220301E-5,0.25,-2.60858554998276E-6,9.16122548623843E-7,-2.61241364042447E-6,249.991333,249.991333,21391.34375,21416.673828125,57.1995750373137,20.6154505560608,24.807261,0,0,0,40,4449,250.10205,21404.0087890625,,,,,,,,,,,,,0,,,,0.00245,,,,,,249.991333,,,,
,31014119.025,249.9853058,16677.009765625,1.75975688844845E-5,9.18449195715636E-7,1,0.999253354069792,40.0298881530762,1.99665872144668,15.1599999517202,0.000204066349500818,7.12690087003715E-6,0.25,-2.42257483578266E-6,1.76304541643475E-5,-2.41233342903036E-6,249.9853058,249.9853058,16669.572265625,16684.447265625,57.1425161554099,20.6159538126008,24.427608,0,0,0,40,4449,250.11805,16677.009765625,,,,,,,,,,,,,0,,,,0,,,,,,249.9853058,,,,
,31014215.2,249.9916077,11871.8637695313,3.37773533678114E-5,9.29591794638275E-7,1,0.999253354069792,40.0298881530762,1.99640506331026,15.1599999517202,0.000383420649950671,6.10959924579837E-5,0.25,-4.62794175927384E-7,3.38370150981481E-5,-4.3575508994776E-7,249.9916077,249.9916077,11866.7978515625,11876.9296875,56.8853603725829,20.616239720897,24.427608,0,0,0,40,4449,250.125,11871.8637695313,,,,,,,,,,,,,0,,,,-0.0049,,,,,,249.9916077,,,,
,31014312.11,249.9943848,7026.76806640625,4.64555007633731E-5,5.9016672795127E-7,1,0.999253354069792,40.0298881530762,1.99663153034524,15.1599999517202,0.000527590624411316,8.28948196500785E-5,0.25,-7.37401679091487E-7,4.65376308612665E-5,-7.00349718062498E-7,249.9943848,249.9943848,7019.294921875,7034.2412109375,57.0604451608906,20.6138698438964,24.427608,0,0,0,40,4449,250.1267,7026.76806640625,,,,,,,,,,,,,0,,,,0,,,,,,249.9943848,,,,
,31014405.21,249.9919281,2375.97509765625,4.71063310354475E-5,4.351794877205E-7,1,0.999253354069792,40.0298881530762,1.9966367177829,15.1599999517202,0.000533825462455634,9.0733072622619E-5,0.25,-1.5825052186188E-7,4.7189125652206E-5,-1.19611441990356E-7,249.9919281,249.9919281,2370.97436523438,2380.97583007813,57.0291800201214,20.6163156156689,24.427608,0,0,0,40,4449,250.1328,2375.97509765625,,,,,,,,,,,,,0,,,,0,,,,,,249.9919281,,,,
,31014497.265,249.994751,-2222.92041015625,-3.62404674459873E-5,4.83427313532378E-7,1,0.999253354069792,40.0298881530762,1.99676255542542,15.1599999517202,-0.000411303391111764,-6.64116516902218E-5,0.25,4.21623213647393E-7,-3.63044080782627E-5,3.92421993882338E-7,249.994751,249.994751,-2227.9404296875,-2217.900390625,56.8368994043906,20.6148000773991,24.427608,0,0,0,40,4449,250.1306,-2222.92041015625,,,,,,,,,,,,,0,,,,-0.00245,,,,,,249.994751,,,,
,31014593.37,249.999649,-7029.08569335938,-4.5767644620282E-5,5.51982654714728E-7,1,0.999253354069792,40.0298881530762,1.99667379756099,15.1599999517202,-0.000518525328809475,-8.89562500991842E-5,0.25,8.30747964028719E-8,-4.58480190545386E-5,4.54434028372577E-8,249.999649,249.999649,-7036.84521484375,-7021.326171875,57.1253203279868,20.6165403065866,24.807261,0,0,0,40,4449,250.1323,-7029.08569335938,,,,,,,,,,,,,0,,,,0.00245,,,,,,249.999649,,,,
,31014692.485,250.0044861,-11979.720703125,-3.2875871384102E-5,6.57874385915455E-7,1,0.999253354069792,40.0298881530762,1.99647074727095,15.1599999517202,-0.000372475373780838,-6.36404241427308E-5,0.25,8.19444896527544E-8,-3.29336219263973E-5,5.49810952856487E-8,250.0044861,250.0044861,-11984.69140625,-11974.75,57.0635716749676,20.6172668029134,24.807261,0,0,0,40,4449,250.1259,-11979.720703125,,,,,,,,,,,,,0,,,,-0.0049,,,,,,250.0044861,,,,
,31014794.07,250.011261,-17059.4560546875,-1.69173353462128E-5,1.05533375367533E-6,1,0.999253354069792,40.0298881530762,1.99658729564875,15.1599999517202,-0.000191362886164789,-3.45775499141745E-5,0.25,-1.19211954693088E-7,-1.69469176000608E-5,-1.33353062002907E-7,250.011261,250.011261,-17061.900390625,-17057.01171875,56.933039712256,20.6158586609951,24.427608,0,0,0,40,4449,250.123,-17059.4560546875,,,,,,,,,,,,,0,,,,0.0049,,,,,,250.011261,,,,
,31014894.14,250.0090179,-22059.3515625,2.10591326770444E-6,1.10608382355939E-6,1,0.999253354069792,40.0298881530762,1.99658182255909,15.1599999517202,2.13130547424556E-5,1.87674186748559E-5,0.25,1.29188740415523E-6,2.10854576487939E-6,1.29588635005149E-6,250.0090179,250.0090179,-22064.310546875,-22054.392578125,57.0518472471791,20.6176465712919,24.807261,0,0,0,40,4449,250.1118,-22059.3515625,,,,,,,,,,,,,0,,,,0,,,,,,250.0090179,,,,
,31014995.03,250.0094299,-27104.74609375,2.10404847300169E-5,1.1884071108367E-6,1,0.999253354069792,40.0298881530762,1.99654617593582,15.1599999517202,0.000235946069845954,5.48354496624396E-5,0.25,1.19299861324105E-6,2.10764252546014E-5,1.21237572181546E-6,250.0094299,250.0094299,-27107.0703125,-27102.421875,57.034651419756,20.6197073198813,24.427608,0,0,0,40,4449,250.1018,-27104.74609375,,,,,,,,,,,,,0,,,,-0.0049,,,,,,250.0094299,,,,
,31015095.08,250.0110779,-32101.8388671875,4.10937336630127E-5,1.7667946439363E-6,1,0.999253354069792,40.0298881530762,1.99652712607288,15.1599999517202,0.000461561734758988,0.000102803945050532,0.25,1.95099307490795E-6,4.11642445452742E-5,1.9881275148824E-6,250.0110779,250.0110779,-32104.4765625,-32099.201171875,57.0729512171983,20.6232667013724,24.427608,0,0,0,40,4449,250.0945,-32101.8388671875,,,,,,,,,,,,,0,,,,-0.0049,,,,,,250.0110779,,,,
,31015190.73,250.0132446,-36883.634765625,5.93423695261095E-5,1.84795983584781E-6,1,0.999253354069792,40.0298881530762,1.99679126362677,15.1599999517202,0.000671288917919954,0.000121513634659351,0.25,4.37064810690746E-7,5.94461480250664E-5,4.86449302914929E-7,250.0132446,250.0132446,-36890.9296875,-36876.33984375,57.1323549846599,20.6165623701593,24.427608,0,0,0,40,4449,250.0811,-36883.634765625,,,,,,,,,,,,,0,,,,-0.00245,,,,,,250.0132446,,,,
,31015288.065,250.0131073,-41745.939453125,7.7287141577464E-5,2.42554660269922E-6,1,0.999253354069792,40.0298881530762,1.99679569816354,15.1599999517202,0.000869208918387929,0.000187527374032905,0.25,3.15335174166491E-6,7.74201986265065E-5,3.22211762163659E-6,250.0131073,250.0131073,-41748.34375,-41743.53515625,57.2472543769868,20.6179982848787,24.427608,0,0,0,40,4449,250.07165,-41745.939453125,,,,,,,,,,,,,0,,,,0,,,,,,250.0131073,,,,
,31015385.415,250.0114594,-46613.794921875,9.99952125664167E-5,2.44682139286732E-6,1,0.999253354069792,40.0298881530762,1.99683389642386,15.1599999517202,0.00112785072418749,0.000223975850786351,0.25,2.43306337646639E-6,0.000100168732817131,2.51902636662724E-6,250.0114594,250.0114594,-46621.453125,-46606.13671875,56.7720242372945,20.6191921164019,24.427608,0,0,0,40,4449,250.06775,-46613.794921875,,,,,,,,,,,,,0,,,,-0.00245,,,,,,250.0114594,,,,
,31015484.07,250.0124969,-51543.294921875,0.000119094013697495,2.1592287853014E-6,1,0.999253354069792,40.0298881530762,1.99689777951248,15.1599999517202,0.00134534788611089,0.000255000844168706,0.25,1.85953296491526E-6,0.00011930153760768,1.95995038103855E-6,250.0124969,250.0124969,-51548.2578125,-51538.33203125,57.1237570709483,20.617216079996,24.807261,0,0,0,40,4449,250.0585,-51543.294921875,,,,,,,,,,,,,0,,,,-0.0049,,,,,,250.0124969,,,,
,31015581.445,250.0131531,-56407.953125,0.000137359597881084,2.48594535706971E-6,1,0.999253354069792,40.0298881530762,1.99686057107,15.1599999517202,0.00155008071211775,0.000303201008813065,0.25,2.94789387329235E-6,0.000137598312871311,3.0649613118816E-6,250.0131531,250.0131531,-56415.47265625,-56400.43359375,57.1198489283522,20.6180307010109,24.427608,0,0,0,40,4449,250.043,-56407.953125,,,,,,,,,,,,,0,,,,0.00245,,,,,,250.0131531,,,,
,31015681.23,250.0108795,-61397.416015625,0.000159636733941288,2.48986496057163E-6,1,0.999253354069792,40.0298881530762,1.99680030276089,15.1599999517202,0.00180555041829639,0.0003285639993724,0.25,1.32491221993786E-6,0.000159915912152864,1.4570789880579E-6,250.0108795,250.0108795,-61407.51171875,-61387.3203125,56.8095424062176,20.6172615029578,24.807261,0,0,0,40,4449,250.0334,-61397.416015625,,,,,,,,,,,,,0,,,,0,,,,,,250.0108795,,,,
,31015778.11,250.0177002,-66237.34765625,0.000181215661773331,2.99509099088727E-6,1,0.999253354069792,40.0298881530762,1.99688178394786,15.1599999517202,0.00204533326462401,0.000398148578893577,0.25,3.72512481604019E-6,0.00018153075578561,3.87883851090864E-6,250.0177002,250.0177002,-66239.890625,-66234.8046875,56.9314764552176,20.6196289645019,24.427608,0,0,0,40,4449,250.0177,-66237.34765625,,,,,,,,,,,,,0,,,,0.00245,,,,,,250.0177002,,,,
,31015881.455,250.0136261,-71404.2578125,0.000200087845144552,3.02132304132225E-6,1,0.999253354069792,40.0298881530762,1.99675569767744,15.1599999517202,0.00225759812217996,0.000443075700688571,0.25,4.42140949640299E-6,0.000200435567294827,4.59141031532686E-6,250.0136261,250.0136261,-71411.6171875,-71396.8984375,56.9236601700253,20.6221452152074,24.807261,0,0,0,40,4449,250.0058,-71404.2578125,,,,,,,,,,,,,0,,,,-0.00245,,,,,,250.0136261,,,,
,31015980.08,250.0095367,-76331.640625,0.000221358069121558,2.40501738577359E-6,1,0.999253354069792,40.0298881530762,1.99691276665046,15.1599999517202,0.00249871884820908,0.000484794308135124,0.25,4.41328727712144E-6,0.000221743213075901,4.60023427162057E-6,250.0095367,250.0095367,-76338.875,-76324.40625,57.3480844559676,20.6187572715867,24.427608,0,0,0,40,4449,250.0019,-76331.640625,,,,,,,,,,,,,0,,,,0,,,,,,250.0095367,,,,
,31016077.9,250.0144958,-81221.31640625,0.000242647559987711,3.156166620666E-6,1,0.999253354069792,40.0298881530762,1.9969203537701,15.1599999517202,0.00273695525602375,0.000543486467017988,0.25,5.90311200728187E-6,0.000243068881678166,6.10960206645872E-6,250.0144958,250.0144958,-81226.3515625,-81216.28125,57.3942005386022,20.6229292024455,24.807261,0,0,0,40,4449,249.9889,-81221.31640625,,,,,,,,,,,,,0,,,,0.0049,,,,,,250.0144958,,,,
,31016172.17,250.0146027,-85933.00390625,0.000260506013327063,3.60070807764646E-6,1,0.999253354069792,40.0298881530762,1.99689196570039,15.1599999517202,0.00293963914854122,0.000576050848255812,0.25,5.68216963633344E-6,0.000260958914575117,5.9023858081587E-6,250.0146027,250.0146027,-85937.4453125,-85928.5625,56.9471090256022,20.6221923469754,24.427608,0,0,0,40,4449,249.9764,-85933.00390625,,,,,,,,,,,,,0,,,,-0.0049,,,,,,250.0146027,,,,
,31016284.455,250.01091,-89500.80078125,0.000277417794579228,3.85145265021471E-6,1,0.999253354069792,40.0298881530762,1.99700056212954,15.1599999517202,0.0031348985349622,0.000588925643740967,0.25,3.8837358161331E-6,0.000277901915829091,4.11418057823627E-6,250.01091,250.01091,-89505.890625,-89495.7109375,56.902556200006,20.6210911075707,24.807261,0,0,0,40,4449,249.9685,-89500.80078125,,,,,,,,,,,,,0,,,,-0.00245,,,,,,250.01091,,,,
,31016377.07,250.000824,-84872.98046875,0.000257926376734434,3.25583703487167E-6,1,0.999253354069792,40.0298881530762,1.99683889341383,15.1599999517202,0.0029123772067325,0.000559259652617167,0.25,4.64826404311303E-6,0.000258375698667324,4.86466632691782E-6,250.000824,250.000824,-84880.5859375,-84865.375,57.0729512171983,20.6206804209926,24.807261,0,0,0,40,4449,249.9692,-84872.98046875,,,,,,,,,,,,,0,,,,0,,,,,,250.000824,,,,
,31016475.88,250.0001068,-79935.39453125,0.000238700581452575,3.94944580340753E-6,1,0.999253354069792,40.0298881530762,1.99673592713561,15.1599999517202,0.00269274210167438,0.000531467281804345,0.25,5.53048974427018E-6,0.000239115383284614,5.73323364566751E-6,250.0001068,250.0001068,-79942.96875,-79927.8203125,57.1331366131791,20.6230074449718,25.186911,0,0,0,40,4449,249.97465,-79935.39453125,,,,,,,,,,,,,0,,,,0.00245,,,,,,250.0001068,,,,
,31016573.47,249.9906464,-75058.3359375,0.000213106234724054,3.18422855896711E-6,1,0.999253354069792,40.0298881530762,1.99681935304082,15.1599999517202,0.00240914209086421,0.00044549755698349,0.25,2.37664694646255E-6,0.000213478667689736,2.55344462587741E-6,249.9906464,249.9906464,-75070.9140625,-75045.7578125,57.0698247031214,20.6236287829069,24.807261,0,0,0,40,4449,249.96075,-75058.3359375,,,,,,,,,,,,,0,,,,-0.00245,,,,,,249.9906464,,,,
,31016671.935,249.99125675,-70138.8203125,0.00019499425978581,2.85253374917888E-6,1,0.999253354069792,40.0298881530762,1.99660607685997,15.1599999517202,0.00220338098494332,0.000412103405546653,0.25,2.57266533805195E-6,0.000195334682904442,2.7353787400441E-6,249.9912415,249.991272,-70143.796875,-70133.84375,57.3285437429868,20.6264603272312,25.186911,0,0,0,40,4449,249.9771,-70138.8203125,,,,,,,,,,,,,0,,,,0.0049,,,,,,249.99125675,,,,
,31016769.01,249.9906769,-65286.578125,0.000173479278757205,3.33422572520614E-6,1,0.999253354069792,40.0298881530762,1.99652978691678,15.1599999517202,0.00196272268322251,0.00035204915796299,0.25,1.00201557665975E-6,0.000173783163695423,1.14472745999507E-6,249.9906769,249.9906769,-65291.52734375,-65281.62890625,56.8564401173714,20.626664820305,24.807261,0,0,0,40,4449,249.9913,-65286.578125,,,,,,,,,,,,,0,,,,0,,,,,,249.9906769,,,,
,31016866.71,249.9900589,-60404.017578125,0.000156370868604795,2.21496446772832E-6,1,0.999253354069792,40.0298881530762,1.99656049006971,15.1599999517202,0.00176624431434569,0.000334298600970796,0.25,2.40085073251537E-6,0.000156643546920128,2.53231174547905E-6,249.9899597,249.9901581,-60413.80078125,-60394.234375,56.8431524325445,20.6258689493061,24.807261,0,0,0,40,4449,250.00035,-60404.017578125,,,,,,,,,,,,,0,,,,0.00245,,,,,,249.9900589,,,,
,31016963.28,249.9894409,-55579.67578125,0.000135761893969088,2.51014734080412E-6,1,0.999253354069792,40.0298881530762,1.99640880697009,15.1599999517202,0.00153018240416794,0.000308483892389225,0.25,3.69716951959087E-6,0.000135997302517807,3.81430080975959E-6,249.9894409,249.9894409,-55582.21484375,-55577.13671875,56.9314764552176,20.6266959283041,24.427608,0,0,0,40,4449,250.0077,-55579.67578125,,,,,,,,,,,,,0,,,,0,,,,,,249.9894409,,,,
,31017059.345,249.98909,-50775.109375,0.000116189713632172,2.14596811984928E-6,1,0.999253354069792,40.0298881530762,1.99622982203609,15.1599999517202,0.00131030328491566,0.000259187116147235,0.25,2.74000732558416E-6,0.000116391512798305,2.83964631525104E-6,249.98909,249.98909,-50784.609375,-50765.609375,57.017455592333,20.6277430631798,25.186911,0,0,0,40,4449,250.0121,-50775.109375,,,,,,,,,,,,,0,,,,0.0049,,,,,,249.98909,,,,
,31017155.485,249.9884033,-45972.537109375,9.49352003304353E-5,2.61255149077638E-6,1,0.999253354069792,40.0298881530762,1.99624610617762,15.1599999517202,0.001074658166608,0.000188481288921543,0.25,1.81517330779611E-7,9.51017534273445E-5,2.59426717089579E-7,249.9884033,249.9884033,-45977.5546875,-45967.51953125,57.2746113751599,20.6281008887079,24.807261,0,0,0,40,4449,250.02165,-45972.537109375,,,,,,,,,,,,,0,,,,0,,,,,,249.9884033,,,,
,31017253.215,249.9867249,-41087.806640625,7.82934024366639E-5,1.65967627539524E-6,1,0.999253354069792,40.0298881530762,1.99630817773784,15.1599999517202,0.000879786163428561,0.000193011354556222,0.25,3.46694935068178E-6,7.8428039169329E-5,3.53711438245131E-6,249.9867249,249.9867249,-41090.41015625,-41085.203125,56.8728543162753,20.6275600482766,25.186911,0,0,0,40,4449,250.0391,-41087.806640625,,,,,,,,,,,,,0,,,,-0.0049,,,,,,249.9867249,,,,
,31017351.36,249.9881287,-36183.091796875,5.68920930750358E-5,1.6367086098797E-6,1,0.999253354069792,40.0298881530762,1.99640266638699,15.1599999517202,0.000641238010087939,0.000129241838679338,0.25,1.54638819851573E-6,5.69907115646969E-5,1.59573024360295E-6,249.9881287,249.9881287,-36188.12890625,-36178.0546875,56.8173586914099,20.6221288740239,24.427608,0,0,0,40,4449,250.0471,-36183.091796875,,,,,,,,,,,,,0,,,,0.0049,,,,,,249.9881287,,,,
,31017447.735,249.9879913,-31366.412109375,3.85559583479741E-5,1.62148148923776E-6,1,0.999253354069792,40.0298881530762,1.99630183187761,15.1599999517202,0.00043409074591918,9.02205983003933E-5,0.25,1.28083838838212E-6,3.86225956884158E-5,1.3147283995114E-6,249.9879913,249.9879913,-31376.4375,-31356.38671875,57.0643533034868,20.6266488574258,25.186911,0,0,0,40,4449,250.05565,-31366.412109375,,,,,,,,,,,,,0,,,,0,,,,,,249.9879913,,,,
,31017544.045,249.9884033,-26553.3466796875,1.94727509721235E-5,1.19008227003093E-6,1,0.999253354069792,40.0298881530762,1.99628984273644,15.1599999517202,0.000218390838645516,5.04447845370538E-5,0.25,1.07772705336787E-6,1.95060489669401E-5,1.09562013389147E-6,249.9884033,249.9884033,-26558.3125,-26548.380859375,57.1362631272561,20.6294251992525,24.427608,0,0,0,40,4449,250.064,-26553.3466796875,,,,,,,,,,,,,0,,,,0,,,,,,249.9884033,,,,
,31017641.89,249.98853305,-21663.6884765625,6.54509490621611E-7,1.00089467634101E-6,1,0.999253354069792,40.0298881530762,1.99646367165529,15.1599999517202,8.18144295269003E-6,-3.15016879021297E-6,0.25,-3.91671609205862E-7,6.55980628825735E-7,-3.91820616377643E-7,249.988205,249.9888611,-21671.216796875,-21656.16015625,56.9049010855637,20.6236340162569,24.427608,0,0,0,40,4449,250.0712,-21663.6884765625,,,,,,,,,,,,,0,,,,0,,,,,,249.98853305,,,,
,31017736.13,249.9934387,-16953.8056640625,-1.5733560850299E-5,8.28106762081933E-7,1,0.999253354069792,40.0298881530762,1.99635031085698,15.1599999517202,-0.000177370905296522,-3.55074003685049E-5,0.25,-4.06958410124401E-7,-1.57608387926099E-5,-4.20633335987925E-7,249.9934387,249.9934387,-16958.498046875,-16949.11328125,57.1284468420637,20.6240322852625,24.807261,0,0,0,40,4449,250.07005,-16953.8056640625,,,,,,,,,,,,,0,,,,0.00245,,,,,,249.9934387,,,,
,31017832.505,249.9919281,-12136.564453125,-3.22502871763253E-5,7.98656714226901E-7,1,0.999253354069792,40.0298881530762,1.99645444006181,15.1599999517202,-0.000364795818376014,-6.58261404249601E-5,0.25,-2.19587080094862E-7,-3.23067053839216E-5,-2.46568406009061E-7,249.9919281,249.9919281,-12146.640625,-12126.48828125,56.9439825115252,20.6211621560395,24.807261,0,0,0,40,4449,250.08205,-12136.564453125,,,,,,,,,,,,,0,,,,0.00245,,,,,,249.9919281,,,,
,31017928.74,249.9914398,-7325.85400390625,-4.53592048277147E-5,6.18236777276196E-7,1,0.999253354069792,40.0298881530762,1.99627693427365,15.1599999517202,-0.000515145263004739,-8.03918814738831E-5,0.25,7.6707401529981E-7,-4.54394399214163E-5,7.30974326644815E-7,249.9914398,249.9914398,-7328.52978515625,-7323.17822265625,57.0815491309099,20.6246823156581,24.427608,0,0,0,40,4449,250.0867,-7325.85400390625,,,,,,,,,,,,,0,,,,0.00245,,,,,,249.9914398,,,,
,31018025.275,249.9921265,-2502.3076171875,-4.68850647595869E-5,4.19021363781949E-7,1,0.999253354069792,40.0298881530762,1.99635306708347,15.1599999517202,-0.00052982463787574,-9.84900669632646E-5,0.25,-5.66194522844781E-7,-4.69668714326618E-5,-6.05928721007306E-7,249.9921265,249.9921265,-2509.88842773438,-2494.72680664062,56.8290831191983,20.6263695425327,24.807261,0,0,0,40,4449,250.09235,-2502.3076171875,,,,,,,,,,,,,0,,,,0,,,,,,249.9921265,,,,
,31018117.435,249.9959717,2104.37377929687,3.4596769317012E-5,4.48645929637866E-7,1,0.999253354069792,40.0298881530762,1.99649651563836,15.1599999517202,0.000392964208580369,6.12835351117933E-5,0.25,-5.88636577988513E-7,3.46579616491493E-5,-5.61080859703957E-7,249.9959717,249.9959717,2099.33374023438,2109.41381835938,56.7524835243137,20.6222631076655,24.807261,0,0,0,40,4449,250.0943,2104.37377929687,,,,,,,,,,,,,0,,,,0.0049,,,,,,249.9959717,,,,
,31018213.055,249.99771885,6882.84033203125,4.6139720942562E-5,5.68493821209273E-7,1,0.999253354069792,40.0298881530762,1.9961011984258,15.1599999517202,0.000523125755116956,8.66101516465931E-5,0.25,-3.52659547950079E-7,4.62209732072227E-5,-3.15187104467875E-7,249.9972382,249.9981995,6877.88232421875,6887.79833984375,56.9924434797176,20.6219942785259,25.186911,0,0,0,40,4449,250.1003,6882.84033203125,,,,,,,,,,,,,0,,,,-0.0049,,,,,,249.99771885,,,,
,31018310.085,250.0061493,11733.5478515625,3.37561273627459E-5,6.21561648062668E-7,1,0.999253354069792,40.0298881530762,1.99635073793149,15.1599999517202,0.000384499103668188,5.33895099436576E-5,0.25,-1.1395070969471E-6,3.38162919053508E-5,-1.11366754355159E-6,250.0061493,250.0061493,11721.009765625,11746.0859375,57.2902439455445,20.6214906938439,24.807261,0,0,0,40,4449,250.09385,11733.5478515625,,,,,,,,,,,,,0,,,,-0.00245,,,,,,250.0061493,,,,
,31018407.26,250.0066681,16588.552734375,1.79489820819842E-5,9.12754586334695E-7,1,0.999253354069792,40.0298881530762,1.99648296965089,15.1599999517202,0.000205927570600898,1.99325086415437E-5,0.25,-1.35272122096029E-6,1.79815892793508E-5,-1.34030916645049E-6,250.0066681,250.0066681,16583.71484375,16593.390625,57.3176009437176,20.6203752187854,25.186911,0,0,0,40,4449,250.09135,16588.552734375,,,,,,,,,,,,,0,,,,-0.00245,,,,,,250.0066681,,,,
,31018502.94,250.006424,21370.763671875,5.42238198236417E-7,8.16227102060418E-7,1,0.999253354069792,40.0298881530762,1.99650504227606,15.1599999517202,9.64374930165853E-6,-1.91335341745792E-5,0.25,-1.78352507867334E-6,5.44657095691659E-7,-1.78620848563762E-6,250.006424,250.006424,21360.830078125,21380.697265625,56.943200883006,20.6189306416065,25.186911,0,0,0,40,4449,250.0857,21370.763671875,,,,,,,,,,,,,0,,,,-0.0049,,,,,,250.006424,,,,
,31018600.93,250.0091858,26268.5693359375,-1.80471828964364E-5,1.41594877084596E-6,1,0.999253354069792,40.0298881530762,1.99631903944112,15.1599999517202,-0.000200094593654883,-6.007766910573E-5,0.25,-2.17555005853919E-6,-1.80770627816876E-5,-2.19419765086402E-6,250.0091858,250.0091858,26258.55078125,26278.587890625,56.6563432164483,20.6167993321069,24.427608,0,0,0,40,4449,250.0749,26268.5693359375,,,,,,,,,,,,,0,,,,-0.00245,,,,,,250.0091858,,,,
,31018697.18,250.00942995,31079.095703125,-3.76627939819301E-5,1.47480054739309E-6,1,0.999253354069792,40.0298881530762,1.99628868934159,15.1599999517202,-0.000424510711115979,-8.53688172844963E-5,0.25,-1.00733123453477E-6,-3.77280588376257E-5,-1.04000785686646E-6,250.0091553,250.0097046,31076.482421875,31081.708984375,56.8955215433329,20.622305240966,25.186911,0,0,0,40,4449,250.06885,31079.095703125,,,,,,,,,,,,,0,,,,-0.0049,,,,,,250.00942995,,,,
,31018795.525,250.0081482,35996.83203125,-5.64550452683426E-5,2.05546484454138E-6,1,0.999253354069792,40.0298881530762,1.99615072550094,15.1599999517202,-0.000634612035851961,-0.000137591440833699,0.25,-2.36095722291753E-6,-5.65521885386552E-5,-2.41136909045636E-6,250.0072479,250.0090485,35989.4140625,36004.25,57.0979633298137,20.6204868463893,24.427608,0,0,0,40,4449,250.06035,35996.83203125,,,,,,,,,,,,,0,,,,-0.00245,,,,,,250.0081482,,,,
,31018894.655,250.0139465,40951.904296875,-7.48236195129686E-5,1.81763008479382E-6,1,0.999253354069792,40.0298881530762,1.99618143504061,15.1599999517202,-0.000843782804995052,-0.000166924947428232,0.25,-1.76594122953975E-6,-7.49534830740373E-5,-1.8302783232286E-6,250.0139465,250.0139465,40941.8046875,40962.00390625,56.8783257159099,20.6197786224269,25.186911,0,0,0,40,4449,250.0463,40951.904296875,,,,,,,,,,,,,0,,,,0.00245,,,,,,250.0139465,,,,
,31018992.26,250.0153503,45826.9375,-9.60738126509865E-5,2.21298388898185E-6,1,0.999253354069792,40.0298881530762,1.9961719041363,15.1599999517202,-0.00108429569835395,-0.000209255783783414,0.25,-1.81934750012498E-6,-9.62409344663562E-5,-1.90105835957829E-6,250.0153503,250.0153503,45819.51171875,45834.36328125,57.0002597649099,20.618468577909,25.186911,0,0,0,40,4449,250.03975,45826.9375,,,,,,,,,,,,,0,,,,-0.0049,,,,,,250.0153503,,,,
,31019092.42,250.0101471,50834.76171875,-0.000115394341101215,2.38242063202096E-6,1,0.999253354069792,40.0298881530762,1.99609402366632,15.1599999517202,-0.00130389812281383,-0.000242115175214759,0.25,-1.37170766785166E-6,-0.000115595774837293,-1.46828279764389E-6,250.0101471,250.0101471,50827.3203125,50842.203125,56.7524835243137,20.6174049118047,24.807261,0,0,0,40,4449,250.03265,50834.76171875,,,,,,,,,,,,,0,,,,-0.0049,,,,,,250.0101471,,,,
,31019189.84,250.0158081,55704.486328125,-0.000136912197016119,2.29468804094522E-6,1,0.999253354069792,40.0298881530762,1.99625453188648,15.1599999517202,-0.00154421259253632,-0.000304268232260446,0.25,-3.1274467246898E-6,-0.000137149962149783,-3.24450386634936E-6,250.0158081,250.0158081,55699.7109375,55709.26171875,56.8408075469868,20.6172125644298,24.427608,0,0,0,40,4449,250.0147,55704.486328125,,,,,,,,,,,,,0,,,,0.00245,,,,,,250.0158081,,,,
,31019289.375,250.0092926,60679.86328125,-0.000155887683288584,2.3740124645102E-6,1,0.999253354069792,40.0298881530762,1.99615878593323,15.1599999517202,-0.00175767020891852,-0.000349215771616366,0.25,-3.80774812455046E-6,-0.000156158263541797,-3.94126600267136E-6,250.0092926,250.0092926,60672.37890625,60687.34765625,56.9627415959868,20.6183908953217,24.807261,0,0,0,40,4449,250.0123,60679.86328125,,,,,,,,,,,,,0,,,,0.0049,,,,,,250.0092926,,,,
,31019386.495,250.0144958,65532.79296875,-0.000174331771448059,2.94229501941548E-6,1,0.999253354069792,40.0298881530762,1.99600706578636,15.1599999517202,-0.0019691186995494,-0.000369574302971365,0.25,-2.40983084355882E-6,-0.000174635863980325,-2.55568654863476E-6,250.0144958,250.0144958,65525.3046875,65540.28125,56.7259081546598,20.6215760559318,24.807261,0,0,0,40,4449,250.0036,65532.79296875,,,,,,,,,,,,,0,,,,-0.00245,,,,,,250.0144958,,,,
,31019484.74,250.0112152,70443.015625,-0.000198491843766311,3.10463197913649E-6,1,0.999253354069792,40.0298881530762,1.99601674876174,15.1599999517202,-0.0022413927239226,-0.000424431538742085,0.25,-3.06527466284697E-6,-0.000198837872563112,-3.23166288669947E-6,250.0112152,250.0112152,70433.1015625,70452.9296875,56.9908802226791,20.6205172046376,25.186911,0,0,0,40,4449,249.99005,70443.015625,,,,,,,,,,,,,0,,,,0,,,,,,250.0112152,,,,
,31019580.22,250.0118103,75218.20703125,-0.000214141680310176,3.3927000217702E-6,1,0.999253354069792,40.0298881530762,1.99612803605865,15.1599999517202,-0.0024169945049527,-0.000465110672137827,0.25,-3.94228858746767E-6,-0.000214514505493846,-4.12264631282077E-6,250.0118103,250.0118103,75210.7109375,75225.703125,56.5656743082175,20.6191543737631,24.807261,0,0,0,40,4449,249.98155,75218.20703125,,,,,,,,,,,,,0,,,,0,,,,,,250.0118103,,,,
,31019677.125,250.01088715,80061.5625,-0.000235514800865918,3.0241691414778E-6,1,0.999253354069792,40.0298881530762,1.9961709767552,15.1599999517202,-0.00265602123648884,-0.000524602074922822,0.25,-5.4893379049156E-6,-0.000235923950383153,-5.68942473325514E-6,250.0107727,250.0110016,80059.078125,80064.046875,56.7446672391214,20.6168042389181,24.807261,0,0,0,40,4449,249.9728,80061.5625,,,,,,,,,,,,,0,,,,-0.00245,,,,,,250.01088715,,,,
,31019773.235,250.0141449,84865.30078125,-0.000252189393041366,3.12107652350713E-6,1,0.999253354069792,40.0298881530762,1.99622039958603,15.1599999517202,-0.0028480720400213,-0.000539062242712826,0.25,-3.87405086286579E-6,-0.000252629141796098,-4.08446475117808E-6,250.0141449,250.0141449,84862.9296875,84867.671875,56.8978664288906,20.6157551218424,24.427608,0,0,0,40,4449,249.96415,84865.30078125,,,,,,,,,,,,,0,,,,0.0049,,,,,,250.0141449,,,,
,31019865.945,250.0137634,89500.6640625,-0.000274317433884841,3.53599865113948E-6,1,0.999253354069792,40.0298881530762,1.99616253208419,15.1599999517202,-0.00309397897231735,-0.000608884284864059,0.25,-6.20480224600361E-6,-0.000274794208554546,-6.43684063678866E-6,250.0137634,250.0137634,89495.46875,89505.859375,56.7845302936022,20.6174620762686,24.427608,0,0,0,40,4449,249.9521,89500.6640625,,,,,,,,,,,,,0,,,,0,,,,,,250.0137634,,,,
,31019974.655,250.0099792,86023.5546875,-0.0002608580029298,3.33950763561152E-6,1,0.999253354069792,40.0298881530762,1.99620473218048,15.1599999517202,-0.00294576249184624,-0.000558659957748402,0.25,-4.10198251592116E-6,-0.000261312837522636,-4.31973339114233E-6,250.0099792,250.0099792,86013.609375,86033.5,56.8181403199291,20.6182328778186,24.807261,0,0,0,40,4449,249.9442,86023.5546875,,,,,,,,,,,,,0,,,,-0.00245,,,,,,250.0099792,,,,
,31020071.175,250.00408935,81200.44921875,-0.000240670735970683,4.1586903660967E-6,1,0.999253354069792,40.0298881530762,1.99615385415385,15.1599999517202,-0.00270944362631944,-0.000563199206670779,0.25,-8.004354730375E-6,-0.000241086971825082,-8.2129786364063E-6,250.0039978,250.0041809,81190.3125,81210.5859375,56.6438371601406,20.6157699276442,24.427608,0,0,0,40,4449,249.94735,81200.44921875,,,,,,,,,,,,,0,,,,-0.0049,,,,,,250.00408935,,,,
,31020168.145,249.9943848,76351.625,-0.000220132514957209,3.75361896054866E-6,1,0.999253354069792,40.0298881530762,1.99652445768766,15.1599999517202,-0.00248873527142565,-0.000457163439910725,0.25,-2.19392466268013E-6,-0.000220517417992325,-2.37602127919602E-6,249.9943848,249.9943848,76351.625,76351.625,56.739977468006,20.6167198075608,25.186911,0,0,0,40,4449,249.9549,76351.625,,,,,,,,,,,,,0,,,,0,,,,,,249.9943848,,,,
,31020264.325,249.9891663,71543.06640625,-0.000201475135104616,2.68877885825703E-6,1,0.999253354069792,40.0298881530762,1.99676900856125,15.1599999517202,-0.00227678146909084,-0.000425886333466003,0.25,-2.66291086139965E-6,-0.000201826891835938,-2.83097579285453E-6,249.9891663,249.9891663,71538.078125,71548.0546875,56.7743691228522,20.613621246625,24.807261,0,0,0,40,4449,249.96415,71543.06640625,,,,,,,,,,,,,0,,,,-0.00245,,,,,,249.9891663,,,,
,31020362.235,249.9889221,66649.74609375,-0.000181312710508166,3.04646697122028E-6,1,0.999253354069792,40.0298881530762,1.99657672081496,15.1599999517202,-0.00204267554497201,-0.000418238079946389,0.25,-5.48720952641624E-6,-0.000181626728837111,-5.64411032560541E-6,249.9889221,249.9889221,66644.75,66654.7421875,56.8329912617945,20.616460767175,24.807261,0,0,0,40,4449,249.9758,66649.74609375,,,,,,,,,,,,,0,,,,-0.00245,,,,,,249.9889221,,,,
,31020460.97,249.9808807,61714.369140625,-0.000161825710296057,3.04049951899671E-6,1,0.999253354069792,40.0298881530762,1.99655526798201,15.1599999517202,-0.00182614561342476,-0.000355811625693436,0.25,-3.35456880748074E-6,-0.000162107252758447,-3.49209217368065E-6,249.9808807,249.9808807,61707.171875,61721.56640625,57.2667950899676,20.6162427998802,24.807261,0,0,0,40,4449,249.99685,61714.369140625,,,,,,,,,,,,,0,,,,0,,,,,,249.9808807,,,,
,31020558.93,249.9900665,56816.232421875,-0.000140485444047414,2.22423576002275E-6,1,0.999253354069792,40.0298881530762,1.99662148668611,15.1599999517202,-0.00158610128083006,-0.000304727123531129,0.25,-2.54360175588796E-6,-0.000140730089755924,-2.66251916079338E-6,249.9900665,249.9900665,56814.13671875,56818.328125,57.0112025641791,20.6152995026064,24.807261,0,0,0,40,4449,249.9949,56816.232421875,,,,,,,,,,,,,0,,,,0.0049,,,,,,249.9900665,,,,
,31020656.11,249.9894714,51961.32421875,-0.000120774454092057,2.32149877883301E-6,1,0.999253354069792,40.0298881530762,1.99644037405346,15.1599999517202,-0.00135965946527265,-0.000283767473139421,0.25,-4.11317317762266E-6,-0.000120983186754339,-4.21893235651192E-6,249.9894714,249.9894714,51956.19921875,51966.44921875,56.9017745714868,20.6169221723027,24.807261,0,0,0,40,4449,250.00565,51961.32421875,,,,,,,,,,,,,0,,,,-0.0049,,,,,,249.9894714,,,,
,31020754.205,249.98833465,47058.53125,-9.97479027437561E-5,1.71398083548882E-6,1,0.999253354069792,40.0298881530762,1.99648333200562,15.1599999517202,-0.00112368201487,-0.000230256469511473,0.25,-3.03382249731245E-6,-9.9920579263268E-5,-3.12064912493432E-6,249.9880981,249.9885712,47053.3203125,47063.7421875,56.973684395256,20.6192856890732,24.427608,0,0,0,40,4449,250.01645,47058.53125,,,,,,,,,,,,,0,,,,0,,,,,,249.98833465,,,,
,31020852.195,249.9908142,42160.892578125,-8.13763646250492E-5,2.26242330711333E-6,1,0.999253354069792,40.0298881530762,1.99648726875877,15.1599999517202,-0.000919644151769941,-0.000171009976879546,0.25,-9.88134876777382E-7,-8.15184335549438E-5,-1.05645403331852E-6,249.9908142,249.9908142,42155.85546875,42165.9296875,57.3215090863138,20.6180607098976,24.807261,0,0,0,40,4449,250.02395,42160.892578125,,,,,,,,,,,,,0,,,,-0.0049,,,,,,249.9908142,,,,
,31020948.125,249.9896088,37366.341796875,-6.21612254291627E-5,1.83868061383036E-6,1,0.999253354069792,40.0298881530762,1.99647646058208,15.1599999517202,-0.000700471622476204,-0.000142255530807121,0.25,-1.78135183335496E-6,-6.22689011213897E-5,-1.83541047358793E-6,249.9896088,249.9896088,37363.62890625,37369.0546875,56.8783257159099,20.6201896372243,24.427608,0,0,0,40,4449,250.03405,37366.341796875,,,,,,,,,,,,,0,,,,-0.00245,,,,,,249.9896088,,,,
,31021045.175,249.99086,32515.759765625,-4.19111988275552E-5,1.3380918319443E-6,1,0.999253354069792,40.0298881530762,1.99623689141077,15.1599999517202,-0.000472300908139316,-9.54789186465284E-5,0.25,-1.16359523450526E-6,-4.19838196779042E-5,-1.20002452120868E-6,249.99086,249.99086,32510.73828125,32520.78125,56.7438856106022,20.6205597518209,24.427608,0,0,0,40,4449,250.0383,32515.759765625,,,,,,,,,,,,,0,,,,0,,,,,,249.99086,,,,
,31021141.2,249.9891052,27716.4130859375,-2.43192005428179E-5,1.63820078235638E-6,1,0.999253354069792,40.0298881530762,1.99616335870922,15.1599999517202,-0.000270551146092668,-7.5549737121721E-5,0.25,-2.4546460304596E-6,-2.43598751326503E-5,-2.47893436106002E-6,249.9891052,249.9891052,27709.048828125,27723.77734375,56.5867782782368,20.6204692181261,24.427608,0,0,0,40,4449,250.0423,27716.4130859375,,,,,,,,,,,,,0,,,,-0.00245,,,,,,249.9891052,,,,
,31021237.665,249.9892273,22893.3896484375,-6.67178424066193E-6,1.02319704036806E-6,1,0.999253354069792,40.0298881530762,1.99625286803217,15.1599999517202,-7.40800352450643E-5,-2.15734847137349E-5,0.25,-7.48127243235395E-7,-6.68288006219946E-6,-7.54928447303977E-7,249.9892273,249.9892273,22886.115234375,22900.6640625,57.017455592333,20.6209428734177,25.186911,0,0,0,40,4449,250.054,22893.3896484375,,,,,,,,,,,,,0,,,,0,,,,,,249.9892273,,,,
,31021334.325,249.9923401,18063.6181640625,1.31564994109067E-5,1.04684696502178E-6,1,0.999253354069792,40.0298881530762,1.99603136919295,15.1599999517202,0.000151176603524364,1.30768910328501E-5,0.25,-1.12669670550336E-6,1.31805184345252E-5,-1.11783904550939E-6,249.9923401,249.9923401,18058.69921875,18068.537109375,57.0237086204868,20.6246150650535,24.427608,0,0,0,40,4449,250.0634,18063.6181640625,,,,,,,,,,,,,0,,,,-0.00245,,,,,,249.9923401,,,,
,31021428.615,249.9892273,13351.6103515625,2.91478511719718E-5,7.8681078808458E-7,1,0.999253354069792,40.0298881530762,1.99601388236164,15.1599999517202,0.000330847736519902,5.24798580311864E-5,0.25,-4.19896362078112E-7,2.91993553328574E-5,-3.96601568987543E-7,249.9892273,249.9892273,13341.8486328125,13361.3720703125,56.455464687006,20.6255059886413,25.186911,0,0,0,40,4449,250.0717,13351.6103515625,,,,,,,,,,,,,0,,,,0.00245,,,,,,249.9892273,,,,
,31021525.985,249.9939575,8483.2177734375,4.29358771306727E-5,5.2793263236957E-7,1,0.999253354069792,40.0298881530762,1.99605433560891,15.1599999517202,0.00048732349517861,7.75191712338129E-5,0.25,-5.9975928918562E-7,4.30117181188643E-5,-5.65372898909182E-7,249.9939575,249.9939575,8478.0849609375,8488.3505859375,57.2331850636407,20.6267745568952,25.186911,0,0,0,40,4449,250.0726,8483.2177734375,,,,,,,,,,,,,0,,,,-0.00245,,,,,,249.9939575,,,,
,31021621.71,249.9906769,3697.8779296875,4.87299333984987E-5,4.52725332455803E-7,1,0.999253354069792,40.0298881530762,1.99607527366795,15.1599999517202,0.000552268109318549,9.27303641726358E-5,0.25,-2.61277369914727E-7,4.88156645707036E-5,-2.21478762425901E-7,249.9906769,249.9906769,3690.5947265625,3705.1611328125,57.3621537693137,20.6224845372252,24.807261,0,0,0,40,4449,250.089,3697.8779296875,,,,,,,,,,,,,0,,,,0,,,,,,249.9906769,,,,
,31021697.05,249.9943085,-0.296863585710526,2.42963287219106E-5,4.54130264424684E-7,1,0.999253354069792,40.0298881530762,1.99595608991223,15.1599999517202,0.000274663885570169,5.01329165120739E-5,0.25,2.14265379123039E-7,2.4338784349751E-5,2.34724934018845E-7,249.9943085,249.9943085,-0.304475486278534,-0.289251685142517,56.9588334533906,20.6291707253069,24.427608,0,0,0,40,4417,250.0856,-0.296863585710526,,,,,,,,,,,,,0,,,,-0.00245,,,,,,249.9943085,,,,