File: data/doubleLayers/dl_5/ppms/data/DD205_6_HYST_100OE_10K.DAT
[Header]
; VSM Data File (default extension .dat)
; Copyright (c) 2003-2013, Quantum Design, Inc. All rights reserved.
TITLE,
FILEOPENTIME,30938216.02,12/25/2018,9:58 am
BYAPP,VSM,2.0,2.0
INFO,PPMS VSM Option Release 1.4.10 Build 1,APPNAME
INFO,Quantum Design Linear Motor Servo Controller,MOTOR_MODULE_NAME
INFO,3101-100 M1,MOTOR_HW_VERSION
INFO,MMC1014,MOTOR_SERIAL_NUMBER
INFO,SRV No X-over 01.03.11,MOTOR_SOFTWARE_VERSION
INFO,Quantum Design VSM Detection Module,VSM_MODULE_NAME
INFO,3101-150 F0,VSM_HW_VERSION
INFO,VSM707,VSM_SERIAL_NUMBER
INFO,VSM No X-over 01.02.05 May 20 2008 13:51:47,VSM_SOFTWARE_VERSION
INFO,704,PREAMP_SERIAL_NUMBER
INFO,822,COIL_SERIAL_NUMBER
INFO,0,MOMENT_UNITS
INFO,CoFe2O4,SAMPLE_MATERIAL
INFO,AH11 DL,SAMPLE_COMMENT
INFO,30.27,SAMPLE_MASS
INFO,,SAMPLE_VOLUME
INFO,,SAMPLE_MOLECULAR_WEIGHT
INFO,,SAMPLE_SIZE
INFO,,SAMPLE_SHAPE
DATATYPE,COMMENT,1
DATATYPE,TIME,2
STARTUPAXIS,X,2
STARTUPAXIS,Y1,5
[Data]
Comment,Time Stamp (sec),Temperature (K),Magnetic Field (Oe),Moment (emu),M. Std. Err. (emu),Transport Action,Averaging Time (sec),Frequency (Hz),Peak Amplitude (mm),Center Position (mm),Coil Signal' (mV),Coil Signal" (mV),Range (mV),M. Quad. Signal (emu),M. Raw' (emu),M. Raw" (emu),Min. Temperature (K),Max. Temperature (K),Min. Field (Oe),Max. Field (Oe),Mass (grams),Motor Lag (deg),Pressure (Torr),VSM Status (code),Motor Status (code),Measure Status (code),Measure Count,PPMS Status (code),System Temp. (K),System Field (Oe),Sample Position (deg),Bridge 1 Resistance (ohms),Bridge 1 Excitation (에),Bridge 2 Resistance (ohms),Bridge 2 Excitation (에),Bridge 3 Resistance (ohms),Bridge 3 Excitation (에),Bridge 4 Resistance (ohms),Bridge 4 Excitation (에),Signal 1 Vin (V),Signal 2 Vin (V),Digital Inputs (code),Drive 1 Iout (mA),Drive 1 Ipower (W),Drive 2 Iout (mA),Drive 2 Ipower (W),Pressure (),Map 20 (),Map 21 (),Map 22 (),Map 23 (),Map 24 (),Map 25 (),Map 26 (),Map 27 (),Map 28 (),Map 29 ()
,30938232.13,10.0049267,99.3960113525391,,,2,,,,15.9100000429153,,,,,,,10.0049267,10.0049267,99.3960113525391,99.3960113525391,,,12.278775,,,,-99999999,4369,9.9884,99.3960113525391,,,,,,,,,,,,,,,,,,,,,,,10.0049267,,,,
,30938381.54,9.999876,4211.197265625,7.80981175238769E-6,3.59977894031971E-7,1,0.999253354069792,40.0298881530762,1.99680473239154,15.9000009298325,8.77775829442874E-5,1.54605737661245E-5,0.25,-1.28727429839029E-8,7.76676398570664E-6,2.68096003630298E-8,9.999876,9.999876,4203.5634765625,4218.8310546875,55.7621601904482,20.589342414811,13.038077,0,0,0,40,4449,9.9868,4211.197265625,,,,,,,,,,,,,0,,,,0,,,,,,9.999876,,,,
,30938469.25,10.0000925,8597.11376953125,-4.65195418645382E-6,4.35029132776474E-7,1,0.999253354069792,40.0298881530762,1.99659247956401,15.9000009298325,-5.27019676315939E-5,-6.93543510623541E-6,0.25,2.11653618404707E-7,-4.62887823986407E-6,1.85476723041529E-7,10.0000925,10.0000925,8592.103515625,8602.1240234375,56.4679707433137,20.5966974940105,12.278775,0,0,0,40,4449,9.98685,8597.11376953125,,,,,,,,,,,,,0,,,,0,,,,,,10.0000925,,,,
,30938558.76,10.0011845,13070.595703125,-1.60698723943806E-5,4.8900325551008E-7,1,0.999253354069792,40.0298881530762,1.99647520723458,15.9000009298325,-0.000181312514067739,-2.84668723549134E-5,0.25,3.36025183069618E-7,-1.59940715423908E-5,2.42493946732399E-7,10.0011845,10.0011845,13065.4345703125,13075.7568359375,56.1858028478713,20.6014051278615,13.038077,0,0,0,40,4449,9.9859,13070.595703125,,,,,,,,,,,,,0,,,,0,,,,,,10.0011845,,,,
,30938650.24,10.0012665,17643.3603515625,-2.52873267161697E-5,4.33133471949958E-7,1,0.999253354069792,40.0298881530762,1.99652910061978,15.9000009298325,-0.000281676082184467,-6.58606308336624E-5,0.25,-1.334624791109E-6,-2.51674565337791E-5,-1.48147934513836E-6,10.0012665,10.0012665,17638.38671875,17648.333984375,56.2944492120444,20.6009790773509,12.658426,0,0,0,40,4449,9.9844,17643.3603515625,,,,,,,,,,,,,0,,,,0.00245,,,,,,10.0012665,,,,
,30938740.05,9.9998169,22130.810546875,-2.9478240686145E-5,4.43275178146972E-7,1,0.999253354069792,40.0298881530762,1.99632066845035,15.9000009298325,-0.000329335909366358,-7.19400022152535E-5,0.25,-1.11513843666752E-6,-2.93536754932297E-5,-1.29733658221749E-6,9.9998169,9.9998169,22125.826171875,22135.794921875,56.5797436215637,20.6077200278958,13.038077,0,0,0,40,4449,9.9836,22130.810546875,,,,,,,,,,,,,0,,,,0.0049,,,,,,9.9998169,,,,
,30938829.785,9.9999285,26618.7880859375,-3.12155651992071E-5,5.1657609705698E-7,1,0.999253354069792,40.0298881530762,1.99628673559921,15.9000009298325,-0.000350502542983347,-6.72609481564247E-5,0.25,-3.77278240917488E-7,-3.11028666471073E-5,-5.81700703255473E-7,9.9999285,9.9999285,26613.95703125,26623.619140625,56.8204852054868,20.6092322054853,13.038077,0,0,0,40,4449,9.9822,26618.7880859375,,,,,,,,,,,,,0,,,,-0.00245,,,,,,9.9999285,,,,
,30938920.045,10.0005503,31129.0712890625,-3.90097627066578E-5,4.88598160890613E-7,1,0.999253354069792,40.0298881530762,1.9962320785521,15.9000009298325,-0.000436489640239556,-9.36943628973249E-5,0.25,-1.31565894596008E-6,-3.88814319416757E-5,-1.57759317324862E-6,10.0005503,10.0005503,31126.509765625,31131.6328125,56.5828701356406,20.6066254579221,12.278775,0,0,0,40,4449,9.984,31129.0712890625,,,,,,,,,,,,,0,,,,0,,,,,,10.0005503,,,,
,30939009.765,9.9989462,35611.91796875,-4.99625124851493E-5,4.86562340617089E-7,1,0.999253354069792,40.0298881530762,1.99618685493654,15.9000009298325,-0.000564315016233755,-9.21317709983814E-5,0.25,8.03613607356131E-7,-4.98389855026569E-5,4.5146680548663E-7,9.9989462,9.9989462,35604.20703125,35619.62890625,57.085457273506,20.6110670183211,13.038077,0,0,0,40,4449,9.9844,35611.91796875,,,,,,,,,,,,,0,,,,0,,,,,,9.9989462,,,,
,30939100.355,9.9981918,40139.88671875,-6.24309216078851E-5,6.9797760702949E-7,1,0.999253354069792,40.0298881530762,1.99630526170183,15.9000009298325,-0.000701274717617766,-0.000138800980360756,0.25,-1.08216139888653E-6,-6.22917708204758E-5,-1.5269360232395E-6,9.9981918,9.9981918,40132.546875,40147.2265625,56.7087123272368,20.6091492199138,12.658426,0,0,0,40,4449,9.98635,40139.88671875,,,,,,,,,,,,,0,,,,-0.0049,,,,,,9.9981918,,,,
,30939188.045,9.9975958,44522.732421875,-7.41509664918409E-5,8.81066828758494E-7,1,0.999253354069792,40.0298881530762,1.99617652702336,15.9000009298325,-0.000835028122111412,-0.000155085047896913,0.25,-4.04194098152545E-7,-7.40261357096995E-5,-9.43039408939401E-7,9.9975958,9.9975958,44515.24609375,44530.21875,56.5688008222944,20.6097052964808,13.038077,0,0,0,40,4449,9.98885,44522.732421875,,,,,,,,,,,,,0,,,,0.00245,,,,,,9.9975958,,,,
,30939276.27,9.996623,48930.349609375,-8.98919207962895E-5,7.08206167883499E-7,1,0.999253354069792,40.0298881530762,1.9960105203328,15.9000009298325,-0.00101067070107253,-0.00019918348205589,0.25,-1.46763466771553E-6,-8.97743037625056E-5,-2.12744895967434E-6,9.996623,9.996623,48922.671875,48938.02734375,56.9510171681983,20.6133948121145,12.278775,0,0,0,40,4449,9.9917,48930.349609375,,,,,,,,,,,,,0,,,,-0.00245,,,,,,9.996623,,,,
,30939367.985,9.9956307,53515.771484375,-0.000106245123585421,8.62447191605767E-7,1,0.999253354069792,40.0298881530762,1.99601526182615,15.9000009298325,-0.00119916573689817,-0.000212898062104984,0.25,2.768634709947E-7,-0.000106169995972495,-5.11126512044605E-7,9.9954948,9.9957666,53510.71875,53520.82421875,56.4421770021791,20.6158754023051,12.658426,0,0,0,40,4449,9.9959,53515.771484375,,,,,,,,,,,,,0,,,,0.00245,,,,,,9.9956307,,,,
,30939466.195,9.9949131,58425.95703125,-0.000125670510376715,6.58937904294147E-7,1,0.999253354069792,40.0298881530762,1.99603326654992,15.9000009298325,-0.0014162775685175,-0.000267639624353687,0.25,-1.06002960251428E-6,-0.000125631352214918,-1.99494738469878E-6,9.9948235,9.9950027,58418.3984375,58433.515625,57.0338697912368,20.6124966355522,12.658426,0,0,0,40,4449,9.9996,58425.95703125,,,,,,,,,,,,,0,,,,0.00245,,,,,,9.9949131,,,,
,30939565.275,9.9949379,63376.458984375,-0.000149318415650676,9.58090669445353E-7,1,0.999253354069792,40.0298881530762,1.99613465934703,15.9000009298325,-0.00168553195656691,-0.000307678406808655,0.25,-3.31935895776989E-7,-0.00014934765556457,-1.44266521615783E-6,9.9949379,9.9949379,63371.6015625,63381.31640625,56.9455457685637,20.6119046609026,13.038077,0,0,0,40,4449,10.0038,63376.458984375,,,,,,,,,,,,,0,,,,0,,,,,,9.9949379,,,,
,30939663.96,9.995038,68308.94921875,-0.000164257324199524,8.44210421549141E-7,1,0.999253354069792,40.0298881530762,1.99596937277817,15.9000009298325,-0.00185687670273039,-0.00032721789479592,0.25,6.35410652374861E-7,-0.000164368752677913,-5.81083775336392E-7,9.995038,9.995038,68303.9921875,68313.90625,56.7462304961599,20.6172136934917,13.038077,0,0,0,40,4449,10.0092,68308.94921875,,,,,,,,,,,,,0,,,,0,,,,,,9.995038,,,,
,30939758.415,9.994545,73031.71484375,-0.000182917328552811,7.5639927140183E-7,1,0.999253354069792,40.0298881530762,1.99593799826447,15.9000009298325,-0.00206636284518619,-0.000377004896773917,0.25,-4.05884644824663E-7,-0.000183105815746027,-1.75240647778254E-6,9.994545,9.994545,73021.6796875,73041.75,56.9752476522945,20.6177060933875,12.658426,0,0,0,40,4449,10.01395,73031.71484375,,,,,,,,,,,,,0,,,,0,,,,,,9.994545,,,,
,30939856.98,9.9963145,77957.65625,-0.000202946772344562,8.85799571950062E-7,1,0.999253354069792,40.0298881530762,1.99596043069501,15.9000009298325,-0.00229617961977148,-0.000403846461463547,0.25,8.26951664201019E-7,-0.000203244608617263,-6.51108638039323E-7,9.9963045,9.9963245,77950.3984375,77964.9140625,57.0432493334676,20.6145681604105,12.278775,0,0,0,40,4449,10.01885,77957.65625,,,,,,,,,,,,,0,,,,0,,,,,,9.9963145,,,,
,30939958.08,9.9950523,83010.6015625,-0.000224551511708381,8.1416539909269E-7,1,0.999253354069792,40.0298881530762,1.99598194596141,15.9000009298325,-0.0025400756620165,-0.00045547505622737,0.25,1.46169124528118E-7,-0.000224960036004924,-1.47045585759946E-6,9.9950523,9.9950523,83008.3203125,83012.8828125,56.7079306987175,20.6155587953846,12.658426,0,0,0,40,4449,10.02225,83010.6015625,,,,,,,,,,,,,0,,,,0,,,,,,9.9950523,,,,
,30940053.555,9.9948034,87783.67578125,-0.00024390211594682,9.39632177719338E-7,1,0.999253354069792,40.0298881530762,1.99585072069446,15.9000009298325,-0.00275413148934501,-0.000525862413746724,0.25,-2.60549864285652E-6,-0.000244407546820541,-4.34396243233581E-6,9.9945974,9.9950094,87776.109375,87791.2421875,56.997133250833,20.6129119494127,11.899124,0,0,0,40,4449,10.028,87783.67578125,,,,,,,,,,,,,0,,,,-0.0049,,,,,,9.9948034,,,,
,30940167.04,9.9971218,87598.2421875,-0.000244964500563956,8.91152994155758E-7,1,0.999253354069792,40.0298881530762,1.99607509021646,15.9000009298325,-0.00277571544275357,-0.000476363265054291,0.25,1.96573352811502E-6,-0.000245501620808518,2.2855814934602E-7,9.9971218,9.9971218,87593.1015625,87603.3828125,57.1112510146407,20.6179621787704,11.899124,0,0,0,40,4449,10.0303,87598.2421875,,,,,,,,,,,,,0,,,,0,,,,,,9.9971218,,,,
,30940263.405,10.0002623,82784.69921875,-0.0002240514829854,6.3233369610739E-7,1,0.999253354069792,40.0298881530762,1.99616056651517,15.9000009298325,-0.00253672533448855,-0.000442654881292421,0.25,1.19333610755524E-6,-0.000224462986848271,-4.18761387180823E-7,10.0002623,10.0002623,82779.921875,82789.4765625,56.8611298884868,20.6207808782905,12.658426,0,0,0,40,4449,10.02845,82784.69921875,,,,,,,,,,,,,0,,,,0,,,,,,10.0002623,,,,
,30940364.31,10.0021458,77738.51171875,-0.000205389946175855,7.1330064664475E-7,1,0.999253354069792,40.0298881530762,1.99606336390902,15.9000009298325,-0.00232735244580026,-0.000389535855617964,0.25,2.53454178135933E-6,-0.000205700278250073,1.04037118812757E-6,10.0021458,10.0021458,77731,77746.0234375,56.8892685151791,20.6162900749069,12.278775,0,0,0,40,4449,10.0263,77738.51171875,,,,,,,,,,,,,0,,,,-0.00245,,,,,,10.0021458,,,,
,30940465.79,10.0050278,72665.078125,-0.000185384446960439,8.29457360859138E-7,1,0.999253354069792,40.0298881530762,1.99589158168399,15.9000009298325,-0.00209202245638192,-0.000393733581467145,0.25,-1.44261582275465E-6,-0.000185562306636477,-2.80917060644636E-6,10.0050278,10.0050278,72657.578125,72672.578125,57.0612267894099,20.6192567758581,11.899124,0,0,0,40,4449,10.02595,72665.078125,,,,,,,,,,,,,0,,,,-0.00245,,,,,,10.0050278,,,,
,30940567.45,10.0030565,67584.9453125,-0.000166007740063293,7.95481815179984E-7,1,0.999253354069792,40.0298881530762,1.99605544226099,15.9000009298325,-0.00187714411135168,-0.000327813053639874,0.25,8.98593963393583E-7,-0.000166111839468031,-3.31724665773676E-7,10.0030565,10.0030565,67579.9375,67589.953125,56.7931282073137,20.6176972589237,11.899124,0,0,0,40,4449,10.0204,67584.9453125,,,,,,,,,,,,,0,,,,0,,,,,,10.0030565,,,,
,30940667.455,10.0040417,62584.357421875,-0.000143889623482287,6.7755893960049E-7,1,0.999253354069792,40.0298881530762,1.99588933785584,15.9000009298325,-0.0016229027214649,-0.0003022063763426,0.25,-8.30533814154487E-7,-0.000143903589900771,-1.90127601819006E-6,10.0040417,10.0040417,62572.00390625,62596.7109375,56.9150622563137,20.6225059468165,11.899124,0,0,0,40,4449,10.01635,62584.357421875,,,,,,,,,,,,,0,,,,-0.0049,,,,,,10.0040417,,,,
,30940767.875,10.003243,57565.83203125,-0.000122327385517791,9.33394492976627E-7,1,0.999253354069792,40.0298881530762,1.99598117444657,15.9000009298325,-0.00138400649609585,-0.000229684743429018,0.25,1.69769255900606E-6,-0.000122299510645772,7.87121459943967E-7,10.0032015,10.0032845,57553.28515625,57578.37890625,57.1034347294484,20.6234096472915,12.658426,0,0,0,40,4449,10.0138,57565.83203125,,,,,,,,,,,,,0,,,,-0.0049,,,,,,10.003243,,,,
,30940869.775,10.0026979,52472.703125,-0.000105147782020719,8.57907343378182E-7,1,0.999253354069792,40.0298881530762,1.9959463388905,15.9000009298325,-0.00118224606060682,-0.000234928090573041,0.25,-1.8774760596772E-6,-0.000105046579350662,-2.65452928131916E-6,10.0026979,10.0026979,52465.203125,52480.203125,56.8978664288906,20.6236671549489,12.278775,0,0,0,40,4449,10.0101,52472.703125,,,,,,,,,,,,,0,,,,0,,,,,,10.0026979,,,,
,30940968.31,10.003931,47548.490234375,-8.38064808770172E-5,8.92094933993042E-7,1,0.999253354069792,40.0298881530762,1.99580013069008,15.9000009298325,-0.000944615191115851,-0.000171263718473648,0.25,-9.36349719164002E-8,-8.36943294814209E-5,-7.08364179886277E-7,10.003931,10.003931,47538.45703125,47558.5234375,57.0737328457176,20.625319963258,12.278775,0,0,0,40,4449,10.0065,47548.490234375,,,,,,,,,,,,,0,,,,0,,,,,,10.003931,,,,
,30941068.155,10.0031433,42558.078125,-6.25664169861938E-5,6.8128274904994E-7,1,0.999253354069792,40.0298881530762,1.99573770622062,15.9000009298325,-0.00070796653652193,-0.000110321277800657,0.25,1.47370397484168E-6,-6.24613416531271E-5,1.01872963550745E-6,10.0031433,10.0031433,42555.66796875,42560.48828125,57.1081245005637,20.6285250122324,12.278775,0,0,0,40,4449,10.0024,42558.078125,,,,,,,,,,,,,0,,,,0,,,,,,10.0031433,,,,
,30941169.515,10.0026522,37488.0625,-4.73844763837284E-5,6.21414635393724E-7,1,0.999253354069792,40.0298881530762,1.99596267001861,15.9000009298325,-0.000530775688595333,-0.00011224227563027,0.25,-1.44154622515658E-6,-4.72612244127265E-5,-1.77334862605785E-6,10.0026522,10.0026522,37478.1328125,37497.9921875,56.861911517006,20.6266516428267,12.658426,0,0,0,40,4449,10.0011,37488.0625,,,,,,,,,,,,,0,,,,-0.0049,,,,,,10.0026522,,,,
,30941271.32,10.0058956,32403.5546875,-2.83672023204373E-5,5.67769771390099E-7,1,0.999253354069792,40.0298881530762,1.99583320939755,15.9000009298325,-0.000318628918834906,-6.1230008388766E-5,0.25,-3.42240280139846E-7,-2.82818685805956E-5,-5.36268308774399E-7,10.0055618,10.0062294,32391.16796875,32415.94140625,56.9815006804483,20.62624967325,12.278775,0,0,0,40,4449,10.00155,32403.5546875,,,,,,,,,,,,,0,,,,0.00245,,,,,,10.0058956,,,,
,30941362.775,10.0022144,27831.1103515625,-1.1116509524654E-5,5.09839310844659E-7,1,0.999253354069792,40.0298881530762,1.99579942289471,15.9000009298325,-0.000124371035637593,-2.63842722191009E-5,0.25,-3.4995863872449E-7,-1.10763273132573E-5,-4.22755993400237E-7,10.0022144,10.0022144,27823.775390625,27838.4453125,56.8079791491791,20.626558082164,12.658426,0,0,0,40,4449,9.9996,27831.1103515625,,,,,,,,,,,,,0,,,,0.0049,,,,,,10.0022144,,,,
,30941453.805,10.0010319,23283.076171875,4.2995964009805E-6,4.33445000008532E-7,1,0.999253354069792,40.0298881530762,1.99579511625808,15.9000009298325,4.81369378115753E-5,9.89030460329436E-6,0.25,1.08898219142353E-7,4.28225628144934E-6,1.36000170732151E-7,10.0010319,10.0010319,23280.56640625,23285.5859375,57.1581487257945,20.6285902195527,12.278775,0,0,0,40,4449,9.9986,23283.076171875,,,,,,,,,,,,,0,,,,0,,,,,,10.0010319,,,,
,30941542.21,10.0011225,18862.8623046875,2.02364914081706E-5,3.85240568791404E-7,1,0.999253354069792,40.0298881530762,1.99557419856522,15.9000009298325,0.000228343938039176,3.5882240927119E-5,0.25,-4.28588959518021E-7,2.01519852145126E-5,-3.02844112583721E-7,10.0011225,10.0011225,18847.923828125,18877.80078125,57.1214121853907,20.6293249269664,12.658426,0,0,0,40,4449,9.9977,18862.8623046875,,,,,,,,,,,,,0,,,,-0.00245,,,,,,10.0011225,,,,
,30941630.485,9.9999313,14452.6958007813,3.52043307435988E-5,3.76321894233208E-7,1,0.999253354069792,40.0298881530762,1.99570029856395,15.9000009298325,0.000395382368467665,7.19896901559711E-5,0.25,1.1841718507471E-7,3.5037665430823E-5,3.22696208643293E-7,9.9999313,9.9999313,14445.27734375,14460.1142578125,57.2863358029484,20.6295966886976,11.899124,0,0,0,40,4449,9.9976,14452.6958007813,,,,,,,,,,,,,0,,,,-0.00245,,,,,,9.9999313,,,,
,30941717.97,9.9991655,10080.3793945312,4.94581490517688E-5,3.56758679244099E-7,1,0.999253354069792,40.0298881530762,1.99554909519331,15.9000009298325,0.000554690731327624,0.000104056106387661,0.25,4.45942743024543E-7,4.92040537350962E-5,7.15691195489531E-7,9.9991655,9.9991655,10072.7509765625,10088.0078125,57.1112510146407,20.6306550344051,11.899124,0,0,0,40,4449,9.99935,10080.3793945312,,,,,,,,,,,,,0,,,,0,,,,,,9.9991655,,,,
,30941806.14,9.9982595,5674.55004882812,6.37593171899138E-5,3.07655217586788E-7,1,0.999253354069792,40.0298881530762,1.99560818653812,15.9000009298325,0.000716030517082389,0.000127551761443502,0.25,1.21481572571766E-8,6.34135720855898E-5,3.42099082366456E-7,9.9982595,9.9982595,5669.7021484375,5679.39794921875,57.1620568683907,20.6304112714497,12.278775,0,0,0,40,4449,10.00035,5674.55004882812,,,,,,,,,,,,,0,,,,0.0049,,,,,,9.9982595,,,,
,30941895.85,10.0000896,1188.57836914062,7.73977999474045E-5,3.28671562566738E-7,1,0.999253354069792,40.0298881530762,1.9954843143371,15.9000009298325,0.000868738790882326,0.000155696869212804,0.25,1.19287540386358E-7,7.69563525352621E-5,4.96031489556142E-7,10.0000896,10.0000896,1186.16491699219,1190.99182128906,57.2198973788137,20.6312711932565,11.899124,0,0,0,40,4449,10,1188.57836914062,,,,,,,,,,,,,0,,,,-0.0049,,,,,,10.0000896,,,,
,30941989.18,9.998353,-3471.896484375,8.84526780039004E-5,3.20808560754647E-7,1,0.999253354069792,40.0298881530762,1.99552026133798,15.9000009298325,0.000992267571572991,0.00018190468384259,0.25,4.74679350888305E-7,8.79578483725732E-5,9.1616279972299E-7,9.998353,9.998353,-3471.896484375,-3471.896484375,57.2464727484676,20.6298549040159,11.899124,0,0,0,40,4449,10.0007,-3471.896484375,,,,,,,,,,,,,0,,,,-0.0049,,,,,,9.998353,,,,
,30942089.22,9.9989319,-8471.29052734375,0.000100729047222553,3.499332090668E-7,1,0.999253354069792,40.0298881530762,1.99567372940364,15.9000009298325,0.00113069737940911,0.000205949191915648,0.25,3.89406615245759E-7,0.000100201601694492,9.29390746251434E-7,9.9989319,9.9989319,-8481.314453125,-8461.2666015625,57.0862389020253,20.631057758027,12.278775,0,0,0,40,4449,10.0005,-8471.29052734375,,,,,,,,,,,,,0,,,,-0.00245,,,,,,9.9989319,,,,
,30942191.905,10.0002813,-13606.9965820312,0.000106885608355484,3.74070314836621E-7,1,0.999253354069792,40.0298881530762,1.99555483575471,15.9000009298325,0.00119989090346925,0.000220639702881707,0.25,5.52885356804965E-7,0.0001063704820165,1.16567441057156E-6,10.0002813,10.0002813,-13614.5,-13599.4931640625,57.2019199228714,20.6333560473688,11.899124,0,0,0,40,4449,10.0014,-13606.9965820312,,,,,,,,,,,,,0,,,,0,,,,,,10.0002813,,,,
,30942291.09,10.0004287,-18561.810546875,0.000100370175656245,3.93918753032105E-7,1,0.999253354069792,40.0298881530762,1.99563071133655,15.9000009298325,0.00112637868212439,0.000212474820063569,0.25,9.45714019906409E-7,9.99293605502958E-5,1.55413091510255E-6,10.00035,10.0005074,-18571.755859375,-18551.865234375,57.108906129083,20.6331099546208,12.278775,0,0,0,40,4449,10.0007,-18561.810546875,,,,,,,,,,,,,0,,,,0.00245,,,,,,10.0004287,,,,
,30942393.38,9.9995804,-23676.275390625,7.96638371978455E-5,4.79396301671329E-7,1,0.999253354069792,40.0298881530762,1.99580812003535,15.9000009298325,0.00089359614995691,0.000173973197788628,0.25,1.19031868826068E-6,7.93509816634018E-5,1.69757952101385E-6,9.9995804,9.9995804,-23683.931640625,-23668.619140625,57.0119841926983,20.635681021447,11.519473,0,0,0,40,4449,10.0008,-23676.275390625,,,,,,,,,,,,,0,,,,-0.00245,,,,,,9.9995804,,,,
,30942495.235,10.00010535,-28768.814453125,6.18929988866014E-5,4.98825096289473E-7,1,0.999253354069792,40.0298881530762,1.99558224935592,15.9000009298325,0.000695043435564339,0.000132458179985851,0.25,6.62146201693563E-7,6.16838535704447E-5,1.07487464255587E-6,10.0000696,10.0001411,-28776.30078125,-28761.328125,57.1894138665637,20.6349120857294,12.658426,0,0,0,40,4449,10.00055,-28768.814453125,,,,,,,,,,,,,0,,,,0.00245,,,,,,10.00010535,,,,
,30942598.61,9.9994354,-33930.5,5.79588650225621E-5,6.1980707085211E-7,1,0.999253354069792,40.0298881530762,1.99551546199718,15.9000009298325,0.000653679927132717,0.000110294046495396,0.25,-6.2013132078234E-7,5.7802997807864E-5,-2.16179740147527E-7,9.9994354,9.9994354,-33938.07421875,-33922.92578125,57.1182856713137,20.6355500852064,11.519473,0,0,0,40,4449,10.0015,-33930.5,,,,,,,,,,,,,0,,,,0,,,,,,9.9994354,,,,
,30942699.165,9.9989929,-38957.728515625,6.46638831086212E-5,5.95873492383899E-7,1,0.999253354069792,40.0298881530762,1.99551780054097,15.9000009298325,0.000725743276053789,0.000145080333894019,0.25,1.2463406239303E-6,6.45108071811158E-5,1.70422864652848E-6,9.9989929,9.9989929,-38965.06640625,-38950.390625,57.5919525539676,20.6354370214903,12.278775,0,0,0,40,4449,10.0026,-38957.728515625,,,,,,,,,,,,,0,,,,-0.00245,,,,,,9.9989929,,,,
,30942801.89,9.9986124,-44089.880859375,7.60855175909185E-5,6.37501824073135E-7,1,0.999253354069792,40.0298881530762,1.99577006907175,15.9000009298325,0.000856769256974525,0.000158198193120991,0.25,3.36071525258228E-7,7.59545643851499E-5,8.88334540721013E-7,9.9986124,9.9986124,-44097.4375,-44082.32421875,57.1042163579676,20.6341688457304,11.899124,0,0,0,40,4449,10.00505,-44089.880859375,,,,,,,,,,,,,0,,,,-0.0049,,,,,,9.9986124,,,,
,30942904.625,9.997344,-49227.697265625,9.46526953452141E-5,6.68545536683651E-7,1,0.999253354069792,40.0298881530762,1.99608618243779,15.9000009298325,0.00106725971439831,0.000193140767803912,0.25,7.24416320728458E-8,9.45425619575354E-5,7.69382516623212E-7,9.997344,9.997344,-49235.14453125,-49220.25,57.1128142716791,20.6376315313542,11.899124,0,0,0,40,4449,10.0075,-49227.697265625,,,,,,,,,,,,,0,,,,-0.00245,,,,,,9.997344,,,,
,30943006.385,9.9963398,-54312.017578125,0.000110799570330966,6.23852767397466E-7,1,0.999253354069792,40.0298881530762,1.99602144963427,15.9000009298325,0.00124729569096076,0.000240781511099479,0.25,1.37150796208178E-6,0.000110717624480508,2.19290183003063E-6,9.9963398,9.9963398,-54316.953125,-54307.08203125,57.2386564632753,20.6360569937138,11.899124,0,0,0,40,4449,10.01,-54312.017578125,,,,,,,,,,,,,0,,,,-0.00245,,,,,,9.9963398,,,,
,30943107.17,9.9971676,-59349.044921875,0.000131983099353912,7.9996211266223E-7,1,0.999253354069792,40.0298881530762,1.99603439020358,15.9000009298325,0.00148620446150069,0.000288573702140745,0.25,1.7745192854009E-6,0.000131948613319979,2.75659646684988E-6,9.9971676,9.9971676,-59358.9296875,-59339.16015625,57.5020652742561,20.6394218858127,11.899124,0,0,0,40,4449,10.0139,-59349.044921875,,,,,,,,,,,,,0,,,,0.00245,,,,,,9.9971676,,,,
,30943206.68,9.9957628,-64324.314453125,0.000151095177588737,1.12259889412701E-6,1,0.999253354069792,40.0298881530762,1.99601151763245,15.9000009298325,0.00170404082164657,0.000320188130936116,0.25,1.11935965346026E-6,0.000151131906414297,2.24299724144868E-6,9.9957628,9.9957628,-64336.9453125,-64311.68359375,57.5348936720638,20.6417754118862,11.899124,0,0,0,40,4449,10.01585,-64324.314453125,,,,,,,,,,,,,0,,,,-0.0049,,,,,,9.9957628,,,,
,30943308.365,9.99608995,-69403.47265625,0.000168501482460557,7.74504601966546E-7,1,0.999253354069792,40.0298881530762,1.99581619025042,15.9000009298325,0.00190701976066729,0.000323886225557178,0.25,-1.69400089198157E-6,0.000168639322287466,-4.48554105064013E-7,9.9959717,9.9962082,-69413.4765625,-69393.46875,57.220679007333,20.6401411674176,11.899124,0,0,0,40,4449,10.02115,-69403.47265625,,,,,,,,,,,,,0,,,,0,,,,,,9.99608995,,,,
,30943411.41,9.99574755,-74555.49609375,0.000188524910485565,7.95394146958886E-7,1,0.999253354069792,40.0298881530762,1.99579351886143,15.9000009298325,0.00212951952556359,0.000390281478336473,0.25,5.72469286789952E-7,0.000188741335217148,1.95676204148784E-6,9.9956989,9.9957962,-74565.546875,-74545.4453125,57.2558522906984,20.6394812160928,11.519473,0,0,0,40,4449,10.02445,-74555.49609375,,,,,,,,,,,,,0,,,,-0.00245,,,,,,9.99574755,,,,
,30943511.77,9.99523635,-79569.3828125,0.000211426194672612,8.2801998374431E-7,1,0.999253354069792,40.0298881530762,1.99553727437127,15.9000009298325,0.00238671695624945,0.000449616889292046,0.25,1.70338858135686E-6,0.00021174379721108,3.24149196273863E-6,9.9951715,9.9953012,-79582.015625,-79556.75,57.2800827747945,20.6406797116945,12.278775,0,0,0,40,4449,10.0301,-79569.3828125,,,,,,,,,,,,,0,,,,0,,,,,,9.99523635,,,,
,30943614.61,9.9952621,-84709.1953125,0.000229735732385707,8.83896719787835E-7,1,0.999253354069792,40.0298881530762,1.99576313352216,15.9000009298325,0.00259962525935729,0.00046119004107265,0.25,-5.66901479193344E-7,0.000230184509521001,1.07867542319365E-6,9.9952621,9.9952621,-84719.578125,-84698.8125,57.4301554504868,20.6418449631769,11.519473,0,0,0,40,4449,10.0335,-84709.1953125,,,,,,,,,,,,,0,,,,0,,,,,,9.9952621,,,,
,30943708.485,9.9947195,-89401.0546875,0.000249676267589477,9.17654741304114E-7,1,0.999253354069792,40.0298881530762,1.99601230156576,15.9000009298325,0.00282473665118502,0.000511272189142089,0.25,2.77681183731005E-7,0.000250237671074683,2.04352711597126E-6,9.9947195,9.9947195,-89411.1171875,-89390.9921875,57.3816944822945,20.6400684234578,12.278775,0,0,0,40,4449,10.0381,-89401.0546875,,,,,,,,,,,,,0,,,,0,,,,,,9.9947195,,,,
,30943824.19,9.9990091,-85959.76953125,0.000236969085517768,9.78096656937423E-7,1,0.999253354069792,40.0298881530762,1.99563795704428,15.9000009298325,0.00268135186771094,0.000476817815825559,0.25,-4.81949506782223E-7,0.000237451968238407,1.20965310637169E-6,9.9990091,9.9990091,-85964.421875,-85955.1171875,57.3981086811984,20.6429940029217,12.278775,0,0,0,40,4449,10.0386,-85959.76953125,,,,,,,,,,,,,0,,,,0.0049,,,,,,9.9990091,,,,
,30943916.585,10.0018854,-81342.51171875,0.000216792507927659,8.35053508094684E-7,1,0.999253354069792,40.0298881530762,1.99565214258742,15.9000009298325,0.0024519870354854,0.000437595613913598,0.25,-3.26494779059719E-7,0.000217161884640146,1.24064765937165E-6,10.0018854,10.0018854,-81357.578125,-81327.4453125,57.1925403806407,20.643444034983,11.899124,0,0,0,40,4449,10.0369,-81342.51171875,,,,,,,,,,,,,0,,,,0,,,,,,10.0018854,,,,
,30944014.48,10.0033445,-76450.12109375,0.000200470391557636,7.86424316254271E-7,1,0.999253354069792,40.0298881530762,1.99601946041282,15.9000009298325,0.00226047335476478,0.000440454500004242,0.25,2.85558752297664E-6,0.000200714265751189,4.32522859136857E-6,10.0033445,10.0033445,-76460.21875,-76440.0234375,57.2722664896022,20.6413128889563,11.899124,0,0,0,40,4449,10.0334,-76450.12109375,,,,,,,,,,,,,0,,,,0,,,,,,10.0033445,,,,
,30944109.63,10.0038843,-71695.48046875,0.000182066623709504,7.79583042198953E-7,1,0.999253354069792,40.0298881530762,1.99574877524824,15.9000009298325,0.00205122740179547,0.000403554518066358,0.25,2.91254082137291E-6,0.000182215669212505,4.25800159793086E-6,10.0038843,10.0038843,-71697.9140625,-71693.046875,57.3347967711407,20.643148597177,11.519473,0,0,0,40,4449,10.0298,-71695.48046875,,,,,,,,,,,,,0,,,,0,,,,,,10.0038843,,,,
,30944204.845,10.0038872,-66935.98046875,0.000160472235856107,5.84877937269377E-7,1,0.999253354069792,40.0298881530762,1.99574670125258,15.9000009298325,0.00180594856574445,0.000362493715986071,0.25,3.17473947868035E-6,0.000160533773534052,4.36700019132484E-6,10.0038872,10.0038872,-66941.140625,-66930.8203125,57.1425161554099,20.6413790185245,11.899124,0,0,0,40,4449,10.02575,-66935.98046875,,,,,,,,,,,,,0,,,,-0.0049,,,,,,10.0038872,,,,
,30944296.34,10.003644,-62362.921875,0.000143162003081814,6.20607081003201E-7,1,0.999253354069792,40.0298881530762,1.99578533498732,15.9000009298325,0.00161362896098324,0.000305949578286438,0.25,1.29501767578357E-6,0.000143169501567318,2.36046366372718E-6,10.003644,10.003644,-62372.94921875,-62352.89453125,57.146424298006,20.6453131822262,11.519473,0,0,0,40,4449,10.02285,-62362.921875,,,,,,,,,,,,,0,,,,0.00245,,,,,,10.003644,,,,
,30944391.685,10.0040569,-57598.130859375,0.000123376585763904,5.37162240941859E-7,1,0.999253354069792,40.0298881530762,1.9954306532126,15.9000009298325,0.0013886482134016,0.000269684537410435,0.25,1.66368032235641E-6,0.000123323740014077,2.58096194934473E-6,10.0040569,10.0040569,-57610.58984375,-57585.671875,57.0416860764291,20.6449712935801,11.899124,0,0,0,40,4449,10.0194,-57598.130859375,,,,,,,,,,,,,0,,,,0,,,,,,10.0040569,,,,
,30944484.95,10.004137,-52936.109375,0.000104066103884653,9.44192475445444E-7,1,0.999253354069792,40.0298881530762,1.99564756514468,15.9000009298325,0.00117448530481093,0.00020743992290624,0.25,-3.63154301685363E-7,0.000103987201982345,4.08209897924758E-7,10.004137,10.004137,-52943.5078125,-52928.7109375,57.3301070000253,20.6466480648285,11.519473,0,0,0,40,4449,10.0165,-52936.109375,,,,,,,,,,,,,0,,,,0.0049,,,,,,10.004137,,,,
,30944579,10.0034199,-48236.1484375,8.68359327613783E-5,7.28008857765696E-7,1,0.999253354069792,40.0298881530762,1.9955907496781,15.9000009298325,0.000978524443737096,0.000178604900113844,0.25,1.98541690297698E-7,8.6725116737585E-5,8.36392945490356E-7,10.0034199,10.0034199,-48241.125,-48231.171875,57.0737328457176,20.6458618821667,11.899124,0,0,0,40,4449,10.0116,-48236.1484375,,,,,,,,,,,,,0,,,,-0.0049,,,,,,10.0034199,,,,
,30944674.715,10.0041695,-43451.51171875,6.96073252115953E-5,5.82814972632884E-7,1,0.999253354069792,40.0298881530762,1.99528133380603,15.9000009298325,0.000782510308964029,0.000150654240100219,0.25,8.38308660939387E-7,6.94790244104752E-5,1.34153957826748E-6,10.0041695,10.0041695,-43459.12890625,-43443.89453125,57.1628384969099,20.6456009628777,11.899124,0,0,0,40,4449,10.0096,-43451.51171875,,,,,,,,,,,,,0,,,,0,,,,,,10.0041695,,,,
,30944766.57,10.0031528,-38863.890625,5.19647411234473E-5,5.308368703918E-7,1,0.999253354069792,40.0298881530762,1.99553765058553,15.9000009298325,0.000583674081804406,0.000114045457162026,0.25,7.75938371680147E-7,5.18428198414742E-5,1.14424163988096E-6,10.0031528,10.0031528,-38876.15234375,-38851.62890625,57.1401712698522,20.6408054844007,12.278775,0,0,0,40,4449,10.0067,-38863.890625,,,,,,,,,,,,,0,,,,0.00245,,,,,,10.0031528,,,,
,30944858.89,10.0027294,-34249.365234375,3.28680811010127E-5,5.65340603161818E-7,1,0.999253354069792,40.0298881530762,1.99559620024567,15.9000009298325,0.000370651185217529,6.29590790218689E-5,0.25,-3.15893788935532E-7,3.27805569826575E-5,-8.64972097651841E-8,10.0027294,10.0027294,-34254.31640625,-34244.4140625,57.1331366131791,20.6410445527983,11.899124,0,0,0,40,4449,10.006,-34249.365234375,,,,,,,,,,,,,0,,,,0,,,,,,10.0027294,,,,
,30944952.46,10.0016832,-29571.865234375,1.67184229014916E-5,4.38692561666398E-7,1,0.999253354069792,40.0298881530762,1.99557845712097,15.9000009298325,0.000187968231274139,3.46187125657063E-5,0.25,7.47879976731065E-8,1.66640279716729E-5,1.87290892767266E-7,10.0016832,10.0016832,-29581.873046875,-29561.857421875,56.9807190519291,20.6375461319344,11.899124,0,0,0,40,4449,10.00515,-29571.865234375,,,,,,,,,,,,,0,,,,-0.00245,,,,,,10.0016832,,,,
,30945044.63,10.0015554,-24964.568359375,1.27599227843612E-6,3.90523901052438E-7,1,0.999253354069792,40.0298881530762,1.99542525728369,15.9000009298325,1.33540741932099E-5,8.12985545571682E-6,0.25,4.94091799430458E-7,1.26805919984698E-6,5.00556764005478E-7,10.0015554,10.0015554,-24969.486328125,-24959.650390625,57.0964000727753,20.6417541273093,11.899124,0,0,0,40,4449,10.0032,-24964.568359375,,,,,,,,,,,,,0,,,,0.0049,,,,,,10.0015554,,,,
,30945135.6,9.9997053,-20420.0625,-1.48527153667578E-5,4.24803040822237E-7,1,0.999253354069792,40.0298881530762,1.99570894094735,15.9000009298325,-0.000166052067854947,-3.51631968937438E-5,0.25,-4.68519102746442E-7,-1.47880879424739E-5,-5.59017132814757E-7,9.9997053,9.9997053,-20427.646484375,-20412.478515625,56.9994781363906,20.6415496721508,12.278775,0,0,0,40,4449,10.004,-20420.0625,,,,,,,,,,,,,0,,,,0.00245,,,,,,9.9997053,,,,
,30945229.01,10.0000038,-15751.9760742187,-3.12402834201375E-5,3.90172253309821E-7,1,0.999253354069792,40.0298881530762,1.99527138037358,15.9000009298325,-0.000351153513013658,-6.20753805585628E-5,0.25,5.8202135453186E-8,-3.10970109286068E-5,-1.26706887700447E-7,10.0000038,10.0000038,-15759.56640625,-15744.3857421875,57.1972301517561,20.6419682761843,11.899124,0,0,0,40,4449,10.00435,-15751.9760742187,,,,,,,,,,,,,0,,,,-0.00245,,,,,,10.0000038,,,,
,30945327.405,9.9982376,-10832.3403320312,-4.7438139742253E-5,4.04518543970809E-7,1,0.999253354069792,40.0298881530762,1.9957924735276,15.9000009298325,-0.000532657277404775,-9.6869215266711E-5,0.25,-1.62113789736751E-7,-4.71987936975946E-5,-4.24839144695741E-7,9.9982376,9.9982376,-10842.0439453125,-10822.63671875,57.0315249056791,20.6404598026586,11.519473,0,0,0,40,4449,10.0037,-10832.3403320312,,,,,,,,,,,,,0,,,,0,,,,,,9.9982376,,,,
,30945424.98,9.9988241,-5956.58447265625,-6.32075469680614E-5,3.33318275037881E-7,1,0.999253354069792,40.0298881530762,1.99547711009244,15.9000009298325,-0.000709002920460438,-0.000130942417897631,0.25,-4.11452775742722E-7,-6.28639701327028E-5,-7.37680021110431E-7,9.9988241,9.9988241,-5959.21630859375,-5953.95263671875,56.8298647477175,20.6411914425651,11.519473,0,0,0,40,4449,10.0057,-5956.58447265625,,,,,,,,,,,,,0,,,,0.0049,,,,,,9.9988241,,,,
,30945526.28,10.0010786,-890.009460449219,-7.86988115816495E-5,3.30483995890324E-7,1,0.999253354069792,40.0298881530762,1.99534546878094,15.9000009298325,-0.000882636873564857,-0.000161868094106353,0.25,-4.40308216613753E-7,-7.82472730494482E-5,-8.20263602725156E-7,10.0010786,10.0010786,-900.042785644531,-879.976135253906,57.2425646058714,20.6406437769825,11.899124,0,0,0,40,4449,10.00505,-890.009460449219,,,,,,,,,,,,,0,,,,0,,,,,,10.0010786,,,,
,30945625.335,9.9989767,4055.90661621094,-9.02036403535784E-5,3.74649072832198E-7,1,0.999253354069792,40.0298881530762,1.99556227124711,15.9000009298325,-0.00101102246159525,-0.000190832828301206,0.25,-9.53913125370752E-7,-8.96999493580088E-5,-1.40517473599732E-6,9.9989767,9.9989767,4048.51342773438,4063.2998046875,57.3668435404292,20.640837287516,11.519473,0,0,0,40,4449,10.00545,4055.90661621094,,,,,,,,,,,,,0,,,,0,,,,,,9.9989767,,,,
,30945723.5,9.9990921,8962.22705078125,-0.000101491814714921,3.46204035366369E-7,1,0.999253354069792,40.0298881530762,1.99524904275548,15.9000009298325,-0.00113784974610459,-0.000214333955381095,0.25,-9.9942807463688E-7,-0.000100960955741831,-1.54405907880853E-6,9.9990921,9.9990921,8952.3583984375,8972.095703125,57.423902422333,20.6400809332791,12.278775,0,0,0,40,4449,10.0068,8962.22705078125,,,,,,,,,,,,,0,,,,0,,,,,,9.9990921,,,,
,30945826.595,10.0007467,14114.958984375,-0.000105929019051146,3.68757359280614E-7,1,0.999253354069792,40.0298881530762,1.9952784838709,15.9000009298325,-0.00118725396985209,-0.000228696467496688,0.25,-1.43862686578107E-6,-0.000105418076748071,-2.04559506663509E-6,10.0007467,10.0007467,14104.78515625,14125.1328125,57.1815975813714,20.6391497780157,11.519473,0,0,0,40,4449,10.00625,14114.958984375,,,,,,,,,,,,,0,,,,0,,,,,,10.0007467,,,,
,30945930.105,10.0008774,19289.716796875,-9.62175511562888E-5,4.71938867980882E-7,1,0.999253354069792,40.0298881530762,1.99531564110243,15.9000009298325,-0.00107897183133275,-0.000207679452744189,0.25,-1.25889060832565E-6,-9.57994806479809E-5,-1.84533115621942E-6,10.0008774,10.0008774,19287.033203125,19292.400390625,57.1808159528522,20.6397391823797,11.519473,0,0,0,40,4449,10.0057,19289.716796875,,,,,,,,,,,,,0,,,,-0.00245,,,,,,10.0008774,,,,
,30946033.615,10.0002756,24462.2216796875,-7.52284924132474E-5,3.87056666273445E-7,1,0.999253354069792,40.0298881530762,1.99532015479126,15.9000009298325,-0.000843231634122846,-0.000166956272008997,0.25,-1.36022114907919E-6,-7.49374648037079E-5,-1.84189811250188E-6,10.0002756,10.0002756,24454.578125,24469.865234375,57.1769078102561,20.6401512562362,11.519473,0,0,0,40,4449,10.00535,24462.2216796875,,,,,,,,,,,,,0,,,,0,,,,,,10.0002756,,,,
,30946131.405,9.9997058,29350.1103515625,-5.91546765992908E-5,5.01336998595321E-7,1,0.999253354069792,40.0298881530762,1.99524811385843,15.9000009298325,-0.000662134272075578,-0.000138241299323377,0.25,-1.66722289693697E-6,-5.89513971340164E-5,-2.06008629740925E-6,9.9996023,9.9998093,29342.466796875,29357.75390625,57.0119841926983,20.6385436439997,11.899124,0,0,0,40,4449,10.0049,29350.1103515625,,,,,,,,,,,,,0,,,,0,,,,,,9.9997058,,,,
,30946233.245,9.9992857,34439.98046875,-5.70059788119918E-5,4.83773308562943E-7,1,0.999253354069792,40.0298881530762,1.99528572406376,15.9000009298325,-0.000639368243125351,-0.000128105719890741,0.25,-1.13294435569716E-6,-5.68436355196594E-5,-1.52668024965079E-6,9.9992857,9.9992857,34430.2109375,34449.75,57.1049979864868,20.6404980690906,11.899124,0,0,0,40,4449,10.0064,34439.98046875,,,,,,,,,,,,,0,,,,0,,,,,,9.9992857,,,,
,30946333.68,9.998683,39459.525390625,-6.5131514223597E-5,5.35014853752749E-7,1,0.999253354069792,40.0298881530762,1.99535777028027,15.9000009298325,-0.00072986638933348,-0.000152283856220846,0.25,-1.80111103527262E-6,-6.49768778237336E-5,-2.26222397325378E-6,9.998683,9.998683,39452.1015625,39466.94921875,57.1456426694868,20.6384934376226,11.139823,0,0,0,40,4449,10.008,39459.525390625,,,,,,,,,,,,,0,,,,0.0049,,,,,,9.998683,,,,
,30946427.075,9.9994726,44129.990234375,-7.82019649225407E-5,6.71525714345582E-7,1,0.999253354069792,40.0298881530762,1.99534145997556,15.9000009298325,-0.000879566413090773,-0.000167333454420902,0.25,-7.68463562012201E-7,-7.80646224097884E-5,-1.33545027942698E-6,9.9994726,9.9994726,44125.29296875,44134.6875,57.0846756449868,20.6369488423449,11.519473,0,0,0,40,4449,10.00795,44129.990234375,,,,,,,,,,,,,0,,,,0,,,,,,9.9994726,,,,
,30946518.61,9.9981136,48702.923828125,-9.11707154632324E-5,4.98282004564834E-7,1,0.999253354069792,40.0298881530762,1.99586481789892,15.9000009298325,-0.00102715771225561,-0.000189762373891184,0.25,-4.03628076386008E-7,-9.10572906716747E-5,-1.07378365470687E-6,9.9981136,9.9981136,48692.99609375,48712.8515625,57.1964485232368,20.6354392391789,11.899124,0,0,0,40,4449,10.00905,48702.923828125,,,,,,,,,,,,,0,,,,0.0049,,,,,,9.9981136,,,,
,30946610.06,9.9977093,53275.62109375,-0.000108809403868115,8.30233325698128E-7,1,0.999253354069792,40.0298881530762,1.99552659646125,15.9000009298325,-0.00122443793178196,-0.000236590234314817,0.25,-1.36669125084578E-6,-0.000108717636210914,-2.17223539326494E-6,9.9977093,9.9977093,53270.6796875,53280.5625,57.1167224142753,20.6359911061027,11.519473,0,0,0,40,4449,10.01155,53275.62109375,,,,,,,,,,,,,0,,,,0.0049,,,,,,9.9977093,,,,
,30946705.63,9.9972076,58053.490234375,-0.000125601856525974,7.40937301240214E-7,1,0.999253354069792,40.0298881530762,1.99540593400387,15.9000009298325,-0.00141420592915169,-0.000271969306625249,0.25,-1.46417737282934E-6,-0.000125555243326007,-2.39831496876135E-6,9.9972076,9.9972076,58048.47265625,58058.5078125,57.1237570709483,20.6375135164238,12.278775,0,0,0,40,4449,10.0136,58053.490234375,,,,,,,,,,,,,0,,,,-0.00245,,,,,,9.9972076,,,,
,30946797.205,9.9962254,62626.6875,-0.000144671692581719,7.90513273707327E-7,1,0.999253354069792,40.0298881530762,1.99538442988794,15.9000009298325,-0.00163059592005859,-0.000307881924296744,0.25,-1.1987491834946E-6,-0.000144683591954659,-2.27535053235159E-6,9.9962254,9.9962254,62616.59375,62636.78125,57.2331850636407,20.6344267270584,11.519473,0,0,0,40,4449,10.0165,62626.6875,,,,,,,,,,,,,0,,,,0,,,,,,9.9962254,,,,
,30946890.63,9.9962425,67299.546875,-0.000162081513951755,7.16240145192284E-7,1,0.999253354069792,40.0298881530762,1.99525264709994,15.9000009298325,-0.00182355248268933,-0.000366796960124847,0.25,-3.27283314049278E-6,-0.000162148342627114,-4.47675986892942E-6,9.9962425,9.9962425,67294.4921875,67304.6015625,57.0760777312753,20.6358297997832,11.899124,0,0,0,40,4449,10.0197,67299.546875,,,,,,,,,,,,,0,,,,0.0049,,,,,,9.9962425,,,,
,30946985.75,9.99687,72054.953125,-0.000182137623451163,7.19739688119798E-7,1,0.999253354069792,40.0298881530762,1.99578654335081,15.9000009298325,-0.00205363193622869,-0.000395370438893211,0.25,-2.17454268985376E-6,-0.000182297617625397,-3.51914698086272E-6,9.99687,9.99687,72052.28125,72057.625,56.7540467813522,20.6333562843695,11.519473,0,0,0,40,4449,10.0218,72054.953125,,,,,,,,,,,,,0,,,,0,,,,,,9.99687,,,,
,30947079.39,9.9957094,76733.04296875,-0.00019935069597224,7.93192716948579E-7,1,0.999253354069792,40.0298881530762,1.99532346467022,15.9000009298325,-0.0022508011860438,-0.000417582754006663,0.25,-1.0464314370418E-6,-0.000199610744641913,-2.50467061629685E-6,9.9956617,9.9957571,76725.4765625,76740.609375,57.0862389020253,20.6341294403904,12.278775,0,0,0,40,4449,10.0267,76733.04296875,,,,,,,,,,,,,0,,,,0.00245,,,,,,9.9957094,,,,
,30947169.195,9.9961014,81221.6171875,-0.000216708845697635,6.92405779265447E-7,1,0.999253354069792,40.0298881530762,1.99519117481814,15.9000009298325,-0.00244722496215748,-0.000455400107536883,0.25,-1.27193407889055E-6,-0.000217064588061925,-2.84163686119413E-6,9.9961014,9.9961014,81213.984375,81229.25,56.8298647477175,20.6379998846295,11.519473,0,0,0,40,4449,10.02955,81221.6171875,,,,,,,,,,,,,0,,,,-0.00245,,,,,,9.9961014,,,,
,30947259.72,9.9957228,85747.2578125,-0.000235428967925313,9.10650727566056E-7,1,0.999253354069792,40.0298881530762,1.99511648002817,15.9000009298325,-0.0026562459492389,-0.000512362152469009,0.25,-2.94853060263133E-6,-0.000235880745838873,-4.63704535298533E-6,9.9957228,9.9957228,85742.4140625,85752.1015625,57.1182856713137,20.6358592862204,11.519473,0,0,0,40,4449,10.0334,85747.2578125,,,,,,,,,,,,,0,,,,-0.0049,,,,,,9.9957228,,,,
,30947347.07,9.9958572,89999.5625,-0.00025088210046903,9.39882108681416E-7,1,0.999253354069792,40.0298881530762,1.99564732379087,15.9000009298325,-0.0028340171211844,-0.000535791508346373,0.25,-2.23737491107701E-6,-0.000251442293619219,-4.01296651454503E-6,9.9958572,9.9958572,89999.5546875,89999.5703125,57.2042648084291,20.6350661403185,11.899124,0,0,0,40,4417,10.03755,89999.5625,,,,,,,,,,,,,0,,,,0,,,,,,9.9958572,,,,
,30947451.045,9.9990606,85761.30859375,-0.00023396910492574,8.25687976930645E-7,1,0.999253354069792,40.0298881530762,1.99546142615894,15.9000009298325,-0.00264234811706348,-0.000497404030781236,0.25,-1.88118846232082E-6,-0.000234425806903858,-3.55706120975551E-6,9.9990606,9.9990606,85753.8515625,85768.765625,57.0151107067753,20.6321970785662,11.899124,0,0,0,40,4449,10.0378,85761.30859375,,,,,,,,,,,,,0,,,,-0.00245,,,,,,9.9990606,,,,
,30947539.65,10.0018063,81332.53125,-0.000218091588996401,9.01917031573968E-7,1,0.999253354069792,40.0298881530762,1.99553284007127,15.9000009298325,-0.00246543086440399,-0.000446339452149765,0.25,-2.15182058454755E-7,-0.000218459087425848,-1.79267459631815E-6,10.0018063,10.0018063,81324.8046875,81340.2578125,57.2269320354868,20.6332134841066,11.519473,0,0,0,40,4449,10.0352,81332.53125,,,,,,,,,,,,,0,,,,0,,,,,,10.0018063,,,,
,30947636.75,10.0027313,76479.18359375,-0.00019765763992386,8.82265212764535E-7,1,0.999253354069792,40.0298881530762,1.99555824399122,15.9000009298325,-0.00223473240718275,-0.000398302633530865,0.25,3.5869057161289E-7,-0.000197921753368574,-1.08605150944098E-6,10.0027313,10.0027313,76476.8046875,76481.5625,57.088583787583,20.631333303001,11.519473,0,0,0,40,4449,10.0332,76479.18359375,,,,,,,,,,,,,0,,,,-0.0049,,,,,,10.0027313,,,,
,30947732.93,10.0034685,71670.34765625,-0.000177971747470419,8.46614313247333E-7,1,0.999253354069792,40.0298881530762,1.99532419928178,15.9000009298325,-0.00200460990592346,-0.000394795804525393,0.25,-2.88226549637479E-6,-0.000178116808555947,-4.19754316810032E-6,10.0034685,10.0034685,71667.8125,71672.8828125,57.3269804859484,20.6344671542188,11.899124,0,0,0,40,4449,10.0306,71670.34765625,,,,,,,,,,,,,0,,,,-0.0049,,,,,,10.0034685,,,,
,30947827.71,10.0035295,66932.5859375,-0.000157405824882582,7.89766791700687E-7,1,0.999253354069792,40.0298881530762,1.99561072582232,15.9000009298325,-0.00177464802431795,-0.000337097308895689,0.25,-1.48070464277742E-6,-0.000157478258189945,-2.64932009420569E-6,10.0035295,10.0035295,66930.0859375,66935.0859375,57.2120810936214,20.6316345666855,12.278775,0,0,0,40,4449,10.02635,66932.5859375,,,,,,,,,,,,,0,,,,0,,,,,,10.0035295,,,,
,30947922.565,10.0042191,62189.015625,-0.000142370990330544,8.35269612194837E-7,1,0.999253354069792,40.0298881530762,1.99547092711064,15.9000009298325,-0.00160650336641468,-0.000292795720701423,0.25,-2.76724055268416E-7,-0.00014238369449746,-1.33621395193896E-6,10.0042191,10.0042191,62176.609375,62201.421875,56.8986480574099,20.6357189157084,11.899124,0,0,0,40,4449,10.0221,62189.015625,,,,,,,,,,,,,0,,,,0.0049,,,,,,10.0042191,,,,
,30948016.055,10.0035152,57518.205078125,-0.000123045803797545,5.68931705793861E-7,1,0.999253354069792,40.0298881530762,1.9953879080727,15.9000009298325,-0.00138561199901638,-0.000264927276544019,0.25,-1.30235120307799E-6,-0.00012299481073266,-2.21724763581569E-6,10.0035152,10.0035152,57513.23828125,57523.171875,56.8634747740445,20.6356729529774,11.899124,0,0,0,40,4449,10.01925,57518.205078125,,,,,,,,,,,,,0,,,,-0.00245,,,,,,10.0035152,,,,
,30948110.89,10.0040712,52775.984375,-0.000103519876645929,5.73070738010052E-7,1,0.999253354069792,40.0298881530762,1.99508575153735,15.9000009298325,-0.00116447415527272,-0.000225789733195601,0.25,-1.36805746414052E-6,-0.000103426926308894,-2.13383476391421E-6,10.0040712,10.0040712,52766.12890625,52785.83984375,57.0666981890445,20.6395480797943,11.899124,0,0,0,40,4449,10.01575,52775.984375,,,,,,,,,,,,,0,,,,0.00245,,,,,,10.0040712,,,,
,30948206.535,10.0039015,47995.533203125,-8.75427110387309E-5,6.63693681102251E-7,1,0.999253354069792,40.0298881530762,1.99548440596072,15.9000009298325,-0.000985264720706514,-0.000186425877802464,0.25,-7.66554981568163E-7,-8.74246719074904E-5,-1.40851261113812E-6,10.0039015,10.0039015,47983.0234375,48008.04296875,56.8509687177368,20.6374458142498,12.278775,0,0,0,40,4449,10.0117,47995.533203125,,,,,,,,,,,,,0,,,,0,,,,,,10.0039015,,,,
,30948300.495,10.0039024,43300.15234375,-6.71938153979204E-5,6.7468625464172E-7,1,0.999253354069792,40.0298881530762,1.99560226072787,15.9000009298325,-0.000754747641165689,-0.000149529688564012,0.25,-1.17149800524511E-6,-6.7066274576396E-5,-1.65637676563607E-6,10.0039024,10.0039024,43295.171875,43305.1328125,57.007294421583,20.6358550797569,11.519473,0,0,0,40,4449,10.009,43300.15234375,,,,,,,,,,,,,0,,,,-0.0049,,,,,,10.0039024,,,,
,30948395.73,10.0026436,38540.048828125,-5.02656649108918E-5,4.95418953329394E-7,1,0.999253354069792,40.0298881530762,1.99514815995357,15.9000009298325,-0.000563355972119663,-0.000116457667868515,0.25,-1.29864529658077E-6,-5.01421148465152E-5,-1.65310404049134E-6,10.0026436,10.0026436,38532.72265625,38547.375,56.9400743689291,20.6410331890737,11.899124,0,0,0,40,4449,10.00655,38540.048828125,,,,,,,,,,,,,0,,,,0,,,,,,10.0026436,,,,
,30948493.2,10.0025854,33670.5234375,-3.23810188680694E-5,5.59588537953817E-7,1,0.999253354069792,40.0298881530762,1.99555227469006,15.9000009298325,-0.000361923249077205,-7.98526257374853E-5,0.25,-1.27365262648864E-6,-3.22818148804781E-5,-1.49447573359559E-6,10.0025854,10.0025854,33660.640625,33680.40625,57.024490249006,20.6375311773445,11.899124,0,0,0,40,4449,10.00455,33670.5234375,,,,,,,,,,,,,0,,,,0.00245,,,,,,10.0025854,,,,
,30948587.69,10.0022273,28948.31640625,-1.47640652670128E-5,4.79141848827478E-7,1,0.999253354069792,40.0298881530762,1.99516136523655,15.9000009298325,-0.000162937822425325,-4.73485874050778E-5,0.25,-1.55857639407442E-6,-1.47050485787224E-5,-1.65255923761624E-6,10.0021219,10.0023327,28943.375,28953.2578125,57.1862873524868,20.6410202055992,11.519473,0,0,0,40,4449,10.0036,28948.31640625,,,,,,,,,,,,,0,,,,0.00245,,,,,,10.0022273,,,,
,30948680.155,10.0016174,24325.169921875,1.66119715033084E-6,4.04463867162957E-7,1,0.999253354069792,40.0298881530762,1.99505757731353,15.9000009298325,1.98175131520132E-5,-3.00697098088751E-6,0.25,-5.65226696021176E-7,1.65859482023803E-6,-5.52362428004017E-7,10.0016174,10.0016174,24320.146484375,24330.193359375,57.004167907506,20.6427027462731,11.519473,0,0,0,40,4449,10.00215,24325.169921875,,,,,,,,,,,,,0,,,,0,,,,,,10.0016174,,,,
,30948775.76,10.0007515,19547.6376953125,1.82313932998402E-5,3.72093846154883E-7,1,0.999253354069792,40.0298881530762,1.99511195003042,15.9000009298325,0.000205648948186578,3.25359836397282E-5,0.25,-3.67896889646626E-7,1.8156367013348E-5,-2.53892527181466E-7,10.0007515,10.0007515,19542.673828125,19552.6015625,57.3105662870445,20.6434973497206,11.519473,0,0,0,40,4449,10.0018,19547.6376953125,,,,,,,,,,,,,0,,,,-0.0049,,,,,,10.0007515,,,,
,30948869.12,9.9997158,14880.7001953125,3.42803364412796E-5,4.13896963611827E-7,1,0.999253354069792,40.0298881530762,1.99496395043409,15.9000009298325,0.000386145922620139,6.30151123578081E-5,0.25,-5.14444427482812E-7,3.41230419680717E-5,-3.11534366156887E-7,9.9997158,9.9997158,14870.8330078125,14890.5673828125,57.2691399755253,20.6458396115279,11.519473,0,0,0,40,4449,10.00235,14880.7001953125,,,,,,,,,,,,,0,,,,-0.00245,,,,,,9.9997158,,,,
,30948962.6,9.9990711,10210.4067382813,4.97862405939571E-5,3.45770609948171E-7,1,0.999253354069792,40.0298881530762,1.99500169366565,15.9000009298325,0.000560234725374604,9.34760946396401E-5,0.25,-5.52770049148866E-7,4.95364996484292E-5,-2.75663175262684E-7,9.9990711,9.9990711,10197.8681640625,10222.9453125,57.1081245005637,20.6465123051456,11.519473,0,0,0,40,4449,10.00275,10210.4067382813,,,,,,,,,,,,,0,,,,0,,,,,,9.9990711,,,,
,30949052.83,9.99894615,5700.00903320313,6.46921651870091E-5,3.100522407373E-7,1,0.999253354069792,40.0298881530762,1.99539457177653,15.9000009298325,0.000726841079223667,0.000127115404732133,0.25,-1.91680521956633E-7,6.43425328130507E-5,1.44322402190611E-7,9.9987001,9.9991922,5694.8583984375,5705.15966796875,56.9729027667368,20.6414056957425,11.899124,0,0,0,40,4449,10.0045,5700.00903320313,,,,,,,,,,,,,0,,,,0.00245,,,,,,9.99894615,,,,
,30949143.845,10.0003119,1148.71636962891,7.83010625108706E-5,3.86242523399436E-7,1,0.999253354069792,40.0298881530762,1.99518454556271,15.9000009298325,0.000877855872536603,0.000162522194683291,0.25,5.69037007041811E-7,7.78521252823968E-5,9.474463741115E-7,10.0003119,10.0003119,1145.98059082031,1151.4521484375,57.1206305568714,20.6405828868296,11.519473,0,0,0,40,4449,10.003,1148.71636962891,,,,,,,,,,,,,0,,,,0,,,,,,10.0003119,,,,
,30949167.46,10.0021734,-0.44910129904747,8.14909091183867E-5,3.17180779555566E-7,1,0.999253354069792,40.0298881530762,1.99538691400721,15.9000009298325,0.000914695696123285,0.000163341464000567,0.25,7.91092408498737E-8,8.10223966918458E-5,4.71435685318284E-7,10.0021734,10.0021734,-0.487160742282867,-0.411041855812073,57.2910255740638,20.6382971260872,11.519473,0,0,0,40,4417,10.0006,-0.44910129904747,,,,,,,,,,,,,0,,,,-0.00245,,,,,,10.0021734,,,,