File: data/doubleLayers/dl_2-5/ppms/DD205_5/KoelnPPMS/CooldownTests/DD205_5_1T_HYS_1TFCC.DAT
[Header]
; VSM Data File (default extension .dat)
; Copyright (c) 2003-2013, Quantum Design, Inc. All rights reserved.
TITLE,
FILEOPENTIME,23224061.31,09/27/2018,4:06 am
BYAPP,VSM,2.0,2.0
INFO,PPMS VSM Option Release 1.4.10 Build 1,APPNAME
INFO,Quantum Design Linear Motor Servo Controller,MOTOR_MODULE_NAME
INFO,3101-100 M1,MOTOR_HW_VERSION
INFO,MMC1014,MOTOR_SERIAL_NUMBER
INFO,SRV No X-over 01.03.11,MOTOR_SOFTWARE_VERSION
INFO,Quantum Design VSM Detection Module,VSM_MODULE_NAME
INFO,3101-150 F0,VSM_HW_VERSION
INFO,VSM707,VSM_SERIAL_NUMBER
INFO,VSM No X-over 01.02.05 May 20 2008 13:51:47,VSM_SOFTWARE_VERSION
INFO,704,PREAMP_SERIAL_NUMBER
INFO,822,COIL_SERIAL_NUMBER
INFO,0,MOMENT_UNITS
INFO,,SAMPLE_MATERIAL
INFO,,SAMPLE_COMMENT
INFO,,SAMPLE_MASS
INFO,,SAMPLE_VOLUME
INFO,,SAMPLE_MOLECULAR_WEIGHT
INFO,,SAMPLE_SIZE
INFO,,SAMPLE_SHAPE
DATATYPE,COMMENT,1
DATATYPE,TIME,2
STARTUPAXIS,X,2
STARTUPAXIS,Y1,5
[Data]
Comment,Time Stamp (sec),Temperature (K),Magnetic Field (Oe),Moment (emu),M. Std. Err. (emu),Transport Action,Averaging Time (sec),Frequency (Hz),Peak Amplitude (mm),Center Position (mm),Coil Signal' (mV),Coil Signal" (mV),Range (mV),M. Quad. Signal (emu),M. Raw' (emu),M. Raw" (emu),Min. Temperature (K),Max. Temperature (K),Min. Field (Oe),Max. Field (Oe),Mass (grams),Motor Lag (deg),Pressure (Torr),VSM Status (code),Motor Status (code),Measure Status (code),Measure Count,PPMS Status (code),System Temp. (K),System Field (Oe),Sample Position (deg),Bridge 1 Resistance (ohms),Bridge 1 Excitation (에),Bridge 2 Resistance (ohms),Bridge 2 Excitation (에),Bridge 3 Resistance (ohms),Bridge 3 Excitation (에),Bridge 4 Resistance (ohms),Bridge 4 Excitation (에),Signal 1 Vin (V),Signal 2 Vin (V),Digital Inputs (code),Drive 1 Iout (mA),Drive 1 Ipower (W),Drive 2 Iout (mA),Drive 2 Ipower (W),Pressure (),Map 20 (),Map 21 (),Map 22 (),Map 23 (),Map 24 (),Map 25 (),Map 26 (),Map 27 (),Map 28 (),Map 29 ()
,23224076.14,10.0047092,9999.5078125,,,2,,,,16.7900003269315,,,,,,,10.0047092,10.0047092,9999.5078125,9999.5078125,,,12.658426,,,,-99999999,4369,10.0157,9999.5078125,,,,,,,,,,,,,,,,,,,,,,,10.0047092,,,,
,23224194.94,10.0155191,334.837463378906,6.75157807998699E-5,3.54920974247909E-7,1,0.999253354069792,40.0298881530762,1.99650640296618,16.780000180006,0.000758055419435706,0.000136474301066872,0.25,1.60039128574676E-7,6.71278693923901E-5,4.85380638932565E-7,10.0155191,10.0155191,331.289337158203,338.385589599609,55.8418862994097,20.5729275387077,12.658426,0,0,0,40,4449,9.9955,334.837463378906,,,,,,,,,,,,,0,,,,0,,,,,,10.0155191,,,,
,23224213.93,10.0094461,809.327575683594,6.78060447799887E-5,3.19185578308423E-7,1,0.999253354069792,40.0298881530762,1.99642537104212,16.780000180006,0.000761368058916655,0.000136676939403484,0.25,1.25177513493556E-7,6.74179883445544E-5,4.53702920401334E-7,10.0094461,10.0094461,805.402221679688,813.2529296875,56.0732483411021,20.5725926700605,13.417728,0,0,0,40,4449,9.9966,809.327575683594,,,,,,,,,,,,,0,,,,-0.00245,,,,,,10.0094461,,,,
,23224232.44,10.0083714,1270.84381103516,6.69586648315604E-5,2.88886127802989E-7,1,0.999253354069792,40.0298881530762,1.99632750869393,16.780000180006,0.000752560400923043,0.000130880205645244,0.25,-2.41820516412336E-7,6.65787135831211E-5,8.63879794373568E-8,10.0083714,10.0083714,1264.63659667969,1277.05102539062,56.2530229005252,20.5686239005753,12.658426,0,0,0,40,4449,9.9959,1270.84381103516,,,,,,,,,,,,,0,,,,-0.00245,,,,,,10.0083714,,,,
,23224250.805,10.006937,1730.15228271484,6.5293242607101E-5,3.24468380743414E-7,1,0.999253354069792,40.0298881530762,1.99637540342931,16.780000180006,0.000733625773745207,0.000129044298100541,0.25,-1.11748487925682E-7,6.49236862117432E-5,2.09360239258492E-7,10.006937,10.006937,1726.49377441406,1733.81079101562,55.9778896617559,20.5706898294808,12.658426,0,0,0,40,4449,9.9972,1730.15228271484,,,,,,,,,,,,,0,,,,0,,,,,,10.006937,,,,
,23224268.49,10.0045538,2170.849609375,6.49516079072024E-5,3.10413116990363E-7,1,0.999253354069792,40.0298881530762,1.99620931854848,16.780000180006,0.000729806205814528,0.000128029139277313,0.25,-1.42577101439916E-7,6.458570568776E-5,1.78798534715977E-7,10.0045538,10.0045538,2165.86743164062,2175.83178710938,55.954440806179,20.5667320448281,12.658426,0,0,0,40,4449,9.99365,2170.849609375,,,,,,,,,,,,,0,,,,0,,,,,,10.0045538,,,,
,23224286.625,10.0060577,2624.85290527344,6.29817623101309E-5,2.8337211583051E-7,1,0.999253354069792,40.0298881530762,1.99628231838756,16.780000180006,0.000708082584159963,0.000122091298139459,0.25,-3.23716750493067E-7,6.26295145049271E-5,-9.21572897370382E-9,10.0060577,10.0060577,2622.36376953125,2627.34204101562,56.496109370006,20.5696861813024,13.038077,0,0,0,40,4449,9.99605,2624.85290527344,,,,,,,,,,,,,0,,,,-0.00245,,,,,,10.0060577,,,,
,23224304.985,10.0047092,3081.62609863281,6.1544643493427E-5,3.29470379111687E-7,1,0.999253354069792,40.0298881530762,1.99638502535443,16.780000180006,0.000691640638494971,0.000121215873996253,0.25,-1.48928204788517E-7,6.1201275470295E-5,1.59305897958393E-7,10.0047092,10.0047092,3079.19604492188,3084.05615234375,56.1897109904675,20.5743464891053,13.038077,0,0,0,40,4449,9.9972,3081.62609863281,,,,,,,,,,,,,0,,,,0.00245,,,,,,10.0047092,,,,
,23224323.45,10.0021353,3543.1728515625,5.97079982303235E-5,3.38443240364831E-7,1,0.999253354069792,40.0298881530762,1.9963389934034,16.780000180006,0.000670925500458893,0.000118045750693961,0.25,-1.06599395977749E-7,5.93763836485667E-5,1.94080565711623E-7,10.0021353,10.0021353,3540.67602539063,3545.66967773438,56.0826278833329,20.5734263004281,12.658426,0,0,0,40,4449,9.99675,3543.1728515625,,,,,,,,,,,,,0,,,,0,,,,,,10.0021353,,,,
,23224341.945,10.0015459,4004.97631835937,5.88120184114871E-5,3.20749488770894E-7,1,0.999253354069792,40.0298881530762,1.99628697675303,16.780000180006,0.000660902690318233,0.000116038790301983,0.25,-1.2788742813961E-7,5.84872179349827E-5,1.70270908995875E-7,10.00144,10.0016518,3999.8359375,4010.11669921875,56.3624508932175,20.5738788614248,12.658426,0,0,0,40,4449,9.9969,4004.97631835937,,,,,,,,,,,,,0,,,,0,,,,,,10.0015459,,,,
,23224359.795,10.0001001,4450.7685546875,5.72232988995447E-5,3.16563999210968E-7,1,0.999253354069792,40.0298881530762,1.99624661039661,16.780000180006,0.000643138954588605,0.000112438070437649,0.25,-1.67808632150906E-7,5.69091551605944E-5,1.24310732624623E-7,10.0001001,10.0001001,4447.09423828125,4454.44287109375,56.1584458496982,20.5700616545807,12.658426,0,0,0,40,4449,9.99745,4450.7685546875,,,,,,,,,,,,,0,,,,0.00245,,,,,,10.0001001,,,,
,23224378.665,10.0011024,4923.04638671875,5.57109668853128E-5,3.12638220416621E-7,1,0.999253354069792,40.0298881530762,1.99640731039291,16.780000180006,0.000626726091120798,0.000106575869164312,0.25,-4.23594651515479E-7,5.5408216479446E-5,-1.359169024334E-7,10.0011024,10.0011024,4921.74267578125,4924.35009765625,56.1310888515252,20.5758166487689,13.038077,0,0,0,40,4449,9.9965,4923.04638671875,,,,,,,,,,,,,0,,,,0,,,,,,10.0011024,,,,
,23224397.085,10.0003881,5382.21923828125,5.45490765484004E-5,2.92186442950213E-7,1,0.999253354069792,40.0298881530762,1.99627120993513,16.780000180006,0.000612763501905559,0.000109247583348218,0.25,1.94387651668803E-8,5.42521229130123E-5,3.00530255590265E-7,10.0003881,10.0003881,5375.88671875,5388.5517578125,56.1310888515252,20.5738221379214,13.038077,0,0,0,40,4449,9.99845,5382.21923828125,,,,,,,,,,,,,0,,,,0.00245,,,,,,10.0003881,,,,
,23224414.94,9.9994154,5827.95190429688,5.28410163580013E-5,3.3669851550891E-7,1,0.999253354069792,40.0298881530762,1.99634070625603,16.780000180006,0.000593928552824547,0.000104070272435733,0.25,-1.39823968750475E-7,5.25558224980811E-5,1.35022051107688E-7,9.9994154,9.9994154,5825.3720703125,5830.53173828125,56.2561494146021,20.5737714641652,13.038077,0,0,0,40,4449,9.99905,5827.95190429688,,,,,,,,,,,,,0,,,,0,,,,,,9.9994154,,,,
,23224433.62,9.9983501,6295.10009765625,5.09789540199942E-5,3.23771529567683E-7,1,0.999253354069792,40.0298881530762,1.99623794846085,16.780000180006,0.000573120949768327,9.96669518960716E-5,0.25,-2.01999146848446E-7,5.07058549974862E-5,6.52462496529281E-8,9.9983501,9.9983501,6290.12939453125,6300.07080078125,56.6203883045637,20.571132545109,13.038077,0,0,0,40,4449,9.99775,6295.10009765625,,,,,,,,,,,,,0,,,,-0.00245,,,,,,9.9983501,,,,
,23224452.45,10.0002193,6764.60546875,4.9858752646146E-5,3.90504123191632E-7,1,0.999253354069792,40.0298881530762,1.99628705690511,16.780000180006,0.000560982470433663,9.51081370383602E-5,0.25,-4.10609860268288E-7,4.95944735143519E-5,-1.46396129101779E-7,10.0002193,10.0002193,6761.681640625,6767.529296875,56.4085669758521,20.5759976418379,12.658426,0,0,0,40,4449,10.00045,6764.60546875,,,,,,,,,,,,,0,,,,0,,,,,,10.0002193,,,,
,23224470.78,9.9969606,7223.6884765625,4.81818260969212E-5,3.09584096284212E-7,1,0.999253354069792,40.0298881530762,1.99613415564382,16.780000180006,0.000541193743972111,9.69599044692717E-5,0.25,5.14569807023967E-8,4.79257061116491E-5,3.06012934362424E-7,9.9969606,9.9969606,7219.67138671875,7227.70556640625,56.188147733429,20.5717736982435,13.417728,0,0,0,40,4449,9.99685,7223.6884765625,,,,,,,,,,,,,0,,,,-0.00245,,,,,,9.9969606,,,,
,23224489.26,9.9996262,7685.85522460937,4.67965692686939E-5,3.88862137112619E-7,1,0.999253354069792,40.0298881530762,1.99618781377133,16.780000180006,0.000525769197432203,9.35980727154114E-5,0.25,-3.2273257097672E-9,4.65497121268277E-5,2.45884298017226E-7,9.9996262,9.9996262,7681.91015625,7689.80029296875,56.5813068786021,20.5735693831285,13.038077,0,0,0,40,4449,10.0001,7685.85522460937,,,,,,,,,,,,,0,,,,0.0049,,,,,,9.9996262,,,,
,23224507.955,9.9973736,8151.37036132813,4.52317104351671E-5,3.76725012524215E-7,1,0.999253354069792,40.0298881530762,1.9962299802822,16.780000180006,0.000508918064168008,8.65324537300766E-5,0.25,-3.55413684756985E-7,4.49965958310462E-5,-1.11232476851123E-7,9.9973736,9.9973736,8146.634765625,8156.10595703125,56.2522412720059,20.5756349937543,13.417728,0,0,0,40,4449,9.9977,8151.37036132813,,,,,,,,,,,,,0,,,,0.00245,,,,,,9.9973736,,,,
,23224526.425,9.9996853,8613.68701171875,4.40438758517898E-5,3.73561614340958E-7,1,0.999253354069792,40.0298881530762,1.99607982435225,16.780000180006,0.000495652129236318,8.36036635212344E-5,0.25,-4.05738040350741E-7,4.38168396674527E-5,-1.66165969648035E-7,9.9996519,9.9997187,8611.392578125,8615.9814453125,55.8395414138521,20.5724193183284,12.658426,0,0,0,40,4449,10.00255,8613.68701171875,,,,,,,,,,,,,0,,,,-0.0049,,,,,,9.9996853,,,,
,23224545.61,9.9962168,9094.126953125,4.22128563797326E-5,3.83798960986067E-7,1,0.999253354069792,40.0298881530762,1.99624972401589,16.780000180006,0.000474832464366811,8.16578612457027E-5,0.25,-2.55074464600035E-7,4.1996133921462E-5,-2.46674573426042E-8,9.9962168,9.9962168,9091.447265625,9096.806640625,56.401532319179,20.5738928097805,13.038077,0,0,0,40,4449,10,9094.126953125,,,,,,,,,,,,,0,,,,-0.0049,,,,,,9.9962168,,,,
,23224563.795,9.9971313,9548.912109375,4.06976685364936E-5,3.90165333071994E-7,1,0.999253354069792,40.0298881530762,1.99616727874161,16.780000180006,0.000457936627706247,7.78903098732284E-5,0.25,-3.21716320230443E-7,4.04906158714287E-5,-9.78299495802165E-8,9.9971313,9.9971313,9543.8720703125,9553.9521484375,56.9142806277945,20.5744722319357,12.658426,0,0,0,40,4449,10.00085,9548.912109375,,,,,,,,,,,,,0,,,,-0.00245,,,,,,9.9971313,,,,
,23224584.055,9.9979124,9999.4384765625,3.89180652690143E-5,4.97812070424136E-7,1,0.999253354069792,40.0298881530762,1.99609828386553,16.780000180006,0.000437697084207746,7.57010776885846E-5,0.25,-2.00685882493271E-7,3.87208981183007E-5,1.41511540600994E-8,9.9979124,9.9979124,9999.4306640625,9999.4462890625,56.005246659929,20.5710070465756,13.038077,0,0,0,40,4417,10.00165,9999.4384765625,,,,,,,,,,,,,0,,,,-0.00245,,,,,,9.9979124,,,,
,23224620.715,9.9989567,9594.263671875,4.04995895487145E-5,4.28635249102914E-7,1,0.999253354069792,40.0298881530762,1.99609974139947,16.780000180006,0.000455356433769625,7.9407248206354E-5,0.25,-1.51342286589825E-7,4.02927699981359E-5,7.07236317076755E-8,9.9989567,9.9989567,9591.6884765625,9596.8388671875,56.1834579623136,20.5709529698241,13.417728,0,0,0,40,4449,10.0029,9594.263671875,,,,,,,,,,,,,0,,,,0,,,,,,9.9989567,,,,
,23224638.78,9.9973125,9144.1162109375,4.21004633949636E-5,3.25504840170961E-7,1,0.999253354069792,40.0298881530762,1.99617083436281,16.780000180006,0.000473024943866495,8.43966683191046E-5,0.25,8.79528145887213E-9,4.18830555480795E-5,2.37384735364564E-7,9.9973125,9.9973125,9140.455078125,9147.77734375,56.3905895199098,20.5715503455883,13.038077,0,0,0,40,4449,10.0007,9144.1162109375,,,,,,,,,,,,,0,,,,0,,,,,,9.9973125,,,,
,23224656.725,9.9978685,8695.6865234375,4.35147921887563E-5,3.9765092528327E-7,1,0.999253354069792,40.0298881530762,1.99625034834842,16.780000180006,0.000489300758219538,8.50783869004678E-5,0.25,-1.8114542825213E-7,4.32895775213722E-5,5.46680121418451E-8,9.9978685,9.9978685,8690.875,8700.498046875,56.2397352156983,20.5754301601457,13.038077,0,0,0,40,4449,10.002,8695.6865234375,,,,,,,,,,,,,0,,,,0,,,,,,9.9978685,,,,
,23224675.365,9.9976492,8230.5400390625,4.50251732990423E-5,4.57367932434697E-7,1,0.999253354069792,40.0298881530762,1.99610029416459,16.780000180006,0.00050652567798089,8.6358647701961E-5,0.25,-3.33926976291894E-7,4.47913011038057E-5,-9.07035141040897E-8,9.9971962,9.9981022,8226.9169921875,8234.1630859375,56.2756901275829,20.5732641790321,13.417728,0,0,0,40,4449,10.0043,8230.5400390625,,,,,,,,,,,,,0,,,,0,,,,,,9.9976492,,,,
,23224694.52,9.9985332,7752.49584960937,4.64695255910463E-5,3.58182292094978E-7,1,0.999253354069792,40.0298881530762,1.99608765267197,16.780000180006,0.000523028168558631,8.75736755058043E-5,0.25,-4.81091919375901E-7,4.62271736170185E-5,-2.30974274632666E-7,9.9985332,9.9985332,7749.861328125,7755.13037109375,56.3632325217367,20.5718105092636,12.658426,0,0,0,40,4449,10.00265,7752.49584960937,,,,,,,,,,,,,0,,,,0,,,,,,9.9985332,,,,
,23224713.445,9.99817465,7280.41821289063,4.77437039509043E-5,3.70029606075273E-7,1,0.999253354069792,40.0298881530762,1.99605657745264,16.780000180006,0.000537248370367412,9.04962953583435E-5,0.25,-4.45804937285425E-7,4.74927433361551E-5,-1.90728484951879E-7,9.9977951,9.9985542,7275.6318359375,7285.20458984375,56.4085669758521,20.5728908931351,12.658426,0,0,0,40,4449,10.00045,7280.41821289063,,,,,,,,,,,,,0,,,,0,,,,,,9.99817465,,,,
,23224731.99,9.9996195,6816.26928710937,4.98595268122224E-5,3.22523175325421E-7,1,0.999253354069792,40.0298881530762,1.99600722231715,16.780000180006,0.000560210741798042,9.90715982028356E-5,0.25,-5.70107574412036E-8,4.95935736869907E-5,2.05505831583754E-7,9.9996195,9.9996195,6811.13818359375,6821.400390625,56.7368509539291,20.57612739957,12.278775,0,0,0,40,4449,10.00195,6816.26928710937,,,,,,,,,,,,,0,,,,0,,,,,,9.9996195,,,,
,23224749.96,9.9998617,6368.1015625,5.10098350592579E-5,3.67210427804208E-7,1,0.999253354069792,40.0298881530762,1.99602865178202,16.780000180006,0.000572329664216956,0.000105808677242641,0.25,3.39816330261568E-7,5.07340064093663E-5,6.04582194727398E-7,9.9998617,9.9998617,6364.345703125,6371.857421875,56.3991874336214,20.5765781490828,13.038077,0,0,0,40,4449,10.0023,6368.1015625,,,,,,,,,,,,,0,,,,0,,,,,,9.9998617,,,,
,23224768.95,10.000206,5893.40112304687,5.24992450435045E-5,3.43263198269485E-7,1,0.999253354069792,40.0298881530762,1.99595707542968,16.780000180006,0.000589361985568428,0.000106860452572625,0.25,1.70802503425736E-7,5.22145301588311E-5,4.42444377096524E-7,10.000206,10.000206,5889.6708984375,5897.13134765625,56.1318704800444,20.5753793392665,12.658426,0,0,0,40,4449,10.0019,5893.40112304687,,,,,,,,,,,,,0,,,,0,,,,,,10.000206,,,,
,23224785.88,10.0000849,5469.93334960937,5.38957529885392E-5,3.68122816990039E-7,1,0.999253354069792,40.0298881530762,1.99588336904408,16.780000180006,0.000605108392866689,0.000109086552897237,0.25,1.2274520388675E-7,5.36021477847397E-5,4.00246968320136E-7,10.0000849,10.0000849,5464.7822265625,5475.08447265625,56.381209977679,20.5738908788971,12.658426,0,0,0,40,4449,10.00195,5469.93334960937,,,,,,,,,,,,,0,,,,0,,,,,,10.0000849,,,,
,23224804.835,9.9996052,4996.5048828125,5.5504622996484E-5,3.01871845845111E-7,1,0.999253354069792,40.0298881530762,1.9959104996924,16.780000180006,0.000623218919153819,0.000112006857595775,0.25,9.85640024863019E-8,5.5200602370298E-5,3.82617489657197E-7,9.9996052,9.9996052,4995.134765625,4997.875,56.1865844763906,20.572576912414,12.658426,0,0,0,40,4449,10.0013,4996.5048828125,,,,,,,,,,,,,0,,,,0,,,,,,9.9996052,,,,
,23224823.945,10.0017509,4519.29052734375,5.70010829199036E-5,2.71371521852991E-7,1,0.999253354069792,40.0298881530762,1.99610270539608,16.780000180006,0.000640210817155179,0.000114184114371955,0.25,2.75262227273862E-8,5.66874255923484E-5,3.17714261098308E-7,10.0017509,10.0017509,4512.904296875,4525.6767578125,56.2514596434867,20.5766811134682,13.038077,0,0,0,40,4449,10.00225,4519.29052734375,,,,,,,,,,,,,0,,,,0,,,,,,10.0017509,,,,
,23224842.36,10.0010433,4059.23449707031,5.82293049624756E-5,2.96284900564028E-7,1,0.999253354069792,40.0298881530762,1.99600796696941,16.780000180006,0.000653997894521577,0.000116401228271721,0.25,9.12141387697193E-9,5.7907239182948E-5,3.03793596219224E-7,10.0010433,10.0010433,4055.49438476562,4062.974609375,56.045891342929,20.573526105438,13.038077,0,0,0,40,4449,10.0014,4059.23449707031,,,,,,,,,,,,,0,,,,0,,,,,,10.0010433,,,,
,23224861.25,10.0008535,3586.74768066406,6.04333537193659E-5,3.25159018948117E-7,1,0.999253354069792,40.0298881530762,1.99597302617525,16.780000180006,0.000678614045053977,0.000121400684969551,0.25,6.4786557887816E-8,6.00970070794463E-5,3.68338448285402E-7,10.0008535,10.0008535,3582.93896484375,3590.55639648438,56.3053920113137,20.5724606462707,13.038077,0,0,0,40,4449,10.00025,3586.74768066406,,,,,,,,,,,,,0,,,,-0.00245,,,,,,10.0008535,,,,
,23224878.955,10.0022831,3144.59387207031,6.1218811193424E-5,3.03990471031697E-7,1,0.999253354069792,40.0298881530762,1.99589511568897,16.780000180006,0.000687716785902778,0.000121129493114603,0.25,-9.64734671769285E-8,6.08772370195313E-5,2.10097224118505E-7,10.0022831,10.0022831,3140.82006835937,3148.36767578125,56.4109118614098,20.5717118979194,12.278775,0,0,0,40,4449,10.00035,3144.59387207031,,,,,,,,,,,,,0,,,,-0.0049,,,,,,10.0022831,,,,
,23224896.06,10.0019836,2717.02111816406,6.27096868379409E-5,3.14525019406675E-7,1,0.999253354069792,40.0298881530762,1.99590035412626,16.780000180006,0.000704359387904328,0.000124577624490432,0.25,-5.24221637889028E-8,6.23579595791807E-5,2.59580868608995E-7,10.0019836,10.0019836,2713.35498046875,2720.68725585938,56.7470121246791,20.5737096885475,12.278775,0,0,0,40,4449,9.99955,2717.02111816406,,,,,,,,,,,,,0,,,,-0.00245,,,,,,10.0019836,,,,
,23224915.205,10.0038719,2238.55297851562,6.42589194310248E-5,2.72488197218184E-7,1,0.999253354069792,40.0298881530762,1.99587577650473,16.780000180006,0.000721199623348883,0.000130645560047983,0.25,2.14991947518678E-7,6.38954052333261E-5,5.31206567488769E-7,10.0038719,10.0038719,2233.2626953125,2243.84326171875,56.4648442292367,20.5755207137385,13.038077,0,0,0,40,4449,9.99875,2238.55297851562,,,,,,,,,,,,,0,,,,0.00245,,,,,,10.0038719,,,,
,23224933.155,10.0033684,1788.939453125,6.54731216089396E-5,3.08156903405636E-7,1,0.999253354069792,40.0298881530762,1.99584187818831,16.780000180006,0.00073566603807084,0.000128216332956627,0.25,-2.147769842377E-7,6.51032579373257E-5,1.0803213436638E-7,10.0033684,10.0033684,1784.07800292969,1793.80090332031,56.3124266679867,20.5748369232994,13.038077,0,0,0,40,4449,9.99595,1788.939453125,,,,,,,,,,,,,0,,,,-0.00245,,,,,,10.0033684,,,,
,23224951.35,10.0051861,1335.44604492188,6.64765490033766E-5,3.16955581645435E-7,1,0.999253354069792,40.0298881530762,1.99585820285702,16.780000180006,0.00074704844986633,0.000129504805490232,0.25,-2.76331427783207E-7,6.60997269303894E-5,4.99668924008878E-8,10.0051861,10.0051861,1329.12768554688,1341.76440429688,56.1131113955829,20.5722485054721,12.658426,0,0,0,40,4449,9.99725,1335.44604492188,,,,,,,,,,,,,0,,,,-0.00245,,,,,,10.0051861,,,,
,23224970.07,10.0054979,868.087341308594,6.73040109224298E-5,2.31363489151141E-7,1,0.999253354069792,40.0298881530762,1.9958509594494,16.780000180006,0.00075601507726797,0.000132871261895765,0.25,-1.2146481995471E-7,6.69202022932801E-5,2.06241811505962E-7,10.0054979,10.0054979,864.666625976563,871.508056640625,56.4429586306983,20.5734085209598,13.038077,0,0,0,40,4449,9.99705,868.087341308594,,,,,,,,,,,,,0,,,,-0.0049,,,,,,10.0054979,,,,
,23224988.74,10.0052853,400.819580078125,6.75885263864154E-5,3.23718631353838E-7,1,0.999253354069792,40.0298881530762,1.99581391771595,16.780000180006,0.00075902065819995,0.000134336851139481,0.25,-3.94425628557958E-8,6.72013352619432E-5,2.87595930949139E-7,10.0052853,10.0052853,396.998840332031,404.640319824219,56.5047072837175,20.5735846824567,12.278775,0,0,0,40,4449,9.9928,400.819580078125,,,,,,,,,,,,,0,,,,0,,,,,,10.0052853,,,,
,23225006.585,10.0092468,-45.4629650115967,6.6678924840815E-5,3.2268217984957E-7,1,0.999253354069792,40.0298881530762,1.99590184065048,16.780000180006,0.000748493475195586,0.000134417215859982,0.25,1.29845698099414E-7,6.62953195019566E-5,4.50563150125383E-7,10.0092468,10.0092468,-48.0964050292969,-42.8295249938965,56.5719273363714,20.5737649481613,12.658426,0,0,0,40,4449,9.992,-45.4629650115967,,,,,,,,,,,,,0,,,,-0.00245,,,,,,10.0092468,,,,
,23225025.1,10.0038185,-508.113967895508,6.49544548076753E-5,2.96590008023364E-7,1,0.999253354069792,40.0298881530762,1.99577137845176,16.780000180006,0.000729589385572688,0.000128192520786911,0.25,-1.1899827659984E-7,6.45830271550374E-5,1.96087591537273E-7,10.0038185,10.0038185,-514.617614746094,-501.610321044922,56.3475999513521,20.5716652033827,12.658426,0,0,0,40,4449,9.98895,-508.113967895508,,,,,,,,,,,,,0,,,,0,,,,,,10.0038185,,,,
,23225043.6,10.0031767,-970.310729980469,6.50368355079E-5,3.50280943861526E-7,1,0.999253354069792,40.0298881530762,1.99583500413879,16.780000180006,0.000729950392498582,0.000131749559569113,0.25,1.80997808903651E-7,6.46648148817858E-5,4.96321239434318E-7,10.0031767,10.0031767,-974.267944335938,-966.353515625,56.485948199256,20.5733373635171,12.278775,0,0,0,40,4449,9.99325,-970.310729980469,,,,,,,,,,,,,0,,,,0,,,,,,10.0031767,,,,
,23225061.925,10.0008202,-1427.40826416016,6.58280015576809E-5,3.27788920872277E-7,1,0.999253354069792,40.0298881530762,1.9959215771513,16.780000180006,0.000738898020494956,0.000133245299839805,0.25,1.71203859243383E-7,6.54529893575292E-5,4.92141671216782E-7,10.0008202,10.0008202,-1431.28735351562,-1423.52917480469,56.2155047316021,20.5738428749963,12.658426,0,0,0,40,4449,9.9923,-1427.40826416016,,,,,,,,,,,,,0,,,,0,,,,,,10.0008202,,,,
,23225080.4,10.00012825,-1888.76977539062,6.68333426722738E-5,3.16898567078655E-7,1,0.999253354069792,40.0298881530762,1.99577545982109,16.780000180006,0.000750705072550971,0.000132142252432181,0.25,-1.06940495621711E-7,6.64556040337896E-5,2.22347368329338E-7,10.0000257,10.0002308,-1892.60900878906,-1884.93054199219,56.218631245679,20.5709449777254,12.658426,0,0,0,40,4449,9.9953,-1888.76977539062,,,,,,,,,,,,,0,,,,-0.00245,,,,,,10.00012825,,,,
,23225098.605,9.9986877,-2341.6416015625,6.81437081912126E-5,3.77636834078902E-7,1,0.999253354069792,40.0298881530762,1.99582364616469,16.780000180006,0.000765253396299818,0.000135907296164617,0.25,-6.99832298889408E-9,6.77597762124394E-5,3.30105706079892E-7,9.9986877,9.9986877,-2346.388671875,-2336.89453125,56.4327974599483,20.5745527094234,12.658426,0,0,0,40,4449,9.99535,-2341.6416015625,,,,,,,,,,,,,0,,,,0.00245,,,,,,9.9986877,,,,
,23225115.945,9.9980087,-2776.28308105469,6.95146987885054E-5,3.10408460011319E-7,1,0.999253354069792,40.0298881530762,1.99587582461362,16.780000180006,0.000779404114408899,0.000145877779193388,0.25,6.34619570234392E-7,6.91216005728403E-5,9.76864012914983E-7,9.9980087,9.9980087,-2778.39672851562,-2774.16943359375,56.6610329875637,20.574239009132,13.038077,0,0,0,40,4449,9.99705,-2776.28308105469,,,,,,,,,,,,,0,,,,0,,,,,,9.9980087,,,,
,23225133.49,9.9970417,-3214.43591308594,7.05863789727887E-5,3.23326378454595E-7,1,0.999253354069792,40.0298881530762,1.99578850472581,16.780000180006,0.000792217269140536,0.000143569994406205,0.25,2.36788441737097E-7,7.01910974997302E-5,5.88656974846958E-7,9.9970417,9.9970417,-3215.591796875,-3213.28002929687,56.4867298277752,20.5730433621062,12.278775,0,0,0,40,4449,9.99525,-3214.43591308594,,,,,,,,,,,,,0,,,,-0.0049,,,,,,9.9970417,,,,
,23225151.67,9.99751,-3669.98950195313,7.20075515317094E-5,2.81736149451929E-7,1,0.999253354069792,40.0298881530762,1.9957456006021,16.780000180006,0.000808559008576859,0.000144296370555548,0.25,4.65077404796839E-8,7.16073181020958E-5,4.08776558513288E-7,9.99751,9.99751,-3673.86059570313,-3666.11840820313,56.272563613506,20.5736573834182,13.038077,0,0,0,40,4449,9.9996,-3669.98950195313,,,,,,,,,,,,,0,,,,0.00245,,,,,,9.99751,,,,
,23225169.75,9.9958458,-4121.21044921875,7.31478512396346E-5,3.40647804582237E-7,1,0.999253354069792,40.0298881530762,1.99580241043268,16.780000180006,0.000821608293931518,0.000145471248914099,0.25,-5.46223174533343E-8,7.27438987704213E-5,3.16226137666368E-7,9.9958458,9.9958458,-4126.71435546875,-4115.70654296875,56.5109603118714,20.5732499260646,12.658426,0,0,0,40,4449,9.99895,-4121.21044921875,,,,,,,,,,,,,0,,,,-0.0049,,,,,,9.9958458,,,,
,23225189.18,9.9968996,-4606.43896484375,7.45672509877887E-5,3.31522545827753E-7,1,0.999253354069792,40.0298881530762,1.99585141913706,16.780000180006,0.00083724175531839,0.000150303961860811,0.25,1.20004412101585E-7,7.41569352103981E-5,4.99616994349489E-7,9.9968996,9.9968996,-4611.51611328125,-4601.36181640625,56.3007022401983,20.5752257553229,13.038077,0,0,0,40,4449,10.00065,-4606.43896484375,,,,,,,,,,,,,0,,,,0,,,,,,9.9968996,,,,
,23225206.62,9.9956312,-5042.18383789063,7.58222257379438E-5,3.18126020580302E-7,1,0.999253354069792,40.0298881530762,1.99568493024788,16.780000180006,0.000851302581551564,0.000152754949877555,0.25,1.13359144999046E-7,7.54072614400388E-5,5.01754582432646E-7,9.9956312,9.9956312,-5046.2197265625,-5038.14794921875,56.5156500829868,20.5738085334821,12.658426,0,0,0,40,4449,10.0008,-5042.18383789063,,,,,,,,,,,,,0,,,,0,,,,,,9.9956312,,,,
,23225225.655,9.9959097,-5518.46435546875,7.71718876139369E-5,2.89774464117828E-7,1,0.999253354069792,40.0298881530762,1.99575299043507,16.780000180006,0.000866187433635614,0.000157313027804794,0.25,2.7557438631034E-7,7.67512258756837E-5,6.72649419924413E-7,9.9959097,9.9959097,-5520.98681640625,-5515.94189453125,56.3210245816983,20.5731902685189,12.658426,0,0,0,40,4449,10.0014,-5518.46435546875,,,,,,,,,,,,,0,,,,-0.00245,,,,,,9.9959097,,,,
,23225244.555,9.995059,-5990.875,7.83803529671358E-5,3.64301139889144E-7,1,0.999253354069792,40.0298881530762,1.99583470311926,16.780000180006,0.000880115546450028,0.000158099845607418,0.25,1.2691342084765E-7,7.79564833952528E-5,5.33716364392953E-7,9.995059,9.995059,-5995.931640625,-5985.818359375,56.5047072837175,20.5751353937486,12.658426,0,0,0,40,4449,10.0028,-5990.875,,,,,,,,,,,,,0,,,,-0.00245,,,,,,9.995059,,,,
,23225262.36,9.9953098,-6435.7802734375,7.9750461860406E-5,2.74719069064238E-7,1,0.999253354069792,40.0298881530762,1.99570306982359,16.780000180006,0.000894873100004664,0.000164226107347639,0.25,4.26384098485872E-7,7.93201572354505E-5,8.41286904786303E-7,9.9953098,9.9953098,-6438.13037109375,-6433.43017578125,56.8853603725829,20.5719040755098,12.658426,0,0,0,40,4449,10.0036,-6435.7802734375,,,,,,,,,,,,,0,,,,0,,,,,,9.9953098,,,,
,23225281.065,9.9954538,-6902.9716796875,8.10491570027544E-5,3.83795999663159E-7,1,0.999253354069792,40.0298881530762,1.99579634291504,16.780000180006,0.000909836312777054,0.00016512155240544,0.25,2.71017277024756E-7,8.06154375736798E-5,6.96325517454037E-7,9.9954538,9.9954538,-6907.93408203125,-6898.00927734375,56.5203398541021,20.5752983833602,12.658426,0,0,0,40,4449,10.0047,-6902.9716796875,,,,,,,,,,,,,0,,,,-0.00245,,,,,,9.9954538,,,,
,23225298.82,9.9964666,-7347.4677734375,8.21967946905904E-5,3.44116267318526E-7,1,0.999253354069792,40.0298881530762,1.9958763627114,16.780000180006,0.000921928100638242,0.000172285220592937,0.25,7.00692123713962E-7,8.17573701329557E-5,1.13245707354294E-6,9.9964666,9.9964666,-7349.84814453125,-7345.08740234375,56.7477937531983,20.5772305809981,12.278775,0,0,0,40,4449,10.005,-7347.4677734375,,,,,,,,,,,,,0,,,,0,,,,,,9.9964666,,,,
,23225316.61,9.9948759,-7792.59594726563,8.35873000288664E-5,3.84055655437595E-7,1,0.999253354069792,40.0298881530762,1.99571013611224,16.780000180006,0.000938719487754364,0.000168238045357322,0.25,9.07462957798924E-8,8.31465278407346E-5,5.35855025103145E-7,9.9946022,9.9951496,-7794.84814453125,-7790.34375,56.8025077495445,20.5732334972181,12.658426,0,0,0,40,4449,10.00605,-7792.59594726563,,,,,,,,,,,,,0,,,,0.0049,,,,,,9.9948759,,,,
,23225334.54,9.9960537,-8239.69384765625,8.4593055915261E-5,2.85433579073515E-7,1,0.999253354069792,40.0298881530762,1.99577350030987,16.780000180006,0.00094906330314887,0.000175958466991495,0.25,5.95142652732648E-7,8.41471607980531E-5,1.04576851536803E-6,9.9960537,9.9960537,-8244.6875,-8234.7001953125,56.8017261210252,20.575080302294,12.658426,0,0,0,40,4449,10.00525,-8239.69384765625,,,,,,,,,,,,,0,,,,-0.0049,,,,,,9.9960537,,,,
,23225353.18,9.9956312,-8705.5537109375,8.52330931411732E-5,2.86558029846162E-7,1,0.999253354069792,40.0298881530762,1.99575895909505,16.780000180006,0.000956948104557297,0.000173499825680274,0.25,2.58870150059969E-7,8.47887149707721E-5,7.17634022289016E-7,9.9956312,9.9956312,-8709.1904296875,-8701.9169921875,56.2280107879098,20.5748349001586,12.658426,0,0,0,40,4449,10.00725,-8705.5537109375,,,,,,,,,,,,,0,,,,0.0049,,,,,,9.9956312,,,,
,23225371.855,9.9959822,-9172.39306640625,8.66263371986355E-5,3.34115418773968E-7,1,0.999253354069792,40.0298881530762,1.99588223235489,16.780000180006,0.000972129725163439,0.00017946246030755,0.25,5.36905980356731E-7,8.61763716401187E-5,1.00475785650327E-6,9.9959822,9.9959822,-9177.61328125,-9167.1728515625,56.3585427506213,20.5739305416547,12.658426,0,0,0,40,4449,10.0074,-9172.39306640625,,,,,,,,,,,,,0,,,,-0.00245,,,,,,9.9959822,,,,
,23225390.505,9.9959249,-9638.5,8.78569629975687E-5,4.37723113116077E-7,1,0.999253354069792,40.0298881530762,1.99571532012846,16.780000180006,0.000985263797571197,0.00018556201449865,0.25,8.58209026684294E-7,8.7402128629148E-5,1.33415033418063E-6,9.9959249,9.9959249,-9640.1181640625,-9636.8818359375,56.5985027060252,20.5757822461042,13.038077,0,0,0,40,4449,10.00825,-9638.5,,,,,,,,,,,,,0,,,,0,,,,,,9.9959249,,,,
,23225428.99,9.9973249,-9955.19677734375,8.85570722552414E-5,4.20451971827975E-7,1,0.999253354069792,40.0298881530762,1.99567623574423,16.780000180006,0.00099334112816627,0.000185811999242761,0.25,7.534879499087E-7,8.81014608328108E-5,1.23588674153429E-6,9.9973249,9.9973249,-9960.2421875,-9950.1513671875,56.8580033744099,20.5782269266837,13.038077,0,0,0,40,4449,10.00865,-9955.19677734375,,,,,,,,,,,,,0,,,,-0.0049,,,,,,9.9973249,,,,
,23225448.375,9.9974566,-9474.259765625,8.68965005176607E-5,4.17604467281157E-7,1,0.999253354069792,40.0298881530762,1.99578818648471,16.780000180006,0.000975496911271826,0.000178022176879584,0.25,3.58950783900604E-7,8.64481808468622E-5,8.31138387767565E-7,9.9974566,9.9974566,-9479.1279296875,-9469.3916015625,56.1936191330636,20.575190714059,12.658426,0,0,0,40,4449,10.0092,-9474.259765625,,,,,,,,,,,,,0,,,,-0.0049,,,,,,9.9974566,,,,
,23225466.425,9.9975176,-9022.65869140625,8.52819236053417E-5,4.20177127858299E-7,1,0.999253354069792,40.0298881530762,1.99583872883147,16.780000180006,0.000957521567452001,0.000173808030308813,0.25,2.74629394599215E-7,8.48393171336072E-5,7.3558267539704E-7,9.9975176,9.9975176,-9025.3955078125,-9019.921875,56.3515080939483,20.575764603565,13.038077,0,0,0,40,4449,10.0088,-9022.65869140625,,,,,,,,,,,,,0,,,,0,,,,,,9.9975176,,,,
,23225484.665,9.9984245,-8566.92138671875,8.41965150395787E-5,4.60217728994498E-7,1,0.999253354069792,40.0298881530762,1.99579816655553,16.780000180006,0.000944825967490147,0.000174149838616942,0.25,5.02161296610939E-7,8.37553081497842E-5,9.53196239842053E-7,9.9984245,9.9984245,-8570.6875,-8563.1552734375,56.5445703381983,20.5766842622994,12.658426,0,0,0,40,4449,10.0087,-8566.92138671875,,,,,,,,,,,,,0,,,,0,,,,,,9.9984245,,,,
,23225503.845,9.9980583,-8088.73583984375,8.25254153971354E-5,3.83154425226482E-7,1,0.999253354069792,40.0298881530762,1.99577566371993,16.780000180006,0.000926167531228332,0.000169908643243539,0.25,4.25976666746785E-7,8.20902984219908E-5,8.65472203117926E-7,9.9980583,9.9980583,-8093.8720703125,-8083.599609375,56.3210245816983,20.5751483756097,13.038077,0,0,0,40,4449,10.00855,-8088.73583984375,,,,,,,,,,,,,0,,,,0.0049,,,,,,9.9980583,,,,
,23225523.54,9.9984846,-7597.48413085938,8.12600626213994E-5,3.62391333467904E-7,1,0.999253354069792,40.0298881530762,1.99587763749225,16.780000180006,0.000911725950244663,0.000168715277435885,0.25,5.47902144625013E-7,8.08279234565957E-5,9.77020034330925E-7,9.9984846,9.9984846,-7599.9873046875,-7594.98095703125,56.6508718168137,20.5759648857681,12.658426,0,0,0,40,4449,10.0093,-7597.48413085938,,,,,,,,,,,,,0,,,,0.0049,,,,,,9.9984846,,,,
,23225542.43,9.9989901,-7125.9462890625,7.99554541211785E-5,3.95188817290864E-7,1,0.999253354069792,40.0298881530762,1.99568597008132,16.780000180006,0.000897436245685716,0.000163392420907129,0.25,3.11011000077303E-7,7.95286649755294E-5,7.31660139609195E-7,9.9989901,9.9989901,-7128.3046875,-7123.587890625,56.3827732347175,20.5731868385881,13.038077,0,0,0,40,4449,10.0093,-7125.9462890625,,,,,,,,,,,,,0,,,,-0.0049,,,,,,9.9989901,,,,
,23225561.25,9.998786,-6655.98657226563,7.81046603299876E-5,3.541595095399E-7,1,0.999253354069792,40.0298881530762,1.99573947169917,16.780000180006,0.000875660379726986,0.000165193779481158,0.25,8.03742726985522E-7,7.76824468484495E-5,1.20927913591191E-6,9.998786,9.998786,-6660.93408203125,-6651.0390625,56.618043419006,20.5763536062481,12.658426,0,0,0,40,4449,10.0091,-6655.98657226563,,,,,,,,,,,,,0,,,,0.00245,,,,,,9.998786,,,,
,23225580.125,9.9985161,-6183.8330078125,7.68593995672609E-5,3.9245549393377E-7,1,0.999253354069792,40.0298881530762,1.99576377128409,16.780000180006,0.000862166456011147,0.000159823226695805,0.25,5.50233677839683E-7,7.6442586931072E-5,9.47927972974647E-7,9.9985161,9.9985161,-6188.8955078125,-6178.7705078125,56.6813553290637,20.5780949722813,12.658426,0,0,0,40,4449,10.00935,-6183.8330078125,,,,,,,,,,,,,0,,,,0.00245,,,,,,9.9985161,,,,
,23225597.825,10.0003796,-5740.3544921875,7.54677380582145E-5,3.14408848308491E-7,1,0.999253354069792,40.0298881530762,1.99596482943158,16.780000180006,0.000847227011769201,0.000153474014340806,0.25,2.34172827001734E-7,7.5057710314638E-5,6.2388207822811E-7,10.0003796,10.0003796,-5746.74609375,-5733.962890625,56.496109370006,20.5756704383316,12.658426,0,0,0,40,4449,10.00915,-5740.3544921875,,,,,,,,,,,,,0,,,,-0.00245,,,,,,10.0003796,,,,
,23225616.695,10.0002198,-5271.13452148438,7.37261285619655E-5,3.99409460645999E-7,1,0.999253354069792,40.0298881530762,1.99569165657476,16.780000180006,0.000827101616521322,0.000152371046757569,0.25,4.50595519888606E-7,7.33220325292898E-5,8.27606655554819E-7,10.0001831,10.0002565,-5274.8154296875,-5267.45361328125,56.5305010248521,20.5745567374448,12.278775,0,0,0,40,4449,10.0089,-5271.13452148438,,,,,,,,,,,,,0,,,,0,,,,,,10.0002198,,,,
,23225635.245,10.0003967,-4806.373046875,7.2324062623272E-5,2.81008226878091E-7,1,0.999253354069792,40.0298881530762,1.99577078473724,16.780000180006,0.000811788890930943,0.000147161348583303,0.25,2.38478222087773E-7,7.19264281777169E-5,6.07025970384865E-7,10.0003967,10.0003967,-4812.68896484375,-4800.05712890625,56.4523381729291,20.5749213084058,13.038077,0,0,0,40,4449,10.00825,-4806.373046875,,,,,,,,,,,,,0,,,,0,,,,,,10.0003967,,,,
,23225653.625,10.0010777,-4347.27001953125,7.10233567942361E-5,3.4709475453637E-7,1,0.999253354069792,40.0298881530762,1.99573874179748,16.780000180006,0.000796993850060689,0.000145401325472081,0.25,3.16025201961736E-7,7.06303054854744E-5,6.75188641695699E-7,10.0010777,10.0010777,-4349.52001953125,-4345.02001953125,56.5375356815252,20.575995913544,12.658426,0,0,0,40,4449,10.0076,-4347.27001953125,,,,,,,,,,,,,0,,,,0,,,,,,10.0010777,,,,
,23225672.75,10.0012379,-3868.69848632812,6.94948152180974E-5,3.38107988003671E-7,1,0.999253354069792,40.0298881530762,1.9956756073587,16.780000180006,0.000779842416807031,0.000141987762728431,0.25,2.86999281472376E-7,6.91081985536023E-5,6.36234335046083E-7,10.0012379,10.0012379,-3870.33349609375,-3867.0634765625,56.4640626007175,20.5760073601604,13.038077,0,0,0,40,4449,10.0082,-3868.69848632812,,,,,,,,,,,,,0,,,,-0.00245,,,,,,10.0012379,,,,
,23225691.915,10.0017138,-3390.14001464844,6.7974700295258E-5,2.84648953140315E-7,1,0.999253354069792,40.0298881530762,1.9957524267463,16.780000180006,0.000763029250638535,0.00013753306420689,0.25,1.62751528146281E-7,6.75951012629947E-5,5.02772704728617E-7,10.0017138,10.0017138,-3394.98217773438,-3385.2978515625,56.4265444317944,20.5733224572718,12.658426,0,0,0,40,4449,10.0072,-3390.14001464844,,,,,,,,,,,,,0,,,,0.00245,,,,,,10.0017138,,,,
,23225710.09,10.0015106,-2935.40002441406,6.68851598839021E-5,3.01860653896524E-7,1,0.999253354069792,40.0298881530762,1.99587560470514,16.780000180006,0.000750569991073922,0.000136752065435886,0.25,2.88559981229409E-7,6.65091620471459E-5,6.20369670662511E-7,10.0015106,10.0015106,-2940.52221679687,-2930.27783203125,56.7978179784291,20.5774160356345,12.278775,0,0,0,40,4449,10.00665,-2935.40002441406,,,,,,,,,,,,,0,,,,-0.00245,,,,,,10.0015106,,,,
,23225729.065,10.0029135,-2460.61120605469,6.5563109916415E-5,3.46381676235261E-7,1,0.999253354069792,40.0298881530762,1.99582591160997,16.780000180006,0.00073530106640676,0.00013626529592403,0.25,4.82866214291358E-7,6.51917371718255E-5,8.04949105891463E-7,10.0029135,10.0029135,-2465.43505859375,-2455.78735351562,56.5140868259483,20.5767416535141,13.038077,0,0,0,40,4449,10.00515,-2460.61120605469,,,,,,,,,,,,,0,,,,0.0049,,,,,,10.0029135,,,,
,23225747.705,10.0029078,-1995.73071289062,6.41641712077227E-5,3.29726452595642E-7,1,0.999253354069792,40.0298881530762,1.9957222741664,16.780000180006,0.000720309787438422,0.000129112179652705,0.25,9.72659490255916E-8,6.38009087367123E-5,4.1269657753229E-7,10.0029078,10.0029078,-2003.19384765625,-1988.267578125,56.4984542555637,20.574473536833,12.278775,0,0,0,40,4449,10.00485,-1995.73071289062,,,,,,,,,,,,,0,,,,0,,,,,,10.0029078,,,,
,23225766.82,10.004426,-1517.28070068359,6.31031898427262E-5,3.1472108611035E-7,1,0.999253354069792,40.0298881530762,1.99570464449098,16.780000180006,0.000708711643894413,0.00012507756961656,0.25,-7.12985264681789E-8,6.27451432611757E-5,2.38026777474425E-7,10.004426,10.004426,-1520.91088867187,-1513.65051269531,56.482821685179,20.5750144649374,12.658426,0,0,0,40,4449,10.0033,-1517.28070068359,,,,,,,,,,,,,0,,,,0.0049,,,,,,10.004426,,,,
,23225785.405,10.004858,-1053.45489501953,6.16081066021301E-5,3.38974969035748E-7,1,0.999253354069792,40.0298881530762,1.99565904449386,16.780000180006,0.000691917351165924,0.000121949343323466,0.25,-8.21509703482006E-8,6.12571760440375E-5,2.18277277942831E-7,10.004858,10.004858,-1058.55554199219,-1048.35424804688,56.7040225561214,20.5747016479051,12.278775,0,0,0,40,4449,10.0015,-1053.45489501953,,,,,,,,,,,,,0,,,,-0.0049,,,,,,10.004858,,,,
,23225804.625,10.0060883,-572.555694580078,6.12386376669152E-5,3.03485573645994E-7,1,0.999253354069792,40.0298881530762,1.99582031832444,16.780000180006,0.000687659654964869,0.000122047204233319,0.25,-6.85539338600298E-9,6.08881128547329E-5,2.89794673894247E-7,10.0060883,10.0060883,-573.76318359375,-571.348205566406,56.3663590358137,20.5774142243672,12.658426,0,0,0,40,4449,10.0003,-572.555694580078,,,,,,,,,,,,,0,,,,-0.00245,,,,,,10.0060883,,,,
,23225823.61,10.0081711,-97.7276191711426,6.19531452047018E-5,2.59048522865992E-7,1,0.999253354069792,40.0298881530762,1.99567620272167,16.780000180006,0.000695842170347586,0.000122223799673258,0.25,-1.15789333565169E-7,6.15979572270457E-5,1.83660989299975E-7,10.0081711,10.0081711,-101.42333984375,-94.0318984985352,56.310081782429,20.575030357613,13.038077,0,0,0,40,4449,9.99765,-97.7276191711426,,,,,,,,,,,,,0,,,,0.00245,,,,,,10.0081711,,,,
,23225842.83,10.0068235,381.754013061523,6.40333398559295E-5,2.51201203225885E-7,1,0.999253354069792,40.0298881530762,1.99578147049545,16.780000180006,0.000718734387704227,0.000129238008602373,0.25,1.38078937002348E-7,6.36656190243032E-5,4.46853483429378E-7,10.0068235,10.0068235,375.611358642578,387.896667480469,56.5602029085829,20.5728267236693,12.278775,0,0,0,40,4449,9.99555,381.754013061523,,,,,,,,,,,,,0,,,,-0.00245,,,,,,10.0068235,,,,
,23225861.13,10.0029273,838.661590576172,6.41855217518893E-5,2.77194219300565E-7,1,0.999253354069792,40.0298881530762,1.99571613454509,16.780000180006,0.000720706604222654,0.000128009913306291,0.25,3.5251349478934E-10,6.3818845742059E-5,3.12110883233613E-7,10.0028324,10.0030222,832.441040039063,844.882141113281,56.5039256551983,20.5744227218228,12.278775,0,0,0,40,4449,9.9982,838.661590576172,,,,,,,,,,,,,0,,,,0,,,,,,10.0029273,,,,
,23225879.245,10.0009632,1290.01361083984,6.33818300682174E-5,2.85927426680502E-7,1,0.999253354069792,40.0298881530762,1.99565151749703,16.780000180006,0.000711141658843407,0.000129413669542544,0.25,2.6663112661461E-7,6.30198175930619E-5,5.74556670929467E-7,10.0009632,10.0009632,1286.45874023438,1293.56848144531,56.3726120639675,20.5747297587009,13.038077,0,0,0,40,4449,9.99965,1290.01361083984,,,,,,,,,,,,,0,,,,0.0049,,,,,,10.0009632,,,,
,23225896.875,9.9998245,1730.90338134766,6.23846215151547E-5,2.84931920677968E-7,1,0.999253354069792,40.0298881530762,1.99565118575461,16.780000180006,0.000700201387890327,0.000126072183579048,0.25,1.44293114930737E-7,6.20302986594512E-5,4.49677134314915E-7,9.9998245,9.9998245,1725.982421875,1735.82434082031,56.3632325217367,20.5737499489312,13.038077,0,0,0,40,4449,9.99955,1730.90338134766,,,,,,,,,,,,,0,,,,-0.00245,,,,,,9.9998245,,,,
,23225915.715,9.999054,2200.02368164062,6.09364169884493E-5,3.60986702957306E-7,1,0.999253354069792,40.0298881530762,1.99570053044979,16.780000180006,0.000684508926993661,0.000120178721331043,0.25,-1.25581724413131E-7,6.05931940411375E-5,1.75992949853725E-7,9.999054,9.999054,2197.59228515625,2202.455078125,56.4929828559291,20.5739401814084,12.658426,0,0,0,40,4449,10.0015,2200.02368164062,,,,,,,,,,,,,0,,,,0,,,,,,9.999054,,,,
,23225934.22,9.9978209,2661.5966796875,5.97300539358755E-5,3.03797626009383E-7,1,0.999253354069792,40.0298881530762,1.99571520267104,16.780000180006,0.000670758612781389,0.000119051091276726,0.25,-1.37703942897914E-8,5.93946655423266E-5,2.82988644860301E-7,9.9978209,9.9978209,2656.3095703125,2666.8837890625,56.3898078913906,20.5727347504371,12.658426,0,0,0,40,4449,10.00225,2661.5966796875,,,,,,,,,,,,,0,,,,0.00245,,,,,,9.9978209,,,,
,23225952.68,9.9976215,3122.45397949219,5.82574019235941E-5,2.63187767965247E-7,1,0.999253354069792,40.0298881530762,1.99572221958773,16.780000180006,0.000653734019050314,0.000118973436322801,0.25,2.38936962953756E-7,5.79306203005451E-5,5.28742912272533E-7,9.9976215,9.9976215,3121.43212890625,3123.47583007812,56.5219031111406,20.5733006877941,12.278775,0,0,0,40,4449,10.00315,3122.45397949219,,,,,,,,,,,,,0,,,,0.0049,,,,,,9.9976215,,,,
,23225971.54,9.9970798,3596.24267578125,5.70481782532218E-5,2.85979243102027E-7,1,0.999253354069792,40.0298881530762,1.99570402960655,16.780000180006,0.000641431884026733,0.000109453649831893,0.25,-3.95885504980386E-7,5.67330049717473E-5,-1.06759090957108E-7,9.9970798,9.9970798,3593.7998046875,3598.685546875,56.4968909985252,20.5736721706965,12.658426,0,0,0,40,4449,10.006,3596.24267578125,,,,,,,,,,,,,0,,,,0.0049,,,,,,9.9970798,,,,
,23225989.345,9.9965162,4040.19470214844,5.52141707948014E-5,3.05200711764056E-7,1,0.999253354069792,40.0298881530762,1.99573254616859,16.780000180006,0.000619951121458919,0.000110922129705414,0.25,5.88431377712492E-8,5.4908460468256E-5,3.37906478433412E-7,9.9965162,9.9965162,4036.38598632812,4044.00341796875,56.5273745107752,20.5747430197359,12.278775,0,0,0,40,4449,10.0045,4040.19470214844,,,,,,,,,,,,,0,,,,0,,,,,,9.9965162,,,,
,23226008.475,9.9963112,4518.89184570313,5.42732750461545E-5,3.62277338246197E-7,1,0.999253354069792,40.0298881530762,1.99560038407058,16.780000180006,0.00060920323523745,0.000109951027556273,0.25,1.38175952134868E-7,5.39740566263165E-5,4.1385957142461E-7,9.9963112,9.9963112,4514.2587890625,4523.52490234375,56.5664559367368,20.5729904845383,12.658426,0,0,0,40,4449,10.007,4518.89184570313,,,,,,,,,,,,,0,,,,-0.0049,,,,,,9.9963112,,,,
,23226026.02,9.9966469,4957.58642578125,5.26520137689469E-5,3.8644299503786E-7,1,0.999253354069792,40.0298881530762,1.99566232027656,16.780000180006,0.000592492258648791,9.85088006573823E-5,0.25,-5.94546482677973E-7,5.23670059492376E-5,-3.21473515316393E-7,9.9966469,9.9966469,4951.23291015625,4963.93994140625,56.4406137451406,20.5762181957264,12.658426,0,0,0,40,4449,10.0059,4957.58642578125,,,,,,,,,,,,,0,,,,-0.00245,,,,,,9.9966469,,,,
,23226045.26,9.9966125,5439.19995117188,5.14452055127584E-5,3.35364124182459E-7,1,0.999253354069792,40.0298881530762,1.99563793889095,16.780000180006,0.000578409817446042,9.91474188049999E-5,0.25,-3.2497027812782E-7,5.11671222630547E-5,-5.77955834494065E-8,9.9966125,9.9966125,5434.025390625,5444.37451171875,56.371048806929,20.5762524915113,12.278775,0,0,0,40,4449,10.00735,5439.19995117188,,,,,,,,,,,,,0,,,,0.00245,,,,,,9.9966125,,,,
,23226063.07,9.995738,5883.4052734375,4.97423131691507E-5,3.25616166996503E-7,1,0.999253354069792,40.0298881530762,1.99563474861875,16.780000180006,0.000559285994524681,9.58381053607605E-5,0.25,-3.18505812388481E-7,4.94750086346046E-5,-5.85677717022036E-8,9.995738,9.995738,5878.40380859375,5888.40673828125,56.4992358840829,20.5760766687865,12.278775,0,0,0,40,4449,10.00805,5883.4052734375,,,,,,,,,,,,,0,,,,0,,,,,,9.995738,,,,
,23226080.685,9.9961081,6323.45678710937,4.87829644510835E-5,3.63185330294702E-7,1,0.999253354069792,40.0298881530762,1.99564160126056,16.780000180006,0.000548824113574981,9.22768423578032E-5,0.25,-4.66728107985066E-7,4.85231574120561E-5,-2.09424452993366E-7,9.9961081,9.9961081,6321.07861328125,6325.8349609375,56.6922981283329,20.5744582586073,13.038077,0,0,0,40,4449,10.0082,6323.45678710937,,,,,,,,,,,,,0,,,,0,,,,,,9.9961081,,,,
,23226098.61,9.995183,6771.95483398438,4.69714808548039E-5,3.66015540240604E-7,1,0.999253354069792,40.0298881530762,1.99568823445131,16.780000180006,0.000528014134115046,9.14362716601828E-5,0.25,-2.21134204762841E-7,4.6721660766692E-5,2.6918854063214E-8,9.995183,9.995183,6770.64599609375,6773.263671875,56.1998721612175,20.5742170856657,12.658426,0,0,0,40,4449,10.0089,6771.95483398438,,,,,,,,,,,,,0,,,,0,,,,,,9.995183,,,,
,23226116.25,9.99577665,7211.42797851562,4.58140114581618E-5,3.82842827013805E-7,1,0.999253354069792,40.0298881530762,1.99563971771016,16.780000180006,0.000515270683528296,8.7707489078441E-5,0.25,-3.48616432083653E-7,4.55725387340441E-5,-1.04500178911159E-7,9.9957151,9.9958382,7207.755859375,7215.10009765625,56.5727089648906,20.5744602788858,12.278775,0,0,0,40,4449,10.0111,7211.42797851562,,,,,,,,,,,,,0,,,,0.00245,,,,,,9.99577665,,,,
,23226135.08,9.9956656,7682.76049804687,4.42488517586772E-5,3.57963303957866E-7,1,0.999253354069792,40.0298881530762,1.99569330504104,16.780000180006,0.000496892031219755,8.92415064446526E-5,0.25,6.46273017559868E-8,4.40150638234593E-5,2.99809545306835E-7,9.9956656,9.9956656,7677.796875,7687.72412109375,56.5859966497175,20.5753450422893,12.278775,0,0,0,40,4449,10.0105,7682.76049804687,,,,,,,,,,,,,0,,,,0.00245,,,,,,9.9956656,,,,
,23226153.68,9.9961982,8147.23901367187,4.30251215950702E-5,3.61882436609809E-7,1,0.999253354069792,40.0298881530762,1.99559639240469,16.780000180006,0.000483389536714421,8.53995979568577E-5,0.25,-6.08670743921088E-8,4.2799978217182E-5,1.69936261672384E-7,9.9960804,9.996316,8142.06103515625,8152.4169921875,56.3022654972367,20.5721689111687,12.658426,0,0,0,40,4449,10.0123,8147.23901367187,,,,,,,,,,,,,0,,,,0,,,,,,9.9961982,,,,
,23226171.665,9.9963636,8598.54443359375,4.20269192128358E-5,2.72538466356088E-7,1,0.999253354069792,40.0298881530762,1.99563824553374,16.780000180006,0.000472930636211758,7.93261904575292E-5,0.25,-4.25566300116281E-7,4.18104373657093E-5,-1.96811928188327E-7,9.9963636,9.9963636,8597.5576171875,8599.53125,56.7845302936022,20.5762272518518,12.278775,0,0,0,40,4449,10.0113,8598.54443359375,,,,,,,,,,,,,0,,,,0,,,,,,9.9963636,,,,
,23226190.21,9.9964552,9061.34375,3.99575561366923E-5,3.13433060792926E-7,1,0.999253354069792,40.0298881530762,1.99555753796411,16.780000180006,0.000449041064504911,7.87994495670785E-5,0.25,-1.05131590402713E-7,3.97515692171161E-5,1.12164513872347E-7,9.9964552,9.9964552,9054.99609375,9067.69140625,56.5742722219291,20.5744466157714,12.278775,0,0,0,40,4449,10.012,9061.34375,,,,,,,,,,,,,0,,,,0,,,,,,9.9964552,,,,
,23226208.725,9.9964881,9523.53955078125,3.83368841494198E-5,3.1838505947797E-7,1,0.999253354069792,40.0298881530762,1.99552363164822,16.780000180006,0.000432170395724702,6.81239055328752E-5,0.25,-7.68173452331673E-7,3.81443029580442E-5,-5.54958249853041E-7,9.9962673,9.9967089,9517.3544921875,9529.724609375,56.4429586306983,20.5736256918084,12.658426,0,0,0,40,4449,10.01295,9523.53955078125,,,,,,,,,,,,,0,,,,-0.0049,,,,,,9.9964881,,,,
,23226229.79,9.9953241,9999.73583984375,3.71622965583398E-5,4.15438143420032E-7,1,0.999253354069792,40.0298881530762,1.99564250147487,16.780000180006,0.000418689347576247,6.76152123455432E-5,0.25,-6.0599627777614E-7,3.69763020636405E-5,-3.98739708174772E-7,9.9953241,9.9953241,9999.720703125,9999.7509765625,56.2444249868136,20.5725110339909,12.278775,0,0,0,40,4417,10.0128,9999.73583984375,,,,,,,,,,,,,0,,,,0.0049,,,,,,9.9953241,,,,