File: data/doubleLayers/dl_2-5/ppms/DD205_5/KoelnPPMS/CooldownTests/DD205_5_1TFCC_TEST.DAT
[Header]
; VSM Data File (default extension .dat)
; Copyright (c) 2003-2013, Quantum Design, Inc. All rights reserved.
TITLE,
FILEOPENTIME,23217343.53,09/27/2018,2:14 am
BYAPP,VSM,2.0,2.0
INFO,PPMS VSM Option Release 1.4.10 Build 1,APPNAME
INFO,Quantum Design Linear Motor Servo Controller,MOTOR_MODULE_NAME
INFO,3101-100 M1,MOTOR_HW_VERSION
INFO,MMC1014,MOTOR_SERIAL_NUMBER
INFO,SRV No X-over 01.03.11,MOTOR_SOFTWARE_VERSION
INFO,Quantum Design VSM Detection Module,VSM_MODULE_NAME
INFO,3101-150 F0,VSM_HW_VERSION
INFO,VSM707,VSM_SERIAL_NUMBER
INFO,VSM No X-over 01.02.05 May 20 2008 13:51:47,VSM_SOFTWARE_VERSION
INFO,704,PREAMP_SERIAL_NUMBER
INFO,822,COIL_SERIAL_NUMBER
INFO,0,MOMENT_UNITS
INFO,,SAMPLE_MATERIAL
INFO,,SAMPLE_COMMENT
INFO,,SAMPLE_MASS
INFO,,SAMPLE_VOLUME
INFO,,SAMPLE_MOLECULAR_WEIGHT
INFO,,SAMPLE_SIZE
INFO,,SAMPLE_SHAPE
DATATYPE,COMMENT,1
DATATYPE,TIME,2
STARTUPAXIS,X,2
STARTUPAXIS,Y1,5
[Data]
Comment,Time Stamp (sec),Temperature (K),Magnetic Field (Oe),Moment (emu),M. Std. Err. (emu),Transport Action,Averaging Time (sec),Frequency (Hz),Peak Amplitude (mm),Center Position (mm),Coil Signal' (mV),Coil Signal" (mV),Range (mV),M. Quad. Signal (emu),M. Raw' (emu),M. Raw" (emu),Min. Temperature (K),Max. Temperature (K),Min. Field (Oe),Max. Field (Oe),Mass (grams),Motor Lag (deg),Pressure (Torr),VSM Status (code),Motor Status (code),Measure Status (code),Measure Count,PPMS Status (code),System Temp. (K),System Field (Oe),Sample Position (deg),Bridge 1 Resistance (ohms),Bridge 1 Excitation (에),Bridge 2 Resistance (ohms),Bridge 2 Excitation (에),Bridge 3 Resistance (ohms),Bridge 3 Excitation (에),Bridge 4 Resistance (ohms),Bridge 4 Excitation (에),Signal 1 Vin (V),Signal 2 Vin (V),Digital Inputs (code),Drive 1 Iout (mA),Drive 1 Ipower (W),Drive 2 Iout (mA),Drive 2 Ipower (W),Pressure (),Map 20 (),Map 21 (),Map 22 (),Map 23 (),Map 24 (),Map 25 (),Map 26 (),Map 27 (),Map 28 (),Map 29 ()
,23217382.95,89.4358139,9999.5078125,,,2,,,,16.7400004118681,,,,,,,89.4358139,89.4358139,9999.5078125,9999.5078125,,,23.288654,,,,-99999999,4374,114.3029,9999.5078125,,,,,,,,,,,,,,,,,,,,,,,89.4358139,,,,
,23218441.41,268.2712402,9999.5078125,,,2,,,,16.0700004324317,,,,,,,268.2712402,268.2712402,9999.5078125,9999.5078125,,,27.085165,,,,-99999999,4374,290.6262,9999.5078125,,,,,,,,,,,,,,,,,,,,,,,268.2712402,,,,
,23219304.18,300.1776428,9999.5078125,3.84664976268826E-5,7.79155542170205E-7,1,0.999253354069792,40.0298881530762,2.00812769816697,15.9200001507998,0.000436231096039242,8.18338994838531E-5,0.25,5.34021241390095E-7,3.84647538919266E-5,5.59483517881679E-7,300.1776428,300.1776428,9999.5078125,9999.5078125,56.5531682519098,20.5586300102611,28.603769,0,0,0,40,4374,300.24525,9999.5078125,,,,,,,,,,,,,0,,,,-0.0049,,,,,,300.1776428,,,,
,23219339.735,299.793396,9999.5078125,3.73251028719677E-5,6.86008952144327E-7,1,0.999253354069792,40.0298881530762,2.00828242355698,15.9200001507998,0.000424685834188749,7.15519732899394E-5,0.25,-1.73337470488362E-7,3.73243758914028E-5,-1.48511042659078E-7,299.7774353,299.8093567,9999.5078125,9999.5078125,56.4984542555637,20.5588360052387,28.603769,0,0,0,40,4374,299.257,9999.5078125,,,,,,,,,,,,,0,,,,0.00245,,,,,,299.793396,,,,
,23219374.195,299.2551575,9999.5078125,3.79550867376316E-5,6.50658183297479E-7,1,0.999253354069792,40.0298881530762,2.00822819581337,15.9200001507998,0.000430935400421019,7.80428588218454E-5,0.25,2.8833769782369E-7,3.79547573906903E-5,3.13732880345335E-7,299.2551575,299.2551575,9999.5078125,9999.5078125,56.8892685151791,20.5610254595177,28.224119,0,0,0,40,4374,297.72255,9999.5078125,,,,,,,,,,,,,0,,,,-0.00245,,,,,,299.2551575,,,,
,23219408.48,298.42358395,9999.5078125,3.8474918844252E-5,7.14480627922094E-7,1,0.999253354069792,40.0298881530762,2.00826779908206,15.9200001507998,0.000438504656701744,6.9615020196597E-5,0.25,-5.43588998842777E-7,3.84762751103701E-5,-5.17609491522412E-7,298.3731689,298.473999,9999.5078125,9999.5078125,56.7134020983521,20.5562609686691,28.603769,0,0,0,40,4374,295.32075,9999.5078125,,,,,,,,,,,,,0,,,,0.0049,,,,,,298.42358395,,,,
,23219442.095,297.1513977,9999.5078125,3.65737802688005E-5,7.87353572064676E-7,1,0.999253354069792,40.0298881530762,2.00828099805461,15.9200001507998,0.000416327846104286,6.92410399210652E-5,0.25,-2.4766896501709E-7,3.65765363698473E-5,-2.22687736592547E-7,297.1513977,297.1513977,9999.5078125,9999.5078125,56.6438371601406,20.5608290857705,28.983419,0,0,0,40,4374,292.45025,9999.5078125,,,,,,,,,,,,,0,,,,0,,,,,,297.1513977,,,,
,23219475.005,295.5837708,9999.5078125,3.77685792301159E-5,9.65784255064772E-7,1,0.999253354069792,40.0298881530762,2.00822424628835,15.9200001507998,0.000428894345427484,7.75442599497851E-5,0.25,2.75061771010631E-7,3.77731609626759E-5,3.01233400401174E-7,295.5837708,295.5837708,9999.5078125,9999.5078125,56.6805737005445,20.5606863139466,28.224119,0,0,0,40,4374,289.43865,9999.5078125,,,,,,,,,,,,,0,,,,0,,,,,,295.5837708,,,,
,23219508.46,293.6382446,9999.5078125,3.67048358729522E-5,8.20027083082826E-7,1,0.999253354069792,40.0298881530762,2.00821912950075,15.9200001507998,0.000416835637065913,7.54045525412677E-5,0.25,2.70440419901474E-7,3.67118245711307E-5,2.96224644812429E-7,293.6382446,293.6382446,9999.5078125,9999.5078125,56.6672860157175,20.5618562555368,28.603769,0,0,0,40,4374,286.3307,9999.5078125,,,,,,,,,,,,,0,,,,0,,,,,,293.6382446,,,,
,23219541.335,291.4837036,9999.5078125,3.85416225501144E-5,1.03089592330279E-6,1,0.999253354069792,40.0298881530762,2.00812138343254,15.9200001507998,0.000437447669357108,8.06837100236563E-5,0.25,4.15826731091907E-7,3.85518235892779E-5,4.43315014584714E-7,291.4837036,291.4837036,9999.5078125,9999.5078125,56.6086638767752,20.5629823371075,28.603769,0,0,0,40,4374,283.2219,9999.5078125,,,,,,,,,,,,,0,,,,0.0049,,,,,,291.4837036,,,,
,23219603.845,287.0586548,9999.5078125,3.84595715100863E-5,7.81577421984744E-7,1,0.999253354069792,40.0298881530762,1.98446988520244,15.9499999135733,0.000430279488657852,8.76762436273122E-5,0.25,1.13073007384894E-6,3.847529228839E-5,1.15924274122426E-6,287.0586548,287.0586548,9999.5078125,9999.5078125,56.6571248449675,20.5674579273341,28.603769,0,0,0,40,4374,277.2352,9999.5078125,,,,,,,,,,,,,0,,,,0,,,,,,287.0586548,,,,
,23219636.845,284.3961182,9999.5078125,3.87523575775165E-5,8.78020778972945E-7,1,0.999253354069792,40.0298881530762,1.98446811870618,15.9499999135733,0.000436379970719758,7.22902299835491E-5,0.25,-2.89247070943666E-7,3.87729285877907E-5,-2.60769799917374E-7,284.3961182,284.3961182,9999.5078125,9999.5078125,56.6899532427752,20.5682233239725,28.983419,0,0,0,40,4374,274.0907,9999.5078125,,,,,,,,,,,,,0,,,,-0.00245,,,,,,284.3961182,,,,
,23219670.5,281.7541504,9999.5078125,4.01632913223909E-5,9.40070084765341E-7,1,0.999253354069792,40.0298881530762,1.9843832808747,15.9499999135733,0.000453187635821702,6.97615616763222E-5,0.25,-7.59408989290119E-7,4.01887491324794E-5,-7.29790327262964E-7,281.7541504,281.7541504,9999.5078125,9999.5078125,56.5422254526406,20.5681811422855,28.603769,0,0,0,40,4374,270.9185,9999.5078125,,,,,,,,,,,,,0,,,,0.0049,,,,,,281.7541504,,,,
,23219703.71,278.9641724,9999.5078125,3.80288136629706E-5,8.00617313944417E-7,1,0.999253354069792,40.0298881530762,1.9844485394717,15.9499999135733,0.000426892681782982,7.91376188169603E-5,0.25,4.42954084841735E-7,3.80558359860819E-5,4.72155623604939E-7,278.9641724,278.9641724,9999.5078125,9999.5078125,56.709493955756,20.568617420633,28.603769,0,0,0,40,4374,267.84845,9999.5078125,,,,,,,,,,,,,0,,,,0,,,,,,278.9641724,,,,
,23219767.055,273.7893677,9999.5078125,3.92914230835223E-5,7.79641873999404E-7,1,0.999253354069792,40.0298881530762,1.98439075024892,15.9499999135733,0.000440832811080153,8.35220603568281E-5,0.25,6.11921093774098E-7,3.93264755739838E-5,6.43098625692316E-7,273.7893677,273.7893677,9999.5078125,9999.5078125,56.4617177151598,20.5688244491666,28.224119,0,0,0,40,4374,262.13635,9999.5078125,,,,,,,,,,,,,0,,,,-0.00245,,,,,,273.7893677,,,,
,23219800.985,270.8056641,9999.5078125,3.86584712063653E-5,5.59297568934384E-7,1,0.999253354069792,40.0298881530762,1.98441359634025,15.9499999135733,0.000435268873419601,7.36123044152032E-5,0.25,-1.60394042518142E-7,3.86976744577991E-5,-1.30006453737628E-7,270.8056641,270.8056641,9999.5078125,9999.5078125,56.7032409276022,20.5667222513167,28.224119,0,0,0,40,4374,259.14,9999.5078125,,,,,,,,,,,,,0,,,,0.0049,,,,,,270.8056641,,,,
,23219834.945,267.9959106,9999.5078125,3.90151766045945E-5,5.49498485327033E-7,1,0.999253354069792,40.0298881530762,1.98454722393122,15.9499999135733,0.000439796118844226,7.17735720945364E-5,0.25,-3.87145506152062E-7,3.90588321112312E-5,-3.56312205070009E-7,267.9959106,267.9959106,9999.5078125,9999.5078125,56.4671891147944,20.5653261676174,28.603769,0,0,0,40,4374,256.1539,9999.5078125,,,,,,,,,,,,,0,,,,0,,,,,,267.9959106,,,,
,23219898.36,262.6963196,9999.5078125,3.9842387272349E-5,4.65004938308026E-7,1,0.999253354069792,40.0298881530762,2.00836305310977,15.9799996763468,0.000452767915921571,8.32672599224276E-5,0.25,4.0481643245211E-7,3.9893833683488E-5,4.38108642019594E-7,262.6963196,262.6963196,9999.5078125,9999.5078125,56.5555131374675,20.5630511597318,28.983419,0,0,0,40,4374,250.67115,9999.5078125,,,,,,,,,,,,,0,,,,-0.00245,,,,,,262.6963196,,,,
,23219932.315,259.8110352,9999.5078125,3.99878779982425E-5,4.93778727896569E-7,1,0.999253354069792,40.0298881530762,2.00824187032185,15.9799996763468,0.000455360519427151,7.82765764637415E-5,0.25,-5.95713561267666E-8,4.00439942857983E-5,-2.63101539920874E-8,259.8110352,259.8110352,9999.5078125,9999.5078125,56.424981174756,20.5646605660164,28.603769,0,0,0,40,4374,247.79385,9999.5078125,,,,,,,,,,,,,0,,,,0,,,,,,259.8110352,,,,
,23219965.665,256.9978027,9999.5078125,3.98670618946776E-5,4.9400742677531E-7,1,0.999253354069792,40.0298881530762,2.00846268895973,15.9799996763468,0.000454252046944022,7.70500819340001E-5,0.25,-1.48185354618081E-7,3.99270605778722E-5,-1.14709685887772E-7,256.9978027,256.9978027,9999.5078125,9999.5078125,56.4875114562944,20.5634631634094,28.224119,0,0,0,40,4374,245.00945,9999.5078125,,,,,,,,,,,,,0,,,,0,,,,,,256.9978027,,,,
,23220028.705,251.80862425,9999.5078125,4.0393205364618E-5,5.37982435838428E-7,1,0.999253354069792,40.0298881530762,1.98482465310493,16.0000007599592,0.000453575698126137,8.63315386968428E-5,0.25,6.59531008898039E-7,4.04607024209687E-5,6.95678585517606E-7,251.6934662,251.9237823,9999.5078125,9999.5078125,56.5758354789675,20.5623178446281,28.224119,0,0,0,40,4374,239.8006,9999.5078125,,,,,,,,,,,,,0,,,,-0.0049,,,,,,251.80862425,,,,
,23220061.52,249.1260071,9999.5078125,3.98737921237012E-5,6.42295239629771E-7,1,0.999253354069792,40.0298881530762,1.98481631442938,16.0000007599592,0.0004467746552714,9.10446846168664E-5,0.25,1.16698658637121E-6,3.99437266451629E-5,1.20411234851332E-6,249.1260071,249.1260071,9999.5078125,9999.5078125,56.4687523718329,20.5634887068423,28.983419,0,0,0,40,4374,237.1632,9999.5078125,,,,,,,,,,,,,0,,,,0,,,,,,249.1260071,,,,
,23220095.02,246.3905182,9999.5078125,3.98926261465658E-5,4.56761021770047E-7,1,0.999253354069792,40.0298881530762,1.98498604911666,16.0000007599592,0.000447883789284639,8.63838641112569E-5,0.25,7.48022815030883E-7,3.99667853985588E-5,7.84974262719426E-7,246.3905182,246.3905182,9999.5078125,9999.5078125,56.5922496778714,20.562755101984,28.603769,0,0,0,40,4374,234.48585,9999.5078125,,,,,,,,,,,,,0,,,,-0.00245,,,,,,246.3905182,,,,
,23220158.145,241.3357086,9999.5078125,4.00750857234958E-5,4.49476207910658E-7,1,0.999253354069792,40.0298881530762,2.00884046171906,16.0199999809265,0.000456922765195179,7.76967811120533E-5,0.25,-1.35196581425061E-7,4.01574582002856E-5,-9.88256891804932E-8,241.3357086,241.3357086,9999.5078125,9999.5078125,56.3874630058329,20.5575291660643,28.603769,0,0,0,40,4374,229.50585,9999.5078125,,,,,,,,,,,,,0,,,,0.0049,,,,,,241.3357086,,,,
,23220191.78,238.5756378,9999.5078125,4.00403008380966E-5,4.12535720486811E-7,1,0.999253354069792,40.0298881530762,2.00900306509354,16.0199999809265,0.000455748690473205,8.25785835833486E-5,0.25,2.97499771210726E-7,4.01260493833196E-5,3.3526231933121E-7,238.4810638,238.6702118,9999.5078125,9999.5078125,56.6399290175445,20.5591087699344,28.224119,0,0,0,40,4374,226.914,9999.5078125,,,,,,,,,,,,,0,,,,0,,,,,,238.5756378,,,,
,23220224.03,236.1542664,9999.5078125,4.04143742050375E-5,5.46386353958574E-7,1,0.999253354069792,40.0298881530762,2.00897839053278,16.0199999809265,0.000460813089127956,7.88987378605042E-5,0.25,-9.12882111078681E-8,4.05046771788932E-5,-5.3520862534964E-8,236.1542664,236.1542664,9999.5078125,9999.5078125,56.6102271338137,20.5592365399606,28.603769,0,0,0,40,4374,224.4414,9999.5078125,,,,,,,,,,,,,0,,,,0.00245,,,,,,236.1542664,,,,
,23220257.17,233.5579834,9999.5078125,4.03640585794468E-5,5.34335208677782E-7,1,0.999253354069792,40.0298881530762,2.00898007154598,16.0199999809265,0.000460035364766866,8.02226075155804E-5,0.25,3.24413826793958E-8,4.04577518983586E-5,7.09641207595422E-8,233.5579834,233.5579834,9999.5078125,9999.5078125,56.5359724244868,20.5617167721179,27.844467,0,0,0,40,4374,221.9232,9999.5078125,,,,,,,,,,,,,0,,,,-0.00245,,,,,,233.5579834,,,,
,23220320.44,228.6422272,9999.5078125,4.08768473625687E-5,4.23606408814883E-7,1,0.999253354069792,40.0298881530762,1.98523455063032,16.0499997437,0.000460680371387949,8.04538024080131E-5,0.25,4.20486848707573E-8,4.09786205508983E-5,8.21257797383729E-8,228.6422272,228.6422272,9999.5078125,9999.5078125,56.5492601093137,20.5586775352118,28.224119,0,0,0,40,4374,217.1941,9999.5078125,,,,,,,,,,,,,0,,,,-0.0049,,,,,,228.6422272,,,,
,23220352.905,226.1619873,9999.5078125,4.02646824941847E-5,4.78098977907006E-7,1,0.999253354069792,40.0298881530762,1.98521329722822,16.0499997437,0.000453494865450322,8.10986999220289E-5,0.25,2.04452370520597E-7,4.03681759545729E-5,2.44893402710581E-7,226.1619873,226.1619873,9999.5078125,9999.5078125,56.5437887096791,20.5601771577574,28.603769,0,0,0,40,4374,214.7885,9999.5078125,,,,,,,,,,,,,0,,,,0.00245,,,,,,226.1619873,,,,
,23220385.595,223.6374969,9999.5078125,4.05135438450101E-5,5.38867192855577E-7,1,0.999253354069792,40.0298881530762,1.98528841147517,16.0499997437,0.000457295005005646,7.61852046439813E-5,0.25,-2.76006477445739E-7,4.06216312775216E-5,-2.36012377664736E-7,223.6374969,223.6374969,9999.5078125,9999.5078125,56.7462304961599,20.5607548307731,27.844467,0,0,0,40,4374,212.3499,9999.5078125,,,,,,,,,,,,,0,,,,-0.0049,,,,,,223.6374969,,,,
,23220448.385,218.8794098,9999.5078125,3.99091803762948E-5,6.0449800411389E-7,1,0.999253354069792,40.0298881530762,1.99629480515049,16.0700008273125,0.00045117445929124,8.5568797688035E-5,0.25,6.18968053163057E-7,4.00211431819721E-5,6.61941235536744E-7,218.8794098,218.8794098,9999.5078125,9999.5078125,56.4968909985252,20.5567215770287,27.844467,0,0,0,40,4374,207.7257,9999.5078125,,,,,,,,,,,,,0,,,,0,,,,,,218.8794098,,,,
,23220481.155,216.4959412,9999.5078125,4.06719551174079E-5,4.8173685042446E-7,1,0.999253354069792,40.0298881530762,1.99628250597851,16.0700008273125,0.000462349246519887,7.27111080857161E-5,0.25,-6.48844317247342E-7,4.07906281185905E-5,-6.08093806335344E-7,216.4959412,216.4959412,9999.5078125,9999.5078125,56.6399290175445,20.5560920723417,28.224119,0,0,0,40,4374,205.29635,9999.5078125,,,,,,,,,,,,,0,,,,-0.00245,,,,,,216.4959412,,,,
,23220514.235,214.0106812,9999.5078125,4.19346336598419E-5,5.04095366825622E-7,1,0.999253354069792,40.0298881530762,1.99617655854342,16.0700008273125,0.000473560689970215,9.31528062612292E-5,0.25,9.34170630614497E-7,4.20587611840325E-5,9.81576004600835E-7,214.0106812,214.0106812,9999.5078125,9999.5078125,56.7524835243137,20.5556227214346,28.603769,0,0,0,40,4374,202.85145,9999.5078125,,,,,,,,,,,,,0,,,,0,,,,,,214.0106812,,,,
,23220545.645,211.6094666,9999.5078125,4.06627840456164E-5,4.62993637851578E-7,1,0.999253354069792,40.0298881530762,1.99641200853947,16.0700008273125,0.000458975757046892,9.21300848656246E-5,0.25,1.06266481933963E-6,4.07861937253971E-5,1.10980819419602E-6,211.6094666,211.6094666,9999.5078125,9999.5078125,56.6102271338137,20.5594063866044,27.844467,0,0,0,40,4374,200.5479,9999.5078125,,,,,,,,,,,,,0,,,,0,,,,,,211.6094666,,,,
,23220607.36,207.0774078,9999.5078125,4.01017448398707E-5,4.45136768455009E-7,1,0.999253354069792,40.0298881530762,2.00881280963826,16.0900000482798,0.000456672164786612,8.40424712742709E-5,0.25,4.00858100842988E-7,4.02300922692551E-5,4.46675322446188E-7,207.0774078,207.0774078,9999.5078125,9999.5078125,56.8345545188329,20.5587473207654,28.224119,0,0,0,40,4374,196.08095,9999.5078125,,,,,,,,,,,,,0,,,,-0.00245,,,,,,207.0774078,,,,
,23220640.085,204.6763458,9999.5078125,4.01140978156501E-5,4.55583808940484E-7,1,0.999253354069792,40.0298881530762,2.00892451723544,16.0900000482798,0.000456625570087175,8.55006602599746E-5,0.25,5.24885294194703E-7,4.02454660964243E-5,5.71835121044852E-7,204.6763458,204.6763458,9999.5078125,9999.5078125,56.5242479966983,20.5559238506537,27.844467,0,0,0,40,4374,193.7575,9999.5078125,,,,,,,,,,,,,0,,,,0.00245,,,,,,204.6763458,,,,
,23220672.6,202.3281403,9999.5078125,4.03198641764815E-5,5.40720299479979E-7,1,0.999253354069792,40.0298881530762,2.0088485196825,16.0900000482798,0.000459808426410221,8.12083229818876E-5,0.25,1.11951304176163E-7,4.04554265438964E-5,1.58473673867845E-7,202.3281403,202.3281403,9999.5078125,9999.5078125,56.8837971155445,20.5579676965728,28.603769,0,0,0,40,4374,191.4834,9999.5078125,,,,,,,,,,,,,0,,,,-0.0049,,,,,,202.3281403,,,,
,23220704.46,199.9642639,9999.5078125,4.10982108798644E-5,4.68599573820519E-7,1,0.999253354069792,40.0298881530762,2.00890640019932,16.0900000482798,0.000468312881347073,8.52020437115735E-5,0.25,3.2527498652469E-7,4.12392576426011E-5,3.74139693227582E-7,199.9642639,199.9642639,9999.5078125,9999.5078125,56.831428004756,20.5567439925761,27.844467,0,0,0,40,4374,189.26535,9999.5078125,,,,,,,,,,,,,0,,,,0,,,,,,199.9642639,,,,
,23220767.24,195.50849155,9999.5078125,4.07133220458746E-5,4.89113198452547E-7,1,0.999253354069792,40.0298881530762,2.00892120504805,16.1199998110533,0.000464668053545772,8.05468552279838E-5,0.25,-1.82833667807322E-8,4.0859189317677E-5,3.03905322591095E-8,195.4214478,195.5955353,9999.5078125,9999.5078125,56.6735390438714,20.5582668715585,27.844467,0,0,0,40,4374,184.9272,9999.5078125,,,,,,,,,,,,,0,,,,0,,,,,,195.50849155,,,,
,23220799.89,193.2135468,9999.5078125,4.05952447617242E-5,4.6339703480043E-7,1,0.999253354069792,40.0298881530762,2.00885464605863,16.1199998110533,0.000463618298406584,7.8709554049278E-5,0.25,-1.59793814351662E-7,4.07437794808986E-5,-1.11010581378625E-7,193.2135468,193.2135468,9999.5078125,9999.5078125,56.8243933480829,20.5588499342391,28.224119,0,0,0,40,4374,182.7166,9999.5078125,,,,,,,,,,,,,0,,,,0,,,,,,193.2135468,,,,
,23220832.485,190.9792786,9999.5078125,4.11905339041647E-5,5.05923552554268E-7,1,0.999253354069792,40.0298881530762,2.00878976830771,16.1199998110533,0.000470614426306372,7.88339864433574E-5,0.25,-2.53421619611603E-7,4.13442200246135E-5,-2.03478646304725E-7,190.9792786,190.9792786,9999.5078125,9999.5078125,56.8157954343714,20.5593188188885,28.224119,0,0,0,40,4374,180.53785,9999.5078125,,,,,,,,,,,,,0,,,,0.00245,,,,,,190.9792786,,,,
,23220864.795,188.7010498,9999.5078125,4.05126514038068E-5,5.27684881221138E-7,1,0.999253354069792,40.0298881530762,2.00892562138134,16.1199998110533,0.000461129289527277,8.79138304713617E-5,0.25,6.58154261862237E-7,4.06655185624528E-5,7.11507082503058E-7,188.7010498,188.7010498,9999.5078125,9999.5078125,56.7962547213906,20.5585446223024,27.844467,0,0,0,40,4374,178.36675,9999.5078125,,,,,,,,,,,,,0,,,,0,,,,,,188.7010498,,,,
,23220927.375,184.3874817,9999.5078125,4.76106977273939E-5,1.13973203079889E-5,1,0.999253354069792,40.0298881530762,2.00909600651101,16.1499995738268,0.00056140827468439,-8.0562386910528E-6,0.25,-8.9854118234886E-6,4.78092015844199E-5,-8.95900804151279E-6,184.3874817,184.3874817,9999.5078125,9999.5078125,56.668849272756,20.5572305546017,28.603769,0,0,0,40,4374,174.22325,9999.5078125,,,,,,,,,,,,,0,,,,0.00245,,,,,,184.3874817,,,,
,23220960.46,182.2668762,9999.5078125,3.88384453492574E-5,5.064825937762E-7,1,0.999253354069792,40.0298881530762,2.00925444641946,16.1499995738268,0.000441911096452563,8.61273754741274E-5,0.25,7.87717694378409E-7,3.89923043354664E-5,8.42017111952435E-7,182.2668762,182.2668762,9999.5078125,9999.5078125,56.821266834006,20.5524520955716,27.844467,0,0,0,40,4374,172.06855,9999.5078125,,,,,,,,,,,,,0,,,,-0.0049,,,,,,182.2668762,,,,
,23220993.26,180.0247498,9999.5078125,4.00554782068713E-5,4.26466735188108E-7,1,0.999253354069792,40.0298881530762,2.00944470530045,16.1499995738268,0.000457109118208839,8.14863771685876E-5,0.25,1.67586360771097E-7,4.02176722665619E-5,2.21925012129941E-7,180.0247498,180.0247498,9999.5078125,9999.5078125,56.7063674416791,20.5578871627809,27.844467,0,0,0,40,4374,169.9404,9999.5078125,,,,,,,,,,,,,0,,,,-0.00245,,,,,,180.0247498,,,,
,23221026.145,177.865799,9999.5078125,4.09937874861431E-5,5.3874324374362E-7,1,0.999253354069792,40.0298881530762,2.00927293770388,16.1499995738268,0.000467242407005113,8.66468218901992E-5,0.25,4.55444097919296E-7,4.11619881002083E-5,5.13176169180152E-7,177.865799,177.865799,9999.5078125,9999.5078125,56.7305979257752,20.5581375753878,27.464817,0,0,0,40,4374,167.8407,9999.5078125,,,,,,,,,,,,,0,,,,0.00245,,,,,,177.865799,,,,
,23221087.28,173.7225952,9999.5078125,4.0119182207506E-5,4.53667400350883E-7,1,0.999253354069792,40.0298881530762,1.99666043943341,16.1799993366003,0.000457159172394586,6.9531548743141E-5,0.25,-8.56941758635686E-7,4.02904227222057E-5,-8.04118469659906E-7,173.7225952,173.7225952,9999.5078125,9999.5078125,56.5305010248521,20.5519850154222,27.464817,0,0,0,40,4374,163.96535,9999.5078125,,,,,,,,,,,,,0,,,,-0.0049,,,,,,173.7225952,,,,
,23221120.22,171.5570984,9999.5078125,4.00335783438527E-5,4.31243775733811E-7,1,0.999253354069792,40.0298881530762,1.99635321067901,16.1799993366003,0.000456777048634253,6.57455244907982E-5,0.25,-1.17603656983439E-6,4.02074006535889E-5,-1.12375650795058E-6,171.5570984,171.5570984,9999.5078125,9999.5078125,56.689171614256,20.5542732869988,27.464817,0,0,0,40,4374,161.904,9999.5078125,,,,,,,,,,,,,0,,,,-0.0049,,,,,,171.5570984,,,,
,23221152.55,169.3989868,9999.5078125,3.96265041337833E-5,5.81677807679779E-7,1,0.999253354069792,40.0298881530762,1.99635934185571,16.1799993366003,0.000450713280038349,7.34005080543725E-5,0.25,-4.32245625125283E-7,3.97999307613194E-5,-3.76382385102724E-7,169.3317871,169.4661865,9999.5078125,9999.5078125,56.6258597041983,20.5556195566338,28.224119,0,0,0,40,4374,159.9132,9999.5078125,,,,,,,,,,,,,0,,,,-0.00245,,,,,,169.3989868,,,,
,23221185.815,167.1925507,9999.5078125,3.94340390787051E-5,6.24439315895069E-7,1,0.999253354069792,40.0298881530762,1.99626765375418,16.1799993366003,0.000449830502339873,6.55872027643404E-5,0.25,-1.08813705796747E-6,3.96100308299732E-5,-1.03443041390951E-6,167.1925507,167.1925507,9999.5078125,9999.5078125,56.9033378285253,20.5566118618581,27.844467,0,0,0,40,4374,157.87695,9999.5078125,,,,,,,,,,,,,0,,,,0.0049,,,,,,167.1925507,,,,
,23221248.08,163.286026,9999.5078125,3.83163961438556E-5,5.82998997981657E-7,1,0.999253354069792,40.0298881530762,1.98479827288759,16.21999964118,0.000433963323083991,6.77866947923061E-5,0.25,-6.69505378387944E-7,3.84909211256052E-5,-6.13669378066111E-7,163.286026,163.286026,9999.5078125,9999.5078125,56.6133536478906,20.5646966756638,27.464817,0,0,0,40,4374,154.08875,9999.5078125,,,,,,,,,,,,,0,,,,0.00245,,,,,,163.286026,,,,
,23221281.475,161.2231445,9999.5078125,3.98687221543634E-5,4.74702830933004E-7,1,0.999253354069792,40.0298881530762,1.98498376080716,16.21999964118,0.000450929868831086,7.44468501945122E-5,0.25,-3.52113860868353E-7,4.00519831345475E-5,-2.91307206958959E-7,161.2231445,161.2231445,9999.5078125,9999.5078125,56.472660514429,20.5642738058274,27.844467,0,0,0,40,4374,152.0866,9999.5078125,,,,,,,,,,,,,0,,,,0,,,,,,161.2231445,,,,
,23221314.835,159.0105133,9999.5078125,3.92472564204551E-5,5.18142319999162E-7,1,0.999253354069792,40.0298881530762,1.98484466245855,16.21999964118,0.000442939946046083,7.87797363268088E-5,0.25,1.38695356940657E-7,3.94291865223512E-5,2.01975769334586E-7,159.0105133,159.0105133,9999.5078125,9999.5078125,56.7118388413137,20.5642788128328,27.464817,0,0,0,40,4374,150.09635,9999.5078125,,,,,,,,,,,,,0,,,,0.0049,,,,,,159.0105133,,,,
,23221349.22,156.9578171,9999.5078125,3.9666032486522E-5,5.72284007218949E-7,1,0.999253354069792,40.0298881530762,1.9848771298114,16.21999964118,0.000447988235646883,7.79519527108418E-5,0.25,-9.30752613223894E-9,3.98522269517605E-5,5.52388281867559E-8,156.8659058,157.0497284,9999.5078125,9999.5078125,56.6086638767752,20.5656013156413,27.844467,0,0,0,40,4374,148.05315,9999.5078125,,,,,,,,,,,,,0,,,,-0.00245,,,,,,156.9578171,,,,
touchdown = 11.009999550879 mm,23221412.11,153.0938873,9999.5078125,3.87367163195705E-5,6.04332078195293E-7,1,0.999253354069792,40.0298881530762,2.00877163565506,16.2499994039536,0.00044230935315441,7.84485266897134E-5,0.25,1.14671137640174E-7,3.89220961747306E-5,1.80690981537847E-7,153.0938873,153.0938873,9999.5078125,9999.5078125,56.3194613246598,20.5584433337915,27.844467,0,0,0,40,4374,144.3801,9999.5078125,,,,,,,,,,,,,0,,,,0,,,,,,153.0938873,,,,
,23221445.17,151.0788574,9999.5078125,3.79992371665933E-5,6.13983539398219E-7,1,0.999253354069792,40.0298881530762,2.00853821285484,16.2499994039536,0.000434852817749627,7.12652729118741E-5,0.25,-3.86463519000885E-7,3.81838115183108E-5,-3.22805396540801E-7,151.0788574,151.0788574,9999.5078125,9999.5078125,56.6962062709291,20.5660109282204,27.464817,0,0,0,40,4374,142.4561,9999.5078125,,,,,,,,,,,,,0,,,,0,,,,,,151.0788574,,,,
,23221479.135,148.9529724,9999.5078125,3.75781307556456E-5,4.6457552472773E-7,1,0.999253354069792,40.0298881530762,2.00869240428946,16.2499994039536,0.000428433579378146,7.99681993339788E-5,0.25,4.4660270674517E-7,3.77611405138191E-5,5.14929607783803E-7,148.9529724,148.9529724,9999.5078125,9999.5078125,56.780622151006,20.5625648771726,27.844467,0,0,0,40,4374,140.53845,9999.5078125,,,,,,,,,,,,,0,,,,0,,,,,,148.9529724,,,,
,23221512.5,147.0532227,9999.5078125,3.7498247007535E-5,4.22270292289892E-7,1,0.999253354069792,40.0298881530762,2.00854655956618,16.2499994039536,0.000429465705474612,6.85936799186865E-5,0.25,-5.36271026985271E-7,3.76842670320296E-5,-4.7155059944479E-7,147.0532227,147.0532227,9999.5078125,9999.5078125,56.6954246424098,20.5653677094284,27.464817,0,0,0,40,4374,138.6602,9999.5078125,,,,,,,,,,,,,0,,,,0,,,,,,147.0532227,,,,
,23221546.33,144.999649,9999.5078125,3.81284879846103E-5,4.77920569206059E-7,1,0.999253354069792,40.0298881530762,2.00840967849476,16.2499994039536,0.000436544057320294,7.05025747113591E-5,0.25,-4.80461648008878E-7,3.83193310398113E-5,-4.12883689787598E-7,144.999649,144.999649,9999.5078125,9999.5078125,56.6594697305252,20.5638180065385,27.844467,0,0,0,40,4374,136.74995,9999.5078125,,,,,,,,,,,,,0,,,,0,,,,,,144.999649,,,,
,23221609.285,141.3989716,9999.5078125,3.78830188362486E-5,4.81949286991544E-7,1,0.999253354069792,40.0298881530762,1.98460291722889,16.2899997085333,0.000425409890249773,8.9024532699583E-5,0.25,1.26941164210676E-6,3.80723098790878E-5,1.34821725572148E-6,141.3989716,141.3989716,9999.5078125,9999.5078125,56.7227816405829,20.5629493421922,27.464817,0,0,0,40,4374,133.23795,9999.5078125,,,,,,,,,,,,,0,,,,-0.0049,,,,,,141.3989716,,,,
,23221642.07,139.4118958,9999.5078125,3.9230016375813E-5,9.82760489281595E-7,1,0.999253354069792,40.0298881530762,1.98471489936394,16.2899997085333,0.000435399080830015,0.000121862853945934,0.25,3.93885012460178E-6,3.94225176935393E-5,4.03554319489556E-6,139.4118958,139.4118958,9999.5078125,9999.5078125,56.7774956369291,20.5645024939876,27.464817,0,0,0,40,4374,131.41185,9999.5078125,,,,,,,,,,,,,0,,,,0,,,,,,139.4118958,,,,
,23221675.02,137.5439758,9999.5078125,3.77696378137476E-5,5.09039088539891E-7,1,0.999253354069792,40.0298881530762,1.98469514064427,16.2899997085333,0.000423782702654511,9.10912420864892E-5,0.25,1.46800582827448E-6,3.79608821180123E-5,1.55091848797288E-6,137.5439758,137.5439758,9999.5078125,9999.5078125,56.7759323798906,20.5654020058129,27.844467,0,0,0,40,4374,129.6099,9999.5078125,,,,,,,,,,,,,0,,,,-0.00245,,,,,,137.5439758,,,,
,23221707.51,135.7266083,9999.5078125,3.79496762562011E-5,6.25039020228898E-7,1,0.999253354069792,40.0298881530762,1.98473175236289,16.2899997085333,0.000426978206185428,8.49258225612776E-5,0.25,8.88745901930323E-7,3.81443121695647E-5,9.7074817436041E-7,135.7266083,135.7266083,9999.5078125,9999.5078125,57.0291800201214,20.5676997015457,27.844467,0,0,0,40,4374,127.83555,9999.5078125,,,,,,,,,,,,,0,,,,0.0049,,,,,,135.7266083,,,,
,23221740.705,133.7696533,9999.5078125,3.8331276965352E-5,5.56934124321971E-7,1,0.999253354069792,40.0298881530762,1.98468671536471,16.2899997085333,0.000429674666047803,9.49579720062754E-5,0.25,1.70818786796985E-6,3.85275777189061E-5,1.79707942370089E-6,133.7696533,133.7696533,9999.5078125,9999.5078125,56.9705578811791,20.5657432091866,27.844467,0,0,0,40,4374,126.0253,9999.5078125,,,,,,,,,,,,,0,,,,0,,,,,,133.7696533,,,,
,23221802.145,130.3195953,9999.5078125,3.78060520415933E-5,5.21608626222511E-7,1,0.999253354069792,40.0298881530762,1.98482047466312,16.3199994713068,0.000424012496753377,9.26737691461877E-5,0.25,1.59329779412872E-6,3.80020265507299E-5,1.68407813806579E-6,130.3195953,130.3195953,9999.5078125,9999.5078125,56.8400259184676,20.5665126393892,27.085165,0,0,0,40,4374,122.6987,9999.5078125,,,,,,,,,,,,,0,,,,-0.00245,,,,,,130.3195953,,,,
,23221834.565,128.5226898,9999.5078125,4.11295255582771E-5,5.31369214548303E-7,1,0.999253354069792,40.0298881530762,1.98476712215303,16.3199994713068,0.000456649469509635,0.000127344110744007,0.25,4.07869038049479E-6,4.13386083574367E-5,4.19210998787079E-6,128.5226898,128.5226898,9999.5078125,9999.5078125,56.4398321166213,20.5746219758886,26.705515,0,0,0,40,4374,120.91625,9999.5078125,,,,,,,,,,,,,0,,,,0,,,,,,128.5226898,,,,
,23221866.645,126.5982971,9999.5078125,4.07263697711544E-5,6.91579928027756E-7,1,0.999253354069792,40.0298881530762,1.98479753339624,16.3199994713068,0.000452287225856155,0.000125554859062327,0.25,3.98818344473856E-6,4.09345758526775E-5,4.10253420772288E-6,126.5982971,126.5982971,9999.5078125,9999.5078125,56.5101786833521,20.5771172426903,27.085165,0,0,0,40,4374,119.1803,9999.5078125,,,,,,,,,,,,,0,,,,-0.00245,,,,,,126.5982971,,,,
,23221899.595,124.7909164,9999.5078125,4.14541103631728E-5,6.36884382875086E-7,1,0.999253354069792,40.0298881530762,1.98478623580766,16.3199994713068,0.000461955138798019,0.000118775302857339,0.25,3.25829650062897E-6,4.16687511197383E-5,3.37291411684247E-6,124.7909164,124.7909164,9999.5078125,9999.5078125,56.6594697305252,20.5784710740968,27.085165,0,0,0,40,4374,117.38125,9999.5078125,,,,,,,,,,,,,0,,,,-0.0049,,,,,,124.7909164,,,,
,23221931.92,123.0106049,9999.5078125,4.05721622267804E-5,5.84272427259406E-7,1,0.999253354069792,40.0298881530762,1.9848631821496,16.3199994713068,0.000455127870233504,9.9255396877006E-5,0.25,1.68214863002385E-6,4.07866315897936E-5,1.78870428089641E-6,123.0106049,123.0106049,9999.5078125,9999.5078125,56.5070521692752,20.5778668779863,27.085165,0,0,0,40,4374,115.62585,9999.5078125,,,,,,,,,,,,,0,,,,-0.00245,,,,,,123.0106049,,,,
,23221992.125,119.51474,9999.5078125,4.02845828181306E-5,6.27518512509766E-7,1,0.999253354069792,40.0298881530762,1.98499094216185,16.3700003176928,0.00044765417006506,0.000123071552833043,0.25,3.83441703468713E-6,4.04936447889941E-5,3.95674384181463E-6,119.51474,119.51474,9999.5078125,9999.5078125,56.5805252500829,20.5735917143663,27.085165,0,0,0,40,4374,112.4079,9999.5078125,,,,,,,,,,,,,0,,,,0.0049,,,,,,119.51474,,,,
,23222025.065,117.6864395,9999.5078125,3.99838497269641E-5,6.14702847723967E-7,1,0.999253354069792,40.0298881530762,1.98487857534103,16.3700003176928,0.000442186682386536,0.000134171293666492,0.25,4.86705034279008E-6,4.01890731218631E-5,4.9970737567768E-6,117.6864395,117.6864395,9999.5078125,9999.5078125,56.3765202065637,20.5741255481938,27.464817,0,0,0,40,4374,110.63095,9999.5078125,,,,,,,,,,,,,0,,,,0,,,,,,117.6864395,,,,
,23222055.86,115.966053,9999.5078125,3.94851465448753E-5,6.38680194033114E-7,1,0.999253354069792,40.0298881530762,1.98484281871522,16.3700003176928,0.000437631124473478,0.000126998013057562,0.25,4.31710709129546E-6,3.96894023426983E-5,4.44553063096271E-6,115.9059677,116.0261383,9999.5078125,9999.5078125,56.4906379703714,20.5756450806858,26.705515,0,0,0,40,4374,109.0008,9999.5078125,,,,,,,,,,,,,0,,,,0.0049,,,,,,115.966053,,,,
,23222085.07,114.3483429,9999.5078125,3.95083504653484E-5,5.20418098931804E-7,1,0.999253354069792,40.0298881530762,1.98479432197235,16.3700003176928,0.000436575998576337,0.000134508435699878,0.25,4.97529053139284E-6,3.97111432676996E-5,5.1100227510025E-6,114.3483429,114.3483429,9999.5078125,9999.5078125,56.6203883045637,20.5790340535231,27.085165,0,0,0,40,4374,107.4603,9999.5078125,,,,,,,,,,,,,0,,,,0,,,,,,114.3483429,,,,
,23222113.61,112.7477188,9999.5078125,4.12044033811696E-5,5.34958094347584E-7,1,0.999253354069792,40.0298881530762,1.98487627047718,16.3700003176928,0.000454932659168724,0.000142592486932628,0.25,5.39000941309712E-6,4.14154352703474E-5,5.53440070358346E-6,112.7477188,112.7477188,9999.5078125,9999.5078125,56.6125720193714,20.5784620018088,26.325863,0,0,0,40,4374,105.9762,9999.5078125,,,,,,,,,,,,,0,,,,-0.00245,,,,,,112.7477188,,,,
touchdown = 11.1699998378754 mm,23222172.84,109.4682541,9999.5078125,3.91364412410169E-5,4.75396800455099E-7,1,0.999253354069792,40.0298881530762,2.00877402326814,16.4000000804663,0.00044023471591396,0.000118922630702741,0.25,3.53288679778247E-6,3.93413084609735E-5,3.66709742254615E-6,109.4682541,109.4682541,9999.5078125,9999.5078125,56.3186796961406,20.5699698656514,27.085165,0,0,0,40,4374,102.8945,9999.5078125,,,,,,,,,,,,,0,,,,0.00245,,,,,,109.4682541,,,,
,23222200.395,107.9859619,9999.5078125,4.0223236390132E-5,5.27854405448155E-7,1,0.999253354069792,40.0298881530762,2.00877526004502,16.4000000804663,0.000452630071250705,0.000121244713620554,0.25,3.54236468691484E-6,4.04338648592689E-5,3.68271477263776E-6,107.9859619,107.9859619,9999.5078125,9999.5078125,56.5148684544675,20.5731217042323,26.325863,0,0,0,40,4374,101.4741,9999.5078125,,,,,,,,,,,,,0,,,,-0.0049,,,,,,107.9859619,,,,
,23222226.65,106.51332475,9999.5078125,3.99715256446293E-5,4.54713604624303E-7,1,0.999253354069792,40.0298881530762,2.00857471885997,16.4000000804663,0.000448905112978118,0.000125294414450319,0.25,3.93913651803447E-6,4.01793123211249E-5,4.08377080776075E-6,106.4595871,106.5670624,9999.5078125,9999.5078125,56.4765686570252,20.5740993057723,26.705515,0,0,0,40,4374,100.11995,9999.5078125,,,,,,,,,,,,,0,,,,-0.00245,,,,,,106.51332475,,,,
,23222263.89,104.5450439,9999.5078125,4.0002863098548E-5,4.93461362631169E-7,1,0.999253354069792,40.0298881530762,2.00863380080281,16.4000000804663,0.000449022220588763,0.000126759519192015,0.25,4.0574431432303E-6,4.02097751893247E-5,4.20703519260106E-6,104.5450439,104.5450439,9999.5078125,9999.5078125,56.5797436215637,20.5747669974743,25.946213,0,0,0,40,4374,98.2061,9999.5078125,,,,,,,,,,,,,0,,,,-0.00245,,,,,,104.5450439,,,,
,23222309.385,101.9973907,9999.5078125,4.07523882958295E-5,4.57642208022962E-7,1,0.999253354069792,40.0298881530762,2.00857550665636,16.4000000804663,0.000455971609954965,0.000137301228246812,0.25,4.84294592097774E-6,4.09596594977641E-5,5.00491775201395E-6,101.9973907,101.9973907,9999.5078125,9999.5078125,56.5281561392944,20.5740527326816,26.325863,0,0,0,40,4374,95.81595,9999.5078125,,,,,,,,,,,,,0,,,,-0.00245,,,,,,101.9973907,,,,
,23222384.295,98.02040865,9999.5078125,3.996534582117E-5,5.89005619043495E-7,1,0.999253354069792,40.0298881530762,1.98475974663369,16.4500009268522,0.000443667159890115,0.000124053947584147,0.25,3.93731019140679E-6,4.01684367703448E-5,4.10146109051213E-6,97.9434128,98.0974045,9999.5078125,9999.5078125,56.6328943608714,20.5773742120653,26.325863,0,0,0,40,4374,91.97665,9999.5078125,,,,,,,,,,,,,0,,,,0,,,,,,98.02040865,,,,
,23222427.605,95.7491837,9999.5078125,3.9430648214501E-5,4.85740316923951E-7,1,0.999253354069792,40.0298881530762,1.98468864438788,16.4500009268522,0.000439495037637885,0.000112164114359033,0.25,2.97389518991456E-6,3.96322257595632E-5,3.13683514328531E-6,95.7491837,95.7491837,9999.5078125,9999.5078125,56.2155047316021,20.5788781893981,26.705515,0,0,0,40,4374,89.81255,9999.5078125,,,,,,,,,,,,,0,,,,0,,,,,,95.7491837,,,,
,23222470.47,93.4416504,9999.5078125,4.04536459406529E-5,6.20354306194194E-7,1,0.999253354069792,40.0298881530762,1.98472168756623,16.4500009268522,0.000450908283169608,0.000114890818132054,0.25,3.02874953636646E-6,4.06580145594934E-5,3.20217196949929E-6,93.4416504,93.4416504,9999.5078125,9999.5078125,56.8368994043906,20.5776102494428,25.566563,0,0,0,40,4374,87.68085,9999.5078125,,,,,,,,,,,,,0,,,,0.00245,,,,,,93.4416504,,,,
,23222514.84,90.9711075,9999.5078125,4.03731424381158E-5,6.27744960260481E-7,1,0.999253354069792,40.0298881530762,1.98453846114176,16.4500009268522,0.000448257697431981,0.000124145175049809,0.25,3.85691294763615E-6,4.05706002589517E-5,4.04134702547687E-6,90.9711075,90.9711075,9999.5078125,9999.5078125,56.4992358840829,20.581752432005,25.946213,0,0,0,40,4374,85.4889,9999.5078125,,,,,,,,,,,,,0,,,,-0.00245,,,,,,90.9711075,,,,
,23222587.415,87.0508423,9999.5078125,3.95837306234743E-5,6.55674958881356E-7,1,0.999253354069792,40.0298881530762,2.00846167718843,16.499999910593,0.000443955245990921,0.000126001722557953,0.25,4.02310017352388E-6,3.9769191279544E-5,4.21734013405376E-6,87.0508423,87.0508423,9999.5078125,9999.5078125,56.6438371601406,20.5781267189624,26.325863,0,0,0,40,4374,81.8322,9999.5078125,,,,,,,,,,,,,0,,,,0,,,,,,87.0508423,,,,
,23222625.51,85.0088501,9999.5078125,4.01725137169124E-5,6.30488681975132E-7,1,0.999253354069792,40.0298881530762,2.00848689411004,16.499999910593,0.00045107295115421,0.000124693062149297,0.25,3.79800167306791E-6,4.03572491931032E-5,4.00064026199594E-6,85.0088501,85.0088501,9999.5078125,9999.5078125,56.9056827140829,20.5763564572419,25.566563,0,0,0,40,4374,79.90725,9999.5078125,,,,,,,,,,,,,0,,,,-0.00245,,,,,,85.0088501,,,,
,23222652.58,83.5402756,9999.5078125,4.02961116482346E-5,6.98652590121397E-7,1,0.999253354069792,40.0298881530762,2.00846303825625,16.499999910593,0.000450545627036109,0.000135589111808736,0.25,4.72594837674873E-6,4.04732546782335E-5,4.93894143180719E-6,83.5402756,83.5402756,9999.5078125,9999.5078125,56.4398321166213,20.5765756107978,25.946213,0,0,0,40,4374,78.5303,9999.5078125,,,,,,,,,,,,,0,,,,-0.0049,,,,,,83.5402756,,,,
,23222680.585,82.0800171,9999.5078125,3.9858332743219E-5,6.31897197379016E-7,1,0.999253354069792,40.0298881530762,2.00843998348488,16.499999910593,0.000447378375360119,0.000124054840243836,0.25,3.7888431781523E-6,4.00332349852093E-5,4.00067608358962E-6,82.0800171,82.0800171,9999.5078125,9999.5078125,56.4429586306983,20.5761396089358,25.946213,0,0,0,40,4374,77.0898,9999.5078125,,,,,,,,,,,,,0,,,,0,,,,,,82.0800171,,,,
,23222707.725,80.5597382,9999.5078125,3.94629029923366E-5,5.9880451470586E-7,1,0.999253354069792,40.0298881530762,2.00845179546935,16.499999910593,0.000443351274688232,0.00012022080929957,0.25,3.51855121563943E-6,3.96326042009966E-5,3.73258860541612E-6,80.5597382,80.5597382,9999.5078125,9999.5078125,56.3718304354483,20.5762437732035,25.946213,0,0,0,40,4374,75.7091,9999.5078125,,,,,,,,,,,,,0,,,,0.0049,,,,,,80.5597382,,,,
,23222734.875,79.0674362,9999.5078125,3.94612680125841E-5,5.81034279874032E-7,1,0.999253354069792,40.0298881530762,2.00847137894726,16.499999910593,0.000443144422836454,0.000120954540923272,0.25,3.57823885969459E-6,3.96253846101026E-5,3.79826021436108E-6,79.0674362,79.0674362,9999.5078125,9999.5078125,56.4241995462367,20.5763482557083,25.186911,0,0,0,40,4374,74.2914,9999.5078125,,,,,,,,,,,,,0,,,,0.00245,,,,,,79.0674362,,,,
,23222791.205,75.9766769,9999.5078125,3.93160258483811E-5,5.65292254451875E-7,1,0.999253354069792,40.0298881530762,2.00847726002596,16.550000756979,0.000441298164761169,0.000120886260337229,0.25,3.58807803174951E-6,3.94666047816414E-5,3.819627675831E-6,75.9766769,75.9766769,9999.5078125,9999.5078125,56.7579549239483,20.5774530985482,24.807261,0,0,0,40,4374,71.3325,9999.5078125,,,,,,,,,,,,,0,,,,0.0049,,,,,,75.9766769,,,,
,23222818.555,74.492012,9999.5078125,3.95332938659861E-5,5.7182018245077E-7,1,0.999253354069792,40.0298881530762,2.00843297877018,16.550000756979,0.000443841399700282,0.000120432582617516,0.25,3.50491624922153E-6,3.9677934904556E-5,3.7434836163579E-6,74.492012,74.492012,9999.5078125,9999.5078125,56.4953277414867,20.5782488311547,25.186911,0,0,0,40,4374,69.87795,9999.5078125,,,,,,,,,,,,,0,,,,0,,,,,,74.492012,,,,
,23222845.705,72.9637146,9999.5078125,3.90473110956358E-5,5.87764957455341E-7,1,0.999253354069792,40.0298881530762,2.00832107558484,16.550000756979,0.000438769927082206,0.000116145624564831,0.25,3.21155657527408E-6,3.91837450443965E-5,3.45231227940984E-6,72.9637146,72.9637146,9999.5078125,9999.5078125,56.4820400566598,20.5788988906739,24.807261,0,0,0,40,4374,68.4291,9999.5078125,,,,,,,,,,,,,0,,,,0,,,,,,72.9637146,,,,
,23222873.015,71.3420868,9999.5078125,3.9021205105013E-5,5.21799569674359E-7,1,0.999253354069792,40.0298881530762,2.00831801973197,16.550000756979,0.000438006605874812,0.000118127299882614,0.25,3.38531772182986E-6,3.91478193108641E-5,3.63280724962544E-6,71.3420868,71.3420868,9999.5078125,9999.5078125,56.5195582255829,20.5793730043342,25.186911,0,0,0,40,4374,66.9596,9999.5078125,,,,,,,,,,,,,0,,,,-0.00245,,,,,,71.3420868,,,,
,23222900.155,69.9101715,9999.5078125,3.90835818510458E-5,5.75212042946616E-7,1,0.999253354069792,40.0298881530762,2.00831004789937,16.550000756979,0.00043756398145622,0.000124060207160725,0.25,3.89023535386042E-6,3.91976084586423E-5,4.14603091971399E-6,69.9101715,69.9101715,9999.5078125,9999.5078125,56.5609845371021,20.5790188300271,25.186911,0,0,0,40,4374,65.48175,9999.5078125,,,,,,,,,,,,,0,,,,-0.00245,,,,,,69.9101715,,,,
,23222927.115,68.3149948,9999.5078125,3.81074454165279E-5,5.01913413465569E-7,1,0.999253354069792,40.0298881530762,2.00834549523119,16.550000756979,0.000428182995353347,0.000111719645182649,0.25,2.97805627855467E-6,3.82139220770408E-5,3.23032110752244E-6,68.2536926,68.376297,9999.5078125,9999.5078125,56.1013869677944,20.5770389434091,24.807261,0,0,0,40,4374,64.0526,9999.5078125,,,,,,,,,,,,,0,,,,0,,,,,,68.3149948,,,,
,23222982.91,65.0061951,9999.5078125,3.88413992443667E-5,5.2664127634707E-7,1,0.999253354069792,40.0298881530762,2.00841951773773,16.5999997407198,0.00043815263779033,0.000102795715304263,0.25,2.05504330134168E-6,3.89324503426442E-5,2.32118935624396E-6,65.0061951,65.0061951,9999.5078125,9999.5078125,56.3475999513521,20.5808831491755,24.047956,0,0,0,40,4374,60.994,9999.5078125,,,,,,,,,,,,,0,,,,0.00245,,,,,,65.0061951,,,,
,23223010.495,63.4375267,9999.5078125,3.90216389238381E-5,5.44497760439168E-7,1,0.999253354069792,40.0298881530762,2.00839159353298,16.5999997407198,0.000437968798837119,0.000114693660027523,0.25,3.06464183628919E-6,3.90926181392856E-5,3.34000677926261E-6,63.4375267,63.4375267,9999.5078125,9999.5078125,56.7688977232175,20.5790807870154,24.427608,0,0,0,40,4374,59.4383,9999.5078125,,,,,,,,,,,,,0,,,,0,,,,,,63.4375267,,,,
,23223038.235,61.807312,9999.5078125,3.99750840738227E-5,4.70682914189724E-7,1,0.999253354069792,40.0298881530762,2.00817881796183,16.5999997407198,0.00045021199179267,0.000107660254767023,0.25,2.27394787503154E-6,4.0038566701227E-5,2.55917726169629E-6,61.807312,61.807312,9999.5078125,9999.5078125,56.3327490094867,20.5839087379917,24.427608,0,0,0,40,4374,57.8561,9999.5078125,,,,,,,,,,,,,0,,,,-0.0049,,,,,,61.807312,,,,
,23223065.265,60.1042404,9999.5078125,4.01117050368396E-5,4.54282633626588E-7,1,0.999253354069792,40.0298881530762,2.00817740810225,16.5999997407198,0.000451866409013518,0.000106357087135361,0.25,2.13318210459228E-6,4.01606861309397E-5,2.42349273567894E-6,60.1042404,60.1042404,9999.5078125,9999.5078125,56.5766171074867,20.5830373626082,24.047956,0,0,0,40,4374,56.30405,9999.5078125,,,,,,,,,,,,,0,,,,-0.0049,,,,,,60.1042404,,,,
,23223092.89,58.413002,9999.5078125,4.0459123158279E-5,4.03198313915981E-7,1,0.999253354069792,40.0298881530762,2.00823059582598,16.5999997407198,0.000455651338486551,0.000106918675267844,0.25,2.11912348853121E-6,4.04912044274575E-5,2.41560811084738E-6,58.413002,58.413002,9999.5078125,9999.5078125,56.7376325824483,20.5804511930904,24.047956,0,0,0,40,4374,54.6779,9999.5078125,,,,,,,,,,,,,0,,,,0,,,,,,58.413002,,,,
,23223134.86,55.7612915,9999.5078125,,,2,,,,16.650000192225,,,,,,,55.7612915,55.7612915,9999.5078125,9999.5078125,,,23.668306,,,,-99999999,4374,52.1623,9999.5078125,,,,,,,,,,,,,,,,,,,,,,,55.7612915,,,,
,23223174.95,52.9502335,9999.5078125,3.91384737498145E-5,4.58875387742707E-7,1,0.999253354069792,40.0298881530762,1.9957289196393,16.6400000452995,0.000439041252705588,9.43789476353459E-5,0.25,1.30804858075956E-6,3.9120163837087E-5,1.59895663207197E-6,52.9502335,52.9502335,9999.5078125,9999.5078125,56.6047557341791,20.5797044150379,23.288654,0,0,0,40,4374,49.7392,9999.5078125,,,,,,,,,,,,,0,,,,-0.00245,,,,,,52.9502335,,,,
,23223201.705,51.0462952,9999.5078125,3.8315341524394E-5,4.48840410820428E-7,1,0.999253354069792,40.0298881530762,1.99573952129302,16.6400000452995,0.000429930936243186,9.05465972708825E-5,0.25,1.12074005318038E-6,3.82804223619625E-5,1.40476826414475E-6,51.0462952,51.0462952,9999.5078125,9999.5078125,55.8090579016021,20.576970868553,22.149702,0,0,0,40,4374,48.0992,9999.5078125,,,,,,,,,,,,,0,,,,-0.00245,,,,,,51.0462952,,,,
,23223228.895,49.0952187,9999.5078125,3.77102904486531E-5,3.89888408660039E-7,1,0.999253354069792,40.0298881530762,1.99578272357037,16.6400000452995,0.000424072723902149,8.28250967361045E-5,0.25,5.50100800791868E-7,3.76618436206289E-5,8.28212055864605E-7,49.0952187,49.0952187,9999.5078125,9999.5078125,56.533627538929,20.5774118230386,22.149702,0,0,0,40,4374,46.4153,9999.5078125,,,,,,,,,,,,,0,,,,-0.0049,,,,,,49.0952187,,,,
,23223256.155,47.2174568,9999.5078125,3.73739700757089E-5,4.11504180801844E-7,1,0.999253354069792,40.0298881530762,1.99584745647096,16.6400000452995,0.000420320701185126,8.07936609773575E-5,0.25,4.36678771517695E-7,3.73082174238919E-5,7.09291560720914E-7,47.2174568,47.2174568,9999.5078125,9999.5078125,56.546915223756,20.5746013542952,21.01075,0,0,0,40,4374,44.6433,9999.5078125,,,,,,,,,,,,,0,,,,0,,,,,,47.2174568,,,,
,23223310.67,42.9917259,9999.5078125,3.64484137834085E-5,3.34034449470165E-7,1,0.999253354069792,40.0298881530762,2.00859007264828,16.669999808073,0.000412677714391567,7.54327418511076E-5,0.25,1.0340712496648E-7,3.63507236319856E-5,3.59853075217825E-7,42.9051361,43.0783157,9999.5078125,9999.5078125,56.6313311038329,20.5733791908405,20.251448,0,0,0,40,4374,40.8291,9999.5078125,,,,,,,,,,,,,0,,,,0,,,,,,42.9917259,,,,
,23223336.64,40.8251305,9999.5078125,3.68957309320554E-5,2.81870144401489E-7,1,0.999253354069792,40.0298881530762,2.00842789081141,16.669999808073,0.00041774961621866,7.49858211744574E-5,0.25,-5.9509254376119E-9,3.67800662184766E-5,2.46966547165494E-7,40.8251305,40.8251305,9999.5078125,9999.5078125,56.6665043871983,20.5753174013117,20.631098,0,0,0,40,4374,38.74695,9999.5078125,,,,,,,,,,,,,0,,,,-0.00245,,,,,,40.8251305,,,,
,23223361.48,38.7282295,9999.5078125,3.69851615812162E-5,3.28831188584097E-7,1,0.999253354069792,40.0298881530762,2.00848787797283,16.669999808073,0.000419586253239917,6.96308604097974E-5,0.25,-4.85189220817028E-7,3.68569415994573E-5,-2.37396995218892E-7,38.7282295,38.7282295,9999.5078125,9999.5078125,56.2209761312367,20.5774665179681,20.251448,0,0,0,40,4374,36.6898,9999.5078125,,,,,,,,,,,,,0,,,,0,,,,,,38.7282295,,,,
,23223385.51,36.42328265,9999.5078125,3.69085869553194E-5,3.46315245927517E-7,1,0.999253354069792,40.0298881530762,2.00852973458596,16.669999808073,0.000418199976908616,7.14667886280257E-5,0.25,-2.98731187428951E-7,3.67648857696723E-5,-6.01858785612375E-8,36.3217354,36.5248299,9999.5078125,9999.5078125,56.5797436215637,20.5726159320113,19.871798,0,0,0,40,4374,34.45885,9999.5078125,,,,,,,,,,,,,0,,,,0.0049,,,,,,36.42328265,,,,
touchdown = 11.4799998700619 mm,23223437.335,30.6138,9999.5078125,3.7649826811271E-5,4.28924176814893E-7,1,0.999253354069792,40.0298881530762,1.99607471580602,16.7100001126528,0.000423612283666864,7.3272943726973E-5,0.25,-2.09583706206352E-7,3.74754245066254E-5,1.4372522531729E-8,30.6138,30.6138,9999.5078125,9999.5078125,56.8087607776983,20.5671785137654,18.353191,0,0,0,40,4374,28.7313,9999.5078125,,,,,,,,,,,,,0,,,,-0.00245,,,,,,30.6138,,,,
,23223457.75,27.9462051,9999.5078125,3.84530285969768E-5,3.78941467143163E-7,1,0.999253354069792,40.0298881530762,1.99612046659237,16.7100001126528,0.000432773302954201,7.36651869520621E-5,0.25,-3.10091336369798E-7,3.82673528134919E-5,-8.77404239216055E-8,27.9462051,27.9462051,9999.5078125,9999.5078125,56.3382204091213,20.5700353074679,18.353191,0,0,0,40,4374,26.0515,9999.5078125,,,,,,,,,,,,,0,,,,0,,,,,,27.9462051,,,,
,23223478.8,24.5369473,9999.5078125,3.87699607435328E-5,3.64437629283272E-7,1,0.999253354069792,40.0298881530762,1.99618814198644,16.7100001126528,0.00043620329684279,7.47141630674862E-5,0.25,-2.66620269390474E-7,3.85762920694215E-5,-4.8479121521105E-8,24.5369473,24.5369473,9999.5078125,9999.5078125,56.6539983308906,20.5722410216801,17.593889,0,0,0,40,4374,22.8693,9999.5078125,,,,,,,,,,,,,0,,,,-0.00245,,,,,,24.5369473,,,,
,23223529.625,13.3019428,9999.5078125,3.93700973390886E-5,8.99301065883274E-7,1,0.999253354069792,40.0298881530762,2.00897343202375,16.7399998754263,0.000446151801026785,7.34080764736779E-5,0.25,-5.25249168160708E-7,3.91721545138917E-5,-3.06272978779588E-7,13.3019428,13.3019428,9999.5078125,9999.5078125,56.0818462548136,20.5674162166827,15.695635,0,0,0,40,4374,12.3315,9999.5078125,,,,,,,,,,,,,0,,,,0,,,,,,13.3019428,,,,
,23223554.685,10.5858688,9999.5078125,3.95675607109596E-5,5.46972319197412E-7,1,0.999253354069792,40.0298881530762,2.00912713692074,16.7399998754263,0.000448390751829818,7.39726058224908E-5,0.25,-5.11029911181562E-7,3.9368752078715E-5,-2.91043026624111E-7,10.5858688,10.5858688,9999.5078125,9999.5078125,56.0857543974098,20.5699144988524,14.556682,0,0,0,40,4374,10.125,9999.5078125,,,,,,,,,,,,,0,,,,0,,,,,,10.5858688,,,,
,23223589.07,9.8857985,9999.5078125,3.90439330833293E-5,3.58542130957801E-7,1,0.999253354069792,40.0298881530762,2.00934486173362,16.7399998754263,0.00044272366169085,7.17639502692078E-5,0.25,-6.13694726602204E-7,3.88484007065547E-5,-3.96061957340511E-7,9.8857985,9.8857985,9999.5078125,9999.5078125,56.2874145553713,20.5794899857168,13.797379,0,0,0,40,4373,9.9719,9999.5078125,,,,,,,,,,,,,0,,,,0,,,,,,9.8857985,,,,
,23223627,10.0571861,9999.5078125,3.95113073933532E-5,3.34421756021452E-7,1,0.999253354069792,40.0298881530762,1.99662909732309,16.7399998754263,0.0004448786261551,7.4648551068571E-5,0.25,-4.0179978827487E-7,3.93122194298383E-5,-1.82678697595873E-7,10.0571861,10.0571861,9999.5078125,9999.5078125,56.8494054606983,20.5752014685687,13.417728,0,0,0,40,4373,10.12265,9999.5078125,,,,,,,,,,,,,0,,,,0.00245,,,,,,10.0571861,,,,
,23223664.275,9.9936209,9999.5078125,3.96293203160871E-5,5.21094347016366E-7,1,0.999253354069792,40.0298881530762,1.99655368293543,16.7399998754263,0.000446038223446541,7.57278108840847E-5,0.25,-3.26568764648633E-7,3.94292217311439E-5,-1.07182598926649E-7,9.9936209,9.9936209,9999.5078125,9999.5078125,56.5219031111406,20.573806810148,12.658426,0,0,0,40,4373,10.0148,9999.5078125,,,,,,,,,,,,,0,,,,0.00245,,,,,,9.9936209,,,,
,23223703.97,9.9831486,9999.5078125,3.94553808972653E-5,4.29946216694363E-7,1,0.999253354069792,40.0298881530762,1.99660049587851,16.7399998754263,0.00044509229223128,6.9777194460118E-5,0.25,-8.25173099394075E-7,3.92589084114774E-5,-6.04202407615736E-7,9.9786692,9.987628,9999.5078125,9999.5078125,56.4773502855444,20.576441341664,13.038077,0,0,0,40,4373,10.04215,9999.5078125,,,,,,,,,,,,,0,,,,0.00245,,,,,,9.9831486,,,,
,23223742.505,10.0010014,9999.5078125,3.97868273114517E-5,3.88469032793577E-7,1,0.999253354069792,40.0298881530762,1.99649538833087,16.7399998754263,0.000448854874814488,7.01010454634857E-5,0.25,-8.55131121836886E-7,3.958882975444E-5,-6.32186832942581E-7,10.0010014,10.0010014,9999.5078125,9999.5078125,56.3773018350829,20.5755218768722,13.038077,0,0,0,40,4373,10.0256,9999.5078125,,,,,,,,,,,,,0,,,,0,,,,,,10.0010014,,,,
,23223750.99,9.9804354,9999.5078125,3.9799301356497E-5,4.0411269919756E-7,1,0.999253354069792,40.0298881530762,1.99659205464618,16.7399998754263,0.000447742948259528,7.72695029855607E-5,0.25,-2.19820824273393E-7,3.95977511408571E-5,-4.46176943784155E-11,9.9804354,9.9804354,9999.5078125,9999.5078125,56.4382688595829,20.5795724688516,12.658426,0,0,0,40,4369,10.01425,9999.5078125,,,,,,,,,,,,,0,,,,0,,,,,,9.9804354,,,,