File: data/doubleLayers/dl_2-5/ppms/DD205_5/KoelnPPMS/CooldownTests/DD205_5_ZFC_TEST.DAT
[Header]
; VSM Data File (default extension .dat)
; Copyright (c) 2003-2013, Quantum Design, Inc. All rights reserved.
TITLE,
FILEOPENTIME,23209867.03,09/27/2018,12:09 am
BYAPP,VSM,2.0,2.0
INFO,PPMS VSM Option Release 1.4.10 Build 1,APPNAME
INFO,Quantum Design Linear Motor Servo Controller,MOTOR_MODULE_NAME
INFO,3101-100 M1,MOTOR_HW_VERSION
INFO,MMC1014,MOTOR_SERIAL_NUMBER
INFO,SRV No X-over 01.03.11,MOTOR_SOFTWARE_VERSION
INFO,Quantum Design VSM Detection Module,VSM_MODULE_NAME
INFO,3101-150 F0,VSM_HW_VERSION
INFO,VSM707,VSM_SERIAL_NUMBER
INFO,VSM No X-over 01.02.05 May 20 2008 13:51:47,VSM_SOFTWARE_VERSION
INFO,704,PREAMP_SERIAL_NUMBER
INFO,822,COIL_SERIAL_NUMBER
INFO,0,MOMENT_UNITS
INFO,,SAMPLE_MATERIAL
INFO,,SAMPLE_COMMENT
INFO,,SAMPLE_MASS
INFO,,SAMPLE_VOLUME
INFO,,SAMPLE_MOLECULAR_WEIGHT
INFO,,SAMPLE_SIZE
INFO,,SAMPLE_SHAPE
DATATYPE,COMMENT,1
DATATYPE,TIME,2
STARTUPAXIS,X,2
STARTUPAXIS,Y1,5
[Data]
Comment,Time Stamp (sec),Temperature (K),Magnetic Field (Oe),Moment (emu),M. Std. Err. (emu),Transport Action,Averaging Time (sec),Frequency (Hz),Peak Amplitude (mm),Center Position (mm),Coil Signal' (mV),Coil Signal" (mV),Range (mV),M. Quad. Signal (emu),M. Raw' (emu),M. Raw" (emu),Min. Temperature (K),Max. Temperature (K),Min. Field (Oe),Max. Field (Oe),Mass (grams),Motor Lag (deg),Pressure (Torr),VSM Status (code),Motor Status (code),Measure Status (code),Measure Count,PPMS Status (code),System Temp. (K),System Field (Oe),Sample Position (deg),Bridge 1 Resistance (ohms),Bridge 1 Excitation (에),Bridge 2 Resistance (ohms),Bridge 2 Excitation (에),Bridge 3 Resistance (ohms),Bridge 3 Excitation (에),Bridge 4 Resistance (ohms),Bridge 4 Excitation (에),Signal 1 Vin (V),Signal 2 Vin (V),Digital Inputs (code),Drive 1 Iout (mA),Drive 1 Ipower (W),Drive 2 Iout (mA),Drive 2 Ipower (W),Pressure (),Map 20 (),Map 21 (),Map 22 (),Map 23 (),Map 24 (),Map 25 (),Map 26 (),Map 27 (),Map 28 (),Map 29 ()
,23209908.66,299.9168396,-0.350146800279617,,,2,,,,15.5599998086691,,,,,,,299.9168396,299.9168396,-0.350146800279617,-0.350146800279617,,,30.122374,,,,-99999999,4421,299.9453,-0.350146800279617,,,,,,,,,,,,,,,,,,,,,,,299.9168396,,,,
,23210045.65,299.6021729,-0.357758656144142,1.958894073279E-7,3.36649640018528E-7,1,0.999253354069792,40.0298881530762,1.99690622899658,15.5499996617436,2.00249435281762E-6,1.61037593175889E-6,0.25,1.08476091844706E-7,1.95813911956002E-7,1.08605076281246E-7,299.6021729,299.6021729,-0.380594313144684,-0.3349229991436,55.9700733765636,20.5449942245289,29.363071,0,0,0,40,4422,298.7834,-0.357758656144142,,,,,,,,,,,,,0,,,,0.0049,,,,,,299.6021729,,,,
,23210085.135,299.0738525,-0.327311113476753,4.58825270417331E-7,3.04738664900918E-7,1,0.999253354069792,40.0298881530762,1.99708387004808,15.5499996617436,5.67913025966276E-6,-1.93143822151852E-6,0.25,-2.50292830958647E-7,4.58994612286132E-7,-2.49985338936011E-7,299.0738525,299.0738525,-0.3349229991436,-0.319699227809906,56.4226362891983,20.5451148943005,29.363071,0,0,0,40,4422,297.14565,-0.327311113476753,,,,,,,,,,,,,0,,,,-0.0049,,,,,,299.0738525,,,,
,23210123.685,298.1555786,-0.350146800279617,4.95549473672029E-7,3.52532625852262E-7,1,0.999253354069792,40.0298881530762,1.99720287909287,15.5499996617436,6.63924827944145E-6,-5.00059942453705E-6,0.25,-5.28020016033397E-7,4.95925307590828E-7,-5.27702090395066E-7,298.1555786,298.1555786,-0.350146800279617,-0.350146800279617,56.2921043264867,20.5448013364973,30.122374,0,0,0,40,4422,294.48155,-0.350146800279617,,,,,,,,,,,,,0,,,,-0.0049,,,,,,298.1555786,,,,
,23210162.38,296.6668091,-0.365370556712151,1.30336688016714E-7,3.30398413478256E-7,1,0.999253354069792,40.0298881530762,1.99710761653339,15.5499996617436,1.84191223102266E-6,-1.86731128433971E-6,0.25,-1.87692304852008E-7,1.30477313987196E-7,-1.87619054426517E-7,296.6668091,296.6668091,-0.380594313144684,-0.350146800279617,56.330404123929,20.5451882765106,29.742722,0,0,0,40,4422,291.10465,-0.365370556712151,,,,,,,,,,,,,0,,,,0.00245,,,,,,296.6668091,,,,
,23210199.96,294.77590945,-0.365370556712151,9.33549985428563E-8,2.55113615069206E-7,1,0.999253354069792,40.0298881530762,1.9972479662805,15.5499996617436,1.64058310023278E-6,-3.1905739964145E-6,0.25,-2.98249778434173E-7,9.35776937375953E-8,-2.98230783689282E-7,294.6879883,294.8638306,-0.380594313144684,-0.350146800279617,56.4132567469675,20.5484471343075,29.363071,0,0,0,40,4422,287.6652,-0.365370556712151,,,,,,,,,,,,,0,,,,0,,,,,,294.77590945,,,,
,23210238.125,292.5101929,-0.304475456476212,4.46297496972305E-7,3.20635105275381E-7,1,0.999253354069792,40.0298881530762,1.99724714749916,15.5499996617436,5.34065125422606E-6,-8.10440942924721E-7,0.25,-1.48989948003295E-7,4.46508179823436E-7,-1.48708753851577E-7,292.5101929,292.5101929,-0.319699227809906,-0.289251685142517,56.3616692646983,20.5475465517796,29.742722,0,0,0,40,4422,284.1204,-0.304475456476212,,,,,,,,,,,,,0,,,,-0.0049,,,,,,292.5101929,,,,
,23210274.045,289.9307861,-0.296863570809364,7.41079683105405E-7,3.33813945014796E-7,1,0.999253354069792,40.0298881530762,1.99732003463556,15.5499996617436,8.41827754524415E-6,1.25660407051209E-6,0.25,-1.73705652601097E-8,7.41334881853581E-7,-1.68435202484875E-8,289.9307861,289.9307861,-0.319699227809906,-0.274027913808823,56.5133051974291,20.5490617813322,29.742722,0,0,0,40,4422,280.76805,-0.296863570809364,,,,,,,,,,,,,0,,,,-0.0049,,,,,,289.9307861,,,,
,23210340.72,285.0983887,-0.243580371141434,5.48608294829205E-7,3.19010765072184E-7,1,0.999253354069792,40.0298881530762,1.9973744083439,15.5800003558397,6.02888994143683E-6,2.10878307070676E-6,0.25,9.12645735435795E-8,5.48815190229255E-7,9.17153579928399E-8,285.0983887,285.0983887,-0.258804142475128,-0.228356599807739,56.3452550657944,20.5461106605585,29.742722,0,0,0,40,4422,274.5435,-0.243580371141434,,,,,,,,,,,,,0,,,,0,,,,,,285.0983887,,,,
,23210376.82,282.1454468,-0.258804142475128,5.66363881172189E-7,3.17860872938186E-7,1,0.999253354069792,40.0298881530762,1.99741690668201,15.5800003558397,7.09778473991715E-6,-2.85879924225249E-6,0.25,-3.50786436021082E-7,5.66969747684952E-7,-3.50574345710588E-7,282.1454468,282.1454468,-0.274027913808823,-0.243580371141434,56.4327974599483,20.550775476813,30.122374,0,0,0,40,4422,271.19025,-0.258804142475128,,,,,,,,,,,,,0,,,,0,,,,,,282.1454468,,,,
,23210414.265,279.0956726,-0.251192256808281,3.29129561323731E-7,3.39262037129362E-7,1,0.999253354069792,40.0298881530762,1.99737511309959,15.5800003558397,4.2720027311055E-6,-2.5087924027972E-6,0.25,-2.78719763980753E-7,3.29576885909675E-7,-2.78668372132486E-7,279.0956726,279.0956726,-0.274027913808823,-0.228356599807739,56.5195582255829,20.5505292239466,29.742722,0,0,0,40,4422,267.72485,-0.251192256808281,,,,,,,,,,,,,0,,,,-0.00245,,,,,,279.0956726,,,,
,23210480.795,273.6085358,-0.205520942807198,2.94953243178843E-7,3.22125220043069E-7,1,0.999253354069792,40.0298881530762,1.99744692185059,15.599999576807,3.37814907998783E-6,3.53535192014058E-7,0.25,-1.99103321152352E-8,2.95237367321546E-7,-1.96977195436735E-8,273.4905396,273.726532,-0.213132828474045,-0.19790905714035,56.445303516256,20.5481429253908,29.742722,0,0,0,40,4422,261.712,-0.205520942807198,,,,,,,,,,,,,0,,,,0.0049,,,,,,273.6085358,,,,
,23210516.045,270.6208191,-0.235968485474586,2.48962615936646E-7,3.36675890419649E-7,1,0.999253354069792,40.0298881530762,1.99736233544601,15.599999576807,2.58847762778138E-6,1.81592555221241E-6,0.25,1.17229141168719E-7,2.49122780918976E-7,1.1754599972301E-7,270.6208191,270.6208191,-0.243580371141434,-0.228356599807739,56.6594697305252,20.5481485942526,29.742722,0,0,0,40,4422,258.5569,-0.235968485474586,,,,,,,,,,,,,0,,,,-0.00245,,,,,,270.6208191,,,,
,23210551.545,267.6543884,-0.228356599807739,4.24683604518868E-7,3.47296022156504E-7,1,0.999253354069792,40.0298881530762,1.99740125126496,15.599999576807,7.15226308491272E-6,-1.26816759372238E-5,0.25,-1.19365650419133E-6,4.26121918899529E-7,-1.19465472544619E-6,267.6543884,267.6543884,-0.243580371141434,-0.213132828474045,56.790783321756,20.5491196979223,29.363071,0,0,0,40,4422,255.4348,-0.228356599807739,,,,,,,,,,,,,0,,,,0.00245,,,,,,267.6543884,,,,
,23210617.995,261.8661499,-0.19790904968977,1.22598103448239E-7,2.87455859604917E-7,1,0.999253354069792,40.0298881530762,1.99729783984041,15.6299993395805,1.40601824719045E-6,1.38982401459316E-7,0.25,-8.98927671107427E-9,1.22768461269578E-7,-8.89971860109824E-9,261.8661499,261.8661499,-0.213132828474045,-0.182685270905495,56.5000175126021,20.549945049646,29.363071,0,0,0,40,4422,249.66085,-0.19790904968977,,,,,,,,,,,,,0,,,,0,,,,,,261.8661499,,,,
,23210652.75,259.0841064,-0.220744714140892,2.26212183938002E-7,2.87592866456203E-7,1,0.999253354069792,40.0298881530762,1.9973393337212,15.6299993395805,4.3839103613926E-6,-1.00599363602482E-5,0.25,-9.27464077953539E-7,2.2731400435549E-7,-9.2859809182437E-7,259.0841064,259.0841064,-0.228356599807739,-0.213132828474045,56.8439340610637,20.5500904631465,29.742722,0,0,0,40,4422,246.7229,-0.220744714140892,,,,,,,,,,,,,0,,,,0,,,,,,259.0841064,,,,
,23210688.765,255.9662781,-0.205520942807198,6.74388777250012E-7,2.70448908541373E-7,1,0.999253354069792,40.0298881530762,1.99730782243921,15.6299993395805,9.31925593567191E-6,-8.3637226299769E-6,0.25,-8.55370818074429E-7,6.76155087065995E-7,-8.56111561706866E-7,255.9662781,255.9662781,-0.213132828474045,-0.19790905714035,56.567237565256,20.5500367363213,29.742722,0,0,0,40,4422,243.7003,-0.205520942807198,,,,,,,,,,,,,0,,,,0,,,,,,255.9662781,,,,
,23210754.78,250.5161133,-0.175073385238647,2.38647969399922E-7,3.4582200541374E-7,1,0.999253354069792,40.0298881530762,1.99733506363716,15.6399998813868,3.4069354077464E-6,-3.58484550492274E-6,0.25,-3.57826434050462E-7,2.39374310035948E-7,-3.58236589797157E-7,250.5161133,250.5161133,-0.182685270905495,-0.1674614995718,56.6430555316214,20.5448629170878,29.742722,0,0,0,40,4422,238.27195,-0.175073385238647,,,,,,,,,,,,,0,,,,0,,,,,,250.5161133,,,,
,23210787.83,247.7265015,-0.220744714140892,-3.371118798382E-9,2.49289723968249E-7,1,0.999253354069792,40.0298881530762,1.99733599969599,15.6399998813868,4.99533265056089E-7,-3.10611517522039E-6,0.25,-2.73558707958297E-7,-3.13439409379743E-9,-2.74061895678145E-7,247.7265015,247.7265015,-0.228356599807739,-0.213132828474045,56.7954730928714,20.5482765668397,29.363071,0,0,0,40,4422,235.58755,-0.220744714140892,,,,,,,,,,,,,0,,,,-0.00245,,,,,,247.7265015,,,,
,23210822.955,244.8568115,-0.251192256808281,1.93100998259868E-7,3.44145656425939E-7,1,0.999253354069792,40.0298881530762,1.99725559231929,15.6399998813868,2.56463847628621E-6,-1.79108943767142E-6,0.25,-1.91574398205887E-7,1.93646067070081E-7,-1.91770022117958E-7,244.8568115,244.8568115,-0.289251685142517,-0.213132828474045,56.5766171074867,20.5498588656085,30.122374,0,0,0,40,4422,232.79805,-0.251192256808281,,,,,,,,,,,,,0,,,,0.0049,,,,,,244.8568115,,,,
,23210888.235,239.5904541,-0.1674614995718,6.5232290886861E-7,2.69778914258042E-7,1,0.999253354069792,40.0298881530762,1.99729249747686,15.6699996441603,8.20591842729383E-6,-3.40248706226365E-6,0.25,-4.13420330266847E-7,6.54083723574859E-7,-4.13690111487667E-7,239.4922485,239.6886597,-0.1674614995718,-0.1674614995718,56.5258112537367,20.5516989219341,29.363071,0,0,0,40,4422,227.66065,-0.1674614995718,,,,,,,,,,,,,0,,,,0.00245,,,,,,239.5904541,,,,
,23210923.94,236.6810455,-0.137013956904411,1.21234306407922E-6,2.55046393126941E-7,1,0.999253354069792,40.0298881530762,1.99727991905671,15.6699996441603,1.51460336648082E-5,-5.71190690615273E-6,0.25,-7.14345485281349E-7,1.21569787325061E-6,-7.1478818322288E-7,236.6810455,236.6810455,-0.137013956904411,-0.137013956904411,56.8603482599676,20.5496648192481,29.742722,0,0,0,40,4422,224.9014,-0.137013956904411,,,,,,,,,,,,,0,,,,0.00245,,,,,,236.6810455,,,,
,23210958.99,233.9488525,-0.0837307535111904,1.73825597421901E-7,2.6500985690686E-7,1,0.999253354069792,40.0298881530762,1.99728932197695,15.6699996441603,2.94052226661257E-6,-5.24791004448662E-6,0.25,-4.93139197413312E-7,1.74696814829121E-7,-4.94111776182793E-7,233.9488525,233.9488525,-0.0913426354527473,-0.0761188715696335,56.7556100383906,20.5522352487673,29.363071,0,0,0,40,4422,222.2204,-0.0837307535111904,,,,,,,,,,,,,0,,,,0,,,,,,233.9488525,,,,
,23211023.405,229.0202637,-0.121790185570717,1.38298442182381E-7,2.52591253852814E-7,1,0.999253354069792,40.0298881530762,1.99739796346992,15.6999994069338,1.99863570178219E-6,-2.20872945045259E-6,0.25,-2.18818263390326E-7,1.38855349494215E-7,-2.19224919970053E-7,229.0202637,229.0202637,-0.137013956904411,-0.106566414237022,56.6039741056598,20.5517515812013,29.363071,0,0,0,40,4422,217.3387,-0.121790185570717,,,,,,,,,,,,,0,,,,-0.00245,,,,,,229.0202637,,,,
,23211059.555,226.2997437,-0.0608950909227133,5.45838044449162E-7,3.5304800411269E-7,1,0.999253354069792,40.0298881530762,1.99745617824894,15.6999994069338,6.98800773627954E-6,-3.52642274646112E-6,0.25,-4.05753864889754E-7,5.47644475569371E-7,-4.06253819249036E-7,226.2997437,226.2997437,-0.0913426354527473,-0.0304475463926792,56.8830154870253,20.5500299787043,29.363071,0,0,0,40,4422,214.6157,-0.0608950909227133,,,,,,,,,,,,,0,,,,0,,,,,,226.2997437,,,,
,23211094.095,223.4492493,-0.0532832089811564,3.28665143332457E-7,2.07432521206331E-7,1,0.999253354069792,40.0298881530762,1.99743978382671,15.6999994069338,3.67582774904897E-6,9.42295366225419E-7,0.25,2.60335573668063E-8,3.29515411281006E-7,2.64348270715002E-8,223.4492493,223.4492493,-0.0761188715696335,-0.0304475463926792,56.7016776705637,20.5501295838424,28.983419,0,0,0,40,4422,212.01475,-0.0532832089811564,,,,,,,,,,,,,0,,,,0,,,,,,223.4492493,,,,
touchdown = 10.4900002479553 mm,23211159.325,218.594101,-0.0456713177263737,2.14150976873502E-7,3.24344159352845E-7,1,0.999253354069792,40.0298881530762,1.99735210946442,15.7299991697073,4.06033525149533E-6,-8.97429403541595E-6,0.25,-8.28474182335496E-7,2.1561830842416E-7,-8.30596442225139E-7,218.594101,218.594101,-0.0456713177263737,-0.0456713177263737,56.6821369575829,20.5444331585328,28.983419,0,0,0,40,4422,207.086,-0.0456713177263737,,,,,,,,,,,,,0,,,,-0.00245,,,,,,218.594101,,,,
,23211194.705,215.8065186,-0.0456713177263737,6.48020090156812E-8,3.06225487325209E-7,1,0.999253354069792,40.0298881530762,1.9972805544176,15.7299991697073,2.25291316901034E-6,-8.61308986556898E-6,0.25,-7.7065091795483E-7,6.58054954524847E-8,-7.72835480886174E-7,215.8065186,215.8065186,-0.0456713177263737,-0.0456713177263737,56.607882248256,20.5479597527787,29.363071,0,0,0,40,4406,204.4435,-0.0456713177263737,,,,,,,,,,,,,0,,,,-0.0049,,,,,,215.8065186,,,,
,23211228.585,213.2335968,-0.0456713177263737,6.01008811363727E-7,3.29782778024926E-7,1,0.999253354069792,40.0298881530762,1.99718132228263,15.7299991697073,8.05565364524826E-6,-5.94859647440367E-6,0.25,-6.28838798603706E-7,6.03491892828969E-7,-6.30086057509251E-7,213.2335968,213.2335968,-0.0456713177263737,-0.0456713177263737,56.3952792910252,20.5471367947355,29.363071,0,0,0,40,4374,201.90735,-0.0456713177263737,,,,,,,,,,,,,0,,,,0,,,,,,213.2335968,,,,
,23211262.445,210.6855469,-0.0456713177263737,1.29643654566681E-7,3.04415969022021E-7,1,0.999253354069792,40.0298881530762,1.99727660495225,15.7299991697073,1.46716549429376E-6,2.75544954864928E-7,0.25,1.77171560570512E-9,1.30042701935683E-7,1.91849134192297E-9,210.6855469,210.6855469,-0.0456713177263737,-0.0456713177263737,56.6524350738522,20.5497716758415,29.363071,0,0,0,40,4374,199.4115,-0.0456713177263737,,,,,,,,,,,,,0,,,,-0.00245,,,,,,210.6855469,,,,
,23211325.74,205.96984865,-0.0456713177263737,4.61407627599432E-7,2.53038249001327E-7,1,0.999253354069792,40.0298881530762,1.99736256720437,15.760000795126,5.67230316977566E-6,-1.60695618267885E-6,0.25,-2.21792109251351E-7,4.6315477681663E-7,-2.21994373607049E-7,205.8811188,206.0585785,-0.0456713177263737,-0.0456713177263737,56.6797920720252,20.5465392526936,29.742722,0,0,0,40,4374,194.8369,-0.0456713177263737,,,,,,,,,,,,,0,,,,0,,,,,,205.96984865,,,,
,23211359.195,203.4787445,-0.0456713177263737,2.93815477363234E-7,2.4688141825099E-7,1,0.999253354069792,40.0298881530762,1.99721771899281,15.760000795126,3.10341505850168E-6,1.90433980627955E-6,0.25,1.16791666345886E-7,2.94660028750807E-7,1.17515318615503E-7,203.4787445,203.4787445,-0.0456713177263737,-0.0456713177263737,56.729816297256,20.5481296103492,29.363071,0,0,0,40,4374,192.45735,-0.0456713177263737,,,,,,,,,,,,,0,,,,0,,,,,,203.4787445,,,,
,23211392.35,201.092865,-0.0456713177263737,7.58084681499808E-7,3.13427983861538E-7,1,0.999253354069792,40.0298881530762,1.99714640151005,15.760000795126,9.13344446715137E-6,-1.56590590973166E-6,0.25,-2.69736678174362E-7,7.60977817321004E-7,-2.69776914325155E-7,201.092865,201.092865,-0.0456713177263737,-0.0456713177263737,56.6797920720252,20.546763580144,29.742722,0,0,0,40,4374,190.12525,-0.0456713177263737,,,,,,,,,,,,,0,,,,0,,,,,,201.092865,,,,
,23211426.495,198.6060791,-0.0456713177263737,3.31661235394846E-7,2.70892264129575E-7,1,0.999253354069792,40.0298881530762,1.99708679865797,15.760000795126,4.59258160268924E-6,-4.11740805504113E-6,0.25,-4.20499171277913E-7,3.33311655173509E-7,-4.21573542179749E-7,198.6060791,198.6060791,-0.0456713177263737,-0.0456713177263737,56.5625477941406,20.5492563071004,28.983419,0,0,0,40,4374,187.73535,-0.0456713177263737,,,,,,,,,,,,,0,,,,-0.0049,,,,,,198.6060791,,,,
,23211489.655,194.03946685,-0.0456713177263737,2.11372895496732E-7,2.97452580739275E-7,1,0.999253354069792,40.0298881530762,1.99731414723728,15.7999992370605,2.75675615131585E-6,-1.64087438787383E-6,0.25,-1.81313771467794E-7,2.12359755944949E-7,-1.8171491457266E-7,193.9397888,194.1391449,-0.0456713177263737,-0.0456713177263737,56.4679707433137,20.5489424880088,28.983419,0,0,0,40,4374,183.38215,-0.0456713177263737,,,,,,,,,,,,,0,,,,0,,,,,,194.03946685,,,,
,23211523.21,191.6959839,-0.0456713177263737,4.92854703558744E-7,2.65674836546259E-7,1,0.999253354069792,40.0298881530762,1.99725083456721,15.7999992370605,6.22361503286545E-6,-2.64900936492539E-6,0.25,-3.19066461528161E-7,4.95072277247268E-7,-3.19638887997202E-7,191.6959839,191.6959839,-0.0456713177263737,-0.0456713177263737,56.7579549239483,20.5498552485606,29.742722,0,0,0,40,4374,181.08685,-0.0456713177263737,,,,,,,,,,,,,0,,,,-0.00245,,,,,,191.6959839,,,,
,23211557.35,189.2495422,-0.0456713177263737,2.22470101003372E-7,2.73003433686643E-7,1,0.999253354069792,40.0298881530762,1.99724642342824,15.7999992370605,2.83460447365074E-6,-1.34008072355406E-6,0.25,-1.56737289907801E-7,2.2350689578708E-7,-1.57049894706298E-7,189.2495422,189.2495422,-0.0456713177263737,-0.0456713177263737,56.7063674416791,20.5531805755235,28.983419,0,0,0,40,4374,178.7927,-0.0456713177263737,,,,,,,,,,,,,0,,,,-0.00245,,,,,,189.2495422,,,,
touchdown = 10.5999996885657 mm,23211620.5,184.8425446,-0.0456713177263737,4.06284903642672E-7,2.38690217246782E-7,1,0.999253354069792,40.0298881530762,1.99744236823623,15.8399995416403,5.07440092708361E-6,-1.85218534394707E-6,0.25,-2.3379225673434E-7,4.08176564164612E-7,-2.34179907263141E-7,184.8425446,184.8425446,-0.0456713177263737,-0.0456713177263737,56.5562947659868,20.5492947359221,28.983419,0,0,0,40,4374,174.57025,-0.0456713177263737,,,,,,,,,,,,,0,,,,0.0049,,,,,,184.8425446,,,,
,23211654.31,182.4790955,-0.0456713177263737,-1.54482910713048E-7,3.06352618749653E-7,1,0.999253354069792,40.0298881530762,1.99742124883691,15.8399995416403,-6.99276038587497E-7,-6.36935334643994E-6,0.25,-5.34098657831384E-7,-1.54393620017322E-7,-5.36428750634467E-7,182.4790955,182.4790955,-0.0456713177263737,-0.0456713177263737,56.4054404617752,20.5522278961806,28.983419,0,0,0,40,4374,172.3369,-0.0456713177263737,,,,,,,,,,,,,0,,,,-0.00245,,,,,,182.4790955,,,,
,23211687.87,180.2422333,-0.0456713177263737,1.93607006848077E-7,2.89779093391246E-7,1,0.999253354069792,40.0298881530762,1.99715272805674,15.8399995416403,2.17239908960735E-6,5.30180593013931E-7,0.25,1.30190600373807E-8,1.94373172785656E-7,1.33315749452433E-8,180.2422333,180.2422333,-0.0456713177263737,-0.0456713177263737,56.3561978650637,20.5522361890162,28.983419,0,0,0,40,4374,170.13455,-0.0456713177263737,,,,,,,,,,,,,0,,,,-0.00245,,,,,,180.2422333,,,,
,23211722.665,177.9971924,-0.0456713177263737,5.46547327419039E-7,1.94493503616118E-7,1,0.999253354069792,40.0298881530762,1.9973692381613,15.8399995416403,6.71626380012293E-6,-1.85182925858681E-6,0.25,-2.58167589926193E-7,5.49148288468201E-7,-2.58482590686842E-7,177.9971924,177.9971924,-0.0456713177263737,-0.0456713177263737,56.5453519667175,20.5508297827418,29.363071,0,0,0,40,4374,167.8903,-0.0456713177263737,,,,,,,,,,,,,0,,,,0,,,,,,177.9971924,,,,
,23211785.67,173.7120056,-0.0456713177263737,1.11601575951021E-7,1.92130280657886E-7,1,0.999253354069792,40.0298881530762,1.99747101281922,15.87999984622,1.79094212601061E-6,-2.78735843093836E-6,0.25,-2.64848083222546E-7,1.12448818345669E-7,-2.6581259604774E-7,173.7120056,173.7120056,-0.0456713177263737,-0.0456713177263737,56.7618630665445,20.5492167912588,28.983419,0,0,0,40,4374,163.8588,-0.0456713177263737,,,,,,,,,,,,,0,,,,-0.0049,,,,,,173.7120056,,,,
,23211819.94,171.4361115,-0.0456713177263737,4.3487093084962E-7,2.15673807171258E-7,1,0.999253354069792,40.0298881530762,1.99733075127357,15.87999984622,5.48166064171246E-6,-2.25882195807945E-6,0.25,-2.74581200869786E-7,4.37137143123425E-7,-2.75136240719312E-7,171.4361115,171.4361115,-0.0456713177263737,-0.0456713177263737,56.4836033136983,20.5534276450182,29.363071,0,0,0,40,4374,161.6955,-0.0456713177263737,,,,,,,,,,,,,0,,,,0.00245,,,,,,171.4361115,,,,
,23211854.26,169.1656342,-0.0456713177263737,1.65893013045661E-7,2.16551203386776E-7,1,0.999253354069792,40.0298881530762,1.99719166647637,15.87999984622,3.18016579441208E-6,-7.11744970759681E-6,0.25,-6.55578593485578E-7,1.67579282790497E-7,-6.58197197757353E-7,169.1656342,169.1656342,-0.0456713177263737,-0.0456713177263737,56.4773502855444,20.5536764298191,28.983419,0,0,0,40,4374,159.54485,-0.0456713177263737,,,,,,,,,,,,,0,,,,0.00245,,,,,,169.1656342,,,,
,23211888.095,166.9669647,-0.0456713177263737,5.74587553912642E-7,2.38490077963996E-7,1,0.999253354069792,40.0298881530762,1.99723194395791,15.87999984622,6.72285225823328E-6,6.2174837128692E-9,0.25,-9.94940526725943E-8,5.77279720416917E-7,-9.90753601598178E-8,166.9669647,166.9669647,-0.0456713177263737,-0.0456713177263737,56.861911517006,20.5517512242934,28.983419,0,0,0,40,4374,157.4601,-0.0456713177263737,,,,,,,,,,,,,0,,,,0,,,,,,166.9669647,,,,
touchdown = 10.6899999082088 mm,23211952.41,162.8623505,-0.0456713177263737,6.73967763285798E-8,3.00515356548673E-7,1,0.999253354069792,40.0298881530762,1.99735312926805,15.9200001507998,1.76837545220721E-6,-5.62418192007337E-6,0.25,-5.06838078240281E-7,6.84884429974309E-8,-5.09033390307832E-7,162.8623505,162.8623505,-0.0456713177263737,-0.0456713177263737,56.6563432164483,20.5511071044182,28.983419,0,0,0,40,4374,153.53065,-0.0456713177263737,,,,,,,,,,,,,0,,,,-0.0049,,,,,,162.8623505,,,,
,23211987.13,160.5543365,-0.0456713177263737,2.22571856848872E-7,2.9799612600515E-7,1,0.999253354069792,40.0298881530762,1.9972304607857,15.9200001507998,3.4184917564453E-6,-4.66954501041071E-6,0.25,-4.49835458237325E-7,2.24306976581591E-7,-4.51552198232614E-7,160.5543365,160.5543365,-0.0456713177263737,-0.0456713177263737,56.6938613853714,20.5539074263453,29.363071,0,0,0,40,4374,151.4402,-0.0456713177263737,,,,,,,,,,,,,0,,,,0,,,,,,160.5543365,,,,
,23212022.7,158.3655243,-0.0456713177263737,1.48324096367639E-7,3.39882651515515E-7,1,0.999253354069792,40.0298881530762,1.99717070144137,15.9200001507998,2.52549710471434E-6,-4.53072960630132E-6,0.25,-4.24677581235952E-7,1.49700284399911E-7,-4.26415362580424E-7,158.3655243,158.3655243,-0.0456713177263737,-0.0456713177263737,56.7665528376599,20.5553647557662,28.224119,0,0,0,40,4374,149.34065,-0.0456713177263737,,,,,,,,,,,,,0,,,,-0.0049,,,,,,158.3655243,,,,
,23212057.22,156.2651062,-0.0456713177263737,3.6348224854756E-7,2.94311914752877E-7,1,0.999253354069792,40.0298881530762,1.99708762894157,15.9200001507998,6.37973805467825E-6,-1.21950611828399E-5,0.25,-1.13685075211249E-6,3.67066831453298E-7,-1.14160588589469E-6,156.2651062,156.2651062,-0.0456713177263737,-0.0456713177263737,56.577398736006,20.556820980603,28.603769,0,0,0,40,4374,147.3145,-0.0456713177263737,,,,,,,,,,,,,0,,,,-0.00245,,,,,,156.2651062,,,,
,23212091.5,154.1144867,-0.0456713177263737,1.76732873026031E-7,2.97333647835294E-7,1,0.999253354069792,40.0298881530762,1.99710423210786,15.9200001507998,2.3179348289457E-6,-1.42935733723294E-6,0.25,-1.56621220853405E-7,1.77838077377112E-7,-1.5707013526673E-7,154.1144867,154.1144867,-0.0456713177263737,-0.0456713177263737,56.7798405224868,20.5559483503337,28.983419,0,0,0,40,4374,145.30735,-0.0456713177263737,,,,,,,,,,,,,0,,,,0,,,,,,154.1144867,,,,
,23212155.38,150.1881485,-0.0456713177263737,1.41439291113942E-7,3.41125843459112E-7,1,0.999253354069792,40.0298881530762,1.99675923880468,15.9699991345406,1.91982821538907E-6,-1.51556127585098E-6,0.25,-1.58077887070574E-7,1.42402878150365E-7,-1.58598830001164E-7,150.1086731,150.2676239,-0.0456713177263737,-0.0456713177263737,56.5172133400252,20.5573535807563,28.224119,0,0,0,40,4374,141.61695,-0.0456713177263737,,,,,,,,,,,,,0,,,,0.0049,,,,,,150.1881485,,,,
,23212190.515,148.1544647,-0.0456713177263737,8.47783073828477E-8,3.01142783546431E-7,1,0.999253354069792,40.0298881530762,1.99679676379171,15.9699991345406,1.57872678865904E-6,-3.36175738201065E-6,0.25,-3.10705140269627E-7,8.57492562784961E-8,-3.12078348467428E-7,148.1544647,148.1544647,-0.0456713177263737,-0.0456713177263737,56.729816297256,20.5547012520446,28.983419,0,0,0,40,4374,139.6177,-0.0456713177263737,,,,,,,,,,,,,0,,,,0,,,,,,148.1544647,,,,
,23212225.515,145.9383392,-0.0456713177263737,3.33447855200103E-7,2.99441144741558E-7,1,0.999253354069792,40.0298881530762,1.99684483633335,15.9699991345406,4.65508101733545E-6,-4.30751876375958E-6,0.25,-4.37313739686325E-7,3.35899758231536E-7,-4.38873383690562E-7,145.9383392,145.9383392,-0.0456713177263737,-0.0456713177263737,56.892395029256,20.5566845596158,28.224119,0,0,0,40,4374,137.6305,-0.0456713177263737,,,,,,,,,,,,,0,,,,0,,,,,,145.9383392,,,,
,23212259.575,144.0363464,-0.0456713177263737,5.8785493630339E-7,3.16737999358687E-7,1,0.999253354069792,40.0298881530762,1.99690324238787,15.9699991345406,6.79514023196249E-6,5.00596051594322E-7,0.25,-5.8515383420933E-8,5.90903751228403E-7,-5.77108200267488E-8,144.0363464,144.0363464,-0.0456713177263737,-0.0456713177263737,56.7970363499099,20.5582406098084,28.603769,0,0,0,40,4374,135.69085,-0.0456713177263737,,,,,,,,,,,,,0,,,,-0.00245,,,,,,144.0363464,,,,
,23212323.6,140.2542725,-0.0456713177263737,3.02519288096819E-7,2.49083914687945E-7,1,0.999253354069792,40.0298881530762,1.99711438254756,16.0199999809265,3.42617188992902E-6,6.66534821882211E-7,0.25,5.8429760446344E-9,3.04045314819308E-7,6.46153890790441E-9,140.2542725,140.2542725,-0.0456713177263737,-0.0456713177263737,57.0909286731407,20.5565495775765,28.603769,0,0,0,40,4374,132.09545,-0.0456713177263737,,,,,,,,,,,,,0,,,,0.0049,,,,,,140.2542725,,,,
,23212359.14,138.12701415,-0.0456713177263737,2.13159811012098E-7,2.76645202481746E-7,1,0.999253354069792,40.0298881530762,1.99670529251368,16.0199999809265,3.15307410564587E-6,-3.76422679682447E-6,0.25,-3.68522736246657E-7,2.1498725489935E-7,-3.69986724566407E-7,138.0528564,138.2011719,-0.0456713177263737,-0.0456713177263737,56.7712426087752,20.5658201587598,28.224119,0,0,0,40,4374,130.1048,-0.0456713177263737,,,,,,,,,,,,,0,,,,0.00245,,,,,,138.12701415,,,,
,23212393.87,136.0711975,-0.0456713177263737,2.26587276735555E-7,3.12729242451745E-7,1,0.999253354069792,40.0298881530762,1.99652161640621,16.0199999809265,2.65652728194835E-6,-2.09067758842133E-8,0.25,-4.14180100733962E-8,2.2784258635762E-7,-4.1169361116196E-8,136.0711975,136.0711975,-0.0456713177263737,-0.0456713177263737,56.3585427506213,20.5645970261538,27.844467,0,0,0,40,4374,128.1846,-0.0456713177263737,,,,,,,,,,,,,0,,,,0.00245,,,,,,136.0711975,,,,
,23212428.78,134.0562744,-0.0456713177263737,2.85165626532428E-7,3.04454407922913E-7,1,0.999253354069792,40.0298881530762,1.99651607121356,16.0199999809265,3.6168499742782E-6,-1.59107785739248E-6,0.25,-1.89863599051312E-7,2.87047092680184E-7,-1.90255461231989E-7,134.0562744,134.0562744,-0.0456713177263737,-0.0456713177263737,56.6649411301598,20.565994059751,28.603769,0,0,0,40,4374,126.2824,-0.0456713177263737,,,,,,,,,,,,,0,,,,-0.0049,,,,,,134.0562744,,,,
,23212463.075,132.06987,-0.0456713177263737,2.09040419792561E-7,2.75788853320907E-7,1,0.999253354069792,40.0298881530762,1.99651965787887,16.0199999809265,3.18741892937207E-6,-4.2326782415021E-6,0.25,-4.0906495342024E-7,2.11012822007118E-7,-4.1076099392112E-7,132.06987,132.06987,-0.0456713177263737,-0.0456713177263737,56.7649895806214,20.5661417907198,28.224119,0,0,0,40,4374,124.3922,-0.0456713177263737,,,,,,,,,,,,,0,,,,-0.00245,,,,,,132.06987,,,,
,23212527.405,128.4355164,-0.0456713177263737,5.31081961088241E-7,2.93552198367377E-7,1,0.999253354069792,40.0298881530762,1.99706372421405,16.0799995064735,7.07450711501689E-6,-4.88305617991229E-6,0.25,-5.22517246213347E-7,5.3507197254198E-7,-5.24094279853268E-7,128.4355164,128.4355164,-0.0456713177263737,-0.0456713177263737,56.4367056025444,20.5591218813842,28.224119,0,0,0,40,4374,120.8516,-0.0456713177263737,,,,,,,,,,,,,0,,,,0,,,,,,128.4355164,,,,
,23212561.86,126.47576525,-0.0456713177263737,-1.80821264560674E-7,3.43995095172636E-7,1,0.999253354069792,40.0298881530762,1.99659571287262,16.0799995064735,-5.90090822065078E-7,-8.7313984934919E-6,0.25,-7.3676706431173E-7,-1.80085537886122E-7,-7.41112718786887E-7,126.401207,126.5503235,-0.0456713177263737,-0.0456713177263737,56.238953587179,20.5672941234952,28.224119,0,0,0,40,4374,118.9416,-0.0456713177263737,,,,,,,,,,,,,0,,,,-0.00245,,,,,,126.47576525,,,,
,23212595.47,124.5187073,-0.0456713177263737,2.10219376519664E-7,2.91050270908667E-7,1,0.999253354069792,40.0298881530762,1.99679916663657,16.0799995064735,2.41734373186364E-6,2.56218731080721E-7,0.25,-1.42433360972573E-8,2.11379991120585E-7,-1.38218894382451E-8,124.5187073,124.5187073,-0.0456713177263737,-0.0456713177263737,56.6751023009098,20.5708176351583,28.224119,0,0,0,40,4374,117.1019,-0.0456713177263737,,,,,,,,,,,,,0,,,,-0.00245,,,,,,124.5187073,,,,
,23212629.885,122.5847626,-0.0456713177263737,4.91117428099424E-7,2.67495839017277E-7,1,0.999253354069792,40.0298881530762,1.99683613538166,16.0799995064735,6.18017879697328E-6,-2.44290804669251E-6,0.25,-3.0093496128126E-7,4.94494778343727E-7,-3.01360460456079E-7,122.5847626,122.5847626,-0.0456713177263737,-0.0456713177263737,56.6250780756791,20.5724855780863,27.464817,0,0,0,40,4374,115.2105,-0.0456713177263737,,,,,,,,,,,,,0,,,,-0.00245,,,,,,122.5847626,,,,
touchdown = 10.9000001102686 mm,23212693.025,118.9026794,-0.0456713177263737,4.99797743389105E-7,2.82065298758203E-7,1,0.999253354069792,40.0298881530762,1.99659783029757,16.1400008946657,6.38518482102056E-6,-3.03248694351543E-6,0.25,-3.54422813955046E-7,5.03419003343205E-7,-3.55066569971629E-7,118.9026794,118.9026794,-0.0456713177263737,-0.0456713177263737,56.506270540756,20.5687511223702,28.224119,0,0,0,40,4374,111.78125,-0.0456713177263737,,,,,,,,,,,,,0,,,,0,,,,,,118.9026794,,,,
,23212726.815,116.983078,-0.0456713177263737,3.22333131471864E-7,2.46761505452123E-7,1,0.999253354069792,40.0298881530762,1.99675903274266,16.1400008946657,4.524418314077E-6,-4.27140197524253E-6,0.25,-4.32348011643113E-7,3.25228253797521E-7,-4.33853488923016E-7,116.983078,116.983078,-0.0456713177263737,-0.0456713177263737,56.404658833256,20.5749235764439,27.844467,0,0,0,40,4374,109.9466,-0.0456713177263737,,,,,,,,,,,,,0,,,,0,,,,,,116.983078,,,,
,23212757.485,115.3018723,-0.0456713177263737,4.48299355369774E-7,2.9452407024596E-7,1,0.999253354069792,40.0298881530762,1.99671134367269,16.1400008946657,5.22208223475624E-6,1.66574060126823E-7,0.25,-6.39509856901186E-8,4.50919856500835E-7,-6.3087546587409E-8,115.3018723,115.3018723,-0.0456713177263737,-0.0456713177263737,56.5719273363714,20.5743246810152,27.844467,0,0,0,40,4374,108.2993,-0.0456713177263737,,,,,,,,,,,,,0,,,,-0.00245,,,,,,115.3018723,,,,
,23212789.06,113.5237885,-0.0456713177263737,3.49192385174447E-7,2.05215602572429E-7,1,0.999253354069792,40.0298881530762,1.99667860965055,16.1400008946657,4.32768650255048E-6,-1.3525919154017E-6,0.25,-1.80279326875124E-7,3.51603959690383E-7,-1.80295052514639E-7,113.5237885,113.5237885,-0.0456713177263737,-0.0456713177263737,56.9213152844676,20.5770979537479,27.464817,0,0,0,40,4374,106.6096,-0.0456713177263737,,,,,,,,,,,,,0,,,,0.00245,,,,,,113.5237885,,,,
,23212820.81,111.7685013,-0.0456713177263737,1.81140024135367E-7,3.05282028647489E-7,1,0.999253354069792,40.0298881530762,1.99669679740375,16.1400008946657,2.61079470701967E-6,-2.78552877075025E-6,0.25,-2.76904387254929E-7,1.82923644771134E-7,-2.77904294501811E-7,111.7685013,111.7685013,-0.0456713177263737,-0.0456713177263737,56.5719273363714,20.5760451948717,27.464817,0,0,0,40,4374,104.9485,-0.0456713177263737,,,,,,,,,,,,,0,,,,0.0049,,,,,,111.7685013,,,,
,23212852.66,109.8966446,-0.0456713177263737,5.99197153939503E-7,2.74706207228609E-7,1,0.999253354069792,40.0298881530762,1.99662210136673,16.1400008946657,7.23396121952049E-6,-1.22387278837635E-6,0.25,-2.12910549445797E-7,6.03110887810606E-7,-2.12318956006489E-7,109.8966446,109.8966446,-0.0456713177263737,-0.0456713177263737,56.2428617297752,20.5770124672703,27.464817,0,0,0,40,4374,103.2927,-0.0456713177263737,,,,,,,,,,,,,0,,,,0.0049,,,,,,109.8966446,,,,
,23212908.74,106.8155441,-0.0456713177263737,1.2821544404344E-7,2.61705139962186E-7,1,0.999253354069792,40.0298881530762,1.99661099438553,16.1899998784065,1.84141013664146E-6,-1.93147225437974E-6,0.25,-1.92506256747131E-7,1.29514245221154E-7,-1.93166300151657E-7,106.8155441,106.8155441,-0.0456713177263737,-0.0456713177263737,56.1865844763906,20.571958122881,27.464817,0,0,0,40,4374,100.3323,-0.0456713177263737,,,,,,,,,,,,,0,,,,-0.00245,,,,,,106.8155441,,,,
,23212945.375,104.851799,-0.0456713177263737,4.57049368640502E-7,3.08903985114001E-7,1,0.999253354069792,40.0298881530762,1.99653135250708,16.1899998784065,5.76890205120041E-6,-2.35986623417388E-6,0.25,-2.88060518446257E-7,4.60475812881342E-7,-2.88176737605714E-7,104.851799,104.851799,-0.0456713177263737,-0.0456713177263737,56.8157954343714,20.5744748777275,27.085165,0,0,0,40,4374,98.40525,-0.0456713177263737,,,,,,,,,,,,,0,,,,-0.0049,,,,,,104.851799,,,,
,23212990.155,102.3640747,-0.0456713177263737,3.14992534106523E-7,3.38173942768727E-7,1,0.999253354069792,40.0298881530762,1.99688667964104,16.1899998784065,4.03706122338612E-6,-1.96906339959516E-6,0.25,-2.28708852453261E-7,3.17477908231729E-7,-2.2890599048821E-7,102.3640747,102.3640747,-0.0456713177263737,-0.0456713177263737,56.5813068786021,20.5752202150453,27.085165,0,0,0,40,4374,96.0334,-0.0456713177263737,,,,,,,,,,,,,0,,,,0.00245,,,,,,102.3640747,,,,
,23213034.74,99.8544998,-0.0456713177263737,2.68547121572155E-7,2.18946110693534E-7,1,0.999253354069792,40.0298881530762,1.99673448873763,16.1899998784065,3.77713067880622E-6,-3.58214728539632E-6,0.25,-3.62559305769697E-7,2.71273526827568E-7,-3.63594020304878E-7,99.8544998,99.8544998,-0.0456713177263737,-0.0456713177263737,56.8329912617945,20.5728331270222,27.464817,0,0,0,40,4374,93.70775,-0.0456713177263737,,,,,,,,,,,,,0,,,,0.00245,,,,,,99.8544998,,,,
,23213108.53,95.8094177,-0.0456713177263737,3.57444090698522E-7,2.61356277932137E-7,1,0.999253354069792,40.0298881530762,1.99665795900835,16.2499994039536,4.60373780762112E-6,-2.36010395989266E-6,0.25,-2.70799269807364E-7,3.60382298754538E-7,-2.70911316667726E-7,95.8094177,95.8094177,-0.0456713177263737,-0.0456713177263737,56.7180918694675,20.567935574947,26.705515,0,0,0,40,4374,89.9266,-0.0456713177263737,,,,,,,,,,,,,0,,,,0,,,,,,95.8094177,,,,
,23213153.12,93.4060516,-0.0456713177263737,1.69382547340758E-7,2.91946729712141E-7,1,0.999253354069792,40.0298881530762,1.99665660103474,16.2499994039536,2.61833266184806E-6,-3.59058893523751E-6,0.25,-3.45984793803936E-7,1.71643048764337E-7,-3.47158455017956E-7,93.4060516,93.4060516,-0.0456713177263737,-0.0456713177263737,56.3264959813329,20.572290872165,26.705515,0,0,0,40,4374,87.6844,-0.0456713177263737,,,,,,,,,,,,,0,,,,-0.00245,,,,,,93.4060516,,,,
,23213199.47,90.9277573,-0.0456713177263737,-2.8062736190596E-8,2.87181122177615E-7,1,0.999253354069792,40.0298881530762,1.99667016152294,16.2499994039536,7.27671150514324E-7,-5.97497133280345E-6,0.25,-5.21054405193049E-7,-2.60612813739397E-8,-5.23900790564245E-7,90.8450928,91.0104218,-0.0456713177263737,-0.0456713177263737,56.3499448369098,20.5741745177145,26.705515,0,0,0,40,4374,85.3573,-0.0456713177263737,,,,,,,,,,,,,0,,,,-0.00245,,,,,,90.9277573,,,,
,23213242.445,88.6299438,-0.0456713177263737,3.21066029306804E-7,3.25370236422858E-7,1,0.999253354069792,40.0298881530762,1.99661175298263,16.2499994039536,4.29069480500165E-6,-2.99452399356075E-6,0.25,-3.20497075562298E-7,3.24103445332738E-7,-3.2076173049561E-7,88.6299438,88.6299438,-0.0456713177263737,-0.0456713177263737,56.7743691228522,20.5724834218309,26.325863,0,0,0,40,4374,83.16735,-0.0456713177263737,,,,,,,,,,,,,0,,,,0,,,,,,88.6299438,,,,
,23213311.685,84.7466202,-0.0456713177263737,2.16876050513608E-7,3.0040405006863E-7,1,0.999253354069792,40.0298881530762,1.99663341596012,16.3199994713068,2.87185204816426E-6,-1.8712005094336E-6,0.25,-2.03261820497545E-7,2.18899588565606E-7,-2.03260058076493E-7,84.7466202,84.7466202,-0.0456713177263737,-0.0456713177263737,56.4593728296021,20.571228851184,26.325863,0,0,0,40,4374,79.6052,-0.0456713177263737,,,,,,,,,,,,,0,,,,0.00245,,,,,,84.7466202,,,,
,23213340.66,83.17427825,-0.0456713177263737,4.03564015418434E-7,2.59533081926785E-7,1,0.999253354069792,40.0298881530762,1.99661170925387,16.3199994713068,5.38701518399322E-6,-3.72355707517693E-6,0.25,-3.99616643131501E-7,4.07450551103873E-7,-3.99619566849611E-7,83.106575,83.2419815,-0.0456713177263737,-0.0456713177263737,56.4335790884675,20.5729863056444,26.325863,0,0,0,40,4374,78.1304,-0.0456713177263737,,,,,,,,,,,,,0,,,,0.00245,,,,,,83.17427825,,,,
,23213369.975,81.6025391,-0.0456713177263737,3.43655447881625E-7,2.61172851106982E-7,1,0.999253354069792,40.0298881530762,1.99653832856896,16.3199994713068,4.18583284298131E-6,-9.10902650851375E-7,0.25,-1.41309422475634E-7,3.45991175320432E-7,-1.40271055178369E-7,81.6025391,81.6025391,-0.0456713177263737,-0.0456713177263737,56.8947399148137,20.5694101584192,25.946213,0,0,0,40,4374,76.5963,-0.0456713177263737,,,,,,,,,,,,,0,,,,0,,,,,,81.6025391,,,,
,23213399.055,79.94007495,-0.0456713177263737,1.75243720276478E-7,2.77461993366779E-7,1,0.999253354069792,40.0298881530762,1.99660019660337,16.3199994713068,2.0061335845845E-6,2.57087745902778E-7,0.25,-8.51572457993316E-9,1.76098043400719E-7,-7.65403643031679E-9,79.8749695,80.0051804,-0.0456713177263737,-0.0456713177263737,56.0029017743713,20.5770511344771,25.946213,0,0,0,40,4374,75.0879,-0.0456713177263737,,,,,,,,,,,,,0,,,,-0.00245,,,,,,79.94007495,,,,
,23213428.085,78.3230438,-0.0456713177263737,1.3934343051039E-7,2.79253321029001E-7,1,0.999253354069792,40.0298881530762,1.99642772539167,16.3199994713068,2.16716356791272E-6,-3.01050160019444E-6,0.25,-2.9012785177535E-7,1.41510178477078E-7,-2.90686825525049E-7,78.2595901,78.3864975,-0.0456713177263737,-0.0456713177263737,56.4546830584867,20.5776888190329,25.566563,0,0,0,40,4374,73.5561,-0.0456713177263737,,,,,,,,,,,,,0,,,,0,,,,,,78.3230438,,,,
,23213485.205,75.141983,-0.0456713177263737,2.46197572278646E-7,2.59130143018693E-7,1,0.999253354069792,40.0298881530762,1.99656873566884,16.380000859499,3.81730944846509E-6,-5.24558770552414E-6,0.25,-5.0638263857783E-7,2.50091462725568E-7,-5.07077568144009E-7,75.141983,75.141983,-0.0456713177263737,-0.0456713177263737,56.4460851447752,20.5699925274578,25.946213,0,0,0,40,4374,70.4904,-0.0456713177263737,,,,,,,,,,,,,0,,,,-0.00245,,,,,,75.141983,,,,
,23213514.345,73.5114059,-0.0456713177263737,4.60841008873013E-7,2.45086084610582E-7,1,0.999253354069792,40.0298881530762,1.99644403611995,16.380000859499,5.61093379455267E-6,-1.22378949667187E-6,0.25,-1.90231910531283E-7,4.63766653801804E-7,-1.88273228212681E-7,73.5114059,73.5114059,-0.0456713177263737,-0.0456713177263737,56.310081782429,20.570787428578,25.946213,0,0,0,40,4374,68.9228,-0.0456713177263737,,,,,,,,,,,,,0,,,,-0.0049,,,,,,73.5114059,,,,
,23213543.345,71.8170624,-0.0456713177263737,2.07786698153983E-7,3.05304405580392E-7,1,0.999253354069792,40.0298881530762,1.99635128792812,16.380000859499,2.63273677400118E-6,-1.12964783918128E-6,0.25,-1.36806248774666E-7,2.09383174937194E-7,-1.36050639289712E-7,71.8170624,71.8170624,-0.0456713177263737,-0.0456713177263737,56.3788650921214,20.5715817798994,25.186911,0,0,0,40,4374,67.3302,-0.0456713177263737,,,,,,,,,,,,,0,,,,0,,,,,,71.8170624,,,,
,23213571.665,70.1663361,-0.0456713177263737,-1.58228414055938E-7,3.40287186848967E-7,1,0.999253354069792,40.0298881530762,1.9964109235131,16.380000859499,-1.39849801224811E-6,-2.52593970063257E-6,0.25,-1.94561535298656E-7,-1.57554856237187E-7,-1.96219606613194E-7,70.1663361,70.1663361,-0.0456713177263737,-0.0456713177263737,56.5609845371021,20.5739414218313,25.186911,0,0,0,40,4374,65.7778,-0.0456713177263737,,,,,,,,,,,,,0,,,,0,,,,,,70.1663361,,,,
,23213599.775,68.6016006,-0.0456713177263737,2.11281576912827E-7,2.43412329701468E-7,1,0.999253354069792,40.0298881530762,1.99648069696937,16.380000859499,3.21965506319308E-6,-4.17986191374166E-6,0.25,-4.0678762896122E-7,2.14568199975972E-7,-4.06710291276173E-7,68.6016006,68.6016006,-0.0456713177263737,-0.0456713177263737,56.7110572127945,20.5723639771246,24.807261,0,0,0,40,4374,64.23705,-0.0456713177263737,,,,,,,,,,,,,0,,,,-0.0049,,,,,,68.6016006,,,,
,23213628.225,66.9252319,-0.0456713177263737,2.51734247699019E-7,2.87452731433374E-7,1,0.999253354069792,40.0298881530762,1.99637422285111,16.380000859499,3.78665411337839E-6,-4.70458535306319E-6,0.25,-4.60562205922794E-7,2.55500789687578E-7,-4.60203761249034E-7,66.9252319,66.9252319,-0.0456713177263737,-0.0456713177263737,56.1850212193521,20.5746693367685,25.186911,0,0,0,40,4374,62.66145,-0.0456713177263737,,,,,,,,,,,,,0,,,,0,,,,,,66.9252319,,,,
,23213684.58,63.5738487,-0.0456713177263737,4.15515818489024E-7,3.2106744933624E-7,1,0.999253354069792,40.0298881530762,2.0090571528731,16.4299998432398,4.82695540788652E-6,3.14893181313296E-7,0.25,-4.70261243142179E-8,4.16728236742141E-7,-4.42337592688164E-8,63.5738487,63.5738487,-0.0456713177263737,-0.0456713177263737,56.2670922138713,20.5742911374528,24.427608,0,0,0,40,4374,59.5047,-0.0456713177263737,,,,,,,,,,,,,0,,,,-0.0049,,,,,,63.5738487,,,,
,23213712.68,61.8731194,-0.0456713177263737,2.83807820673449E-7,3.33937488533184E-7,1,0.999253354069792,40.0298881530762,2.00902860441888,16.4299998432398,3.59222317828042E-6,-1.43390443639536E-6,0.25,-1.77057239602106E-7,2.85554490173262E-7,-1.75343533074561E-7,61.8731194,61.8731194,-0.0456713177263737,-0.0456713177263737,56.4953277414867,20.5747438207641,24.427608,0,0,0,40,4374,57.8782,-0.0456713177263737,,,,,,,,,,,,,0,,,,0,,,,,,61.8731194,,,,
,23213741.095,60.0407867,-0.0456713177263737,2.68997948774629E-7,2.68945421885372E-7,1,0.999253354069792,40.0298881530762,2.00893737241343,16.4299998432398,4.35852336421318E-6,-6.66391239779606E-6,0.25,-6.34306115717915E-7,2.73931848965538E-7,-6.33165672842688E-7,60.0407867,60.0407867,-0.0456713177263737,-0.0456713177263737,56.597721077506,20.5782989663622,24.807261,0,0,0,40,4374,56.22105,-0.0456713177263737,,,,,,,,,,,,,0,,,,0,,,,,,60.0407867,,,,
,23213768.99,58.3356514,-0.0456713177263737,3.06186374627625E-7,3.12190220559914E-7,1,0.999253354069792,40.0298881530762,2.00898744217312,16.4299998432398,4.47706189267958E-6,-4.90224816656473E-6,0.25,-4.86350599526303E-7,3.10001567862947E-7,-4.84494644733733E-7,58.3356514,58.3356514,-0.0456713177263737,-0.0456713177263737,56.5516049948714,20.5773724554265,24.807261,0,0,0,40,4374,54.5826,-0.0456713177263737,,,,,,,,,,,,,0,,,,0.0049,,,,,,58.3356514,,,,
,23213797.565,56.4889641,-0.0456713177263737,1.80740824974897E-7,3.11752868486154E-7,1,0.999253354069792,40.0298881530762,2.00906616741155,16.4299998432398,2.23873966699766E-6,-6.55988664746529E-7,0.25,-9.03006404383512E-8,1.81460954186599E-7,-8.89869614504998E-8,56.4889641,56.4889641,-0.0456713177263737,-0.0456713177263737,56.3264959813329,20.5783325551979,24.427608,0,0,0,40,4374,52.8353,-0.0456713177263737,,,,,,,,,,,,,0,,,,0,,,,,,56.4889641,,,,
,23213854.06,52.6819305,-0.0456713177263737,3.68578594409214E-9,3.53432741081091E-7,1,0.999253354069792,40.0298881530762,1.98496427217401,16.499999910593,5.21811093728252E-7,-2.65813689736417E-6,0.25,-2.37553460866492E-7,5.44752725280695E-9,-2.37336712461157E-7,52.6819305,52.6819305,-0.0456713177263737,-0.0456713177263737,56.719655126506,20.5782378931665,22.909004,0,0,0,40,4374,49.3512,-0.0456713177263737,,,,,,,,,,,,,0,,,,-0.00245,,,,,,52.6819305,,,,
,23213881.875,50.5315895,-0.0456713177263737,4.54981673654214E-7,3.25613071361016E-7,1,0.999253354069792,40.0298881530762,1.98497997589823,16.499999910593,5.21304550324799E-6,3.07229371139365E-7,0.25,-5.45897483383128E-8,4.54779936629585E-7,-5.1161761277172E-8,50.5315895,50.5315895,-0.0456713177263737,-0.0456713177263737,56.6094455052945,20.5782606732688,22.529354,0,0,0,40,4374,47.6387,-0.0456713177263737,,,,,,,,,,,,,0,,,,0,,,,,,50.5315895,,,,
,23213910.275,48.5133858,-0.0456713177263737,2.61331902273856E-7,2.67957743902617E-7,1,0.999253354069792,40.0298881530762,1.9849226078161,16.499999910593,3.74967233041025E-6,-4.02801434072664E-6,0.25,-4.06421206293722E-7,2.6379798369274E-7,-4.0375674880982E-7,48.5133858,48.5133858,-0.0456713177263737,-0.0456713177263737,56.750138638756,20.5780498753822,22.149702,0,0,0,40,4374,45.8421,-0.0456713177263737,,,,,,,,,,,,,0,,,,-0.00245,,,,,,48.5133858,,,,
,23213938.75,46.3849068,-0.0456713177263737,6.06862839384791E-7,3.0348527448304E-7,1,0.999253354069792,40.0298881530762,1.98483735969915,16.499999910593,7.65683685556201E-6,-3.5479754082136E-6,0.25,-4.25914328478272E-7,6.08411420636173E-7,-4.20549710639818E-7,46.3849068,46.3849068,-0.0456713177263737,-0.0456713177263737,56.5938129349098,20.5796409172422,21.770052,0,0,0,40,4374,43.9077,-0.0456713177263737,,,,,,,,,,,,,0,,,,-0.0049,,,,,,46.3849068,,,,
,23213964.37,44.45289425,-0.0456713177263737,-2.6554379207732E-8,3.02967536476618E-7,1,0.999253354069792,40.0298881530762,1.98492292691139,16.499999910593,1.56181556340564E-7,-2.57642444668896E-6,0.25,-2.25314000120425E-7,-2.49113089729696E-8,-2.24835093053062E-7,44.3770905,44.528698,-0.0456713177263737,-0.0456713177263737,56.5093970548329,20.5773793052373,21.770052,0,0,0,40,4374,42.11545,-0.0456713177263737,,,,,,,,,,,,,0,,,,0.00245,,,,,,44.45289425,,,,
,23214018.735,39.9932327,-0.0456713177263737,1.02839333856892E-8,2.94958136173491E-7,1,0.999253354069792,40.0298881530762,1.98511011170193,16.550000756979,9.50324746791476E-7,-4.63964830351538E-6,0.25,-4.16542636397821E-7,1.29212493502199E-8,-4.14819679856048E-7,39.9932327,39.9932327,-0.0456713177263737,-0.0456713177263737,56.299920611679,20.575646871337,20.631098,0,0,0,40,4374,37.8206,-0.0456713177263737,,,,,,,,,,,,,0,,,,0,,,,,,39.9932327,,,,
,23214044.94,37.5281296,-0.0456713177263737,3.09900058194989E-7,2.74088186724935E-7,1,0.999253354069792,40.0298881530762,1.98500868100664,16.550000756979,3.98258981874706E-6,-2.26964305024016E-6,0.25,-2.58404219931381E-7,3.10107710533799E-7,-2.55359665707431E-7,37.5281296,37.5281296,-0.0456713177263737,-0.0456713177263737,56.2811615272175,20.573438119225,20.631098,0,0,0,40,4374,35.4585,-0.0456713177263737,,,,,,,,,,,,,0,,,,-0.0049,,,,,,37.5281296,,,,
,23214070.175,34.9941483,-0.0456713177263737,4.93014896796711E-7,2.86011425503909E-7,1,0.999253354069792,40.0298881530762,1.98505164132496,16.550000756979,5.98944370195379E-6,-1.69126021135151E-6,0.25,-2.39340221905245E-7,4.92027973680996E-7,-2.35315431967335E-7,34.9941483,34.9941483,-0.0456713177263737,-0.0456713177263737,56.0943523111213,20.5721494524666,20.251448,0,0,0,40,4374,33.0268,-0.0456713177263737,,,,,,,,,,,,,0,,,,-0.0049,,,,,,34.9941483,,,,
,23214122.615,28.5810432,-0.0456713177263737,1.72656400659709E-7,2.7736152926411E-7,1,0.999253354069792,40.0298881530762,1.98512657970801,16.5699999779463,3.02053350811188E-6,-5.78998334003423E-6,0.25,-5.48913256457022E-7,1.74549568464941E-7,-5.45004676129238E-7,28.5810432,28.5810432,-0.0456713177263737,-0.0456713177263737,56.5711457078521,20.5698437818622,18.732843,0,0,0,40,4374,26.67825,-0.0456713177263737,,,,,,,,,,,,,0,,,,-0.00245,,,,,,28.5810432,,,,
,23214145.965,24.9009609,-0.0456713177263737,1.82256592612081E-7,3.33180749190611E-7,1,0.999253354069792,40.0298881530762,1.98499847296589,16.5699999779463,2.46226319370223E-6,-2.03665231836491E-6,0.25,-2.14703483956214E-7,1.82286702194896E-7,-2.12581454870953E-7,24.9009609,24.9009609,-0.0456713177263737,-0.0456713177263737,56.3616692646983,20.5711156799452,17.973541,0,0,0,40,4374,23.2161,-0.0456713177263737,,,,,,,,,,,,,0,,,,-0.00245,,,,,,24.9009609,,,,
,23214184,17.2692547,-0.0456713177263737,,,2,,,,16.6200004294515,,,,,,,17.2692547,17.2692547,-0.0456713177263737,-0.0456713177263737,,,16.834587,,,,-99999999,4374,15.6333,-0.0456713177263737,,,,,,,,,,,,,,,,,,,,,,,17.2692547,,,,
,23214221.805,10.6608257,-0.0456713177263737,3.62583056180039E-7,3.61975369768274E-7,1,0.999253354069792,40.0298881530762,1.99668184499283,16.610000282526,4.77342009093699E-6,-3.22093739466454E-6,0.25,-3.51113906666146E-7,3.62192119529347E-7,-3.47348901512748E-7,10.6608257,10.6608257,-0.0456713177263737,-0.0456713177263737,56.2577126716406,20.5687982318723,14.556682,0,0,0,40,4374,10.2623,-0.0456713177263737,,,,,,,,,,,,,0,,,,-0.0049,,,,,,10.6608257,,,,
,23214255.935,10.0166283,-0.0456713177263737,3.5645103047934E-7,2.8654405084379E-7,1,0.999253354069792,40.0298881530762,1.99685267418962,16.610000282526,5.12403325211229E-6,-5.59363350296321E-6,0.25,-5.6120203130497E-7,3.57108314391687E-7,-5.56260076894978E-7,10.0166283,10.0166283,-0.0456713177263737,-0.0456713177263737,56.435142345506,20.5723092938164,14.177031,0,0,0,40,4373,10.06705,-0.0456713177263737,,,,,,,,,,,,,0,,,,-0.00245,,,,,,10.0166283,,,,
,23214295.565,10.0310497,-0.0456713177263737,4.80770460373565E-7,3.96786512933314E-7,1,0.999253354069792,40.0298881530762,1.99684433271118,16.610000282526,6.40317490009317E-6,-4.68404017280963E-6,0.25,-5.023138860834E-7,4.8042973038117E-7,-4.97110998634932E-7,10.0310497,10.0310497,-0.0456713177263737,-0.0456713177263737,56.9416376259676,20.5710583046628,13.038077,0,0,0,40,4373,10.0684,-0.0456713177263737,,,,,,,,,,,,,0,,,,0,,,,,,10.0310497,,,,
,23214334.56,9.9743328,-0.0456713177263737,1.72492733002523E-7,2.51051618009734E-7,1,0.999253354069792,40.0298881530762,1.99687371194986,16.610000282526,2.22178398593334E-6,-1.25481408902016E-6,0.25,-1.42323663459013E-7,1.72187831622085E-7,-1.40674676186462E-7,9.9743328,9.9743328,-0.0456713177263737,-0.0456713177263737,56.506270540756,20.5747059124504,12.658426,0,0,0,40,4373,10.0163,-0.0456713177263737,,,,,,,,,,,,,0,,,,0,,,,,,9.9743328,,,,
,23214375.085,10.0059328,-0.0456713177263737,1.64264398077643E-7,2.38952689937543E-7,1,0.999253354069792,40.0298881530762,1.99654512109536,16.610000282526,2.1904626814602E-6,-1.6171059482615E-6,0.25,-1.73133497292479E-7,1.64155257903071E-7,-1.71347173225775E-7,10.0059328,10.0059328,-0.0456713177263737,-0.0456713177263737,56.5258112537367,20.5811433840005,13.417728,0,0,0,40,4373,10.0306,-0.0456713177263737,,,,,,,,,,,,,0,,,,0,,,,,,10.0059328,,,,
,23214392.46,10.0031643,-0.0456713177263737,1.85040653531509E-7,2.70551094608212E-7,1,0.999253354069792,40.0298881530762,1.99656227495659,16.610000282526,2.32070306496757E-6,-9.94777863833288E-7,0.25,-1.21418661173083E-7,1.84562901140839E-7,-1.19829278055769E-7,10.0031643,10.0031643,-0.0456713177263737,-0.0456713177263737,56.9916618511983,20.5796905358565,12.658426,0,0,0,40,4369,10.03055,-0.0456713177263737,,,,,,,,,,,,,0,,,,0,,,,,,10.0031643,,,,