File: data/doubleLayers/dl_2-5/ppms/DD205_5/KoelnPPMS/CooldownTests/DD205_5_1T_HYS_ZFC.DAT
[Header]
; VSM Data File (default extension .dat)
; Copyright (c) 2003-2013, Quantum Design, Inc. All rights reserved.
TITLE,
FILEOPENTIME,23214700.88,09/27/2018,1:30 am
BYAPP,VSM,2.0,2.0
INFO,PPMS VSM Option Release 1.4.10 Build 1,APPNAME
INFO,Quantum Design Linear Motor Servo Controller,MOTOR_MODULE_NAME
INFO,3101-100 M1,MOTOR_HW_VERSION
INFO,MMC1014,MOTOR_SERIAL_NUMBER
INFO,SRV No X-over 01.03.11,MOTOR_SOFTWARE_VERSION
INFO,Quantum Design VSM Detection Module,VSM_MODULE_NAME
INFO,3101-150 F0,VSM_HW_VERSION
INFO,VSM707,VSM_SERIAL_NUMBER
INFO,VSM No X-over 01.02.05 May 20 2008 13:51:47,VSM_SOFTWARE_VERSION
INFO,704,PREAMP_SERIAL_NUMBER
INFO,822,COIL_SERIAL_NUMBER
INFO,0,MOMENT_UNITS
INFO,,SAMPLE_MATERIAL
INFO,,SAMPLE_COMMENT
INFO,,SAMPLE_MASS
INFO,,SAMPLE_VOLUME
INFO,,SAMPLE_MOLECULAR_WEIGHT
INFO,,SAMPLE_SIZE
INFO,,SAMPLE_SHAPE
DATATYPE,COMMENT,1
DATATYPE,TIME,2
STARTUPAXIS,X,2
STARTUPAXIS,Y1,5
[Data]
Comment,Time Stamp (sec),Temperature (K),Magnetic Field (Oe),Moment (emu),M. Std. Err. (emu),Transport Action,Averaging Time (sec),Frequency (Hz),Peak Amplitude (mm),Center Position (mm),Coil Signal' (mV),Coil Signal" (mV),Range (mV),M. Quad. Signal (emu),M. Raw' (emu),M. Raw" (emu),Min. Temperature (K),Max. Temperature (K),Min. Field (Oe),Max. Field (Oe),Mass (grams),Motor Lag (deg),Pressure (Torr),VSM Status (code),Motor Status (code),Measure Status (code),Measure Count,PPMS Status (code),System Temp. (K),System Field (Oe),Sample Position (deg),Bridge 1 Resistance (ohms),Bridge 1 Excitation (에),Bridge 2 Resistance (ohms),Bridge 2 Excitation (에),Bridge 3 Resistance (ohms),Bridge 3 Excitation (에),Bridge 4 Resistance (ohms),Bridge 4 Excitation (에),Signal 1 Vin (V),Signal 2 Vin (V),Digital Inputs (code),Drive 1 Iout (mA),Drive 1 Ipower (W),Drive 2 Iout (mA),Drive 2 Ipower (W),Pressure (),Map 20 (),Map 21 (),Map 22 (),Map 23 (),Map 24 (),Map 25 (),Map 26 (),Map 27 (),Map 28 (),Map 29 ()
,23214716.75,10.0114946,-0.0456713177263737,,,2,,,,16.6899995654821,,,,,,,10.0114946,10.0114946,-0.0456713177263737,-0.0456713177263737,,,13.038077,,,,-99999999,4369,9.9915,-0.0456713177263737,,,,,,,,,,,,,,,,,,,,,,,10.0114946,,,,
,23214776.28,10.0090637,345.900253295898,1.21973698581592E-6,2.66545941095677E-7,1,0.999253354069792,40.0298881530762,1.99626716974972,16.669999808073,1.45006743819489E-5,-2.08036269580286E-6,0.25,-4.01838183425238E-7,1.21468550982461E-6,-3.93639416554023E-7,10.0090637,10.0090637,341.064727783203,350.735778808594,56.2412984727367,20.5723837430627,13.038077,0,0,0,40,4449,9.98625,345.900253295898,,,,,,,,,,,,,0,,,,0.00245,,,,,,10.0090637,,,,
,23214794.2,10.006135,792.282531738281,1.533861175919E-6,2.79523437649741E-7,1,0.999253354069792,40.0298881530762,1.99616927314311,16.669999808073,1.76865203307625E-5,4.70483110010913E-7,0.25,-2.30535828725686E-7,1.52621459563024E-6,-2.21771875559932E-7,10.006135,10.006135,787.371826171875,797.193237304687,56.2444249868136,20.5731057973978,13.417728,0,0,0,40,4449,9.9892,792.282531738281,,,,,,,,,,,,,0,,,,0.0049,,,,,,10.006135,,,,
,23214813.51,10.0058212,1272.81799316406,9.90013483178754E-7,2.20366100008842E-7,1,0.999253354069792,40.0298881530762,1.99598787818914,16.669999808073,1.22931067562828E-5,-4.64027445006432E-6,0.25,-5.89060332629306E-7,9.87253715256646E-7,-5.80874967659012E-7,10.0058212,10.0058212,1270.30700683594,1275.32897949219,56.5328459104098,20.5773062953079,13.417728,0,0,0,40,4449,9.9889,1272.81799316406,,,,,,,,,,,,,0,,,,0.0049,,,,,,10.0058212,,,,
,23214832.17,10.00218725,1739.59539794922,7.35053440726807E-8,2.44844491321172E-7,1,0.999253354069792,40.0298881530762,1.99620247381709,16.669999808073,1.48305042526764E-6,-3.55396229556098E-6,0.25,-3.2948683264716E-7,7.47061188985021E-8,-3.27258529923169E-7,10.0014954,10.0028791,1734.55590820313,1744.63488769531,56.3311857524483,20.5779031083454,13.038077,0,0,0,40,4449,9.98795,1739.59539794922,,,,,,,,,,,,,0,,,,-0.0049,,,,,,10.00218725,,,,
,23214850.73,10.0038033,2201.25659179687,-9.75935203266034E-7,2.53203029941366E-7,1,0.999253354069792,40.0298881530762,1.99604334184575,16.669999808073,-1.02156036989482E-5,-6.14036274878839E-6,0.25,-3.7332013906302E-7,-9.68585149502095E-7,-3.76032282520073E-7,10.0038033,10.0038033,2196.296875,2206.21630859375,56.0685585699867,20.5805245145001,13.417728,0,0,0,40,4449,9.9872,2201.25659179687,,,,,,,,,,,,,0,,,,-0.00245,,,,,,10.0038033,,,,
,23214869.93,10.0012283,2679.91674804687,-2.61813583506165E-6,3.65603147016334E-7,1,0.999253354069792,40.0298881530762,1.9960248814692,16.669999808073,-2.86536433282305E-5,-9.4502053209703E-6,0.25,-3.76124258152675E-7,-2.60156593974586E-6,-3.87019786904726E-7,10.0012283,10.0012283,2676.21069335938,2683.62280273438,56.0795013692559,20.5779547154351,13.417728,0,0,0,40,4449,9.98855,2679.91674804687,,,,,,,,,,,,,0,,,,0,,,,,,10.0012283,,,,
,23214887.145,9.9999037,3109.92565917969,-3.38762271602324E-6,3.52117451515308E-7,1,0.999253354069792,40.0298881530762,1.99570308866582,16.669999808073,-3.65464166556686E-5,-1.51729165136825E-5,0.25,-7.48990405586125E-7,-3.36494501969793E-6,-7.61730699229509E-7,9.9999037,9.9999037,3106.28588867188,3113.5654296875,56.5023623981598,20.5816919352738,13.038077,0,0,0,40,4449,9.98805,3109.92565917969,,,,,,,,,,,,,0,,,,-0.00245,,,,,,9.9999037,,,,
,23214904.985,10.00282815,3555.60534667969,-4.67292183593458E-6,3.38254800711811E-7,1,0.999253354069792,40.0298881530762,1.99564091518206,16.669999808073,-5.12860305290568E-5,-1.60136999859722E-5,0.25,-5.95258947934227E-7,-4.64393818113815E-6,-6.15437674694675E-7,10.0026579,10.0029984,3553.10180664063,3558.10888671875,56.7618630665445,20.5797226832965,13.797379,0,0,0,40,4449,9.9901,3555.60534667969,,,,,,,,,,,,,0,,,,0.0049,,,,,,10.00282815,,,,
,23214921.89,10.0004597,3978.14562988281,-5.89547642992464E-6,2.95567340008505E-7,1,0.999253354069792,40.0298881530762,1.9956903944828,16.669999808073,-6.51264702494143E-5,-1.78440788936466E-5,0.25,-5.40653697198274E-7,-5.86010914427603E-6,-5.67467263789953E-7,10.0004597,10.0004597,3975.67944335937,3980.61181640625,56.5000175126021,20.5814028870288,13.038077,0,0,0,40,4449,9.98835,3978.14562988281,,,,,,,,,,,,,0,,,,-0.00245,,,,,,10.0004597,,,,
,23214939.36,10.0010509,4414.09741210937,-7.25631408371459E-6,4.32265963992169E-7,1,0.999253354069792,40.0298881530762,1.99614099769736,16.669999808073,-8.00040569366603E-5,-2.29507668835934E-5,0.25,-7.52695639461594E-7,-7.21252432589758E-6,-7.85457410479654E-7,10.0010509,10.0010509,4407.79931640625,4420.3955078125,56.4023139476983,20.5833755308773,12.658426,0,0,0,40,4449,9.9899,4414.09741210937,,,,,,,,,,,,,0,,,,0.00245,,,,,,10.0010509,,,,
,23214956.055,10.0002546,4833.17846679687,-8.36266147192268E-6,3.21665361376056E-7,1,0.999253354069792,40.0298881530762,1.99571777210409,16.669999808073,-9.26478760048981E-5,-2.38469030332242E-5,0.25,-6.35839261170777E-7,-8.31358718502604E-6,-6.75136656529555E-7,10.0002546,10.0002546,4830.755859375,4835.60107421875,56.4750053999867,20.5829118653872,12.658426,0,0,0,40,4449,9.98795,4833.17846679687,,,,,,,,,,,,,0,,,,0.0049,,,,,,10.0002546,,,,
,23214973.22,9.9999361,5261.38134765625,-9.44909011846919E-6,4.21736804657759E-7,1,0.999253354069792,40.0298881530762,1.99573462056304,16.669999808073,-0.000105339613175878,-2.32823278645512E-5,0.25,-3.91951919661991E-7,-9.39557309030655E-6,-4.38443333468785E-7,9.9999361,9.9999361,5257.56640625,5265.1962890625,56.3178980676213,20.5816590846319,13.038077,0,0,0,40,4449,9.9887,5261.38134765625,,,,,,,,,,,,,0,,,,0,,,,,,9.9999361,,,,
,23214989.135,10.0006504,5658.78466796875,-1.02807247384438E-5,3.62009999896661E-7,1,0.999253354069792,40.0298881530762,1.99574084927343,16.669999808073,-0.000114100299099047,-2.82200805553622E-5,0.25,-6.83281856282193E-7,-1.02214387788909E-5,-7.32777678319852E-7,10.0006504,10.0006504,5655.2001953125,5662.369140625,56.7055858131598,20.5820379341204,13.038077,0,0,0,40,4449,9.9892,5658.78466796875,,,,,,,,,,,,,0,,,,-0.00245,,,,,,10.0006504,,,,
,23215005.945,9.9990072,6079.8720703125,-1.14779965958783E-5,3.35131493403016E-7,1,0.999253354069792,40.0298881530762,1.99569800596219,16.669999808073,-0.000128140115304639,-2.7287071697216E-5,0.25,-3.86796756510641E-7,-1.14140808201922E-5,-4.44457275096959E-7,9.9990072,9.9990072,6074.59033203125,6085.15380859375,56.6211699330829,20.5863750440835,13.417728,0,0,0,40,4449,9.98825,6079.8720703125,,,,,,,,,,,,,0,,,,-0.00245,,,,,,9.9990072,,,,
,23215022.105,9.9992638,6483.38134765625,-1.26930261474859E-5,3.18630650550637E-7,1,0.999253354069792,40.0298881530762,1.99558287213764,16.669999808073,-0.000140959534532951,-3.43395964947744E-5,0.25,-7.98199795419262E-7,-1.2620759346605E-5,-8.60362031139956E-7,9.9992638,9.9992638,6479.630859375,6487.1318359375,56.3765202065637,20.5896732604252,13.038077,0,0,0,40,4449,9.98845,6483.38134765625,,,,,,,,,,,,,0,,,,0,,,,,,9.9992638,,,,
,23215039.62,9.9996681,6919.50805664062,-1.38363637296303E-5,3.84123277733784E-7,1,0.999253354069792,40.0298881530762,1.99542353708746,16.669999808073,-0.000154074876516213,-3.50418750463328E-5,0.25,-6.56914654211044E-7,-1.37591216258959E-5,-7.26281994887015E-7,9.9996681,9.9996681,6916.98388671875,6922.0322265625,56.6571248449675,20.5890481688047,13.417728,0,0,0,40,4449,9.98905,6919.50805664062,,,,,,,,,,,,,0,,,,-0.00245,,,,,,9.9996681,,,,
,23215055.595,9.9982843,7319.40161132813,-1.47580088379994E-5,4.0101806551304E-7,1,0.999253354069792,40.0298881530762,1.99530527491926,16.669999808073,-0.000164120896970673,-3.85674991332914E-5,0.25,-8.06427782805816E-7,-1.4675477261503E-5,-8.80308921461339E-7,9.9982843,9.9982843,7317.03857421875,7321.7646484375,56.0060282884482,20.5896547014002,13.038077,0,0,0,40,4449,9.98885,7319.40161132813,,,,,,,,,,,,,0,,,,0,,,,,,9.9982843,,,,
,23215072.235,9.9994001,7735.2958984375,-1.58911420004788E-5,3.64749924243791E-7,1,0.999253354069792,40.0298881530762,1.99547102652554,16.669999808073,-0.000175852568988288,-4.65247699872291E-5,0.25,-1.31228662344732E-6,-1.58003779273484E-5,-1.39001384652857E-6,9.9994001,9.9994001,7731.57177734375,7739.02001953125,56.2514596434867,20.5927847099576,13.038077,0,0,0,40,4449,9.9882,7735.2958984375,,,,,,,,,,,,,0,,,,0,,,,,,9.9994001,,,,
,23215088.68,9.9996719,8147.32495117187,-1.70742047308685E-5,3.49475834385704E-7,1,0.999253354069792,40.0298881530762,1.99531198056434,16.669999808073,-0.000190468059538328,-4.13827307104391E-5,0.25,-6.43402802536459E-7,-1.69812821582119E-5,-7.31497249234147E-7,9.9996719,9.9996719,8146.13818359375,8148.51171875,55.9755447761982,20.5883372651515,13.417728,0,0,0,40,4449,9.98965,8147.32495117187,,,,,,,,,,,,,0,,,,0,,,,,,9.9996719,,,,
,23215105.505,9.9993162,8567.4677734375,-1.82903947403241E-5,4.32399770931178E-7,1,0.999253354069792,40.0298881530762,1.99632547320851,16.669999808073,-0.000203636444797439,-4.71819584200908E-5,0.25,-9.40403177572612E-7,-1.81900709313347E-5,-1.03405478945014E-6,9.9993162,9.9993162,8563.8115234375,8571.1240234375,56.2772533846213,20.5818933708705,13.038077,0,0,0,40,4449,9.98875,8567.4677734375,,,,,,,,,,,,,0,,,,-0.0049,,,,,,9.9993162,,,,
,23215121.96,9.9989014,8978.82275390625,-1.93825657536741E-5,3.72882726269006E-7,1,0.999253354069792,40.0298881530762,1.99653258853848,16.669999808073,-0.000215563477567333,-5.14689035396742E-5,0.25,-1.12615842520549E-6,-1.92761412840564E-5,-1.22535329318744E-6,9.9989014,9.9989014,8975.837890625,8981.8076171875,56.6618146160829,20.5813825808257,13.417728,0,0,0,40,4449,9.9887,8978.82275390625,,,,,,,,,,,,,0,,,,-0.0049,,,,,,9.9989014,,,,
,23215137.625,9.9986,9369.953125,-2.01871589993582E-5,5.05111888309489E-7,1,0.999253354069792,40.0298881530762,1.99658598398185,16.669999808073,-0.000225626253346062,-4.74243913176933E-5,0.25,-6.22066575461759E-7,-2.00799073003682E-5,-7.28833747714592E-7,9.9986,9.9986,9366.388671875,9373.517578125,56.3757385780444,20.5784758719323,12.658426,0,0,0,40,4449,9.98935,9369.953125,,,,,,,,,,,,,0,,,,0,,,,,,9.9986,,,,
,23215154.52,9.99931005,9792.61181640625,-2.14549819262678E-5,5.0285243614469E-7,1,0.999253354069792,40.0298881530762,1.99671157441508,16.669999808073,-0.000239516220207404,-5.21044598836281E-5,0.25,-8.11445868677423E-7,-2.13408751152643E-5,-9.24843293636709E-7,9.9992886,9.9993315,9789.0185546875,9796.205078125,56.2803798986983,20.5850372427383,13.038077,0,0,0,40,4449,9.99,9792.61181640625,,,,,,,,,,,,,0,,,,0,,,,,,9.99931005,,,,
,23215192.035,9.9993277,9800.1650390625,-2.17404100488521E-5,4.19711427082989E-7,1,0.999253354069792,40.0298881530762,1.996674579488,16.669999808073,-0.000243029484286526,-5.09398933405402E-5,0.25,-6.57018445121462E-7,-2.16257032468038E-5,-7.72781494159037E-7,9.9993277,9.9993277,9796.294921875,9804.03515625,56.7431039820829,20.5788240013149,13.417728,0,0,0,40,4449,9.98975,9800.1650390625,,,,,,,,,,,,,0,,,,0,,,,,,9.9993277,,,,
,23215208.895,9.9989748,9378.31640625,-2.04341291979707E-5,4.38807917110418E-7,1,0.999253354069792,40.0298881530762,1.99653474643367,16.669999808073,-0.000227388757214544,-5.35716148287911E-5,0.25,-1.12513426214736E-6,-2.03228792934175E-5,-1.23067188857904E-6,9.9989748,9.9989748,9376.9326171875,9379.7001953125,56.4312342029098,20.5753865580051,12.658426,0,0,0,40,4449,9.9906,9378.31640625,,,,,,,,,,,,,0,,,,0,,,,,,9.9989748,,,,
,23215225.235,9.9989367,8971.8056640625,-1.84650380280902E-5,4.08531937949673E-7,1,0.999253354069792,40.0298881530762,1.99661595337462,16.669999808073,-0.000206109907015535,-4.4866667939699E-5,0.25,-7.02006877049986E-7,-1.83656510355174E-5,-7.98415548280742E-7,9.9989367,9.9989367,8967.9072265625,8975.7041015625,56.2772533846213,20.5757248966561,12.658426,0,0,0,40,4449,9.9889,8971.8056640625,,,,,,,,,,,,,0,,,,0,,,,,,9.9989367,,,,
,23215242.18,9.9989815,8546.98486328125,-1.78692072066E-5,3.63012330756854E-7,1,0.999253354069792,40.0298881530762,1.99663150908123,16.669999808073,-0.000199760726514779,-4.16971929219838E-5,0.25,-5.26808897880442E-7,-1.77732778319496E-5,-6.20317242856697E-7,9.9989815,9.9989815,8543.53125,8550.4384765625,56.3257143528137,20.5793666085083,13.038077,0,0,0,40,4449,9.99005,8546.98486328125,,,,,,,,,,,,,0,,,,-0.00245,,,,,,9.9989815,,,,
,23215258.625,9.9987621,8136.57177734375,-1.64016202697331E-5,3.63049535810565E-7,1,0.999253354069792,40.0298881530762,1.99674529256934,16.669999808073,-0.00018257808514116,-4.26563302305851E-5,0.25,-8.74025735037241E-7,-1.63109740911021E-5,-9.5729485629939E-7,9.9987621,9.9987621,8131.38427734375,8141.75927734375,56.2069068178906,20.5779708321373,12.658426,0,0,0,40,4449,9.9897,8136.57177734375,,,,,,,,,,,,,0,,,,0.00245,,,,,,9.9987621,,,,
,23215275.25,9.9999475,7722.64135742188,-1.52833089488736E-5,4.83635631017761E-7,1,0.999253354069792,40.0298881530762,1.99669854948554,16.669999808073,-0.000171607752183857,-3.13945486000617E-5,0.25,-7.1762749536467E-8,-1.52023424032943E-5,-1.52777708474962E-7,9.9999475,9.9999475,7717.94921875,7727.33349609375,56.4265444317944,20.5766949737905,12.658426,0,0,0,40,4449,9.9902,7722.64135742188,,,,,,,,,,,,,0,,,,0.00245,,,,,,9.9999475,,,,
,23215291.745,9.9999342,7310.74755859375,-1.41914772000594E-5,3.97455719637528E-7,1,0.999253354069792,40.0298881530762,1.99666700230087,16.669999808073,-0.000156776690778873,-4.35505012592762E-5,0.25,-1.34851347931347E-6,-1.41090707289194E-5,-1.41650974909934E-6,9.9999342,9.9999342,7308.130859375,7313.3642578125,56.4273260603137,20.576629238372,13.417728,0,0,0,40,4449,9.99015,7310.74755859375,,,,,,,,,,,,,0,,,,0.00245,,,,,,9.9999342,,,,
,23215308.48,9.9997578,6894.06860351562,-1.28703687318766E-5,3.99888157428015E-7,1,0.999253354069792,40.0298881530762,1.99666959906427,16.669999808073,-0.000142351469957894,-3.85222872965113E-5,0.25,-1.13679078048291E-6,-1.27957285910711E-5,-1.19848557268555E-6,9.9997578,9.9997578,6888.73681640625,6899.400390625,56.3413469231983,20.5773046413865,13.038077,0,0,0,40,4449,9.9895,6894.06860351562,,,,,,,,,,,,,0,,,,0.00245,,,,,,9.9997578,,,,
,23215324.21,10.000247,6499.22290039063,-1.11830539185223E-5,3.62565086272602E-7,1,0.999253354069792,40.0298881530762,1.99664359891709,16.669999808073,-0.00012409704848166,-3.11517580454523E-5,0.25,-7.8171134992454E-7,-1.11189851574988E-5,-8.36071627975004E-7,10.000247,10.000247,6494.0087890625,6504.43701171875,56.6829185861022,20.5778478315141,13.417728,0,0,0,40,4449,9.98965,6499.22290039063,,,,,,,,,,,,,0,,,,0,,,,,,10.000247,,,,
,23215341.175,10.000042,6077.08227539063,-1.05441902973239E-5,4.47199747698521E-7,1,0.999253354069792,40.0298881530762,1.99655779565487,16.669999808073,-0.000117463954027381,-2.67605357705796E-5,0.25,-5.051295113726E-7,-1.04846927018543E-5,-5.57288855028112E-7,10.000042,10.000042,6072.0556640625,6082.10888671875,56.2952308405636,20.5786571674935,12.658426,0,0,0,40,4449,9.98895,6077.08227539063,,,,,,,,,,,,,0,,,,-0.0049,,,,,,10.000042,,,,
,23215358.745,10.0003061,5637.1220703125,-9.32685937967612E-6,3.9397761596656E-7,1,0.999253354069792,40.0298881530762,1.99649737438067,16.669999808073,-0.000102822734373442,-2.97046948291389E-5,0.25,-9.84259546745424E-7,-9.27117596382114E-6,-1.02717107693648E-6,10.0003061,10.0003061,5632.103515625,5642.140625,56.2162863601213,20.5770462101914,13.038077,0,0,0,40,4449,9.98965,5637.1220703125,,,,,,,,,,,,,0,,,,0.0049,,,,,,10.0003061,,,,
,23215375.11,10.0004997,5227.37353515625,-8.48271729263606E-6,3.9309154230267E-7,1,0.999253354069792,40.0298881530762,1.99642852603021,16.669999808073,-9.39410147194635E-5,-2.45983599920991E-5,0.25,-6.80356805845177E-7,-8.43296492832626E-6,-7.20280883059395E-7,10.0004997,10.0004997,5225.1474609375,5229.599609375,56.8056342636214,20.5775650800588,12.658426,0,0,0,40,4449,9.98955,5227.37353515625,,,,,,,,,,,,,0,,,,0,,,,,,10.0004997,,,,
,23215392.405,10.0012779,4795.39184570313,-6.57088483594508E-6,3.71377546317818E-7,1,0.999253354069792,40.0298881530762,1.99640070362414,16.669999808073,-7.26216703414309E-5,-1.98632001026298E-5,0.25,-5.99285174231867E-7,-6.53180017037996E-6,-6.29597441572106E-7,10.0012779,10.0012779,4790.173828125,4800.60986328125,56.2538045290444,20.5774628705912,12.658426,0,0,0,40,4449,9.98805,4795.39184570313,,,,,,,,,,,,,0,,,,-0.00245,,,,,,10.0012779,,,,
,23215409.32,10.001236,4373.72680664063,-5.7324109513386E-6,3.09473878142776E-7,1,0.999253354069792,40.0298881530762,1.99648974571581,16.669999808073,-6.37524261413943E-5,-1.50992719687367E-5,0.25,-3.24526515907252E-7,-5.6991769984484E-6,-3.51878323603129E-7,10.001236,10.001236,4367.39306640625,4380.060546875,56.8634747740445,20.5778354973354,12.658426,0,0,0,40,4449,9.98925,4373.72680664063,,,,,,,,,,,,,0,,,,0,,,,,,10.001236,,,,
,23215426.14,10.0011654,3951.67248535156,-4.45139118954493E-6,4.09604854670091E-7,1,0.999253354069792,40.0298881530762,1.99652888386422,16.669999808073,-4.89382004459425E-5,-1.49144298894476E-5,0.25,-5.36036590680916E-7,-4.42403427704214E-6,-5.55565655399195E-7,10.0011654,10.0011654,3947.67626953125,3955.66870117188,56.3374387806021,20.5813622073617,12.658426,0,0,0,40,4449,9.98885,3951.67248535156,,,,,,,,,,,,,0,,,,-0.00245,,,,,,10.0011654,,,,
,23215443.32,10.0004358,3523.0732421875,-3.63960561747794E-6,3.64459824289948E-7,1,0.999253354069792,40.0298881530762,1.99628813040663,16.669999808073,-4.00019444667038E-5,-1.22265848914531E-5,0.25,-4.41394148326201E-7,-3.61713645916844E-6,-4.5722550346625E-7,10.0004358,10.0004358,3520.63647460937,3525.51000976562,57.0471574760637,20.5786301882538,12.658426,0,0,0,40,4449,9.9875,3523.0732421875,,,,,,,,,,,,,0,,,,-0.0049,,,,,,10.0004358,,,,
,23215461.1,10.0014791,3079.546875,-2.167633811144E-6,2.99217155665738E-7,1,0.999253354069792,40.0298881530762,1.99640200097217,16.669999808073,-2.28764260202445E-5,-1.26163011680183E-5,0.25,-7.37812634706428E-7,-2.15182865037633E-6,-7.44513780041264E-7,10.0014791,10.0014791,3075.6162109375,3083.4775390625,56.6735390438714,20.5763452649651,13.417728,0,0,0,40,4449,9.98815,3079.546875,,,,,,,,,,,,,0,,,,-0.0049,,,,,,10.0014791,,,,
,23215478.665,10.0010958,2640.75830078125,-7.96857351727877E-7,3.01164953909819E-7,1,0.999253354069792,40.0298881530762,1.99639321220596,16.669999808073,-8.68183715598288E-6,-3.10589920733722E-6,0.25,-1.34877245744322E-7,-7.91711298452089E-7,-1.38076522856311E-7,10.0010958,10.0010958,2635.88818359375,2645.62841796875,56.6938613853714,20.5780679987979,13.417728,0,0,0,40,4449,9.98835,2640.75830078125,,,,,,,,,,,,,0,,,,0.00245,,,,,,10.0010958,,,,
,23215495.415,10.0026722,2221.31579589844,2.58047517883036E-7,3.17088702477822E-7,1,0.999253354069792,40.0298881530762,1.99630261756684,16.669999808073,4.35326030903856E-6,-7.67194297620343E-6,0.25,-7.28879146967336E-7,2.60191485510676E-7,-7.23492776672775E-7,10.0026722,10.0026722,2218.48046875,2224.15112304687,56.4077853473329,20.5779368507348,13.038077,0,0,0,40,4449,9.987,2221.31579589844,,,,,,,,,,,,,0,,,,0,,,,,,10.0026722,,,,
,23215512.25,10.0028105,1800.22869873047,1.13633862002209E-6,2.49766603675352E-7,1,0.999253354069792,40.0298881530762,1.99645629670557,16.669999808073,1.32712586107563E-5,-5.85031925013503E-7,0.25,-2.53973778682525E-7,1.13114936754075E-6,-2.46952842274751E-7,10.0028105,10.0028105,1796.86535644531,1803.59204101562,56.1748600486021,20.5779748067988,13.038077,0,0,0,40,4449,9.9849,1800.22869873047,,,,,,,,,,,,,0,,,,0.00245,,,,,,10.0028105,,,,
,23215528.475,10.0035582,1393.87823486328,1.95011762285534E-6,3.3967609568192E-7,1,0.999253354069792,40.0298881530762,1.99647007837673,16.669999808073,2.27112366539508E-5,-6.45646767068433E-7,0.25,-4.03904720887781E-7,1.94100393552966E-6,-3.92075574359302E-7,10.0035582,10.0035582,1388.66442871094,1399.09204101562,56.3178980676213,20.5797484864862,12.658426,0,0,0,40,4449,9.9835,1393.87823486328,,,,,,,,,,,,,0,,,,0.0049,,,,,,10.0035582,,,,
,23215544.84,10.0045748,987.121002197266,3.2355423421197E-6,3.26119698653163E-7,1,0.999253354069792,40.0298881530762,1.99647460099497,16.669999808073,3.73603037850739E-5,7.3174442695198E-7,0.25,-5.09552026164655E-7,3.21955996964372E-6,-4.90903108297669E-7,10.0045748,10.0045748,984.866088867187,989.375915527344,56.2233210167944,20.5798897783786,12.658426,0,0,0,40,4449,9.9852,987.121002197266,,,,,,,,,,,,,0,,,,0,,,,,,10.0045748,,,,
,23215561.665,10.0046501,565.50244140625,3.17403930159592E-6,2.95472542449976E-7,1,0.999253354069792,40.0298881530762,1.99651968691293,16.669999808073,3.62615690786687E-5,2.90553728723099E-6,0.25,-3.05032649899434E-7,3.1573460356532E-6,-2.87913979797662E-7,10.0046501,10.0046501,561.908081054687,569.096801757812,56.5312826533714,20.5793162626688,12.658426,0,0,0,40,4449,9.9824,565.50244140625,,,,,,,,,,,,,0,,,,0,,,,,,10.0046501,,,,
,23215578.14,10.006773,153.424728393555,2.48984099536726E-6,2.68662882938334E-7,1,0.999253354069792,40.0298881530762,1.99600502619101,16.669999808073,2.85364949501023E-5,1.72112935166763E-6,0.25,-2.88876861319684E-7,2.4769419560717E-6,-2.75205595842111E-7,10.0065384,10.0070076,149.866958618164,156.982498168945,56.567237565256,20.5731648742282,13.038077,0,0,0,40,4449,9.98145,153.424728393555,,,,,,,,,,,,,0,,,,0.00245,,,,,,10.006773,,,,
,23215594.52,10.008513,-255.215278625488,2.89812066634659E-7,2.76966365599425E-7,1,0.999253354069792,40.0298881530762,1.99579298577411,16.669999808073,4.14341550499708E-6,-4.42938488985531E-6,0.25,-4.45935590096892E-7,2.90302799127812E-7,-4.41977800861827E-7,10.008112,10.008914,-260.135101318359,-250.295455932617,56.6031924771406,20.5763270260142,13.417728,0,0,0,40,4449,9.98105,-255.215278625488,,,,,,,,,,,,,0,,,,0.0049,,,,,,10.008513,,,,
,23215611.5,10.000267,-679.78125,-4.31199424875432E-7,2.58334098923052E-7,1,0.999253354069792,40.0298881530762,1.99547864675314,16.669999808073,-4.32625889203692E-6,-3.75889366674458E-6,0.25,-2.58221191819547E-7,-4.27480945737168E-7,-2.58835054099527E-7,10.000267,10.000267,-684.761657714844,-674.800842285156,56.5625477941406,20.5785800594311,13.038077,0,0,0,40,4449,9.9807,-679.78125,,,,,,,,,,,,,0,,,,0,,,,,,10.000267,,,,
,23215628.375,10.0014286,-1101.51721191406,-4.32341370011515E-7,2.89953590307461E-7,1,0.999253354069792,40.0298881530762,1.99525932312242,16.669999808073,-4.33691235009849E-6,-3.77058941282918E-6,0.25,-2.5907998713241E-7,-4.28614762775188E-7,-2.59709296528639E-7,10.0014286,10.0014286,-1104.17321777344,-1098.86120605469,56.4679707433137,20.5786538533374,13.417728,0,0,0,40,4449,9.9829,-1101.51721191406,,,,,,,,,,,,,0,,,,0,,,,,,10.0014286,,,,
,23215644.785,9.9987364,-1509.41467285156,6.07258141302273E-7,3.19170557403937E-7,1,0.999253354069792,40.0298881530762,1.99505381767821,16.669999808073,7.09914205047429E-6,-3.79346345429259E-7,0.25,-1.41673850464862E-7,6.04502462321421E-7,-1.37896618295669E-7,9.9987364,9.9987364,-1512.72204589844,-1506.10729980469,56.4273260603137,20.5810215000349,13.038077,0,0,0,40,4449,9.9829,-1509.41467285156,,,,,,,,,,,,,0,,,,0,,,,,,9.9987364,,,,
,23215662.805,9.998045,-1960.13757324219,1.51294648683371E-6,2.64437218211901E-7,1,0.999253354069792,40.0298881530762,1.99494340666853,16.669999808073,1.81102668944691E-5,-3.32906861635386E-6,0.25,-5.65398432011568E-7,1.50717245873219E-6,-5.54753319960769E-7,9.998045,9.998045,-1965.06066894531,-1955.21447753906,56.0130629451213,20.5824426324913,13.417728,0,0,0,40,4449,9.9861,-1960.13757324219,,,,,,,,,,,,,0,,,,0.0049,,,,,,9.998045,,,,
,23215681,9.9965744,-2414.12036132813,3.12934504077768E-6,2.84867783557938E-7,1,0.999253354069792,40.0298881530762,1.99505267751644,16.669999808073,3.54821428052549E-5,4.25577043925579E-6,0.25,-1.77001156170549E-7,3.11260152369228E-6,-1.60511092460695E-7,9.9965744,9.9965744,-2416.73901367187,-2411.50170898438,56.5133051974291,20.5838752841911,13.038077,0,0,0,40,4449,9.98545,-2414.12036132813,,,,,,,,,,,,,0,,,,0,,,,,,9.9965744,,,,
,23215698.12,9.9965048,-2840.99255371094,3.8312030497566E-6,2.45449980773372E-7,1,0.999253354069792,40.0298881530762,1.99512441035396,16.669999808073,4.35291819486062E-5,4.72472259626308E-6,0.25,-2.6008526108039E-7,3.81102158467581E-6,-2.39552491712773E-7,9.9965048,9.9965048,-2846.17065429687,-2835.814453125,56.6141352764098,20.583255227706,12.658426,0,0,0,40,4449,9.98685,-2840.99255371094,,,,,,,,,,,,,0,,,,0.00245,,,,,,9.9965048,,,,
,23215716.4,9.9966621,-3298.84765625,5.18291244570654E-6,3.32784500175526E-7,1,0.999253354069792,40.0298881530762,1.99507797981664,16.669999808073,5.825345616247E-5,9.958010156351E-6,0.25,-3.43347466722002E-8,5.15417405813294E-6,-8.18022544181655E-9,9.9966621,9.9966621,-3303.927734375,-3293.767578125,56.5093970548329,20.5830154453072,13.038077,0,0,0,40,4449,9.98825,-3298.84765625,,,,,,,,,,,,,0,,,,0,,,,,,9.9966621,,,,
,23215735.03,9.9961023,-3765.13061523438,6.30554254393502E-6,3.26363239395107E-7,1,0.999253354069792,40.0298881530762,1.99498173309948,16.669999808073,7.16584031751208E-5,7.68120849117126E-6,0.25,-4.3690434826955E-7,6.27275581478297E-6,-4.02693124649961E-7,9.9961023,9.9961023,-3766.51220703125,-3763.7490234375,56.7696793517368,20.5868146955539,12.658426,0,0,0,40,4449,9.9895,-3765.13061523438,,,,,,,,,,,,,0,,,,0.00245,,,,,,9.9961023,,,,
,23215754.01,9.9953146,-4239.75537109375,7.46324903918004E-6,3.49801537433981E-7,1,0.999253354069792,40.0298881530762,1.99499215530641,16.669999808073,8.40210207042006E-5,1.35745974015229E-5,0.25,-1.1806150849711E-7,7.42266208346933E-6,-7.95415923967427E-8,9.9953146,9.9953146,-4243.70556640625,-4235.80517578125,56.7415407250445,20.5828110413467,13.417728,0,0,0,40,4449,9.9898,-4239.75537109375,,,,,,,,,,,,,0,,,,-0.0049,,,,,,9.9953146,,,,
,23215772.885,9.995388,-4711.34692382812,8.71886001145808E-6,3.26307900176693E-7,1,0.999253354069792,40.0298881530762,1.99503032697975,16.669999808073,9.81850396387318E-5,1.57272619874032E-5,0.25,-1.49962894321568E-7,8.67178168004163E-6,-1.0461165050083E-7,9.995388,9.995388,-4713.80517578125,-4708.888671875,56.4710972573906,20.5831106552576,13.038077,0,0,0,40,4449,9.9912,-4711.34692382812,,,,,,,,,,,,,0,,,,0.00245,,,,,,9.995388,,,,
,23215791.77,9.9946356,-5182.48291015625,1.00596324478749E-5,3.60204770053064E-7,1,0.999253354069792,40.0298881530762,1.99497022306806,16.669999808073,0.000113148295355292,1.8909925783142E-5,0.25,-1.05303155410611E-7,1.00052920311326E-5,-5.30157707558212E-8,9.9946356,9.9946356,-5186.16455078125,-5178.80126953125,56.3655774072944,20.5879500969739,13.038077,0,0,0,40,4449,9.9921,-5182.48291015625,,,,,,,,,,,,,0,,,,0,,,,,,9.9946356,,,,
,23215809.905,9.9944563,-5637.20043945313,1.11877399191035E-5,2.85245377742505E-7,1,0.999253354069792,40.0298881530762,1.9948413587953,16.669999808073,0.000125309530394545,2.39731568815625E-5,0.25,1.44694141679466E-7,1.11263060191583E-5,2.01786634393102E-7,9.9944563,9.9944563,-5638.32568359375,-5636.0751953125,56.5406621956021,20.5875902895104,12.658426,0,0,0,40,4449,9.9926,-5637.20043945313,,,,,,,,,,,,,0,,,,0,,,,,,9.9944563,,,,
,23215828.105,9.9942913,-6091.0146484375,1.23903525052405E-5,3.69807951902992E-7,1,0.999253354069792,40.0298881530762,1.99474800421788,16.669999808073,0.000138890775160912,2.59147015479964E-5,0.25,1.03269713363179E-7,1.23230019325946E-5,1.67218535668376E-7,9.9942913,9.9942913,-6098.5048828125,-6083.5244140625,56.5234663681791,20.5907537547087,12.658426,0,0,0,40,4449,9.9936,-6091.0146484375,,,,,,,,,,,,,0,,,,0,,,,,,9.9942913,,,,
,23215845.57,9.9947386,-6528.15161132813,1.38727332798351E-5,3.89416592183942E-7,1,0.999253354069792,40.0298881530762,1.99497959202015,16.669999808073,0.000155358983072592,2.99787371872441E-5,0.25,2.00638774694202E-7,1.37973105954309E-5,2.72227848581776E-7,9.9947386,9.9947386,-6531.05810546875,-6525.2451171875,56.3890262628713,20.5879459400149,12.658426,0,0,0,40,4449,9.9956,-6528.15161132813,,,,,,,,,,,,,0,,,,0,,,,,,9.9947386,,,,
,23215864.255,9.9947929,-6994.35693359375,1.49771017460023E-5,4.11846730700261E-7,1,0.999253354069792,40.0298881530762,1.99479426761385,16.669999808073,0.00016720412449928,3.52468298097234E-5,0.25,4.72919998913974E-7,1.48948255782729E-5,5.4936108300223E-7,9.9947929,9.9947929,-7000.41943359375,-6988.29443359375,56.269437099429,20.5882154023031,13.038077,0,0,0,40,4449,9.99605,-6994.35693359375,,,,,,,,,,,,,0,,,,-0.00245,,,,,,9.9947929,,,,
,23215882.14,9.9947042,-7441.50830078125,1.58515453479475E-5,4.09555770947675E-7,1,0.999253354069792,40.0298881530762,1.99479840512915,16.669999808073,0.00017775635340762,3.29041606716165E-5,0.25,1.07947951404267E-7,1.57670574685836E-5,1.91467776495719E-7,9.9947042,9.9947042,-7445.22216796875,-7437.79443359375,56.3421285517175,20.5878891259587,13.417728,0,0,0,40,4449,9.99735,-7441.50830078125,,,,,,,,,,,,,0,,,,-0.00245,,,,,,9.9947042,,,,
,23215900.53,9.9934111,-7901.04663085938,1.73550091838427E-5,3.50264324706231E-7,1,0.999253354069792,40.0298881530762,1.9948442313329,16.669999808073,0.000195698365070102,3.00115876269528E-5,0.25,-4.18156316050502E-7,1.72659684500497E-5,-3.23302313852566E-7,9.9934111,9.9934111,-7904.31005859375,-7897.783203125,56.7165286124291,20.5860085244656,13.038077,0,0,0,40,4449,9.998,-7901.04663085938,,,,,,,,,,,,,0,,,,0,,,,,,9.9934111,,,,
,23215918.81,9.99445865,-8358.642578125,1.87757572206449E-5,3.45372428167177E-7,1,0.999253354069792,40.0298881530762,1.99490367743692,16.669999808073,0.000210463194842015,3.95967101605675E-5,0.25,1.81617622080353E-7,1.86766937143862E-5,2.81543328531349E-7,9.9943552,9.9945621,-8362.9345703125,-8354.3505859375,56.5539498804291,20.5864937143654,13.038077,0,0,0,40,4449,9.9993,-8358.642578125,,,,,,,,,,,,,0,,,,-0.0049,,,,,,9.99445865,,,,
,23215937.115,9.9944429,-8815.70654296875,2.00663186522568E-5,4.41167541442277E-7,1,0.999253354069792,40.0298881530762,1.99495677631629,16.669999808073,0.000225670260221452,3.82404609343336E-5,0.25,-1.69959888613705E-7,1.99631196849451E-5,-6.05915506278327E-8,9.9944429,9.9944429,-8819.1455078125,-8812.267578125,56.6031924771406,20.5834943379315,12.658426,0,0,0,40,4449,10.0005,-8815.70654296875,,,,,,,,,,,,,0,,,,0.00245,,,,,,9.9944429,,,,
,23215955.56,9.9940653,-9276.05517578125,2.06068463282809E-5,4.51890450281376E-7,1,0.999253354069792,40.0298881530762,1.99488251662742,16.669999808073,0.000232053192932564,3.75663419082205E-5,0.25,-3.27009645637333E-7,2.05024496710156E-5,-2.13214008558286E-7,9.9940653,9.9940653,-9282.35546875,-9269.7548828125,56.0185343447559,20.5836095683487,13.038077,0,0,0,40,4449,10.00085,-9276.05517578125,,,,,,,,,,,,,0,,,,0.00245,,,,,,9.9940653,,,,
,23215974.445,9.9935608,-9749.9482421875,2.22035724614281E-5,4.22737750387283E-7,1,0.999253354069792,40.0298881530762,1.99496994868625,16.669999808073,0.000248092389597824,5.14854942707071E-5,0.25,6.26838962051132E-7,2.20865768926038E-5,7.45209038160368E-7,9.9935608,9.9935608,-9754.5537109375,-9745.3427734375,56.6297678467945,20.584394562043,12.658426,0,0,0,40,4449,10.00185,-9749.9482421875,,,,,,,,,,,,,0,,,,0,,,,,,9.9935608,,,,
,23216012.79,9.9953709,-9837.59619140625,2.20287336151916E-5,3.93476817106646E-7,1,0.999253354069792,40.0298881530762,1.99510340355286,16.669999808073,0.000247477387977689,4.36722224383003E-5,0.25,-3.81617620056606E-8,2.19164289474523E-5,8.27947394404994E-8,9.9953709,9.9953709,-9839.0029296875,-9836.189453125,56.5195582255829,20.5827394285312,12.278775,0,0,0,40,4449,10.0038,-9837.59619140625,,,,,,,,,,,,,0,,,,0.0049,,,,,,9.9953709,,,,
,23216031,9.9961987,-9383.70166015625,2.06397442970548E-5,4.2340599809352E-7,1,0.999253354069792,40.0298881530762,1.9951952044845,16.669999808073,0.000231927857145681,4.0620735500121E-5,0.25,-6.16051296124095E-8,2.05339109755073E-5,5.11658848942255E-8,9.9961987,9.9961987,-9389.8037109375,-9377.599609375,56.3264959813329,20.5823783993643,12.278775,0,0,0,40,4449,10.003,-9383.70166015625,,,,,,,,,,,,,0,,,,-0.00245,,,,,,9.9961987,,,,
,23216049.84,9.9952803,-8914.04052734375,1.98043318136004E-5,4.63168280959483E-7,1,0.999253354069792,40.0298881530762,1.99492017868883,16.669999808073,0.000221718097738341,4.3373404225645E-5,0.25,3.3371827822273E-7,1.96999191480825E-5,4.39203442494689E-7,9.9952803,9.9952803,-8915.1494140625,-8912.931640625,56.2936675835252,20.5838799376826,13.038077,0,0,0,40,4449,10.00415,-8914.04052734375,,,,,,,,,,,,,0,,,,0.0049,,,,,,9.9952803,,,,
,23216068.055,9.9973097,-8458.63134765625,1.78708954766068E-5,4.13090218142992E-7,1,0.999253354069792,40.0298881530762,1.99492443169405,16.669999808073,0.000200370882144086,3.74251424207726E-5,0.25,1.49226830870097E-7,1.77768699186387E-5,2.44593550420468E-7,9.9973097,9.9973097,-8463.75,-8453.5126953125,56.262402442756,20.5857340263847,12.658426,0,0,0,40,4449,10.00365,-8458.63134765625,,,,,,,,,,,,,0,,,,0.00245,,,,,,9.9973097,,,,
,23216086.655,9.9965382,-7994.19946289063,1.66323915585083E-5,3.46674098368339E-7,1,0.999253354069792,40.0298881530762,1.9949874128233,16.669999808073,0.000186159345055061,3.66515586210419E-5,0.25,3.01563099348176E-7,1.65434244716721E-5,3.88890545895226E-7,9.9965382,9.9965382,-7996.6015625,-7991.79736328125,56.3593243791406,20.5845517932707,12.278775,0,0,0,40,4449,10.00345,-7994.19946289063,,,,,,,,,,,,,0,,,,0.00245,,,,,,9.9965382,,,,
,23216105.44,9.9980221,-7524.93090820312,1.6105560866441E-5,4.66988179174044E-7,1,0.999253354069792,40.0298881530762,1.99500240018637,16.669999808073,0.000180311483266246,3.51875807058728E-5,0.25,2.65668789405169E-7,1.60189904736107E-5,3.49801774860773E-7,9.9980221,9.9980221,-7530.2734375,-7519.58837890625,56.4804767996214,20.5858731138653,13.038077,0,0,0,40,4449,10.0061,-7524.93090820312,,,,,,,,,,,,,0,,,,-0.00245,,,,,,9.9980221,,,,
,23216124.17,9.9977865,-7058.0283203125,1.4439002238623E-5,3.41567457808545E-7,1,0.999253354069792,40.0298881530762,1.995026809138,16.669999808073,0.000162707000615493,2.56071172346559E-5,0.25,-2.90220106149656E-7,1.43636848719722E-5,-2.12484588512398E-7,9.9977865,9.9977865,-7062.5673828125,-7053.4892578125,56.3053920113137,20.5858310758091,13.038077,0,0,0,40,4449,10.00395,-7058.0283203125,,,,,,,,,,,,,0,,,,0.00245,,,,,,9.9977865,,,,
,23216141.45,9.998477,-6626.24145507812,1.31885853147746E-5,3.84096951716772E-7,1,0.999253354069792,40.0298881530762,1.9950796630451,16.669999808073,0.000147543279322038,2.94126737982722E-5,0.25,2.71765621398999E-7,1.31165494811881E-5,3.39486276390759E-7,9.998477,9.998477,-6630.76806640625,-6621.71484375,56.506270540756,20.5847800719091,13.038077,0,0,0,40,4449,10.0041,-6626.24145507812,,,,,,,,,,,,,0,,,,-0.00245,,,,,,9.998477,,,,
,23216159.56,9.9982471,-6173.9375,1.18637373943451E-5,4.09209765145811E-7,1,0.999253354069792,40.0298881530762,1.99524458704726,16.669999808073,0.000133687550350998,2.10687012608526E-5,0.25,-2.35203550467166E-7,1.18010600002201E-5,-1.72101107937611E-7,9.9982471,9.9982471,-6179.22900390625,-6168.64599609375,56.3053920113137,20.5839539412339,12.658426,0,0,0,40,4449,10.0051,-6173.9375,,,,,,,,,,,,,0,,,,0.00245,,,,,,9.9982471,,,,
,23216177.22,9.9994688,-5732.95336914063,1.02046049810622E-5,3.75194977932079E-7,1,0.999253354069792,40.0298881530762,1.99545870590354,16.669999808073,0.000114878291779291,1.88050191078045E-5,0.25,-1.41299301622205E-7,1.01500525345502E-5,-8.7671976363477E-8,9.9994688,9.9994688,-5736.90478515625,-5729.001953125,56.5766171074867,20.5825956616283,12.658426,0,0,0,40,4449,10.005,-5732.95336914063,,,,,,,,,,,,,0,,,,0,,,,,,9.9994688,,,,
,23216195.705,9.9986496,-5270.83862304687,9.14182787287716E-6,4.30840951815371E-7,1,0.999253354069792,40.0298881530762,1.99519654278464,16.669999808073,0.000102514353436658,1.8999149585563E-5,0.25,6.56742532338851E-8,9.09167051628202E-6,1.12368939600663E-7,9.9985533,9.9987459,-5273.96240234375,-5267.71484375,56.4992358840829,20.5852071043678,12.658426,0,0,0,40,4449,10.00485,-5270.83862304687,,,,,,,,,,,,,0,,,,0,,,,,,9.9986496,,,,
,23216214.59,9.9996777,-4798.9609375,8.24617548165727E-6,3.31277359858936E-7,1,0.999253354069792,40.0298881530762,1.99501928785345,16.669999808073,9.13358088303653E-5,2.34552869315799E-5,0.25,6.22411861442646E-7,8.19779074371775E-6,6.61165480411629E-7,9.9996777,9.9996777,-4802.3193359375,-4795.6025390625,56.6313311038329,20.5865412365481,13.038077,0,0,0,40,4449,10.00445,-4798.9609375,,,,,,,,,,,,,0,,,,-0.00245,,,,,,9.9996777,,,,
,23216233.29,10.0009394,-4331.34790039063,6.64057641193525E-6,3.66659450306695E-7,1,0.999253354069792,40.0298881530762,1.99505762956632,16.669999808073,7.42241875111194E-5,1.51039433681054E-5,0.25,1.64374049134817E-7,6.6031348595589E-6,1.97204617932269E-7,10.0009394,10.0009394,-4334.94873046875,-4327.7470703125,57.0385595623522,20.5861916435173,12.278775,0,0,0,40,4449,10.0053,-4331.34790039063,,,,,,,,,,,,,0,,,,0,,,,,,10.0009394,,,,
,23216251.97,10.0005455,-3865.0908203125,4.94960738238292E-6,3.08459456504961E-7,1,0.999253354069792,40.0298881530762,1.99506572106692,16.669999808073,5.59859783156666E-5,7.52431107001935E-6,0.25,-2.09858777481391E-7,4.92323292698253E-6,-1.83710090714116E-7,10.0005455,10.0005455,-3867.50634765625,-3862.67529296875,56.7102755842752,20.5841716166936,12.278775,0,0,0,40,4449,10.004,-3865.0908203125,,,,,,,,,,,,,0,,,,0,,,,,,10.0005455,,,,
,23216271.54,10.0011301,-3375.47045898438,4.06265775586631E-6,3.09068715577111E-7,1,0.999253354069792,40.0298881530762,1.99533450145931,16.669999808073,4.57793133082467E-5,7.18135011129456E-6,0.25,-8.26264114487086E-8,4.04042962814533E-6,-6.17936235172083E-8,10.0011301,10.0011301,-3377.82202148438,-3373.11889648438,56.7751507513714,20.5807904224068,13.038077,0,0,0,40,4449,10.0029,-3375.47045898438,,,,,,,,,,,,,0,,,,0.0049,,,,,,10.0011301,,,,
,23216290.38,10.0017757,-2904.30541992188,2.44419178902136E-6,2.62673703729953E-7,1,0.999253354069792,40.0298881530762,1.99548074897708,16.669999808073,2.74479010143024E-5,4.85591081243719E-6,0.25,-1.96156859745232E-9,2.4305094632348E-6,1.02287985666145E-8,10.0017757,10.0017757,-2910.51391601562,-2898.09692382812,56.8243933480829,20.5824896068069,12.278775,0,0,0,40,4449,10.00185,-2904.30541992188,,,,,,,,,,,,,0,,,,-0.00245,,,,,,10.0017757,,,,
,23216309.225,10.0021229,-2433.14025878906,1.72448630146807E-6,2.60105435189101E-7,1,0.999253354069792,40.0298881530762,1.99543613616128,16.669999808073,1.96524409794457E-5,1.80709573173967E-6,0.25,-1.45509074928352E-7,1.71549899851968E-6,-1.36149863565941E-7,10.0021229,10.0021229,-2438.14965820313,-2428.130859375,56.3874630058329,20.5797403367561,13.038077,0,0,0,40,4449,10.00115,-2433.14025878906,,,,,,,,,,,,,0,,,,0.00245,,,,,,10.0021229,,,,
,23216327.685,10.0047455,-1972.4130859375,4.29281653576952E-7,2.80626775636438E-7,1,0.999253354069792,40.0298881530762,1.99527208927598,16.669999808073,5.60046768778865E-6,-3.53967971484589E-6,0.25,-3.9156754838936E-7,4.28781682573198E-7,-3.87239725475886E-7,10.0047455,10.0047455,-1978.67358398438,-1966.15258789062,57.0182372208522,20.5814999529284,12.278775,0,0,0,40,4449,10.00055,-1972.4130859375,,,,,,,,,,,,,0,,,,-0.00245,,,,,,10.0047455,,,,
,23216345.695,10.0029945,-1522.26531982422,-9.34362344420495E-7,2.68336027904219E-7,1,0.999253354069792,40.0298881530762,1.99550183699589,16.669999808073,-9.41542254410637E-6,-7.91641294584958E-6,0.25,-5.39090790111636E-7,-9.26416593854248E-7,-5.4060358285956E-7,10.0029945,10.0029945,-1523.49438476562,-1521.03625488281,56.3280592383713,20.579671853919,12.658426,0,0,0,40,4449,9.9988,-1522.26531982422,,,,,,,,,,,,,0,,,,-0.00245,,,,,,10.0029945,,,,
,23216364.715,10.0045223,-1046.13677978516,-1.73970689942176E-6,2.96802518573978E-7,1,0.999253354069792,40.0298881530762,1.99541545513143,16.669999808073,-1.85951288006194E-5,-8.74177413015552E-6,0.25,-4.69627855383984E-7,-1.72749897029301E-6,-4.7541920223551E-7,10.0045223,10.0045223,-1048.98193359375,-1043.29162597656,56.6360208749483,20.5784898312075,13.038077,0,0,0,40,4449,9.9969,-1046.13677978516,,,,,,,,,,,,,0,,,,0,,,,,,10.0045223,,,,
,23216383.445,10.0053759,-577.77099609375,-2.22840261329358E-6,2.81433843922599E-7,1,0.999253354069792,40.0298881530762,1.99545687943275,16.669999808073,-2.4018318216598E-5,-1.00737388916643E-5,0.25,-5.01518125492927E-7,-2.21321746568852E-6,-5.09441212932101E-7,10.0053759,10.0053759,-583.844177246094,-571.697814941406,56.5305010248521,20.578970105246,12.278775,0,0,0,40,4449,9.99665,-577.77099609375,,,,,,,,,,,,,0,,,,0,,,,,,10.0053759,,,,
,23216401.63,10.0069151,-124.298889160156,-1.64494948927397E-6,2.35149345218302E-7,1,0.999253354069792,40.0298881530762,1.99561891377604,16.669999808073,-1.77548340801647E-5,-7.30160257823932E-6,0.25,-3.58213950946758E-7,-1.63377729393098E-6,-3.64092073141842E-7,10.0069151,10.0069151,-126.877182006836,-121.720596313477,56.6219515616021,20.581233947642,12.658426,0,0,0,40,4449,9.99385,-124.298889160156,,,,,,,,,,,,,0,,,,0.0049,,,,,,10.0069151,,,,
,23216419.43,10.0096998,320.163986206055,2.37142585380266E-7,3.0536617204187E-7,1,0.999253354069792,40.0298881530762,1.99549441737057,16.669999808073,2.95529740717149E-6,-1.17637431574083E-6,0.25,-1.4689277615001E-7,2.36492412124963E-7,-1.44904607752801E-7,10.0096998,10.0096998,317.837677001953,322.490295410156,56.5797436215637,20.5788999680131,13.038077,0,0,0,40,4449,9.99425,320.163986206055,,,,,,,,,,,,,0,,,,-0.00245,,,,,,10.0096998,,,,
,23216437.54,10.0023422,773.789123535156,1.32930509855995E-6,2.73986666289083E-7,1,0.999253354069792,40.0298881530762,1.99548927926575,16.669999808073,1.6299992741572E-5,-5.09411351927237E-6,0.25,-6.89822579750808E-7,1.32505546696285E-6,-6.79427657986424E-7,10.0023422,10.0023422,770.175476074219,777.402770996094,56.5742722219291,20.5791399923349,13.038077,0,0,0,40,4449,9.9946,773.789123535156,,,,,,,,,,,,,0,,,,0.0049,,,,,,10.0023422,,,,
,23216455.845,10.0018654,1230.21380615234,6.45354097694575E-7,2.36654356026134E-7,1,0.999253354069792,40.0298881530762,1.99536242652991,16.669999808073,8.50670541695472E-6,-5.81447113414875E-6,0.25,-6.32547964529164E-7,6.44765479363076E-7,-6.2579766534733E-7,10.0018654,10.0018654,1226.43420410156,1233.99340820312,56.5711457078521,20.5798001054998,13.038077,0,0,0,40,4449,9.99535,1230.21380615234,,,,,,,,,,,,,0,,,,-0.00245,,,,,,10.0018654,,,,
,23216474.1,9.9998426,1684.58801269531,-4.02938627730359E-7,3.32664741504571E-7,1,0.999253354069792,40.0298881530762,1.99551307553694,16.669999808073,-3.85805436478493E-6,-4.55278284063189E-6,0.25,-3.33905583746521E-7,-3.99015691351148E-7,-3.339886977439E-7,9.9998426,9.9998426,1680.81567382813,1688.3603515625,56.5117419403906,20.5786714092632,12.278775,0,0,0,40,4449,9.99705,1684.58801269531,,,,,,,,,,,,,0,,,,-0.00245,,,,,,9.9998426,,,,
,23216492.9,10.0002623,2153.6865234375,-1.67552042822609E-6,2.59400349667328E-7,1,0.999253354069792,40.0298881530762,1.99552763916908,16.669999808073,-1.78478145499078E-5,-8.7742218411659E-6,0.25,-4.8372633355176E-7,-1.66367478088417E-6,-4.89263355647399E-7,10.0002623,10.0002623,2149.89038085938,2157.48266601562,56.7173102409483,20.5804375002965,13.038077,0,0,0,40,4449,9.9967,2153.6865234375,,,,,,,,,,,,,0,,,,0.00245,,,,,,10.0002623,,,,
,23216511.04,9.9980164,2607.54089355469,-2.60548343938883E-6,3.29082075750148E-7,1,0.999253354069792,40.0298881530762,1.99561708240841,16.669999808073,-2.83008886521992E-5,-1.05765292973977E-5,0.25,-4.7885915980302E-7,-2.58846544366463E-6,-4.89100647250521E-7,9.9980164,9.9980164,2603.51611328125,2611.56567382813,56.2842880412944,20.5780657480548,12.278775,0,0,0,40,4449,9.9976,2607.54089355469,,,,,,,,,,,,,0,,,,0.00245,,,,,,9.9980164,,,,
,23216529.135,9.9978313,3059.56213378906,-3.32811671957897E-6,3.62950384834572E-7,1,0.999253354069792,40.0298881530762,1.99546553481947,16.669999808073,-3.62631464339489E-5,-1.28633031309545E-5,0.25,-5.54039704217729E-7,-3.30673748272767E-6,-5.67559476801399E-7,9.9978313,9.9978313,3053.26586914063,3065.8583984375,56.4632809721983,20.5798072909671,12.658426,0,0,0,40,4449,9.9979,3059.56213378906,,,,,,,,,,,,,0,,,,0,,,,,,9.9978313,,,,
,23216546.58,9.9969492,3494.75244140625,-4.94340846574539E-6,3.18372713884343E-7,1,0.999253354069792,40.0298881530762,1.99544474251763,16.669999808073,-5.433972917347E-5,-1.64308622563785E-5,0.25,-5.84481869562826E-7,-4.91295822789296E-6,-6.06057518128766E-7,9.9969492,9.9969492,3493.0986328125,3496.40625,56.2944492120444,20.5810021846787,12.658426,0,0,0,40,4449,9.9992,3494.75244140625,,,,,,,,,,,,,0,,,,-0.0049,,,,,,9.9969492,,,,
,23216564.95,9.9982004,3954.86608886719,-6.26847351815335E-6,3.4594436397128E-7,1,0.999253354069792,40.0298881530762,1.99554002620349,16.669999808073,-6.98528318168916E-5,-1.55355497989717E-5,0.25,-2.6887181419551E-7,-6.23240672669253E-6,-2.99065100304673E-7,9.9982004,9.9982004,3951.31372070313,3958.41845703125,56.6274229612368,20.578278515734,12.658426,0,0,0,40,4449,10.0012,3954.86608886719,,,,,,,,,,,,,0,,,,-0.0049,,,,,,9.9982004,,,,
,23216583.67,9.9959993,4423.90673828125,-7.70534665541587E-6,4.13979086913851E-7,1,0.999253354069792,40.0298881530762,1.99532295809341,16.669999808073,-8.52599119827269E-5,-2.24595560834639E-5,0.25,-6.29881368608268E-7,-7.6597132680697E-6,-6.65609071350129E-7,9.9959993,9.9959993,4421.28125,4426.5322265625,56.333530638006,20.5779988814143,12.278775,0,0,0,40,4449,10.0009,4423.90673828125,,,,,,,,,,,,,0,,,,0,,,,,,9.9959993,,,,
,23216601.895,9.996336,4878.84204101562,-8.64990696778564E-6,3.36397920783238E-7,1,0.999253354069792,40.0298881530762,1.99549792105471,16.669999808073,-9.56783748316154E-5,-2.54618889886668E-5,0.25,-7.2874987881341E-7,-8.59880770006861E-6,-7.69037942289133E-7,9.996336,9.996336,4876.08056640625,4881.603515625,56.2717819849867,20.5799955918771,12.658426,0,0,0,40,4449,10.0028,4878.84204101562,,,,,,,,,,,,,0,,,,0.00245,,,,,,9.996336,,,,
,23216620.5,9.9957323,5343.82104492188,-9.90161745652969E-6,3.10016639925656E-7,1,0.999253354069792,40.0298881530762,1.9955060252735,16.669999808073,-0.000109993945859821,-2.65252189712891E-5,0.25,-6.00374082090192E-7,-9.84461399433928E-6,-6.4812027061055E-7,9.9957323,9.9957323,5341.12548828125,5346.5166015625,56.3288408668906,20.5783562116695,12.658426,0,0,0,40,4449,10.0019,5343.82104492188,,,,,,,,,,,,,0,,,,0.00245,,,,,,9.9957323,,,,
,23216638.975,9.9961424,5804.69189453125,-1.11647327034377E-5,3.5833422844187E-7,1,0.999253354069792,40.0298881530762,1.99545515229777,16.669999808073,-0.000123555454226421,-3.25547437929368E-5,0.25,-9.12177225481354E-7,-1.10995729313882E-5,-9.65133354376418E-7,9.9961424,9.9961424,5798.26220703125,5811.12158203125,56.4796951711021,20.581087385905,12.278775,0,0,0,40,4449,10.0035,5804.69189453125,,,,,,,,,,,,,0,,,,-0.0049,,,,,,9.9961424,,,,
,23216657,9.9959049,6255.95483398438,-1.24370950322164E-5,3.35899711048285E-7,1,0.999253354069792,40.0298881530762,1.99546442771224,16.669999808073,-0.000138341800526877,-3.23277358929977E-5,0.25,-6.65035910479878E-7,-1.23667060229099E-5,-7.26355774764621E-7,9.9959049,9.9959049,6253.44091796875,6258.46875,56.3382204091213,20.5784664453107,12.658426,0,0,0,40,4449,10.0039,6255.95483398438,,,,,,,,,,,,,0,,,,0,,,,,,9.9959049,,,,
,23216673.6,9.9957838,6671.04321289063,-1.35556468893866E-5,3.54192196173301E-7,1,0.999253354069792,40.0298881530762,1.99546479500547,16.669999808073,-0.000150863944387909,-3.48104656387745E-5,0.25,-6.86526328815766E-7,-1.34795123002988E-5,-7.53998309924073E-7,9.9957838,9.9957838,6668.17431640625,6673.912109375,56.5758354789675,20.5777641629952,12.278775,0,0,0,40,4449,10.00445,6671.04321289063,,,,,,,,,,,,,0,,,,0,,,,,,9.9957838,,,,
,23216691.055,9.9957829,7106.48706054687,-1.46945668232484E-5,3.33271968340175E-7,1,0.999253354069792,40.0298881530762,1.99539296089207,16.669999808073,-0.000164020247636481,-3.5030114178373E-5,0.25,-5.02879753285808E-7,-1.46137551075302E-5,-5.7779676884302E-7,9.9957829,9.9957829,7102.798828125,7110.17529296875,55.8942554101982,20.5797688935223,13.038077,0,0,0,40,4449,10.0054,7106.48706054687,,,,,,,,,,,,,0,,,,-0.00245,,,,,,9.9957829,,,,
,23216709.715,9.9956551,7574.2294921875,-1.60798585181237E-5,4.0407626794498E-7,1,0.999253354069792,40.0298881530762,1.99543278059793,16.669999808073,-0.000178716123002296,-4.26933207714694E-5,0.25,-9.37840222580349E-7,-1.59899102314539E-5,-1.01834440097112E-6,9.9956551,9.9956551,7570.4716796875,7577.9873046875,56.5453519667175,20.5792500159052,12.658426,0,0,0,40,4449,10.0063,7574.2294921875,,,,,,,,,,,,,0,,,,0,,,,,,9.9956551,,,,
,23216727.43,9.99570035,8015.814453125,-1.7476026044133E-5,4.1425399901034E-7,1,0.999253354069792,40.0298881530762,1.99557743260161,16.669999808073,-0.000194609650861065,-4.4403495287688E-5,0.25,-8.40507665434388E-7,-1.73797745521916E-5,-9.29543584896846E-7,9.9956055,9.9957952,8012.53076171875,8019.09814453125,57.0010413934291,20.5811876019122,12.658426,0,0,0,40,4449,10.00745,8015.814453125,,,,,,,,,,,,,0,,,,-0.00245,,,,,,9.99570035,,,,
,23216745.94,9.9959812,8478.234375,-1.86212105206603E-5,3.23606374467501E-7,1,0.999253354069792,40.0298881530762,1.99544595856329,16.669999808073,-0.000206879635176019,-4.99872522418064E-5,0.25,-1.1331495377445E-6,-1.85180041194238E-5,-1.22744906379847E-6,9.9959812,9.9959812,8474.390625,8482.078125,56.4609360866406,20.5792450552342,12.658426,0,0,0,40,4449,10.00755,8478.234375,,,,,,,,,,,,,0,,,,0.0049,,,,,,9.9959812,,,,
,23216764.67,9.9960213,8947.46337890625,-1.91818136977389E-5,4.10400241476795E-7,1,0.999253354069792,40.0298881530762,1.99550308071566,16.669999808073,-0.000214576164881507,-4.3329607058632E-5,0.25,-4.39608625295564E-7,-1.90801022206648E-5,-5.41223654473132E-7,9.9960213,9.9960213,8944.90234375,8950.0244140625,56.3647957787752,20.5777901863819,12.658426,0,0,0,40,4449,10.00865,8947.46337890625,,,,,,,,,,,,,0,,,,-0.0049,,,,,,9.9960213,,,,
,23216782.875,9.9959221,9402.10693359375,-2.08848165120843E-5,4.03304478920963E-7,1,0.999253354069792,40.0298881530762,1.99551428682849,16.669999808073,-0.000232548178055059,-5.32835481924303E-5,0.25,-1.02144795201492E-6,-2.07718508080889E-5,-1.13001303573554E-6,9.9959221,9.9959221,9399.7099609375,9404.50390625,56.933039712256,20.5794846239228,12.658426,0,0,0,40,4449,10.0087,9402.10693359375,,,,,,,,,,,,,0,,,,0,,,,,,9.9959221,,,,
,23216801.555,9.9971986,9868.23583984375,-2.22008283457006E-5,4.31882518841697E-7,1,0.999253354069792,40.0298881530762,1.99545477024686,16.669999808073,-0.000247993835173245,-5.22082553525078E-5,0.25,-6.9037190441129E-7,-2.20837040218763E-5,-8.08602774751339E-7,9.9971943,9.9972029,9864.123046875,9872.3486328125,56.5781803645252,20.5787990659894,13.038077,0,0,0,40,4449,10.00895,9868.23583984375,,,,,,,,,,,,,0,,,,-0.00245,,,,,,9.9971986,,,,
,23216809.885,9.9967537,9999.720703125,-2.23310122418278E-5,4.33015514472086E-7,1,0.999253354069792,40.0298881530762,1.9955221932019,16.669999808073,-0.000249046976907285,-5.48261807821185E-5,0.25,-8.99802433506603E-7,-2.22123030097128E-5,-1.01790472372651E-6,9.9967537,9.9967537,9999.720703125,9999.720703125,56.313208296506,20.5781417080146,12.658426,0,0,0,40,4417,10.009,9999.720703125,,,,,,,,,,,,,0,,,,0.00245,,,,,,9.9967537,,,,