File: data/doubleLayers/dl_0-25/ppms/data/DD205_10_FCW_100OE.DAT
[Header]
; VSM Data File (default extension .dat)
; Copyright (c) 2003-2013, Quantum Design, Inc. All rights reserved.
TITLE,
FILEOPENTIME,31520424.83,01/01/2019,3:42 am
BYAPP,VSM,2.0,2.0
INFO,PPMS VSM Option Release 1.4.10 Build 1,APPNAME
INFO,Quantum Design Linear Motor Servo Controller,MOTOR_MODULE_NAME
INFO,3101-100 M1,MOTOR_HW_VERSION
INFO,MMC1014,MOTOR_SERIAL_NUMBER
INFO,SRV No X-over 01.03.11,MOTOR_SOFTWARE_VERSION
INFO,Quantum Design VSM Detection Module,VSM_MODULE_NAME
INFO,3101-150 F0,VSM_HW_VERSION
INFO,VSM707,VSM_SERIAL_NUMBER
INFO,VSM No X-over 01.02.05 May 20 2008 13:51:47,VSM_SOFTWARE_VERSION
INFO,704,PREAMP_SERIAL_NUMBER
INFO,822,COIL_SERIAL_NUMBER
INFO,0,MOMENT_UNITS
INFO,CoFe2O4,SAMPLE_MATERIAL
INFO,Double Layer thin concentration,SAMPLE_COMMENT
INFO,27.44,SAMPLE_MASS
INFO,,SAMPLE_VOLUME
INFO,,SAMPLE_MOLECULAR_WEIGHT
INFO,,SAMPLE_SIZE
INFO,,SAMPLE_SHAPE
DATATYPE,COMMENT,1
DATATYPE,TIME,2
STARTUPAXIS,X,2
STARTUPAXIS,Y1,5
[Data]
Comment,Time Stamp (sec),Temperature (K),Magnetic Field (Oe),Moment (emu),M. Std. Err. (emu),Transport Action,Averaging Time (sec),Frequency (Hz),Peak Amplitude (mm),Center Position (mm),Coil Signal' (mV),Coil Signal" (mV),Range (mV),M. Quad. Signal (emu),M. Raw' (emu),M. Raw" (emu),Min. Temperature (K),Max. Temperature (K),Min. Field (Oe),Max. Field (Oe),Mass (grams),Motor Lag (deg),Pressure (Torr),VSM Status (code),Motor Status (code),Measure Status (code),Measure Count,PPMS Status (code),System Temp. (K),System Field (Oe),Sample Position (deg),Bridge 1 Resistance (ohms),Bridge 1 Excitation (에),Bridge 2 Resistance (ohms),Bridge 2 Excitation (에),Bridge 3 Resistance (ohms),Bridge 3 Excitation (에),Bridge 4 Resistance (ohms),Bridge 4 Excitation (에),Signal 1 Vin (V),Signal 2 Vin (V),Digital Inputs (code),Drive 1 Iout (mA),Drive 1 Ipower (W),Drive 2 Iout (mA),Drive 2 Ipower (W),Pressure (),Map 20 (),Map 21 (),Map 22 (),Map 23 (),Map 24 (),Map 25 (),Map 26 (),Map 27 (),Map 28 (),Map 29 ()
,31520558.2,10.0019512,99.6243667602539,1.80115050032902E-5,3.2991769845007E-7,1,0.999253354069792,40.0298881530762,2.0080987690928,20.1099999248981,0.000203429567585937,3.61527708536222E-5,0.25,2.45000740132912E-9,1.79080689857573E-5,8.93023805517724E-8,10.0019512,10.0019512,99.6243667602539,99.6243667602539,57.3973270526791,20.6428648970487,11.899124,0,0,0,40,4369,9.9955,99.6243667602539,,,,,,,,,,,,,0,,,,0,,,,,,10.0019512,,,,
,31520688.36,13.0467749,99.6243667602539,1.8021099717954E-5,3.13855226796757E-7,1,0.999253354069792,40.0298881530762,2.00805964493945,20.1099999248981,0.000204017234342482,3.34439248088535E-5,0.25,-2.39014660544564E-7,1.79186669040566E-5,-1.5072860117934E-7,13.0467749,13.0467749,99.6243667602539,99.6243667602539,56.872072687756,20.6428347403854,12.658426,0,0,0,40,4370,13.153,99.6243667602539,,,,,,,,,,,,,0,,,,-0.0049,,,,,,13.0467749,,,,
,31520828.215,16.5069447,99.6243667602539,1.7569020158356E-5,2.93114770052391E-7,1,0.999253354069792,40.0298881530762,2.00820314653433,20.1099999248981,0.000198967824181888,3.22862069233749E-5,0.25,-2.61407126568936E-7,1.7469126725023E-5,-1.75170968972519E-7,16.5069447,16.5069447,99.6243667602539,99.6243667602539,56.9385111118906,20.6408616534581,13.797379,0,0,0,40,4370,16.6685,99.6243667602539,,,,,,,,,,,,,0,,,,0,,,,,,16.5069447,,,,
,31520979.84,20.3116093,99.6243667602539,,,2,,,,20.1799997994304,,,,,,,20.3116093,20.3116093,99.6243667602539,99.6243667602539,,,14.177031,,,,-99999999,4370,20.4757,99.6243667602539,,,,,,,,,,,,,,,,,,,,,,,20.3116093,,,,
,31521110,23.5233307,99.6243667602539,1.76653961370017E-5,3.4705420437184E-7,1,0.999253354069792,40.0298881530762,2.00789130422686,20.1299991458654,0.000199400981886545,3.61347277385848E-5,0.25,5.93812203682617E-8,1.75654471407988E-5,1.47157143255959E-7,23.5233307,23.5233307,99.6243667602539,99.6243667602539,57.0979633298137,20.6407458300665,14.556682,0,0,0,40,4370,23.754,99.6243667602539,,,,,,,,,,,,,0,,,,-0.0049,,,,,,23.5233307,,,,
,31521249.975,27.0089197,99.6243667602539,1.79172771647049E-5,2.89629016622862E-7,1,0.999253354069792,40.0298881530762,2.00800042911049,20.1299991458654,0.000202870799304009,3.34364986909019E-5,0.25,-2.29388288328721E-7,1.78211383429194E-5,-1.34467903639992E-7,26.9803619,27.0374775,99.6243667602539,99.6243667602539,57.362935397833,20.6394493455336,14.556682,0,0,0,40,4370,27.28785,99.6243667602539,,,,,,,,,,,,,0,,,,-0.0049,,,,,,27.0089197,,,,
,31521398.91,30.6642609,99.6243667602539,,,2,,,,20.1900003412366,,,,,,,30.6642609,30.6642609,99.6243667602539,99.6243667602539,,,14.936333,,,,-99999999,4370,31.0221,99.6243667602539,,,,,,,,,,,,,,,,,,,,,,,30.6642609,,,,
,31521533.75,34.0141068,99.6243667602539,1.79786071598058E-5,3.1285825738816E-7,1,0.999253354069792,40.0298881530762,2.00819120947935,20.1399996876717,0.000203431776101679,3.54130371343961E-5,0.25,-8.20877623944041E-8,1.78965682581775E-5,2.60870873093741E-8,34.0141068,34.0141068,99.6243667602539,99.6243667602539,57.3465211989291,20.6411153343802,15.695635,0,0,0,40,4370,34.4315,99.6243667602539,,,,,,,,,,,,,0,,,,0,,,,,,34.0141068,,,,
,31521675.845,37.5306435,99.6243667602539,1.84219750646094E-5,2.93008649826063E-7,1,0.999253354069792,40.0298881530762,2.00829973891969,20.1399996876717,0.000208555416509446,3.65767481243217E-5,0.25,-6.92515075418608E-8,1.83503722410441E-5,4.99550413514185E-8,37.5306435,37.5306435,99.6243667602539,99.6243667602539,57.4403166212368,20.6395037885349,16.075285,0,0,0,40,4370,38.0149,99.6243667602539,,,,,,,,,,,,,0,,,,0,,,,,,37.5306435,,,,
,31521820.47,41.1192131,99.6243667602539,,,2,,,,20.1700001889467,,,,,,,41.1192131,41.1192131,99.6243667602539,99.6243667602539,,,15.695635,,,,-99999999,4370,41.6665,99.6243667602539,,,,,,,,,,,,,,,,,,,,,,,41.1192131,,,,
,31521939.36,44.041851,99.6243667602539,1.78464362636689E-5,2.7207278201797E-7,1,0.999253354069792,40.0298881530762,2.00821265546184,20.1200004667044,0.000202149238845555,3.67882944961315E-5,0.25,3.42138786959129E-8,1.78071189791647E-5,1.62446518319406E-7,44.041851,44.041851,99.6243667602539,99.6243667602539,57.0893654161022,20.6410029656285,16.454937,0,0,0,40,4370,44.6794,99.6243667602539,,,,,,,,,,,,,0,,,,0.0049,,,,,,44.041851,,,,
,31522080.605,47.5096626,99.6243667602539,1.80622047252343E-5,3.62811231609086E-7,1,0.999253354069792,40.0298881530762,2.00821198777386,20.1200004667044,0.000205985365016422,3.07992750073502E-5,0.25,-5.39844242615178E-7,1.80464820127746E-5,-4.05597126974745E-7,47.5096626,47.5096626,99.6243667602539,99.6243667602539,57.1307917276214,20.6384533393142,16.834587,0,0,0,40,4370,48.264,99.6243667602539,,,,,,,,,,,,,0,,,,-0.0049,,,,,,47.5096626,,,,
,31522204.915,50.5646935,99.6243667602539,1.76356471315182E-5,3.32902688862142E-7,1,0.999253354069792,40.0298881530762,2.00797300337994,20.1200004667044,0.000201099923362374,3.12009546302802E-5,0.25,-4.30530298818884E-7,1.76371548008627E-5,-2.99317443426305E-7,50.5646935,50.5646935,99.6243667602539,99.6243667602539,57.0158923352945,20.641965010109,17.214239,0,0,0,40,4370,51.4302,99.6243667602539,,,,,,,,,,,,,0,,,,0,,,,,,50.5646935,,,,
,31522326.72,53.5388298,99.6243667602539,1.80697065178824E-5,2.91472813128092E-7,1,0.999253354069792,40.0298881530762,1.98379506449188,20.0999993830919,0.000203683257063201,3.26838122842202E-5,0.25,-3.45543348752901E-7,1.80876085724657E-5,-2.13188564646738E-7,53.5388298,53.5388298,99.6243667602539,99.6243667602539,57.085457273506,20.6457777750039,17.593889,0,0,0,40,4374,54.5374,99.6243667602539,,,,,,,,,,,,,0,,,,0,,,,,,53.5388298,,,,
,31522468.96,57.0234127,99.6243667602539,1.8185440055129E-5,3.56307102843035E-7,1,0.999253354069792,40.0298881530762,1.98395341353983,20.0999993830919,0.000205014639106661,3.40034019590716E-5,0.25,-2.47439143339717E-7,1.82209417377883E-5,-1.19008073637312E-7,56.9971466,57.0496788,99.6243667602539,99.6243667602539,57.1331366131791,20.6448015423547,17.593889,0,0,0,40,4374,58.1441,99.6243667602539,,,,,,,,,,,,,0,,,,-0.00245,,,,,,57.0234127,,,,
,31522611.12,60.5266953,99.6243667602539,1.78275127942635E-5,3.78450792724335E-7,1,0.999253354069792,40.0298881530762,1.98388107610697,20.0999993830919,0.000201139726640964,3.33904590998293E-5,0.25,-2.33497741426343E-7,1.78776200634587E-5,-1.14192747716568E-7,60.5266953,60.5266953,99.6243667602539,99.6243667602539,57.3215090863138,20.6461994047658,17.593889,0,0,0,40,4374,61.74165,99.6243667602539,,,,,,,,,,,,,0,,,,-0.0049,,,,,,60.5266953,,,,
,31522751.755,64.0112228,99.6243667602539,1.80788659607742E-5,3.13819295949493E-7,1,0.999253354069792,40.0298881530762,2.00807955139518,20.0800001621246,0.000206285730383684,3.54455454246718E-5,0.25,-1.26901762652646E-7,1.81417585451263E-5,-1.32025965469874E-8,64.0112228,64.0112228,99.6243667602539,99.6243667602539,57.0049495360253,20.6392768672628,18.353191,0,0,0,40,4374,65.30185,99.6243667602539,,,,,,,,,,,,,0,,,,0.00245,,,,,,64.0112228,,,,
,31522894.51,67.5070419,99.6243667602539,1.79521000311754E-5,2.8959465116258E-7,1,0.999253354069792,40.0298881530762,2.00798190677325,20.0800001621246,0.000205587506263434,3.1630472721198E-5,0.25,-4.32464860140467E-7,1.80267230836124E-5,-3.28779095309682E-7,67.5070419,67.5070419,99.6243667602539,99.6243667602539,57.5223876157561,20.6405262282321,17.973541,0,0,0,40,4374,68.9087,99.6243667602539,,,,,,,,,,,,,0,,,,0,,,,,,67.5070419,,,,
,31523036.555,71.036026,99.6243667602539,1.7758875640459E-5,3.11598902097244E-7,1,0.999253354069792,40.0298881530762,2.00788839119643,20.0800001621246,0.000201947097529546,3.97667814938157E-5,0.25,3.21836637495346E-7,1.78365019563459E-5,4.1987316743039E-7,71.036026,71.036026,99.6243667602539,99.6243667602539,57.2964969736984,20.6433234900046,17.973541,0,0,0,40,4374,72.5054,99.6243667602539,,,,,,,,,,,,,0,,,,-0.0049,,,,,,71.036026,,,,
,31523177.88,74.5306244,99.6243667602539,1.816456847004E-5,3.28990823046981E-7,1,0.999253354069792,40.0298881530762,2.00777667773791,20.0599990785122,0.000206835184255591,3.94908523332415E-5,0.25,2.31756230438999E-7,1.82509421747216E-5,3.24262966700631E-7,74.5306244,74.5306244,99.6243667602539,99.6243667602539,57.4887775894292,20.6429958835453,18.732843,0,0,0,40,4374,76.0855,99.6243667602539,,,,,,,,,,,,,0,,,,-0.0049,,,,,,74.5306244,,,,
,31523319.655,78.0025406,99.6243667602539,1.80491319631998E-5,3.74175785779416E-7,1,0.999253354069792,40.0298881530762,2.00826632902259,20.0599990785122,0.00020644766675665,3.461384059014E-5,0.25,-1.69748536956152E-7,1.81417211723406E-5,-8.66194890901571E-8,78.0025406,78.0025406,99.6243667602539,99.6243667602539,57.4926857320253,20.6460612546724,18.353191,0,0,0,40,4374,79.66965,99.6243667602539,,,,,,,,,,,,,0,,,,-0.00245,,,,,,78.0025406,,,,
,31523464.455,81.5486374,99.6243667602539,1.83269317595608E-5,2.72247353642026E-7,1,0.999253354069792,40.0298881530762,2.00796380977046,20.0599990785122,0.000209938738919121,3.34421294498326E-5,0.25,-3.15340390780958E-7,1.84252516754231E-5,-2.38177381173162E-7,81.5486374,81.5486374,99.6243667602539,99.6243667602539,56.8587850029291,20.646131349769,18.353191,0,0,0,40,4374,83.34585,99.6243667602539,,,,,,,,,,,,,0,,,,-0.0049,,,,,,81.5486374,,,,
,31523605.005,85.0608292,99.6243667602539,1.80406215498311E-5,3.84807102367341E-7,1,0.999253354069792,40.0298881530762,1.98402060233861,20.0299993157387,0.000203761650543427,3.57898995224088E-5,0.25,-1.79348298972219E-8,1.8138731554567E-5,5.40327310503388E-8,85.0608292,85.0608292,99.6243667602539,99.6243667602539,57.4090514804676,20.6466217782996,19.492144,0,0,0,40,4374,86.89935,99.6243667602539,,,,,,,,,,,,,0,,,,-0.0049,,,,,,85.0608292,,,,
,31523744.83,88.5286636,99.6243667602539,1.77596932855797E-5,3.15878151025802E-7,1,0.999253354069792,40.0298881530762,1.98399441182827,20.0299993157387,0.00020060448754126,3.52438485949469E-5,0.25,-1.21314055658997E-8,1.7858034736229E-5,5.39299035086821E-8,88.5286636,88.5286636,99.6243667602539,99.6243667602539,57.1339182416984,20.6463328631938,19.112494,0,0,0,40,4374,90.3895,99.6243667602539,,,,,,,,,,,,,0,,,,-0.0049,,,,,,88.5286636,,,,
,31523884.925,92.0281143,99.6243667602539,1.79019672542508E-5,3.43161855988207E-7,1,0.999253354069792,40.0298881530762,1.98372828999628,20.0299993157387,0.000202819630332945,3.20020640088747E-5,0.25,-3.19704912925999E-7,1.80033952539192E-5,-2.59227920071078E-7,92.0281143,92.0281143,99.6243667602539,99.6243667602539,57.0424677049483,20.648471128214,19.492144,0,0,0,40,4374,93.90275,99.6243667602539,,,,,,,,,,,,,0,,,,-0.00245,,,,,,92.0281143,,,,
,31524007.195,95.0529404,99.6243667602539,1.79255770354414E-5,3.85411997183921E-7,1,0.999253354069792,40.0298881530762,2.00828122324406,19.9999995529652,0.000205143643975711,3.44087419118036E-5,0.25,-1.42984149860177E-7,1.80272013786873E-5,-8.49154677786037E-8,95.0529404,95.0529404,99.6243667602539,99.6243667602539,56.9963516223137,20.6372714481613,19.492144,0,0,0,40,4374,96.9746,99.6243667602539,,,,,,,,,,,,,0,,,,-0.0049,,,,,,95.0529404,,,,
,31524146.565,98.5392609,99.6243667602539,1.81242430209783E-5,3.40229767728688E-7,1,0.999253354069792,40.0298881530762,2.00785742123076,19.9999995529652,0.000206976729586107,3.70784523552381E-5,0.25,5.98484527235031E-8,1.82267703178829E-5,1.16094153819844E-7,98.5392609,98.5392609,99.6243667602539,99.6243667602539,57.3738781971022,20.6457248414788,19.492144,0,0,0,40,4374,100.4706,99.6243667602539,,,,,,,,,,,,,0,,,,0,,,,,,98.5392609,,,,
,31524287.485,102.0239105,99.6243667602539,1.79585933021923E-5,3.20070423746967E-7,1,0.999253354069792,40.0298881530762,2.00792783143786,19.9999995529652,0.000205142618323726,3.64612980346958E-5,0.25,3.8087993338903E-8,1.80603966914134E-5,9.04110519189433E-8,102.0239105,102.0239105,99.6243667602539,99.6243667602539,57.2230238928907,20.6430012818958,19.112494,0,0,0,40,4374,104.0273,99.6243667602539,,,,,,,,,,,,,0,,,,0,,,,,,102.0239105,,,,
,31524408.35,105.0355225,99.6243667602539,1.77549244196586E-5,3.35568538360701E-7,1,0.999253354069792,40.0298881530762,2.00796758190505,19.9699997901917,0.000203452557371073,3.2434582244665E-5,0.25,-2.76051935816236E-7,1.78563389907199E-5,-2.28625934415569E-7,105.0355225,105.0355225,99.6243667602539,99.6243667602539,57.4520410490253,20.6443042030769,19.492144,0,0,0,40,4374,107.0707,99.6243667602539,,,,,,,,,,,,,0,,,,0,,,,,,105.0355225,,,,
,31524548.23,108.5119934,99.6243667602539,1.78415192797325E-5,3.32612050195322E-7,1,0.999253354069792,40.0298881530762,2.00809140821921,19.9699997901917,0.000203883112873935,3.58433768303984E-5,0.25,9.57332677761512E-9,1.79423091190688E-5,5.61915843202346E-8,108.5119934,108.5119934,99.6243667602539,99.6243667602539,57.3871658819292,20.6459444915901,20.251448,0,0,0,40,4374,110.5832,99.6243667602539,,,,,,,,,,,,,0,,,,0,,,,,,108.5119934,,,,
,31524689.815,112.0320816,99.6243667602539,1.78787304245008E-5,3.36021798574928E-7,1,0.999253354069792,40.0298881530762,2.00822428338521,19.9699997901917,0.000204311379816878,3.59413176405816E-5,0.25,1.39558522428952E-8,1.7979197149013E-5,5.82405107109664E-8,112.0320816,112.0320816,99.6243667602539,99.6243667602539,57.6154014095446,20.6423081436822,19.871798,0,0,0,40,4374,114.1479,99.6243667602539,,,,,,,,,,,,,0,,,,-0.00245,,,,,,112.0320816,,,,
,31524830.75,115.5106735,99.6243667602539,1.80295636329232E-5,3.13122862185637E-7,1,0.999253354069792,40.0298881530762,2.0080906259309,19.9299994856119,0.000206543712802555,3.32147014876728E-5,0.25,-2.48503611653457E-7,1.81308150543109E-5,-2.07545147181018E-7,115.5106735,115.5106735,99.6243667602539,99.6243667602539,56.8791073444291,20.6456730246947,19.871798,0,0,0,40,4374,117.6907,99.6243667602539,,,,,,,,,,,,,0,,,,-0.0049,,,,,,115.5106735,,,,
,31524970.33,119.0027313,99.6243667602539,1.78280582241768E-5,3.11609633261412E-7,1,0.999253354069792,40.0298881530762,2.00804194001973,19.9299994856119,0.000203870339985124,3.48454122955444E-5,0.25,-6.83619599390978E-8,1.79269292856678E-5,-2.88585343122102E-8,119.0027313,119.0027313,99.6243667602539,99.6243667602539,57.281646031833,20.6473305238122,19.871798,0,0,0,40,4374,121.1977,99.6243667602539,,,,,,,,,,,,,0,,,,0,,,,,,119.0027313,,,,
,31525111.995,122.5166168,99.6243667602539,1.79025195742683E-5,2.59701915978393E-7,1,0.999253354069792,40.0298881530762,2.00812406161507,19.9299994856119,0.000205626884394741,2.97949226537596E-5,0.25,-5.21447127654836E-7,1.80018136883946E-5,-4.86112099987252E-7,122.5166168,122.5166168,99.6243667602539,99.6243667602539,57.1081245005637,20.643198199141,20.251448,0,0,0,40,4374,124.76025,99.6243667602539,,,,,,,,,,,,,0,,,,-0.00245,,,,,,122.5166168,,,,
,31525253.49,126.0563812,99.6243667602539,1.74738703597458E-5,2.8190441392333E-7,1,0.999253354069792,40.0298881530762,2.00811593266946,19.8899991810322,0.00020005269192707,3.27293515632233E-5,0.25,-1.87928571991475E-7,1.75690413491601E-5,-1.5331980656578E-7,126.0563812,126.0563812,99.6243667602539,99.6243667602539,57.4926857320253,20.6406432019941,20.251448,0,0,0,40,4374,128.3164,99.6243667602539,,,,,,,,,,,,,0,,,,-0.0049,,,,,,126.0563812,,,,
,31525393.64,129.5331726,99.6243667602539,1.77044910333417E-5,3.44644571289154E-7,1,0.999253354069792,40.0298881530762,2.00810675885931,19.8899991810322,0.000202266610470418,3.55216219529231E-5,0.25,1.786334872293E-8,1.77993686710984E-5,5.25369402734505E-8,129.5091553,129.5571899,99.6243667602539,99.6243667602539,57.1964485232368,20.6435568360834,20.251448,0,0,0,40,4374,131.8375,99.6243667602539,,,,,,,,,,,,,0,,,,0,,,,,,129.5331726,,,,
,31525533.975,133.0178299,99.6243667602539,1.80113896607138E-5,4.190371518217E-7,1,0.999253354069792,40.0298881530762,2.00822051054761,19.8899991810322,0.000206414982653155,3.24400089509348E-5,0.25,-3.03945670867015E-7,1.81072840561265E-5,-2.71798619081379E-7,132.9923248,133.043335,99.6243667602539,99.6243667602539,57.2566339192176,20.6411347928429,20.251448,0,0,0,40,4374,135.3537,99.6243667602539,,,,,,,,,,,,,0,,,,0,,,,,,133.0178299,,,,
,31525654.015,136.0118179,99.6243667602539,1.78683271706277E-5,3.76250608339022E-7,1,0.999253354069792,40.0298881530762,2.00818378586,19.8400001972914,0.000204726756876149,3.23644605271448E-5,0.25,-2.84251944696523E-7,1.7962298633532E-5,-2.53372344093571E-7,135.9841766,136.0394592,99.6243667602539,99.6243667602539,57.2824276603522,20.6414986000259,20.251448,0,0,0,40,4374,138.36735,99.6243667602539,,,,,,,,,,,,,0,,,,-0.0049,,,,,,136.0118179,,,,
,31525794.7,139.5117798,99.6243667602539,1.78844164420486E-5,4.22972587982072E-7,1,0.999253354069792,40.0298881530762,2.0083088974473,19.8400001972914,0.00020450968167695,3.46746331820369E-5,0.25,-8.3602144404658E-8,1.79767412008228E-5,-5.28628364442999E-8,139.5117798,139.5117798,99.6243667602539,99.6243667602539,57.5020652742561,20.6441335644321,20.631098,0,0,0,40,4374,141.90745,99.6243667602539,,,,,,,,,,,,,0,,,,-0.00245,,,,,,139.5117798,,,,
,31525934.875,143.00380705,99.6243667602539,1.76896955729544E-5,3.47107301127778E-7,1,0.999253354069792,40.0298881530762,2.00830668857512,19.8400001972914,0.000201840496767244,3.67398384810906E-5,0.25,1.32464168936809E-7,1.77792422183309E-5,1.62851392130876E-7,142.9778442,143.0297699,99.6243667602539,99.6243667602539,57.4176493941791,20.6435322020219,20.631098,0,0,0,40,4374,145.42675,99.6243667602539,,,,,,,,,,,,,0,,,,0.00245,,,,,,143.00380705,,,,
,31526054.855,146.0148926,99.6243667602539,1.75551568020718E-5,3.31213816131642E-7,1,0.999253354069792,40.0298881530762,2.0082605836592,19.7999998927116,0.000201388611731873,3.01342513629321E-5,0.25,-4.21131716081015E-7,1.76436795048881E-5,-3.94632982926014E-7,146.0148926,146.0148926,99.6243667602539,99.6243667602539,57.4418798782753,20.6411693186775,21.01075,0,0,0,40,4374,148.4342,99.6243667602539,,,,,,,,,,,,,0,,,,0,,,,,,146.0148926,,,,
,31526196.51,149.52555085,99.6243667602539,1.78077613333659E-5,3.65730618126829E-7,1,0.999253354069792,40.0298881530762,2.00822060762522,19.7999998927116,0.000204640692389467,2.84070639539888E-5,0.25,-6.15089593535801E-7,1.78963054444162E-5,-5.90086096332345E-7,149.4998169,149.5512848,99.6243667602539,99.6243667602539,57.3332335141022,20.6453097558947,21.01075,0,0,0,40,4374,151.9859,99.6243667602539,,,,,,,,,,,,,0,,,,-0.0049,,,,,,149.52555085,,,,
,31526336.635,153.02173615,99.6243667602539,1.78190024277918E-5,3.11359504149314E-7,1,0.999253354069792,40.0298881530762,2.00813882113863,19.7999998927116,0.000204465811552756,3.00165583892679E-5,0.25,-4.74905702089945E-7,1.79057875379112E-5,-4.50064976789104E-7,152.9974365,153.0460358,99.6243667602539,99.6243667602539,57.7639108281984,20.6413058488663,20.631098,0,0,0,40,4374,155.4971,99.6243667602539,,,,,,,,,,,,,0,,,,0,,,,,,153.02173615,,,,
,31526477.74,156.5309906,99.6243667602539,1.77115600834659E-5,4.00216714881062E-7,1,0.999253354069792,40.0298881530762,2.00829355701123,19.7500009089708,0.000203051929560524,3.08534629433371E-5,0.25,-3.82026358482321E-7,1.77960563811167E-5,-3.57718748395254E-7,156.5309906,156.5309906,99.6243667602539,99.6243667602539,56.7696793517368,20.6438786850858,21.01075,0,0,0,40,4374,159.0356,99.6243667602539,,,,,,,,,,,,,0,,,,-0.0049,,,,,,156.5309906,,,,
,31526616.755,160.0079346,99.6243667602539,1.76376052481918E-5,3.44338726923876E-7,1,0.999253354069792,40.0298881530762,2.00811018315354,19.7500009089708,0.000201764684055643,3.30345124841468E-5,0.25,-1.76894318571061E-7,1.77198099940163E-5,-1.52490810744865E-7,159.9823914,160.0334778,99.6243667602539,99.6243667602539,57.1565854687561,20.6457262924155,20.631098,0,0,0,40,4374,162.5237,99.6243667602539,,,,,,,,,,,,,0,,,,-0.0049,,,,,,160.0079346,,,,
,31526756.645,163.5023651,99.6243667602539,1.7842588428861E-5,2.69701970746112E-7,1,0.999253354069792,40.0298881530762,2.00807564974672,19.7500009089708,0.000204346587684775,3.1921733140952E-5,0.25,-3.08962876768143E-7,1.79242241481796E-5,-2.85595923709777E-7,163.5023651,163.5023651,99.6243667602539,99.6243667602539,57.6943458899869,20.6491980692497,21.01075,0,0,0,40,4374,166.0211,99.6243667602539,,,,,,,,,,,,,0,,,,-0.00245,,,,,,163.5023651,,,,
,31526897.235,167.0025482,99.6243667602539,1.80611312282858E-5,2.96853890420427E-7,1,0.999253354069792,40.0298881530762,2.00799569741235,19.7000000625849,0.000206342679386346,3.50605613589203E-5,0.25,-7.09741373824977E-8,1.81416704405787E-5,-4.69261783273535E-8,167.0025482,167.0025482,99.6243667602539,99.6243667602539,56.9080275996406,20.6468771819273,21.01075,0,0,0,40,4374,169.5359,99.6243667602539,,,,,,,,,,,,,0,,,,0,,,,,,167.0025482,,,,
,31527036.655,170.5222626,99.6243667602539,1.79908155554885E-5,3.30094692900193E-7,1,0.999253354069792,40.0298881530762,2.008013763812,19.7000000625849,0.000206287262178847,3.05129506993648E-5,0.25,-4.56160714245745E-7,1.80697468489599E-5,-4.34541764298239E-7,170.5222626,170.5222626,99.6243667602539,99.6243667602539,57.1362631272561,20.6514956574075,21.3904,0,0,0,40,4374,173.0301,99.6243667602539,,,,,,,,,,,,,0,,,,0,,,,,,170.5222626,,,,
,31527177.82,174.0135803,99.6243667602539,1.78485918591121E-5,3.65586784025544E-7,1,0.999253354069792,40.0298881530762,2.00800246797972,19.7000000625849,0.000203907038315112,3.44529614221285E-5,0.25,-8.53488600985417E-8,1.79246149658847E-5,-6.29212929855816E-8,174.0135803,174.0135803,99.6243667602539,99.6243667602539,57.5528711280061,20.6501485778331,21.3904,0,0,0,40,4374,176.5625,99.6243667602539,,,,,,,,,,,,,0,,,,-0.00245,,,,,,174.0135803,,,,
,31527317,177.5022278,99.6243667602539,1.78662163509919E-5,3.8521866466836E-7,1,0.999253354069792,40.0298881530762,2.00793392554848,19.6499992161989,0.000204895404713698,2.9797082315134E-5,0.25,-4.95360538209374E-7,1.79409897120708E-5,-4.75188671512794E-7,177.5022278,177.5022278,99.6243667602539,99.6243667602539,57.1995750373137,20.6454021261617,21.3904,0,0,0,40,4374,180.0441,99.6243667602539,,,,,,,,,,,,,0,,,,-0.00245,,,,,,177.5022278,,,,
,31527457.155,181.016449,99.6243667602539,1.81050915738125E-5,3.39533695396606E-7,1,0.999253354069792,40.0298881530762,2.00798809243864,19.6499992161989,0.000207077256682539,3.3306054192534E-5,0.25,-2.28652194820893E-7,1.81786176504981E-5,-2.07617143332182E-7,181.016449,181.016449,99.6243667602539,99.6243667602539,57.4262473078907,20.6471116187334,21.01075,0,0,0,40,4374,183.55015,99.6243667602539,,,,,,,,,,,,,0,,,,-0.0049,,,,,,181.016449,,,,
,31527597.665,184.5124283,99.6243667602539,1.74871195152682E-5,3.85518915687268E-7,1,0.999253354069792,40.0298881530762,2.00786147714145,19.6499992161989,0.000199144594175182,3.6947791287259E-5,0.25,1.98916468072075E-7,1.75557810351857E-5,2.20391423727455E-7,184.484787,184.5400696,99.6243667602539,99.6243667602539,57.6458849217946,20.6475370031414,21.770052,0,0,0,40,4374,187.07145,99.6243667602539,,,,,,,,,,,,,0,,,,0.00245,,,,,,184.5124283,,,,
,31527718.32,187.5167389,99.6243667602539,1.80264431346411E-5,3.39409923847448E-7,1,0.999253354069792,40.0298881530762,2.00782543497122,19.6000002324581,0.00020684235763932,2.90007253753149E-5,0.25,-5.90561061468761E-7,1.80964877276647E-5,-5.71941654932643E-7,187.5167389,187.5167389,99.6243667602539,99.6243667602539,57.3433946848522,20.6454634916556,21.3904,0,0,0,40,4374,190.09455,99.6243667602539,,,,,,,,,,,,,0,,,,-0.00245,,,,,,187.5167389,,,,
,31527858.48,191.0077972,99.6243667602539,1.78159177933299E-5,3.58214785046457E-7,1,0.999253354069792,40.0298881530762,2.00790323712542,19.6000002324581,0.000203097661890341,3.62250387292714E-5,0.25,7.99104909478083E-8,1.78824463382353E-5,1.00376482197235E-7,191.0077972,191.0077972,99.6243667602539,99.6243667602539,56.9994781363906,20.6484129854053,21.770052,0,0,0,40,4374,193.61575,99.6243667602539,,,,,,,,,,,,,0,,,,-0.0049,,,,,,191.0077972,,,,
,31527999.375,194.5126343,99.6243667602539,1.74848743495807E-5,3.3633161528788E-7,1,0.999253354069792,40.0298881530762,2.00785260511425,19.6000002324581,0.000199876831190271,3.2210375928545E-5,0.25,-2.13643615609472E-7,1.75485659588549E-5,-1.95078042349564E-7,194.5126343,194.5126343,99.6243667602539,99.6243667602539,57.7779801415446,20.6483121953816,22.149702,0,0,0,40,4374,197.15895,99.6243667602539,,,,,,,,,,,,,0,,,,-0.00245,,,,,,194.5126343,,,,
,31528139.835,198.0022049,99.6243667602539,1.71905654307087E-5,3.94668483871193E-7,1,0.999253354069792,40.0298881530762,2.00803068454553,19.5499993860722,0.00019706368426888,2.84640056904977E-5,0.25,-4.90456371299368E-7,1.72515762587759E-5,-4.73586996796945E-7,197.9740448,198.030365,99.6243667602539,99.6243667602539,56.8181403199291,20.6474042874617,22.149702,0,0,0,40,4374,200.68055,99.6243667602539,,,,,,,,,,,,,0,,,,0.00245,,,,,,198.0022049,,,,
,31528279.28,201.506485,99.6243667602539,1.84462601725172E-5,3.79988769234996E-7,1,0.999253354069792,40.0298881530762,2.0080250228636,19.5499993860722,0.000211341377336917,3.10722411329471E-5,0.25,-4.79162172268311E-7,1.8509587953088E-5,-4.61268323757059E-7,201.506485,201.506485,99.6243667602539,99.6243667602539,57.4403166212368,20.647457891748,21.3904,0,0,0,40,4374,204.17585,99.6243667602539,,,,,,,,,,,,,0,,,,0,,,,,,201.506485,,,,
,31528420.345,205.0108948,99.6243667602539,1.79915715217855E-5,3.26596890429751E-7,1,0.999253354069792,40.0298881530762,2.00824668581136,19.5499993860722,0.000205290427666558,3.51420944879409E-5,0.25,-4.29481893901425E-8,1.8050842001242E-5,-2.44481267786294E-8,204.9819336,205.039856,99.6243667602539,99.6243667602539,57.0932735586983,20.6446896045683,22.149702,0,0,0,40,4374,207.7097,99.6243667602539,,,,,,,,,,,,,0,,,,-0.0049,,,,,,205.0108948,,,,
,31528561.68,208.5533752,99.6243667602539,1.77690404048027E-5,3.74933520899087E-7,1,0.999253354069792,40.0298881530762,2.00817948747586,19.5000004023314,0.000203574442499619,2.97885568524858E-5,0.25,-4.72918862639341E-7,1.78259510794447E-5,-4.56391163511872E-7,208.5533752,208.5533752,99.6243667602539,99.6243667602539,57.1503324406022,20.6424079953612,21.770052,0,0,0,40,4374,211.2476,99.6243667602539,,,,,,,,,,,,,0,,,,-0.0049,,,,,,208.5533752,,,,
,31528700.485,212.006424,99.6243667602539,1.80954951448112E-5,3.57936402763042E-7,1,0.999253354069792,40.0298881530762,2.00811280963753,19.5000004023314,0.00020689015001276,3.26017229146432E-5,0.25,-2.82135534621971E-7,1.81511782399435E-5,-2.65004338323857E-7,212.006424,212.006424,99.6243667602539,99.6243667602539,57.2316218066022,20.6430792598142,21.770052,0,0,0,40,4374,214.72525,99.6243667602539,,,,,,,,,,,,,0,,,,0,,,,,,212.006424,,,,
,31528840.56,215.5021667,99.6243667602539,1.74400536264933E-5,4.0978129575551E-7,1,0.999253354069792,40.0298881530762,2.00800032773214,19.5000004023314,0.000199822202282795,2.87668865032748E-5,0.25,-5.03902779006116E-7,1.74919091952914E-5,-4.88385634754236E-7,215.5021667,215.5021667,99.6243667602539,99.6243667602539,57.5700669554292,20.6464657201293,22.149702,0,0,0,40,4374,218.2391,99.6243667602539,,,,,,,,,,,,,0,,,,0.00245,,,,,,215.5021667,,,,
,31528981.205,219.0153809,99.6243667602539,1.766937483951E-5,3.71834954491637E-7,1,0.999253354069792,40.0298881530762,2.00820909911584,19.4499995559454,0.000201872160713433,3.24499277433936E-5,0.25,-2.20264672472894E-7,1.77195405280639E-5,-2.03995277911966E-7,219.0153809,219.0153809,99.6243667602539,99.6243667602539,57.2925888311022,20.6418334966108,22.149702,0,0,0,40,4374,221.75015,99.6243667602539,,,,,,,,,,,,,0,,,,0,,,,,,219.0153809,,,,
,31529121.64,222.5125275,99.6243667602539,1.78372066349323E-5,4.06982411357158E-7,1,0.999253354069792,40.0298881530762,2.00800795333381,19.4499995559454,0.000203108899264238,3.64228680720262E-5,0.25,1.00104602608564E-7,1.78854329341418E-5,1.17103427684903E-7,222.4841614,222.5408936,99.6243667602539,99.6243667602539,57.6154014095446,20.643135957459,22.529354,0,0,0,40,4374,225.2821,99.6243667602539,,,,,,,,,,,,,0,,,,-0.00245,,,,,,222.5125275,,,,
,31529262.5,226.0263519,99.6243667602539,1.77552329190537E-5,3.11904166426245E-7,1,0.999253354069792,40.0298881530762,2.00811999479669,19.4499995559454,0.000203126300256055,3.06966265154665E-5,0.25,-3.87576309743066E-7,1.78015635292685E-5,-3.72239909768666E-7,226.0263519,226.0263519,99.6243667602539,99.6243667602539,57.505191788333,20.6459097721987,21.770052,0,0,0,40,4374,228.8066,99.6243667602539,,,,,,,,,,,,,0,,,,0.0049,,,,,,226.0263519,,,,
,31529382.18,229.0087738,99.6243667602539,1.80544395558658E-5,4.24514516946171E-7,1,0.999253354069792,40.0298881530762,2.0081591515968,19.4000005722046,0.000205776886660456,3.55637384765503E-5,0.25,-1.19333736013506E-8,1.80993551166514E-5,4.39277223932644E-9,229.0087738,229.0087738,99.6243667602539,99.6243667602539,57.2621053188522,20.6434534398163,21.770052,0,0,0,40,4374,231.8002,99.6243667602539,,,,,,,,,,,,,0,,,,0.00245,,,,,,229.0087738,,,,
,31529522.16,232.5008392,99.6243667602539,1.78174226872833E-5,3.2742342911149E-7,1,0.999253354069792,40.0298881530762,2.00814980175464,19.4000005722046,0.000203084648480888,3.48939869336833E-5,0.25,-2.89088181086726E-8,1.78596216831884E-5,-1.31275239903852E-8,232.5008392,232.5008392,99.6243667602539,99.6243667602539,57.4551675631022,20.6445879906726,22.149702,0,0,0,40,4374,235.3208,99.6243667602539,,,,,,,,,,,,,0,,,,-0.00245,,,,,,232.5008392,,,,
,31529663.97,236.0322571,99.6243667602539,1.78684877057694E-5,4.32465769607485E-7,1,0.999253354069792,40.0298881530762,2.00833568644105,19.4000005722046,0.000203938238137181,3.33878948701886E-5,0.25,-1.69558742772316E-7,1.79087459071369E-5,-1.54329620184146E-7,236.0035553,236.0609589,99.6243667602539,99.6243667602539,57.6904377473907,20.6432296164436,22.149702,0,0,0,40,4374,238.88145,99.6243667602539,,,,,,,,,,,,,0,,,,0,,,,,,236.0322571,,,,
,31529783.695,239.0334473,99.6243667602539,1.73787424287286E-5,4.00012890648714E-7,1,0.999253354069792,40.0298881530762,2.00828079804176,19.3399991840124,0.000198356879476092,3.22719875499856E-5,0.25,-1.81939195673978E-7,1.74160959339296E-5,-1.67374353511094E-7,239.0334473,239.0334473,99.6243667602539,99.6243667602539,57.4723633905253,20.6419188029049,22.149702,0,0,0,40,4374,241.8951,99.6243667602539,,,,,,,,,,,,,0,,,,0,,,,,,239.0334473,,,,
,31529924.515,242.5460358,99.6243667602539,1.7162739456052E-5,4.72774874018223E-7,1,0.999253354069792,40.0298881530762,2.00837917621902,19.3399991840124,0.000195625700449551,3.33150745627131E-5,0.25,-5.24423767530751E-8,1.719741300422E-5,-3.80347981928818E-8,242.5460358,242.5460358,99.6243667602539,99.6243667602539,57.5380201861407,20.6413812236683,22.909004,0,0,0,40,4374,245.4197,99.6243667602539,,,,,,,,,,,,,0,,,,0.0049,,,,,,242.5460358,,,,
,31530065.01,246.0239258,99.6243667602539,1.70892069375167E-5,3.99093558283723E-7,1,0.999253354069792,40.0298881530762,2.00841990201478,19.3399991840124,0.000195319562898423,2.99863610359202E-5,0.25,-3.313659378903E-7,1.71218790806164E-5,-3.1778857121394E-7,246.0239258,246.0239258,99.6243667602539,99.6243667602539,57.7224845166792,20.6410889303873,22.149702,0,0,0,40,4374,248.9418,99.6243667602539,,,,,,,,,,,,,0,,,,0.0049,,,,,,246.0239258,,,,
,31530205.11,249.5392761,99.6243667602539,1.69307341721764E-5,4.36834284995425E-7,1,0.999253354069792,40.0298881530762,2.00843253390164,19.2799996584654,0.000193219187443704,3.12405547400315E-5,0.25,-1.93223482443069E-7,1.69608929695331E-5,-1.79726743213107E-7,249.5392761,249.5392761,99.6243667602539,99.6243667602539,57.139389641333,20.6342013032199,22.529354,0,0,0,40,4374,252.4461,99.6243667602539,,,,,,,,,,,,,0,,,,-0.00245,,,,,,249.5392761,,,,
,31530344.835,253.0315094,99.6243667602539,1.7041490211157E-5,3.56599699127358E-7,1,0.999253354069792,40.0298881530762,2.00855849574211,19.2799996584654,0.000194375256937633,3.19940418122475E-5,0.25,-1.45870385849872E-7,1.70697023817786E-5,-1.32410499790397E-7,253.0315094,253.0315094,99.6243667602539,99.6243667602539,57.3504293415253,20.6381752460583,22.149702,0,0,0,40,4374,255.95355,99.6243667602539,,,,,,,,,,,,,0,,,,-0.0049,,,,,,253.0315094,,,,
,31530484.89,256.50587465,99.6243667602539,1.67958849270808E-5,3.82796789967718E-7,1,0.999253354069792,40.0298881530762,2.00840023256959,19.2799996584654,0.000191466512787393,3.19270074199767E-5,0.25,-1.08394361148669E-7,1.68215932419261E-5,-9.52763750470136E-8,256.4798889,256.5318604,99.6243667602539,99.6243667602539,57.5786648691407,20.6377371126382,22.529354,0,0,0,40,4374,259.46575,99.6243667602539,,,,,,,,,,,,,0,,,,0,,,,,,256.50587465,,,,
,31530625.885,260.0114746,99.6243667602539,1.62037149658784E-5,2.95242820506411E-7,1,0.999253354069792,40.0298881530762,2.00850436619779,19.2300006747246,0.000185283964122411,2.74433009347206E-5,0.25,-3.99093374106291E-7,1.62267267962312E-5,-3.8704375550281E-7,259.985321,260.0376282,99.6243667602539,99.6243667602539,57.2675767184868,20.6358988261417,22.529354,0,0,0,40,4374,262.9883,99.6243667602539,,,,,,,,,,,,,0,,,,-0.00245,,,,,,260.0114746,,,,
,31530768.09,263.5483093,99.6243667602539,1.63859152521849E-5,3.63151730540431E-7,1,0.999253354069792,40.0298881530762,2.00830378837505,19.2300006747246,0.000186470261076579,3.26812326657249E-5,0.25,3.01860108188217E-8,1.64067851826795E-5,4.27698986903074E-8,263.523468,263.5731506,99.6243667602539,99.6243667602539,57.4536043060638,20.6411901764961,22.909004,0,0,0,40,4374,266.55555,99.6243667602539,,,,,,,,,,,,,0,,,,0.0049,,,,,,263.5483093,,,,
,31530908.155,267.0086975,99.6243667602539,1.67405019087042E-5,3.78882203217767E-7,1,0.999253354069792,40.0298881530762,2.0084188686064,19.2300006747246,0.000190746471192474,3.19202326133523E-5,0.25,-9.77465749993145E-8,1.67598542247075E-5,-8.5242289713692E-8,267.0086975,267.0086975,99.6243667602539,99.6243667602539,57.5903892969292,20.6395828228248,23.288654,0,0,0,40,4374,270.06025,99.6243667602539,,,,,,,,,,,,,0,,,,-0.0049,,,,,,267.0086975,,,,
,31531029.155,270.0058899,99.6243667602539,1.60169213274725E-5,4.48579797286375E-7,1,0.999253354069792,40.0298881530762,2.00841501603368,19.1799998283386,0.000183165609857915,2.65929507379007E-5,0.25,-4.39908378660578E-7,1.60339788043356E-5,-4.28458907213364E-7,270.0058899,270.0058899,99.6243667602539,99.6243667602539,57.2230238928907,20.635634104926,23.288654,0,0,0,40,4374,273.1167,99.6243667602539,,,,,,,,,,,,,0,,,,0,,,,,,270.0058899,,,,
,31531169.78,273.539917,99.6243667602539,1.65900318004719E-5,3.70325521648483E-7,1,0.999253354069792,40.0298881530762,2.00830669798239,19.1799998283386,0.000189252798080635,3.00376188533984E-5,0.25,-2.35943611836333E-7,1.66054360427038E-5,-2.2401281445485E-7,273.539917,273.539917,99.6243667602539,99.6243667602539,57.5817913832176,20.6380625447691,23.288654,0,0,0,40,4374,276.6136,99.6243667602539,,,,,,,,,,,,,0,,,,0,,,,,,273.539917,,,,
,31531309.665,277.0121765,99.6243667602539,1.61137616133936E-5,3.63360678736077E-7,1,0.999253354069792,40.0298881530762,2.0083882532973,19.1799998283386,0.000182951172912758,3.40930416152439E-5,0.25,2.03417775032795E-7,1.61264058853912E-5,2.15200224606341E-7,277.0121765,277.0121765,99.6243667602539,99.6243667602539,57.627125837333,20.6342917887646,22.909004,0,0,0,40,4374,280.11935,99.6243667602539,,,,,,,,,,,,,0,,,,0,,,,,,277.0121765,,,,
touchdown = 14.1399996355176 mm,31531442.625,280.3315735,99.6243667602539,1.60670412947135E-5,4.46879961892505E-7,1,0.999253354069792,40.0298881530762,2.00826571938199,19.1300008445978,0.000182615107445489,3.26803886871249E-5,0.25,8.80362800360941E-8,1.60778218917047E-5,9.95190473468342E-8,280.3315735,280.3315735,99.6243667602539,99.6243667602539,57.0776409883137,20.6331823879263,22.529354,0,0,0,40,4374,283.45135,99.6243667602539,,,,,,,,,,,,,0,,,,0,,,,,,280.3315735,,,,
,31531569.845,283.520813,99.6243667602539,1.62504242947355E-5,3.74343715839799E-7,1,0.999253354069792,40.0298881530762,2.0082621867557,19.1300008445978,0.000185393487041829,2.89209751097482E-5,0.25,-2.73749160144069E-7,1.62597259183562E-5,-2.62502279653541E-7,283.520813,283.520813,99.6243667602539,99.6243667602539,57.5005020172176,20.6364565879429,22.909004,0,0,0,40,4374,286.6138,99.6243667602539,,,,,,,,,,,,,0,,,,-0.0049,,,,,,283.520813,,,,
,31531709.755,287.0093079,99.6243667602539,1.53474280410751E-5,3.9362393585835E-7,1,0.999253354069792,40.0298881530762,1.99573287193453,19.1300008445978,0.000173851161361358,2.81654065348412E-5,0.25,-1.68386830541926E-7,1.53542294375909E-5,-1.57850402915526E-7,287.0093079,287.0093079,99.6243667602539,99.6243667602539,57.4309370790061,20.6361983451716,22.909004,0,0,0,40,4374,290.1348,99.6243667602539,,,,,,,,,,,,,0,,,,0,,,,,,287.0093079,,,,
touchdown = 14.0800001099706 mm,31531859.76,290.7319031,99.6243667602539,1.59501307108844E-5,4.07170108539967E-7,1,0.999253354069792,40.0298881530762,2.00832733542658,19.0699994564056,0.000181987277313551,2.80273602606621E-5,0.25,-2.99375329175428E-7,1.59551553357754E-5,-2.88608573319202E-7,290.7319031,290.7319031,99.6243667602539,99.6243667602539,57.2089545795445,20.6297532124306,22.909004,0,0,0,40,4374,293.8907,99.6243667602539,,,,,,,,,,,,,0,,,,0.0049,,,,,,290.7319031,,,,
,31531991.845,294.0028534,99.6243667602539,1.5896633329796E-5,4.15576420284009E-7,1,0.999253354069792,40.0298881530762,2.00842080351099,19.0699994564056,0.000181118844873409,2.93443289013631E-5,0.25,-1.73975142829463E-7,1.5899693791939E-5,-1.63330268331857E-7,293.9794922,294.0262146,99.6243667602539,99.6243667602539,57.4864327038715,20.6345671522403,23.288654,0,0,0,40,4374,297.18365,99.6243667602539,,,,,,,,,,,,,0,,,,-0.00245,,,,,,294.0028534,,,,
,31532132.475,297.5112457,99.6243667602539,1.49824665123622E-5,4.48190550205816E-7,1,0.999253354069792,40.0298881530762,2.00856730031497,19.0699994564056,0.000170725555794405,2.74714059653622E-5,0.25,-1.8000012394588E-7,1.49834806180879E-5,-1.70089053641949E-7,297.4844055,297.5380859,99.6243667602539,99.6243667602539,57.217552493256,20.6306208069329,22.909004,0,0,0,40,4374,300.71305,99.6243667602539,,,,,,,,,,,,,0,,,,0.00245,,,,,,297.5112457,,,,
touchdown = 14.019999653101 mm,31532276.76,301.0973511,99.6243667602539,1.51804924604277E-5,3.99385952470514E-7,1,0.999253354069792,40.0298881530762,2.00843005597068,19.0099999308586,0.000172231204088119,3.1970120520094E-5,0.25,1.8199286322856E-7,1.51793367655483E-5,1.91890566876662E-7,301.0973511,301.0973511,99.6243667602539,99.6243667602539,57.3809128537753,20.6238590086901,23.288654,0,0,0,40,4374,304.3395,99.6243667602539,,,,,,,,,,,,,0,,,,-0.00245,,,,,,301.0973511,,,,
,31532413.34,304.5104675,99.6243667602539,1.4593566765147E-5,4.83878792338534E-7,1,0.999253354069792,40.0298881530762,2.00836618368568,19.0099999308586,0.000165271501904523,3.23199621987166E-5,0.25,3.15004270979933E-7,1.45905916566729E-5,3.24345989364187E-7,304.5104675,304.5104675,99.6243667602539,99.6243667602539,57.301968373333,20.627822477763,23.668306,0,0,0,40,4374,307.7498,99.6243667602539,,,,,,,,,,,,,0,,,,0,,,,,,304.5104675,,,,
,31532554.985,308.01773075,99.6243667602539,1.4755030564315E-5,4.46736148235988E-7,1,0.999253354069792,40.0298881530762,2.00832466382177,19.0099999308586,0.000167891936147725,2.79625132889593E-5,0.25,-9.58114620434091E-8,1.47504480237209E-5,-8.64039812823748E-8,307.9898682,308.0455933,99.6243667602539,99.6243667602539,57.3809128537753,20.6283537663446,23.288654,0,0,0,40,4374,311.30215,99.6243667602539,,,,,,,,,,,,,0,,,,-0.0049,,,,,,308.01773075,,,,
touchdown = 13.9600001275539 mm,31532696.86,311.5412903,99.6243667602539,1.42268020775879E-5,4.03570952704232E-7,1,0.999253354069792,40.0298881530762,2.00858331214472,18.9500004053116,0.000161940207414372,2.66198788984913E-5,0.25,-1.22309538798082E-7,1.42206229804375E-5,-1.13334800970068E-7,311.5412903,311.5412903,99.6243667602539,99.6243667602539,57.495030617583,20.6250967847025,23.288654,0,0,0,40,4374,314.877,99.6243667602539,,,,,,,,,,,,,0,,,,0,,,,,,311.5412903,,,,
,31532838.57,315.0682373,99.6243667602539,1.38406545235367E-5,4.27959447732227E-7,1,0.999253354069792,40.0298881530762,1.99611424820673,18.9500004053116,0.000156224491842802,2.78623985781256E-5,0.25,6.89274744465193E-8,1.3832798575554E-5,7.74550316583132E-8,315.0682373,315.0682373,99.6243667602539,99.6243667602539,57.4379717356792,20.6318089334336,23.288654,0,0,0,40,4374,318.4074,99.6243667602539,,,,,,,,,,,,,0,,,,-0.0049,,,,,,315.0682373,,,,
,31532979.01,318.5235596,99.6243667602539,1.34459502764027E-5,3.68620555630654E-7,1,0.999253354069792,40.0298881530762,1.99626014027,18.9500004053116,0.000151890528685811,2.63209294972187E-5,0.25,1.07392928728953E-9,1.34367204483075E-5,9.28998527342569E-9,318.5235596,318.5235596,99.6243667602539,99.6243667602539,57.5239508727946,20.6320841159041,23.288654,0,0,0,40,4374,321.92775,99.6243667602539,,,,,,,,,,,,,0,,,,0,,,,,,318.5235596,,,,
touchdown = 13.9100002124906 mm,31533115.37,321.9109497,99.6243667602539,1.38691614565969E-5,3.90024968588822E-7,1,0.999253354069792,40.0298881530762,1.9963681188848,18.8999995589256,0.000157545346709939,2.20398556646975E-5,0.25,-4.50967579916445E-7,1.38582625242135E-5,-4.42231269462609E-7,321.9109497,321.9109497,99.6243667602539,99.6243667602539,56.9361662263329,20.6282358359109,23.288654,0,0,0,40,4374,325.3523,99.6243667602539,,,,,,,,,,,,,0,,,,0,,,,,,321.9109497,,,,
,31533240.475,325.0328369,99.6243667602539,1.40998803985201E-5,5.3661985548656E-7,1,0.999253354069792,40.0298881530762,1.99621237197943,18.8999995589256,0.000159375314575976,2.67984747585094E-5,0.25,-6.91256951840693E-8,1.40870226737962E-5,-6.06427839269544E-8,325.0040283,325.0616455,99.6243667602539,99.6243667602539,57.4395349927176,20.6292678609198,23.668306,0,0,0,40,4374,328.5019,99.6243667602539,,,,,,,,,,,,,0,,,,0,,,,,,325.0328369,,,,
,31533380.2,328.5021057,99.6243667602539,1.3413664419516E-5,4.19273687630983E-7,1,0.999253354069792,40.0298881530762,1.99635962807956,18.8999995589256,0.00015137224501903,2.68721313330764E-5,0.25,5.64582506567885E-8,1.33997360421837E-5,6.43148300308988E-8,328.5021057,328.5021057,99.6243667602539,99.6243667602539,57.3918556530445,20.6272582788013,23.288654,0,0,0,40,4374,332.0051,99.6243667602539,,,,,,,,,,,,,0,,,,-0.0049,,,,,,328.5021057,,,,
,31533520.95,331.9884949,99.6243667602539,,,2,,,,18.889999755621,,,,,,,331.9884949,331.9884949,99.6243667602539,99.6243667602539,,,23.668306,,,,-99999999,4374,335.5271,99.6243667602539,,,,,,,,,,,,,,,,,,,,,,,331.9884949,,,,
,31533642.085,335.0382385,99.6243667602539,1.36027358732438E-5,4.2546869469056E-7,1,0.999253354069792,40.0298881530762,1.99644930409974,18.8400000333786,0.000155342853868246,1.64752105535393E-5,0.25,-8.96485361194102E-7,1.35860803954522E-5,-8.87497622884973E-7,335.0382385,335.0382385,99.6243667602539,99.6243667602539,57.2449094914291,20.6265399339236,23.288654,0,0,0,40,4374,338.5628,99.6243667602539,,,,,,,,,,,,,0,,,,0.0049,,,,,,335.0382385,,,,
,31533781.995,338.5163269,99.6243667602539,1.27887181925916E-5,4.62572076655812E-7,1,0.999253354069792,40.0298881530762,1.99624320139367,18.8400000333786,0.00014468656214425,2.31564674140371E-5,0.25,-1.63264023347005E-7,1.27711350095432E-5,-1.55733858454853E-7,338.5163269,338.5163269,99.6243667602539,99.6243667602539,57.2183341217753,20.6325212616122,24.047956,0,0,0,40,4374,342.08145,99.6243667602539,,,,,,,,,,,,,0,,,,-0.00245,,,,,,338.5163269,,,,
,31533940.08,342.4092712,99.6243667602539,,,2,,,,18.8300002300739,,,,,,,342.4092712,342.4092712,99.6243667602539,99.6243667602539,,,24.047956,,,,-99999999,4374,346.0201,99.6243667602539,,,,,,,,,,,,,,,,,,,,,,,342.4092712,,,,
,31534065.135,345.52186585,99.6243667602539,1.24412637109296E-5,3.90817211474046E-7,1,0.999253354069792,40.0298881530762,1.99615429764221,18.7800005078316,0.000141745064011435,1.6577300065878E-5,0.25,-6.85345840944845E-7,1.24214762390839E-5,-6.77277941346162E-7,345.4916077,345.552124,99.6243667602539,99.6243667602539,57.0909286731407,20.6269376133701,24.047956,0,0,0,40,4374,349.16725,99.6243667602539,,,,,,,,,,,,,0,,,,-0.00245,,,,,,345.52186585,,,,
,31534225.26,349.00283815,99.6243667602539,1.2646368313614E-5,4.85427664581271E-7,1,0.999253354069792,40.0298881530762,1.99615971106119,18.7800005078316,0.00014243797037534,2.62462880365174E-5,0.25,1.3620185575826E-7,1.26242977959628E-5,1.43004492986247E-7,348.9992676,349.0064087,99.6243667602539,99.6243667602539,57.4207759082561,20.6285353198468,23.668306,0,0,0,40,4374,350.72335,99.6243667602539,,,,,,,,,,,,,0,,,,0,,,,,,349.00283815,,,,
,31534518.805,349.78260805,99.6243667602539,1.2502793916994E-5,4.81783411452285E-7,1,0.999253354069792,40.0298881530762,1.99598314925038,18.7800005078316,0.000141587061177658,2.14303272027485E-5,0.25,-2.65514585356533E-7,1.24808673022029E-5,-2.58087559075426E-7,349.7810059,349.7842102,99.6243667602539,99.6243667602539,57.1049979864868,20.6267466405868,23.668306,0,0,0,40,4369,350.78335,99.6243667602539,,,,,,,,,,,,,0,,,,0.00245,,,,,,349.78260805,,,,