File: data/doubleLayers/dl_0-25/ppms/data/DD205_10_HYST_100OE_10K.DAT
[Header]
; VSM Data File (default extension .dat)
; Copyright (c) 2003-2013, Quantum Design, Inc. All rights reserved.
TITLE,
FILEOPENTIME,31540391.00,01/01/2019,9:15 am
BYAPP,VSM,2.0,2.0
INFO,PPMS VSM Option Release 1.4.10 Build 1,APPNAME
INFO,Quantum Design Linear Motor Servo Controller,MOTOR_MODULE_NAME
INFO,3101-100 M1,MOTOR_HW_VERSION
INFO,MMC1014,MOTOR_SERIAL_NUMBER
INFO,SRV No X-over 01.03.11,MOTOR_SOFTWARE_VERSION
INFO,Quantum Design VSM Detection Module,VSM_MODULE_NAME
INFO,3101-150 F0,VSM_HW_VERSION
INFO,VSM707,VSM_SERIAL_NUMBER
INFO,VSM No X-over 01.02.05 May 20 2008 13:51:47,VSM_SOFTWARE_VERSION
INFO,704,PREAMP_SERIAL_NUMBER
INFO,822,COIL_SERIAL_NUMBER
INFO,0,MOMENT_UNITS
INFO,CoFe2O4,SAMPLE_MATERIAL
INFO,Double Layer thin concentration,SAMPLE_COMMENT
INFO,27.44,SAMPLE_MASS
INFO,,SAMPLE_VOLUME
INFO,,SAMPLE_MOLECULAR_WEIGHT
INFO,,SAMPLE_SIZE
INFO,,SAMPLE_SHAPE
DATATYPE,COMMENT,1
DATATYPE,TIME,2
STARTUPAXIS,X,2
STARTUPAXIS,Y1,5
[Data]
Comment,Time Stamp (sec),Temperature (K),Magnetic Field (Oe),Moment (emu),M. Std. Err. (emu),Transport Action,Averaging Time (sec),Frequency (Hz),Peak Amplitude (mm),Center Position (mm),Coil Signal' (mV),Coil Signal" (mV),Range (mV),M. Quad. Signal (emu),M. Raw' (emu),M. Raw" (emu),Min. Temperature (K),Max. Temperature (K),Min. Field (Oe),Max. Field (Oe),Mass (grams),Motor Lag (deg),Pressure (Torr),VSM Status (code),Motor Status (code),Measure Status (code),Measure Count,PPMS Status (code),System Temp. (K),System Field (Oe),Sample Position (deg),Bridge 1 Resistance (ohms),Bridge 1 Excitation (에),Bridge 2 Resistance (ohms),Bridge 2 Excitation (에),Bridge 3 Resistance (ohms),Bridge 3 Excitation (에),Bridge 4 Resistance (ohms),Bridge 4 Excitation (에),Signal 1 Vin (V),Signal 2 Vin (V),Digital Inputs (code),Drive 1 Iout (mA),Drive 1 Ipower (W),Drive 2 Iout (mA),Drive 2 Ipower (W),Pressure (),Map 20 (),Map 21 (),Map 22 (),Map 23 (),Map 24 (),Map 25 (),Map 26 (),Map 27 (),Map 28 (),Map 29 ()
,31540406.47,10.0039825,99.6243667602539,,,2,,,,19.9699995973706,,,,,,,10.0039825,10.0039825,99.6243667602539,99.6243667602539,,,12.658426,,,,-99999999,4369,9.9905,99.6243667602539,,,,,,,,,,,,,,,,,,,,,,,10.0039825,,,,
,31540541.285,10.0007048,4231.34375,8.62102347039248E-6,3.86240991578622E-7,1,0.999253354069792,40.0298881530762,1.99722043677654,19.9200008064508,9.7787178118122E-5,1.2162623690933E-5,0.25,-4.50875651592563E-7,8.57573096809483E-6,-4.04649383343634E-7,10.0007048,10.0007048,4198.8271484375,4263.8603515625,55.7832641604674,20.5916610119552,12.278775,0,0,0,40,4449,9.9906,4231.34375,,,,,,,,,,,,,0,,,,-0.00245,,,,,,10.0007048,,,,
,31540628.41,10.0001898,8584.7080078125,-2.4321789440838E-6,3.24078079498691E-7,1,0.999253354069792,40.0298881530762,1.99711481415353,19.9200008064508,-2.62245495924905E-5,-1.11282999784605E-5,0.25,-5.56681748724618E-7,-2.41651520967844E-6,-5.66891041253559E-7,10.0001898,10.0001898,8557.3916015625,8612.0244140625,56.4007506906598,20.5943211824184,13.038077,0,0,0,40,4449,9.98855,8584.7080078125,,,,,,,,,,,,,0,,,,0.00245,,,,,,10.0001898,,,,
,31540717,10.0009661,13012.94140625,-1.24832526474369E-5,4.1585415682399E-7,1,0.999253354069792,40.0298881530762,1.99694358686705,19.9200008064508,-0.000139547882978702,-2.95607900721365E-5,0.25,-4.00982094071265E-7,-1.24205227047647E-5,-4.70382173735821E-7,10.0009661,10.0009661,12980.458984375,13045.423828125,56.567237565256,20.606360039406,12.658426,0,0,0,40,4449,9.98725,13012.94140625,,,,,,,,,,,,,0,,,,0,,,,,,10.0009661,,,,
,31540804.79,10.0012856,17400.826171875,-2.06065560162779E-5,4.1874411735937E-7,1,0.999253354069792,40.0298881530762,1.9966425985336,19.9200008064508,-0.000229505957692188,-5.38854492507607E-5,0.25,-1.10696127519848E-6,-2.05083053201346E-5,-1.22618180676644E-6,10.0012856,10.0012856,17368.326171875,17433.326171875,56.7329428113329,20.6013116401922,12.658426,0,0,0,40,4449,9.9866,17400.826171875,,,,,,,,,,,,,0,,,,0.0049,,,,,,10.0012856,,,,
,31540892.99,10.00091745,21810.7158203125,-2.49651980306083E-5,5.48201264492527E-7,1,0.999253354069792,40.0298881530762,1.99667792853041,19.9200008064508,-0.000280311667729877,-5.33564593323723E-5,0.25,-2.71285547753993E-7,-2.48631766861657E-5,-4.27770577149771E-7,10.0008793,10.0009556,21785.830078125,21835.6015625,56.6930797568522,20.604815293197,12.278775,0,0,0,40,4449,9.98485,21810.7158203125,,,,,,,,,,,,,0,,,,0,,,,,,10.00091745,,,,
,31540982.05,10.00009585,26261.1953125,-2.79968213905963E-5,4.81736379599187E-7,1,0.999253354069792,40.0298881530762,1.99664610310669,19.9200008064508,-0.000313700712553181,-6.42512005401031E-5,0.25,-6.87012574137589E-7,-2.78924269809754E-5,-8.68554942821901E-7,9.9999561,10.0002356,26258.740234375,26263.650390625,56.5625477941406,20.6088791081199,12.278775,0,0,0,40,4449,9.9856,26261.1953125,,,,,,,,,,,,,0,,,,0,,,,,,10.00009585,,,,
,31541069.465,10.0002356,30631.68359375,-3.25653372647412E-5,5.93393427141154E-7,1,0.999253354069792,40.0298881530762,1.99656971849565,19.9200008064508,-0.000363565270515856,-8.29908758527963E-5,0.25,-1.52240042672875E-6,-3.24536452868275E-5,-1.73893051376957E-6,10.0002356,10.0002356,30606.185546875,30657.181640625,56.8697278021983,20.6090272730591,13.038077,0,0,0,40,4449,9.98515,30631.68359375,,,,,,,,,,,,,0,,,,0,,,,,,10.0002356,,,,
,31541158.085,9.9988356,35059.78515625,-4.1387242582701E-5,5.93882846141498E-7,1,0.999253354069792,40.0298881530762,1.99644787331311,19.9200008064508,-0.000463882308103362,-9.63888796429789E-5,0.25,-1.11668630104812E-6,-4.12700262377718E-5,-1.40283803999476E-6,9.9988356,9.9988356,35029.7265625,35089.84375,57.2097362080637,20.6077471671656,12.658426,0,0,0,40,4449,9.9864,35059.78515625,,,,,,,,,,,,,0,,,,0,,,,,,9.9988356,,,,
,31541246.165,9.9976182,39461.849609375,-5.21815153208952E-5,7.90780015863825E-7,1,0.999253354069792,40.0298881530762,1.99655706502138,19.9200008064508,-0.000585351078549267,-0.000120590121379713,0.25,-1.311177750547E-6,-5.20585790681145E-5,-1.68089936830023E-6,9.9975805,9.9976559,39431.70703125,39491.9921875,56.7360693254098,20.6095000761551,12.278775,0,0,0,40,4449,9.9864,39461.849609375,,,,,,,,,,,,,0,,,,0.00245,,,,,,9.9976182,,,,
,31541332.75,9.9976482,43787.375,-6.57604084173557E-5,7.06142392501917E-7,1,0.999253354069792,40.0298881530762,1.99651567511218,19.9200008064508,-0.000738121521802082,-0.000151331080035233,0.25,-1.58217045953979E-6,-6.56357704896487E-5,-2.05678940131895E-6,9.9975166,9.9977798,43759.66015625,43815.08984375,56.8322096332752,20.6130279457861,12.658426,0,0,0,40,4449,9.9893,43787.375,,,,,,,,,,,,,0,,,,-0.00245,,,,,,9.9976482,,,,
,31541418.7,9.99669075,48085.5703125,-7.90079764347647E-5,7.89597779966627E-7,1,0.999253354069792,40.0298881530762,1.99648002207368,19.9200008064508,-0.000886041859163455,-0.000188308548099551,0.25,-2.46296000554032E-6,-7.88891650030949E-5,-3.0402003822894E-6,9.9966431,9.9967384,48057.7265625,48113.4140625,57.0534105042176,20.613893451828,12.278775,0,0,0,40,4449,9.9923,48085.5703125,,,,,,,,,,,,,0,,,,0,,,,,,9.99669075,,,,
,31541506.42,9.9958229,52468.40234375,-9.22096506908787E-5,7.93067154614568E-7,1,0.999253354069792,40.0298881530762,1.99641868403514,19.9200008064508,-0.00103899247895044,-0.000195054892615288,0.25,-6.70399760163681E-7,-9.21280897630677E-5,-1.3526448766815E-6,9.9958229,9.9958229,52465.66796875,52471.13671875,57.0706063316407,20.6163266026102,12.658426,0,0,0,40,4449,9.9955,52468.40234375,,,,,,,,,,,,,0,,,,0,,,,,,9.9958229,,,,
,31541601.275,9.99573615,57210.955078125,-0.000108692647358465,1.0676832882518E-6,1,0.999253354069792,40.0298881530762,1.99635335470823,19.9200008064508,-0.00122319355601036,-0.000241433808560913,0.25,-1.79805530859481E-6,-0.000108639576398953,-2.60583943968216E-6,9.9957228,9.9957495,57178.546875,57243.36328125,56.8376810329099,20.6156374211335,12.658426,0,0,0,40,4449,9.99915,57210.955078125,,,,,,,,,,,,,0,,,,0,,,,,,9.99573615,,,,
,31541701.425,9.9955797,62216.248046875,-0.000125429192057116,6.96479982576316E-7,1,0.999253354069792,40.0298881530762,1.99613610892844,19.9200008064508,-0.00141313069887308,-0.000272774963551183,0.25,-1.54907768238717E-6,-0.000125430987223323,-2.48262266920026E-6,9.9955797,9.9955797,62211.16796875,62221.328125,57.1049979864868,20.6162137905126,12.278775,0,0,0,40,4449,10.00375,62216.248046875,,,,,,,,,,,,,0,,,,0.0049,,,,,,9.9955797,,,,
,31541803.875,9.9939365,67336.93359375,-0.000142336010188817,1.05929967749092E-6,1,0.999253354069792,40.0298881530762,1.9960343011688,19.9200008064508,-0.00160446339486852,-0.000308581976125104,0.25,-1.66564956852025E-6,-0.000142404125676389,-2.7221948600021E-6,9.9939365,9.9939365,67334.5,67339.3671875,56.618043419006,20.6168616659322,11.899124,0,0,0,40,4449,10.0089,67336.93359375,,,,,,,,,,,,,0,,,,-0.0049,,,,,,9.9939365,,,,
,31541902.25,9.994463,72252.0546875,-0.000163349484563615,1.28024196668742E-6,1,0.999253354069792,40.0298881530762,1.99594596705686,19.9200008064508,-0.00183846179087316,-0.000374052418752388,0.25,-3.67028544492404E-6,-0.000163482966426062,-4.87753323719919E-6,9.994463,9.994463,72247.09375,72257.015625,56.739977468006,20.616632857681,12.278775,0,0,0,40,4449,10.0144,72252.0546875,,,,,,,,,,,,,0,,,,0,,,,,,9.994463,,,,
,31542001.125,9.9941826,77194.81640625,-0.000179696918536322,9.47813086202727E-7,1,0.999253354069792,40.0298881530762,1.99606793387922,19.9200008064508,-0.00202729076473474,-0.00038989745192579,0.25,-2.12416631207337E-6,-0.000179929184097122,-3.43903225006046E-6,9.9941826,9.9941826,77164.96875,77224.6640625,57.217552493256,20.6149574928105,12.658426,0,0,0,40,4449,10.0189,77194.81640625,,,,,,,,,,,,,0,,,,-0.0049,,,,,,9.9941826,,,,
,31542102.195,9.9952936,82248.06640625,-0.000198223221627308,1.1530612179008E-6,1,0.999253354069792,40.0298881530762,1.99577651804798,19.9200008064508,-0.00223535905543133,-0.000438416076703865,0.25,-3.08739556767791E-6,-0.000198549684676408,-4.52296643929437E-6,9.9952936,9.9952936,82243.25,82252.8828125,57.2652318329291,20.6187573260491,12.658426,0,0,0,40,4449,10.0237,82248.06640625,,,,,,,,,,,,,0,,,,-0.0049,,,,,,9.9952936,,,,
,31542197.69,9.9949684,87021.3828125,-0.00021377693180447,1.24134810802024E-6,1,0.999253354069792,40.0298881530762,1.99575494561679,19.9200008064508,-0.0024084930814306,-0.000489941069027632,0.25,-4.85031958579873E-6,-0.000214190539504119,-6.38274112520041E-6,9.9949684,9.9949684,86991.3046875,87051.4609375,57.0135474497368,20.6177818464642,12.658426,0,0,0,40,4449,10.0285,87021.3828125,,,,,,,,,,,,,0,,,,0,,,,,,9.9949684,,,,
,31542306.23,9.9969664,88350.58203125,-0.000220181971638373,1.24458972168766E-6,1,0.999253354069792,40.0298881530762,1.99600501135434,19.9200008064508,-0.0024791899267366,-0.000515764634274498,0.25,-5.9774992743151E-6,-0.000220620974079149,-7.55225516020556E-6,9.9969664,9.9969664,88348.0859375,88353.078125,57.0151107067753,20.6169494683471,12.658426,0,0,0,40,4449,10.0328,88350.58203125,,,,,,,,,,,,,0,,,,0,,,,,,9.9969664,,,,
,31542399.985,10.0006275,83662.31640625,-0.000201467769638348,1.17676657050908E-6,1,0.999253354069792,40.0298881530762,1.99586303513032,19.9200008064508,-0.00226679522369233,-0.000476097052659844,0.25,-5.83487003153552E-6,-0.000201800840892546,-7.29390209262992E-6,10.0006275,10.0006275,83635.0625,83689.5703125,56.9205336559483,20.6187113497753,12.278775,0,0,0,40,4449,10.02945,83662.31640625,,,,,,,,,,,,,0,,,,0,,,,,,10.0006275,,,,
,31542502.21,10.0022092,78553.2578125,-0.000180419189505684,8.03491868022498E-7,1,0.999253354069792,40.0298881530762,1.99591115367817,19.9200008064508,-0.0020307214820843,-0.000418010993199208,0.25,-4.48366118631502E-6,-0.00018065421045734,-5.80362723635245E-6,10.0021715,10.0022469,78521.109375,78585.40625,56.9658681100637,20.6195353223989,11.899124,0,0,0,40,4449,10.0275,78553.2578125,,,,,,,,,,,,,0,,,,0.00245,,,,,,10.0022092,,,,
,31542599.455,10.0028009,73692.05078125,-0.000163719388729002,7.0162769700202E-7,1,0.999253354069792,40.0298881530762,1.9956346577989,19.9200008064508,-0.00184536332773923,-0.000359371463988221,0.25,-2.30854782475503E-6,-0.000163882602780489,-3.51453478286641E-6,10.0028009,10.0028009,73686.890625,73697.2109375,57.2660134614484,20.6247164233168,11.899124,0,0,0,40,4449,10.0249,73692.05078125,,,,,,,,,,,,,0,,,,-0.0098,,,,,,10.0028009,,,,
,31542699.385,10.0032072,68697.00390625,-0.000148453927704672,7.38820298409158E-7,1,0.999253354069792,40.0298881530762,1.99546635552141,19.9200008064508,-0.00167189890750994,-0.000328845935891844,0.25,-2.36320835861802E-6,-0.000148537842544281,-3.46415491632529E-6,10.0032072,10.0032072,68689.4296875,68704.578125,56.9408559974483,20.6248492101633,12.278775,0,0,0,40,4449,10.02065,68697.00390625,,,,,,,,,,,,,0,,,,-0.00245,,,,,,10.0032072,,,,
,31542797.32,10.004405,63801.005859375,-0.000128384513846046,7.58176581366873E-7,1,0.999253354069792,40.0298881530762,1.9955928703084,19.9200008064508,-0.00144693844139945,-0.000275405299736742,0.25,-1.25290524779262E-6,-0.000128407405136451,-2.20796594966164E-6,10.004405,10.004405,63766.421875,63835.58984375,57.3160376866791,20.6237051707859,12.278775,0,0,0,40,4449,10.0171,63801.005859375,,,,,,,,,,,,,0,,,,0,,,,,,10.004405,,,,
,31542900.515,10.0026665,58643.130859375,-0.000113826367295621,8.07306542073709E-7,1,0.999253354069792,40.0298881530762,1.99561903764261,19.9200008064508,-0.00128215275851755,-0.000244682708315582,0.25,-1.16482989546378E-6,-0.000113791727986853,-2.01165964400615E-6,10.0026665,10.0026665,58638.015625,58648.24609375,57.017455592333,20.6231847257168,11.899124,0,0,0,40,4449,10.0147,58643.130859375,,,,,,,,,,,,,0,,,,0.0049,,,,,,10.0026665,,,,
,31543000.29,10.0036483,53658.220703125,-9.50543712301774E-5,5.57718129880352E-7,1,0.999253354069792,40.0298881530762,1.99546771068149,19.9200008064508,-0.00106728592534729,-0.000219869215151637,0.25,-2.3626717325837E-6,-9.49691390680462E-5,-3.06591722637326E-6,10.0034304,10.0038662,53625.7734375,53690.66796875,57.2957153451791,20.6267016059717,12.278775,0,0,0,40,4449,10.00975,53658.220703125,,,,,,,,,,,,,0,,,,0,,,,,,10.0036483,,,,
,31543103.425,10.0046592,48500.43359375,-7.7976099867716E-5,7.34670106285465E-7,1,0.999253354069792,40.0298881530762,1.99531149169994,19.9200008064508,-0.000874560271627048,-0.000182745270915047,0.25,-2.16343405242565E-6,-7.7864105597825E-5,-2.73410147674415E-6,10.0046406,10.0046778,48472.984375,48527.8828125,57.126101956506,20.6306322679689,11.899124,0,0,0,40,4449,10.00725,48500.43359375,,,,,,,,,,,,,0,,,,0,,,,,,10.0046592,,,,
,31543208.285,10.003581,43260.2578125,-6.08903150479831E-5,7.02063078957076E-7,1,0.999253354069792,40.0298881530762,1.99526658716756,19.9200008064508,-0.000682888695988893,-0.000140716170024281,0.25,-1.52644761390746E-6,-6.07711169033361E-5,-1.96494973418004E-6,10.003581,10.003581,43255.421875,43265.09375,56.9760292808137,20.6327838622316,11.899124,0,0,0,40,4449,10.00255,43260.2578125,,,,,,,,,,,,,0,,,,0,,,,,,10.003581,,,,
,31543308.54,10.0026865,38247.802734375,-4.41586461742207E-5,6.76319996707634E-7,1,0.999253354069792,40.0298881530762,1.99546155585913,19.9200008064508,-0.000493907896742901,-0.000108224442965048,0.25,-1.66552480227495E-6,-4.40450234276763E-5,-1.97524659374091E-6,10.0026865,10.0026865,38242.89453125,38252.7109375,57.4090514804676,20.6293703270159,12.278775,0,0,0,40,4449,10.0015,38247.802734375,,,,,,,,,,,,,0,,,,0.0049,,,,,,10.0026865,,,,
,31543409.43,10.001749,33205.845703125,-2.7850663094447E-5,6.76054100093915E-7,1,0.999253354069792,40.0298881530762,1.99546416689743,19.9200008064508,-0.000308266983576764,-8.53229657255935E-5,0.25,-2.57513202728607E-6,-2.77537645215294E-5,-2.76025992472058E-6,10.001749,10.001749,33200.59375,33211.09765625,57.0057311645445,20.6346984172505,12.658426,0,0,0,40,4449,9.9991,33205.845703125,,,,,,,,,,,,,0,,,,0,,,,,,10.001749,,,,
,31543508.955,10.0009794,28233.43359375,-1.18543579542337E-5,6.35156404506732E-7,1,0.999253354069792,40.0298881530762,1.99545838076976,19.9200008064508,-0.000130524456642511,-3.975135303587E-5,0.25,-1.40575540587958E-6,-1.18051030953014E-5,-1.48017396164854E-6,10.0009794,10.0009794,28228.2734375,28238.59375,57.0409044479099,20.6298179324763,12.278775,0,0,0,40,4449,9.999,28233.43359375,,,,,,,,,,,,,0,,,,0,,,,,,10.0009794,,,,
,31543607.26,10.0010576,23318.40625,4.0354330443214E-6,4.72912764094426E-7,1,0.999253354069792,40.0298881530762,1.99549380982635,19.9200008064508,4.64450509914667E-5,2.183543316446E-6,0.25,-5.28989010001755E-7,4.02321429692817E-6,-5.01102294010035E-7,10.0010576,10.0010576,23285.8828125,23350.9296875,57.2566339192176,20.6357348276767,11.899124,0,0,0,40,4449,9.99815,23318.40625,,,,,,,,,,,,,0,,,,0,,,,,,10.0010576,,,,
,31543704.205,10.0001297,18473.3095703125,1.8810291889706E-5,3.93798550734113E-7,1,0.999253354069792,40.0298881530762,1.9953539110446,19.9200008064508,0.000213126123608655,2.82865514971572E-5,0.25,-8.48273115718042E-7,1.87337735309947E-5,-7.29909162227275E-7,10.0001297,10.0001297,18443.380859375,18503.23828125,57.1558038402368,20.6344695922174,11.899124,0,0,0,40,4449,9.9982,18473.3095703125,,,,,,,,,,,,,0,,,,-0.00245,,,,,,10.0001297,,,,
,31543801.6,9.9997745,13606.2065429688,3.33515963416937E-5,4.57773257109423E-7,1,0.999253354069792,40.0298881530762,1.9954971144638,19.9200008064508,0.000375159310553785,6.4549548728375E-5,0.25,-2.09726939794371E-7,3.31930597079101E-5,-1.66889870267622E-8,9.9997416,9.9998074,13576.0751953125,13636.337890625,57.0870205305445,20.6343842430505,12.278775,0,0,0,40,4449,9.9994,13606.2065429688,,,,,,,,,,,,,0,,,,-0.00245,,,,,,9.9997745,,,,
,31543898.585,9.9993777,8758.05322265625,4.81832132005742E-5,3.38530974072333E-7,1,0.999253354069792,40.0298881530762,1.99542789042602,19.9200008064508,0.00054145579758229,9.48904435315108E-5,0.25,-1.36597145070127E-7,4.79337261737524E-5,1.24404251426825E-7,9.9992828,9.9994726,8727.953125,8788.1533203125,57.0729512171983,20.6367109737072,11.899124,0,0,0,40,4449,9.9993,8758.05322265625,,,,,,,,,,,,,0,,,,0.00245,,,,,,9.9993777,,,,
,31543997.045,9.99924325,3837.89990234375,6.17225456876872E-5,3.56147199567706E-7,1,0.999253354069792,40.0298881530762,1.99529186588498,19.9200008064508,0.000693139929255177,0.000122466925738665,0.25,-6.71683477689586E-8,6.13806730963731E-5,2.44662531049505E-7,9.9989767,9.9995098,3835.44189453125,3840.35791015625,57.1479875550445,20.639732967946,11.899124,0,0,0,40,4449,10.0017,3837.89990234375,,,,,,,,,,,,,0,,,,0,,,,,,9.99924325,,,,
,31544094.815,9.9995718,-1049.12335205078,7.06018805478347E-5,3.63301337415531E-7,1,0.999253354069792,40.0298881530762,1.99534641103232,19.9200008064508,0.000792004448369187,0.000144250532556615,0.25,3.08444550939353E-7,7.01977457490873E-5,6.50417575344256E-7,9.9995718,9.9995718,-1071.64379882812,-1026.60290527344,57.0995265868522,20.6388705078462,11.899124,0,0,0,40,4449,9.99645,-1049.12335205078,,,,,,,,,,,,,0,,,,0,,,,,,9.9995718,,,,
,31544194.72,9.9989424,-6042.08837890625,8.19901886882243E-5,3.04828243028272E-7,1,0.999253354069792,40.0298881530762,1.99531648128932,19.9200008064508,0.000919464629533479,0.000170735869539845,0.25,6.12900428796957E-7,8.15445961060652E-5,1.03615310032534E-6,9.9989424,9.9989424,-6046.96533203125,-6037.21142578125,57.2980602307368,20.6426290012834,11.519473,0,0,0,40,4449,9.99965,-6042.08837890625,,,,,,,,,,,,,0,,,,0.00245,,,,,,9.9989424,,,,
,31544292.93,9.9994822,-10950.4711914062,9.06528838990738E-5,3.76621876170322E-7,1,0.999253354069792,40.0298881530762,1.99538852652399,19.9200008064508,0.00101706600869846,0.000188667125083769,0.25,6.28314464159993E-7,9.01946117045471E-5,1.12956886595146E-6,9.9994822,9.9994822,-10980.40234375,-10920.5400390625,56.983845566006,20.6398378855078,12.278775,0,0,0,40,4449,10,-10950.4711914062,,,,,,,,,,,,,0,,,,0.00245,,,,,,9.9994822,,,,
,31544393.715,10.0006809,-15988.216796875,9.15011827510559E-5,3.92636400727676E-7,1,0.999253354069792,40.0298881530762,1.99552061729939,19.9200008064508,0.00102622348724056,0.000195450782093788,0.25,1.03902709101176E-6,9.10763602284973E-5,1.57658930278198E-6,10.0006809,10.0006809,-15993.296875,-15983.13671875,57.2019199228714,20.6382447443702,11.519473,0,0,0,40,4449,9.9996,-15988.216796875,,,,,,,,,,,,,0,,,,0.00245,,,,,,10.0006809,,,,
,31544492.255,10.0005283,-20912.4755859375,8.06818415038111E-5,4.76231831785269E-7,1,0.999253354069792,40.0298881530762,1.99535485498996,19.9200008064508,0.000904605639808906,0.000175911453889575,0.25,1.20146744250166E-6,8.0342994505623E-5,1.70123655598297E-6,10.0005283,10.0005283,-20915.212890625,-20909.73828125,57.3340151426215,20.64218463165,11.899124,0,0,0,40,4449,9.9987,-20912.4755859375,,,,,,,,,,,,,0,,,,0,,,,,,10.0005283,,,,
,31544592.81,10.0004892,-25937.220703125,6.29249730086165E-5,5.00542691724626E-7,1,0.999253354069792,40.0298881530762,1.99556936985008,19.9200008064508,0.000705425266303168,0.000140174108455674,0.25,1.17572773283481E-6,6.26906839329422E-5,1.58391101342958E-6,10.0004892,10.0004892,-25967.259765625,-25907.181640625,56.9424192544868,20.6350275653361,11.899124,0,0,0,40,4449,9.99805,-25937.220703125,,,,,,,,,,,,,0,,,,0.00245,,,,,,10.0004892,,,,
,31544689.585,10.0005679,-30774.685546875,5.22630434974951E-5,4.71292388562929E-7,1,0.999253354069792,40.0298881530762,1.9953337867961,19.9200008064508,0.00058534363086316,0.00012083197611262,0.25,1.35150571716881E-6,5.20919880191075E-5,1.70277658860021E-6,10.0004358,10.0007,-30804.580078125,-30744.791015625,57.1378263842945,20.640161098314,12.278775,0,0,0,40,4449,9.99825,-30774.685546875,,,,,,,,,,,,,0,,,,0,,,,,,10.0005679,,,,
,31544788.865,9.9992943,-35734.451171875,5.23850756164328E-5,7.10495562529161E-7,1,0.999253354069792,40.0298881530762,1.9956068867082,19.9200008064508,0.00058896060119894,0.000110811862314975,0.25,4.21778159419204E-7,5.22473798312261E-5,7.87980473361102E-7,9.9992943,9.9992943,-35766.828125,-35702.07421875,57.3332335141022,20.6378586304119,11.899124,0,0,0,40,4449,9.9997,-35734.451171875,,,,,,,,,,,,,0,,,,0,,,,,,9.9992943,,,,
,31544890.47,9.9983091,-40814.36328125,6.10530142583667E-5,7.65803899863764E-7,1,0.999253354069792,40.0298881530762,1.99536042853656,19.9200008064508,0.000686295258804715,0.000131467531572023,0.25,6.82584554876196E-7,6.09239644924427E-5,1.11959428435686E-6,9.9983091,9.9983091,-40819.38671875,-40809.33984375,56.9119357422368,20.6409684594936,11.899124,0,0,0,40,4449,10.00105,-40814.36328125,,,,,,,,,,,,,0,,,,0.0049,,,,,,9.9983091,,,,
,31544990.81,9.998456,-45829.103515625,7.44015308653981E-5,8.7235220034028E-7,1,0.999253354069792,40.0298881530762,1.99533758413163,19.9200008064508,0.000834363110307182,0.000173693128423486,0.25,2.01192982508966E-6,7.42746538482938E-5,2.55231634911246E-6,9.998456,9.998456,-45861.609375,-45796.59765625,57.1980117802753,20.6426256817199,11.519473,0,0,0,40,4449,10.0013,-45829.103515625,,,,,,,,,,,,,0,,,,0.0049,,,,,,9.998456,,,,
,31545091.81,9.9976778,-50878.923828125,8.88137513055413E-5,1.1202749057507E-6,1,0.999253354069792,40.0298881530762,1.99521713193436,19.9200008064508,0.000998378566617147,0.000196696665415081,0.25,1.44222774158679E-6,8.87151429767911E-5,2.09684805609344E-6,9.9976778,9.9976778,-50883.765625,-50874.08203125,57.5630322987561,20.6449603762236,11.899124,0,0,0,40,4449,10.0045,-50878.923828125,,,,,,,,,,,,,0,,,,-0.00245,,,,,,9.9976778,,,,
,31545190.795,9.9967813,-55823.216796875,0.00010418178407651,9.84952220682635E-7,1,0.999253354069792,40.0298881530762,1.99550824068657,19.9200008064508,0.00116655713141666,0.000260368493587058,0.25,4.30164599069334E-6,0.00010409776368692,5.07370784211801E-6,9.9967813,9.9967813,-55855.8515625,-55790.58203125,57.2183341217753,20.641379601245,11.899124,0,0,0,40,4449,10.00735,-55823.216796875,,,,,,,,,,,,,0,,,,-0.00245,,,,,,9.9967813,,,,
,31545290.125,9.9960241,-60785.345703125,0.000119737863260816,7.73126859166679E-7,1,0.999253354069792,40.0298881530762,1.99530572000211,19.9200008064508,0.00134451372746371,0.000281241604765066,0.25,3.33759908413736E-6,0.000119709864960737,4.22877874735512E-6,9.9960241,9.9960241,-60787.83203125,-60782.859375,57.6255625802946,20.6458090063164,11.899124,0,0,0,40,4449,10.0113,-60785.345703125,,,,,,,,,,,,,0,,,,0,,,,,,9.9960241,,,,
,31545390.065,9.9957304,-65782.84765625,0.000137104418158136,9.28205039243917E-7,1,0.999253354069792,40.0298881530762,1.99534647707547,19.9200008064508,0.00154328974788449,0.000305322322184498,0.25,2.33093723865182E-6,0.000137145866077437,3.35017890001596E-6,9.9956722,9.9957886,-65810.25,-65755.4453125,57.268358347006,20.6458472367211,11.899124,0,0,0,40,4449,10.01565,-65782.84765625,,,,,,,,,,,,,0,,,,0.00245,,,,,,9.9957304,,,,
,31545490.675,9.9959984,-70809.81640625,0.000157718827119975,9.12492089640504E-7,1,0.999253354069792,40.0298881530762,1.99534698494033,19.9200008064508,0.00178162648532424,0.000320729641677817,0.25,-2.50249907921743E-8,0.000157855069108983,1.13965866767207E-6,9.9959984,9.9959984,-70812.4140625,-70807.21875,57.0534105042176,20.6455655645296,11.899124,0,0,0,40,4449,10.0208,-70809.81640625,,,,,,,,,,,,,0,,,,0,,,,,,9.9959984,,,,
,31545588.86,9.9960728,-75716.66796875,0.000171974952831826,1.01281171757785E-6,1,0.999253354069792,40.0298881530762,1.99533284641801,19.9200008064508,0.00193848254842292,0.000377322829234788,0.25,2.41428557370651E-6,0.000172174454954332,3.67669448501161E-6,9.9960728,9.9960728,-75719.3203125,-75714.015625,57.1362631272561,20.6462452870574,11.899124,0,0,0,40,4449,10.02265,-75716.66796875,,,,,,,,,,,,,0,,,,0,,,,,,9.9960728,,,,
,31545684.85,9.9954882,-80514.30859375,0.000190288440945584,1.32388352795845E-6,1,0.999253354069792,40.0298881530762,1.99543417962268,19.9200008064508,0.0021515974936436,0.00038550440499999,0.25,-1.59362503456902E-7,0.00019060006128833,1.21921256888878E-6,9.9952717,9.9957047,-80546.7734375,-80481.84375,57.2488176340253,20.647074800785,11.899124,0,0,0,40,4449,10.0274,-80514.30859375,,,,,,,,,,,,,0,,,,0,,,,,,9.9954882,,,,
,31545783.055,9.9958925,-85421.45703125,0.000208828715326673,1.13579450952813E-6,1,0.999253354069792,40.0298881530762,1.99540472205716,19.9200008064508,0.00235599280779638,0.000456775999712574,0.25,2.81305806335733E-6,0.000209223274879411,4.31249933720589E-6,9.9958925,9.9958925,-85424.0234375,-85418.890625,57.3551191126407,20.6481305964612,12.278775,0,0,0,40,4449,10.03215,-85421.45703125,,,,,,,,,,,,,0,,,,0,,,,,,9.9958925,,,,
,31545873.22,9.9951057,-89927.8984375,0.000227229157423599,1.33832927533523E-6,1,0.999253354069792,40.0298881530762,1.99564018327962,19.9200008064508,0.00256166933484022,0.000513845674300232,0.25,4.55138513853904E-6,0.000227717641581211,6.16570935680155E-6,9.9951057,9.9951057,-89930.25,-89925.546875,57.4825245612753,20.6466291721132,11.519473,0,0,0,40,4449,10.0363,-89927.8984375,,,,,,,,,,,,,0,,,,0,,,,,,9.9951057,,,,
,31545971.43,9.9989295,-85934.51953125,0.000210817413572809,1.25537087140744E-6,1,0.999253354069792,40.0298881530762,1.9953541470573,19.9200008064508,0.00238484783521726,0.000425609751061452,0.25,-2.98770069539694E-7,0.000211245708305843,1.20652076320427E-6,9.9987869,9.9990721,-85959.3125,-85909.7265625,57.1042163579676,20.6485479912119,11.519473,0,0,0,40,4449,10.0355,-85934.51953125,,,,,,,,,,,,,0,,,,0,,,,,,9.9989295,,,,
,31546058.935,10.0008392,-81562.30078125,0.000195931108851776,1.29829618357692E-6,1,0.999253354069792,40.0298881530762,1.99535232596776,19.9200008064508,0.00220872648800369,0.000434488231494987,0.25,3.15985116952413E-6,0.000196243141087991,4.58131385692649E-6,10.0008392,10.0008392,-81592.1796875,-81532.421875,57.454385934583,20.6474190774131,11.899124,0,0,0,40,4449,10.03405,-81562.30078125,,,,,,,,,,,,,0,,,,0,,,,,,10.0008392,,,,
,31546149.03,10.00225115,-77059.52734375,0.000177322079768152,9.4999203041178E-7,1,0.999253354069792,40.0298881530762,1.9953885946437,19.9200008064508,0.00200068895462926,0.000379832631521293,0.25,1.67251356870121E-6,0.000177552496020415,2.96977037373992E-6,10.0022135,10.0022888,-77094.6640625,-77024.390625,57.2144259791791,20.6431639192839,11.519473,0,0,0,40,4449,10.03185,-77059.52734375,,,,,,,,,,,,,0,,,,0,,,,,,10.00225115,,,,
,31546240.095,10.003088,-72509.5546875,0.000162990916583609,9.45567561138174E-7,1,0.999253354069792,40.0298881530762,1.99556165510433,19.9200008064508,0.00183478961199003,0.000369498391762664,0.25,3.33773641672441E-6,0.000163129963717647,4.54158575380712E-6,10.003088,10.003088,-72541.6171875,-72477.4921875,57.301968373333,20.6437224063218,11.519473,0,0,0,40,4449,10.02835,-72509.5546875,,,,,,,,,,,,,0,,,,0,,,,,,10.003088,,,,
,31546331.895,10.0042276,-67920.20703125,0.000146481621472076,9.67523790963003E-7,1,0.999253354069792,40.0298881530762,1.99548626503472,19.9200008064508,0.00164649219756487,0.000341657232016648,0.25,3.85364336978142E-6,0.000146543301598205,4.94170153024077E-6,10.0042276,10.0042276,-67950.234375,-67890.1796875,56.9775925378522,20.6429669612231,11.899124,0,0,0,40,4449,10.02595,-67920.20703125,,,,,,,,,,,,,0,,,,0,,,,,,10.0042276,,,,
,31546423.565,10.0037622,-63340.453125,0.000130979404806414,9.42918807035682E-7,1,0.999253354069792,40.0298881530762,1.99547538802511,19.9200008064508,0.00147580063764072,0.000282267303771494,0.25,1.39516555068267E-6,0.000130996410770254,2.36972331419723E-6,10.0037622,10.0037622,-63373.01171875,-63307.89453125,57.3191642007561,20.6445166069069,12.278775,0,0,0,40,4449,10.02255,-63340.453125,,,,,,,,,,,,,0,,,,0,,,,,,10.0037622,,,,
,31546522.97,10.0037508,-58372.8046875,0.000113774628416308,8.48604840561363E-7,1,0.999253354069792,40.0298881530762,1.99543834063701,19.9200008064508,0.00128124875259488,0.0002455285319094,0.25,1.2515930980282E-6,0.000113736426861384,2.09791933967724E-6,10.0037508,10.0037508,-58375.26953125,-58370.33984375,56.9525804252368,20.6439261319155,11.139823,0,0,0,40,4449,10.0186,-58372.8046875,,,,,,,,,,,,,0,,,,0,,,,,,10.0037508,,,,
,31546624.78,10.0038166,-53283.064453125,9.5047535551224E-5,5.98859822141899E-7,1,0.999253354069792,40.0298881530762,1.99528680995551,19.9200008064508,0.00106967652730059,0.000205403289017966,0.25,1.08385656554895E-6,9.49682589117089E-5,1.78760776308211E-6,10.0038166,10.0038166,-53288.046875,-53278.08203125,57.3066581444484,20.6452124860297,12.278775,0,0,0,40,4449,10.0154,-53283.064453125,,,,,,,,,,,,,0,,,,0,,,,,,10.0038166,,,,
,31546723.79,10.0039835,-48336.373046875,7.87256584251687E-5,8.59011358628416E-7,1,0.999253354069792,40.0298881530762,1.99527462117077,19.9200008064508,0.000886117698404948,0.000166839772445793,0.25,6.18048163990519E-7,7.8622781449749E-5,1.19591042213519E-6,10.0039778,10.0039892,-48366.28515625,-48306.4609375,57.4801796757176,20.6457010269379,11.899124,0,0,0,40,4449,10.0118,-48336.373046875,,,,,,,,,,,,,0,,,,0,,,,,,10.0039835,,,,
,31546824.765,10.00421955,-43288.958984375,6.00128765296808E-5,7.1510756934096E-7,1,0.999253354069792,40.0298881530762,1.99533712242464,19.9200008064508,0.000674062080835205,0.000133199966610538,0.25,1.0168014654001E-6,5.98991094560214E-5,1.44989623920152E-6,10.0041151,10.004324,-43323.59375,-43254.32421875,57.4410982497561,20.6429982979925,11.899124,0,0,0,40,4449,10.0081,-43288.958984375,,,,,,,,,,,,,0,,,,0,,,,,,10.00421955,,,,
,31546924.465,10.00335785,-38306.84765625,4.49035574204801E-5,5.96832411652576E-7,1,0.999253354069792,40.0298881530762,1.99580364792518,19.9200008064508,0.000504019275544965,0.000100651368368502,0.25,8.57410824135841E-7,4.47942352660454E-5,1.17437865682088E-6,10.003355,10.0033607,-38337.0390625,-38276.65625,57.1425161554099,20.6378065044143,11.519473,0,0,0,40,4449,10.00625,-38306.84765625,,,,,,,,,,,,,0,,,,0,,,,,,10.00335785,,,,
,31547026.715,10.0016565,-33197.134765625,2.81664093108498E-5,5.7665241129717E-7,1,0.999253354069792,40.0298881530762,1.99581539951259,19.9200008064508,0.000314157208317932,7.32663260870307E-5,0.25,1.4461411920949E-6,2.80763895535368E-5,1.63664578425256E-6,10.0016565,10.0016565,-33224.57421875,-33169.6953125,57.2753930036791,20.6367505867868,11.899124,0,0,0,40,4449,10.00335,-33197.134765625,,,,,,,,,,,,,0,,,,0.0049,,,,,,10.0016565,,,,
,31547127.105,10.0018072,-28180.4716796875,1.17440801356932E-5,4.96657406641553E-7,1,0.999253354069792,40.0298881530762,1.99571532903532,19.9200008064508,0.000131348122518221,2.81165457204608E-5,0.25,3.91092726662371E-7,1.17019069199681E-5,4.68153458592372E-7,10.0017414,10.001873,-28213.125,-28147.818359375,57.3652802833907,20.6397452529393,11.139823,0,0,0,40,4449,10.0037,-28180.4716796875,,,,,,,,,,,,,0,,,,-0.0049,,,,,,10.0018072,,,,
,31547228.21,10.001399,-23128.2939453125,-5.14543330219647E-6,3.92147366166942E-7,1,0.999253354069792,40.0298881530762,1.99552908465039,19.9200008064508,-5.88404973890133E-5,-4.90288437460277E-6,0.25,4.86021826528765E-7,-5.1285428358759E-6,4.51242576363469E-7,10.001399,10.001399,-23160.966796875,-23095.62109375,57.1604936113522,20.6405506644128,11.899124,0,0,0,40,4449,10.00285,-23128.2939453125,,,,,,,,,,,,,0,,,,0.00245,,,,,,10.001399,,,,
,31547330.225,9.9999962,-18028.412109375,-2.06512007315993E-5,4.43939474098074E-7,1,0.999253354069792,40.0298881530762,1.99561310454828,19.9200008064508,-0.000232471996435805,-3.96165421405158E-5,0.25,1.69223470066956E-7,-2.05616694159601E-5,4.31941663873068E-8,9.9999962,9.9999962,-18033.33984375,-18023.484375,57.2886806885061,20.642002834949,11.139823,0,0,0,40,4449,10.002,-18028.412109375,,,,,,,,,,,,,0,,,,0,,,,,,9.9999962,,,,
,31547429.445,9.99912595,-13068.4985351562,-3.5295858991423E-5,3.56791841601655E-7,1,0.999253354069792,40.0298881530762,1.99546590984412,19.9200008064508,-0.000396156050085778,-7.30626046282967E-5,0.25,-2.02574662183006E-7,-3.51239841980713E-5,-4.03451870182209E-7,9.9991016,9.9991503,-13095.9326171875,-13041.064453125,57.241001348833,20.6441728986121,11.519473,0,0,0,40,4449,10.003,-13068.4985351562,,,,,,,,,,,,,0,,,,0,,,,,,9.99912595,,,,
,31547526.395,9.9992027,-8222.92138671875,-4.9724131192537E-5,3.72366968543707E-7,1,0.999253354069792,40.0298881530762,1.99563702459566,19.9200008064508,-0.000557928689954167,-0.000102845766396609,0.25,-2.98570908119536E-7,-4.94622433157473E-5,-5.63656794049406E-7,9.9992027,9.9992027,-8247.8203125,-8198.0224609375,56.9807190519291,20.6417093805895,11.139823,0,0,0,40,4449,10.00385,-8222.92138671875,,,,,,,,,,,,,0,,,,0,,,,,,9.9992027,,,,
,31547620.885,9.9998722,-3499.52612304687,-6.2798120701619E-5,2.9212934910953E-7,1,0.999253354069792,40.0298881530762,1.99564904285843,19.9200008064508,-0.000704475221484913,-0.000129393152288987,0.25,-3.5820517568635E-7,-6.24468105549971E-5,-6.71642579852738E-7,9.9998722,9.9998722,-3529.38403320313,-3469.66821289063,57.4489145349484,20.6400524727011,11.519473,0,0,0,40,4449,10.0041,-3499.52612304687,,,,,,,,,,,,,0,,,,0,,,,,,9.9998722,,,,
,31547711.41,9.9996786,1024.9450378418,-7.07280453405988E-5,3.20126050832848E-7,1,0.999253354069792,40.0298881530762,1.99550636838955,19.9200008064508,-0.000793159775103422,-0.000146319455839137,0.25,-4.69434761640155E-7,-7.03223261853709E-5,-8.11008901996065E-7,9.9992952,10.000062,997.549865722656,1052.34020996094,57.0760777312753,20.638731668326,11.519473,0,0,0,40,4449,10.0006,1024.9450378418,,,,,,,,,,,,,0,,,,-0.00245,,,,,,9.9996786,,,,
,31547799.535,9.9987998,5425.66015625,-8.11777033666126E-5,2.84354362202488E-7,1,0.999253354069792,40.0298881530762,1.99541814463155,19.9200008064508,-0.00090982931165307,-0.000172016520554432,0.25,-8.75073423444982E-7,-8.07316679666894E-5,-1.28903341290255E-6,9.9987535,9.9988461,5392.89501953125,5458.42529296875,57.2933704596215,20.640600232678,11.519473,0,0,0,40,4449,10.0027,5425.66015625,,,,,,,,,,,,,0,,,,-0.00245,,,,,,9.9987998,,,,
,31547888.745,9.99975015,9886.83056640625,-8.93175660505767E-5,3.6073309856841E-7,1,0.999253354069792,40.0298881530762,1.99537797041677,19.9200008064508,-0.00100135761836714,-0.000189430122658586,0.25,-9.42937367218137E-7,-8.8856549049345E-5,-1.42808929721109E-6,9.9996271,9.9998732,9856.7724609375,9916.888671875,57.180034324333,20.6392662250406,11.519473,0,0,0,40,4449,10.003,9886.83056640625,,,,,,,,,,,,,0,,,,0.00245,,,,,,9.99975015,,,,
,31547978.145,10.0001001,14357.3115234375,-9.26098574459873E-5,4.06971651995319E-7,1,0.999253354069792,40.0298881530762,1.99534778078874,19.9200008064508,-0.00103893883946485,-0.00019485963075714,0.25,-8.0292379808102E-7,-9.21677786634456E-5,-1.33735402266771E-6,10.0000648,10.0001354,14329.8681640625,14384.7548828125,57.1956668947176,20.6415094597471,11.899124,0,0,0,40,4449,10.0019,14357.3115234375,,,,,,,,,,,,,0,,,,-0.0049,,,,,,10.0001001,,,,
,31548068.03,10.0005445,18847.2431640625,-8.5706559405028E-5,4.40454262831208E-7,1,0.999253354069792,40.0298881530762,1.99525769487128,19.9200008064508,-0.000960297361792462,-0.000189104084010226,0.25,-1.49086190832999E-6,-8.53282865578133E-5,-2.00909706917743E-6,10.0005445,10.0005445,18812.26953125,18882.216796875,57.1026531009291,20.6420029213821,11.139823,0,0,0,40,4449,10.00125,18847.2431640625,,,,,,,,,,,,,0,,,,-0.00245,,,,,,10.0005445,,,,
,31548165.505,10.0006771,23719.7861328125,-6.98007123332795E-5,4.10136946895399E-7,1,0.999253354069792,40.0298881530762,1.99542955662086,19.9200008064508,-0.000783217309391917,-0.000150202851675886,0.25,-8.46781201177944E-7,-6.95281559419488E-5,-1.29217298557523E-6,10.0006771,10.0006771,23689.767578125,23749.8046875,56.9275683126214,20.6411205584005,11.519473,0,0,0,40,4449,10.0012,23719.7861328125,,,,,,,,,,,,,0,,,,0,,,,,,10.0006771,,,,
,31548269.35,10.0002742,28907.3388671875,-5.41898141305339E-5,5.21613064237668E-7,1,0.999253354069792,40.0298881530762,1.9952243911454,19.9200008064508,-0.000606898470061451,-0.000124559069782395,0.25,-1.34425842913069E-6,-5.40023484475686E-5,-1.70348699312123E-6,10.0002022,10.0003462,28877.41796875,28937.259765625,56.9252234270637,20.6418821537231,11.519473,0,0,0,40,4449,10.00055,28907.3388671875,,,,,,,,,,,,,0,,,,0.00245,,,,,,10.0002742,,,,
,31548369.86,9.9992294,33932.51171875,-5.09176462297054E-5,6.69016038909413E-7,1,0.999253354069792,40.0298881530762,1.99509741535008,19.9200008064508,-0.000571190054920093,-0.000113353076092905,0.25,-9.1930109787712E-7,-5.07705646745867E-5,-1.27013636150904E-6,9.9992294,9.9992294,33925.0546875,33939.96875,56.9596150819099,20.6418455443546,11.139823,0,0,0,40,4449,10.0021,33932.51171875,,,,,,,,,,,,,0,,,,0,,,,,,9.9992294,,,,
,31548470.465,9.9989386,38959.76953125,-5.71245845127319E-5,6.71279660427412E-7,1,0.999253354069792,40.0298881530762,1.99520433683077,19.9200008064508,-0.000638716078421117,-0.000141012906427474,0.25,-2.24366957281796E-6,-5.69812280309459E-5,-2.64562766243213E-6,9.9989386,9.9989386,38957.359375,38962.1796875,57.2667950899676,20.6398969064062,11.519473,0,0,0,40,4449,10.0025,38959.76953125,,,,,,,,,,,,,0,,,,-0.0049,,,,,,9.9989386,,,,
,31548570.02,9.9981661,43936.970703125,-6.8795474752387E-5,8.10334808049561E-7,1,0.999253354069792,40.0298881530762,1.99519163633055,19.9200008064508,-0.000774219287291108,-0.000144292201332846,0.25,-4.1891633085116E-7,-6.86751338847059E-5,-9.1781776731564E-7,9.9981661,9.9981661,43934.453125,43939.48828125,57.0932735586983,20.6398221141527,11.519473,0,0,0,40,4449,10.0044,43936.970703125,,,,,,,,,,,,,0,,,,0,,,,,,9.9981661,,,,
,31548668.36,9.99796775,48852.904296875,-8.28113747225302E-5,8.73529020756879E-7,1,0.999253354069792,40.0298881530762,1.9952447616817,19.9200008064508,-0.000932141073915181,-0.000175508209641924,0.25,-6.49734128424378E-7,-8.27075357936126E-5,-1.25830623126474E-6,9.9978514,9.9980841,48818.015625,48887.79296875,57.1073428720445,20.639715712005,11.519473,0,0,0,40,4449,10.0074,48852.904296875,,,,,,,,,,,,,0,,,,0.00245,,,,,,9.99796775,,,,
,31548768.905,9.9961348,53877.7890625,-9.8588282907715E-5,8.39479219194726E-7,1,0.999253354069792,40.0298881530762,1.99516914350293,19.9200008064508,-0.00111330299088864,-0.000192107549290396,0.25,7.33772234929549E-7,-9.8525641659275E-5,1.94754088996764E-9,9.9961348,9.9961348,53875.47265625,53880.10546875,56.7548284098714,20.6393795116048,11.519473,0,0,0,40,4449,10.0106,53877.7890625,,,,,,,,,,,,,0,,,,0,,,,,,9.9961348,,,,
,31548867.395,9.99574755,58800.572265625,-0.000115987629571407,9.78618594880927E-7,1,0.999253354069792,40.0298881530762,1.9952381399188,19.9200008064508,-0.00130272388345827,-0.000269009888700063,0.25,-2.93494645288123E-6,-0.000115941060048047,-3.79753502950106E-6,9.9956045,9.9958906,58777.94921875,58823.1953125,56.8712910592368,20.6380260017966,11.899124,0,0,0,40,4449,10.01455,58800.572265625,,,,,,,,,,,,,0,,,,0,,,,,,9.99574755,,,,
,31548968.045,9.9958992,63830.94921875,-0.000133665313437368,8.29934189797309E-7,1,0.999253354069792,40.0298881530762,1.99513594682095,19.9200008064508,-0.00151107607628216,-0.00025922905837373,0.25,1.12671262044495E-6,-0.000133707589945185,1.32996497609355E-7,9.9958992,9.9958992,63825.87890625,63836.01953125,57.2996234877753,20.6395776327956,11.139823,0,0,0,40,4449,10.01865,63830.94921875,,,,,,,,,,,,,0,,,,0,,,,,,9.9958992,,,,
,31549066.93,9.995738,68773.59375,-0.000149133893357239,1.21589323355056E-6,1,0.999253354069792,40.0298881530762,1.99503805800293,19.9200008064508,-0.00168319213376383,-0.000308265063380885,0.25,-4.2398717222949E-7,-0.000149233616664786,-1.52854649939475E-6,9.995738,9.995738,68773.59375,68773.59375,57.027616763083,20.6380774993579,11.899124,0,0,0,40,4449,10.0234,68773.59375,,,,,,,,,,,,,0,,,,0.00245,,,,,,9.995738,,,,
,31549166.045,9.9956179,73728.83203125,-0.000166993264916856,1.19916103982182E-6,1,0.999253354069792,40.0298881530762,1.99502756610277,19.9200008064508,-0.00188752565706192,-0.000334246762529146,0.25,4.96031208318271E-7,-0.000167181197538144,-7.30853221453806E-7,9.9956179,9.9956179,73726.453125,73731.2109375,56.9189703989099,20.6389190068626,11.899124,0,0,0,40,4449,10.0269,73728.83203125,,,,,,,,,,,,,0,,,,0.00245,,,,,,9.9956179,,,,
,31549260.485,9.9957418,78447.00390625,-0.000183794460502232,9.67123711639836E-7,1,0.999253354069792,40.0298881530762,1.99513082705811,19.9200008064508,-0.00207888484824381,-0.000364795750941366,0.25,8.18894053436037E-7,-0.000184071597227713,-5.18099825351593E-7,9.9957418,9.9957418,78419.609375,78474.3984375,57.220679007333,20.6398671399233,11.899124,0,0,0,40,4449,10.0298,78447.00390625,,,,,,,,,,,,,0,,,,-0.00245,,,,,,9.9957418,,,,
,31549349.52,9.9959316,82898.26953125,-0.000199783440404202,1.33932219554433E-6,1,0.999253354069792,40.0298881530762,1.99504515115693,19.9200008064508,-0.00225782978279363,-0.00041085389926104,0.25,-3.82786658763992E-7,-0.000200141590569277,-1.82244864426825E-6,9.9959316,9.9959316,82873.34375,82923.1953125,57.0666981890445,20.6395702148149,11.519473,0,0,0,40,4449,10.0332,82898.26953125,,,,,,,,,,,,,0,,,,-0.00245,,,,,,9.9959316,,,,
,31549434.365,9.99531695,87141.4140625,-0.000211967530019158,1.48566533602764E-6,1,0.999253354069792,40.0298881530762,1.99507688940517,19.9200008064508,-0.00239465505733216,-0.000445050349728077,0.25,-1.22059947005073E-6,-0.000212404931816084,-2.73200729369949E-6,9.9953098,9.9953241,87116.328125,87166.5,57.2378748347561,20.6369880203457,11.899124,0,0,0,40,4449,10.03685,87141.4140625,,,,,,,,,,,,,0,,,,0,,,,,,9.99531695,,,,
,31549531.675,9.99732255,88752.80859375,-0.000219903155058848,1.35070882526758E-6,1,0.999253354069792,40.0298881530762,1.99506191007614,19.9200008064508,-0.00248124722830119,-0.000480164385897289,0.25,-2.90129934454805E-6,-0.000220369313086446,-4.46553202088909E-6,9.99722,9.9974251,88723.3125,88782.3046875,57.1104693861214,20.6368171300547,11.139823,0,0,0,40,4449,10.03965,88752.80859375,,,,,,,,,,,,,0,,,,-0.00245,,,,,,9.99732255,,,,
,31549616.805,9.9998541,84498.9375,-0.000203215571431478,1.54902464983979E-6,1,0.999253354069792,40.0298881530762,1.99515306927826,19.9200008064508,-0.0022935063990328,-0.000437384408374324,0.25,-2.11177235682198E-6,-0.000203590784082657,-3.57325687768535E-6,9.9998541,9.9998541,84468.984375,84528.890625,57.1644017539484,20.6379693956452,11.519473,0,0,0,40,4449,10.038,84498.9375,,,,,,,,,,,,,0,,,,0.00245,,,,,,9.9998541,,,,
,31549707.585,10.0022068,79959.98828125,-0.000187569659692467,1.19117967209582E-6,1,0.999253354069792,40.0298881530762,1.99512312205282,19.9200008064508,-0.00211577653337714,-0.000405897640578726,0.25,-2.13894877241562E-6,-0.000187852391513775,-3.50328961424225E-6,10.0022068,10.0022068,79930.0234375,79989.953125,57.2089545795445,20.6378616392867,11.139823,0,0,0,40,4449,10.0358,79959.98828125,,,,,,,,,,,,,0,,,,0.00245,,,,,,10.0022068,,,,
,31549799.245,10.0031414,75376.5546875,-0.000172778110628219,1.39212333264475E-6,1,0.999253354069792,40.0298881530762,1.99535749995365,19.9200008064508,-0.00194882524826807,-0.000371755343053391,0.25,-1.77657017546473E-6,-0.000172978623993436,-3.04484837635521E-6,10.0031242,10.0031586,75346.671875,75406.4375,57.119067299833,20.6368412219192,11.139823,0,0,0,40,4449,10.0333,75376.5546875,,,,,,,,,,,,,0,,,,-0.0049,,,,,,10.0031414,,,,
,31549890.055,10.0031643,70838,-0.000157201708794249,1.18077837354381E-6,1,0.999253354069792,40.0298881530762,1.99534782656822,19.9200008064508,-0.0017701803424248,-0.000350811236108304,0.25,-2.7311709796179E-6,-0.000157317521931026,-3.89437281131069E-6,10.0031643,10.0031643,70833.15625,70842.84375,56.9275683126214,20.6361813607038,11.519473,0,0,0,40,4449,10.0299,70838,,,,,,,,,,,,,0,,,,-0.00245,,,,,,10.0031643,,,,
,31549977.515,10.0040293,66464.87109375,-0.000140115985131156,1.31306991045187E-6,1,0.999253354069792,40.0298881530762,1.99526692028162,19.9200008064508,-0.00157597434389462,-0.00031896944707654,0.25,-2.99687942483207E-6,-0.000140162238135752,-4.03834918656326E-6,10.0039816,10.004077,66434.8984375,66494.84375,57.0635716749676,20.6393461800304,11.519473,0,0,0,40,4449,10.027,66464.87109375,,,,,,,,,,,,,0,,,,0,,,,,,10.0040293,,,,
,31550069.07,10.0047007,61889.11328125,-0.000124501535855729,9.51529304936425E-7,1,0.999253354069792,40.0298881530762,1.99521816008067,19.9200008064508,-0.00139863805963078,-0.000289400859453786,0.25,-3.20063108292148E-6,-0.000124487185287306,-4.1274341762304E-6,10.0047007,10.0047007,61886.61328125,61891.61328125,57.169873153583,20.6384451169566,11.519473,0,0,0,40,4449,10.0233,61889.11328125,,,,,,,,,,,,,0,,,,0.00245,,,,,,10.0047007,,,,
,31550159.265,10.0043626,57381.076171875,-0.000109111073941434,1.03535871751256E-6,1,0.999253354069792,40.0298881530762,1.99520697709744,19.9200008064508,-0.00122658819553729,-0.000245902924076065,0.25,-2.13011047909879E-6,-0.000109057163829128,-2.9409887713891E-6,10.0043507,10.0043745,57353.66796875,57408.484375,57.017455592333,20.6406420364805,11.139823,0,0,0,40,4449,10.02055,57381.076171875,,,,,,,,,,,,,0,,,,-0.00245,,,,,,10.0043626,,,,
,31550248.495,10.00373455,52920.486328125,-9.34289128850258E-5,9.61048332708961E-7,1,0.999253354069792,40.0298881530762,1.9951690395962,19.9200008064508,-0.00104830147434833,-0.000218875186750021,0.25,-2.57226168269779E-6,-9.33364561283892E-5,-3.26248996294102E-6,10.0036201,10.003849,52890.30078125,52950.671875,57.047939104583,20.6406244126705,11.899124,0,0,0,40,4449,10.01745,52920.486328125,,,,,,,,,,,,,0,,,,0,,,,,,10.00373455,,,,
,31550338.69,10.0039387,48413.099609375,-7.947471135426E-5,6.70480398494119E-7,1,0.999253354069792,40.0298881530762,1.99540991487212,19.9200008064508,-0.000891763480391521,-0.000184259983688125,0.25,-2.02729434754324E-6,-7.93611632566994E-5,-2.60901757185731E-6,10.0039387,10.0039387,48387.9921875,48438.20703125,57.2519441481022,20.6417207330613,11.139823,0,0,0,40,4449,10.01405,48413.099609375,,,,,,,,,,,,,0,,,,0,,,,,,10.0039387,,,,
,31550428.15,10.0044765,43939.9140625,-6.43876953282047E-5,7.9000712459122E-7,1,0.999253354069792,40.0298881530762,1.99539073408589,19.9200008064508,-0.000720180276514108,-0.000160068387742078,0.25,-2.61159791510289E-6,-6.42589649011089E-5,-3.0747552236716E-6,10.0044765,10.0044765,43909.9375,43969.890625,56.9986965078714,20.6423269090714,11.139823,0,0,0,40,4449,10.01085,43939.9140625,,,,,,,,,,,,,0,,,,-0.00245,,,,,,10.0044765,,,,
,31550519.31,10.00297305,39384.59375,-4.79082894229084E-5,7.25076004705557E-7,1,0.999253354069792,40.0298881530762,1.99545133637472,19.9200008064508,-0.000536641203499415,-0.000113356590923097,0.25,-1.44375782349035E-6,-4.77933183780425E-5,-1.78255247108861E-6,10.0029268,10.0030193,39352.15234375,39417.03515625,57.1253203279868,20.6412562406233,11.519473,0,0,0,40,4449,10.0085,39384.59375,,,,,,,,,,,,,0,,,,0.00245,,,,,,10.00297305,,,,
,31550611.97,10.0028305,34754.734375,-3.3670814407928E-5,6.68131353210419E-7,1,0.999253354069792,40.0298881530762,1.99519751555194,19.9200008064508,-0.000377059508949938,-7.89060538468811E-5,0.25,-9.56660331088359E-7,-3.35740369650186E-5,-1.18889806498815E-6,10.0028305,10.0028305,34754.734375,34754.734375,57.2550706621791,20.6444556059274,11.519473,0,0,0,40,4449,10.0061,34754.734375,,,,,,,,,,,,,0,,,,0,,,,,,10.0028305,,,,
,31550700.83,10.0026703,30314.8359375,-1.92297669615738E-5,6.29761238102247E-7,1,0.999253354069792,40.0298881530762,1.99530653414518,19.9200008064508,-0.000213378467141131,-5.54863746932868E-5,0.25,-1.47799107640761E-6,-1.91592603439364E-5,-1.6037119153127E-6,10.0026703,10.0026703,30312.48828125,30317.18359375,57.1683098965445,20.6448710543945,11.519473,0,0,0,40,4449,10.0043,30314.8359375,,,,,,,,,,,,,0,,,,0,,,,,,10.0026703,,,,
,31550789.86,10.001503,25864.2607421875,-3.85350104840911E-6,4.9946175909783E-7,1,0.999253354069792,40.0298881530762,1.99530889954264,19.9200008064508,-4.2582844210768E-5,-1.19920962586965E-5,0.25,-3.75127059769412E-7,-3.83713918863732E-6,-3.99014155671142E-7,10.0013857,10.0016203,25839.24609375,25889.275390625,57.2269320354868,20.6447503544049,11.519473,0,0,0,40,4449,10.00415,25864.2607421875,,,,,,,,,,,,,0,,,,0,,,,,,10.001503,,,,
,31550879.215,10.0008841,21396.5615234375,1.05371383354389E-5,4.39780918673561E-7,1,0.999253354069792,40.0298881530762,1.99540288636676,19.9200008064508,0.000119242590454907,1.68795575298399E-5,0.25,-3.85650348882837E-7,1.04967927921243E-5,-3.17848835959019E-7,10.0008841,10.0008841,21366.45703125,21426.666015625,57.3379232852176,20.6439036557072,11.519473,0,0,0,40,4449,10.00405,21396.5615234375,,,,,,,,,,,,,0,,,,0.00245,,,,,,10.0008841,,,,
,31550968.725,10.0006065,16921.6611328125,2.36459224604673E-5,4.60768812105147E-7,1,0.999253354069792,40.0298881530762,1.99536784788613,19.9200008064508,0.000267764926096222,3.61756153627845E-5,0.25,-1.00846811851497E-6,2.35458148584659E-5,-8.62265985756609E-7,10.0006065,10.0006065,16919.259765625,16924.0625,57.3363600281791,20.6469127652543,11.519473,0,0,0,40,4449,10.0044,16921.6611328125,,,,,,,,,,,,,0,,,,0,,,,,,10.0006065,,,,
,31551056.25,9.9997578,12549.2055664062,3.70371713349632E-5,4.65802829097267E-7,1,0.999253354069792,40.0298881530762,1.99533609584103,19.9200008064508,0.000416084291475615,7.42575246619897E-5,0.25,2.07119099993171E-10,3.68563681416549E-5,2.10624697436129E-7,9.9997578,9.9997578,12521.6005859375,12576.810546875,57.2300585495638,20.6472307179241,11.519473,0,0,0,40,4449,10.0038,12549.2055664062,,,,,,,,,,,,,0,,,,0,,,,,,9.9997578,,,,
,31551143.385,9.99867205,8193.74047851562,5.01461490747975E-5,3.56465937512826E-7,1,0.999253354069792,40.0298881530762,1.99532370725784,19.9200008064508,0.000563744258705644,9.71576211927984E-5,0.25,-2.81581166228474E-7,4.9885050373666E-5,-1.13027928047518E-8,9.9986277,9.9987164,8169.11083984375,8218.3701171875,57.3043132588907,20.6461118851555,11.519473,0,0,0,40,4449,10.0046,8193.74047851562,,,,,,,,,,,,,0,,,,0.00245,,,,,,9.99867205,,,,
,31551233.78,9.9996243,3675.63696289063,6.23879859847203E-5,3.30847795995498E-7,1,0.999253354069792,40.0298881530762,1.9956221027194,19.9200008064508,0.000701036466000265,0.000122004113948103,0.25,-2.27615574743675E-7,6.20425910206187E-5,8.77696455946184E-8,9.9996243,9.9996243,3670.61547851562,3680.65844726562,57.4395349927176,20.6395428623303,11.139823,0,0,0,40,4449,10.0047,3675.63696289063,,,,,,,,,,,,,0,,,,0,,,,,,9.9996243,,,,
,31551307.28,10.0032415,-0.852531313896179,7.15535466877575E-5,3.73842626827965E-7,1,0.999253354069792,40.0298881530762,1.99566981948865,19.9200008064508,0.000803420778112903,0.000142550070010288,0.25,-1.00023150984485E-8,7.1142549950127E-5,3.34938963076182E-7,10.0032415,10.0032415,-1.20267808437347,-0.502384543418884,57.2699216040445,20.6403544322829,11.899124,0,0,0,40,4417,10.0005,-0.852531313896179,,,,,,,,,,,,,0,,,,0,,,,,,10.0032415,,,,