File: data/doubleLayers/dl_0-25/ppms/data/DD205_10_HYST_100OE_100K.DAT
[Header]
; VSM Data File (default extension .dat)
; Copyright (c) 2003-2013, Quantum Design, Inc. All rights reserved.
TITLE,
FILEOPENTIME,31576200.89,01/01/2019,7:12 pm
BYAPP,VSM,2.0,2.0
INFO,PPMS VSM Option Release 1.4.10 Build 1,APPNAME
INFO,Quantum Design Linear Motor Servo Controller,MOTOR_MODULE_NAME
INFO,3101-100 M1,MOTOR_HW_VERSION
INFO,MMC1014,MOTOR_SERIAL_NUMBER
INFO,SRV No X-over 01.03.11,MOTOR_SOFTWARE_VERSION
INFO,Quantum Design VSM Detection Module,VSM_MODULE_NAME
INFO,3101-150 F0,VSM_HW_VERSION
INFO,VSM707,VSM_SERIAL_NUMBER
INFO,VSM No X-over 01.02.05 May 20 2008 13:51:47,VSM_SOFTWARE_VERSION
INFO,704,PREAMP_SERIAL_NUMBER
INFO,822,COIL_SERIAL_NUMBER
INFO,0,MOMENT_UNITS
INFO,CoFe2O4,SAMPLE_MATERIAL
INFO,Double Layer thin concentration,SAMPLE_COMMENT
INFO,27.44,SAMPLE_MASS
INFO,,SAMPLE_VOLUME
INFO,,SAMPLE_MOLECULAR_WEIGHT
INFO,,SAMPLE_SIZE
INFO,,SAMPLE_SHAPE
DATATYPE,COMMENT,1
DATATYPE,TIME,2
STARTUPAXIS,X,2
STARTUPAXIS,Y1,5
[Data]
Comment,Time Stamp (sec),Temperature (K),Magnetic Field (Oe),Moment (emu),M. Std. Err. (emu),Transport Action,Averaging Time (sec),Frequency (Hz),Peak Amplitude (mm),Center Position (mm),Coil Signal' (mV),Coil Signal" (mV),Range (mV),M. Quad. Signal (emu),M. Raw' (emu),M. Raw" (emu),Min. Temperature (K),Max. Temperature (K),Min. Field (Oe),Max. Field (Oe),Mass (grams),Motor Lag (deg),Pressure (Torr),VSM Status (code),Motor Status (code),Measure Status (code),Measure Count,PPMS Status (code),System Temp. (K),System Field (Oe),Sample Position (deg),Bridge 1 Resistance (ohms),Bridge 1 Excitation (에),Bridge 2 Resistance (ohms),Bridge 2 Excitation (에),Bridge 3 Resistance (ohms),Bridge 3 Excitation (에),Bridge 4 Resistance (ohms),Bridge 4 Excitation (에),Signal 1 Vin (V),Signal 2 Vin (V),Digital Inputs (code),Drive 1 Iout (mA),Drive 1 Ipower (W),Drive 2 Iout (mA),Drive 2 Ipower (W),Pressure (),Map 20 (),Map 21 (),Map 22 (),Map 23 (),Map 24 (),Map 25 (),Map 26 (),Map 27 (),Map 28 (),Map 29 ()
,31576215.52,99.9924393,-0.213132828474045,,,2,,,,20.0899995797873,,,,,,,99.9924393,99.9924393,-0.213132828474045,-0.213132828474045,,,20.251448,,,,-99999999,4369,99.9249,-0.213132828474045,,,,,,,,,,,,,,,,,,,,,,,99.9924393,,,,
,31576382.815,99.9948883,5442.0380859375,4.54032662279994E-5,3.9448748419365E-7,1,0.999253354069792,40.0298881530762,2.00889294831279,20.0399998575449,0.000520613251873414,8.22449111527844E-5,0.25,-7.85310329844273E-7,4.56613060764429E-5,-6.48951893009276E-7,99.9948883,99.9948883,5434.6767578125,5449.3994140625,56.2944492120444,20.6122936476924,20.251448,0,0,0,40,4449,99.9363,5442.0380859375,,,,,,,,,,,,,0,,,,0.00245,,,,,,99.9948883,,,,
,31576461.27,99.99972915,9362.25146484375,3.57153300566901E-5,6.15334017193587E-7,1,0.999253354069792,40.0298881530762,2.00872212694438,20.0399998575449,0.000409732268966829,6.33472251983833E-5,0.25,-7.34872087294851E-7,3.59188571317988E-5,-6.28700276430485E-7,99.9996033,99.999855,9357.2548828125,9367.248046875,56.6055373626983,20.6136340224228,19.871798,0,0,0,40,4449,99.9358,9362.25146484375,,,,,,,,,,,,,0,,,,0,,,,,,99.99972915,,,,
,31576539.695,100.0021057,13283.0073242187,2.55054293531651E-5,6.62696355316271E-7,1,0.999253354069792,40.0298881530762,2.00859164485922,20.0399998575449,0.00029277301005379,4.41717679557009E-5,0.25,-6.17545554285588E-7,2.56512014549652E-5,-5.42580153069173E-7,100.0021057,100.0021057,13280.453125,13285.5615234375,57.0768593597945,20.621615615263,20.251448,0,0,0,40,4449,99.93415,13283.0073242187,,,,,,,,,,,,,0,,,,0,,,,,,100.0021057,,,,
,31576604.465,100.0040741,16521.146484375,1.68098292809069E-5,8.28022367031615E-7,1,0.999253354069792,40.0298881530762,2.00855726735173,20.0399998575449,0.000193463472335529,2.62196963388424E-5,0.25,-6.59851998141139E-7,1.6906757295832E-5,-6.12060596766315E-7,100.0040741,100.0040741,16498.515625,16543.77734375,56.9557069393137,20.6218193215393,20.251448,0,0,0,40,4449,99.93105,16521.146484375,,,,,,,,,,,,,0,,,,0,,,,,,100.0040741,,,,
,31576667.315,100.0056,19661.8984375,6.49334509120025E-6,9.66733955608454E-7,1,0.999253354069792,40.0298881530762,2.00872311293662,20.0399998575449,7.64152320672258E-5,5.82186494240073E-7,0.25,-1.08998527904119E-6,6.53336607544117E-6,-1.07631601609027E-6,100.0056,100.0056,19636.81640625,19686.98046875,57.1956668947176,20.6253725485588,20.251448,0,0,0,40,4449,99.9262,19661.8984375,,,,,,,,,,,,,0,,,,-0.00245,,,,,,100.0056,,,,
,31576732.52,100.0057449,22920.8193359375,-3.31509489912245E-6,9.75135801889365E-7,1,0.999253354069792,40.0298881530762,2.00868869295286,20.0399998575449,-3.71257181912635E-5,-1.1035244303244E-5,0.25,-3.82940298900973E-7,-3.33268045303186E-6,-3.95190441467963E-7,100.0057449,100.0057449,22915.6328125,22926.005859375,57.1831608384099,20.6245594736904,19.871798,0,0,0,40,4449,99.9218,22920.8193359375,,,,,,,,,,,,,0,,,,-0.00245,,,,,,100.0057449,,,,
,31576790.895,100.0069733,25838.859375,-1.09809629097927E-5,1.34393141730896E-6,1,0.999253354069792,40.0298881530762,2.00863864541948,20.0399998575449,-0.0001229406895125,-3.67395217298217E-5,0.25,-1.28492567563294E-6,-1.10392302511127E-5,-1.32548364642806E-6,100.0069733,100.0069733,25808.83203125,25868.88671875,56.7900016932368,20.6243864641427,20.631098,0,0,0,40,4449,99.91925,25838.859375,,,,,,,,,,,,,0,,,,-0.0049,,,,,,100.0069733,,,,
,31576851.985,100.0079269,28893.3408203125,-2.16628654096231E-5,1.40662752749894E-6,1,0.999253354069792,40.0298881530762,2.00867319856725,20.0399998575449,-0.000246207460024933,-5.1595688596528E-5,0.25,-7.0811884966132E-7,-2.17834690540151E-5,-7.77543356565704E-7,100.0079269,100.0079269,28888.212890625,28898.46875,57.0588819038522,20.6265224464927,19.871798,0,0,0,40,4449,99.9165,28893.3408203125,,,,,,,,,,,,,0,,,,0.0049,,,,,,100.0079269,,,,
,31576913.295,100.007103,31956.296875,-3.1932011864372E-5,1.86813547003833E-6,1,0.999253354069792,40.0298881530762,2.00868118017086,20.0399998575449,-0.000359822151396955,-9.37129261404663E-5,0.25,-2.58887939513399E-6,-3.21053143762709E-5,-2.69961499637601E-6,100.007103,100.007103,31926.546875,31986.046875,56.9713395096983,20.6258917670428,19.871798,0,0,0,40,4449,99.9093,31956.296875,,,,,,,,,,,,,0,,,,-0.00245,,,,,,100.007103,,,,
,31576973.3,100.0086212,34956.900390625,-4.23161896179148E-5,1.96843876687408E-6,1,0.999253354069792,40.0298881530762,2.00864060920619,20.0399998575449,-0.000479798316414002,-0.000107279537517744,0.25,-1.95223281836267E-6,-4.25505332886991E-5,-2.09011678242845E-6,100.0086212,100.0086212,34924.453125,34989.34765625,57.0299616486406,20.6256261282359,20.251448,0,0,0,40,4449,99.90465,34956.900390625,,,,,,,,,,,,,0,,,,-0.00245,,,,,,100.0086212,,,,
,31577036.37,100.0100708,38104.935546875,-5.26489695625273E-5,1.47876454684104E-6,1,0.999253354069792,40.0298881530762,2.00900334438445,20.0399998575449,-0.000596703248911327,-0.000135540703906364,0.25,-2.60815778576478E-6,-5.29403083598338E-5,-2.78010380215912E-6,100.0100708,100.0100708,38102.12890625,38107.7421875,56.7470121246791,20.6157679404236,20.251448,0,0,0,40,4449,99.8978,38104.935546875,,,,,,,,,,,,,0,,,,0,,,,,,100.0100708,,,,
,31577095.495,100.0105438,41064.41796875,-6.33761556306088E-5,1.29294415437829E-6,1,0.999253354069792,40.0298881530762,2.00908278444267,20.0399998575449,-0.000720161608952804,-0.000152633039903308,0.25,-2.21923669313611E-6,-6.37299451736828E-5,-2.42026906967202E-6,100.0105438,100.0105438,41037.12890625,41091.70703125,57.0674798175637,20.6191636432396,20.251448,0,0,0,40,4449,99.8919,41064.41796875,,,,,,,,,,,,,0,,,,-0.00245,,,,,,100.0105438,,,,
,31577157.855,100.0102615,44179.638671875,-7.56453018477347E-5,2.25531643668692E-6,1,0.999253354069792,40.0298881530762,1.99636238022378,20.0399998575449,-0.000849700759526496,-0.000207792541685914,0.25,-5.00011308046813E-6,-7.60610600866632E-5,-5.25252854928961E-6,100.0102615,100.0102615,44154.74609375,44204.53125,56.9408559974483,20.6260404571638,19.871798,0,0,0,40,4449,99.88795,44179.638671875,,,,,,,,,,,,,0,,,,0,,,,,,100.0102615,,,,
,31577219.225,100.008831,47248.31640625,-8.48501512226865E-5,1.5274434003576E-6,1,0.999253354069792,40.0298881530762,1.9963552458928,20.0399998575449,-0.000960430018201824,-0.000191326504952571,0.25,-1.935754214764E-6,-8.53278457388356E-5,-2.19696141265696E-6,100.0087738,100.0088882,47218.44921875,47278.18359375,56.7016776705637,20.6244377594904,20.631098,0,0,0,40,4449,99.88205,47248.31640625,,,,,,,,,,,,,0,,,,0,,,,,,100.008831,,,,
,31577279.755,100.00839995,50274.58984375,-9.4217683449813E-5,1.4544708841191E-6,1,0.999253354069792,40.0298881530762,1.99625372892293,20.0399998575449,-0.00106407455388277,-0.000225777520921917,0.25,-3.32425469553979E-6,-9.47451884891241E-5,-3.61986081235021E-6,100.00811,100.0086899,50246.90234375,50302.27734375,56.9791557948906,20.6246222440653,20.251448,0,0,0,40,4449,99.87985,50274.58984375,,,,,,,,,,,,,0,,,,-0.00245,,,,,,100.00839995,,,,
,31577341.46,100.007164,53355.54296875,-0.000106240447215995,1.89667081189862E-6,1,0.999253354069792,40.0298881530762,1.99617522702492,20.0399998575449,-0.00120103557421535,-0.000247650098543566,0.25,-3.13993195641611E-6,-0.00010683765430318,-3.46849761007297E-6,100.007164,100.007164,53355.54296875,53355.54296875,57.1096877576022,20.6258139444964,20.251448,0,0,0,40,4449,99.8744,53355.54296875,,,,,,,,,,,,,0,,,,-0.0049,,,,,,100.007164,,,,
,31577401.71,100.0068893,56366.560546875,-0.000116130296797993,2.26943460356142E-6,1,0.999253354069792,40.0298881530762,1.99617361369474,20.0399998575449,-0.00130814633975619,-0.000297470684569773,0.25,-5.78895710841332E-6,-0.000116776879225849,-6.16017971798968E-6,100.0068893,100.0068893,56334.1640625,56398.95703125,57.3394865422561,20.6237675835576,19.871798,0,0,0,40,4449,99.87045,56366.560546875,,,,,,,,,,,,,0,,,,-0.00245,,,,,,100.0068893,,,,
,31577462.42,100.00787735,59402.744140625,-0.000126551260843205,2.02500377609419E-6,1,0.999253354069792,40.0298881530762,1.99611350256891,20.0399998575449,-0.00142890010239667,-0.000304789189365025,0.25,-4.60563544293507E-6,-0.000127261534993132,-4.99891463210405E-6,100.0077362,100.0080185,59372.75390625,59432.734375,57.1839424669291,20.6253419275206,19.871798,0,0,0,40,4449,99.8659,59402.744140625,,,,,,,,,,,,,0,,,,0.0049,,,,,,100.00787735,,,,
,31577521.605,100.0083046,62361.302734375,-0.000138565201167649,2.61175427243704E-6,1,0.999253354069792,40.0298881530762,1.99598265784741,20.0399998575449,-0.00157118779888335,-0.00029538304627087,0.25,-1.67202382364568E-6,-0.00013935339499893,-2.08171916910448E-6,100.0079422,100.008667,62331.328125,62391.27734375,57.1026531009291,20.6236879526226,20.251448,0,0,0,40,4449,99.86055,62361.302734375,,,,,,,,,,,,,0,,,,0,,,,,,100.0083046,,,,
,31577582.525,100.00772855,65402.568359375,-0.000152103247018293,2.19059653187517E-6,1,0.999253354069792,40.0298881530762,1.99615323253785,20.0399998575449,-0.00172230548586982,-0.000338739835858908,0.25,-3.11048940842688E-6,-0.000152965592302232,-3.56565738286486E-6,100.0076141,100.007843,65370.26953125,65434.8671875,57.0338697912368,20.6214358962191,20.251448,0,0,0,40,4449,99.8551,65402.568359375,,,,,,,,,,,,,0,,,,-0.0049,,,,,,100.00772855,,,,
,31577643.57,100.0070801,68456.23828125,-0.00016194671283249,2.28299507269998E-6,1,0.999253354069792,40.0298881530762,1.99607592461243,20.0399998575449,-0.00183564466137801,-0.000349614832106407,0.25,-2.34269455360232E-6,-0.000162868530326956,-2.81975497722398E-6,100.0070572,100.007103,68428.8125,68483.6640625,56.7438856106022,20.621669513046,20.251448,0,0,0,40,4449,99.8529,68456.23828125,,,,,,,,,,,,,0,,,,0,,,,,,100.0070801,,,,
,31577704.76,100.0064697,71514.75,-0.00017243087689322,2.39436743821614E-6,1,0.999253354069792,40.0298881530762,1.9959722189805,20.0399998575449,-0.00195361940650125,-0.000376649735360492,0.25,-2.88528299538648E-6,-0.000173412183660303,-3.39333691460022E-6,100.0064697,100.0064697,71486.9609375,71542.5390625,57.0385595623522,20.6241352794118,20.631098,0,0,0,40,4449,99.8489,71514.75,,,,,,,,,,,,,0,,,,0,,,,,,100.0064697,,,,
,31577765.215,100.0089645,74538.36328125,-0.000185346028718024,2.42899602505975E-6,1,0.999253354069792,40.0298881530762,1.99603933136488,20.0399998575449,-0.00209538177433976,-0.000431333480653095,0.25,-5.43189721782415E-6,-0.000186395190286144,-5.98913449147235E-6,100.0089645,100.0089645,74535.84375,74540.8828125,57.0878021590637,20.6245034525298,20.631098,0,0,0,40,4449,99.84365,74538.36328125,,,,,,,,,,,,,0,,,,0,,,,,,100.0089645,,,,
,31577832.15,100.00712585,77882.39453125,-0.000194628184836651,1.85801619513569E-6,1,0.999253354069792,40.0298881530762,1.99605742519517,20.0399998575449,-0.00219945080479759,-0.000458071731521689,0.25,-6.15804207090374E-6,-0.000195729787218196,-6.74316791157967E-6,100.0070877,100.007164,77850.0234375,77914.765625,57.0463758475445,20.6232604922567,20.251448,0,0,0,40,4449,99.8405,77882.39453125,,,,,,,,,,,,,0,,,,-0.00245,,,,,,100.00712585,,,,
,31577896.955,100.0071602,81121.3828125,-0.000206240857100552,1.77529572401835E-6,1,0.999253354069792,40.0298881530762,1.99615636958011,20.0399998575449,-0.00233268281597703,-0.000474735920407747,0.25,-5.58726573970178E-6,-0.000207412018741032,-6.19923379383809E-6,100.0069046,100.0074158,81088.96875,81153.796875,56.7391958394868,20.6249683967009,20.251448,0,0,0,40,4449,99.8348,81121.3828125,,,,,,,,,,,,,0,,,,-0.0049,,,,,,100.0071602,,,,
,31577962.71,100.0070572,84409.8984375,-0.000218248077967987,1.97469381463583E-6,1,0.999253354069792,40.0298881530762,1.99640377331357,20.0399998575449,-0.00247048149088157,-0.000492832598901766,0.25,-5.07044370319862E-6,-0.000219491051630504,-5.71029544573836E-6,100.0070572,100.0070572,84382.375,84437.421875,57.1198489283522,20.6192309482316,20.631098,0,0,0,40,4449,99.83125,84409.8984375,,,,,,,,,,,,,0,,,,0,,,,,,100.0070572,,,,
,31578034.37,100.0057144,87990.9453125,-0.000228818687098256,2.05992760461685E-6,1,0.999253354069792,40.0298881530762,1.99622941991841,20.0399998575449,-0.00259031099506904,-0.00051452928620087,0.25,-5.13165224910222E-6,-0.000230123814097864,-5.79811892059913E-6,100.0057144,100.0057144,87990.9453125,87990.9453125,57.0964000727753,20.6202035822604,20.631098,0,0,0,40,4449,99.82815,87990.9453125,,,,,,,,,,,,,0,,,,-0.0049,,,,,,100.0057144,,,,
,31578108.85,100.0037766,89047.2421875,-0.00023548277254139,2.39194709277405E-6,1,0.999253354069792,40.0298881530762,1.99619907898376,20.0399998575449,-0.0026676006194775,-0.000518770378548479,0.25,-4.33732608072127E-6,-0.000236828966204605,-5.01677255759186E-6,100.0037766,100.0037766,89017.25,89077.234375,57.3480844559676,20.6212313571633,20.251448,0,0,0,40,4449,99.82545,89047.2421875,,,,,,,,,,,,,0,,,,0,,,,,,100.0037766,,,,
,31578169.25,100.0022125,86028.7109375,-0.000224692252935876,2.56486457681358E-6,1,0.999253354069792,40.0298881530762,1.99622306189411,20.0399998575449,-0.00254197576233192,-0.000514402337051578,0.25,-5.84282920713736E-6,-0.000225970829442589,-6.50373668257901E-6,100.0022125,100.0022125,86023.6484375,86033.7734375,56.8642564025637,20.6237891328759,19.871798,0,0,0,40,4449,99.8252,86028.7109375,,,,,,,,,,,,,0,,,,-0.00245,,,,,,100.0022125,,,,
,31578241.215,99.99826815,82432,-0.000211469869474339,2.3324228527108E-6,1,0.999253354069792,40.0298881530762,1.99631183499313,20.0399998575449,-0.0023908723249947,-0.000493287615042926,0.25,-6.29996331987273E-6,-0.000212669626963156,-6.92967714985799E-6,99.9981842,99.9983521,82424.8046875,82439.1953125,56.902556200006,20.6213990658968,20.251448,0,0,0,40,4449,99.82695,82432,,,,,,,,,,,,,0,,,,0,,,,,,99.99826815,,,,
,31578314.71,99.99873735,78758.48828125,-0.000198800900828934,2.39700547170725E-6,1,0.999253354069792,40.0298881530762,1.99613390490855,20.0399998575449,-0.00224990345335111,-0.00044960403631201,0.25,-4.67981159723227E-6,-0.000199930966627172,-5.26762502658413E-6,99.9986115,99.9988632,78726.2890625,78790.6875,57.2660134614484,20.6247705337805,20.631098,0,0,0,40,4449,99.8277,78758.48828125,,,,,,,,,,,,,0,,,,0,,,,,,99.99873735,,,,
,31578393.805,99.9969635,74801.453125,-0.000183853465719728,2.08139883045348E-6,1,0.999253354069792,40.0298881530762,1.99629045161501,20.0399998575449,-0.00208331743553186,-0.000401932064774556,0.25,-3.1023163400352E-6,-0.000184900743511475,-3.64186499511194E-6,99.9969254,99.9970016,74796.3984375,74806.5078125,56.7243448976214,20.6208367338159,20.251448,0,0,0,40,4449,99.8284,74801.453125,,,,,,,,,,,,,0,,,,0,,,,,,99.9969635,,,,
,31578478.3,99.9972992,70578.1171875,-0.000166413433793219,2.19232758227508E-6,1,0.999253354069792,40.0298881530762,1.99611081377038,20.0399998575449,-0.00188389429986758,-0.000373043635051306,0.25,-3.62109123538269E-6,-0.0001673578048588,-4.11698190442E-6,99.9972382,99.9973602,70548.125,70608.109375,57.1714364106214,20.6220476259216,20.251448,0,0,0,40,4449,99.832,70578.1171875,,,,,,,,,,,,,0,,,,0.00245,,,,,,99.9972992,,,,
,31578554.49,99.9966049,66769.6875,-0.000154486629191259,2.06780696684298E-6,1,0.999253354069792,40.0298881530762,1.99611472192653,20.0399998575449,-0.00174976256079476,-0.000341206713306968,0.25,-2.91043324246791E-6,-0.000155363553723491,-3.37059373955246E-6,99.9966049,99.9966049,66764.625,66774.75,57.2081729510253,20.6271056206251,19.871798,0,0,0,40,4449,99.834,66769.6875,,,,,,,,,,,,,0,,,,-0.0049,,,,,,99.9966049,,,,
,31578641.26,99.996582,62434.244140625,-0.000138853938008363,2.08069818413461E-6,1,0.999253354069792,40.0298881530762,1.99616550644944,20.0399998575449,-0.00156712424098404,-0.000338608670598566,0.25,-5.4226826730287E-6,-0.000139632937629364,-5.85478529644883E-6,99.996582,99.996582,62421.63671875,62446.8515625,57.068261446083,20.6270541539105,20.631098,0,0,0,40,4449,99.83745,62434.244140625,,,,,,,,,,,,,0,,,,-0.00245,,,,,,99.996582,,,,
,31578745.29,99.9937439,57233.322265625,-0.000117744548353843,2.54696330201176E-6,1,0.999253354069792,40.0298881530762,1.99604631786282,20.0399998575449,-0.00133062942921195,-0.000276647731183301,0.25,-3.67489571208225E-6,-0.000118406659502721,-4.03848584448587E-6,99.9937439,99.9937439,57223.2734375,57243.37109375,56.973684395256,20.6254151482248,19.871798,0,0,0,40,4449,99.8421,57233.322265625,,,,,,,,,,,,,0,,,,0.00245,,,,,,99.9937439,,,,
,31578847.975,99.9939194,52101.083984375,-0.000102289366537215,2.21101022315899E-6,1,0.999253354069792,40.0298881530762,1.99618603519867,20.0399998575449,-0.00115808862926192,-0.000228663879177827,0.25,-2.16217496243086E-6,-0.000102866616727869,-2.47425255644505E-6,99.9939194,99.9939194,52095.9609375,52106.20703125,56.8548768603329,20.6250354524194,20.251448,0,0,0,40,4449,99.84885,52101.083984375,,,,,,,,,,,,,0,,,,-0.0049,,,,,,99.9939194,,,,
,31578951.84,99.9938583,46910.71484375,-8.49637446767557E-5,2.01519969739101E-6,1,0.999253354069792,40.0298881530762,1.99618376630809,20.0399998575449,-0.000956928419818609,-0.000218375499373387,0.25,-4.29726309949268E-6,-8.54350353381006E-5,-4.57249263335485E-6,99.9938583,99.9938583,46903.38671875,46918.04296875,57.3863842534099,20.6253286756246,20.631098,0,0,0,40,4449,99.853,46910.71484375,,,,,,,,,,,,,0,,,,0.00245,,,,,,99.9938583,,,,
,31579057.835,99.9930496,41613.505859375,-6.77787501307512E-5,1.65672781816572E-6,1,0.999253354069792,40.0298881530762,1.99611648364066,20.0399998575449,-0.00076307053553026,-0.000175763285496576,0.25,-3.5643321717301E-6,-6.81536209093826E-5,-3.78606298187857E-6,99.9930496,99.9930496,41606.109375,41620.90234375,57.1909771236022,20.6252292878792,20.251448,0,0,0,40,4449,99.85995,41613.505859375,,,,,,,,,,,,,0,,,,0,,,,,,99.9930496,,,,
,31579164.83,99.99215315,36264.072265625,-4.64777135106357E-5,1.8434422265036E-6,1,0.999253354069792,40.0298881530762,1.99610298060844,20.0399998575449,-0.000524990899355162,-0.000110608409443577,0.25,-1.57060394505415E-6,-4.6736913610194E-5,-1.71863565918083E-6,99.9919815,99.9923248,36254.109375,36274.03515625,57.268358347006,20.6275798150288,20.631098,0,0,0,40,4449,99.8704,36264.072265625,,,,,,,,,,,,,0,,,,0.00245,,,,,,99.99215315,,,,
,31579272.655,99.9917908,30873.9375,-2.90402476852341E-5,1.36876682758185E-6,1,0.999253354069792,40.0298881530762,1.99608372991005,20.0399998575449,-0.000324927297012227,-8.67095307157944E-5,0.25,-2.52969970310043E-6,-2.91972467226081E-5,-2.6315673502316E-6,99.9917908,99.9917908,30871.29296875,30876.58203125,57.5419283287369,20.6286177769258,20.251448,0,0,0,40,4449,99.8758,30873.9375,,,,,,,,,,,,,0,,,,0,,,,,,99.9917908,,,,
,31579379.955,99.9916687,25511.646484375,-1.084170646395E-5,1.39490150194577E-6,1,0.999253354069792,40.0298881530762,1.99637287722267,20.0399998575449,-0.000119148765418817,-4.47448963473604E-5,0.25,-2.03264040324882E-6,-1.08969025584395E-5,-2.07703855991886E-6,99.9916687,99.9916687,25504.265625,25519.02734375,57.2324034351214,20.6263163879635,19.871798,0,0,0,40,4449,99.88715,25511.646484375,,,,,,,,,,,,,0,,,,0.00245,,,,,,99.9916687,,,,
,31579486.955,99.9917908,20164.55859375,7.41201964448975E-6,1.07193234793277E-6,1,0.999253354069792,40.0298881530762,1.99633565535717,20.0399998575449,8.69873877822945E-5,-8.99999169013206E-7,0.25,-1.38152915134538E-6,7.45812449275885E-6,-1.36670330274028E-6,99.9917908,99.9917908,20157.103515625,20172.013671875,57.1034347294484,20.62926654259,20.631098,0,0,0,40,4449,99.8936,20164.55859375,,,,,,,,,,,,,0,,,,0.00245,,,,,,99.9917908,,,,
,31579594.45,99.9907303,14792.7260742187,2.3369416118153E-5,1.11886080528929E-6,1,0.999253354069792,40.0298881530762,1.99622445332008,20.0399998575449,0.000267901677185495,3.32738873800086E-5,0.25,-1.17833398043217E-6,2.35049029887054E-5,-1.11318657621616E-6,99.9907303,99.9907303,14790.2880859375,14795.1640625,56.9815006804483,20.6271685917715,20.631098,0,0,0,40,4449,99.9031,14792.7260742187,,,,,,,,,,,,,0,,,,0,,,,,,99.9907303,,,,
,31579700.16,99.992157,9508.37890625,3.93349326732928E-5,6.42220065828842E-7,1,0.999253354069792,40.0298881530762,1.99636242214049,20.0399998575449,0.000447982307647112,7.29147858310873E-5,0.25,-4.96355146964725E-7,3.95581085215521E-5,-3.77620358559425E-7,99.992157,99.992157,9498.4091796875,9518.3486328125,57.3176009437176,20.6266943663695,21.01075,0,0,0,40,4449,99.9088,9508.37890625,,,,,,,,,,,,,0,,,,-0.00245,,,,,,99.992157,,,,
,31579804.625,99.9922409,4284.9482421875,5.26979543720284E-5,4.67969637190954E-7,1,0.999253354069792,40.0298881530762,1.99621609887351,20.0399998575449,0.000599910249209005,9.89094068426745E-5,0.25,-5.57425992569422E-7,5.29962560007421E-5,-3.96939875653224E-7,99.9922409,99.9922409,4279.98681640625,4289.90966796875,57.166746639506,20.6254436881616,20.631098,0,0,0,40,4449,99.918,4284.9482421875,,,,,,,,,,,,,0,,,,-0.0049,,,,,,99.9922409,,,,
,31579911.36,99.9930496,-1044.18841552734,5.93167705068241E-5,3.63414445493859E-7,1,0.999253354069792,40.0298881530762,1.99626334697635,20.0399998575449,0.000674000751028031,0.000118563323943189,0.25,8.27366813940046E-9,5.96503499425302E-5,1.92958633361953E-7,99.9930496,99.9930496,-1051.73999023438,-1036.63684082031,57.3613721407945,20.6287938546086,20.631098,0,0,0,40,4449,99.9227,-1044.18841552734,,,,,,,,,,,,,0,,,,0,,,,,,99.9930496,,,,
,31580017.585,99.9991302,-6351.97778320312,5.8695003043424E-5,5.58478977669139E-7,1,0.999253354069792,40.0298881530762,1.99602042289517,20.0399998575449,0.000665750387715489,0.000123635519274953,0.25,5.65959906113762E-7,5.90237330438018E-5,7.51016820171118E-7,99.9991302,99.9991302,-6356.98388671875,-6346.9716796875,57.3856026248907,20.6356000599287,20.631098,0,0,0,40,4449,99.9254,-6351.97778320312,,,,,,,,,,,,,0,,,,0.0049,,,,,,99.9991302,,,,
,31580124.385,100.004425,-11692.73828125,4.01642771802926E-5,9.39697471289669E-7,1,0.999253354069792,40.0298881530762,1.99612496351812,20.0399998575449,0.000454798721645368,8.91161724139623E-5,0.25,7.84778436909502E-7,4.03883050220247E-5,9.12987212086253E-7,100.004425,100.004425,-11700.1748046875,-11685.3017578125,57.8319125093715,20.6333055317623,20.631098,0,0,0,40,4449,99.91905,-11692.73828125,,,,,,,,,,,,,0,,,,0,,,,,,100.004425,,,,
,31580229.935,100.008812,-16967.546875,1.5811523664869E-5,9.34882312943202E-7,1,0.999253354069792,40.0298881530762,1.99611784716222,20.0399998575449,0.000178202190474286,3.98623682372942E-5,0.25,7.29878373064983E-7,1.58985580905009E-5,7.82449860692445E-7,100.008812,100.008812,-16977.626953125,-16957.466796875,57.71154171741,20.6360643433042,20.631098,0,0,0,40,4449,99.90925,-16967.546875,,,,,,,,,,,,,0,,,,0,,,,,,100.008812,,,,
,31580336.865,100.0091667,-22312.109375,1.07128293290134E-5,1.12199055875427E-6,1,0.999253354069792,40.0298881530762,1.99615718735064,20.0399998575449,0.000121197929270439,2.44096186204065E-5,0.25,2.65973242551663E-7,1.07725943316731E-5,3.00102015654997E-7,100.0090942,100.0092392,-22319.669921875,-22304.548828125,56.912717370756,20.6343539332878,20.631098,0,0,0,40,4449,99.8983,-22312.109375,,,,,,,,,,,,,0,,,,-0.00245,,,,,,100.0091667,,,,
,31580442.04,100.0110626,-27569.4306640625,2.03804762934391E-5,1.37911496748349E-6,1,0.999253354069792,40.0298881530762,1.99614970935457,20.0399998575449,0.00023009732174279,4.91433502581216E-5,0.25,7.44473029344231E-7,2.04936384356449E-5,8.10362755882716E-7,100.0110626,100.0110626,-27576.986328125,-27561.875,57.4254656793715,20.6365316252634,20.631098,0,0,0,40,4449,99.8878,-27569.4306640625,,,,,,,,,,,,,0,,,,0,,,,,,100.0110626,,,,
,31580550.68,100.0107193,-32998.7734375,3.64405265655506E-5,1.49572520775921E-6,1,0.999253354069792,40.0298881530762,1.9961855243457,20.0399998575449,0.000411806829472177,8.57129075444697E-5,0.25,1.14193167428697E-6,3.6643788630782E-5,1.2579369309252E-6,100.0107193,100.0107193,-33003.78125,-32993.765625,57.3988903097176,20.6336107493489,20.251448,0,0,0,40,4449,99.87665,-32998.7734375,,,,,,,,,,,,,0,,,,0,,,,,,100.0107193,,,,
,31580659.445,100.0105171,-38432.90625,5.47527032315265E-5,1.95042337810477E-6,1,0.999253354069792,40.0298881530762,1.99619294399072,20.0399998575449,0.000617783443263459,0.000134331380413688,0.25,2.20480855787644E-6,5.50571909257688E-5,2.38075503703065E-6,100.0103302,100.010704,-38440.46484375,-38425.34765625,57.1440794124484,20.6361666564021,21.01075,0,0,0,40,4449,99.8668,-38432.90625,,,,,,,,,,,,,0,,,,-0.00245,,,,,,100.0105171,,,,
,31580769.635,100.0106049,-43942.37109375,7.2665336547321E-5,1.58215176931917E-6,1,0.999253354069792,40.0298881530762,1.99608146209706,20.0399998575449,0.000819750715584103,0.000178888361429695,0.25,2.98202462221478E-6,7.30700198813317E-5,3.2143120089492E-6,100.0106049,100.0106049,-43947.23828125,-43937.50390625,57.1581487257945,20.6337958153109,20.251448,0,0,0,40,4449,99.856,-43942.37109375,,,,,,,,,,,,,0,,,,0,,,,,,100.0106049,,,,
,31580878.965,100.0095062,-49404.865234375,9.1693779113324E-5,1.8606755495239E-6,1,0.999253354069792,40.0298881530762,1.99600744725325,20.0399998575449,0.00104016669778594,0.000192816246014023,0.25,8.68522047077401E-7,9.22138891645852E-5,1.14319228745119E-6,100.0095062,100.0095062,-49409.75,-49399.98046875,57.4168677656599,20.6363198867703,20.251448,0,0,0,40,4449,99.84495,-49404.865234375,,,,,,,,,,,,,0,,,,0,,,,,,100.0095062,,,,
,31580988.605,100.0080872,-54883.87109375,0.000111009378937352,1.60283290673114E-6,1,0.999253354069792,40.0298881530762,1.99606075343065,20.0399998575449,0.00125416616380777,0.000262828006327157,0.25,3.6399863746543E-6,0.000111632570343912,3.98485960387501E-6,100.0080872,100.0080872,-54886.296875,-54881.4453125,57.4106147375061,20.6378972984688,21.01075,0,0,0,40,4449,99.8374,-54883.87109375,,,,,,,,,,,,,0,,,,-0.00245,,,,,,100.0080872,,,,
,31581097.155,100.0085678,-60310.806640625,0.000131292669329302,2.17225878634923E-6,1,0.999253354069792,40.0298881530762,1.99611319077717,20.0399998575449,0.00148174184702067,0.000320167081395158,0.25,5.12676715067676E-6,0.0001320286545326,5.53653527656331E-6,100.0085678,100.0085678,-60318.3046875,-60303.30859375,57.4528226775445,20.6321750170821,20.631098,0,0,0,40,4449,99.8259,-60310.806640625,,,,,,,,,,,,,0,,,,0,,,,,,100.0085678,,,,
,31581207.265,100.0076523,-65812.95703125,0.000151010717550655,1.98432894193877E-6,1,0.999253354069792,40.0298881530762,1.99625092886576,20.0399998575449,0.00170614910441453,0.000358344512385083,0.25,5.02594574027357E-6,0.000151861306270868,5.48892471839675E-6,100.0076523,100.0076523,-65820.515625,-65805.3984375,57.4317187075253,20.636139500748,20.631098,0,0,0,40,4449,99.82145,-65812.95703125,,,,,,,,,,,,,0,,,,0.0049,,,,,,100.0076523,,,,
,31581315.625,100.0084229,-71226.76171875,0.000170080660594522,2.34905560631228E-6,1,0.999253354069792,40.0298881530762,1.99617340929392,20.0399998575449,0.00192665434462634,0.000374516539473232,0.25,3.10640016093177E-6,0.000171047633509667,3.60950328885318E-6,100.0084229,100.0084229,-71231.7109375,-71221.8125,57.5184794731599,20.6364253452199,20.631098,0,0,0,40,4449,99.8127,-71226.76171875,,,,,,,,,,,,,0,,,,0,,,,,,100.0084229,,,,
,31581424.29,100.00774,-76659.01171875,0.000189065242787276,2.40110329446693E-6,1,0.999253354069792,40.0298881530762,1.99605475101328,20.0399998575449,0.00213548398591804,0.00045120132897287,0.25,6.52849855375511E-6,0.000190133249808875,7.1012870811339E-6,100.0075912,100.0078888,-76663.96875,-76654.0546875,57.3582456267176,20.6381194199628,21.01075,0,0,0,40,4449,99.8042,-76659.01171875,,,,,,,,,,,,,0,,,,0,,,,,,100.00774,,,,
,31581534.72,100.0067368,-82175.80859375,0.000210061551582624,1.92153600074431E-6,1,0.999253354069792,40.0298881530762,1.99606660740998,20.0399998575449,0.00237810872398166,0.000470337515522963,0.25,4.53215969996698E-6,0.000211257910947252,5.14823817267396E-6,100.0067368,100.0067368,-82185.84375,-82165.7734375,56.9744660237753,20.6379162821594,20.631098,0,0,0,40,4449,99.797,-82175.80859375,,,,,,,,,,,,,0,,,,0,,,,,,100.0067368,,,,
,31581643.07,100.0063553,-87592.25,0.000230703023068107,2.02001706937633E-6,1,0.999253354069792,40.0298881530762,1.99616147642199,20.0399998575449,0.00261152804881291,0.000518896769995561,0.25,5.18619072818206E-6,0.000232018547478112,5.85894421595603E-6,100.0063553,100.0063553,-87602.2734375,-87582.2265625,57.3793495967368,20.6413404625764,20.631098,0,0,0,40,4449,99.79255,-87592.25,,,,,,,,,,,,,0,,,,-0.00245,,,,,,100.0063553,,,,
,31581768.05,100.0030746,-87151.31640625,0.000230856152622708,2.2188974259004E-6,1,0.999253354069792,40.0298881530762,1.9964731960138,20.0399998575449,0.00261803859968558,0.000494296189772416,0.25,2.9877651879413E-6,0.000232178507587927,3.6487341479673E-6,100.0030746,100.0030746,-87159.0234375,-87143.609375,57.115940785756,20.6337793583878,20.631098,0,0,0,40,4449,99.78805,-87151.31640625,,,,,,,,,,,,,0,,,,-0.00245,,,,,,100.0030746,,,,
,31581877.485,100.0001755,-81680.01171875,0.00020839340582854,1.83370728742521E-6,1,0.999253354069792,40.0298881530762,1.99631725889422,20.0399998575449,0.00235941652826062,0.000467158396008826,0.25,4.53970519080277E-6,0.00020957995759326,5.15163399099951E-6,100.0001755,100.0001755,-81687.4375,-81672.5859375,57.3598088837561,20.634554283497,20.631098,0,0,0,40,4449,99.7895,-81680.01171875,,,,,,,,,,,,,0,,,,0,,,,,,100.0001755,,,,
,31581985.36,99.9985275,-76290.48828125,0.000189351147491468,2.25507790711045E-6,1,0.999253354069792,40.0298881530762,1.99625049240234,20.0399998575449,0.00214377494605486,0.000424212601992657,0.25,4.09949850367977E-6,0.000190427539925721,4.65952893955933E-6,99.9985275,99.9985275,-76295.3359375,-76285.640625,57.2324034351214,20.6351936370931,20.251448,0,0,0,40,4449,99.79185,-76290.48828125,,,,,,,,,,,,,0,,,,-0.00245,,,,,,99.9985275,,,,
,31582094,99.9978027,-70860.8984375,0.000169574523197235,2.10748678813066E-6,1,0.999253354069792,40.0298881530762,1.9961947853815,20.0399998575449,0.00191865768834104,0.000386404698634009,0.25,4.24061771981007E-6,0.000170535223610269,4.74916656606383E-6,99.9978027,99.9978027,-70868.5703125,-70853.2265625,57.4473512779099,20.6350060235979,20.631098,0,0,0,40,4449,99.7961,-70860.8984375,,,,,,,,,,,,,0,,,,-0.00245,,,,,,99.9978027,,,,
,31582200.2,99.9959259,-65551.8125,0.00014898030140878,2.24492334390298E-6,1,0.999253354069792,40.0298881530762,1.99619635474979,20.0399998575449,0.00168229038178196,0.00035849333570803,0.25,5.39594040373596E-6,0.000149818080449016,5.85552929826979E-6,99.9959259,99.9959259,-65556.703125,-65546.921875,57.688092861833,20.634416872232,21.01075,0,0,0,40,4449,99.7967,-65551.8125,,,,,,,,,,,,,0,,,,0,,,,,,99.9959259,,,,
,31582305.615,99.9959183,-60284.328125,0.000131756796799512,1.86750919767517E-6,1,0.999253354069792,40.0298881530762,1.99627824335371,20.0399998575449,0.00148872939077069,0.000312024104594638,0.25,4.3263924767143E-6,0.000132497716122845,4.7330896405937E-6,99.9959183,99.9959183,-60289.42578125,-60279.23046875,57.3496477130061,20.6325319327422,20.251448,0,0,0,40,4449,99.8021,-60284.328125,,,,,,,,,,,,,0,,,,0,,,,,,99.9959183,,,,
,31582412.595,99.9948883,-54937.78125,0.000114258476032692,1.92283288281451E-6,1,0.999253354069792,40.0298881530762,1.99622407371984,20.0399998575449,0.00129347212321393,0.000256315208291252,0.25,2.49451179144798E-6,0.000114903532063353,2.84246801229119E-6,99.9948883,99.9948883,-54947.6953125,-54927.8671875,57.1003082153714,20.6313350220746,20.631098,0,0,0,40,4449,99.8076,-54937.78125,,,,,,,,,,,,,0,,,,0.00245,,,,,,99.9948883,,,,
,31582521.165,99.99410625,-49513.75,9.36234077708683E-5,1.33736326778758E-6,1,0.999253354069792,40.0298881530762,1.99614756426148,20.0399998575449,0.00105937375937011,0.000212568254958172,0.25,2.26664780612204E-6,9.41503874715039E-5,2.55506615622051E-6,99.9938354,99.9943771,-49526.37890625,-49501.12109375,57.1440794124484,20.6339990864884,20.631098,0,0,0,40,4449,99.8133,-49513.75,,,,,,,,,,,,,0,,,,-0.00245,,,,,,99.99410625,,,,
,31582630.035,99.9927216,-44068.75,7.51883428768309E-5,1.7618690269429E-6,1,0.999253354069792,40.0298881530762,1.99629057905251,20.0399998575449,0.000852109158304882,0.000163415029772422,0.25,1.1757012412376E-6,7.56127208430272E-5,1.40528175390632E-6,99.9927216,99.9927216,-44073.8828125,-44063.6171875,57.2902439455445,20.6340547706496,20.631098,0,0,0,40,4449,99.81975,-44068.75,,,,,,,,,,,,,0,,,,-0.0049,,,,,,99.9927216,,,,
,31582738.865,99.9926872,-38631.77734375,5.57390417582987E-5,1.49957609100377E-6,1,0.999253354069792,40.0298881530762,1.99636598791046,20.0399998575449,0.000629874707966563,0.000131579407279751,0.25,1.78837363556695E-6,5.60503645488042E-5,1.96496636034141E-6,99.9925842,99.9927902,-38641.80078125,-38621.75390625,57.3871658819292,20.6349964491033,21.01075,0,0,0,40,4449,99.8266,-38631.77734375,,,,,,,,,,,,,0,,,,0.00245,,,,,,99.9926872,,,,
,31582846.08,99.9921112,-33275.255859375,3.59583214494396E-5,1.62457945738688E-6,1,0.999253354069792,40.0298881530762,1.99625052839139,20.0399998575449,0.000406145121953892,8.58622334369097E-5,0.25,1.23950454676573E-6,3.61585517086052E-5,1.35465022677046E-6,99.9921112,99.9921112,-33285.5546875,-33264.95703125,57.4168677656599,20.635361427452,21.01075,0,0,0,40,4449,99.8356,-33275.255859375,,,,,,,,,,,,,0,,,,0,,,,,,99.9921112,,,,
,31582952.01,99.9910507,-27978.546875,1.93153832778584E-5,1.36039947424408E-6,1,0.999253354069792,40.0298881530762,1.99619065455217,20.0399998575449,0.000218357231007934,4.49787448986109E-5,0.25,5.64990027555846E-7,1.9423059339048E-5,6.26652161630678E-7,99.9910507,99.9910507,-27983.57421875,-27973.51953125,57.4504777919868,20.6339629633589,20.251448,0,0,0,40,4449,99.8457,-27978.546875,,,,,,,,,,,,,0,,,,-0.00245,,,,,,99.9910507,,,,
,31583059.045,99.9924774,-22631.2451171875,1.23589549521112E-6,1.16224573816002E-6,1,0.999253354069792,40.0298881530762,1.99621255239246,20.0399998575449,1.19626041646957E-5,1.43123885177359E-5,0.25,1.04239326770958E-6,1.23970771898162E-6,1.05205252800621E-6,99.9924774,99.9924774,-22641.244140625,-22621.24609375,57.3340151426215,20.6314083413023,20.251448,0,0,0,40,4449,99.85195,-22631.2451171875,,,,,,,,,,,,,0,,,,-0.00245,,,,,,99.9924774,,,,
,31583166.47,99.9886856,-17259.11328125,-1.51789313217598E-5,1.22568998424107E-6,1,0.999253354069792,40.0298881530762,1.99629971552961,20.0399998575449,-0.000173952058625269,-2.19685816276937E-5,0.25,7.33953931808112E-7,-1.5266878262955E-5,6.9156609822444E-7,99.9886856,99.9886856,-17264.111328125,-17254.115234375,57.3512109700445,20.6299253961025,20.631098,0,0,0,40,4449,99.86575,-17259.11328125,,,,,,,,,,,,,0,,,,0,,,,,,99.9886856,,,,
,31583273.59,99.989418,-11906.5678710938,-3.21886689891364E-5,7.63002818259756E-7,1,0.999253354069792,40.0298881530762,1.99621488783515,20.0399998575449,-0.000365734607760136,-6.44130491348701E-5,0.25,-1.19746564457905E-8,-3.23700970023256E-5,-1.11300966670625E-7,99.989418,99.989418,-11911.8125,-11901.3232421875,57.3410497992945,20.6327321899001,20.251448,0,0,0,40,4449,99.87405,-11906.5678710938,,,,,,,,,,,,,0,,,,-0.0049,,,,,,99.989418,,,,
,31583379.585,99.9919128,-6606.50415039063,-4.72819211433209E-5,5.22709261764428E-7,1,0.999253354069792,40.0298881530762,1.99623317190937,20.0399998575449,-0.000536936985477418,-9.6272618786451E-5,0.25,-1.62568895388195E-7,-4.75476124449344E-5,-3.10064043910871E-7,99.9919128,99.9919128,-6614.07421875,-6598.93408203125,57.3199458292753,20.6330190186301,21.01075,0,0,0,40,4449,99.88275,-6606.50415039063,,,,,,,,,,,,,0,,,,-0.00245,,,,,,99.9919128,,,,
,31583484.985,99.9922791,-1340.54119873047,-5.91025491321578E-5,3.12955898508571E-7,1,0.999253354069792,40.0298881530762,1.9961803773067,20.0399998575449,-0.000670670314915992,-0.000123076113297341,0.25,-4.43438411407689E-7,-5.94335368013477E-5,-6.29974907567791E-7,99.9922791,99.9922791,-1345.72521972656,-1335.35717773438,57.0182372208522,20.6316938909804,20.631098,0,0,0,40,4449,99.8892,-1340.54119873047,,,,,,,,,,,,,0,,,,0,,,,,,99.9922791,,,,
,31583589.775,99.99651335,3892.69494628906,-6.00155935545135E-5,4.68793810915644E-7,1,0.999253354069792,40.0298881530762,1.99634706772493,20.0399998575449,-0.000680813934029825,-0.000126543669688513,0.25,-5.8759431296638E-7,-6.03514435163786E-5,-7.77399669587053E-7,99.9963531,99.9966736,3882.67602539063,3902.7138671875,57.0588819038522,20.630185129922,20.251448,0,0,0,40,4449,99.89035,3892.69494628906,,,,,,,,,,,,,0,,,,0,,,,,,99.99651335,,,,
,31583695.955,100.0018616,9202.07666015625,-4.9510146925461E-5,5.56577951972518E-7,1,0.999253354069792,40.0298881530762,1.99627390619446,20.0399998575449,-0.000561569472619741,-0.00010470625888017,0.25,-5.13359848165806E-7,-4.97874809865668E-5,-6.69321725391222E-7,100.0018616,100.0018616,9187.0087890625,9217.14453125,57.3035316303714,20.6261608920394,21.01075,0,0,0,40,4449,99.88955,9202.07666015625,,,,,,,,,,,,,0,,,,0.0049,,,,,,100.0018616,,,,
,31583801.99,100.0047455,14504.3393554687,-2.5115548868215E-5,1.01497030109733E-6,1,0.999253354069792,40.0298881530762,1.99622696903347,20.0399998575449,-0.000283355007799188,-6.17319756941316E-5,0.25,-1.01920656429191E-6,-2.52541032193525E-5,-1.10217136295255E-6,100.0047455,100.0047455,14494.3564453125,14514.322265625,57.3011867448138,20.6274284022211,21.01075,0,0,0,40,4449,99.88155,14504.3393554687,,,,,,,,,,,,,0,,,,0,,,,,,100.0047455,,,,
,31583909.54,100.0080795,19879.125,-1.06579002661082E-5,1.15129046537667E-6,1,0.999253354069792,40.0298881530762,1.9964411051555,20.0399998575449,-0.000119076306013445,-3.29154936239252E-5,0.25,-1.02370103730448E-6,-1.07149871564663E-5,-1.06205254467004E-6,100.0080795,100.0080795,19866.853515625,19891.396484375,57.3418314278138,20.6263324057537,21.01075,0,0,0,40,4449,99.872,19879.125,,,,,,,,,,,,,0,,,,0,,,,,,100.0080795,,,,
,31584017.52,100.0098038,25273.5830078125,-1.45946035958971E-5,1.06117875947183E-6,1,0.999253354069792,40.0298881530762,1.99614336036843,20.0399998575449,-0.000164138989292146,-3.88005747923715E-5,0.25,-8.50583916813309E-7,-1.46746053467749E-5,-8.99708959382161E-7,100.0098038,100.0098038,25268.705078125,25278.4609375,57.4145228801022,20.6302896118989,21.01075,0,0,0,40,4449,99.86215,25273.5830078125,,,,,,,,,,,,,0,,,,-0.0049,,,,,,100.0098038,,,,
,31584126.18,100.0117111,30703.6953125,-2.9785004489636E-5,1.47456103388353E-6,1,0.999253354069792,40.0298881530762,1.99612388276707,20.0399998575449,-0.000334941146259566,-7.94000206516625E-5,0.25,-1.75540185094364E-6,-2.9948517619915E-5,-1.8551806579138E-6,100.0117111,100.0117111,30696.189453125,30711.201171875,57.1745629246983,20.628726850425,20.631098,0,0,0,40,4449,99.8507,30703.6953125,,,,,,,,,,,,,0,,,,-0.00245,,,,,,100.0117111,,,,
,31584236.015,100.0116348,36193.861328125,-4.68280362219696E-5,1.29440169070647E-6,1,0.999253354069792,40.0298881530762,1.99617068091978,20.0399998575449,-0.000526548703378991,-0.000125199117426653,0.25,-2.79270072399059E-6,-4.70855061195951E-5,-2.94880171485048E-6,100.0116348,100.0116348,36183.703125,36204.01953125,57.187068981006,20.6289249828455,20.631098,0,0,0,40,4449,99.84,36193.861328125,,,,,,,,,,,,,0,,,,0.00245,,,,,,100.0116348,,,,
,31584341.915,100.0105286,41485.857421875,-6.40032999481761E-5,1.67980755875736E-6,1,0.999253354069792,40.0298881530762,1.99617391525574,20.0399998575449,-0.000721687816129485,-0.000159694353532619,0.25,-2.81277231153136E-6,-6.43588506068495E-5,-3.01912720696273E-6,100.0105286,100.0105286,41480.98046875,41490.734375,57.2449094914291,20.6285500220031,20.631098,0,0,0,40,4449,99.8315,41485.857421875,,,,,,,,,,,,,0,,,,0,,,,,,100.0105286,,,,
,31584451.485,100.0102615,46966.173828125,-8.47143223282325E-5,1.99432426073792E-6,1,0.999253354069792,40.0298881530762,1.99613244642032,20.0399998575449,-0.000957939011906934,-0.000195837677545787,0.25,-2.35807259985694E-6,-8.51898341354908E-5,-2.62163126268334E-6,100.0102615,100.0102615,46963.8359375,46968.51171875,57.0932735586983,20.6270585338147,21.01075,0,0,0,40,4449,99.8211,46966.173828125,,,,,,,,,,,,,0,,,,-0.0049,,,,,,100.0102615,,,,
,31584560.085,100.0090485,52390.498046875,-0.000101400787814367,1.79810749857536E-6,1,0.999253354069792,40.0298881530762,1.99609556065645,20.0399998575449,-0.00114307752231954,-0.000254578029593441,0.25,-4.59950130576659E-6,-0.000101965760222505,-4.92294971050214E-6,100.0090485,100.0090485,52385.47265625,52395.5234375,57.2167708647368,20.625692978028,20.631098,0,0,0,40,4449,99.80965,52390.498046875,,,,,,,,,,,,,0,,,,0,,,,,,100.0090485,,,,
,31584669.07,100.0091019,57840.27734375,-0.000122293909595317,1.92358026494134E-6,1,0.999253354069792,40.0298881530762,1.9961173457077,20.0399998575449,-0.00138227949008543,-0.000286258878383937,0.25,-3.72124762000169E-6,-0.000122981874613606,-4.09826825159051E-6,100.0091019,100.0091019,57832.64453125,57847.91015625,57.0729512171983,20.6253241727917,20.631098,0,0,0,40,4449,99.8018,57840.27734375,,,,,,,,,,,,,0,,,,0.00245,,,,,,100.0091019,,,,
,31584778.875,100.0077286,63328.4765625,-0.000140385889538676,1.86558796321298E-6,1,0.999253354069792,40.0298881530762,1.99618585792806,20.0399998575449,-0.00158609774723377,-0.000332848612713745,0.25,-4.64683208735209E-6,-0.000141175969252138,-5.07869206946382E-6,100.0077286,100.0077286,63320.89453125,63336.05859375,57.126101956506,20.6246333860616,21.01075,0,0,0,40,4449,99.7935,63328.4765625,,,,,,,,,,,,,0,,,,0,,,,,,100.0077286,,,,
,31584888.985,100.0074081,68830.86328125,-0.000161820781355875,2.20222427979111E-6,1,0.999253354069792,40.0298881530762,1.99600804957293,20.0399998575449,-0.00183454222595063,-0.000347134284290383,0.25,-2.14729430683035E-6,-0.000162742337514854,-2.6230992928866E-6,100.0074081,100.0074081,68823.1484375,68838.578125,57.1565854687561,20.6284026531455,20.631098,0,0,0,40,4449,99.78875,68830.86328125,,,,,,,,,,,,,0,,,,0.0049,,,,,,100.0074081,,,,
,31584996.83,100.0075684,74223.29296875,-0.000181576270263271,2.01464869853384E-6,1,0.999253354069792,40.0298881530762,1.99617931182261,20.0399998575449,-0.00205777643254733,-0.000394785335440105,0.25,-2.87417123584303E-6,-0.00018261071095558,-3.40678913730437E-6,100.0075684,100.0075684,74215.890625,74230.6953125,57.119067299833,20.6252415273528,20.631098,0,0,0,40,4449,99.77795,74223.29296875,,,,,,,,,,,,,0,,,,0,,,,,,100.0075684,,,,
,31585105.855,100.0073471,79671.09765625,-0.000199338151268075,2.14408559531261E-6,1,0.999253354069792,40.0298881530762,1.99591733536323,20.0399998575449,-0.00225932775166424,-0.000430388225856397,0.25,-2.89882678049638E-6,-0.000200476410331853,-3.47764539067275E-6,100.0073471,100.0073471,79668.7421875,79673.453125,57.1073428720445,20.6265747437592,20.631098,0,0,0,40,4449,99.7733,79671.09765625,,,,,,,,,,,,,0,,,,0,,,,,,100.0073471,,,,
,31585213.3,100.0067978,85042.00390625,-0.000218956921407675,1.90924955404197E-6,1,0.999253354069792,40.0298881530762,1.99590255223631,20.0399998575449,-0.00248425024549595,-0.000458183053765743,0.25,-1.90715887412712E-6,-0.000220212811696747,-2.53081670904023E-6,100.0067978,100.0067978,85037.0546875,85046.953125,57.0940551872176,20.6273707136976,20.631098,0,0,0,40,4449,99.767,85042.00390625,,,,,,,,,,,,,0,,,,0.00245,,,,,,100.0067978,,,,
,31585335.535,100.004509,89853.26171875,-0.000237815294272603,2.49344352649934E-6,1,0.999253354069792,40.0298881530762,1.99588318258341,20.0399998575449,-0.0026872451781286,-0.000560156782853878,0.25,-7.57732441680925E-6,-0.000239166003615573,-8.28178276913991E-6,100.004509,100.004509,89850.890625,89855.6328125,57.0948368157368,20.6269620628549,20.631098,0,0,0,40,4449,99.7641,89853.26171875,,,,,,,,,,,,,0,,,,-0.00245,,,,,,100.004509,,,,
,31585439.925,100.0024643,84641.7109375,-0.000220696267295241,1.9062064319524E-6,1,0.999253354069792,40.0298881530762,1.99594980849407,20.0399998575449,-0.00249656450021232,-0.000504439648346609,0.25,-5.67138506555773E-6,-0.000221951499647119,-6.3219683596841E-6,100.0024643,100.0024643,84634.3046875,84649.1171875,57.2769562607176,20.6242329692719,20.631098,0,0,0,40,4449,99.7655,84641.7109375,,,,,,,,,,,,,0,,,,0,,,,,,100.0024643,,,,
,31585549.425,99.9979477,79167.59765625,-0.000197535903660529,2.2740926288392E-6,1,0.999253354069792,40.0298881530762,1.99575555935533,20.0399998575449,-0.00223752783666399,-0.000433291450167533,0.25,-3.47308370029488E-6,-0.000198662023475333,-4.05057207800934E-6,99.9979477,99.9979477,79160.296875,79174.8984375,57.2284952925253,20.6313434839603,20.631098,0,0,0,40,4449,99.7687,79167.59765625,,,,,,,,,,,,,0,,,,0,,,,,,99.9979477,,,,
,31585657.29,99.9956131,73772.078125,-0.000179754580459488,2.22118878270214E-6,1,0.999253354069792,40.0298881530762,1.99591943765021,20.0399998575449,-0.00202846836053093,-0.000438691019725684,0.25,-7.06173684134989E-6,-0.000180766530576678,-7.61359772273752E-6,99.9956131,99.9956131,73762.1796875,73781.9765625,57.5919525539676,20.6288720756086,20.631098,0,0,0,40,4449,99.7725,73772.078125,,,,,,,,,,,,,0,,,,-0.0049,,,,,,99.9956131,,,,
,31585764.44,99.9963531,68419.8125,-0.000159865896201607,2.34991635060713E-6,1,0.999253354069792,40.0298881530762,1.99610003044064,20.0399998575449,-0.00180458509597298,-0.000387813412180304,0.25,-6.06840716271097E-6,-0.000160764879802719,-6.5614633255007E-6,99.9963531,99.9963531,68419.8125,68419.8125,57.2722664896022,20.6259755664763,20.631098,0,0,0,40,4449,99.7747,68419.8125,,,,,,,,,,,,,0,,,,0.0049,,,,,,99.9963531,,,,
,31585872.805,99.995018,62999.328125,-0.000138451301299462,1.41762150884978E-6,1,0.999253354069792,40.0298881530762,1.99601694921844,20.0399998575449,-0.0015645794255983,-0.000325579198444576,0.25,-4.34880032376178E-6,-0.000139231082538633,-4.7736387405778E-6,99.995018,99.995018,62986.93359375,63011.72265625,57.3402681707753,20.6302370417763,20.631098,0,0,0,40,4449,99.7807,62999.328125,,,,,,,,,,,,,0,,,,0,,,,,,99.995018,,,,
,31585980.21,99.9942932,57633.291015625,-0.000120763628879965,2.01969488341374E-6,1,0.999253354069792,40.0298881530762,1.99600939415249,20.0399998575449,-0.00136465104227086,-0.000284147832098994,0.25,-3.80524435778251E-6,-0.000121442558898939,-4.17847551895677E-6,99.9942932,99.9942932,57628.1875,57638.39453125,57.1018714724099,20.6278835485813,21.01075,0,0,0,40,4449,99.7878,57633.291015625,,,,,,,,,,,,,0,,,,-0.00245,,,,,,99.9942932,,,,
,31586087.45,99.9947205,52273.814453125,-0.000101758756553688,2.09320567745225E-6,1,0.999253354069792,40.0298881530762,1.99597171684005,20.0399998575449,-0.00115099236890722,-0.00023297703444544,0.25,-2.63679716216313E-6,-0.000102331490012925,-2.95023849950452E-6,99.9947205,99.9947205,52270.96484375,52276.6640625,57.2902439455445,20.6293327613137,20.631098,0,0,0,40,4449,99.7909,52273.814453125,,,,,,,,,,,,,0,,,,0,,,,,,99.9947205,,,,
,31586196.325,99.9927063,46833.81640625,-8.30052625194405E-5,1.52850264063498E-6,1,0.999253354069792,40.0298881530762,1.99600177429821,20.0399998575449,-0.000936916458067619,-0.000201201052777035,0.25,-3.13115417214232E-6,-8.34687265023207E-5,-3.39420017023412E-6,99.9927063,99.9927063,46828.8671875,46838.765625,57.3090030300061,20.6284777755468,20.631098,0,0,0,40,4449,99.7998,46833.81640625,,,,,,,,,,,,,0,,,,-0.0049,,,,,,99.9927063,,,,
,31586303.725,99.9921875,41463.78515625,-6.23499011306279E-5,1.60186866090353E-6,1,0.999253354069792,40.0298881530762,1.99602943102821,20.0399998575449,-0.000704925273585632,-0.000144571376285501,0.25,-1.7731135931318E-6,-6.26991302750878E-5,-1.96871757657896E-6,99.9921875,99.9921875,41456.25390625,41471.31640625,57.3387049137368,20.6280710633877,20.631098,0,0,0,40,4449,99.8081,41463.78515625,,,,,,,,,,,,,0,,,,-0.00245,,,,,,99.9921875,,,,
,31586411.83,99.9906921,36059.40234375,-4.61079267351744E-5,1.58585150364252E-6,1,0.999253354069792,40.0298881530762,1.99617119414082,20.0399998575449,-0.000517097259675169,-0.000130983715388114,0.25,-3.42816462102143E-6,-4.63593843543661E-5,-3.5857954130001E-6,99.9906921,99.9906921,36049.58984375,36069.21484375,57.0604451608906,20.6267788262478,20.631098,0,0,0,40,4449,99.8162,36059.40234375,,,,,,,,,,,,,0,,,,0,,,,,,99.9906921,,,,
,31586517.365,99.9904938,30787.0908203125,-2.67566083501567E-5,1.48217478922346E-6,1,0.999253354069792,40.0298881530762,1.99603787367939,20.0399998575449,-0.000300463957518371,-7.36557157820834E-5,0.25,-1.78210082758458E-6,-2.69028759395947E-5,-1.87292357116145E-6,99.9904938,99.9904938,30782.37109375,30791.810546875,57.505191788333,20.629210182165,20.631098,0,0,0,40,4449,99.82545,30787.0908203125,,,,,,,,,,,,,0,,,,0,,,,,,99.9904938,,,,
,31586623.59,99.9911194,25474.39453125,-1.04919252888861E-5,1.66307070347505E-6,1,0.999253354069792,40.0298881530762,1.996094898712,20.0399998575449,-0.000115335274892514,-4.30331966054973E-5,0.25,-1.94394874317014E-6,-1.05453921733557E-5,-1.98681080528765E-6,99.9911194,99.9911194,25469.375,25479.4140625,57.2761746321984,20.632615852051,21.01075,0,0,0,40,4449,99.8358,25474.39453125,,,,,,,,,,,,,0,,,,0,,,,,,99.9911194,,,,
,31586732.235,99.9893875,20045.0087890625,7.75553575529263E-6,1.06277033943707E-6,1,0.999253354069792,40.0298881530762,1.99603632907973,20.0399998575449,9.04560271615063E-5,2.18731543566491E-6,0.25,-1.17020304195826E-6,7.80293013513258E-6,-1.15310980170921E-6,99.9893875,99.9893875,20032.587890625,20057.4296875,57.4668919908907,20.631005683189,20.251448,0,0,0,40,4449,99.8464,20045.0087890625,,,,,,,,,,,,,0,,,,-0.0049,,,,,,99.9893875,,,,
,31586838.04,99.9918365,14760.8227539062,2.36329980796044E-5,9.69645765168532E-7,1,0.999253354069792,40.0298881530762,1.99609358042606,20.0399998575449,0.000271294294147008,3.14377708176465E-5,0.25,-1.38612639191213E-6,2.3770584480451E-5,-1.32127512083746E-6,99.9918365,99.9918365,14750.8623046875,14770.783203125,57.495030617583,20.6311072598897,20.631098,0,0,0,40,4449,99.8539,14760.8227539062,,,,,,,,,,,,,0,,,,-0.0049,,,,,,99.9918365,,,,
,31586944.465,99.9912796,9441.09130859375,3.99062768854131E-5,7.24584710550911E-7,1,0.999253354069792,40.0298881530762,1.9960721083074,20.0399998575449,0.000454430552769922,7.39358462349852E-5,0.25,-5.06108097142026E-7,4.01326552025946E-5,-3.85554886967939E-7,99.9912796,99.9912796,9433.3095703125,9448.873046875,57.1206305568714,20.6295769808047,20.631098,0,0,0,40,4449,99.86305,9441.09130859375,,,,,,,,,,,,,0,,,,0.00245,,,,,,99.9912796,,,,
,31587051.055,99.9907608,4113.07543945313,5.37860103254488E-5,3.97738569680923E-7,1,0.999253354069792,40.0298881530762,1.99604405091951,20.0399998575449,0.000612148160317176,0.000101496821488821,0.25,-5.20360788409112E-7,5.40902515882583E-5,-3.56131016227026E-7,99.9907608,99.9907608,4105.33203125,4120.81884765625,56.699332785006,20.6312933520579,21.01075,0,0,0,40,4449,99.87365,4113.07543945313,,,,,,,,,,,,,0,,,,-0.00245,,,,,,99.9907608,,,,
,31587135.145,99.9934082,-0.190297164022923,6.03948780071474E-5,3.38492551344746E-7,1,0.999253354069792,40.0298881530762,1.99589033037796,20.0399998575449,0.00068632260352345,0.000119585170061492,0.25,-8.96529305714922E-8,6.0734706464971E-5,9.80956091828253E-8,99.9934082,99.9934082,-0.19790905714035,-0.182685270905495,57.3379232852176,20.632654941483,20.631098,0,0,0,40,4417,99.8782,-0.190297164022923,,,,,,,,,,,,,0,,,,0,,,,,,99.9934082,,,,