File: data/doubleLayers/dl_0-25/ppms/data/DD205_10_HYST_100OE_150K.DAT
[Header]
; VSM Data File (default extension .dat)
; Copyright (c) 2003-2013, Quantum Design, Inc. All rights reserved.
TITLE,
FILEOPENTIME,31588355.36,01/01/2019,10:34 pm
BYAPP,VSM,2.0,2.0
INFO,PPMS VSM Option Release 1.4.10 Build 1,APPNAME
INFO,Quantum Design Linear Motor Servo Controller,MOTOR_MODULE_NAME
INFO,3101-100 M1,MOTOR_HW_VERSION
INFO,MMC1014,MOTOR_SERIAL_NUMBER
INFO,SRV No X-over 01.03.11,MOTOR_SOFTWARE_VERSION
INFO,Quantum Design VSM Detection Module,VSM_MODULE_NAME
INFO,3101-150 F0,VSM_HW_VERSION
INFO,VSM707,VSM_SERIAL_NUMBER
INFO,VSM No X-over 01.02.05 May 20 2008 13:51:47,VSM_SOFTWARE_VERSION
INFO,704,PREAMP_SERIAL_NUMBER
INFO,822,COIL_SERIAL_NUMBER
INFO,0,MOMENT_UNITS
INFO,CoFe2O4,SAMPLE_MATERIAL
INFO,Double Layer thin concentration,SAMPLE_COMMENT
INFO,27.44,SAMPLE_MASS
INFO,,SAMPLE_VOLUME
INFO,,SAMPLE_MOLECULAR_WEIGHT
INFO,,SAMPLE_SIZE
INFO,,SAMPLE_SHAPE
DATATYPE,COMMENT,1
DATATYPE,TIME,2
STARTUPAXIS,X,2
STARTUPAXIS,Y1,5
[Data]
Comment,Time Stamp (sec),Temperature (K),Magnetic Field (Oe),Moment (emu),M. Std. Err. (emu),Transport Action,Averaging Time (sec),Frequency (Hz),Peak Amplitude (mm),Center Position (mm),Coil Signal' (mV),Coil Signal" (mV),Range (mV),M. Quad. Signal (emu),M. Raw' (emu),M. Raw" (emu),Min. Temperature (K),Max. Temperature (K),Min. Field (Oe),Max. Field (Oe),Mass (grams),Motor Lag (deg),Pressure (Torr),VSM Status (code),Motor Status (code),Measure Status (code),Measure Count,PPMS Status (code),System Temp. (K),System Field (Oe),Sample Position (deg),Bridge 1 Resistance (ohms),Bridge 1 Excitation (에),Bridge 2 Resistance (ohms),Bridge 2 Excitation (에),Bridge 3 Resistance (ohms),Bridge 3 Excitation (에),Bridge 4 Resistance (ohms),Bridge 4 Excitation (에),Signal 1 Vin (V),Signal 2 Vin (V),Digital Inputs (code),Drive 1 Iout (mA),Drive 1 Ipower (W),Drive 2 Iout (mA),Drive 2 Ipower (W),Pressure (),Map 20 (),Map 21 (),Map 22 (),Map 23 (),Map 24 (),Map 25 (),Map 26 (),Map 27 (),Map 28 (),Map 29 ()
,31588370.53,149.9789886,-0.228356599807739,,,2,,,,19.8100002416968,,,,,,,149.9789886,149.9789886,-0.228356599807739,-0.228356599807739,,,21.770052,,,,-99999999,4369,149.8717,-0.228356599807739,,,,,,,,,,,,,,,,,,,,,,,149.9789886,,,,
,31588509.935,149.97786715,4473.88500976562,4.0492118107603E-5,5.11045008157436E-7,1,0.999253354069792,40.0298881530762,1.99650026779034,19.7599995881319,0.000460824954347721,7.51207674963054E-5,0.25,-4.41249011458385E-7,4.0691183650159E-5,-3.78485285982953E-7,149.9776459,149.9780884,4446.546875,4501.22314453125,56.6422739031022,20.6067303771588,22.149702,0,0,0,40,4449,149.9046,4473.88500976562,,,,,,,,,,,,,0,,,,0,,,,,,149.97786715,,,,
,31588603.995,149.9838104,9170.27490234375,3.5920612759393E-5,7.38919920232593E-7,1,0.999253354069792,40.0298881530762,1.99641960414986,19.7599995881319,0.000408982585980235,6.54911097562698E-5,0.25,-4.92203053646121E-7,3.60973867662601E-5,-4.37150189386752E-7,149.9838104,149.9838104,9167.931640625,9172.6181640625,56.8994296859291,20.6149587276671,22.149702,0,0,0,40,4449,149.9191,9170.27490234375,,,,,,,,,,,,,0,,,,0.00245,,,,,,149.9838104,,,,
,31588697.64,149.9898453,13850.0122070312,2.60438951836775E-5,9.99906788642185E-7,1,0.999253354069792,40.0298881530762,1.99643403282984,19.7599995881319,0.00029679337868599,4.59786906207627E-5,0.25,-4.89296123343491E-7,2.61722912775699E-5,-4.50130797799052E-7,149.9895325,149.9901581,13820.1943359375,13879.830078125,56.8759808303522,20.6189645115659,21.3904,0,0,0,40,4449,149.926,13850.0122070312,,,,,,,,,,,,,0,,,,-0.00245,,,,,,149.9898453,,,,
,31588791.715,149.9965973,18552.767578125,1.20292359225496E-5,9.90931830099149E-7,1,0.999253354069792,40.0298881530762,1.9964218240012,19.7599995881319,0.000138942449095889,1.05637723107893E-5,0.25,-1.16557526297131E-6,1.20900430801873E-5,-1.15213908323859E-6,149.996521,149.9966736,18527.8515625,18577.68359375,57.2331850636407,20.619315667083,22.149702,0,0,0,40,4449,149.92725,18552.767578125,,,,,,,,,,,,,0,,,,0,,,,,,149.9965973,,,,
,31588886.33,149.9960785,23285.1708984375,-3.27216760148297E-6,1.6345784926853E-6,1,0.999253354069792,40.0298881530762,1.99618351185343,19.7599995881319,-3.31715925493856E-5,-2.93878351632745E-5,0.25,-2.0175273837522E-6,-3.28500367653127E-6,-2.03261138826127E-6,149.9960785,149.9960785,23255.267578125,23315.07421875,57.075296102756,20.6218509937508,22.149702,0,0,0,40,4449,149.9265,23285.1708984375,,,,,,,,,,,,,0,,,,-0.0049,,,,,,149.9960785,,,,
,31588983.175,150.00034335,28125.5302734375,-1.86275388812786E-5,1.84720906950069E-6,1,0.999253354069792,40.0298881530762,1.99624901508622,19.7599995881319,-0.000211427532357865,-3.76564140902998E-5,0.25,-7.05718982078756E-8,-1.87187491444914E-5,-1.00405821030744E-7,150.0000916,150.0005951,28123.125,28127.935546875,56.976810909333,20.6210667401675,21.3904,0,0,0,40,4449,149.9278,28125.5302734375,,,,,,,,,,,,,0,,,,0,,,,,,150.00034335,,,,
,31589077.865,150.00177,32858.2109375,-3.60146185173288E-5,1.91395765687191E-6,1,0.999253354069792,40.0298881530762,1.99614730865758,19.7599995881319,-0.000410873035744923,-6.06486304701292E-5,0.25,9.33467920339391E-7,-3.61926886631873E-5,8.81196074969716E-7,150.00177,150.00177,32830.8984375,32885.5234375,57.2292769210445,20.6226259113435,22.149702,0,0,0,40,4449,149.9268,32858.2109375,,,,,,,,,,,,,0,,,,0,,,,,,150.00177,,,,
,31589172.615,150.0028839,37591.078125,-5.04019178007036E-5,2.00485014542219E-6,1,0.999253354069792,40.0298881530762,1.99614746796688,19.7599995881319,-0.000574016841037951,-9.05852070223402E-5,0.25,8.03532894110512E-7,-5.06503754783211E-5,7.2814539475297E-7,150.0028839,150.0028839,37558.56640625,37623.58984375,57.3668435404292,20.6234540951314,22.149702,0,0,0,40,4449,149.92235,37591.078125,,,,,,,,,,,,,0,,,,0,,,,,,150.0028839,,,,
,31589267.18,150.0077362,42318.435546875,-6.86652171600406E-5,2.15315265514499E-6,1,0.999253354069792,40.0298881530762,1.99615042977672,19.7599995881319,-0.000776083940999561,-0.000157462078904909,0.25,-1.90393798245383E-6,-6.89990526670635E-5,-2.02103392236828E-6,150.0077362,150.0077362,42315.96875,42320.90234375,57.2480360055061,20.6276722268939,22.149702,0,0,0,40,4449,149.914,42318.435546875,,,,,,,,,,,,,0,,,,0,,,,,,150.0077362,,,,
,31589361.525,150.008461,47033.5078125,-8.45640056926888E-5,2.55199856736577E-6,1,0.999253354069792,40.0298881530762,1.99600087582268,19.7599995881319,-0.000957903238144797,-0.000181324948473451,0.25,-1.23723250763223E-6,-8.49769663073627E-5,-1.37560896896948E-6,150.008194,150.008728,47003.1640625,47063.8515625,57.2402197203138,20.6252717437443,22.149702,0,0,0,40,4449,149.90935,47033.5078125,,,,,,,,,,,,,0,,,,0,,,,,,150.008461,,,,
,31589456.055,150.0084991,51758.916015625,-0.000101636079888751,2.08890059085767E-6,1,0.999253354069792,40.0298881530762,1.99593156610199,19.7599995881319,-0.00115227838430243,-0.000212026694148082,0.25,-9.68140566537071E-7,-0.000102133329993299,-1.13142810335558E-6,150.0084991,150.0084991,51756.375,51761.45703125,56.9291315696599,20.6237353436024,21.770052,0,0,0,40,4449,149.8986,51758.916015625,,,,,,,,,,,,,0,,,,-0.0049,,,,,,150.0084991,,,,
,31589549.82,150.0100861,56443.796875,-0.000116192220765823,2.90010717772897E-6,1,0.999253354069792,40.0298881530762,1.99601990105118,19.7599995881319,-0.00131683052054344,-0.000245458495076444,0.25,-1.37637377273661E-6,-0.000116760386028307,-1.56381653080713E-6,150.0100861,150.0100861,56419.03125,56468.5625,56.9517987967176,20.6262855603011,22.149702,0,0,0,40,4449,149.89005,56443.796875,,,,,,,,,,,,,0,,,,0,,,,,,150.0100861,,,,
,31589645.04,150.01081085,61202.021484375,-0.000134696782793675,2.32473982402451E-6,1,0.999253354069792,40.0298881530762,1.99595510858682,19.7599995881319,-0.00152592741248325,-0.000287834001423986,0.25,-1.88617745155929E-6,-0.000135355128558361,-2.10424095365408E-6,150.0107422,150.0108795,61171.703125,61232.33984375,56.946327397083,20.625025811663,22.149702,0,0,0,40,4449,149.8808,61202.021484375,,,,,,,,,,,,,0,,,,-0.00245,,,,,,150.01081085,,,,
,31589738.975,150.0094223,65899.79296875,-0.000150166047194349,2.82159178992872E-6,1,0.999253354069792,40.0298881530762,1.99606532083813,19.7599995881319,-0.00170403980884626,-0.000304970999949472,0.25,-7.00277858034464E-7,-0.000150902340737713,-9.35765519162313E-7,150.0093079,150.0095367,65874.7265625,65924.859375,57.3488660844868,20.6233963946024,22.529354,0,0,0,40,4449,149.87255,65899.79296875,,,,,,,,,,,,,0,,,,0.00245,,,,,,150.0094223,,,,
,31589835.125,150.00923155,70702.484375,-0.000167878018380299,2.86890449271297E-6,1,0.999253354069792,40.0298881530762,1.99593870781223,19.7599995881319,-0.00190383107861504,-0.00034715568545944,0.25,-1.33265262702612E-6,-0.000168700494792233,-1.59777145317059E-6,150.0088806,150.0095825,70672.5703125,70732.3984375,57.1651833824676,20.6270001420317,22.149702,0,0,0,40,4449,149.86355,70702.484375,,,,,,,,,,,,,0,,,,0.00245,,,,,,150.00923155,,,,
,31589929.905,150.0124741,75442.90625,-0.000186693747600235,2.89989008517719E-6,1,0.999253354069792,40.0298881530762,1.99609209000492,19.7599995881319,-0.00211386600846399,-0.000406210677945594,0.25,-3.25427159078405E-6,-0.000187605873946292,-3.55687942514185E-6,150.0124207,150.0125275,75410.21875,75475.59375,57.2011382943522,20.6270795935244,21.770052,0,0,0,40,4449,149.8539,75442.90625,,,,,,,,,,,,,0,,,,0.00245,,,,,,150.0124741,,,,
,31590028.805,150.0087128,80384.0625,-0.000200435931517017,3.23751607800861E-6,1,0.999253354069792,40.0298881530762,1.99605065999155,19.7599995881319,-0.00227293481966611,-0.000415930138252044,0.25,-1.71861076868648E-6,-0.000201418178801507,-2.03370659947358E-6,150.008194,150.0092316,80354.203125,80413.921875,57.6239993232561,20.6258142935605,21.770052,0,0,0,40,4449,149.84985,80384.0625,,,,,,,,,,,,,0,,,,0.00245,,,,,,150.0087128,,,,
,31590124.51,150.01187895,85172.17578125,-0.000225034233621032,2.8697383335556E-6,1,0.999253354069792,40.0298881530762,1.99603356408542,19.7599995881319,-0.00254741841484088,-0.00049247876144471,0.25,-4.17666760711135E-6,-0.000226133833102916,-4.54032098907343E-6,150.011734,150.0120239,85142.25,85202.1015625,56.9525804252368,20.6253847528789,22.149702,0,0,0,40,4449,149.8427,85172.17578125,,,,,,,,,,,,,0,,,,0,,,,,,150.01187895,,,,
,31590216.6,150.0080566,89772.90625,-0.000241291022838456,2.29182696195523E-6,1,0.999253354069792,40.0298881530762,1.99611477576143,19.7599995881319,-0.00273470715163829,-0.000509986265669014,0.25,-2.88667781913603E-6,-0.000242472773613145,-3.26760046739228E-6,150.0080566,150.0080566,89745.375,89800.4375,57.2433462343907,20.628022729098,22.149702,0,0,0,40,4449,149.83085,89772.90625,,,,,,,,,,,,,0,,,,0.00245,,,,,,150.0080566,,,,
,31590322.6,150.0026855,85713.9609375,-0.000223090962943401,2.2502690803235E-6,1,0.999253354069792,40.0298881530762,1.99608092292323,19.7599995881319,-0.00252758660155172,-0.000476130879438557,0.25,-3.07472623195537E-6,-0.000224182771499412,-3.42990515324278E-6,150.0026855,150.0026855,85684.0546875,85743.8671875,57.3652802833907,20.6271216420608,22.149702,0,0,0,40,4449,149.8312,85713.9609375,,,,,,,,,,,,,0,,,,0,,,,,,150.0026855,,,,
,31590418.685,150.00183105,80913.16015625,-0.000204696863317055,2.6825314285418E-6,1,0.999253354069792,40.0298881530762,1.99632703539963,19.7599995881319,-0.00231627498023198,-0.000455182390147739,0.25,-4.42758969321219E-6,-0.000205695957177169,-4.76245364475587E-6,150.0016022,150.0020599,80880.3359375,80945.984375,57.1386080128137,20.6241319871755,22.149702,0,0,0,40,4449,149.83065,80913.16015625,,,,,,,,,,,,,0,,,,0.00245,,,,,,150.00183105,,,,
,31590514.01,149.99627685,76146.87109375,-0.000189146047230309,2.14898672469204E-6,1,0.999253354069792,40.0298881530762,1.99607999140647,19.7599995881319,-0.00213716309864112,-0.000437144204225956,0.25,-5.55120611354401E-6,-0.000190066801798571,-5.86877592599374E-6,149.99617,149.9963837,76116.8125,76176.9296875,57.0393411908714,20.6303528436823,22.149702,0,0,0,40,4449,149.8334,76146.87109375,,,,,,,,,,,,,0,,,,-0.00245,,,,,,149.99627685,,,,
,31590609.165,149.9942856,71390.58984375,-0.000171698269350253,3.03327179137304E-6,1,0.999253354069792,40.0298881530762,1.99622287795986,19.7599995881319,-0.00194181123618412,-0.000387312176257044,0.25,-4.19881505206315E-6,-0.00017253518206082,-4.4838313528981E-6,149.9942627,149.9943085,71363.15625,71418.0234375,57.3895107674868,20.6284761602508,21.770052,0,0,0,40,4449,149.83845,71390.58984375,,,,,,,,,,,,,0,,,,0,,,,,,149.9942856,,,,
,31590707.12,149.9936829,66495.0859375,-0.000153569009264834,3.38100353958845E-6,1,0.999253354069792,40.0298881530762,1.99614432502747,19.7599995881319,-0.00173313367959488,-0.000366950232806526,0.25,-5.56380842030532E-6,-0.000154314573965198,-5.82840420840058E-6,149.9936829,149.9936829,66464.90625,66525.265625,57.2761746321984,20.6298678716534,22.149702,0,0,0,40,4449,149.84415,66495.0859375,,,,,,,,,,,,,0,,,,-0.00245,,,,,,149.9936829,,,,
,31590803.16,149.99222565,61691.359375,-0.000137542355899619,2.01946753815241E-6,1,0.999253354069792,40.0298881530762,1.99615603287429,19.7599995881319,-0.00155650180655055,-0.000304350176054102,0.25,-2.84236123080367E-6,-0.000138213264239312,-3.06951869974199E-6,149.9916077,149.9928436,61661.1953125,61721.5234375,57.3168193151984,20.6303720392246,22.149702,0,0,0,40,4449,149.8515,61691.359375,,,,,,,,,,,,,0,,,,-0.00245,,,,,,149.99222565,,,,
,31590899.61,149.993782,56870.923828125,-0.000117791599920179,2.47236396462198E-6,1,0.999253354069792,40.0298881530762,1.99605797132711,19.7599995881319,-0.00133617877203059,-0.000241967858346997,0.25,-7.90043493475026E-7,-0.0001183685807114,-9.77098372754815E-7,149.9933929,149.9941711,56843.65234375,56898.1953125,57.0002597649099,20.6308979379144,22.149702,0,0,0,40,4449,149.8579,56870.923828125,,,,,,,,,,,,,0,,,,0,,,,,,149.993782,,,,
,31590993.875,149.9944611,52158.67578125,-9.97037597407136E-5,2.14712064329801E-6,1,0.999253354069792,40.0298881530762,1.99584920947913,19.7599995881319,-0.0011306113571912,-0.000206354857233721,0.25,-8.0594872720284E-7,-0.000100191816871614,-9.65439393201919E-7,149.9944611,149.9944611,52126.02734375,52191.32421875,57.1503324406022,20.6330354290483,22.149702,0,0,0,40,4449,149.8616,52158.67578125,,,,,,,,,,,,,0,,,,-0.0049,,,,,,149.9944611,,,,
,31591092.15,149.9920349,47248.2578125,-8.45695265186193E-5,2.3716148175946E-6,1,0.999253354069792,40.0298881530762,1.99609610883346,19.7599995881319,-0.000958749586543868,-0.000177097654190711,0.25,-8.63287661709208E-7,-8.49831312731974E-5,-9.99869949018026E-7,149.9919128,149.992157,47213.47265625,47283.04296875,57.4090514804676,20.6316302030075,22.149702,0,0,0,40,4449,149.86935,47248.2578125,,,,,,,,,,,,,0,,,,0.00245,,,,,,149.9920349,,,,
,31591188.5,149.99210355,42433.3359375,-6.58125996871157E-5,2.238389550417E-6,1,0.999253354069792,40.0298881530762,1.99592442243149,19.7599995881319,-0.000743053174680869,-0.000154975248902448,0.25,-2.1832997369747E-6,-6.61320254820487E-5,-2.29731957230141E-6,149.9920959,149.9921112,42401.12890625,42465.54296875,57.4879959609099,20.6350014995588,22.529354,0,0,0,40,4449,149.8763,42433.3359375,,,,,,,,,,,,,0,,,,-0.00245,,,,,,149.99210355,,,,
,31591284.5,149.9920044,37633,-4.95457024401923E-5,1.91077012397235E-6,1,0.999253354069792,40.0298881530762,1.99615026740288,19.7599995881319,-0.000560562612688651,-0.000110309617648667,0.25,-1.08229282798657E-6,-4.97870012025072E-5,-1.1656099205193E-6,149.9920044,149.9920044,37602.69140625,37663.30859375,57.5176978446407,20.6312240701713,22.529354,0,0,0,40,4449,149.88185,37633,,,,,,,,,,,,,0,,,,0.00245,,,,,,149.9920044,,,,
,31591378.705,149.99314885,32928.275390625,-3.43265575848135E-5,1.76660679889884E-6,1,0.999253354069792,40.0298881530762,1.99613166175332,19.7599995881319,-0.000388222266923282,-7.72643762020552E-5,0.25,-8.23627365898856E-7,-3.44935810979011E-5,-8.8186727293589E-7,149.9930573,149.9932404,32900.65234375,32955.8984375,57.2621053188522,20.6301454731896,22.149702,0,0,0,40,4449,149.89015,32928.275390625,,,,,,,,,,,,,0,,,,0,,,,,,149.99314885,,,,
,31591474.875,149.99134065,28120.828125,-1.87707756648393E-5,1.48518202448604E-6,1,0.999253354069792,40.0298881530762,1.99612178648593,19.7599995881319,-0.000211611171586319,-4.61480713848248E-5,0.25,-7.93509630378885E-7,-1.88615459911671E-5,-8.27124174565027E-7,149.9910126,149.9916687,28093.173828125,28148.482421875,57.4223391652945,20.6329468214871,22.529354,0,0,0,40,4449,149.8947,28120.828125,,,,,,,,,,,,,0,,,,0,,,,,,149.99134065,,,,
,31591571.505,149.9911194,23288.2900390625,-1.76074090517641E-6,1.54780763996897E-6,1,0.999253354069792,40.0298881530762,1.99585764666156,19.7599995881319,-1.83899244736386E-5,-1.26928348898457E-5,0.25,-8.11029289784116E-7,-1.76808371590044E-6,-8.17800630425941E-7,149.9911194,149.9911194,23260.720703125,23315.859375,56.9900985941599,20.6342807722129,22.529354,0,0,0,40,4449,149.90365,23288.2900390625,,,,,,,,,,,,,0,,,,0,,,,,,149.9911194,,,,
,31591670.48,149.9918823,18343.1552734375,1.23991570752573E-5,1.64756481141159E-6,1,0.999253354069792,40.0298881530762,1.99602494489495,19.7599995881319,0.000140074918702329,2.87565150411691E-5,0.25,3.7211883234735E-7,1.24593297171075E-5,3.93684922821386E-7,149.9918823,149.9918823,18338.380859375,18347.9296875,57.3621537693137,20.6326918276311,22.149702,0,0,0,40,4449,149.9117,18343.1552734375,,,,,,,,,,,,,0,,,,0.0049,,,,,,149.9918823,,,,
,31591766.57,149.9922638,13541.1298828125,2.74890635401042E-5,9.63161122690212E-7,1,0.999253354069792,40.0298881530762,1.9959002424793,19.7599995881319,0.000312647799159442,5.15861302323234E-5,0.25,-2.46244844523005E-7,2.76241489441916E-5,-2.03571456939404E-7,149.992218,149.9923096,13511.1318359375,13571.1279296875,57.6232176947369,20.6360033755873,22.529354,0,0,0,40,4449,149.91735,13541.1298828125,,,,,,,,,,,,,0,,,,-0.00735,,,,,,149.9922638,,,,
,31591859.63,149.9911957,8890.90380859375,3.95662406056062E-5,7.48437392608708E-7,1,0.999253354069792,40.0298881530762,1.99615347744367,19.7599995881319,0.000449430568317374,7.78844502852962E-5,0.25,-3.53670721991663E-8,3.97601355595315E-5,2.77611129307986E-8,149.9909363,149.9914551,8863.4375,8918.3701171875,57.5216059872369,20.6340905648408,22.149702,0,0,0,40,4449,149.9248,8890.90380859375,,,,,,,,,,,,,0,,,,0,,,,,,149.9911957,,,,
,31591952.235,149.99446105,4262.6484375,4.71068800403996E-5,4.83716761271248E-7,1,0.999253354069792,40.0298881530762,1.99593571967644,19.7599995881319,0.000534821368210585,9.39047140381494E-5,0.25,6.22250979229164E-8,4.73375219536999E-5,1.38052170559792E-7,149.9944153,149.9945068,4235.1494140625,4290.1474609375,57.2730481181214,20.6354936933441,22.149702,0,0,0,40,4449,149.926,4262.6484375,,,,,,,,,,,,,0,,,,0,,,,,,149.99446105,,,,
,31592044.82,149.995697,-365.603988647461,4.38667913959859E-5,3.70595173227125E-7,1,0.999253354069792,40.0298881530762,1.99612750644256,19.7599995881319,0.000498859163587995,8.29866874308923E-5,0.25,-3.3548187949938E-7,4.4082178360198E-5,-2.66702496809074E-7,149.995697,149.995697,-368.278625488281,-362.929351806641,57.7076335748138,20.6354315943691,22.149702,0,0,0,40,4449,149.93145,-365.603988647461,,,,,,,,,,,,,0,,,,0,,,,,,149.995697,,,,
,31592139.25,149.9981842,-5082.49462890625,2.16740265225143E-5,5.67069804815241E-7,1,0.999253354069792,40.0298881530762,1.9960187512513,19.7599995881319,0.00024562566726915,4.58315019147105E-5,0.25,2.59695886341917E-7,2.17797761494209E-5,2.95701994543606E-7,149.9981842,149.9981842,-5112.576171875,-5052.4130859375,57.6927826329484,20.6376475042137,22.149702,0,0,0,40,4449,149.93175,-5082.49462890625,,,,,,,,,,,,,0,,,,0.00245,,,,,,149.9981842,,,,
,31592234.52,150.0020447,-9846.318359375,-7.07153263854556E-6,8.34421402832646E-7,1,0.999253354069792,40.0298881530762,1.99605795510307,19.7599995881319,-8.03853973730496E-5,-1.3552247997804E-5,0.25,3.86420599842528E-8,-7.10623757514687E-6,2.75234667420539E-8,150.0020447,150.0020447,-9876.18359375,-9816.453125,57.5989872106407,20.6381597383514,21.770052,0,0,0,40,4449,149.9293,-9846.318359375,,,,,,,,,,,,,0,,,,0,,,,,,150.0020447,,,,
,31592330.075,150.0055847,-14621.3481445313,-1.56703172098449E-5,9.756674148985E-7,1,0.999253354069792,40.0298881530762,1.99602374528765,19.7599995881319,-0.000177997785395812,-3.07840569392707E-5,0.25,1.92534967143991E-8,-1.57471277145E-5,-5.65058390171941E-9,150.0055847,150.0055847,-14623.8642578125,-14618.83203125,57.4692368764484,20.6360669142719,21.770052,0,0,0,40,4449,149.92325,-14621.3481445313,,,,,,,,,,,,,0,,,,0,,,,,,150.0055847,,,,
,31592426.82,150.0082245,-19458.7333984375,-7.32669172062436E-6,1.07977085570673E-6,1,0.999253354069792,40.0298881530762,1.99613395038319,19.7599995881319,-8.59488728403201E-5,1.22626676035246E-6,0.25,1.38434045867939E-6,-7.36479905146988E-6,1.37946614785547E-6,150.0081024,150.0083466,-19491.376953125,-19426.08984375,57.6060218673138,20.6383692676334,22.529354,0,0,0,40,4449,149.91455,-19458.7333984375,,,,,,,,,,,,,0,,,,-0.0049,,,,,,150.0082245,,,,
,31592521.955,150.010788,-24213.6474609375,6.18211640172151E-6,1.21099730983177E-6,1,0.999253354069792,40.0298881530762,1.99612566656378,19.7599995881319,6.89724357907061E-5,1.93393203476145E-5,0.25,6.25897399200646E-7,6.2114238053461E-6,6.38776471079916E-7,150.010788,150.010788,-24238.806640625,-24188.48828125,57.7373354585446,20.637184580679,22.149702,0,0,0,40,4449,149.9043,-24213.6474609375,,,,,,,,,,,,,0,,,,0.00245,,,,,,150.010788,,,,
,31592618.71,150.01102445,-29048.3818359375,2.17626244985782E-5,1.62734718057171E-6,1,0.999253354069792,40.0298881530762,1.9958329184223,19.7599995881319,0.000247383165517176,4.15698903185902E-5,0.25,-1.30257665209861E-7,2.18695175411041E-5,-9.64527446483886E-8,150.0108795,150.0111694,-29075.927734375,-29020.8359375,57.4567308201407,20.6418820173189,22.529354,0,0,0,40,4449,149.8924,-29048.3818359375,,,,,,,,,,,,,0,,,,0.00245,,,,,,150.01102445,,,,
,31592716.3,150.0104065,-33923.0625,3.71030904230939E-5,1.47713846817955E-6,1,0.999253354069792,40.0298881530762,1.99600448118343,19.7599995881319,0.000417130763911754,9.767440745827E-5,0.25,2.13763505217926E-6,3.72816449894938E-5,2.20666964236341E-6,150.0104065,150.0104065,-33928.00390625,-33918.12109375,57.7701638563523,20.6431514562015,21.770052,0,0,0,40,4449,149.88325,-33923.0625,,,,,,,,,,,,,0,,,,0.00245,,,,,,150.0104065,,,,
,31592813.13,150.0118866,-38765.142578125,5.41921365907467E-5,1.80231368794875E-6,1,0.999253354069792,40.0298881530762,1.99611412118509,19.7599995881319,0.000613869805308957,0.000116358340445085,0.25,8.05751378809439E-7,5.44566428097944E-5,8.9496981537513E-7,150.0118866,150.0118866,-38789.78515625,-38740.5,57.2167708647368,20.6394209583988,21.770052,0,0,0,40,4449,149.8777,-38765.142578125,,,,,,,,,,,,,0,,,,0,,,,,,150.0118866,,,,
,31592911.83,150.0098114,-43697.396484375,7.25789335846388E-5,2.15561430574355E-6,1,0.999253354069792,40.0298881530762,1.99609725369364,19.7599995881319,0.000822588192202731,0.000153282835859272,0.25,8.54636864909148E-7,7.29336204606022E-5,9.72679323201586E-7,150.0098114,150.0098114,-43727.31640625,-43667.4765625,57.6247809517753,20.6406691846841,22.149702,0,0,0,40,4449,149.8648,-43697.396484375,,,,,,,,,,,,,0,,,,-0.00245,,,,,,150.0098114,,,,
,31593008.82,150.0102234,-48544.80078125,8.91412366456954E-5,2.27471331865E-6,1,0.999253354069792,40.0298881530762,1.99610056864584,19.7599995881319,0.00100406198753478,0.000224093672994373,0.25,4.20510776062964E-6,8.95720246086178E-5,4.3651390352975E-6,150.0102234,150.0102234,-48574.578125,-48515.0234375,57.6325972369676,20.6369513155056,22.529354,0,0,0,40,4449,149.8561,-48544.80078125,,,,,,,,,,,,,0,,,,0.00245,,,,,,150.0102234,,,,
,31593108.39,150.0094147,-53520.109375,0.000106456725987946,1.84217230210126E-6,1,0.999253354069792,40.0298881530762,1.9961346201095,19.7599995881319,0.0012035669267834,0.00024209626848983,0.25,2.77440881329788E-6,0.000106974839413314,2.95396761402897E-6,150.0094147,150.0094147,-53522.57421875,-53517.64453125,57.3801312252561,20.6396143354806,22.529354,0,0,0,40,4449,149.8457,-53520.109375,,,,,,,,,,,,,0,,,,0.0049,,,,,,150.0094147,,,,
,31593203.665,150.0105743,-58282.208984375,0.000123828026217728,2.16532074145471E-6,1,0.999253354069792,40.0298881530762,1.99614184700385,19.7599995881319,0.00139618516256867,0.000303320799403721,0.25,5.14003480117479E-6,0.000124427851394385,5.35768682299506E-6,150.0101318,150.0110168,-58314.53125,-58249.88671875,57.9225814176023,20.6373789565131,22.149702,0,0,0,40,4449,149.83435,-58282.208984375,,,,,,,,,,,,,0,,,,-0.00245,,,,,,150.0105743,,,,
,31593299.815,150.0125885,-63089.7421875,0.000140484377437505,2.16943523038213E-6,1,0.999253354069792,40.0298881530762,1.99618749924566,19.7599995881319,0.00159022592023873,0.000308526553085713,0.25,2.69743631447162E-6,0.000141169910148956,2.92828968400969E-6,150.0125885,150.0125885,-63112.24609375,-63067.23828125,57.9866749561792,20.6412364297446,22.529354,0,0,0,40,4449,149.8233,-63089.7421875,,,,,,,,,,,,,0,,,,-0.0049,,,,,,150.0125885,,,,
,31593396.89,150.0122528,-67939.6015625,0.000157551844576196,2.46696651233772E-6,1,0.999253354069792,40.0298881530762,1.99619502153355,19.7599995881319,0.00177746926396207,0.000380243811580602,0.25,6.0400107948505E-6,0.000158316195061482,6.31291928302763E-6,150.0122528,150.0122528,-67944.59375,-67934.609375,57.7779801415446,20.6436633509042,22.529354,0,0,0,40,4449,149.8147,-67939.6015625,,,,,,,,,,,,,0,,,,0,,,,,,150.0122528,,,,
,31593497.085,150.0117035,-72948.46875,0.000174688683493738,2.55329281810403E-6,1,0.999253354069792,40.0298881530762,1.99606138638339,19.7599995881319,0.00197550987234113,0.000393845317134259,0.25,4.25611786181742E-6,0.000175540159168834,4.54581615043194E-6,150.0117035,150.0117035,-72955.9375,-72941,57.4942489890638,20.6436824332517,22.149702,0,0,0,40,4449,149.8018,-72948.46875,,,,,,,,,,,,,0,,,,0,,,,,,150.0117035,,,,
,31593591.055,150.0113754,-77640.7578125,0.000191522172633999,2.18191387955711E-6,1,0.999253354069792,40.0298881530762,1.99610251900861,19.7599995881319,0.00216678850250135,0.00042682291755003,0.25,4.22840494561439E-6,0.000192456596343562,4.54292261087579E-6,150.0110168,150.011734,-77668.125,-77613.390625,57.8584878790253,20.6427787295135,22.149702,0,0,0,40,4449,149.79195,-77640.7578125,,,,,,,,,,,,,0,,,,-0.00245,,,,,,150.0113754,,,,
,31593688.39,150.0094604,-82508.01953125,0.00021298845670265,2.75036023597305E-6,1,0.999253354069792,40.0298881530762,1.99609752627724,19.7599995881319,0.00241191461977527,0.000461627933897809,0.25,3.55581895058427E-6,0.000214029637075503,3.89884223031789E-6,150.0094604,150.0094604,-82540.6015625,-82475.4375,57.4887775894292,20.6461931110221,22.909004,0,0,0,40,4449,149.78655,-82508.01953125,,,,,,,,,,,,,0,,,,-0.00245,,,,,,150.0094604,,,,
,31593783.095,150.0109558,-87239.9609375,0.000227793852845604,2.71433488399009E-6,1,0.999253354069792,40.0298881530762,1.99611162976961,19.7599995881319,0.00258517127786922,0.000461689775496618,0.25,9.83830917823187E-7,0.000228911954557574,1.33569531368971E-6,150.0109558,150.0109558,-87242.453125,-87237.46875,57.8866265057177,20.6439581644248,22.149702,0,0,0,40,4449,149.7759,-87239.9609375,,,,,,,,,,,,,0,,,,0,,,,,,150.0109558,,,,
,31593892.125,150.0077209,-88068.015625,0.000230588962034748,3.03194060097139E-6,1,0.999253354069792,40.0298881530762,1.99626075573387,19.7599995881319,0.00260996521272975,0.00050824274641925,0.25,4.59303230220921E-6,0.000231715366448966,4.96671127546216E-6,150.0077209,150.0077209,-88097.984375,-88038.046875,57.5200427301984,20.6406838782343,22.149702,0,0,0,40,4449,149.76765,-88068.015625,,,,,,,,,,,,,0,,,,0,,,,,,150.0077209,,,,
,31593986.335,150.0009155,-83361.234375,0.000214330535599898,2.50780119898558E-6,1,0.999253354069792,40.0298881530762,1.99620437014259,19.7599995881319,0.00242688441692041,0.000466588167787043,0.25,3.75688860039664E-6,0.000215378089450531,4.10280201909132E-6,150.0009155,150.0009155,-83366.0859375,-83356.3828125,57.7576578000446,20.6426189229402,22.529354,0,0,0,40,4449,149.77,-83361.234375,,,,,,,,,,,,,0,,,,0.00245,,,,,,150.0009155,,,,
,31594081.14,149.9961853,-78623.96484375,0.000199067482668604,2.76654937279035E-6,1,0.999253354069792,40.0298881530762,1.99610787344407,19.7599995881319,0.00225461336073211,0.000429549692304947,0.25,3.15453559158093E-6,0.000200040744696818,3.47518624193141E-6,149.9961853,149.9961853,-78653.7578125,-78594.171875,57.4520410490253,20.6435069816573,22.149702,0,0,0,40,4449,149.775,-78623.96484375,,,,,,,,,,,,,0,,,,0,,,,,,149.9961853,,,,
,31594177.93,149.9940796,-73783.984375,0.00017855717514652,2.93531037051931E-6,1,0.999253354069792,40.0298881530762,1.99606553264726,19.7599995881319,0.0020226552217962,0.000383089389897478,0.25,2.63534192585795E-6,0.000179430258250297,2.92292780289453E-6,149.9940796,149.9940796,-73786.3203125,-73781.6484375,57.4121779945445,20.6432024582956,22.149702,0,0,0,40,4449,149.7798,-73783.984375,,,,,,,,,,,,,0,,,,-0.00245,,,,,,149.9940796,,,,
,31594273.985,149.99273685,-68984.5234375,0.000161568720974,3.11856259529307E-6,1,0.999253354069792,40.0298881530762,1.99610323494622,19.7599995881319,0.00182607872001604,0.000370568437740114,0.25,4.49007884234061E-6,0.000162355307127186,4.76146214165189E-6,149.9923859,149.9930878,-69009.390625,-68959.65625,57.6161830380638,20.6412608513843,22.149702,0,0,0,40,4449,149.7877,-68984.5234375,,,,,,,,,,,,,0,,,,0,,,,,,149.99273685,,,,
,31594371.33,149.99183655,-64119.703125,0.000144954275806473,2.90148812449955E-6,1,0.999253354069792,40.0298881530762,1.99618178121087,19.7599995881319,0.00164033894476256,0.000321105030400619,0.25,3.02658924634605E-6,0.000145661351250796,3.26588711887118E-6,149.9917297,149.9919434,-64147.46484375,-64091.94140625,57.4215575367753,20.6427516577678,22.149702,0,0,0,40,4449,149.79385,-64119.703125,,,,,,,,,,,,,0,,,,-0.0049,,,,,,149.99183655,,,,
,31594468.88,149.9915314,-59244.826171875,0.00012818186728705,2.26075342353362E-6,1,0.999253354069792,40.0298881530762,1.99603298149381,19.7599995881319,0.00145042924400018,0.000283953109524929,0.25,2.67777751789796E-6,0.000128806975113174,2.89003939401312E-6,149.9915314,149.9915314,-59274.80859375,-59214.84375,57.5442732142945,20.6421393468143,22.529354,0,0,0,40,4449,149.8028,-59244.826171875,,,,,,,,,,,,,0,,,,0,,,,,,149.9915314,,,,
,31594567.275,149.9892426,-54325.029296875,0.000107914390101569,2.59954075635137E-6,1,0.999253354069792,40.0298881530762,1.99606265694263,19.7599995881319,0.00122218154425139,0.00023291015643871,0.25,1.71241589398796E-6,0.000108441381896509,1.8890008748571E-6,149.9892426,149.9892426,-54327.53515625,-54322.5234375,57.6748051770061,20.6400907339965,22.149702,0,0,0,40,4449,149.8107,-54325.029296875,,,,,,,,,,,,,0,,,,0,,,,,,149.9892426,,,,
,31594663.02,149.98994445,-49542.947265625,9.15632817990524E-5,2.24806729426134E-6,1,0.999253354069792,40.0298881530762,1.99603480752925,19.7599995881319,0.00103790341721051,0.000192329929574826,0.25,9.86971458295074E-7,9.20110488592517E-5,1.13495403989418E-6,149.9895172,149.9903717,-49575.28515625,-49510.609375,57.6380686366023,20.638706173023,21.770052,0,0,0,40,4449,149.82145,-49542.947265625,,,,,,,,,,,,,0,,,,-0.00245,,,,,,149.98994445,,,,
,31594761.92,149.9891052,-44598.07421875,7.41354822962287E-5,2.17801952324717E-6,1,0.999253354069792,40.0298881530762,1.99613580579922,19.7599995881319,0.00083520275957206,0.000185524987103403,0.25,3.42219535500556E-6,7.4493828183782E-5,3.55524651832131E-6,149.9891052,149.9891052,-44603.11328125,-44593.03515625,57.7310824303907,20.6394717146834,22.149702,0,0,0,40,4449,149.83055,-44598.07421875,,,,,,,,,,,,,0,,,,0,,,,,,149.9891052,,,,
,31594856.135,149.9923553,-39890.611328125,5.85984671244984E-5,1.97393730429801E-6,1,0.999253354069792,40.0298881530762,1.99608256648327,19.7599995881319,0.000660471308608813,0.000144775700958111,0.25,2.54059862154268E-6,5.88818926747426E-5,2.64523367760734E-6,149.9923553,149.9923553,-39895.546875,-39885.67578125,57.6325972369676,20.6393946425189,21.770052,0,0,0,40,4449,149.83245,-39890.611328125,,,,,,,,,,,,,0,,,,0,,,,,,149.9923553,,,,
,31594953.175,149.99153135,-35040.7109375,4.27987169672485E-5,1.28761392174023E-6,1,0.999253354069792,40.0298881530762,1.99619627801421,19.7599995881319,0.000486372856364591,8.30296426783316E-5,0.25,-1.44718945789295E-7,4.30088282059821E-5,-7.79089818361726E-8,149.9913177,149.991745,-35073.1875,-35008.234375,57.4293738219676,20.6358673725303,22.149702,0,0,0,40,4449,149.84445,-35040.7109375,,,,,,,,,,,,,0,,,,-0.00245,,,,,,149.99153135,,,,
,31595048.3,149.99087525,-30288.677734375,2.58065861294606E-5,1.64020830890786E-6,1,0.999253354069792,40.0298881530762,1.99603716147821,19.7599995881319,0.000291822425108683,5.82470765345733E-5,0.25,6.3344281391783E-7,2.59321136138262E-5,6.77376760763478E-7,149.9906769,149.9910736,-30321.0078125,-30256.34765625,57.5771016121022,20.6377885287595,22.909004,0,0,0,40,4449,149.8542,-30288.677734375,,,,,,,,,,,,,0,,,,0.00245,,,,,,149.99087525,,,,
,31595141.85,149.991272,-25611.65625,1.09300012174933E-5,1.57628776158578E-6,1,0.999253354069792,40.0298881530762,1.99605939930857,19.7599995881319,0.00012133339839133,3.76714190680579E-5,0.25,1.41306604553614E-6,1.09813388895981E-5,1.43733229126141E-6,149.991272,149.991272,-25644.158203125,-25579.154296875,57.5919525539676,20.6361824297612,22.529354,0,0,0,40,4449,149.862,-25611.65625,,,,,,,,,,,,,0,,,,-0.00245,,,,,,149.991272,,,,
,31595237.99,149.9894867,-20806.7236328125,-4.81700912610847E-6,1.48053965267127E-6,1,0.999253354069792,40.0298881530762,1.99609062990402,19.7599995881319,-5.58886853949836E-5,-2.74214482663615E-6,0.25,5.97705639324163E-7,-4.84156879106655E-6,5.92972613255392E-7,149.9894867,149.9894867,-20811.73828125,-20801.708984375,57.3363600281791,20.6385432649138,22.529354,0,0,0,40,4449,149.8684,-20806.7236328125,,,,,,,,,,,,,0,,,,0,,,,,,149.9894867,,,,
,31595333.85,149.9894867,-16017.1186523438,-1.9770635948752E-5,1.11645184833588E-6,1,0.999253354069792,40.0298881530762,1.99600791226098,19.7599995881319,-0.000223888922629193,-4.27561911779542E-5,0.25,-3.20669795884591E-7,-1.9867005857159E-5,-3.53770546797827E-7,149.9894867,149.9894867,-16039.744140625,-15994.4931640625,57.7771985130253,20.6404522934059,22.909004,0,0,0,40,4449,149.8796,-16017.1186523438,,,,,,,,,,,,,0,,,,0,,,,,,149.9894867,,,,
,31595429.195,149.9915619,-11249.2231445312,-3.29322928436474E-5,1.10774096276683E-6,1,0.999253354069792,40.0298881530762,1.99620539804091,19.7599995881319,-0.000373281743212593,-6.94400808836606E-5,0.25,-3.7673808588453E-7,-3.3093037567479E-5,-4.31229920211173E-7,149.9915619,149.9915619,-11281.7646484375,-11216.681640625,57.1128142716791,20.6388729116244,22.529354,0,0,0,40,4449,149.8871,-11249.2231445312,,,,,,,,,,,,,0,,,,0,,,,,,149.9915619,,,,
,31595527.03,149.9915924,-6361.28930664062,-4.36764459547361E-5,6.30624944065763E-7,1,0.999253354069792,40.0298881530762,1.99590783978712,19.7599995881319,-0.000495214632927447,-9.08152145163096E-5,0.25,-3.87964509604915E-7,-4.38897761904305E-5,-4.59843279157891E-7,149.9915924,149.9915924,-6363.95458984375,-6358.6240234375,57.6622991206984,20.6386894024649,22.909004,0,0,0,40,4449,149.8975,-6361.28930664062,,,,,,,,,,,,,0,,,,-0.0049,,,,,,149.9915924,,,,
,31595623.39,149.9938354,-1542.40026855469,-4.8274698577865E-5,3.21789757733347E-7,1,0.999253354069792,40.0298881530762,1.99611994308018,19.7599995881319,-0.000547662119841005,-9.89156144997607E-5,0.25,-2.9916100317677E-7,-4.85106589049477E-5,-3.78121268691489E-7,149.9938354,149.9938354,-1549.95983886719,-1534.84069824219,57.4465696493907,20.6352628909521,22.149702,0,0,0,40,4449,149.8997,-1542.40026855469,,,,,,,,,,,,,0,,,,0,,,,,,149.9938354,,,,
,31595716.625,149.9954834,3112.74670410156,-3.22934695096994E-5,5.35531290453045E-7,1,0.999253354069792,40.0298881530762,1.99629408449337,19.7599995881319,-0.000365135889576616,-7.33759532838202E-5,0.25,-8.34127515694453E-7,-3.24503040022637E-5,-8.90022968088634E-7,149.9954834,149.9954834,3082.728515625,3142.76489257812,57.6279074658522,20.6352928219112,22.149702,0,0,0,40,4449,149.901,3112.74670410156,,,,,,,,,,,,,0,,,,-0.00245,,,,,,149.9954834,,,,
,31595812.415,150.0017624,7902.39428710937,-3.40872365601019E-6,6.60122120568254E-7,1,0.999253354069792,40.0298881530762,1.99620061640809,19.7599995881319,-3.80122972160604E-5,-1.07742012662031E-5,0.25,-3.54788214691387E-7,-3.42485341389815E-6,-3.61983526366228E-7,150.001709,150.0018158,7872.31591796875,7932.47265625,57.65057469291,20.6372756441206,22.529354,0,0,0,40,4449,149.90145,7902.39428710937,,,,,,,,,,,,,0,,,,0.0049,,,,,,150.0017624,,,,
,31595907.915,150.0027008,12672.8500976563,1.63237389602565E-5,7.42412052196903E-7,1,0.999253354069792,40.0298881530762,1.99601373620309,19.7599995881319,0.000186962204983012,2.32093873466835E-5,0.25,-8.00101152746717E-7,1.64049923127034E-5,-7.77946930335918E-7,150.0027008,150.0027008,12645.3671875,12700.3330078125,57.6396318936407,20.6371002185647,22.909004,0,0,0,40,4449,149.8961,12672.8500976563,,,,,,,,,,,,,0,,,,-0.0049,,,,,,150.0027008,,,,
,31596003.43,150.00572205,17450.4560546875,1.16952279929852E-5,9.23905840203117E-7,1,0.999253354069792,40.0298881530762,1.99626902422732,19.7599995881319,0.000133769001800139,1.77640872477562E-5,0.25,-4.73385213441725E-7,1.17532903530306E-5,-4.57071023867069E-7,150.0054474,150.0059967,17423.20703125,17477.705078125,57.6177462951023,20.6343827838823,22.529354,0,0,0,40,4449,149.89455,17450.4560546875,,,,,,,,,,,,,0,,,,0,,,,,,150.00572205,,,,
,31596101.195,150.0100861,22335.7958984375,-6.1940388216857E-7,1.36826238188726E-6,1,0.999253354069792,40.0298881530762,1.99628530346266,19.7599995881319,-5.06661199498935E-6,-1.25256161522752E-5,0.25,-9.9490440159727E-7,-6.20858492311787E-7,-1.0007646607759E-6,150.0100861,150.0100861,22305.744140625,22365.84765625,57.6896561188715,20.6325360671953,22.909004,0,0,0,40,4449,149.8808,22335.7958984375,,,,,,,,,,,,,0,,,,0.00245,,,,,,150.0100861,,,,
,31596196.51,150.0102997,27101.3505859375,-1.48618767075887E-5,2.07756738186046E-6,1,0.999253354069792,40.0298881530762,1.99627109973899,19.7599995881319,-0.000167771587245604,-3.53045158487888E-5,0.25,-5.19417104733184E-7,-1.49339043399898E-5,-5.45516360948356E-7,150.0102997,150.0102997,27068.94921875,27133.751953125,57.6537012069869,20.6297830927783,22.149702,0,0,0,40,4449,149.87485,27101.3505859375,,,,,,,,,,,,,0,,,,0.00245,,,,,,150.0102997,,,,
,31596294.625,150.012207,32003.7763671875,-3.09805587037672E-5,1.71581314339666E-6,1,0.999253354069792,40.0298881530762,1.99611824735925,19.7599995881319,-0.000350408555289515,-6.95545453786878E-5,0.25,-7.27636170663856E-7,-3.11313000339522E-5,-7.80161541953802E-7,150.012207,150.012207,31976.353515625,32031.19921875,56.9916618511983,20.6316962455758,22.909004,0,0,0,40,4449,149.864,32003.7763671875,,,,,,,,,,,,,0,,,,-0.00245,,,,,,150.012207,,,,
,31596388.625,150.0108185,36701.462890625,-4.79624203014367E-5,1.57886602870536E-6,1,0.999253354069792,40.0298881530762,1.99599581937473,19.7599995881319,-0.000545224101675249,-9.17623567781923E-5,0.25,2.7445042512461E-7,-4.81980506200638E-5,2.00214912024084E-7,150.0106659,150.0109711,36669.02734375,36733.8984375,57.7990841115638,20.6369191151319,22.149702,0,0,0,40,4449,149.85265,36701.462890625,,,,,,,,,,,,,0,,,,-0.00245,,,,,,150.0108185,,,,
,31596485.985,150.0113068,41569.005859375,-6.38328219143708E-5,2.4026816133023E-6,1,0.999253354069792,40.0298881530762,1.99583620185439,19.7599995881319,-0.000724177498008145,-0.000130167974514848,0.25,-3.4405671407186E-7,-6.41453684494796E-5,-4.46035214728216E-7,150.0113068,150.0113068,41566.67578125,41571.3359375,56.9752476522945,20.6393945170575,22.909004,0,0,0,40,4449,149.841,41569.005859375,,,,,,,,,,,,,0,,,,0,,,,,,150.0113068,,,,
,31596584.51,150.0119476,46491.7890625,-8.23818097665144E-5,2.30239549098788E-6,1,0.999253354069792,40.0298881530762,1.9962460433643,19.7599995881319,-0.000932874578258657,-0.000179070047791549,0.25,-1.41679065365855E-6,-8.27837418588953E-5,-1.552774941696E-6,150.0119476,150.0119476,46489.0703125,46494.5078125,57.484869446833,20.631825155702,22.529354,0,0,0,40,4449,149.83085,46491.7890625,,,,,,,,,,,,,0,,,,-0.00245,,,,,,150.0119476,,,,
,31596681.47,150.0098724,51339.271484375,-9.79588100394069E-5,2.30338387104836E-6,1,0.999253354069792,40.0298881530762,1.99602981360851,19.7599995881319,-0.00110957622172643,-0.000210471353228616,0.25,-1.47064982570412E-6,-9.84371905124534E-5,-1.63082545725275E-6,150.0098724,150.0098724,51336.79296875,51341.75,56.8783257159099,20.6354711245031,22.149702,0,0,0,40,4449,149.8183,51339.271484375,,,,,,,,,,,,,0,,,,0,,,,,,150.0098724,,,,
,31596779.89,150.0092697,56256.75390625,-0.00011841826428506,2.32913831256808E-6,1,0.999253354069792,40.0298881530762,1.99596397307979,19.7599995881319,-0.00133837915943953,-0.000271072237615915,0.25,-3.24455169785934E-6,-0.000118994415826112,-3.44477950904895E-6,150.0090179,150.0095215,56224.171875,56289.3359375,57.0627900464484,20.6346178435034,22.909004,0,0,0,40,4449,149.81425,56256.75390625,,,,,,,,,,,,,0,,,,0,,,,,,150.0092697,,,,
,31596876.235,150.0096283,61072.232421875,-0.000133627690407169,2.32305244373728E-6,1,0.999253354069792,40.0298881530762,1.99589273616022,19.7599995881319,-0.00151939145342463,-0.000253267834411346,0.25,9.70904008094031E-7,-0.000134285186897973,7.68358156455257E-7,150.0096283,150.0096283,61042.27734375,61102.1875,57.3144744296407,20.6348485491887,22.149702,0,0,0,40,4449,149.80495,61072.232421875,,,,,,,,,,,,,0,,,,0.00245,,,,,,150.0096283,,,,
,31596971.755,150.0113983,65847.484375,-0.000149535751850163,2.45946129153833E-6,1,0.999253354069792,40.0298881530762,1.99600052903189,19.7599995881319,-0.00169410586667103,-0.000319347491649391,0.25,-2.0766300399686E-6,-0.000150266774351943,-2.31808176906975E-6,150.0113983,150.0113983,65819.9296875,65875.0390625,57.7537496574484,20.635646911248,22.529354,0,0,0,40,4449,149.7929,65847.484375,,,,,,,,,,,,,0,,,,0,,,,,,150.0113983,,,,
,31597069.57,150.00823975,70735.2578125,-0.000169350297210824,3.39219962624997E-6,1,0.999253354069792,40.0298881530762,1.99605654827859,19.7599995881319,-0.00192330149515919,-0.000334911183822699,0.25,3.80371988472841E-9,-0.000170182029772307,-2.57198545145649E-7,150.0081482,150.0083313,70702.75,70767.765625,57.1386080128137,20.6302844304944,22.529354,0,0,0,40,4449,149.787,70735.2578125,,,,,,,,,,,,,0,,,,0,,,,,,150.00823975,,,,
,31597165,150.0098419,75505.671875,-0.000186758962195161,2.90432178143288E-6,1,0.999253354069792,40.0298881530762,1.99602232924458,19.7599995881319,-0.00210981474211181,-0.000433434954696593,0.25,-5.64111955083747E-6,-0.000187667713188459,-5.95573889694815E-6,150.0098419,150.0098419,75475.78125,75535.5625,57.5825730117369,20.6299576908917,22.149702,0,0,0,40,4449,149.77875,75505.671875,,,,,,,,,,,,,0,,,,-0.00245,,,,,,150.0098419,,,,
,31597260.965,150.011795,80304.53125,-0.000204038148403169,2.54357483319293E-6,1,0.999253354069792,40.0298881530762,1.99601765663431,19.7599995881319,-0.00230531547511123,-0.000471811458262642,0.25,-6.0121767731513E-6,-0.000205031445474636,-6.35414448675642E-6,150.011795,150.011795,80274.5703125,80334.4921875,57.1175040427945,20.6298345085654,22.529354,0,0,0,40,4449,149.76375,80304.53125,,,,,,,,,,,,,0,,,,-0.00245,,,,,,150.011795,,,,
,31597356.68,150.009552,85087.9453125,-0.000222541179771527,2.67189469421524E-6,1,0.999253354069792,40.0298881530762,1.99606618421669,19.7599995881319,-0.002516968370927,-0.000500048817621615,0.25,-5.2764082180232E-6,-0.000223626797417302,-5.64195101406322E-6,150.009552,150.009552,85083.140625,85092.75,57.3519925985638,20.6313978477697,22.149702,0,0,0,40,4449,149.7573,85087.9453125,,,,,,,,,,,,,0,,,,0,,,,,,150.009552,,,,
,31597449.535,150.0081482,89730.453125,-0.000239634524742381,2.92673344082126E-6,1,0.999253354069792,40.0298881530762,1.99601858984497,19.7599995881319,-0.00271324939565772,-0.000521151296512412,0.25,-4.16004745771207E-6,-0.000240806133516284,-4.54498919876108E-6,150.0081482,150.0081482,89700.8359375,89760.0703125,57.3613721407945,20.6297988291919,22.149702,0,0,0,40,4449,149.7508,89730.453125,,,,,,,,,,,,,0,,,,-0.00245,,,,,,150.0081482,,,,
,31597555.795,150.0035248,85751.84765625,-0.000224173561322179,2.9027131256837E-6,1,0.999253354069792,40.0298881530762,1.99604528076892,19.7599995881319,-0.00254016033795412,-0.000476411532486304,0.25,-2.91138987584702E-6,-0.000225270878265566,-3.26766812067598E-6,150.0035248,150.0035248,85749.109375,85754.5859375,57.0964000727753,20.6331448119776,22.909004,0,0,0,40,4449,149.74775,85751.84765625,,,,,,,,,,,,,0,,,,0.0049,,,,,,150.0035248,,,,
,31597651.86,149.9986267,80948.25,-0.000205919071976092,3.26907064930521E-6,1,0.999253354069792,40.0298881530762,1.9959990565534,19.7599995881319,-0.0023330345944314,-0.000438905688019346,0.25,-2.78758704464211E-6,-0.000206926649324584,-3.11648219720196E-6,149.9986267,149.9986267,80945.7734375,80950.7265625,57.423902422333,20.6326992298776,22.149702,0,0,0,40,4449,149.7519,80948.25,,,,,,,,,,,,,0,,,,-0.0049,,,,,,149.9986267,,,,
,31597748.93,149.9924774,76097.11328125,-0.000190697413073483,2.99939021636384E-6,1,0.999253354069792,40.0298881530762,1.99608674758513,19.7599995881319,-0.00215737701114567,-0.000425351216528753,0.25,-4.24232161654069E-6,-0.000191627768333265,-4.55605716836777E-6,149.9924774,149.9924774,76067.1015625,76127.125,57.3465211989291,20.6313438062561,22.909004,0,0,0,40,4449,149.7576,76097.11328125,,,,,,,,,,,,,0,,,,-0.00245,,,,,,149.9924774,,,,
,31597845.42,149.99385835,71273.5625,-0.000171142233905698,2.99094271576487E-6,1,0.999253354069792,40.0298881530762,1.99599436504709,19.7599995881319,-0.00194009525934441,-0.000358543399138846,0.25,-1.76595739947075E-6,-0.000171980118891461,-2.03836847210181E-6,149.9936066,149.9941101,71243.6171875,71303.5078125,57.4051433378714,20.6312635849778,22.149702,0,0,0,40,4449,149.76505,71273.5625,,,,,,,,,,,,,0,,,,0,,,,,,149.99385835,,,,
,31597941.815,149.9917526,66453,-0.000153032304809123,2.82661031020806E-6,1,0.999253354069792,40.0298881530762,1.99615364662564,19.7599995881319,-0.00172967843539606,-0.000350772165678906,0.25,-4.2325266059378E-6,-0.000153777258752344,-4.48992214176512E-6,149.9915771,149.9919281,66420.6484375,66485.3515625,57.4403166212368,20.6297433790144,22.529354,0,0,0,40,4449,149.7714,66453,,,,,,,,,,,,,0,,,,-0.00245,,,,,,149.9917526,,,,
,31598037.55,149.9923401,61667.041015625,-0.000134047602574011,2.72543308916428E-6,1,0.999253354069792,40.0298881530762,1.99615669976901,19.7599995881319,-0.00151787333023232,-0.000291335397806289,0.25,-2.30495191798907E-6,-0.000134702151262891,-2.52419823496968E-6,149.9923401,149.9923401,61642.07421875,61692.0078125,57.3433946848522,20.6290632572099,22.149702,0,0,0,40,4449,149.77875,61667.041015625,,,,,,,,,,,,,0,,,,-0.00245,,,,,,149.9923401,,,,
,31598135.575,149.9915314,56766.73828125,-0.000118505911541728,2.58971170688973E-6,1,0.999253354069792,40.0298881530762,1.9959572744171,19.7599995881319,-0.00133917213089142,-0.000272386312472816,0.25,-3.34508199618167E-6,-0.000119082400586648,-3.54592241786767E-6,149.9915314,149.9915314,56734.3125,56799.1640625,57.2777378892368,20.6314560291336,22.529354,0,0,0,40,4449,149.78855,56766.73828125,,,,,,,,,,,,,0,,,,0,,,,,,149.9915314,,,,
,31598232.45,149.98812865,51929.25390625,-0.000100365855991923,2.15865945997722E-6,1,0.999253354069792,40.0298881530762,1.99604587602652,19.7599995881319,-0.0011373799280767,-0.000212603876935985,0.25,-1.23904955425308E-6,-0.00010085647796462,-1.40181635004219E-6,149.9879303,149.988327,51896.98828125,51961.51953125,57.2988418592561,20.6345205022506,22.529354,0,0,0,40,4449,149.79815,51929.25390625,,,,,,,,,,,,,0,,,,0,,,,,,149.98812865,,,,
,31598328.165,149.9876709,47144.09765625,-8.28747830309525E-5,2.38482245113176E-6,1,0.999253354069792,40.0298881530762,1.99639880900253,19.7599995881319,-0.000938282095807274,-0.000181556089892424,0.25,-1.54865401966803E-6,-8.32789898403272E-5,-1.68603221352776E-6,149.9873962,149.9879456,47114.07421875,47174.12109375,57.2441278629099,20.6295365173098,22.529354,0,0,0,40,4449,149.80715,47144.09765625,,,,,,,,,,,,,0,,,,0,,,,,,149.9876709,,,,
,31598424.605,149.9878082,42323.68359375,-6.71916313531244E-5,2.00504180202853E-6,1,0.999253354069792,40.0298881530762,1.99626368806453,19.7599995881319,-0.000761337814610542,-0.000143368973188999,0.25,-9.18949321734161E-7,-6.7519800623361E-5,-1.02899397705319E-6,149.9878082,149.9878082,42296.046875,42351.3203125,57.2456911199484,20.6290917807164,22.909004,0,0,0,40,4449,149.82135,42323.68359375,,,,,,,,,,,,,0,,,,0,,,,,,149.9878082,,,,
,31598520.455,149.9905548,37531.10546875,-5.1648819656954E-5,2.04466672795338E-6,1,0.999253354069792,40.0298881530762,1.99619164750848,19.7599995881319,-0.000586159929152628,-0.00010471205093562,0.25,-2.22859398984442E-7,-5.19017782339029E-5,-3.05319783661165E-7,149.9905548,149.9905548,37528.609375,37533.6015625,57.004167907506,20.6311644436715,22.149702,0,0,0,40,4449,149.8278,37531.10546875,,,,,,,,,,,,,0,,,,-0.0049,,,,,,149.9905548,,,,
,31598614.815,149.993103,32816.455078125,-3.51335475079703E-5,2.05746182978925E-6,1,0.999253354069792,40.0298881530762,1.99599338256622,19.7599995881319,-0.000399697926167109,-6.5440192892765E-5,0.25,3.5772124743702E-7,-3.53063864563702E-5,3.03965660033298E-7,149.993103,149.993103,32786.01953125,32846.890625,57.7295191733523,20.6339854831291,22.909004,0,0,0,40,4449,149.8329,32816.455078125,,,,,,,,,,,,,0,,,,0.00245,,,,,,149.993103,,,,
,31598711.15,149.9934235,28001.5771484375,-1.8863877553029E-5,1.3919425038776E-6,1,0.999253354069792,40.0298881530762,1.99616364024818,19.7599995881319,-0.000213331905238788,-4.2549179791347E-5,0.25,-4.60314466182546E-7,-1.89556266123698E-5,-4.92460226400995E-7,149.9933167,149.9935303,27969.095703125,28034.05859375,57.2370932062368,20.6301362766025,22.529354,0,0,0,40,4449,149.84135,28001.5771484375,,,,,,,,,,,,,0,,,,0,,,,,,149.9934235,,,,
,31598807.345,149.9922943,23193.771484375,-3.54886291928225E-6,1.5351517438797E-6,1,0.999253354069792,40.0298881530762,1.99560236081218,19.7599995881319,-3.75758009911008E-5,-2.26263721115636E-5,0.25,-1.37453959510942E-6,-3.56407358207985E-6,-1.38691560324448E-6,149.9919281,149.9926605,23166.3984375,23221.14453125,57.6935642614676,20.6366201984519,22.529354,0,0,0,40,4449,149.84575,23193.771484375,,,,,,,,,,,,,0,,,,0,,,,,,149.9922943,,,,
,31598902.26,149.993927,18451.5703125,1.15712073146315E-5,1.31513314818968E-6,1,0.999253354069792,40.0298881530762,1.99548090876393,19.7599995881319,0.000131957293146674,1.95399742451962E-5,0.25,-2.9477106148234E-7,1.1628381720431E-5,-2.77781946647669E-7,149.9937744,149.9940796,18418.658203125,18484.482421875,57.0620084179291,20.6393544734418,22.909004,0,0,0,40,4449,149.85215,18451.5703125,,,,,,,,,,,,,0,,,,0,,,,,,149.993927,,,,
,31598999.095,149.9944153,13611.75390625,2.67608311421005E-5,1.07119365418726E-6,1,0.999253354069792,40.0298881530762,1.9953567507018,19.7599995881319,0.000304061690180489,5.14942508830297E-5,0.25,-1.2631108764587E-7,2.68921503014083E-5,-8.41895041635522E-8,149.9944153,149.9944153,13581.875,13641.6328125,57.3129111726022,20.6390275290507,22.909004,0,0,0,40,4449,149.85815,13611.75390625,,,,,,,,,,,,,0,,,,0,,,,,,149.9944153,,,,
,31599093.345,149.99201965,8901.4228515625,3.89506196198972E-5,5.92997128149373E-7,1,0.999253354069792,40.0298881530762,1.99568948816129,19.7599995881319,0.000443283714654157,7.12358865618095E-5,0.25,-5.12165653962016E-7,3.91422528723182E-5,-4.52321327155189E-7,149.9918213,149.992218,8868.6865234375,8934.1591796875,57.4895592179484,20.6399990966061,22.149702,0,0,0,40,4449,149.86355,8901.4228515625,,,,,,,,,,,,,0,,,,-0.0049,,,,,,149.99201965,,,,
,31599189.635,149.9947968,4088.26940917969,4.78500316144644E-5,3.83055774873104E-7,1,0.999253354069792,40.0298881530762,1.99592484387779,19.7599995881319,0.000543371448337504,9.47211612215432E-5,0.25,4.64637332442172E-9,4.80843948883986E-5,8.14309564039515E-8,149.9947968,149.9947968,4055.64379882812,4120.89501953125,57.4754899046022,20.6425481391758,22.909004,0,0,0,40,4449,149.8691,4088.26940917969,,,,,,,,,,,,,0,,,,-0.00245,,,,,,149.9947968,,,,
,31599271.99,149.9936066,-0.312087342143059,4.6294517145047E-5,3.67581740591107E-7,1,0.999253354069792,40.0298881530762,1.99603389061648,19.7599995881319,0.000526335317558236,8.81989911923812E-5,0.25,-2.99193318526767E-7,4.65217288441051E-5,-2.26291700517928E-7,149.9936066,149.9936066,-0.3349229991436,-0.289251685142517,57.8022106256407,20.6405681412097,22.529354,0,0,0,40,4417,149.8746,-0.312087342143059,,,,,,,,,,,,,0,,,,-0.00245,,,,,,149.9936066,,,,