File: data/doubleLayers/dl_0-25/ppms/data/DD205_10_ZFCW_100OE.DAT
[Header]
; VSM Data File (default extension .dat)
; Copyright (c) 2003-2013, Quantum Design, Inc. All rights reserved.
TITLE,
FILEOPENTIME,31480003.06,12/31/2018,4:28 pm
BYAPP,VSM,2.0,2.0
INFO,PPMS VSM Option Release 1.4.10 Build 1,APPNAME
INFO,Quantum Design Linear Motor Servo Controller,MOTOR_MODULE_NAME
INFO,3101-100 M1,MOTOR_HW_VERSION
INFO,MMC1014,MOTOR_SERIAL_NUMBER
INFO,SRV No X-over 01.03.11,MOTOR_SOFTWARE_VERSION
INFO,Quantum Design VSM Detection Module,VSM_MODULE_NAME
INFO,3101-150 F0,VSM_HW_VERSION
INFO,VSM707,VSM_SERIAL_NUMBER
INFO,VSM No X-over 01.02.05 May 20 2008 13:51:47,VSM_SOFTWARE_VERSION
INFO,704,PREAMP_SERIAL_NUMBER
INFO,822,COIL_SERIAL_NUMBER
INFO,0,MOMENT_UNITS
INFO,CoFe2O4,SAMPLE_MATERIAL
INFO,Double Layer thin concentration,SAMPLE_COMMENT
INFO,27.44,SAMPLE_MASS
INFO,,SAMPLE_VOLUME
INFO,,SAMPLE_MOLECULAR_WEIGHT
INFO,,SAMPLE_SIZE
INFO,,SAMPLE_SHAPE
DATATYPE,COMMENT,1
DATATYPE,TIME,2
STARTUPAXIS,X,2
STARTUPAXIS,Y1,5
[Data]
Comment,Time Stamp (sec),Temperature (K),Magnetic Field (Oe),Moment (emu),M. Std. Err. (emu),Transport Action,Averaging Time (sec),Frequency (Hz),Peak Amplitude (mm),Center Position (mm),Coil Signal' (mV),Coil Signal" (mV),Range (mV),M. Quad. Signal (emu),M. Raw' (emu),M. Raw" (emu),Min. Temperature (K),Max. Temperature (K),Min. Field (Oe),Max. Field (Oe),Mass (grams),Motor Lag (deg),Pressure (Torr),VSM Status (code),Motor Status (code),Measure Status (code),Measure Count,PPMS Status (code),System Temp. (K),System Field (Oe),Sample Position (deg),Bridge 1 Resistance (ohms),Bridge 1 Excitation (에),Bridge 2 Resistance (ohms),Bridge 2 Excitation (에),Bridge 3 Resistance (ohms),Bridge 3 Excitation (에),Bridge 4 Resistance (ohms),Bridge 4 Excitation (에),Signal 1 Vin (V),Signal 2 Vin (V),Digital Inputs (code),Drive 1 Iout (mA),Drive 1 Ipower (W),Drive 2 Iout (mA),Drive 2 Ipower (W),Pressure (),Map 20 (),Map 21 (),Map 22 (),Map 23 (),Map 24 (),Map 25 (),Map 26 (),Map 27 (),Map 28 (),Map 29 ()
,31492488.83,9.9997511,99.6243667602539,,,2,,,,20.2200001040101,,,,,,,9.9997511,9.9997511,99.6243667602539,99.6243667602539,,,11.899124,,,,-99999999,4373,9.9957,99.6243667602539,,,,,,,,,,,,,,,,,,,,,,,9.9997511,,,,
,31492690.115,12.5034971,99.6243667602539,-9.21130701951885E-8,2.89229120754603E-7,1,0.999253354069792,40.0298881530762,1.99810284502862,20.1699994504452,-7.95399725909589E-7,-1.53564722868035E-6,0.25,-1.20254183144138E-7,-9.10037527453075E-8,-1.20007351110279E-7,12.5034971,12.5034971,99.6243667602539,99.6243667602539,55.9317735791213,20.5756498389854,12.658426,0,0,0,40,4370,12.61305,99.6243667602539,,,,,,,,,,,,,0,,,,0,,,,,,12.5034971,,,,
,31492831.335,16.0468826,99.6243667602539,1.7188132966157E-7,2.67557490381463E-7,1,0.999253354069792,40.0298881530762,1.99806602593955,20.1699994504452,2.26947607380253E-6,-1.55699850701086E-6,0.25,-1.69036417599093E-7,1.71707187461059E-7,-1.67234485465029E-7,16.0468826,16.0468826,99.6243667602539,99.6243667602539,56.5617661656214,20.5813571339896,13.038077,0,0,0,40,4370,16.1698,99.6243667602539,,,,,,,,,,,,,0,,,,0,,,,,,16.0468826,,,,
,31492972.025,19.5352135,99.6243667602539,-1.40180413946544E-7,2.48377782221588E-7,1,0.999253354069792,40.0298881530762,1.99800149497364,20.1699994504452,-1.19484673142326E-6,-2.42420247423417E-6,0.25,-1.90773740608114E-7,-1.38450345342377E-7,-1.90355416157791E-7,19.5352135,19.5352135,99.6243667602539,99.6243667602539,56.3671406643329,20.5798811586666,13.417728,0,0,0,40,4370,19.6969,99.6243667602539,,,,,,,,,,,,,0,,,,0,,,,,,19.5352135,,,,
,31493111.915,23.00429915,99.6243667602539,2.07461382029882E-9,2.57726405497835E-7,1,0.999253354069792,40.0298881530762,1.99767355713791,20.1699994504452,2.87038978074111E-7,-1.47978432261042E-6,0.25,-1.32029444424806E-7,2.71780629245542E-9,-1.31271461090489E-7,22.9781265,23.0304718,99.6243667602539,99.6243667602539,56.5727089648906,20.5807722531454,14.556682,0,0,0,40,4370,23.2172,99.6243667602539,,,,,,,,,,,,,0,,,,0,,,,,,23.00429915,,,,
,31493254.345,26.51713565,99.6243667602539,-2.25220329966318E-7,3.29860202853646E-7,1,0.999253354069792,40.0298881530762,1.99772306353793,20.1699994504452,-2.01052153259721E-6,-3.37977274710511E-6,0.25,-2.60574879236698E-7,-2.22636628441045E-7,-2.60318950772092E-7,26.4937096,26.5405617,99.6243667602539,99.6243667602539,56.9549253107945,20.5831918213659,14.936333,0,0,0,40,4370,26.81095,99.6243667602539,,,,,,,,,,,,,0,,,,0.00245,,,,,,26.51713565,,,,
,31493395.9,30.0595589,99.6243667602539,-5.90125582009856E-9,2.72115961253842E-7,1,0.999253354069792,40.0298881530762,1.99768259545453,20.1699994504452,-1.45100897868873E-7,4.29825357194943E-7,0.25,3.92786230445344E-8,-6.08775581077381E-9,3.90439518191625E-8,30.0595589,30.0595589,99.6243667602539,99.6243667602539,56.7821854080445,20.5836605705535,14.556682,0,0,0,40,4370,30.3807,99.6243667602539,,,,,,,,,,,,,0,,,,0,,,,,,30.0595589,,,,
,31493536.12,33.5112305,99.6243667602539,-1.67046887766573E-7,2.89005928981716E-7,1,0.999253354069792,40.0298881530762,1.99747920102763,20.1699994504452,-1.30878010591054E-6,-3.52572108038966E-6,0.25,-2.83609977512855E-7,-1.64584165360126E-7,-2.83274258400679E-7,33.5112305,33.5112305,99.6243667602539,99.6243667602539,56.9009929429675,20.5830354513502,14.936333,0,0,0,40,4370,33.899,99.6243667602539,,,,,,,,,,,,,0,,,,0,,,,,,33.5112305,,,,
,31493678.54,37.02173995,99.6243667602539,2.24493490520838E-7,2.49180762421092E-7,1,0.999253354069792,40.0298881530762,1.99736127301244,20.1699994504452,3.34311654173658E-6,-4.10542570430527E-6,0.25,-4.05040483334186E-7,2.26179808093989E-7,-4.01978017380836E-7,36.9951973,37.0482826,99.6243667602539,99.6243667602539,56.8157954343714,20.5868664904573,15.315984,0,0,0,40,4370,37.5054,99.6243667602539,,,,,,,,,,,,,0,,,,-0.00245,,,,,,37.02173995,,,,
,31493819.955,40.5226364,99.6243667602539,9.30849695570471E-8,2.97070948177723E-7,1,0.999253354069792,40.0298881530762,1.99748020201203,20.1699994504452,1.42572508600102E-6,-1.91216918893909E-6,0.25,-1.86501195043634E-7,9.40621972587571E-8,-1.85270747054975E-7,40.5226364,40.5226364,99.6243667602539,99.6243667602539,56.9189703989099,20.591960940735,16.075285,0,0,0,40,4370,41.074,99.6243667602539,,,,,,,,,,,,,0,,,,0.00245,,,,,,40.5226364,,,,
,31493941.89,43.532753,99.6243667602539,-2.52969577125428E-7,2.58897936939811E-7,1,0.999253354069792,40.0298881530762,1.99748582809463,20.1500002294779,-2.62656432971664E-6,-1.76244864742046E-6,0.25,-1.10835923825086E-7,-2.51585357933605E-7,-1.12384140982199E-7,43.532753,43.532753,99.6243667602539,99.6243667602539,57.1792526958137,20.5927404482002,16.075285,0,0,0,40,4370,44.1609,99.6243667602539,,,,,,,,,,,,,0,,,,-0.0049,,,,,,43.532753,,,,
,31494082.39,47.0010262,99.6243667602539,-2.96440072737831E-8,2.82693890439331E-7,1,0.999253354069792,40.0298881530762,1.99730051788652,20.1500002294779,5.65731462888969E-7,-5.05590673070849E-6,0.25,-4.42781403130939E-7,-2.63393610582205E-8,-4.42440368977286E-7,47.0010262,47.0010262,99.6243667602539,99.6243667602539,57.0369963053137,20.5968219685534,16.454937,0,0,0,40,4370,47.7138,99.6243667602539,,,,,,,,,,,,,0,,,,0,,,,,,47.0010262,,,,
,31494227.015,50.5218887,99.6243667602539,7.19966210475961E-8,3.27869962977975E-7,1,0.999253354069792,40.0298881530762,1.99720038607115,20.1500002294779,1.92291784942199E-6,-6.01012946210814E-6,0.25,-5.45090956571292E-7,7.60433342756859E-8,-5.44496217782322E-7,50.5218887,50.5218887,99.6243667602539,99.6243667602539,56.8666012881214,20.5989190103717,16.834587,0,0,0,40,4370,51.3899,99.6243667602539,,,,,,,,,,,,,0,,,,0.0049,,,,,,50.5218887,,,,
,31494348.865,53.5141754,99.6243667602539,-1.56619644613616E-7,2.8673741466738E-7,1,0.999253354069792,40.0298881530762,1.99711233460797,20.1299991458654,-1.18286850563633E-6,-3.58162958629261E-6,0.25,-2.88599213209007E-7,-1.54630731651792E-7,-2.89989873245518E-7,53.5141754,53.5141754,99.6243667602539,99.6243667602539,57.2339666921599,20.5953763802086,16.834587,0,0,0,40,4374,54.48065,99.6243667602539,,,,,,,,,,,,,0,,,,0.0049,,,,,,53.5141754,,,,
,31494491.485,57.0366592,99.6243667602539,-1.73466438314765E-7,2.7076308132007E-7,1,0.999253354069792,40.0298881530762,1.99703509675871,20.1299991458654,-1.30365882034533E-6,-4.01904030638624E-6,0.25,-3.23940371593521E-7,-1.71489322656448E-7,-3.25767961921063E-7,57.0366592,57.0366592,99.6243667602539,99.6243667602539,57.0307432771599,20.5988324913944,17.214239,0,0,0,40,4374,58.1037,99.6243667602539,,,,,,,,,,,,,0,,,,0.0049,,,,,,57.0366592,,,,
,31494632.465,60.5302048,99.6243667602539,1.49975143677391E-7,3.26840279655242E-7,1,0.999253354069792,40.0298881530762,1.99713652031236,20.1299991458654,2.1558015337519E-6,-2.24059599086908E-6,0.25,-2.2471952201801E-7,1.51894546067442E-7,-2.24317076646515E-7,60.5302048,60.5302048,99.6243667602539,99.6243667602539,56.9705578811791,20.5970574792681,17.214239,0,0,0,40,4374,61.6658,99.6243667602539,,,,,,,,,,,,,0,,,,-0.0049,,,,,,60.5302048,,,,
,31494755.4,63.5406418,99.6243667602539,6.99521423820447E-8,3.23509386928064E-7,1,0.999253354069792,40.0298881530762,1.99719152425678,20.1099999248981,1.36935472843118E-6,-3.07570799992232E-6,0.25,-2.83856384356543E-7,7.19955175521277E-8,-2.84358132589469E-7,63.5406418,63.5406418,99.6243667602539,99.6243667602539,57.0612267894099,20.5991077272007,17.214239,0,0,0,40,4374,64.7816,99.6243667602539,,,,,,,,,,,,,0,,,,0.00245,,,,,,63.5406418,,,,
,31494896.585,67.0040436,99.6243667602539,-3.36431763267402E-8,2.79569283079686E-7,1,0.999253354069792,40.0298881530762,1.99720523356761,20.1099999248981,4.67197421618255E-7,-4.81885600634529E-6,0.25,-4.18800696782682E-7,-3.12879586633593E-8,-4.20648417943913E-7,67.0040436,67.0040436,99.6243667602539,99.6243667602539,57.4379717356792,20.599677810698,17.973541,0,0,0,40,4374,68.3582,99.6243667602539,,,,,,,,,,,,,0,,,,0.0049,,,,,,67.0040436,,,,
,31495037.71,70.5032883,99.6243667602539,-1.00186921632437E-7,2.82665056428269E-7,1,0.999253354069792,40.0298881530762,1.99716836184366,20.1099999248981,-4.92167633551552E-7,-3.821060298832E-6,0.25,-3.18816995541826E-7,-9.88725960638433E-8,-3.20773037178295E-7,70.5032883,70.5032883,99.6243667602539,99.6243667602539,57.0495023616214,20.6021414986292,17.973541,0,0,0,40,4374,71.9363,99.6243667602539,,,,,,,,,,,,,0,,,,-0.0049,,,,,,70.5032883,,,,
,31495181.68,74.0423126,99.6243667602539,2.43034331921967E-8,3.1927154674547E-7,1,0.999253354069792,40.0298881530762,1.97150529675578,20.0900007039309,-7.8330047874979E-8,2.02203451164027E-6,0.25,1.75975521578604E-7,2.35240287807135E-8,1.76939310188203E-7,74.0423126,74.0423126,99.6243667602539,99.6243667602539,57.1425161554099,20.5991420540508,18.353191,0,0,0,40,4374,75.5684,99.6243667602539,,,,,,,,,,,,,0,,,,-0.0049,,,,,,74.0423126,,,,
,31495324.015,77.5765381,99.6243667602539,6.31964915235054E-8,3.03342637672643E-7,1,0.999253354069792,40.0298881530762,1.9712928943628,20.0900007039309,1.62289898188983E-6,-5.02630172755273E-6,0.25,-4.592781594927E-7,6.5676128803169E-8,-4.61301456632207E-7,77.5765381,77.5765381,99.6243667602539,99.6243667602539,56.9682129956214,20.6040572298279,17.593889,0,0,0,40,4374,79.1742,99.6243667602539,,,,,,,,,,,,,0,,,,0,,,,,,77.5765381,,,,
,31495464.09,81.0271988,99.6243667602539,2.59113885604057E-7,2.83979947805452E-7,1,0.999253354069792,40.0298881530762,1.97117663529965,20.0900007039309,3.19326390054433E-6,-1.1006010626127E-6,0.25,-1.43966296621965E-7,2.61104111104693E-7,-1.43594655510998E-7,81.0271988,81.0271988,99.6243667602539,99.6243667602539,57.0424677049483,20.6068547163539,18.732843,0,0,0,40,4374,82.74085,99.6243667602539,,,,,,,,,,,,,0,,,,0,,,,,,81.0271988,,,,
,31495605.24,84.5116882,99.6243667602539,1.4457233178761E-7,2.9842370912481E-7,1,0.999253354069792,40.0298881530762,1.99685385634155,20.0599990785122,2.33366806558292E-6,-3.61999482220411E-6,0.25,-3.44154694464914E-7,1.46746921532375E-7,-3.45432314536334E-7,84.5116882,84.5116882,99.6243667602539,99.6243667602539,57.034651419756,20.6009697679078,18.353191,0,0,0,40,4374,86.28555,99.6243667602539,,,,,,,,,,,,,0,,,,0.00245,,,,,,84.5116882,,,,
,31495746.835,88.053833,99.6243667602539,4.35791148100995E-8,2.34440552434907E-7,1,0.999253354069792,40.0298881530762,1.99672268555311,20.0599990785122,1.35106219806158E-6,-4.76359463334467E-6,0.25,-4.26905953960831E-7,4.54261073766945E-8,-4.29098817489162E-7,88.053833,88.053833,99.6243667602539,99.6243667602539,56.997133250833,20.601067204752,18.732843,0,0,0,40,4374,89.8588,99.6243667602539,,,,,,,,,,,,,0,,,,0,,,,,,88.053833,,,,
,31495885.44,91.5058975,99.6243667602539,1.04503106152423E-7,3.1891778183935E-7,1,0.999253354069792,40.0298881530762,1.99673262223503,20.0599990785122,1.87306441235798E-6,-3.68135285846456E-6,0.25,-3.42348120284398E-7,1.06291729548206E-7,-3.4389529300638E-7,91.5058975,91.5058975,99.6243667602539,99.6243667602539,56.709493955756,20.6043531420296,18.732843,0,0,0,40,4374,93.3181,99.6243667602539,,,,,,,,,,,,,0,,,,-0.0049,,,,,,91.5058975,,,,
,31496029.89,95.0654755,99.6243667602539,1.77866553291183E-7,2.86761793651143E-7,1,0.999253354069792,40.0298881530762,1.99706784103987,20.0200006365776,2.16192257061862E-6,-4.40371597870158E-7,0.25,-7.00348725923296E-8,1.79100213405007E-7,-6.98455238704566E-8,95.0654755,95.0654755,99.6243667602539,99.6243667602539,57.2198973788137,20.6000779037141,18.732843,0,0,0,40,4374,96.94735,99.6243667602539,,,,,,,,,,,,,0,,,,-0.0049,,,,,,95.0654755,,,,
,31496167.75,98.50680925,99.6243667602539,3.44903044460768E-7,2.91796798398404E-7,1,0.999253354069792,40.0298881530762,1.99693829021467,20.0200006365776,3.79840846132052E-6,1.3842005222748E-6,0.25,6.11578523027938E-8,3.46668388212194E-7,6.25695929885218E-8,98.4813538,98.5322647,99.6243667602539,99.6243667602539,57.1761261817368,20.604206453591,19.492144,0,0,0,40,4374,100.4,99.6243667602539,,,,,,,,,,,,,0,,,,-0.00245,,,,,,98.50680925,,,,
,31496308.64,102.0067139,99.6243667602539,-8.21553007258437E-8,2.48709472351628E-7,1,0.999253354069792,40.0298881530762,1.99683363879901,20.0200006365776,-3.66511219690043E-8,-5.27474099396847E-6,0.25,-4.49613993814068E-7,-8.13153585947581E-8,-4.52403694880307E-7,102.0067139,102.0067139,99.6243667602539,99.6243667602539,57.2144259791791,20.6039175297454,19.492144,0,0,0,40,4374,103.9579,99.6243667602539,,,,,,,,,,,,,0,,,,-0.00245,,,,,,102.0067139,,,,
,31496430.84,105.0363998,99.6243667602539,-3.77839318874782E-8,2.64517496762598E-7,1,0.999253354069792,40.0298881530762,1.99689073144468,19.9900008738041,5.04858800600716E-7,-5.40227025937669E-6,0.25,-4.68606166048383E-7,-3.67043014748194E-8,-4.71366697604013E-7,105.0363998,105.0363998,99.6243667602539,99.6243667602539,56.7876568076791,20.6036579487744,19.112494,0,0,0,40,4374,107.0333,99.6243667602539,,,,,,,,,,,,,0,,,,-0.00245,,,,,,105.0363998,,,,
,31496570.225,108.522171,99.6243667602539,1.19672429580323E-8,2.88100816040499E-7,1,0.999253354069792,40.0298881530762,1.99675713890828,19.9900008738041,1.05260078482026E-6,-5.20616413087577E-6,0.25,-4.60105617219793E-7,1.32364468723206E-8,-4.62673830688769E-7,108.522171,108.522171,99.6243667602539,99.6243667602539,57.4723633905253,20.6062922731563,19.112494,0,0,0,40,4374,110.5416,99.6243667602539,,,,,,,,,,,,,0,,,,0,,,,,,108.522171,,,,
,31496712.415,112.0229645,99.6243667602539,2.84585023494543E-7,3.02600998098832E-7,1,0.999253354069792,40.0298881530762,1.99677757708796,19.9900008738041,3.52335788628425E-6,-1.08091593029088E-6,0.25,-1.449262534632E-7,2.86543203634866E-7,-1.45036907530508E-7,112.0229645,112.0229645,99.6243667602539,99.6243667602539,57.4074882234292,20.6082406714067,19.871798,0,0,0,40,4374,114.11595,99.6243667602539,,,,,,,,,,,,,0,,,,-0.0049,,,,,,112.0229645,,,,
,31496853.985,115.5477753,99.6243667602539,3.2884042098655E-7,3.1909736127919E-7,1,0.999253354069792,40.0298881530762,1.99675770608351,19.9500005692244,4.04213153292738E-6,-1.08493485129252E-6,0.25,-1.52989929838751E-7,3.31035550364409E-7,-1.53071559580447E-7,115.5477753,115.5477753,99.6243667602539,99.6243667602539,57.146424298006,20.6052080954479,19.492144,0,0,0,40,4374,117.6821,99.6243667602539,,,,,,,,,,,,,0,,,,0,,,,,,115.5477753,,,,
,31496992.95,119.0003204,99.6243667602539,-3.23361100426907E-8,3.32907475255709E-7,1,0.999253354069792,40.0298881530762,1.99661820791798,19.9500005692244,-6.42023051053184E-8,-1.79881306764853E-6,0.25,-1.52612716039567E-7,-3.21736164198729E-8,-1.53530099700438E-7,119.0003204,119.0003204,99.6243667602539,99.6243667602539,56.8025077495445,20.6071974337147,19.871798,0,0,0,40,4374,121.1677,99.6243667602539,,,,,,,,,,,,,0,,,,-0.0049,,,,,,119.0003204,,,,
,31497134.07,122.5047989,99.6243667602539,5.18337149516142E-10,2.92870888251388E-7,1,0.999253354069792,40.0298881530762,1.99657432095195,19.9500005692244,9.82430826514588E-7,-5.5867417302037E-6,0.25,-4.91663597014487E-7,1.57069642709461E-9,-4.94358863117188E-7,122.5047989,122.5047989,99.6243667602539,99.6243667602539,57.0315249056791,20.6089702951815,19.871798,0,0,0,40,4374,124.71925,99.6243667602539,,,,,,,,,,,,,0,,,,-0.00245,,,,,,122.5047989,,,,
,31497275.285,126.02491,99.6243667602539,8.31724185848E-8,2.46785203729293E-7,1,0.999253354069792,40.0298881530762,1.99686975634337,19.8999997228384,1.2318978520019E-6,-1.47541353762762E-6,0.25,-1.44335195122183E-7,8.39181175215464E-8,-1.44948502197771E-7,125.9994202,126.0503998,99.6243667602539,99.6243667602539,56.9908802226791,20.6012696601592,19.492144,0,0,0,40,4374,128.26095,99.6243667602539,,,,,,,,,,,,,0,,,,0.00245,,,,,,126.02491,,,,
,31497416.215,129.5402527,99.6243667602539,2.0939397575654E-7,3.16105324414855E-7,1,0.999253354069792,40.0298881530762,1.99662078014182,19.8999997228384,2.25327048019607E-6,1.13906877881228E-6,0.25,6.36770388396444E-8,2.10392033755426E-7,6.44274898776279E-8,129.5402527,129.5402527,99.6243667602539,99.6243667602539,56.8306463762368,20.6103968303586,20.251448,0,0,0,40,4374,131.807,99.6243667602539,,,,,,,,,,,,,0,,,,-0.0049,,,,,,129.5402527,,,,
,31497555.47,133.00495145,99.6243667602539,6.64566106781201E-8,2.66148194580363E-7,1,0.999253354069792,40.0298881530762,1.99654018022789,19.8999997228384,1.18551365046121E-6,-2.33446673547827E-6,0.25,-2.17037852549048E-7,6.72153530745681E-8,-2.18061893299604E-7,132.9760742,133.0338287,99.6243667602539,99.6243667602539,57.0080760501022,20.6094264543323,19.871798,0,0,0,40,4374,135.29705,99.6243667602539,,,,,,,,,,,,,0,,,,-0.00245,,,,,,133.00495145,,,,
,31497696.19,136.508461,99.6243667602539,3.51476503360472E-7,2.96323595343793E-7,1,0.999253354069792,40.0298881530762,1.99677854579689,19.8599994182587,3.72010848928079E-6,2.26754737601604E-6,0.25,1.38235649110105E-7,3.53061938017024E-7,1.39590554404541E-7,136.4799652,136.5369568,99.6243667602539,99.6243667602539,56.997133250833,20.6059626454585,19.871798,0,0,0,40,4374,138.8331,99.6243667602539,,,,,,,,,,,,,0,,,,0.00245,,,,,,136.508461,,,,
,31497837.64,140.0050659,99.6243667602539,5.94296354202889E-7,2.77814561564761E-7,1,0.999253354069792,40.0298881530762,1.99685582048792,19.8599994182587,7.38900208980937E-6,-2.46872047522614E-6,0.25,-3.20868293701354E-7,5.97909269776483E-7,-3.21487891928416E-7,140.0050659,140.0050659,99.6243667602539,99.6243667602539,57.2738297466407,20.6073014393704,20.251448,0,0,0,40,4374,142.3757,99.6243667602539,,,,,,,,,,,,,0,,,,0,,,,,,140.0050659,,,,
,31497978.265,143.5223083,99.6243667602539,3.21533064100319E-7,3.50049480337446E-7,1,0.999253354069792,40.0298881530762,1.99691655953469,19.8599994182587,4.07576865994016E-6,-1.7855088652943E-6,0.25,-2.13173249594557E-7,3.23517131861497E-7,-2.13714945500259E-7,143.5223083,143.5223083,99.6243667602539,99.6243667602539,56.9369478548522,20.6069896292902,20.631098,0,0,0,40,4374,145.9041,99.6243667602539,,,,,,,,,,,,,0,,,,0,,,,,,143.5223083,,,,
,31498099.105,146.5319672,99.6243667602539,1.75894689035577E-7,2.78430535213979E-7,1,0.999253354069792,40.0298881530762,1.99692138449155,19.8199991136789,3.07178556166843E-6,-5.81120466209231E-6,0.25,-5.42092022707081E-7,1.77651466870338E-7,-5.44512413643487E-7,146.5319672,146.5319672,99.6243667602539,99.6243667602539,57.0049495360253,20.6036452082232,20.631098,0,0,0,40,4374,148.9419,99.6243667602539,,,,,,,,,,,,,0,,,,0,,,,,,146.5319672,,,,
,31498239.36,150.0470123,99.6243667602539,4.19084344898726E-7,3.42308530686751E-7,1,0.999253354069792,40.0298881530762,1.9968309335385,19.8199991136789,5.5505545534875E-6,-3.70239322557282E-6,0.25,-3.98884033495912E-7,4.21764785062925E-7,-4.00183877898706E-7,150.0470123,150.0470123,99.6243667602539,99.6243667602539,57.3293253715061,20.607209999735,20.631098,0,0,0,40,4374,152.46775,99.6243667602539,,,,,,,,,,,,,0,,,,0,,,,,,150.0470123,,,,
,31498378.975,153.5057526,99.6243667602539,5.89285283028393E-7,2.83883845456928E-7,1,0.999253354069792,40.0298881530762,1.99693068903275,19.8199991136789,7.34303121315242E-6,-2.55776260975302E-6,0.25,-3.27755502870816E-7,5.92621013721264E-7,-3.28440937459712E-7,153.5057526,153.5057526,99.6243667602539,99.6243667602539,57.4059249663907,20.6070765388275,20.631098,0,0,0,40,4374,155.96655,99.6243667602539,,,,,,,,,,,,,0,,,,0,,,,,,153.5057526,,,,
,31498499.335,156.5079803,99.6243667602539,2.82943042327761E-7,3.02683742397136E-7,1,0.999253354069792,40.0298881530762,1.99696386055247,19.7700001299381,3.18285679276152E-6,7.39809838117603E-7,0.25,1.5866717357941E-8,2.84260616189279E-7,1.63593456059667E-8,156.5079803,156.5079803,99.6243667602539,99.6243667602539,57.0354330482753,20.6026005760417,20.251448,0,0,0,40,4374,158.9836,99.6243667602539,,,,,,,,,,,,,0,,,,-0.0049,,,,,,156.5079803,,,,
,31498639.32,160.0012207,99.6243667602539,4.95558365399741E-7,3.30718273437154E-7,1,0.999253354069792,40.0298881530762,1.99677581059355,19.7700001299381,5.5474742794044E-6,1.44553498689704E-6,0.25,4.10211807779975E-8,4.97802306586147E-7,4.19207558512109E-8,160.0012207,160.0012207,99.6243667602539,99.6243667602539,56.8689461736791,20.6107685411691,20.631098,0,0,0,40,4374,162.488,99.6243667602539,,,,,,,,,,,,,0,,,,-0.00245,,,,,,160.0012207,,,,
,31498780.885,163.5589752,99.6243667602539,4.41976577016067E-7,3.06302692291958E-7,1,0.999253354069792,40.0298881530762,1.99690589332682,19.7700001299381,5.15244783884182E-6,1.11373589624907E-7,0.25,-6.70980309323968E-8,4.44080559346072E-7,-6.67897326278323E-8,163.5589752,163.5589752,99.6243667602539,99.6243667602539,56.9744660237753,20.6096352561408,21.01075,0,0,0,40,4374,166.037,99.6243667602539,,,,,,,,,,,,,0,,,,-0.0049,,,,,,163.5589752,,,,
,31498900.745,166.5370178,99.6243667602539,7.21669150233803E-7,3.48982026260712E-7,1,0.999253354069792,40.0298881530762,1.99686871402389,19.7199992835522,8.64292589285524E-6,-1.14474993407848E-6,0.25,-2.2634564773361E-7,7.25199384128062E-7,-2.26379244817033E-7,166.5370178,166.5370178,99.6243667602539,99.6243667602539,56.8267382336406,20.6082366878755,20.251448,0,0,0,40,4374,169.0337,99.6243667602539,,,,,,,,,,,,,0,,,,0,,,,,,166.5370178,,,,
,31499040.53,170.0467987,99.6243667602539,7.89354235886777E-7,3.12541347629244E-7,1,0.999253354069792,40.0298881530762,1.99705623682172,19.7199992835522,9.05744377140042E-6,1.02415205758739E-6,0.25,-4.71093326141129E-8,7.92863876526672E-7,-4.62753908705079E-8,170.0467987,170.0467987,99.6243667602539,99.6243667602539,56.9439825115252,20.6051503090279,20.251448,0,0,0,40,4374,172.5362,99.6243667602539,,,,,,,,,,,,,0,,,,-0.0049,,,,,,170.0467987,,,,
,31499179.68,173.5147705,99.6243667602539,6.51439865228096E-7,3.56295811742566E-7,1,0.999253354069792,40.0298881530762,1.99677932813886,19.7199992835522,6.71395314887461E-6,5.21120142455909E-6,0.25,3.45692863718587E-7,6.537767564643E-7,3.48003428739398E-7,173.5147705,173.5147705,99.6243667602539,99.6243667602539,57.1182856713137,20.612057176166,21.01075,0,0,0,40,4374,176.01745,99.6243667602539,,,,,,,,,,,,,0,,,,0.00245,,,,,,173.5147705,,,,
,31499319.36,177.0015106,99.6243667602539,5.87101742096909E-7,3.19099887148898E-7,1,0.999253354069792,40.0298881530762,1.99671901036491,19.6700002998114,6.78774003585994E-6,4.53671348334369E-7,0.25,-6.21105797722263E-8,5.89624860401869E-7,-6.16359182628556E-8,177.0015106,177.0015106,99.6243667602539,99.6243667602539,56.8462789466214,20.609495740659,21.01075,0,0,0,40,4374,179.4977,99.6243667602539,,,,,,,,,,,,,0,,,,0.0049,,,,,,177.0015106,,,,
,31499459.6,180.5161133,99.6243667602539,9.24004998219329E-7,3.19850066251821E-7,1,0.999253354069792,40.0298881530762,1.9964393558603,19.6700002998114,1.1235501677588E-5,-2.48047484584976E-6,0.25,-3.79160055195874E-7,9.2821878914662E-7,-3.79574714440095E-7,180.4915314,180.5406952,99.6243667602539,99.6243667602539,57.1049979864868,20.6132395435879,21.01075,0,0,0,40,4374,183.0194,99.6243667602539,,,,,,,,,,,,,0,,,,0,,,,,,180.5161133,,,,
,31499601.61,184.0518341,99.6243667602539,7.08240642046498E-7,3.18309631486797E-7,1,0.999253354069792,40.0298881530762,1.99620350980238,19.6700002998114,7.97205070463942E-6,1.76934512346844E-6,0.25,3.28343346938419E-8,7.1100193883829E-7,3.3805069457214E-8,184.0518341,184.0518341,99.6243667602539,99.6243667602539,57.0330881627176,20.6109384098332,21.01075,0,0,0,40,4374,186.57415,99.6243667602539,,,,,,,,,,,,,0,,,,0,,,,,,184.0518341,,,,
,31499740.665,187.5204468,99.6243667602539,9.66496955243646E-7,3.24149119627956E-7,1,0.999253354069792,40.0298881530762,1.99665803559173,19.6199994534254,1.07533033193462E-5,3.14532330606559E-6,0.25,1.09203867942672E-7,9.700889900913E-7,1.10744407264816E-7,187.5204468,187.5204468,99.6243667602539,99.6243667602539,56.800944492506,20.6069906202282,21.3904,0,0,0,40,4374,190.0608,99.6243667602539,,,,,,,,,,,,,0,,,,0.00245,,,,,,187.5204468,,,,
,31499882.005,191.0184937,99.6243667602539,7.67441880117177E-7,2.96516693325824E-7,1,0.999253354069792,40.0298881530762,1.9965942449109,19.6199994534254,8.9111949062809E-6,3.4597410849065E-7,0.25,-1.02844664335535E-7,7.70427724768082E-7,-1.0236047903951E-7,191.0184937,191.0184937,99.6243667602539,99.6243667602539,56.8548768603329,20.612735421673,21.01075,0,0,0,40,4374,193.61725,99.6243667602539,,,,,,,,,,,,,0,,,,0,,,,,,191.0184937,,,,
,31500022.415,194.5444946,99.6243667602539,1.19454405495143E-6,3.54291428099665E-7,1,0.999253354069792,40.0298881530762,1.99681090805413,19.6199994534254,1.45318791029061E-5,-3.26954829917955E-6,0.25,-4.95640450176163E-7,1.19942630401387E-6,-4.96117114305891E-7,194.5444946,194.5444946,99.6243667602539,99.6243667602539,56.8595666314483,20.6120178571927,20.631098,0,0,0,40,4374,197.1334,99.6243667602539,,,,,,,,,,,,,0,,,,0,,,,,,194.5444946,,,,
,31500142.73,197.5171356,99.6243667602539,1.37453250337668E-6,3.004641285303E-7,1,0.999253354069792,40.0298881530762,1.99676672458817,19.5700004696846,1.62685442928934E-5,-1.1659534019418E-6,0.25,-3.41506127405852E-7,1.37976028507824E-6,-3.41221220439293E-7,197.5171356,197.5171356,99.6243667602539,99.6243667602539,57.190195495083,20.6096185731555,21.3904,0,0,0,40,4374,200.1608,99.6243667602539,,,,,,,,,,,,,0,,,,-0.00245,,,,,,197.5171356,,,,
,31500282.085,201.0042267,99.6243667602539,1.34892156381213E-6,3.49845167708968E-7,1,0.999253354069792,40.0298881530762,1.99699320995778,19.5700004696846,1.62637094100464E-5,-2.86263801428946E-6,0.25,-4.865649337448E-7,1.35405398978832E-6,-4.86797391334211E-7,200.9772644,201.031189,99.6243667602539,99.6243667602539,57.3160376866791,20.6090676772476,21.3904,0,0,0,40,4374,203.65035,99.6243667602539,,,,,,,,,,,,,0,,,,-0.0049,,,,,,201.0042267,,,,
,31500423.39,204.5224762,99.6243667602539,1.39517910278425E-6,2.91961195910818E-7,1,0.999253354069792,40.0298881530762,1.99694134259372,19.5700004696846,1.58464721861277E-5,2.64012907971882E-6,0.25,-9.541797437699E-9,1.39980394564769E-6,-8.12327765708243E-9,204.5224762,204.5224762,99.6243667602539,99.6243667602539,57.2222422643714,20.610581059222,21.3904,0,0,0,40,4374,207.18995,99.6243667602539,,,,,,,,,,,,,0,,,,0.00245,,,,,,204.5224762,,,,
touchdown = 14.5199997350574 mm,31500554.83,207.8134308,99.6243667602539,2.04795347928303E-6,3.13245978046288E-7,1,0.999253354069792,40.0298881530762,1.99732646285021,19.5099990814924,2.36625319160062E-5,1.57153474132453E-6,0.25,-2.1705542606963E-7,2.05472837941383E-6,-2.156627889244E-7,207.8134308,207.8134308,99.6243667602539,99.6243667602539,57.2152076076984,20.6023691895474,21.3904,0,0,0,40,4374,210.4895,99.6243667602539,,,,,,,,,,,,,0,,,,0,,,,,,207.8134308,,,,
,31500683.61,211.0188293,99.6243667602539,2.15813763395447E-6,3.59234474285631E-7,1,0.999253354069792,40.0298881530762,1.99710824793026,19.5099990814924,2.49733469577244E-5,1.40805057377493E-6,0.25,-2.50528176146814E-7,2.16506636030076E-6,-2.49144814409325E-7,211.0188293,211.0188293,99.6243667602539,99.6243667602539,56.9979148793522,20.6077680982391,21.770052,0,0,0,40,4374,213.7186,99.6243667602539,,,,,,,,,,,,,0,,,,-0.0049,,,,,,211.0188293,,,,
,31500824.44,214.5415955,99.6243667602539,2.60262444403391E-6,3.68893893455976E-7,1,0.999253354069792,40.0298881530762,1.99704603579318,19.5099990814924,2.97386232281348E-5,3.8507422836109E-6,0.25,-1.12245556622179E-7,2.61048319615693E-6,-1.10028341962881E-7,214.5415955,214.5415955,99.6243667602539,99.6243667602539,57.2378748347561,20.6099885612786,21.770052,0,0,0,40,4374,217.24255,99.6243667602539,,,,,,,,,,,,,0,,,,-0.00245,,,,,,214.5415955,,,,
touchdown = 14.469999819994 mm,31500972.49,218.2283173,99.6243667602539,3.08845116246575E-6,4.0942338342994E-7,1,0.999253354069792,40.0298881530762,1.99731801372274,19.4600000977516,3.52680873723746E-5,4.69629775815475E-6,0.25,-1.21963605009206E-7,3.0973818413557E-6,-1.19346176949528E-7,218.2283173,218.2283173,99.6243667602539,99.6243667602539,57.1808159528522,20.6045134896625,21.01075,0,0,0,40,4374,220.9603,99.6243667602539,,,,,,,,,,,,,0,,,,-0.0049,,,,,,218.2283173,,,,
,31501104.815,221.51296235,99.6243667602539,2.87131959016337E-6,3.53998032366828E-7,1,0.999253354069792,40.0298881530762,1.99728272064876,19.4600000977516,3.30376858306403E-5,2.90600973832023E-6,0.25,-2.42046461216319E-7,2.8794233913554E-6,-2.40002921914144E-7,221.486084,221.5398407,99.6243667602539,99.6243667602539,57.190195495083,20.6065820403794,21.3904,0,0,0,40,4374,224.2741,99.6243667602539,,,,,,,,,,,,,0,,,,-0.00245,,,,,,221.51296235,,,,
,31501246.515,225.0696564,99.6243667602539,3.08818887959792E-6,2.90899482582344E-7,1,0.999253354069792,40.0298881530762,1.99718446874054,19.4600000977516,3.63645008320878E-5,-1.70137000921489E-6,0.25,-6.85939147366853E-7,3.09692053692744E-6,-6.84880660190292E-7,225.0696564,225.0696564,99.6243667602539,99.6243667602539,57.0596635323714,20.6063831906241,21.770052,0,0,0,40,4374,227.8182,99.6243667602539,,,,,,,,,,,,,0,,,,-0.0049,,,,,,225.0696564,,,,
touchdown = 14.4199999049306 mm,31501388.73,228.61380005,99.6243667602539,3.23286852292865E-6,4.56627753488474E-7,1,0.999253354069792,40.0298881530762,1.9972928538619,19.4099992513657,3.61935409187725E-5,9.00714988688608E-6,0.25,2.33517505251032E-7,3.24074107819092E-6,2.37036391898556E-7,228.5887146,228.6388855,99.6243667602539,99.6243667602539,57.1894138665637,20.6029435251338,21.770052,0,0,0,40,4374,231.3947,99.6243667602539,,,,,,,,,,,,,0,,,,0,,,,,,228.61380005,,,,
,31501525.495,232.0011597,99.6243667602539,4.39200246252577E-6,4.12201254959846E-7,1,0.999253354069792,40.0298881530762,1.99718470201221,19.4099992513657,5.0284071897468E-5,5.76942823149001E-6,0.25,-2.53021869007929E-7,4.4026995805821E-6,-2.49707943207007E-7,231.9755707,232.0267487,99.6243667602539,99.6243667602539,56.9088092281599,20.6091410463593,21.770052,0,0,0,40,4374,234.81225,99.6243667602539,,,,,,,,,,,,,0,,,,0,,,,,,232.0011597,,,,
,31501664.775,235.5052032,99.6243667602539,4.42712688278901E-6,2.67417844439393E-7,1,0.999253354069792,40.0298881530762,1.99709296055484,19.4099992513657,5.08630982930169E-5,4.74654554579465E-6,0.25,-3.49211980993545E-7,4.4374514209904E-6,-3.46123594570852E-7,235.5052032,235.5052032,99.6243667602539,99.6243667602539,57.1925403806407,20.6104980620429,21.3904,0,0,0,40,4374,238.3111,99.6243667602539,,,,,,,,,,,,,0,,,,-0.0049,,,,,,235.5052032,,,,
touchdown = 14.3699999898672 mm,31501805.785,238.9792328,99.6243667602539,5.22546469308709E-6,3.51540578447057E-7,1,0.999253354069792,40.0298881530762,1.99722842327803,19.3600002676249,5.92418378193573E-5,1.01560055286235E-5,0.25,-1.02927069433936E-8,5.23666788831824E-6,-5.8173663780341E-9,238.9792328,238.9792328,99.6243667602539,99.6243667602539,56.8587850029291,20.6089689724063,21.3904,0,0,0,40,4374,241.854,99.6243667602539,,,,,,,,,,,,,0,,,,0.0049,,,,,,238.9792328,,,,
,31501926.335,242.00862885,99.6243667602539,5.13956678467895E-6,3.8151235766748E-7,1,0.999253354069792,40.0298881530762,1.99698181796037,19.3600002676249,5.90800783437669E-5,5.22981651983044E-6,0.25,-4.2988976196966E-7,5.15039800207684E-6,-4.2640745960933E-7,241.9844818,242.0327759,99.6243667602539,99.6243667602539,56.8830154870253,20.612629145277,22.149702,0,0,0,40,4374,244.8777,99.6243667602539,,,,,,,,,,,,,0,,,,-0.00245,,,,,,242.00862885,,,,
,31502067.22,245.5222626,99.6243667602539,5.72104625753393E-6,3.27108731487091E-7,1,0.999253354069792,40.0298881530762,1.99704916774227,19.3600002676249,6.46169706555911E-5,1.24013314347056E-5,0.25,1.02359080829348E-7,5.73190731746805E-6,1.073228395392E-7,245.5222626,245.5222626,99.6243667602539,99.6243667602539,57.149550812083,20.61226776995,22.529354,0,0,0,40,4374,248.41025,99.6243667602539,,,,,,,,,,,,,0,,,,-0.0049,,,,,,245.5222626,,,,
,31502208.75,249.0299683,99.6243667602539,,,2,,,,19.3600000748038,,,,,,,249.0299683,249.0299683,99.6243667602539,99.6243667602539,,,22.149702,,,,-99999999,4374,251.9615,99.6243667602539,,,,,,,,,,,,,,,,,,,,,,,249.0299683,,,,
,31502329.03,252.0276337,99.6243667602539,6.40605613466213E-6,3.83940956099474E-7,1,0.999253354069792,40.0298881530762,1.99683537874518,19.3099994212389,7.25442563459092E-5,1.26459070697765E-5,0.25,5.67529286386358E-9,6.41684017919693E-6,1.08588089548038E-8,252.0276337,252.0276337,99.6243667602539,99.6243667602539,57.075296102756,20.6115527765844,22.149702,0,0,0,40,4374,254.9721,99.6243667602539,,,,,,,,,,,,,0,,,,-0.0049,,,,,,252.0276337,,,,
,31502469.28,255.5225372,99.6243667602539,6.42988054738911E-6,4.2667072342111E-7,1,0.999253354069792,40.0298881530762,1.99685747138031,19.3099994212389,7.27647692914435E-5,1.2928292204093E-5,0.25,2.66891816615016E-8,6.43989256296805E-6,3.18392727116688E-8,255.4962463,255.5488281,99.6243667602539,99.6243667602539,56.9682129956214,20.6121402557714,22.149702,0,0,0,40,4374,258.4838,99.6243667602539,,,,,,,,,,,,,0,,,,0.0049,,,,,,255.5225372,,,,
,31502609.65,259.0391541,99.6243667602539,8.00524953287105E-6,4.42939152077147E-7,1,0.999253354069792,40.0298881530762,1.99685299022482,19.3099994212389,9.03744235172969E-5,1.72864048931916E-5,0.25,1.38653897457508E-7,8.01663318933202E-6,1.45110258202498E-7,259.0391541,259.0391541,99.6243667602539,99.6243667602539,57.2034831799099,20.6136832793609,21.770052,0,0,0,40,4374,262.006,99.6243667602539,,,,,,,,,,,,,0,,,,-0.0049,,,,,,259.0391541,,,,
,31502730.21,262.0128021,99.6243667602539,8.48351905503361E-6,3.57221787628363E-7,1,0.999253354069792,40.0298881530762,1.99671888733342,19.2499998956919,9.62195838698861E-5,1.56510924848049E-5,0.25,-8.83631069385127E-8,8.49486831066674E-6,-8.19399901516303E-8,261.9873352,262.038269,99.6243667602539,99.6243667602539,56.8603482599676,20.6095738148508,22.529354,0,0,0,40,4374,265.0158,99.6243667602539,,,,,,,,,,,,,0,,,,0.00245,,,,,,262.0128021,,,,
,31502871.655,265.5605774,99.6243667602539,8.78488044467072E-6,3.83746971559062E-7,1,0.999253354069792,40.0298881530762,1.99682755352809,19.2499998956919,9.89206283377565E-5,2.02988829116951E-5,0.25,2.70157187930603E-7,8.79524624012961E-6,2.77147678765095E-7,265.5605774,265.5605774,99.6243667602539,99.6243667602539,57.129228470583,20.6146284199521,22.149702,0,0,0,40,4374,268.5623,99.6243667602539,,,,,,,,,,,,,0,,,,0,,,,,,265.5605774,,,,
,31503011.18,269.0211792,99.6243667602539,9.26861459392327E-6,3.72621001174824E-7,1,0.999253354069792,40.0298881530762,1.9968367947293,19.2499998956919,0.000106250577980886,1.04802502879823E-5,0.25,-6.80800758450446E-7,9.27913065705704E-6,-6.74611979971467E-7,269.0211792,269.0211792,99.6243667602539,99.6243667602539,57.085457273506,20.6131765161004,21.770052,0,0,0,40,4374,272.0546,99.6243667602539,,,,,,,,,,,,,0,,,,0.00245,,,,,,269.0211792,,,,
,31503152.055,272.5482483,99.6243667602539,1.00818395917791E-5,4.12079290402671E-7,1,0.999253354069792,40.0298881530762,1.99683793877788,19.2000009119511,0.000113696192080041,2.21416652296794E-5,0.25,2.08809349475469E-7,1.00912998957104E-5,2.16423974066199E-7,272.5482483,272.5482483,99.6243667602539,99.6243667602539,57.1307917276214,20.6151485569424,22.149702,0,0,0,40,4374,275.577,99.6243667602539,,,,,,,,,,,,,0,,,,0.0049,,,,,,272.5482483,,,,
,31503292.035,276.0209656,99.6243667602539,9.86595899482322E-6,4.25664829380835E-7,1,0.999253354069792,40.0298881530762,1.99681525809533,19.2000009119511,0.000111823237318561,1.83378764825632E-5,0.25,-8.9528140734493E-8,9.8742054678644E-6,-8.24552062025439E-8,275.9944153,276.0475159,99.6243667602539,99.6243667602539,56.9596150819099,20.6153129690815,22.149702,0,0,0,40,4374,279.07745,99.6243667602539,,,,,,,,,,,,,0,,,,0.00245,,,,,,276.0209656,,,,
,31503432.625,279.5242004,99.6243667602539,1.10044017568451E-5,3.66800589312265E-7,1,0.999253354069792,40.0298881530762,1.99674478230738,19.2000009119511,0.00012435848474397,2.2460283599294E-5,0.25,7.78721460676536E-8,1.10120908705889E-5,8.57801489206547E-8,279.5242004,279.5242004,99.6243667602539,99.6243667602539,57.1432977839291,20.6152514039675,22.529354,0,0,0,40,4374,282.5733,99.6243667602539,,,,,,,,,,,,,0,,,,-0.00245,,,,,,279.5242004,,,,
,31503573.715,283.0393982,99.6243667602539,1.08790235744681E-5,4.89309020368676E-7,1,0.999253354069792,40.0298881530762,1.99678242395276,19.1399995237589,0.000123376482800251,1.96161579389522E-5,0.25,-1.51462376900812E-7,1.0885416220346E-5,-1.43902087399651E-7,283.0393982,283.0393982,99.6243667602539,99.6243667602539,57.027616763083,20.6140228120745,22.529354,0,0,0,40,4374,286.1242,99.6243667602539,,,,,,,,,,,,,0,,,,-0.00245,,,,,,283.0393982,,,,
,31503714.305,286.5361023,99.6243667602539,1.0986046307371E-5,4.56451237332211E-7,1,0.999253354069792,40.0298881530762,1.99681092203791,19.1399995237589,0.000125145270426459,1.6523454164428E-5,0.25,-4.43098568331685E-7,1.09913247335296E-5,-4.35688836896555E-7,286.5361023,286.5361023,99.6243667602539,99.6243667602539,57.129228470583,20.6153999726824,22.909004,0,0,0,40,4374,289.6427,99.6243667602539,,,,,,,,,,,,,0,,,,-0.00245,,,,,,286.5361023,,,,
,31503853.845,290.005249,99.6243667602539,1.19404279205733E-5,4.33080875137494E-7,1,0.999253354069792,40.0298881530762,1.99684546164213,19.1399995237589,0.000134826871155987,2.47398172515383E-5,0.25,1.18195145220668E-7,1.19442667585292E-5,1.26387029075196E-7,290.005249,290.005249,99.6243667602539,99.6243667602539,57.119067299833,20.6146342999778,22.529354,0,0,0,40,4374,293.1328,99.6243667602539,,,,,,,,,,,,,0,,,,0.00245,,,,,,290.005249,,,,
,31503974.74,293.0226135,99.6243667602539,1.23953021665036E-5,4.05945008810561E-7,1,0.999253354069792,40.0298881530762,1.99691475655478,19.0799999982119,0.000139930882215306,2.58061347583254E-5,0.25,1.33920810250543E-7,1.239794177626E-5,1.42309895494225E-7,292.9971008,293.0481262,99.6243667602539,99.6243667602539,57.1511140691214,20.6152275491838,22.529354,0,0,0,40,4374,296.16945,99.6243667602539,,,,,,,,,,,,,0,,,,0.00245,,,,,,293.0226135,,,,
,31504116.905,296.5678711,99.6243667602539,1.22068057418659E-5,5.05467145333486E-7,1,0.999253354069792,40.0298881530762,1.99694460581131,19.0799999982119,0.000138647418895793,2.04474237268514E-5,0.25,-3.06893086088909E-7,1.22081503201191E-5,-2.98806104370156E-7,296.5678711,296.5678711,99.6243667602539,99.6243667602539,57.3160376866791,20.6155613307132,22.529354,0,0,0,40,4374,299.7225,99.6243667602539,,,,,,,,,,,,,0,,,,0,,,,,,296.5678711,,,,
,31504256.57,300.0238953,99.6243667602539,1.2905174855492E-5,4.47403074827027E-7,1,0.999253354069792,40.0298881530762,1.99715309517616,19.0799999982119,0.000146149134955324,2.40812430094777E-5,0.25,-1.06402761856834E-7,1.29048573822733E-5,-9.79379661448783E-8,300.0238953,300.0238953,99.6243667602539,99.6243667602539,56.9955699937945,20.6121511657102,22.149702,0,0,0,40,4374,303.2274,99.6243667602539,,,,,,,,,,,,,0,,,,-0.0049,,,,,,300.0238953,,,,
,31504375.815,303.0068054,99.6243667602539,1.27126684113237E-5,4.43346546649609E-7,1,0.999253354069792,40.0298881530762,1.9971196833747,19.0200004726648,0.000144509630228937,2.04969238191236E-5,0.25,-3.89684602964578E-7,1.27111869841187E-5,-3.81393197126012E-7,303.0068054,303.0068054,99.6243667602539,99.6243667602539,56.8478422036599,20.6132845056905,22.529354,0,0,0,40,4374,306.22615,99.6243667602539,,,,,,,,,,,,,0,,,,0,,,,,,303.0068054,,,,
,31504517.92,306.5238342,99.6243667602539,1.22667137976382E-5,4.5956360021981E-7,1,0.999253354069792,40.0298881530762,1.99706620725892,19.0200004726648,0.000139127194161895,2.14607226313515E-5,0.25,-2.26795065216918E-7,1.22636497519459E-5,-2.18894660432578E-7,306.5238342,306.5238342,99.6243667602539,99.6243667602539,56.8361177758714,20.6133829095493,22.909004,0,0,0,40,4374,309.7844,99.6243667602539,,,,,,,,,,,,,0,,,,0,,,,,,306.5238342,,,,
,31504657.69,310.0013123,99.6243667602539,1.29553487165526E-5,3.9430708042898E-7,1,0.999253354069792,40.0298881530762,1.9971473641117,19.0200004726648,0.000146602737211519,2.4524537326165E-5,0.25,-7.47998527133678E-8,1.29504064640378E-5,-6.65989232854058E-8,310.0013123,310.0013123,99.6243667602539,99.6243667602539,57.0119841926983,20.611840310939,22.529354,0,0,0,40,4374,313.2872,99.6243667602539,,,,,,,,,,,,,0,,,,0,,,,,,310.0013123,,,,
,31504799.125,313.5191956,99.6243667602539,1.33137364172149E-5,3.89956707013425E-7,1,0.999253354069792,40.0298881530762,1.99725597478373,18.9599990844727,0.000151240063956679,2.17789489857079E-5,0.25,-3.79503788454177E-7,1.33071859144921E-5,-3.71022245983344E-7,313.4936829,313.5447083,99.6243667602539,99.6243667602539,57.0526288756983,20.6094773678655,22.909004,0,0,0,40,4374,316.8336,99.6243667602539,,,,,,,,,,,,,0,,,,0.0049,,,,,,313.5191956,,,,
,31504941.39,317.0283508,99.6243667602539,1.33953475985081E-5,3.87502265597637E-7,1,0.999253354069792,40.0298881530762,1.99721961784614,18.9599990844727,0.000151870153739755,2.34995543892876E-5,0.25,-2.41025850753438E-7,1.33870070197383E-5,-2.32641764474148E-7,317.0283508,317.0283508,99.6243667602539,99.6243667602539,57.0182372208522,20.6097837413582,22.909004,0,0,0,40,4374,320.3885,99.6243667602539,,,,,,,,,,,,,0,,,,-0.00245,,,,,,317.0283508,,,,
,31505081.715,320.5235596,99.6243667602539,1.34620103812148E-5,4.03905317070019E-7,1,0.999253354069792,40.0298881530762,1.99697301183691,18.9599990844727,0.000152457410736294,2.43713986788984E-5,0.25,-1.74811106836471E-7,1.34519290161728E-5,-1.66510274398649E-7,320.4966431,320.5504761,99.6243667602539,99.6243667602539,56.8634747740445,20.6131718184457,22.909004,0,0,0,40,4374,323.91535,99.6243667602539,,,,,,,,,,,,,0,,,,0.00245,,,,,,320.5235596,,,,
,31505221.61,324.01060485,99.6243667602539,1.27451342725173E-5,4.14944296635571E-7,1,0.999253354069792,40.0298881530762,1.99717328740038,18.8999995589256,0.000144440152213641,2.24653205423496E-5,0.25,-2.19184827892884E-7,1.2734061774207E-5,-2.11353383274097E-7,323.9807129,324.0404968,99.6243667602539,99.6243667602539,56.943200883006,20.6095236100489,22.909004,0,0,0,40,4374,327.4352,99.6243667602539,,,,,,,,,,,,,0,,,,0.00245,,,,,,324.01060485,,,,
,31505363.41,327.5142517,99.6243667602539,1.26995966809452E-5,5.34963020585661E-7,1,0.999253354069792,40.0298881530762,1.9972716077418,18.8999995589256,0.000143730265304158,2.34395677170958E-5,0.25,-1.24828041251588E-7,1.26869522789182E-5,-1.1718362305125E-7,327.5142517,327.5142517,99.6243667602539,99.6243667602539,57.034651419756,20.6133898209985,23.288654,0,0,0,40,4374,330.9894,99.6243667602539,,,,,,,,,,,,,0,,,,0,,,,,,327.5142517,,,,
,31505503.985,331.0040283,99.6243667602539,1.33143928938863E-5,3.93322118518379E-7,1,0.999253354069792,40.0298881530762,1.99709137889963,18.8999995589256,0.000150570060835349,2.50714888590166E-5,0.25,-8.63129329462932E-8,1.32994931566364E-5,-7.84250717091809E-8,331.0040283,331.0040283,99.6243667602539,99.6243667602539,56.648526931256,20.6146130753372,22.909004,0,0,0,40,4374,334.52215,99.6243667602539,,,,,,,,,,,,,0,,,,0,,,,,,331.0040283,,,,
,31505645.27,334.51521305,99.6243667602539,1.33585334134331E-5,4.17063548409496E-7,1,0.999253354069792,40.0298881530762,1.99744929999854,18.8400000333786,0.000151464035525383,2.2919053953166E-5,0.25,-2.84514540734807E-7,1.33420743096054E-5,-2.76433047066418E-7,334.4874268,334.5429993,99.6243667602539,99.6243667602539,56.9369478548522,20.6077572657904,22.529354,0,0,0,40,4374,338.056,99.6243667602539,,,,,,,,,,,,,0,,,,0,,,,,,334.51521305,,,,
,31505786.28,338.03504945,99.6243667602539,1.27322218897818E-5,4.20986790241457E-7,1,0.999253354069792,40.0298881530762,1.99721341708919,18.8400000333786,0.000142838503992726,3.04459164595161E-5,0.25,4.90945518948677E-7,1.27145531087285E-5,4.97558413081124E-7,338.0098267,338.0602722,99.6243667602539,99.6243667602539,56.7063674416791,20.6114966398013,22.909004,0,0,0,40,4374,341.58905,99.6243667602539,,,,,,,,,,,,,0,,,,0,,,,,,338.03504945,,,,
,31505926.465,341.5321655,99.6243667602539,1.22497518323061E-5,5.04511351408362E-7,1,0.999253354069792,40.0298881530762,1.99725650073024,18.8400000333786,0.000138297118319524,2.41789675918055E-5,0.25,1.98920826552101E-8,1.22315440247867E-5,2.679493849382E-8,341.5321655,341.5321655,99.6243667602539,99.6243667602539,56.9017745714868,20.6118684820666,23.288654,0,0,0,40,4374,345.1004,99.6243667602539,,,,,,,,,,,,,0,,,,0,,,,,,341.5321655,,,,
,31506048.145,344.5309753,99.6243667602539,1.18828502578143E-5,4.26353834823493E-7,1,0.999253354069792,40.0298881530762,1.9976139625639,18.7800005078316,0.000134574103257087,2.10883235369555E-5,0.25,-1.90321495230339E-7,1.18640913958608E-5,-1.83355133379598E-7,344.5309753,344.5309753,99.6243667602539,99.6243667602539,56.9353845978137,20.6027430976517,22.909004,0,0,0,40,4374,348.1493,99.6243667602539,,,,,,,,,,,,,0,,,,0,,,,,,344.5309753,,,,
,31506188.43,348.012619,99.6243667602539,1.19261812240198E-5,4.4649390266109E-7,1,0.999253354069792,40.0298881530762,1.99747450807302,18.7800005078316,0.000133806089806036,2.82867916341717E-5,0.25,4.40089428465639E-7,1.19055958375349E-5,4.45960370771733E-7,347.9868469,348.0383911,99.6243667602539,99.6243667602539,57.1362631272561,20.6058231884773,23.668306,0,0,0,40,4374,351.65785,99.6243667602539,,,,,,,,,,,,,0,,,,0,,,,,,348.012619,,,,
,31506544.915,349.7868347,99.6243667602539,1.21993026538077E-5,5.19689544105233E-7,1,0.999253354069792,40.0298881530762,1.99749680191623,18.7800005078316,0.00013896983320037,1.67689532645762E-5,0.25,-6.27173903554803E-7,1.2178111407001E-5,-6.19277255286837E-7,349.7868347,349.7868347,99.6243667602539,99.6243667602539,56.9197520274291,20.6048229142376,23.668306,0,0,0,40,4369,350.7882,99.6243667602539,,,,,,,,,,,,,0,,,,-0.00245,,,,,,349.7868347,,,,