File: data/doubleLayers/dl_0-25/ppms/data/DD205_10_HYST_100OE_200K.DAT
[Header]
; VSM Data File (default extension .dat)
; Copyright (c) 2003-2013, Quantum Design, Inc. All rights reserved.
TITLE,
FILEOPENTIME,31600522.88,01/02/2019,1:57 am
BYAPP,VSM,2.0,2.0
INFO,PPMS VSM Option Release 1.4.10 Build 1,APPNAME
INFO,Quantum Design Linear Motor Servo Controller,MOTOR_MODULE_NAME
INFO,3101-100 M1,MOTOR_HW_VERSION
INFO,MMC1014,MOTOR_SERIAL_NUMBER
INFO,SRV No X-over 01.03.11,MOTOR_SOFTWARE_VERSION
INFO,Quantum Design VSM Detection Module,VSM_MODULE_NAME
INFO,3101-150 F0,VSM_HW_VERSION
INFO,VSM707,VSM_SERIAL_NUMBER
INFO,VSM No X-over 01.02.05 May 20 2008 13:51:47,VSM_SOFTWARE_VERSION
INFO,704,PREAMP_SERIAL_NUMBER
INFO,822,COIL_SERIAL_NUMBER
INFO,0,MOMENT_UNITS
INFO,CoFe2O4,SAMPLE_MATERIAL
INFO,Double Layer thin concentration,SAMPLE_COMMENT
INFO,27.44,SAMPLE_MASS
INFO,,SAMPLE_VOLUME
INFO,,SAMPLE_MOLECULAR_WEIGHT
INFO,,SAMPLE_SIZE
INFO,,SAMPLE_SHAPE
DATATYPE,COMMENT,1
DATATYPE,TIME,2
STARTUPAXIS,X,2
STARTUPAXIS,Y1,5
[Data]
Comment,Time Stamp (sec),Temperature (K),Magnetic Field (Oe),Moment (emu),M. Std. Err. (emu),Transport Action,Averaging Time (sec),Frequency (Hz),Peak Amplitude (mm),Center Position (mm),Coil Signal' (mV),Coil Signal" (mV),Range (mV),M. Quad. Signal (emu),M. Raw' (emu),M. Raw" (emu),Min. Temperature (K),Max. Temperature (K),Min. Field (Oe),Max. Field (Oe),Mass (grams),Motor Lag (deg),Pressure (Torr),VSM Status (code),Motor Status (code),Measure Status (code),Measure Count,PPMS Status (code),System Temp. (K),System Field (Oe),Sample Position (deg),Bridge 1 Resistance (ohms),Bridge 1 Excitation (에),Bridge 2 Resistance (ohms),Bridge 2 Excitation (에),Bridge 3 Resistance (ohms),Bridge 3 Excitation (에),Bridge 4 Resistance (ohms),Bridge 4 Excitation (에),Signal 1 Vin (V),Signal 2 Vin (V),Digital Inputs (code),Drive 1 Iout (mA),Drive 1 Ipower (W),Drive 2 Iout (mA),Drive 2 Ipower (W),Pressure (),Map 20 (),Map 21 (),Map 22 (),Map 23 (),Map 24 (),Map 25 (),Map 26 (),Map 27 (),Map 28 (),Map 29 ()
,31600537.95,199.9902191,-0.19790905714035,,,2,,,,19.5200003618002,,,,,,,199.9902191,199.9902191,-0.19790905714035,-0.19790905714035,,,23.288654,,,,-99999999,4369,199.9134,-0.19790905714035,,,,,,,,,,,,,,,,,,,,,,,199.9902191,,,,
,31600678.15,199.9813385,4483.83740234375,4.28118208290605E-5,4.86813389850951E-7,1,0.999253354069792,40.0298881530762,1.9966485176475,19.4700006395578,0.000486381596228903,8.03120926370391E-5,0.25,-3.56644322197571E-7,4.29600051849115E-5,-3.11400830325837E-7,199.9813385,199.9813385,4451.61865234375,4516.05615234375,56.4202914036406,20.6093354747933,23.288654,0,0,0,40,4449,199.9432,4483.83740234375,,,,,,,,,,,,,0,,,,0,,,,,,199.9813385,,,,
,31600772.38,199.9850006,9192.4267578125,3.74971099191475E-5,6.24627284804286E-7,1,0.999253354069792,40.0298881530762,1.99678288574816,19.4700006395578,0.000426584887922386,6.71461148451444E-5,0.25,-5.94409821703031E-7,3.76272077600669E-5,-5.5581456536686E-7,199.9850006,199.9850006,9167.0712890625,9217.7822265625,56.8759808303522,20.6088887004924,22.909004,0,0,0,40,4449,199.9548,9192.4267578125,,,,,,,,,,,,,0,,,,0,,,,,,199.9850006,,,,
,31600869.675,199.9886398,14054.8881835938,2.52511235563474E-5,8.62307537018007E-7,1,0.999253354069792,40.0298881530762,1.99681453442131,19.4700006395578,0.00028621022070778,5.13375141222176E-5,0.25,1.39150052584818E-7,2.53381523601362E-5,1.66959026006047E-7,199.9882507,199.9890289,14024.03125,14085.7451171875,56.7587365524675,20.6088158009532,23.668306,0,0,0,40,4449,199.9638,14054.8881835938,,,,,,,,,,,,,0,,,,0,,,,,,199.9886398,,,,
,31600963.705,199.991333,18755.0439453125,1.20942076381648E-5,9.72588166604722E-7,1,0.999253354069792,40.0298881530762,1.99677591776957,19.4700006395578,0.000136514968537983,2.78408733067144E-5,0.25,3.53384006645316E-7,1.21355830821338E-5,3.67671949082907E-7,199.991333,199.991333,18727.66796875,18782.419921875,56.9017745714868,20.6142940394098,22.909004,0,0,0,40,4449,199.96845,18755.0439453125,,,,,,,,,,,,,0,,,,-0.00245,,,,,,199.991333,,,,
,31601057.365,199.99637605,23437.65625,-4.01930351314139E-6,1.1711512661624E-6,1,0.999253354069792,40.0298881530762,1.99663234772389,19.4700006395578,-4.52097889883866E-5,-1.01472505905932E-5,0.25,-1.96380907373221E-7,-4.03296938985822E-6,-2.01394588885838E-7,199.9962006,199.9965515,23410.130859375,23465.181640625,57.210517836583,20.6162348706255,23.668306,0,0,0,40,4449,199.9667,23437.65625,,,,,,,,,,,,,0,,,,-0.00245,,,,,,199.99637605,,,,
,31601152.785,199.99819945,28203.7109375,-2.00730211395797E-5,1.42103329311146E-6,1,0.999253354069792,40.0298881530762,1.9965251470456,19.4700006395578,-0.000228929252326258,-3.25026448432928E-5,0.25,6.21102665541609E-7,-2.01430018620594E-5,6.01633482723009E-7,199.9972534,199.9991455,28173.982421875,28233.439453125,57.0862389020253,20.6166849515952,22.909004,0,0,0,40,4449,199.9702,28203.7109375,,,,,,,,,,,,,0,,,,-0.0049,,,,,,199.99819945,,,,
,31601248.205,199.9990845,32973.1484375,-3.45982307096767E-5,1.35682287797677E-6,1,0.999253354069792,40.0298881530762,1.99645689099385,19.4700006395578,-0.000394466507876551,-5.6638664496086E-5,0.25,1.01596709015084E-6,-3.47187989984838E-5,9.82289688930739E-7,199.9990845,199.9990845,32945.296875,33001,56.8900501436983,20.6175991728283,22.909004,0,0,0,40,4449,199.96955,32973.1484375,,,,,,,,,,,,,0,,,,-0.00245,,,,,,199.9990845,,,,
,31601344.68,200.0045624,37795.58203125,-5.12479912514906E-5,1.68331247553378E-6,1,0.999253354069792,40.0298881530762,1.99687636879043,19.4700006395578,-0.000579017820348601,-0.000114978648380292,0.25,-1.23340617139365E-6,-5.14236460289735E-5,-1.29264303856849E-6,200.0045624,200.0045624,37763.21484375,37827.94921875,56.8673829166406,20.6116969576994,23.288654,0,0,0,40,4449,199.96435,37795.58203125,,,,,,,,,,,,,0,,,,-0.00245,,,,,,200.0045624,,,,
,31601441.59,200.0051727,42640.486328125,-6.84761204158999E-5,2.08850685186392E-6,1,0.999253354069792,40.0298881530762,1.99667484625378,19.4700006395578,-0.000776459738806317,-0.000137110306065474,0.25,-1.93216071483954E-7,-6.8712405971754E-5,-2.67199769451365E-7,200.0051727,200.0051727,42635.31640625,42645.65625,57.1487691835637,20.6154544647105,23.288654,0,0,0,40,4449,199.9617,42640.486328125,,,,,,,,,,,,,0,,,,0,,,,,,200.0051727,,,,
,31601536.56,200.0083313,47386.119140625,-8.53247592995857E-5,1.64621846178693E-6,1,0.999253354069792,40.0298881530762,1.9966202792354,19.4700006395578,-0.000966250113954936,-0.000177944529217382,0.25,-8.67009222724216E-7,-8.56185310753698E-5,-9.61184681436461E-7,200.0083313,200.0083313,47353.4375,47418.80078125,57.119067299833,20.6171893480916,23.288654,0,0,0,40,4449,199.9542,47386.119140625,,,,,,,,,,,,,0,,,,0,,,,,,200.0083313,,,,
,31601632.585,200.0083466,52186.326171875,-0.000102866420140904,2.28781516892749E-6,1,0.999253354069792,40.0298881530762,1.99657898798049,19.4700006395578,-0.00116215306908359,-0.000230201865715082,0.25,-2.42754163679794E-6,-0.000103219147682985,-2.54563257899736E-6,200.0083466,200.0083466,52156.23046875,52216.421875,57.0135474497368,20.618877863214,23.668306,0,0,0,40,4449,199.95205,52186.326171875,,,,,,,,,,,,,0,,,,0,,,,,,200.0083466,,,,
,31601728.27,200.0091858,56966.126953125,-0.000119043009656706,2.47498105980379E-6,1,0.999253354069792,40.0298881530762,1.99672939006496,19.4700006395578,-0.00134689755722622,-0.000255543849473654,0.25,-1.85067151480343E-6,-0.000119452265721291,-1.98377259938821E-6,200.0091858,200.0091858,56963.53515625,56968.71875,57.2253687784484,20.6149808156273,22.909004,0,0,0,40,4449,199.9394,56966.126953125,,,,,,,,,,,,,0,,,,0,,,,,,200.0091858,,,,
,31601823.025,200.0121918,61704.0234375,-0.000137272662922726,2.84538308320049E-6,1,0.999253354069792,40.0298881530762,1.99676387040887,19.4700006395578,-0.00155452407665357,-0.000286946169557792,0.25,-1.45255139095479E-6,-0.000137745347603591,-1.60338864523686E-6,200.0121918,200.0121918,61671.69140625,61736.35546875,56.9291315696599,20.6123062299705,22.909004,0,0,0,40,4449,199.92995,61704.0234375,,,,,,,,,,,,,0,,,,0,,,,,,200.0121918,,,,
,31601918.735,200.0114746,66487.04296875,-0.000152329028181387,2.79808592810482E-6,1,0.999253354069792,40.0298881530762,1.99665618368122,19.4700006395578,-0.00172317721469967,-0.000328550364388962,0.25,-2.50668458127859E-6,-0.000152852664348664,-2.67682711934639E-6,200.0114136,200.0115356,66459.4765625,66514.609375,57.3512109700445,20.6154201872748,23.288654,0,0,0,40,4449,199.92005,66487.04296875,,,,,,,,,,,,,0,,,,0,,,,,,200.0114746,,,,
,31602015.49,200.0108185,71324.7109375,-0.000172104479198744,3.1424889348252E-6,1,0.999253354069792,40.0298881530762,1.99670885582484,19.4700006395578,-0.00194270084970582,-0.000395570490510118,0.25,-4.97952972522924E-6,-0.000172693888032207,-5.17879679417519E-6,200.0108185,200.0108185,71297.34375,71352.078125,57.3254172289099,20.6141042206353,23.288654,0,0,0,40,4449,199.912,71324.7109375,,,,,,,,,,,,,0,,,,0,,,,,,200.0108185,,,,
,31602112.11,200.0144043,76155.75390625,-0.000187458689532726,3.58966193567036E-6,1,0.999253354069792,40.0298881530762,1.9966800115991,19.4700006395578,-0.00212530480919142,-0.000377212893801191,0.25,-6.95809744805272E-7,-0.000188105722665047,-8.96102928288455E-7,200.0144043,200.0144043,76125.59375,76185.9140625,57.3332335141022,20.6139733371684,23.668306,0,0,0,40,4449,199.89775,76155.75390625,,,,,,,,,,,,,0,,,,-0.0049,,,,,,200.0144043,,,,
,31602208.595,200.0136566,80976.546875,-0.000204662616054795,2.65001140263178E-6,1,0.999253354069792,40.0298881530762,1.9965613793801,19.4700006395578,-0.00231655105731335,-0.00043295187329175,0.25,-2.62396862316541E-6,-0.000205367139606658,-2.84862502157942E-6,200.0136566,200.0136566,80954.1640625,80998.9296875,57.2089545795445,20.6171947554407,22.909004,0,0,0,40,4449,199.8878,80976.546875,,,,,,,,,,,,,0,,,,0,,,,,,200.0136566,,,,
,31602303.705,200.0131989,85732.1953125,-0.000220616231356603,3.42534553337832E-6,1,0.999253354069792,40.0298881530762,1.99661861591381,19.4700006395578,-0.00249685313584772,-0.00046869564950351,0.25,-3.0037044236287E-6,-0.000221375569667086,-3.2459838950134E-6,200.0131989,200.0131989,85702.234375,85762.15625,57.261323690333,20.6167321607983,23.288654,0,0,0,40,4449,199.8785,85732.1953125,,,,,,,,,,,,,0,,,,0.00245,,,,,,200.0131989,,,,
,31602409.195,200.010437,89733.77734375,-0.000237292643377361,3.0346071525569E-6,1,0.999253354069792,40.0298881530762,1.99653565352274,19.4700006395578,-0.00268436749592727,-0.000510540735788891,0.25,-3.79856457254263E-6,-0.000238108877144746,-4.06066856384574E-6,200.010437,200.010437,89714.046875,89753.5078125,57.4254656793715,20.6141829310034,23.288654,0,0,0,40,4449,199.8719,89733.77734375,,,,,,,,,,,,,0,,,,-0.00245,,,,,,200.010437,,,,
,31602501.095,200.005188,85144.28515625,-0.0002214686068541,3.68953968927986E-6,1,0.999253354069792,40.0298881530762,1.99635493728194,19.4700006395578,-0.00251707847422419,-0.000407714792405604,0.25,2.51526047484642E-6,-0.000222236740764482,2.29108180661988E-6,200.005188,200.005188,85114.4140625,85174.15625,57.5653771843138,20.6221801081071,23.288654,0,0,0,40,4449,199.86775,85144.28515625,,,,,,,,,,,,,0,,,,0.00245,,,,,,200.005188,,,,
,31602596.605,200.00073245,80370.65234375,-0.000199068286138705,3.1786558508027E-6,1,0.999253354069792,40.0298881530762,1.99655355044349,19.4700006395578,-0.00224722568321973,-0.000455644812198108,0.25,-5.59593380770176E-6,-0.000199750416809182,-5.82505274126559E-6,200.0006104,200.0008545,80340.75,80400.5546875,57.5896076684099,20.6191817641277,23.288654,0,0,0,40,4449,199.86855,80370.65234375,,,,,,,,,,,,,0,,,,-0.0049,,,,,,200.00073245,,,,
,31602694.865,199.9936142,75458.91015625,-0.00018610019893702,2.92756665660685E-6,1,0.999253354069792,40.0298881530762,1.9965465839762,19.4700006395578,-0.0021045222932111,-0.000404672109841005,0.25,-3.35431995532984E-6,-0.000186739845081645,-3.56245676909573E-6,199.9933624,199.993866,75431.5625,75486.2578125,57.0909286731407,20.6183395466184,22.909004,0,0,0,40,4449,199.8752,75458.91015625,,,,,,,,,,,,,0,,,,-0.00245,,,,,,199.9936142,,,,
,31602790.385,199.9927368,70680.98046875,-0.000170149337221802,2.6833358848429E-6,1,0.999253354069792,40.0298881530762,1.99671179293319,19.4700006395578,-0.00192633622501334,-0.000358248572245249,0.25,-2.02917537914129E-6,-0.000170735200634023,-2.2162623567914E-6,199.9925995,199.9928741,70653.375,70708.5859375,57.2581971762561,20.6146974762168,23.288654,0,0,0,40,4449,199.8851,70680.98046875,,,,,,,,,,,,,0,,,,0.00245,,,,,,199.9927368,,,,
,31602885.59,199.9906006,65922.62109375,-0.000150727037154907,2.62478675877367E-6,1,0.999253354069792,40.0298881530762,1.99675562127625,19.4700006395578,-0.00170311020460062,-0.000336783037535499,0.25,-3.50909210245831E-6,-0.000151244169631248,-3.68106403875981E-6,199.9906006,199.9906006,65895.1171875,65950.125,57.1214121853907,20.614805486069,23.668306,0,0,0,40,4449,199.8974,65922.62109375,,,,,,,,,,,,,0,,,,0,,,,,,199.9906006,,,,
,31602980.715,199.9888763,61169.720703125,-0.000132123654399751,2.08315321048692E-6,1,0.999253354069792,40.0298881530762,1.99649245086155,19.4700006395578,-0.00149525223781504,-0.000280578750209352,0.25,-1.78865566225173E-6,-0.000132578287016505,-1.93524319833588E-6,199.9888763,199.9888763,61167.09765625,61172.34375,57.5403650716984,20.618028516206,23.668306,0,0,0,40,4449,199.9013,61169.720703125,,,,,,,,,,,,,0,,,,0,,,,,,199.9888763,,,,
,31603075.94,199.987381,56409.125,-0.000117307478767614,2.50153154053072E-6,1,0.999253354069792,40.0298881530762,1.99676279082253,19.4700006395578,-0.00132804863856899,-0.000247414768874419,0.25,-1.4351319327386E-6,-0.000117711258377297,-1.56500337612635E-6,199.9873352,199.9874268,56403.984375,56414.265625,57.3770047111791,20.6172370302812,22.909004,0,0,0,40,4449,199.91055,56409.125,,,,,,,,,,,,,0,,,,-0.00245,,,,,,199.987381,,,,
,31603172.435,199.9916077,51586.341796875,-9.95322327330028E-5,2.5257794797819E-6,1,0.999253354069792,40.0298881530762,1.99692239828356,19.4700006395578,-0.0011339788087926,-0.0001691746180982,0.25,2.37551659363753E-6,-9.98786149492928E-5,2.27752280735167E-6,199.9914551,199.9917603,51556.5,51616.18359375,57.5520894994869,20.6149166722014,23.288654,0,0,0,40,4449,199.91635,51586.341796875,,,,,,,,,,,,,0,,,,0,,,,,,199.9916077,,,,
,31603266.875,199.9897003,46866.41015625,-8.34117076332219E-5,1.72629010902491E-6,1,0.999253354069792,40.0298881530762,1.9966857642766,19.4700006395578,-0.000946482028180347,-0.000163216421668277,0.25,9.95078690230042E-8,-8.36999513741648E-5,1.06805198769341E-8,199.9897003,199.9897003,46838.703125,46894.1171875,57.3238539718714,20.619386176358,23.288654,0,0,0,40,4449,199.92665,46866.41015625,,,,,,,,,,,,,0,,,,-0.00245,,,,,,199.9897003,,,,
,31603362.435,199.99163815,42088.384765625,-6.5201329249314E-5,2.26066618029152E-6,1,0.999253354069792,40.0298881530762,1.99664686552948,19.4700006395578,-0.000739452158277701,-0.000129772348941073,0.25,-1.15268753743131E-7,-6.54264131969536E-5,-1.85506259664144E-7,199.991394,199.9918823,42055.64453125,42121.125,57.6247809517753,20.6184885615582,22.909004,0,0,0,40,4449,199.9305,42088.384765625,,,,,,,,,,,,,0,,,,0.00245,,,,,,199.99163815,,,,
,31603458.48,199.98770905,37288.515625,-5.11487660301726E-5,1.83344619103199E-6,1,0.999253354069792,40.0298881530762,1.99670810658292,19.4700006395578,-0.00057673842811244,-0.000121150180168862,0.25,-1.79542274710597E-6,-5.13235001472359E-5,-1.85651496831619E-6,199.9875946,199.9878235,37258.859375,37318.171875,57.6497930643907,20.6193222098012,22.909004,0,0,0,40,4449,199.93815,37288.515625,,,,,,,,,,,,,0,,,,-0.00245,,,,,,199.98770905,,,,
,31603553.33,199.9916687,32548.814453125,-3.45506641967778E-5,1.42183230410693E-6,1,0.999253354069792,40.0298881530762,1.99669795291918,19.4700006395578,-0.00038965803253041,-8.13924449226698E-5,0.25,-1.17365598067917E-6,-3.46687214682658E-5,-1.21485413208685E-6,199.9916687,199.9916687,32521.373046875,32576.255859375,57.4317187075253,20.6224233806602,22.909004,0,0,0,40,4449,199.95145,32548.814453125,,,,,,,,,,,,,0,,,,0,,,,,,199.9916687,,,,
,31603648.82,199.991745,27776.1474609375,-1.67935494464056E-5,9.75411412258662E-7,1,0.999253354069792,40.0298881530762,1.99672710664703,19.4700006395578,-0.000190236713832762,-3.47333969567554E-5,0.25,-1.44830179281085E-7,-1.68513843371391E-5,-1.63417521769488E-7,199.9916229,199.9918671,27743.734375,27808.560546875,57.3230723433522,20.6213830716762,23.288654,0,0,0,40,4449,199.9555,27776.1474609375,,,,,,,,,,,,,0,,,,0.00245,,,,,,199.991745,,,,
,31603744.42,199.9889832,22998.0859375,-8.97243336414698E-7,1.01576206391186E-6,1,0.999253354069792,40.0298881530762,1.99683679746375,19.4700006395578,-1.04038557818723E-5,-4.77549251729593E-7,0.25,1.13745601649741E-7,-9.00464221134868E-7,1.1317034207584E-7,199.9889832,199.9889832,22965.447265625,23030.724609375,57.5817913832176,20.6221813635957,22.909004,0,0,0,40,4449,199.96525,22998.0859375,,,,,,,,,,,,,0,,,,-0.00245,,,,,,199.9889832,,,,
,31603840.75,199.9893494,18183.5068359375,1.35374675012635E-5,8.6874072292531E-7,1,0.999253354069792,40.0298881530762,1.99676737533389,19.4700006395578,0.000154794939272534,1.97079592061198E-5,0.25,-6.14144310125504E-7,1.35848720762155E-5,-6.01634831255908E-7,199.9892731,199.9894257,18153.4453125,18213.568359375,57.2957153451791,20.6236765828764,23.288654,0,0,0,40,4449,199.9713,18183.5068359375,,,,,,,,,,,,,0,,,,-0.00245,,,,,,199.9893494,,,,
,31603935.925,199.9891968,13426.2099609375,2.75805516146692E-5,5.45750165722022E-7,1,0.999253354069792,40.0298881530762,1.99624887905083,19.4700006395578,0.000314815511872303,4.28921118614442E-5,0.25,-1.00881376941786E-6,2.76768641661457E-5,-9.82442584525109E-7,199.9889374,199.9894562,13401.318359375,13451.1015625,57.5622506702369,20.6286522192713,23.668306,0,0,0,40,4449,199.97325,13426.2099609375,,,,,,,,,,,,,0,,,,-0.0049,,,,,,199.9891968,,,,
,31604033.675,199.9916534,8543.41259765625,4.01535616800051E-5,6.53013245197073E-7,1,0.999253354069792,40.0298881530762,1.99658339512123,19.4700006395578,0.000455816334602402,7.73423648681093E-5,0.25,-1.56430304237285E-7,4.02923469612433E-5,-1.134435888854E-7,199.9914703,199.9918365,8513.41796875,8573.4072265625,57.8076820252753,20.6264110783069,22.909004,0,0,0,40,4449,199.9872,8543.41259765625,,,,,,,,,,,,,0,,,,-0.00245,,,,,,199.9916534,,,,
,31604129.555,199.9940186,3747.83557128906,4.39789450646246E-5,4.44227256419006E-7,1,0.999253354069792,40.0298881530762,1.99682273614579,19.4700006395578,0.000498969714635724,8.66127555622085E-5,0.25,-4.59735634182035E-9,4.4130758762338E-5,4.31232444387531E-8,199.9940186,199.9940186,3720.28955078125,3775.38159179687,57.5747567265446,20.6249646125579,23.288654,0,0,0,40,4449,199.9912,3747.83557128906,,,,,,,,,,,,,0,,,,-0.00245,,,,,,199.9940186,,,,
,31604222.415,199.99346925,-891.723907470703,2.05850940732181E-5,3.79127981843134E-7,1,0.999253354069792,40.0298881530762,1.99673311995166,19.4700006395578,0.000232977963717152,4.37818489165893E-5,0.25,2.83689232533835E-7,2.06558408943007E-5,3.07026399058028E-7,199.993042,199.9938965,-921.485107421875,-861.962707519531,57.4121779945445,20.6256291018755,23.288654,0,0,0,40,4449,199.99535,-891.723907470703,,,,,,,,,,,,,0,,,,0,,,,,,199.99346925,,,,
,31604316.75,199.9998627,-5604.8662109375,-2.79661471793561E-5,5.07272465529985E-7,1,0.999253354069792,40.0298881530762,1.99677326770384,19.4700006395578,-0.000317264389973403,-5.52033586087079E-5,0.25,-8.35137327964863E-9,-2.80626699062092E-5,-3.87204446380644E-8,199.9994507,200.0002747,-5632.37353515625,-5577.35888671875,57.2871174314676,20.6251260607456,23.668306,0,0,0,40,4449,199.99265,-5604.8662109375,,,,,,,,,,,,,0,,,,-0.0049,,,,,,199.9998627,,,,
,31604411.575,200.0022278,-10345.7856445312,-3.28172309106273E-5,7.05168950267782E-7,1,0.999253354069792,40.0298881530762,1.99683070937694,19.4700006395578,-0.000372258509490263,-6.50669983675598E-5,0.25,-3.50689407968499E-8,-3.29304741273806E-5,-7.07435576139658E-8,200.0018921,200.0025635,-10350.73828125,-10340.8330078125,57.6615174921792,20.6261065110411,23.668306,0,0,0,40,4449,199.9911,-10345.7856445312,,,,,,,,,,,,,0,,,,0,,,,,,200.0022278,,,,
,31604507.275,200.0047455,-15128.80859375,-2.12427060978442E-5,7.12305781340685E-7,1,0.999253354069792,40.0298881530762,1.99684972627766,19.4700006395578,-0.000242256371403438,-3.46917167380674E-5,0.25,6.31858905151895E-7,-2.13167203317047E-5,6.11061353310309E-7,200.0042267,200.0052643,-15158.875,-15098.7421875,57.2136443506599,20.6262647777926,23.288654,0,0,0,40,4449,199.98715,-15128.80859375,,,,,,,,,,,,,0,,,,0,,,,,,200.0047455,,,,
,31604600.405,200.00831605,-19783.529296875,-8.19646727571089E-6,8.49324356074419E-7,1,0.999253354069792,40.0298881530762,1.99673645454335,19.4700006395578,-9.46165613828647E-5,-6.77913629518717E-6,0.25,8.26061667939382E-7,-8.22565507929976E-6,8.20060882683091E-7,200.0082703,200.0083618,-19815.890625,-19751.16796875,57.495030617583,20.628058371302,23.288654,0,0,0,40,4449,199.97925,-19783.529296875,,,,,,,,,,,,,0,,,,0.00245,,,,,,200.00831605,,,,
,31604692.895,200.0082397,-24405.8984375,6.92240092318258E-6,9.44996321896406E-7,1,0.999253354069792,40.0298881530762,1.99677000703362,19.4700006395578,8.138764574625E-5,-2.77896545736427E-6,0.25,-1.44725375711477E-6,6.94786059824438E-6,-1.44478610195817E-6,200.0082397,200.0082397,-24428.16015625,-24383.63671875,57.5677220698715,20.6278293601112,23.288654,0,0,0,40,4449,199.9738,-24405.8984375,,,,,,,,,,,,,0,,,,0,,,,,,200.0082397,,,,
,31604788.295,200.0102081,-29173.1494140625,2.16580968661117E-5,1.37466500963662E-6,1,0.999253354069792,40.0298881530762,1.9967841567156,19.4700006395578,0.000244758891554669,4.81916143864878E-5,0.25,4.86117451179979E-7,2.17323512783094E-5,5.11108954695914E-7,200.0098724,200.0105438,-29195.6171875,-29150.681640625,57.6349421225253,20.6273932699437,22.909004,0,0,0,40,4449,199.96235,-29173.1494140625,,,,,,,,,,,,,0,,,,0,,,,,,200.0102081,,,,
,31604884.06,200.0114441,-33960.505859375,3.71988239028046E-5,1.10322581031519E-6,1,0.999253354069792,40.0298881530762,1.99663962051785,19.4700006395578,0.000421563155277301,7.58167209330142E-5,0.25,2.22457922381557E-7,3.73270282497485E-5,2.63194891036487E-7,200.0114441,200.0114441,-33992.93359375,-33928.078125,57.5614690417176,20.6307748362034,23.668306,0,0,0,40,4449,199.9556,-33960.505859375,,,,,,,,,,,,,0,,,,0,,,,,,200.0114441,,,,
,31604981.5,200.0133972,-38827.5703125,5.41494108365558E-5,1.53434805183569E-6,1,0.999253354069792,40.0298881530762,1.99681464488994,19.4700006395578,0.000617020064913808,9.13184488996019E-5,0.25,-1.35562442295486E-6,5.43378489762933E-5,-1.30223293671489E-6,200.0133972,200.0133972,-38830.0625,-38825.078125,57.515352959083,20.6269598084952,23.288654,0,0,0,40,4449,199.9457,-38827.5703125,,,,,,,,,,,,,0,,,,0,,,,,,200.0133972,,,,
,31605077.125,200.0129089,-43607.228515625,7.15507413502367E-5,2.0037803762368E-6,1,0.999253354069792,40.0298881530762,1.99670996707588,19.4700006395578,0.000811526011446311,0.000142179057981903,0.25,1.05833465401017E-7,7.17977233062704E-5,1.82790225128858E-7,200.0129089,200.0129089,-43642.234375,-43572.22265625,57.6107116384292,20.6287191289649,23.668306,0,0,0,40,4449,199.9334,-43607.228515625,,,,,,,,,,,,,0,,,,0.00245,,,,,,200.0129089,,,,
,31605173.275,200.0130768,-48412.494140625,8.81747932942099E-5,1.71036516913304E-6,1,0.999253354069792,40.0298881530762,1.99669991851328,19.4700006395578,0.000999941145957468,0.000175959306456573,0.25,1.96473066707619E-7,8.84791149048532E-5,2.91354082747577E-7,200.0130768,200.0130768,-48439.9765625,-48385.01171875,57.6091483813907,20.6284968903553,23.668306,0,0,0,40,4449,199.92595,-48412.494140625,,,,,,,,,,,,,0,,,,-0.00245,,,,,,200.0130768,,,,
,31605268.715,200.013504,-53184.779296875,0.000105631749608266,1.85294336466124E-6,1,0.999253354069792,40.0298881530762,1.99662836529762,19.4700006395578,0.00119958317642075,0.000200925040479385,0.25,-6.3388894762529E-7,0.000105997279011821,-5.2344528708844E-7,200.013504,200.013504,-53217.078125,-53152.48046875,57.7943943404484,20.6319363649848,23.668306,0,0,0,40,4449,199.9144,-53184.779296875,,,,,,,,,,,,,0,,,,-0.00245,,,,,,200.013504,,,,
,31605364.305,200.0125351,-57962.1328125,0.000122706676879858,1.72376955038644E-6,1,0.999253354069792,40.0298881530762,1.99655823712622,19.4700006395578,0.00139117913185025,0.000246440032962825,0.25,4.13760829332325E-7,0.000123130108832317,5.45769554140033E-7,200.0119629,200.0131073,-57994.59765625,-57929.66796875,57.2863358029484,20.6358432919359,23.288654,0,0,0,40,4449,199.90425,-57962.1328125,,,,,,,,,,,,,0,,,,0,,,,,,200.0125351,,,,
,31605460.82,200.015564,-62784.732421875,0.00013840342780796,1.92534970058576E-6,1,0.999253354069792,40.0298881530762,1.99656987237181,19.4700006395578,0.00157213153355555,0.000260793239481944,0.25,-1.04685391588963E-6,0.000138882663290669,-9.0348538451558E-7,200.015564,200.015564,-62817.1171875,-62752.34765625,57.4403166212368,20.634516723068,23.288654,0,0,0,40,4449,199.89175,-62784.732421875,,,,,,,,,,,,,0,,,,-0.00245,,,,,,200.015564,,,,
,31605557.755,200.0165405,-67629.53125,0.000156190785678465,2.89177113290382E-6,1,0.999253354069792,40.0298881530762,1.99658322816629,19.4700006395578,0.00177479338713912,0.000290842161440462,0.25,-1.48691325545642E-6,0.000156731976726446,-1.32651337177052E-6,200.0165405,200.0165405,-67634.625,-67624.4375,57.2793011462753,20.6356024589033,23.668306,0,0,0,40,4449,199.8752,-67629.53125,,,,,,,,,,,,,0,,,,0.0049,,,,,,200.0165405,,,,
,31605652.555,200.0125885,-72366.31640625,0.000171527705696438,2.79710283362411E-6,1,0.999253354069792,40.0298881530762,1.99667753037767,19.4700006395578,0.00194448067659966,0.000346333106649472,0.25,7.40149357730251E-7,0.000172119601524638,9.24121797614526E-7,200.0125885,200.0125885,-72396.2421875,-72336.390625,57.8084636537946,20.6321691143045,23.288654,0,0,0,40,4449,199.8676,-72366.31640625,,,,,,,,,,,,,0,,,,0.00245,,,,,,200.0125885,,,,
,31605751.33,200.0085754,-77300.984375,0.000190730026480369,2.41453201347985E-6,1,0.999253354069792,40.0298881530762,1.99666981224131,19.4700006395578,0.00215997222012876,0.000397678481873976,0.25,1.93189847923584E-6,0.000191387105127418,2.13985590029516E-6,200.0085754,200.0085754,-77303.53125,-77298.4375,57.332451885583,20.6318138768062,23.288654,0,0,0,40,4449,199.8618,-77300.984375,,,,,,,,,,,,,0,,,,0,,,,,,200.0085754,,,,
,31605846.95,200.01204685,-82083.59375,0.000206311959245927,2.66934887602329E-6,1,0.999253354069792,40.0298881530762,1.99657569513988,19.4700006395578,0.00234700357277889,0.000368680799256429,0.25,-3.32820011451465E-6,0.000207028470734794,-3.12243230666327E-6,200.0119019,200.0121918,-82116.078125,-82051.109375,57.9475935302177,20.6341741586328,23.288654,0,0,0,40,4449,199.84615,-82083.59375,,,,,,,,,,,,,0,,,,0.00245,,,,,,200.01204685,,,,
,31605941.375,200.0131836,-86800.484375,0.000225062503621155,3.44612854174762E-6,1,0.999253354069792,40.0298881530762,1.99674210092716,19.4700006395578,0.00255315603899504,0.000444590959203123,0.25,1.0453062112119E-7,0.000225840265500596,3.4140245975424E-7,200.01297,200.0133972,-86828.0625,-86772.90625,57.7279559163138,20.6343718306225,23.288654,0,0,0,40,4449,199.83925,-86800.484375,,,,,,,,,,,,,0,,,,-0.00245,,,,,,200.0131836,,,,
,31606048.08,200.0103912,-88620.203125,0.000234142067937962,2.83686731093811E-6,1,0.999253354069792,40.0298881530762,1.99676706741643,19.4700006395578,0.00266119198687694,0.000433721147083237,0.25,-2.43055555594686E-6,0.000234953923002029,-2.19310264263138E-6,200.0103912,200.0103912,-88622.6796875,-88617.7265625,57.647448178833,20.6310519157397,23.668306,0,0,0,40,4449,199.8325,-88620.203125,,,,,,,,,,,,,0,,,,-0.0049,,,,,,200.0103912,,,,
,31606139.69,200.0021515,-84043.35546875,0.000215849904016381,3.04865505849632E-6,1,0.999253354069792,40.0298881530762,1.99676207112839,19.4700006395578,0.0024536236093628,0.000397872126982685,0.25,-2.41425578025661E-6,0.000216598511311889,-2.19547321180179E-6,200.0018158,200.0024872,-84075.9921875,-84010.71875,57.7701638563523,20.6316322179521,23.288654,0,0,0,40,4449,199.8332,-84043.35546875,,,,,,,,,,,,,0,,,,-0.00245,,,,,,200.0021515,,,,
,31606235.91,200.00000765,-79233.30078125,0.000197524317354237,3.01001966316459E-6,1,0.999253354069792,40.0298881530762,1.99721332412007,19.4700006395578,0.00224324800072248,0.000378841004643226,0.25,-9.17002994952884E-7,0.000198207957998131,-7.11864628322498E-7,199.9991913,200.000824,-79263.203125,-79203.3984375,57.5192611016792,20.6202504272172,23.668306,0,0,0,40,4449,199.8302,-79233.30078125,,,,,,,,,,,,,0,,,,0.00245,,,,,,200.00000765,,,,
,31606332.235,199.9931946,-74418.80859375,0.000181725791215584,3.11509478599307E-6,1,0.999253354069792,40.0298881530762,1.99689228242276,19.4700006395578,0.00206392383185558,0.000346104907986469,0.25,-1.05399826473081E-6,0.000182354958818051,-8.6558528006092E-7,199.9931946,199.9931946,-74445.984375,-74391.6328125,57.5653771843138,20.6299551149888,23.668306,0,0,0,40,4449,199.8397,-74418.80859375,,,,,,,,,,,,,0,,,,-0.00245,,,,,,199.9931946,,,,
,31606430.99,199.9907227,-69481.9453125,0.000162361964582672,2.77537366324884E-6,1,0.999253354069792,40.0298881530762,1.99700774943672,19.4700006395578,0.00184180677271523,0.000322467000997788,0.25,2.23437971103358E-7,0.000162922818901069,3.96173323480593E-7,199.9907227,199.9907227,-69484.3046875,-69479.5859375,57.5442732142945,20.6195316825833,23.668306,0,0,0,40,4449,199.84865,-69481.9453125,,,,,,,,,,,,,0,,,,-0.0098,,,,,,199.9907227,,,,
,31606526.53,199.9877014,-64709.7578125,0.000145390028830348,2.59940884235442E-6,1,0.999253354069792,40.0298881530762,1.99700349728338,19.4700006395578,0.00164749251419454,0.00029902967750154,0.25,1.10500212838394E-6,0.000145891264134924,1.26312517021923E-6,199.9877014,199.9877014,-64742.21875,-64677.296875,57.4528226775445,20.619256006521,23.668306,0,0,0,40,4449,199.85925,-64709.7578125,,,,,,,,,,,,,0,,,,0,,,,,,199.9877014,,,,
,31606624.625,199.9893646,-59807.142578125,0.000128155223689254,2.53056721571777E-6,1,0.999253354069792,40.0298881530762,1.99701291296431,19.4700006395578,0.00145780787797291,0.000231301993495669,0.25,-1.87129501095717E-6,0.000128600017320557,-1.74146332395875E-6,199.9893646,199.9893646,-59839.58203125,-59774.703125,57.6185279236215,20.6227319546553,22.909004,0,0,0,40,4449,199.86945,-59807.142578125,,,,,,,,,,,,,0,,,,0.00245,,,,,,199.9893646,,,,
,31606720.985,199.9890366,-54989.986328125,0.00011155847394777,2.31755799887829E-6,1,0.999253354069792,40.0298881530762,1.99709139148126,19.4700006395578,0.00126155905059727,0.000244554808489459,0.25,2.17799662670191E-6,0.000111941577085086,2.30440978295375E-6,199.9888306,199.9892426,-55022.4609375,-54957.51171875,57.6568277210638,20.6200045669514,22.909004,0,0,0,40,4449,199.8767,-54989.986328125,,,,,,,,,,,,,0,,,,-0.00245,,,,,,199.9890366,,,,
,31606818.485,199.9894257,-50118.283203125,9.39214886789636E-5,1.9515389456002E-6,1,0.999253354069792,40.0298881530762,1.99701787488578,19.4700006395578,0.00106733817465197,0.000175570479180667,0.25,-8.38166935654469E-7,9.42468430533929E-5,-7.40766634146377E-7,199.9894257,199.9894257,-50120.96484375,-50115.6015625,57.5716302124676,20.6226052929804,23.288654,0,0,0,40,4449,199.88415,-50118.283203125,,,,,,,,,,,,,0,,,,0,,,,,,199.9894257,,,,
,31606914.405,199.98986055,-45323.4765625,7.84760248425469E-5,2.18503599923418E-6,1,0.999253354069792,40.0298881530762,1.99708777929644,19.4700006395578,0.000890562068397371,0.00015407860140931,0.25,-5.04517996477519E-8,7.87471556542865E-5,3.33391656813789E-8,199.9898529,199.9898682,-45353.41796875,-45293.53515625,57.5239508727946,20.6185928608731,23.668306,0,0,0,40,4449,199.89415,-45323.4765625,,,,,,,,,,,,,0,,,,-0.0049,,,,,,199.98986055,,,,
,31607010.9,199.9869537,-40503.396484375,6.11786540173512E-5,1.96444060315987E-6,1,0.999253354069792,40.0298881530762,1.99684788262075,19.4700006395578,0.000698407081356206,9.58119658994148E-5,0.25,-2.18049681517924E-6,6.13923062260251E-5,-2.12244477041781E-6,199.9869537,199.9869537,-40505.72265625,-40501.0703125,57.352774227083,20.6250658307973,23.668306,0,0,0,40,4449,199.904,-40503.396484375,,,,,,,,,,,,,0,,,,-0.0049,,,,,,199.9869537,,,,
,31607105.62,199.9872208,-35768.474609375,4.4802485112521E-5,1.49640365766409E-6,1,0.999253354069792,40.0298881530762,1.9968663041379,19.4700006395578,0.000510113427561956,7.79385343525702E-5,0.25,-9.11835891115052E-7,4.49582016067968E-5,-8.66869051845175E-7,199.9871674,199.9872742,-35798.5859375,-35738.36328125,57.637287008083,20.6238289622565,23.668306,0,0,0,40,4449,199.91625,-35768.474609375,,,,,,,,,,,,,0,,,,0,,,,,,199.9872208,,,,
,31607201.505,199.9910202,-30973.65625,2.72291566670892E-5,1.49834523780941E-6,1,0.999253354069792,40.0298881530762,1.99684466677639,19.4700006395578,0.000310629276442377,4.38778018595756E-5,0.25,-8.61804481183526E-7,2.73241157544498E-5,-8.35484304810253E-7,199.9909058,199.9911346,-31006.99609375,-30940.31640625,57.5794464976599,20.6235582672655,23.668306,0,0,0,40,4449,199.92575,-30973.65625,,,,,,,,,,,,,0,,,,-0.00245,,,,,,199.9910202,,,,
,31607295.525,199.9916077,-26276.359375,1.20262155454425E-5,1.23879503403632E-6,1,0.999253354069792,40.0298881530762,1.99676292568807,19.4700006395578,0.000138507722115226,1.17874013738418E-5,0.25,-1.04976810163944E-6,1.20688741679784E-5,-1.04043095613453E-6,199.9916077,199.9916077,-26298.951171875,-26253.767578125,57.3988903097176,20.624881401364,23.668306,0,0,0,40,4449,199.92945,-26276.359375,,,,,,,,,,,,,0,,,,0,,,,,,199.9916077,,,,
,31607390.65,199.9918365,-21521.4111328125,-2.94737504635687E-6,9.22937166600681E-7,1,0.999253354069792,40.0298881530762,1.99690145520142,19.4700006395578,-3.12256697285271E-5,-1.85607069229156E-5,0.25,-1.12398191776619E-6,-2.95633814966885E-6,-1.13104493830374E-6,199.9918365,199.9918365,-21546.466796875,-21496.35546875,57.6834030907176,20.6237801301492,23.668306,0,0,0,40,4449,199.93565,-21521.4111328125,,,,,,,,,,,,,0,,,,0.0049,,,,,,199.9918365,,,,
,31607486.975,199.9924316,-16709.3642578125,-1.76906329489698E-5,8.12519285611167E-7,1,0.999253354069792,40.0298881530762,1.99676211331982,19.4700006395578,-0.00019841226803086,-4.80455669946514E-5,0.25,-1.1622776329497E-6,-1.77504527937156E-5,-1.18542177646892E-6,199.9924316,199.9924316,-16739.30078125,-16679.427734375,57.7459333722561,20.625800244169,24.047956,0,0,0,40,4449,199.943,-16709.3642578125,,,,,,,,,,,,,0,,,,-0.00245,,,,,,199.9924316,,,,
,31607583.825,199.9875946,-11869.3422851562,-3.1434254144499E-5,7.76649832817212E-7,1,0.999253354069792,40.0298881530762,1.99676030188925,19.4700006395578,-0.000357067372102388,-5.93963057295016E-5,0.25,2.2436061700152E-7,-3.15430209804262E-5,1.91088430276286E-7,199.9875946,199.9875946,-11871.6513671875,-11867.033203125,57.6740235484869,20.6258563572057,23.288654,0,0,0,40,4449,199.9539,-11869.3422851562,,,,,,,,,,,,,0,,,,0,,,,,,199.9875946,,,,
,31607679.985,199.993576,-7060.99194335938,-4.17263439221813E-5,4.97573947991034E-7,1,0.999253354069792,40.0298881530762,1.99655059750805,19.4700006395578,-0.000473737310133709,-7.9941469259021E-5,0.25,2.00408245030345E-7,-4.18705996717866E-5,1.55840362597464E-7,199.993576,199.993576,-7088.5068359375,-7033.47705078125,57.5395834431792,20.6281251345632,23.288654,0,0,0,40,4449,199.9581,-7060.99194335938,,,,,,,,,,,,,0,,,,0.00245,,,,,,199.993576,,,,
,31607774.04,199.99391175,-2360.27978515625,-4.31310007499544E-5,3.63647660649777E-7,1,0.999253354069792,40.0298881530762,1.99666599757182,19.4700006395578,-0.000488865606678559,-8.7509560087494E-5,0.25,-2.22282993340957E-7,-4.32796377178183E-5,-2.69890115765309E-7,199.9930725,199.994751,-2390.275390625,-2330.2841796875,57.6482298073523,20.6273190188295,23.668306,0,0,0,40,4449,199.9644,-2360.27978515625,,,,,,,,,,,,,0,,,,-0.00245,,,,,,199.99391175,,,,
,31607865.675,199.99398805,2216.62121582031,-3.27978307638825E-6,3.15871866372053E-7,1,0.999253354069792,40.0298881530762,1.99670363384073,19.4700006395578,-3.81364574507424E-5,-1.12005827778939E-6,0.25,4.70941447649532E-7,-3.29161556817279E-6,4.69005213440809E-7,199.9936676,199.9943085,2184.26684570313,2248.9755859375,57.5200427301984,20.6226526019433,23.668306,0,0,0,40,4449,199.9696,2216.62121582031,,,,,,,,,,,,,0,,,,0.00245,,,,,,199.99398805,,,,
,31607961.345,199.99700165,6999.99340820312,3.40562934713035E-5,4.56863205188935E-7,1,0.999253354069792,40.0298881530762,1.99669349514591,19.4700006395578,0.000387017784234123,6.33195294825056E-5,0.25,-3.33843213808655E-7,3.4174213292703E-5,-2.9805572712534E-7,199.9961853,199.997818,6972.59765625,7027.38916015625,57.4825245612753,20.625958384826,23.668306,0,0,0,40,4449,199.9621,6999.99340820312,,,,,,,,,,,,,0,,,,-0.00245,,,,,,199.99700165,,,,
,31608057.07,200.0010834,11783.2661132812,3.07996668441795E-5,5.81114061804086E-7,1,0.999253354069792,40.0298881530762,1.9968328954595,19.4700006395578,0.00034901604732894,6.31213581248104E-5,0.25,2.14010005969551E-7,3.09057544165543E-5,2.48107203051697E-7,200.0003357,200.0018311,11755.6611328125,11810.87109375,57.5036285312945,20.6161239363202,23.668306,0,0,0,40,4449,199.96305,11783.2661132812,,,,,,,,,,,,,0,,,,-0.0049,,,,,,200.0010834,,,,
,31608153.53,200.00447845,16606.0625,1.82218961054927E-5,1.03373113176447E-6,1,0.999253354069792,40.0298881530762,1.99679517028741,19.4700006395578,0.000205569476362078,4.26055989400492E-5,0.25,5.90449789677316E-7,1.82841615332851E-5,6.12192482378216E-7,200.0041046,200.0048523,16578.52734375,16633.59765625,57.7342089444676,20.6202406523896,23.668306,0,0,0,40,4449,199.961,16606.0625,,,,,,,,,,,,,0,,,,0,,,,,,200.00447845,,,,
,31608249.145,200.0088654,21383.109375,3.0147146990343E-6,8.36321666950698E-7,1,0.999253354069792,40.0298881530762,1.99670963754799,19.4700006395578,3.38842142809313E-5,7.76692226386183E-6,0.25,1.61010838480822E-7,3.02494833000543E-6,1.64821363358987E-7,200.0088654,200.0088654,21350.681640625,21415.537109375,57.2324034351214,20.6203034571475,24.047956,0,0,0,40,4449,199.95285,21383.109375,,,,,,,,,,,,,0,,,,0,,,,,,200.0088654,,,,
,31608344.26,200.0113831,26138.3671875,-1.22812603596286E-5,1.00207382291437E-6,1,0.999253354069792,40.0298881530762,1.9966950694154,19.4700006395578,-0.000139433005523034,-2.35949715619272E-5,0.25,5.32362893350031E-8,-1.23237176170159E-5,4.0183661257902E-8,200.0113831,200.0113831,26108.455078125,26168.279296875,57.5849178972945,20.6213196607117,23.668306,0,0,0,40,4449,199.944,26138.3671875,,,,,,,,,,,,,0,,,,0,,,,,,200.0113831,,,,
,31608441.19,200.0094604,30983.7958984375,-2.86156951203167E-5,1.27874094845595E-6,1,0.999253354069792,40.0298881530762,1.99676913969181,19.4700006395578,-0.00032653824194834,-4.55152837785146E-5,0.25,9.58142969084257E-7,-2.87155288493252E-5,9.30665434173241E-7,200.0094604,200.0094604,30981.283203125,30986.30859375,57.4457880208715,20.6194599990781,23.288654,0,0,0,40,4449,199.9372,30983.7958984375,,,,,,,,,,,,,0,,,,-0.00245,,,,,,200.0094604,,,,
,31608536.355,200.0125275,35738.85546875,-4.40906356028325E-5,1.45582094154475E-6,1,0.999253354069792,40.0298881530762,1.99661502545144,19.4700006395578,-0.000501251888802832,-8.06973658604061E-5,0.25,5.44178763438998E-7,-4.42434621480358E-5,4.98709299147248E-7,200.0125275,200.0125275,35708.8046875,35768.90625,57.251162519583,20.6216942347498,23.668306,0,0,0,40,4449,199.9287,35738.85546875,,,,,,,,,,,,,0,,,,0,,,,,,200.0125275,,,,
,31608633.805,200.0116882,40609.328125,-6.14821249760201E-5,1.72667223143766E-6,1,0.999253354069792,40.0298881530762,1.99680252334007,19.4700006395578,-0.000700786727224426,-0.000102439920552161,0.25,1.64880690711821E-6,-6.16962059207318E-5,1.58859905220334E-6,200.0116882,200.0116882,40606.76953125,40611.88671875,57.2839909173907,20.6204225738301,23.288654,0,0,0,40,4449,199.9149,40609.328125,,,,,,,,,,,,,0,,,,0,,,,,,200.0116882,,,,
,31608730.23,200.0103912,45429.77734375,-7.86409346941185E-5,2.27293241396549E-6,1,0.999253354069792,40.0298881530762,1.9966792489678,19.4700006395578,-0.00089442328148711,-0.000141908566234962,0.25,1.14917099359633E-6,-7.89137585804872E-5,1.06900830230259E-6,200.0103912,200.0103912,45400.00390625,45459.55078125,56.9682129956214,20.6195789617839,24.047956,0,0,0,40,4449,199.9066,45429.77734375,,,,,,,,,,,,,0,,,,-0.00245,,,,,,200.0103912,,,,
,31608826.575,200.01297,50247.166015625,-9.759235452598E-5,2.0435346002574E-6,1,0.999253354069792,40.0298881530762,1.99669398510265,19.4700006395578,-0.00110807018897447,-0.00018707819044382,0.25,4.58916436083661E-7,-9.79299109621056E-5,3.56298840011152E-7,200.01297,200.01297,50242.19921875,50252.1328125,57.4723633905253,20.6189154824141,23.668306,0,0,0,40,4449,199.8958,50247.166015625,,,,,,,,,,,,,0,,,,0,,,,,,200.01297,,,,
,31608924.05,200.0140457,55117.03125,-0.000112902889753141,1.75113779107899E-6,1,0.999253354069792,40.0298881530762,1.99650652164412,19.4700006395578,-0.00128108024875845,-0.000220509349906001,0.25,1.69135094627671E-7,-0.000113293047323115,4.94105487862018E-8,200.013916,200.0141754,55084.61328125,55149.44921875,57.3004051162945,20.6236866204795,23.668306,0,0,0,40,4449,199.88445,55117.03125,,,,,,,,,,,,,0,,,,0.0049,,,,,,200.0140457,,,,
,31609021.265,200.0115433,59977.4453125,-0.00013226011273749,2.66754856591346E-6,1,0.999253354069792,40.0298881530762,1.99649434988667,19.4700006395578,-0.00149969634342977,-0.000264171605684548,0.25,-3.18498695335704E-7,-0.000132716665752868,-4.6024707486448E-7,200.0114136,200.011673,59947.54296875,60007.34765625,57.3856026248907,20.6242347919823,23.668306,0,0,0,40,4449,199.8746,59977.4453125,,,,,,,,,,,,,0,,,,0,,,,,,200.0115433,,,,
,31609118.4,200.0111084,64830.615234375,-0.000147724321777387,2.56231448821129E-6,1,0.999253354069792,40.0298881530762,1.99663992217675,19.4700006395578,-0.00168099835187445,-0.000261473219754798,0.25,2.60630447119637E-6,-0.000148237449599285,2.45854118867816E-6,200.0111084,200.0111084,64800.47265625,64860.7578125,56.9783741663714,20.621310252968,23.668306,0,0,0,40,4449,199.86545,64830.615234375,,,,,,,,,,,,,0,,,,0,,,,,,200.0111084,,,,
,31609214.47,200.0127563,69633.37890625,-0.000165853164967768,2.67017417108678E-6,1,0.999253354069792,40.0298881530762,1.99649459038599,19.4700006395578,-0.00188260885282353,-0.000319753941148339,0.25,6.15013886008448E-7,-0.000166426853909986,4.41497413690377E-7,200.0127563,200.0127563,69598.3515625,69668.40625,57.5270773868715,20.6241462934523,23.288654,0,0,0,40,4449,199.8556,69633.37890625,,,,,,,,,,,,,0,,,,0,,,,,,200.0127563,,,,
,31609311.585,200.01137545,74488.6171875,-0.000184162922014655,3.13186322662358E-6,1,0.999253354069792,40.0298881530762,1.99648454592501,19.4700006395578,-0.00208799889077669,-0.000369078430190881,0.25,-5.53968041761759E-7,-0.00018479870463194,-7.50496988090528E-7,200.0108643,200.0118866,74461.15625,74516.078125,57.495030617583,20.6216028270709,23.668306,0,0,0,40,4449,199.84845,74488.6171875,,,,,,,,,,,,,0,,,,0.00245,,,,,,200.01137545,,,,
,31609409.825,200.0115509,79396.33984375,-0.00019938796256537,2.79067758741871E-6,1,0.999253354069792,40.0298881530762,1.99651520390848,19.4700006395578,-0.00226603411093138,-0.000368598189545471,0.25,2.13240237380129E-6,-0.000200079252911407,1.92952214465346E-6,200.0115509,200.0115509,79394.0390625,79398.640625,57.5427099572561,20.6213667829354,23.668306,0,0,0,40,4449,199.83645,79396.33984375,,,,,,,,,,,,,0,,,,0,,,,,,200.0115509,,,,
,31609506.36,200.0101471,84222.54296875,-0.000216206590512482,2.9394769144503E-6,1,0.999253354069792,40.0298881530762,1.99658498177155,19.4700006395578,-0.00245159350685974,-0.000432332577462704,0.25,-5.64491833544636E-7,-0.000216953241061337,-7.93931435701105E-7,200.0101471,200.0101471,84217.4453125,84227.640625,57.0463758475445,20.6199955648736,23.668306,0,0,0,40,4449,199.8296,84222.54296875,,,,,,,,,,,,,0,,,,0,,,,,,200.0101471,,,,
,31609599.945,200.01120755,88900.52734375,-0.000233097910469932,3.25186398514745E-6,1,0.999253354069792,40.0298881530762,1.99667619844147,19.4700006395578,-0.00265001337776926,-0.000427137642588772,0.25,2.82787515366482E-6,-0.000233906568412625,2.59290011611563E-6,200.0106506,200.0117645,88875.4765625,88925.578125,57.5200427301984,20.6161891074357,23.288654,0,0,0,40,4449,199.8164,88900.52734375,,,,,,,,,,,,,0,,,,0,,,,,,200.01120755,,,,
,31609707.345,200.00637055,86503.453125,-0.000224177721870344,2.83017630447559E-6,1,0.999253354069792,40.0298881530762,1.99650432726941,19.4700006395578,-0.00254734942719857,-0.000416769492730508,0.25,2.19000492137061E-6,-0.000224954878531732,1.96192603523947E-6,200.0063019,200.0064392,86478.7890625,86528.1171875,57.4082698519484,20.6208189820372,23.668306,0,0,0,40,4449,199.81445,86503.453125,,,,,,,,,,,,,0,,,,0,,,,,,200.00637055,,,,
,31609801.75,200.00191495,81782.546875,-0.000207482215301887,3.46634239649738E-6,1,0.999253354069792,40.0298881530762,1.99670193258888,19.4700006395578,-0.00235400749405574,-0.000407948190656506,0.25,7.22264398985012E-8,-0.000208199401989441,-1.46095340031362E-7,200.00177,200.0020599,81754.8671875,81810.2265625,57.3668435404292,20.6151986249997,24.047956,0,0,0,40,4449,199.8168,81782.546875,,,,,,,,,,,,,0,,,,0.00245,,,,,,200.00191495,,,,
,31609897.56,199.9952698,76990.97265625,-0.000191367746301753,3.02269836163164E-6,1,0.999253354069792,40.0298881530762,1.99663048414094,19.4700006395578,-0.00218254392858869,-0.000310381828037545,0.25,5.87333528711161E-6,-0.00019203534166079,5.6916053866584E-6,199.9952698,199.9952698,76960.8671875,77021.078125,57.2746113751599,20.6154417713474,23.288654,0,0,0,40,4449,199.82405,76990.97265625,,,,,,,,,,,,,0,,,,0,,,,,,199.9952698,,,,
,31609997.77,199.99084475,71982.7265625,-0.000172095117888096,3.30126264372402E-6,1,0.999253354069792,40.0298881530762,1.99657811795809,19.4700006395578,-0.00195558718810791,-0.000320020695633345,0.25,1.67648818349694E-6,-0.000172691644136274,1.50019219498798E-6,199.9906006,199.9910889,71957.5625,72007.890625,57.1706547821022,20.6217839349063,23.668306,0,0,0,40,4449,199.82855,71982.7265625,,,,,,,,,,,,,0,,,,0.00245,,,,,,199.99084475,,,,
,31610094.505,199.989151,67147.296875,-0.000151550889403074,3.08291848156445E-6,1,0.999253354069792,40.0298881530762,1.99663970603537,19.4700006395578,-0.00171743110769899,-0.000309199686517054,0.25,-9.36266673356362E-7,-0.000152073608561807,-1.10019504549164E-6,199.989151,199.989151,67114.6171875,67179.9765625,57.4106147375061,20.6178842123913,24.047956,0,0,0,40,4449,199.8354,67147.296875,,,,,,,,,,,,,0,,,,0,,,,,,199.989151,,,,
,31610192.085,199.9897919,62268.603515625,-0.000138996210905432,2.27506196158044E-6,1,0.999253354069792,40.0298881530762,1.99658386071566,19.4700006395578,-0.00157910886601589,-0.000260575763924267,0.25,1.16921564119454E-6,-0.000139477732835184,1.02556809101483E-6,199.9897919,199.9897919,62265.9140625,62271.29296875,57.4489145349484,20.6209397221362,23.668306,0,0,0,40,4449,199.8479,62268.603515625,,,,,,,,,,,,,0,,,,0,,,,,,199.9897919,,,,
,31610289.5,199.98909,57400.779296875,-0.000119237456750066,3.21081771960556E-6,1,0.999253354069792,40.0298881530762,1.99668597163195,19.4700006395578,-0.00135378051926893,-0.000228835104699605,0.25,5.36962209064723E-7,-0.000119649999373149,4.11860531300806E-7,199.98909,199.98909,57378.1640625,57423.39453125,57.5372385576215,20.6187900184791,23.668306,0,0,0,40,4449,199.8549,57400.779296875,,,,,,,,,,,,,0,,,,-0.0049,,,,,,199.98909,,,,
,31610387.805,199.987442,52485.619140625,-0.000102204523398669,2.4518691659096E-6,1,0.999253354069792,40.0298881530762,1.9965631543875,19.4700006395578,-0.00116000585089847,-0.000197978797134317,0.25,2.97921424773653E-7,-0.000102557935703653,1.89905905023172E-7,199.9873047,199.9875793,52460.8828125,52510.35546875,57.3840393678522,20.6245279335193,23.288654,0,0,0,40,4449,199.86435,52485.619140625,,,,,,,,,,,,,0,,,,0.00245,,,,,,199.987442,,,,
,31610485.22,199.987915,47618.2578125,-8.21313326374562E-5,2.07126806456174E-6,1,0.999253354069792,40.0298881530762,1.99657311795366,19.4700006395578,-0.000934574790765187,-0.000145320426284257,0.25,1.45391863996823E-6,-8.24166062349967E-5,1.37113881104957E-6,199.987915,199.987915,47588.421875,47648.09375,57.4887775894292,20.6248991564017,23.288654,0,0,0,40,4449,199.87555,47618.2578125,,,,,,,,,,,,,0,,,,-0.00245,,,,,,199.987915,,,,
,31610579.32,199.9889832,42912.646484375,-6.78562883903157E-5,2.19580511614544E-6,1,0.999253354069792,40.0298881530762,1.99668341318569,19.4700006395578,-0.000768327929116136,-0.000142243579193914,0.25,-7.53263016429018E-7,-6.80898655998516E-5,-8.28545764881413E-7,199.9889832,199.9889832,42879.90625,42945.38671875,57.3754414541407,20.6255976033662,23.288654,0,0,0,40,4449,199.88085,42912.646484375,,,,,,,,,,,,,0,,,,-0.00245,,,,,,199.9889832,,,,
,31610674.33,199.9870911,38165.3671875,-5.15695347952609E-5,1.76848343637129E-6,1,0.999253354069792,40.0298881530762,1.9967134166565,19.4700006395578,-0.000585058716057813,-0.000101566947269744,0.25,3.85003446941891E-9,-5.17476547396214E-5,-5.14753523037471E-8,199.9870911,199.9870911,38138.015625,38192.71875,57.2769562607176,20.6225341679948,23.668306,0,0,0,40,4449,199.8928,38165.3671875,,,,,,,,,,,,,0,,,,-0.00245,,,,,,199.9870911,,,,
,31610771.775,199.9903107,33298.060546875,-3.6777898398307E-5,1.46142793492094E-6,1,0.999253354069792,40.0298881530762,1.99674292237999,19.4700006395578,-0.000417657877422886,-7.01024025915178E-5,0.25,2.08477146906799E-7,-3.69051347972329E-5,1.69657045861558E-7,199.9903107,199.9903107,33295.19140625,33300.9296875,57.5856995258138,20.6238127324159,23.288654,0,0,0,40,4449,199.90165,33298.060546875,,,,,,,,,,,,,0,,,,0,,,,,,199.9903107,,,,
,31610866.53,199.9903183,28560.849609375,-1.93890627520588E-5,1.36742642628628E-6,1,0.999253354069792,40.0298881530762,1.99670162192448,19.4700006395578,-0.000221905653087864,-2.70328403386055E-5,0.25,9.84700600644057E-7,-1.94570777994436E-5,9.67217935576782E-7,199.9898071,199.9908295,28533.251953125,28588.447265625,57.4309370790061,20.6242861670135,23.288654,0,0,0,40,4449,199.9047,28560.849609375,,,,,,,,,,,,,0,,,,-0.00245,,,,,,199.9903183,,,,
,31610964.76,199.9877472,23650.291015625,-3.91698328474921E-6,1.32628401040217E-6,1,0.999253354069792,40.0298881530762,1.99666535281203,19.4700006395578,-4.44113304925516E-5,-7.86385527271156E-6,0.25,-1.28611828520728E-8,-3.93049478852854E-6,-1.71319581519188E-8,199.9877472,199.9877472,23615.1875,23685.39453125,57.2183341217753,20.6261143151376,23.668306,0,0,0,40,4449,199.9118,23650.291015625,,,,,,,,,,,,,0,,,,-0.00245,,,,,,199.9877472,,,,
,31611059.22,199.9872131,18930.3349609375,1.07664859391631E-5,8.84378249837076E-7,1,0.999253354069792,40.0298881530762,1.99666845327605,19.4700006395578,0.000122913209724909,1.67727196122983E-5,0.25,-3.91515794963585E-7,1.08040832635635E-5,-3.81231924060917E-7,199.9872131,199.9872131,18903.0078125,18957.662109375,57.2957153451791,20.6241948142839,23.668306,0,0,0,40,4449,199.92455,18930.3349609375,,,,,,,,,,,,,0,,,,0.00245,,,,,,199.9872131,,,,
,31611155.375,199.99007415,14125.6293945313,2.60892170700257E-5,1.07501946321204E-6,1,0.999253354069792,40.0298881530762,1.99667259153483,19.4700006395578,0.000294867453369236,5.77710229662212E-5,0.25,5.60983188013124E-7,2.61786808623228E-5,5.91159971225829E-7,199.9899902,199.9901581,14095.8896484375,14155.369140625,57.657609349583,20.6250638827707,24.047956,0,0,0,40,4449,199.9349,14125.6293945313,,,,,,,,,,,,,0,,,,0,,,,,,199.99007415,,,,
,31611251.6,199.9904785,9313.294921875,3.80182481090944E-5,6.53782697615471E-7,1,0.999253354069792,40.0298881530762,1.99683431299157,19.4700006395578,0.000431426835791643,7.43986627770008E-5,0.25,-4.58299999547839E-8,3.81495430448733E-5,-4.77253982354197E-9,199.9904785,199.9904785,9288.2890625,9338.30078125,57.77250874191,20.6233612494408,23.668306,0,0,0,40,4449,199.93575,9313.294921875,,,,,,,,,,,,,0,,,,-0.00245,,,,,,199.9904785,,,,
,31611346.595,199.9924927,4567.81616210937,4.49084198110834E-5,5.27108364499822E-7,1,0.999253354069792,40.0298881530762,1.99651505561988,19.4700006395578,0.000509308671662165,8.91880972412121E-5,0.25,6.21077097674556E-8,4.50633713220617E-5,1.11070532511922E-7,199.9924927,199.9924927,4540.23486328125,4595.3974609375,57.5247325013138,20.6280082983716,24.047956,0,0,0,40,4449,199.947,4567.81616210937,,,,,,,,,,,,,0,,,,0.0049,,,,,,199.9924927,,,,
,31611437.78,199.994545,-0.388206228613853,3.46673196160639E-5,3.85217054499227E-7,1,0.999253354069792,40.0298881530762,1.99677288274548,19.4700006395578,0.000393772093638522,6.56342837950829E-5,0.25,-2.36219401614296E-7,3.4787236181115E-5,-1.99365774950376E-7,199.9944611,199.9946289,-0.42626565694809,-0.350146800279617,57.4231207938138,20.6252617936873,23.668306,0,0,0,40,4417,199.95025,-0.388206228613853,,,,,,,,,,,,,0,,,,0.00245,,,,,,199.994545,,,,