File: data/doubleLayers/dl_0-25/ppms/data/DD205_10_HYST_100OE_20K.DAT
[Header]
; VSM Data File (default extension .dat)
; Copyright (c) 2003-2013, Quantum Design, Inc. All rights reserved.
TITLE,
FILEOPENTIME,31552168.88,01/01/2019,12:31 pm
BYAPP,VSM,2.0,2.0
INFO,PPMS VSM Option Release 1.4.10 Build 1,APPNAME
INFO,Quantum Design Linear Motor Servo Controller,MOTOR_MODULE_NAME
INFO,3101-100 M1,MOTOR_HW_VERSION
INFO,MMC1014,MOTOR_SERIAL_NUMBER
INFO,SRV No X-over 01.03.11,MOTOR_SOFTWARE_VERSION
INFO,Quantum Design VSM Detection Module,VSM_MODULE_NAME
INFO,3101-150 F0,VSM_HW_VERSION
INFO,VSM707,VSM_SERIAL_NUMBER
INFO,VSM No X-over 01.02.05 May 20 2008 13:51:47,VSM_SOFTWARE_VERSION
INFO,704,PREAMP_SERIAL_NUMBER
INFO,822,COIL_SERIAL_NUMBER
INFO,0,MOMENT_UNITS
INFO,CoFe2O4,SAMPLE_MATERIAL
INFO,Double Layer thin concentration,SAMPLE_COMMENT
INFO,27.44,SAMPLE_MASS
INFO,,SAMPLE_VOLUME
INFO,,SAMPLE_MOLECULAR_WEIGHT
INFO,,SAMPLE_SIZE
INFO,,SAMPLE_SHAPE
DATATYPE,COMMENT,1
DATATYPE,TIME,2
STARTUPAXIS,X,2
STARTUPAXIS,Y1,5
[Data]
Comment,Time Stamp (sec),Temperature (K),Magnetic Field (Oe),Moment (emu),M. Std. Err. (emu),Transport Action,Averaging Time (sec),Frequency (Hz),Peak Amplitude (mm),Center Position (mm),Coil Signal' (mV),Coil Signal" (mV),Range (mV),M. Quad. Signal (emu),M. Raw' (emu),M. Raw" (emu),Min. Temperature (K),Max. Temperature (K),Min. Field (Oe),Max. Field (Oe),Mass (grams),Motor Lag (deg),Pressure (Torr),VSM Status (code),Motor Status (code),Measure Status (code),Measure Count,PPMS Status (code),System Temp. (K),System Field (Oe),Sample Position (deg),Bridge 1 Resistance (ohms),Bridge 1 Excitation (에),Bridge 2 Resistance (ohms),Bridge 2 Excitation (에),Bridge 3 Resistance (ohms),Bridge 3 Excitation (에),Bridge 4 Resistance (ohms),Bridge 4 Excitation (에),Signal 1 Vin (V),Signal 2 Vin (V),Digital Inputs (code),Drive 1 Iout (mA),Drive 1 Ipower (W),Drive 2 Iout (mA),Drive 2 Ipower (W),Pressure (),Map 20 (),Map 21 (),Map 22 (),Map 23 (),Map 24 (),Map 25 (),Map 26 (),Map 27 (),Map 28 (),Map 29 ()
,31552183.3,20.0009747,-0.365370541810989,,,2,,,,20.3100003236532,,,,,,,20.0009747,20.0009747,-0.365370541810989,-0.365370541810989,,,13.038077,,,,-99999999,4369,20.0117,-0.365370541810989,,,,,,,,,,,,,,,,,,,,,,,20.0009747,,,,
,31552337.785,20.0007935,5152.68310546875,5.50671717756609E-5,3.63775560140548E-7,1,0.999253354069792,40.0298881530762,1.98455223674815,20.2600006014109,0.000615217283675723,0.000109021232821656,0.25,-3.83947478885114E-8,5.4766556983633E-5,2.46094556906255E-7,20.0007935,20.0007935,5150.46728515625,5154.89892578125,56.6016292201021,20.6240356614123,13.797379,0,0,0,40,4449,20.0115,5152.68310546875,,,,,,,,,,,,,0,,,,0,,,,,,20.0007935,,,,
,31552443.33,20.0009365,10426.8720703125,3.90535903459755E-5,3.10631555401974E-7,1,0.999253354069792,40.0298881530762,1.98446375530819,20.2600006014109,0.000437802920873555,6.98637610627478E-5,0.25,-7.11798808363978E-7,3.8859754584219E-5,-4.91586054125659E-7,20.0009365,20.0009365,10396.87890625,10456.865234375,56.6641595016406,20.6296860532346,13.797379,0,0,0,40,4449,20.0104,10426.8720703125,,,,,,,,,,,,,0,,,,0,,,,,,20.0009365,,,,
,31552548.295,20.0005436,15671.439453125,2.35906842028745E-5,3.93415393468945E-7,1,0.999253354069792,40.0298881530762,1.98436658871773,20.2600006014109,0.000263699092322867,4.7092626416169E-5,0.25,-2.8669563440946E-9,2.34819677849256E-5,1.36860793142609E-7,20.0005436,20.0005436,15639.1474609375,15703.7314453125,56.7352876968906,20.632862552512,13.797379,0,0,0,40,4449,20.0092,15671.439453125,,,,,,,,,,,,,0,,,,-0.00245,,,,,,20.0005436,,,,
,31552647.39,20.002449,20623.77734375,8.32496915247361E-6,4.63344054239435E-7,1,0.999253354069792,40.0298881530762,1.9843634414242,20.2600006014109,9.38200586766518E-5,1.26120159854594E-5,0.25,-3.62736846431427E-7,8.29277161851129E-6,-3.09188348778143E-7,20.002449,20.002449,20596.2421875,20651.3125,56.8001628639868,20.6335882190775,13.038077,0,0,0,40,4449,20.0076,20623.77734375,,,,,,,,,,,,,0,,,,0.00245,,,,,,20.002449,,,,
,31552742.88,20.0020714,25396.751953125,-6.65244687807416E-6,5.63782200427047E-7,1,0.999253354069792,40.0298881530762,1.98434810299728,20.2600006014109,-7.19206075052007E-5,-2.72967419447225E-5,0.25,-1.24694519136986E-6,-6.61993566833283E-6,-1.28585941471354E-6,20.0020714,20.0020714,25369.1953125,25424.30859375,56.8032893780637,20.6354008814926,13.417728,0,0,0,40,4449,20.0058,25396.751953125,,,,,,,,,,,,,0,,,,-0.00245,,,,,,20.0020714,,,,
,31552837.84,20.00207805,30144.396484375,-2.09291421306799E-5,6.49920496767294E-7,1,0.999253354069792,40.0298881530762,1.98427568062315,20.2600006014109,-0.000230822904214025,-6.10742509764491E-5,0.25,-1.69834571438351E-6,-2.08512799513318E-5,-1.83488234053194E-6,20.001976,20.0021801,30112.15625,30176.63671875,56.760299809506,20.6390481801265,13.797379,0,0,0,40,4449,20.004,30144.396484375,,,,,,,,,,,,,0,,,,-0.0049,,,,,,20.00207805,,,,
,31552933.68,20.0016556,34931.931640625,-3.60891093964797E-5,6.88919448080392E-7,1,0.999253354069792,40.0298881530762,1.98428554754999,20.2600006014109,-0.000403652817588821,-7.51292252655481E-5,0.25,-2.2080024960246E-7,-3.59913852198314E-5,-4.72388486255295E-7,20.0016556,20.0016556,34904.3828125,34959.48046875,56.9314764552176,20.6386815563199,13.038077,0,0,0,40,4449,20.0018,34931.931640625,,,,,,,,,,,,,0,,,,0,,,,,,20.0016556,,,,
,31553027.35,20.00150105,39614.482421875,-5.18802252961937E-5,8.61993480456808E-7,1,0.999253354069792,40.0298881530762,1.9841305528393,20.2600006014109,-0.000575698401690279,-0.000134839697756989,0.25,-2.70088630408312E-6,-5.17483613165868E-5,-3.0659737376208E-6,20.0014324,20.0015697,39581.6484375,39647.31640625,56.8087607776983,20.6392895472229,13.038077,0,0,0,40,4449,20.00075,39614.482421875,,,,,,,,,,,,,0,,,,0,,,,,,20.00150105,,,,
,31553122.72,20.0011978,44379.392578125,-6.79495941550422E-5,8.59263156286737E-7,1,0.999253354069792,40.0298881530762,1.98421825850051,20.2600006014109,-0.000757127808834918,-0.000161668415022766,0.25,-2.18789131227737E-6,-6.78202469624078E-5,-2.67865373376551E-6,20.0010872,20.0013084,44349.625,44409.16015625,57.1432977839291,20.6405444839834,13.797379,0,0,0,40,4449,19.99965,44379.392578125,,,,,,,,,,,,,0,,,,0,,,,,,20.0011978,,,,
,31553219.3,20.0011568,49207.685546875,-8.27168510440825E-5,8.34213520231852E-7,1,0.999253354069792,40.0298881530762,1.9840837819035,20.2600006014109,-0.000922208852225602,-0.000196113740297767,0.25,-2.58717658336796E-6,-8.2600853186462E-5,-3.19342719151902E-6,20.0009804,20.0013332,49177.75390625,49237.6171875,57.1472059265253,20.6407528766186,13.417728,0,0,0,40,4449,19.99835,49207.685546875,,,,,,,,,,,,,0,,,,0.0049,,,,,,20.0011568,,,,
,31553313.62,20.00047015,53922.7109375,-0.000101705162302177,9.69700172673878E-7,1,0.999253354069792,40.0298881530762,1.98415384675453,20.2600006014109,-0.00113780139424197,-0.000222839909399495,0.25,-1.53439016547032E-6,-0.000101622624731813,-2.28789395610342E-6,20.0002098,20.0007305,53895.078125,53950.34375,57.0291800201214,20.6421592269213,13.417728,0,0,0,40,4449,19.99845,53922.7109375,,,,,,,,,,,,,0,,,,-0.00245,,,,,,20.00047015,,,,
,31553407.625,20.0014763,58620.4296875,-0.000114933161863222,1.14785290619062E-6,1,0.999253354069792,40.0298881530762,1.98415455748348,20.2600006014109,-0.00128179089024341,-0.000277348572253103,0.25,-3.99595854915153E-6,-0.000114875241016444,-4.85031270736115E-6,20.0014763,20.0014763,58598.015625,58642.84375,56.7415407250445,20.6413348645321,13.417728,0,0,0,40,4449,19.9973,58620.4296875,,,,,,,,,,,,,0,,,,-0.00245,,,,,,20.0014763,,,,
,31553503.17,20.0015774,63395.912109375,-0.000133060148349215,1.41153373468202E-6,1,0.999253354069792,40.0298881530762,1.98408188250273,20.2600006014109,-0.00148510431793576,-0.000318190755162465,0.25,-4.35721330267998E-6,-0.000133054062201683,-5.34770288041644E-6,20.0015774,20.0015774,63365.8984375,63425.92578125,57.1307917276214,20.6398943483279,13.417728,0,0,0,40,4449,19.9964,63395.912109375,,,,,,,,,,,,,0,,,,0,,,,,,20.0015774,,,,
,31553599.39,20.0020847,68206.18359375,-0.000149136989605391,1.07819448301216E-6,1,0.999253354069792,40.0298881530762,1.98400796565057,20.2600006014109,-0.00167116861126571,-0.000323601197685885,0.25,-1.93495757424219E-6,-0.000149215590588976,-3.04099581969497E-6,20.0018768,20.0022926,68178.8125,68233.5546875,57.0690430746022,20.6431926244512,13.797379,0,0,0,40,4449,19.9945,68206.18359375,,,,,,,,,,,,,0,,,,0.00245,,,,,,20.0020847,,,,
,31553695.535,20.00145245,73013.89453125,-0.000163304074593233,1.37224871958134E-6,1,0.999253354069792,40.0298881530762,1.98388852881733,20.2600006014109,-0.00183287571326055,-0.000341564764588238,0.25,-9.79470863216644E-7,-0.000163464478018979,-2.18200975191348E-6,20.0014458,20.0014591,72986.234375,73041.5546875,56.8470605751406,20.6437728851524,13.417728,0,0,0,40,4449,19.99345,73013.89453125,,,,,,,,,,,,,0,,,,-0.00245,,,,,,20.00145245,,,,
,31553789.57,20.00075055,77711.92578125,-0.000182045445973309,1.30067682750792E-6,1,0.999253354069792,40.0298881530762,1.98407283275333,20.2600006014109,-0.00204484501534456,-0.000377161081252992,0.25,-7.68396489901937E-7,-0.000182294488195404,-2.09674360282811E-6,20.0006828,20.0008183,77684.3828125,77739.46875,57.0471574760637,20.6405482600007,13.417728,0,0,0,40,4449,19.9908,77711.92578125,,,,,,,,,,,,,0,,,,-0.00245,,,,,,20.00075055,,,,
,31553886.225,20.00163075,82545.14453125,-0.00019978183127335,1.36748973359375E-6,1,0.999253354069792,40.0298881530762,1.98391968635097,20.2600006014109,-0.00224010790820585,-0.000439613570634531,0.25,-3.13603395641827E-6,-0.000200110789037234,-4.58143131420227E-6,20.0015106,20.0017509,82512.890625,82577.3984375,56.7814037795252,20.6444621582273,13.417728,0,0,0,40,4449,19.99005,82545.14453125,,,,,,,,,,,,,0,,,,0.0049,,,,,,20.00163075,,,,
,31553978.24,20.0029469,87145.72265625,-0.000213946783721979,1.43499497523136E-6,1,0.999253354069792,40.0298881530762,1.98416938575273,20.2600006014109,-0.00239885250666233,-0.000477370804877609,0.25,-3.94538036247699E-6,-0.000214364286591504,-5.47606302023294E-6,20.0029469,20.0029469,87115.78125,87175.6640625,56.953362053756,20.6393564103457,13.417728,0,0,0,40,4449,19.9889,87145.72265625,,,,,,,,,,,,,0,,,,0,,,,,,20.0029469,,,,
,31554085.165,20.00127505,88269.6953125,-0.000216569260194329,2.17126906725774E-6,1,0.999253354069792,40.0298881530762,1.98403920571624,20.2600006014109,-0.00242499567516244,-0.000501538474791334,0.25,-5.62653980349349E-6,-0.000216996834630186,-7.17467358829824E-6,20.0011997,20.0013504,88247.140625,88292.25,57.1503324406022,20.6374524270559,13.797379,0,0,0,40,4449,19.98815,88269.6953125,,,,,,,,,,,,,0,,,,0,,,,,,20.00127505,,,,
,31554176.395,20.0004864,83709.17578125,-0.000201125901310904,1.26269537461077E-6,1,0.999253354069792,40.0298881530762,1.98386267981179,20.2600006014109,-0.00225649791381006,-0.00043596963356347,0.25,-2.57242586733458E-6,-0.000201478154228057,-4.02229074590336E-6,20.0004864,20.0004864,83679.2890625,83739.0625,57.0057311645445,20.6399648627351,13.038077,0,0,0,40,4449,19.98775,83709.17578125,,,,,,,,,,,,,0,,,,0.0049,,,,,,20.0004864,,,,
,31554273.51,19.9993343,78852.69921875,-0.000186657746720219,1.32539164524478E-6,1,0.999253354069792,40.0298881530762,1.9838218535174,20.2600006014109,-0.00209783482320345,-0.00037974753721408,0.25,-1.725906549267E-7,-0.000186933864821814,-1.53029874349868E-6,19.9993343,19.9993343,78844.953125,78860.4453125,57.075296102756,20.6442279622611,13.417728,0,0,0,40,4449,19.9882,78852.69921875,,,,,,,,,,,,,0,,,,-0.0049,,,,,,19.9993343,,,,
,31554370.925,19.99900725,73984.66796875,-0.00017334790733826,1.40927229995435E-6,1,0.999253354069792,40.0298881530762,1.9837323511725,20.2600006014109,-0.00194264721735777,-0.000379027461865056,0.25,-2.5063784644805E-6,-0.000173521057616754,-3.7824171964384E-6,19.9989853,19.9990292,73952.0390625,74017.296875,56.8845787440637,20.648489476302,13.417728,0,0,0,40,4449,19.98955,73984.66796875,,,,,,,,,,,,,0,,,,-0.00245,,,,,,19.99900725,,,,
,31554468.29,19.99904635,69116.4609375,-0.000152459243972087,1.25781494488467E-6,1,0.999253354069792,40.0298881530762,1.98377494306453,20.2600006014109,-0.00170429384424971,-0.000353241300640474,0.25,-3.97756850774713E-6,-0.000152536711090559,-5.10857686323525E-6,19.9989853,19.9991074,69089.046875,69143.875,57.0330881627176,20.6496448393618,13.038077,0,0,0,40,4449,19.9908,69116.4609375,,,,,,,,,,,,,0,,,,0.00245,,,,,,19.99904635,,,,
,31554564.25,19.9991531,64320.96484375,-0.000134031808125302,9.30188150282714E-7,1,0.999253354069792,40.0298881530762,1.98387862661379,20.2600006014109,-0.00149355191933825,-0.000333691061849209,0.25,-5.56367368779857E-6,-0.000134028145854724,-6.56158164004178E-6,19.9991531,19.9991531,64291.05859375,64350.87109375,57.187068981006,20.6470759436025,13.417728,0,0,0,40,4449,19.9923,64320.96484375,,,,,,,,,,,,,0,,,,0.00245,,,,,,19.9991531,,,,
,31554659.695,19.9990749,59550.107421875,-0.000118821463025264,1.03149037517494E-6,1,0.999253354069792,40.0298881530762,1.98385589662253,20.2600006014109,-0.00132885590058046,-0.000265772532747849,0.25,-2.26487375688026E-6,-0.00011878589677751,-3.14892938990558E-6,19.9990749,19.9990749,59517.75390625,59582.4609375,57.2566339192176,20.6486827814445,13.038077,0,0,0,40,4449,19.9927,59550.107421875,,,,,,,,,,,,,0,,,,0.00245,,,,,,19.9990749,,,,
,31554756.065,19.99868105,54732.33984375,-9.9206067879388E-5,1.17913486821066E-6,1,0.999253354069792,40.0298881530762,1.98387480474709,20.2600006014109,-0.00110783572674045,-0.000228153711154558,0.25,-2.45908276546561E-6,-9.91262906808456E-5,-3.19418818686297E-6,19.9986,19.9987621,54699.8125,54764.8671875,57.1941036376791,20.646714667472,13.417728,0,0,0,40,4449,19.9946,54732.33984375,,,,,,,,,,,,,0,,,,-0.0049,,,,,,19.99868105,,,,
,31554849.26,19.9992599,50075.1796875,-8.46872769318578E-5,9.85787165462624E-7,1,0.999253354069792,40.0298881530762,1.98393352826384,20.2600006014109,-0.000946821641676149,-0.000186193278722782,0.25,-1.3461059219541E-6,-8.45855448242216E-5,-1.9694817375055E-6,19.9992599,19.9992599,50047.640625,50102.71875,57.2019199228714,20.6471830252735,13.417728,0,0,0,40,4449,19.99545,50075.1796875,,,,,,,,,,,,,0,,,,0.00245,,,,,,19.9992599,,,,
,31554943.515,19.9997101,45364.716796875,-6.92079851089935E-5,7.34038348434164E-7,1,0.999253354069792,40.0298881530762,1.98393378922272,20.2600006014109,-0.000775598471408308,-0.000139805645612206,0.25,-9.53711550347548E-9,-6.90994721156491E-5,-5.14568698258541E-7,19.9997101,19.9997101,45334.7265625,45394.70703125,57.1151591572368,20.6484917753734,13.417728,0,0,0,40,4449,19.99545,45364.716796875,,,,,,,,,,,,,0,,,,-0.0049,,,,,,19.9997101,,,,
,31555038.945,19.9991665,40591.8515625,-5.38207648440012E-5,7.64098215235069E-7,1,0.999253354069792,40.0298881530762,1.98395498740156,20.2600006014109,-0.000600291595440899,-0.000122945125733813,0.25,-1.28807008145454E-6,-5.3700301663604E-5,-1.67179203292197E-6,19.9991665,19.9991665,40586.8671875,40596.8359375,57.1307917276214,20.6484468671721,13.417728,0,0,0,40,4449,19.9957,40591.8515625,,,,,,,,,,,,,0,,,,0,,,,,,19.9991665,,,,
,31555134.82,19.998785,35801.84765625,-3.79200002155272E-5,7.73215007695174E-7,1,0.999253354069792,40.0298881530762,1.98401614054902,20.2600006014109,-0.00042106859123344,-9.58795201922147E-5,0.25,-1.7438659943281E-6,-3.78101879149449E-5,-2.00560469418954E-6,19.998785,19.998785,35774.62890625,35829.06640625,57.129228470583,20.6459088007623,13.038077,0,0,0,40,4449,19.99775,35801.84765625,,,,,,,,,,,,,0,,,,-0.00245,,,,,,19.998785,,,,
,31555230.76,19.9985409,31004,-2.26691789923656E-5,5.60093345879547E-7,1,0.999253354069792,40.0298881530762,1.98393727785785,20.2600006014109,-0.000249209561663637,-7.05168176379916E-5,0.25,-2.22912358807235E-6,-2.25841557517962E-5,-2.37688637348598E-6,19.9985409,19.9985409,30971.62109375,31036.37890625,57.1972301517561,20.6496182422721,13.417728,0,0,0,40,4449,19.9983,31004,,,,,,,,,,,,,0,,,,-0.00245,,,,,,19.9985409,,,,
,31555326.38,19.9989624,26228.8291015625,-6.54248498847072E-6,6.17150204754552E-7,1,0.999253354069792,40.0298881530762,1.98393699629315,20.2600006014109,-7.01724568007433E-5,-2.99127836279384E-5,0.25,-1.50052357991513E-6,-6.50920767070681E-6,-1.53821716206779E-6,19.9989624,19.9989624,26223.857421875,26233.80078125,57.1245386994676,20.6494502281709,13.417728,0,0,0,40,4449,19.9991,26228.8291015625,,,,,,,,,,,,,0,,,,0.00245,,,,,,19.9989624,,,,
,31555418.86,19.9981327,21603.6005859375,8.32188268210149E-6,4.72332187257904E-7,1,0.999253354069792,40.0298881530762,1.98374795573762,20.2600006014109,9.4576684682792E-5,8.08336727179003E-6,0.25,-7.67531510575591E-7,8.29307658957355E-6,-7.11891520890851E-7,19.9981022,19.9981632,21575.568359375,21631.6328125,57.0666981890445,20.6519016016963,13.417728,0,0,0,40,4449,20.00035,21603.6005859375,,,,,,,,,,,,,0,,,,-0.00245,,,,,,19.9981327,,,,
,31555512.695,19.9983978,16916.3896484375,2.23046900154231E-5,4.33410619818197E-7,1,0.999253354069792,40.0298881530762,1.9838006964569,20.2600006014109,0.000250532206228981,3.75432954329954E-5,0.25,-6.2873996612864E-7,2.22082200081633E-5,-4.91906704835408E-7,19.9983978,19.9983978,16914.068359375,16918.7109375,56.8462789466214,20.6515500803382,13.417728,0,0,0,40,4449,20.00225,16916.3896484375,,,,,,,,,,,,,0,,,,0,,,,,,19.9983978,,,,
,31555605.945,19.9980421,12254.1240234375,3.67989269472057E-5,4.24329218021056E-7,1,0.999253354069792,40.0298881530762,1.98368919465575,20.2600006014109,0.00041241905532695,6.59237579028935E-5,0.25,-6.65958746494292E-7,3.66219661453171E-5,-4.53689992706477E-7,19.998024,19.9980602,12222.048828125,12286.19921875,57.1894138665637,20.65403708402,13.417728,0,0,0,40,4449,20.00365,12254.1240234375,,,,,,,,,,,,,0,,,,-0.0049,,,,,,19.9980421,,,,
,31555699.835,19.9979076,7561.31518554687,5.10737281970106E-5,3.46156972724112E-7,1,0.999253354069792,40.0298881530762,1.98384022204664,20.2600006014109,0.000570756723476247,9.9691849520799E-5,0.25,-1.7039916824436E-7,5.08044715356586E-5,1.03042201151319E-7,19.9979076,19.9979076,7528.7158203125,7593.91455078125,57.2058280654676,20.6527240236895,13.797379,0,0,0,40,4449,20.0054,7561.31518554687,,,,,,,,,,,,,0,,,,-0.00245,,,,,,19.9979076,,,,
,31555793.725,19.9995899,2865.99011230469,6.42008734723036E-5,3.33047753563677E-7,1,0.999253354069792,40.0298881530762,1.98376330612351,20.2600006014109,0.000716644995895997,0.000128365941085551,0.25,8.43609227056446E-8,6.38403173121075E-5,4.05239996806544E-7,19.9995899,19.9995899,2836.09106445313,2895.88916015625,57.0299616486406,20.6518283237975,13.797379,0,0,0,40,4449,20.0056,2865.99011230469,,,,,,,,,,,,,0,,,,-0.00245,,,,,,19.9995899,,,,
,31555888.345,20.00018595,-1858.99688720703,7.25500863640168E-5,2.95401616791608E-7,1,0.999253354069792,40.0298881530762,1.98385089895538,20.2600006014109,0.000809457806729529,0.000147155754546875,0.25,2.87908858629627E-7,7.2137531971287E-5,6.44785764806465E-7,20.000185,20.0001869,-1888.81457519531,-1829.17919921875,56.9596150819099,20.6527807238181,13.417728,0,0,0,40,4449,20.00505,-1858.99688720703,,,,,,,,,,,,,0,,,,0,,,,,,20.00018595,,,,
,31555983.52,19.99909685,-6614.46166992188,8.27981496710098E-5,3.54277467735159E-7,1,0.999253354069792,40.0298881530762,1.98377135864517,20.2600006014109,0.000924344483489467,0.000166323393560598,0.25,1.52552583098796E-7,8.23535732771984E-5,5.87854542017894E-7,19.9990711,19.9991226,-6641.92333984375,-6587,57.2456911199484,20.6540072348501,13.417728,0,0,0,40,4449,20.0062,-6614.46166992188,,,,,,,,,,,,,0,,,,0.00245,,,,,,19.99909685,,,,
,31556076.47,19.9997921,-11260.2314453125,8.98643401012099E-5,4.13072093219477E-7,1,0.999253354069792,40.0298881530762,1.98383375142669,20.2600006014109,0.00100283536433354,0.000185038175707175,0.25,5.33258191294451E-7,8.94124248378246E-5,1.03448751451398E-6,19.9997921,19.9997921,-11290.51953125,-11229.943359375,56.9189703989099,20.6538486096303,13.417728,0,0,0,40,4449,20.00635,-11260.2314453125,,,,,,,,,,,,,0,,,,0.00245,,,,,,19.9997921,,,,
,31556170.48,20.0006561,-15960.3354492187,8.78722135062125E-5,4.53615951108654E-7,1,0.999253354069792,40.0298881530762,1.98373356761336,20.2600006014109,0.000979968908703202,0.000186569170946803,0.25,9.90201181190345E-7,8.74636267413729E-5,1.50783606158281E-6,20.0006561,20.0006561,-15992.837890625,-15927.8330078125,56.9510171681983,20.6552797119643,13.417728,0,0,0,40,4449,20.00425,-15960.3354492187,,,,,,,,,,,,,0,,,,-0.00245,,,,,,20.0006561,,,,
,31556264.53,20.0013199,-20660.5205078125,7.36237589835543E-5,4.31089920786734E-7,1,0.999253354069792,40.0298881530762,1.98367883212604,20.2600006014109,0.000821438688661202,0.000156236341938185,0.25,7.93690169866005E-7,7.33142523257843E-5,1.25086165985071E-6,20.0013199,20.0013199,-20685.759765625,-20635.28125,56.8931766577752,20.6572353681763,13.038077,0,0,0,40,4449,20.00335,-20660.5205078125,,,,,,,,,,,,,0,,,,-0.00245,,,,,,20.0013199,,,,
,31556359.815,20.0018024,-25422.5732421875,5.67288349843704E-5,5.27292928768848E-7,1,0.999253354069792,40.0298881530762,1.98384304424066,20.2600006014109,0.000631532044414106,0.000130254920196876,0.25,1.47217568805237E-6,5.65116163893003E-5,1.83764843370656E-6,20.0018024,20.0018024,-25452.44140625,-25392.705078125,57.2894623170253,20.6552633558032,13.417728,0,0,0,40,4449,20.0019,-25422.5732421875,,,,,,,,,,,,,0,,,,0.00245,,,,,,20.0018024,,,,
,31556455.61,20.0019512,-30207.2568359375,4.77248333489368E-5,6.67882613346824E-7,1,0.999253354069792,40.0298881530762,1.98390040816067,20.2600006014109,0.000533933886147961,9.64861189570302E-5,0.25,5.15332454475118E-8,4.75735063749089E-5,3.75132709584557E-7,20.0019512,20.0019512,-30234.490234375,-30180.0234375,57.3816944822945,20.6555880859863,13.417728,0,0,0,40,4449,19.99995,-30207.2568359375,,,,,,,,,,,,,0,,,,0.00245,,,,,,20.0019512,,,,
,31556550.805,20.0018501,-34964.603515625,4.8620344709037E-5,6.56210222544391E-7,1,0.999253354069792,40.0298881530762,1.98383152375233,20.2600006014109,0.000542061711846075,0.000110285888233145,0.25,1.1095082968876E-6,4.84831781904004E-5,1.44635615294424E-6,20.0018501,20.0018501,-34967.30859375,-34961.8984375,57.1104693861214,20.655913108364,13.417728,0,0,0,40,4449,19.9992,-34964.603515625,,,,,,,,,,,,,0,,,,0,,,,,,20.0018501,,,,
,31556647.955,20.0017071,-39822.021484375,5.80186343846821E-5,6.6160726225653E-7,1,0.999253354069792,40.0298881530762,1.98388772555842,20.2600006014109,0.000647990943168303,0.000127231762324131,0.25,9.17729887356571E-7,5.78874660229385E-5,1.33096098196681E-6,20.0017071,20.0017071,-39824.5703125,-39819.47265625,57.373096568583,20.6553582329783,13.417728,0,0,0,40,4449,19.9979,-39822.021484375,,,,,,,,,,,,,0,,,,0.0049,,,,,,20.0017071,,,,
,31556742.795,20.00204945,-44562.025390625,7.13084826028635E-5,6.68424885727008E-7,1,0.999253354069792,40.0298881530762,1.98397268801449,20.2600006014109,0.000794774343129649,0.0001679825461782,0.25,2.14757724993587E-6,7.11751651222772E-5,2.66317736602125E-6,20.0020409,20.002058,-44592.0703125,-44531.98046875,57.1354814987368,20.6549961726268,13.038077,0,0,0,40,4449,19.99605,-44562.025390625,,,,,,,,,,,,,0,,,,0,,,,,,20.00204945,,,,
,31556837.875,20.0011654,-49312.33984375,8.64676952746503E-5,7.85923166554358E-7,1,0.999253354069792,40.0298881530762,1.98380850288356,20.2600006014109,0.000963269243493982,0.000208534422468125,0.25,3.02127505940103E-6,8.63450168983843E-5,3.65481006072326E-6,20.0009918,20.001339,-49344.75,-49279.9296875,57.2652318329291,20.6563845327211,13.797379,0,0,0,40,4449,19.9961,-49312.33984375,,,,,,,,,,,,,0,,,,0,,,,,,20.0011654,,,,
,31556933.555,20.0005322,-54094.146484375,0.000100928984683478,9.19978671442499E-7,1,0.999253354069792,40.0298881530762,1.98383423107305,20.2600006014109,0.00112609165291374,0.000237042347064388,0.25,2.94312332576821E-6,0.000100838235026395,3.69006789354718E-6,20.0005322,20.0005322,-54121.4921875,-54066.80078125,57.261323690333,20.6584335139262,13.417728,0,0,0,40,4449,19.99565,-54094.146484375,,,,,,,,,,,,,0,,,,0,,,,,,20.0005322,,,,
,31557030.44,20.0014305,-58936.71484375,0.000118048847457946,1.13979425021663E-6,1,0.999253354069792,40.0298881530762,1.98392849261381,20.2600006014109,0.00132220660824217,0.000252823054321342,0.25,1.25076675608387E-6,0.000118014123662811,2.12908009115832E-6,20.0013313,20.0015297,-58968.9765625,-58904.453125,57.2839909173907,20.657397915399,13.417728,0,0,0,40,4449,19.9942,-58936.71484375,,,,,,,,,,,,,0,,,,0,,,,,,20.0014305,,,,
,31557128.62,20.0005531,-63846.294921875,0.000134015141180558,9.16378748334671E-7,1,0.999253354069792,40.0298881530762,1.98371763795328,20.2600006014109,0.00149762095390115,0.000309006755592943,0.25,3.37106453554655E-6,0.000134022039825412,4.3683653238834E-6,20.0004196,20.0006866,-63876.12890625,-63816.4609375,57.3394865422561,20.6577584820559,13.038077,0,0,0,40,4449,19.99315,-63846.294921875,,,,,,,,,,,,,0,,,,0,,,,,,20.0005531,,,,
,31557226.235,20.0015182,-68723.15625,0.000151980792148647,1.41373384937347E-6,1,0.999253354069792,40.0298881530762,1.98403359329141,20.2600006014109,0.00170423725324318,0.000323655685516317,0.25,1.42642010446427E-6,0.000152071686481088,2.55259275943159E-6,20.0015182,20.0015182,-68723.15625,-68723.15625,57.4973755031407,20.6551627659797,13.417728,0,0,0,40,4449,19.9914,-68723.15625,,,,,,,,,,,,,0,,,,-0.0049,,,,,,20.0015182,,,,
,31557322.56,20.0011539,-73537.875,0.000168294739422869,1.36581797911749E-6,1,0.999253354069792,40.0298881530762,1.98382394085577,20.2600006014109,0.00188750943483217,0.000359787343481917,0.25,1.70300530260855E-6,0.000168462118935358,2.94196025184177E-6,20.0011539,20.0011539,-73560.390625,-73515.359375,57.0713879601599,20.6597726995318,13.417728,0,0,0,40,4449,19.9908,-73537.875,,,,,,,,,,,,,0,,,,0,,,,,,20.0011539,,,,
,31557420.705,20.0017071,-78439.97265625,0.000187811483111211,1.28604394569267E-6,1,0.999253354069792,40.0298881530762,1.98400933054447,20.2600006014109,0.00210478717725341,0.000416208556366473,0.25,3.20498075203412E-6,0.000188061342143482,4.57675780109188E-6,20.0017071,20.0017071,-78442.28125,-78437.6640625,57.2480360055061,20.65678818388,13.038077,0,0,0,40,4449,19.9896,-78439.97265625,,,,,,,,,,,,,0,,,,0,,,,,,20.0017071,,,,
,31557515.84,20.0016909,-83197.14453125,0.000204349580696176,1.32479049040909E-6,1,0.999253354069792,40.0298881530762,1.98402522618178,20.2600006014109,0.00228686225727944,0.000475749680835734,0.25,5.52595323956007E-6,0.000204679017194607,7.00622620177374E-6,20.0016022,20.0017796,-83229.3984375,-83164.890625,57.129228470583,20.6596743382824,13.417728,0,0,0,40,4449,19.9877,-83197.14453125,,,,,,,,,,,,,0,,,,0.00245,,,,,,20.0016909,,,,
,31557608.65,20.0015049,-87834.2890625,0.000217673683341563,1.56879881430963E-6,1,0.999253354069792,40.0298881530762,1.98398697784246,20.2600006014109,0.00244097678137552,0.000483235917497034,0.25,3.80125683614669E-6,0.000218110178787888,5.35518769868773E-6,20.0015049,20.0015049,-87866.9296875,-87801.6484375,57.3050948874099,20.6621310060554,13.417728,0,0,0,40,4449,19.9858,-87834.2890625,,,,,,,,,,,,,0,,,,0.00245,,,,,,20.0015049,,,,
,31557714.625,20.00158025,-87666.01953125,0.000214949869002672,1.41325253366942E-6,1,0.999253354069792,40.0298881530762,1.98396448152657,20.2600006014109,0.00240610711393205,0.000500923824881995,0.25,5.86379638561412E-6,0.000215363454239937,7.40347345992605E-6,20.0014706,20.0016899,-87698.546875,-87633.4921875,57.4504777919868,20.6598519832945,13.797379,0,0,0,40,4449,19.985,-87666.01953125,,,,,,,,,,,,,0,,,,0,,,,,,20.00158025,,,,
,31557805.83,19.9995365,-83109.1171875,0.000202262451903259,1.30891660750206E-6,1,0.999253354069792,40.0298881530762,1.98395097807622,20.2600006014109,0.00225829542288284,0.00049928799064631,0.25,7.99622123357503E-6,0.000202569051239125,9.46622879088801E-6,19.9995365,19.9995365,-83136.328125,-83081.90625,57.2503808910638,20.6586615973134,13.417728,0,0,0,40,4449,19.98505,-83109.1171875,,,,,,,,,,,,,0,,,,-0.00245,,,,,,19.9995365,,,,
,31557901.56,19.999239,-78323.58203125,0.000184183695634031,1.23074751448314E-6,1,0.999253354069792,40.0298881530762,1.98411912425964,20.2600006014109,0.00206666191170206,0.000394635238533766,0.25,1.93725116221199E-6,0.000184435863082514,3.28110907976567E-6,19.999239,19.999239,-78353.7734375,-78293.390625,56.9299131981791,20.6562495638947,13.417728,0,0,0,40,4449,19.9863,-78323.58203125,,,,,,,,,,,,,0,,,,0.00245,,,,,,19.999239,,,,
,31557996.215,19.9995823,-73594.03125,0.000165969645948573,1.06817643701202E-6,1,0.999253354069792,40.0298881530762,1.9839468107565,20.2600006014109,0.00185098340467295,0.000413499638695178,0.25,6.90003028943084E-6,0.000166097094325324,8.12736033590108E-6,19.9995823,19.9995823,-73621.6015625,-73566.4609375,57.3129111726022,20.6585082921591,13.038077,0,0,0,40,4449,19.98795,-73594.03125,,,,,,,,,,,,,0,,,,0,,,,,,19.9995823,,,,
,31558091.275,19.99862285,-68842.171875,0.000152395212049207,1.17880130821092E-6,1,0.999253354069792,40.0298881530762,1.98393327306047,20.2600006014109,0.0017067167016911,0.000336193154233109,0.25,2.46923117318734E-6,0.000152480216526539,3.59903153244208E-6,19.998455,19.9987907,-68874.546875,-68809.796875,57.2839909173907,20.6599011636598,13.038077,0,0,0,40,4449,19.9889,-68842.171875,,,,,,,,,,,,,0,,,,-0.00245,,,,,,19.99862285,,,,
,31558185.915,19.99870775,-64114.875,0.000136082154936047,1.25171479687557E-6,1,0.999253354069792,40.0298881530762,1.98388550014468,20.2600006014109,0.00152365726614984,0.000298394854052838,0.25,2.05058599623849E-6,0.00013610265904219,3.06283580488811E-6,19.9986839,19.9987316,-64142.35546875,-64087.39453125,57.4520410490253,20.6595696157446,13.417728,0,0,0,40,4449,19.99055,-64114.875,,,,,,,,,,,,,0,,,,0.00245,,,,,,19.99870775,,,,
,31558280.365,19.99884795,-59392.19140625,0.000120719696798489,1.16270628877342E-6,1,0.999253354069792,40.0298881530762,1.98397196267941,20.2600006014109,0.00134835156707582,0.000279953617351158,0.25,3.18535547732497E-6,0.000120675185244182,4.08333218043559E-6,19.9987526,19.9989433,-59424.63671875,-59359.74609375,57.2660134614484,20.6574194679406,13.797379,0,0,0,40,4449,19.9916,-59392.19140625,,,,,,,,,,,,,0,,,,0,,,,,,19.99884795,,,,
,31558375.215,19.9983654,-54654.873046875,0.000103069647054853,9.09886828623105E-7,1,0.999253354069792,40.0298881530762,1.98402069067568,20.2600006014109,0.00115643362568908,0.000207197990048273,0.25,-1.06576073203674E-7,0.000103005739346565,6.58753808175853E-7,19.9983654,19.9983654,-54657.140625,-54652.60546875,57.4731450190445,20.656145745217,13.417728,0,0,0,40,4449,19.992,-54654.873046875,,,,,,,,,,,,,0,,,,-0.0049,,,,,,19.9983654,,,,
,31558473.885,19.99914835,-49723.779296875,8.44982719322161E-5,8.63303149829514E-7,1,0.999253354069792,40.0298881530762,1.98397985478783,20.2600006014109,0.000946280456450242,0.000176981546506752,0.25,5.59189244423445E-7,8.43995425856082E-5,1.1815948448749E-6,19.9989929,19.9993038,-49751.40234375,-49696.15625,57.1346998702176,20.6535053596861,13.417728,0,0,0,40,4449,19.99235,-49723.779296875,,,,,,,,,,,,,0,,,,-0.00245,,,,,,19.99914835,,,,
,31558569.495,19.9993134,-44943.560546875,6.87549896369902E-5,8.78535259324044E-7,1,0.999253354069792,40.0298881530762,1.98406062410536,20.2600006014109,0.000771776250131503,0.000132001627424019,0.25,-6.0482988203112E-7,6.86486564674538E-5,-1.02728821036119E-7,19.9993134,19.9993134,-44948.6484375,-44938.47265625,57.3090030300061,20.6479999461496,13.038077,0,0,0,40,4449,19.9939,-44943.560546875,,,,,,,,,,,,,0,,,,0.00245,,,,,,19.9993134,,,,
,31558664.795,19.99924565,-40180.833984375,5.45026304247206E-5,7.65083500243328E-7,1,0.999253354069792,40.0298881530762,1.98394781174756,20.2600006014109,0.000608003361258305,0.000123747076875078,0.25,1.23808568061911E-6,5.4378767937727E-5,1.62609730158288E-6,19.9991531,19.9993382,-40210.875,-40150.79296875,57.2761746321984,20.6492442189823,13.797379,0,0,0,40,4449,19.9936,-40180.833984375,,,,,,,,,,,,,0,,,,0.00245,,,,,,19.99924565,,,,
,31558759.68,19.9979343,-35438.146484375,3.69624625816965E-5,6.0947279457298E-7,1,0.999253354069792,40.0298881530762,1.98432680597942,20.2600006014109,0.000412071098787864,8.46300541499637E-5,0.25,9.11011621265851E-7,3.68595487292243E-5,1.16762920916058E-6,19.9979343,19.9979343,-35467.98828125,-35408.3046875,57.2910255740638,20.6469502358675,13.797379,0,0,0,40,4449,19.99585,-35438.146484375,,,,,,,,,,,,,0,,,,0,,,,,,19.9979343,,,,
,31558855.155,19.9983826,-30668.9755859375,2.09889029798485E-5,6.75121792327436E-7,1,0.999253354069792,40.0298881530762,1.98411949551729,20.2600006014109,0.000231027302244249,6.37505526561551E-5,0.25,1.92635416046606E-6,2.09104106751748E-5,2.06319515268481E-6,19.9983826,19.9983826,-30696.21875,-30641.732421875,56.9174071418714,20.649973070184,13.417728,0,0,0,40,4449,19.9971,-30668.9755859375,,,,,,,,,,,,,0,,,,0.00245,,,,,,19.9983826,,,,
,31558951.695,19.9988699,-25843.796875,6.18477456634179E-6,5.41480044329785E-7,1,0.999253354069792,40.0298881530762,1.98396628314019,20.2600006014109,6.83150888104637E-5,1.72338689462138E-5,0.25,4.31383191020376E-7,6.15957808243753E-6,4.70399432970402E-7,19.9988079,19.9989319,-25873.75390625,-25813.83984375,57.027616763083,20.6517822599738,13.038077,0,0,0,40,4449,19.9985,-25843.796875,,,,,,,,,,,,,0,,,,0,,,,,,19.9988699,,,,
,31559046.95,19.9987965,-21082.1005859375,-9.34830918917829E-6,5.10297009445526E-7,1,0.999253354069792,40.0298881530762,1.98414047609281,20.2600006014109,-0.000104894054512027,-1.66874188179095E-5,0.25,1.81694157560401E-7,-9.31116733783015E-6,1.22237019546282E-7,19.9986401,19.9989529,-21112.0625,-21052.138671875,57.2886806885061,20.6465240414663,13.038077,0,0,0,40,4449,19.99955,-21082.1005859375,,,,,,,,,,,,,0,,,,0.00245,,,,,,19.9987965,,,,
,31559141.74,19.9981108,-16344.66015625,-2.44424677532008E-5,4.73241012218E-7,1,0.999253354069792,40.0298881530762,1.98394274132568,20.2600006014109,-0.000272510413419092,-5.25411932970917E-5,0.25,-3.31891695216983E-7,-2.43293346664272E-5,-4.76276668360129E-7,19.9979973,19.9982243,-16374.61328125,-16314.70703125,57.146424298006,20.6488947033546,13.797379,0,0,0,40,4449,20.0012,-16344.66015625,,,,,,,,,,,,,0,,,,0,,,,,,19.9981108,,,,
,31559235.88,19.9985733,-11637.041015625,-3.85056178973708E-5,3.70995531293484E-7,1,0.999253354069792,40.0298881530762,1.98385697088924,20.2600006014109,-0.000429735830633811,-7.91976426467798E-5,0.25,-2.19202442242844E-7,-3.83132394074969E-5,-4.35079943415382E-7,19.9985733,19.9985733,-11667.1650390625,-11606.9169921875,57.1886322380445,20.651625545398,13.417728,0,0,0,40,4449,20.00255,-11637.041015625,,,,,,,,,,,,,0,,,,0.00245,,,,,,19.9985733,,,,
,31559331.235,19.99831865,-6873.677734375,-5.24975352736234E-5,3.94465645890986E-7,1,0.999253354069792,40.0298881530762,1.98389518121226,20.2600006014109,-0.000585619428301728,-0.000108273921255974,0.25,-3.4730209366233E-7,-5.22153200010385E-5,-6.2295170725597E-7,19.9983139,19.9983234,-6903.572265625,-6843.783203125,57.1995750373137,20.6489597897343,13.797379,0,0,0,40,4449,20.0042,-6873.677734375,,,,,,,,,,,,,0,,,,0,,,,,,19.99831865,,,,
,31559426.475,20.0001278,-2110.30163574219,-6.58108624670467E-5,3.05841613831127E-7,1,0.999253354069792,40.0298881530762,1.98377475819503,20.2600006014109,-0.000733880328455136,-0.000135563584520392,0.25,-4.46467822547914E-7,-6.54366149860762E-5,-7.70169172727029E-7,20.0000858,20.0001698,-2140.39306640625,-2080.21020507813,57.1315733561406,20.6530963403982,13.797379,0,0,0,40,4449,20.00425,-2110.30163574219,,,,,,,,,,,,,0,,,,-0.0049,,,,,,20.0001278,,,,
,31559520.47,19.99925995,2580.35583496094,-7.34161162275766E-5,3.81150592041804E-7,1,0.999253354069792,40.0298881530762,1.98379871831421,20.2600006014109,-0.000818443223431137,-0.000152796172038091,0.25,-6.35659681808244E-7,-7.2999882220695E-5,-9.98195017189304E-7,19.9991226,19.9993973,2547.9736328125,2612.73803710938,57.0573186468137,20.6523258956602,13.797379,0,0,0,40,4449,20.00315,2580.35583496094,,,,,,,,,,,,,0,,,,-0.00245,,,,,,19.99925995,,,,
,31559614.18,19.9990463,7267.482421875,-8.34207879591484E-5,3.69182068242194E-7,1,0.999253354069792,40.0298881530762,1.98396240862959,20.2600006014109,-0.00092874611322317,-0.000182647537195037,0.25,-1.49721321661188E-6,-8.29697217999367E-5,-1.93261863581163E-6,19.9990463,19.9990463,7237.51904296875,7297.44580078125,57.1823792098907,20.6439384493809,13.797379,0,0,0,40,4449,20.00375,7267.482421875,,,,,,,,,,,,,0,,,,-0.00245,,,,,,19.9990463,,,,
,31559709.875,19.99998475,12050.53515625,-8.89924905151587E-5,3.90283067966428E-7,1,0.999253354069792,40.0298881530762,1.98376008627278,20.2600006014109,-0.000991793562503152,-0.000190778753758274,0.25,-1.19701764044006E-6,-8.85470679846629E-5,-1.69523599332911E-6,19.9999161,20.0000534,12015.625,12085.4453125,57.0510656186599,20.6500585941302,13.797379,0,0,0,40,4449,20.0054,12050.53515625,,,,,,,,,,,,,0,,,,0,,,,,,19.99998475,,,,
,31559805.605,20.0007992,16835.5576171875,-8.50104276162331E-5,4.98193349146003E-7,1,0.999253354069792,40.0298881530762,1.98377575705484,20.2600006014109,-0.000948122580279026,-0.000180662740172264,0.25,-9.66406568418108E-7,-8.46219119249399E-5,-1.47233433762909E-6,20.0007191,20.0008793,16808.25,16862.865234375,56.9760292808137,20.6500977461091,13.038077,0,0,0,40,4449,20.0032,16835.5576171875,,,,,,,,,,,,,0,,,,-0.00245,,,,,,20.0007992,,,,
,31559900.83,20.0018587,21593.076171875,-6.93334686097977E-5,4.97392626866589E-7,1,0.999253354069792,40.0298881530762,1.98379680376432,20.2600006014109,-0.000772732931546636,-0.000152473997997635,0.25,-1.21927398963275E-6,-6.90453340183836E-5,-1.6520025534312E-6,20.0018501,20.0018673,21565.576171875,21620.576171875,57.2277136640061,20.6503340986921,13.417728,0,0,0,40,4449,20.0017,21593.076171875,,,,,,,,,,,,,0,,,,-0.00245,,,,,,20.0018587,,,,
,31559998.455,20.0017128,26473.0947265625,-5.32187189169355E-5,5.28534209009674E-7,1,0.999253354069792,40.0298881530762,1.98378186179871,20.2600006014109,-0.000592036116041431,-0.00012480020970616,0.25,-1.6100841581109E-6,-5.30190838326901E-5,-1.95533881476345E-6,20.0017128,20.0017128,26468.189453125,26478,57.1729996676599,20.6491206455887,13.417728,0,0,0,40,4449,20.0001,26473.0947265625,,,,,,,,,,,,,0,,,,0,,,,,,20.0017128,,,,
,31560094.47,20.0016594,31273.8994140625,-4.68967270002738E-5,6.13099299165422E-7,1,0.999253354069792,40.0298881530762,1.98384530841633,20.2600006014109,-0.000521451118764918,-0.00011298547658528,0.25,-1.67159199534899E-6,-4.67421995990955E-5,-1.98695579830416E-6,20.0016594,20.0016594,31271.23828125,31276.560546875,57.1565854687561,20.6482130192513,13.038077,0,0,0,40,4449,19.9994,31273.8994140625,,,,,,,,,,,,,0,,,,0,,,,,,20.0016594,,,,
,31560188.935,20.00150775,35994.03515625,-5.03470742057438E-5,7.28406606945895E-7,1,0.999253354069792,40.0298881530762,1.98377985123553,20.2600006014109,-0.000562060869120487,-0.000110314127250761,0.25,-7.98803533198902E-7,-5.02129403194118E-5,-1.15059642575747E-6,20.0013809,20.0016346,35964.02734375,36024.04296875,57.1448610409676,20.6480975857127,13.797379,0,0,0,40,4449,19.9975,35994.03515625,,,,,,,,,,,,,0,,,,-0.0049,,,,,,20.00150775,,,,
,31560284.245,20.00190925,40758.814453125,-6.11043214975267E-5,6.67959550030116E-7,1,0.999253354069792,40.0298881530762,1.98386051301743,20.2600006014109,-0.000679318402526623,-0.000151754622787094,0.25,-2.54903192843001E-6,-6.09608178811914E-5,-2.98277551932779E-6,20.0016975,20.002121,40731.22265625,40786.40625,57.1417345268907,20.6492708858564,13.417728,0,0,0,40,4449,19.9965,40758.814453125,,,,,,,,,,,,,0,,,,0.00245,,,,,,20.00190925,,,,
,31560379.87,20.0015011,45539.82421875,-7.36055417227665E-5,8.1922744761716E-7,1,0.999253354069792,40.0298881530762,1.98377941653274,20.2600006014109,-0.000820676690773144,-0.000171765336632034,0.25,-2.06983183376848E-6,-7.34764317422098E-5,-2.60403082065714E-6,20.0015011,20.0015011,45515.11328125,45564.53515625,57.3535558556022,20.6496752544204,13.417728,0,0,0,40,4449,19.99565,45539.82421875,,,,,,,,,,,,,0,,,,-0.0049,,,,,,20.0015011,,,,
,31560476.22,20.0011263,50354.552734375,-9.10858797836456E-5,9.20875185438105E-7,1,0.999253354069792,40.0298881530762,1.98379151277077,20.2600006014109,-0.00101523218131931,-0.000217380615758966,0.25,-2.97510807933229E-6,-9.09677523820776E-5,-3.64434966312503E-6,20.0009785,20.0012741,50322.171875,50386.93359375,57.2316218066022,20.6484250645285,13.417728,0,0,0,40,4449,19.9947,50354.552734375,,,,,,,,,,,,,0,,,,0,,,,,,20.0011263,,,,
,31560572.75,20.000639,55177.228515625,-0.000103132955835632,9.10942782669287E-7,1,0.999253354069792,40.0298881530762,1.98389275758435,20.2600006014109,-0.00115444534724954,-0.000222228331429567,0.25,-1.22176486988242E-6,-0.000103064412588422,-1.98714962395554E-6,20.000639,20.000639,55174.77734375,55179.6796875,57.0299616486406,20.6440579883728,13.038077,0,0,0,40,4449,19.9945,55177.228515625,,,,,,,,,,,,,0,,,,-0.0049,,,,,,20.000639,,,,
,31560668.22,20.001173,59949.859375,-0.000121326220761931,1.1293766755671E-6,1,0.999253354069792,40.0298881530762,1.98371474135782,20.2600006014109,-0.00135758036278081,-0.000267186702749193,0.25,-1.94013509124036E-6,-0.000121297229784259,-2.8429815099137E-6,20.001173,20.001173,59947.3046875,59952.4140625,57.0870205305445,20.6469444331177,13.417728,0,0,0,40,4449,19.99335,59949.859375,,,,,,,,,,,,,0,,,,0.00245,,,,,,20.001173,,,,
,31560766.46,20.0015106,64860.232421875,-0.000139682729188442,1.23405397711114E-6,1,0.999253354069792,40.0298881530762,1.98367841847038,20.2600006014109,-0.00155961663736555,-0.000330156371704034,0.25,-4.23215603636602E-6,-0.000139697310286638,-5.2715324103324E-6,20.0015106,20.0015106,64855.37890625,64865.0859375,57.217552493256,20.6489937195656,13.038077,0,0,0,40,4449,19.9923,64860.232421875,,,,,,,,,,,,,0,,,,0,,,,,,20.0015106,,,,
,31560859.265,20.001153,69498.17578125,-0.000155163767853026,1.06930865855566E-6,1,0.999253354069792,40.0298881530762,1.9837491901143,20.2600006014109,-0.00173395492556577,-0.000362882576692684,0.25,-4.34856747653322E-6,-0.000155245442580693,-5.49943370734555E-6,20.0010452,20.0012608,69468.1328125,69528.21875,57.1659650109868,20.6473293138481,13.417728,0,0,0,40,4449,19.99135,69498.17578125,,,,,,,,,,,,,0,,,,-0.00245,,,,,,20.001153,,,,
,31560951.94,20.0017986,74130.68359375,-0.000171177598586428,1.09856479324798E-6,1,0.999253354069792,40.0298881530762,1.98353242886293,20.2600006014109,-0.0019132267521625,-0.000401653809649795,0.25,-4.91446377003296E-6,-0.000171332682257289,-6.17694816452008E-6,20.0017986,20.0017986,74110.7578125,74150.609375,57.0416860764291,20.6492673635656,13.038077,0,0,0,40,4449,19.9886,74130.68359375,,,,,,,,,,,,,0,,,,0,,,,,,20.0017986,,,,
,31561049.485,20.0012016,79006.640625,-0.000185128139255428,1.16816856232179E-6,1,0.999253354069792,40.0298881530762,1.9834930798335,20.2600006014109,-0.0020719115313685,-0.000423380659797566,0.25,-4.33570065380929E-6,-0.000185373878715786,-5.68804864050339E-6,20.0012016,20.0012016,79004.2109375,79009.0703125,57.0268351345637,20.6492099670012,13.417728,0,0,0,40,4449,19.9878,79006.640625,,,,,,,,,,,,,0,,,,0.0049,,,,,,20.0012016,,,,
,31561145.43,20.0021267,83802.53515625,-0.000206255409085632,1.50065669128328E-6,1,0.999253354069792,40.0298881530762,1.98361909880621,20.2600006014109,-0.00230539087329518,-0.000493717062422553,0.25,-6.78978782301113E-6,-0.000206588194828118,-8.28395690520844E-6,20.0020485,20.0022049,83772.390625,83832.6796875,56.9791557948906,20.6467122502941,13.797379,0,0,0,40,4449,19.98585,83802.53515625,,,,,,,,,,,,,0,,,,0.00245,,,,,,20.0021267,,,,
,31561236.555,20.00136475,88358.17578125,-0.000218930982852417,1.28123240907496E-6,1,0.999253354069792,40.0298881530762,1.98349738514899,20.2600006014109,-0.00244948169165366,-0.000514294817606944,0.25,-6.34771502486987E-6,-0.000219359845922639,-7.91378059822553E-6,20.001339,20.0013905,88330.796875,88385.5546875,56.9424192544868,20.6502137191581,13.797379,0,0,0,40,4449,19.9846,88358.17578125,,,,,,,,,,,,,0,,,,0.00245,,,,,,20.00136475,,,,
,31561343.235,20.00050165,87138.47265625,-0.000213526730624926,1.29800905955701E-6,1,0.999253354069792,40.0298881530762,1.98357591846898,20.2600006014109,-0.00239259682191415,-0.000481081095136918,0.25,-4.36296886049067E-6,-0.00021394027818677,-5.89156371677474E-6,20.0004711,20.0005322,87108.421875,87168.5234375,57.0119841926983,20.6503744216765,13.038077,0,0,0,40,4449,19.9843,87138.47265625,,,,,,,,,,,,,0,,,,0.0049,,,,,,20.00050165,,,,
,31561435.365,19.9998741,82532.72265625,-0.000198853621114948,1.45380099947648E-6,1,0.999253354069792,40.0298881530762,1.98355254474798,20.2600006014109,-0.00222612580272592,-0.000455149735144442,0.25,-4.69191514186283E-6,-0.000199169547136285,-6.1334039808519E-6,19.9998722,19.999876,82510.2578125,82555.1875,56.9017745714868,20.6498229908019,13.417728,0,0,0,40,4449,19.98465,82532.72265625,,,,,,,,,,,,,0,,,,-0.0049,,,,,,19.9998741,,,,
,31561530.21,19.99936865,77788.65234375,-0.000185617068857607,1.3517068726143E-6,1,0.999253354069792,40.0298881530762,1.98368695691625,20.2600006014109,-0.00207288208123177,-0.00044949754680075,0.25,-6.56760115084551E-6,-0.000185829924067342,-7.92991459326566E-6,19.9992485,19.9994888,77761.0546875,77816.25,57.1354814987368,20.6478613089506,13.038077,0,0,0,40,4449,19.98535,77788.65234375,,,,,,,,,,,,,0,,,,0.00245,,,,,,19.99936865,,,,
,31561627.585,19.99794675,72922.8671875,-0.000168929068160448,1.08740725645997E-6,1,0.999253354069792,40.0298881530762,1.98360463006793,20.2600006014109,-0.00188684121843676,-0.000402649394741705,0.25,-5.40765187110955E-6,-0.00016906139643447,-6.65627492231133E-6,19.9978657,19.9980278,72898.015625,72947.71875,57.0315249056791,20.6486010174905,13.417728,0,0,0,40,4449,19.9865,72922.8671875,,,,,,,,,,,,,0,,,,0.00245,,,,,,19.99794675,,,,
,31561723.445,19.9973946,68129.6484375,-0.000148378377217626,1.18345079001501E-6,1,0.999253354069792,40.0298881530762,1.98369160020636,20.2600006014109,-0.00165340386072309,-0.000371843973303153,0.25,-6.37200221888627E-6,-0.000148422646415046,-7.47523922746466E-6,19.9973946,19.9973946,68099.765625,68159.53125,56.9369478548522,20.6480609786555,13.417728,0,0,0,40,4449,19.988,68129.6484375,,,,,,,,,,,,,0,,,,-0.0049,,,,,,19.9973946,,,,
,31561818.37,19.9987602,63386.8671875,-0.000133773246823394,1.20703266628563E-6,1,0.999253354069792,40.0298881530762,1.9837280668522,20.2600006014109,-0.00149398710995182,-0.000313297710802439,0.25,-3.79764249054308E-6,-0.000133771347243439,-4.79332643710841E-6,19.9987602,19.9987602,63361.765625,63411.96875,57.1378263842945,20.6497135438138,13.038077,0,0,0,40,4449,19.9903,63386.8671875,,,,,,,,,,,,,0,,,,-0.00245,,,,,,19.9987602,,,,
,31561914.315,19.9978886,58591.046875,-0.000117427546240314,1.06942376418744E-6,1,0.999253354069792,40.0298881530762,1.98370042963247,20.2600006014109,-0.0013123347880999,-0.000266576558472151,0.25,-2.59177539639161E-6,-0.000117379130148682,-3.46502317138703E-6,19.9978886,19.9978886,58568.44140625,58613.65234375,57.1941036376791,20.6487670130197,13.417728,0,0,0,40,4449,19.99095,58591.046875,,,,,,,,,,,,,0,,,,-0.00245,,,,,,19.9978886,,,,
,31562009.055,19.99839405,53855.525390625,-0.00010029385555024,8.32809179697804E-7,1,0.999253354069792,40.0298881530762,1.98384138252016,20.2600006014109,-0.0011174420643307,-0.00024409506236562,0.25,-3.68699963668913E-6,-0.000100195665694286,-4.42844738034354E-6,19.9980927,19.9986954,53825.48828125,53885.5625,56.8064158921406,20.6492399507877,13.797379,0,0,0,40,4449,19.99225,53855.525390625,,,,,,,,,,,,,0,,,,0,,,,,,19.99839405,,,,
,31562105.815,19.99887085,49015.29296875,-8.42975240280073E-5,1.01606825849493E-6,1,0.999253354069792,40.0298881530762,1.98383036736587,20.2600006014109,-0.000937871317663601,-0.000209974918779491,0.25,-3.54151549504896E-6,-8.41709977285698E-5,-4.15797773654743E-6,19.9988384,19.9989033,48987.62109375,49042.96484375,57.1010898438907,20.6451930878684,13.797379,0,0,0,40,4449,19.9921,49015.29296875,,,,,,,,,,,,,0,,,,-0.00245,,,,,,19.99887085,,,,
,31562200.87,19.99955365,44265.0625,-6.72906493978267E-5,7.12617481483048E-7,1,0.999253354069792,40.0298881530762,1.98382305582377,20.2600006014109,-0.000750502215377255,-0.000155246700202895,0.25,-1.73654827149967E-6,-6.71648835340592E-5,-2.22307382818112E-6,19.9994926,19.9996147,44240.125,44290,56.9385111118906,20.6477377467146,13.417728,0,0,0,40,4449,19.99335,44265.0625,,,,,,,,,,,,,0,,,,-0.00245,,,,,,19.99955365,,,,
,31562295.36,19.9994221,39541.71484375,-5.07191699781107E-5,7.39917638584063E-7,1,0.999253354069792,40.0298881530762,1.98391992847375,20.2600006014109,-0.000565800673085595,-0.000114873341941144,0.25,-1.12861665183362E-6,-5.06006739860733E-5,-1.48868992185282E-6,19.9994221,19.9994221,39516.73046875,39566.69921875,57.1769078102561,20.6492551995853,13.417728,0,0,0,40,4449,19.9933,39541.71484375,,,,,,,,,,,,,0,,,,-0.00245,,,,,,19.9994221,,,,
,31562389.815,19.99921605,34822.509765625,-3.45531605056425E-5,5.63522838592472E-7,1,0.999253354069792,40.0298881530762,1.98376050183264,20.2600006014109,-0.000381816006569194,-9.72478954523707E-5,0.25,-2.47478037430397E-6,-3.44433862147129E-5,-2.70945103781058E-6,19.9990215,19.9994106,34789.89453125,34855.125,56.9760292808137,20.6508617120233,13.797379,0,0,0,40,4449,19.9943,34822.509765625,,,,,,,,,,,,,0,,,,0.00245,,,,,,19.99921605,,,,
,31562484.38,19.9993572,30095.1005859375,-1.89282027089566E-5,6.11490687623245E-7,1,0.999253354069792,40.0298881530762,1.98366489035386,20.2600006014109,-0.000208413472347587,-5.6772578206083E-5,0.25,-1.67490141421681E-6,-1.88567464516239E-5,-1.7978896963916E-6,19.9993572,19.9993572,30067.708984375,30122.4921875,56.7774956369291,20.6493433502655,13.417728,0,0,0,40,4449,19.99645,30095.1005859375,,,,,,,,,,,,,0,,,,0.00245,,,,,,19.9993572,,,,
,31562580,19.997797,25317.150390625,-4.01822544642935E-6,4.00022780849508E-7,1,0.999253354069792,40.0298881530762,1.98381140704056,20.2600006014109,-4.06525863428684E-5,-3.19712498999371E-5,0.25,-2.13798829088662E-6,-3.9895132930806E-6,-2.15638637869796E-6,19.997797,19.997797,25314.60546875,25319.6953125,57.2136443506599,20.6501254726692,13.417728,0,0,0,40,4449,19.9976,25317.150390625,,,,,,,,,,,,,0,,,,0.0049,,,,,,19.997797,,,,
,31562674.125,19.9986954,20612.6201171875,1.11331157960996E-5,4.94846801034035E-7,1,0.999253354069792,40.0298881530762,1.98386186471367,20.2600006014109,0.000126173727204035,1.27453661129012E-5,0.25,-8.53320859280778E-7,1.10923450865363E-5,-7.80193125913051E-7,19.9986954,19.9986954,20582.60546875,20642.634765625,57.166746639506,20.6493647116954,13.038077,0,0,0,40,4449,19.9987,20612.6201171875,,,,,,,,,,,,,0,,,,0,,,,,,19.9986954,,,,
,31562766.455,19.9981499,15997.6533203125,2.54757040416271E-5,3.81357698611274E-7,1,0.999253354069792,40.0298881530762,1.9837975414787,20.2600006014109,0.000285756103766437,4.49375235256168E-5,0.25,-5.32132551520182E-7,2.53622028641136E-5,-3.78244011364131E-7,19.9981499,19.9981499,15970.119140625,16025.1875,57.2699216040445,20.6484477531737,13.417728,0,0,0,40,4449,20.00095,15997.6533203125,,,,,,,,,,,,,0,,,,0.0049,,,,,,19.9981499,,,,
,31562862.21,19.9986782,11212.5844726562,4.02019404921336E-5,4.01455632435616E-7,1,0.999253354069792,40.0298881530762,1.98380703613324,20.2600006014109,0.000449755921424844,7.642881502746E-5,0.25,-3.29634281232015E-7,4.00027921429156E-5,-1.02706012695751E-7,19.9986782,19.9986782,11207.8203125,11217.3486328125,57.0995265868522,20.6511572825676,13.038077,0,0,0,40,4449,20.0018,11212.5844726562,,,,,,,,,,,,,0,,,,0,,,,,,19.9986782,,,,
,31562955.42,19.99819275,6554.98388671875,5.37625527501829E-5,2.88199922792292E-7,1,0.999253354069792,40.0298881530762,1.98388188472589,20.2600006014109,0.000600503901140489,0.000106437668501768,0.25,-4.08264904452017E-8,5.34743823399439E-5,2.42339579761214E-7,19.9979839,19.9984016,6525.2431640625,6584.724609375,57.332451885583,20.6517774678273,13.797379,0,0,0,40,4449,20.00365,6554.98388671875,,,,,,,,,,,,,0,,,,0,,,,,,19.99819275,,,,
,31563051.64,20.0000725,1743.97644042969,6.69713283353356E-5,3.05693379505214E-7,1,0.999253354069792,40.0298881530762,1.98384858648478,20.2600006014109,0.000747085628799235,0.00013653253735271,0.25,3.28340846627692E-7,6.65897748460916E-5,6.5695011315435E-7,20.0000725,20.0000725,1711.50964355469,1776.44323730469,57.2503808910638,20.6501825418565,13.417728,0,0,0,40,4449,20.00385,1743.97644042969,,,,,,,,,,,,,0,,,,0,,,,,,20.0000725,,,,
,31563086.655,20.00104045,-0.235968492925167,7.02828905345851E-5,3.34247329714752E-7,1,0.999253354069792,40.0298881530762,1.98384988971103,20.2600006014109,0.00078554029489682,0.000134412857965743,0.25,-4.42777607017474E-7,6.98808945654777E-5,-9.96392531167069E-8,20.0009384,20.0011425,-0.304475486278534,-0.1674614995718,57.2652318329291,20.6516198421478,13.797379,0,0,0,40,4417,20.00415,-0.235968492925167,,,,,,,,,,,,,0,,,,-0.00245,,,,,,20.00104045,,,,