File: data/doubleLayers/dl_0-25/ppms/data/DD205_10_HYST_100OE_300K.DAT
[Header]
; VSM Data File (default extension .dat)
; Copyright (c) 2003-2013, Quantum Design, Inc. All rights reserved.
TITLE,
FILEOPENTIME,31624981.02,01/02/2019,8:45 am
BYAPP,VSM,2.0,2.0
INFO,PPMS VSM Option Release 1.4.10 Build 1,APPNAME
INFO,Quantum Design Linear Motor Servo Controller,MOTOR_MODULE_NAME
INFO,3101-100 M1,MOTOR_HW_VERSION
INFO,MMC1014,MOTOR_SERIAL_NUMBER
INFO,SRV No X-over 01.03.11,MOTOR_SOFTWARE_VERSION
INFO,Quantum Design VSM Detection Module,VSM_MODULE_NAME
INFO,3101-150 F0,VSM_HW_VERSION
INFO,VSM707,VSM_SERIAL_NUMBER
INFO,VSM No X-over 01.02.05 May 20 2008 13:51:47,VSM_SOFTWARE_VERSION
INFO,704,PREAMP_SERIAL_NUMBER
INFO,822,COIL_SERIAL_NUMBER
INFO,0,MOMENT_UNITS
INFO,CoFe2O4,SAMPLE_MATERIAL
INFO,Double Layer thin concentration,SAMPLE_COMMENT
INFO,27.44,SAMPLE_MASS
INFO,,SAMPLE_VOLUME
INFO,,SAMPLE_MOLECULAR_WEIGHT
INFO,,SAMPLE_SIZE
INFO,,SAMPLE_SHAPE
DATATYPE,COMMENT,1
DATATYPE,TIME,2
STARTUPAXIS,X,2
STARTUPAXIS,Y1,5
[Data]
Comment,Time Stamp (sec),Temperature (K),Magnetic Field (Oe),Moment (emu),M. Std. Err. (emu),Transport Action,Averaging Time (sec),Frequency (Hz),Peak Amplitude (mm),Center Position (mm),Coil Signal' (mV),Coil Signal" (mV),Range (mV),M. Quad. Signal (emu),M. Raw' (emu),M. Raw" (emu),Min. Temperature (K),Max. Temperature (K),Min. Field (Oe),Max. Field (Oe),Mass (grams),Motor Lag (deg),Pressure (Torr),VSM Status (code),Motor Status (code),Measure Status (code),Measure Count,PPMS Status (code),System Temp. (K),System Field (Oe),Sample Position (deg),Bridge 1 Resistance (ohms),Bridge 1 Excitation (에),Bridge 2 Resistance (ohms),Bridge 2 Excitation (에),Bridge 3 Resistance (ohms),Bridge 3 Excitation (에),Bridge 4 Resistance (ohms),Bridge 4 Excitation (에),Signal 1 Vin (V),Signal 2 Vin (V),Digital Inputs (code),Drive 1 Iout (mA),Drive 1 Ipower (W),Drive 2 Iout (mA),Drive 2 Ipower (W),Pressure (),Map 20 (),Map 21 (),Map 22 (),Map 23 (),Map 24 (),Map 25 (),Map 26 (),Map 27 (),Map 28 (),Map 29 ()
,31624996.59,299.999054,-0.365370541810989,,,2,,,,18.9399996706843,,,,,,,299.999054,299.999054,-0.365370541810989,-0.365370541810989,,,25.566563,,,,-99999999,4369,300.1906,-0.365370541810989,,,,,,,,,,,,,,,,,,,,,,,299.999054,,,,
,31625138.36,299.9817352,4613.3046875,4.33462750723898E-5,4.96489482840767E-7,1,0.999253354069792,40.0298881530762,1.99668820122697,18.8900008797646,0.000490336109767863,8.34365893595668E-5,0.25,-1.30426624667777E-7,4.33450977277161E-5,-1.01680165547942E-7,299.9809875,299.9824829,4590.90576171875,4635.70361328125,56.3952792910252,20.5956049381835,25.186911,0,0,0,40,4449,300.21635,4613.3046875,,,,,,,,,,,,,0,,,,0.00245,,,,,,299.9817352,,,,
,31625234.555,299.9748535,9417.30810546875,3.55243143211867E-5,7.00554950839959E-7,1,0.999253354069792,40.0298881530762,1.99657676538234,18.8900008797646,0.000401127056807273,7.24467755683353E-5,0.25,2.53144386517383E-7,3.55231213944972E-5,2.76673312882941E-7,299.9745483,299.9751587,9387.349609375,9447.2666015625,56.5766171074867,20.6021095125162,25.566563,0,0,0,40,4449,300.233,9417.30810546875,,,,,,,,,,,,,0,,,,-0.00245,,,,,,299.9748535,,,,
,31625330.885,299.9836731,14234.9389648438,2.30654612927553E-5,9.52990743339759E-7,1,0.999253354069792,40.0298881530762,1.9965339057216,18.8900008797646,0.000258904188670047,5.59079107083024E-5,0.25,9.48976891134528E-7,2.30641614734678E-5,9.64216702197167E-7,299.98349,299.9838562,14205.0048828125,14264.873046875,56.6055373626983,20.6038930850091,24.807261,0,0,0,40,4449,300.25225,14234.9389648438,,,,,,,,,,,,,0,,,,-0.00245,,,,,,299.9836731,,,,
,31625428.545,299.9837952,19114.5107421875,8.26723961565308E-6,1.22753504966754E-6,1,0.999253354069792,40.0298881530762,1.99651382027007,18.8900008797646,9.09572003368476E-5,3.06566991231427E-5,0.25,1.27936105614634E-6,8.26615323751589E-6,1.2847910515741E-6,299.9837952,299.9837952,19087.033203125,19141.98828125,56.9643048530253,20.6048096922594,25.566563,0,0,0,40,4449,300.24955,19114.5107421875,,,,,,,,,,,,,0,,,,-0.00245,,,,,,299.9837952,,,,
,31625527.42,299.9920349,24057.3837890625,-8.57652348804722E-6,1.25952624449183E-6,1,0.999253354069792,40.0298881530762,1.99654921583303,18.8900008797646,-9.59144214831506E-5,-2.2841394158974E-5,0.25,-5.34447808108517E-7,-8.57591908629334E-6,-5.40098018238453E-7,299.9920349,299.9920349,24024.9453125,24089.822265625,57.0190188493714,20.6045173383102,25.566563,0,0,0,40,4449,300.25865,24057.3837890625,,,,,,,,,,,,,0,,,,0,,,,,,299.9920349,,,,
,31625627.46,299.9933167,29057.4462890625,-2.43722783722741E-5,1.40844931283312E-6,1,0.999253354069792,40.0298881530762,1.99663845622311,18.8900008797646,-0.000275459012698121,-4.82709155305033E-5,0.25,-4.6875195441104E-8,-2.43715336572173E-5,-6.29573749695152E-8,299.9933167,299.9933167,29052.578125,29062.314453125,56.6821369575829,20.6035910955425,25.566563,0,0,0,40,4449,300.26705,29057.4462890625,,,,,,,,,,,,,0,,,,0,,,,,,299.9933167,,,,
,31625718.23,299.9934387,33592.80859375,-3.85584580490796E-5,1.53787242635291E-6,1,0.999253354069792,40.0298881530762,1.99661306343058,18.8900008797646,-0.000439037506173784,-5.76111139784899E-5,0.25,1.5847510586066E-6,-3.85583756208038E-5,1.55928411051335E-6,299.9934387,299.9934387,33565.25390625,33620.36328125,56.9908802226791,20.6055023363511,25.186911,0,0,0,40,4449,300.2629,33592.80859375,,,,,,,,,,,,,0,,,,-0.0049,,,,,,299.9934387,,,,
,31625812.915,299.9985962,38324.9375,-5.49662691648696E-5,1.78982505706525E-6,1,0.999253354069792,40.0298881530762,1.99670790668761,18.8900008797646,-0.000621662110170512,-0.000106531456468296,0.25,1.00864157073153E-7,-5.49647219976204E-5,6.46620788885857E-8,299.9985962,299.9985962,38292.6328125,38357.2421875,57.1995750373137,20.604391374373,25.566563,0,0,0,40,4449,300.26745,38324.9375,,,,,,,,,,,,,0,,,,0,,,,,,299.9985962,,,,
,31625908.805,300.0019379,43117.59765625,-7.03965678857755E-5,2.4792247113316E-6,1,0.999253354069792,40.0298881530762,1.9967093758502,18.8900008797646,-0.000794508579278145,-0.000146070192588981,0.25,-7.22856640366875E-7,-7.03940217220524E-5,-7.69147227502184E-7,300.0010071,300.0028687,43089.75390625,43145.44140625,57.1542405831984,20.6045326678065,25.186911,0,0,0,40,4449,300.25985,43117.59765625,,,,,,,,,,,,,0,,,,-0.00245,,,,,,300.0019379,,,,
,31626007.29,300.0030518,48040.677734375,-8.68283932341342E-5,2.47422414961795E-6,1,0.999253354069792,40.0298881530762,1.99661284723348,18.8900008797646,-0.000983967816314664,-0.000156770614659711,0.25,1.17691149477379E-6,-8.68266149493149E-5,1.11981931389784E-6,300.0030518,300.0030518,48038.2421875,48043.11328125,57.1683098965445,20.6061954078321,25.186911,0,0,0,40,4449,300.25485,48040.677734375,,,,,,,,,,,,,0,,,,0,,,,,,300.0030518,,,,
,31626106.36,300.0062561,52992.92578125,-0.000103672477154768,2.19572351698806E-6,1,0.999253354069792,40.0298881530762,1.99664797267249,18.8900008797646,-0.0011716239801973,-0.000205922766131473,0.25,-2.52090456103655E-7,-0.000103669260155024,-3.20130132350129E-7,300.0062561,300.0062561,52990.06640625,52995.78515625,57.2589788047753,20.6048132222538,25.186911,0,0,0,40,4449,300.2521,52992.92578125,,,,,,,,,,,,,0,,,,0,,,,,,300.0062561,,,,
,31626202.62,300.008606,57802.900390625,-0.000120876120227994,2.12411164612982E-6,1,0.999253354069792,40.0298881530762,1.9966132490449,18.8900008797646,-0.00136698624071866,-0.000234531405594498,0.25,1.9765018091059E-7,-0.000120872689875435,1.183972177417E-7,300.008606,300.008606,57773.1640625,57832.63671875,57.088583787583,20.6056428667968,25.566563,0,0,0,40,4449,300.2514,57802.900390625,,,,,,,,,,,,,0,,,,-0.00245,,,,,,300.008606,,,,
,31626300.385,300.00506595,62691.740234375,-0.000137080807786799,2.93552732152897E-6,1,0.999253354069792,40.0298881530762,1.99642338387209,18.8900008797646,-0.00154978614537851,-0.000267785643350661,0.25,6.15502231141018E-8,-0.000137076837331034,-2.82217147907282E-8,300.0049744,300.0051575,62661.80078125,62721.6796875,57.1980117802753,20.6089690910196,25.186911,0,0,0,40,4449,300.2321,62691.740234375,,,,,,,,,,,,,0,,,,0,,,,,,300.00506595,,,,
,31626394.97,300.0136108,67416.640625,-0.000155899859182781,2.99804462697801E-6,1,0.999253354069792,40.0298881530762,1.99648989220508,18.8900008797646,-0.00176975373256756,-0.000263285051556468,0.25,3.72070183544071E-6,-0.000155897694411786,3.61861913978344E-6,300.0136108,300.0136108,67389.234375,67444.046875,57.2386564632753,20.6088836424004,25.186911,0,0,0,40,4449,300.2354,67416.640625,,,,,,,,,,,,,0,,,,0,,,,,,300.0136108,,,,
,31626492.325,300.0150757,72284.328125,-0.000173939376324712,3.51892467268279E-6,1,0.999253354069792,40.0298881530762,1.9964605686697,18.8900008797646,-0.00196520593953696,-0.000347438825650108,0.25,-5.98374702559104E-7,-0.000173933857680736,-7.11994532720066E-7,300.0150757,300.0150757,72281.8359375,72286.8203125,57.0932735586983,20.6070344994534,25.566563,0,0,0,40,4449,300.2253,72284.328125,,,,,,,,,,,,,0,,,,0,,,,,,300.0150757,,,,
,31626589.155,300.0117798,77124.86328125,-0.000190117900844633,3.01243636760705E-6,1,0.999253354069792,40.0298881530762,1.99652588333861,18.8900008797646,-0.00215404809189345,-0.000345214905334515,0.25,2.40208057478508E-6,-0.000190113899237099,2.27795053417883E-6,300.0117798,300.0117798,77089.8359375,77159.890625,57.251162519583,20.6026876661075,25.946213,0,0,0,40,4449,300.21335,77124.86328125,,,,,,,,,,,,,0,,,,-0.00245,,,,,,300.0117798,,,,
,31626688.02,300.0108337,82065.90234375,-0.000205748828311556,3.57836752605344E-6,1,0.999253354069792,40.0298881530762,1.99635392431229,18.8900008797646,-0.00232853744023862,-0.000387527438537707,0.25,1.36442732755114E-6,-0.000205743712457422,1.23029567314445E-6,300.0108337,300.0108337,82063.3671875,82068.4375,57.1253203279868,20.6083919008448,25.566563,0,0,0,40,4449,300.20685,82065.90234375,,,,,,,,,,,,,0,,,,-0.0049,,,,,,300.0108337,,,,
,31626782.955,300.01130675,86811.5234375,-0.000221789515861806,3.72455666510188E-6,1,0.999253354069792,40.0298881530762,1.99637990291821,18.8900008797646,-0.00251412154734875,-0.000394574420191723,0.25,3.52032512049996E-6,-0.000221785345414396,3.37584586493826E-6,300.0107727,300.0118408,86781.6796875,86841.3671875,56.8501870892175,20.6065836716495,25.946213,0,0,0,40,4449,300.18985,86811.5234375,,,,,,,,,,,,,0,,,,0,,,,,,300.01130675,,,,
,31626891.865,300.0111237,88505.25,-0.000226908492238364,3.78799652629237E-6,1,0.999253354069792,40.0298881530762,1.99642391471243,18.8900008797646,-0.00256628113422607,-0.000437868654139459,0.25,5.78111849303075E-7,-0.000226902264553021,4.30452300687261E-7,300.0108643,300.0113831,88477.859375,88532.640625,57.108906129083,20.6081153756897,25.186911,0,0,0,40,4449,300.19085,88505.25,,,,,,,,,,,,,0,,,,0,,,,,,300.0111237,,,,
,31626986.485,300.0047607,83776.875,-0.000215874043401183,3.47703471749552E-6,1,0.999253354069792,40.0298881530762,1.99641709555861,18.8900008797646,-0.00243817102944936,-0.00043565386037943,0.25,-1.13759852028062E-6,-0.000215867053280623,-1.27820520433635E-6,300.0047607,300.0047607,83774.3046875,83779.4453125,56.8486238321791,20.6059812931618,25.566563,0,0,0,40,4449,300.1858,83776.875,,,,,,,,,,,,,0,,,,0.0049,,,,,,300.0047607,,,,
,31627083.06,299.99745175,78950.48046875,-0.000193721229735256,3.19593277924591E-6,1,0.999253354069792,40.0298881530762,1.99635549457904,18.8900008797646,-0.00218938018676165,-0.000382414949189833,0.25,-2.6691951373375E-7,-0.000193715484647225,-3.93278520239155E-7,299.9972534,299.9976501,78920.5234375,78980.4375,56.8001628639868,20.6040691483244,25.186911,0,0,0,40,4449,300.1828,78950.48046875,,,,,,,,,,,,,0,,,,0.0049,,,,,,299.99745175,,,,
,31627180.07,299.99879455,74099.83203125,-0.000179888006298028,3.93638535368804E-6,1,0.999253354069792,40.0298881530762,1.99629297124254,18.8900008797646,-0.00203371710277348,-0.000350843239182418,0.25,1.28568449867022E-7,-0.000179882896243088,1.10842772232984E-8,299.9981689,299.9994202,74072.1953125,74127.46875,57.3559007411599,20.6074432337004,25.946213,0,0,0,40,4449,300.2016,74099.83203125,,,,,,,,,,,,,0,,,,0,,,,,,299.99879455,,,,
,31627277.155,299.9910889,69243.6796875,-0.000163309742021945,3.62774774259498E-6,1,0.999253354069792,40.0298881530762,1.99635221768009,18.8900008797646,-0.00185276306253817,-0.000281473055242989,0.25,3.3939834469815E-6,-0.000163307279572748,3.28710256480401E-6,299.9910889,299.9910889,69239.0078125,69248.3515625,57.0901470446214,20.6095544145316,25.566563,0,0,0,40,4449,300.2046,69243.6796875,,,,,,,,,,,,,0,,,,0,,,,,,299.9910889,,,,
,31627372.61,299.9876404,64473.4296875,-0.000143303438500802,3.24206437806842E-6,1,0.999253354069792,40.0298881530762,1.99625763178797,18.8900008797646,-0.00161667059643508,-0.000299192263376022,0.25,-1.64066269952083E-6,-0.000143298264404863,-1.73442660824165E-6,299.9876404,299.9876404,64445.87890625,64500.98046875,56.9947883652753,20.6109573448447,25.946213,0,0,0,40,4449,300.2128,64473.4296875,,,,,,,,,,,,,0,,,,0,,,,,,299.9876404,,,,
,31627470.43,299.9859924,59585.177734375,-0.000128489779781714,3.16609162322871E-6,1,0.999253354069792,40.0298881530762,1.99626441561415,18.8900008797646,-0.00145623012873434,-0.000229740493233563,0.25,1.93709098032827E-6,-0.000128487371900388,1.85282293529845E-6,299.9859924,299.9859924,59582.89453125,59587.4609375,57.149550812083,20.6080438500911,25.566563,0,0,0,40,4449,300.2195,59585.177734375,,,,,,,,,,,,,0,,,,-0.0049,,,,,,299.9859924,,,,
,31627568.945,299.9878845,54659.630859375,-0.000109064003282077,2.75221738260385E-6,1,0.999253354069792,40.0298881530762,1.99606637105131,18.8900008797646,-0.00123414348334925,-0.000205428508988269,0.25,7.20658578119028E-7,-0.00010906133998091,6.49075375834354E-7,299.9878845,299.9878845,54654.4609375,54664.80078125,57.301968373333,20.611543323446,25.566563,0,0,0,40,4449,300.2336,54659.630859375,,,,,,,,,,,,,0,,,,0,,,,,,299.9878845,,,,
,31627664.76,299.98016355,49872.41796875,-9.39525810951869E-5,2.81326108623432E-6,1,0.999253354069792,40.0298881530762,1.99615818734,18.8900008797646,-0.0010664068117935,-0.000158423092487322,0.25,2.26198428032195E-6,-9.39513851200894E-5,2.2002018386044E-6,299.9797668,299.9805603,49847.265625,49897.5703125,57.4129596230638,20.6118243077725,25.566563,0,0,0,40,4449,300.23255,49872.41796875,,,,,,,,,,,,,0,,,,-0.00245,,,,,,299.98016355,,,,
,31627761.82,299.98913575,45019.755859375,-7.61280116777735E-5,2.25232378413264E-6,1,0.999253354069792,40.0298881530762,1.99617108636905,18.8900008797646,-0.000854750743843247,-0.00018229850120334,0.25,-2.93828095452018E-6,-7.61238771098776E-5,-2.98825780251061E-6,299.9891052,299.9891663,44989.73046875,45049.78125,57.5231692442753,20.6122352335859,25.186911,0,0,0,40,4449,300.25245,45019.755859375,,,,,,,,,,,,,0,,,,-0.00245,,,,,,299.98913575,,,,
,31627857.62,299.9932556,40234.00390625,-6.03540639695885E-5,1.91459776105375E-6,1,0.999253354069792,40.0298881530762,1.99626383810117,18.8900008797646,-0.000680883196106117,-0.00012600776786199,0.25,-6.90660992449517E-7,-6.03518504796401E-5,-7.30372991231322E-7,299.9926147,299.9938965,40201.61328125,40266.39453125,57.3902923960061,20.6117128324385,25.566563,0,0,0,40,4449,300.2551,40234.00390625,,,,,,,,,,,,,0,,,,0,,,,,,299.9932556,,,,
,31627953.335,299.991333,35448.91015625,-4.63164274773621E-5,1.9890110574097E-6,1,0.999253354069792,40.0298881530762,1.9959604281821,18.8900008797646,-0.000526283940149167,-7.45112535669597E-5,0.25,1.43197167127507E-6,-4.63160217726362E-5,1.40140730600469E-6,299.991333,299.991333,35419.1171875,35478.703125,57.3433946848522,20.6152774738865,25.186911,0,0,0,40,4449,300.2638,35448.91015625,,,,,,,,,,,,,0,,,,0,,,,,,299.991333,,,,
,31628049.03,299.9922485,30664.09765625,-2.85023850510419E-5,1.48374725272932E-6,1,0.999253354069792,40.0298881530762,1.9962945237427,18.8900008797646,-0.00032236979999302,-5.47985422708752E-5,0.25,9.05247945417888E-8,-2.85016117272191E-5,7.17198261754822E-8,299.9915466,299.9929504,30631.53125,30696.6640625,57.0299616486406,20.6134615371654,25.566563,0,0,0,40,4449,300.2705,30664.09765625,,,,,,,,,,,,,0,,,,-0.00245,,,,,,299.9922485,,,,
,31628144.54,299.9923706,25891.05078125,-1.36370961102913E-5,1.50915479656181E-6,1,0.999253354069792,40.0298881530762,1.99617794808886,18.8900008797646,-0.000153230453915732,-3.19903168832736E-5,0.25,-4.67424059119729E-7,-1.36363880111336E-5,-4.76415452416282E-7,299.9923706,299.9923706,25858.51171875,25923.58984375,57.5208243587176,20.6161019990956,25.566563,0,0,0,40,4449,300.27305,25891.05078125,,,,,,,,,,,,,0,,,,0,,,,,,299.9923706,,,,
,31628239.555,299.9894714,21143.8408203125,1.30811421144901E-6,1.01598719199456E-6,1,0.999253354069792,40.0298881530762,1.99614654510248,18.8900008797646,1.51939783102598E-5,2.06702843846498E-7,0.25,-2.08353526624013E-7,1.30821366974708E-6,-2.07482858571738E-7,299.9894714,299.9894714,21111.521484375,21176.16015625,57.4121779945445,20.6142695537194,25.566563,0,0,0,40,4449,300.291,21143.8408203125,,,,,,,,,,,,,0,,,,0,,,,,,299.9894714,,,,
,31628333.695,299.9880981,16439.4150390625,1.58526251954246E-5,8.41892838462153E-7,1,0.999253354069792,40.0298881530762,1.996268811612,18.8900008797646,0.00018068167946982,2.2476199916419E-5,0.25,-7.58239379644644E-7,1.58526631942802E-5,-7.47730257878639E-7,299.9880981,299.9880981,16409.373046875,16469.45703125,57.4559491916215,20.6145122667583,25.946213,0,0,0,40,4449,300.2967,16439.4150390625,,,,,,,,,,,,,0,,,,0,,,,,,299.9880981,,,,
,31628429.265,299.989624,11664.6684570312,2.96012630709293E-5,5.6907038907632E-7,1,0.999253354069792,40.0298881530762,1.99633221153141,18.8900008797646,0.000334421643681212,5.9121459256755E-5,0.25,1.01344502052063E-7,2.9600327178744E-5,1.20940310929101E-7,299.989624,299.989624,11637.3349609375,11692.001953125,57.3160376866791,20.6147142345016,25.186911,0,0,0,40,4449,300.304,11664.6684570312,,,,,,,,,,,,,0,,,,0,,,,,,299.989624,,,,
,31628524.155,299.99597165,6919.17724609375,4.07240644707157E-5,4.63391584533835E-7,1,0.999253354069792,40.0298881530762,1.99635569285203,18.8900008797646,0.000461543357097598,7.29321021729288E-5,0.25,-6.04148766614715E-7,4.07232582881376E-5,-5.77145762954828E-7,299.9957275,299.9962158,6888.88232421875,6949.47216796875,57.0838940164676,20.6146983278458,25.186911,0,0,0,40,4449,300.302,6919.17724609375,,,,,,,,,,,,,0,,,,0,,,,,,299.99597165,,,,
,31628616.455,299.9994507,2305.74084472656,4.18247758465195E-5,3.17639316990653E-7,1,0.999253354069792,40.0298881530762,1.99624214195612,18.8900008797646,0.000473631161592565,7.69841339743718E-5,0.25,-4.36056852825306E-7,4.18238189592454E-5,-4.08310758261464E-7,299.9994507,299.9994507,2275.92797851562,2335.5537109375,57.4793980471984,20.6168309059494,25.566563,0,0,0,40,4449,300.30385,2305.74084472656,,,,,,,,,,,,,0,,,,0,,,,,,299.9994507,,,,
,31628708.64,299.997345,-2297.9267578125,-4.1103414644016E-5,4.28643921477625E-7,1,0.999253354069792,40.0298881530762,1.99620584764776,18.8900008797646,-0.000462841606778688,-9.07346894196583E-5,0.25,-9.05523483063005E-7,-4.11015927942209E-5,-9.32751265354707E-7,299.997345,299.997345,-2327.568359375,-2268.28515625,57.187068981006,20.616530059372,25.946213,0,0,0,40,4449,300.305,-2297.9267578125,,,,,,,,,,,,,0,,,,0.00245,,,,,,299.997345,,,,
,31628802.385,299.993927,-6984.36108398438,-4.02537522118062E-5,5.44280168351045E-7,1,0.999253354069792,40.0298881530762,1.99613478984998,18.8900008797646,-0.00045451221189373,-8.16213692500009E-5,0.25,-2.46764197741776E-7,-4.0252399154566E-5,-2.73429556998731E-7,299.9935608,299.9942932,-7017.0654296875,-6951.65673828125,57.2081729510253,20.6182606875763,25.566563,0,0,0,40,4449,300.30705,-6984.36108398438,,,,,,,,,,,,,0,,,,0,,,,,,299.993927,,,,
,31628895.745,300.0004272,-11650.0849609375,-2.97687024759245E-5,9.11938203533896E-7,1,0.999253354069792,40.0298881530762,1.9962060505603,18.8900008797646,-0.000336349678419882,-5.91244620076551E-5,0.25,-7.2918309807565E-8,-2.97677690291122E-5,-9.26247886006186E-8,300.0004272,300.0004272,-11674.74609375,-11625.423828125,57.2331850636407,20.6169245127135,25.946213,0,0,0,40,4449,300.3174,-11650.0849609375,,,,,,,,,,,,,0,,,,0,,,,,,300.0004272,,,,
,31628992.26,300.0033569,-16475.357421875,-1.63694487278101E-5,9.71908638627983E-7,1,0.999253354069792,40.0298881530762,1.99619180752188,18.8900008797646,-0.000184707910570359,-3.39281701896361E-5,0.25,-1.65427359188478E-7,-1.63688516520897E-5,-1.76250835700349E-7,300.0033569,300.0033569,-16507.650390625,-16443.064453125,57.495030617583,20.6190250083846,25.566563,0,0,0,40,4449,300.30505,-16475.357421875,,,,,,,,,,,,,0,,,,0.0049,,,,,,300.0033569,,,,
,31629089.84,300.00585935,-21352.5322265625,-4.00155910789091E-7,1.14052899075442E-6,1,0.999253354069792,40.0298881530762,1.99628695378329,18.8900008797646,-2.59479175157999E-6,-1.19149610323688E-5,0.25,-9.84717842091675E-7,-3.99493195195545E-7,-9.84952929117925E-7,300.0057678,300.0059509,-21380.517578125,-21324.546875,57.2761746321984,20.6157895721465,25.186911,0,0,0,40,4449,300.3002,-21352.5322265625,,,,,,,,,,,,,0,,,,0.00245,,,,,,300.00585935,,,,
,31629187.085,300.00845335,-26212.185546875,1.5391719665998E-5,1.50814621128453E-6,1,0.999253354069792,40.0298881530762,1.99632941743016,18.8900008797646,0.000173802889179753,3.1234474975472E-5,0.25,9.63578327823888E-8,1.53911964317311E-5,1.06517401221513E-7,300.0080261,300.0088806,-26247.240234375,-26177.130859375,57.3949821671215,20.6184071903262,25.566563,0,0,0,40,4449,300.28795,-26212.185546875,,,,,,,,,,,,,0,,,,-0.00245,,,,,,300.00845335,,,,
,31629283.21,300.0076904,-31017.4326171875,3.16061573747703E-5,1.56311718950236E-6,1,0.999253354069792,40.0298881530762,1.9961492645932,18.8900008797646,0.000357151700190719,6.2479240135911E-5,0.25,5.15808463624502E-8,3.16051822826974E-5,7.24266755818488E-8,300.0071716,300.0082092,-31050.025390625,-30984.83984375,57.5575608991215,20.6219978967214,25.186911,0,0,0,40,4449,300.28075,-31017.4326171875,,,,,,,,,,,,,0,,,,-0.00245,,,,,,300.0076904,,,,
,31629378.985,300.0086365,-35802.1953125,4.49005445700941E-5,1.96800125165196E-6,1,0.999253354069792,40.0298881530762,1.99634380268703,18.8900008797646,0.000507144226378938,9.03964584087649E-5,0.25,2.17372171455332E-7,4.48990657686563E-5,2.46950132841075E-7,300.0086365,300.0086365,-35832.18359375,-35772.20703125,57.5591241561599,20.6182317491737,25.946213,0,0,0,40,4449,300.28805,-35802.1953125,,,,,,,,,,,,,0,,,,0,,,,,,300.0086365,,,,
,31629475.62,300.015625,-40632.087890625,6.34754807001214E-5,1.52457092937588E-6,1,0.999253354069792,40.0298881530762,1.99636253435018,18.8900008797646,0.000721612880835053,0.000100888052813998,0.25,-2.07276674006118E-6,6.34749447273092E-5,-2.03092255529308E-6,300.015625,300.015625,-40634.65625,-40629.51953125,57.4074882234292,20.6195245710982,25.946213,0,0,0,40,4449,300.2616,-40632.087890625,,,,,,,,,,,,,0,,,,-0.0049,,,,,,300.015625,,,,
,31629570.935,300.01269535,-45397.220703125,8.06286712510287E-5,2.31021331040997E-6,1,0.999253354069792,40.0298881530762,1.99635116729159,18.8900008797646,0.000913748977832415,0.000144675026591503,0.25,-1.17107296166757E-6,8.06270409959477E-5,-1.11802250566769E-6,300.0126038,300.0127869,-45427.46484375,-45366.9765625,57.1855057239676,20.6157231800261,25.186911,0,0,0,40,4449,300.25825,-45397.220703125,,,,,,,,,,,,,0,,,,-0.00245,,,,,,300.01269535,,,,
,31629666.05,300.00923155,-50149.88671875,9.66043753098733E-5,2.25366132081514E-6,1,0.999253354069792,40.0298881530762,1.99633613397273,18.8900008797646,0.00109403161774547,0.000177721725555219,0.25,-1.01539183732927E-6,9.66021843046187E-5,-9.51907497004361E-7,300.0090637,300.0093994,-50174.515625,-50125.2578125,57.6107116384292,20.6178119260752,25.946213,0,0,0,40,4449,300.23785,-50149.88671875,,,,,,,,,,,,,0,,,,-0.00245,,,,,,300.00923155,,,,
,31629760.81,300.0162964,-54886.44921875,0.0001142723197242,2.88486400233867E-6,1,0.999253354069792,40.0298881530762,1.9962307903643,18.8900008797646,0.00129611425068165,0.000198318860610287,0.25,-2.25338498981078E-6,0.00011427039599334,-2.17834188727179E-6,300.0159912,300.0166016,-54916.4453125,-54856.453125,57.1706547821022,20.6166061922317,25.566563,0,0,0,40,4449,300.2327,-54886.44921875,,,,,,,,,,,,,0,,,,0,,,,,,300.0162964,,,,
,31629854.93,300.0140991,-59591.712890625,0.000128141189249182,1.93255655769722E-6,1,0.999253354069792,40.0298881530762,1.99610514939598,18.8900008797646,0.00144983153343802,0.000242581726430336,0.25,-7.3903980088036E-7,0.000128137876905334,-6.55035603689583E-7,300.013916,300.0142822,-59619.2734375,-59564.15234375,57.3926372815638,20.6195752079524,25.186911,0,0,0,40,4449,300.22445,-59591.712890625,,,,,,,,,,,,,0,,,,-0.00245,,,,,,300.0140991,,,,
,31629950.445,300.01133725,-64364.126953125,0.000145698621077662,2.81135624301865E-6,1,0.999253354069792,40.0298881530762,1.99627867552477,18.8900008797646,0.00165240054049446,0.000254016123021641,0.25,-2.77103417108706E-6,0.000145696142248455,-2.67557078138946E-6,300.0106506,300.0120239,-64396.734375,-64331.51953125,57.146424298006,20.619938501856,25.946213,0,0,0,40,4449,300.21165,-64364.126953125,,,,,,,,,,,,,0,,,,-0.00245,,,,,,300.01133725,,,,
,31630044.79,300.00950625,-69079.0546875,0.000161963760875776,2.58113927938863E-6,1,0.999253354069792,40.0298881530762,1.99642834691229,18.8900008797646,0.0018346292715391,0.000296070392903053,0.25,-1.8704308327993E-6,0.000161960233508155,-1.76447071935696E-6,300.0084229,300.0105896,-69104.0703125,-69054.0390625,57.5161345876022,20.6187736895108,25.946213,0,0,0,40,4449,300.2108,-69079.0546875,,,,,,,,,,,,,0,,,,0,,,,,,300.00950625,,,,
,31630140.695,300.0209045,-73870.7734375,0.000177560618653435,2.74627732287681E-6,1,0.999253354069792,40.0298881530762,1.99617563877636,18.8900008797646,0.00200988827554762,0.000331291005271452,0.25,-1.45335891433681E-6,0.000177556298976843,-1.33734315516437E-6,300.0209045,300.0209045,-73900.71875,-73840.828125,57.4575124486599,20.6249905583225,25.946213,0,0,0,40,4449,300.18945,-73870.7734375,,,,,,,,,,,,,0,,,,-0.00245,,,,,,300.0209045,,,,
,31630235.445,300.0141602,-78607.96875,0.000194765848642401,3.14151172701361E-6,1,0.999253354069792,40.0298881530762,1.99644181799819,18.8900008797646,0.00220539542937141,0.00036071325831174,0.25,-1.83512599543407E-6,0.000194761326716981,-1.70801036908367E-6,300.0141602,300.0141602,-78627.9140625,-78588.0234375,57.4332819645638,20.6226765528527,25.946213,0,0,0,40,4449,300.1777,-78607.96875,,,,,,,,,,,,,0,,,,0.00245,,,,,,300.0141602,,,,
,31630333.52,300.015564,-83510.3125,0.000216102025501983,3.36525266503586E-6,1,0.999253354069792,40.0298881530762,1.99648607435231,18.8900008797646,0.00244978690031212,0.000384402114431502,0.25,-3.43667878543349E-6,0.000216097923604603,-3.29577050826987E-6,300.015564,300.015564,-83515.2265625,-83505.3984375,57.1550222117176,20.6207382909321,25.566563,0,0,0,40,4449,300.1682,-83510.3125,,,,,,,,,,,,,0,,,,0,,,,,,300.015564,,,,
,31630424.665,300.0116272,-88062.17578125,0.00022820254388298,2.89514467960676E-6,1,0.999253354069792,40.0298881530762,1.9964553080682,18.8900008797646,0.00258378534733715,0.000424036527354602,0.25,-2.02646488379806E-6,0.000228197213982818,-1.87788557594227E-6,300.0110474,300.012207,-88092.1796875,-88032.171875,57.4715817620061,20.6215877704939,25.566563,0,0,0,40,4449,300.159,-88062.17578125,,,,,,,,,,,,,0,,,,-0.00245,,,,,,300.0116272,,,,
,31630531.835,300.0121765,-87358.8671875,0.000224312045286375,3.6324382997265E-6,1,0.999253354069792,40.0298881530762,1.99638304575449,18.8900008797646,0.00254160718169637,0.000405484415087178,0.25,-2.99229784334184E-6,0.000224307450770707,-2.84619397504335E-6,300.0121765,300.0121765,-87363.7890625,-87353.9453125,57.4145228801022,20.6239254566767,25.566563,0,0,0,40,4449,300.1565,-87358.8671875,,,,,,,,,,,,,0,,,,-0.0049,,,,,,300.0121765,,,,
,31630624.89,300.0027161,-82709.14453125,0.000209201712888756,3.57401478998764E-6,1,0.999253354069792,40.0298881530762,1.99638003687686,18.8900008797646,0.00237038498225824,0.000378222250901344,0.25,-2.78621357459317E-6,0.000209197483459866,-2.64978532549165E-6,300.0027161,300.0027161,-82711.5546875,-82706.734375,57.5528711280061,20.6248809888919,25.186911,0,0,0,40,4449,300.15315,-82709.14453125,,,,,,,,,,,,,0,,,,0.00245,,,,,,300.0027161,,,,
,31630717.475,299.9965515,-78081.58984375,0.00019170343766804,3.49818782177698E-6,1,0.999253354069792,40.0298881530762,1.99618699309548,18.8900008797646,0.00217042068104242,0.000355200541775225,0.25,-1.78842495405206E-6,0.000191699094471209,-1.6632844944621E-6,299.9965515,299.9965515,-78109.234375,-78053.9453125,57.3199458292753,20.6239137018036,25.946213,0,0,0,40,4449,300.16085,-78081.58984375,,,,,,,,,,,,,0,,,,0,,,,,,299.9965515,,,,
,31630813.745,299.9906921,-73269.19140625,0.000179974824510865,2.76377963235477E-6,1,0.999253354069792,40.0298881530762,1.99616116465857,18.8900008797646,0.00203717694497653,0.000335948688956418,0.25,-1.45941335206581E-6,0.000179970630207522,-1.3417938950202E-6,299.9906921,299.9906921,-73301.7734375,-73236.609375,57.3856026248907,20.6263442651712,25.566563,0,0,0,40,4449,300.1672,-73269.19140625,,,,,,,,,,,,,0,,,,0.00245,,,,,,299.9906921,,,,
,31630910.18,299.994873,-68452.79296875,0.00015888658228386,2.95424936913027E-6,1,0.999253354069792,40.0298881530762,1.99626431014385,18.8900008797646,0.00180463329532664,0.000261558670702384,0.25,-4.38837891579613E-6,0.000158884873214857,-4.2843279050432E-6,299.994873,299.994873,-68455.1796875,-68450.40625,57.3402681707753,20.6247492252181,25.186911,0,0,0,40,4449,300.17365,-68452.79296875,,,,,,,,,,,,,0,,,,0.0049,,,,,,299.994873,,,,
,31631004.025,299.99139405,-63760.14453125,0.000143918296578752,2.65695920829313E-6,1,0.999253354069792,40.0298881530762,1.9963894365188,18.8900008797646,0.00163115158799723,0.000257537382283245,0.25,-2.15233342196837E-6,0.000143915566350007,-2.05802915586042E-6,299.991272,299.9915161,-63787.859375,-63732.4296875,57.6114932669484,20.6210033035308,25.186911,0,0,0,40,4449,300.1791,-63760.14453125,,,,,,,,,,,,,0,,,,0.0049,,,,,,299.99139405,,,,
,31631098.565,299.9815674,-59037.732421875,0.000126202248808995,2.98318027208337E-6,1,0.999253354069792,40.0298881530762,1.9962193002301,18.8900008797646,0.00143392580942254,0.000204566992117777,0.25,-3.76737914427014E-6,0.000126201124788446,-3.68453743007797E-6,299.9810181,299.9821167,-59070.2578125,-59005.20703125,57.5216059872369,20.6259209298354,25.186911,0,0,0,40,4449,300.18845,-59037.732421875,,,,,,,,,,,,,0,,,,0,,,,,,299.9815674,,,,
,31631193.205,299.982605,-54307.8046875,0.000108771373997468,2.17220363268344E-6,1,0.999253354069792,40.0298881530762,1.99636520695249,18.8900008797646,0.00123301314157559,0.000193334615447353,0.25,-1.74240628244636E-6,0.000108769409302895,-1.67097427710817E-6,299.9820557,299.9831543,-54337.703125,-54277.90625,57.5309855294676,20.6223707752027,25.566563,0,0,0,40,4449,300.21315,-54307.8046875,,,,,,,,,,,,,0,,,,0,,,,,,299.982605,,,,
,31631289.645,299.9856873,-49486.21875,9.24926984049486E-5,2.37180196826491E-6,1,0.999253354069792,40.0298881530762,1.99632257543896,18.8900008797646,0.00104677868822331,0.000174097739075253,0.25,-6.23544238550082E-7,9.24904486040794E-5,-5.62757194420197E-7,299.9856873,299.9856873,-49486.21875,-49486.21875,57.6716786629292,20.622198799701,25.186911,0,0,0,40,4449,300.2127,-49486.21875,,,,,,,,,,,,,0,,,,0,,,,,,299.9856873,,,,
,31631383.695,299.9894409,-44786.126953125,7.79663766972726E-5,2.00554837670553E-6,1,0.999253354069792,40.0298881530762,1.9961957892961,18.8900008797646,0.000880419336264411,0.00015774276422614,0.25,4.47181331309626E-7,7.79638253393786E-5,4.98448627696263E-7,299.9894409,299.9894409,-44788.7578125,-44783.49609375,57.3973270526791,20.624399972096,25.946213,0,0,0,40,4449,300.219,-44786.126953125,,,,,,,,,,,,,0,,,,-0.00245,,,,,,299.9894409,,,,
,31631477.535,299.9908142,-40095.599609375,6.03806499600088E-5,2.11957998983144E-6,1,0.999253354069792,40.0298881530762,1.99617592905464,18.8900008797646,0.000684664486958319,0.000105799159587405,0.25,-1.10131593452815E-6,6.0379620197458E-5,-1.06152751539842E-6,299.9908142,299.9908142,-40100.48828125,-40090.7109375,57.65057469291,20.6234098829895,25.566563,0,0,0,40,4449,300.21955,-40095.599609375,,,,,,,,,,,,,0,,,,0.0049,,,,,,299.9908142,,,,
,31631571.61,299.9916077,-35393.51171875,4.48218702534981E-5,1.52258023104051E-6,1,0.999253354069792,40.0298881530762,1.99608449592276,18.8900008797646,0.000507417205151829,8.31619006463272E-5,0.25,-4.08080716078019E-7,4.48208325478527E-5,-3.78526688919095E-7,299.9916077,299.9916077,-35398.5,-35388.5234375,57.4856510753522,20.6229936547151,25.946213,0,0,0,40,4449,300.2289,-35393.51171875,,,,,,,,,,,,,0,,,,0,,,,,,299.9916077,,,,
,31631664.945,299.9882813,-30728.6123046875,2.87685642366677E-5,1.37521379584051E-6,1,0.999253354069792,40.0298881530762,1.99615491171712,18.8900008797646,0.000328071763457408,3.96472694530482E-5,0.25,-1.47675035931779E-6,2.87687016037075E-5,-1.45772717310812E-6,299.9882813,299.9882813,-30761.17578125,-30696.048828125,57.2542890336599,20.622428623166,25.566563,0,0,0,40,4449,300.23595,-30728.6123046875,,,,,,,,,,,,,0,,,,0,,,,,,299.9882813,,,,
,31631757.1,299.99464415,-26123.72265625,1.61695349532147E-5,1.36587801615623E-6,1,0.999253354069792,40.0298881530762,1.99619335719383,18.8900008797646,0.000185935802083855,1.34081901645038E-5,0.25,-1.61528586903875E-6,1.61701266553086E-5,-1.60456029690686E-6,299.9944153,299.994873,-26153.564453125,-26093.880859375,57.393418910083,20.6183173306846,25.946213,0,0,0,40,4449,300.24225,-26123.72265625,,,,,,,,,,,,,0,,,,0.00245,,,,,,299.99464415,,,,
,31631852.035,299.98693845,-21378.765625,8.838178377288E-7,1.03018895893747E-6,1,0.999253354069792,40.0298881530762,1.99623478085094,18.8900008797646,1.2098098379137E-5,-1.04339812394399E-5,0.25,-1.07618460912599E-6,8.84503425886926E-7,-1.07556903121831E-6,299.9865417,299.9873352,-21411.119140625,-21346.412109375,56.9729027667368,20.618290408995,25.946213,0,0,0,40,4449,300.254,-21378.765625,,,,,,,,,,,,,0,,,,0,,,,,,299.98693845,,,,
,31631946.335,299.9928589,-16666.5771484375,-1.41475200923067E-5,1.16136588256945E-6,1,0.999253354069792,40.0298881530762,1.99624129384007,18.8900008797646,-0.000158150102189309,-3.79238971241268E-5,0.25,-9.03807408949045E-7,-1.4146505893225E-5,-9.1314078659224E-7,299.9928589,299.9928589,-16689.08203125,-16644.072265625,57.5817913832176,20.6198560023012,25.566563,0,0,0,40,4449,300.2586,-16666.5771484375,,,,,,,,,,,,,0,,,,0,,,,,,299.9928589,,,,
,31632038.98,299.98846435,-12036.4399414062,-2.82760373187294E-5,6.48762148931564E-7,1,0.999253354069792,40.0298881530762,1.99635499135583,18.8900008797646,-0.000318757327549254,-6.04924134207623E-5,0.25,-4.52169319944591E-7,-2.8274909084957E-5,-4.7087871170373E-7,299.9880371,299.9888916,-12056.4580078125,-12016.421875,57.159711982833,20.617083749303,25.946213,0,0,0,40,4449,300.2697,-12036.4399414062,,,,,,,,,,,,,0,,,,0,,,,,,299.98846435,,,,
,31632132.085,299.9861145,-7383.2138671875,-3.99080482304362E-5,6.33576107522947E-7,1,0.999253354069792,40.0298881530762,1.99636954778364,18.8900008797646,-0.000450560673197136,-8.14999761267425E-5,0.25,-2.95108340177069E-7,-3.99066844340929E-5,-3.21544539505144E-7,299.9861145,299.9861145,-7408.17626953125,-7358.25146484375,57.1886322380445,20.617193423509,25.946213,0,0,0,40,4449,300.2787,-7383.2138671875,,,,,,,,,,,,,0,,,,0.00245,,,,,,299.9861145,,,,
,31632225.98,299.98942565,-2689.80529785156,-4.29626527214969E-5,3.9993566017392E-7,1,0.999253354069792,40.0298881530762,1.996742562462,18.8900008797646,-0.000485503035198174,-8.5620781699882E-5,0.25,-1.29029081455531E-7,-4.29613024915156E-5,-1.57515251723155E-7,299.9887695,299.9900818,-2714.90625,-2664.70434570313,57.241001348833,20.6116134088231,25.946213,0,0,0,40,4449,300.27015,-2689.80529785156,,,,,,,,,,,,,0,,,,-0.00245,,,,,,299.98942565,,,,
,31632317.025,299.9925842,1860.30987548828,3.99550440569484E-5,4.56653474108127E-7,1,0.999253354069792,40.0298881530762,1.99657858191853,18.8900008797646,0.000452341799695634,7.46457919650448E-5,0.25,-3.20038683070389E-7,3.99540755386911E-5,-2.93532732452253E-7,299.9925842,299.9925842,1855.32409667969,1865.29565429687,57.5317671579869,20.6136976073644,25.946213,0,0,0,40,4449,300.2879,1860.30987548828,,,,,,,,,,,,,0,,,,0.00245,,,,,,299.9925842,,,,
,31632410.245,299.9948425,6518.28466796875,4.12803657441878E-5,5.80395394875393E-7,1,0.999253354069792,40.0298881530762,1.99657658381945,18.8900008797646,0.000467309871902538,7.73282704555424E-5,0.25,-3.1236839376237E-7,4.12793511116126E-5,-2.85001784320823E-7,299.9948425,299.9948425,6493.45947265625,6543.10986328125,57.0776409883137,20.6132147921362,25.566563,0,0,0,40,4449,300.28455,6518.28466796875,,,,,,,,,,,,,0,,,,0.00245,,,,,,299.9948425,,,,
,31632505.915,300.0048523,11301.361328125,3.12125294553329E-5,7.25580639714407E-7,1,0.999253354069792,40.0298881530762,1.99643272230691,18.8900008797646,0.000353111384313282,5.96319458642421E-5,0.25,-1.32915577903595E-7,3.12116840877586E-5,-1.12243544158775E-7,300.0048523,300.0048523,11276.34375,11326.37890625,57.301968373333,20.6144534096722,25.566563,0,0,0,40,4449,300.28995,11301.361328125,,,,,,,,,,,,,0,,,,0,,,,,,300.0048523,,,,
,31632600.84,300.0030518,16044.1821289062,1.74844290322677E-5,9.07203376416389E-7,1,0.999253354069792,40.0298881530762,1.99621210645843,18.8900008797646,0.000197927611262254,3.25647097088223E-5,0.25,-1.48404994438677E-7,1.74840063622342E-5,-1.36832506637503E-7,300.0030518,300.0030518,16014.416015625,16073.9482421875,57.3840393678522,20.6169395457046,25.186911,0,0,0,40,4449,300.27975,16044.1821289062,,,,,,,,,,,,,0,,,,-0.00245,,,,,,300.0030518,,,,
,31632698.565,300.0056458,20929.06640625,2.02592380955478E-6,1.21610302662667E-6,1,0.999253354069792,40.0298881530762,1.99630878733542,18.8900008797646,2.17741395325284E-5,1.04734564416511E-5,0.25,5.755100166467E-7,2.02548296963416E-6,5.76831986901361E-7,300.0056458,300.0056458,20901.4375,20956.6953125,57.1784710672945,20.614374944373,26.325863,0,0,0,40,4449,300.2759,20929.06640625,,,,,,,,,,,,,0,,,,0,,,,,,300.0056458,,,,
,31632794.965,300.0144043,25748.9013671875,-1.31788787946623E-5,1.27144170470174E-6,1,0.999253354069792,40.0298881530762,1.99630878114298,18.8900008797646,-0.000149191265741231,-2.45664573885902E-5,0.25,1.10101157855156E-7,-1.317855500908E-5,1.01394874200142E-7,300.0144043,300.0144043,25719.005859375,25778.796875,57.1432977839291,20.6130042183856,25.946213,0,0,0,40,4449,300.2668,25748.9013671875,,,,,,,,,,,,,0,,,,0.00245,,,,,,300.0144043,,,,
,31632891.775,300.01022335,30586.9990234375,-2.88356319200977E-5,1.58997966539028E-6,1,0.999253354069792,40.0298881530762,1.9963087954699,18.8900008797646,-0.00032593097053212,-5.66514110805446E-5,0.25,-1.56178658388229E-8,-2.88347601091377E-5,-3.46407483527437E-8,300.0099487,300.010498,30557.130859375,30616.8671875,56.9557069393137,20.6130150300147,25.566563,0,0,0,40,4449,300.2586,30586.9990234375,,,,,,,,,,,,,0,,,,-0.0049,,,,,,300.01022335,,,,
,31632989.11,300.0111084,35449.849609375,-4.52764793698611E-5,1.66312629866662E-6,1,0.999253354069792,40.0298881530762,1.99626743989313,18.8900008797646,-0.000517069790002731,-5.82611773857263E-5,0.25,2.69032391932301E-6,-4.5276900980565E-5,2.66040382345081E-6,300.0111084,300.0111084,35419.78515625,35479.9140625,57.2191157502945,20.6101021054853,25.946213,0,0,0,40,4449,300.2424,35449.849609375,,,,,,,,,,,,,0,,,,0.0049,,,,,,300.0111084,,,,
,31633086.75,300.0111389,40332.212890625,-6.28873035349561E-5,1.91001496409594E-6,1,0.999253354069792,40.0298881530762,1.99609628608434,18.8900008797646,-0.000712888282158895,-0.000111178780883244,0.25,1.05929062603736E-6,-6.28861276850162E-5,1.0178570798148E-6,300.0111389,300.0111389,40296.9296875,40367.49609375,57.024490249006,20.6147884508626,25.566563,0,0,0,40,4449,300.2357,40332.212890625,,,,,,,,,,,,,0,,,,-0.00245,,,,,,300.0111389,,,,
,31633183.66,300.0142517,45178.0859375,-7.77802971332699E-5,1.96165200180882E-6,1,0.999253354069792,40.0298881530762,1.99615002126974,18.8900008797646,-0.000881030287851615,-0.000141592719813352,0.25,9.49049467909151E-7,-7.77786006640297E-5,8.97869717290833E-7,300.0142517,300.0142517,45145.4921875,45210.6796875,57.2316218066022,20.6135337747775,25.566563,0,0,0,40,4449,300.2276,45178.0859375,,,,,,,,,,,,,0,,,,0,,,,,,300.0142517,,,,
,31633278.62,300.0101624,49923.04296875,-9.46064961184303E-5,2.19829133085751E-6,1,0.999253354069792,40.0298881530762,1.99607542649609,18.8900008797646,-0.0010687556905624,-0.000188550234906664,0.25,-2.90731259207557E-7,-9.46035023695024E-5,-3.5287290520821E-7,300.0101624,300.0101624,49893.30078125,49952.78515625,57.1753445532176,20.6141783134142,25.566563,0,0,0,40,4449,300.21755,49923.04296875,,,,,,,,,,,,,0,,,,0,,,,,,300.0101624,,,,
,31633374.46,300.0127563,54713.12890625,-0.0001130744711297,2.27444094231737E-6,1,0.999253354069792,40.0298881530762,1.99589281813912,18.8900008797646,-0.0012804057307552,-0.000207261701752499,0.25,1.25176238336355E-6,-0.000113071939398438,1.17752413496926E-6,300.0127563,300.0127563,54680.7421875,54745.515625,57.1815975813714,20.6119839251654,25.946213,0,0,0,40,4449,300.20525,54713.12890625,,,,,,,,,,,,,0,,,,-0.00245,,,,,,300.0127563,,,,
,31633471.515,300.0092773,59563.134765625,-0.000128586147077816,2.98050439865898E-6,1,0.999253354069792,40.0298881530762,1.99605090523795,18.8900008797646,-0.00145422779086605,-0.000246884686647679,0.25,4.34888912848362E-7,-0.000128582643367186,3.50589110637975E-7,300.0092773,300.0092773,59542.98828125,59583.28125,57.1565854687561,20.6098768825648,25.566563,0,0,0,40,4449,300.18645,59563.134765625,,,,,,,,,,,,,0,,,,0,,,,,,300.0092773,,,,
,31633568.345,300.0124359,64403.658203125,-0.000148044554915968,3.11464501139226E-6,1,0.999253354069792,40.0298881530762,1.99600952057069,18.8900008797646,-0.00168630023707605,-0.000214724907105878,0.25,6.65090974602474E-6,-0.000148044540646523,6.55378596256993E-6,300.0122986,300.0125732,64381.23046875,64426.0859375,57.1894138665637,20.6115008485004,26.325863,0,0,0,40,4449,300.18255,64403.658203125,,,,,,,,,,,,,0,,,,-0.00245,,,,,,300.0124359,,,,
,31633666.14,300.01138305,69288.9609375,-0.000165657505176409,2.70898071327201E-6,1,0.999253354069792,40.0298881530762,1.99589763546306,18.8900008797646,-0.0018814059860817,-0.000271505261578339,0.25,4.6772664009602E-6,-0.000165655693291365,4.56880256726423E-6,300.0109558,300.0118103,69263.9453125,69313.9765625,56.933039712256,20.6097949028398,25.946213,0,0,0,40,4449,300.1834,69288.9609375,,,,,,,,,,,,,0,,,,0,,,,,,300.01138305,,,,
,31633765.1,300.01600645,74239.12109375,-0.000181439549020605,3.22838745187506E-6,1,0.999253354069792,40.0298881530762,1.99592643417479,18.8900008797646,-0.00205642495058577,-0.000321901030351853,0.25,2.95270865833632E-6,-0.000181436125737452,2.83411929702944E-6,300.0158691,300.0161438,74206.765625,74271.4765625,56.800944492506,20.6074238349447,25.566563,0,0,0,40,4449,300.1737,74239.12109375,,,,,,,,,,,,,0,,,,0.00245,,,,,,300.01600645,,,,
,31633863.94,300.01823425,79177.3046875,-0.000202546875412253,2.84462732655162E-6,1,0.999253354069792,40.0298881530762,1.99602854551239,18.8900008797646,-0.00230374488598636,-0.000313312538062281,0.25,7.37063922468498E-6,-0.000202545707037725,7.23829161732844E-6,300.0179138,300.0185547,79144.859375,79209.75,56.8525319747752,20.6060895372975,25.566563,0,0,0,40,4449,300.15505,79177.3046875,,,,,,,,,,,,,0,,,,0,,,,,,300.01823425,,,,
,31633963.28,300.0145264,84145.6953125,-0.000217947338562045,3.67992588976942E-6,1,0.999253354069792,40.0298881530762,1.99597836109475,18.8900008797646,-0.00247564649238532,-0.000355611661429868,0.25,6.29540668671799E-6,-0.000217945053940768,6.15322271945835E-6,300.0145264,300.0145264,84143.234375,84148.15625,56.8767624588714,20.6061668928491,25.946213,0,0,0,40,4449,300.14415,84145.6953125,,,,,,,,,,,,,0,,,,-0.0049,,,,,,300.0145264,,,,
,31634058.57,300.0148315,88908.94921875,-0.000233800824091187,2.94292366210325E-6,1,0.999253354069792,40.0298881530762,1.9958829353704,18.8900008797646,-0.00265782566682852,-0.000368637064329861,0.25,7.88786621338328E-6,-0.000233799119990663,7.73549126087745E-6,300.0148315,300.0148315,88876.4609375,88941.4375,56.7962547213906,20.6062225598871,25.946213,0,0,0,40,4449,300.13445,88908.94921875,,,,,,,,,,,,,0,,,,-0.00245,,,,,,300.0148315,,,,
,31634166.695,300.0079651,86398.6640625,-0.000224858154987655,3.46872430805369E-6,1,0.999253354069792,40.0298881530762,1.99595644295525,18.8900008797646,-0.00254523088084308,-0.000418191422352584,0.25,1.95536901818179E-6,-0.000224852898601083,1.8088778404256E-6,300.0079041,300.0080261,86368.5859375,86428.7421875,57.0213637349291,20.6071090575392,25.566563,0,0,0,40,4449,300.1115,86398.6640625,,,,,,,,,,,,,0,,,,-0.0049,,,,,,300.0079651,,,,
,31634261.37,299.99505615,81667.55859375,-0.000209256225924709,3.47904013640508E-6,1,0.999253354069792,40.0298881530762,1.99600338268358,18.8900008797646,-0.00237775762661385,-0.00033680167701481,0.25,6.45441311043421E-6,-0.000209254440564509,6.31779825467651E-6,299.9950256,299.9950867,81640.0625,81695.0546875,56.8955215433329,20.6096422655532,25.946213,0,0,0,40,4449,300.13455,81667.55859375,,,,,,,,,,,,,0,,,,0.00245,,,,,,299.99505615,,,,
,31634358.525,299.9925842,76811.2890625,-0.000191828126638591,3.00047989625075E-6,1,0.999253354069792,40.0298881530762,1.99594672795435,18.8900008797646,-0.00217953123773724,-0.000309514067742842,0.25,5.84873605929151E-6,-0.000191826453703183,5.72334835665742E-6,299.9925842,299.9925842,76806.1640625,76816.4140625,57.1581487257945,20.6123268601772,26.325863,0,0,0,40,4449,300.14225,76811.2890625,,,,,,,,,,,,,0,,,,0.00245,,,,,,299.9925842,,,,
,31634455.12,299.9922485,71982.82421875,-0.00017268550798676,3.23816104905532E-6,1,0.999253354069792,40.0298881530762,1.99602267006937,18.8900008797646,-0.00195776054324171,-0.000303719538157672,0.25,3.04609723667269E-6,-0.000172682545877222,2.93314892557433E-6,299.9922485,299.9922485,71952.7578125,72012.890625,57.1612752398714,20.6106478117708,26.325863,0,0,0,40,4449,300.14775,71982.82421875,,,,,,,,,,,,,0,,,,0.0049,,,,,,299.9922485,,,,
,31634551.97,299.98782345,67142.1875,-0.000157586424889525,2.5241587917252E-6,1,0.999253354069792,40.0298881530762,1.9959442118382,18.8900008797646,-0.00179460336671646,-0.0002304566599175,0.25,6.91148936918278E-6,-0.000157586441724783,6.80817780194603E-6,299.9875793,299.9880676,67109.546875,67174.828125,57.0291800201214,20.6136025841269,26.325863,0,0,0,40,4449,300.1588,67142.1875,,,,,,,,,,,,,0,,,,0.00245,,,,,,299.98782345,,,,
,31634650.62,299.9909363,62208.703125,-0.000140967224425205,2.80408195221415E-6,1,0.999253354069792,40.0298881530762,1.9960884431115,18.8900008797646,-0.00159871156491017,-0.000245080461727612,0.25,2.73991359422186E-6,-0.000140964963267016,2.64748318778333E-6,299.9909363,299.9909363,62206.20703125,62211.19921875,57.2378748347561,20.6117309400884,25.946213,0,0,0,40,4449,300.1617,62208.703125,,,,,,,,,,,,,0,,,,0,,,,,,299.9909363,,,,
,31634747.55,299.9934845,57363.1796875,-0.000121254777693466,2.80272674590562E-6,1,0.999253354069792,40.0298881530762,1.99605952867364,18.8900008797646,-0.00137898726295275,-0.000188560664899724,0.25,4.3250075880719E-6,-0.000121254106117749,4.24535221151389E-6,299.9928589,299.9941101,57338.19140625,57388.16796875,57.3207274577945,20.6124013758003,25.946213,0,0,0,40,4449,300.16645,57363.1796875,,,,,,,,,,,,,0,,,,0,,,,,,299.9934845,,,,
,31634842.245,299.9865112,52630.34765625,-0.00010258859371777,2.11667471793944E-6,1,0.999253354069792,40.0298881530762,1.99604192178119,18.8900008797646,-0.001163420447057,-0.00017842572906625,0.25,1.987669254984E-6,-0.000102586949638789,1.92024989662711E-6,299.9865112,299.9865112,52605.51171875,52655.18359375,57.1214121853907,20.6116116876307,26.325863,0,0,0,40,4449,300.17345,52630.34765625,,,,,,,,,,,,,0,,,,0,,,,,,299.9865112,,,,
,31634939.025,299.9912109,47793.341796875,-8.62152312070777E-5,2.14013920446178E-6,1,0.999253354069792,40.0298881530762,1.99601478212065,18.8900008797646,-0.00097871596498449,-0.000144215985081334,0.25,2.17751762214158E-6,-8.62141638650145E-5,2.12077986791175E-6,299.9912109,299.9912109,47768.0859375,47818.59765625,57.2112994651022,20.6153431457338,25.946213,0,0,0,40,4449,300.17955,47793.341796875,,,,,,,,,,,,,0,,,,-0.00245,,,,,,299.9912109,,,,
,31635034.845,299.9837646,43002.6953125,-7.20032360922455E-5,2.22390589503601E-6,1,0.999253354069792,40.0298881530762,1.99601360206113,18.8900008797646,-0.000813742897817852,-0.000141441576803864,0.25,-3.92521823001247E-8,-7.20011382732646E-5,-8.66324366015084E-8,299.9837646,299.9837646,42975.19921875,43030.19140625,57.0971817012945,20.6181491195129,26.325863,0,0,0,40,4449,300.199,43002.6953125,,,,,,,,,,,,,0,,,,0,,,,,,299.9837646,,,,
,31635128.925,299.98776245,38302.521484375,-5.50995232152905E-5,1.6201890078935E-6,1,0.999253354069792,40.0298881530762,1.99594646454715,18.8900008797646,-0.000623393339927875,-0.000104149328974904,0.25,3.31302657639818E-7,-5.50981443579936E-5,2.94994410655151E-7,299.9870911,299.9884338,38272.54296875,38332.5,57.5161345876022,20.6180022155864,25.566563,0,0,0,40,4449,300.186,38302.521484375,,,,,,,,,,,,,0,,,,-0.00245,,,,,,299.98776245,,,,
,31635220.955,299.9867859,33702.81640625,-3.94802237186314E-5,1.51668775329623E-6,1,0.999253354069792,40.0298881530762,1.99597310435418,18.8900008797646,-0.000447254553615374,-7.13278634802873E-5,0.25,5.29275988939616E-7,-3.9479427598105E-5,5.03227949251879E-7,299.9867859,299.9867859,33685.10546875,33720.52734375,57.2972786022176,20.6190435241056,25.946213,0,0,0,40,4449,300.21395,33702.81640625,,,,,,,,,,,,,0,,,,0,,,,,,299.9867859,,,,
,31635313.955,299.9915924,29055.1875,-2.24460091072585E-5,1.10931256195877E-6,1,0.999253354069792,40.0298881530762,1.99619062974394,18.8900008797646,-0.00025521992393714,-3.52912010879386E-5,0.25,7.66767633367552E-7,-2.24458589697435E-5,7.5192996330225E-7,299.9911499,299.9920349,29027.671875,29082.703125,57.1339182416984,20.6131337376103,25.946213,0,0,0,40,4449,300.21785,29055.1875,,,,,,,,,,,,,0,,,,0,,,,,,299.9915924,,,,
,31635408.42,299.9853363,24332.4013671875,-6.57385319111442E-6,1.03938153284688E-6,1,0.999253354069792,40.0298881530762,1.99623232535979,18.8900008797646,-7.66776085113214E-5,7.96589802844021E-7,0.25,1.20943887410485E-6,-6.57446114589066E-6,1.20506053537671E-6,299.9847107,299.9859619,24305.228515625,24359.57421875,57.4731450190445,20.6202891875862,25.566563,0,0,0,40,4449,300.2252,24332.4013671875,,,,,,,,,,,,,0,,,,0.00245,,,,,,299.9853363,,,,
,31635504.895,299.9908142,19512.74609375,8.29376212363599E-6,1.19354974028303E-6,1,0.999253354069792,40.0298881530762,1.99627946409824,18.8900008797646,9.10838382009327E-5,3.16457581878383E-5,0.25,1.36256716092238E-6,8.29261790918403E-6,1.36801173654933E-6,299.9908142,299.9908142,19477.5859375,19547.90625,57.1722180391407,20.6197654814463,26.325863,0,0,0,40,4449,300.2388,19512.74609375,,,,,,,,,,,,,0,,,,0,,,,,,299.9908142,,,,
,31635600.705,299.99360655,14725.1181640625,2.11153852981156E-5,8.38030175118034E-7,1,0.999253354069792,40.0298881530762,1.99628550056905,18.8900008797646,0.000237872598807422,4.60626568470288E-5,0.25,4.16480653855471E-7,2.11144872789737E-5,4.30444308671792E-7,299.9935608,299.9936523,14695.3837890625,14754.8525390625,57.2042648084291,20.6176220773489,26.325863,0,0,0,40,4449,300.24215,14725.1181640625,,,,,,,,,,,,,0,,,,0,,,,,,299.99360655,,,,
,31635695.095,299.9872131,10007.9399414062,3.39856964631158E-5,7.14702472828142E-7,1,0.999253354069792,40.0298881530762,1.99641542545095,18.8900008797646,0.000384091854137308,6.71793351416073E-5,0.25,5.42735280801204E-8,3.39846649610442E-5,7.67849383567168E-8,299.9872131,299.9872131,9983.1298828125,10032.75,57.1417345268907,20.6161168785729,25.566563,0,0,0,40,4449,300.25035,10007.9399414062,,,,,,,,,,,,,0,,,,-0.00245,,,,,,299.9872131,,,,
,31635786.67,299.98799135,5430.07202148438,4.31075556246841E-5,4.51418418097417E-7,1,0.999253354069792,40.0298881530762,1.99641642298792,18.8900008797646,0.000486266967530417,9.04999579019331E-5,0.25,5.3672018348656E-7,4.31059341240142E-5,5.65279490804217E-7,299.9870911,299.9888916,5400.0009765625,5460.14306640625,57.3535558556022,20.6161152468601,26.325863,0,0,0,40,4449,300.2675,5430.07202148438,,,,,,,,,,,,,0,,,,0.00245,,,,,,299.98799135,,,,
,31635876.525,299.9860535,936.251007080078,3.72611342824257E-5,4.53304167643697E-7,1,0.999253354069792,40.0298881530762,1.99640220766859,18.8900008797646,0.000421606790647664,7.07675074803532E-5,0.25,-1.95812092366516E-7,3.72601713686353E-5,-1.71092027810974E-7,299.9860535,299.9860535,911.444580078125,961.057434082031,57.2238055214099,20.6178679437561,26.325863,0,0,0,40,4449,300.271,936.251007080078,,,,,,,,,,,,,0,,,,-0.0049,,,,,,299.9860535,,,,
,31635895.27,299.98640445,-0.624174684286118,1.069330707483E-5,4.98884243189366E-7,1,0.999253354069792,40.0298881530762,1.99633000077281,18.8900008797646,0.000122310767840637,1.26838508632785E-5,0.25,-7.30677797250261E-7,1.06934779530569E-5,-7.23563129012039E-7,299.9856873,299.9871216,-0.715517342090607,-0.532832026481628,57.1198489283522,20.6187042997976,25.566563,0,0,0,40,4417,300.2695,-0.624174684286118,,,,,,,,,,,,,0,,,,-0.00245,,,,,,299.98640445,,,,