File: data/doubleLayers/dl_0-25/ppms/data/DD205_10_FCC_100OE.DAT
[Header]
; VSM Data File (default extension .dat)
; Copyright (c) 2003-2013, Quantum Design, Inc. All rights reserved.
TITLE,
FILEOPENTIME,31506549.27,12/31/2018,11:51 pm
BYAPP,VSM,2.0,2.0
INFO,PPMS VSM Option Release 1.4.10 Build 1,APPNAME
INFO,Quantum Design Linear Motor Servo Controller,MOTOR_MODULE_NAME
INFO,3101-100 M1,MOTOR_HW_VERSION
INFO,MMC1014,MOTOR_SERIAL_NUMBER
INFO,SRV No X-over 01.03.11,MOTOR_SOFTWARE_VERSION
INFO,Quantum Design VSM Detection Module,VSM_MODULE_NAME
INFO,3101-150 F0,VSM_HW_VERSION
INFO,VSM707,VSM_SERIAL_NUMBER
INFO,VSM No X-over 01.02.05 May 20 2008 13:51:47,VSM_SOFTWARE_VERSION
INFO,704,PREAMP_SERIAL_NUMBER
INFO,822,COIL_SERIAL_NUMBER
INFO,0,MOMENT_UNITS
INFO,CoFe2O4,SAMPLE_MATERIAL
INFO,Double Layer thin concentration,SAMPLE_COMMENT
INFO,27.44,SAMPLE_MASS
INFO,,SAMPLE_VOLUME
INFO,,SAMPLE_MOLECULAR_WEIGHT
INFO,,SAMPLE_SIZE
INFO,,SAMPLE_SHAPE
DATATYPE,COMMENT,1
DATATYPE,TIME,2
STARTUPAXIS,X,2
STARTUPAXIS,Y1,5
[Data]
Comment,Time Stamp (sec),Temperature (K),Magnetic Field (Oe),Moment (emu),M. Std. Err. (emu),Transport Action,Averaging Time (sec),Frequency (Hz),Peak Amplitude (mm),Center Position (mm),Coil Signal' (mV),Coil Signal" (mV),Range (mV),M. Quad. Signal (emu),M. Raw' (emu),M. Raw" (emu),Min. Temperature (K),Max. Temperature (K),Min. Field (Oe),Max. Field (Oe),Mass (grams),Motor Lag (deg),Pressure (Torr),VSM Status (code),Motor Status (code),Measure Status (code),Measure Count,PPMS Status (code),System Temp. (K),System Field (Oe),Sample Position (deg),Bridge 1 Resistance (ohms),Bridge 1 Excitation (에),Bridge 2 Resistance (ohms),Bridge 2 Excitation (에),Bridge 3 Resistance (ohms),Bridge 3 Excitation (에),Bridge 4 Resistance (ohms),Bridge 4 Excitation (에),Signal 1 Vin (V),Signal 2 Vin (V),Digital Inputs (code),Drive 1 Iout (mA),Drive 1 Ipower (W),Drive 2 Iout (mA),Drive 2 Ipower (W),Pressure (),Map 20 (),Map 21 (),Map 22 (),Map 23 (),Map 24 (),Map 25 (),Map 26 (),Map 27 (),Map 28 (),Map 29 ()
,31506686.805,349.5808411,99.6243667602539,1.22137234926384E-5,5.09338881079538E-7,1,0.999253354069792,40.0298881530762,1.99731051812083,18.7800005078316,0.000138009490740966,2.32164565078659E-5,0.25,-5.8487060989952E-8,1.21922745811173E-5,-5.15771522206097E-8,349.5808411,349.5808411,99.6243667602539,99.6243667602539,57.0112025641791,20.6080614429489,22.909004,0,0,0,40,4369,350.2804,99.6243667602539,,,,,,,,,,,,,0,,,,-0.00245,,,,,,349.5808411,,,,
,31506834.78,346.9785767,99.6243667602539,1.24170653835416E-5,4.68744156453061E-7,1,0.999253354069792,40.0298881530762,1.99732563031033,18.7800005078316,0.000140521320774689,2.24453771173264E-5,0.25,-1.62280615935059E-7,1.23964047877068E-5,-1.5498937752694E-7,346.9785767,346.9785767,99.6243667602539,99.6243667602539,57.0424677049483,20.6060954611958,23.668306,0,0,0,40,4374,345.37615,99.6243667602539,,,,,,,,,,,,,0,,,,-0.00245,,,,,,346.9785767,,,,
,31506983.64,343.4824524,99.6243667602539,1.26867101147637E-5,4.81703178134615E-7,1,0.999253354069792,40.0298881530762,1.99726733136123,18.7800005078316,0.000143834406842477,2.14998055629285E-5,0.25,-2.9297366802907E-7,1.26671790747299E-5,-2.85261482008359E-7,343.4824524,343.4824524,99.6243667602539,99.6243667602539,56.8564401173714,20.6088086404684,23.668306,0,0,0,40,4374,341.53,99.6243667602539,,,,,,,,,,,,,0,,,,0,,,,,,343.4824524,,,,
,31507131.515,339.9624634,99.6243667602539,1.23325569649958E-5,4.21728042541423E-7,1,0.999253354069792,40.0298881530762,1.99714177425899,18.7800005078316,0.000138917777050901,2.615516499735E-5,0.25,1.80388592089003E-7,1.23147849077937E-5,1.87272911593776E-7,339.9624634,339.9624634,99.6243667602539,99.6243667602539,57.1081245005637,20.6128031376781,23.668306,0,0,0,40,4374,337.609,99.6243667602539,,,,,,,,,,,,,0,,,,0.0049,,,,,,339.9624634,,,,
,31507274.695,336.4944763,99.6243667602539,1.28325175359409E-5,4.45668422003211E-7,1,0.999253354069792,40.0298881530762,1.99715920919758,18.7800005078316,0.000144641700350534,2.67928698772719E-5,0.25,1.49886973154166E-7,1.28155732507434E-5,1.57211659809379E-7,336.4944763,336.4944763,99.6243667602539,99.6243667602539,56.831428004756,20.6114128862479,23.288654,0,0,0,40,4374,333.951,99.6243667602539,,,,,,,,,,,,,0,,,,0,,,,,,336.4944763,,,,
,31507418.515,332.9585266,99.6243667602539,1.35483886160394E-5,3.66181624714762E-7,1,0.999253354069792,40.0298881530762,1.99738513793792,18.7800005078316,0.000152419453309183,3.01782328642128E-5,0.25,3.24939723241921E-7,1.35320520980248E-5,3.32591637783808E-7,332.9585266,332.9585266,99.6243667602539,99.6243667602539,56.9119357422368,20.6085753961926,23.288654,0,0,0,40,4374,330.29735,99.6243667602539,,,,,,,,,,,,,0,,,,0.0049,,,,,,332.9585266,,,,
,31507558.86,329.4989929,99.6243667602539,1.36367556494847E-5,5.10814809732857E-7,1,0.999253354069792,40.0298881530762,1.9976391455614,18.7299996614456,0.000154375148193774,2.50442674031192E-5,0.25,-1.45454696924778E-7,1.36222300081213E-5,-1.37108299215455E-7,329.4989929,329.4989929,99.6243667602539,99.6243667602539,56.6532167023714,20.6024587819769,23.288654,0,0,0,40,4374,326.76145,99.6243667602539,,,,,,,,,,,,,0,,,,-0.00245,,,,,,329.4989929,,,,
,31507700.965,325.98088075,99.6243667602539,1.33445332283472E-5,3.9170414824325E-7,1,0.999253354069792,40.0298881530762,1.99778247022803,18.7299996614456,0.000150906045595046,2.56085905344669E-5,0.25,-4.5436106997063E-8,1.33318964325808E-5,-3.72754829035397E-8,325.9557495,326.006012,99.6243667602539,99.6243667602539,56.8267382336406,20.6068927200188,23.668306,0,0,0,40,4374,323.1503,99.6243667602539,,,,,,,,,,,,,0,,,,-0.0049,,,,,,325.98088075,,,,
,31507842.745,322.48101805,99.6243667602539,1.39211008095094E-5,4.12800052105776E-7,1,0.999253354069792,40.0298881530762,1.99784264776993,18.7299996614456,0.00015817773520356,2.25174246741371E-5,0.25,-4.19221560177942E-7,1.39098519426557E-5,-4.10297284786385E-7,322.4558105,322.5062256,99.6243667602539,99.6243667602539,56.9322580837368,20.604614801308,22.909004,0,0,0,40,4374,319.57595,99.6243667602539,,,,,,,,,,,,,0,,,,-0.0049,,,,,,322.48101805,,,,
,31507985.255,318.948822,99.6243667602539,1.37542384133797E-5,4.65121660737458E-7,1,0.999253354069792,40.0298881530762,1.99822781147232,18.7400002032518,0.000155933324778286,2.45442139720935E-5,0.25,-2.11792826620708E-7,1.37447075888732E-5,-2.03056951524987E-7,318.948822,318.948822,99.6243667602539,99.6243667602539,57.2347483206791,20.5922011421347,23.288654,0,0,0,40,4374,315.99165,99.6243667602539,,,,,,,,,,,,,0,,,,-0.00245,,,,,,318.948822,,,,
,31508127.06,315.4549255,99.6243667602539,1.41625819850715E-5,4.73027247853629E-7,1,0.999253354069792,40.0298881530762,1.99827765752051,18.7400002032518,0.000160848758433252,2.37620333415187E-5,0.25,-3.52130212438036E-7,1.41545986829345E-5,-3.4296552530947E-7,315.4549255,315.4549255,99.6243667602539,99.6243667602539,56.9424192544868,20.5882301324147,23.288654,0,0,0,40,4374,312.4249,99.6243667602539,,,,,,,,,,,,,0,,,,-0.0049,,,,,,315.4549255,,,,
,31508267.22,311.99023435,99.6243667602539,1.4769024635632E-5,4.85715835420052E-7,1,0.999253354069792,40.0298881530762,1.99827980294507,18.7400002032518,0.000166333172518602,3.30019801588855E-5,0.25,3.5940471752728E-7,1.47620457401106E-5,3.6871032355631E-7,311.9647827,312.015686,99.6243667602539,99.6243667602539,57.0495023616214,20.5850596958396,24.047956,0,0,0,40,4374,308.91735,99.6243667602539,,,,,,,,,,,,,0,,,,-0.0049,,,,,,311.99023435,,,,
,31508387.99,308.97964475,99.6243667602539,1.44374517354784E-5,4.29289501169607E-7,1,0.999253354069792,40.0298881530762,1.99819184109482,18.7500007450581,0.000163631985015273,2.63606079969127E-5,0.25,-1.70627836450016E-7,1.44325061282157E-5,-1.61201130530275E-7,308.9547424,309.0045471,99.6243667602539,99.6243667602539,56.9095908566791,20.5870257086778,23.668306,0,0,0,40,4374,305.86615,99.6243667602539,,,,,,,,,,,,,0,,,,0.00245,,,,,,308.97964475,,,,
,31508529.11,305.4919434,99.6243667602539,1.4607819968813E-5,4.43004103434914E-7,1,0.999253354069792,40.0298881530762,1.9982627281919,18.7500007450581,0.000166352384964059,2.22700811680971E-5,0.25,-5.6223752048495E-7,1.46048838508455E-5,-5.52500178829603E-7,305.4919434,305.4919434,99.6243667602539,99.6243667602539,56.8064158921406,20.5871294238514,23.288654,0,0,0,40,4374,302.3203,99.6243667602539,,,,,,,,,,,,,0,,,,-0.00245,,,,,,305.4919434,,,,
,31508670,301.9963379,99.6243667602539,1.42136863579782E-5,5.17346613699489E-7,1,0.999253354069792,40.0298881530762,1.99825813569966,18.7500007450581,0.000160315356920595,3.07246876657443E-5,0.25,2.52955601035699E-7,1.42120697623445E-5,2.62413274707192E-7,301.9963379,301.9963379,99.6243667602539,99.6243667602539,56.9705578811791,20.5858845239273,23.288654,0,0,0,40,4374,298.78035,99.6243667602539,,,,,,,,,,,,,0,,,,0,,,,,,301.9963379,,,,
,31508791.67,298.9520264,99.6243667602539,1.47169806352405E-5,4.11822030206316E-7,1,0.999253354069792,40.0298881530762,1.997331753189,18.7699999660254,0.000166258633170163,2.99430942883712E-5,0.25,9.74332505912055E-8,1.47170137092929E-5,1.0737489449976E-7,298.9520264,298.9520264,99.6243667602539,99.6243667602539,56.9416376259676,20.6069318108567,23.668306,0,0,0,40,4374,295.725,99.6243667602539,,,,,,,,,,,,,0,,,,-0.00245,,,,,,298.9520264,,,,
,31508933.065,295.4691467,99.6243667602539,1.52526136497671E-5,3.93159903891023E-7,1,0.999253354069792,40.0298881530762,1.99737099267978,18.7699999660254,0.000174465846250096,1.87367206067549E-5,0.25,-9.86599240922656E-7,1.52552894824345E-5,-9.76275720448449E-7,295.4691467,295.4691467,99.6243667602539,99.6243667602539,56.8759808303522,20.6099445646167,23.288654,0,0,0,40,4374,292.1856,99.6243667602539,,,,,,,,,,,,,0,,,,0.0049,,,,,,295.4691467,,,,
,31509074.94,291.9237976,99.6243667602539,1.57311001896038E-5,4.13220613195894E-7,1,0.999253354069792,40.0298881530762,1.99718183358576,18.7699999660254,0.00017820109924765,2.93922289497749E-5,0.25,-1.27770796190684E-7,1.57352458301681E-5,-1.16862672723928E-7,291.9237976,291.9237976,99.6243667602539,99.6243667602539,57.1073428720445,20.6086696036469,24.047956,0,0,0,40,4374,288.62265,99.6243667602539,,,,,,,,,,,,,0,,,,0.0049,,,,,,291.9237976,,,,
,31509193.66,288.996582,99.6243667602539,1.55707079011194E-5,3.8788546528782E-7,1,0.999253354069792,40.0298881530762,1.99737068828062,18.7899991869926,0.00017721204438399,2.45197567852012E-5,0.25,-5.31268013560456E-7,1.55767284257562E-5,-5.20495040699206E-7,288.996582,288.996582,99.6243667602539,99.6243667602539,56.9486722826406,20.6080754850601,23.668306,0,0,0,40,4374,285.64385,99.6243667602539,,,,,,,,,,,,,0,,,,-0.00245,,,,,,288.996582,,,,
,31509334.57,285.4914093,99.6243667602539,1.50716276304087E-5,4.02913639507101E-7,1,0.999253354069792,40.0298881530762,1.99729384825097,18.7899991869926,0.000171423543961562,2.44496511638669E-5,0.25,-4.51323916053401E-7,1.50793071489994E-5,-4.40770065929633E-7,285.4641113,285.5187073,99.6243667602539,99.6243667602539,57.0260535060445,20.6105302085211,23.288654,0,0,0,40,4374,282.11815,99.6243667602539,,,,,,,,,,,,,0,,,,-0.00245,,,,,,285.4914093,,,,
,31509474.595,281.9830627,99.6243667602539,1.54933206862885E-5,4.73938840252916E-7,1,0.999253354069792,40.0298881530762,1.99706335856504,18.7899991869926,0.000175817082747237,2.74739346381198E-5,0.25,-2.57337098834371E-7,1.55030168428532E-5,-2.46251261171435E-7,281.9830627,281.9830627,99.6243667602539,99.6243667602539,57.169873153583,20.6116889448319,24.047956,0,0,0,40,4374,278.6121,99.6243667602539,,,,,,,,,,,,,0,,,,0.00245,,,,,,281.9830627,,,,
,31509615.465,278.4887695,99.6243667602539,1.57641421039243E-5,3.62048036563222E-7,1,0.999253354069792,40.0298881530762,1.99707905406406,18.8200008124113,0.000179385341892528,2.52391498235253E-5,0.25,-5.02249248239386E-7,1.57761601848048E-5,-4.91002909949866E-7,278.4642944,278.5132446,99.6243667602539,99.6243667602539,56.8275198621599,20.6089124867809,23.668306,0,0,0,40,4374,275.08245,99.6243667602539,,,,,,,,,,,,,0,,,,0,,,,,,278.4887695,,,,
,31509756.125,274.9850769,99.6243667602539,1.57079185744168E-5,4.49932599075284E-7,1,0.999253354069792,40.0298881530762,1.99698260833383,18.8200008124113,0.000177956592564215,2.97845499653109E-5,0.25,-9.12415914757594E-8,1.57215630485598E-5,-7.95640677056359E-8,274.9580383,275.0121155,99.6243667602539,99.6243667602539,56.8869236296214,20.6118733362286,24.047956,0,0,0,40,4374,271.57505,99.6243667602539,,,,,,,,,,,,,0,,,,0,,,,,,274.9850769,,,,
,31509896.89,271.4812927,99.6243667602539,1.63277082421223E-5,3.11976095013898E-7,1,0.999253354069792,40.0298881530762,1.99688213757471,18.8200008124113,0.000185321687752291,2.90635040181308E-5,0.25,-2.62780777255621E-7,1.63440656435325E-5,-2.50626527152976E-7,271.4812927,271.4812927,99.6243667602539,99.6243667602539,57.1565854687561,20.612904595159,24.047956,0,0,0,40,4374,268.0461,99.6243667602539,,,,,,,,,,,,,0,,,,0.0049,,,,,,271.4812927,,,,
,31510037.08,267.9658813,99.6243667602539,1.62715670736592E-5,3.84674679541584E-7,1,0.999253354069792,40.0298881530762,1.99684361393483,18.8400000333786,0.000184531807174553,2.99615086054377E-5,0.25,-1.74188980425941E-7,1.62898468968964E-5,-1.61813593267646E-7,267.9658813,267.9658813,99.6243667602539,99.6243667602539,56.9627415959868,20.6086829207411,23.668306,0,0,0,40,4374,264.5342,99.6243667602539,,,,,,,,,,,,,0,,,,0,,,,,,267.9658813,,,,
,31510177.495,264.4805908,99.6243667602539,1.6462537979401E-5,4.94044684469474E-7,1,0.999253354069792,40.0298881530762,1.99677197451539,18.8400000333786,0.000187067926865532,2.82767509049872E-5,0.25,-3.56560441063759E-7,1.64832223338953E-5,-3.44079770789079E-7,264.4552612,264.5059204,99.6243667602539,99.6243667602539,56.9439825115252,20.6114184191337,23.668306,0,0,0,40,4374,261.0351,99.6243667602539,,,,,,,,,,,,,0,,,,0.00245,,,,,,264.4805908,,,,
,31510318.055,260.98605345,99.6243667602539,1.70265796715804E-5,4.10123161576837E-7,1,0.999253354069792,40.0298881530762,1.99671523441249,18.8400000333786,0.000192469340895015,3.51699377549479E-5,0.25,1.5402271326133E-7,1.70496781538582E-5,1.678188336071E-7,260.9625244,261.0095825,99.6243667602539,99.6243667602539,57.0838940164676,20.612569839015,24.047956,0,0,0,40,4374,257.50585,99.6243667602539,,,,,,,,,,,,,0,,,,0.00245,,,,,,260.98605345,,,,
,31510439.04,257.9457092,99.6243667602539,1.62603015077151E-5,4.20144356253999E-7,1,0.999253354069792,40.0298881530762,1.99708765987447,18.8699997961521,0.000184008548437205,3.27390817434459E-5,0.25,7.11777512543684E-8,1.62841765121378E-5,8.44424724289194E-8,257.9457092,257.9457092,99.6243667602539,99.6243667602539,57.0354330482753,20.6066053897673,23.288654,0,0,0,40,4374,254.4878,99.6243667602539,,,,,,,,,,,,,0,,,,-0.00245,,,,,,257.9457092,,,,
,31510577.585,254.4984741,99.6243667602539,1.67200493349797E-5,5.03689638203541E-7,1,0.999253354069792,40.0298881530762,1.99702367027664,18.8699997961521,0.000189197118274933,3.38489882098234E-5,0.25,8.89619406710768E-8,1.67466278553173E-5,1.02860971892293E-7,254.4733429,254.5236053,99.6243667602539,99.6243667602539,56.6539983308906,20.6102061293584,23.668306,0,0,0,40,4374,251.0201,99.6243667602539,,,,,,,,,,,,,0,,,,-0.00245,,,,,,254.4984741,,,,
,31510718.75,250.9924774,99.6243667602539,1.7270824003711E-5,3.33225404446151E-7,1,0.999253354069792,40.0298881530762,1.99674100324668,18.8699997961521,0.000195694709742229,3.34212482787343E-5,0.25,-4.45298526326337E-8,1.73005302454587E-5,-3.01513500115531E-8,250.9924774,250.9924774,99.6243667602539,99.6243667602539,56.8071975206598,20.6137389590376,23.288654,0,0,0,40,4374,247.4844,99.6243667602539,,,,,,,,,,,,,0,,,,-0.0049,,,,,,250.9924774,,,,
,31510837.505,247.98719025,99.6243667602539,1.68498069841322E-5,3.52091922389161E-7,1,0.999253354069792,40.0298881530762,1.99678399680345,18.8999995589256,0.000191891355252608,2.71736165796828E-5,0.25,-5.23641651290105E-7,1.6880981562749E-5,-5.1028883771731E-7,247.9626007,248.0117798,99.6243667602539,99.6243667602539,56.5992843345444,20.6141136459825,23.668306,0,0,0,40,4374,244.53245,99.6243667602539,,,,,,,,,,,,,0,,,,0.0049,,,,,,247.98719025,,,,
,31510977.565,244.4870148,99.6243667602539,1.72039736710317E-5,4.33618113450784E-7,1,0.999253354069792,40.0298881530762,1.99687518023027,18.8999995589256,0.000195003245926902,3.32499089304295E-5,0.25,-4.93832477527633E-8,1.72375062093918E-5,-3.46153684804075E-8,244.4870148,244.4870148,99.6243667602539,99.6243667602539,56.7587365524675,20.6136466089609,23.668306,0,0,0,40,4374,241.0378,99.6243667602539,,,,,,,,,,,,,0,,,,0,,,,,,244.4870148,,,,
,31511118.58,240.9573059,99.6243667602539,1.73993352469078E-5,3.4734051481159E-7,1,0.999253354069792,40.0298881530762,1.99678423823257,18.8999995589256,0.000198384642746404,2.69937642278152E-5,0.25,-6.35947884663006E-7,1.74359119711174E-5,-6.21961629771816E-7,240.9573059,240.9573059,99.6243667602539,99.6243667602539,57.0901470446214,20.6148218590167,23.668306,0,0,0,40,4374,237.5063,99.6243667602539,,,,,,,,,,,,,0,,,,-0.00245,,,,,,240.9573059,,,,
,31511238.055,237.9855728,99.6243667602539,1.74359228799262E-5,3.90710244149741E-7,1,0.999253354069792,40.0298881530762,1.99704626276927,18.9500004053116,0.000198178259278532,3.09131916948252E-5,0.25,-2.97220728343191E-7,1.74740853764868E-5,-2.82294966153041E-7,237.9614105,238.0097351,99.6243667602539,99.6243667602539,56.8165770628906,20.606138489558,23.668306,0,0,0,40,4374,234.5091,99.6243667602539,,,,,,,,,,,,,0,,,,0,,,,,,237.9855728,,,,
,31511378.165,234.4867096,99.6243667602539,1.80165760164375E-5,3.79725484896304E-7,1,0.999253354069792,40.0298881530762,1.99697033903954,18.9500004053116,0.000204884255780333,3.14334191158978E-5,0.25,-3.5258475794245E-7,1.80582407960678E-5,-3.37007561908234E-7,234.4867096,234.4867096,99.6243667602539,99.6243667602539,57.1214121853907,20.612336441277,23.288654,0,0,0,40,4374,231.00085,99.6243667602539,,,,,,,,,,,,,0,,,,0,,,,,,234.4867096,,,,
,31511517,230.99816895,99.6243667602539,1.74519312801446E-5,3.61810470836333E-7,1,0.999253354069792,40.0298881530762,1.99674227176957,18.9500004053116,0.00019889570267489,2.79687764331598E-5,0.25,-5.60632043129665E-7,1.74945984813237E-5,-5.45819151762829E-7,230.9682465,231.0280914,99.6243667602539,99.6243667602539,56.9385111118906,20.6156622466739,24.047956,0,0,0,40,4374,227.52775,99.6243667602539,,,,,,,,,,,,,0,,,,0,,,,,,230.99816895,,,,
,31511657.495,227.4888916,99.6243667602539,1.76929272832858E-5,4.61545094530427E-7,1,0.999253354069792,40.0298881530762,1.99666715526587,18.9699996262789,0.000200805661879733,3.32765210135148E-5,0.25,-1.34689490469437E-7,1.77379130925725E-5,-1.18328146815365E-7,227.4888916,227.4888916,99.6243667602539,99.6243667602539,57.075296102756,20.6096788985891,23.288654,0,0,0,40,4374,224.0163,99.6243667602539,,,,,,,,,,,,,0,,,,-0.0049,,,,,,227.4888916,,,,
,31511797.31,223.986969,99.6243667602539,1.76232690839857E-5,3.63860610811749E-7,1,0.999253354069792,40.0298881530762,1.99646438878803,18.9699996262789,0.000200566578864373,2.99943940306857E-5,0.25,-4.12549229494342E-7,1.76704511309736E-5,-3.96684943986293E-7,223.9617615,224.0121765,99.6243667602539,99.6243667602539,57.2238055214099,20.6152757357716,24.047956,0,0,0,40,4374,220.5169,99.6243667602539,,,,,,,,,,,,,0,,,,0,,,,,,223.986969,,,,
,31511937.695,220.4820404,99.6243667602539,1.75159407415804E-5,3.66990531733086E-7,1,0.999253354069792,40.0298881530762,1.99650965205253,18.9699996262789,0.000198813705477864,3.30384638050141E-5,0.25,-1.26098846086826E-7,1.75646426568184E-5,-1.09258394579198E-7,220.4820404,220.4820404,99.6243667602539,99.6243667602539,57.2925888311022,20.6121408189704,23.668306,0,0,0,40,4374,217.00955,99.6243667602539,,,,,,,,,,,,,0,,,,0.00245,,,,,,220.4820404,,,,
,31512076.585,216.9991608,99.6243667602539,1.74845489844609E-5,3.77972630696925E-7,1,0.999253354069792,40.0298881530762,1.99648044277099,19.0099999308586,0.000198587783358193,3.23492619328467E-5,0.25,-1.82079382216248E-7,1.7535269282038E-5,-1.65103730681136E-7,216.9991608,216.9991608,99.6243667602539,99.6243667602539,57.1472059265253,20.6135562932175,23.668306,0,0,0,40,4374,213.54675,99.6243667602539,,,,,,,,,,,,,0,,,,-0.00245,,,,,,216.9991608,,,,
,31512217.02,213.4954071,99.6243667602539,1.73747788107581E-5,4.25083375556599E-7,1,0.999253354069792,40.0298881530762,1.99650670538974,19.0099999308586,0.000198014043899593,2.84210352381167E-5,0.25,-5.10188548899106E-7,1.74275511332872E-5,-4.93971041876512E-7,213.4954071,213.4954071,99.6243667602539,99.6243667602539,56.9885353371214,20.6122658284807,23.668306,0,0,0,40,4374,210.03535,99.6243667602539,,,,,,,,,,,,,0,,,,0.00245,,,,,,213.4954071,,,,
,31512356.575,209.98665615,99.6243667602539,1.76579074206618E-5,3.29581284120642E-7,1,0.999253354069792,40.0298881530762,1.99645056850248,19.0099999308586,0.000200462721820731,3.34710678404253E-5,0.25,-1.14610325362184E-7,1.7713179337527E-5,-9.65483549010509E-8,209.9642181,210.0090942,99.6243667602539,99.6243667602539,56.9478906541214,20.614483719705,23.668306,0,0,0,40,4374,206.5486,99.6243667602539,,,,,,,,,,,,,0,,,,0.0049,,,,,,209.98665615,,,,
,31512498.095,206.4560242,99.6243667602539,1.76328354605955E-5,4.01439641817106E-7,1,0.999253354069792,40.0298881530762,1.9966225262626,19.0399996936321,0.000199919511531843,3.5147040621104E-5,0.25,3.65305386350614E-8,1.76899119195737E-5,5.5442243887781E-8,206.4560242,206.4560242,99.6243667602539,99.6243667602539,56.7814037795252,20.6102482407669,24.047956,0,0,0,40,4374,203.02475,99.6243667602539,,,,,,,,,,,,,0,,,,0,,,,,,206.4560242,,,,
,31512636.25,202.99565885,99.6243667602539,1.84669458122995E-5,3.73612898913029E-7,1,0.999253354069792,40.0298881530762,1.99649690758129,19.0399996936321,0.00020986530354154,3.40605085769081E-5,0.25,-2.04709873638492E-7,1.85290617349083E-5,-1.85284582863051E-7,202.9716644,203.0196533,99.6243667602539,99.6243667602539,57.5090999309292,20.6117611897542,23.288654,0,0,0,40,4374,199.57215,99.6243667602539,,,,,,,,,,,,,0,,,,0.00245,,,,,,202.99565885,,,,
,31512776.805,199.4689941,99.6243667602539,1.8242048434126E-5,3.89178819584157E-7,1,0.999253354069792,40.0298881530762,1.99646243805962,19.0399996936321,0.000208164068204056,2.88452393896736E-5,0.25,-6.26140480733661E-7,1.83059540340173E-5,-6.07991418598089E-7,199.4689941,199.4689941,99.6243667602539,99.6243667602539,57.0807675023906,20.6168758522009,22.909004,0,0,0,40,4374,196.056,99.6243667602539,,,,,,,,,,,,,0,,,,0,,,,,,199.4689941,,,,
,31512896.245,196.4869995,99.6243667602539,1.81360586437219E-5,3.59033284472904E-7,1,0.999253354069792,40.0298881530762,1.99657051181989,19.0900005400181,0.000205536493420062,3.70190909537657E-5,0.25,1.11968019491082E-7,1.82004938341215E-5,1.32968177280354E-7,196.4869995,196.4869995,99.6243667602539,99.6243667602539,57.1706547821022,20.6096126270597,23.668306,0,0,0,40,4374,193.05675,99.6243667602539,,,,,,,,,,,,,0,,,,0.00245,,,,,,196.4869995,,,,
,31513036.03,192.9781799,99.6243667602539,1.78818753908449E-5,4.04543799913404E-7,1,0.999253354069792,40.0298881530762,1.99651550459498,19.0900005400181,0.000202775410551827,3.59127796945361E-5,0.25,5.78731502315172E-8,1.79474423897033E-5,7.88808680797494E-8,192.9781799,192.9781799,99.6243667602539,99.6243667602539,57.0565370182945,20.613938069837,23.288654,0,0,0,40,4374,189.5616,99.6243667602539,,,,,,,,,,,,,0,,,,-0.00245,,,,,,192.9781799,,,,
,31513176.3,189.47556305,99.6243667602539,1.73104494016656E-5,3.32452467404862E-7,1,0.999253354069792,40.0298881530762,1.99646847557733,19.0900005400181,0.000196768327805868,3.21453810768194E-5,0.25,-1.75607910382572E-7,1.73760821104891E-5,-1.55647359977782E-7,189.4497986,189.5013275,99.6243667602539,99.6243667602539,56.9283499411406,20.6144603719596,23.288654,0,0,0,40,4374,186.05245,99.6243667602539,,,,,,,,,,,,,0,,,,0,,,,,,189.47556305,,,,
,31513315.9,185.9659729,99.6243667602539,1.80082315114256E-5,3.15689691424567E-7,1,0.999253354069792,40.0298881530762,1.99634658597777,19.1300008445978,0.000204355640113202,3.54822966056199E-5,0.25,-3.48968820719101E-9,1.80782382156419E-5,1.84892676166036E-8,185.9659729,185.9659729,99.6243667602539,99.6243667602539,56.9783741663714,20.6126235242744,23.288654,0,0,0,40,4374,182.57025,99.6243667602539,,,,,,,,,,,,,0,,,,0,,,,,,185.9659729,,,,
,31513456.33,182.4822083,99.6243667602539,1.78244549135019E-5,3.32482040021738E-7,1,0.999253354069792,40.0298881530762,1.99618838411419,19.1300008445978,0.000203041662916824,3.07180743897499E-5,0.25,-3.92032601357718E-7,1.78961141308999E-5,-3.71265413746926E-7,182.4822083,182.4822083,99.6243667602539,99.6243667602539,57.1776894387753,20.6190747746793,22.909004,0,0,0,40,4374,179.0666,99.6243667602539,,,,,,,,,,,,,0,,,,0.00245,,,,,,182.4822083,,,,
,31513597.46,178.95602415,99.6243667602539,1.78381002164578E-5,3.37889101183308E-7,1,0.999253354069792,40.0298881530762,1.99598086573299,19.1300008445978,0.000202090544385426,3.71123785402493E-5,0.25,1.68460529648524E-7,1.79109812151701E-5,1.92107083590634E-7,178.929718,178.9823303,99.6243667602539,99.6243667602539,57.0135474497368,20.6185959075864,23.288654,0,0,0,40,4374,175.5093,99.6243667602539,,,,,,,,,,,,,0,,,,0,,,,,,178.95602415,,,,
,31513735.43,175.4788513,99.6243667602539,1.80883062098498E-5,3.20552055837128E-7,1,0.999253354069792,40.0298881530762,1.99618765258034,19.1900003701448,0.000205043318475849,3.71972648257923E-5,0.25,1.31156362647928E-7,1.81641043508102E-5,1.55607973751239E-7,175.4788513,175.4788513,99.6243667602539,99.6243667602539,57.2581971762561,20.618367967887,22.529354,0,0,0,40,4374,172.1098,99.6243667602539,,,,,,,,,,,,,0,,,,0.0049,,,,,,175.4788513,,,,
,31513872.665,171.996933,99.6243667602539,1.82018982393941E-5,3.75631723681397E-7,1,0.999253354069792,40.0298881530762,1.99616179085866,19.1900003701448,0.000206581822066163,3.60960294204777E-5,0.25,1.34357542238177E-8,1.82801593090352E-5,3.82085215727898E-8,171.9706116,172.0232544,99.6243667602539,99.6243667602539,57.1042163579676,20.6174152434558,22.909004,0,0,0,40,4374,168.7071,99.6243667602539,,,,,,,,,,,,,0,,,,0.00245,,,,,,171.996933,,,,
,31514013.33,168.4674988,99.6243667602539,1.79937638683784E-5,3.28200506978747E-7,1,0.999253354069792,40.0298881530762,1.99611252432927,19.1900003701448,0.000204758855788893,3.26762413745705E-5,0.25,-2.52564432555616E-7,1.80732997639602E-5,-2.28527721670514E-7,168.4674988,168.4674988,99.6243667602539,99.6243667602539,57.210517836583,20.6196034076856,23.288654,0,0,0,40,4374,165.2134,99.6243667602539,,,,,,,,,,,,,0,,,,0,,,,,,168.4674988,,,,
,31514151.4,164.9685211,99.6243667602539,1.77921520367624E-5,4.18749216291159E-7,1,0.999253354069792,40.0298881530762,1.99607899752487,19.2499998956919,0.00020224028834954,3.36962551069988E-5,0.25,-1.286027139799E-7,1.78723611439396E-5,-1.03573333234057E-7,164.9685211,164.9685211,99.6243667602539,99.6243667602539,57.105779615006,20.6185323581602,22.529354,0,0,0,40,4374,161.7738,99.6243667602539,,,,,,,,,,,,,0,,,,0,,,,,,164.9685211,,,,
,31514291.045,161.49312595,99.6243667602539,1.77049167985764E-5,3.55330422419506E-7,1,0.999253354069792,40.0298881530762,1.99587994307716,19.2499998956919,0.000200973563189708,3.5110150880063E-5,0.25,1.033832172724E-8,1.77862005312119E-5,3.66652751345342E-8,161.4667969,161.519455,99.6243667602539,99.6243667602539,57.403580080833,20.6227317591494,22.149702,0,0,0,40,4374,158.28675,99.6243667602539,,,,,,,,,,,,,0,,,,0,,,,,,161.49312595,,,,
,31514429.94,157.99539945,99.6243667602539,1.77123950448472E-5,3.11681003187148E-7,1,0.999253354069792,40.0298881530762,1.99569907268006,19.2499998956919,0.000200660206914167,3.74185844785122E-5,0.25,2.11520399612229E-7,1.77950443258354E-5,2.3964956136384E-7,157.9694366,158.0213623,99.6243667602539,99.6243667602539,57.1503324406022,20.6302608761653,22.529354,0,0,0,40,4374,154.8173,99.6243667602539,,,,,,,,,,,,,0,,,,-0.00245,,,,,,157.99539945,,,,
,31514550.33,154.9796753,99.6243667602539,1.74306640895041E-5,3.71812353632315E-7,1,0.999253354069792,40.0298881530762,1.99577160685951,19.3099994212389,0.000197390047043648,3.74047138676551E-5,0.25,2.58230901469184E-7,1.75132671112427E-5,2.86935731495697E-7,154.9796753,154.9796753,99.6243667602539,99.6243667602539,56.8837971155445,20.6233482262651,22.529354,0,0,0,40,4374,151.8168,99.6243667602539,,,,,,,,,,,,,0,,,,0,,,,,,154.9796753,,,,
,31514689.545,151.4989319,99.6243667602539,1.7657100266758E-5,2.81907926030246E-7,1,0.999253354069792,40.0298881530762,1.99550744185538,19.3099994212389,0.000200851151735455,3.26959285720743E-5,0.25,-1.96795406679543E-7,1.77430514954356E-5,-1.68955968477598E-7,151.4710999,151.5267639,99.6243667602539,99.6243667602539,57.4457880208715,20.6297612355857,22.909004,0,0,0,40,4374,148.3423,99.6243667602539,,,,,,,,,,,,,0,,,,0.00245,,,,,,151.4989319,,,,
,31514829.26,147.9859314,99.6243667602539,1.76295479971772E-5,2.7960388987327E-7,1,0.999253354069792,40.0298881530762,1.99564548898906,19.3099994212389,0.000200606181628216,3.24318040185087E-5,0.25,-2.16717467344557E-7,1.77169158421397E-5,-1.88005964192683E-7,147.9859314,147.9859314,99.6243667602539,99.6243667602539,57.3918556530445,20.6287098237887,22.149702,0,0,0,40,4374,144.8663,99.6243667602539,,,,,,,,,,,,,0,,,,0.00245,,,,,,147.9859314,,,,
touchdown = 14.3699999898672 mm,31514961.405,144.6664276,99.6243667602539,1.79462651395341E-5,3.51090590641146E-7,1,0.999253354069792,40.0298881530762,1.99601491175941,19.3600002676249,0.000204223488176522,3.32445960967237E-5,0.25,-2.02149958085254E-7,1.80365787984482E-5,-1.71777249507981E-7,144.6664276,144.6664276,99.6243667602539,99.6243667602539,56.8228300910445,20.6230780921434,22.529354,0,0,0,40,4374,141.5713,99.6243667602539,,,,,,,,,,,,,0,,,,-0.0049,,,,,,144.6664276,,,,
,31515088.075,141.4898529,99.6243667602539,1.75155608835879E-5,3.4725512029937E-7,1,0.999253354069792,40.0298881530762,1.99548738507512,19.3600002676249,0.000199385077101587,3.18743638878511E-5,0.25,-2.48254213915573E-7,1.76050646100949E-5,-2.17811304521536E-7,141.4637146,141.5159912,99.6243667602539,99.6243667602539,57.2152076076984,20.6297567685702,22.149702,0,0,0,40,4374,138.41745,99.6243667602539,,,,,,,,,,,,,0,,,,-0.00245,,,,,,141.4898529,,,,
,31515227.555,137.9483337,99.6243667602539,1.77341024109101E-5,3.65936787811149E-7,1,0.999253354069792,40.0298881530762,1.99552900938939,19.3600002676249,0.000201863534895214,3.2440671143297E-5,0.25,-2.38056858755842E-7,1.782607186678E-5,-2.05899287406242E-7,137.9483337,137.9483337,99.6243667602539,99.6243667602539,56.9822823089676,20.6295409087182,22.529354,0,0,0,40,4374,134.9505,99.6243667602539,,,,,,,,,,,,,0,,,,0,,,,,,137.9483337,,,,
touchdown = 14.4400000572205 mm,31515374.945,134.2418518,99.6243667602539,1.79296941530366E-5,4.02770444644969E-7,1,0.999253354069792,40.0298881530762,2.00829666308533,19.4300003349781,0.000205334648036866,3.3096179054741E-5,0.25,-2.33846851352069E-7,1.80240362149247E-5,-1.9982710217696E-7,134.2418518,134.2418518,99.6243667602539,99.6243667602539,56.3851181202752,20.6256619281865,21.770052,0,0,0,40,4374,131.2894,99.6243667602539,,,,,,,,,,,,,0,,,,0,,,,,,134.2418518,,,,
,31515505.685,130.9683533,99.6243667602539,1.81652868217224E-5,4.33720371721021E-7,1,0.999253354069792,40.0298881530762,1.99559018521355,19.4300003349781,0.000206652472737796,3.41168122752633E-5,0.25,-1.69152633250026E-7,1.82618793554715E-5,-1.32886915455194E-7,130.9683533,130.9683533,99.6243667602539,99.6243667602539,57.4067065949099,20.630505279787,22.149702,0,0,0,40,4374,128.03855,99.6243667602539,,,,,,,,,,,,,0,,,,0,,,,,,130.9683533,,,,
,31515644.735,127.4733353,99.6243667602539,1.74844637510996E-5,3.48334802860208E-7,1,0.999253354069792,40.0298881530762,1.99532971819321,19.4300003349781,0.000199034394469055,3.20379197139012E-5,0.25,-2.34697565934354E-7,1.75786828749168E-5,-1.98572322474362E-7,127.4733353,127.4733353,99.6243667602539,99.6243667602539,57.0440309619868,20.6325566738222,21.3904,0,0,0,40,4374,124.5854,99.6243667602539,,,,,,,,,,,,,0,,,,0,,,,,,127.4733353,,,,
touchdown = 14.4999995827675 mm,31515787.685,123.8471298,99.6243667602539,1.79963621227515E-5,3.63503083046161E-7,1,0.999253354069792,40.0298881530762,2.00792736174552,19.4899998605251,0.000205795964581828,3.49591806511777E-5,0.25,-8.74041195396123E-8,1.80940653843234E-5,-4.75282294253753E-8,123.8471298,123.8471298,99.6243667602539,99.6243667602539,57.0620084179291,20.6275511134155,21.770052,0,0,0,40,4374,121.0229,99.6243667602539,,,,,,,,,,,,,0,,,,-0.0049,,,,,,123.8471298,,,,
,31515922.5,120.46331405,99.6243667602539,1.7877835786419E-5,3.30902559659282E-7,1,0.999253354069792,40.0298881530762,1.99527506868229,19.4899998605251,0.000204173472426623,2.90791721996078E-5,0.25,-5.67937116818919E-7,1.79768894627717E-5,-5.29051733920463E-7,120.439209,120.4874191,99.6243667602539,99.6243667602539,57.4637654768138,20.6327506824458,22.149702,0,0,0,40,4374,117.6823,99.6243667602539,,,,,,,,,,,,,0,,,,0.00245,,,,,,120.46331405,,,,
,31516060.445,116.9936142,99.6243667602539,1.8013476324022E-5,3.63154224550675E-7,1,0.999253354069792,40.0298881530762,1.99531542589867,19.4899998605251,0.00020459778681334,3.58012454417246E-5,0.25,-2.13772823624957E-9,1.81126940476419E-5,4.23156503839031E-8,116.9638214,117.023407,99.6243667602539,99.6243667602539,57.76234757116,20.6331958505943,21.3904,0,0,0,40,4374,114.2529,99.6243667602539,,,,,,,,,,,,,0,,,,0,,,,,,116.9936142,,,,
touchdown = 14.5699996501207 mm,31516199.695,113.4838715,99.6243667602539,1.79152920050152E-5,3.67923116088888E-7,1,0.999253354069792,40.0298881530762,1.99533589219477,19.5599999278784,0.000203745490854018,3.41582799960006E-5,0.25,-1.32092814533726E-7,1.80149117655723E-5,-8.62292896911327E-8,113.4838715,113.4838715,99.6243667602539,99.6243667602539,57.3723149400638,20.6347759897253,21.3904,0,0,0,40,4374,110.79935,99.6243667602539,,,,,,,,,,,,,0,,,,-0.0049,,,,,,113.4838715,,,,
,31516338.71,109.9773788,99.6243667602539,1.79086059686935E-5,3.50766116166377E-7,1,0.999253354069792,40.0298881530762,1.99529966909973,19.5599999278784,0.00020396025216354,3.24965044739895E-5,0.25,-2.79853208156572E-7,1.80090347607869E-5,-2.32218631002835E-7,109.9773788,109.9773788,99.6243667602539,99.6243667602539,57.3113479155637,20.6415708165025,21.3904,0,0,0,40,4374,107.3441,99.6243667602539,,,,,,,,,,,,,0,,,,0.00245,,,,,,109.9773788,,,,
,31516476.795,106.49192425,99.6243667602539,1.77692026095178E-5,3.43917788062804E-7,1,0.999253354069792,40.0298881530762,1.99509674343632,19.5599999278784,0.000202789860518988,2.9768824269816E-5,0.25,-4.98177131838757E-7,1.78697411233902E-5,-4.49305377390391E-7,106.4647598,106.5190887,99.6243667602539,99.6243667602539,57.2480360055061,20.6403181453736,20.631098,0,0,0,40,4374,103.9151,99.6243667602539,,,,,,,,,,,,,0,,,,0,,,,,,106.49192425,,,,
touchdown = 14.639999717474 mm,31516611.765,103.0684433,99.6243667602539,1.73590773610244E-5,2.8558557491483E-7,1,0.999253354069792,40.0298881530762,1.99538368639633,19.6299999952316,0.000196778686139724,3.68169698132718E-5,0.25,1.91045764480584E-7,1.74552663840688E-5,2.45550090696087E-7,103.0684433,103.0684433,99.6243667602539,99.6243667602539,56.7149653553906,20.6355064586629,21.01075,0,0,0,40,4374,100.5792,99.6243667602539,,,,,,,,,,,,,0,,,,0,,,,,,103.0684433,,,,
,31516736.315,99.9524765,99.6243667602539,1.80400357573923E-5,3.35255333338987E-7,1,0.999253354069792,40.0298881530762,1.99515806717859,19.6299999952316,0.000205065742228048,3.48818278999117E-5,0.25,-1.01766229229819E-7,1.81406375372698E-5,-4.36360166659151E-8,99.9524765,99.9524765,99.6243667602539,99.6243667602539,57.2081729510253,20.6439733360625,21.3904,0,0,0,40,4374,97.48525,99.6243667602539,,,,,,,,,,,,,0,,,,-0.0049,,,,,,99.9524765,,,,
,31516873.835,96.4486542,99.6243667602539,1.79330409748133E-5,4.11465127349427E-7,1,0.999253354069792,40.0298881530762,1.9951005285087,19.6299999952316,0.000204277691346874,3.21708479009869E-5,0.25,-3.25299999132941E-7,1.80332019670753E-5,-2.64936504202016E-7,96.4486542,96.4486542,99.6243667602539,99.6243667602539,57.0455942190253,20.6367799052989,20.631098,0,0,0,40,4374,94.0816,99.6243667602539,,,,,,,,,,,,,0,,,,0,,,,,,96.4486542,,,,
,31517009.72,93.0313339,99.6243667602539,,,2,,,,19.7499997848272,,,,,,,93.0313339,93.0313339,99.6243667602539,99.6243667602539,,,20.631098,,,,-99999999,4374,90.7199,99.6243667602539,,,,,,,,,,,,,,,,,,,,,,,93.0313339,,,,
,31517129.53,89.9749603,99.6243667602539,1.79599497080692E-5,3.14658318749223E-7,1,0.999253354069792,40.0298881530762,2.007863452894,19.7000000625849,0.000204711785915673,3.86124286821047E-5,0.25,2.08875199882483E-7,1.80558581045494E-5,2.80516325928109E-7,89.9749603,89.9749603,99.6243667602539,99.6243667602539,57.3856026248907,20.6386551688359,21.01075,0,0,0,40,4374,87.7407,99.6243667602539,,,,,,,,,,,,,0,,,,0,,,,,,89.9749603,,,,
,31517268.86,86.4729614,99.6243667602539,1.80989491975745E-5,3.68720334181037E-7,1,0.999253354069792,40.0298881530762,2.00773076392624,19.7000000625849,0.00020778386301349,3.02744468383803E-5,0.25,-5.50440765278405E-7,1.81965086897761E-5,-4.77038407761235E-7,86.4729614,86.4729614,99.6243667602539,99.6243667602539,57.0901470446214,20.6395851744004,20.631098,0,0,0,40,4374,84.2987,99.6243667602539,,,,,,,,,,,,,0,,,,0,,,,,,86.4729614,,,,
,31517419.69,82.6284103,99.6243667602539,,,2,,,,19.8100002416968,,,,,,,82.6284103,82.6284103,99.6243667602539,99.6243667602539,,,20.251448,,,,-99999999,4374,80.5912,99.6243667602539,,,,,,,,,,,,,,,,,,,,,,,82.6284103,,,,
,31517544.11,79.4640427,99.6243667602539,1.79532203396834E-5,3.54763928719409E-7,1,0.999253354069792,40.0298881530762,2.00782109018101,19.7599995881319,0.000204676557073392,3.77319456926211E-5,0.25,1.17774012354486E-7,1.80402320569296E-5,2.05828225197619E-7,79.4640427,79.4640427,99.6243667602539,99.6243667602539,57.4090514804676,20.6354936100282,19.871798,0,0,0,40,4374,77.54965,99.6243667602539,,,,,,,,,,,,,0,,,,-0.0049,,,,,,79.4640427,,,,
,31517681.505,75.9528503,99.6243667602539,1.80742916319895E-5,2.94775310145574E-7,1,0.999253354069792,40.0298881530762,2.0080620756008,19.7599995881319,0.000206470669206099,3.54516050047861E-5,0.25,-1.09773864947317E-7,1.8157794571314E-5,-1.54111862273324E-8,75.9528503,75.9528503,99.6243667602539,99.6243667602539,57.6154014095446,20.6381652939573,19.492144,0,0,0,40,4374,74.1453,99.6243667602539,,,,,,,,,,,,,0,,,,0,,,,,,75.9528503,,,,
,31517830.73,72.1644135,99.6243667602539,,,2,,,,19.8800003090501,,,,,,,72.1644135,72.1644135,99.6243667602539,99.6243667602539,,,19.871798,,,,-99999999,4374,70.4929,99.6243667602539,,,,,,,,,,,,,,,,,,,,,,,72.1644135,,,,
,31517955.02,68.9943771,99.6243667602539,1.80791946058277E-5,3.34349247035979E-7,1,0.999253354069792,40.0298881530762,1.98366997182735,19.8299996554852,0.000203659231904888,3.67188060327552E-5,0.25,2.62713047826528E-8,1.81467967536904E-5,1.35840650857802E-7,68.9943771,68.9943771,99.6243667602539,99.6243667602539,57.4285921934484,20.646119936617,19.492144,0,0,0,40,4374,67.41595,99.6243667602539,,,,,,,,,,,,,0,,,,0.00245,,,,,,68.9943771,,,,
,31518093.805,65.4766083,99.6243667602539,1.81210101872349E-5,3.48565487125161E-7,1,0.999253354069792,40.0298881530762,1.98352759502111,19.8299996554852,0.00020426715238997,3.52682671456565E-5,0.25,-1.15393121817638E-7,1.81789444094679E-5,1.42646333796486E-9,65.4766083,65.4766083,99.6243667602539,99.6243667602539,57.5192611016792,20.6474027870647,19.492144,0,0,0,40,4374,64.0165,99.6243667602539,,,,,,,,,,,,,0,,,,-0.0049,,,,,,65.4766083,,,,
,31518239.63,61.7348366,99.6243667602539,,,2,,,,19.9500003764033,,,,,,,61.7348366,61.7348366,99.6243667602539,99.6243667602539,,,19.112494,,,,-99999999,4374,60.4329,99.6243667602539,,,,,,,,,,,,,,,,,,,,,,,61.7348366,,,,
,31518367.1,58.482193,99.6243667602539,1.80236917384154E-5,3.05055884525085E-7,1,0.999253354069792,40.0298881530762,1.98382565873312,19.8999997228384,0.000203118902474791,3.37391085351974E-5,0.25,-2.42211711791169E-7,1.8054313767368E-5,-1.13583184492553E-7,58.482193,58.482193,99.6243667602539,99.6243667602539,57.0940551872176,20.644548956952,19.112494,0,0,0,40,4374,57.29895,99.6243667602539,,,,,,,,,,,,,0,,,,-0.00245,,,,,,58.482193,,,,
,31518505.57,54.9552841,99.6243667602539,1.8115278162637E-5,3.06863954480914E-7,1,0.999253354069792,40.0298881530762,1.98360788281168,19.8999997228384,0.000203561221492338,3.59398195599521E-5,0.25,-6.34990821487566E-8,1.81272520080995E-5,6.99883196537636E-8,54.9552841,54.9552841,99.6243667602539,99.6243667602539,57.3996719382368,20.6506078565933,18.732843,0,0,0,40,4374,53.89425,99.6243667602539,,,,,,,,,,,,,0,,,,0,,,,,,54.9552841,,,,
,31518646.81,51.3995895,99.6243667602539,,,2,,,,20.0099999019504,,,,,,,51.3995895,51.3995895,99.6243667602539,99.6243667602539,,,18.353191,,,,-99999999,4374,50.428,99.6243667602539,,,,,,,,,,,,,,,,,,,,,,,51.3995895,,,,
,31518760.695,48.47900775,99.6243667602539,1.82435663682639E-5,3.47809278070592E-7,1,0.999253354069792,40.0298881530762,2.00806828372918,19.9599992483854,0.000206937201852266,3.69633488085324E-5,0.25,-2.77413277512585E-8,1.82198721808174E-5,1.06833892596017E-7,48.4542618,48.5037537,99.6243667602539,99.6243667602539,57.5567792706022,20.6378732320415,17.973541,0,0,0,40,4370,47.61985,99.6243667602539,,,,,,,,,,,,,0,,,,0.00245,,,,,,48.47900775,,,,
,31518896.945,44.9846592,99.6243667602539,1.83126602050622E-5,3.3698681907284E-7,1,0.999253354069792,40.0298881530762,2.00798102715212,19.9599992483854,0.000207678587583946,3.60843660976858E-5,0.25,-1.10477608896906E-7,1.82709965626987E-5,2.08304584859182E-8,44.9554482,45.0138702,99.6243667602539,99.6243667602539,57.4528226775445,20.6394270605577,17.973541,0,0,0,40,4370,44.28345,99.6243667602539,,,,,,,,,,,,,0,,,,0,,,,,,44.9846592,,,,
,31519034.69,41.493885,99.6243667602539,1.81311094158136E-5,3.35959626414331E-7,1,0.999253354069792,40.0298881530762,2.00811948888529,19.9599992483854,0.000205259025167651,3.67102819766803E-5,0.25,-1.35618529183553E-8,1.80723651539529E-5,1.09952827489452E-7,41.493885,41.493885,99.6243667602539,99.6243667602539,56.9588334533906,20.6358946244882,17.593889,0,0,0,40,4370,40.8913,99.6243667602539,,,,,,,,,,,,,0,,,,0,,,,,,41.493885,,,,
,31519153.39,38.4788589,99.6243667602539,1.78603205859771E-5,3.3533293618107E-7,1,0.999253354069792,40.0298881530762,1.9956003260566,20.0100000947714,0.000201202469572378,3.39680334432863E-5,0.25,-1.8077141510378E-7,1.77913118588484E-5,-6.4856580867886E-8,38.4788589,38.4788589,99.6243667602539,99.6243667602539,57.0260535060445,20.6346489860638,17.214239,0,0,0,40,4370,37.9694,99.6243667602539,,,,,,,,,,,,,0,,,,0,,,,,,38.4788589,,,,
,31519291.625,34.9715958,99.6243667602539,1.81855402436258E-5,3.12006840772146E-7,1,0.999253354069792,40.0298881530762,1.99573822645301,20.0100000947714,0.000204463025791259,3.61437962218136E-5,0.25,-3.57504186039442E-8,1.81025323116175E-5,7.37357658741066E-8,34.9715958,34.9715958,99.6243667602539,99.6243667602539,57.0502839901407,20.6367036375123,16.834587,0,0,0,40,4370,34.5555,99.6243667602539,,,,,,,,,,,,,0,,,,-0.0049,,,,,,34.9715958,,,,
,31519430.275,31.4824791,99.6243667602539,1.83372280252294E-5,3.57097232282227E-7,1,0.999253354069792,40.0298881530762,1.99593837385465,20.0100000947714,0.000205717809832537,3.84980112843892E-5,0.25,1.55441484141414E-7,1.82434980488079E-5,2.57370846102597E-7,31.4824791,31.4824791,99.6243667602539,99.6243667602539,56.973684395256,20.6362786075961,16.075285,0,0,0,40,4370,31.1233,99.6243667602539,,,,,,,,,,,,,0,,,,0,,,,,,31.4824791,,,,
,31519568.51,27.99190715,99.6243667602539,1.82074699543402E-5,2.9926740301831E-7,1,0.999253354069792,40.0298881530762,2.00839334294526,20.0599990785122,0.000205552199771824,3.7629988070108E-5,0.25,8.88218526423277E-8,1.81086065371492E-5,1.84160015770075E-7,27.9606667,28.0231476,99.6243667602539,99.6243667602539,57.2964969736984,20.6384888859185,15.695635,0,0,0,40,4370,27.69575,99.6243667602539,,,,,,,,,,,,,0,,,,0.0049,,,,,,27.99190715,,,,
,31519707.885,24.4483566,99.6243667602539,1.81840549899354E-5,3.56661778263199E-7,1,0.999253354069792,40.0298881530762,2.00813663563492,20.0599990785122,0.000205890724478524,3.37840560828542E-5,0.25,-2.41823454059574E-7,1.8083039465901E-5,-1.49287315121542E-7,24.4483566,24.4483566,99.6243667602539,99.6243667602539,57.2214606358522,20.6435137349085,15.315984,0,0,0,40,4370,24.2327,99.6243667602539,,,,,,,,,,,,,0,,,,0.00245,,,,,,24.4483566,,,,
,31519845.57,20.9905758,99.6243667602539,1.79337225712563E-5,3.70382166395181E-7,1,0.999253354069792,40.0298881530762,2.00820582103812,20.0599990785122,0.000202352098468905,3.71857637364227E-5,0.25,1.06697421984833E-7,1.78303607888687E-5,1.93403672626147E-7,20.9905758,20.9905758,99.6243667602539,99.6243667602539,56.8963031718522,20.6434279221489,14.936333,0,0,0,40,4370,20.81545,99.6243667602539,,,,,,,,,,,,,0,,,,-0.00245,,,,,,20.9905758,,,,
,31519985.71,17.4712048,99.6243667602539,1.80135372138219E-5,2.82413719962424E-7,1,0.999253354069792,40.0298881530762,2.00810245810058,20.0900007039309,0.000203283818892868,3.70841245117471E-5,0.25,8.46602830525301E-8,1.79093171803107E-5,1.7099851282998E-7,17.4712048,17.4712048,99.6243667602539,99.6243667602539,57.1839424669291,20.6446589484993,14.556682,0,0,0,40,4370,17.3218,99.6243667602539,,,,,,,,,,,,,0,,,,0,,,,,,17.4712048,,,,
,31520125.045,13.9808083,99.6243667602539,1.80581595273539E-5,2.99928332008165E-7,1,0.999253354069792,40.0298881530762,2.00798057287377,20.0900007039309,0.000204527843840928,3.29527337454787E-5,0.25,-2.8896906228986E-7,1.795571353304E-5,-2.00216674121172E-7,13.9808083,13.9808083,99.6243667602539,99.6243667602539,57.4512594205061,20.6414383736546,13.797379,0,0,0,40,4370,13.86515,99.6243667602539,,,,,,,,,,,,,0,,,,0,,,,,,13.9808083,,,,
,31520263.3,10.4892473,99.6243667602539,1.82282107963018E-5,2.80074027989935E-7,1,0.999253354069792,40.0298881530762,2.00795788343242,20.0900007039309,0.000206406542920435,3.35254722815621E-5,0.25,-2.68444266704743E-7,1.81248225693215E-5,-1.78991109494874E-7,10.4892473,10.4892473,99.6243667602539,99.6243667602539,57.0604451608906,20.6403082713668,12.658426,0,0,0,40,4370,10.40875,99.6243667602539,,,,,,,,,,,,,0,,,,0,,,,,,10.4892473,,,,
,31520418.795,10.0022035,99.6243667602539,1.80913476415102E-5,3.51468764428919E-7,1,0.999253354069792,40.0298881530762,2.0079856212611,20.1099999248981,0.000205125080118468,3.17794109985931E-5,0.25,-3.98781658185287E-7,1.79893882234185E-5,-3.09240297485354E-7,10.0017977,10.0026093,99.6243667602539,99.6243667602539,57.0432493334676,20.643374204047,12.658426,0,0,0,40,4369,9.99445,99.6243667602539,,,,,,,,,,,,,0,,,,0,,,,,,10.0022035,,,,