File: data/doubleLayers/dl_0-25/ppms/data/DD205_10_HYST_INIT_300K.DAT
[Header]
; VSM Data File (default extension .dat)
; Copyright (c) 2003-2013, Quantum Design, Inc. All rights reserved.
TITLE,
FILEOPENTIME,31469421.42,12/31/2018,1:32 pm
BYAPP,VSM,2.0,2.0
INFO,PPMS VSM Option Release 1.4.10 Build 1,APPNAME
INFO,Quantum Design Linear Motor Servo Controller,MOTOR_MODULE_NAME
INFO,3101-100 M1,MOTOR_HW_VERSION
INFO,MMC1014,MOTOR_SERIAL_NUMBER
INFO,SRV No X-over 01.03.11,MOTOR_SOFTWARE_VERSION
INFO,Quantum Design VSM Detection Module,VSM_MODULE_NAME
INFO,3101-150 F0,VSM_HW_VERSION
INFO,VSM707,VSM_SERIAL_NUMBER
INFO,VSM No X-over 01.02.05 May 20 2008 13:51:47,VSM_SOFTWARE_VERSION
INFO,704,PREAMP_SERIAL_NUMBER
INFO,822,COIL_SERIAL_NUMBER
INFO,0,MOMENT_UNITS
INFO,CoFe2O4,SAMPLE_MATERIAL
INFO,Double Layer thin concentration,SAMPLE_COMMENT
INFO,27.44,SAMPLE_MASS
INFO,,SAMPLE_VOLUME
INFO,,SAMPLE_MOLECULAR_WEIGHT
INFO,,SAMPLE_SIZE
INFO,,SAMPLE_SHAPE
DATATYPE,COMMENT,1
DATATYPE,TIME,2
STARTUPAXIS,X,2
STARTUPAXIS,Y1,5
[Data]
Comment,Time Stamp (sec),Temperature (K),Magnetic Field (Oe),Moment (emu),M. Std. Err. (emu),Transport Action,Averaging Time (sec),Frequency (Hz),Peak Amplitude (mm),Center Position (mm),Coil Signal' (mV),Coil Signal" (mV),Range (mV),M. Quad. Signal (emu),M. Raw' (emu),M. Raw" (emu),Min. Temperature (K),Max. Temperature (K),Min. Field (Oe),Max. Field (Oe),Mass (grams),Motor Lag (deg),Pressure (Torr),VSM Status (code),Motor Status (code),Measure Status (code),Measure Count,PPMS Status (code),System Temp. (K),System Field (Oe),Sample Position (deg),Bridge 1 Resistance (ohms),Bridge 1 Excitation (에),Bridge 2 Resistance (ohms),Bridge 2 Excitation (에),Bridge 3 Resistance (ohms),Bridge 3 Excitation (에),Bridge 4 Resistance (ohms),Bridge 4 Excitation (에),Signal 1 Vin (V),Signal 2 Vin (V),Digital Inputs (code),Drive 1 Iout (mA),Drive 1 Ipower (W),Drive 2 Iout (mA),Drive 2 Ipower (W),Pressure (),Map 20 (),Map 21 (),Map 22 (),Map 23 (),Map 24 (),Map 25 (),Map 26 (),Map 27 (),Map 28 (),Map 29 ()
,31469436.88,300.0158691,0.0456713177263737,,,2,,,,18.8399998405576,,,,,,,300.0158691,300.0158691,0.0456713177263737,0.0456713177263737,,,22.909004,,,,-99999999,4369,300.3095,0.0456713177263737,,,,,,,,,,,,,,,,,,,,,,,300.0158691,,,,
,31469570.25,300.0322876,4039.38439941406,4.17243983488404E-5,5.12329297676374E-7,1,0.999253354069792,40.0298881530762,2.00071933892881,18.7899991869926,0.000472675684586455,8.17511385427592E-5,0.25,-1.23817566904054E-8,4.17231145092106E-5,1.52828726599302E-8,300.0322876,300.0322876,4012.0400390625,4066.72875976562,56.0974788251982,20.5394509734882,22.909004,0,0,0,40,4449,300.26425,4039.38439941406,,,,,,,,,,,,,0,,,,-0.00245,,,,,,300.0322876,,,,
,31469658.345,300.0340881,8442.158203125,3.57448117421609E-5,8.46945162381404E-7,1,0.999253354069792,40.0298881530762,2.00045397409395,18.7899991869926,0.000404113944623449,7.44741440731287E-5,0.25,3.82092142249886E-7,3.57434506499561E-5,4.05765655310527E-7,300.0340881,300.0340881,8412.16015625,8472.15625,56.2092517034482,20.5430169425389,22.909004,0,0,0,40,4449,300.2418,8442.158203125,,,,,,,,,,,,,0,,,,0.00245,,,,,,300.0340881,,,,
,31469745.485,300.0288696,12797.8901367188,2.32037727139129E-5,8.18023709790466E-7,1,0.999253354069792,40.0298881530762,2.00006093259843,18.7899991869926,0.000260929872308174,5.61386367930849E-5,0.25,9.37066842932688E-7,2.3202438286921E-5,9.52403059504238E-7,300.0288696,300.0288696,12795.4892578125,12800.291015625,56.414820004006,20.5477031975061,22.909004,0,0,0,40,4449,300.21885,12797.8901367188,,,,,,,,,,,,,0,,,,0.0049,,,,,,300.0288696,,,,
,31469833.715,300.0308533,17205.759765625,9.78761068135488E-6,6.80083864981168E-7,1,0.999253354069792,40.0298881530762,2.00007092560885,18.7899991869926,0.000108027919602969,3.54297642772202E-5,0.25,1.43282661619281E-6,9.78636116340639E-6,1.43925895642082E-6,300.0308533,300.0308533,17203.26171875,17208.2578125,56.4413953736598,20.5471144922534,23.668306,0,0,0,40,4449,300.1926,17205.759765625,,,,,,,,,,,,,0,,,,-0.0049,,,,,,300.0308533,,,,
,31469925.14,300.023468,21775.9697265625,-5.49985465922071E-6,1.07706649169564E-6,1,0.999253354069792,40.0298881530762,1.99992242789669,18.7899991869926,-6.55693529389951E-5,8.20445303528816E-6,0.25,1.67743398248971E-6,-5.50079604264479E-6,1.67374667860973E-6,300.023468,300.023468,21766.00390625,21785.935546875,56.546915223756,20.5475675137106,22.529354,0,0,0,40,4449,300.17855,21775.9697265625,,,,,,,,,,,,,0,,,,0,,,,,,300.023468,,,,
,31470013.375,300.02059935,26186.40234375,-2.02218650593236E-5,1.3053786256528E-6,1,0.999253354069792,40.0298881530762,1.99978232885119,18.7899991869926,-0.000230397287204162,-3.14321099495242E-5,0.25,7.27601423082642E-7,-2.02217324469206E-5,7.14221395119529E-7,300.0200195,300.0211792,26158.69140625,26214.11328125,56.4992358840829,20.5498107170889,22.529354,0,0,0,40,4449,300.1673,26186.40234375,,,,,,,,,,,,,0,,,,0,,,,,,300.02059935,,,,
,31470104.675,300.0142822,30751.765625,-3.70083056944414E-5,1.91204480739835E-6,1,0.999253354069792,40.0298881530762,1.9997575417161,18.7899991869926,-0.000422598375691633,-5.20398991489592E-5,0.25,1.8158837514172E-6,-3.70083922169737E-5,1.79140503659483E-6,300.0142822,300.0142822,30746.859375,30756.671875,56.6149169049291,20.5523530819393,23.288654,0,0,0,40,4449,300.1539,30751.765625,,,,,,,,,,,,,0,,,,0,,,,,,300.0142822,,,,
,31470187.295,300.0077515,34879.81640625,-4.94669992237061E-5,1.79574765769102E-6,1,0.999253354069792,40.0298881530762,1.99970102033786,18.7899991869926,-0.000563704909939967,-7.61621915113837E-5,0.25,1.84379810498096E-6,-4.94667430112823E-5,1.81112643767185E-6,300.0077515,300.0077515,34849.92578125,34909.70703125,56.6133536478906,20.5524605147295,22.529354,0,0,0,40,4449,300.15555,34879.81640625,,,,,,,,,,,,,0,,,,0,,,,,,300.0077515,,,,
,31470271.695,300.0086975,39097.330078125,-6.53540769609686E-5,1.40837420690154E-6,1,0.999253354069792,40.0298881530762,1.99976265112865,18.7899991869926,-0.000747328586153284,-8.58534467054964E-5,0.25,3.7405781227491E-6,-6.53545977419658E-5,3.69741440601472E-6,300.0083313,300.0090637,39067.51171875,39127.1484375,56.6680676442368,20.5512549670532,23.668306,0,0,0,40,4449,300.15,39097.330078125,,,,,,,,,,,,,0,,,,0.00245,,,,,,300.0086975,,,,
,31470353.145,300.0133972,43165.783203125,-7.76963649025472E-5,2.34406672412364E-6,1,0.999253354069792,40.0298881530762,1.99973171395826,18.7899991869926,-0.000882403710260712,-0.000136965532828282,0.25,1.36462983600661E-6,-7.76949436306484E-5,1.31345117546232E-6,300.0122375,300.0145569,43140.95703125,43190.609375,56.7384142109675,20.5505349247982,22.909004,0,0,0,40,4449,300.1381,43165.783203125,,,,,,,,,,,,,0,,,,0.00245,,,,,,300.0133972,,,,
,31470433.4,300.0119019,47178.953125,-9.46487609691484E-5,2.04083737471185E-6,1,0.999253354069792,40.0298881530762,1.9997005620704,18.7899991869926,-0.00108471960363776,-0.000110270935737581,0.25,6.65914328001145E-6,-9.46503245102302E-5,6.59670622878118E-6,300.0119019,300.0119019,47158.9375,47198.96875,56.8650380310829,20.5515790289042,23.668306,0,0,0,40,4449,300.13215,47178.953125,,,,,,,,,,,,,0,,,,0.00245,,,,,,300.0119019,,,,
,31470513.5,300.0065918,51181.8828125,-0.000109873740881954,2.17256135784087E-6,1,0.999253354069792,40.0298881530762,1.99972658160646,18.7899991869926,-0.00125209639047924,-0.000169132788309648,0.25,4.09837112803867E-6,-0.000109873192146033,4.02606780964625E-6,300.0065613,300.0066223,51156.7890625,51206.9765625,56.6055373626983,20.5522442897198,23.668306,0,0,0,40,4449,300.13185,51181.8828125,,,,,,,,,,,,,0,,,,0.00245,,,,,,300.0065918,,,,
,31470593.305,300.003067,55169.873046875,-0.000126553970556099,2.13259725820967E-6,1,0.999253354069792,40.0298881530762,1.9996665914893,18.7899991869926,-0.00144032106133777,-0.000205299470599446,0.25,3.79347914976949E-6,-0.000126552750203845,3.71030688298218E-6,300.002655,300.003479,55139.79296875,55199.953125,56.5187765970637,20.5531276745357,23.288654,0,0,0,40,4449,300.13235,55169.873046875,,,,,,,,,,,,,0,,,,0.00245,,,,,,300.003067,,,,
,31470671.96,300.0096741,59102.771484375,-0.00014125064678449,2.29003375417476E-6,1,0.999253354069792,40.0298881530762,1.99965541157761,18.7899991869926,-0.00161399382139135,-0.000192097649799229,0.25,7.50554236649882E-6,-0.000141251401448606,7.41269913418757E-6,300.0096741,300.0096741,59072.78515625,59132.7578125,56.6735390438714,20.5517868113049,23.288654,0,0,0,40,4449,300.1228,59102.771484375,,,,,,,,,,,,,0,,,,-0.00245,,,,,,300.0096741,,,,
,31470750.24,300.0011292,63016.55859375,-0.000151380285472235,2.86688786095496E-6,1,0.999253354069792,40.0298881530762,1.99969576770447,18.7899991869926,-0.00171869142103049,-0.000269843263917888,0.25,2.39425621404075E-6,-0.00015137744308854,2.29501679723239E-6,300.0011292,300.0011292,62986.43359375,63046.68359375,56.7548284098714,20.5522634199853,23.288654,0,0,0,40,4449,300.12015,63016.55859375,,,,,,,,,,,,,0,,,,-0.00245,,,,,,300.0011292,,,,
,31470829.15,300.0080261,66959.73046875,-0.000167531251083764,2.66253220150394E-6,1,0.999253354069792,40.0298881530762,1.99964295257782,18.7899991869926,-0.00190476244006465,-0.000282753558088916,0.25,4.05145269637958E-6,-0.000167528989225513,3.94169175437265E-6,300.0073242,300.008728,66929.6484375,66989.8125,56.7524835243137,20.5516032866893,23.288654,0,0,0,40,4449,300.1212,66959.73046875,,,,,,,,,,,,,0,,,,0,,,,,,300.0080261,,,,
,31470906.855,300.0125122,70842.57421875,-0.000182336765005978,1.96271603666929E-6,1,0.999253354069792,40.0298881530762,1.99954560305787,18.7899991869926,-0.00207650024364039,-0.000287515830255236,0.25,6.19460959607824E-6,-0.000182335448288132,6.0752073273594E-6,300.0125122,300.0125122,70812.546875,70872.6015625,56.7829670365637,20.5532802206162,22.909004,0,0,0,40,4449,300.11105,70842.57421875,,,,,,,,,,,,,0,,,,0.00245,,,,,,300.0125122,,,,
,31470985.17,300.0065613,74758.35546875,-0.000199558358913748,2.14638744219811E-6,1,0.999253354069792,40.0298881530762,1.99957578276379,18.7899991869926,-0.00227155856271716,-0.000321020321740913,0.25,6.21921367268677E-6,-0.000199556601001729,6.08867303362384E-6,300.0062256,300.006897,74730.859375,74785.8515625,56.7884384361983,20.5529012601129,23.288654,0,0,0,40,4449,300.09375,74758.35546875,,,,,,,,,,,,,0,,,,0,,,,,,300.0065613,,,,
,31471065.665,300.00917055,78782.0078125,-0.000208131454895054,2.5365130010685E-6,1,0.999253354069792,40.0298881530762,1.99951455764439,18.7899991869926,-0.00236982256473806,-0.000330493349848116,0.25,6.86678943993389E-6,-0.000208129858659903,6.73077691632023E-6,300.0084534,300.0098877,78749.546875,78814.46875,56.8220484625252,20.5542449038426,23.668306,0,0,0,40,4449,300.10755,78782.0078125,,,,,,,,,,,,,0,,,,0,,,,,,300.00917055,,,,
,31471143.46,300.0074768,82670.47265625,-0.000224133758224651,2.11340476889806E-6,1,0.999253354069792,40.0298881530762,1.99952110952659,18.7899991869926,-0.0025499106379061,-0.0003681719597009,0.25,6.31106157549545E-6,-0.000224131354555516,6.16476948525213E-6,300.0071716,300.007782,82643.0234375,82697.921875,56.780622151006,20.5533445549192,23.288654,0,0,0,40,4449,300.10465,82670.47265625,,,,,,,,,,,,,0,,,,-0.00245,,,,,,300.0074768,,,,
,31471219.985,300.0058594,86496.66015625,-0.000240518406029695,3.8040641979109E-6,1,0.999253354069792,40.0298881530762,1.99947680158354,18.7899991869926,-0.00273065484555796,-0.000427413091017981,0.25,3.91610506069273E-6,-0.000240513989699985,3.75935519649187E-6,300.0053711,300.0063477,86466.546875,86526.7734375,56.9517987967176,20.5554750888432,23.668306,0,0,0,40,4449,300.0989,86496.66015625,,,,,,,,,,,,,0,,,,0,,,,,,300.0058594,,,,
,31471309.34,300.0105896,89790.04296875,-0.000252893224362281,2.49731680861609E-6,1,0.999253354069792,40.0298881530762,1.99943057979838,18.7899991869926,-0.00286924933635752,-0.00045998936614993,0.25,3.18153018291346E-6,-0.000252887938818413,3.0168817342008E-6,300.0101318,300.0110474,89763.1796875,89816.90625,56.8157954343714,20.5531297290728,23.288654,0,0,0,40,4449,300.0942,89790.04296875,,,,,,,,,,,,,0,,,,0.0049,,,,,,300.0105896,,,,
,31471385.585,300.008728,85983.81640625,-0.000235779528945011,2.5958519553717E-6,1,0.999253354069792,40.0298881530762,1.9993882263067,18.7899991869926,-0.00268322009423902,-0.000381570142829259,0.25,7.14298066441322E-6,-0.000235777325521408,6.98919612908232E-6,300.008728,300.008728,85953.7265625,86013.90625,56.770460980256,20.5537653952497,22.909004,0,0,0,40,4449,300.08885,85983.81640625,,,,,,,,,,,,,0,,,,0,,,,,,300.008728,,,,
,31471462.22,300.0006409,82152.64453125,-0.000222420645143803,2.3366044427755E-6,1,0.999253354069792,40.0298881530762,1.99954834935972,18.7899991869926,-0.00253232653903196,-0.00035455723275108,0.25,7.21726463247118E-6,-0.000222418935086433,7.0720367910898E-6,300.0006409,300.0006409,82150.28125,82155.0078125,56.7352876968906,20.5558737067253,23.288654,0,0,0,40,4449,300.08985,82152.64453125,,,,,,,,,,,,,0,,,,0,,,,,,300.0006409,,,,
,31471539.72,299.99491885,78278.31640625,-0.000207762901343513,2.05872889114899E-6,1,0.999253354069792,40.0298881530762,1.99970897685319,18.7899991869926,-0.00235733425118033,-0.000379073882701228,0.25,2.5150753913239E-6,-0.000207758580786211,2.37940778237865E-6,299.994751,299.9950867,78250.6875,78305.9453125,56.7220000120637,20.5574364009429,23.288654,0,0,0,40,4449,300.09565,78278.31640625,,,,,,,,,,,,,0,,,,-0.0049,,,,,,299.99491885,,,,
,31471617.445,299.9909973,74391.7265625,-0.000194731042594807,2.76217760521282E-6,1,0.999253354069792,40.0298881530762,1.99960621695016,18.7899991869926,-0.00221386686176655,-0.000329283453215575,0.25,4.65348677584127E-6,-0.000194728511078987,4.52614024816078E-6,299.9909973,299.9909973,74366.703125,74416.75,56.6696309012752,20.5556258448013,23.668306,0,0,0,40,4449,300.10275,74391.7265625,,,,,,,,,,,,,0,,,,0,,,,,,299.9909973,,,,
,31471696.045,299.9872589,70463.28125,-0.000179141316674861,3.12388582477095E-6,1,0.999253354069792,40.0298881530762,1.99951611953949,18.7899991869926,-0.00204523424356465,-0.000252739019401918,0.25,8.71242847053824E-6,-0.000179141902348594,8.59503817126026E-6,299.9871216,299.9873962,70438.140625,70488.421875,56.8337728903137,20.5568840069415,23.288654,0,0,0,40,4449,300.11155,70463.28125,,,,,,,,,,,,,0,,,,0,,,,,,299.9872589,,,,
,31471775.415,299.98770145,66497.29296875,-0.000164500525992672,2.5240363315035E-6,1,0.999253354069792,40.0298881530762,1.99954897129746,18.7899991869926,-0.0018737972143708,-0.000256988947591815,0.25,5.80097927342701E-6,-0.000164499617490258,5.693142950783E-6,299.9876404,299.9877625,66469.765625,66524.8203125,56.9220969129868,20.5579154687706,22.909004,0,0,0,40,4449,300.12305,66497.29296875,,,,,,,,,,,,,0,,,,-0.0049,,,,,,299.98770145,,,,
,31471855.93,299.98243715,62471.796875,-0.000149800164130639,2.22240032682153E-6,1,0.999253354069792,40.0298881530762,1.99946226579469,18.7899991869926,-0.0016991293443442,-0.000275273125330722,0.25,1.63824747376505E-6,-0.000149796972417033,1.54005737145855E-6,299.9819336,299.9829407,62446.7421875,62496.8515625,56.9158438848329,20.5590242343312,23.668306,0,0,0,40,4449,300.1315,62471.796875,,,,,,,,,,,,,0,,,,-0.0049,,,,,,299.98243715,,,,
,31471936.59,299.9802856,58440.845703125,-0.000132278325128946,1.7900099184324E-6,1,0.999253354069792,40.0298881530762,1.99949607266626,18.7899991869926,-0.00150863353231367,-0.000195611368732583,0.25,5.63944190505732E-6,-0.000132278260151042,5.55253593790049E-6,299.9802856,299.9802856,58438.3203125,58443.37109375,56.9580518248714,20.5591461251972,23.288654,0,0,0,40,4449,300.14355,58440.845703125,,,,,,,,,,,,,0,,,,-0.0049,,,,,,299.9802856,,,,
,31472016.035,299.9858093,54469.923828125,-0.000121125263194884,2.31310094456879E-6,1,0.999253354069792,40.0298881530762,1.99948626547206,18.7899991869926,-0.0013858816799421,-0.000153400541675997,0.25,7.43558065605015E-6,-0.000121126667217067,7.35585882476483E-6,299.9858093,299.9858093,54439.66796875,54500.1796875,56.973684395256,20.5597878343117,23.668306,0,0,0,40,4449,300.14235,54469.923828125,,,,,,,,,,,,,0,,,,-0.00245,,,,,,299.9858093,,,,
,31472096.04,299.9852295,50469.33984375,-0.000104026286747111,1.6729729869997E-6,1,0.999253354069792,40.0298881530762,1.99941285888758,18.7899991869926,-0.00118902028051211,-0.000138539779744042,0.25,5.78540254397119E-6,-0.000104027098518834,5.71689157539238E-6,299.9852295,299.9852295,50442,50496.6796875,56.8204852054868,20.5612317360588,23.288654,0,0,0,40,4449,300.16105,50469.33984375,,,,,,,,,,,,,0,,,,0,,,,,,299.9852295,,,,
,31472173.805,299.9910583,46584.203125,-9.1268108996543E-5,1.9544870420013E-6,1,0.999253354069792,40.0298881530762,1.99935117511908,18.7899991869926,-0.00104193375423152,-0.000128642378878744,0.25,4.44897831661793E-6,-9.12683881062836E-5,4.38883401401359E-6,299.9910583,299.9910583,46554.16796875,46614.23828125,56.8689461736791,20.5630459533755,22.909004,0,0,0,40,4449,300.17065,46584.203125,,,,,,,,,,,,,0,,,,0,,,,,,299.9910583,,,,
,31472252.715,299.9885254,42640.365234375,-7.85160665164014E-5,1.7394043548381E-6,1,0.999253354069792,40.0298881530762,1.99958422265427,18.7899991869926,-0.000894514507340577,-0.000121874118435861,0.25,2.83875242093962E-6,-7.85156612330539E-5,2.78699413194882E-6,299.9883423,299.9887085,42610.2890625,42670.44140625,57.0026046504676,20.5584103754479,23.668306,0,0,0,40,4449,300.1759,42640.365234375,,,,,,,,,,,,,0,,,,0,,,,,,299.9885254,,,,
,31472331.72,299.9880676,38689.640625,-6.24217764318981E-5,1.65558298080442E-6,1,0.999253354069792,40.0298881530762,1.99958103268941,18.7899991869926,-0.000713742367091738,-8.19586651713683E-5,0.25,3.57589601652268E-6,-6.24223222107052E-5,3.5346723785015E-6,299.9880676,299.9880676,38687.02734375,38692.25390625,56.9697762526599,20.5607831348792,23.288654,0,0,0,40,4449,300.179,38689.640625,,,,,,,,,,,,,0,,,,0,,,,,,299.9880676,,,,
,31472408.795,299.9866791,34839.87109375,-4.9860200171892E-5,1.66250012735397E-6,1,0.999253354069792,40.0298881530762,1.99954292204041,18.7899991869926,-0.00056770244711117,-7.93059563962232E-5,0.25,1.63373766838496E-6,-4.98598317337509E-5,1.60081839328167E-6,299.9862671,299.9870911,34809.94140625,34869.80078125,56.8376810329099,20.5643686132885,23.288654,0,0,0,40,4449,300.19025,34839.87109375,,,,,,,,,,,,,0,,,,0.00245,,,,,,299.9866791,,,,
,31472486.59,299.9848175,30949.0087890625,-3.47807231312054E-5,1.59373473888954E-6,1,0.999253354069792,40.0298881530762,1.99938062809794,18.7899991869926,-0.000395767597534703,-5.65347209119188E-5,0.25,1.03207017140795E-6,-3.47803964224541E-5,1.0090914992444E-6,299.9835815,299.9860535,30921.373046875,30976.64453125,56.9095908566791,20.5629227024802,22.909004,0,0,0,40,4449,300.20175,30949.0087890625,,,,,,,,,,,,,0,,,,-0.00245,,,,,,299.9848175,,,,
,31472565.135,299.9885254,27026.310546875,-2.16582135543831E-5,1.15694289028362E-6,1,0.999253354069792,40.0298881530762,1.99944043381994,18.7899991869926,-0.000246008558928743,-3.7778905821876E-5,0.25,4.15385946547157E-7,-2.16578564128965E-5,4.01071518335103E-7,299.9884949,299.9885559,26994.064453125,27058.556640625,56.9916618511983,20.5641843238067,23.288654,0,0,0,40,4449,300.202,27026.310546875,,,,,,,,,,,,,0,,,,0,,,,,,299.9885254,,,,
,31472643.525,299.9900818,23108.310546875,-7.80507796964227E-6,6.70338394482861E-7,1,0.999253354069792,40.0298881530762,1.99946785307021,18.7899991869926,-9.17672555688307E-5,4.33990870218935E-6,0.25,1.73563119278864E-6,-7.80599666697032E-6,1.73042212518708E-6,299.9900208,299.9901428,23080.96484375,23135.65625,57.0018230219483,20.5632930290801,23.288654,0,0,0,40,4449,300.20695,23108.310546875,,,,,,,,,,,,,0,,,,0.00245,,,,,,299.9900818,,,,
,31472722.155,299.9914856,19175.2275390625,4.90545205331912E-6,8.16274179276434E-7,1,0.999253354069792,40.0298881530762,1.99941652817234,18.7899991869926,5.4688720744782E-5,1.45018188523223E-5,0.25,4.31066800237947E-7,4.90502296433056E-6,4.3429852674444E-7,299.9914856,299.9914856,19172.79296875,19177.662109375,56.9510171681983,20.5657913107046,22.909004,0,0,0,40,4449,300.2176,19175.2275390625,,,,,,,,,,,,,0,,,,0,,,,,,299.9914856,,,,
,31472800.18,299.9905548,15277.3642578125,1.70210517482645E-5,8.76420016591257E-7,1,0.999253354069792,40.0298881530762,1.99939266299629,18.7899991869926,0.00019136357659185,4.10513722782532E-5,0.25,6.77152527990055E-7,1.70201037791443E-5,6.88398281891684E-7,299.9899902,299.9911194,15244.6640625,15310.064453125,57.0588819038522,20.5646103350996,23.288654,0,0,0,40,4449,300.2231,15277.3642578125,,,,,,,,,,,,,0,,,,0,,,,,,299.9905548,,,,
,31472878.055,299.9837952,11386.6801757813,2.89405924235455E-5,6.9387936552703E-7,1,0.999253354069792,40.0298881530762,1.99936331542232,18.7899991869926,0.000325501866718392,6.90229912837666E-5,0.25,1.08288088917927E-6,2.89390312166722E-5,1.10201771008526E-6,299.9837952,299.9837952,11361.6591796875,11411.701171875,57.0768593597945,20.5671534042861,23.668306,0,0,0,40,4449,300.22335,11386.6801757813,,,,,,,,,,,,,0,,,,-0.00245,,,,,,299.9837952,,,,
,31472953.195,299.9822083,7630.88623046875,3.84352259073817E-5,6.10513233859408E-7,1,0.999253354069792,40.0298881530762,1.99949136387717,18.7899991869926,0.000433774783395477,8.32577906138026E-5,0.25,6.94807943586466E-7,3.84336454936958E-5,7.20259046169841E-7,299.9822083,299.9822083,7603.4765625,7658.2958984375,56.9557069393137,20.5672086660706,23.668306,0,0,0,40,4449,300.2439,7630.88623046875,,,,,,,,,,,,,0,,,,0,,,,,,299.9822083,,,,
,31473028.86,299.9871216,3847.51416015625,4.2737841210859E-5,4.03684793824295E-7,1,0.999253354069792,40.0298881530762,1.99946118445527,18.7899991869926,0.000483745573478866,8.4386069032139E-5,0.25,4.90918559434188E-8,4.27365542959148E-5,7.74296503478759E-8,299.9871216,299.9871216,3819.810546875,3875.2177734375,57.115940785756,20.5671500618658,23.668306,0,0,0,40,4449,300.24435,3847.51416015625,,,,,,,,,,,,,0,,,,0,,,,,,299.9871216,,,,
,31473102.46,299.9920959,168.740158081055,2.31961098585346E-5,4.5767380134086E-7,1,0.999253354069792,40.0298881530762,1.99941766542764,18.7899991869926,0.000262633406093323,4.53130535287152E-5,0.25,-1.63642227550474E-8,2.31954350644572E-5,-9.74800087792324E-10,299.9920959,299.9920959,141.344497680664,196.135818481445,57.166746639506,20.5679299584445,23.668306,0,0,0,40,4449,300.2307,168.740158081055,,,,,,,,,,,,,0,,,,-0.00245,,,,,,299.9920959,,,,
,31473177.215,299.9946747,-3561.78015136719,-4.22305103877509E-5,4.83723129966019E-7,1,0.999253354069792,40.0298881530762,1.99944386361748,18.7899991869926,-0.000477605604434695,-8.56545495468204E-5,0.25,-2.49101857183138E-7,-4.2229094309204E-5,-2.77096986628956E-7,299.9942017,299.9951477,-3591.97045898438,-3531.58984375,57.1221938139099,20.5673052873608,23.288654,0,0,0,40,4449,300.25745,-3561.78015136719,,,,,,,,,,,,,0,,,,0.00245,,,,,,299.9946747,,,,
,31473254.18,299.99481205,-7412.3203125,-3.76049515137431E-5,5.45908522388068E-7,1,0.999253354069792,40.0298881530762,1.99935441745894,18.7899991869926,-0.00042377589719558,-8.49203306642267E-5,0.25,-9.86004567923562E-7,-3.76031852759319E-5,-1.01089661198826E-6,299.9945374,299.9950867,-7442.400390625,-7382.240234375,56.9799374234099,20.5695076860923,22.909004,0,0,0,40,4449,300.2518,-7412.3203125,,,,,,,,,,,,,0,,,,0,,,,,,299.99481205,,,,
,31473331.695,299.99977115,-11285.6005859375,-2.83885039878509E-5,7.12785723281071E-7,1,0.999253354069792,40.0298881530762,1.99935994316167,18.7899991869926,-0.000318360591997353,-7.30802030629797E-5,0.25,-1.5369418858822E-6,-2.8386642112001E-5,-1.55569708697249E-6,299.9987183,300.000824,-11315.3837890625,-11255.8173828125,57.1432977839291,20.5719130535959,23.668306,0,0,0,40,4449,300.25255,-11285.6005859375,,,,,,,,,,,,,0,,,,0,,,,,,299.99977115,,,,
,31473410.54,300.0042725,-15229.2280273438,-1.71367029545848E-5,1.15008445504005E-6,1,0.999253354069792,40.0298881530762,1.99930120726609,18.7899991869926,-0.000191713026397805,-4.67670907673553E-5,0.25,-1.1621851349389E-6,-1.71354222684639E-5,-1.17349167542099E-6,300.0042725,300.0042725,-15259.0849609375,-15199.37109375,57.2011382943522,20.570811543342,23.668306,0,0,0,40,4449,300.24655,-15229.2280273438,,,,,,,,,,,,,0,,,,-0.00245,,,,,,300.0042725,,,,
,31473489.955,300.0041809,-19196.34375,-4.01227147030772E-6,8.4368125615973E-7,1,0.999253354069792,40.0298881530762,1.99929676235742,18.7899991869926,-4.20196742167666E-5,-2.74951209529013E-5,0.25,-1.73368251979312E-6,-4.0110054045101E-6,-1.73628418652434E-6,300.0041809,300.0041809,-19201.40625,-19191.28125,57.2284952925253,20.5714541306145,23.668306,0,0,0,40,4449,300.2463,-19196.34375,,,,,,,,,,,,,0,,,,-0.00245,,,,,,300.0041809,,,,
,31473566.635,300.0040283,-23027.083984375,7.80949850514704E-6,1.01837211871065E-6,1,0.999253354069792,40.0298881530762,1.99941486840481,18.7899991869926,9.23381361397146E-5,-7.35093073633931E-6,0.25,-2.00237647911256E-6,7.81058936852327E-6,-1.99715617851338E-6,300.0040283,300.0040283,-23029.501953125,-23024.666015625,57.098744958333,20.5727818341566,23.288654,0,0,0,40,4449,300.23495,-23027.083984375,,,,,,,,,,,,,0,,,,0.0049,,,,,,300.0040283,,,,
,31473642.755,300.0093384,-26832.3857421875,2.10224967803648E-5,1.4545768104504E-6,1,0.999253354069792,40.0298881530762,1.99937548898778,18.7899991869926,0.000243587629167952,8.92074567220416E-6,0.25,-2.85428783889782E-6,2.10237529766966E-5,-2.84032091306706E-6,300.0093384,300.0093384,-26857.732421875,-26807.0390625,56.9658681100637,20.5735666331142,23.668306,0,0,0,40,4449,300.2292,-26832.3857421875,,,,,,,,,,,,,0,,,,0,,,,,,300.0093384,,,,
,31473721.31,300.0057983,-30760.3173828125,3.34373222818675E-5,1.27306194323196E-6,1,0.999253354069792,40.0298881530762,1.99933404313268,18.7899991869926,0.000383766957221399,3.53341996942018E-5,0.25,-2.67195997758752E-6,3.34380913316851E-5,-2.64982013463066E-6,300.0057983,300.0057983,-30765.279296875,-30755.35546875,57.1847240954484,20.5741839490573,23.668306,0,0,0,40,4449,300.23445,-30760.3173828125,,,,,,,,,,,,,0,,,,0.0049,,,,,,300.0057983,,,,
,31473800.915,300.0116272,-34735.04296875,4.80836408325608E-5,1.1880281769469E-6,1,0.999253354069792,40.0298881530762,1.99940684523995,18.7899991869926,0.000546904783814145,7.95568933640633E-5,0.25,-1.30330803404031E-6,4.80830631752974E-5,-1.27157189341199E-6,300.0116272,300.0116272,-34737.4453125,-34732.640625,57.166746639506,20.5752800090842,23.668306,0,0,0,40,4449,300.2238,-34735.04296875,,,,,,,,,,,,,0,,,,0.0049,,,,,,300.0116272,,,,
,31473878.35,300.01190185,-38606.068359375,6.24166610082737E-5,1.2023915455201E-6,1,0.999253354069792,40.0298881530762,1.99945183550726,18.7899991869926,0.00070867373402985,0.000110607048986851,0.25,-1.04402422698821E-6,6.24154860293695E-5,-1.00288186516812E-6,300.0117493,300.0120544,-38635.9921875,-38576.14453125,57.0862389020253,20.5734752058064,23.668306,0,0,0,40,4449,300.21705,-38606.068359375,,,,,,,,,,,,,0,,,,0.00245,,,,,,300.01190185,,,,
,31473957.46,300.0124817,-42561.01953125,7.74947528262219E-5,1.6832697360228E-6,1,0.999253354069792,40.0298881530762,1.99941808153258,18.7899991869926,0.000883512622482854,0.000116213198592671,0.25,-3.16097317451112E-6,7.74945229546079E-5,-3.10988446109731E-6,300.0124817,300.0124817,-42593.328125,-42528.7109375,57.1511140691214,20.5744658614795,22.909004,0,0,0,40,4449,300.2275,-42561.01953125,,,,,,,,,,,,,0,,,,0,,,,,,300.0124817,,,,
,31474038.71,300.0115662,-46621.646484375,9.22150751768686E-5,2.0939680751204E-6,1,0.999253354069792,40.0298881530762,1.99944844983743,18.7899991869926,0.00105503584014378,0.000117035371711808,0.25,-5.63880873722978E-6,9.22160415487003E-5,-5.57801234136085E-6,300.0115662,300.0115662,-46626.74609375,-46616.546875,57.1081245005637,20.5732653314661,23.288654,0,0,0,40,4449,300.2071,-46621.646484375,,,,,,,,,,,,,0,,,,0,,,,,,300.0115662,,,,
,31474116.94,300.0121765,-50531.82421875,0.00010452286603207,2.02331505591056E-6,1,0.999253354069792,40.0298881530762,1.99954689665944,18.7899991869926,0.00118831914353042,0.000176451951705413,0.25,-2.52354683183065E-6,0.000104521420050236,-2.45481200334313E-6,300.0119629,300.0123901,-50564.37109375,-50499.27734375,57.2402197203138,20.5778545551341,22.909004,0,0,0,40,4449,300.19835,-50531.82421875,,,,,,,,,,,,,0,,,,-0.00245,,,,,,300.0121765,,,,
,31474196.08,300.0105896,-54489.328125,0.000120566091356608,1.76315094655744E-6,1,0.999253354069792,40.0298881530762,1.9994877428603,18.7899991869926,0.00136553147406387,0.00023322252072476,0.25,-2.8808797455279E-7,0.000120562713949978,-2.08956186148631E-7,300.0105896,300.0105896,-54516.8046875,-54461.8515625,57.1941036376791,20.5760024853667,23.668306,0,0,0,40,4449,300.19955,-54489.328125,,,,,,,,,,,,,0,,,,0,,,,,,300.0105896,,,,
,31474275.46,300.0105591,-58454.810546875,0.000130597352000638,2.72742142346887E-6,1,0.999253354069792,40.0298881530762,1.99953891626054,18.7899991869926,0.00148135263808154,0.000240102769422741,0.25,-1.41874610517113E-6,0.00013059442611659,-1.33307577305521E-6,300.0105591,300.0105591,-58484.96484375,-58424.65625,57.1690915250637,20.5789073123885,23.288654,0,0,0,40,4449,300.1866,-58454.810546875,,,,,,,,,,,,,0,,,,0,,,,,,300.0105591,,,,
,31474356.285,300.010498,-62492.7109375,0.000145339091368771,2.11379941007175E-6,1,0.999253354069792,40.0298881530762,1.99947240012513,18.7899991869926,0.00165658144815717,0.000220634598468809,0.25,-5.6916348112892E-6,0.000145338536662765,-5.59626397604853E-6,300.010498,300.010498,-62517.76171875,-62467.66015625,57.1432977839291,20.5746368804378,22.909004,0,0,0,40,4449,300.1775,-62492.7109375,,,,,,,,,,,,,0,,,,0,,,,,,300.010498,,,,
,31474435.775,300.0149078,-66465.09375,0.000162490393317702,2.17300799898088E-6,1,0.999253354069792,40.0298881530762,1.99939638315649,18.7899991869926,0.00184774069697105,0.000271277820742786,0.25,-4.18884917306025E-6,0.00016248832968212,-4.08239226978302E-6,300.0148315,300.0149841,-66495.1796875,-66435.0078125,57.1010898438907,20.5776986649779,23.288654,0,0,0,40,4449,300.1773,-66465.09375,,,,,,,,,,,,,0,,,,-0.0049,,,,,,300.0149078,,,,
,31474516.055,300.0174866,-70477.671875,0.000178414650547473,2.27268850132911E-6,1,0.999253354069792,40.0298881530762,1.99932214659889,18.7899991869926,0.00203432570277481,0.000265667240898548,0.25,-7.44239608917255E-6,0.000178414233675988,-7.32552925198419E-6,300.0169373,300.0180359,-70507.53125,-70447.8125,57.1229754424291,20.5785247431554,23.288654,0,0,0,40,4449,300.15465,-70477.671875,,,,,,,,,,,,,0,,,,0,,,,,,300.0174866,,,,
,31474597.03,300.0122986,-74525.3515625,0.000190770154549902,2.71538603169473E-6,1,0.999253354069792,40.0298881530762,1.99941824450209,18.7899991869926,0.00217094989298763,0.000309223495220198,0.25,-5.73654133479759E-6,0.000190768299395365,-5.61177233346725E-6,300.0122986,300.0122986,-74555.3046875,-74495.3984375,56.994006736756,20.5790854139249,22.909004,0,0,0,40,4449,300.1461,-74525.3515625,,,,,,,,,,,,,0,,,,0,,,,,,300.0122986,,,,
,31474677.76,300.01313785,-78560.3828125,0.000206362628489519,1.99457292957103E-6,1,0.999253354069792,40.0298881530762,1.99929311361989,18.7899991869926,0.00234929196382058,0.000328468241546568,0.25,-6.73614006177496E-6,0.000206360969518193,-6.60128964377247E-6,300.0129395,300.0133362,-78592.8203125,-78527.9453125,57.1518956976407,20.5801380562029,22.909004,0,0,0,40,4449,300.1319,-78560.3828125,,,,,,,,,,,,,0,,,,0,,,,,,300.01313785,,,,
,31474759.16,300.0175476,-82628.16796875,0.000220899457798424,2.49193044817409E-6,1,0.999253354069792,40.0298881530762,1.99930125540358,18.7899991869926,0.00251753379099873,0.000335787345077463,0.25,-8.60803939393363E-6,0.000220898566295253,-8.46379943104428E-6,300.017334,300.0177612,-82655.734375,-82600.6015625,57.1010898438907,20.5801763433359,23.288654,0,0,0,40,4449,300.13185,-82628.16796875,,,,,,,,,,,,,0,,,,0,,,,,,300.0175476,,,,
,31474836.805,300.01083375,-86508.31640625,0.000235705383794587,3.04979415172061E-6,1,0.999253354069792,40.0298881530762,1.99944267020546,18.7899991869926,0.00268381493082624,0.000373557462944959,0.25,-7.83873569715143E-6,0.000235703620045568,-7.68501792357055E-6,300.0101013,300.0115662,-86533.28125,-86483.3515625,57.0565370182945,20.5815811964788,23.288654,0,0,0,40,4449,300.11935,-86508.31640625,,,,,,,,,,,,,0,,,,0.00245,,,,,,300.01083375,,,,
,31474927.47,300.0109253,-89743.01171875,0.000246220818893485,2.23675101835898E-6,1,0.999253354069792,40.0298881530762,1.99937786455419,18.7899991869926,0.00280079980889589,0.000405567495501693,0.25,-6.83179896184379E-6,0.000246218100168938,-6.67139433393652E-6,300.0109253,300.0109253,-89777.4296875,-89708.59375,57.1010898438907,20.5804157171458,23.288654,0,0,0,40,4449,300.11095,-89743.01171875,,,,,,,,,,,,,0,,,,0,,,,,,300.0109253,,,,
,31475003.89,300.0035095,-85929.9765625,0.000232149151465195,2.90713146276237E-6,1,0.999253354069792,40.0298881530762,1.99935450422936,18.7899991869926,0.00263887445441484,0.000392942761087615,0.25,-5.50888427034195E-6,0.000232146033523658,-5.3575249871551E-6,300.0035095,300.0035095,-85939.9765625,-85919.9765625,57.0135474497368,20.5824131810774,23.288654,0,0,0,40,4449,300.1131,-85929.9765625,,,,,,,,,,,,,0,,,,0.00245,,,,,,300.0035095,,,,
,31475081.055,300.0038757,-82072.30078125,0.000216248509125898,2.69605203710518E-6,1,0.999253354069792,40.0298881530762,1.99934757908634,18.7899991869926,0.00246635078973222,0.000318525835918744,0.25,-9.32776621515629E-6,0.000216248328363302,-9.18650792773367E-6,300.0038757,300.0038757,-82097.1796875,-82047.421875,57.1339182416984,20.5788331314098,23.288654,0,0,0,40,4449,300.10845,-82072.30078125,,,,,,,,,,,,,0,,,,0.00245,,,,,,300.0038757,,,,
,31475160.975,299.9948425,-78076.3828125,0.000204794854720067,2.56023386304519E-6,1,0.999253354069792,40.0298881530762,1.99940719606537,18.7899991869926,0.00233728138446441,0.000293038477643164,0.25,-9.59574723477102E-6,0.000204795240878535,-9.46180914294367E-6,299.9948425,299.9948425,-78108.875,-78043.890625,57.2730481181214,20.5801858600018,23.288654,0,0,0,40,4449,300.1006,-78076.3828125,,,,,,,,,,,,,0,,,,0,,,,,,299.9948425,,,,
,31475240.94,299.99191285,-74083.7265625,0.000186760608696771,2.23562054259969E-6,1,0.999253354069792,40.0298881530762,1.99941418849545,18.7899991869926,0.00212734247965226,0.000291044357192227,0.25,-6.64767888427761E-6,0.000186759601909845,-6.52548322087436E-6,299.9918518,299.9919739,-74116.1171875,-74051.3359375,57.017455592333,20.5803405073614,23.288654,0,0,0,40,4449,300.1256,-74083.7265625,,,,,,,,,,,,,0,,,,-0.00245,,,,,,299.99191285,,,,
,31475320.705,299.9848022,-70096.2421875,0.00017370104145103,2.17597421288598E-6,1,0.999253354069792,40.0298881530762,1.99936490432394,18.7899991869926,0.00197848164746717,0.000271012557443014,0.25,-6.15411377229891E-6,0.000173700124862297,-6.04035593007802E-6,299.9848022,299.9848022,-70123.5625,-70068.921875,57.1440794124484,20.5814382496143,23.668306,0,0,0,40,4449,300.1388,-70096.2421875,,,,,,,,,,,,,0,,,,0.00245,,,,,,299.9848022,,,,
,31475399.935,299.9908447,-66136.1171875,0.000161493893739937,2.06800449624807E-6,1,0.999253354069792,40.0298881530762,1.99926515258066,18.7899991869926,0.00184166522416574,0.000238604570946539,0.25,-6.90104204890672E-6,0.000161493773118663,-6.79514339493265E-6,299.9908447,299.9908447,-66166.046875,-66106.1875,57.2574155477368,20.5796269804817,23.288654,0,0,0,40,4449,300.15105,-66136.1171875,,,,,,,,,,,,,0,,,,0,,,,,,299.9908447,,,,
,31475480.115,299.98776245,-62130.884765625,0.00014363758956053,2.08929710885333E-6,1,0.999253354069792,40.0298881530762,1.99927812609279,18.7899991869926,0.00163594827535479,0.000224316686637484,0.25,-5.06980974949069E-6,0.00014363679385522,-4.97555470605299E-6,299.986908,299.9886169,-62158.09765625,-62103.671875,57.2292769210445,20.5799563046346,23.288654,0,0,0,40,4449,300.14285,-62130.884765625,,,,,,,,,,,,,0,,,,0,,,,,,299.98776245,,,,
,31475560.565,299.9853821,-58108.36328125,0.00013243478434889,1.97098686876552E-6,1,0.999253354069792,40.0298881530762,1.99932067442989,18.7899991869926,0.00150653986354957,0.000217478989949677,0.25,-3.73340308611263E-6,0.000132433440693141,-3.6464474589621E-6,299.9853821,299.9853821,-58110.80859375,-58105.91796875,57.1167224142753,20.5790149665283,23.288654,0,0,0,40,4449,300.16255,-58108.36328125,,,,,,,,,,,,,0,,,,0,,,,,,299.9853821,,,,
,31475642.13,299.9867554,-54033.078125,0.000114979107827397,2.07451805494951E-6,1,0.999253354069792,40.0298881530762,1.99923080153442,18.7899991869926,0.00130878303588889,0.000183783576837772,0.25,-3.68505852101117E-6,0.000114978222540893,-3.60947999107068E-6,299.9863892,299.9871216,-54063.3671875,-54002.7890625,57.0338697912368,20.5805622593034,23.668306,0,0,0,40,4449,300.17385,-54033.078125,,,,,,,,,,,,,0,,,,0,,,,,,299.9867554,,,,
,31475724.61,299.9853821,-49910.552734375,0.000100795014194986,2.03714977378193E-6,1,0.999253354069792,40.0298881530762,1.99930769164317,18.7899991869926,0.00114664210364872,0.00016532231807184,0.25,-2.8590881119682E-6,0.000100793995396985,-2.79277929012417E-6,299.9853821,299.9853821,-49945.375,-49875.73046875,57.0760777312753,20.5851667315881,23.288654,0,0,0,40,4449,300.17625,-49910.552734375,,,,,,,,,,,,,0,,,,0,,,,,,299.9853821,,,,
,31475806.965,299.98924255,-45795.384765625,8.63784168702303E-5,1.60068804160126E-6,1,0.999253354069792,40.0298881530762,1.99917590132095,18.7899991869926,0.000987983460049912,0.000110463238449578,0.25,-5.2068610501121E-6,8.63793415210578E-5,-5.14990223853954E-6,299.9891357,299.9893494,-45822.9921875,-45767.77734375,57.1073428720445,20.580726080104,23.288654,0,0,0,40,4449,300.18105,-45795.384765625,,,,,,,,,,,,,0,,,,-0.00245,,,,,,299.98924255,,,,
,31475888.735,299.9905701,-41707.822265625,7.8206073067393E-5,1.2122661496312E-6,1,0.999253354069792,40.0298881530762,1.99935696011799,18.7899991869926,0.000898737100465817,7.60651228180325E-5,0.25,-6.83039788001008E-6,7.8208298138196E-5,-6.77871944819715E-6,299.9905701,299.9905701,-41739.796875,-41675.84765625,57.281646031833,20.588993636357,23.668306,0,0,0,40,4449,300.19075,-41707.822265625,,,,,,,,,,,,,0,,,,0,,,,,,299.9905701,,,,
,31475973.11,299.9848938,-37489.96484375,5.77867249683219E-5,1.57717523175056E-6,1,0.999253354069792,40.0298881530762,1.99919353096682,18.7899991869926,0.000663508424716726,5.92000963897872E-5,0.25,-4.78204176255504E-6,5.77882062109318E-5,-4.74382927137966E-6,299.9848938,299.9848938,-37492.2734375,-37487.65625,57.0534105042176,20.580779044885,22.909004,0,0,0,40,4449,300.1964,-37489.96484375,,,,,,,,,,,,,0,,,,-0.0049,,,,,,299.9848938,,,,
,31476054.195,299.9902649,-33439.97265625,4.42825007420193E-5,1.30530237843996E-6,1,0.999253354069792,40.0298881530762,1.99915700598587,18.7899991869926,0.000505593264823463,6.18167476380038E-5,0.25,-2.21113351231647E-6,4.4282668666581E-5,-2.18186673068005E-6,299.9902649,299.9902649,-33470.10546875,-33409.83984375,57.1323549846599,20.5813929052911,23.668306,0,0,0,40,4449,300.2014,-33439.97265625,,,,,,,,,,,,,0,,,,0,,,,,,299.9902649,,,,
,31476136.17,299.9910736,-29342.064453125,3.02690131181258E-5,1.43754384090948E-6,1,0.999253354069792,40.0298881530762,1.99915519029312,18.7899991869926,0.000346199291982865,3.87644990221127E-5,0.25,-1.81973076183932E-6,3.02693298465748E-5,-1.7996994929449E-6,299.9906006,299.9915466,-29367.173828125,-29316.955078125,57.0878021590637,20.581720826253,22.909004,0,0,0,40,4449,300.2104,-29342.064453125,,,,,,,,,,,,,0,,,,0,,,,,,299.9910736,,,,
,31476219.155,299.9827271,-25194.2509765625,1.41593372710744E-5,1.05643890399325E-6,1,0.999253354069792,40.0298881530762,1.99909969847815,18.7899991869926,0.000162814190154659,1.30987441210549E-5,0.25,-1.2959923152366E-6,1.41597832359123E-5,-1.28660162482037E-6,299.9827271,299.9827271,-25199.048828125,-25189.453125,57.1722180391407,20.5815187964419,23.288654,0,0,0,40,4449,300.2226,-25194.2509765625,,,,,,,,,,,,,0,,,,-0.00245,,,,,,299.9827271,,,,
,31476301.895,299.9894104,-21059.375,7.69828090534076E-7,9.92683648139784E-7,1,0.999253354069792,40.0298881530762,1.99908992740536,18.7899991869926,1.28129659104038E-5,-2.21495971862329E-5,0.25,-2.09020250339919E-6,7.71187483148512E-7,-2.08963238785086E-6,299.9894104,299.9894104,-21061.833984375,-21056.916015625,57.014329078256,20.5798301914402,23.288654,0,0,0,40,4449,300.2159,-21059.375,,,,,,,,,,,,,0,,,,0,,,,,,299.9894104,,,,
,31476384.005,299.9863434,-16953.8916015625,-1.25496885876712E-5,9.84135035612019E-7,1,0.999253354069792,40.0298881530762,1.99904840733335,18.7899991869926,-0.000138578896786326,-4.46401417045233E-5,0.25,-1.76951111209186E-6,-1.25481515165034E-5,-1.7777626217144E-6,299.9853821,299.9873047,-16983.984375,-16923.798828125,57.1034347294484,20.5799850456525,23.668306,0,0,0,40,4449,300.23505,-16953.8916015625,,,,,,,,,,,,,0,,,,-0.00245,,,,,,299.9863434,,,,
,31476467.63,299.9933319,-12773.5815429688,-2.43462846376653E-5,8.95736466300539E-7,1,0.999253354069792,40.0298881530762,1.99906642245065,18.7899991869926,-0.000272554724464936,-6.51851976950267E-5,0.25,-1.54069935854464E-6,-2.43445465426222E-5,-1.55677477159905E-6,299.9930115,299.9936523,-12801.0791015625,-12746.083984375,56.9713395096983,20.581991894343,23.288654,0,0,0,40,4449,300.2321,-12773.5815429688,,,,,,,,,,,,,0,,,,0,,,,,,299.9933319,,,,
,31476547.105,299.99298095,-8802.640625,-3.50319835448339E-5,6.98120234551572E-7,1,0.999253354069792,40.0298881530762,1.99905978268753,18.7899991869926,-0.000393639513543622,-8.53653970180442E-5,0.25,-1.47217347929903E-6,-3.50299740239556E-5,-1.49534260579917E-6,299.9926147,299.9933472,-8837.7265625,-8767.5546875,57.1339182416984,20.5807367113082,22.909004,0,0,0,40,4449,300.2316,-8802.640625,,,,,,,,,,,,,0,,,,0,,,,,,299.99298095,,,,
,31476626.82,299.9901123,-4819.65112304687,-4.29825278443742E-5,4.34484913815666E-7,1,0.999253354069792,40.0298881530762,1.99903199081026,18.7899991869926,-0.000485926577419013,-8.76734541390375E-5,0.25,-2.9866499229606E-7,-4.29810641004756E-5,-3.27152929644934E-7,299.9899597,299.9902649,-4849.619140625,-4789.68310546875,56.9885353371214,20.5821726962351,22.909004,0,0,0,40,4449,300.2505,-4819.65112304687,,,,,,,,,,,,,0,,,,0.00245,,,,,,299.9901123,,,,
,31476706.335,299.9869537,-842.826690673828,-3.62943501067792E-5,3.76264913792243E-7,1,0.999253354069792,40.0298881530762,1.99911595035186,18.7899991869926,-0.000409913409444819,-7.64490042506024E-5,0.25,-4.65511874236547E-7,-3.62929756011032E-5,-4.89572579031574E-7,299.9865417,299.9873657,-875.133972167969,-810.519409179688,57.0721695886791,20.5835172065323,23.668306,0,0,0,40,4449,300.2599,-842.826690673828,,,,,,,,,,,,,0,,,,-0.00245,,,,,,299.9869537,,,,
,31476783.74,299.99243165,3017.65295410156,4.22776003907013E-5,4.89496805818637E-7,1,0.999253354069792,40.0298881530762,1.9990004727077,18.7899991869926,0.000478102242243309,8.53555013827824E-5,0.25,2.16121865487369E-7,4.2276208075832E-5,2.44150440452847E-7,299.9920654,299.9927979,2987.490234375,3047.81567382812,57.0776409883137,20.5808458185575,23.668306,0,0,0,40,4449,300.2655,3017.65295410156,,,,,,,,,,,,,0,,,,0,,,,,,299.99243165,,,,
,31476866.025,299.9957275,7135.02978515625,3.94642308137823E-5,4.9395398228025E-7,1,0.999253354069792,40.0298881530762,1.99904088219532,18.7899991869926,0.000446368555544752,7.92549556706484E-5,0.25,1.64465531450791E-7,3.94629526567857E-5,1.90614521943091E-7,299.9957275,299.9957275,7127.5986328125,7142.4609375,57.0838940164676,20.5796536199997,23.288654,0,0,0,40,4449,300.2586,7135.02978515625,,,,,,,,,,,,,0,,,,0,,,,,,299.9957275,,,,
,31476945.805,300.0063477,11121.4814453125,2.9830793236555E-5,7.93971749064209E-7,1,0.999253354069792,40.0298881530762,1.99894578522399,18.7899991869926,0.000336190776989833,6.68392358945966E-5,0.25,7.36928052953974E-7,2.98294111837806E-5,7.56662708983084E-7,300.0063477,300.0063477,11091.72265625,11151.240234375,57.1722180391407,20.5803066085338,23.288654,0,0,0,40,4449,300.2514,11121.4814453125,,,,,,,,,,,,,0,,,,0,,,,,,300.0063477,,,,
,31477028.065,300.00140385,15234.4428710938,1.7605935563574E-5,1.02947390738246E-6,1,0.999253354069792,40.0298881530762,1.99896481225707,18.7899991869926,0.000197458519702589,4.49944203624414E-5,0.25,9.24932513429044E-7,1.76047997419674E-5,9.36556487548154E-7,300.0011292,300.0016785,15204.794921875,15264.0908203125,57.0666981890445,20.5805051346708,22.909004,0,0,0,40,4449,300.2526,15234.4428710938,,,,,,,,,,,,,0,,,,0,,,,,,300.00140385,,,,
,31477111.725,300.0090637,19414.1875,4.06136313079254E-6,1.05200475706871E-6,1,0.999253354069792,40.0298881530762,1.99889955480439,18.7899991869926,4.49595895006689E-5,1.37786373147519E-5,0.25,5.13733427964348E-7,4.06090168965552E-6,5.1640363372027E-7,300.0088806,300.0092468,19381.900390625,19446.474609375,57.0377779338329,20.5812877898544,22.909004,0,0,0,40,4449,300.25375,19414.1875,,,,,,,,,,,,,0,,,,-0.00735,,,,,,300.0090637,,,,
,31477193.875,300.0046387,23522.5302734375,-7.74232021604346E-6,8.3667513106368E-7,1,0.999253354069792,40.0298881530762,1.99887363673849,18.7899991869926,-9.11915189079303E-5,5.38885232526402E-6,0.25,1.81754519823834E-6,-7.74329068783125E-6,1.8123753082636E-6,300.004303,300.0049744,23489.8125,23555.248046875,57.0112025641791,20.5802618920065,24.047956,0,0,0,40,4449,300.23635,23522.5302734375,,,,,,,,,,,,,0,,,,0.00245,,,,,,300.0046387,,,,
,31477274.085,300.01226805,27530.6953125,-2.37869575935795E-5,1.22817306901902E-6,1,0.999253354069792,40.0298881530762,1.99897511796074,18.7899991869926,-0.000273103626059858,-2.43084070538806E-5,0.25,1.9735858663085E-6,-2.37875471029374E-5,1.95782206360298E-6,300.012207,300.0123291,27498.126953125,27563.263671875,56.9799374234099,20.5864620912418,23.288654,0,0,0,40,4449,300.2308,27530.6953125,,,,,,,,,,,,,0,,,,0,,,,,,300.01226805,,,,
,31477353.955,300.0067444,31521.7392578125,-3.64402476578196E-5,1.50993641255991E-6,1,0.999253354069792,40.0298881530762,1.9988521184751,18.7899991869926,-0.000413632607845268,-6.44908831606376E-5,0.25,6.15349826923052E-7,-3.6439569646584E-5,5.91293821909493E-7,300.0067444,300.0067444,31491.73828125,31551.740234375,57.1175040427945,20.5785316289383,23.288654,0,0,0,40,4449,300.23405,31521.7392578125,,,,,,,,,,,,,0,,,,0.00245,,,,,,300.0067444,,,,
,31477433.105,300.008255,35476.810546875,-4.99227402920469E-5,1.41411877247846E-6,1,0.999253354069792,40.0298881530762,1.99881904561166,18.7899991869926,-0.000570378022787758,-6.69090485454936E-5,0.25,2.73749436453857E-6,-4.99230593498146E-5,2.70450892975908E-6,300.006958,300.009552,35449.24609375,35504.375,57.1323549846599,20.5800993767503,22.909004,0,0,0,40,4449,300.225,35476.810546875,,,,,,,,,,,,,0,,,,0.00245,,,,,,300.008255,,,,
,31477512.84,300.0115204,39464.294921875,-6.31291117555575E-5,1.64024514075841E-6,1,0.999253354069792,40.0298881530762,1.99881854986696,18.7899991869926,-0.000719489934489261,-9.48451015458677E-5,0.25,2.55718032907805E-6,-6.31289134453072E-5,2.51553204378366E-6,300.0110779,300.0119629,39432.14453125,39496.4453125,57.075296102756,20.5785935977829,23.668306,0,0,0,40,4449,300.2193,39464.294921875,,,,,,,,,,,,,0,,,,0.00245,,,,,,300.0115204,,,,
,31477593.955,300.01655575,43517.484375,-7.87603355164721E-5,2.04512441291978E-6,1,0.999253354069792,40.0298881530762,1.9988149728712,18.7899991869926,-0.000897884407966232,-0.000116913716982305,0.25,3.31537786175772E-6,-7.87601584717643E-5,3.26346130538639E-6,300.0160522,300.0170593,43485.140625,43549.828125,57.078422616833,20.577153841214,23.288654,0,0,0,40,4449,300.22055,43517.484375,,,,,,,,,,,,,0,,,,0,,,,,,300.01655575,,,,
,31477674.585,300.00979615,47548.337890625,-9.12749412625049E-5,2.31331107633709E-6,1,0.999253354069792,40.0298881530762,1.99874235860975,18.7899991869926,-0.00103250663817547,-0.000181725240839092,0.25,-2.43594565317694E-7,-9.12720749734339E-5,-3.03586023656774E-7,300.0093079,300.0102844,47518.1171875,47578.55859375,56.9275683126214,20.5772290002996,23.288654,0,0,0,40,4449,300.20275,47548.337890625,,,,,,,,,,,,,0,,,,0,,,,,,300.00979615,,,,
,31477753.365,300.0121765,51484.09375,-0.000105762086409486,2.32350551412778E-6,1,0.999253354069792,40.0298881530762,1.9987613601719,18.7899991869926,-0.00120213120712498,-0.000177471859823195,0.25,2.64226727393693E-6,-0.000105760682575865,2.57272984953015E-6,300.0121765,300.0121765,51451.53125,51516.65625,57.0620084179291,20.5771048130748,22.909004,0,0,0,40,4449,300.1954,51484.09375,,,,,,,,,,,,,0,,,,0,,,,,,300.0121765,,,,
,31477834.22,300.00891115,55524.16015625,-0.000120771725679539,2.2498561748964E-6,1,0.999253354069792,40.0298881530762,1.99874451719212,18.7899991869926,-0.00137303987580174,-0.000200842471564436,0.25,3.17750007279298E-6,-0.000120770246798763,3.0981657170668E-6,300.0088501,300.0089722,55493.70703125,55554.61328125,56.8494054606983,20.58045623602,22.909004,0,0,0,40,4449,300.1926,55524.16015625,,,,,,,,,,,,,0,,,,0,,,,,,300.00891115,,,,
,31477916.05,300.0150604,59614.919921875,-0.000135843915498961,2.58286201716048E-6,1,0.999253354069792,40.0298881530762,1.99884137661231,18.7899991869926,-0.00154738530289788,-0.000209062047873963,0.25,5.06327646750647E-6,-0.000135843203538836,4.97408102703366E-6,300.0142517,300.0158691,59582.4921875,59647.34765625,56.9986965078714,20.5801127059205,22.909004,0,0,0,40,4449,300.1808,59614.919921875,,,,,,,,,,,,,0,,,,0,,,,,,300.0150604,,,,
,31477998.92,300.0128479,63758.220703125,-0.00014959089765452,2.75904739574317E-6,1,0.999253354069792,40.0298881530762,1.99861497429322,18.7899991869926,-0.00170517338403401,-0.000222219711163028,0.25,6.28018933986052E-6,-0.000149590591830713,6.18204281768908E-6,300.0128479,300.0128479,63725.83984375,63790.6015625,56.9197520274291,20.5788682833636,22.909004,0,0,0,40,4449,300.16835,63758.220703125,,,,,,,,,,,,,0,,,,0,,,,,,300.0128479,,,,
,31478081.88,300.0094299,67904.54296875,-0.00016459408302343,3.8968048652839E-6,1,0.999253354069792,40.0298881530762,1.998596626582,18.7899991869926,-0.00187018379568473,-0.000279099037084124,0.25,3.8530017173945E-6,-0.000164591772034254,3.7452131178907E-6,300.0094299,300.0094299,67870.0703125,67939.015625,56.994006736756,20.5778173263037,22.909004,0,0,0,40,4449,300.16635,67904.54296875,,,,,,,,,,,,,0,,,,-0.00245,,,,,,300.0094299,,,,
,31478165.345,300.01528935,72077.02734375,-0.000180271980488596,2.39713704041989E-6,1,0.999253354069792,40.0298881530762,1.99856778010322,18.7899991869926,-0.00205377759643772,-0.00027402683638775,0.25,7.01696062093238E-6,-0.000180271247130419,6.89894139276548E-6,300.0148621,300.0157166,72041.9609375,72112.09375,56.9002113144483,20.5788524225922,22.909004,0,0,0,40,4449,300.1567,72077.02734375,,,,,,,,,,,,,0,,,,0,,,,,,300.01528935,,,,
,31478246.685,300.01283265,76143.359375,-0.000194217657712771,3.04420181671435E-6,1,0.999253354069792,40.0298881530762,1.9985986166749,18.7899991869926,-0.00220520021851812,-0.00033845412782294,0.25,3.74007283443369E-6,-0.000194214397151932,3.61316169612545E-6,300.0123291,300.0133362,76110.65625,76176.0625,57.0713879601599,20.5789804664885,23.668306,0,0,0,40,4449,300.14305,76143.359375,,,,,,,,,,,,,0,,,,0,,,,,,300.01283265,,,,
,31478326.485,300.0102844,80131.2265625,-0.000208173541102167,2.92218543950442E-6,1,0.999253354069792,40.0298881530762,1.99859229561969,18.7899991869926,-0.00236217917862777,-0.000371276369896415,0.25,3.2573008298773E-6,-0.000208169584805927,3.12143192366113E-6,300.0102844,300.0102844,80128.5546875,80133.8984375,56.9478906541214,20.578429755342,23.288654,0,0,0,40,4449,300.14265,80131.2265625,,,,,,,,,,,,,0,,,,0,,,,,,300.0102844,,,,
,31478406.145,300.0114136,84112.5546875,-0.000223175860969148,2.82765872312986E-6,1,0.999253354069792,40.0298881530762,1.99862323771273,18.7899991869926,-0.00254006403386776,-0.000354092222666503,0.25,7.37525302008442E-6,-0.000223174151210759,7.22962370877417E-6,300.0114136,300.0114136,84082.3515625,84142.7578125,56.7634263235829,20.5786242000051,22.909004,0,0,0,40,4449,300.13225,84112.5546875,,,,,,,,,,,,,0,,,,0,,,,,,300.0114136,,,,
,31478481.85,300.01397705,87898.59765625,-0.000243153036032735,3.30665221220482E-6,1,0.999253354069792,40.0298881530762,1.99857763231665,18.7899991869926,-0.00276668525449709,-0.000389748029215787,0.25,7.68461030784154E-6,-0.000243150931086098,7.52611057010131E-6,300.013916,300.0140381,87866.046875,87931.1484375,56.9650864815445,20.5779615300138,23.668306,0,0,0,40,4449,300.1297,87898.59765625,,,,,,,,,,,,,0,,,,0,,,,,,300.01397705,,,,
,31478524.14,300.0166626,89999.5859375,-0.000245726978709338,3.38548678022782E-6,1,0.999253354069792,40.0298881530762,1.99859648265175,18.7899991869926,-0.00279038351195679,-0.000426281727294596,0.25,4.90240965276896E-6,-0.000245722969469671,4.74239811984845E-6,300.0166626,300.0166626,89999.5703125,89999.6015625,56.9291315696599,20.5769409556748,22.909004,0,0,0,40,4417,300.1203,89999.5859375,,,,,,,,,,,,,0,,,,0,,,,,,300.0166626,,,,