File: data/doubleLayers/dl_0-25/ppms/data/DD205_10_HYST_100OE_50K.DAT
[Header]
; VSM Data File (default extension .dat)
; Copyright (c) 2003-2013, Quantum Design, Inc. All rights reserved.
TITLE,
FILEOPENTIME,31564105.66,01/01/2019,3:50 pm
BYAPP,VSM,2.0,2.0
INFO,PPMS VSM Option Release 1.4.10 Build 1,APPNAME
INFO,Quantum Design Linear Motor Servo Controller,MOTOR_MODULE_NAME
INFO,3101-100 M1,MOTOR_HW_VERSION
INFO,MMC1014,MOTOR_SERIAL_NUMBER
INFO,SRV No X-over 01.03.11,MOTOR_SOFTWARE_VERSION
INFO,Quantum Design VSM Detection Module,VSM_MODULE_NAME
INFO,3101-150 F0,VSM_HW_VERSION
INFO,VSM707,VSM_SERIAL_NUMBER
INFO,VSM No X-over 01.02.05 May 20 2008 13:51:47,VSM_SOFTWARE_VERSION
INFO,704,PREAMP_SERIAL_NUMBER
INFO,822,COIL_SERIAL_NUMBER
INFO,0,MOMENT_UNITS
INFO,CoFe2O4,SAMPLE_MATERIAL
INFO,Double Layer thin concentration,SAMPLE_COMMENT
INFO,27.44,SAMPLE_MASS
INFO,,SAMPLE_VOLUME
INFO,,SAMPLE_MOLECULAR_WEIGHT
INFO,,SAMPLE_SIZE
INFO,,SAMPLE_SHAPE
DATATYPE,COMMENT,1
DATATYPE,TIME,2
STARTUPAXIS,X,2
STARTUPAXIS,Y1,5
[Data]
Comment,Time Stamp (sec),Temperature (K),Magnetic Field (Oe),Moment (emu),M. Std. Err. (emu),Transport Action,Averaging Time (sec),Frequency (Hz),Peak Amplitude (mm),Center Position (mm),Coil Signal' (mV),Coil Signal" (mV),Range (mV),M. Quad. Signal (emu),M. Raw' (emu),M. Raw" (emu),Min. Temperature (K),Max. Temperature (K),Min. Field (Oe),Max. Field (Oe),Mass (grams),Motor Lag (deg),Pressure (Torr),VSM Status (code),Motor Status (code),Measure Status (code),Measure Count,PPMS Status (code),System Temp. (K),System Field (Oe),Sample Position (deg),Bridge 1 Resistance (ohms),Bridge 1 Excitation (에),Bridge 2 Resistance (ohms),Bridge 2 Excitation (에),Bridge 3 Resistance (ohms),Bridge 3 Excitation (에),Bridge 4 Resistance (ohms),Bridge 4 Excitation (에),Signal 1 Vin (V),Signal 2 Vin (V),Digital Inputs (code),Drive 1 Iout (mA),Drive 1 Ipower (W),Drive 2 Iout (mA),Drive 2 Ipower (W),Pressure (),Map 20 (),Map 21 (),Map 22 (),Map 23 (),Map 24 (),Map 25 (),Map 26 (),Map 27 (),Map 28 (),Map 29 ()
,31564120.69,49.9998436,-0.0608950927853584,,,2,,,,20.2799996295571,,,,,,,49.9998436,49.9998436,-0.0608950927853584,-0.0608950927853584,,,16.454937,,,,-99999999,4369,50.0366,-0.0608950927853584,,,,,,,,,,,,,,,,,,,,,,,49.9998436,,,,
,31564266.11,49.9998322,4693.16430664063,5.3737982791815E-5,3.33371897654369E-7,1,0.999253354069792,40.0298881530762,1.98381834241897,20.2300008386374,0.000603672257614512,0.000104529142671368,0.25,-3.69846327337001E-7,5.37213320879764E-5,3.0186630715329E-8,49.9997025,49.9999619,4660.77587890625,4725.552734375,56.4648442292367,20.6286800271629,16.834587,0,0,0,40,4449,50.0324,4693.16430664063,,,,,,,,,,,,,0,,,,0,,,,,,49.9998322,,,,
,31564363.765,50.00123595,9572.09033203125,3.97368088965254E-5,5.63071326627346E-7,1,0.999253354069792,40.0298881530762,1.9839060354836,20.2300008386374,0.000448052491589497,6.87888515744801E-5,0.25,-1.03314824784203E-6,3.97397767643309E-5,-7.37432380480994E-7,50.0011787,50.0012932,9542.158203125,9602.0224609375,56.4585912010829,20.6331987153442,17.214239,0,0,0,40,4449,50.0342,9572.09033203125,,,,,,,,,,,,,0,,,,0,,,,,,50.00123595,,,,
,31564459.69,49.9998131,14367.736328125,2.61277806919517E-5,5.70217701634327E-7,1,0.999253354069792,40.0298881530762,1.98400464737963,20.2300008386374,0.000296830326981993,3.33831272755036E-5,0.25,-1.7354660727221E-6,2.61442126234567E-5,-1.54164353250671E-6,49.9998131,49.9998131,14360.1943359375,14375.2783203125,56.6203883045637,20.6338645492968,16.454937,0,0,0,40,4449,50.03175,14367.736328125,,,,,,,,,,,,,0,,,,0.0049,,,,,,49.9998131,,,,
,31564554.985,50.0006332,19126.7998046875,1.35416928831088E-5,5.79150340465511E-7,1,0.999253354069792,40.0298881530762,1.98392765383431,20.2300008386374,0.000155659116527263,7.41979006737192E-6,0.25,-1.77957643352448E-6,1.35602443069312E-5,-1.67998793313778E-6,50.0006332,50.0006332,19121.818359375,19131.78125,56.9400743689291,20.6351009843099,16.834587,0,0,0,40,4449,50.0342,19126.7998046875,,,,,,,,,,,,,0,,,,-0.0049,,,,,,50.0006332,,,,
,31564647.275,50.0020561,23739.732421875,-7.78222665958174E-7,7.58822168988205E-7,1,0.999253354069792,40.0298881530762,1.98404320698431,20.2300008386374,-2.6685247485735E-6,-3.52793835153484E-5,0.25,-3.00063526730806E-6,-7.56593304835775E-7,-3.00832903832284E-6,50.0019798,50.0021324,23709.791015625,23769.673828125,57.7295191733523,20.6333146605597,17.214239,0,0,0,40,4449,50.0334,23739.732421875,,,,,,,,,,,,,0,,,,0,,,,,,50.0020561,,,,
,31564742.455,50.0021629,28500.4384765625,-1.41200012212719E-5,8.76742187810632E-7,1,0.999253354069792,40.0298881530762,1.9840121200411,20.2300008386374,-0.00015455933694714,-5.12403719201269E-5,0.25,-2.01716082288599E-6,-1.41180689972433E-5,-2.12260831225876E-6,50.0021629,50.0021629,28467.87109375,28533.005859375,57.0440309619868,20.6340371122808,17.214239,0,0,0,40,4449,50.03095,28500.4384765625,,,,,,,,,,,,,0,,,,0.00245,,,,,,50.0021629,,,,
,31564837.63,50.001112,33257.859375,-2.89398905223252E-5,7.77801937872417E-7,1,0.999253354069792,40.0298881530762,1.98402535783023,20.2300008386374,-0.000320801040774386,-8.3191718824516E-5,0.25,-2.19089696455717E-6,-2.89577043199288E-5,-2.40442295025058E-6,50.0005646,50.0016594,33230.26171875,33285.45703125,57.0995265868522,20.6360193871145,17.214239,0,0,0,40,4449,50.025,33257.859375,,,,,,,,,,,,,0,,,,0.00245,,,,,,50.001112,,,,
,31564935.165,50.0018692,38130.40625,-4.31229602939642E-5,9.64235771964546E-7,1,0.999253354069792,40.0298881530762,1.9840837638824,20.2300008386374,-0.000478698201563006,-0.000121009778849864,0.25,-3.00131553040782E-6,-4.31627225685161E-5,-3.31746540771579E-6,50.0017967,50.0019417,38097.71484375,38163.09765625,57.139389641333,20.6342953839257,16.834587,0,0,0,40,4449,50.0247,38130.40625,,,,,,,,,,,,,0,,,,0.00245,,,,,,50.0018692,,,,
,31565032.305,50.0023613,42987.94921875,-5.92882498820912E-5,1.05024469623304E-6,1,0.999253354069792,40.0298881530762,1.98412886881908,20.2300008386374,-0.000661779114859622,-0.000147238392256116,0.25,-2.42475821950572E-6,-5.93702834430415E-5,-2.85371585338531E-6,50.0023613,50.0023613,42985.5703125,42990.328125,57.0838940164676,20.634227931684,17.214239,0,0,0,40,4449,50.0298,42987.94921875,,,,,,,,,,,,,0,,,,-0.0049,,,,,,50.0023613,,,,
,31565127.295,50.002573,47733.361328125,-7.38718392438776E-5,1.34960640765573E-6,1,0.999253354069792,40.0298881530762,1.98400877081281,20.2300008386374,-0.000825959104047418,-0.000176545640032877,0.25,-2.40916548950692E-6,-7.39960008118824E-5,-2.9380006422726E-6,50.0024452,50.0027008,47703.42578125,47763.296875,57.034651419756,20.6354898016412,17.214239,0,0,0,40,4449,50.02315,47733.361328125,,,,,,,,,,,,,0,,,,-0.0049,,,,,,50.002573,,,,
,31565223.045,50.0021439,52518.58984375,-8.88886937516738E-5,1.18428792214596E-6,1,0.999253354069792,40.0298881530762,1.98403296060591,20.2300008386374,-0.000989814812141245,-0.000236341175470707,0.25,-5.02636576447371E-6,-8.90438340058627E-5,-5.66110371354465E-6,50.0021439,50.0021439,52516.19140625,52520.98828125,57.3996719382368,20.6371396115547,17.593889,0,0,0,40,4449,50.0205,52518.58984375,,,,,,,,,,,,,0,,,,-0.00245,,,,,,50.0021439,,,,
,31565321.75,50.0024643,57453.640625,-0.000106615579575608,1.09750862065417E-6,1,0.999253354069792,40.0298881530762,1.98383725769625,20.2300008386374,-0.00118924970617361,-0.000273082511526491,0.25,-5.11090226545513E-6,-0.000106832879433297,-5.86240703194989E-6,50.0024643,50.0024643,57418.09375,57489.1875,57.3691884259868,20.6375759616019,16.834587,0,0,0,40,4449,50.0187,57453.640625,,,,,,,,,,,,,0,,,,-0.00245,,,,,,50.0024643,,,,
,31565418.185,50.00227735,62273.384765625,-0.000124236083785416,9.74722710704394E-7,1,0.999253354069792,40.0298881530762,1.98390944357989,20.2300008386374,-0.00138613056550587,-0.00031839209663085,0.25,-5.97518907535176E-6,-0.000124516286619212,-6.84139000176692E-6,50.0022354,50.0023193,62240.86328125,62305.90625,56.9385111118906,20.6394579897111,17.214239,0,0,0,40,4449,50.01875,62273.384765625,,,,,,,,,,,,,0,,,,0,,,,,,50.00227735,,,,
,31565515.515,50.0018044,67139.375,-0.000138836580982596,1.36958189296959E-6,1,0.999253354069792,40.0298881530762,1.98387334867964,20.2300008386374,-0.00155623781988476,-0.000317402603608031,0.25,-3.27228075003734E-6,-0.000139202065266333,-4.21941344633323E-6,50.0018044,50.0018044,67134.4296875,67144.3203125,57.2152076076984,20.6379210206775,16.834587,0,0,0,40,4449,50.0192,67139.375,,,,,,,,,,,,,0,,,,0,,,,,,50.0018044,,,,
,31565610.15,50.0036163,71867.0390625,-0.00015318486439997,1.39401602089372E-6,1,0.999253354069792,40.0298881530762,1.98391994283227,20.2300008386374,-0.00170832347974818,-0.000401088319901977,0.25,-8.1372188736979E-6,-0.000153587706921118,-9.18233253631884E-6,50.0036163,50.0036163,71837.1015625,71896.9765625,57.1448610409676,20.637498824344,16.834587,0,0,0,40,4449,50.01925,71867.0390625,,,,,,,,,,,,,0,,,,-0.00245,,,,,,50.0036163,,,,
,31565709.18,50.002224,76820.19140625,-0.000167149118650452,1.44629395035841E-6,1,0.999253354069792,40.0298881530762,1.98393633222624,20.2300008386374,-0.00187242718236066,-0.000393160706638164,0.25,-4.93721822255875E-6,-0.000167647477697152,-6.05028449251358E-6,50.002224,50.002224,76795.140625,76845.2421875,56.9713395096983,20.638530895312,17.214239,0,0,0,40,4449,50.01715,76820.19140625,,,,,,,,,,,,,0,,,,-0.0049,,,,,,50.002224,,,,
,31565806.505,50.0021706,81683.34375,-0.000182668628546119,1.62327001780903E-6,1,0.999253354069792,40.0298881530762,1.98394190778188,20.2300008386374,-0.00204735257725735,-0.000425846257184382,0.25,-5.06780759478076E-6,-0.000183248599542061,-6.26606084543475E-6,50.0020142,50.002327,81653.4375,81713.25,56.9854088230445,20.6371513922212,17.214239,0,0,0,40,4449,50.0135,81683.34375,,,,,,,,,,,,,0,,,,0,,,,,,50.0021706,,,,
,31565899.335,50.0028648,86321.421875,-0.00019679084842314,1.85102261662425E-6,1,0.999253354069792,40.0298881530762,1.98393523466818,20.2300008386374,-0.00220107705392427,-0.000486269873484145,0.25,-7.91306035565562E-6,-0.000197432578950885,-9.19468493294388E-6,50.0028648,50.0028648,86291.3125,86351.53125,57.0643533034868,20.6357800450859,17.214239,0,0,0,40,4449,50.012,86321.421875,,,,,,,,,,,,,0,,,,0,,,,,,50.0028648,,,,
,31566005.805,50.0000877,89181.90234375,-0.000207844739265999,1.60987804756181E-6,1,0.999253354069792,40.0298881530762,1.98406756649279,20.2300008386374,-0.00232711691752626,-0.000502348431215686,0.25,-7.36546519784807E-6,-0.000208549379983422,-8.70396164550829E-6,50.0000877,50.0000877,89146.9765625,89216.828125,57.3394865422561,20.6334341839643,16.834587,0,0,0,40,4449,50.01265,89181.90234375,,,,,,,,,,,,,0,,,,0,,,,,,50.0000877,,,,
,31566097.58,50.0004921,84593.97265625,-0.000189321375105578,1.64780450856131E-6,1,0.999253354069792,40.0298881530762,1.98394282676692,20.2300008386374,-0.0021161729255942,-0.000474709578844851,0.25,-8.22054323376133E-6,-0.000189923457057365,-9.46182711295254E-6,50.0004921,50.0004921,84589.0390625,84598.90625,57.3848209963715,20.6388042229486,17.214239,0,0,0,40,4449,50.0206,84593.97265625,,,,,,,,,,,,,0,,,,0.00245,,,,,,50.0004921,,,,
,31566191.815,50.0005951,79882.97265625,-0.000175001845469579,1.77584297043588E-6,1,0.999253354069792,40.0298881530762,1.98412088330528,20.2300008386374,-0.00196359608263112,-0.000396080242631111,0.25,-3.7920635212213E-6,-0.000175552757356907,-4.94265785829026E-6,50.0005951,50.0005951,79860.53125,79905.4140625,57.1221938139099,20.6358817720074,17.214239,0,0,0,40,4449,50.0129,79882.97265625,,,,,,,,,,,,,0,,,,0,,,,,,50.0005951,,,,
,31566288.67,50.0006676,75041.3046875,-0.000158533263716147,1.73285919731557E-6,1,0.999253354069792,40.0298881530762,1.98406735426378,20.2300008386374,-0.00177523669465623,-0.000376594853482144,0.25,-5.00569547287004E-6,-0.000158992795533858,-6.06778429873322E-6,50.0006676,50.0006676,75036.3671875,75046.2421875,57.1604936113522,20.6380089089019,16.834587,0,0,0,40,4449,50.01305,75041.3046875,,,,,,,,,,,,,0,,,,0,,,,,,50.0006676,,,,
,31566384.97,49.99963,70225.88671875,-0.000146304564949675,1.6434177453785E-6,1,0.999253354069792,40.0298881530762,1.98409700911873,20.2300008386374,-0.00164247721417244,-0.000322596317690174,0.25,-2.39509934063451E-6,-0.000146715355017399,-3.3818395242728E-6,49.99963,49.99963,70223.3359375,70228.4375,57.3801312252561,20.6364246475834,17.593889,0,0,0,40,4449,50.014,70225.88671875,,,,,,,,,,,,,0,,,,0,,,,,,49.99963,,,,
,31566480.04,50.0000515,65475.408203125,-0.000128172835680164,1.25403218720188E-6,1,0.999253354069792,40.0298881530762,1.98387597415936,20.2300008386374,-0.00143324866707621,-0.00031170245606719,0.25,-4.67805228713846E-6,-0.000128489843491747,-5.56086021080983E-6,49.9997406,50.0003624,65445.39453125,65505.421875,57.312129544083,20.6399195722953,16.834587,0,0,0,40,4449,50.01255,65475.408203125,,,,,,,,,,,,,0,,,,0,,,,,,50.0000515,,,,
,31566574.585,50.0007591,60749.525390625,-0.000110981784352075,1.06040794797656E-6,1,0.999253354069792,40.0298881530762,1.98401443036889,20.2300008386374,-0.00123707556970981,-0.000290829778467047,0.25,-5.90417083651626E-6,-0.000111220574891748,-6.68216282244808E-6,50.0007591,50.0007591,60721.859375,60777.19140625,57.3355783996599,20.6411394246082,17.593889,0,0,0,40,4449,50.0148,60749.525390625,,,,,,,,,,,,,0,,,,-0.00245,,,,,,50.0007591,,,,
,31566669.165,49.9989433,56021.916015625,-9.65064581830508E-5,1.34575377701862E-6,1,0.999253354069792,40.0298881530762,1.98399261631845,20.2300008386374,-0.00107487637231046,-0.00025619500306296,0.25,-5.42402355191786E-6,-9.66910501859666E-5,-6.10827070766357E-6,49.9986038,49.9992828,55994.2734375,56049.55859375,57.3652802833907,20.6420941002119,17.214239,0,0,0,40,4449,50.011,56021.916015625,,,,,,,,,,,,,0,,,,-0.00245,,,,,,49.9989433,,,,
,31566763.685,49.9986801,51296.71875,-7.92986556014672E-5,1.14438986259716E-6,1,0.999253354069792,40.0298881530762,1.98397755860018,20.2300008386374,-0.000884468819655584,-0.000202370126177415,0.25,-3.73083562928525E-6,-7.94375468818431E-5,-4.29689738719975E-6,49.9986801,49.9986801,51261.78125,51331.65625,57.4426615067945,20.6414963947641,17.593889,0,0,0,40,4449,50.01225,51296.71875,,,,,,,,,,,,,0,,,,-0.00245,,,,,,49.9986801,,,,
,31566859.805,49.9992294,46491.33984375,-6.47612323144425E-5,1.23003887451805E-6,1,0.999253354069792,40.0298881530762,1.98405595613979,20.2300008386374,-0.00071580336767388,-0.000200685755769927,0.25,-6.19378813237967E-6,-6.48369265425973E-5,-6.66608339583467E-6,49.9992294,49.9992294,46488.77734375,46493.90234375,57.024490249006,20.6430825341951,17.593889,0,0,0,40,4449,50.0149,46491.33984375,,,,,,,,,,,,,0,,,,-0.0049,,,,,,49.9992294,,,,
,31566956.1,50.0004768,41678.009765625,-4.99912321356843E-5,1.30448430977714E-6,1,0.999253354069792,40.0298881530762,1.98404614155423,20.2300008386374,-0.00055190275063622,-0.000157702290127399,0.25,-5.02891187770704E-6,-5.00354298484841E-5,-5.39621547504146E-6,50.0004768,50.0004768,41675.796875,41680.22265625,57.1206305568714,20.644546777214,17.214239,0,0,0,40,4449,50.0152,41678.009765625,,,,,,,,,,,,,0,,,,-0.0049,,,,,,50.0004768,,,,
,31567050.765,50.0004387,36948.365234375,-3.32786852055049E-5,9.52030761227988E-7,1,0.999253354069792,40.0298881530762,1.98407881918842,20.2300008386374,-0.000367114371381481,-0.000106040349050039,0.25,-3.44201798139665E-6,-3.32990144668602E-5,-3.68789105142788E-6,50.0004387,50.0004387,36918.375,36978.35546875,57.3402681707753,20.6440440939613,17.593889,0,0,0,40,4449,50.0116,36948.365234375,,,,,,,,,,,,,0,,,,0,,,,,,50.0004387,,,,
,31567144.355,49.9999924,32271.08984375,-2.05840032511247E-5,1.03042988410359E-6,1,0.999253354069792,40.0298881530762,1.9839599399178,20.2300008386374,-0.000227229453048377,-6.43065101747191E-5,0.25,-2.01549297262075E-6,-2.05921619317461E-5,-2.16802020242846E-6,49.9999619,50.0000229,32240.9609375,32301.21875,57.3363600281791,20.6431633048176,17.214239,0,0,0,40,4449,50.01165,32271.08984375,,,,,,,,,,,,,0,,,,0.00245,,,,,,49.9999924,,,,
,31567238.68,50.0004063,27558.7529296875,-4.89919633567027E-6,6.37287484417017E-7,1,0.999253354069792,40.0298881530762,1.98412121031153,20.2300008386374,-4.9364533873551E-5,-4.1439593178351E-5,0.25,-2.80580514730442E-6,-4.88276987399729E-6,-2.84419847683882E-6,50.0003014,50.0005112,27528.740234375,27588.765625,57.5825730117369,20.6434559857843,17.973541,0,0,0,40,4449,50.0105,27558.7529296875,,,,,,,,,,,,,0,,,,-0.0049,,,,,,50.0004063,,,,
,31567334.085,50.00001145,22788.75,8.54715520627531E-6,6.37116947181801E-7,1,0.999253354069792,40.0298881530762,1.98412902919524,20.2300008386374,9.92494273334752E-5,-7.16100776841434E-7,0.25,-1.60383575722103E-6,8.5640613194255E-6,-1.54166859818677E-6,50.0000076,50.0000153,22756.26171875,22821.23828125,57.3387049137368,20.6451293057994,17.593889,0,0,0,40,4449,50.0105,22788.75,,,,,,,,,,,,,0,,,,0,,,,,,50.00001145,,,,
,31567430.335,50.0003929,17978.3095703125,2.17663657355669E-5,5.81256238666999E-7,1,0.999253354069792,40.0298881530762,1.98406750613594,20.2300008386374,0.000248631691172501,2.06284781466787E-5,0.25,-2.08558465200485E-6,2.17889597338912E-5,-1.92491940872801E-6,50.0003929,50.0003929,17948.458984375,18008.16015625,57.4098331089868,20.6466724191516,17.214239,0,0,0,40,4449,50.0138,17978.3095703125,,,,,,,,,,,,,0,,,,-0.0049,,,,,,50.0003929,,,,
,31567526.455,50.0004063,13173.650390625,3.53214354231259E-5,4.90915352895637E-7,1,0.999253354069792,40.0298881530762,1.98427064381588,20.2300008386374,0.000399822696297239,5.33332907417799E-5,0.25,-1.61582865284446E-6,3.53358060710105E-5,-1.35345508028955E-6,50.0003548,50.0004578,13145.943359375,13201.357421875,57.4840878183138,20.6421871939147,16.834587,0,0,0,40,4449,50.01745,13173.650390625,,,,,,,,,,,,,0,,,,0,,,,,,50.0004063,,,,
,31567621.755,49.9990196,8410.63232421875,4.80285999742944E-5,4.84206870261685E-7,1,0.999253354069792,40.0298881530762,1.98419300693011,20.2300008386374,0.000539934362237939,9.23103793406778E-5,0.25,-4.32568526783423E-7,4.80229471279293E-5,-7.513941151672E-8,49.9988136,49.9992256,8378.17578125,8443.0888671875,57.5614690417176,20.6440672321276,17.593889,0,0,0,40,4449,50.0137,8410.63232421875,,,,,,,,,,,,,0,,,,-0.0049,,,,,,49.9990196,,,,
,31567715.64,49.99967195,3717.8271484375,6.03519505385172E-5,3.26383920114445E-7,1,0.999253354069792,40.0298881530762,1.98411601233543,20.2300008386374,0.000677602694330021,0.000119796741148006,0.25,-2.02233259994333E-7,6.03285958093383E-5,2.46944279728866E-7,49.9996414,49.9997025,3695.23876953125,3740.41552734375,57.4153045086215,20.6444928943475,16.834587,0,0,0,40,4449,50.0124,3717.8271484375,,,,,,,,,,,,,0,,,,0,,,,,,49.99967195,,,,
,31567810.955,50.0004387,-1044.23352050781,6.75825101899572E-5,2.89692813611482E-7,1,0.999253354069792,40.0298881530762,1.98438495914821,20.2300008386374,0.000757949428992686,0.000138863391640365,0.25,1.93514255286807E-7,6.7545801457743E-5,6.96173433503314E-7,50.0004387,50.0004387,-1046.62475585938,-1041.84228515625,57.749059886333,20.6417125056934,17.593889,0,0,0,40,4449,50.0096,-1044.23352050781,,,,,,,,,,,,,0,,,,-0.0049,,,,,,50.0004387,,,,
,31567902.595,50.00049785,-5624.982421875,7.50895721384849E-5,3.60043346095329E-7,1,0.999253354069792,40.0298881530762,1.98426204095232,20.2300008386374,0.000840659080516309,0.000163191552372459,0.25,1.00634656918584E-6,7.5057818741079E-5,1.56481722975909E-6,50.0003853,50.0006104,-5647.26513671875,-5602.69970703125,57.6638623777369,20.6463509013556,17.214239,0,0,0,40,4449,50.01305,-5624.982421875,,,,,,,,,,,,,0,,,,-0.00245,,,,,,50.00049785,,,,
,31567997.19,49.99988935,-10353.3994140625,7.74043745546576E-5,4.62112897277124E-7,1,0.999253354069792,40.0298881530762,1.98426044923791,20.2300008386374,0.000866007399349542,0.000172554558868191,0.25,1.42018234308869E-6,7.73873199656208E-5,1.99577477302604E-6,49.9998245,49.9999542,-10380.9755859375,-10325.8232421875,57.4715817620061,20.6453014775564,17.593889,0,0,0,40,4449,50.0147,-10353.3994140625,,,,,,,,,,,,,0,,,,-0.00245,,,,,,49.99988935,,,,
,31568091.125,50.0008602,-15045.7724609375,6.81080278761874E-5,6.08339153985147E-7,1,0.999253354069792,40.0298881530762,1.9841900539858,20.2300008386374,0.000762250781985864,0.000151381973166306,0.25,1.20770804055523E-6,6.81103929878045E-5,1.71362951268772E-6,50.0008316,50.0008888,-15073.2470703125,-15018.2978515625,57.4450063923522,20.6476289277764,17.973541,0,0,0,40,4449,50.01105,-15045.7724609375,,,,,,,,,,,,,0,,,,-0.00245,,,,,,50.0008602,,,,
,31568186.185,50.0007515,-19798.2607421875,4.80464433894853E-5,5.97171727789665E-7,1,0.999253354069792,40.0298881530762,1.98411987698935,20.2300008386374,0.000536303572365287,0.000115390139816994,0.25,1.61660981151926E-6,4.80550701357143E-5,1.97299718450889E-6,50.0007515,50.0007515,-19825.783203125,-19770.73828125,57.3895107674868,20.6499339702213,17.973541,0,0,0,40,4449,50.016,-19798.2607421875,,,,,,,,,,,,,0,,,,-0.00245,,,,,,50.0007515,,,,
,31568282.335,50.0021057,-24603.0107421875,3.27849273383309E-5,7.73902206256109E-7,1,0.999253354069792,40.0298881530762,1.9841920264803,20.2300008386374,0.000363477916549136,9.31007601524665E-5,0.25,2.38069768388855E-6,3.27901122579156E-5,2.62401480813944E-6,50.0021057,50.0021057,-24607.916015625,-24598.10546875,57.6615174921792,20.6494688424802,17.593889,0,0,0,40,4449,50.0145,-24603.0107421875,,,,,,,,,,,,,0,,,,-0.0049,,,,,,50.0021057,,,,
,31568377.87,50.0007935,-29378.2236328125,2.79067443421923E-5,1.111708298629E-6,1,0.999253354069792,40.0298881530762,1.98439020948759,20.2300008386374,0.000310557389389765,7.34394484706127E-5,0.25,1.50825906386906E-6,2.79223335312955E-5,1.71426369599875E-6,50.0007935,50.0007935,-29400.74609375,-29355.701171875,57.2652318329291,20.6449657058402,17.973541,0,0,0,40,4449,50.0128,-29378.2236328125,,,,,,,,,,,,,0,,,,-0.00245,,,,,,50.0007935,,,,
,31568474.65,50.0010872,-34215.177734375,3.5017653644226E-5,1.14801461712757E-6,1,0.999253354069792,40.0298881530762,1.98433137809708,20.2300008386374,0.000387335511592816,0.000105756441840422,0.25,3.10275055262328E-6,3.50375857173977E-5,3.36145056283303E-6,50.0010872,50.0010872,-34247.55078125,-34182.8046875,57.3559007411599,20.6475055748341,17.214239,0,0,0,40,4449,50.00615,-34215.177734375,,,,,,,,,,,,,0,,,,-0.00245,,,,,,50.0010872,,,,
,31568573.46,50.0013084,-39152.298828125,4.46834209481768E-5,1.23215639282829E-6,1,0.999253354069792,40.0298881530762,1.9844706425201,20.2300008386374,0.000497311343361864,0.00011889946970202,0.25,2.53073637093368E-6,4.47310588882258E-5,2.85708092640143E-6,50.0013084,50.0013084,-39154.46875,-39150.12890625,57.5231692442753,20.6446571557223,17.214239,0,0,0,40,4449,50.0079,-39152.298828125,,,,,,,,,,,,,0,,,,0,,,,,,50.0013084,,,,
,31568669.815,50.0018444,-43967.11328125,6.18322571713475E-5,1.28106064607529E-6,1,0.999253354069792,40.0298881530762,1.98437484966322,20.2300008386374,0.000683773677983365,0.000189787943883928,0.25,5.74891768966335E-6,6.18976025443463E-5,6.20114923718057E-6,50.0016823,50.0020065,-43997.23046875,-43936.99609375,57.3777863396984,20.6464146557148,17.973541,0,0,0,40,4449,50.00875,-43967.11328125,,,,,,,,,,,,,0,,,,0,,,,,,50.0018444,,,,
,31568767.345,50.0017052,-48842.291015625,7.1031916098295E-5,1.04798866115995E-6,1,0.999253354069792,40.0298881530762,1.98441505650107,20.2300008386374,0.000785247642950073,0.000220693337962856,0.25,6.84163616308768E-6,7.11228599659644E-5,7.35799946205421E-6,50.0017052,50.0017052,-48874.59375,-48809.98828125,57.2660134614484,20.6450540243238,17.593889,0,0,0,40,4449,50.00165,-48842.291015625,,,,,,,,,,,,,0,,,,-0.0049,,,,,,50.0017052,,,,
,31568863.855,50.0017471,-53666.861328125,8.69299539787987E-5,1.25883574603167E-6,1,0.999253354069792,40.0298881530762,1.98441910641592,20.2300008386374,0.000965330775618907,0.000247331190282813,0.25,6.35182809005456E-6,8.70760962112672E-5,6.97441440157075E-6,50.0017471,50.0017471,-53672.046875,-53661.67578125,57.393418910083,20.6449934158571,17.593889,0,0,0,40,4449,50.0005,-53666.861328125,,,,,,,,,,,,,0,,,,0.0049,,,,,,50.0017471,,,,
,31568960.415,50.0023537,-58491.9375,0.000101962653539084,1.36948006370631E-6,1,0.999253354069792,40.0298881530762,1.98446611973248,20.2300008386374,0.00113599307042239,0.000270997726643262,0.25,5.75521822471864E-6,0.000102169055489619,6.47446792507445E-6,50.0023537,50.0023537,-58494.39453125,-58489.48046875,57.1456426694868,20.6498060032726,17.593889,0,0,0,40,4449,50.0021,-58491.9375,,,,,,,,,,,,,0,,,,0,,,,,,50.0023537,,,,
,31569055.5,50.0009537,-63244.53515625,0.000115331466615123,1.27913091148056E-6,1,0.999253354069792,40.0298881530762,1.98441193674823,20.2300008386374,0.00128386217483032,0.000313925068826126,0.25,7.17184153175992E-6,0.000115585212778768,7.97846035792175E-6,50.0009537,50.0009537,-63272.0078125,-63217.0625,57.1448610409676,20.6470796783837,17.973541,0,0,0,40,4449,50.0065,-63244.53515625,,,,,,,,,,,,,0,,,,0.00245,,,,,,50.0009537,,,,
,31569151.245,50.0010605,-68028.828125,0.000132211405442926,1.42418399256604E-6,1,0.999253354069792,40.0298881530762,1.98421724080378,20.2300008386374,0.00147896635172138,0.000320736129390824,0.25,4.75423532207677E-6,0.000132553069262203,5.65876748872563E-6,50.0010605,50.0010605,-68058.5546875,-67999.1015625,57.4450063923522,20.6527866340316,17.593889,0,0,0,40,4449,50.00575,-68028.828125,,,,,,,,,,,,,0,,,,0,,,,,,50.0010605,,,,
,31569248.74,50.0036736,-72900.90234375,0.000152427166086629,1.22072809146526E-6,1,0.999253354069792,40.0298881530762,1.98407302363069,20.2300008386374,0.00171430656313556,0.000319772777747181,0.25,1.05091555914522E-6,0.00015288087417227,2.06693155371492E-6,50.0036736,50.0036736,-72905.7421875,-72896.0625,57.3699700545061,20.6542405364945,17.973541,0,0,0,40,4449,50.0025,-72900.90234375,,,,,,,,,,,,,0,,,,-0.0049,,,,,,50.0036736,,,,
,31569346.605,50.0030212,-77792.8046875,0.000166945413786447,1.49121444625807E-6,1,0.999253354069792,40.0298881530762,1.98428775156712,20.2300008386374,0.00187388772332826,0.000374022148397754,0.25,3.27070127771761E-6,0.000167459958451472,4.37412045276583E-6,50.0030212,50.0030212,-77822.6015625,-77763.0078125,57.6810582051599,20.6504098764858,17.593889,0,0,0,40,4449,50.00385,-77792.8046875,,,,,,,,,,,,,0,,,,0,,,,,,50.0030212,,,,
,31569445.91,50.0014648,-82755.125,0.000181642267617827,1.52442320223824E-6,1,0.999253354069792,40.0298881530762,1.9842711623335,20.2300008386374,0.002040119377112,0.000401938243857307,0.25,3.12618197768358E-6,0.000182238235730691,4.3074949260398E-6,50.0014648,50.0014648,-82760.1171875,-82750.1328125,57.5341120435445,20.6510226333175,17.593889,0,0,0,40,4449,50.0063,-82755.125,,,,,,,,,,,,,0,,,,0,,,,,,50.0014648,,,,
,31569538.875,50.0019531,-87401.9296875,0.000195483824918184,1.63435236164806E-6,1,0.999253354069792,40.0298881530762,1.98436888156722,20.2300008386374,0.00219615823236987,0.000431984524981729,0.25,3.32351507309865E-6,0.000196157151520418,4.57660913041946E-6,50.0019531,50.0019531,-87407.15625,-87396.703125,57.2535074051407,20.6498617604179,17.973541,0,0,0,40,4449,49.9966,-87401.9296875,,,,,,,,,,,,,0,,,,0,,,,,,50.0019531,,,,
,31569646.155,49.9991989,-88000.72265625,0.00020101215152271,1.79208560092228E-6,1,0.999253354069792,40.0298881530762,1.98440057483615,20.2300008386374,0.00225715534685211,0.000450874413578843,0.25,4.01082453584846E-6,0.000201704977235249,5.29899102811912E-6,49.9991989,49.9991989,-88033.0703125,-87968.375,57.5325487865061,20.6494985034448,17.214239,0,0,0,40,4449,50.0011,-88000.72265625,,,,,,,,,,,,,0,,,,0.00245,,,,,,49.9991989,,,,
,31569738.12,49.99851605,-83405.84765625,0.000185693969101263,1.87276631986386E-6,1,0.999253354069792,40.0298881530762,1.98452467772418,20.2300008386374,0.0020826051926876,0.000429507754803441,0.25,4.84413823444513E-6,0.000186296877536808,6.05506769290838E-6,49.9984283,49.9986038,-83436.109375,-83375.5859375,57.4864327038715,20.6476847850833,17.593889,0,0,0,40,4449,50.0022,-83405.84765625,,,,,,,,,,,,,0,,,,-0.00245,,,,,,49.99851605,,,,
,31569834.605,49.9994736,-78581.23828125,0.000170760647896256,1.3899100663683E-6,1,0.999253354069792,40.0298881530762,1.98449562740366,20.2300008386374,0.00191342293784345,0.000402349732305362,0.25,5.09957902043003E-6,0.000171280565310304,6.23127386233333E-6,49.9994736,49.9994736,-78583.640625,-78578.8359375,57.6599542351407,20.6458786287943,17.214239,0,0,0,40,4449,50.0032,-78581.23828125,,,,,,,,,,,,,0,,,,0.00245,,,,,,49.9994736,,,,
,31569929.865,49.99939725,-73821.4375,0.000154253251109972,1.52606818266537E-6,1,0.999253354069792,40.0298881530762,1.98441953036739,20.2300008386374,0.00172459567430525,0.000382756458895024,0.25,6.31247938192172E-6,0.000154683136123058,7.35396601569606E-6,49.9993286,49.9994659,-73856.6171875,-73786.2578125,57.5184794731599,20.6447037510635,17.593889,0,0,0,40,4449,49.99945,-73821.4375,,,,,,,,,,,,,0,,,,0,,,,,,49.99939725,,,,
,31570026.935,50.0004921,-68969.5859375,0.00013790096815664,1.81769947394304E-6,1,0.999253354069792,40.0298881530762,1.9844412007861,20.2300008386374,0.00154412494868627,0.000327413945752395,0.25,4.32427951614106E-6,0.000138266916251047,5.26364323042534E-6,50.0004921,50.0004921,-68999.46875,-68939.703125,57.5012836457369,20.6446169777799,17.214239,0,0,0,40,4449,50.0007,-68969.5859375,,,,,,,,,,,,,0,,,,0,,,,,,50.0004921,,,,
,31570127.365,49.9991112,-63950.10546875,0.000125397242391241,1.415547832096E-6,1,0.999253354069792,40.0298881530762,1.9843138522602,20.2300008386374,0.00140563087556548,0.000287077579272921,0.25,2.9812827692395E-6,0.000125709786178935,3.84413248593745E-6,49.9991112,49.9991112,-63952.484375,-63947.7265625,57.3965454241599,20.6507015194554,17.973541,0,0,0,40,4449,50.0017,-63950.10546875,,,,,,,,,,,,,0,,,,-0.0049,,,,,,49.9991112,,,,
,31570224.545,49.9992447,-59092.525390625,0.000107633171014142,1.28836513687632E-6,1,0.999253354069792,40.0298881530762,1.98428125443865,20.2300008386374,0.0012001569343833,0.000280147587930266,0.25,5.55191298800464E-6,0.000107857646639505,6.3088885824936E-6,49.9992447,49.9992447,-59095.078125,-59089.97265625,57.6529195784676,20.6485162773664,17.593889,0,0,0,40,4449,50.0026,-59092.525390625,,,,,,,,,,,,,0,,,,0.0049,,,,,,49.9992447,,,,
,31570321.53,49.998558,-54245.548828125,9.29512478788325E-5,1.45747176700427E-6,1,0.999253354069792,40.0298881530762,1.98430092118851,20.2300008386374,0.00103852520068557,0.000229076707277874,0.25,3.64859076142672E-6,9.31320710716909E-5,4.3065978796203E-6,49.998558,49.998558,-54248.05078125,-54243.046875,57.5583425276407,20.6479050136602,17.593889,0,0,0,40,4449,50.0002,-54245.548828125,,,,,,,,,,,,,0,,,,0,,,,,,49.998558,,,,
,31570417.32,49.9989433,-49458.55859375,7.78725880157033E-5,1.26325330461052E-6,1,0.999253354069792,40.0298881530762,1.98428075740741,20.2300008386374,0.000863630928176373,0.000226429991136549,0.25,6.12265791879658E-6,7.79844805659873E-5,6.68545926422761E-6,49.9989433,49.9989433,-49490.9765625,-49426.140625,57.7303008018715,20.6469749063904,17.214239,0,0,0,40,4449,50.0043,-49458.55859375,,,,,,,,,,,,,0,,,,0,,,,,,49.9989433,,,,
,31570513.68,50.0005493,-44644.1015625,6.06550353564067E-5,1.29117580085525E-6,1,0.999253354069792,40.0298881530762,1.98444577226488,20.2300008386374,0.00067801864102964,0.000146074228621678,0.25,2.07365723605117E-6,6.07466855584977E-5,2.51062393693606E-6,50.0005493,50.0005493,-44648.765625,-44639.4375,57.5434915857753,20.6450453955014,17.214239,0,0,0,40,4449,50.0049,-44644.1015625,,,,,,,,,,,,,0,,,,-0.0049,,,,,,50.0005493,,,,
,31570608.015,49.9991722,-39928.357421875,4.57519548128212E-5,9.41575005740944E-7,1,0.999253354069792,40.0298881530762,1.98441203031949,20.2300008386374,0.000509151773155203,0.000122065653849428,0.25,2.62031336317347E-6,4.58023466239854E-5,2.95415368643657E-6,49.9991722,49.9991722,-39955.93359375,-39900.78125,57.2214606358522,20.6448221202739,17.214239,0,0,0,40,4449,50.0033,-39928.357421875,,,,,,,,,,,,,0,,,,0.00245,,,,,,49.9991722,,,,
,31570702.065,50.0007477,-35228.517578125,3.13355034245443E-5,8.90319393375851E-7,1,0.999253354069792,40.0298881530762,1.98441381016461,20.2300008386374,0.000344690789735307,0.00010546761665096,0.25,3.73960597234601E-6,3.13480678680528E-5,3.97210929420419E-6,50.0007477,50.0007477,-35233.703125,-35223.33203125,57.2863358029484,20.6397546350074,17.593889,0,0,0,40,4449,50.0067,-35228.517578125,,,,,,,,,,,,,0,,,,0,,,,,,50.0007477,,,,
,31570797.71,50.0003281,-30448.8408203125,1.77129939919626E-5,6.90774560875272E-7,1,0.999253354069792,40.0298881530762,1.98437475595737,20.2300008386374,0.000194253463061506,6.2568732892665E-5,0.25,2.37701246314972E-6,1.77134913509176E-5,2.50907932895587E-6,50.0003281,50.0003281,-30451.19140625,-30446.490234375,57.4700185049676,20.6423071563956,17.214239,0,0,0,40,4449,50.00225,-30448.8408203125,,,,,,,,,,,,,0,,,,-0.00245,,,,,,50.0003281,,,,
,31570892.73,49.9989891,-25698.8203125,2.35755934555556E-6,7.30488886477054E-7,1,0.999253354069792,40.0298881530762,1.98437798878617,20.2300008386374,2.23794044634981E-5,2.75773642026001E-5,0.25,2.02976714476067E-6,2.34438274579727E-6,2.04864918109103E-6,49.9989891,49.9989891,-25728.80078125,-25668.83984375,57.3551191126407,20.6431602600805,17.593889,0,0,0,40,4449,50.001,-25698.8203125,,,,,,,,,,,,,0,,,,-0.00245,,,,,,49.9989891,,,,
,31570986.98,49.9985962,-20989.18359375,-1.1475714124199E-5,6.12240651708588E-7,1,0.999253354069792,40.0298881530762,1.98444236908144,20.2300008386374,-0.000131799982336217,-7.15557247009339E-6,0.25,1.43089049001548E-6,-1.14919264679846E-5,1.34671155545826E-6,49.9982758,49.9989166,-21016.64453125,-20961.72265625,57.423902422333,20.6387507599762,17.593889,0,0,0,40,4449,50.00155,-20989.18359375,,,,,,,,,,,,,0,,,,0.00245,,,,,,49.9985962,,,,
,31571081.17,49.99864005,-16282.2221679687,-2.48991039684444E-5,5.33251879140434E-7,1,0.999253354069792,40.0298881530762,1.98448681237559,20.2300008386374,-0.000280893443925017,-4.33157178431596E-5,0.25,6.30341425944765E-7,-2.49095699489995E-5,4.45722303827896E-7,49.998558,49.9987221,-16314.7138671875,-16249.73046875,57.2081729510253,20.6394039119507,17.593889,0,0,0,40,4449,50.006,-16282.2221679687,,,,,,,,,,,,,0,,,,0,,,,,,49.99864005,,,,
,31571176.565,49.9996605,-11516.8247070312,-3.86272364771932E-5,4.22370471814433E-7,1,0.999253354069792,40.0298881530762,1.9843172322897,20.2300008386374,-0.00043403421538609,-7.59533183882994E-5,0.25,1.96590445485535E-7,-3.86277110784384E-5,-9.06300536634783E-8,49.9996605,49.9996605,-11546.89453125,-11486.7548828125,57.5145713305638,20.6422137749334,17.593889,0,0,0,40,4449,50.0044,-11516.8247070312,,,,,,,,,,,,,0,,,,0,,,,,,49.9996605,,,,
,31571272.11,50.0005207,-6738.9248046875,-5.17783400780728E-5,3.72293035525545E-7,1,0.999253354069792,40.0298881530762,1.98433004471875,20.2300008386374,-0.000581555768020525,-0.000102406812450234,0.25,2.08805816301547E-7,-5.17658701415627E-5,-1.76559478465559E-7,50.0004463,50.0005951,-6763.7587890625,-6714.0908203125,57.6521379499484,20.6388799263835,17.593889,0,0,0,40,4449,50.0068,-6738.9248046875,,,,,,,,,,,,,0,,,,-0.00245,,,,,,50.0005207,,,,
,31571366.345,50.0006943,-2030.31658935547,-6.37626190248084E-5,3.55829503878201E-7,1,0.999253354069792,40.0298881530762,1.98446029908844,20.2300008386374,-0.000714523676414108,-0.000134557990654781,0.25,-4.97453308579851E-7,-6.37279625738945E-5,-9.71609744176982E-7,50.0006943,50.0006943,-2035.52661132813,-2025.10656738281,57.0080760501022,20.6412480049535,17.593889,0,0,0,40,4449,50.0069,-2030.31658935547,,,,,,,,,,,,,0,,,,0,,,,,,50.0006943,,,,
,31571460.235,49.9999161,2660.2333984375,-6.99643747367835E-5,3.98032094221802E-7,1,0.999253354069792,40.0298881530762,1.98434173047368,20.2300008386374,-0.000783703435073472,-0.00014925971879555,0.25,-6.90089418527567E-7,-6.99270108685792E-5,-1.21034473210122E-6,49.9999161,49.9999161,2627.775390625,2692.69140625,57.3285437429868,20.6402737407217,17.214239,0,0,0,40,4449,50.00365,2660.2333984375,,,,,,,,,,,,,0,,,,0,,,,,,49.9999161,,,,
,31571556.055,50.0007057,7452.38525390625,-7.66552913623113E-5,3.44208949650433E-7,1,0.999253354069792,40.0298881530762,1.98435531368472,20.2300008386374,-0.000858269080019892,-0.000166801321341697,0.25,-1.04388947448512E-6,-7.66295292351132E-5,-1.61404706081055E-6,50.0007057,50.0007057,7447.32080078125,7457.44970703125,57.2191157502945,20.638903043056,17.973541,0,0,0,40,4449,50.0087,7452.38525390625,,,,,,,,,,,,,0,,,,-0.0049,,,,,,50.0007057,,,,
,31571648.525,49.99913975,12073.2236328125,-7.59371996549441E-5,4.78229797665263E-7,1,0.999253354069792,40.0298881530762,1.98434473672422,20.2300008386374,-0.000848693704123112,-0.000174899538460707,0.25,-1.89184061393177E-6,-7.59234637790474E-5,-2.45638816349258E-6,49.9989166,49.9993629,12040.9130859375,12105.5341796875,57.7099784603715,20.637760166767,17.593889,0,0,0,40,4449,50.00525,12073.2236328125,,,,,,,,,,,,,0,,,,-0.00245,,,,,,49.99913975,,,,
,31571742.885,50.0006332,16788.0185546875,-6.21273494143098E-5,4.89840552455755E-7,1,0.999253354069792,40.0298881530762,1.9844021952272,20.2300008386374,-0.000694585252242261,-0.000142925883441843,0.25,-1.53044665125639E-6,-6.21321226246839E-5,-1.99173414530648E-6,50.0006332,50.0006332,16757.830078125,16818.20703125,57.1878506095253,20.6365303205115,17.973541,0,0,0,40,4449,50.0039,16788.0185546875,,,,,,,,,,,,,0,,,,0,,,,,,50.0006332,,,,
,31571839.075,50.0002937,21597.5537109375,-4.15788281931295E-5,6.98505494218202E-7,1,0.999253354069792,40.0298881530762,1.98446436262997,20.2300008386374,-0.000462523632340641,-0.00010936364184668,0.25,-2.24340527922937E-6,-4.15840100576675E-5,-2.55196469315599E-6,50.0002937,50.0002937,21590.166015625,21604.94140625,57.1745629246983,20.6381419635965,17.214239,0,0,0,40,4449,49.9994,21597.5537109375,,,,,,,,,,,,,0,,,,0,,,,,,50.0002937,,,,
,31571935.43,50.0011158,26412.93359375,-3.09985552126332E-5,9.86475847279991E-7,1,0.999253354069792,40.0298881530762,1.9842651006475,20.2300008386374,-0.000342138593887043,-9.68093098629353E-5,0.25,-3.03199282398288E-6,-3.10007412090887E-5,-3.26245143636019E-6,50.0008392,50.0013924,26388.140625,26437.7265625,57.5302039009484,20.6372799943754,17.593889,0,0,0,40,4449,50.00325,26412.93359375,,,,,,,,,,,,,0,,,,0.00245,,,,,,50.0011158,,,,
,31572031.96,50.0014305,31238.787109375,-3.11953672550044E-5,8.63728055924716E-7,1,0.999253354069792,40.0298881530762,1.98429927151269,20.2300008386374,-0.000344680649036244,-9.59410260387917E-5,0.25,-2.91830387319714E-6,-3.1206891287537E-5,-3.14948908317838E-6,50.0014305,50.0014305,31211.580078125,31265.994140625,57.5137897020446,20.6364523097901,17.593889,0,0,0,40,4449,50.0032,31238.787109375,,,,,,,,,,,,,0,,,,0.00245,,,,,,50.0014305,,,,
,31572126.46,50.0007687,35961.634765625,-3.98720025444189E-5,8.87498131687567E-7,1,0.999253354069792,40.0298881530762,1.98439260065127,20.2300008386374,-0.000442989188631657,-0.000109852721554132,0.25,-2.59266304719573E-6,-3.99052570661564E-5,-2.88552187207831E-6,50.0004578,50.0010796,35929.25390625,35994.015625,57.2855541744291,20.6354724208616,17.593889,0,0,0,40,4449,50.00155,35961.634765625,,,,,,,,,,,,,0,,,,-0.00245,,,,,,50.0007687,,,,
,31572223.2,50.00177765,40796.498046875,-5.34445045564275E-5,9.54308599831351E-7,1,0.999253354069792,40.0298881530762,1.98439323205914,20.2300008386374,-0.000593107719424342,-0.000151883497677303,0.25,-3.88758982677003E-6,-5.34998086169635E-5,-4.27837388116521E-6,50.0016212,50.0019341,40766.3046875,40826.69140625,57.2214606358522,20.6365560636358,17.593889,0,0,0,40,4449,49.99985,40796.498046875,,,,,,,,,,,,,0,,,,0,,,,,,50.00177765,,,,
,31572321.635,50.0012894,45716.615234375,-6.84106867247289E-5,1.00607760935534E-6,1,0.999253354069792,40.0298881530762,1.9844826416573,20.2300008386374,-0.000759379749173009,-0.000194709682993038,0.25,-5.00217031317346E-6,-6.84986998942503E-5,-5.49888475698653E-6,50.0012894,50.0012894,45713.8984375,45719.33203125,57.1370447557753,20.6371800491999,17.973541,0,0,0,40,4449,49.9993,45716.615234375,,,,,,,,,,,,,0,,,,-0.0049,,,,,,50.0012894,,,,
,31572416.44,50.0005302,50454.560546875,-8.33223628938654E-5,1.04446395096924E-6,1,0.999253354069792,40.0298881530762,1.98442911359786,20.2300008386374,-0.000929400314782146,-0.000213283959914077,0.25,-3.97297865176567E-6,-8.34643146184234E-5,-4.56890912263672E-6,50.0005302,50.0005302,50452.109375,50457.01171875,57.3316702570638,20.6357521440365,17.214239,0,0,0,40,4449,49.99985,50454.560546875,,,,,,,,,,,,,0,,,,0,,,,,,50.0005302,,,,
,31572513.82,50.0011711,55319.623046875,-0.000100199887857678,1.25996492805483E-6,1,0.999253354069792,40.0298881530762,1.98456214100891,20.2300008386374,-0.00112074010992682,-0.000241253115312014,0.25,-3.42574321487434E-6,-0.000100403418627198,-4.13226646248212E-6,50.0011711,50.0011711,55289.55078125,55349.6953125,57.5278590153907,20.6333625316651,17.973541,0,0,0,40,4449,50.0001,55319.623046875,,,,,,,,,,,,,0,,,,-0.00245,,,,,,50.0011711,,,,
,31572609.285,50.0007763,60092.4609375,-0.000114742191360624,1.2060465209485E-6,1,0.999253354069792,40.0298881530762,1.98448295282683,20.2300008386374,-0.00128508786288453,-0.000268191209984923,0.25,-3.21093999725633E-6,-0.000115005366257918,-4.00937351092509E-6,50.0006027,50.0009499,60062.5703125,60122.3515625,57.4207759082561,20.6342252611267,17.593889,0,0,0,40,4449,50.00265,60092.4609375,,,,,,,,,,,,,0,,,,0,,,,,,50.0007763,,,,
,31572708.345,50.0004654,65042.873046875,-0.000132417404195457,1.53245866595781E-6,1,0.999253354069792,40.0298881530762,1.98442488476316,20.2300008386374,-0.00147636063439872,-0.000348342690111354,0.25,-7.1623377767775E-6,-0.000132726281990107,-8.08179988787619E-6,50.0004654,50.0004654,65040.48046875,65045.265625,57.2355299491984,20.6303292263379,17.214239,0,0,0,40,4449,49.9963,65042.873046875,,,,,,,,,,,,,0,,,,-0.00245,,,,,,50.0004654,,,,
,31572805.4,50.0003624,69895.38671875,-0.000150445585165203,1.23409659605955E-6,1,0.999253354069792,40.0298881530762,1.98434250395533,20.2300008386374,-0.00167542876358546,-0.000408151297926421,0.25,-9.24554341518765E-6,-0.0001508200872352,-1.02810209476469E-5,50.0003624,50.0003624,69862.9921875,69927.78125,57.4879959609099,20.6341413594896,17.593889,0,0,0,40,4449,49.99455,69895.38671875,,,,,,,,,,,,,0,,,,0,,,,,,50.0003624,,,,
,31572902.95,50.00190355,74773.05078125,-0.000165345475582551,1.63102943263111E-6,1,0.999253354069792,40.0298881530762,1.98444443309868,20.2300008386374,-0.00184777374627664,-0.000415464282781459,0.25,-7.22800370694906E-6,-0.000165809336860643,-8.34297330647927E-6,50.0017929,50.0020142,74740.6171875,74805.484375,57.5083183024099,20.6315841472761,17.214239,0,0,0,40,4449,49.9942,74773.05078125,,,,,,,,,,,,,0,,,,-0.00245,,,,,,50.00190355,,,,
,31573001.4,50.001667,79693.515625,-0.000181135046991446,1.25373008385293E-6,1,0.999253354069792,40.0298881530762,1.98438958186487,20.2300008386374,-0.00203035869492776,-0.000422833166787421,0.25,-5.062231166705E-6,-0.000181696173235341,-6.25777020603457E-6,50.001667,50.001667,79688.5703125,79698.4609375,57.5286406439099,20.6308747999325,17.593889,0,0,0,40,4449,49.9942,79693.515625,,,,,,,,,,,,,0,,,,-0.00245,,,,,,50.001667,,,,
,31573096.76,50.00141905,84459.9921875,-0.000200202645728641,1.34118272150213E-6,1,0.999253354069792,40.0298881530762,1.98484062122221,20.2300008386374,-0.00225260728337162,-0.000424862169261379,0.25,-1.82929290350853E-6,-0.000200881754447548,-3.11907660579889E-6,50.0013466,50.0014915,84427.59375,84492.390625,57.2222422643714,20.6228936254392,17.593889,0,0,0,40,4449,49.99385,84459.9921875,,,,,,,,,,,,,0,,,,0,,,,,,50.00141905,,,,
,31573188.15,50.0011482,89030.36328125,-0.000216938245412467,1.52081002346883E-6,1,0.999253354069792,40.0298881530762,1.98469593667028,20.2300008386374,-0.00243529711497543,-0.000492938876645699,0.25,-4.88822023128592E-6,-0.000217689819731475,-6.27608726227038E-6,50.0009613,50.0013351,89005.34375,89055.3828125,57.555997642083,20.6269586121339,17.973541,0,0,0,40,4449,49.993,89030.36328125,,,,,,,,,,,,,0,,,,-0.00245,,,,,,50.0011482,,,,
,31573292.985,49.9970627,86531.5546875,-0.000205716993900554,1.19782898884241E-6,1,0.999253354069792,40.0298881530762,1.98441127002594,20.2300008386374,-0.00230943510253111,-0.000463893366946663,0.25,-4.31901196567177E-6,-0.000206414164014815,-5.64421365376274E-6,49.9970627,49.9970627,86499.203125,86563.90625,57.2839909173907,20.630701563642,17.973541,0,0,0,40,4449,49.99585,86531.5546875,,,,,,,,,,,,,0,,,,0,,,,,,49.9970627,,,,
,31573385.765,49.9985847,81890.30078125,-0.000189831794045985,1.24516929971261E-6,1,0.999253354069792,40.0298881530762,1.9844784223945,20.2300008386374,-0.00212863784383879,-0.00044021296365204,0.25,-5.04975573437103E-6,-0.000190436973310211,-6.29370508492429E-6,49.9985847,49.9985847,81860.75,81919.8515625,57.2394380917945,20.6281732730732,17.593889,0,0,0,40,4449,49.99675,81890.30078125,,,,,,,,,,,,,0,,,,0.00245,,,,,,49.9985847,,,,
,31573482.285,49.9983482,77066.18359375,-0.000169926899507457,1.10707811396539E-6,1,0.999253354069792,40.0298881530762,1.98455835091433,20.2300008386374,-0.00190273198227853,-0.00040760161798133,0.25,-5.71093764647225E-6,-0.000170430219975791,-6.84410137640015E-6,49.9983482,49.9983482,77060.890625,77071.4765625,57.1808159528522,20.6307375208107,17.593889,0,0,0,40,4449,49.9991,77066.18359375,,,,,,,,,,,,,0,,,,-0.00245,,,,,,49.9983482,,,,
,31573577.235,49.9995499,72318.171875,-0.000157515427382918,9.11968714159257E-7,1,0.999253354069792,40.0298881530762,1.98476457872126,20.2300008386374,-0.00176393482143674,-0.000375948186865982,0.25,-5.11446708282084E-6,-0.000157953668603988,-6.17835438053581E-6,49.9995499,49.9995499,72313.1796875,72323.1640625,57.4528226775445,20.6284814690286,17.214239,0,0,0,40,4449,49.9946,72318.171875,,,,,,,,,,,,,0,,,,0,,,,,,49.9995499,,,,
,31573673.55,50.000164,67505.171875,-0.000139786544576908,1.18478206436936E-6,1,0.999253354069792,40.0298881530762,1.98466680534888,20.2300008386374,-0.00156266433484575,-0.000346654649350672,0.25,-5.68899989264853E-6,-0.000140140017157623,-6.64860918924392E-6,50.000164,50.000164,67505.171875,67505.171875,57.5544343850446,20.6307906360496,17.973541,0,0,0,40,4449,49.9951,67505.171875,,,,,,,,,,,,,0,,,,-0.0049,,,,,,50.000164,,,,
,31573768.275,49.998661,62769.787109375,-0.000123905236827496,1.00972805252696E-6,1,0.999253354069792,40.0298881530762,1.98463657360075,20.2300008386374,-0.00138655472629649,-0.000297590015408834,0.25,-4.17752613947995E-6,-0.000124199263604909,-5.03589860511598E-6,49.998661,49.998661,62737.2734375,62802.30078125,57.1339182416984,20.6328384072332,17.593889,0,0,0,40,4449,50.0013,62769.787109375,,,,,,,,,,,,,0,,,,-0.00245,,,,,,49.998661,,,,
,31573863.43,49.9992733,58013.8203125,-0.000108619928814298,1.1861069833817E-6,1,0.999253354069792,40.0298881530762,1.98458721491105,20.2300008386374,-0.0012159875066654,-0.000256531834019233,0.25,-3.27193198766418E-6,-0.00010885712576645,-4.03212598023102E-6,49.9992104,49.9993362,57983.53125,58044.109375,57.576319983583,20.6309680508902,17.593889,0,0,0,40,4449,49.99705,58013.8203125,,,,,,,,,,,,,0,,,,-0.00245,,,,,,49.9992733,,,,
,31573957.455,49.99943925,53313.1171875,-9.42406208462606E-5,1.17510888360196E-6,1,0.999253354069792,40.0298881530762,1.98462660627015,20.2300008386374,-0.00104964871194041,-0.000251194925674589,0.25,-5.37845178402857E-6,-9.44079688246802E-5,-6.05057647154881E-6,49.9992485,49.99963,53280.296875,53345.9375,57.054973761256,20.6302769648057,17.973541,0,0,0,40,4449,49.9979,53313.1171875,,,,,,,,,,,,,0,,,,-0.00245,,,,,,49.99943925,,,,
,31574053.35,49.9989891,48523.162109375,-7.85189987741782E-5,1.13869541277927E-6,1,0.999253354069792,40.0298881530762,1.9845559550243,20.2300008386374,-0.000874865992775544,-0.000206136267453535,0.25,-4.19964121692806E-6,-7.86420986144076E-5,-4.76416112159327E-6,49.9989891,49.9989891,48493.1484375,48553.17578125,57.5012836457369,20.6326538138425,17.593889,0,0,0,40,4449,50.00155,48523.162109375,,,,,,,,,,,,,0,,,,-0.00245,,,,,,49.9989891,,,,
,31574149.025,49.9997063,43739.80859375,-6.2262214265089E-5,8.75383192548412E-7,1,0.999253354069792,40.0298881530762,1.98450300327425,20.2300008386374,-0.000689449354329797,-0.000186183500830663,0.25,-5.35002163601185E-6,-6.23303186794816E-5,-5.80480524704527E-6,49.9997063,49.9997063,43734.578125,43745.0390625,57.2886806885061,20.6324516240351,17.214239,0,0,0,40,4449,50.00075,43739.80859375,,,,,,,,,,,,,0,,,,-0.0049,,,,,,49.9997063,,,,
,31574244.885,50.0000343,38947.802734375,-4.65776330943107E-5,1.07300372351921E-6,1,0.999253354069792,40.0298881530762,1.98446771474727,20.2300008386374,-0.000517062495696669,-0.000131289438052488,0.25,-3.29166283741018E-6,-4.66219645146347E-5,-3.63291226755973E-6,50.0000343,50.0000343,38942.60546875,38953,57.5942974395253,20.6356450507168,17.214239,0,0,0,40,4449,49.99795,38947.802734375,,,,,,,,,,,,,0,,,,0,,,,,,50.0000343,,,,
,31574340.65,49.99937055,34160.501953125,-3.05583870741441E-5,8.46631509443572E-7,1,0.999253354069792,40.0298881530762,1.98455417630666,20.2300008386374,-0.00033625738536281,-0.000102229578872489,0.25,-3.59101970148713E-6,-3.05692189276898E-5,-3.81786076789462E-6,49.9992485,49.9994926,34120.421875,34200.58203125,57.2027015513907,20.632507659618,17.214239,0,0,0,40,4449,50.00065,34160.501953125,,,,,,,,,,,,,0,,,,0,,,,,,49.99937055,,,,
,31574437.605,49.9995117,29315.6748046875,-1.47570948898582E-5,9.09062636521801E-7,1,0.999253354069792,40.0298881530762,1.98464786674485,20.2300008386374,-0.000161326856742689,-5.5023379336299E-5,0.25,-2.23752283720707E-6,-1.47546787911713E-5,-2.3478353766976E-6,49.9995117,49.9995117,29313.033203125,29318.31640625,57.2519441481022,20.6335577718256,17.973541,0,0,0,40,4449,49.9986,29315.6748046875,,,,,,,,,,,,,0,,,,-0.0049,,,,,,49.9995117,,,,
,31574532.265,49.9996414,24585.322265625,1.44493502161574E-7,6.27760724058631E-7,1,0.999253354069792,40.0298881530762,1.98446788204414,20.2300008386374,5.70002501791702E-6,-2.2333693744593E-5,0.25,-2.01387326384917E-6,1.59439016322461E-7,-2.0141966817762E-6,49.9996414,49.9996414,24560.1796875,24610.46484375,57.2910255740638,20.6365075146439,17.214239,0,0,0,40,4449,50.00315,24585.322265625,,,,,,,,,,,,,0,,,,0,,,,,,49.9996414,,,,
,31574627.83,49.9989643,19808.1171875,1.41069355909094E-5,6.74027545507366E-7,1,0.999253354069792,40.0298881530762,1.98457192885801,20.2300008386374,0.000161026405595955,1.43078703935948E-5,0.25,-1.26840110645399E-6,1.41223305433182E-5,-1.16450104159756E-6,49.9988632,49.9990654,19778.203125,19838.03125,57.4520410490253,20.6345524665393,17.593889,0,0,0,40,4449,50.003,19808.1171875,,,,,,,,,,,,,0,,,,0.0049,,,,,,49.9989643,,,,
,31574722.87,49.9988251,15058.26171875,2.89926208171285E-5,4.89816490303861E-7,1,0.999253354069792,40.0298881530762,1.9845813910379,20.2300008386374,0.000328012321990676,4.51880356096499E-5,0.25,-1.20144376684773E-6,2.90063350242394E-5,-9.86362226945714E-7,49.9988251,49.9988251,15055.841796875,15060.681640625,57.126101956506,20.6346040550239,17.593889,0,0,0,40,4449,50.0049,15058.26171875,,,,,,,,,,,,,0,,,,0.0049,,,,,,49.9988251,,,,
,31574816.11,49.99912645,10398.1977539062,4.15944894621695E-5,4.26622095787107E-7,1,0.999253354069792,40.0298881530762,1.98460554245243,20.2300008386374,0.000468670503282484,7.48166124638427E-5,0.25,-8.33312602735963E-7,4.15971515554969E-5,-5.23872312120462E-7,49.9989243,49.9993286,10363.30078125,10433.0947265625,56.9643048530253,20.6348931203869,17.593889,0,0,0,40,4449,50.0031,10398.1977539062,,,,,,,,,,,,,0,,,,-0.00245,,,,,,49.99912645,,,,
,31574908.41,49.9991722,5785.16064453125,5.43018631596372E-5,3.60263715327688E-7,1,0.999253354069792,40.0298881530762,1.98464674669153,20.2300008386374,0.000610500884680298,0.000104424861340561,0.25,-4.84875169765636E-7,5.42881755971888E-5,-8.0621508936837E-8,49.9991722,49.9991722,5754.90185546875,5815.41943359375,57.4981571316599,20.6339211403531,17.593889,0,0,0,40,4449,50.0032,5785.16064453125,,,,,,,,,,,,,0,,,,0,,,,,,49.9991722,,,,
,31575003.78,49.998661,1016.75106811523,6.63207711680475E-5,3.25123263344119E-7,1,0.999253354069792,40.0298881530762,1.98505779799725,20.2300008386374,0.000743510893634385,0.000139241484574431,0.25,4.50645301969261E-7,6.62826949385433E-5,9.4378020517686E-7,49.998661,49.998661,991.564758300781,1041.93737792969,57.3316702570638,20.6311963487425,17.593889,0,0,0,40,4449,50.00725,1016.75106811523,,,,,,,,,,,,,0,,,,0.00245,,,,,,49.998661,,,,
,31575025.92,50.0004845,-0.289251700043678,6.75548807886424E-5,3.38172533685213E-7,1,0.999253354069792,40.0298881530762,1.98493562896561,20.2300008386374,0.000757622148926606,0.000139920388395441,0.25,2.89815433606354E-7,6.75153907747133E-5,7.92151453565573E-7,50.0004845,50.0004845,-0.304475486278534,-0.274027913808823,57.4528226775445,20.6337245458736,17.973541,0,0,0,40,4417,50.0092,-0.289251700043678,,,,,,,,,,,,,0,,,,0,,,,,,50.0004845,,,,