File: data/doubleLayers/dl_0-25/ppms/data/DD205_10_HYST_100OE_250K.DAT
[Header]
; VSM Data File (default extension .dat)
; Copyright (c) 2003-2013, Quantum Design, Inc. All rights reserved.
TITLE,
FILEOPENTIME,31612733.73,01/02/2019,5:20 am
BYAPP,VSM,2.0,2.0
INFO,PPMS VSM Option Release 1.4.10 Build 1,APPNAME
INFO,Quantum Design Linear Motor Servo Controller,MOTOR_MODULE_NAME
INFO,3101-100 M1,MOTOR_HW_VERSION
INFO,MMC1014,MOTOR_SERIAL_NUMBER
INFO,SRV No X-over 01.03.11,MOTOR_SOFTWARE_VERSION
INFO,Quantum Design VSM Detection Module,VSM_MODULE_NAME
INFO,3101-150 F0,VSM_HW_VERSION
INFO,VSM707,VSM_SERIAL_NUMBER
INFO,VSM No X-over 01.02.05 May 20 2008 13:51:47,VSM_SOFTWARE_VERSION
INFO,704,PREAMP_SERIAL_NUMBER
INFO,822,COIL_SERIAL_NUMBER
INFO,0,MOMENT_UNITS
INFO,CoFe2O4,SAMPLE_MATERIAL
INFO,Double Layer thin concentration,SAMPLE_COMMENT
INFO,27.44,SAMPLE_MASS
INFO,,SAMPLE_VOLUME
INFO,,SAMPLE_MOLECULAR_WEIGHT
INFO,,SAMPLE_SIZE
INFO,,SAMPLE_SHAPE
DATATYPE,COMMENT,1
DATATYPE,TIME,2
STARTUPAXIS,X,2
STARTUPAXIS,Y1,5
[Data]
Comment,Time Stamp (sec),Temperature (K),Magnetic Field (Oe),Moment (emu),M. Std. Err. (emu),Transport Action,Averaging Time (sec),Frequency (Hz),Peak Amplitude (mm),Center Position (mm),Coil Signal' (mV),Coil Signal" (mV),Range (mV),M. Quad. Signal (emu),M. Raw' (emu),M. Raw" (emu),Min. Temperature (K),Max. Temperature (K),Min. Field (Oe),Max. Field (Oe),Mass (grams),Motor Lag (deg),Pressure (Torr),VSM Status (code),Motor Status (code),Measure Status (code),Measure Count,PPMS Status (code),System Temp. (K),System Field (Oe),Sample Position (deg),Bridge 1 Resistance (ohms),Bridge 1 Excitation (에),Bridge 2 Resistance (ohms),Bridge 2 Excitation (에),Bridge 3 Resistance (ohms),Bridge 3 Excitation (에),Bridge 4 Resistance (ohms),Bridge 4 Excitation (에),Signal 1 Vin (V),Signal 2 Vin (V),Digital Inputs (code),Drive 1 Iout (mA),Drive 1 Ipower (W),Drive 2 Iout (mA),Drive 2 Ipower (W),Pressure (),Map 20 (),Map 21 (),Map 22 (),Map 23 (),Map 24 (),Map 25 (),Map 26 (),Map 27 (),Map 28 (),Map 29 ()
,31612749.58,249.9869232,-0.3349229991436,,,2,,,,19.229999550581,,,,,,,249.9869232,249.9869232,-0.3349229991436,-0.3349229991436,,,23.668306,,,,-99999999,4369,250.0383,-0.3349229991436,,,,,,,,,,,,,,,,,,,,,,,249.9869232,,,,
,31612891.75,249.9779053,4581.01977539063,4.4097900962559E-5,5.02811482712085E-7,1,0.999253354069792,40.0298881530762,1.99681491150154,19.1799998283386,0.000499246476474261,8.79972731762103E-5,0.25,1.21270086493771E-7,4.4175207612959E-5,1.57912805426959E-7,249.9779053,249.9779053,4550.95068359375,4611.0888671875,56.4875114562944,20.5992703819687,24.047956,0,0,0,40,4449,250.0578,4581.01977539063,,,,,,,,,,,,,0,,,,-0.0049,,,,,,249.9779053,,,,
,31612988.275,249.9786224,9401.99462890625,3.7593983205391E-5,5.74963747515489E-7,1,0.999253354069792,40.0298881530762,1.99674869837759,19.1799998283386,0.000426057556406617,7.23785918786657E-5,0.25,-1.29467169903981E-7,3.76600832732199E-5,-9.86727971822181E-8,249.9784698,249.978775,9371.9404296875,9432.048828125,56.6360208749483,20.6060855006873,24.427608,0,0,0,40,4449,250.08505,9401.99462890625,,,,,,,,,,,,,0,,,,-0.00245,,,,,,249.9786224,,,,
,31613086.815,249.9865341,14327.296875,2.4251846067908E-5,9.04530268765309E-7,1,0.999253354069792,40.0298881530762,1.99670590284495,19.1799998283386,0.000273696886570147,5.33031189535818E-5,0.25,5.00350513329876E-7,2.42940017066895E-5,5.21216757432777E-7,249.9860687,249.9869995,14299.9462890625,14354.6474609375,57.0307432771599,20.6073293097861,24.427608,0,0,0,40,4449,250.09735,14327.296875,,,,,,,,,,,,,0,,,,0,,,,,,249.9865341,,,,
,31613183.465,249.9889526,19159.380859375,1.14453274243038E-5,1.05059706883188E-6,1,0.999253354069792,40.0298881530762,1.99653836539993,19.1799998283386,0.000127881203337673,3.25111907657029E-5,0.25,8.85802958066201E-7,1.14646879404839E-5,8.96779367260871E-7,249.9889526,249.9889526,19127.02734375,19191.734375,57.0424677049483,20.6100363117237,24.427608,0,0,0,40,4449,250.1011,19159.380859375,,,,,,,,,,,,,0,,,,0,,,,,,249.9889526,,,,
,31613283.71,249.9915771,24169.4677734375,-4.83766889497034E-6,1.16093846342532E-6,1,0.999253354069792,40.0298881530762,1.99636621734669,19.1799998283386,-5.49829096909137E-5,-8.34913480619722E-6,0.25,1.01681962266473E-7,-4.84624406995781E-6,9.78835428243055E-8,249.9915771,249.9915771,24139.642578125,24199.29296875,57.2238055214099,20.6111962204134,24.807261,0,0,0,40,4449,250.11,24169.4677734375,,,,,,,,,,,,,0,,,,0,,,,,,249.9915771,,,,
,31613382.135,250.0000458,29087.2333984375,-2.12689459394918E-5,1.58903066193184E-6,1,0.999253354069792,40.0298881530762,1.99642325423807,19.1799998283386,-0.000243913745296867,-2.41761953254505E-5,0.25,1.5536408722449E-6,-2.13075511024853E-5,1.53890652813124E-6,250.0000458,250.0000458,29082.05078125,29092.416015625,57.1339182416984,20.6105531673262,24.427608,0,0,0,40,4449,250.11015,29087.2333984375,,,,,,,,,,,,,0,,,,0,,,,,,250.0000458,,,,
,31613480.315,249.99708555,33994.646484375,-3.91608441149247E-5,1.58609770442433E-6,1,0.999253354069792,40.0298881530762,1.99653075533063,19.1799998283386,-0.000442788421725164,-8.10401424220454E-5,0.25,-3.64478665531226E-7,-3.92292865981918E-5,-3.97223886727426E-7,249.9970398,249.9971313,33964.71484375,34024.578125,57.271484861083,20.6070062804747,24.427608,0,0,0,40,4449,250.11135,33994.646484375,,,,,,,,,,,,,0,,,,-0.00245,,,,,,249.99708555,,,,
,31613578.36,250.00385285,38894.619140625,-5.46805928420145E-5,2.03220859957527E-6,1,0.999253354069792,40.0298881530762,1.99636198970672,19.1799998283386,-0.000619577423598121,-0.000105314570461435,0.25,1.82736784130744E-7,-5.47767201864477E-5,1.38290839997245E-7,250.0036621,250.0040436,38866.85546875,38922.3828125,56.9775925378522,20.6111943350293,24.047956,0,0,0,40,4449,250.1065,38894.619140625,,,,,,,,,,,,,0,,,,0.00245,,,,,,250.00385285,,,,
,31613677.655,250.0092163,43857.15625,-6.88151085560623E-5,1.87280164278828E-6,1,0.999253354069792,40.0298881530762,1.99620890254824,19.1799998283386,-0.000782949988125468,-0.000113650551813532,0.25,1.89699239401529E-6,-6.8937442326781E-5,1.84406285558237E-6,250.0092163,250.0092163,43854.828125,43859.484375,57.1995750373137,20.6174530407472,24.427608,0,0,0,40,4449,250.0944,43857.15625,,,,,,,,,,,,,0,,,,0,,,,,,250.0092163,,,,
,31613775.875,250.0082092,48770.021484375,-8.80817114491239E-5,2.2385333074452E-6,1,0.999253354069792,40.0298881530762,1.99602045145868,19.1799998283386,-0.00100259459957246,-0.000142416290072394,0.25,2.69654817042336E-6,-8.82385270375918E-5,2.62937847778388E-6,250.0082092,250.0082092,48767.7109375,48772.33203125,57.054973761256,20.619215848362,24.047956,0,0,0,40,4449,250.0957,48770.021484375,,,,,,,,,,,,,0,,,,0,,,,,,250.0082092,,,,
,31613873.695,250.0088348,53657.44921875,-0.000106368096908859,2.19541619229313E-6,1,0.999253354069792,40.0298881530762,1.9961588403177,19.1799998283386,-0.00120895489551979,-0.000182752525804096,0.25,2.30613953856687E-6,-0.000106556701768123,2.22348410931299E-6,250.0088348,250.0088348,53630.11328125,53684.78515625,57.187068981006,20.6153340606258,24.427608,0,0,0,40,4449,250.0868,53657.44921875,,,,,,,,,,,,,0,,,,-0.00245,,,,,,250.0088348,,,,
,31613971.585,250.0092468,58547.6875,-0.00012317613281481,2.43707013166154E-6,1,0.999253354069792,40.0298881530762,1.99610107505131,19.1799998283386,-0.00140229466758267,-0.000198118904166825,0.25,3.86319972883589E-6,-0.000123395522756674,3.76972657067534E-6,250.0092468,250.0092468,58522.69921875,58572.67578125,57.3918556530445,20.6126949616292,24.047956,0,0,0,40,4449,250.07745,58547.6875,,,,,,,,,,,,,0,,,,0,,,,,,250.0092468,,,,
,31614070.305,250.0094299,63483.119140625,-0.000140298623702279,2.91004293315566E-6,1,0.999253354069792,40.0298881530762,1.99602649304029,19.1799998283386,-0.00159545050285164,-0.000235556820889214,0.25,3.52516474894493E-6,-0.000140547812308988,3.41733562392799E-6,250.0094299,250.0094299,63475.62890625,63490.609375,57.2402197203138,20.6152843244606,24.807261,0,0,0,40,4449,250.06685,63483.119140625,,,,,,,,,,,,,0,,,,0.0049,,,,,,250.0094299,,,,
,31614169.655,250.0094299,68451.02734375,-0.000157097541907207,2.92702978503862E-6,1,0.999253354069792,40.0298881530762,1.99602109089859,19.1799998283386,-0.00178090680972936,-0.000295901542410737,0.25,1.10840276279584E-6,-0.000157374281253045,9.82879448099789E-7,250.0094299,250.0094299,68448.5859375,68453.46875,57.1151591572368,20.6174960656316,24.807261,0,0,0,40,4449,250.0613,68451.02734375,,,,,,,,,,,,,0,,,,-0.0049,,,,,,250.0094299,,,,
,31614268.68,250.0124664,73401.2265625,-0.000177346611153428,3.07291547773951E-6,1,0.999253354069792,40.0298881530762,1.99599480596787,19.1799998283386,-0.00200821846054775,-0.00034679864145107,0.25,1.23970807809912E-7,-0.000177658111544528,-1.94857168965961E-8,250.0124664,250.0124664,73396.046875,73406.40625,57.3816944822945,20.6190083953869,24.047956,0,0,0,40,4449,250.0509,73401.2265625,,,,,,,,,,,,,0,,,,0.00245,,,,,,250.0124664,,,,
,31614368.47,250.0136261,78389.3515625,-0.000197075051460049,2.51617783751767E-6,1,0.999253354069792,40.0298881530762,1.99615877743561,19.1799998283386,-0.00223189157108442,-0.000384835957236398,0.25,1.87988684292136E-7,-0.000197421264149679,2.89164668596306E-8,250.0136261,250.0136261,78384.1796875,78394.5234375,57.5825730117369,20.61926473419,24.427608,0,0,0,40,4449,250.0395,78389.3515625,,,,,,,,,,,,,0,,,,-0.0049,,,,,,250.0136261,,,,
,31614466.14,250.0134583,83270.34375,-0.000209508324846366,3.03292374677043E-6,1,0.999253354069792,40.0298881530762,1.9961461455573,19.1799998283386,-0.00237741281926953,-0.000381850810085159,0.25,2.60718156257374E-6,-0.000209878354682379,2.4425735649164E-6,250.0134583,250.0134583,83267.7578125,83272.9296875,57.1862873524868,20.6126159897235,24.807261,0,0,0,40,4449,250.0346,83270.34375,,,,,,,,,,,,,0,,,,0,,,,,,250.0134583,,,,
,31614560.78,250.01425935,88003.22265625,-0.000226545273411969,3.14139857560345E-6,1,0.999253354069792,40.0298881530762,1.99603637434561,19.1799998283386,-0.0025735463734011,-0.000395925821159617,0.25,4.31636527111511E-6,-0.000226946621544629,4.14128156947085E-6,250.0142212,250.0142975,87970.859375,88035.5859375,57.1722180391407,20.615367735808,24.427608,0,0,0,40,4449,250.0208,88003.22265625,,,,,,,,,,,,,0,,,,0,,,,,,250.01425935,,,,
,31614669.475,250.014389,87323.4453125,-0.000224803137246131,3.6848955379075E-6,1,0.999253354069792,40.0298881530762,1.99612749089975,19.1799998283386,-0.00255436864212441,-0.000390005193122806,0.25,4.53872879604001E-6,-0.000225201599142171,4.36538559011131E-6,250.0137634,250.0150146,87298.328125,87348.5625,57.2777378892368,20.6136125176871,24.047956,0,0,0,40,4449,250.00555,87323.4453125,,,,,,,,,,,,,0,,,,-0.0049,,,,,,250.014389,,,,
,31614765.705,250.0034027,82512.578125,-0.000209441708950431,2.6579675074744E-6,1,0.999253354069792,40.0298881530762,1.99604509867641,19.1799998283386,-0.00237600959657316,-0.000384786173138527,0.25,2.33482757017824E-6,-0.000209811470741331,2.16973158055465E-6,250.0030365,250.0037689,82485.25,82539.90625,57.3097846585253,20.6145076056705,24.427608,0,0,0,40,4449,250.00765,82512.578125,,,,,,,,,,,,,0,,,,-0.00245,,,,,,250.0034027,,,,
,31614865.25,249.9891052,77533.859375,-0.000188334477944389,3.21477750757293E-6,1,0.999253354069792,40.0298881530762,1.99611655316687,19.1799998283386,-0.00213855458719534,-0.000334936479619124,0.25,3.07861928196071E-6,-0.000188667839659484,2.93163485155731E-6,249.9891052,249.9891052,77531.4921875,77536.2265625,57.2621053188522,20.6157906674443,24.427608,0,0,0,40,4449,250.0155,77533.859375,,,,,,,,,,,,,0,,,,-0.0049,,,,,,249.9891052,,,,
,31614965.67,249.9881592,72515.140625,-0.000175885359840974,3.77929153041438E-6,1,0.999253354069792,40.0298881530762,1.9961564275753,19.1799998283386,-0.00198843238975136,-0.000363545331320293,0.25,-1.60594626563284E-6,-0.000176193038904449,-1.75131457470343E-6,249.9881592,249.9881592,72512.578125,72517.703125,57.3543374841214,20.6189300102909,24.427608,0,0,0,40,4449,250.0281,72515.140625,,,,,,,,,,,,,0,,,,0,,,,,,249.9881592,,,,
,31615065.25,249.9898834,67537.3671875,-0.000154352646909365,2.55459861168788E-6,1,0.999253354069792,40.0298881530762,1.99620464485734,19.1799998283386,-0.00175291440840802,-0.000273631099169956,0.25,2.60152213509107E-6,-0.000154625881133367,2.48079846187574E-6,249.9898834,249.9898834,67534.625,67540.109375,57.3066581444484,20.6149126105663,24.427608,0,0,0,40,4449,250.0377,67537.3671875,,,,,,,,,,,,,0,,,,0,,,,,,249.9898834,,,,
,31615164.415,249.9933548,62582.005859375,-0.000137153871821932,1.89064062897373E-6,1,0.999253354069792,40.0298881530762,1.99631406333734,19.1799998283386,-0.00155836343492458,-0.000239194110750022,0.25,2.6615400417766E-6,-0.000137396912145868,2.55470898736505E-6,249.9931641,249.9935455,62551.86328125,62612.1484375,57.4098331089868,20.6180520749565,24.047956,0,0,0,40,4449,250.04655,62582.005859375,,,,,,,,,,,,,0,,,,0,,,,,,249.9933548,,,,
,31615262.3,249.9911041,57688.041015625,-0.000121327485481162,2.65596607193629E-6,1,0.999253354069792,40.0298881530762,1.99617444845161,19.1799998283386,-0.00137320368904916,-0.000241829424357194,0.25,-3.16948871113681E-7,-0.00012154030182066,-4.1629559737329E-7,249.9911041,249.9911041,57658.3984375,57717.68359375,57.146424298006,20.6173023214472,24.807261,0,0,0,40,4449,250.0502,57688.041015625,,,,,,,,,,,,,0,,,,0,,,,,,249.9911041,,,,
,31615359.955,249.98957825,52808.3125,-0.000103431593791318,2.67116076298073E-6,1,0.999253354069792,40.0298881530762,1.99620696746339,19.1799998283386,-0.00117249939696199,-0.000195632169104367,0.25,6.59891362304737E-7,-0.000103613769516635,5.76707096938499E-7,249.989502,249.9896545,52775.9921875,52840.6328125,57.5184794731599,20.6204826279854,24.427608,0,0,0,40,4449,250.05975,52808.3125,,,,,,,,,,,,,0,,,,0,,,,,,249.98957825,,,,
,31615456.4,249.9918213,47987.96484375,-8.79880803579706E-5,2.69233438830758E-6,1,0.999253354069792,40.0298881530762,1.99627474747318,19.1799998283386,-0.000999740690992742,-0.00015329909035669,0.25,1.72082042510764E-6,-8.81439841456541E-5,1.65198875013508E-6,249.9918213,249.9918213,47962.99609375,48012.93359375,57.5044101598138,20.6154607653385,24.807261,0,0,0,40,4449,250.0677,47987.96484375,,,,,,,,,,,,,0,,,,-0.00245,,,,,,249.9918213,,,,
,31615552.36,249.9926147,43190.306640625,-7.07733438568214E-5,1.94681456515106E-6,1,0.999253354069792,40.0298881530762,1.99622297167169,19.1799998283386,-0.000801534162583617,-0.000138231059749903,0.25,6.59331205141291E-8,-7.08976574655488E-5,8.16874722562253E-9,249.9926147,249.9926147,43185.375,43195.23828125,57.2636685758907,20.6208581462468,24.807261,0,0,0,40,4449,250.0631,43190.306640625,,,,,,,,,,,,,0,,,,0,,,,,,249.9926147,,,,
,31615647.155,249.98716735,38452.796875,-5.37227553771542E-5,2.02264343861319E-6,1,0.999253354069792,40.0298881530762,1.99630729610819,19.1799998283386,-0.000609092925875033,-0.000101251808188877,0.25,3.75176410398915E-7,-5.3817390051764E-5,3.31843102749487E-7,249.9868927,249.987442,38417.609375,38487.984375,57.4622022197753,20.618779495432,24.807261,0,0,0,40,4449,250.08805,38452.796875,,,,,,,,,,,,,0,,,,0,,,,,,249.98716735,,,,
,31615742.76,249.9904785,33675.43359375,-3.64973242838326E-5,1.99841860087095E-6,1,0.999253354069792,40.0298881530762,1.99619294189906,19.1799998283386,-0.000415236299340223,-6.03468806171231E-5,0.25,9.99948591965544E-7,-3.65622180872385E-5,9.71776744353009E-7,249.9904785,249.9904785,33675.43359375,33675.43359375,57.5388018146599,20.6209284024246,24.427608,0,0,0,40,4449,250.0914,33675.43359375,,,,,,,,,,,,,0,,,,0.0049,,,,,,249.9904785,,,,
,31615838.62,249.9928436,28885.1435546875,-2.16570134433978E-5,1.72999161092791E-6,1,0.999253354069792,40.0298881530762,1.99623986379814,19.1799998283386,-0.000246431290603077,-3.56353202606735E-5,0.25,6.08788775834026E-7,-2.16955294058386E-5,5.92075469957322E-7,249.9925842,249.993103,28857.48828125,28912.798828125,57.4262473078907,20.6191348200491,24.807261,0,0,0,40,4449,250.09605,28885.1435546875,,,,,,,,,,,,,0,,,,0.0049,,,,,,249.9928436,,,,
,31615935.415,249.98994445,24045.208984375,-5.1074375773804E-6,1.14520513080077E-6,1,0.999253354069792,40.0298881530762,1.99612291799699,19.1799998283386,-5.86763516621501E-5,-5.15721395095235E-6,0.25,4.30277779579509E-7,-5.11675669849557E-6,4.26834153102035E-7,249.9899292,249.9899597,24015.271484375,24075.146484375,57.5270773868715,20.6202991165264,24.427608,0,0,0,40,4449,250.1046,24045.208984375,,,,,,,,,,,,,0,,,,0.00245,,,,,,249.98994445,,,,
,31616032.23,249.99235535,19207.818359375,9.85858511436846E-6,1.43905644712261E-6,1,0.999253354069792,40.0298881530762,1.996513214095,19.1799998283386,0.000111453180477874,2.0493990483484E-5,0.25,9.99034213862444E-8,9.87580627617773E-6,1.08193564393301E-7,249.9923401,249.9923706,19177.923828125,19237.712890625,57.4809613042369,20.6158232423438,24.807261,0,0,0,40,4449,250.11425,19207.818359375,,,,,,,,,,,,,0,,,,0.00245,,,,,,249.99235535,,,,
,31616128.325,249.9936142,14403.166015625,2.39516754682019E-5,7.61019798106923E-7,1,0.999253354069792,40.0298881530762,1.99636674396685,19.1799998283386,0.000269668982983597,5.60738356321611E-5,0.25,7.97843473630964E-7,2.39930532509263E-5,8.18982488262192E-7,249.9935455,249.9936829,14375.6552734375,14430.6767578125,57.4051433378714,20.6220800088402,24.047956,0,0,0,40,4449,250.11275,14403.166015625,,,,,,,,,,,,,0,,,,0.00245,,,,,,249.9936142,,,,
,31616224.7,249.9931641,9588.24267578125,3.71676409792879E-5,7.55256401124272E-7,1,0.999253354069792,40.0298881530762,1.99637527991915,19.1799998283386,0.000420085153052924,7.7687179408058E-5,0.25,4.14398409197168E-7,3.72325253341534E-5,4.45789124627082E-7,249.9931641,249.9931641,9583.2138671875,9593.271484375,57.5528711280061,20.622527009689,24.047956,0,0,0,40,4449,250.11975,9588.24267578125,,,,,,,,,,,,,0,,,,0,,,,,,249.9931641,,,,
,31616318.57,249.990921,4897.59594726562,4.49880694740444E-5,4.38971651383431E-7,1,0.999253354069792,40.0298881530762,1.99651271082545,19.1799998283386,0.000509879142349114,8.61361615101519E-5,0.25,-1.96304037923046E-7,4.5067181629494E-5,-1.59497352646155E-7,249.990921,249.990921,4895.23828125,4899.95361328125,57.4043617093522,20.6200595421571,24.427608,0,0,0,40,4449,250.1241,4897.59594726562,,,,,,,,,,,,,0,,,,0,,,,,,249.990921,,,,
,31616406.895,249.99362945,478.766784667969,3.51094749000833E-5,3.43571247133358E-7,1,0.999253354069792,40.0298881530762,1.9963394393306,19.1799998283386,0.000397525800850575,6.92910027663129E-5,0.25,2.99649683137698E-8,3.51710583346661E-5,5.90323642736891E-8,249.9934387,249.9938202,451.134094238281,506.399475097656,57.3371416566984,20.6236306139579,24.047956,0,0,0,40,4449,250.12605,478.766784667969,,,,,,,,,,,,,0,,,,0.00245,,,,,,249.99362945,,,,
,31616498.395,249.9989014,-4089.77392578125,-4.17188814622543E-5,4.34236429491415E-7,1,0.999253354069792,40.0298881530762,1.99650221794155,19.1799998283386,-0.000472607085177164,-8.11317288187106E-5,0.25,7.11975651047857E-8,-4.17921408684559E-5,3.68672720412722E-8,249.9984894,249.9993134,-4122.37060546875,-4057.17724609375,57.3816944822945,20.6195021114976,24.047956,0,0,0,40,4449,250.13375,-4089.77392578125,,,,,,,,,,,,,0,,,,0,,,,,,249.9989014,,,,
,31616591.715,249.9989624,-8756.12255859375,-3.84013463641281E-5,4.79971268094306E-7,1,0.999253354069792,40.0298881530762,1.99646784200114,19.1799998283386,-0.000434141401204286,-7.97316794049632E-5,0.25,-3.80669244224538E-7,-3.84684151383816E-5,-4.13022670980618E-7,249.9989624,249.9989624,-8781.25,-8730.9951171875,57.352774227083,20.6225727779081,24.427608,0,0,0,40,4449,250.1306,-8756.12255859375,,,,,,,,,,,,,0,,,,-0.00245,,,,,,249.9989624,,,,
,31616685.88,250.0050507,-13462.0991210938,-2.59427244079146E-5,8.5210797661013E-7,1,0.999253354069792,40.0298881530762,1.99651342129411,19.1799998283386,-0.000292177119568624,-6.03310981056212E-5,0.25,-8.28113425184577E-7,-2.59875604332398E-5,-8.50949632461125E-7,250.0050507,250.0050507,-13494.658203125,-13429.5400390625,57.6052402387946,20.6224935805737,24.427608,0,0,0,40,4449,250.1249,-13462.0991210938,,,,,,,,,,,,,0,,,,0.00245,,,,,,250.0050507,,,,
,31616780.765,250.010437,-18204.5400390625,-1.39101687141068E-5,1.07467730359998E-6,1,0.999253354069792,40.0298881530762,1.99643560355703,19.1799998283386,-0.0001552307971531,-4.05652404157452E-5,0.25,-1.16967956362986E-6,-1.39336110168979E-5,-1.18318404521722E-6,250.0102081,250.0106659,-18207.16015625,-18201.919921875,57.6208728091792,20.622018068564,24.427608,0,0,0,40,4449,250.12085,-18204.5400390625,,,,,,,,,,,,,0,,,,-0.00245,,,,,,250.010437,,,,
,31616876.205,250.0082855,-22974.58203125,2.69905195120786E-6,1.43697296037909E-6,1,0.999253354069792,40.0298881530762,1.99649041463333,19.1799998283386,3.33093190286384E-5,-1.05139215524407E-5,0.25,-1.39645995637669E-6,2.70493627585417E-6,-1.39669077708891E-6,250.0082855,250.0082855,-22999.556640625,-22949.607421875,57.7365538300253,20.6223417902788,24.807261,0,0,0,40,4449,250.10945,-22974.58203125,,,,,,,,,,,,,0,,,,-0.00245,,,,,,250.0082855,,,,
,31616971.825,250.00398255,-27752.1376953125,1.84793732741686E-5,1.49815079968016E-6,1,0.999253354069792,40.0298881530762,1.99648052922044,19.1799998283386,0.000211299197649314,2.46346615734719E-5,0.25,-1.02945145654824E-6,1.85126491448837E-5,-1.01608170813268E-6,250.0035858,250.0043793,-27782.083984375,-27722.19140625,57.4731450190445,20.6265316239727,24.427608,0,0,0,40,4449,250.1131,-27752.1376953125,,,,,,,,,,,,,0,,,,0,,,,,,250.00398255,,,,
,31617068.78,250.0103989,-32598.994140625,3.3673327426567E-5,1.63345043175007E-6,1,0.999253354069792,40.0298881530762,1.99629934982645,19.1799998283386,0.00038261007900846,5.86576924446644E-5,0.25,-6.59655307828796E-7,3.37329598754774E-5,-6.33194472469908E-7,250.0096741,250.0111237,-32634.240234375,-32563.748046875,57.9210181605638,20.6286059338947,24.047956,0,0,0,40,4449,250.10425,-32598.994140625,,,,,,,,,,,,,0,,,,-0.0049,,,,,,250.0103989,,,,
,31617165.99,250.01275635,-37456.03515625,4.93304099867765E-5,1.66926938518706E-6,1,0.999253354069792,40.0298881530762,1.9963643489417,19.1799998283386,0.00056285327917578,7.25355623271777E-5,0.25,-2.14951795768473E-6,4.94187396130281E-5,-2.11288360523789E-6,250.0125732,250.0129395,-37481.01953125,-37431.05078125,57.5872627828522,20.6260740246617,24.807261,0,0,0,40,4449,250.0905,-37456.03515625,,,,,,,,,,,,,0,,,,0.00245,,,,,,250.01275635,,,,
,31617261.83,250.014801,-42246.06640625,6.59426751603635E-5,1.87556893960831E-6,1,0.999253354069792,40.0298881530762,1.99630778218811,19.1799998283386,0.000751884283840571,9.97986862019954E-5,0.25,-2.62259662584169E-6,6.6060545232615E-5,-2.57325864419898E-6,250.0142517,250.0153503,-42278.61328125,-42213.51953125,57.6013320961984,20.6279280724752,24.427608,0,0,0,40,4449,250.07945,-42246.06640625,,,,,,,,,,,,,0,,,,-0.0049,,,,,,250.014801,,,,
,31617358.055,250.01371765,-47056.28515625,8.51636109450508E-5,2.21897431370657E-6,1,0.999253354069792,40.0298881530762,1.99640006324771,19.1799998283386,0.000967521260009933,0.000149449998571528,0.25,-1.57172301852248E-6,8.53143649758493E-5,-1.50491418297121E-6,250.0132904,250.0141449,-47086.046875,-47026.5234375,57.6052402387946,20.628243490198,24.427608,0,0,0,40,4449,250.06465,-47056.28515625,,,,,,,,,,,,,0,,,,0,,,,,,250.01371765,,,,
,31617455.45,250.0112991,-51923.3359375,9.96296624387375E-5,2.01904667462517E-6,1,0.999253354069792,40.0298881530762,1.99637499724486,19.1799998283386,0.00112974988401232,0.000186960858706822,0.25,-7.67696850296328E-7,9.98051699027299E-5,-6.87779630015264E-7,250.0108337,250.0117645,-51948.30859375,-51898.36328125,57.3660619119099,20.6256427855881,24.427608,0,0,0,40,4449,250.06035,-51923.3359375,,,,,,,,,,,,,0,,,,0,,,,,,250.0112991,,,,
,31617552.9,250.0096283,-56792.94140625,0.000119255144808342,2.26031440792518E-6,1,0.999253354069792,40.0298881530762,1.9964039726182,19.1799998283386,0.00135405054998044,0.000213766277837146,0.25,-1.80412270495364E-6,0.000119465967138172,-1.71015831270424E-6,250.0096283,250.0096283,-56825.37109375,-56760.51171875,57.5145713305638,20.6262107820293,24.047956,0,0,0,40,4449,250.04675,-56792.94140625,,,,,,,,,,,,,0,,,,-0.00245,,,,,,250.0096283,,,,
,31617649.22,250.0104523,-61607.486328125,0.000133214885074104,2.48219374336289E-6,1,0.999253354069792,40.0298881530762,1.99635647840645,19.1799998283386,0.00151415964008211,0.000229319879649665,0.25,-2.850874783793E-6,0.000133451076867781,-2.74754010421728E-6,250.0104523,250.0104523,-61637.34765625,-61577.625,57.6693337773715,20.6270181293179,24.427608,0,0,0,40,4449,250.04045,-61607.486328125,,,,,,,,,,,,,0,,,,-0.00245,,,,,,250.0104523,,,,
,31617744.93,250.01602935,-66387.63671875,0.000151529523642684,2.54691888260476E-6,1,0.999253354069792,40.0298881530762,1.99658323217001,19.1799998283386,0.00171863376990342,0.000283261539559211,0.25,-1.26602900904543E-6,0.000151796568269426,-1.14519907574692E-6,250.0155945,250.0164642,-66420.1328125,-66355.140625,57.6927826329484,20.6224944603213,24.427608,0,0,0,40,4449,250.0286,-66387.63671875,,,,,,,,,,,,,0,,,,-0.0049,,,,,,250.01602935,,,,
,31617839.055,250.0151672,-71095.08203125,0.000167362910187158,3.07369120375706E-6,1,0.999253354069792,40.0298881530762,1.99647511238265,19.1799998283386,0.00189485791170035,0.000331636141521728,0.25,2.61285261141859E-7,0.000167656538168446,3.97454905878182E-7,250.0149841,250.0153503,-71127.5390625,-71062.625,57.65057469291,20.6249726085969,24.807261,0,0,0,40,4449,250.0156,-71095.08203125,,,,,,,,,,,,,0,,,,0,,,,,,250.0151672,,,,
,31617935.615,250.0127716,-75919.55859375,0.000184711115970617,2.72789636487158E-6,1,0.999253354069792,40.0298881530762,1.99639429416436,19.1799998283386,0.00209428023412296,0.000348185700706007,0.25,-1.28432249700679E-6,0.000185036495170527,-1.1370300835769E-6,250.0127716,250.0127716,-75924.5703125,-75914.546875,57.5083183024099,20.6288815819473,24.427608,0,0,0,40,4449,250.00595,-75919.55859375,,,,,,,,,,,,,0,,,,-0.0049,,,,,,250.0127716,,,,
,31618033.01,250.0163574,-80787.0546875,0.000205432590305152,2.86198852139663E-6,1,0.999253354069792,40.0298881530762,1.99640607955311,19.1799998283386,0.00233386841883647,0.000360536216815355,0.25,-3.78693302430897E-6,0.00020579637849756,-3.62751733038789E-6,250.0163574,250.0163574,-80792.15625,-80781.953125,57.738898715583,20.628624478611,24.427608,0,0,0,40,4449,249.9931,-80787.0546875,,,,,,,,,,,,,0,,,,-0.0049,,,,,,250.0163574,,,,
,31618127.67,250.012558,-85519.30859375,0.000221508882997801,3.02330369106519E-6,1,0.999253354069792,40.0298881530762,1.99635979894856,19.1799998283386,0.00251691265906548,0.000386085885410571,0.25,-4.31753764433939E-6,0.000221901383904461,-4.14633345142206E-6,250.012558,250.012558,-85549.4140625,-85489.203125,57.5528711280061,20.6317091160647,24.807261,0,0,0,40,4449,249.98085,-85519.30859375,,,,,,,,,,,,,0,,,,-0.00245,,,,,,250.012558,,,,
,31618232.695,250.0117874,-89955.7109375,0.000236847580671014,2.6625161665073E-6,1,0.999253354069792,40.0298881530762,1.99670990803091,19.1799998283386,0.00268646768229146,0.000442779567049179,0.25,-1.97726675088432E-6,0.000237265165523635,-1.78985260036947E-6,250.0116577,250.0119171,-89980.3203125,-89931.1015625,57.4629838482945,20.6228882079122,24.427608,0,0,0,40,4449,249.9727,-89955.7109375,,,,,,,,,,,,,0,,,,0.00245,,,,,,250.0117874,,,,
,31618325.075,250.0059662,-85355.65625,0.000220216340651819,3.0522905098331E-6,1,0.999253354069792,40.0298881530762,1.99652531879103,19.1799998283386,0.00249732289589173,0.000413284041904059,0.25,-1.69456832075989E-6,0.000220604504246414,-1.51978069493144E-6,250.0059662,250.0059662,-85380.890625,-85330.421875,57.5724118409869,20.623935033997,24.047956,0,0,0,40,4449,249.96785,-85355.65625,,,,,,,,,,,,,0,,,,0,,,,,,250.0059662,,,,
,31618420.62,249.99451445,-80578.18359375,0.000199309507884751,2.79440699803884E-6,1,0.999253354069792,40.0298881530762,1.99662373559698,19.1799998283386,0.00225777947166577,0.000388830155915974,0.25,-2.30304327808141E-7,0.000199659822178341,-6.95697940898149E-8,249.9944763,249.9945526,-80608.140625,-80548.2265625,57.3043132588907,20.6224847042963,24.427608,0,0,0,40,4449,249.9769,-80578.18359375,,,,,,,,,,,,,0,,,,0.0049,,,,,,249.99451445,,,,
,31618517.585,249.9929047,-75732.875,0.000186039439582085,3.3327331562551E-6,1,0.999253354069792,40.0298881530762,1.99656738256249,19.1799998283386,0.00211053236199026,0.000344863386599039,0.25,-1.81060844348616E-6,0.000186367706579432,-1.66313866311745E-6,249.9926453,249.9931641,-75760.6015625,-75705.1484375,57.3660619119099,20.6226747647559,24.807261,0,0,0,40,4449,249.98045,-75732.875,,,,,,,,,,,,,0,,,,0,,,,,,249.9929047,,,,
,31618613.77,249.9883194,-70928.24609375,0.000167300032458816,2.79748192197018E-6,1,0.999253354069792,40.0298881530762,1.99645136019137,19.1799998283386,0.00189810379357143,0.000308571217464965,0.25,-1.76420202066142E-6,0.000167595350695164,-1.63161925857273E-6,249.988205,249.9884338,-70958.3125,-70898.1796875,57.5950790680446,20.6243463750813,24.427608,0,0,0,40,4449,249.99285,-70928.24609375,,,,,,,,,,,,,0,,,,0,,,,,,249.9883194,,,,
,31618712.225,249.9897156,-66006.140625,0.000150307104783581,3.25678138394869E-6,1,0.999253354069792,40.0298881530762,1.9964783078705,19.1799998283386,0.00170193150850388,0.000296842447681664,0.25,1.46358083173828E-7,0.000150570994369085,2.6870485952413E-7,249.9897156,249.9897156,-66036.046875,-65976.234375,57.5130080735253,20.6243130198119,25.186911,0,0,0,40,4449,250.00275,-66006.140625,,,,,,,,,,,,,0,,,,0,,,,,,249.9897156,,,,
,31618809.26,249.9914703,-61156.478515625,0.000134456848624802,2.32408037344532E-6,1,0.999253354069792,40.0298881530762,1.99644864347204,19.1799998283386,0.00152658522624613,0.00024161320569656,0.25,-1.98166032300887E-6,0.000134694601939036,-1.87575825673006E-6,249.9914703,249.9914703,-61188.78125,-61124.17578125,57.4410982497561,20.621001777542,24.427608,0,0,0,40,4449,250.00755,-61156.478515625,,,,,,,,,,,,,0,,,,0.00245,,,,,,249.9914703,,,,
,31618906.275,249.9911346,-56309.185546875,0.000116236541093801,2.06039854357707E-6,1,0.999253354069792,40.0298881530762,1.99642392053599,19.1799998283386,0.00132010971059999,0.000206514188265719,0.25,-1.92125475934243E-6,0.000116442233876825,-1.82992875610952E-6,249.9911346,249.9911346,-56336.5390625,-56281.83203125,57.4012351952753,20.6229338212218,24.047956,0,0,0,40,4449,250.0183,-56309.185546875,,,,,,,,,,,,,0,,,,-0.00245,,,,,,249.9911346,,,,
,31619000.49,249.9889984,-51599.650390625,0.000101054138229886,2.39781608080399E-6,1,0.999253354069792,40.0298881530762,1.99650752080547,19.1799998283386,0.00114761520041295,0.000180194873250971,0.25,-1.61323726731729E-6,0.000101232914132842,-1.53362118011328E-6,249.9889984,249.9889984,-51624.7734375,-51574.52734375,57.5505262424484,20.6198871335616,24.427608,0,0,0,40,4449,250.02395,-51599.650390625,,,,,,,,,,,,,0,,,,-0.00245,,,,,,249.9889984,,,,
,31619098.715,249.9874954,-46689.759765625,8.3353168983817E-5,2.08107200591533E-6,1,0.999253354069792,40.0298881530762,1.99645325327981,19.1799998283386,0.000946548659900401,0.000148754025009739,0.25,-1.31958325350882E-6,8.35006159397034E-5,-1.25379440607461E-6,249.9874115,249.9875793,-46722.16015625,-46657.359375,57.7459333722561,20.6209647891995,24.427608,0,0,0,40,4449,250.0336,-46689.759765625,,,,,,,,,,,,,0,,,,0,,,,,,249.9874954,,,,
,31619195.545,249.9885101,-41850.310546875,6.66168864440237E-5,2.00384816989092E-6,1,0.999253354069792,40.0298881530762,1.99637229436407,19.1799998283386,0.000761312481317012,9.09233196650661E-5,0.25,-3.5235544286174E-6,6.67367383169289E-5,-3.47523355229838E-6,249.9884033,249.9886169,-41880.3125,-41820.30859375,57.7099784603715,20.6270391904395,24.047956,0,0,0,40,4449,250.04335,-41850.310546875,,,,,,,,,,,,,0,,,,0,,,,,,249.9885101,,,,
,31619291.445,249.990097,-37057.474609375,5.04357857167472E-5,1.58682934317479E-6,1,0.999253354069792,40.0298881530762,1.99640824961983,19.1799998283386,0.000571942499206068,9.45495548553321E-5,0.25,-3.97442687786221E-7,5.0524659600569E-5,-3.56816608092943E-7,249.990097,249.990097,-37082.64453125,-37032.3046875,57.332451885583,20.6211364336705,24.807261,0,0,0,40,4449,250.05395,-37057.474609375,,,,,,,,,,,,,0,,,,0,,,,,,249.990097,,,,
,31619388.78,249.9858093,-32193.439453125,3.34211180111244E-5,1.53843343480001E-6,1,0.999253354069792,40.0298881530762,1.99638055138818,19.1799998283386,0.000380023307917954,5.66991121586672E-5,0.25,-7.89083234373435E-7,3.34804426604176E-5,-7.63048903185625E-7,249.9858093,249.9858093,-32196.115234375,-32190.763671875,57.6185279236215,20.6187323451289,24.427608,0,0,0,40,4449,250.0658,-32193.439453125,,,,,,,,,,,,,0,,,,0,,,,,,249.9858093,,,,
,31619484.27,249.9916077,-27423.5419921875,1.89818798870797E-5,1.3339466532597E-6,1,0.999253354069792,40.0298881530762,1.99657252811341,19.1799998283386,0.000218251207070058,1.84060273180386E-5,0.25,-1.6666671463969E-6,1.90165692365223E-5,-1.6539992460613E-6,249.9916077,249.9916077,-27458.546875,-27388.537109375,57.3504293415253,20.615888332089,24.807261,0,0,0,40,4449,250.0721,-27423.5419921875,,,,,,,,,,,,,0,,,,0,,,,,,249.9916077,,,,
,31619578.87,249.9870224,-22693.51171875,2.0837653378992E-6,1.15456399998898E-6,1,0.999253354069792,40.0298881530762,1.99650139694127,19.1799998283386,2.61090216163034E-5,-1.03825739859304E-5,0.25,-1.27815249694236E-6,2.08847453002761E-6,-1.27868223276707E-6,249.9869232,249.9871216,-22725.732421875,-22661.291015625,57.7654740852369,20.6191966268491,24.807261,0,0,0,40,4449,250.0753,-22693.51171875,,,,,,,,,,,,,0,,,,0,,,,,,249.9870224,,,,
,31619675.125,249.98993685,-17883.6240234375,-1.31633793403522E-5,9.81495272927744E-7,1,0.999253354069792,40.0298881530762,1.99644014320044,19.1799998283386,-0.000148861975977374,-2.70593768137593E-5,0.25,-1.06574593916683E-7,-1.31863959767197E-5,-1.17601807064744E-7,249.9898529,249.9900208,-17913.5859375,-17853.662109375,57.4622022197753,20.6194888686024,24.807261,0,0,0,40,4449,250.0856,-17883.6240234375,,,,,,,,,,,,,0,,,,-0.00245,,,,,,249.98993685,,,,
,31619771.425,249.98994445,-13070.8813476563,-2.74763419737173E-5,9.34534671446083E-7,1,0.999253354069792,40.0298881530762,1.99643102776243,19.1799998283386,-0.000309525180789914,-6.33883193071001E-5,0.25,-8.32310179536629E-7,-2.75238793940654E-5,-8.56424051581979E-7,249.989624,249.9902649,-13106.240234375,-13035.5224609375,57.5372385576215,20.6208045425261,24.807261,0,0,0,40,4449,250.0908,-13070.8813476563,,,,,,,,,,,,,0,,,,0,,,,,,249.98994445,,,,
,31619868.33,249.9896851,-8225.3515625,-4.0277128543327E-5,6.52979518234693E-7,1,0.999253354069792,40.0298881530762,1.99626454242189,19.1799998283386,-0.000455344980926115,-8.33801443473268E-5,0.25,-3.78230964426246E-7,-4.03475030258466E-5,-4.12136883859348E-7,249.9896851,249.9896851,-8257.9560546875,-8192.7470703125,57.3605905122753,20.6215515856206,24.427608,0,0,0,40,4449,250.09855,-8225.3515625,,,,,,,,,,,,,0,,,,-0.00245,,,,,,249.9896851,,,,
,31619963.275,249.99354555,-3482.4677734375,-4.38134303188531E-5,3.93042880615711E-7,1,0.999253354069792,40.0298881530762,1.99636104099275,19.1799998283386,-0.000495251556335657,-9.12534486778049E-5,0.25,-4.59834220120297E-7,-4.38899334080056E-5,-4.96836409028212E-7,249.9932404,249.9938507,-3514.7783203125,-3450.1572265625,57.6701154058907,20.6212953440295,24.427608,0,0,0,40,4449,250.0983,-3482.4677734375,,,,,,,,,,,,,0,,,,0,,,,,,249.99354555,,,,
,31620056.01,249.9985199,1154.60729980469,1.80711602947308E-5,4.26761225894037E-7,1,0.999253354069792,40.0298881530762,1.99629147821412,19.1799998283386,0.000204898505726613,3.39735106298452E-5,0.25,-1.33851363700297E-7,1.81029780041878E-5,-1.19151648416805E-7,249.9985199,249.9985199,1132.11865234375,1177.09594726562,57.3543374841214,20.6210413301308,24.427608,0,0,0,40,4449,250.10145,1154.60729980469,,,,,,,,,,,,,0,,,,0.0049,,,,,,249.9985199,,,,
,31620149.615,249.9973831,5830.59619140625,4.25735585401643E-5,3.89715266716532E-7,1,0.999253354069792,40.0298881530762,1.99630827811348,19.1799998283386,0.000482760430394868,7.98112687354274E-5,0.25,-3.35357287430145E-7,4.26485387969034E-5,-3.0079178806425E-7,249.9970703,249.9976959,5797.9482421875,5863.244140625,57.3910740245253,20.6178147901787,24.427608,0,0,0,40,4449,250.1051,5830.59619140625,,,,,,,,,,,,,0,,,,0.00245,,,,,,249.9973831,,,,
,31620245.865,250.0018921,10644.1040039062,3.37878231443942E-5,6.79029880637506E-7,1,0.999253354069792,40.0298881530762,1.9962808474086,19.1799998283386,0.000382151360256534,6.89833112499204E-5,0.25,2.32225542513189E-7,3.38469164052233E-5,2.60504307567266E-7,250.0018921,250.0018921,10611.7177734375,10676.490234375,57.4575124486599,20.6199972987138,24.047956,0,0,0,40,4449,250.09855,10644.1040039062,,,,,,,,,,,,,0,,,,0,,,,,,250.0018921,,,,
,31620341.3,250.00292205,15411.95703125,2.04159232429745E-5,8.16753861663589E-7,1,0.999253354069792,40.0298881530762,1.99620600303193,19.1799998283386,0.000231328794927308,3.92230496260023E-5,0.25,-7.6722520819436E-8,2.04518100276141E-5,-6.00350665662216E-8,250.0025635,250.0032806,15379.419921875,15444.494140625,57.5161345876022,20.6169597552148,24.427608,0,0,0,40,4449,250.09705,15411.95703125,,,,,,,,,,,,,0,,,,0,,,,,,250.00292205,,,,
,31620436.595,250.0052643,20174.046875,6.1391977944353E-6,8.53636226300839E-7,1,0.999253354069792,40.0298881530762,1.9962140635986,19.1799998283386,6.89671391900629E-5,1.52265558693454E-5,0.25,2.80012629916527E-7,6.14973987283335E-6,2.85556516174623E-7,250.0050812,250.0054474,20146.48828125,20201.60546875,57.576319983583,20.6176038572439,24.047956,0,0,0,40,4449,250.09325,20174.046875,,,,,,,,,,,,,0,,,,0,,,,,,250.0052643,,,,
,31620531.955,250.0042725,24941.9443359375,-8.68692748977723E-6,9.24157157413891E-7,1,0.999253354069792,40.0298881530762,1.99625319556741,19.1799998283386,-0.000100077084534484,-7.20422789483589E-6,0.25,8.70294167990374E-7,-8.70288721184885E-6,8.64680941216486E-7,250.0042725,250.0042725,24939.376953125,24944.51171875,57.3136928011214,20.6167316564817,24.807261,0,0,0,40,4449,250.0896,24941.9443359375,,,,,,,,,,,,,0,,,,0.00245,,,,,,250.0042725,,,,
,31620627.03,250.0083466,29692.1611328125,-2.52608992299703E-5,1.50927396740119E-6,1,0.999253354069792,40.0298881530762,1.99609608152305,19.1799998283386,-0.000287542394259496,-4.08528946519997E-5,0.25,7.72754890031078E-7,-2.53058623112967E-5,7.53373879330758E-7,250.0083466,250.0083466,29687.15234375,29697.169921875,57.6279074658522,20.618329576627,24.427608,0,0,0,40,4449,250.0888,29692.1611328125,,,,,,,,,,,,,0,,,,-0.0049,,,,,,250.0083466,,,,
,31620722.765,250.01151275,34477.291015625,-3.99011085407165E-5,1.42755212044738E-6,1,0.999253354069792,40.0298881530762,1.99613614866544,19.1799998283386,-0.000452485825189472,-7.44106631526415E-5,0.25,3.48030597298451E-7,-3.99714138647521E-5,3.15927361001785E-7,250.0111847,250.0118408,34449.76953125,34504.8125,57.3176009437176,20.6185878378125,24.807261,0,0,0,40,4449,250.07145,34477.291015625,,,,,,,,,,,,,0,,,,-0.00245,,,,,,250.01151275,,,,
,31620821.265,250.012764,39399.4765625,-5.76141338823286E-5,1.72800277040317E-6,1,0.999253354069792,40.0298881530762,1.99638596173158,19.1799998283386,-0.000652850387091335,-0.000110814780663402,0.25,2.05878443716384E-7,-5.77154105967335E-5,1.59068424225661E-7,250.0120392,250.0134888,39366.7578125,39432.1953125,57.3269804859484,20.6165994829075,24.047956,0,0,0,40,4449,250.06185,39399.4765625,,,,,,,,,,,,,0,,,,0,,,,,,250.012764,,,,
,31620917.45,250.01139835,44207.537109375,-7.31379836355302E-5,2.06447651396554E-6,1,0.999253354069792,40.0298881530762,1.99616337191454,19.1799998283386,-0.000828621990106677,-0.000140933521509412,0.25,2.36966793365401E-7,-7.32665413677975E-5,1.77583669174134E-7,250.0111237,250.011673,44174.8125,44240.26171875,57.4598573342176,20.6193723164739,24.427608,0,0,0,40,4449,250.05155,44207.537109375,,,,,,,,,,,,,0,,,,-0.00245,,,,,,250.01139835,,,,
,31621016.135,250.01473995,49140.349609375,-9.03597123006173E-5,1.96390134838562E-6,1,0.999253354069792,40.0298881530762,1.9963321919068,19.1799998283386,-0.00102255439081823,-0.000181427893640898,0.25,-3.51526611108508E-7,-9.0518016041182E-5,-4.25917143661513E-7,250.0144653,250.0150146,49112.9375,49167.76171875,57.2988418592561,20.615140304483,24.807261,0,0,0,40,4449,250.0402,49140.349609375,,,,,,,,,,,,,0,,,,0.00245,,,,,,250.01473995,,,,
,31621112.815,250.0130463,53972.978515625,-0.000107698814283376,2.21941675519263E-6,1,0.999253354069792,40.0298881530762,1.99630357267406,19.1799998283386,-0.00122277581863216,-0.000193056765139233,0.25,1.62808578004804E-6,-0.000107889184839125,1.54314017665541E-6,250.0130463,250.0130463,53945.35546875,54000.6015625,57.4809613042369,20.6158331239455,24.807261,0,0,0,40,4449,250.02975,53972.978515625,,,,,,,,,,,,,0,,,,-0.00245,,,,,,250.0130463,,,,
,31621212.41,250.0109406,58950.630859375,-0.000125219120728634,2.37669115594931E-6,1,0.999253354069792,40.0298881530762,1.99619012200749,19.1799998283386,-0.00142013068168367,-0.000233030978443748,0.25,1.13505316855339E-6,-0.000125439867533771,1.03511085085748E-6,250.0109406,250.0109406,58948.1640625,58953.09765625,57.4473512779099,20.6159230233585,24.427608,0,0,0,40,4449,250.0152,58950.630859375,,,,,,,,,,,,,0,,,,0,,,,,,250.0109406,,,,
,31621309.135,250.0124207,63786.298828125,-0.000141712393961248,2.4041212668085E-6,1,0.999253354069792,40.0298881530762,1.99642974381346,19.1799998283386,-0.00160879876375608,-0.00025550351446351,0.25,2.01301051849394E-6,-0.000141962818614262,1.90135561774205E-6,250.0124207,250.0124207,63756.56640625,63816.03125,57.1300100991022,20.6136722742767,24.807261,0,0,0,40,4449,250.00585,63786.298828125,,,,,,,,,,,,,0,,,,0,,,,,,250.0124207,,,,
,31621406.275,250.007431,68641.44921875,-0.000159222618709858,2.52011978553501E-6,1,0.999253354069792,40.0298881530762,1.99622520772137,19.1799998283386,-0.00180360855613926,-0.000308958691049231,0.25,3.2639689515021E-7,-0.000159502463428998,1.97750434349854E-7,250.007431,250.007431,68609.09375,68673.8046875,57.4754899046022,20.6148295088787,24.807261,0,0,0,40,4449,250.00535,68641.44921875,,,,,,,,,,,,,0,,,,-0.00245,,,,,,250.007431,,,,
,31621503.485,250.0130463,73499.25390625,-0.000177677031693582,3.21142116141137E-6,1,0.999253354069792,40.0298881530762,1.99612719043366,19.1799998283386,-0.00201362153825375,-0.000338619424075362,0.25,9.05593645081383E-7,-0.000177989738107545,7.63206650729898E-7,250.0125275,250.0135651,73471.75,73526.7578125,57.2996234877753,20.6165148215511,25.186911,0,0,0,40,4449,249.99155,73499.25390625,,,,,,,,,,,,,0,,,,0.0049,,,,,,250.0130463,,,,
,31621600.6,250.01100925,78354.71875,-0.0001967016590725,3.30099745979945E-6,1,0.999253354069792,40.0298881530762,1.99607391665541,19.1799998283386,-0.00222771404678951,-0.000383275777021664,0.25,2.59697592638724E-7,-0.000197047287751724,1.01009839278919E-7,250.0105591,250.0114594,78319.71875,78389.71875,57.3996719382368,20.6197480135171,24.807261,0,0,0,40,4449,249.98325,78354.71875,,,,,,,,,,,,,0,,,,0,,,,,,250.01100925,,,,
,31621699.815,250.0164642,83313.40234375,-0.000213811586763264,2.66888812431874E-6,1,0.999253354069792,40.0298881530762,1.99605922600768,19.1799998283386,-0.00242405487506718,-0.000401721067984068,0.25,1.5971346186219E-6,-0.000214188329783081,1.42722568060941E-6,250.0164642,250.0164642,83278.5234375,83348.28125,57.1323549846599,20.6160715290133,24.427608,0,0,0,40,4449,249.96675,83313.40234375,,,,,,,,,,,,,0,,,,0.00245,,,,,,250.0164642,,,,
,31621792.85,250.0093536,87963.87890625,-0.000228632309448727,3.89800190000791E-6,1,0.999253354069792,40.0298881530762,1.99617496779558,19.1799998283386,-0.00259997589256976,-0.000384904011091937,0.25,5.65402218513586E-6,-0.000229038436718983,5.47954906879965E-6,250.0093536,250.0093536,87931.515625,87996.2421875,57.4770531616407,20.6114914465463,24.427608,0,0,0,40,4449,249.95735,87963.87890625,,,,,,,,,,,,,0,,,,-0.00245,,,,,,250.0093536,,,,
,31621900.705,250.00813295,87438.40234375,-0.000228301482202984,3.78086215434281E-6,1,0.999253354069792,40.0298881530762,1.99632608125953,19.1799998283386,-0.00258755782439588,-0.000435374251436231,0.25,1.1422699997303E-6,-0.000228703395675747,9.60103723320678E-7,250.0079041,250.0083618,87403.296875,87473.5078125,57.1776894387753,20.6143728373001,24.807261,0,0,0,40,4449,249.95405,87438.40234375,,,,,,,,,,,,,0,,,,0,,,,,,250.00813295,,,,
,31621995.61,249.996521,82692.27734375,-0.000208966199106478,3.18079196081394E-6,1,0.999253354069792,40.0298881530762,1.99649263004469,19.1799998283386,-0.00237260104144997,-0.000375471421457944,0.25,3.0821809914954E-6,-0.000209335777060554,2.91874329991355E-6,249.996521,249.996521,82689.9609375,82694.59375,57.3105662870445,20.6100547661291,24.427608,0,0,0,40,4449,249.9447,82692.27734375,,,,,,,,,,,,,0,,,,-0.00245,,,,,,249.996521,,,,
,31622089.125,249.99674225,78018.484375,-0.000195289549195051,2.62618532216949E-6,1,0.999253354069792,40.0298881530762,1.9964080739206,19.1799998283386,-0.00221532545670594,-0.000361845914279413,0.25,1.9126201035436E-6,-0.000195634131326098,1.75794215671711E-6,249.9964447,249.9970398,77995.90625,78041.0625,57.2394380917945,20.6109692239001,24.807261,0,0,0,40,4449,249.9581,78018.484375,,,,,,,,,,,,,0,,,,-0.00245,,,,,,249.99674225,,,,
,31622186.1,249.99101255,73170.1484375,-0.000176900839296499,3.18632797111756E-6,1,0.999253354069792,40.0298881530762,1.99633226913741,19.1799998283386,-0.00200792736663481,-0.000320425180947594,0.25,2.38065601705505E-6,-0.000177213514319025,2.24145863831779E-6,249.9901733,249.9918518,73137.7734375,73202.5234375,57.3168193151984,20.6129791213205,24.807261,0,0,0,40,4449,249.9683,73170.1484375,,,,,,,,,,,,,0,,,,0,,,,,,249.99101255,,,,
,31622282.715,249.9893341,68341.85546875,-0.000157985543020665,2.60150669901272E-6,1,0.999253354069792,40.0298881530762,1.99638105924817,19.1799998283386,-0.00178987166378674,-0.000305764021709721,0.25,3.96060086050413E-7,-0.000158263370807199,2.68508739582223E-7,249.9893341,249.9893341,68309.234375,68374.4765625,57.352774227083,20.6119205911316,24.047956,0,0,0,40,4449,249.97385,68341.85546875,,,,,,,,,,,,,0,,,,-0.00245,,,,,,249.9893341,,,,
,31622379.41,249.9889984,63506.46875,-0.000143089832663117,2.2850408843675E-6,1,0.999253354069792,40.0298881530762,1.99627050066558,19.1799998283386,-0.00162241038608926,-0.000268944268240731,0.25,1.06325282204847E-6,-0.000143342020892711,9.48789140180244E-7,249.9889984,249.9889984,63476.31640625,63536.62109375,57.2535074051407,20.61570036296,24.427608,0,0,0,40,4449,249.9836,63506.46875,,,,,,,,,,,,,0,,,,-0.00245,,,,,,249.9889984,,,,
,31622476.985,249.9903717,58631.095703125,-0.000123628739846469,2.87809284834532E-6,1,0.999253354069792,40.0298881530762,1.99633064177385,19.1799998283386,-0.00140118011155985,-0.000235905422710174,0.25,6.06842870146721E-7,-0.000123846353467694,5.07248625030988E-7,249.9903717,249.9903717,58608.375,58653.81640625,57.606803495833,20.6147110771025,24.807261,0,0,0,40,4449,249.99505,58631.095703125,,,,,,,,,,,,,0,,,,-0.00245,,,,,,249.9903717,,,,
,31622575.385,249.990303,53710.380859375,-0.000107672447054527,2.426102413987E-6,1,0.999253354069792,40.0298881530762,1.99640098715083,19.1799998283386,-0.00121812260937489,-0.000218459063997382,0.25,-6.1878702640241E-7,-0.0001078610249217,-7.0767321805877E-7,249.9899902,249.9906158,53685.3203125,53735.44140625,57.4270289364099,20.6134508671662,24.807261,0,0,0,40,4449,250.00445,53710.380859375,,,,,,,,,,,,,0,,,,0,,,,,,249.990303,,,,
,31622672.61,249.98480225,48852.681640625,-9.08307671745152E-5,2.55920864985037E-6,1,0.999253354069792,40.0298881530762,1.99660883121137,19.1799998283386,-0.00102745010712541,-0.000185696409299878,0.25,-6.44577818560973E-7,-9.09897537960134E-5,-7.19882557190441E-7,249.984436,249.9851685,48822.84375,48882.51953125,57.2621053188522,20.6112731994527,24.807261,0,0,0,40,4449,250.01725,48852.681640625,,,,,,,,,,,,,0,,,,-0.00245,,,,,,249.98480225,,,,
,31622770.485,249.98982235,43959.564453125,-7.40749441413523E-5,1.58972423891185E-6,1,0.999253354069792,40.0298881530762,1.99640590741591,19.1799998283386,-0.000839950045348664,-0.000139210804780309,0.25,5.53039606027998E-7,-7.42054605342872E-5,4.93433034386159E-7,249.9895782,249.9900665,43924.56640625,43994.5625,57.2886806885061,20.6143024325889,24.427608,0,0,0,40,4449,250.0236,43959.564453125,,,,,,,,,,,,,0,,,,-0.00245,,,,,,249.98982235,,,,
,31622865.57,249.9880981,39206.89453125,-5.8816027975202E-5,1.91512976565941E-6,1,0.999253354069792,40.0298881530762,1.99643038530567,19.1799998283386,-0.000668642179680536,-0.000100685783180038,0.25,1.30895321320102E-6,-5.89203681289811E-5,1.26308781427775E-6,249.9880981,249.9880981,39176.8359375,39236.953125,57.6216544376984,20.6160047108441,24.047956,0,0,0,40,4449,250.0376,39206.89453125,,,,,,,,,,,,,0,,,,0,,,,,,249.9880981,,,,
,31622961.51,249.9918213,34415.232421875,-4.20135112773979E-5,1.5380531523053E-6,1,0.999253354069792,40.0298881530762,1.99621792918931,19.1799998283386,-0.000476153644840139,-8.01186374632976E-5,0.25,2.10547901996086E-7,-4.20874397594678E-5,1.76466062767911E-7,249.9918213,249.9918213,34390.11328125,34440.3515625,57.3559007411599,20.6170631114918,24.427608,0,0,0,40,4449,250.0411,34415.232421875,,,,,,,,,,,,,0,,,,-0.00245,,,,,,249.9918213,,,,
,31623057.46,249.99054715,29617.73828125,-2.40923397783399E-5,1.49907377483182E-6,1,0.999253354069792,40.0298881530762,1.99637612133482,19.1799998283386,-0.000274327607905298,-3.86804329452734E-5,0.25,7.62431661846911E-7,-2.41352587328038E-5,7.43988064660995E-7,249.9901733,249.990921,29588.0234375,29647.453125,57.5739750980253,20.6135749153444,24.807261,0,0,0,40,4449,250.04815,29617.73828125,,,,,,,,,,,,,0,,,,0.00245,,,,,,249.99054715,,,,
,31623151.465,249.9942474,24919.787109375,-9.42256546456535E-6,1.23676055169363E-6,1,0.999253354069792,40.0298881530762,1.99631560594089,19.1799998283386,-0.000108787628856576,-6.47442682020293E-6,0.25,1.06233761729033E-6,-9.43997736039154E-6,1.05645569228219E-6,249.9942474,249.9942474,24890.203125,24949.37109375,57.4481329064291,20.6169552095139,24.427608,0,0,0,40,4449,250.05305,24919.787109375,,,,,,,,,,,,,0,,,,-0.00245,,,,,,249.9942474,,,,
,31623247.97,249.9881668,20094.9501953125,6.95018476882452E-6,1.03409030574898E-6,1,0.999253354069792,40.0298881530762,1.9962638712149,19.1799998283386,7.88351431673096E-5,1.2881706133812E-5,0.25,-6.77385370856403E-8,6.96244024203572E-6,-6.21365094540454E-8,249.9879913,249.9883423,20067.40234375,20122.498046875,57.444224763833,20.6195573421595,24.427608,0,0,0,40,4449,250.0629,20094.9501953125,,,,,,,,,,,,,0,,,,-0.00245,,,,,,249.9881668,,,,
,31623345.745,249.9910736,15210.1845703125,2.16745597718768E-5,1.10351510279999E-6,1,0.999253354069792,40.0298881530762,1.9963123336178,19.1799998283386,0.000244605925591284,4.73911346078576E-5,0.25,4.26126369936201E-7,2.17122494908221E-5,4.44736603134748E-7,249.9910736,249.9910736,15205.0908203125,15215.2783203125,57.73186405891,20.6173177122348,24.807261,0,0,0,40,4449,250.07,15210.1845703125,,,,,,,,,,,,,0,,,,0,,,,,,249.9910736,,,,
,31623440.01,249.988266,10497.6865234375,3.47448201193455E-5,6.3955841128419E-7,1,0.999253354069792,40.0298881530762,1.99637097252229,19.1799998283386,0.000394036182741534,6.49217938684714E-5,0.25,-2.92664771539879E-7,3.48060420755348E-5,-2.64514265524152E-7,249.9882355,249.9882965,10467.84375,10527.529296875,57.4145228801022,20.6208773673482,24.807261,0,0,0,40,4449,250.0804,10497.6865234375,,,,,,,,,,,,,0,,,,-0.0049,,,,,,249.988266,,,,
,31623536.57,249.99060055,5669.8125,4.37802026398093E-5,6.09432204070107E-7,1,0.999253354069792,40.0298881530762,1.99658820465347,19.1799998283386,0.000494383612206636,9.43434381456446E-5,0.25,7.37568692945225E-7,4.38564242919811E-5,7.75017666257417E-7,249.9901733,249.9910278,5644.71630859375,5694.90869140625,57.3762230826599,20.6170549985881,24.807261,0,0,0,40,4449,250.087,5669.8125,,,,,,,,,,,,,0,,,,0,,,,,,249.99060055,,,,
,31623630.555,249.98950195,973.830749511719,3.95182777284774E-5,4.43081475658392E-7,1,0.999253354069792,40.0298881530762,1.99658003851065,19.1799998283386,0.000447776068972325,7.63852741057613E-5,0.25,-1.08944349594356E-7,3.95877177843285E-5,-7.64742525250812E-8,249.9888306,249.9901733,946.191711425781,1001.46978759766,57.4465696493907,20.6188025565535,25.186911,0,0,0,40,4449,250.09315,973.830749511719,,,,,,,,,,,,,0,,,,-0.00245,,,,,,249.98950195,,,,
,31623649.445,249.9904327,25.7656924724579,2.48460626635439E-5,3.73453354927085E-7,1,0.999253354069792,40.0298881530762,1.99652651095483,19.1799998283386,0.000283472770055514,3.67642775211276E-5,0.25,-1.06271770183236E-6,2.48905419958635E-5,-1.04404576963295E-6,249.9896545,249.9912109,-0.456713199615479,51.9880981445313,57.4528226775445,20.6191886252364,24.807261,0,0,0,40,4417,250.0972,25.7656924724579,,,,,,,,,,,,,0,,,,0,,,,,,249.9904327,,,,