File: data/monolayers/magneticStructure/ML_Ac_CoFe_C/PPMS/DD205_4_KOELNPPMS_HYST_100OE_10K.DAT
[Header]
; VSM Data File (default extension .dat)
; Copyright (c) 2003-2013, Quantum Design, Inc. All rights reserved.
TITLE,
FILEOPENTIME,19688769.45,08/16/2018,9:04 pm
BYAPP,VSM,2.0,2.0
INFO,PPMS VSM Option Release 1.4.10 Build 1,APPNAME
INFO,Quantum Design Linear Motor Servo Controller,MOTOR_MODULE_NAME
INFO,3101-100 M1,MOTOR_HW_VERSION
INFO,MMC1014,MOTOR_SERIAL_NUMBER
INFO,SRV No X-over 01.03.11,MOTOR_SOFTWARE_VERSION
INFO,Quantum Design VSM Detection Module,VSM_MODULE_NAME
INFO,3101-150 F0,VSM_HW_VERSION
INFO,VSM707,VSM_SERIAL_NUMBER
INFO,VSM No X-over 01.02.05 May 20 2008 13:51:47,VSM_SOFTWARE_VERSION
INFO,704,PREAMP_SERIAL_NUMBER
INFO,822,COIL_SERIAL_NUMBER
INFO,0,MOMENT_UNITS
INFO,,SAMPLE_MATERIAL
INFO,,SAMPLE_COMMENT
INFO,,SAMPLE_MASS
INFO,,SAMPLE_VOLUME
INFO,,SAMPLE_MOLECULAR_WEIGHT
INFO,,SAMPLE_SIZE
INFO,,SAMPLE_SHAPE
DATATYPE,COMMENT,1
DATATYPE,TIME,2
STARTUPAXIS,X,2
STARTUPAXIS,Y1,5
[Data]
Comment,Time Stamp (sec),Temperature (K),Magnetic Field (Oe),Moment (emu),M. Std. Err. (emu),Transport Action,Averaging Time (sec),Frequency (Hz),Peak Amplitude (mm),Center Position (mm),Coil Signal' (mV),Coil Signal" (mV),Range (mV),M. Quad. Signal (emu),M. Raw' (emu),M. Raw" (emu),Min. Temperature (K),Max. Temperature (K),Min. Field (Oe),Max. Field (Oe),Mass (grams),Motor Lag (deg),Pressure (Torr),VSM Status (code),Motor Status (code),Measure Status (code),Measure Count,PPMS Status (code),System Temp. (K),System Field (Oe),Sample Position (deg),Bridge 1 Resistance (ohms),Bridge 1 Excitation (에),Bridge 2 Resistance (ohms),Bridge 2 Excitation (에),Bridge 3 Resistance (ohms),Bridge 3 Excitation (에),Bridge 4 Resistance (ohms),Bridge 4 Excitation (에),Signal 1 Vin (V),Signal 2 Vin (V),Digital Inputs (code),Drive 1 Iout (mA),Drive 1 Ipower (W),Drive 2 Iout (mA),Drive 2 Ipower (W),Pressure (),Map 20 (),Map 21 (),Map 22 (),Map 23 (),Map 24 (),Map 25 (),Map 26 (),Map 27 (),Map 28 (),Map 29 ()
,19688999.97,10.0674,0.0152237731963396,3.49647130970139E-5,2.30370504450947E-7,1,0.999253354069792,40.0298881530762,1.99448564214866,14.2400003969669,0.000393787011608811,6.16377221641854E-5,0.25,-7.16020137285959E-7,3.47673029502819E-5,-5.43379347677428E-7,10.0674,10.0674,0,0.0304475463926792,53.7385239541595,19.5611276804096,10.38052,0,0,0,40,4417,10.0674,0.0152237731963396,,,,,,,,,,,,,0,,,,,,,,,,,,,,
,19689066.985,10.08395,2628.22058105469,3.34361825368581E-5,2.74903427728245E-7,1,0.999253354069792,40.0298881530762,1.99431105591913,14.2400003969669,0.000375586812220101,6.45898314312779E-5,0.25,-1.86632841629752E-7,3.32492547361822E-5,-1.95781063677395E-8,10.0835,10.0835,2595.31958007813,2661.12158203125,53.7346158115634,19.5621811553493,10.00087,0,0,0,40,4449,10.08395,2628.22058105469,,,,,,,,,,,,,0,,,,,,,,,,,,,,
,19689119.895,10.08525,5264.63403320313,2.5670824136238E-5,3.00708975155723E-7,1,0.999253354069792,40.0298881530762,1.99440266637832,14.2400003969669,0.000288335571416411,5.00796754739019E-5,0.25,-1.0520715235755E-7,2.55314553910691E-5,2.74814199690664E-8,10.0851,10.0851,5259.287109375,5269.98095703125,53.8596763746403,19.5639518353951,10.38052,0,0,0,40,4449,10.08525,5264.63403320313,,,,,,,,,,,,,0,,,,,,,,,,,,,,
,19689175.605,10.08955,8049.46069335938,1.65554462424475E-5,2.84010948594512E-7,1,0.999253354069792,40.0298881530762,1.99445525552447,14.2400003969669,0.000185350989107326,3.59153999260971E-5,0.25,2.50442780385664E-7,1.64672228863099E-5,3.37695943870951E-7,10.0906,10.0906,8021.74169921875,8077.1796875,54.0269448777557,19.563416768104,10.00087,0,0,0,40,4449,10.08955,8049.46069335938,,,,,,,,,,,,,0,,,,,,,,,,,,,,
,19689232.395,10.09285,10888.1665039062,7.59139336459232E-6,3.90939295004509E-7,1,0.999253354069792,40.0298881530762,1.9944125395143,14.2400003969669,8.52062143453655E-5,1.53657845814852E-5,0.25,1.47103739862331E-8,7.55318774306521E-6,5.68413233147438E-8,10.0928,10.0928,10885.6328125,10890.7001953125,53.9995878795826,19.5662225567727,10.38052,0,0,0,40,4449,10.09285,10888.1665039062,,,,,,,,,,,,,0,,,,,,,,,,,,,,
,19689289.085,10.09475,13721.9252929688,-1.58617433686076E-6,3.29807233357366E-7,1,0.999253354069792,40.0298881530762,1.99442305078715,14.2400003969669,-1.74272607518499E-5,-5.3423749172366E-6,0.25,-1.92499629764287E-7,-1.57748296870486E-6,-2.00725709596973E-7,10.0944,10.0944,13694.46875,13749.3818359375,54.0206918496019,19.566704024258,10.38052,0,0,0,40,4449,10.09475,13721.9252929688,,,,,,,,,,,,,0,,,,,,,,,,,,,,
,19689345.945,10.0964,16562.6171875,-1.05898757261847E-5,3.71073110991096E-7,1,0.999253354069792,40.0298881530762,1.99431201873438,14.2400003969669,-0.000118430716508402,-2.41566037097799E-5,0.25,-2.57649812801192E-7,-1.05404439491974E-5,-3.19671911423502E-7,10.0962,10.0962,16532.591796875,16592.642578125,54.0371060485057,19.5659204908978,10.00087,0,0,0,40,4449,10.0964,16562.6171875,,,,,,,,,,,,,0,,,,,,,,,,,,,,
,19689400.055,10.09725,19266.1279296875,-1.95443127339913E-5,4.18473894890252E-7,1,0.999253354069792,40.0298881530762,1.99447855172915,14.2400003969669,-0.00021958179238755,-3.93596492300499E-5,0.25,-5.78026148236271E-9,-1.94608815425091E-5,-1.25937284731611E-7,10.0968,10.0968,19235.990234375,19296.265625,53.8893782583711,19.5620886447398,10.38052,0,0,0,40,4449,10.09725,19266.1279296875,,,,,,,,,,,,,0,,,,,,,,,,,,,,
,19689458.235,10.101,22176.5869140625,-2.85106395440395E-5,4.83857794214959E-7,1,0.999253354069792,40.0298881530762,1.99433067318758,14.2400003969669,-0.000320506073931132,-5.6773174826227E-5,0.25,5.51851442266771E-8,-2.83974668797968E-5,-1.25631634928225E-7,10.101,10.101,22174.25,22178.923828125,54.2200071220057,19.5681543615318,10.00087,0,0,0,40,4449,10.101,22176.5869140625,,,,,,,,,,,,,0,,,,,,,,,,,,,,
,19689530.69,10.0803,25795.0458984375,-3.97619015556394E-5,5.05865520762065E-7,1,0.999253354069792,40.0298881530762,1.99429811978282,14.2400003969669,-0.000446893570259542,-8.06175542198808E-5,0.25,-4.02622094228447E-8,-3.96178759758371E-5,-3.00406923887188E-7,10.0803,10.0803,25792.828125,25797.263671875,54.0675895607557,19.5617080490192,10.00087,0,0,0,40,4449,10.0803,25795.0458984375,,,,,,,,,,,,,0,,,,,,,,,,,,,,
,19689611.81,10.07625,29850.5458984375,-5.33657876205676E-5,4.93988739178274E-7,1,0.999253354069792,40.0298881530762,1.99416192717144,14.2400003969669,-0.000599063788269013,-0.000113486077957677,0.25,-5.09563197852834E-7,-5.3191876767477E-5,-8.68542621243823E-7,10.0756,10.0756,29840.416015625,29860.67578125,54.1856154671596,19.5617026794776,10.38052,0,0,0,40,4449,10.07625,29850.5458984375,,,,,,,,,,,,,0,,,,,,,,,,,,,,
,19689693.095,10.0733,33911.3359375,-6.53679221834067E-5,4.00657435765385E-7,1,0.999253354069792,40.0298881530762,1.99430539174647,14.2400003969669,-0.000735838723388649,-0.00012974374836206,0.25,2.17337940654025E-7,-6.5188643864856E-5,-2.36868671217425E-7,10.0733,10.0733,33903.98046875,33918.69140625,53.8971945435634,19.5653847948493,10.38052,0,0,0,40,4449,10.0733,33911.3359375,,,,,,,,,,,,,0,,,,,,,,,,,,,,
,19689770.765,10.0697,37793.654296875,-7.90187215019969E-5,4.72394520814435E-7,1,0.999253354069792,40.0298881530762,1.99421213281984,14.2400003969669,-0.000889152164119049,-0.00016068260205378,0.25,-6.23715960333118E-8,-7.88323062058201E-5,-6.22108216613533E-7,10.0697,10.0697,37791.09765625,37796.2109375,53.8456070612942,19.5649231022109,10.38052,0,0,0,40,4449,10.0697,37793.654296875,,,,,,,,,,,,,0,,,,,,,,,,,,,,
,19689847.9,10.0699,41649.49609375,-9.13703489900512E-5,4.76961066490453E-7,1,0.999253354069792,40.0298881530762,1.99419800124199,14.2400003969669,-0.00102766861625884,-0.000190783028480545,0.25,-4.97541596066224E-7,-9.11890095501994E-5,-1.15481464395754E-6,10.0696,10.0696,41639.48828125,41659.50390625,53.9112638569095,19.5614688844799,11.139823,0,0,0,40,4449,10.0699,41649.49609375,,,,,,,,,,,,,0,,,,,,,,,,,,,,
,19689923.85,10.0718,45448.1875,-0.000104561497494495,6.21021361680716E-7,1,0.999253354069792,40.0298881530762,1.99448150989797,14.2400003969669,-0.00117621400756024,-0.000220930595435657,0.25,-7.80879691402343E-7,-0.000104393992420862,-1.54255105218794E-6,10.0712,10.0712,45443.23828125,45453.13671875,54.1011995870826,19.5636266643663,11.139823,0,0,0,40,4449,10.0718,45448.1875,,,,,,,,,,,,,0,,,,,,,,,,,,,,
,19690001.775,10.0714,49343.498046875,-0.000117203622184647,5.56607742273206E-7,1,0.999253354069792,40.0298881530762,1.99459506794014,14.2400003969669,-0.0013198608686715,-0.000243127526888157,0.25,-4.56780634796432E-7,-0.000117065915937806,-1.31955020923995E-6,10.0714,10.0714,49341.0546875,49345.94140625,53.9526901684288,19.5617715178673,10.760172,0,0,0,40,4449,10.0714,49343.498046875,,,,,,,,,,,,,0,,,,,,,,,,,,,,
,19690074.35,10.0722,52968.998046875,-0.000128961580322373,6.40988347094576E-7,1,0.999253354069792,40.0298881530762,1.99455827489051,14.2400003969669,-0.00145258859287846,-0.000268652153928502,0.25,-5.89583450127813E-7,-0.000128856508172063,-1.54470632934687E-6,10.0721,10.0721,52964.0703125,52973.92578125,54.1137056433903,19.5613130334217,11.519473,0,0,0,40,4449,10.0722,52968.998046875,,,,,,,,,,,,,0,,,,,,,,,,,,,,
,19690157.08,10.0764,57101.6953125,-0.000144162360025545,6.67876390548669E-7,1,0.999253354069792,40.0298881530762,1.99453948917454,14.2400003969669,-0.0016205653196891,-0.000321987864126564,0.25,-2.56646634236324E-6,-0.000144089084602434,-3.63770029111584E-6,10.076,10.076,57091.515625,57111.875,53.5821982503134,19.5614102926238,11.139823,0,0,0,40,4449,10.0764,57101.6953125,,,,,,,,,,,,,0,,,,,,,,,,,,,,
,19690237.33,10.0796,61114.89453125,-0.000157385319728952,5.47611358745576E-7,1,0.999253354069792,40.0298881530762,1.99450393600589,14.2400003969669,-0.00177212403761587,-0.000339035834895512,0.25,-1.68335416204809E-6,-0.000157373452947883,-2.85481746311641E-6,10.0799,10.0799,61105.03515625,61124.75390625,53.7611911812172,19.5594563658507,11.519473,0,0,0,40,4449,10.0796,61114.89453125,,,,,,,,,,,,,0,,,,,,,,,,,,,,
,19690314.73,10.0825,64983.181640625,-0.000169686701271021,5.87863892701308E-7,1,0.999253354069792,40.0298881530762,1.99445258622543,14.2400003969669,-0.00191172526776447,-0.000363087099722429,0.25,-1.58984352020063E-6,-0.00016973549554969,-2.85139199208336E-6,10.0822,10.0822,64973,64993.36328125,54.0425774481403,19.5584958548615,11.519473,0,0,0,40,4449,10.0825,64983.181640625,,,,,,,,,,,,,0,,,,,,,,,,,,,,
,19690390.065,10.08485,68748.87109375,-0.000183039684894409,5.37328409830151E-7,1,0.999253354069792,40.0298881530762,1.99451890693333,14.2400003969669,-0.00206231099936286,-0.000395120395584983,0.25,-2.01427836380261E-6,-0.000183150603963677,-3.37102633218096E-6,10.0847,10.0847,68741.28125,68756.4609375,53.922988284698,19.5600940077767,11.139823,0,0,0,40,4449,10.08485,68748.87109375,,,,,,,,,,,,,0,,,,,,,,,,,,,,
,19690467.435,10.0881,72614.5625,-0.000195599239098593,5.03251844353654E-7,1,0.999253354069792,40.0298881530762,1.9943977392416,14.2400003969669,-0.00220413419509236,-0.000423863858112614,0.25,-2.29540393050534E-6,-0.000195780365839193,-3.7381527220899E-6,10.0881,10.0881,72609.421875,72619.703125,54.1824889530827,19.5590120259234,11.139823,0,0,0,40,4449,10.0881,72614.5625,,,,,,,,,,,,,0,,,,,,,,,,,,,,
,19690543.205,10.09145,76403.43359375,-0.00020862607129647,5.8557421533989E-7,1,0.999253354069792,40.0298881530762,1.9944458552169,14.2400003969669,-0.00235313593179556,-0.000444259265380292,0.25,-1.75285325385004E-6,-0.000208887985159624,-3.28081208377127E-6,10.0914,10.0914,76393.3125,76413.5546875,54.1629482401019,19.5584119109437,11.519473,0,0,0,40,4449,10.09145,76403.43359375,,,,,,,,,,,,,0,,,,,,,,,,,,,,
,19690619.99,10.0948,80242.0390625,-0.000220176340035808,4.92700581898299E-7,1,0.999253354069792,40.0298881530762,1.9943575112313,14.2400003969669,-0.00248209478668959,-0.000479769403880175,0.25,-2.81951329252799E-6,-0.000220510615728422,-4.4205047584137E-6,10.0948,10.0948,80232.109375,80251.96875,54.0308530203519,19.5581323870829,11.139823,0,0,0,40,4449,10.0948,80242.0390625,,,,,,,,,,,,,0,,,,,,,,,,,,,,
,19690695.93,10.09775,84037.6484375,-0.00023325186350718,6.10601032819111E-7,1,0.999253354069792,40.0298881530762,1.99440052683192,14.2400003969669,-0.00263220889501093,-0.000497695829150916,0.25,-2.05555834563037E-6,-0.000233677488532947,-3.73438486405206E-6,10.0973,10.0973,84030.0859375,84045.2109375,53.983955309198,19.5554418931434,11.519473,0,0,0,40,4449,10.09775,84037.6484375,,,,,,,,,,,,,0,,,,,,,,,,,,,,
,19690770.485,10.1002,87764.08984375,-0.00024570862526563,6.94942908875838E-7,1,0.999253354069792,40.0298881530762,1.99441342576715,14.2400003969669,-0.00277197997133565,-0.000532945553707501,0.25,-2.93896995803931E-6,-0.000246215199923175,-4.6910819798885E-6,10.1002,10.1002,87759.09375,87769.0859375,53.8987578006019,19.5564441692398,11.139823,0,0,0,40,4449,10.1002,87764.08984375,,,,,,,,,,,,,0,,,,,,,,,,,,,,
,19690860,10.1036,88760.03515625,-0.000249247129648168,6.32943971347715E-7,1,0.999253354069792,40.0298881530762,1.9943366976162,14.2400003969669,-0.00281461716611799,-0.000526001172648993,0.25,-1.69221874641336E-6,-0.000249786878578107,-3.46161182844462E-6,10.1036,10.1036,88752.4609375,88767.609375,53.9651962247365,19.5575234240584,11.139823,0,0,0,40,4449,10.1036,88760.03515625,,,,,,,,,,,,,0,,,,,,,,,,,,,,
,19690931.33,10.1014,85197.15234375,-0.000237105426386636,6.63575487392205E-7,1,0.999253354069792,40.0298881530762,1.99440351327764,14.2400003969669,-0.00267546453982936,-0.000508482027394649,0.25,-2.31814776388857E-6,-0.000237555906254519,-4.01991254222457E-6,10.1014,10.1014,85194.6875,85199.6171875,53.9143903709865,19.5546500315246,11.139823,0,0,0,40,4449,10.1014,85197.15234375,,,,,,,,,,,,,0,,,,,,,,,,,,,,
,19691006.455,10.1003,81440.78515625,-0.000225535602703957,5.85123702115032E-7,1,0.999253354069792,40.0298881530762,1.99435630593854,14.2400003969669,-0.00254261284893449,-0.000492172319212724,0.25,-2.95337939472815E-6,-0.000225897666468563,-4.58891970127824E-6,10.1003,10.1003,81435.6796875,81445.890625,53.770570723448,19.5578303082495,11.139823,0,0,0,40,4449,10.1003,81440.78515625,,,,,,,,,,,,,0,,,,,,,,,,,,,,
,19691083.65,10.0966,77581.69921875,-0.00021299933822179,5.72879035677615E-7,1,0.999253354069792,40.0298881530762,1.99431325250083,14.2400003969669,-0.00240139542125515,-0.000459889131726498,0.25,-2.35165343862304E-6,-0.000213282232165092,-3.90875456241017E-6,10.0963,10.0963,77576.515625,77586.8828125,53.9706676243711,19.5570085456572,11.899124,0,0,0,40,4449,10.0966,77581.69921875,,,,,,,,,,,,,0,,,,,,,,,,,,,,
,19691161.265,10.0931,73700.484375,-0.000199881256448994,6.28294080670356E-7,1,0.999253354069792,40.0298881530762,1.99437602094859,14.2400003969669,-0.00225226774603247,-0.00043481523774607,0.25,-2.49357337136029E-6,-0.000200083017470343,-3.96555702329827E-6,10.0931,10.0931,73697.9921875,73702.9765625,53.9448738832365,19.557409215216,11.899124,0,0,0,40,4449,10.0931,73700.484375,,,,,,,,,,,,,0,,,,,,,,,,,,,,
,19691239.615,10.089,69784.89453125,-0.000186958049249799,5.80561600363403E-7,1,0.999253354069792,40.0298881530762,1.99437153715372,14.2400003969669,-0.00210829997727362,-0.00039358072080184,0.25,-1.17307638677096E-6,-0.00018709444786755,-2.55656644037688E-6,10.089,10.089,69780.0234375,69789.765625,53.7697890949288,19.5560030334142,11.519473,0,0,0,40,4449,10.089,69784.89453125,,,,,,,,,,,,,0,,,,,,,,,,,,,,
,19691314.99,10.0852,66016.55078125,-0.000174414695004646,6.9907313412175E-7,1,0.999253354069792,40.0298881530762,1.99435295453884,14.2400003969669,-0.00196587031456714,-0.000368828505111203,0.25,-1.24613912203584E-6,-0.000174483779356177,-2.54178744629336E-6,10.0853,10.0853,66006.71875,66026.3828125,53.8878150013326,19.5588585405327,11.899124,0,0,0,40,4449,10.0852,66016.55078125,,,,,,,,,,,,,0,,,,,,,,,,,,,,
,19691391.58,10.0808,62190.234375,-0.000161572318361326,5.29642780324831E-7,1,0.999253354069792,40.0298881530762,1.99429321852175,14.2400003969669,-0.00182094994840605,-0.000338713748770712,0.25,-9.00525531589444E-7,-0.000161582370272577,-2.10296722482585E-6,10.0808,10.0808,62182.7734375,62197.6953125,54.227823407198,19.5568513742075,11.139823,0,0,0,40,4449,10.0808,62190.234375,,,,,,,,,,,,,0,,,,,,,,,,,,,,
,19691470.32,10.07655,58254.732421875,-0.000147603926740129,5.89856732898741E-7,1,0.999253354069792,40.0298881530762,1.99428161796814,14.2400003969669,-0.00166141439734569,-0.000317560447131505,0.25,-1.55347576730957E-6,-0.000147553210412307,-2.65140349571578E-6,10.0767,10.0767,58249.53515625,58259.9296875,54.0316346488711,19.5625525624848,11.519473,0,0,0,40,4449,10.07655,58254.732421875,,,,,,,,,,,,,0,,,,,,,,,,,,,,
,19691547.485,10.0738,54396.78515625,-0.000135143119216994,4.88401494532687E-7,1,0.999253354069792,40.0298881530762,1.99436868800144,14.2400003969669,-0.00152059450647259,-0.000290968089203289,0.25,-1.45230417340439E-6,-0.00013504591729338,-2.45440639722468E-6,10.0738,10.0738,54391.94140625,54401.62890625,53.7901114364288,19.5596192905218,11.899124,0,0,0,40,4449,10.0738,54396.78515625,,,,,,,,,,,,,0,,,,,,,,,,,,,,
,19691625.475,10.0708,50501.353515625,-0.000122186308171504,4.52131811537099E-7,1,0.999253354069792,40.0298881530762,1.99439844156596,14.2400003969669,-0.00137549175835395,-0.000256316764971649,0.25,-7.26968438663711E-7,-0.000122055259226684,-1.62819333304846E-6,10.0708,10.0708,50498.9140625,50503.79296875,53.8690559168711,19.5625466206836,11.519473,0,0,0,40,4449,10.0708,50501.353515625,,,,,,,,,,,,,0,,,,,,,,,,,,,,
,19691701.74,10.0659,46685.9375,-0.000108831299775062,4.07590739282831E-7,1,0.999253354069792,40.0298881530762,1.99444943926944,14.2400003969669,-0.00122325846470261,-0.000236224924995194,0.25,-1.36465614605685E-6,-0.000108666864985085,-2.1594488324857E-6,10.0659,10.0659,46681.09375,46690.78125,53.8033991212557,19.5623022350695,11.519473,0,0,0,40,4449,10.0659,46685.9375,,,,,,,,,,,,,0,,,,,,,,,,,,,,
,19691780.935,10.06455,42730.08203125,-9.57458888396347E-5,4.27540399310094E-7,1,0.999253354069792,40.0298881530762,1.99442221589714,14.2400003969669,-0.00107583319946324,-0.000207110157436518,0.25,-1.15335382699227E-6,-9.55621696828146E-5,-1.84374396672975E-6,10.0644,10.0644,42697.84375,42762.3203125,54.0793139885442,19.5607865538966,11.519473,0,0,0,40,4449,10.06455,42730.08203125,,,,,,,,,,,,,0,,,,,,,,,,,,,,
,19691858.065,10.059,38874.78515625,-8.30046563313249E-5,4.46290837223579E-7,1,0.999253354069792,40.0298881530762,1.99439280332332,14.2400003969669,-0.000933891303775159,-0.000170492920348142,0.25,-2.1104786266104E-7,-8.28173198736862E-5,-8.01681234803711E-7,10.0586,10.0586,38864.8203125,38884.75,54.0027143936596,19.5610577098647,12.278775,0,0,0,40,4449,10.059,38874.78515625,,,,,,,,,,,,,0,,,,,,,,,,,,,,
,19691935.565,10.05585,35001.91796875,-6.93706231822297E-5,3.94594467658651E-7,1,0.999253354069792,40.0298881530762,1.99462491248196,14.2400003969669,-0.000778876148903795,-0.00015013352176456,0.25,-8.68994460852705E-7,-6.91807267357711E-5,-1.35111189500528E-6,10.056,10.056,34996.9765625,35006.859375,54.3771144543711,19.5580781856496,11.519473,0,0,0,40,4449,10.05585,35001.91796875,,,,,,,,,,,,,0,,,,,,,,,,,,,,
,19692012.405,10.0532,31161.7001953125,-5.81691698994532E-5,5.39135961399189E-7,1,0.999253354069792,40.0298881530762,1.99463191143205,14.2400003969669,-0.000654179597259163,-0.000118414019053363,0.25,-7.78864842029011E-8,-5.79908497231292E-5,-4.74320379977429E-7,10.0532,10.0532,31159.220703125,31164.1796875,54.3591369984288,19.560761322846,11.899124,0,0,0,40,4449,10.0532,31161.7001953125,,,,,,,,,,,,,0,,,,,,,,,,,,,,
,19692090.195,10.051,27274.0341796875,-4.47967200038504E-5,5.15365925440622E-7,1,0.999253354069792,40.0298881530762,1.99452862628102,14.2400003969669,-0.000503561723349648,-9.11409413724011E-5,0.25,-6.77017621066679E-8,-4.46411406270879E-5,-3.64313432903916E-7,10.051,10.051,27266.3828125,27281.685546875,54.0417958196211,19.5629457937357,11.899124,0,0,0,40,4449,10.051,27274.0341796875,,,,,,,,,,,,,0,,,,,,,,,,,,,,
,19692164.265,10.0479,23572.9462890625,-3.24140133348025E-5,4.29955682254786E-7,1,0.999253354069792,40.0298881530762,1.99445331420063,14.2400003969669,-0.000364023462033048,-6.69904179738157E-5,0.25,-1.5088031390954E-7,-3.22885198929813E-5,-3.58354844341482E-7,10.0474,10.0474,23562.71875,23583.173828125,53.9698859958519,19.5617665878641,12.278775,0,0,0,40,4449,10.0479,23572.9462890625,,,,,,,,,,,,,0,,,,,,,,,,,,,,
,19692239.715,10.0461,19800.2109375,-1.96213485849568E-5,4.49020559962627E-7,1,0.999253354069792,40.0298881530762,1.99448345633645,14.2400003969669,-0.000220277448364755,-4.05330264711074E-5,0.25,-9.55511173550858E-8,-1.95380478754823E-5,-2.16488544706123E-7,10.0461,10.0461,19795.080078125,19805.341796875,54.2653415761211,19.5646225977982,11.899124,0,0,0,40,4449,10.0461,19800.2109375,,,,,,,,,,,,,0,,,,,,,,,,,,,,
,19692320.565,10.0436,15760.3896484375,-6.8507260742917E-6,4.32031612335576E-7,1,0.999253354069792,40.0298881530762,1.99441985986619,14.2400003969669,-7.5528132874236E-5,-2.16961444515623E-5,0.25,-7.07408412422547E-7,-6.81505555975231E-6,-7.44651161869641E-7,10.0439,10.0439,15752.98046875,15767.798828125,54.105889358198,19.5637872065556,11.899124,0,0,0,40,4449,10.0436,15760.3896484375,,,,,,,,,,,,,0,,,,,,,,,,,,,,
,19692396.735,10.0423,11952.2690429688,5.10049293316622E-6,3.61201181551592E-7,1,0.999253354069792,40.0298881530762,1.99436020801589,14.2400003969669,5.71184614633336E-5,1.10726848285754E-5,0.25,7.61085058960988E-8,5.07490461308146E-6,1.04488169777363E-7,10.0423,10.0423,11944.6865234375,11959.8515625,53.8284112338711,19.5662262478546,11.519473,0,0,0,40,4449,10.0423,11952.2690429688,,,,,,,,,,,,,0,,,,,,,,,,,,,,
,19692473.14,10.04025,8133.91015625,1.72766609626495E-5,3.22197310214162E-7,1,0.999253354069792,40.0298881530762,1.99441556222809,14.2400003969669,0.000194467425200764,3.16168614165912E-5,0.25,-2.61001601433066E-7,1.71875032186949E-5,-1.67099989507887E-7,10.0405,10.0405,8126.5029296875,8141.3173828125,54.2950434598519,19.5641454645902,11.519473,0,0,0,40,4449,10.04025,8133.91015625,,,,,,,,,,,,,0,,,,,,,,,,,,,,
,19692549.585,10.03675,4313.658203125,2.94385170550992E-5,2.46110369233581E-7,1,0.999253354069792,40.0298881530762,1.99442335038574,14.2400003969669,0.000330256433996144,5.9562987986662E-5,0.25,7.16784536502888E-8,2.927583620422E-5,2.20805795822412E-7,10.0366,10.0366,4308.76806640625,4318.54833984375,54.3552288558327,19.5640386942481,11.519473,0,0,0,40,4449,10.03675,4313.658203125,,,,,,,,,,,,,0,,,,,,,,,,,,,,
,19692625.18,10.0294,534.406646728516,3.71818182554267E-5,2.40528141348293E-7,1,0.999253354069792,40.0298881530762,1.99438948199453,14.2400003969669,0.000417404805011494,7.30949690668062E-5,0.25,-8.93515351366843E-8,3.69693442170275E-5,9.11816287590932E-8,10.0294,10.0294,529.44873046875,539.364562988281,54.0019327651403,19.5644916908223,11.519473,0,0,0,40,4449,10.0294,534.406646728516,,,,,,,,,,,,,0,,,,,,,,,,,,,,
,19692699.345,10.0292,-3168.31604003906,3.59321593604931E-5,3.77345840086238E-7,1,0.999253354069792,40.0298881530762,1.9944147693416,14.2400003969669,0.000403859043027596,6.8282014611577E-5,0.25,-3.02993102079813E-7,3.57329559769559E-5,-1.21619306042169E-7,10.0291,10.0291,-3178.23608398438,-3158.39599609375,54.1488789267557,19.5649404279709,12.278775,0,0,0,40,4449,10.0292,-3168.31604003906,,,,,,,,,,,,,0,,,,,,,,,,,,,,
,19692774.99,10.0337,-6951.18872070312,4.67031594057829E-5,3.407708105679E-7,1,0.999253354069792,40.0298881530762,1.99443324072023,14.2400003969669,0.000524831789470646,9.00625360583821E-5,0.25,-2.91578685473368E-7,4.64557572801673E-5,-4.39500531337649E-8,10.0338,10.0338,-6953.39501953125,-6948.982421875,53.7182016126595,19.5670470229899,11.899124,0,0,0,40,4449,10.0337,-6951.18872070312,,,,,,,,,,,,,0,,,,,,,,,,,,,,
,19692849.48,10.0361,-10672.0649414062,5.64256813274203E-5,2.51801733433859E-7,1,0.999253354069792,40.0298881530762,1.99448134685152,14.2400003969669,0.000634822389215299,0.000105869115958013,0.25,-6.32909820527799E-7,5.61448199875472E-5,-3.16916765019689E-7,10.0362,10.0362,-10677.302734375,-10666.8271484375,54.0097490503326,19.5676425234368,11.899124,0,0,0,40,4449,10.0361,-10672.0649414062,,,,,,,,,,,,,0,,,,,,,,,,,,,,
,19692926.43,10.03865,-14520.1450195313,6.40336740466687E-5,3.54374801148273E-7,1,0.999253354069792,40.0298881530762,1.99452242945382,14.2400003969669,0.000720731810027624,0.000119863584242255,0.25,-7.6488222958379E-7,6.37366138781721E-5,-3.88391196919814E-7,10.0391,10.0391,-14530.166015625,-14510.1240234375,54.210627579775,19.5682224903169,11.899124,0,0,0,40,4449,10.03865,-14520.1450195313,,,,,,,,,,,,,0,,,,,,,,,,,,,,
,19693002.27,10.03985,-18310.287109375,6.82587293215586E-5,3.38875685728366E-7,1,0.999253354069792,40.0298881530762,1.99441532983496,14.2400003969669,0.000767605060021705,0.000132935144164093,0.25,-3.77128943141953E-7,6.79635241449352E-5,3.99210115153115E-8,10.04,10.04,-18317.814453125,-18302.759765625,53.8870333728134,19.5707118535387,12.278775,0,0,0,40,4449,10.03985,-18310.287109375,,,,,,,,,,,,,0,,,,,,,,,,,,,,
,19693078.73,10.0418,-22130.4853515625,6.95130349699785E-5,3.87735726709782E-7,1,0.999253354069792,40.0298881530762,1.99454544110209,14.2400003969669,0.000782581837131999,0.000132488231385033,0.25,-6.6345828687163E-7,6.92401396431003E-5,-2.20689040763374E-7,10.0417,10.0417,-22135.4609375,-22125.509765625,53.8690559168711,19.5671988694871,11.899124,0,0,0,40,4449,10.0418,-22130.4853515625,,,,,,,,,,,,,0,,,,,,,,,,,,,,
,19693153.555,10.0422,-25870.5205078125,6.96140045558703E-5,5.24830424958572E-7,1,0.999253354069792,40.0298881530762,1.99444998554634,14.2400003969669,0.000783372716841105,0.000136129817795537,0.25,-3.76729263246599E-7,6.93653214162892E-5,8.06302786023826E-8,10.0422,10.0422,-25872.8359375,-25868.205078125,54.1074526152365,19.5666416204355,11.899124,0,0,0,40,4449,10.0422,-25870.5205078125,,,,,,,,,,,,,0,,,,,,,,,,,,,,
,19693231.54,10.0449,-29766.05078125,7.13182881680396E-5,4.58576837907911E-7,1,0.999253354069792,40.0298881530762,1.99443624782949,14.2400003969669,0.000801737550195655,0.000145846337939116,0.25,1.62383493471303E-7,7.10887493402406E-5,6.43487918760271E-7,10.0451,10.0451,-29771.134765625,-29760.966796875,53.9964613655057,19.5699075988147,11.899124,0,0,0,40,4449,10.0449,-29766.05078125,,,,,,,,,,,,,0,,,,,,,,,,,,,,
,19693311.38,10.0475,-33756.2421875,7.74622299615442E-5,5.88949466001331E-7,1,0.999253354069792,40.0298881530762,1.99451093456983,14.2400003969669,0.000872171066899796,0.000153111539074526,0.25,-3.14820366115266E-7,7.72489066127305E-5,2.23090583774163E-7,10.0479,10.0479,-33763.71875,-33748.765625,54.0863486452173,19.5694610850999,11.899124,0,0,0,40,4449,10.0475,-33756.2421875,,,,,,,,,,,,,0,,,,,,,,,,,,,,
,19693389.07,10.04855,-37641.29296875,8.60293685483827E-5,4.00883802508532E-7,1,0.999253354069792,40.0298881530762,1.99448669012003,14.2400003969669,0.000969368823101222,0.000168186108779844,0.25,-5.33379917138877E-7,8.58292834153919E-5,7.69913759710847E-8,10.049,10.049,-37651.26171875,-37631.32421875,54.2833190320634,19.5697613696889,11.899124,0,0,0,40,4449,10.04855,-37641.29296875,,,,,,,,,,,,,0,,,,,,,,,,,,,,
,19693468.03,10.05115,-41586.37109375,9.65769787317966E-5,6.28933098097838E-7,1,0.999253354069792,40.0298881530762,1.99448141627129,14.2400003969669,0.00108837843773509,0.00019051938942193,0.25,-4.65188367451589E-7,9.63918050736977E-5,2.31302360215096E-7,10.0512,10.0512,-41588.66796875,-41584.07421875,54.2215703790442,19.5686194832349,11.899124,0,0,0,40,4449,10.05115,-41586.37109375,,,,,,,,,,,,,0,,,,,,,,,,,,,,
,19693545.345,10.05425,-45449.681640625,0.000108202666028384,4.9288920483823E-7,1,0.999253354069792,40.0298881530762,1.99451346561843,14.2400003969669,0.00122006129003482,0.000212699275311172,0.25,-6.05983634011706E-7,0.000108039664650554,1.84403126462452E-7,10.0551,10.0551,-45462.203125,-45437.16015625,54.1684196397365,19.5707799819496,11.519473,0,0,0,40,4449,10.05425,-45449.681640625,,,,,,,,,,,,,0,,,,,,,,,,,,,,
,19693622.355,10.05695,-49299.814453125,0.0001207702857568,6.33951605393654E-7,1,0.999253354069792,40.0298881530762,1.99455968822273,14.2400003969669,0.00136085439954411,0.000245761975003869,0.25,4.84537347622841E-8,0.000120630963901011,9.37883738586624E-7,10.0565,10.0565,-49309.83984375,-49289.7890625,54.1762359249288,19.571785315183,11.899124,0,0,0,40,4449,10.05695,-49299.814453125,,,,,,,,,,,,,0,,,,,,,,,,,,,,
,19693700.625,10.0603,-53209.66015625,0.000133421470520503,6.20674207002021E-7,1,0.999253354069792,40.0298881530762,1.99454625939268,14.2400003969669,0.00150439215779929,0.000269396708969028,0.25,-1.48856457799926E-7,0.000133321583851954,8.40186712725306E-7,10.0603,10.0603,-53212.1875,-53207.1328125,54.2762843753904,19.5740940465658,11.519473,0,0,0,40,4449,10.0603,-53209.66015625,,,,,,,,,,,,,0,,,,,,,,,,,,,,
,19693776.075,10.0619,-56979.59375,0.000145889624241573,6.16376644030296E-7,1,0.999253354069792,40.0298881530762,1.99451816186496,14.2400003969669,0.00164592640675978,0.000292659342827263,0.25,-3.44878067621048E-7,0.000145835637797357,7.40229212721238E-7,10.0619,10.0619,-56984.91796875,-56974.26953125,54.2067194371788,19.5719568346338,12.278775,0,0,0,40,4449,10.0619,-56979.59375,,,,,,,,,,,,,0,,,,,,,,,,,,,,
,19693854.65,10.0651,-60909.861328125,0.000158723525140015,6.69450164345122E-7,1,0.999253354069792,40.0298881530762,1.9946178754654,14.2400003969669,0.00178918248123501,0.000331239225956312,0.25,7.49954402067186E-7,0.000158715585978469,1.93138734738188E-6,10.0651,10.0651,-60917.33203125,-60902.390625,54.2137540938519,19.5716617101363,12.278775,0,0,0,40,4449,10.0651,-60909.861328125,,,,,,,,,,,,,0,,,,,,,,,,,,,,
,19693933.845,10.0674,-64867.71875,0.000171552980509681,7.08165506014575E-7,1,0.999253354069792,40.0298881530762,1.99459430594178,14.2400003969669,0.00193545361993599,0.000352724401325411,0.25,3.33309439810113E-7,0.000171610009400547,1.60837570763109E-6,10.0674,10.0674,-64875.109375,-64860.328125,54.1676380112173,19.5713009373096,12.278775,0,0,0,40,4449,10.0674,-64867.71875,,,,,,,,,,,,,0,,,,,,,,,,,,,,
,19694013.75,10.0709,-68860.6796875,0.000185236201309839,5.94077627264153E-7,1,0.999253354069792,40.0298881530762,1.99449142516861,14.2400003969669,0.0020893940937087,0.000386862673121726,0.25,8.87311884686564E-7,0.000185358758773183,2.25937466684755E-6,10.0709,10.0709,-68863.296875,-68858.0625,54.197339894948,19.5712685767834,12.278775,0,0,0,40,4449,10.0709,-68860.6796875,,,,,,,,,,,,,0,,,,,,,,,,,,,,
,19694092.4,10.07295,-72788.05859375,0.000198561372965206,8.38018455389013E-7,1,0.999253354069792,40.0298881530762,1.994596790968,14.2400003969669,0.00223992492619155,0.000418304689766503,0.25,1.26583391574696E-6,0.000198755916651311,2.72895261313707E-6,10.0731,10.0731,-72800.7265625,-72775.390625,54.0097490503326,19.5732599081191,12.278775,0,0,0,40,4449,10.07295,-72788.05859375,,,,,,,,,,,,,0,,,,,,,,,,,,,,
,19694170.67,10.0764,-76702.7890625,0.000211216160522997,7.31440622906318E-7,1,0.999253354069792,40.0298881530762,1.99466058418688,14.2400003969669,0.0023834333654674,0.000445486397830908,0.25,1.39099869761973E-6,0.000211489097393431,2.93650516039815E-6,10.0768,10.0768,-76707.765625,-76697.8125,54.0840037596596,19.572791901556,11.899124,0,0,0,40,4449,10.0764,-76702.7890625,,,,,,,,,,,,,0,,,,,,,,,,,,,,
,19694245.385,10.07985,-80435.76171875,0.000222958262394575,6.84176439052692E-7,1,0.999253354069792,40.0298881530762,1.99460585997697,14.2400003969669,0.00251960026661254,0.000453630061109538,0.25,7.09954558534768E-10,0.000223320689982224,1.61657884290589E-6,10.0801,10.0801,-80470.703125,-80400.8203125,54.271594604275,19.569740132706,12.278775,0,0,0,40,4449,10.07985,-80435.76171875,,,,,,,,,,,,,0,,,,,,,,,,,,,,
,19694323.93,10.08355,-84360.390625,0.000237078847400486,5.32193522848579E-7,1,0.999253354069792,40.0298881530762,1.99468056007678,14.2400003969669,0.00267626053788566,0.000503468848596458,0.25,1.87212992115038E-6,0.000237518465358137,3.57664149526238E-6,10.0833,10.0833,-84362.9375,-84357.84375,54.4193223944096,19.5721263481616,12.278775,0,0,0,40,4449,10.08355,-84360.390625,,,,,,,,,,,,,0,,,,,,,,,,,,,,
,19694398.065,10.0859,-88065.25390625,0.000249807036060583,6.30562925072913E-7,1,0.999253354069792,40.0298881530762,1.99465452883301,14.2400003969669,0.0028219094624755,0.00052350526537658,0.25,1.36207654474709E-6,0.000250338707996983,3.13835639364816E-6,10.0857,10.0857,-88075.2734375,-88055.234375,54.3302167432173,19.5728955388942,12.658426,0,0,0,40,4449,10.0859,-88065.25390625,,,,,,,,,,,,,0,,,,,,,,,,,,,,
,19694489.455,10.0884,-88338.11328125,0.000251544983489227,6.71098957281457E-7,1,0.999253354069792,40.0298881530762,1.99483201315437,14.2400003969669,0.00284209793089633,0.000525741701162783,0.25,1.24393172542107E-6,0.000252085883745442,3.03085259615088E-6,10.0884,10.0884,-88343.1484375,-88333.078125,54.116050528948,19.5736703941453,11.519473,0,0,0,40,4449,10.0884,-88338.11328125,,,,,,,,,,,,,0,,,,,,,,,,,,,,
,19694559.905,10.0883,-84818.3671875,0.000239551288279874,5.955045081583E-7,1,0.999253354069792,40.0298881530762,1.99467546102556,14.2400003969669,0.00270456667742853,0.000506982348483244,0.25,1.73886755031213E-6,0.000240004350699338,3.45875821478133E-6,10.0883,10.0883,-84820.6640625,-84816.0703125,54.4302651936788,19.5717041608739,12.278775,0,0,0,40,4449,10.0883,-84818.3671875,,,,,,,,,,,,,0,,,,,,,,,,,,,,
,19694636.25,10.08435,-81003.19140625,0.000227587976829793,6.71224067521953E-7,1,0.999253354069792,40.0298881530762,1.99468881708813,14.2400003969669,0.00256875624781165,0.000481826748965898,0.25,1.66115582719422E-6,0.000227955510215371,3.31106903546444E-6,10.0842,10.0842,-81013.21875,-80993.1640625,54.0746242174288,19.5718530471406,12.278775,0,0,0,40,4449,10.08435,-81003.19140625,,,,,,,,,,,,,0,,,,,,,,,,,,,,
,19694715.12,10.0821,-77062.50390625,0.000213278992074087,6.94857104011559E-7,1,0.999253354069792,40.0298881530762,1.99484726168364,14.2400003969669,0.00240632813782744,0.000453584457199263,0.25,1.73276422766734E-6,0.000213558191017537,3.29268402997569E-6,10.082,10.082,-77069.9453125,-77055.0625,54.2395478349865,19.568013021084,11.899124,0,0,0,40,4449,10.0821,-77062.50390625,,,,,,,,,,,,,0,,,,,,,,,,,,,,
,19694795.795,10.078,-73027.4765625,0.000199029890100909,5.33247238251523E-7,1,0.999253354069792,40.0298881530762,1.99477300051139,14.2400003969669,0.00224432235814438,0.000425558194438086,0.25,1.82038549842816E-6,0.000199224739025605,3.28697050446453E-6,10.0776,10.0776,-73032.46875,-73022.484375,54.3145841728327,19.5659276763739,11.899124,0,0,0,40,4449,10.078,-73027.4765625,,,,,,,,,,,,,0,,,,,,,,,,,,,,
,19694875.655,10.07545,-69040.3046875,0.000186958095972208,5.62354496055815E-7,1,0.999253354069792,40.0298881530762,1.99459736288443,14.2400003969669,0.00210908367433647,0.00038977480691119,0.25,8.33012790937683E-7,0.000187085134853278,2.2174968042535E-6,10.0754,10.0754,-69045.296875,-69035.3125,54.352883970275,19.5680515641728,12.278775,0,0,0,40,4449,10.07545,-69040.3046875,,,,,,,,,,,,,0,,,,,,,,,,,,,,
,19694957.075,10.06805,-64970.19921875,0.000172886450006527,5.98291486593367E-7,1,0.999253354069792,40.0298881530762,1.99463856055696,14.2400003969669,0.00194884980549008,0.000364948646715796,0.25,1.17523172469933E-6,0.000172939271267662,2.46042045238758E-6,10.0676,10.0676,-64972.546875,-64967.8515625,54.2864455461404,19.5710943088662,12.278775,0,0,0,40,4449,10.06805,-64970.19921875,,,,,,,,,,,,,0,,,,,,,,,,,,,,
,19695036.795,10.07345,-60987.365234375,0.000158896056612055,6.05042665745097E-7,1,0.999253354069792,40.0298881530762,1.99459032167189,14.2400003969669,0.00179322557802235,0.000319897097823759,0.25,-2.86292997823764E-7,0.000158896972921897,8.96428070271279E-7,10.074,10.074,-60989.875,-60984.85546875,54.0371060485057,19.5720012589421,12.278775,0,0,0,40,4449,10.07345,-60987.365234375,,,,,,,,,,,,,0,,,,,,,,,,,,,,
,19695119.225,10.0733,-56864.51171875,0.00014539955858005,4.32914979777168E-7,1,0.999253354069792,40.0298881530762,1.99459057291146,14.2400003969669,0.00163926743864949,0.000298166586183446,0.25,2.3124345232517E-7,0.000145339859713832,1.31241052586491E-6,10.0733,10.0733,-56872.22265625,-56856.80078125,54.2200071220057,19.5683207786466,11.899124,0,0,0,40,4449,10.0733,-56864.51171875,,,,,,,,,,,,,0,,,,,,,,,,,,,,
,19695203.59,10.0712,-52647.408203125,0.000130435198706563,4.37790888135114E-7,1,0.999253354069792,40.0298881530762,1.99463560430069,14.2400003969669,0.00147078454286465,0.000262899278283978,0.25,-1.86055329017541E-7,0.000130330542471167,7.80189582257355E-7,10.0712,10.0712,-52654.88671875,-52639.9296875,54.0980730730057,19.5721638953421,12.278775,0,0,0,40,4449,10.0712,-52647.408203125,,,,,,,,,,,,,0,,,,,,,,,,,,,,
,19695287.97,10.06925,-48435.0625,0.000117117933016644,4.72936045481766E-7,1,0.999253354069792,40.0298881530762,1.9946727066186,14.2400003969669,0.00132208631195813,0.000224819296969635,0.25,-1.1497136985536E-6,0.00011698126873593,-2.87282588284523E-7,10.0694,10.0694,-48442.67578125,-48427.44921875,54.1387177560057,19.5683943221044,12.278775,0,0,0,40,4449,10.06925,-48435.0625,,,,,,,,,,,,,0,,,,,,,,,,,,,,
,19695376.36,10.0686,-44017.384765625,0.000101109023352051,5.0513390599006E-7,1,0.999253354069792,40.0298881530762,1.99460169778504,14.2400003969669,0.00113999823480983,0.000198479754781381,0.25,-5.85676379023118E-7,0.000100941723092325,1.49795491268887E-7,10.0694,10.0694,-44024.50390625,-44010.265625,54.3341248858134,19.5650890386978,12.278775,0,0,0,40,4449,10.0686,-44017.384765625,,,,,,,,,,,,,0,,,,,,,,,,,,,,
,19695458.64,10.0612,-39902.646484375,8.7936333014286E-5,5.05283461579359E-7,1,0.999253354069792,40.0298881530762,1.99459325717389,14.2400003969669,0.000990209403705047,0.00017716793021668,0.25,-8.93325158442621E-8,8.77496716185146E-5,5.39917144466011E-7,10.0616,10.0616,-39912.3671875,-39892.92578125,54.2700313472365,19.5679753730761,11.899124,0,0,0,40,4449,10.0612,-39902.646484375,,,,,,,,,,,,,0,,,,,,,,,,,,,,
,19695538.955,10.0564,-35890.3828125,7.4208363972371E-5,5.03670226328515E-7,1,0.999253354069792,40.0298881530762,1.99450846232029,14.2400003969669,0.000835873722220637,0.000145882434094807,0.25,-3.81577394255033E-7,7.402139393952E-5,1.40130867937713E-7,10.0567,10.0567,-35895.4296875,-35885.3359375,53.9018843146788,19.5654576081483,12.278775,0,0,0,40,4449,10.0564,-35890.3828125,,,,,,,,,,,,,0,,,,,,,,,,,,,,
,19695620.14,10.05225,-31835.4873046875,6.08636091285196E-5,4.51561280230998E-7,1,0.999253354069792,40.0298881530762,1.99450754118623,14.2400003969669,0.000685394376195074,0.000118865909740043,0.25,-3.67911538779848E-7,6.06844310943719E-5,5.00992435840455E-8,10.0522,10.0522,-31842.921875,-31828.052734375,53.8088705208903,19.5660376062792,11.899124,0,0,0,40,4449,10.05225,-31835.4873046875,,,,,,,,,,,,,0,,,,,,,,,,,,,,
,19695700.025,10.0497,-27840.5576171875,4.79104656436001E-5,4.2467512798684E-7,1,0.999253354069792,40.0298881530762,1.99455323056836,14.2400003969669,0.000539066734840999,9.48914153903228E-5,0.25,-1.59464931527217E-7,4.77484300479996E-5,1.5998279965991E-7,10.0492,10.0492,-27850.486328125,-27830.62890625,54.2669048331596,19.5673682859532,12.278775,0,0,0,40,4449,10.0497,-27840.5576171875,,,,,,,,,,,,,0,,,,,,,,,,,,,,
,19695778.44,10.04655,-23922.3642578125,3.38154156865604E-5,3.71832540029128E-7,1,0.999253354069792,40.0298881530762,1.99450572698953,14.2400003969669,0.000380364450322181,6.66571262287226E-5,0.25,-1.30982725757089E-7,3.36875441225578E-5,8.72617381025286E-8,10.0462,10.0462,-23932.380859375,-23912.34765625,54.2497090057365,19.5648785992673,12.278775,0,0,0,40,4449,10.04655,-23922.3642578125,,,,,,,,,,,,,0,,,,,,,,,,,,,,
,19695856.905,10.0444,-19999.6923828125,2.15519807565467E-5,3.57191737337652E-7,1,0.999253354069792,40.0298881530762,1.99446829102837,14.2400003969669,0.000242227322392219,4.29975030621299E-5,0.25,-3.09820989153053E-8,2.14617422702779E-5,1.02706040425194E-7,10.0444,10.0444,-20004.787109375,-19994.59765625,54.3286534861788,19.5655442871587,11.899124,0,0,0,40,4449,10.0444,-19999.6923828125,,,,,,,,,,,,,0,,,,,,,,,,,,,,
,19695935.1,10.0422,-16092.087890625,8.73269962051012E-6,3.63793402623172E-7,1,0.999253354069792,40.0298881530762,1.99450456443906,14.2400003969669,9.85816559446508E-5,1.47977915249383E-5,0.25,-2.43357599131184E-7,8.69427000262256E-6,-1.90425549136153E-7,10.0422,10.0422,-16097.0947265625,-16087.0810546875,53.9284596843326,19.5642835343691,12.278775,0,0,0,40,4449,10.0422,-16092.087890625,,,,,,,,,,,,,0,,,,,,,,,,,,,,
,19696010.365,10.0401,-12331.4829101562,-3.83913081511839E-6,3.45263019813179E-7,1,0.999253354069792,40.0298881530762,1.99454620026645,14.2400003969669,-4.21467695278085E-5,-1.31065791225237E-5,0.25,-4.82047580739661E-7,-3.81758661167324E-6,-5.0143562659898E-7,10.0401,10.0401,-12334.1005859375,-12328.865234375,53.9495636543519,19.5643254848582,11.899124,0,0,0,40,4449,10.0401,-12331.4829101562,,,,,,,,,,,,,0,,,,,,,,,,,,,,
,19696088.045,10.03655,-8445.58203125,-1.57321304464918E-5,2.966953440486E-7,1,0.999253354069792,40.0298881530762,1.99453447961759,14.2400003969669,-0.000175122459120999,-3.98734429660073E-5,0.25,-7.48968860244207E-7,-1.56460189470281E-5,-8.29684542948465E-7,10.0363,10.0363,-8455.376953125,-8435.787109375,54.0566467614865,19.5637564454907,11.899124,0,0,0,40,4449,10.03655,-8445.58203125,,,,,,,,,,,,,0,,,,,,,,,,,,,,
,19696164.015,10.03125,-4650.0830078125,-2.81550385948E-5,2.54560194275196E-7,1,0.999253354069792,40.0298881530762,1.99446918876549,14.2400003969669,-0.000314920249397099,-6.23179660804402E-5,0.25,-5.44490821013749E-7,-2.79976446723904E-5,-6.85170178009747E-7,10.0312,10.0312,-4657.521484375,-4642.64453125,54.4318284507173,19.5633363124538,12.278775,0,0,0,40,4449,10.03125,-4650.0830078125,,,,,,,,,,,,,0,,,,,,,,,,,,,,
,19696240.905,10.0241,-805.527954101562,-3.72846820933282E-5,3.27248179206774E-7,1,0.999253354069792,40.0298881530762,1.99454390766072,14.2400003969669,-0.000417309934620293,-8.05417309895219E-5,0.25,-5.54881085485152E-7,-3.70689332783866E-5,-7.32743286593542E-7,10.025,10.025,-812.801818847656,-798.254089355469,54.1309014708134,19.5620538728054,11.899124,0,0,0,40,4449,10.0241,-805.527954101562,,,,,,,,,,,,,0,,,,,,,,,,,,,,
,19696315.615,10.0237,2921.77368164063,-3.53882685983165E-5,2.48874177123821E-7,1,0.999253354069792,40.0298881530762,1.99449820418391,14.2400003969669,-0.000396298029559658,-7.54519700359057E-5,0.25,-4.32983502237434E-7,-3.51879049251531E-5,-6.06938635123414E-7,10.0237,10.0237,2914.47900390625,2929.068359375,54.0644630466788,19.5622660029502,12.658426,0,0,0,40,4449,10.0237,2921.77368164063,,,,,,,,,,,,,0,,,,,,,,,,,,,,
,19696391.805,10.0265,6732.04858398438,-4.63412039801601E-5,3.1335367232141E-7,1,0.999253354069792,40.0298881530762,1.99448566046451,14.2400003969669,-0.000519158663016468,-9.84103329188256E-5,0.25,-5.17197363123214E-7,-4.60907355306577E-5,-7.5785583342415E-7,10.0265,10.0265,6729.283203125,6734.81396484375,54.1652931256596,19.5641258108438,12.278775,0,0,0,40,4449,10.0265,6732.04858398438,,,,,,,,,,,,,0,,,,,,,,,,,,,,
,19696467.97,10.0294,10538.2768554688,-5.58201983188791E-5,4.08516155175221E-7,1,0.999253354069792,40.0298881530762,1.99448587629265,14.2400003969669,-0.000625243830107271,-0.000120215533831112,0.25,-7.53424760252889E-7,-5.55340975801674E-5,-1.05851533854203E-6,10.0293,10.0293,10528.423828125,10548.1298828125,53.9511269113903,19.5634785102973,11.899124,0,0,0,40,4449,10.0294,10538.2768554688,,,,,,,,,,,,,0,,,,,,,,,,,,,,
,19696543.42,10.0314,14309.0561523437,-6.42043120199836E-5,3.24576650301858E-7,1,0.999253354069792,40.0298881530762,1.99444828611114,14.2400003969669,-0.000720047664784961,-0.000134540117830344,0.25,-5.12980140851561E-7,-6.38978049809639E-5,-8.83471218790561E-7,10.0314,10.0314,14306.513671875,14311.5986328125,53.9401841121211,19.5635079066381,12.658426,0,0,0,40,4449,10.0314,14309.0561523437,,,,,,,,,,,,,0,,,,,,,,,,,,,,
,19696617.805,10.0329,18026.796875,-6.88698735450719E-5,3.04888403552851E-7,1,0.999253354069792,40.0298881530762,1.99443118449602,14.2400003969669,-0.000773509446590788,-0.000139451130341012,0.25,-9.51011448446789E-8,-6.85672799579687E-5,-5.12498111262009E-7,10.0333,10.0333,18019.2578125,18034.3359375,54.1309014708134,19.56375155036,12.278775,0,0,0,40,4449,10.0329,18026.796875,,,,,,,,,,,,,0,,,,,,,,,,,,,,
,19696692.63,10.03445,21769.5302734375,-6.96939595725643E-5,3.43753381699698E-7,1,0.999253354069792,40.0298881530762,1.99449248958409,14.2400003969669,-0.000783912395417014,-0.000136498109458754,0.25,3.36787000014312E-7,-6.941576890363E-5,-1.04282981203657E-7,10.0343,10.0343,21762.080078125,21776.98046875,54.0840037596596,19.561353980609,12.658426,0,0,0,40,4449,10.03445,21769.5302734375,,,,,,,,,,,,,0,,,,,,,,,,,,,,
,19696768.325,10.03635,25552.4775390625,-6.98396346282698E-5,3.88706566979055E-7,1,0.999253354069792,40.0298881530762,1.99448314916954,14.2400003969669,-0.000784667303659359,-0.00014343308803079,0.25,-2.33876589905709E-7,-6.95838640910704E-5,-6.8926645212175E-7,10.0358,10.0358,25550.005859375,25554.94921875,53.8799987161403,19.5617546040585,11.899124,0,0,0,40,4449,10.03635,25552.4775390625,,,,,,,,,,,,,0,,,,,,,,,,,,,,
,19696844.27,10.03745,29345.92578125,-7.21864300522314E-5,5.25052145137414E-7,1,0.999253354069792,40.0298881530762,1.9944277506167,14.2400003969669,-0.000811053553838699,-0.000149865700076923,0.25,-3.66005418766946E-7,-7.19495661061871E-5,-8.50818411425453E-7,10.0371,10.0371,29343.6015625,29348.25,54.0832221311403,19.562042077778,12.278775,0,0,0,40,4449,10.03745,29345.92578125,,,,,,,,,,,,,0,,,,,,,,,,,,,,
,19696919.73,10.03955,33116.578125,-7.71228479496341E-5,4.84515537674722E-7,1,0.999253354069792,40.0298881530762,1.99448951837353,14.2400003969669,-0.000867475681359636,-0.000156913699871009,0.25,-8.72536540723308E-8,-7.69024577060599E-5,-6.1961465252226E-7,10.0396,10.0396,33106.46484375,33126.69140625,54.0574283900057,19.5601522896877,12.658426,0,0,0,40,4449,10.03955,33116.578125,,,,,,,,,,,,,0,,,,,,,,,,,,,,
,19696997.35,10.0418,36996.794921875,-8.55290873158527E-5,5.64286370387918E-7,1,0.999253354069792,40.0298881530762,1.99443754929572,14.2400003969669,-0.000962774283189735,-0.000172020466513874,0.25,9.94080312840983E-8,-8.53212613116595E-5,-5.04469238224561E-7,10.0414,10.0414,36989.40234375,37004.1875,54.1512238123134,19.5604101614707,12.658426,0,0,0,40,4449,10.0418,36996.794921875,,,,,,,,,,,,,0,,,,,,,,,,,,,,
,19697074.925,10.04275,40875.162109375,-9.53949212742493E-5,5.21771773587336E-7,1,0.999253354069792,40.0298881530762,1.99450152724638,14.2400003969669,-0.00107231974403942,-0.000202990430476629,0.25,-8.58218801588672E-7,-9.5195382218214E-5,-1.5416395811742E-6,10.0428,10.0428,40862.515625,40887.80859375,53.8205949486788,19.562135773025,11.899124,0,0,0,40,4449,10.04275,40875.162109375,,,,,,,,,,,,,0,,,,,,,,,,,,,,
,19697147.335,10.0448,44492.759765625,-0.000106279445442889,5.79324374448436E-7,1,0.999253354069792,40.0298881530762,1.99453564022337,14.2400003969669,-0.00119706488154094,-0.000215582638125246,0.25,-2.37764203252277E-10,-0.000106104400302296,-7.73436436575517E-7,10.0448,10.0448,44490.23828125,44495.28125,53.8127786634865,19.5604138341394,11.899124,0,0,0,40,4449,10.0448,44492.759765625,,,,,,,,,,,,,0,,,,,,,,,,,,,,
,19697222.425,10.04845,48246.064453125,-0.000117330269713978,5.64441125814497E-7,1,0.999253354069792,40.0298881530762,1.99445860479842,14.2400003969669,-0.0013222686107681,-0.000236596009217534,0.25,1.39970019786723E-7,-0.000117183649159162,-7.22409842129817E-7,10.0481,10.0481,48238.51171875,48253.6171875,54.2332948068327,19.5584198924732,12.278775,0,0,0,40,4449,10.04845,48246.064453125,,,,,,,,,,,,,0,,,,,,,,,,,,,,
,19697295.85,10.0512,51916.9765625,-0.00013037708596466,5.81828066751291E-7,1,0.999253354069792,40.0298881530762,1.99457998504654,14.2400003969669,-0.00146870571627906,-0.000269841313366183,0.25,-4.43541854096379E-7,-0.000130258295592305,-1.40781216765643E-6,10.0513,10.0513,51906.8515625,51927.1015625,54.1137056433903,19.5603373620014,11.899124,0,0,0,40,4449,10.0512,51916.9765625,,,,,,,,,,,,,0,,,,,,,,,,,,,,
,19697371.585,10.0534,55699.75,-0.000141485781715944,6.01805865847038E-7,1,0.999253354069792,40.0298881530762,1.99449256427429,14.2400003969669,-0.00159226543471159,-0.000304641454831312,0.25,-1.51586118131984E-6,-0.000141402110976184,-2.56641614751245E-6,10.0534,10.0534,55694.6328125,55704.8671875,54.004277650698,19.5580151639897,11.899124,0,0,0,40,4449,10.0534,55699.75,,,,,,,,,,,,,0,,,,,,,,,,,,,,
,19697443.875,10.05665,59315.76953125,-0.000154355404967688,6.21570891837125E-7,1,0.999253354069792,40.0298881530762,1.99440328774512,14.2400003969669,-0.00173931294098291,-0.000323105771664963,0.25,-8.23497520588096E-7,-0.000154323890756342,-1.97223862425465E-6,10.0573,10.0573,59308.11328125,59323.42578125,54.0128755644096,19.5576397506232,12.278775,0,0,0,40,4449,10.05665,59315.76953125,,,,,,,,,,,,,0,,,,,,,,,,,,,,
,19697520.29,10.0595,63134.16796875,-0.000166842672056414,5.65442340988953E-7,1,0.999253354069792,40.0298881530762,1.99445741168476,14.2400003969669,-0.00187948246230659,-0.000356343191829795,0.25,-1.50855149926861E-6,-0.000166863181994061,-2.74998124163157E-6,10.0595,10.0595,63126.5703125,63141.765625,53.7924563219865,19.5570855737866,12.278775,0,0,0,40,4449,10.0595,63134.16796875,,,,,,,,,,,,,0,,,,,,,,,,,,,,
,19697595.22,10.0611,66879.88671875,-0.000180266150165545,6.18910272297886E-7,1,0.999253354069792,40.0298881530762,1.99442543690839,14.2400003969669,-0.00203269939850669,-0.000377633194431222,0.25,-9.69121061503652E-7,-0.00018035364453941,-2.30713416425662E-6,10.0611,10.0611,66874.8984375,66884.875,54.0605549040826,19.5576917298082,12.278775,0,0,0,40,4449,10.0611,66879.88671875,,,,,,,,,,,,,0,,,,,,,,,,,,,,
,19697671.185,10.0654,70675.3125,-0.000193162774374335,7.18488318543743E-7,1,0.999253354069792,40.0298881530762,1.99445928913964,14.2400003969669,-0.00218022993774892,-0.000397229067906183,0.25,-3.758950091505E-7,-0.000193324427460902,-1.80293738453105E-6,10.0654,10.0654,70672.9140625,70677.7109375,53.8057440068134,19.5604699221606,11.899124,0,0,0,40,4449,10.0654,70675.3125,,,,,,,,,,,,,0,,,,,,,,,,,,,,
,19697751.43,10.07,74688.0625,-0.000207342875586087,5.6886629173424E-7,1,0.999253354069792,40.0298881530762,1.99446068243308,14.2400003969669,-0.0023421867079916,-0.000420233007488947,0.25,1.43453643108033E-7,-0.000207588757967339,-1.3777334544257E-6,10.07,10.07,74680.6953125,74695.4296875,54.0261632492365,19.5591709734855,12.278775,0,0,0,40,4449,10.07,74688.0625,,,,,,,,,,,,,0,,,,,,,,,,,,,,
,19697828.225,10.07675,78524.3046875,-0.000219436093160366,6.55606073843651E-7,1,0.999253354069792,40.0298881530762,1.99439397507876,14.2400003969669,-0.00247614439104337,-0.000463261145598621,0.25,-1.48983900942993E-6,-0.000219750277840961,-3.08947702424825E-6,10.0774,10.0774,78519.34375,78529.265625,54.0136571929288,19.556866179179,12.278775,0,0,0,40,4449,10.07675,78524.3046875,,,,,,,,,,,,,0,,,,,,,,,,,,,,
,19697904.54,10.0824,82340.62890625,-0.000232564863831091,6.09830489498915E-7,1,0.999253354069792,40.0298881530762,1.99440116762481,14.2400003969669,-0.00262489770528861,-0.000491943650618844,0.25,-1.66788353425008E-6,-0.000232963524820076,-3.3483368825289E-6,10.0824,10.0824,82338.0390625,82343.21875,53.6103368770057,19.5591460334896,11.899124,0,0,0,40,4449,10.0824,82340.62890625,,,,,,,,,,,,,0,,,,,,,,,,,,,,
,19697979.635,10.0882,86096.55859375,-0.00024569940379728,7.49291490373906E-7,1,0.999253354069792,40.0298881530762,1.99447444127823,14.2400003969669,-0.00277421298777851,-0.000518584083548986,0.25,-1.66555569494365E-6,-0.000246186909880931,-3.42319090362534E-6,10.0882,10.0882,86086.28125,86106.8359375,54.068371189275,19.5585035799153,12.658426,0,0,0,40,4449,10.0882,86096.55859375,,,,,,,,,,,,,0,,,,,,,,,,,,,,
,19698058.8,10.09355,89999.515625,-0.000259302256632412,4.8878277346009E-7,1,0.999253354069792,40.0298881530762,1.99448862011583,14.2400003969669,-0.00293030108915054,-0.000537941782227703,0.25,-9.39548287047656E-7,-0.000259890898958093,-2.77158051361325E-6,10.0943,10.0943,89999.3125,89999.71875,54.2708129757557,19.5580645017616,12.278775,0,0,0,40,4417,10.09355,89999.515625,,,,,,,,,,,,,0,,,,,,,,,,,,,,