File: data/monolayers/magneticStructure/ML_Ac_CoFe_C_AH/PPMS/DD205_4_KOELNPPMS_HYST_100OE_300K.DAT
[Header]
; VSM Data File (default extension .dat)
; Copyright (c) 2003-2013, Quantum Design, Inc. All rights reserved.
TITLE,
FILEOPENTIME,19758180.13,08/17/2018,4:21 pm
BYAPP,VSM,2.0,2.0
INFO,PPMS VSM Option Release 1.4.10 Build 1,APPNAME
INFO,Quantum Design Linear Motor Servo Controller,MOTOR_MODULE_NAME
INFO,3101-100 M1,MOTOR_HW_VERSION
INFO,MMC1014,MOTOR_SERIAL_NUMBER
INFO,SRV No X-over 01.03.11,MOTOR_SOFTWARE_VERSION
INFO,Quantum Design VSM Detection Module,VSM_MODULE_NAME
INFO,3101-150 F0,VSM_HW_VERSION
INFO,VSM707,VSM_SERIAL_NUMBER
INFO,VSM No X-over 01.02.05 May 20 2008 13:51:47,VSM_SOFTWARE_VERSION
INFO,704,PREAMP_SERIAL_NUMBER
INFO,822,COIL_SERIAL_NUMBER
INFO,0,MOMENT_UNITS
INFO,,SAMPLE_MATERIAL
INFO,,SAMPLE_COMMENT
INFO,,SAMPLE_MASS
INFO,,SAMPLE_VOLUME
INFO,,SAMPLE_MOLECULAR_WEIGHT
INFO,,SAMPLE_SIZE
INFO,,SAMPLE_SHAPE
DATATYPE,COMMENT,1
DATATYPE,TIME,2
STARTUPAXIS,X,2
STARTUPAXIS,Y1,5
[Data]
Comment,Time Stamp (sec),Temperature (K),Magnetic Field (Oe),Moment (emu),M. Std. Err. (emu),Transport Action,Averaging Time (sec),Frequency (Hz),Peak Amplitude (mm),Center Position (mm),Coil Signal' (mV),Coil Signal" (mV),Range (mV),M. Quad. Signal (emu),M. Raw' (emu),M. Raw" (emu),Min. Temperature (K),Max. Temperature (K),Min. Field (Oe),Max. Field (Oe),Mass (grams),Motor Lag (deg),Pressure (Torr),VSM Status (code),Motor Status (code),Measure Status (code),Measure Count,PPMS Status (code),System Temp. (K),System Field (Oe),Sample Position (deg),Bridge 1 Resistance (ohms),Bridge 1 Excitation (에),Bridge 2 Resistance (ohms),Bridge 2 Excitation (에),Bridge 3 Resistance (ohms),Bridge 3 Excitation (에),Bridge 4 Resistance (ohms),Bridge 4 Excitation (에),Signal 1 Vin (V),Signal 2 Vin (V),Digital Inputs (code),Drive 1 Iout (mA),Drive 1 Ipower (W),Drive 2 Iout (mA),Drive 2 Ipower (W),Pressure (),Map 20 (),Map 21 (),Map 22 (),Map 23 (),Map 24 (),Map 25 (),Map 26 (),Map 27 (),Map 28 (),Map 29 ()
,19758481.985,300.7536,0.449101328849793,-1.69942978367964E-5,4.0624382570295E-7,1,0.999253354069792,40.0298881530762,1.98231118377696,14.2400003969669,-0.000192587185684511,-2.28256968148084E-5,0.25,9.11503784675162E-7,-1.69939362650611E-5,9.00200954820259E-7,300.7528,300.7528,0.395818114280701,0.502384543418884,53.7736972375249,19.541848624155,27.844467,0,0,0,40,4417,300.7536,0.449101328849793,,,,,,,,,,,,,0,,,,,,,,,,,,,,
,19758571.75,300.72795,3600.01574707031,2.69815513692399E-5,5.19780322427394E-7,1,0.999253354069792,40.0298881530762,1.98224457163863,14.2500000074506,0.00030309179726266,5.16262450728509E-5,0.25,-7.66946515197913E-8,2.69800953307914E-5,-5.88329706303533E-8,300.728,300.728,3592.33764648438,3607.69384765625,53.8776538305826,19.5438099111923,27.464817,0,0,0,40,4449,300.72795,3600.01574707031,,,,,,,,,,,,,0,,,,,,,,,,,,,,
,19758647.775,300.7185,7402.2080078125,1.96254891949124E-5,1.04178920415023E-6,1,0.999253354069792,40.0298881530762,1.98235807171554,14.2400003969669,0.000221170918195568,3.35141418004688E-5,0.25,-4.15504872363974E-7,1.96246753416081E-5,-4.02499999520893E-7,300.7188,300.7188,7397.369140625,7407.046875,53.8737456879865,19.5459341148501,27.464817,0,0,0,40,4449,300.7185,7402.2080078125,,,,,,,,,,,,,0,,,,,,,,,,,,,,
,19758725.845,300.7144,11305.2456054688,9.10349714899045E-6,1.27334616153033E-6,1,0.999253354069792,40.0298881530762,1.98233034396404,14.2400003969669,0.000102537713867946,1.58543409278022E-5,0.25,-1.65244208101369E-7,9.10310306878489E-6,-1.5921721295965E-7,300.7144,300.7144,11295.240234375,11315.2509765625,53.811215406448,19.5432955015768,27.464817,0,0,0,40,4449,300.7144,11305.2456054688,,,,,,,,,,,,,0,,,,,,,,,,,,,,
,19758803.095,300.7152,15165.9697265625,-3.13070851051507E-6,1.8456813692774E-6,1,0.999253354069792,40.0298881530762,1.9823926553404,14.2400003969669,-3.17220745536249E-5,-2.58954268825305E-5,0.25,-1.76378954837997E-6,-3.12937033420275E-6,-1.76576014378423E-6,300.7152,300.7152,15163.4130859375,15168.5263671875,54.149660555275,19.5439504669754,27.085165,0,0,0,40,4449,300.7152,15165.9697265625,,,,,,,,,,,,,0,,,,,,,,,,,,,,
,19758879.765,300.71515,18996.326171875,-1.48226366338478E-5,2.05728032532366E-6,1,0.999253354069792,40.0298881530762,1.98232261830427,14.2400003969669,-0.000163886735097902,-4.35234333488103E-5,0.25,-1.30814077443123E-6,-1.48209544882716E-5,-1.31785289585792E-6,300.715,300.715,18986.439453125,19006.212890625,54.0308530203519,19.5460858508242,27.464817,0,0,0,40,4449,300.71515,18996.326171875,,,,,,,,,,,,,0,,,,,,,,,,,,,,
,19758957.025,300.71405,22859.5830078125,-2.6370047362598E-5,2.76583043680843E-6,1,0.999253354069792,40.0298881530762,1.98241986147725,14.2400003969669,-0.00029312160395883,-6.85044077416222E-5,0.25,-1.53204436144196E-6,-2.63675826756482E-5,-1.54935330209422E-6,300.7139,300.7139,22854.52734375,22864.638671875,53.8440438042557,19.5444043737739,27.844467,0,0,0,40,4449,300.71405,22859.5830078125,,,,,,,,,,,,,0,,,,,,,,,,,,,,
,19759033.72,300.71005,26689.728515625,-3.984194255483E-5,3.0883985044639E-6,1,0.999253354069792,40.0298881530762,1.98240347967657,14.2400003969669,-0.000441433047827681,-0.000111782099721307,0.25,-3.05224647979971E-6,-3.98377413609727E-5,-3.07833774390312E-6,300.7101,300.7101,26657.205078125,26722.251953125,54.1379361274865,19.5445742793868,27.844467,0,0,0,40,4449,300.71005,26689.728515625,,,,,,,,,,,,,0,,,,,,,,,,,,,,
,19759112.79,300.7051,30642.9423828125,-5.35717767926231E-5,3.30755377667457E-6,1,0.999253354069792,40.0298881530762,1.98233324337145,14.2500000074506,-0.000597473545390106,-0.000127561186782781,0.25,-2.07914012362374E-6,-5.35674756640898E-5,-2.11430544421234E-6,300.7051,300.7051,30640.560546875,30645.32421875,54.0253816207173,19.5437684778656,27.844467,0,0,0,40,4449,300.7051,30642.9423828125,,,,,,,,,,,,,0,,,,,,,,,,,,,,
,19759192.225,300.69785,34613.33984375,-6.67245325765811E-5,3.96442456670572E-6,1,0.999253354069792,40.0298881530762,1.98241490984326,14.2400003969669,-0.000745915060598127,-0.000148944656034171,0.25,-1.70430148103049E-6,-6.67197800498687E-5,-1.74811272782384E-6,300.6991,300.6991,34608.5546875,34618.125,53.9894267088326,19.542837387135,27.844467,0,0,0,40,4449,300.69785,34613.33984375,,,,,,,,,,,,,0,,,,,,,,,,,,,,
,19759268.5,300.6888,38426.0078125,-7.82470498773981E-5,3.64211967806198E-6,1,0.999253354069792,40.0298881530762,1.98228467628016,14.2400003969669,-0.000879213945577346,-0.00014843326764345,0.25,3.36702153378433E-7,-7.8243042246681E-5,2.85240107821933E-7,300.688,300.688,38416.10546875,38435.91015625,54.0535202474096,19.5447475911354,27.464817,0,0,0,40,4449,300.6888,38426.0078125,,,,,,,,,,,,,0,,,,,,,,,,,,,,
,19759346.04,300.6827,42301.78125,-9.02462418407324E-5,4.4257884607835E-6,1,0.999253354069792,40.0298881530762,1.98241901396522,14.2400003969669,-0.0010105332515896,-0.000191836286054059,0.25,-1.44893169185116E-6,-9.02404368332475E-5,-1.50813581380476E-6,300.6827,300.6827,42299.3359375,42304.2265625,53.912827113948,19.5428007667718,27.085165,0,0,0,40,4449,300.6827,42301.78125,,,,,,,,,,,,,0,,,,,,,,,,,,,,
,19759423.245,300.67185,46159.9609375,-0.00010786420982438,3.76858049393303E-6,1,0.999253354069792,40.0298881530762,1.98247333233126,14.2400003969669,-0.001205839268041,-0.00024085704839671,0.25,-2.76169851322617E-6,-0.000107856643944577,-2.83234629240737E-6,300.6737,300.6737,46152.34375,46167.578125,53.8807803446595,19.5425268609069,27.085165,0,0,0,40,4449,300.67185,46159.9609375,,,,,,,,,,,,,0,,,,,,,,,,,,,,
,19759500.825,300.6631,50038.3046875,-0.000116781309641579,4.27703160839444E-6,1,0.999253354069792,40.0298881530762,1.98239304179582,14.2400003969669,-0.00131096244321945,-0.000229088924909593,0.25,-1.69628007949051E-7,-0.000116775012178027,-2.46199646586667E-7,300.6631,300.6631,50036.09765625,50040.51171875,53.983955309198,19.5427253792068,27.085165,0,0,0,40,4449,300.6631,50038.3046875,,,,,,,,,,,,,0,,,,,,,,,,,,,,
,19759578.71,300.65125,53931.20703125,-0.000132079347289692,3.98477022881282E-6,1,0.999253354069792,40.0298881530762,1.98238176984606,14.2400003969669,-0.00147842130077232,-0.000283722862287273,0.25,-2.38500996958869E-6,-0.000132070851054143,-2.4714210488372E-6,300.6499,300.6499,53918.64453125,53943.76953125,53.9870818232749,19.5412616073799,27.844467,0,0,0,40,4449,300.65125,53931.20703125,,,,,,,,,,,,,0,,,,,,,,,,,,,,
,19759656.835,300.6403,57833.69140625,-0.000140249546842531,4.4257347469837E-6,1,0.999253354069792,40.0298881530762,1.98239876009904,14.2500000074506,-0.00156684277867288,-0.000318849837118839,0.25,-4.09770661129388E-6,-0.000140239564481103,-4.18930004633268E-6,300.6402,300.6402,57831.1640625,57836.21875,53.9276780558134,19.5425935940685,27.844467,0,0,0,40,4449,300.6403,57833.69140625,,,,,,,,,,,,,0,,,,,,,,,,,,,,
,19759735.17,300.62875,61749.474609375,-0.000156182059807031,4.97002800204868E-6,1,0.999253354069792,40.0298881530762,1.98245232325344,14.2400003969669,-0.00175029500167339,-0.000323847700280994,0.25,-1.78181750609688E-6,-0.000156172838251024,-1.88386850926219E-6,300.6288,300.6288,61744.37890625,61754.5703125,54.0308530203519,19.5405689488932,27.464817,0,0,0,40,4449,300.62875,61749.474609375,,,,,,,,,,,,,0,,,,,,,,,,,,,,
,19759812.305,300.6199,65605.4296875,-0.000174098661306054,4.23056689067371E-6,1,0.999253354069792,40.0298881530762,1.98227401089051,14.2400003969669,-0.0019513802073286,-0.000358283059196811,0.25,-1.74725223649966E-6,-0.000174088603841922,-1.86091855339186E-6,300.619,300.619,65597.84375,65613.015625,53.8323193764672,19.5401605651694,27.844467,0,0,0,40,4449,300.6199,65605.4296875,,,,,,,,,,,,,0,,,,,,,,,,,,,,
,19759891.99,300.60785,69588.93359375,-0.000185433655332776,3.50446179067028E-6,1,0.999253354069792,40.0298881530762,1.9823776094734,14.2400003969669,-0.00207912766142626,-0.000378196452610521,0.25,-1.55543273054361E-6,-0.000185423234127035,-1.67640100557628E-6,300.6073,300.6073,69586.2890625,69591.578125,53.8479519468519,19.5418910812824,27.844467,0,0,0,40,4449,300.60785,69588.93359375,,,,,,,,,,,,,0,,,,,,,,,,,,,,
,19759969.585,300.596,73466.9296875,-0.000200160731355139,4.25928898437862E-6,1,0.999253354069792,40.0298881530762,1.98220578647468,14.2500000074506,-0.00224322850256566,-0.000413036053751228,0.25,-2.10989645624363E-6,-0.000200149298468178,-2.24032925807555E-6,300.596,300.596,73459.40625,73474.453125,53.8893782583711,19.5428147840109,27.844467,0,0,0,40,4449,300.596,73466.9296875,,,,,,,,,,,,,0,,,,,,,,,,,,,,
,19760046.065,300.58415,77290.55078125,-0.00021300393575226,3.86030262981691E-6,1,0.999253354069792,40.0298881530762,1.98240474434796,14.2400003969669,-0.00239097477277547,-0.000418912753789816,0.25,-4.04778536347956E-7,-0.000212993071912691,-5.43544181449073E-7,300.584,300.584,77288.15625,77292.9453125,53.8815619731788,19.5404336619539,27.464817,0,0,0,40,4449,300.58415,77290.55078125,,,,,,,,,,,,,0,,,,,,,,,,,,,,
,19760123.44,300.57345,81156.98046875,-0.000220838908594064,4.48765977990499E-6,1,0.999253354069792,40.0298881530762,1.98232008101355,14.2400003969669,-0.00248253564311072,-0.000412871541574505,0.25,1.48900619692141E-6,-0.000220828984839039,1.34517907286091E-6,300.5745,300.5745,81146.9296875,81167.03125,53.8065256353326,19.5397300222047,27.464817,0,0,0,40,4449,300.57345,81156.98046875,,,,,,,,,,,,,0,,,,,,,,,,,,,,
,19760201.36,300.55995,85055.29296875,-0.000236063778913517,5.04872705728348E-6,1,0.999253354069792,40.0298881530762,1.98229772622287,14.2500000074506,-0.00264711836188543,-0.00047907340981752,0.25,-1.76991012325593E-6,-0.000236051111390694,-1.92334064719054E-6,300.5593,300.5593,85045.2890625,85065.296875,53.8018358642172,19.5398770722176,27.085165,0,0,0,40,4449,300.55995,85055.29296875,,,,,,,,,,,,,0,,,,,,,,,,,,,,
,19760275.33,300.54985,88748.3203125,-0.000249029715203857,3.86357643654401E-6,1,0.999253354069792,40.0298881530762,1.98238739835475,14.2400003969669,-0.0027916660465746,-0.000510999982005996,0.25,-2.36520894190149E-6,-0.000249016133001893,-2.5268933502181E-6,300.5499,300.5499,88738.328125,88758.3125,53.7127302130249,19.5398657711938,27.464817,0,0,0,40,4449,300.54985,88748.3203125,,,,,,,,,,,,,0,,,,,,,,,,,,,,
,19760365.21,300.53915,87691.02734375,-0.000248333383543556,4.83297137588929E-6,1,0.999253354069792,40.0298881530762,1.98232478754455,14.2400003969669,-0.00278301185886295,-0.000513972807665935,0.25,-2.75191231771616E-6,-0.00024831967408803,-2.91317808855936E-6,300.5404,300.5404,87683.3828125,87698.671875,53.7596279241788,19.5390419275872,27.844467,0,0,0,40,4449,300.53915,87691.02734375,,,,,,,,,,,,,0,,,,,,,,,,,,,,
,19760440.99,300.5346,83904.51953125,-0.000236828987375225,4.47196124620092E-6,1,0.999253354069792,40.0298881530762,1.98229747767409,14.2400003969669,-0.0026540282859307,-0.000490282477889081,0.25,-2.63554563749825E-6,-0.000236815929087126,-2.78949525503209E-6,300.5346,300.5346,83899.71875,83909.3203125,53.8268479768326,19.5405779488078,27.844467,0,0,0,40,4449,300.5346,83904.51953125,,,,,,,,,,,,,0,,,,,,,,,,,,,,
,19760517.14,300.53475,80097.85546875,-0.000222980016395305,3.11833077011258E-6,1,0.999253354069792,40.0298881530762,1.9821281414318,14.2400003969669,-0.00250249244161753,-0.000439254000830027,0.25,-4.93202956421012E-7,-0.000222969001045019,-6.38388316571469E-7,300.536,300.536,80090.6953125,80105.015625,53.9182985135826,19.5419514000019,27.464817,0,0,0,40,4449,300.53475,80097.85546875,,,,,,,,,,,,,0,,,,,,,,,,,,,,
,19760595.605,300.5351,76177.14453125,-0.000204365544176403,3.28388120535885E-6,1,0.999253354069792,40.0298881530762,1.98218322003159,14.2500000074506,-0.00230012076112213,-0.0003652110608623,0.25,2.87781496916803E-6,-0.000204357604320479,2.74445598769194E-6,300.5349,300.5349,76167.1484375,76187.140625,53.8995394291211,19.539823204705,27.085165,0,0,0,40,4449,300.5351,76177.14453125,,,,,,,,,,,,,0,,,,,,,,,,,,,,
,19760673,300.5396,72306.18359375,-0.000192693717039583,3.64929790180038E-6,1,0.999253354069792,40.0298881530762,1.98215922960877,14.2400003969669,-0.00216287135469513,-0.000378162868437283,0.25,-2.98157180518961E-7,-0.000192684225354226,-4.23876527173376E-7,300.5383,300.5383,72298.671875,72313.6953125,53.9964613655057,19.5410218133972,27.464817,0,0,0,40,4449,300.5396,72306.18359375,,,,,,,,,,,,,0,,,,,,,,,,,,,,
,19760749.895,300.5456,68462.6484375,-0.000183302924852095,3.13411421421805E-6,1,0.999253354069792,40.0298881530762,1.9823354235708,14.2500000074506,-0.00206727602048907,-0.000304141666825694,0.25,4.67020701915357E-6,-0.000183297081495828,4.55026117954348E-6,300.5456,300.5456,68460.2734375,68465.0234375,53.8878150013326,19.543842997596,27.844467,0,0,0,40,4449,300.5456,68462.6484375,,,,,,,,,,,,,0,,,,,,,,,,,,,,
,19760826.175,300.54965,64649.15234375,-0.000173117708128316,3.76906988886661E-6,1,0.999253354069792,40.0298881530762,1.9821891560285,14.2400003969669,-0.00194566179511366,-0.000325364084272193,0.25,1.01360840659163E-6,-0.000173109936785203,9.00386195826457E-7,300.5493,300.5493,64641.58203125,64656.72265625,53.8182500631211,19.5429232569287,27.085165,0,0,0,40,4449,300.54965,64649.15234375,,,,,,,,,,,,,0,,,,,,,,,,,,,,
,19760903.91,300.5569,60765.53125,-0.00015490500903709,3.0781469703717E-6,1,0.999253354069792,40.0298881530762,1.98213502727666,14.2400003969669,-0.00173827803597934,-0.000306400160166046,0.25,-4.53318596108029E-7,-0.000154897117027644,-5.54657110278321E-7,300.5569,300.5569,60762.828125,60768.234375,53.9698859958519,19.5419867896977,27.085165,0,0,0,40,4449,300.5569,60765.53125,,,,,,,,,,,,,0,,,,,,,,,,,,,,
,19760980.82,300.5618,56919.9296875,-0.000144773867408901,3.75114018698579E-6,1,0.999253354069792,40.0298881530762,1.98236143514411,14.2400003969669,-0.00162715610539392,-0.000272605644429843,0.25,8.04224599533234E-7,-0.000144767262284838,7.09366453046049E-7,300.5618,300.5618,56914.92578125,56924.93359375,53.9472187687942,19.5412435336257,27.464817,0,0,0,40,4449,300.5618,56919.9296875,,,,,,,,,,,,,0,,,,,,,,,,,,,,
,19761060,300.5662,52961.791015625,-0.000129774776041689,3.1608379019809E-6,1,0.999253354069792,40.0298881530762,1.98230583406784,14.2400003969669,-0.00145927723998172,-0.000240086473531511,0.25,1.10124551213308E-6,-0.000129769077422104,1.01611651646955E-6,300.5662,300.5662,52956.6875,52966.89453125,53.7893298079095,19.5436584853903,27.464817,0,0,0,40,4449,300.5662,52961.791015625,,,,,,,,,,,,,0,,,,,,,,,,,,,,
,19761137.21,300.57185,49104.052734375,-0.000115523957907031,3.10920790438564E-6,1,0.999253354069792,40.0298881530762,1.98221140769926,14.2400003969669,-0.00129971471780029,-0.000209424007825363,0.25,1.36232621615174E-6,-0.000115519106818854,1.28645846926831E-6,300.5706,300.5706,49098.83203125,49109.2734375,54.0261632492365,19.5441995573211,27.464817,0,0,0,40,4449,300.57185,49104.052734375,,,,,,,,,,,,,0,,,,,,,,,,,,,,
,19761214.775,300.5749,45228.732421875,-0.000103540659703762,3.44341456819128E-6,1,0.999253354069792,40.0298881530762,1.98217944790987,14.2400003969669,-0.00116114568499171,-0.00020923552176688,0.25,-6.97252377756172E-7,-0.000103535035996229,-7.65215627734361E-7,300.5749,300.5749,45226.14453125,45231.3203125,53.7643176952942,19.5431215894716,27.844467,0,0,0,40,4449,300.5749,45228.732421875,,,,,,,,,,,,,0,,,,,,,,,,,,,,
,19761290.235,300.5813,41455.431640625,-8.97094671484046E-5,2.43275186459187E-6,1,0.999253354069792,40.0298881530762,1.98193599322994,14.2400003969669,-0.00100628832093062,-0.000179131895669746,0.25,-4.1413501727697E-7,-8.97046941475235E-5,-4.73078632922032E-7,300.5814,300.5814,41448.02734375,41462.8359375,53.8338826335057,19.5438572279651,27.464817,0,0,0,40,4449,300.5813,41455.431640625,,,,,,,,,,,,,0,,,,,,,,,,,,,,
,19761366.78,300.58465,37629.880859375,-7.63786525446899E-5,2.62339101214528E-6,1,0.999253354069792,40.0298881530762,1.9821961624052,14.2400003969669,-0.000859752852292866,-0.000135842452023832,0.25,1.13392837383886E-6,-7.63755534996317E-5,1.08362622104093E-6,300.5846,300.5846,37625.02734375,37634.734375,53.9956797369865,19.5431950725654,27.844467,0,0,0,40,4449,300.58465,37629.880859375,,,,,,,,,,,,,0,,,,,,,,,,,,,,
,19761442.785,300.58755,33829.529296875,-6.44186252551531E-5,2.25982494070611E-6,1,0.999253354069792,40.0298881530762,1.98230672939107,14.2400003969669,-0.000725578920843029,-0.0001121816234676,0.25,1.16975388993934E-6,-6.44161426390031E-5,1.12728231993798E-6,300.5869,300.5869,33826.91796875,33832.140625,54.1543503263903,19.5437004864179,27.464817,0,0,0,40,4449,300.58755,33829.529296875,,,,,,,,,,,,,0,,,,,,,,,,,,,,
,19761519.875,300.59225,29979.3359375,-5.28002785544217E-5,1.95380771219106E-6,1,0.999253354069792,40.0298881530762,1.98238420251317,14.2400003969669,-0.000593229488939673,-0.000100658026295646,0.25,1.83491212225116E-7,-5.279772189803E-5,1.48690389607502E-7,300.593,300.593,29974.44921875,29984.22265625,53.9644145962173,19.5436021178371,27.464817,0,0,0,40,4449,300.59225,29979.3359375,,,,,,,,,,,,,0,,,,,,,,,,,,,,
,19761596.545,300.5954,26145.9267578125,-3.84271391801877E-5,1.74929123841768E-6,1,0.999253354069792,40.0298881530762,1.98236351249302,14.2400003969669,-0.000431429777541758,-7.50348541329333E-5,0.25,-2.48217126050138E-8,-3.84251679671149E-5,-5.01613538850224E-8,300.5968,300.5968,26135.861328125,26155.9921875,53.9980246225442,19.5461195938501,27.844467,0,0,0,40,4449,300.5954,26145.9267578125,,,,,,,,,,,,,0,,,,,,,,,,,,,,
,19761673.07,300.6011,22323.568359375,-2.52867003496231E-5,1.24225262092097E-6,1,0.999253354069792,40.0298881530762,1.98207963987103,14.2400003969669,-0.000287693192778998,-2.72468762806995E-5,0.25,1.95416367130666E-6,-2.52866973245615E-5,1.93737563726374E-6,300.6011,300.6011,22318.900390625,22328.236328125,53.9222066561788,19.5452536886879,27.464817,0,0,0,40,4449,300.6011,22323.568359375,,,,,,,,,,,,,0,,,,,,,,,,,,,,
,19761749.57,300.60405,18498.423828125,-1.22580653264598E-5,1.13842104244079E-6,1,0.999253354069792,40.0298881530762,1.98214365915607,14.2500000074506,-0.000137582304748546,-2.40890408749489E-5,0.25,-2.17865241539016E-8,-1.22574224469234E-5,-2.98812638093765E-8,300.6045,300.6045,18490.86328125,18505.984375,54.1168321574673,19.5456150852796,28.224119,0,0,0,40,4449,300.60405,18498.423828125,,,,,,,,,,,,,0,,,,,,,,,,,,,,
,19761826.12,300.60755,14672.8525390625,-8.95442129556851E-7,9.9582415457653E-7,1,0.999253354069792,40.0298881530762,1.98228998274735,14.2400003969669,-1.08175915015311E-5,2.6648432050918E-6,0.25,3.924797434686E-7,-8.9565546776345E-7,3.9186773459062E-7,300.6055,300.6055,14667.8515625,14677.853515625,54.4185407658904,19.5459417660416,27.844467,0,0,0,40,4449,300.60755,14672.8525390625,,,,,,,,,,,,,0,,,,,,,,,,,,,,
,19761902.345,300.60815,10862.5678710938,9.41072919065374E-6,6.76015728783039E-7,1,0.999253354069792,40.0298881530762,1.9822589939323,14.2400003969669,0.000105303897181335,2.03777423198146E-5,0.25,1.84437306674835E-7,9.41012253433222E-6,1.9065187251374E-7,300.608,300.608,10849.87890625,10875.2568359375,54.0285081347942,19.5453858922336,27.085165,0,0,0,40,4449,300.60815,10862.5678710938,,,,,,,,,,,,,0,,,,,,,,,,,,,,
,19761978.365,300.61345,7061.34228515625,2.10941620920071E-5,5.11306300592247E-7,1,0.999253354069792,40.0298881530762,1.98238396043379,14.2400003969669,0.000237301907507368,3.84710505141385E-5,0.25,-2.28564179241084E-7,2.10932221641076E-5,-2.14592443044262E-7,300.6147,300.6147,7051.251953125,7071.4326171875,53.9503452828711,19.5471766303462,27.844467,0,0,0,40,4449,300.61345,7061.34228515625,,,,,,,,,,,,,0,,,,,,,,,,,,,,
,19762052.86,300.6131,3340.57177734375,2.73530585201351E-5,5.23888055125075E-7,1,0.999253354069792,40.0298881530762,1.98236755004937,14.2500000074506,0.000308242018846868,4.68139792458665E-5,0.25,-5.69938416372847E-7,2.73520203792591E-5,-5.51796721834359E-7,300.6131,300.6131,3338.16088867188,3342.98266601562,54.1645114971403,19.5464894829262,27.844467,0,0,0,40,4449,300.6131,3340.57177734375,,,,,,,,,,,,,0,,,,,,,,,,,,,,
,19762126.525,300.6169,-342.812271118164,-1.31563815704365E-5,3.76507514994077E-7,1,0.999253354069792,40.0298881530762,1.9822905595531,14.2400003969669,-0.000147788690136647,-2.52011831899378E-5,0.25,3.49789142961624E-8,-1.3155721824386E-5,2.62624029762475E-8,300.6169,300.6169,-350.319854736328,-335.3046875,54.268468090198,19.5450309144068,27.464817,0,0,0,40,4449,300.6169,-342.812271118164,,,,,,,,,,,,,0,,,,,,,,,,,,,,
,19762200.515,300.61605,-4036.86462402344,-2.54684613958129E-5,5.72346897289838E-7,1,0.999253354069792,40.0298881530762,1.98232380416693,14.2400003969669,-0.000285191327571597,-5.40174537819419E-5,0.25,-3.98224370707969E-7,-2.54668771999092E-5,-4.15066150346784E-7,300.6168,300.6168,-4044.33715820313,-4029.39208984375,54.0441407051788,19.5465325417657,27.464817,0,0,0,40,4449,300.61605,-4036.86462402344,,,,,,,,,,,,,0,,,,,,,,,,,,,,
,19762275.76,300.6159,-7798.50366210937,-1.7785197217279E-5,7.67492186991914E-7,1,0.999253354069792,40.0298881530762,1.98224795820777,14.2400003969669,-0.000198615380641015,-4.07956443340516E-5,0.25,-5.520065580797E-7,-1.77839105060883E-5,-5.63746502969736E-7,300.6164,300.6164,-7803.57958984375,-7793.427734375,54.0417958196211,19.5487716209269,27.844467,0,0,0,40,4449,300.6159,-7798.50366210937,,,,,,,,,,,,,0,,,,,,,,,,,,,,
,19762350.04,300.6144,-11512.1801757813,-8.01672215097503E-6,9.47005007932056E-7,1,0.999253354069792,40.0298881530762,1.98239781462026,14.2400003969669,-8.99242725742932E-5,-1.61309073254194E-5,0.25,-4.76254132543869E-8,-8.0162760452108E-6,-5.29243070718865E-8,300.6155,300.6155,-11517.16796875,-11507.1923828125,54.0457039622173,19.5458535379609,28.224119,0,0,0,40,4449,300.6144,-11512.1801757813,,,,,,,,,,,,,0,,,,,,,,,,,,,,
,19762426.785,300.6067,-15347.6215820313,3.32027873703547E-6,8.88943938255795E-7,1,0.999253354069792,40.0298881530762,1.9827650573244,14.2400003969669,3.79455756755233E-5,2.67006648736923E-6,0.25,-3.37514360848822E-7,3.32033111236314E-6,-3.35302827582144E-7,300.6067,300.6067,-15349.7822265625,-15345.4609375,54.3083311446788,19.5460813900885,27.085165,0,0,0,40,4449,300.6067,-15347.6215820313,,,,,,,,,,,,,0,,,,,,,,,,,,,,
,19762503.38,300.5999,-19175.904296875,1.51715572576168E-5,1.40810430345512E-6,1,0.999253354069792,40.0298881530762,1.98254573249617,14.2400003969669,0.000171511821986937,2.2917335510196E-5,0.25,-5.87753326310561E-7,1.51711698906354E-5,-5.77704370471648E-7,300.5993,300.5993,-19183.794921875,-19168.013671875,54.0441407051788,19.5486369958045,27.844467,0,0,0,40,4449,300.5999,-19175.904296875,,,,,,,,,,,,,0,,,,,,,,,,,,,,
,19762578.995,300.5923,-22955.802734375,3.05564199416523E-5,1.27685029345262E-6,1,0.999253354069792,40.0298881530762,1.98247878488656,14.2400003969669,0.00034395809043475,5.46162332588576E-5,0.25,-4.30281701202367E-7,3.05551516243166E-5,-4.10095804918211E-7,300.5922,300.5922,-22961.15234375,-22950.453125,54.146534041198,19.5480992488016,27.844467,0,0,0,40,4449,300.5923,-22955.802734375,,,,,,,,,,,,,0,,,,,,,,,,,,,,
,19762656.115,300.5836,-26806.2177734375,4.09120820196997E-5,1.57439470747756E-6,1,0.999253354069792,40.0298881530762,1.98264304109451,14.2400003969669,0.000463695579605282,5.50517457748344E-5,0.25,-2.18605127309437E-6,4.09114597880115E-5,-2.15896386404084E-6,300.5836,300.5836,-26813.744140625,-26798.69140625,54.2364213209096,19.5473935668627,28.224119,0,0,0,40,4449,300.5836,-26806.2177734375,,,,,,,,,,,,,0,,,,,,,,,,,,,,
,19762733.96,300.57625,-30698.7822265625,5.31863403480107E-5,2.06711397512193E-6,1,0.999253354069792,40.0298881530762,1.98249555848225,14.2400003969669,0.000596872605612416,0.00010559468645535,0.25,1.88765675333708E-7,5.31835496829346E-5,2.23798915343367E-7,300.5763,300.5763,-30706.21484375,-30691.349609375,54.0074041647749,19.5460150627278,27.844467,0,0,0,40,4449,300.57625,-30698.7822265625,,,,,,,,,,,,,0,,,,,,,,,,,,,,
,19762811.865,300.568,-34591.783203125,6.70238694630212E-5,1.92595285812065E-6,1,0.999253354069792,40.0298881530762,1.98249343677647,14.2400003969669,0.00075490344139746,0.000117237599317789,0.25,-1.17177411073303E-6,6.70213039715283E-5,-1.12759199409113E-6,300.5683,300.5683,-34594.2734375,-34589.29296875,54.0675895607557,19.5485813813881,28.224119,0,0,0,40,4449,300.568,-34591.783203125,,,,,,,,,,,,,0,,,,,,,,,,,,,,
,19762889.78,300.55855,-38483.888671875,8.03503895349098E-5,2.43738948535028E-6,1,0.999253354069792,40.0298881530762,1.98247961922804,14.2400003969669,0.00090621736875933,0.000133503883186193,0.25,-2.03196752137003E-6,8.0347756930923E-5,-1.97901399058599E-6,300.5586,300.5586,-38491.1484375,-38476.62890625,54.0558651329673,19.548723177019,27.844467,0,0,0,40,4449,300.55855,-38483.888671875,,,,,,,,,,,,,0,,,,,,,,,,,,,,
,19762966.545,300.54835,-42322.017578125,9.29398669864637E-5,2.19117452042146E-6,1,0.999253354069792,40.0298881530762,1.98253634029948,14.2400003969669,0.00104585480538505,0.000168161689812196,0.25,-1.12709015427868E-6,9.29360552338523E-5,-1.06595143917297E-6,300.5471,300.5471,-42329.35546875,-42314.6796875,54.1097975007942,19.5463588771355,28.224119,0,0,0,40,4449,300.54835,-42322.017578125,,,,,,,,,,,,,0,,,,,,,,,,,,,,
,19763045.735,300.53865,-46279.951171875,0.000104112579888123,2.07807586987977E-6,1,0.999253354069792,40.0298881530762,1.98253507758599,14.2400003969669,0.00116675028028925,0.000216261802046298,0.25,1.22065656300877E-6,0.000104106720153867,1.28896393975916E-6,300.5393,300.5393,-46292.66015625,-46267.2421875,54.085567016698,19.5491082699036,27.844467,0,0,0,40,4449,300.53865,-46279.951171875,,,,,,,,,,,,,0,,,,,,,,,,,,,,
,19763123,300.5294,-50142.849609375,0.000115470992799354,2.06590851036899E-6,1,0.999253354069792,40.0298881530762,1.98264676865566,14.2400003969669,0.00130057387722077,0.000202558635061609,0.25,-1.96842522985533E-6,0.000115466718497376,-1.89257103642454E-6,300.5294,300.5294,-50145.57421875,-50140.125,54.1473156697173,19.5489839338308,27.844467,0,0,0,40,4449,300.5294,-50142.849609375,,,,,,,,,,,,,0,,,,,,,,,,,,,,
,19763201.08,300.5198,-54043.0546875,0.000132849065424208,3.31825040089512E-6,1,0.999253354069792,40.0298881530762,1.98264681995829,14.2400003969669,0.00149516430142577,0.000239640865893035,0.25,-1.6770942203242E-6,0.000132843814094302,-1.58993084410101E-6,300.5198,300.5198,-54048.62109375,-54037.48828125,54.156695211948,19.5480512024409,28.224119,0,0,0,40,4449,300.5198,-54043.0546875,,,,,,,,,,,,,0,,,,,,,,,,,,,,
,19763279.64,300.51315,-57970.322265625,0.00014741480718683,2.84568695677242E-6,1,0.999253354069792,40.0298881530762,1.98265859177058,14.2400003969669,0.00165891796569403,0.000267001814144868,0.25,-1.76428352150419E-6,0.000147408958786688,-1.66765768279671E-6,300.5132,300.5132,-57975.3671875,-57965.27734375,54.0160020784865,19.5473619589009,27.844467,0,0,0,40,4449,300.51315,-57970.322265625,,,,,,,,,,,,,0,,,,,,,,,,,,,,
,19763358.975,300.50265,-61935.263671875,0.000156234659363951,3.81008213798548E-6,1,0.999253354069792,40.0298881530762,1.98277261595083,14.2400003969669,0.00175465231807732,0.000303865612718403,0.25,-1.11531244715116E-8,0.000156227311155225,9.10705523580128E-8,300.501,300.501,-61937.75390625,-61932.7734375,54.1777991819673,19.5489409998971,27.844467,0,0,0,40,4449,300.50265,-61935.263671875,,,,,,,,,,,,,0,,,,,,,,,,,,,,
,19763436.78,300.4933,-65823.13671875,0.000170203561427278,3.39641447266814E-6,1,0.999253354069792,40.0298881530762,1.98249838484356,14.2400003969669,0.00190900664661301,0.000344132663041237,0.25,1.15829810434688E-6,0.000170194857413638,1.26950387368934E-6,300.4933,300.4933,-65825.703125,-65820.5703125,54.0074041647749,19.5508064682794,27.844467,0,0,0,40,4449,300.4933,-65823.13671875,,,,,,,,,,,,,0,,,,,,,,,,,,,,
,19763515.545,300.4848,-69760.83984375,0.000184485499817201,4.71016049968155E-6,1,0.999253354069792,40.0298881530762,1.9823412428648,14.2400003969669,0.0020673892787831,0.000382493026416932,0.25,2.10274181553388E-6,0.000184475579421553,2.22312538591816E-6,300.485,300.485,-69773.4296875,-69748.25,54.1989031519865,19.5517722032211,27.844467,0,0,0,40,4449,300.4848,-69760.83984375,,,,,,,,,,,,,0,,,,,,,,,,,,,,
,19763593.93,300.47425,-73678.34375,0.000199025723723243,3.44821186378461E-6,1,0.999253354069792,40.0298881530762,1.98241639528536,14.2400003969669,0.00222692106449866,0.000432806021407696,0.25,4.06323086849776E-6,0.000199013938223455,4.19289774602078E-6,300.4743,300.4743,-73685.8671875,-73670.8203125,54.3083311446788,19.5521744709948,27.844467,0,0,0,40,4449,300.47425,-73678.34375,,,,,,,,,,,,,0,,,,,,,,,,,,,,
,19763672.615,300.4664,-77608.49609375,0.000209081949165177,3.69549595017706E-6,1,0.999253354069792,40.0298881530762,1.98250396365789,14.2500000074506,0.00234686381863526,0.000412425129923694,0.25,5.04522217601313E-7,0.0002090720950076,6.40781086888817E-7,300.4664,300.4664,-77618.3984375,-77598.59375,54.0589916470442,19.5529282146525,27.844467,0,0,0,40,4449,300.4664,-77608.49609375,,,,,,,,,,,,,0,,,,,,,,,,,,,,
,19763748.025,300.45665,-81376.16015625,0.000228095662910618,3.84404691403068E-6,1,0.999253354069792,40.0298881530762,1.98259658361212,14.2500000074506,0.00255923949665622,0.000456653470884001,0.25,1.1473928651731E-6,0.000228084616339248,1.29587765445186E-6,300.4557,300.4557,-81381.1875,-81371.1328125,54.1621666115827,19.5527032728049,27.085165,0,0,0,40,4449,300.45665,-81376.16015625,,,,,,,,,,,,,0,,,,,,,,,,,,,,
,19763824.635,300.4477,-85204.20703125,0.000240330218707577,3.91976262419356E-6,1,0.999253354069792,40.0298881530762,1.98231960487145,14.2400003969669,0.00269424111170963,0.000492117058536267,0.25,2.19175575485828E-6,0.000240318031504334,2.34801127007424E-6,300.4477,300.4477,-85209.21875,-85199.1953125,54.0019327651403,19.5535939870822,27.844467,0,0,0,40,4449,300.4477,-85204.20703125,,,,,,,,,,,,,0,,,,,,,,,,,,,,
,19763897.805,300.43795,-88861.20703125,0.000253440508251098,5.33545414245363E-6,1,0.999253354069792,40.0298881530762,1.98236667107318,14.2400003969669,0.00283908507868628,0.000531647817845485,0.25,3.4401279857591E-6,0.000253427026040044,3.60470669088721E-6,300.4375,300.4375,-88866.25,-88856.1640625,54.2426743490634,19.5554783220263,27.844467,0,0,0,40,4449,300.43795,-88861.20703125,,,,,,,,,,,,,0,,,,,,,,,,,,,,
,19763987.345,300.4286,-87561.44140625,0.000245520884458076,4.86597562685379E-6,1,0.999253354069792,40.0298881530762,1.98248606039756,14.2400003969669,0.00276644961397987,0.000423158083633961,0.25,-4.851995472273E-6,0.000245513221707786,-4.69213767213948E-6,300.4273,300.4273,-87573.9453125,-87548.9375,54.302078116525,19.5541375225429,27.844467,0,0,0,40,4449,300.4286,-87561.44140625,,,,,,,,,,,,,0,,,,,,,,,,,,,,
,19764061.905,300.42565,-83833.8046875,0.000230224714447042,3.09348878084031E-6,1,0.999253354069792,40.0298881530762,1.98234975702941,14.2400003969669,0.00258815032855149,0.000430113075448901,0.25,-1.58025693691932E-6,0.000230215610642961,-1.43034180753726E-6,300.4256,300.4256,-83841.1953125,-83826.4140625,54.2762843753904,19.5551108229921,28.224119,0,0,0,40,4449,300.42565,-83833.8046875,,,,,,,,,,,,,0,,,,,,,,,,,,,,
,19764141.055,300.43085,-79878.65234375,0.000219275604813303,3.35355249203963E-6,1,0.999253354069792,40.0298881530762,1.98241932798129,14.2500000074506,0.00246070750014343,0.00043528025146516,0.25,7.75395369207237E-7,0.000219265395524966,9.182236215129E-7,300.4325,300.4325,-79883.703125,-79873.6015625,54.0980730730057,19.553195531849,27.844467,0,0,0,40,4449,300.43085,-79878.65234375,,,,,,,,,,,,,0,,,,,,,,,,,,,,
,19764220.545,300.4338,-75906.32421875,0.000206722155175828,4.35086517544212E-6,1,0.999253354069792,40.0298881530762,1.98280913326755,14.2500000074506,0.00231431883982558,0.000444778092704342,0.25,3.78852600468387E-6,0.00020671050190159,3.92317732737639E-6,300.4321,300.4321,-75911.40625,-75901.2421875,54.0714977033519,19.5534152857368,28.224119,0,0,0,40,4449,300.4338,-75906.32421875,,,,,,,,,,,,,0,,,,,,,,,,,,,,
,19764297.685,300.4403,-72050.5703125,0.000192105927722485,4.61202509611312E-6,1,0.999253354069792,40.0298881530762,1.98275102872992,14.2400003969669,0.00215986381066375,0.000359990440255831,0.25,-1.22789888544421E-6,0.00019209814059653,-1.10243701857255E-6,300.44,300.44,-72058.1796875,-72042.9609375,54.0371060485057,19.5544722440822,27.844467,0,0,0,40,4449,300.4403,-72050.5703125,,,,,,,,,,,,,0,,,,,,,,,,,,,,
,19764374.06,300.44715,-68233.5625,0.000183875981502511,4.15902086700765E-6,1,0.999253354069792,40.0298881530762,1.98275143233887,14.2400003969669,0.00206456239161887,0.000360563590576067,0.25,2.48857470413257E-7,0.000183867542944723,3.68992963605645E-7,300.4465,300.4465,-68240.890625,-68226.234375,54.109015872275,19.5528376908503,27.844467,0,0,0,40,4449,300.44715,-68233.5625,,,,,,,,,,,,,0,,,,,,,,,,,,,,
,19764451.485,300.45555,-64365.80859375,0.000166593244099352,2.54325609877177E-6,1,0.999253354069792,40.0298881530762,1.98251577228708,14.2500000074506,0.00186901276086065,0.000334057763866859,0.25,8.86240940778138E-7,0.000166585107127798,9.95156113665474E-7,300.4541,300.4541,-64373.4140625,-64358.203125,54.1074526152365,19.5517376182066,27.844467,0,0,0,40,4449,300.45555,-64365.80859375,,,,,,,,,,,,,0,,,,,,,,,,,,,,
,19764529.785,300.46425,-60452.900390625,0.000150992013128885,3.91422815232141E-6,1,0.999253354069792,40.0298881530762,1.98265891056239,14.2400003969669,0.00170203597730615,0.000256979420312254,0.25,-3.27649881835351E-6,0.000150987253052328,-3.17750519658126E-6,300.4642,300.4642,-60460.171875,-60445.62890625,54.1551319549096,19.550301518832,27.844467,0,0,0,40,4449,300.46425,-60452.900390625,,,,,,,,,,,,,0,,,,,,,,,,,,,,
,19764607.11,300.4695,-56590.255859375,0.000138629440740787,3.51279323108499E-6,1,0.999253354069792,40.0298881530762,1.98238656689063,14.2400003969669,0.00156287681557267,0.000233590007984155,0.25,-3.21475593369359E-6,0.000138625173957603,-3.12377370128622E-6,300.4692,300.4692,-56597.4453125,-56583.06640625,54.1527870693519,19.5509102826136,27.464817,0,0,0,40,4449,300.4695,-56590.255859375,,,,,,,,,,,,,0,,,,,,,,,,,,,,
,19764685.175,300.47575,-52687.423828125,0.00012613262402659,3.3473870218916E-6,1,0.999253354069792,40.0298881530762,1.98237963043702,14.2500000074506,0.00142302477066025,0.000206533070679251,0.25,-3.45930363129731E-6,0.000126129059022075,-3.3764219337252E-6,300.4775,300.4775,-52694.6875,-52680.16015625,53.9745757669673,19.55091200841,27.844467,0,0,0,40,4449,300.47575,-52687.423828125,,,,,,,,,,,,,0,,,,,,,,,,,,,,
,19764763.885,300.48535,-48752.392578125,0.000113287833073972,2.90339874363984E-6,1,0.999253354069792,40.0298881530762,1.98224025544987,14.2400003969669,0.00127672868600163,0.000192963749778625,0.25,-2.44127936825216E-6,0.000113284150939315,-2.3668012423085E-6,300.4853,300.4853,-48757.3203125,-48747.46484375,54.2035929231019,19.5514705540137,27.464817,0,0,0,40,4449,300.48535,-48752.392578125,,,,,,,,,,,,,0,,,,,,,,,,,,,,
,19764841.745,300.49115,-44862.5703125,9.93672416819971E-5,2.90820998229245E-6,1,0.999253354069792,40.0298881530762,1.98237096584517,14.2400003969669,0.0011150360161575,0.000197435788734283,0.25,3.67639994565373E-7,9.93623390164362E-5,4.32907056947116E-7,300.4911,300.4911,-44870.15234375,-44854.98828125,53.9777022810442,19.5498876101653,27.464817,0,0,0,40,4449,300.49115,-44862.5703125,,,,,,,,,,,,,0,,,,,,,,,,,,,,
,19764919.805,300.49915,-40959.650390625,8.50584313782679E-5,2.51891318488801E-6,1,0.999253354069792,40.0298881530762,1.98246811773825,14.2400003969669,0.000955037049561438,0.00016600564439,0.25,4.68301776395676E-8,8.50543818986616E-5,1.02759748083769E-7,300.4996,300.4996,-40967.109375,-40952.19140625,53.8995394291211,19.5461394140213,27.464817,0,0,0,40,4449,300.49915,-40959.650390625,,,,,,,,,,,,,0,,,,,,,,,,,,,,
,19764998.075,300.50375,-37049.099609375,7.74320880180927E-5,2.17866503307526E-6,1,0.999253354069792,40.0298881530762,1.98220473057882,14.2400003969669,0.000872071113103244,0.000135095424229948,0.25,-1.38308283159618E-6,7.74293231801905E-5,-1.33205623813706E-6,300.5039,300.5039,-37054.16796875,-37044.03125,54.1340279848903,19.5480433734941,27.844467,0,0,0,40,4449,300.50375,-37049.099609375,,,,,,,,,,,,,0,,,,,,,,,,,,,,
,19765074.875,300.5101,-33211.94921875,6.29461278114086E-5,2.03900924328638E-6,1,0.999253354069792,40.0298881530762,1.98242925590055,14.2500000074506,0.000705359627102448,0.000130850902260557,0.25,7.47342739964404E-7,6.29426305832847E-5,7.88768382537526E-7,300.5103,300.5103,-33216.72265625,-33207.17578125,54.291916945775,19.5494941238544,28.224119,0,0,0,40,4449,300.5101,-33211.94921875,,,,,,,,,,,,,0,,,,,,,,,,,,,,
,19765154.035,300.5172,-29254.1708984375,4.98577256706382E-5,1.88281808030798E-6,1,0.999253354069792,40.0298881530762,1.98243739321,14.2400003969669,0.000561984149076772,8.46651948437358E-5,0.25,-1.09820220653842E-6,4.98560543406034E-5,-1.06528200642917E-6,300.5175,300.5175,-29258.865234375,-29249.4765625,54.1473156697173,19.5484472302026,27.844467,0,0,0,40,4449,300.5172,-29254.1708984375,,,,,,,,,,,,,0,,,,,,,,,,,,,,
,19765230.645,300.5202,-25426.384765625,3.72755497754383E-5,1.70671561816909E-6,1,0.999253354069792,40.0298881530762,1.98223724906533,14.2400003969669,0.000420838667898772,5.91467892882017E-5,0.25,-1.19034320559989E-6,3.72745385243702E-5,-1.16569334779937E-6,300.5202,300.5202,-25431.54296875,-25421.2265625,54.0808772455826,19.5497225228223,27.464817,0,0,0,40,4449,300.5202,-25426.384765625,,,,,,,,,,,,,0,,,,,,,,,,,,,,
,19765307.57,300.5294,-21581.2568359375,2.49862919190458E-5,9.1950858706049E-7,1,0.999253354069792,40.0298881530762,1.98223320617122,14.2400003969669,0.000280839791162794,4.68803180952601E-5,0.25,-1.53662159089875E-7,2.49851797388343E-5,-1.37157662016044E-7,300.53,300.53,-21588.59375,-21573.919921875,54.2356396923903,19.5489815303428,27.844467,0,0,0,40,4449,300.5294,-21581.2568359375,,,,,,,,,,,,,0,,,,,,,,,,,,,,
,19765385.19,300.5357,-17703.3564453125,1.14691076205685E-5,1.06094808134532E-6,1,0.999253354069792,40.0298881530762,1.98224737778683,14.2500000074506,0.000129921421345153,1.56859009623026E-5,0.25,-5.90055092973683E-7,1.1468937313E-5,-5.82448261298043E-7,300.5343,300.5343,-17710.6484375,-17696.064453125,54.075405845948,19.5486934796742,28.224119,0,0,0,40,4449,300.5357,-17703.3564453125,,,,,,,,,,,,,0,,,,,,,,,,,,,,
,19765461.43,300.5397,-13893.4018554687,7.29288061904572E-7,9.56946209058579E-7,1,0.999253354069792,40.0298881530762,1.98220165960025,14.2400003969669,9.68753671896944E-6,-7.23533406761564E-6,0.25,-7.70777947299501E-7,7.29761943631557E-7,-7.70257953890344E-7,300.5408,300.5408,-13903.52734375,-13883.2763671875,54.0597732755634,19.5498117461032,28.224119,0,0,0,40,4449,300.5397,-13893.4018554687,,,,,,,,,,,,,0,,,,,,,,,,,,,,
,19765537.875,300.54395,-10072.6748046875,-1.13041683650746E-5,8.35352375599921E-7,1,0.999253354069792,40.0298881530762,1.98208413434985,14.2400003969669,-0.000124874377949282,-3.37468513872774E-5,0.25,-1.04733228857458E-6,-1.13029190182232E-5,-1.05476002246079E-6,300.5439,300.5439,-10075.052734375,-10070.296875,54.0488304762942,19.5493067431491,27.464817,0,0,0,40,4449,300.54395,-10072.6748046875,,,,,,,,,,,,,0,,,,,,,,,,,,,,
,19765613.5,300.5497,-6291.49951171875,-2.20966365503728E-5,4.62117841069059E-7,1,0.999253354069792,40.0298881530762,1.9820774667868,14.2400003969669,-0.000248231594292583,-4.20922091541508E-5,0.25,7.92163221898513E-8,-2.20955960418732E-5,6.45835619720208E-8,300.5505,300.5505,-6301.48486328125,-6281.51416015625,53.9589431965826,19.5473529982272,27.464817,0,0,0,40,4449,300.5497,-6291.49951171875,,,,,,,,,,,,,0,,,,,,,,,,,,,,
,19765687.805,300.55255,-2577.83959960938,-2.74431708774851E-5,4.0995444052398E-7,1,0.999253354069792,40.0298881530762,1.98202596009723,14.2400003969669,-0.000306873907909351,-6.04279549587234E-5,0.25,-6.27767707858121E-7,-2.74413939654202E-5,-6.45914697600199E-7,300.5516,300.5516,-2577.83959960938,-2577.83959960938,54.109015872275,19.549452264245,27.844467,0,0,0,40,4449,300.55255,-2577.83959960938,,,,,,,,,,,,,0,,,,,,,,,,,,,,
,19765760.885,300.5548,1072.38159179688,2.2854611732505E-5,3.97242279408507E-7,1,0.999253354069792,40.0298881530762,1.98203805331087,14.2400003969669,0.000257888703917447,3.69149883677344E-5,0.25,-6.7163245691603E-7,2.2853921100517E-5,-6.56457725365957E-7,300.5553,300.5553,1069.89685058594,1074.86633300781,54.0457039622173,19.5489331912204,27.464817,0,0,0,40,4449,300.5548,1072.38159179688,,,,,,,,,,,,,0,,,,,,,,,,,,,,
,19765835.43,300.5569,4798.50830078125,2.52158871927756E-5,4.30460079308415E-7,1,0.999253354069792,40.0298881530762,1.98181976863962,14.2400003969669,0.000283687680431037,4.5431023530417E-5,0.25,-3.21759720180165E-7,2.52148461929136E-5,-3.05046458182602E-7,300.5569,300.5569,4791.19775390625,4805.81884765625,54.0675895607557,19.5489687000274,27.464817,0,0,0,40,4449,300.5569,4798.50830078125,,,,,,,,,,,,,0,,,,,,,,,,,,,,
,19765910.745,300.55435,8564.32421875,1.6699815368894E-5,5.60598569701918E-7,1,0.999253354069792,40.0298881530762,1.98177859363927,14.2400003969669,0.000188014912303106,2.92804641974643E-5,0.25,-2.84951483981653E-7,1.6699175529079E-5,-2.73885708892331E-7,300.5544,300.5544,8559.3974609375,8569.2509765625,54.0019327651403,19.5498906225465,28.224119,0,0,0,40,4449,300.55435,8564.32421875,,,,,,,,,,,,,0,,,,,,,,,,,,,,
,19765986.14,300.5522,12332.5053710938,5.45127638560902E-6,7.3744638422355E-7,1,0.999253354069792,40.0298881530762,1.98205019577275,14.2400003969669,6.00535253486336E-5,1.72224873930418E-5,0.25,5.89576122169167E-7,5.4506166807195E-6,5.93152165032943E-7,300.5519,300.5519,12323.0322265625,12341.978515625,54.0363244199865,19.5507558205268,27.464817,0,0,0,40,4449,300.5522,12332.5053710938,,,,,,,,,,,,,0,,,,,,,,,,,,,,
,19766064.08,300.5466,16227.9428710938,-6.38332624445529E-6,9.28703100635296E-7,1,0.999253354069792,40.0298881530762,1.98189908335386,14.2400003969669,-7.32666926504242E-5,-3.13658273217305E-6,0.25,8.26554678678677E-7,-6.38355814181373E-6,8.2229528998011E-7,300.5466,300.5466,16220.595703125,16235.2900390625,53.9917715943903,19.5499263826652,27.464817,0,0,0,40,4449,300.5466,16227.9428710938,,,,,,,,,,,,,0,,,,,,,,,,,,,,
,19766140.615,300.54175,20053.4365234375,-1.77539333819372E-5,1.5710735745987E-6,1,0.999253354069792,40.0298881530762,1.98189721347746,14.2400003969669,-0.000200353090225263,-2.84821268500093E-5,0.25,5.38827689332777E-7,-1.77534187421638E-5,5.27076350215962E-7,300.5409,300.5409,20018.59765625,20088.275390625,53.872182430948,19.5512365471849,27.844467,0,0,0,40,4449,300.54175,20053.4365234375,,,,,,,,,,,,,0,,,,,,,,,,,,,,
,19766216.92,300.53505,23863.876953125,-3.17530192749156E-5,1.58326019451251E-6,1,0.999253354069792,40.0298881530762,1.98179606561661,14.2500000074506,-0.000358947446403679,-4.72897253994852E-5,0.25,1.28868114749274E-6,-3.17523218671089E-5,1.26766379800173E-6,300.5345,300.5345,23861.4765625,23866.27734375,53.9948981084673,19.5508084448802,27.844467,0,0,0,40,4449,300.53505,23863.876953125,,,,,,,,,,,,,0,,,,,,,,,,,,,,
,19766292.655,300.5288,27652.53515625,-4.34829541548415E-5,1.45973358623258E-6,1,0.999253354069792,40.0298881530762,1.98187016066797,14.2400003969669,-0.000488197771882305,-8.41934886727814E-5,0.25,3.36997991579635E-8,-4.34808684749569E-5,5.02470046842124E-9,300.5303,300.5303,27620.173828125,27684.896484375,53.8768722020634,19.5486324365359,27.464817,0,0,0,40,4449,300.5288,27652.53515625,,,,,,,,,,,,,0,,,,,,,,,,,,,,
,19766370.54,300.52165,31545.6298828125,-5.47247883138816E-5,1.49748806087257E-6,1,0.999253354069792,40.0298881530762,1.98174057609095,14.2400003969669,-0.00061409458569476,-0.000107574820388452,0.25,-1.02026187810885E-7,-5.47220848741779E-5,-1.38078795487708E-7,300.5228,300.5228,31538.427734375,31552.83203125,54.0871302737365,19.5485564694611,27.464817,0,0,0,40,4449,300.52165,31545.6298828125,,,,,,,,,,,,,0,,,,,,,,,,,,,,
,19766447.05,300.51555,35365.806640625,-6.97708961193351E-5,2.00387194352027E-6,1,0.999253354069792,40.0298881530762,1.98170178531839,14.2400003969669,-0.000788213001417257,-0.000106599569510452,0.25,2.59146115134853E-6,-6.9769259821974E-5,2.54540312042999E-6,300.5157,300.5157,35360.57421875,35371.0390625,54.0222551066403,19.547416742077,27.464817,0,0,0,40,4449,300.51555,35365.806640625,,,,,,,,,,,,,0,,,,,,,,,,,,,,
,19766524.36,300.5044,39231.125,-8.30444596996593E-5,2.48974960409467E-6,1,0.999253354069792,40.0298881530762,1.9817416383318,14.2400003969669,-0.00093270000677595,-0.000158540758110611,0.25,2.64095246142897E-7,-8.30406924215233E-5,2.09454975111186E-7,300.5032,300.5032,39218.796875,39243.453125,54.075405845948,19.546994844682,28.224119,0,0,0,40,4449,300.5044,39231.125,,,,,,,,,,,,,0,,,,,,,,,,,,,,
,19766602.535,300.4986,43138.76953125,-9.58311306902644E-5,2.08860431996188E-6,1,0.999253354069792,40.0298881530762,1.98204538389814,14.2500000074506,-0.00107649447352883,-0.00018283316280792,0.25,3.17669301363218E-7,-9.5826816508934E-5,2.54670015531747E-7,300.4986,300.4986,43136.25390625,43141.28515625,53.9480003973134,19.5477791877682,28.224119,0,0,0,40,4449,300.4986,43138.76953125,,,,,,,,,,,,,0,,,,,,,,,,,,,,
,19766680.33,300.49,47027.677734375,-0.00010563577546217,2.05491322868159E-6,1,0.999253354069792,40.0298881530762,1.98188790092288,14.2500000074506,-0.00119025597189802,-0.000180091767205317,0.25,2.25927078733009E-6,-0.000105632311347347,2.18979688458123E-6,300.4891,300.4891,47020.00390625,47035.3515625,53.9167352565442,19.5470898944449,27.844467,0,0,0,40,4449,300.49,47027.677734375,,,,,,,,,,,,,0,,,,,,,,,,,,,,
,19766757.665,300.48305,50893.046875,-0.00012005847791265,2.20406898620668E-6,1,0.999253354069792,40.0298881530762,1.98176278633784,14.2400003969669,-0.0013533709202093,-0.000200698588085933,0.25,2.92126389038681E-6,-0.000120054807468242,2.84235847331531E-6,300.4831,300.4831,50888.3671875,50897.7265625,53.9620697106595,19.547522026392,28.224119,0,0,0,40,4449,300.48305,50893.046875,,,,,,,,,,,,,0,,,,,,,,,,,,,,
,19766835.76,300.4756,54795.853515625,-0.000135784909085096,2.59161222710856E-6,1,0.999253354069792,40.0298881530762,1.98166589000879,14.2500000074506,-0.00152711290208758,-0.000246975656550121,0.25,1.52222872269477E-6,-0.000135779631493581,1.43315135109934E-6,300.4753,300.4753,54785.8828125,54805.82421875,53.9214250276596,19.5475840650696,27.464817,0,0,0,40,4449,300.4756,54795.853515625,,,,,,,,,,,,,0,,,,,,,,,,,,,,
,19766914.085,300.4647,58711.95703125,-0.000145839761976737,3.43346588272067E-6,1,0.999253354069792,40.0298881530762,1.98164373238342,14.2500000074506,-0.00164276414655186,-0.000250337697012155,0.25,2.96441553032557E-6,-0.000145835028082968,2.86876840946648E-6,300.4658,300.4658,58704.4453125,58719.46875,53.8635845172365,19.5498177032207,27.844467,0,0,0,40,4449,300.4647,58711.95703125,,,,,,,,,,,,,0,,,,,,,,,,,,,,
,19766992.46,300.45545,62627.701171875,-0.000156073179195458,2.74921369431323E-6,1,0.999253354069792,40.0298881530762,1.98138556066007,14.2500000074506,-0.00175722782003586,-0.000271270798052905,0.25,2.86935054170317E-6,-0.000156067973154314,2.7671013472303E-6,300.4555,300.4555,62622.87109375,62632.53125,54.0058409077365,19.5495513991997,27.844467,0,0,0,40,4449,300.45545,62627.701171875,,,,,,,,,,,,,0,,,,,,,,,,,,,,
,19767071.755,300.44825,66592.890625,-0.000169546538475369,3.70118147319229E-6,1,0.999253354069792,40.0298881530762,1.98149993788302,14.2400003969669,-0.00190880408750476,-0.000296010431950864,0.25,3.0006555735109E-6,-0.000169540858234866,2.88969167640219E-6,300.4488,300.4488,66590.6640625,66595.1171875,53.8862517442942,19.5480386741364,27.464817,0,0,0,40,4449,300.44825,66592.890625,,,,,,,,,,,,,0,,,,,,,,,,,,,,
,19767149.215,300.4393,70465.8515625,-0.000181544720807191,3.60759208292705E-6,1,0.999253354069792,40.0298881530762,1.98134888743688,14.2500000074506,-0.00204173773617827,-0.000328463219138619,0.25,2.18570214066958E-6,-0.000181538033954628,2.0670439303356E-6,300.4384,300.4384,70458.453125,70473.25,53.9542534254672,19.5509431098938,27.464817,0,0,0,40,4449,300.4393,70465.8515625,,,,,,,,,,,,,0,,,,,,,,,,,,,,
,19767227.815,300.42905,74392.015625,-0.000196657975719368,3.74574443014857E-6,1,0.999253354069792,40.0298881530762,1.98166368088366,14.2500000074506,-0.00220314637455971,-0.000407225689772502,0.25,-2.20844808052252E-6,-0.000196647828346265,-2.33665821074573E-6,300.4291,300.4291,74386.921875,74397.109375,53.8526417179672,19.5497939422412,28.224119,0,0,0,40,4449,300.42905,74392.015625,,,,,,,,,,,,,0,,,,,,,,,,,,,,
,19767308.705,300.42395,78432.58984375,-0.000211829369152846,2.8874395612369E-6,1,0.999253354069792,40.0298881530762,1.98155909301364,14.2400003969669,-0.00237669680942024,-0.00041723181347949,0.25,-4.73461108233985E-7,-0.000211819733608847,-6.11506565996076E-7,300.424,300.424,78430.0390625,78435.140625,54.1777991819673,19.5518151604328,27.844467,0,0,0,40,4449,300.42395,78432.58984375,,,,,,,,,,,,,0,,,,,,,,,,,,,,
,19767387.035,300.41495,82351.66796875,-0.000224877412043136,3.08135693713696E-6,1,0.999253354069792,40.0298881530762,1.98166026059563,14.2400003969669,-0.00252264162010564,-0.000446281364953357,0.25,-7.99217113583745E-7,-0.00022486707553108,-9.45609889555219E-7,300.4132,300.4132,82344.2109375,82359.125,53.8268479768326,19.5496699544997,27.844467,0,0,0,40,4449,300.41495,82351.66796875,,,,,,,,,,,,,0,,,,,,,,,,,,,,
,19767461.62,300.4064,86079.97265625,-0.000240290169467827,3.23441492352101E-6,1,0.999253354069792,40.0298881530762,1.98162446293503,14.2500000074506,-0.00270058955453205,-0.000447449296763992,0.25,1.76613285808236E-6,-0.000240280916263113,1.60973941560331E-6,300.4068,300.4068,86072.578125,86087.3671875,53.9511269113903,19.5500100586971,27.844467,0,0,0,40,4449,300.4064,86079.97265625,,,,,,,,,,,,,0,,,,,,,,,,,,,,
,19767536.83,300.39865,89835.75,-0.000251928688457125,3.73505683942307E-6,1,0.999253354069792,40.0298881530762,1.98156003092648,14.2400003969669,-0.00282799302509683,-0.000488231925106531,0.25,1.47641472914662E-7,-0.000251917962396258,-1.60966141364915E-8,300.3985,300.3985,89830.6953125,89840.8046875,53.6767753011403,19.5491207373703,27.844467,0,0,0,40,4449,300.39865,89835.75,,,,,,,,,,,,,0,,,,,,,,,,,,,,
,19767540.595,300.3978,89999.4609375,-0.000251688354571698,5.23322953671145E-6,1,0.999253354069792,40.0298881530762,1.98169908632577,14.2400003969669,-0.00282762571960317,-0.000475440641772561,0.25,1.24845243758258E-6,-0.0002516783624928,1.08482981413174E-6,300.3978,300.3978,89999.4609375,89999.4609375,53.8854701157749,19.5511110631807,28.224119,0,0,0,40,4417,300.3978,89999.4609375,,,,,,,,,,,,,0,,,,,,,,,,,,,,