File: data/monolayers/magneticStructure/ML_Ac_CoFe_C_AH/PPMS/DD205_4_KOELNPPMS_HYST_100OE_250K.DAT
[Header]
; VSM Data File (default extension .dat)
; Copyright (c) 2003-2013, Quantum Design, Inc. All rights reserved.
TITLE,
FILEOPENTIME,19747967.58,08/17/2018,1:31 pm
BYAPP,VSM,2.0,2.0
INFO,PPMS VSM Option Release 1.4.10 Build 1,APPNAME
INFO,Quantum Design Linear Motor Servo Controller,MOTOR_MODULE_NAME
INFO,3101-100 M1,MOTOR_HW_VERSION
INFO,MMC1014,MOTOR_SERIAL_NUMBER
INFO,SRV No X-over 01.03.11,MOTOR_SOFTWARE_VERSION
INFO,Quantum Design VSM Detection Module,VSM_MODULE_NAME
INFO,3101-150 F0,VSM_HW_VERSION
INFO,VSM707,VSM_SERIAL_NUMBER
INFO,VSM No X-over 01.02.05 May 20 2008 13:51:47,VSM_SOFTWARE_VERSION
INFO,704,PREAMP_SERIAL_NUMBER
INFO,822,COIL_SERIAL_NUMBER
INFO,0,MOMENT_UNITS
INFO,,SAMPLE_MATERIAL
INFO,,SAMPLE_COMMENT
INFO,,SAMPLE_MASS
INFO,,SAMPLE_VOLUME
INFO,,SAMPLE_MOLECULAR_WEIGHT
INFO,,SAMPLE_SIZE
INFO,,SAMPLE_SHAPE
DATATYPE,COMMENT,1
DATATYPE,TIME,2
STARTUPAXIS,X,2
STARTUPAXIS,Y1,5
[Data]
Comment,Time Stamp (sec),Temperature (K),Magnetic Field (Oe),Moment (emu),M. Std. Err. (emu),Transport Action,Averaging Time (sec),Frequency (Hz),Peak Amplitude (mm),Center Position (mm),Coil Signal' (mV),Coil Signal" (mV),Range (mV),M. Quad. Signal (emu),M. Raw' (emu),M. Raw" (emu),Min. Temperature (K),Max. Temperature (K),Min. Field (Oe),Max. Field (Oe),Mass (grams),Motor Lag (deg),Pressure (Torr),VSM Status (code),Motor Status (code),Measure Status (code),Measure Count,PPMS Status (code),System Temp. (K),System Field (Oe),Sample Position (deg),Bridge 1 Resistance (ohms),Bridge 1 Excitation (에),Bridge 2 Resistance (ohms),Bridge 2 Excitation (에),Bridge 3 Resistance (ohms),Bridge 3 Excitation (에),Bridge 4 Resistance (ohms),Bridge 4 Excitation (에),Signal 1 Vin (V),Signal 2 Vin (V),Digital Inputs (code),Drive 1 Iout (mA),Drive 1 Ipower (W),Drive 2 Iout (mA),Drive 2 Ipower (W),Pressure (),Map 20 (),Map 21 (),Map 22 (),Map 23 (),Map 24 (),Map 25 (),Map 26 (),Map 27 (),Map 28 (),Map 29 ()
,19748298.4,250.17005,0.0380594320595264,-1.47318073438993E-5,2.91925447148657E-7,1,0.999253354069792,40.0298881530762,1.99435658671892,14.2400003969669,-0.000167427724276704,-2.45112133197887E-5,0.25,3.88304986356518E-7,-1.47578861677506E-5,3.76811450444695E-7,250.1697,250.1697,0.0304475463926792,0.0456713177263737,53.7948012075442,19.5481419210308,26.705515,0,0,0,40,4417,250.17005,0.0380594320595264,,,,,,,,,,,,,0,,,,,,,,,,,,,,
,19748390.54,250.1813,3679.66479492188,2.47957704265056E-5,5.58825270180586E-7,1,0.999253354069792,40.0298881530762,1.99432785993971,14.2400003969669,0.000280488833209045,4.88226057967771E-5,0.25,1.53278660520753E-8,2.48391036452733E-5,3.5830030442018E-8,250.1832,250.1832,3666.9462890625,3692.38330078125,53.7416504682365,19.5483150251908,26.705515,0,0,0,40,4449,250.1813,3679.66479492188,,,,,,,,,,,,,0,,,,,,,,,,,,,,
,19748467,250.19265,7501.36279296875,1.91446224401817E-5,9.87307814218203E-7,1,0.999253354069792,40.0298881530762,1.99419028457257,14.2400003969669,0.000216999060951205,3.50974971839549E-5,0.25,-2.17596195112565E-7,1.91782626772891E-5,-2.02180531908679E-7,250.1927,250.1927,7496.619140625,7506.1064453125,53.9487820258326,19.5494968085528,27.085165,0,0,0,40,4449,250.19265,7501.36279296875,,,,,,,,,,,,,0,,,,,,,,,,,,,,
,19748543.145,250.2009,11310.3725585938,8.56106460024764E-6,1.30651881590161E-6,1,0.999253354069792,40.0298881530762,1.99439971411541,14.2400003969669,9.67843003969925E-5,1.72113882168599E-5,0.25,3.66093266330668E-8,8.5759955054147E-6,4.37306896864953E-8,250.2009,250.2009,11305.560546875,11315.1845703125,53.7174199841403,19.5463192184625,26.705515,0,0,0,40,4449,250.2009,11310.3725585938,,,,,,,,,,,,,0,,,,,,,,,,,,,,
,19748618.915,250.2081,15093.2919921875,-3.38918641670271E-6,1.56616573770684E-6,1,0.999253354069792,40.0298881530762,1.99435953069263,14.2400003969669,-3.88130052271698E-5,-3.93959424151596E-6,0.25,2.3953914001043E-7,-3.39530596889855E-6,2.37166406045364E-7,250.2074,250.2074,15083.3759765625,15103.2080078125,53.8456070612942,19.5497618381449,26.705515,0,0,0,40,4449,250.2081,15093.2919921875,,,,,,,,,,,,,0,,,,,,,,,,,,,,
,19748694.155,250.2138,18856.3818359375,-1.32375363556527E-5,1.82955745060191E-6,1,0.999253354069792,40.0298881530762,1.9943194407489,14.2400003969669,-0.000153549788140515,-4.10655026400376E-6,0.25,1.93269935405204E-6,-1.32622563492632E-5,1.92518451837691E-6,250.2136,250.2136,18851.408203125,18861.35546875,53.7385239541595,19.5489951188948,26.705515,0,0,0,40,4449,250.2138,18856.3818359375,,,,,,,,,,,,,0,,,,,,,,,,,,,,
,19748769.975,250.2161,22647.0185546875,-2.67124546366186E-5,2.59496530553102E-6,1,0.999253354069792,40.0298881530762,1.99438544003578,14.2400003969669,-0.000301782698686202,-5.48795211167419E-5,0.25,-2.1828234426215E-7,-2.67589497754672E-5,-2.4062089277693E-7,250.2161,250.2161,22644.552734375,22649.484375,53.8737456879865,19.5511620040323,27.085165,0,0,0,40,4449,250.2161,22647.0185546875,,,,,,,,,,,,,0,,,,,,,,,,,,,,
,19748843.485,250.22035,26317.029296875,-4.03452490272663E-5,2.6859585606488E-6,1,0.999253354069792,40.0298881530762,1.99428699931301,14.2400003969669,-0.000454310950994668,-9.1337559497844E-5,0.25,-1.07700101173907E-6,-4.04148573105377E-5,-1.1120126355606E-6,250.2189,250.2189,26307.169921875,26326.888671875,53.8667110313134,19.5519483006349,26.705515,0,0,0,40,4449,250.22035,26317.029296875,,,,,,,,,,,,,0,,,,,,,,,,,,,,
,19748921.015,250.21945,30193.0341796875,-5.33443741182602E-5,2.69684226470659E-6,1,0.999253354069792,40.0298881530762,1.99422049363885,14.2400003969669,-0.000603335767347483,-0.000105388531328085,0.25,-6.50464441938398E-8,-5.34375328709277E-5,-1.08917835748857E-7,250.2191,250.2191,30190.529296875,30195.5390625,53.9980246225442,19.5515110783009,27.085165,0,0,0,40,4449,250.21945,30193.0341796875,,,,,,,,,,,,,0,,,,,,,,,,,,,,
,19748996.83,250.22085,33981.44140625,-6.48999149836171E-5,3.1345080409463E-6,1,0.999253354069792,40.0298881530762,1.99411450256302,14.2400003969669,-0.000732452256079751,-0.000137102242025231,0.25,-8.65152533558052E-7,-6.50126130539415E-5,-9.19843775681351E-7,250.2199,250.2199,33974.0859375,33988.796875,53.8815619731788,19.5513385983444,26.325863,0,0,0,40,4449,250.22085,33981.44140625,,,,,,,,,,,,,0,,,,,,,,,,,,,,
,19749074.845,250.2168,37881.486328125,-7.52367945543988E-5,2.87328274750009E-6,1,0.999253354069792,40.0298881530762,1.9945266828517,14.2500000074506,-0.000851923776592094,-0.000143729619084008,0.25,3.44032515205086E-7,-7.53685643823481E-5,2.83052168421973E-7,250.2165,250.2165,37871.46875,37891.50390625,53.8143419205249,19.5496629833933,26.705515,0,0,0,40,4449,250.2168,37881.486328125,,,,,,,,,,,,,0,,,,,,,,,,,,,,
,19749152.735,250.209,41774.55078125,-8.96462754602684E-5,2.39562435359721E-6,1,0.999253354069792,40.0298881530762,1.99438999857797,14.2400003969669,-0.00101856199354023,-0.000150819220903129,0.25,2.21534397471842E-6,-8.98047918058368E-5,2.14592174369217E-6,250.2085,250.2085,41764.6484375,41784.453125,53.8487335753711,19.5511009600844,26.325863,0,0,0,40,4449,250.209,41774.55078125,,,,,,,,,,,,,0,,,,,,,,,,,,,,
,19749228.99,250.19665,45585.587890625,-0.000104019077271812,2.34881408304811E-6,1,0.999253354069792,40.0298881530762,1.99430932853969,14.2500000074506,-0.0011852478715631,-0.000155231606593378,0.25,4.31721268219502E-6,-0.000104204488574948,4.23980749457336E-6,250.196,250.196,45583.07421875,45588.1015625,53.6478550459288,19.5504593434545,26.325863,0,0,0,40,4449,250.19665,45585.587890625,,,,,,,,,,,,,0,,,,,,,,,,,,,,
,19749305.42,250.1844,49406.197265625,-0.000117959230074455,2.67115062891291E-6,1,0.999253354069792,40.0298881530762,1.99431664103815,14.2500000074506,-0.0013414707026611,-0.000191166720301012,0.25,3.55820944024425E-6,-0.000118168457094194,3.46819983941588E-6,250.1849,250.1849,49396.12890625,49416.265625,53.6869364718903,19.5494543477924,26.325863,0,0,0,40,4449,250.1844,49406.197265625,,,,,,,,,,,,,0,,,,,,,,,,,,,,
,19749381.98,250.17275,53231.4140625,-0.000129557732075564,3.21068403162119E-6,1,0.999253354069792,40.0298881530762,1.99424797641645,14.2400003969669,-0.00147083968619643,-0.000224287888552035,0.25,2.64113845009484E-6,-0.000129786562668632,2.54018242297686E-6,250.1731,250.1731,53228.7890625,53234.0390625,54.0136571929288,19.550643698575,26.325863,0,0,0,40,4449,250.17275,53231.4140625,,,,,,,,,,,,,0,,,,,,,,,,,,,,
,19749457.005,250.1625,56984.224609375,-0.000128677928351299,3.10384543579718E-6,1,0.999253354069792,40.0298881530762,1.99419268443888,14.2400003969669,-0.0014966318489758,-1.62101436030953E-5,0.25,2.08815650147763E-5,-0.000128920124844845,2.08133673006062E-5,250.1629,250.1629,56951.6328125,57016.81640625,53.3649055219672,19.5568034019055,27.085165,0,0,0,40,4449,250.1625,56984.224609375,,,,,,,,,,,,,0,,,,,,,,,,,,,,
,19749536.095,250.151,60935.22265625,-0.000143282633289217,3.16323546057375E-6,1,0.999253354069792,40.0298881530762,1.99399859664435,14.2400003969669,-0.00166174333402685,-4.45700452425426E-5,0.25,2.09067584631593E-5,-0.000143550463907668,2.08268666669744E-5,250.151,250.151,60935.22265625,60935.22265625,53.8682742883518,19.5558292070756,26.325863,0,0,0,40,4449,250.151,60935.22265625,,,,,,,,,,,,,0,,,,,,,,,,,,,,
,19749612.145,250.1407,64736.232421875,-0.000155638170287941,3.64466549015616E-6,1,0.999253354069792,40.0298881530762,1.99409018634791,14.2400003969669,-0.00180550742269178,-4.6172221985995E-5,0.25,2.29077525647134E-5,-0.000155929309407765,2.28214766729495E-5,250.1406,250.1406,64728.91015625,64743.5546875,53.8729640594672,19.5591545392314,26.705515,0,0,0,40,4449,250.1407,64736.232421875,,,,,,,,,,,,,0,,,,,,,,,,,,,,
,19749690.425,250.13285,68649.04296875,-0.000167905553464475,3.51094022949756E-6,1,0.999253354069792,40.0298881530762,1.99387967762981,14.2400003969669,-0.0019439266779618,-7.11132689239656E-5,0.25,2.28294170805496E-5,-0.000168218153045361,2.27332180312806E-5,250.1328,250.1328,68641.5,68656.5859375,53.831537747948,19.5585408187335,26.705515,0,0,0,40,4449,250.13285,68649.04296875,,,,,,,,,,,,,0,,,,,,,,,,,,,,
,19749767.51,250.1223,72502.609375,-0.000179594886283376,3.74727284137877E-6,1,0.999253354069792,40.0298881530762,1.99380345356004,14.2400003969669,-0.00208304052419837,-5.38264585664445E-5,0.25,2.63844638344078E-5,-0.000179930904125804,2.62851989586707E-5,250.1227,250.1227,72495.2734375,72509.9453125,53.7869849223518,19.5583410729265,26.705515,0,0,0,40,4449,250.1223,72502.609375,,,,,,,,,,,,,0,,,,,,,,,,,,,,
,19749845.095,250.11075,76381.0859375,-0.000193899764359497,2.99286537251069E-6,1,0.999253354069792,40.0298881530762,1.99397163649388,14.2400003969669,-0.00224172151038841,-0.000100889223763285,0.25,2.47045811679232E-5,-0.000194259559620948,2.4590989671745E-5,250.1106,250.1106,76373.765625,76388.40625,53.6799018152172,19.5593378542787,26.705515,0,0,0,40,4449,250.11075,76381.0859375,,,,,,,,,,,,,0,,,,,,,,,,,,,,
,19749921.36,250.10105,80191.7734375,-0.000204756441449546,4.21476606366799E-6,1,0.999253354069792,40.0298881530762,1.99393795630506,14.2500000074506,-0.00237620811437644,-5.45931644225223E-5,0.25,3.06798330327492E-5,-0.000205140160376744,3.05681448615252E-5,250.1002,250.1002,80186.734375,80196.8125,53.6595794737172,19.5572788125879,26.705515,0,0,0,40,4449,250.10105,80191.7734375,,,,,,,,,,,,,0,,,,,,,,,,,,,,
,19749998.505,250.0901,84050.484375,-0.000222345404535262,3.99945424355369E-6,1,0.999253354069792,40.0298881530762,1.99417000450983,14.2400003969669,-0.00257756393954557,-7.6892426471873E-5,0.25,3.17589830802744E-5,-0.000222760907539646,3.16352113864324E-5,250.0903,250.0903,84040.4921875,84060.4765625,53.4610458298326,19.5556954758109,26.705515,0,0,0,40,4449,250.0901,84050.484375,,,,,,,,,,,,,0,,,,,,,,,,,,,,
,19750072.505,250.08385,87749.1328125,-0.000232405486501578,3.65673993167085E-6,1,0.999253354069792,40.0298881530762,1.99392503934025,14.2400003969669,-0.00269001732607628,-0.000102586330169743,0.25,3.12308723458973E-5,-0.00023283824924427,3.10982938859734E-5,250.0842,250.0842,87739.0078125,87759.2578125,53.8291928623903,19.5567763228981,26.325863,0,0,0,40,4449,250.08385,87749.1328125,,,,,,,,,,,,,0,,,,,,,,,,,,,,
,19750164.69,250.0699,88572.73046875,-0.000242188567078598,4.29440298827421E-6,1,0.999253354069792,40.0298881530762,1.99369740563527,14.2500000074506,-0.00280308175969433,-0.000106128364727307,0.25,3.26131053575434E-5,-0.000242639721005345,3.24751232044312E-5,250.0704,250.0704,88567.7890625,88577.671875,53.6392571322172,19.5585839589388,26.705515,0,0,0,40,4449,250.0699,88572.73046875,,,,,,,,,,,,,0,,,,,,,,,,,,,,
,19750238.64,250.0657,84877.1953125,-0.000222740808291899,4.04414194401161E-6,1,0.999253354069792,40.0298881530762,1.99389032689402,14.2400003969669,-0.00258474718714017,-6.00475065742839E-5,0.25,3.33158768100622E-5,-0.000223158454144744,3.31945749377356E-5,250.0657,250.0657,84869.5859375,84884.8046875,53.6001757062557,19.5581231001603,26.705515,0,0,0,40,4449,250.0657,84877.1953125,,,,,,,,,,,,,0,,,,,,,,,,,,,,
,19750315.945,250.06605,81013.09765625,-0.00020609942619803,4.86177887994391E-6,1,0.999253354069792,40.0298881530762,1.99380905712535,14.2400003969669,-0.00238453990097192,-9.59437674235706E-5,0.25,2.72564478219861E-5,-0.000206482990009192,2.71377260829813E-5,250.0662,250.0662,81005.5390625,81020.65625,53.5353005391595,19.5601143293146,27.085165,0,0,0,40,4449,250.06605,81013.09765625,,,,,,,,,,,,,0,,,,,,,,,,,,,,
,19750391.46,250.0705,77236.8359375,-0.000203610157115048,4.13843724380931E-6,1,0.999253354069792,40.0298881530762,1.99422189192755,14.2400003969669,-0.00235679321245416,-9.14100992054687E-5,0.25,2.72274309472071E-5,-0.000203989303293673,2.71104589024253E-5,250.0712,250.0712,77231.5390625,77242.1328125,53.780731894198,19.5568942142203,26.325863,0,0,0,40,4449,250.0705,77236.8359375,,,,,,,,,,,,,0,,,,,,,,,,,,,,
,19750468.455,250.07405,73390.453125,-0.000184949230999072,4.2446816899186E-6,1,0.999253354069792,40.0298881530762,1.99408110575699,14.2400003969669,-0.00213895948965561,-9.27637768068124E-5,0.25,2.38714439797579E-5,-0.000185292912209509,2.37634898070697E-5,250.0749,250.0749,73382.953125,73397.953125,53.8737456879865,19.5583075953324,27.085165,0,0,0,40,4449,250.07405,73390.453125,,,,,,,,,,,,,0,,,,,,,,,,,,,,
,19750547.97,250.07885,69414.9140625,-0.000171867099411734,4.73349340096669E-6,1,0.999253354069792,40.0298881530762,1.99426819630489,14.2400003969669,-0.00199690998409592,-3.39112377210812E-5,0.25,2.68060222636837E-5,-0.000172190194402992,2.67136260095577E-5,250.0793,250.0793,69404.8125,69425.015625,53.7557197815826,19.5575901531661,26.325863,0,0,0,40,4449,250.07885,69414.9140625,,,,,,,,,,,,,0,,,,,,,,,,,,,,
,19750628.195,250.0855,65406.453125,-0.000155566772618812,4.23699591579423E-6,1,0.999253354069792,40.0298881530762,1.99380984499361,14.2400003969669,-0.00180644781495724,-3.45696120494784E-5,0.25,2.39206677499533E-5,-0.00015585891622819,2.38362649802724E-5,250.0855,250.0855,65401.8046875,65411.1015625,53.5485882239864,19.5615695800825,26.705515,0,0,0,40,4449,250.0855,65406.453125,,,,,,,,,,,,,0,,,,,,,,,,,,,,
,19750706.505,250.09315,61490.044921875,-0.000142835110201532,3.64733939300431E-6,1,0.999253354069792,40.0298881530762,1.99424564104941,14.2400003969669,-0.00166137987769303,-1.77517217401568E-5,0.25,2.32002538529634E-5,-0.000143104317744844,2.31247774642777E-5,250.093,250.093,61482.4375,61497.65234375,53.7799502656788,19.5569425979416,26.705515,0,0,0,40,4449,250.09315,61490.044921875,,,,,,,,,,,,,0,,,,,,,,,,,,,,
,19750779.805,250.0973,57827.052734375,-0.000132511491621509,4.19255169731726E-6,1,0.999253354069792,40.0298881530762,1.99394909766883,14.2400003969669,-0.0015329603122519,-6.33020005923155E-5,0.25,1.73829019506503E-5,-0.000132757858036621,1.7305496509013E-5,250.0975,250.0975,57819.6484375,57834.45703125,53.7666625808518,19.5590190349054,26.705515,0,0,0,40,4449,250.0973,57827.052734375,,,,,,,,,,,,,0,,,,,,,,,,,,,,
,19750856.75,250.1036,53978.828125,-0.000117675196015578,3.58622542080428E-6,1,0.999253354069792,40.0298881530762,1.99398436211533,14.2400003969669,-0.00137127904845492,1.04518991409667E-6,0.25,2.0499004830122E-5,-0.000117898080203276,2.04390179406319E-5,250.1042,250.1042,53971.40625,53986.25,53.7056955563518,19.5586481264897,26.705515,0,0,0,40,4449,250.1036,53978.828125,,,,,,,,,,,,,0,,,,,,,,,,,,,,
,19750933.935,250.1081,50123.57421875,-0.000107192083379288,2.14245744305509E-6,1,0.999253354069792,40.0298881530762,1.99393557039827,14.2400003969669,-0.00124629075925865,-1.5184815107059E-5,0.25,1.72463141978064E-5,-0.000107393937183387,1.71890650672874E-5,250.1082,250.1082,50118.64453125,50128.50390625,53.8190316916403,19.560411299512,27.085165,0,0,0,40,4449,250.1081,50123.57421875,,,,,,,,,,,,,0,,,,,,,,,,,,,,
,19751011.26,250.1138,46258.26171875,-9.11092211024397E-5,3.05083018047043E-6,1,0.999253354069792,40.0298881530762,1.99398599465868,14.2400003969669,-0.00106012578749228,-8.29181445748101E-6,0.25,1.5066800514531E-5,-9.12811082828958E-5,1.50187656863256E-5,250.114,250.114,46250.57421875,46265.94921875,54.0394509340634,19.5629646115037,26.705515,0,0,0,40,4449,250.1138,46258.26171875,,,,,,,,,,,,,0,,,,,,,,,,,,,,
,19751091.72,250.1205,42237.609375,-8.34380475866056E-5,2.40414636055014E-6,1,0.999253354069792,40.0298881530762,1.99434740072381,14.2400003969669,-0.000966724052940757,-3.24455878085366E-5,0.25,1.16017171160759E-5,-8.35936502981211E-5,1.15537955279384E-5,250.1205,250.1205,42232.94921875,42242.26953125,53.8581131176019,19.5585935745695,26.705515,0,0,0,40,4449,250.1205,42237.609375,,,,,,,,,,,,,0,,,,,,,,,,,,,,
,19751168.925,250.1227,38376.685546875,-7.04117894204047E-5,2.04909789649218E-6,1,0.999253354069792,40.0298881530762,1.99396998311831,14.2400003969669,-0.000816820144675195,-2.06434150487914E-5,0.25,1.03856806177863E-5,-7.05435832063962E-5,1.03462160637434E-5,250.1227,250.1227,38374.4609375,38378.91015625,53.8893782583711,19.5610560114887,27.085165,0,0,0,40,4449,250.1227,38376.685546875,,,,,,,,,,,,,0,,,,,,,,,,,,,,
,19751244.995,250.1309,34576.318359375,-5.55774531697709E-5,2.47325700194881E-6,1,0.999253354069792,40.0298881530762,1.99396092377935,14.2400003969669,-0.000649173494176646,9.33012991798642E-6,0.25,1.04630654225968E-5,-5.56833229380366E-5,1.04358297443193E-5,250.1309,250.1309,34571.72265625,34580.9140625,54.0988547015249,19.5612339352301,26.325863,0,0,0,40,4449,250.1309,34576.318359375,,,,,,,,,,,,,0,,,,,,,,,,,,,,
,19751320.905,250.13695,30781.1171875,-4.56111535963425E-5,1.24930953927291E-6,1,0.999253354069792,40.0298881530762,1.99438364986129,14.2400003969669,-0.000535720572272517,2.40977701010933E-5,0.25,1.0039899078616E-5,-4.56992238872702E-5,1.00200489790367E-5,250.1382,250.1382,30778.310546875,30783.923828125,53.8784354591019,19.5618416985259,26.705515,0,0,0,40,4449,250.13695,30781.1171875,,,,,,,,,,,,,0,,,,,,,,,,,,,,
,19751395.945,250.1398,27033.45703125,-3.43504610480829E-5,1.89664418740746E-6,1,0.999253354069792,40.0298881530762,1.99434718919544,14.2400003969669,-0.000402725678885905,1.39578467544876E-5,0.25,7.19085134574733E-6,-3.44164835936997E-5,7.1752234951049E-6,250.1406,250.1406,27020.935546875,27045.978515625,54.0136571929288,19.5616759895088,26.705515,0,0,0,40,4449,250.1398,27033.45703125,,,,,,,,,,,,,0,,,,,,,,,,,,,,
,19751473.115,250.1455,23175.3173828125,-1.93107585785449E-5,1.30673416498455E-6,1,0.999253354069792,40.0298881530762,1.99399495395525,14.2400003969669,-0.00023354793465883,4.92836101342454E-5,0.25,7.70589703464616E-6,-1.93508838926051E-5,7.70350457965398E-6,250.1451,250.1451,23172.65234375,23177.982421875,54.0331979059096,19.5661030583934,26.325863,0,0,0,40,4449,250.1455,23175.3173828125,,,,,,,,,,,,,0,,,,,,,,,,,,,,
,19751552.68,250.1493,19200.0693359375,-9.84030679162289E-6,1.07102235005769E-6,1,0.999253354069792,40.0298881530762,1.99418949880244,14.2400003969669,-0.000122874237195585,4.73313144373897E-5,0.25,5.89053706724647E-6,-9.86237089310922E-6,5.89274460265117E-6,250.1499,250.1499,19189.970703125,19210.16796875,53.9902083373519,19.5605870041319,26.705515,0,0,0,40,4449,250.1493,19200.0693359375,,,,,,,,,,,,,0,,,,,,,,,,,,,,
,19751628.815,250.1535,15392.546875,3.10378675671068E-7,9.83264336186983E-7,1,0.999253354069792,40.0298881530762,1.99411278933827,14.2500000074506,-5.50919196406945E-6,5.26214267214931E-5,0.25,4.59798461838039E-6,3.07134056554323E-7,4.60628370472159E-6,250.1535,250.1535,15387.5107421875,15397.5830078125,53.8409172901788,19.5615246122618,26.705515,0,0,0,40,4449,250.1535,15392.546875,,,,,,,,,,,,,0,,,,,,,,,,,,,,
,19751703,250.1567,11684.4555664062,1.10257892554882E-5,1.15077558340326E-6,1,0.999253354069792,40.0298881530762,1.99410039090875,14.2400003969669,0.000117163366982891,6.52219498632745E-5,0.25,3.85361155254652E-6,1.10418977484985E-5,3.86944240327295E-6,250.1567,250.1567,11679.76171875,11689.1494140625,53.7416504682365,19.564971804673,27.085165,0,0,0,40,4449,250.1567,11684.4555664062,,,,,,,,,,,,,0,,,,,,,,,,,,,,
,19751779.345,250.1607,7868.53442382813,2.01901770442946E-5,7.51610737487141E-7,1,0.999253354069792,40.0298881530762,1.99429229834449,14.2400003969669,0.000224502228184824,6.21528893178461E-5,0.25,1.99245477389029E-6,2.02238439802603E-5,2.01259931853302E-6,250.1607,250.1607,7866.1328125,7870.93603515625,54.187178724198,19.5638047160664,26.705515,0,0,0,40,4449,250.1607,7868.53442382813,,,,,,,,,,,,,0,,,,,,,,,,,,,,
,19751854.78,250.1648,4097.92565917969,2.70896329692682E-5,3.63742072513943E-7,1,0.999253354069792,40.0298881530762,1.9940794465771,14.2400003969669,0.000305552405475032,5.82240806392566E-5,0.25,4.49141996782977E-7,2.71366338596814E-5,4.72296997396986E-7,250.1627,250.1627,4087.79809570313,4108.05322265625,54.0605549040826,19.5640660652359,27.085165,0,0,0,40,4449,250.1648,4097.92565917969,,,,,,,,,,,,,0,,,,,,,,,,,,,,
,19751928.35,250.1656,423.881195068359,2.10812066295699E-5,3.9052519512365E-7,1,0.999253354069792,40.0298881530762,1.99402709801275,14.2400003969669,0.00023871758231493,3.98768546678995E-5,0.25,-1.30713221198667E-7,2.11181776737701E-5,-1.13523352590755E-7,250.1652,250.1652,418.825500488281,428.936889648438,54.105889358198,19.5644570230139,26.325863,0,0,0,40,4449,250.1656,423.881195068359,,,,,,,,,,,,,0,,,,,,,,,,,,,,
,19752003.75,250.1666,-3341.36169433594,-2.49341729886725E-5,4.58636621292901E-7,1,0.999253354069792,40.0298881530762,1.99433785995442,14.2400003969669,-0.000279883261878895,-6.16233291311592E-5,0.25,-1.12278182418668E-6,-2.4976846322738E-5,-1.14533753378857E-6,250.1664,250.1664,-3348.984375,-3333.73901367188,54.1230851856211,19.5626707854848,26.705515,0,0,0,40,4449,250.1666,-3341.36169433594,,,,,,,,,,,,,0,,,,,,,,,,,,,,
,19752078.295,250.1656,-7068.78125,-2.18041836391704E-5,6.11604523226972E-7,1,0.999253354069792,40.0298881530762,1.99450493916174,14.2500000074506,-0.000240013690506124,-8.13125288419129E-5,0.25,-3.40540874783761E-6,-2.18395029259622E-5,-3.42935821473638E-6,250.1663,250.1663,-7073.8037109375,-7063.7587890625,53.9464371402749,19.5629331965811,26.705515,0,0,0,40,4449,250.1656,-7068.78125,,,,,,,,,,,,,0,,,,,,,,,,,,,,
,19752155.485,250.1625,-10927.7587890625,-1.2360444018072E-5,9.20599659473886E-7,1,0.999253354069792,40.0298881530762,1.9940777053459,14.2500000074506,-0.000132687790570659,-6.53696143927745E-5,0.25,-3.63526630582724E-6,-1.2379063860673E-5,-3.65181630005761E-6,250.163,250.163,-10937.3837890625,-10918.1337890625,53.9323678269288,19.5648254072408,26.705515,0,0,0,40,4449,250.1625,-10927.7587890625,,,,,,,,,,,,,0,,,,,,,,,,,,,,
,19752229.175,250.1584,-14610.5327148438,-2.60601613403301E-6,1.0554325276002E-6,1,0.999253354069792,40.0298881530762,1.9944555599758,14.2500000074506,-1.8864490122546E-5,-6.63486188742308E-5,0.25,-5.41240938974155E-6,-2.6061152334804E-6,-5.42402352878354E-6,250.1584,250.1584,-14615.400390625,-14605.6650390625,54.1035444726403,19.5638606914503,27.085165,0,0,0,40,4449,250.1584,-14610.5327148438,,,,,,,,,,,,,0,,,,,,,,,,,,,,
,19752306.955,250.1517,-18496.30859375,6.95603398884712E-6,7.43910931002921E-7,1,0.999253354069792,40.0298881530762,1.99392655018684,14.2400003969669,9.06707438208924E-5,-5.5497500192493E-5,0.25,-6.11283343448533E-6,6.97323493664159E-6,-6.11780201416097E-6,250.1517,250.1517,-18499.072265625,-18493.544921875,53.8471703183326,19.5675178486468,26.325863,0,0,0,40,4449,250.1517,-18496.30859375,,,,,,,,,,,,,0,,,,,,,,,,,,,,
,19752384.075,250.1445,-22353.720703125,1.85760469802544E-5,1.07357696417432E-6,1,0.999253354069792,40.0298881530762,1.99407777010354,14.2400003969669,0.000228299187017967,-6.83308312477219E-5,0.25,-9.2621420868665E-6,1.86161681266525E-5,-9.26307354635611E-6,250.1446,250.1446,-22356.0703125,-22351.37109375,53.9761390240057,19.564370356976,26.705515,0,0,0,40,4449,250.1445,-22353.720703125,,,,,,,,,,,,,0,,,,,,,,,,,,,,
,19752460.85,250.13535,-26188.755859375,3.05921766556496E-5,1.34024276083124E-6,1,0.999253354069792,40.0298881530762,1.99444994459084,14.2500000074506,0.000364668289851196,-4.69549214135886E-5,0.25,-9.45554651543397E-6,3.06534879778151E-5,-9.44696381110858E-6,250.1362,250.1362,-26193.21484375,-26184.296875,54.0175653355249,19.5641942351146,26.705515,0,0,0,40,4449,250.13535,-26188.755859375,,,,,,,,,,,,,0,,,,,,,,,,,,,,
,19752536.545,250.1288,-29971.6923828125,4.28119808710202E-5,1.5428010458127E-6,1,0.999253354069792,40.0298881530762,1.99427896203625,14.2400003969669,0.00050967112116949,-6.2134122068534E-5,0.25,-1.29167776950478E-5,4.28975264342534E-5,-1.29042537743545E-5,250.1292,250.1292,-29981.736328125,-29961.6484375,54.0167837070057,19.5638209320708,26.705515,0,0,0,40,4449,250.1288,-29971.6923828125,,,,,,,,,,,,,0,,,,,,,,,,,,,,
,19752615.99,250.1191,-33941.68359375,5.66758805958325E-5,2.15212247302948E-6,1,0.999253354069792,40.0298881530762,1.99423643541515,14.2400003969669,0.000667452871169586,-4.04325224584824E-5,0.25,-1.34027844424651E-5,5.67861079898881E-5,-1.33797890839294E-5,250.1191,250.1191,-33944.1796875,-33939.1875,53.8080888923711,19.5683807015084,26.705515,0,0,0,40,4449,250.1191,-33941.68359375,,,,,,,,,,,,,0,,,,,,,,,,,,,,
,19752692.24,250.11195,-37754.5078125,6.65030851001266E-5,2.5072786622557E-6,1,0.999253354069792,40.0298881530762,1.99406960451343,14.2400003969669,0.000778030010643096,-1.80762640408558E-5,0.25,-1.31308771676106E-5,6.66303090350359E-5,-1.30994118040482E-5,250.1109,250.1109,-37761.9609375,-37747.0546875,53.902665943198,19.5682615749257,27.085165,0,0,0,40,4449,250.11195,-37754.5078125,,,,,,,,,,,,,0,,,,,,,,,,,,,,
,19752769.525,250.1035,-41615.041015625,7.68533322204458E-5,2.30979731254688E-6,1,0.999253354069792,40.0298881530762,1.99442470231103,14.2400003969669,0.00090007141042239,-2.55016267199645E-5,0.25,-1.5581773415645E-5,7.70007071592405E-5,-1.55461991810365E-5,250.1035,250.1035,-41620.05859375,-41610.0234375,53.9503452828711,19.5676248715618,26.705515,0,0,0,40,4449,250.1035,-41615.041015625,,,,,,,,,,,,,0,,,,,,,,,,,,,,
,19752848.095,250.0927,-45540.708984375,9.30652448143209E-5,2.17194186036856E-6,1,0.999253354069792,40.0298881530762,1.99419412852548,14.2400003969669,0.00109059772099207,-3.53737527308371E-5,0.25,-1.92660402601245E-5,9.32440606957923E-5,-1.92237525566315E-5,250.0927,250.0927,-45543.29296875,-45538.125,54.0074041647749,19.5655540377705,26.705515,0,0,0,40,4449,250.0927,-45540.708984375,,,,,,,,,,,,,0,,,,,,,,,,,,,,
,19752924.86,250.0836,-49380.947265625,0.000104333668985639,2.81107700812448E-6,1,0.999253354069792,40.0298881530762,1.99413865918418,14.2400003969669,0.00121453490130522,6.94433197254689E-6,0.25,-1.74792404866043E-5,0.000104530798348013,-1.74247171895275E-5,250.0836,250.0836,-49385.63671875,-49376.2578125,53.9136087424672,19.5662040741499,27.085165,0,0,0,40,4449,250.0836,-49380.947265625,,,,,,,,,,,,,0,,,,,,,,,,,,,,
,19753002.835,250.0775,-53275.708984375,0.000119125533355449,2.19300342863908E-6,1,0.999253354069792,40.0298881530762,1.99444127155183,14.2400003969669,0.00138921803619366,-5.28585095805382E-6,0.25,-2.11253481496399E-5,0.000119351582382785,-2.10652625295846E-5,250.0781,250.0781,-53283.2578125,-53268.16015625,54.1410626415634,19.5681971223698,26.705515,0,0,0,40,4449,250.0775,-53275.708984375,,,,,,,,,,,,,0,,,,,,,,,,,,,,
,19753080.22,250.0696,-57143.08203125,0.000133972876648247,2.8279116612638E-6,1,0.999253354069792,40.0298881530762,1.99418653354786,14.2400003969669,0.00155319893595396,4.58147884906812E-5,0.25,-1.91828379177917E-5,0.000134223402992454,-1.91073777711704E-5,250.0696,250.0696,-57145.44921875,-57140.71484375,53.9276780558134,19.5660241663142,26.325863,0,0,0,40,4449,250.0696,-57143.08203125,,,,,,,,,,,,,0,,,,,,,,,,,,,,
,19753157.385,250.05785,-60998.572265625,0.000142914604400734,2.52061838791983E-6,1,0.999253354069792,40.0298881530762,1.99402239555267,14.2400003969669,0.00166696134567912,-1.01064583948585E-5,0.25,-2.56767068301634E-5,0.000143186147644784,-2.56055003236251E-5,250.0574,250.0574,-61008.609375,-60988.53515625,53.8792170876211,19.5689146134698,26.705515,0,0,0,40,4449,250.05785,-60998.572265625,,,,,,,,,,,,,0,,,,,,,,,,,,,,
,19753233.705,250.04825,-64813.998046875,0.000155467782453561,2.96107968235724E-6,1,0.999253354069792,40.0298881530762,1.99410070878439,14.2400003969669,0.00181363936889717,-1.20833018714244E-5,0.25,-2.80281598677267E-5,0.000155763298320076,-2.79510283032151E-5,250.0489,250.0489,-64821.4140625,-64806.58203125,54.0316346488711,19.56968150687,26.705515,0,0,0,40,4449,250.04825,-64813.998046875,,,,,,,,,,,,,0,,,,,,,,,,,,,,
,19753308.79,250.03955,-68564.45703125,0.000168367679696496,5.22991282789247E-6,1,0.999253354069792,40.0298881530762,1.99415189690997,14.2400003969669,0.00195327482845536,4.97666540818824E-5,0.25,-2.47974818990132E-5,0.000168683248342543,-2.47043729478976E-5,250.0404,250.0404,-68569.4296875,-68559.484375,53.9706676243711,19.569769374817,26.705515,0,0,0,40,4449,250.03955,-68564.45703125,,,,,,,,,,,,,0,,,,,,,,,,,,,,
,19753386.22,250.0315,-72434.3984375,0.000178038235381217,4.30362513902094E-6,1,0.999253354069792,40.0298881530762,1.99429346215049,14.2400003969669,0.00206694443554483,4.49092382311488E-5,0.25,-2.69039436898545E-5,0.000178372526885,-2.68068713754345E-5,250.0315,250.0315,-72437.015625,-72431.78125,54.1480972982365,19.5682962908515,26.705515,0,0,0,40,4449,250.0315,-72434.3984375,,,,,,,,,,,,,0,,,,,,,,,,,,,,
,19753463.805,250.019,-76311.8984375,0.00019330036974665,4.27416090101297E-6,1,0.999253354069792,40.0298881530762,1.99426209084675,14.2400003969669,0.00224257146042954,5.75626584606971E-5,0.25,-2.8431806321026E-5,0.000193662766358534,-2.83252528216172E-5,250.0189,250.0189,-76319.40625,-76304.390625,54.0394509340634,19.5687875092912,26.705515,0,0,0,40,4449,250.019,-76311.8984375,,,,,,,,,,,,,0,,,,,,,,,,,,,,
,19753541.5,250.01235,-80196.60546875,0.000208045300925425,4.35823227462879E-6,1,0.999253354069792,40.0298881530762,1.99431664236381,14.2400003969669,0.00240866316987318,9.09901720250476E-5,0.25,-2.80339019322331E-5,0.000208433307598538,-2.79149359895582E-5,250.0136,250.0136,-80206.5078125,-80186.703125,54.085567016698,19.5706911534921,26.705515,0,0,0,40,4449,250.01235,-80196.60546875,,,,,,,,,,,,,0,,,,,,,,,,,,,,
,19753620.615,250.0034,-84146.8515625,0.000224100960736654,5.04324931932242E-6,1,0.999253354069792,40.0298881530762,1.99423444131303,14.2400003969669,0.00259350840889936,0.000103425028355967,0.25,-2.97183458590604E-5,0.000224518590436663,-2.9589602635466E-5,250.0034,250.0034,-84154.3515625,-84139.3515625,54.0175653355249,19.5705202343489,26.705515,0,0,0,40,4449,250.0034,-84146.8515625,,,,,,,,,,,,,0,,,,,,,,,,,,,,
,19753693.84,249.9959,-87806.8515625,0.000239911485926714,4.63504008243106E-6,1,0.999253354069792,40.0298881530762,1.99430159735249,14.2400003969669,0.00277078471835223,0.000144103578167944,0.25,-2.88643783015194E-5,0.000240356259169637,-2.87216126992931E-5,249.996,249.996,-87811.921875,-87801.78125,54.1738910393711,19.572164272061,27.085165,0,0,0,40,4449,249.9959,-87806.8515625,,,,,,,,,,,,,0,,,,,,,,,,,,,,
,19753785.62,249.98585,-88487.984375,0.000235938335829049,5.04338119534471E-6,1,0.999253354069792,40.0298881530762,1.9945650036615,14.2400003969669,0.00273571725920098,8.13292580626897E-5,0.25,-3.37250662624959E-5,0.000236380132146546,-3.35940921407947E-5,249.9858,249.9858,-88498.03125,-88477.9375,54.0167837070057,19.5683401837213,26.705515,0,0,0,40,4449,249.98585,-88487.984375,,,,,,,,,,,,,0,,,,,,,,,,,,,,
,19753859.485,249.9844,-84795.8828125,0.000223510891827938,3.79390972918541E-6,1,0.999253354069792,40.0298881530762,1.99441584931725,14.2400003969669,0.00259196469466345,7.39889234618103E-5,0.25,-3.22185897019515E-5,0.000223929654674238,-3.2094760244902E-5,249.9846,249.9846,-84805.96875,-84785.796875,53.9675411102942,19.5705084606247,26.705515,0,0,0,40,4449,249.9844,-84795.8828125,,,,,,,,,,,,,0,,,,,,,,,,,,,,
,19753935.445,249.98535,-80998.07421875,0.000209525475437444,4.20131291096203E-6,1,0.999253354069792,40.0298881530762,1.99395996500014,14.2400003969669,0.00243538889895119,3.39504268438672E-5,0.25,-3.33318999993873E-5,0.000209920565461844,-3.32210975530014E-5,249.9857,249.9857,-81003.0390625,-80993.109375,54.1887419812365,19.573951245449,27.085165,0,0,0,40,4449,249.98535,-80998.07421875,,,,,,,,,,,,,0,,,,,,,,,,,,,,
,19754012.75,249.99235,-77137.82421875,0.000198539027567349,3.89595900483736E-6,1,0.999253354069792,40.0298881530762,1.99460005424017,14.2400003969669,0.00230960448816583,2.52123130207082E-5,0.25,-3.22001631636499E-5,0.000198913859916534,-3.2096040229976E-5,249.9919,249.9919,-77145.40625,-77130.2421875,54.0793139885442,19.5697412700383,26.705515,0,0,0,40,4449,249.99235,-77137.82421875,,,,,,,,,,,,,0,,,,,,,,,,,,,,
,19754092.695,249.9987,-73139.78515625,0.00018905161214751,3.02275453857512E-6,1,0.999253354069792,40.0298881530762,1.99390872918701,14.2400003969669,0.00219168406082735,6.33589359466446E-5,0.25,-2.71819099232033E-5,0.000189405680309721,-2.70764434432654E-5,249.9982,249.9982,-73147.6796875,-73131.890625,53.8502968324095,19.5737676172247,27.085165,0,0,0,40,4449,249.9987,-73139.78515625,,,,,,,,,,,,,0,,,,,,,,,,,,,,
,19754169.805,250.0056,-69287.609375,0.000174552347733055,3.4659402714713E-6,1,0.999253354069792,40.0298881530762,1.99456192163333,14.2400003969669,0.00201958560224291,8.52763066422284E-5,0.25,-2.27324257913196E-5,0.000174877304781007,-2.26307129356104E-5,250.0058,250.0058,-69290.0703125,-69285.1484375,54.0128755644096,19.5667107810242,26.325863,0,0,0,40,4449,250.0056,-69287.609375,,,,,,,,,,,,,0,,,,,,,,,,,,,,
,19754248.405,250.01385,-65359.771484375,0.000158267473258046,3.63991562563358E-6,1,0.999253354069792,40.0298881530762,1.99442671670187,14.2400003969669,0.00183878263785674,3.27197868524292E-5,0.25,-2.45534584576603E-5,0.000158565272274102,-2.44679884751681E-5,250.0129,250.0129,-65367.26171875,-65352.28125,54.034761162948,19.5675933984367,26.705515,0,0,0,40,4449,250.01385,-65359.771484375,,,,,,,,,,,,,0,,,,,,,,,,,,,,
,19754326.135,250.0205,-61474.330078125,0.000146723838584936,2.93937421906652E-6,1,0.999253354069792,40.0298881530762,1.99438669247208,14.2400003969669,0.00170479969039056,2.93739818678451E-5,0.25,-2.28474787059358E-5,0.000146999957542438,-2.2768239173737E-5,250.0204,250.0204,-61479.5234375,-61469.13671875,54.0097490503326,19.566413781218,26.705515,0,0,0,40,4449,250.0205,-61474.330078125,,,,,,,,,,,,,0,,,,,,,,,,,,,,
,19754404.32,250.02585,-57566.673828125,0.000133184400651355,2.83970378760682E-6,1,0.999253354069792,40.0298881530762,1.99401048498415,14.2400003969669,0.00154210124517599,5.60876775307278E-5,0.25,-1.81376016784158E-5,0.0001334329016604,-1.80609711339907E-5,250.0251,250.0251,-57576.58203125,-57556.765625,53.7994909786595,19.5698233215386,27.085165,0,0,0,40,4449,250.02585,-57566.673828125,,,,,,,,,,,,,0,,,,,,,,,,,,,,
,19754482.02,250.0327,-53684.072265625,0.000123116204966222,2.8357054716791E-6,1,0.999253354069792,40.0298881530762,1.99400617842961,14.2400003969669,0.00142771971864004,3.91712164162082E-5,0.25,-1.78872509231732E-5,0.000123346807013399,-1.78182554272373E-5,250.0327,250.0327,-53689.10546875,-53679.0390625,53.9370575980442,19.5681968717096,26.705515,0,0,0,40,4449,250.0327,-53684.072265625,,,,,,,,,,,,,0,,,,,,,,,,,,,,
,19754558.885,250.04,-49844.501953125,0.000107031758489072,3.22211013649281E-6,1,0.999253354069792,40.0298881530762,1.99401367927865,14.2400003969669,0.00124514450275465,1.1309450883334E-5,0.25,-1.75612031823992E-5,0.000107233850581211,-1.75046429074229E-5,250.0402,250.0402,-49852.11328125,-49836.890625,53.8862517442942,19.5689872835622,26.325863,0,0,0,40,4449,250.04,-49844.501953125,,,,,,,,,,,,,0,,,,,,,,,,,,,,
,19754636.155,250.04605,-45981.30859375,9.38429761771214E-5,2.51446491526886E-6,1,0.999253354069792,40.0298881530762,1.99416567075431,14.2400003969669,0.00109329017169349,1.28452036117554E-6,0.25,-1.61604114330834E-5,9.40207738968424E-5,-1.6112066409198E-5,250.0474,250.0474,-45988.69921875,-45973.91796875,53.8057440068134,19.5662808310399,27.085165,0,0,0,40,4449,250.04605,-45981.30859375,,,,,,,,,,,,,0,,,,,,,,,,,,,,
,19754712.055,250.0544,-42188.3828125,8.17261090059668E-5,2.5109935198021E-6,1,0.999253354069792,40.0298881530762,1.99405919500646,14.2400003969669,0.000956364872374208,-2.36048033637133E-5,0.25,-1.62595089694809E-5,8.18827179713448E-5,-1.62211599873689E-5,250.0544,250.0544,-42190.92578125,-42185.83984375,53.841698918698,19.5648017706168,26.705515,0,0,0,40,4449,250.0544,-42188.3828125,,,,,,,,,,,,,0,,,,,,,,,,,,,,
,19754787.835,250.05975,-38402.9921875,6.95321580701135E-5,1.7365017484866E-6,1,0.999253354069792,40.0298881530762,1.99421041737722,14.2400003969669,0.000812036449334149,-1.03233298364099E-5,0.25,-1.29707322958283E-5,6.96646857258406E-5,-1.29365265504674E-5,250.0607,250.0607,-38408.0625,-38397.921875,53.9175168850634,19.5650605693627,26.705515,0,0,0,40,4449,250.05975,-38402.9921875,,,,,,,,,,,,,0,,,,,,,,,,,,,,
,19754865.475,250.06815,-34520.412109375,5.85062855612271E-5,2.26179683976734E-6,1,0.999253354069792,40.0298881530762,1.99421023131451,14.2500000074506,0.000685423608356034,-2.11061796961869E-5,0.25,-1.2011864318577E-5,5.86186845185536E-5,-1.19849509181954E-5,250.0684,250.0684,-34525.5,-34515.32421875,54.1629482401019,19.5643500341395,27.085165,0,0,0,40,4449,250.06815,-34520.412109375,,,,,,,,,,,,,0,,,,,,,,,,,,,,
,19754942.165,250.07115,-30687.5927734375,4.60431313677792E-5,1.37402975969159E-6,1,0.999253354069792,40.0298881530762,1.99418221096134,14.2400003969669,0.000542409901338743,-3.39329509456795E-5,0.25,-1.09844387586888E-5,4.61328425569012E-5,-1.09659000791167E-5,250.0711,250.0711,-30692.45703125,-30682.728515625,54.146534041198,19.5653576748537,26.705515,0,0,0,40,4449,250.07115,-30687.5927734375,,,,,,,,,,,,,0,,,,,,,,,,,,,,
,19755018.25,250.0776,-26885.58203125,3.37350341453665E-5,1.53072446692466E-6,1,0.999253354069792,40.0298881530762,1.99419318977251,14.2400003969669,0.000397020781244171,-2.25791072795702E-5,0.25,-7.84632142054704E-6,3.38005940571116E-5,-7.8323540047127E-6,250.0776,250.0776,-26890.6328125,-26880.53125,53.9190801421018,19.5628392716355,26.705515,0,0,0,40,4449,250.0776,-26885.58203125,,,,,,,,,,,,,0,,,,,,,,,,,,,,
,19755097.305,250.0846,-22937.30859375,2.14465371731157E-5,1.23983337423057E-6,1,0.999253354069792,40.0298881530762,1.9943252818147,14.2400003969669,0.000259728584649482,-5.65223073591338E-5,0.25,-8.71544105614186E-6,2.14912781514099E-5,-8.71307161143448E-6,250.0847,250.0847,-22942.796875,-22931.8203125,54.1285565852557,19.5609582710476,27.085165,0,0,0,40,4449,250.0846,-22937.30859375,,,,,,,,,,,,,0,,,,,,,,,,,,,,
,19755175.975,250.0882,-19002.173828125,1.06957698083552E-5,1.29210657366506E-6,1,0.999253354069792,40.0298881530762,1.99436163415286,14.2500000074506,0.000132536384401178,-4.55043212506739E-5,0.25,-5.87705425235836E-6,1.07193441689337E-5,-5.87854379062888E-6,250.0882,250.0882,-19004.626953125,-18999.720703125,53.9276780558134,19.560910663753,27.085165,0,0,0,40,4449,250.0882,-19002.173828125,,,,,,,,,,,,,0,,,,,,,,,,,,,,
,19755254.17,250.0966,-15094.6547851562,-1.11609788031678E-6,6.82742224387292E-7,1,0.999253354069792,40.0298881530762,1.99449052129871,14.2400003969669,-2.1417969805862E-6,-6.26535634186405E-5,0.25,-5.34409706355983E-6,-1.11364883795804E-6,-5.35437606680078E-6,250.0954,250.0954,-15102.0361328125,-15087.2734375,54.0331979059096,19.5612050774396,26.705515,0,0,0,40,4449,250.0966,-15094.6547851562,,,,,,,,,,,,,0,,,,,,,,,,,,,,
,19755331.545,250.10155,-11228.9448242187,-1.19132935275918E-5,1.06106068170072E-6,1,0.999253354069792,40.0298881530762,1.99425041745375,14.2400003969669,-0.000126355304475464,-7.19086781343292E-5,0.25,-4.29034480188808E-6,-1.19306160720239E-5,-4.30768320931744E-6,250.1013,250.1013,-11238.919921875,-11218.9697265625,53.8549866035249,19.5638452167413,27.085165,0,0,0,40,4449,250.10155,-11228.9448242187,,,,,,,,,,,,,0,,,,,,,,,,,,,,
,19755406.075,250.1057,-7503.13500976563,-2.09131320312326E-5,5.51538541729455E-7,1,0.999253354069792,40.0298881530762,1.994144278539,14.2400003969669,-0.00023295105605431,-6.19172932290694E-5,0.25,-1.84662243512981E-6,-2.09482235905945E-5,-1.86711794728869E-6,250.1063,250.1063,-7510.57373046875,-7495.6962890625,54.0558651329673,19.5631296467236,27.085165,0,0,0,40,4449,250.1057,-7503.13500976563,,,,,,,,,,,,,0,,,,,,,,,,,,,,
,19755483.405,250.11045,-3636.79650878906,-2.72830995105155E-5,4.70611650273441E-7,1,0.999253354069792,40.0298881530762,1.99427953350912,14.2500000074506,-0.00030594569633479,-6.91339027438001E-5,0.25,-1.37944591414215E-6,-2.73297221975028E-5,-1.40439794972939E-6,250.1097,250.1097,-3646.8505859375,-3626.74243164063,53.8588947461211,19.5598369382797,27.085165,0,0,0,40,4449,250.11045,-3636.79650878906,,,,,,,,,,,,,0,,,,,,,,,,,,,,
,19755556.915,250.1128,40.0292224884033,-1.17510823467834E-5,3.99202379126146E-7,1,0.999253354069792,40.0298881530762,1.99411343310685,14.2400003969669,-0.000132259915589174,-2.69097226053001E-5,0.25,-3.40907760094585E-7,-1.17713706183815E-5,-3.51216745619377E-7,250.1128,250.1128,37.5486145019531,42.5098304748535,54.0120939358903,19.5619142527857,26.325863,0,0,0,40,4449,250.1128,40.0292224884033,,,,,,,,,,,,,0,,,,,,,,,,,,,,
,19755628.92,250.114,3630.14379882812,2.54887354327733E-5,3.45101861508049E-7,1,0.999253354069792,40.0298881530762,1.99419553415209,14.2500000074506,0.000286463125679025,6.08336156382365E-5,0.25,9.57154184420338E-7,2.55325625324164E-5,9.79884265259498E-7,250.1146,250.1146,3624.94091796875,3635.3466796875,53.8729640594672,19.560921586668,26.705515,0,0,0,40,4449,250.114,3630.14379882812,,,,,,,,,,,,,0,,,,,,,,,,,,,,
,19755702.985,250.1129,7332.548828125,2.20198698231767E-5,5.44665718355859E-7,1,0.999253354069792,40.0298881530762,1.99432851070731,14.2400003969669,0.000244336895843081,7.07563807067727E-5,0.25,2.43551160759064E-6,2.2056407361493E-5,2.45795111480153E-6,250.1135,250.1135,7330.02978515625,7335.06787109375,54.2801925179865,19.5614341513808,27.085165,0,0,0,40,4449,250.1129,7332.548828125,,,,,,,,,,,,,0,,,,,,,,,,,,,,
,19755778.34,250.1113,11101.283203125,1.31070741656091E-5,1.12266160706126E-6,1,0.999253354069792,40.0298881530762,1.99441693402921,14.2400003969669,0.00014144170825997,6.52019499408668E-5,0.25,3.49001188587473E-6,1.3127142705456E-5,3.50693204174055E-6,250.1119,250.1119,11093.6328125,11108.93359375,53.9792655380826,19.5601753728795,26.705515,0,0,0,40,4449,250.1113,11101.283203125,,,,,,,,,,,,,0,,,,,,,,,,,,,,
,19755853.475,250.10695,14857.0141601562,2.13097483085152E-6,8.16720859826727E-7,1,0.999253354069792,40.0298881530762,1.99401988068061,14.2400003969669,1.69417454045303E-5,4.5482965421539E-5,0.25,3.65137152091205E-6,2.13169722285664E-6,3.65952094710517E-6,250.107,250.107,14841.8955078125,14872.1328125,53.8792170876211,19.5642417238938,27.085165,0,0,0,40,4449,250.10695,14857.0141601562,,,,,,,,,,,,,0,,,,,,,,,,,,,,
,19755928.16,250.1026,18587.1884765625,-8.95882986267263E-6,1.01091370545907E-6,1,0.999253354069792,40.0298881530762,1.99444925767206,14.2400003969669,-0.000110801858217193,3.68714353133185E-5,0.25,4.81262687524153E-6,-8.97848079338538E-6,4.8136790293964E-6,250.1026,250.1026,18579.642578125,18594.734375,53.7783870086403,19.560466918616,27.085165,0,0,0,40,4449,250.1026,18587.1884765625,,,,,,,,,,,,,0,,,,,,,,,,,,,,
,19756004.175,250.09415,22388.001953125,-1.98406397406785E-5,9.85324919520554E-7,1,0.999253354069792,40.0298881530762,1.99412176545604,14.2400003969669,-0.000236191112617352,2.88406755950393E-5,0.25,5.99035235828385E-6,-1.98803196104009E-5,5.98452574703919E-6,250.0933,250.0933,22377.83203125,22398.171875,53.8456070612942,19.5611149128836,26.705515,0,0,0,40,4449,250.09415,22388.001953125,,,,,,,,,,,,,0,,,,,,,,,,,,,,
,19756081.79,250.0864,26265.6416015625,-3.06972825349054E-5,1.3716737202955E-6,1,0.999253354069792,40.0298881530762,1.99399781412436,14.2400003969669,-0.000364681429837129,4.04101943599247E-5,0.25,8.89607722961194E-6,-3.07583728267308E-5,8.88643898650281E-6,250.0864,250.0864,26260.833984375,26270.44921875,53.892504772448,19.5594086803268,27.085165,0,0,0,40,4449,250.0864,26265.6416015625,,,,,,,,,,,,,0,,,,,,,,,,,,,,
,19756158.73,250.08105,30113.904296875,-4.27811094841847E-5,1.57253918500237E-6,1,0.999253354069792,40.0298881530762,1.99418279569708,14.2400003969669,-0.000501999618121642,2.00995282611518E-5,0.25,9.19589159545123E-6,-4.28636209450775E-5,9.1768883002574E-6,250.0812,250.0812,30103.86328125,30123.9453125,53.6533264455634,19.5597994325386,27.085165,0,0,0,40,4449,250.08105,30113.904296875,,,,,,,,,,,,,0,,,,,,,,,,,,,,
,19756235.495,250.07285,33949.48046875,-5.53471123684664E-5,1.53164302879999E-6,1,0.999253354069792,40.0298881530762,1.99444599699124,14.2400003969669,-0.00064989015583892,2.80670215875297E-5,0.25,1.20790460169614E-5,-5.54540203506052E-5,1.20548319454713E-5,250.0724,250.0724,33937.00390625,33961.95703125,53.7494667534288,19.5551905051353,26.705515,0,0,0,40,4449,250.07285,33949.48046875,,,,,,,,,,,,,0,,,,,,,,,,,,,,
,19756310.19,250.06795,37682.572265625,-7.03632279815761E-5,1.69833444178381E-6,1,0.999253354069792,40.0298881530762,1.99406879223352,14.2400003969669,-0.000819997592207524,7.08728995329678E-7,0.25,1.2264968662994E-5,-7.04966146794751E-5,1.22288312980068E-5,250.0675,250.0675,37675.1171875,37690.02734375,53.8815619731788,19.5598491244729,26.705515,0,0,0,40,4449,250.06795,37682.572265625,,,,,,,,,,,,,0,,,,,,,,,,,,,,
,19756385.08,250.0584,41425.546875,-7.82270205962362E-5,1.70187391789001E-6,1,0.999253354069792,40.0298881530762,1.99435708119963,14.2400003969669,-0.000913815032784711,1.26002897169007E-5,0.25,1.46797244077063E-5,-7.83761913126175E-5,1.464145223739E-5,250.0587,250.0587,41418.02734375,41433.06640625,53.9480003973134,19.5587728073703,26.325863,0,0,0,40,4449,250.0584,41425.546875,,,,,,,,,,,,,0,,,,,,,,,,,,,,
,19756461.885,250.0522,45266.4921875,-9.08977857146381E-5,1.7223731475863E-6,1,0.999253354069792,40.0298881530762,1.99410835352649,14.2400003969669,-0.0010635871126132,2.55023239930458E-5,0.25,1.80176653020006E-5,-9.10719168534949E-5,1.79749664415039E-5,250.0522,250.0522,45261.41015625,45271.57421875,53.6556713311211,19.5566027649832,27.085165,0,0,0,40,4449,250.0522,45266.4921875,,,,,,,,,,,,,0,,,,,,,,,,,,,,
,19756536.06,250.0441,48971.828125,-0.000105631420065099,3.4063187942365E-6,1,0.999253354069792,40.0298881530762,1.99392122199373,14.2400003969669,-0.00123296397483553,1.28549010477687E-5,0.25,1.94546871074486E-5,-0.000105832587336832,1.94025668464874E-5,250.0442,250.0442,48964.37890625,48979.27734375,53.6376938751787,19.5593327001807,27.085165,0,0,0,40,4449,250.0441,48971.828125,,,,,,,,,,,,,0,,,,,,,,,,,,,,
,19756614.01,250.0352,52869.76171875,-0.000117478481243025,3.37085094409198E-6,1,0.999253354069792,40.0298881530762,1.99420028191445,14.2400003969669,-0.00136059468218022,-4.81847085334346E-5,0.25,1.6113162611351E-5,-0.000117697735067477,1.60456260732041E-5,250.0352,250.0352,52862.5625,52876.9609375,53.6673957589095,19.5573564832733,27.085165,0,0,0,40,4449,250.0352,52869.76171875,,,,,,,,,,,,,0,,,,,,,,,,,,,,
,19756688.87,250.02845,56610.21875,-0.000134694971853987,3.5559843229665E-6,1,0.999253354069792,40.0298881530762,1.99403289206898,14.2400003969669,-0.00156627755277783,-1.82658056903376E-5,0.25,2.17432543057172E-5,-0.000134949049240466,2.16716871027193E-5,250.0288,250.0288,56605.125,56615.3125,53.801054235698,19.5581018321424,27.085165,0,0,0,40,4449,250.02845,56610.21875,,,,,,,,,,,,,0,,,,,,,,,,,,,,
,19756764.35,250.01945,60380.96484375,-0.000137783722241417,3.48528838600506E-6,1,0.999253354069792,40.0298881530762,1.99396817509125,14.2400003969669,-0.00160104655767733,-2.50204060573808E-5,0.25,2.168155280617E-5,-0.000138043207840793,2.16074991256483E-5,250.0188,250.0188,60373.5078125,60388.421875,53.760409552698,19.5595694921305,27.464817,0,0,0,40,4449,250.01945,60380.96484375,,,,,,,,,,,,,0,,,,,,,,,,,,,,
,19756840.75,250.0113,64199.69140625,-0.000153594028041208,3.71655439403256E-6,1,0.999253354069792,40.0298881530762,1.99396333715725,14.2400003969669,-0.00178611887594594,-2.00470872956138E-5,0.25,2.48627911320285E-5,-0.000153883890188299,2.47816142629214E-5,250.011,250.011,64197.328125,64202.0546875,53.7338341830442,19.5573977860834,26.705515,0,0,0,40,4449,250.0113,64199.69140625,,,,,,,,,,,,,0,,,,,,,,,,,,,,
,19756916.35,250.00205,67977.703125,-0.000166093609496434,4.41164386570438E-6,1,0.999253354069792,40.0298881530762,1.99433400522764,14.2400003969669,-0.00192018181711018,-8.87821402253742E-5,0.25,2.09549418130114E-5,-0.000166402292851933,2.08569133173702E-5,250.0034,250.0034,67970.2109375,67985.1953125,53.841698918698,19.5579706863833,27.085165,0,0,0,40,4449,250.00205,67977.703125,,,,,,,,,,,,,0,,,,,,,,,,,,,,
,19756995.08,249.99265,71913.35546875,-0.000182757128284163,3.51765574076784E-6,1,0.999253354069792,40.0298881530762,1.99412801154061,14.2400003969669,-0.00211573929414848,-7.96828707873564E-5,0.25,2.46480023228134E-5,-0.000183098128744071,2.45431270529082E-5,249.9929,249.9929,71908.390625,71918.3203125,53.6173715336788,19.5559314135303,26.325863,0,0,0,40,4449,249.99265,71913.35546875,,,,,,,,,,,,,0,,,,,,,,,,,,,,
,19757072.375,249.9856,75776.7734375,-0.000197906253942245,4.11045500596303E-6,1,0.999253354069792,40.0298881530762,1.99397307872277,14.2400003969669,-0.00228716915859591,-0.000108073026641789,0.25,2.47644193211215E-5,-0.000198274005425111,2.46476738968312E-5,249.985,249.985,75766.7890625,75786.7578125,53.7267995263711,19.5566712858375,27.464817,0,0,0,40,4449,249.9856,75776.7734375,,,,,,,,,,,,,0,,,,,,,,,,,,,,
,19757149.06,249.9767,79609.91796875,-0.000209841511218576,3.15160533606388E-6,1,0.999253354069792,40.0298881530762,1.99418489708317,14.2400003969669,-0.0024327955963229,-7.1662981527245E-5,0.25,3.00534195822779E-5,-0.000210234574074406,2.99365236460949E-5,249.9775,249.9775,79604.921875,79614.9140625,53.7010057852365,19.5558051851595,26.705515,0,0,0,40,4449,249.9767,79609.91796875,,,,,,,,,,,,,0,,,,,,,,,,,,,,
,19757226.105,249.96925,83463.85546875,-0.00022435287871524,4.37516562517709E-6,1,0.999253354069792,40.0298881530762,1.99437694396561,14.2400003969669,-0.00259717297884406,-0.000100268056124874,0.25,3.00417790149029E-5,-0.00022477148738242,2.99133655331677E-5,249.9678,249.9678,83458.8515625,83468.859375,53.8456070612942,19.5535037606431,27.085165,0,0,0,40,4449,249.96925,83463.85546875,,,,,,,,,,,,,0,,,,,,,,,,,,,,
,19757301.13,249.959,87212.3828125,-0.000235434696388109,4.50566686841391E-6,1,0.999253354069792,40.0298881530762,1.99395194717182,14.2400003969669,-0.00272740736986135,-9.07731597155775E-5,0.25,3.28008281113371E-5,-0.000235875091370451,3.26685598385487E-5,249.959,249.959,87207.4609375,87217.3046875,53.8284112338711,19.5580011693531,27.085165,0,0,0,40,4449,249.959,87212.3828125,,,,,,,,,,,,,0,,,,,,,,,,,,,,
,19757358.025,249.9555,89999.6640625,-0.000247142893552937,5.58096131541539E-6,1,0.999253354069792,40.0298881530762,1.99399033753425,14.2400003969669,-0.00285684571144009,-0.000131325348802482,0.25,3.12460213523646E-5,-0.000247602646891712,3.11017657247238E-5,249.9556,249.9556,89999.65625,89999.671875,53.7697890949288,19.5548847834502,26.705515,0,0,0,40,4417,249.9555,89999.6640625,,,,,,,,,,,,,0,,,,,,,,,,,,,,