File: data/monolayers/magneticStructure/ML_Ac_CoFe_C-2/PPMS/BackupJuelich/data/Juelich/DD175_23_HYST_5K_100OE.DAT
[Header]
; VSM Data File (default extension .dat)
; Copyright (c) 2003, Quantum Design, Inc. All rights reserved.
TITLE,
FILEOPENTIME,46585514.50,04/05/2017,2:41 pm
BYAPP,VSM,1.0,1.0
INFO,PPMS VSM Option Release 1.3.7 Build 2,APPNAME
INFO,291,COIL_SERIAL_NUMBER
INFO,0,MOMENT_UNITS
INFO,CoFe2O4,SAMPLE_MATERIAL
INFO,,SAMPLE_COMMENT
INFO,,SAMPLE_MASS
INFO,,SAMPLE_VOLUME
INFO,,SAMPLE_MOLECULAR_WEIGHT
INFO,,SAMPLE_SIZE
INFO,,SAMPLE_SHAPE
INFO,36.48,SAMPLE_OFFSET
DATATYPE,COMMENT,1
DATATYPE,TIME,2
STARTUPAXIS,X,2
STARTUPAXIS,Y1,5
[Data]
Comment,Time Stamp (sec),Temperature (K),Magnetic Field (Oe),Moment (emu),M. Std. Err. (emu),Transport Action,Averaging Time (sec),Frequency (Hz),Peak Amplitude (mm),Center Position (mm),Coil Signal' (mV),Coil Signal" (mV),Range (mV),M. Quad. Signal (emu),M. Raw' (emu),M. Raw" (emu),Min. Temperature (K),Max. Temperature (K),Min. Field (Oe),Max. Field (Oe),Mass (grams),Motor Lag (deg),Pressure (Torr),VSM Status (code),Motor Status (code),Measure Status (code),PPMS Status (code),System Temp. (K),System Field (Oe),Sample Position (deg),Bridge 1 Resistance (ohms),Bridge 1 Excitation (에),Bridge 2 Resistance (ohms),Bridge 2 Excitation (에),Bridge 3 Resistance (ohms),Bridge 3 Excitation (에),Bridge 4 Resistance (ohms),Bridge 4 Excitation (에),Signal 1 Vin (V),Signal 2 Vin (V),Digital Inputs (code),Drive 1 Iout (mA),Drive 1 Ipower (W),Drive 2 Iout (mA),Drive 2 Ipower (W),Pressure (),Map 20 (),Map 21 (),Map 22 (),Map 23 (),Map 24 (),Map 25 (),Map 26 (),Map 27 (),Map 28 (),Map 29 ()
,46586077.765,5.02050755,-0.252136304974556,4.2879635943511E-5,3.20000675886952E-7,1,0.999253354069792,40.0298881530762,1.9947777270301,15.5500008817762,0.000465836034000179,5.47795486511308E-5,0.25,-2.45766361065463E-6,4.26308365907549E-5,-2.34838597991374E-6,5.019958,5.0210571,-0.259776800870895,-0.244495809078217,52.2917295650632,18.7051833966163,1.68398195,0,0,0,4417,4.94795,-0.252136304974556,,,,,,,,,,,,,,,,,12.252253,,,,,,5.02050755,,,,
,46586169.78,5.01450565,3859.48425292969,4.57957114308281E-5,3.8923191853605E-7,1,0.999253354069792,40.0298881530762,1.99491021551967,15.5500008817762,0.000495029247749656,7.29600730990559E-5,0.25,-1.28761924412084E-6,4.55294678916705E-5,-1.17289433439008E-6,5.0137582,5.0152531,3834.36743164063,3884.60107421875,52.2768786231978,18.7052975405716,1.69230885,0,0,0,4449,4.93925,3859.48425292969,,,,,,,,,,,,,,,,,13.003003,,,,,,5.01450565,,,,
,46586247.74,5.0113547,7754.73486328125,3.89933200421558E-5,5.45112713824824E-7,1,0.999253354069792,40.0298881530762,1.99490980703194,15.5500008817762,0.000422323761281178,5.76273725594727E-5,0.25,-1.52134600156449E-6,3.87705511772443E-5,-1.41466262562493E-6,5.0112143,5.0114951,7729.703125,7779.7666015625,52.2495216250248,18.70647992117,1.68381395,0,0,0,4449,4.9317,7754.73486328125,,,,,,,,,,,,,,,,,12.252253,,,,,,5.0113547,,,,
,46586324.995,5.0083725,11615.8012695313,3.16545607286704E-5,8.8059432635867E-7,1,0.999253354069792,40.0298881530762,1.99480408125585,15.5500008817762,0.000342651936732472,4.79238528459867E-5,0.25,-1.13482287765527E-6,3.14762222192179E-5,-1.04310035966234E-6,5.0080709,5.0086741,11588.296875,11643.3056640625,52.2846949083902,18.7157866728806,1.70088905,0,0,0,4449,4.927,11615.8012695313,,,,,,,,,,,,,,,,,13.003003,,,,,,5.0083725,,,,
,46586403.195,5.0052011,15524.2744140625,2.3231380845184E-5,6.5505019293359E-7,1,0.999253354069792,40.0298881530762,1.99486368506899,15.5500008817762,0.000252341403717427,3.04496768006553E-5,0.25,-1.27673045549076E-6,2.31040978206964E-5,-1.20248432305002E-6,5.0051799,5.0052223,15491.76953125,15556.779296875,53.1968553903326,18.7129220104165,1.7177944,0,0,0,4449,4.9241,15524.2744140625,,,,,,,,,,,,,,,,,13.003003,,,,,,5.0052011,,,,
,46586482.095,5.00383115,19467.005859375,1.53435872555375E-5,9.30832627811494E-7,1,0.999253354069792,40.0298881530762,1.99489413631956,15.5500008817762,0.000167370266096138,1.62443072124186E-5,0.25,-1.206000596313E-6,1.52624167440254E-5,-1.15196402829861E-6,5.003274,5.0043883,19439.580078125,19494.431640625,52.7458557347364,18.7111924457702,1.70088905,0,0,0,4449,4.92105,19467.005859375,,,,,,,,,,,,,,,,,13.003003,,,,,,5.00383115,,,,
,46586562.065,5.0035775,23464.837890625,6.02147118126287E-6,9.43789476733507E-7,1,0.999253354069792,40.0298881530762,1.99482837146144,15.5500008817762,6.57527548502358E-5,6.02128375018899E-6,0.25,-5.07471968291083E-7,5.99053161873967E-6,-4.84894971020975E-7,5.0022979,5.0048571,23432.29296875,23497.3828125,52.5864035168132,18.7133107698154,1.73504095,0,0,0,4449,4.91795,23464.837890625,,,,,,,,,,,,,,,,,13.003003,,,,,,5.0035775,,,,
,46586640.945,5.00373605,27408.1494140625,-5.04757386184492E-6,8.3053622534775E-7,1,0.999253354069792,40.0298881530762,1.99494613712064,15.5500008817762,-5.18500845231254E-5,-2.35290548504227E-5,0.25,-1.29100066366168E-6,-5.01635873429105E-6,-1.30182131203629E-6,5.0035496,5.0039225,27385.880859375,27430.41796875,53.6416020177749,18.7125175028005,1.69230885,0,0,0,4449,4.91505,27408.1494140625,,,,,,,,,,,,,,,,,12.252253,,,,,,5.00373605,,,,
,46586716.455,5.00289105,31180.861328125,-1.42091692627813E-5,8.68031015245406E-7,1,0.999253354069792,40.0298881530762,1.9949833388744,15.5500008817762,-0.000153046922106834,-2.64294902099514E-5,0.25,6.81288895058423E-8,-1.41360999142379E-5,1.53395011229411E-8,5.002563,5.0032191,31158.38671875,31203.3359375,52.4472736403902,18.712929157067,1.7177944,0,0,0,4449,4.9129,31180.861328125,,,,,,,,,,,,,,,,,13.003003,,,,,,5.00289105,,,,
,46586794.57,5.00331805,35084.166015625,-2.58070477409876E-5,8.62509322661805E-7,1,0.999253354069792,40.0298881530762,1.99489618351096,15.5500008817762,-0.0002762337662106,-5.79204358326374E-5,0.25,-7.92253808678008E-7,-2.56745010635615E-5,-8.88625207434976E-7,5.002995,5.0036411,35061.69140625,35106.640625,52.5942198020056,18.7128281572927,1.7263746,0,0,0,4449,4.91125,35084.166015625,,,,,,,,,,,,,,,,,13.003003,,,,,,5.00331805,,,,
,46586872.67,5.0009625,38989.046875,-3.72618803621398E-5,1.0389449921468E-6,1,0.999253354069792,40.0298881530762,1.9948777981,15.5500008817762,-0.000397635684080923,-9.07404982259503E-5,0.25,-1.79623333461938E-6,-3.7073291958362E-5,-1.93961875604313E-6,5.0002141,5.0017109,38968.93359375,39009.16015625,52.8130757873902,18.718418706858,1.7092995,0,0,0,4449,4.91165,38989.046875,,,,,,,,,,,,,,,,,13.003003,,,,,,5.0009625,,,,
,46586949.345,5.0009899,42820.01171875,-4.88352467096248E-5,9.32269934692093E-7,1,0.999253354069792,40.0298881530762,1.99493877111735,15.5500008817762,-0.000523104364524346,-0.000108444141682387,0.25,-1.36956590184093E-6,-4.85995439392795E-5,-1.57157036703113E-6,5.0008998,5.00108,42797.40625,42842.6171875,52.9733096338325,18.7176337463744,1.7092995,0,0,0,4449,4.91145,42820.01171875,,,,,,,,,,,,,,,,,12.252253,,,,,,5.0009899,,,,
,46587026.47,5.0007362,46676.111328125,-5.93402265308821E-5,7.48674765792669E-7,1,0.999253354069792,40.0298881530762,1.99486000699937,15.5500008817762,-0.000637607049125406,-0.000121152147548709,0.25,-6.65498242534364E-7,-5.90678257997521E-5,-9.2654598726811E-7,5.00073,5.0007424,46646.15625,46706.06640625,52.7145905939671,18.7163450743364,1.73504095,0,0,0,4449,4.91105,46676.111328125,,,,,,,,,,,,,,,,,12.252253,,,,,,5.0007362,,,,
,46587103.295,4.99998785,50516.927734375,-7.14015622059718E-5,1.06684717919456E-6,1,0.999253354069792,40.0298881530762,1.99476989996818,15.5500008817762,-0.000766678919533018,-0.00014930036278549,0.25,-1.1137360713674E-6,-7.108452566749E-5,-1.43909003574747E-6,4.999177,5.0007987,50494.328125,50539.52734375,52.5824953742171,18.717829300416,1.7092995,0,0,0,4449,4.91065,50516.927734375,,,,,,,,,,,,,,,,,13.003003,,,,,,4.99998785,,,,
,46587182.61,4.9991777,54479.591796875,-8.55106141333922E-5,8.64502147593354E-7,1,0.999253354069792,40.0298881530762,1.99484958514089,15.5500008817762,-0.000917224853441582,-0.000185297560764369,0.25,-1.91844906771611E-6,-8.51436862700515E-5,-2.32069689290687E-6,4.9988375,4.9995179,54452.1171875,54507.06640625,53.0553806283518,18.7202947895872,1.71796585,0,0,0,4449,4.91135,54479.591796875,,,,,,,,,,,,,,,,,13.003003,,,,,,4.9991777,,,,
,46587260.35,4.99780515,58365.716796875,-9.54737373498193E-5,1.37890344033181E-6,1,0.999253354069792,40.0298881530762,1.99478032757636,15.5500008817762,-0.00102417349453302,-0.000207344299383201,0.25,-2.16602284037389E-6,-9.50814465185826E-5,-2.63092493287365E-6,4.9977818,4.9978285,58340.71484375,58390.71875,52.8881121252364,18.7189479646496,1.73504095,0,0,0,4449,4.91295,58365.716796875,,,,,,,,,,,,,,,,,12.252253,,,,,,4.99780515,,,,
,46587337.25,4.9978743,62210.625,-0.000107865276595907,9.8351452516806E-7,1,0.999253354069792,40.0298881530762,1.9947401259457,15.5500008817762,-0.00116324050302347,-0.000201108465149296,0.25,6.49943424676171E-7,-0.000107458040799512,9.59881466220058E-8,4.9978743,4.9978743,62188.28125,62232.96875,53.1202557954479,18.7211415035848,1.7007193,0,0,0,4449,4.9148,62210.625,,,,,,,,,,,,,,,,,13.003003,,,,,,4.9978743,,,,
,46587414.275,4.99942755,66059.59765625,-0.000122408564497119,1.21232675793038E-6,1,0.999253354069792,40.0298881530762,1.99480790192655,15.5500008817762,-0.00131877047270642,-0.000237259268617255,0.25,-7.85293126718173E-8,-0.000121966078104307,-7.2178237403636E-7,4.9988732,4.9999819,66036.90625,66082.2890625,53.0162992023902,18.719375523501,1.7092142,0,0,0,4449,4.9144,66059.59765625,,,,,,,,,,,,,,,,,12.252253,,,,,,4.99942755,,,,
,46587491.29,4.9981289,69907.84765625,-0.000136585217173567,1.14498070544713E-6,1,0.999253354069792,40.0298881530762,1.99479971483014,15.5500008817762,-0.0014704770562051,-0.000272115042772183,0.25,-7.48905090163863E-7,-0.000136115015374579,-1.48301205168668E-6,4.9980741,4.9981837,69885.1953125,69930.5,52.738039449544,18.7207512755964,1.71796585,0,0,0,4449,4.9152,69907.84765625,,,,,,,,,,,,,,,,,13.003003,,,,,,4.9981289,,,,
,46587568.275,4.9978609,73755.96484375,-0.000151386026140607,9.98193856286473E-7,1,0.999253354069792,40.0298881530762,1.99475411861539,15.5500008817762,-0.00163229729917012,-0.000289512414318852,0.25,3.1588762952215E-7,-0.000150901607396226,-5.20924336765736E-7,4.9971614,4.9985604,73728.3359375,73783.59375,53.1827860769864,18.7171423355958,1.72646075,0,0,0,4449,4.91635,73755.96484375,,,,,,,,,,,,,,,,,13.003003,,,,,,4.9978609,,,,
,46587644.86,4.99712085,77584.2890625,-0.000161756686066321,1.2713697256452E-6,1,0.999253354069792,40.0298881530762,1.99480159164559,15.5500008817762,-0.00174378851792764,-0.000313450008346278,0.25,-1.77035742348776E-8,-0.000161269949918141,-9.29829289627529E-7,4.996727,4.9975147,77556.8984375,77611.6796875,52.6989580235825,18.7197261597103,1.7524606,0,0,0,4449,4.91845,77584.2890625,,,,,,,,,,,,,,,,,12.252253,,,,,,4.99712085,,,,
,46587722.625,4.99700735,81472.41015625,-0.000177222162081467,1.46306169751176E-6,1,0.999253354069792,40.0298881530762,1.9948104881173,15.5500008817762,-0.0019094302052023,-0.000351774760282236,0.25,-7.67990262472461E-7,-0.000176721440866917,-1.7849406482867E-6,4.9969406,4.9970741,81445.0390625,81499.78125,53.0202073449864,18.7196160712032,1.7437073,0,0,0,4449,4.9204,81472.41015625,,,,,,,,,,,,,,,,,12.252253,,,,,,4.99700735,,,,
,46587799.65,4.99710105,85320.609375,-0.000192342999734301,1.55563081108629E-6,1,0.999253354069792,40.0298881530762,1.9947701634958,15.5500008817762,-0.00207424141946097,-0.000373493575375938,0.25,-3.83625264594267E-8,-0.000191843951614349,-1.16379690198004E-6,4.9963255,4.9978766,85298.109375,85343.109375,52.5801504886594,18.7235805158191,1.72646075,0,0,0,4449,4.92155,85320.609375,,,,,,,,,,,,,,,,,12.252253,,,,,,4.99710105,,,,
,46587876.545,4.99662165,89163.29296875,-0.00020568181134151,1.02499248162422E-6,1,0.999253354069792,40.0298881530762,1.99473464955193,15.5500008817762,-0.00221471442335557,-0.000420582221815055,0.25,-1.97936811357897E-6,-0.000205179285744013,-3.1972583451041E-6,4.9959989,4.9972444,89135.9140625,89190.671875,52.6997396521017,18.7210827346576,1.7437073,0,0,0,4449,4.9232,89163.29296875,,,,,,,,,,,,,,,,,12.252253,,,,,,4.99662165,,,,
,46587967.45,5.00027035,87079.8359375,-0.00019788824746297,1.0063055311151E-6,1,0.999253354069792,40.0298881530762,1.99476804414552,15.5500008817762,-0.00212817620596139,-0.000418021847009138,0.25,-3.15780458325579E-6,-0.000197375207061613,-4.31648833708305E-6,4.9993663,5.0011744,87057.2421875,87102.4296875,53.1866942195826,18.7195284666543,1.7092142,0,0,0,4449,4.92335,87079.8359375,,,,,,,,,,,,,,,,,12.252253,,,,,,5.00027035,,,,
,46588044.415,5.0033507,83231.85546875,-0.000184026380564174,1.42609450808027E-6,1,0.999253354069792,40.0298881530762,1.99482100500401,15.5500008817762,-0.00198434463505978,-0.000357495791954765,0.25,-6.3528648866364E-8,-0.000183528052895839,-1.13030601257665E-6,5.0026631,5.0040383,83209.375,83254.3359375,52.954550549371,18.7231849881363,1.7437073,0,0,0,4449,4.9209,83231.85546875,,,,,,,,,,,,,,,,,12.252253,,,,,,5.0033507,,,,
,46588122.68,5.00356125,79320.87109375,-0.000170802138446198,1.29573153229696E-6,1,0.999253354069792,40.0298881530762,1.99474655635069,15.5400010384619,-0.00183503873996825,-0.000366541670071309,0.25,-3.30669307383654E-6,-0.00017028530727173,-4.2689124106848E-6,5.0031686,5.0039539,79300.984375,79340.7578125,52.9115609808133,18.7208330642476,1.72646075,0,0,0,4449,4.9187,79320.87109375,,,,,,,,,,,,,,,,,13.003003,,,,,,5.00356125,,,,
,46588201.29,5.0027013,75392.859375,-0.000155581853501934,1.1195020750122E-6,1,0.999253354069792,40.0298881530762,1.99475288036345,15.5500008817762,-0.00167701315196936,-0.000301295230401083,0.25,-1.36841876031342E-8,-0.000155095601081036,-8.80634141792925E-7,5.0024853,5.0029173,75367.9375,75417.78125,53.2984670978326,18.7235878892411,1.72646075,0,0,0,4449,4.9151,75392.859375,,,,,,,,,,,,,,,,,12.252253,,,,,,5.0027013,,,,
,46588279.85,5.0031314,71465.03515625,-0.000143445546177717,8.92411482517258E-7,1,0.999253354069792,40.0298881530762,1.99479894331636,15.5500008817762,-0.00154496598478054,-0.000282990001016259,0.25,-5.17728983858618E-7,-0.000142964801852051,-1.29722066391238E-6,5.0030441,5.0032187,71440.0703125,71490,52.6544051979863,18.7223820483518,1.7437073,0,0,0,4449,4.91275,71465.03515625,,,,,,,,,,,,,,,,,13.003003,,,,,,5.0031314,,,,
,46588359.015,5.0045514,67509.71484375,-0.000128652337041035,1.08645963105222E-6,1,0.999253354069792,40.0298881530762,1.99475738704422,15.5500008817762,-0.00138283325171669,-0.000267641178054055,0.25,-1.77112800093807E-6,-0.000128187880239581,-2.44795435089788E-6,5.0043292,5.0047736,67477.2578125,67542.171875,53.1812228199479,18.7233831293665,1.7092142,0,0,0,4449,4.9101,67509.71484375,,,,,,,,,,,,,,,,,13.003003,,,,,,5.0045514,,,,
,46588438.43,5.005954,63541.12109375,-0.000117373305472149,9.78497831050524E-7,1,0.999253354069792,40.0298881530762,1.99484673614812,15.5500008817762,-0.00126628716910836,-0.000216847784068062,0.25,9.00099305287974E-7,-0.000116939051863252,2.90663579914004E-7,5.0056014,5.0063066,63518.6484375,63563.59375,53.0631969135441,18.7282128163697,1.72646075,0,0,0,4449,4.9063,63541.12109375,,,,,,,,,,,,,,,,,13.003003,,,,,,5.005954,,,,
,46588518.565,5.00574755,59532.841796875,-0.000102139043598115,1.08064114231505E-6,1,0.999253354069792,40.0298881530762,1.99481297190866,15.5500008817762,-0.00109980370079452,-0.000199204871816665,0.25,-2.11487269997083E-7,-0.000101735643796095,-7.22090268943709E-7,5.0051622,5.0063329,59510.40625,59555.27734375,52.802132988121,18.7252028073835,1.72646075,0,0,0,4449,4.89985,59532.841796875,,,,,,,,,,,,,,,,,13.003003,,,,,,5.00574755,,,,
,46588598.135,5.0054729,55557.0859375,-8.97063387216855E-5,1.028042902758E-6,1,0.999253354069792,40.0298881530762,1.99470027485649,15.5500008817762,-0.000964971103144835,-0.000178950412129911,0.25,-5.75225627671068E-7,-8.9332878429522E-5,-1.00735597104026E-6,5.0054603,5.0054855,55532.1328125,55582.0390625,52.9389179789864,18.7277589866272,1.7437073,0,0,0,4449,4.89605,55557.0859375,,,,,,,,,,,,,,,,,13.003003,,,,,,5.0054729,,,,
,46588676.415,5.00401495,51644.087890625,-7.86194466755018E-5,8.38527250679274E-7,1,0.999253354069792,40.0298881530762,1.99476827527301,15.5500008817762,-0.000847752886724373,-0.000144649554770964,0.25,6.1190293777919E-7,-7.82829712386728E-5,2.41730205815118E-7,5.0031247,5.0049052,51614.0390625,51674.13671875,52.8928018963518,18.7255964100125,1.72646075,0,0,0,4449,4.894,51644.087890625,,,,,,,,,,,,,,,,,12.252253,,,,,,5.00401495,,,,
,46588757.055,5.0055437,47613.095703125,-6.28491762577976E-5,8.54091772264911E-7,1,0.999253354069792,40.0298881530762,1.99489021870831,15.5500008817762,-0.000674239800175918,-0.000134533548344586,0.25,-1.27891483086319E-6,-6.25606640355896E-5,-1.55556185770932E-6,5.0052428,5.0058446,47590.53125,47635.66015625,52.8537204703902,18.7321946538254,1.7437073,0,0,0,4449,4.8904,47613.095703125,,,,,,,,,,,,,,,,,13.003003,,,,,,5.0055437,,,,
,46588834.8,5.00500845,43727.384765625,-5.12285505595188E-5,8.66402520785633E-7,1,0.999253354069792,40.0298881530762,1.99477396734196,15.5500008817762,-0.000551165218746789,-0.000100029058400853,0.25,-1.59481208856994E-7,-5.09887106983683E-5,-3.79619601228332E-7,5.0047231,5.0052938,43702.36328125,43752.40625,53.2023267899672,18.730568299308,1.7437073,0,0,0,4449,4.8865,43727.384765625,,,,,,,,,,,,,,,,,12.252253,,,,,,5.00500845,,,,
,46588912.74,4.9997139,39833.77734375,-4.01323680032649E-5,7.10092611389354E-7,1,0.999253354069792,40.0298881530762,1.99486858243001,15.5500008817762,-0.000432093583936856,-7.63169999692351E-5,0.25,5.670060987043E-8,-3.99387509622245E-5,-1.09077363509125E-7,4.9996028,4.999825,39808.76171875,39858.79296875,52.7841555321787,18.7238461638966,1.72646075,0,0,0,4449,4.88995,39833.77734375,,,,,,,,,,,,,,,,,13.003003,,,,,,4.9997139,,,,
,46588991.92,5.00030945,35873.72265625,-2.88030531600346E-5,1.14536075893664E-6,1,0.999253354069792,40.0298881530762,1.99490022446911,15.5500008817762,-0.000305330172196308,-8.14102582421247E-5,0.25,-2.4406362283499E-6,-2.86498373868907E-5,-2.54160192486378E-6,5.0002675,5.0003514,35851.28125,35896.1640625,53.2851794130056,18.7274443404817,1.72646075,0,0,0,4449,4.89005,35873.72265625,,,,,,,,,,,,,,,,,13.003003,,,,,,5.00030945,,,,
,46589070.61,5.001421,31943.419921875,-1.66181593061864E-5,7.13870771260558E-7,1,0.999253354069792,40.0298881530762,1.99481395281733,15.5500008817762,-0.000179529422027719,-2.78432730433017E-5,0.25,3.65184031581221E-7,-1.65342234081619E-5,3.01335111440981E-7,5.0005732,5.0022688,31918.33984375,31968.5,52.9694014912364,18.729029171783,1.72646075,0,0,0,4449,4.88695,31943.419921875,,,,,,,,,,,,,,,,,12.252253,,,,,,5.001421,,,,
,46589149.6,5.0036614,27995.5302734375,-6.93250268001635E-6,6.84745350804108E-7,1,0.999253354069792,40.0298881530762,1.99498854132487,15.5500008817762,-7.59314758540428E-5,-5.73849892135132E-6,0.25,6.96982977846336E-7,-6.89842500226364E-6,6.68858988211308E-7,5.003407,5.0039158,27970.5859375,28020.474609375,53.0545989998325,18.726011464012,1.7092142,0,0,0,4449,4.8847,27995.5302734375,,,,,,,,,,,,,,,,,13.003003,,,,,,5.0036614,,,,
,46589226.885,5.0031631,24132.0107421875,3.37709189109833E-6,9.20600380158056E-7,1,0.999253354069792,40.0298881530762,1.99496218209603,15.5500008817762,3.47685059010637E-5,1.528997141488E-5,0.25,8.22412450376336E-7,3.35613542319376E-6,8.29212620252824E-7,5.0028481,5.0034781,24107.005859375,24157.015625,52.8044778736787,18.728193138681,1.72646075,0,0,0,4449,4.88355,24132.0107421875,,,,,,,,,,,,,,,,,13.003003,,,,,,5.0031631,,,,
,46589306.05,5.00359105,20173.873046875,1.36616330699792E-5,6.24105845875204E-7,1,0.999253354069792,40.0298881530762,1.99480863306871,15.5500008817762,0.00014748163438216,2.31562335969039E-5,0.25,-2.6627756490332E-7,1.35871494199591E-5,-2.22141390801407E-7,5.0032377,5.0039444,20153.646484375,20194.099609375,52.7059926802556,18.7298474493033,1.72646075,0,0,0,4449,4.87975,20173.873046875,,,,,,,,,,,,,,,,,13.003003,,,,,,5.00359105,,,,
,46589386.325,5.00495005,16161.2377929687,2.24408911589145E-5,6.45949397312683E-7,1,0.999253354069792,40.0298881530762,1.99484664857696,15.5500008817762,0.000241653851020534,4.13101663620784E-5,0.25,-1.28163502249982E-7,2.23151168395893E-5,-6.1954136099922E-8,5.0044789,5.0054212,16131.0859375,16191.3896484375,52.9099977237748,18.7333873011942,1.7437073,0,0,0,4449,4.87715,16161.2377929687,,,,,,,,,,,,,,,,,12.252253,,,,,,5.00495005,,,,
,46589463.445,5.0013466,12307.7602539062,3.16378709645856E-5,6.26982800000385E-7,1,0.999253354069792,40.0298881530762,1.99473994445294,15.5500008817762,0.000340740468975966,5.76711163314554E-5,0.25,-2.26710263429765E-7,3.14576854413188E-5,-1.3917000092963E-7,5.0011883,5.0015049,12282.80078125,12332.7197265625,53.0671050561402,18.7317167888697,1.71796585,0,0,0,4449,4.8769,12307.7602539062,,,,,,,,,,,,,,,,,13.003003,,,,,,5.0013466,,,,
,46589542.57,5.00080635,8354.35595703125,3.8784952788758E-5,5.50698426305349E-7,1,0.999253354069792,40.0298881530762,1.99486900757762,15.5400010384619,0.000418769943872476,6.46554453622834E-5,0.25,-8.32254293986109E-7,3.85621437238386E-5,-7.29035581672379E-7,5.000639,5.0009737,8329.310546875,8379.4013671875,53.1241639380441,18.7327862836445,1.72646075,0,0,0,4449,4.87405,8354.35595703125,,,,,,,,,,,,,,,,,12.252253,,,,,,5.00080635,,,,
,46589621.49,4.9983282,4408.09423828125,4.55840689900196E-5,4.01985067314806E-7,1,0.999253354069792,40.0298881530762,1.99498250400821,15.5500008817762,0.000493432958638894,6.88251916389151E-5,0.25,-1.63605269609358E-6,4.53203232889252E-5,-1.5187622621689E-6,4.9980841,4.9985723,4385.416015625,4430.7724609375,52.6981763950633,18.7324093486471,1.7092142,0,0,0,4449,4.8785,4408.09423828125,,,,,,,,,,,,,,,,,13.003003,,,,,,4.9983282,,,,
,46589701.54,4.9986646,406.736770629883,4.66593345586221E-5,2.7201397025437E-7,1,0.999253354069792,40.0298881530762,1.9948068592228,15.5500008817762,0.000505108393270163,6.98215800741622E-5,0.25,-1.72520833490438E-6,4.63866745088832E-5,-1.61151732737794E-6,4.9984231,4.9989061,381.667999267578,431.805541992188,53.2812712704095,18.7322455137883,1.72646075,0,0,0,4449,4.8796,406.736770629883,,,,,,,,,,,,,,,,,12.252253,,,,,,4.9986646,,,,
,46589780.15,4.99965645,-3516.2998046875,3.54126455584323E-5,2.68333954982768E-7,1,0.999253354069792,40.0298881530762,1.99502162461994,15.5500008817762,0.000387081647995013,3.21875655494458E-5,0.25,-3.24803093501683E-6,3.52118025160947E-5,-3.14654554432746E-6,4.9992142,5.0000987,-3546.40307617188,-3486.19653320313,53.0045747746017,18.7301575434773,1.72646075,0,0,0,4449,4.87945,-3516.2998046875,,,,,,,,,,,,,,,,,12.252253,,,,,,4.99965645,,,,
,46589859.455,5.00151015,-7483.50170898438,4.07737214730867E-5,5.29866256468461E-7,1,0.999253354069792,40.0298881530762,1.99477711843612,15.5500008817762,0.000445517871415896,3.79102716665637E-5,0.25,-3.66768482082668E-6,4.05457347474207E-5,-3.54454806255388E-6,5.0013461,5.0016742,-7505.8837890625,-7461.11962890625,52.9334465793518,18.734961252595,1.7092142,0,0,0,4449,4.8782,-7483.50170898438,,,,,,,,,,,,,,,,,13.003003,,,,,,5.00151015,,,,
,46589939.28,5.00070045,-11471.9282226562,4.57962326852196E-5,5.8810126479867E-7,1,0.999253354069792,40.0298881530762,1.99491699824245,15.5500008817762,0.000499997081844966,4.53228949499019E-5,0.25,-3.87388893281353E-6,4.55440568381454E-5,-3.7287067644218E-6,5.000288,5.0011129,-11499.3740234375,-11444.482421875,53.2234307599864,18.7320639860608,1.72646075,0,0,0,4449,4.87635,-11471.9282226562,,,,,,,,,,,,,,,,,13.003003,,,,,,5.00070045,,,,
,46590019.17,4.9997108,-15464.9877929687,4.82747127339751E-5,5.50787454406709E-7,1,0.999253354069792,40.0298881530762,1.99495024015889,15.5500008817762,0.000526857839471991,4.92895121353208E-5,0.25,-3.95306957670523E-6,4.80138874449474E-5,-3.79159578557983E-6,4.999464,4.9999576,-15487.45703125,-15442.5185546875,53.1562107073326,18.7337918901473,1.72646075,0,0,0,4449,4.87715,-15464.9877929687,,,,,,,,,,,,,,,,,12.252253,,,,,,4.9997108,,,,
,46590099.11,5.0011971,-19460.2841796875,4.68258538119333E-5,7.18554359421308E-7,1,0.999253354069792,40.0298881530762,1.99491439880952,15.5500008817762,0.000513499446479652,3.42599481081578E-5,0.25,-5.10401332455889E-6,4.65825198112126E-5,-4.9312426260453E-6,5.0011368,5.0012574,-19485.125,-19435.443359375,52.6372093705633,18.7328033264866,1.72646075,0,0,0,4449,4.87665,-19460.2841796875,,,,,,,,,,,,,,,,,12.252253,,,,,,5.0011971,,,,
,46590178.09,5.0013621,-23408.2490234375,3.91771822976641E-5,5.9809095812523E-7,1,0.999253354069792,40.0298881530762,1.99494209205267,15.5500008817762,0.000430878883713683,2.19502069488714E-5,0.25,-4.90277867966499E-6,3.89810718754292E-5,-4.74732243517991E-6,5.0002618,5.0024624,-23433.16015625,-23383.337890625,52.9295384367556,18.7364489754481,1.7437073,0,0,0,4449,4.8767,-23408.2490234375,,,,,,,,,,,,,,,,,12.252253,,,,,,5.0013621,,,,
,46590256.17,5.0023482,-27311.34375,3.43176655786408E-5,7.55828557738977E-7,1,0.999253354069792,40.0298881530762,1.9948706518945,15.5500008817762,0.000377034633152214,2.17240966562414E-5,0.25,-4.06988135448778E-6,3.41502310664524E-5,-3.92851202869914E-6,5.0017724,5.002924,-27331.365234375,-27291.322265625,53.2093614466402,18.731976690624,1.72646075,0,0,0,4449,4.87475,-27311.34375,,,,,,,,,,,,,,,,,13.003003,,,,,,5.0023482,,,,
,46590333.155,4.9996624,-31156.2744140625,3.34895799345009E-5,6.5368209574522E-7,1,0.999253354069792,40.0298881530762,1.994932928568,15.5500008817762,0.000370279981303645,8.39852651949072E-6,0.25,-5.16831205862267E-6,3.33358077754754E-5,-5.01808989035732E-6,4.9993348,4.99999,-31183.81640625,-31128.732421875,53.2117063321979,18.7359182104988,1.72646075,0,0,0,4449,4.8747,-31156.2744140625,,,,,,,,,,,,,,,,,12.252253,,,,,,4.9996624,,,,
,46590412.525,5.00117705,-35126.751953125,3.86081303925153E-5,6.2835211936E-7,1,0.999253354069792,40.0298881530762,1.99488164489498,15.5500008817762,0.000423884542608623,2.6861980505983E-5,0.25,-4.37008561390753E-6,3.84315090556653E-5,-4.19796611813641E-6,5.0007758,5.0015783,-35156.58984375,-35096.9140625,53.3985155482941,18.7318949315539,1.7524606,0,0,0,4449,4.8745,-35126.751953125,,,,,,,,,,,,,,,,,13.003003,,,,,,5.00117705,,,,
,46590491.02,5.00205255,-39046.75390625,4.5007712654465E-5,8.02128615831004E-7,1,0.999253354069792,40.0298881530762,1.99489965309481,15.5500008817762,0.000491227657932966,4.82290331353311E-5,0.25,-3.53248982339158E-6,4.48033146449613E-5,-3.33144143676054E-6,5.0019665,5.0021386,-39074.1484375,-39019.359375,53.0248971161018,18.7357759803659,1.72646075,0,0,0,4449,4.87445,-39046.75390625,,,,,,,,,,,,,,,,,12.252253,,,,,,5.00205255,,,,
,46590569.775,5.000124,-42984.642578125,5.46734777610113E-5,8.13938690696711E-7,1,0.999253354069792,40.0298881530762,1.99488287456971,15.5500008817762,0.000597572959459025,5.43984404144803E-5,0.25,-4.69161353789242E-6,5.44365841469202E-5,-4.43576236403234E-6,4.9998007,5.0004473,-43007.16015625,-42962.125,53.2210858744287,18.7343124903906,1.72646075,0,0,0,4449,4.87395,-42984.642578125,,,,,,,,,,,,,,,,,12.252253,,,,,,5.000124,,,,
,46590648.095,4.99889065,-46897.703125,6.41193499760027E-5,8.20740409113734E-7,1,0.999253354069792,40.0298881530762,1.99487200352511,15.5500008817762,0.000699402548816258,7.24363198639987E-5,0.25,-4.71271037428503E-6,6.38498575720615E-5,-4.40536338403885E-6,4.9985528,4.9992285,-46925.2109375,-46870.1953125,52.8130757873902,18.7391691228053,1.72646075,0,0,0,4449,4.87285,-46897.703125,,,,,,,,,,,,,,,,,13.003003,,,,,,4.99889065,,,,
,46590727.76,5.0015092,-50880.064453125,7.68946796702145E-5,6.29455001918367E-7,1,0.999253354069792,40.0298881530762,1.99494467895411,15.5500008817762,0.000840696868160858,7.70827113953615E-5,0.25,-6.57625001588992E-6,7.65906004069778E-5,-6.19076685945859E-6,5.0014577,5.0015607,-50902.66796875,-50857.4609375,53.1992002758902,18.7383200305203,1.7613018,0,0,0,4449,4.87385,-50880.064453125,,,,,,,,,,,,,,,,,12.252253,,,,,,5.0015092,,,,
,46590808.345,4.9999263,-54904.845703125,9.07640517412934E-5,8.78665363418926E-7,1,0.999253354069792,40.0298881530762,1.99489932813873,15.5500008817762,0.000984517985572937,0.000135725098899278,0.25,-3.62592023606289E-6,9.04036466429002E-5,-3.17370106375266E-6,4.9999046,4.999948,-54929.83203125,-54879.859375,52.7020845376594,18.7372940084201,1.7437073,0,0,0,4449,4.87345,-54904.845703125,,,,,,,,,,,,,,,,,12.252253,,,,,,4.9999263,,,,
,46590886.665,4.9987743,-58820.484375,0.000102848150164011,9.04190866422633E-7,1,0.999253354069792,40.0298881530762,1.99482142371618,15.5500008817762,0.0011162505715832,0.000151151852876895,0.25,-4.3730711755115E-6,0.000102461190847193,-3.84365708859198E-6,4.9985552,4.9989934,-58848.0859375,-58792.8828125,53.1530841932556,18.7397360854906,1.7437073,0,0,0,4449,4.87525,-58820.484375,,,,,,,,,,,,,,,,,12.252253,,,,,,4.9987743,,,,
,46590966.615,4.99663615,-62816.455078125,0.000116568953070506,8.07300962580509E-7,1,0.999253354069792,40.0298881530762,1.99493258742353,15.5500008817762,0.00126285344267382,0.000186111393681602,0.25,-3.60573609065214E-6,0.000116147326555716,-2.99342370295953E-6,4.9956198,4.9976525,-62846.48046875,-62786.4296875,52.3784903306978,18.7367313741203,1.7437073,0,0,0,4449,4.8755,-62816.455078125,,,,,,,,,,,,,,,,,13.003003,,,,,,4.99663615,,,,
,46591044.16,4.9981189,-66691.22265625,0.000128463003733813,1.00163136640077E-6,1,0.999253354069792,40.0298881530762,1.99489735287619,15.5500008817762,0.00138728985276282,0.00023122859653075,0.25,-1.57096277878864E-6,0.000128011513990749,-8.87027919904419E-7,4.9978161,4.9984217,-66718.7265625,-66663.71875,53.2351551877748,18.7421995951974,1.7092142,0,0,0,4449,4.8773,-66691.22265625,,,,,,,,,,,,,,,,,13.003003,,,,,,4.9981189,,,,
,46591123.135,4.9963641,-70639.26171875,0.000142161099850035,1.02979252548417E-6,1,0.999253354069792,40.0298881530762,1.99483889989361,15.5500008817762,0.00154070635835175,0.000226875458753667,0.25,-4.45402140712708E-6,0.000141705455775435,-3.66871258366888E-6,4.9960098,4.9967184,-70661.6640625,-70616.859375,53.1859125910633,18.738529930845,1.7437073,0,0,0,4449,4.8787,-70639.26171875,,,,,,,,,,,,,,,,,13.378378,,,,,,4.9963641,,,,
,46591203.01,4.99782085,-74628.9375,0.000156421788044402,1.03067518918612E-6,1,0.999253354069792,40.0298881530762,1.99476556913059,15.5500008817762,0.00169299917874888,0.000263974988165882,0.25,-3.594828507945E-6,0.000155946609658369,-2.7155134703034E-6,4.9973054,4.9983363,-74653.875,-74604,53.7713523519672,18.7473474811057,1.7092142,0,0,0,4449,4.879,-74628.9375,,,,,,,,,,,,,,,,,12.252253,,,,,,4.99782085,,,,
,46591283.095,4.9955518,-78631.99609375,0.00017118975930239,1.1435508031852E-6,1,0.999253354069792,40.0298881530762,1.99484402700894,15.5500008817762,0.00185377061860653,0.00028639503627238,0.25,-4.19375310760965E-6,0.00017070809006596,-3.21071599628996E-6,4.9950757,4.9960279,-78657.0859375,-78606.90625,53.1507393076979,18.7406692144995,1.73504095,0,0,0,4449,4.8822,-78631.99609375,,,,,,,,,,,,,,,,,12.252253,,,,,,4.9955518,,,,
,46591363.025,4.98980045,-82629.8515625,0.000183942187283005,9.18405616392475E-7,1,0.999253354069792,40.0298881530762,1.99500644624963,15.5500008817762,0.00199339959712707,0.000302544575794118,0.25,-5.01575731086173E-6,0.000183467500796537,-3.93850641270398E-6,4.9893913,4.9902096,-82659.84375,-82599.859375,53.1452679080633,18.7429839667666,1.73521405,0,0,0,4449,4.89105,-82629.8515625,,,,,,,,,,,,,,,,,12.252253,,,,,,4.98980045,,,,
,46591440.98,4.9927819,-86523.12890625,0.000196693910935771,1.1744233673684E-6,1,0.999253354069792,40.0298881530762,1.994943389739,15.5500008817762,0.00212914114237877,0.000339376098306043,0.25,-3.91821868734737E-6,0.000196219606616878,-2.75144214227801E-6,4.9919806,4.9935832,-86553.0234375,-86493.234375,53.1499576791787,18.7428464559885,1.72646075,0,0,0,4449,4.8971,-86523.12890625,,,,,,,,,,,,,,,,,12.252253,,,,,,4.9927819,,,,
,46591533.165,4.9947283,-89667.11328125,0.000208364777156247,1.35012331793903E-6,1,0.999253354069792,40.0298881530762,1.99486658414456,15.5500008817762,0.00225556255193595,0.000360771857550982,0.25,-4.05381338332913E-6,0.000207897428396442,-2.80329552021639E-6,4.9945149,4.9949417,-89696.734375,-89637.4921875,53.1343251087941,18.7428664312282,1.74379425,0,0,0,4449,4.8998,-89667.11328125,,,,,,,,,,,,,,,,,12.252253,,,,,,4.9947283,,,,
,46591610.235,4.99807905,-85820.5859375,0.000194570820232798,1.36315968456775E-6,1,0.999253354069792,40.0298881530762,1.9947999730946,15.5500008817762,0.00210517500971852,0.000339906668734198,0.25,-3.48042315060464E-6,0.000194091874621606,-2.3304841289259E-6,4.9974575,4.9987006,-85848.0234375,-85793.1484375,53.4993456272749,18.7431739361391,1.74379425,0,0,0,4449,4.89955,-85820.5859375,,,,,,,,,,,,,,,,,13.003003,,,,,,4.99807905,,,,
,46591687.915,5.00002935,-81935.1640625,0.000184185916682689,1.21361466782761E-6,1,0.999253354069792,40.0298881530762,1.99494151788104,15.5500008817762,0.00199653008017788,0.000299440380212587,0.25,-5.34208870318209E-6,0.000183705473103056,-4.26578717364391E-6,4.9997497,5.000309,-81960.1640625,-81910.1640625,53.0069196601595,18.7390648683872,1.7700551,0,0,0,4449,4.8985,-81935.1640625,,,,,,,,,,,,,,,,,13.378378,,,,,,5.00002935,,,,
,46591765.875,5.0021646,-78039.79296875,0.000168498604280613,1.09320603803235E-6,1,0.999253354069792,40.0298881530762,1.99496225556695,15.5500008817762,0.00182342128866188,0.000288860934749506,0.25,-3.47924202056209E-6,0.000168015443515763,-2.51638810508263E-6,5.0017433,5.0025859,-78062.171875,-78017.4140625,53.1335434802748,18.7413212815429,1.7092142,0,0,0,4449,4.89605,-78039.79296875,,,,,,,,,,,,,,,,,13.003003,,,,,,5.0021646,,,,
,46591844.955,5.00346445,-74089.45703125,0.00015190555350117,7.87412802681972E-7,1,0.999253354069792,40.0298881530762,1.99485216344394,15.5500008817762,0.00164740672333872,0.000238149954192884,0.25,-5.17753621598373E-6,0.000151449034761436,-4.32071745769793E-6,5.0031409,5.003788,-74114.234375,-74064.6796875,53.3172261822941,18.7400258968013,1.7613018,0,0,0,4449,4.89355,-74089.45703125,,,,,,,,,,,,,,,,,13.003003,,,,,,5.00346445,,,,
,46591925.86,5.0051143,-70044.5546875,0.000142987058333832,9.7720752154505E-7,1,0.999253354069792,40.0298881530762,1.99497148325355,15.5500008817762,0.00154844421823731,0.000235232392224162,0.25,-3.8245741809189E-6,0.000142520708452461,-3.03968827718339E-6,5.0043473,5.0058813,-70071.84375,-70017.265625,52.9834708045825,18.7387349535182,1.73521405,0,0,0,4449,4.88855,-70044.5546875,,,,,,,,,,,,,,,,,12.252253,,,,,,5.0051143,,,,
,46592005.88,5.00494125,-66046.8828125,0.000127103700119022,1.0252724845887E-6,1,0.999253354069792,40.0298881530762,1.99483564142812,15.5500008817762,0.0013801263381349,0.000186357727163341,0.25,-5.48736584737123E-6,0.000126673433603954,-4.79938351075671E-6,5.0045643,5.0053182,-66074.359375,-66019.40625,52.9694014912364,18.7399699546125,1.7092142,0,0,0,4449,4.88415,-66046.8828125,,,,,,,,,,,,,,,,,12.252253,,,,,,5.00494125,,,,
,46592085.53,5.0056343,-62066.283203125,0.000113272677833579,1.14602137753903E-6,1,0.999253354069792,40.0298881530762,1.99483624280172,15.5500008817762,0.00122830846176408,0.000173748885100447,0.25,-4.15812552710207E-6,0.00011286195505461,-3.56377339371573E-6,5.0054202,5.0058484,-62091.2734375,-62041.29296875,52.8521572133517,18.7386353627836,1.72646075,0,0,0,4449,4.8794,-62066.283203125,,,,,,,,,,,,,,,,,12.252253,,,,,,5.0056343,,,,
,46592165.42,5.0033114,-58073.33203125,0.000100753276927864,7.74553425311187E-7,1,0.999253354069792,40.0298881530762,1.9948448293181,15.5500008817762,0.0010955347755829,0.000136610814036103,0.25,-5.34472521707306E-6,0.000100375640537013,-4.82474612184342E-6,5.0032711,5.0033517,-58103.31640625,-58043.34765625,53.2836161559672,18.7394049763243,1.7524606,0,0,0,4449,4.878,-58073.33203125,,,,,,,,,,,,,,,,,12.252253,,,,,,5.0033114,,,,
,46592243.835,5.0028899,-54156.05078125,8.81943920471657E-5,9.44642974434583E-7,1,0.999253354069792,40.0298881530762,1.99484216461751,15.5500008817762,0.000958513272771558,0.000121079073875248,0.25,-4.52281603205558E-6,8.78457281515876E-5,-4.08189739917155E-6,5.0024877,5.0032921,-54185.95703125,-54126.14453125,53.0467827146402,18.7401811772304,1.7437073,0,0,0,4449,4.87625,-54156.05078125,,,,,,,,,,,,,,,,,13.003003,,,,,,5.0028899,,,,
,46592323.21,5.00279545,-50185.748046875,7.33661224105556E-5,7.31539023535892E-7,1,0.999253354069792,40.0298881530762,1.9949034181383,15.5500008817762,0.000800865119685436,8.03183556453043E-5,0.25,-5.64284756347838E-6,7.30705584053541E-5,-5.27989554629062E-6,5.0027122,5.0028787,-50213.421875,-50158.07421875,52.9365730934287,18.7359562271267,1.72646075,0,0,0,4449,4.87335,-50185.748046875,,,,,,,,,,,,,,,,,12.252253,,,,,,5.00279545,,,,
,46592401.455,5.00308635,-46278.041015625,6.21672613908016E-5,8.9267311977699E-7,1,0.999253354069792,40.0298881530762,1.99487490388693,15.5500008817762,0.000680022143720411,5.94003827750984E-5,0.25,-5.57321991628463E-6,6.19085966839161E-5,-5.27231518196612E-6,5.0026298,5.0035429,-46300.5546875,-46255.52734375,53.8166868060826,18.7395638796958,1.72646075,0,0,0,4449,4.86985,-46278.041015625,,,,,,,,,,,,,,,,,13.378378,,,,,,5.00308635,,,,
,46592478.795,5.00561595,-42409.87890625,5.04338875684806E-5,7.80980253907791E-7,1,0.999253354069792,40.0298881530762,1.99482025208464,15.5500008817762,0.000552797601550115,4.12338193131941E-5,0.25,-5.15723022717399E-6,5.02175487791527E-5,-4.9185843318707E-6,5.0054822,5.0057497,-42437.515625,-42382.2421875,53.4227460323903,18.7392105810219,1.7524606,0,0,0,4449,4.8664,-42409.87890625,,,,,,,,,,,,,,,,,13.003003,,,,,,5.00561595,,,,
,46592558.04,5.0054698,-38449.529296875,3.81773414029988E-5,6.54784516910699E-7,1,0.999253354069792,40.0298881530762,1.9947007734452,15.5500008817762,0.000418453881310215,3.06519245868505E-5,0.25,-3.9479067503174E-6,3.8006822573661E-5,-3.77377169878171E-6,5.0048547,5.0060849,-38474.50390625,-38424.5546875,53.496219113198,18.7433868817366,1.72646075,0,0,0,4449,4.86265,-38449.529296875,,,,,,,,,,,,,,,,,12.252253,,,,,,5.0054698,,,,
,46592636.995,5.00425455,-34504.369140625,2.73915850380398E-5,7.23462222567844E-7,1,0.999253354069792,40.0298881530762,1.99491549367702,15.5500008817762,0.00030430342341875,-1.02286990150205E-6,0.25,-4.96540225133333E-6,2.72727327053916E-5,-4.83467605173569E-6,5.0032215,5.0052876,-34526.97265625,-34481.765625,53.2249940170249,18.7433515176398,1.72646075,0,0,0,4449,4.8593,-34504.369140625,,,,,,,,,,,,,,,,,13.003003,,,,,,5.00425455,,,,
,46592716.17,5.0044203,-30546.486328125,1.54775305013215E-5,6.94769903560284E-7,1,0.999253354069792,40.0298881530762,1.99475440653754,15.5500008817762,0.000177025811013363,-2.94323517069105E-5,0.25,-5.48398899056525E-6,1.54173779323067E-5,-5.39895143436957E-6,5.0034299,5.0054107,-30568.857421875,-30524.115234375,53.2015451614479,18.7386662295124,1.7437073,0,0,0,4449,4.85875,-30546.486328125,,,,,,,,,,,,,,,,,13.003003,,,,,,5.0044203,,,,
,46592795.9,5.00257275,-26563.11328125,3.28586964953392E-6,4.94203367004628E-7,1,0.999253354069792,40.0298881530762,1.9947941211801,15.5500008817762,4.18451316347911E-5,-3.03182377104823E-5,0.25,-3.40064647090275E-6,3.28013924297712E-6,-3.37121651250581E-6,5.0020308,5.0031147,-26585.552734375,-26540.673828125,53.1163476528518,18.7406005269986,1.7092142,0,0,0,4449,4.8555,-26563.11328125,,,,,,,,,,,,,,,,,12.252253,,,,,,5.00257275,,,,
,46592874.43,5.00423695,-22638.3408203125,-6.87797447501611E-6,1.1972766145904E-6,1,0.999253354069792,40.0298881530762,1.9947804275781,15.5500008817762,-6.5013139492985E-5,-6.38182716251251E-5,0.25,-4.71323731975431E-6,-6.82523328235729E-6,-4.70994883964784E-6,5.0041771,5.0042968,-22658.23046875,-22618.451171875,52.2307625405632,18.7380023078905,1.72646075,0,0,0,4449,4.8538,-22638.3408203125,,,,,,,,,,,,,,,,,12.252253,,,,,,5.00423695,,,,
,46592952.28,5.0066135,-18747.3916015625,-1.61386471318921E-5,9.10120025339084E-7,1,0.999253354069792,40.0298881530762,1.99469349932126,15.5500008817762,-0.000164976052189445,-7.95027141766256E-5,0.25,-4.53455199655033E-6,-1.60352030471636E-5,-4.55859556703517E-6,5.0061898,5.0070372,-18769.736328125,-18725.046875,52.6622214831786,18.7434957487641,1.7092142,0,0,0,4449,4.8473,-18747.3916015625,,,,,,,,,,,,,,,,,12.252253,,,,,,5.0066135,,,,
,46593030.68,4.9996459,-14829.9331054687,-2.5269713699025E-5,8.83410081644846E-7,1,0.999253354069792,40.0298881530762,1.99470260080216,15.5500008817762,-0.000264932973885162,-8.69915279616206E-5,0.25,-3.62052345264365E-6,-2.51164945360978E-5,-3.67209910093561E-6,4.9989552,5.0003366,-14852.30078125,-14807.5654296875,53.1147843958133,18.7386178104194,1.72646075,0,0,0,4449,4.84775,-14829.9331054687,,,,,,,,,,,,,,,,,13.003003,,,,,,4.9996459,,,,
,46593110.125,5.0032525,-10858.90234375,-3.40451998790279E-5,5.86257258432034E-7,1,0.999253354069792,40.0298881530762,1.99474598593325,15.5500008817762,-0.00035883550182201,-0.000106353151642086,0.25,-3.87660051883649E-6,-3.38392446661388E-5,-3.94472787821464E-6,5.0026822,5.0038228,-10883.7939453125,-10834.0107421875,52.893583524871,18.7377720299127,1.7437073,0,0,0,4449,4.84435,-10858.90234375,,,,,,,,,,,,,,,,,12.252253,,,,,,5.0032525,,,,
,46593188.96,5.00620935,-6918.07104492188,-4.09318530439617E-5,5.07535720889782E-7,1,0.999253354069792,40.0298881530762,1.99467669649755,15.5500008817762,-0.000432194405065003,-0.000123241551941224,0.25,-4.23954129985806E-6,-4.06828755809642E-5,-4.31599077474113E-6,5.0061483,5.0062704,-6935.57470703125,-6900.5673828125,52.5254364923133,18.7377673894042,1.7437073,0,0,0,4449,4.83895,-6918.07104492188,,,,,,,,,,,,,,,,,12.252253,,,,,,5.00620935,,,,
,46593268.025,5.0096464,-2966.77429199219,-4.71737441647311E-5,3.40512678731093E-7,1,0.999253354069792,40.0298881530762,1.99447446637995,15.5500008817762,-0.000500939214386611,-0.000125499709075428,0.25,-3.35833066439746E-6,-4.68880039559295E-5,-3.4472506085145E-6,5.0084834,5.0108094,-2996.66870117188,-2936.8798828125,53.0022298890441,18.7428462888751,1.7437073,0,0,0,4449,4.832,-2966.77429199219,,,,,,,,,,,,,,,,,12.252253,,,,,,5.0096464,,,,
,46593347.665,5.00272895,1015.50881958008,-3.36448208409175E-5,2.87097601211303E-7,1,0.999253354069792,40.0298881530762,1.99467687280599,15.5500008817762,-0.000358865877793739,-8.06337082879355E-5,0.25,-1.57181003374487E-6,-3.34421594230334E-5,-1.63770956210129E-6,5.0027151,5.0027428,990.560974121094,1040.45666503906,52.4371124696402,18.7397435547157,1.7437073,0,0,0,4449,4.8298,1015.50881958008,,,,,,,,,,,,,,,,,13.003003,,,,,,5.00272895,,,,
,46593426.875,5.0068657,4971.9541015625,-3.61494487683989E-5,3.79495397160759E-7,1,0.999253354069792,40.0298881530762,1.99458030790451,15.5500008817762,-0.00038564678129277,-8.62762933757972E-5,0.25,-1.64980437427661E-6,-3.59336278481023E-5,-1.72638823013158E-6,5.0064077,5.0073237,4942.10107421875,5001.80712890625,52.9678382341979,18.7410534565656,1.7437073,0,0,0,4449,4.8239,4971.9541015625,,,,,,,,,,,,,,,,,13.003003,,,,,,5.0068657,,,,
,46593505.55,4.99697255,8902.9501953125,-4.1595123116357E-5,4.76629203130219E-7,1,0.999253354069792,40.0298881530762,1.99465607935159,15.5500008817762,-0.000445570597882682,-8.91762611536009E-5,0.25,-9.51234269459105E-7,-4.13519256134731E-5,-1.05231332162702E-6,4.9969406,4.9970045,8880.28515625,8925.615234375,53.1812228199479,18.7413509839227,1.72646075,0,0,0,4449,4.8308,8902.9501953125,,,,,,,,,,,,,,,,,13.003003,,,,,,4.99697255,,,,
,46593584.225,5.00185085,12836.5170898438,-4.56284720923024E-5,5.84598838847759E-7,1,0.999253354069792,40.0298881530762,1.99468147746391,15.5500008817762,-0.000489539792062422,-9.37709151125918E-5,0.25,-6.5716285456007E-7,-4.536646258422E-5,-7.7898521081319E-7,5.0012498,5.0024519,12814.1943359375,12858.83984375,53.455574430198,18.7386518872627,1.72646075,0,0,0,4449,4.8273,12836.5170898438,,,,,,,,,,,,,,,,,13.003003,,,,,,5.00185085,,,,
,46593663.47,5.00243235,16797.4072265625,-4.61983686819546E-5,6.62587522730087E-7,1,0.999253354069792,40.0298881530762,1.99472105590412,15.5500008817762,-0.000496358384309936,-9.12923825016353E-5,0.25,-3.15860245399744E-7,-4.5938498813742E-5,-4.50399586294138E-7,5.0023494,5.0025153,16777.1640625,16817.650390625,53.0061380316402,18.7417790042097,1.72646075,0,0,0,4449,4.8262,16797.4072265625,,,,,,,,,,,,,,,,,12.252253,,,,,,5.00243235,,,,
,46593742.815,5.0016322,20762.52734375,-4.22841517066923E-5,6.33712237850322E-7,1,0.999253354069792,40.0298881530762,1.99457601410037,15.5500008817762,-0.00045520713295633,-7.85623528916176E-5,0.25,1.84188589678411E-7,-4.20523362893791E-5,4.98326221165844E-8,5.0013332,5.0019312,20739.9765625,20785.078125,53.384446234948,18.741073607735,1.7437073,0,0,0,4449,4.8242,20762.52734375,,,,,,,,,,,,,,,,,13.003003,,,,,,5.0016322,,,,
,46593821.155,5.00076915,24678.3271484375,-3.49643651716375E-5,6.83379697368648E-7,1,0.999253354069792,40.0298881530762,1.99454431924702,15.5500008817762,-0.000376855797484534,-6.26582332863166E-5,0.25,3.74224910707387E-7,-3.4777580064816E-5,2.54881639343617E-7,5.0005355,5.0010028,24653.3203125,24703.333984375,52.9795626619864,18.7389868180278,1.73504095,0,0,0,4449,4.8234,24678.3271484375,,,,,,,,,,,,,,,,,13.003003,,,,,,5.00076915,,,,
,46593900.18,5.0021057,28628.72265625,-2.98393085130107E-5,6.73325612514246E-7,1,0.999253354069792,40.0298881530762,1.99459864376074,15.5500008817762,-0.000321409013180182,-5.49384603044641E-5,0.25,1.90132184876532E-7,-2.9683363305782E-5,8.29192814652634E-8,5.0017438,5.0024676,28601.275390625,28656.169921875,52.9060895811787,18.7370526220414,1.7007193,0,0,0,4449,4.8228,28628.72265625,,,,,,,,,,,,,,,,,12.252253,,,,,,5.0021057,,,,
,46593979.685,4.9940755,32601.8623046875,-3.15964478034697E-5,7.1996776531491E-7,1,0.999253354069792,40.0298881530762,1.99460511791474,15.5500008817762,-0.000338686430815814,-6.7742384335181E-5,0.25,-6.80708539302213E-7,-3.14324617234331E-5,-7.96122826683381E-7,4.993854,4.994297,32579.392578125,32624.33203125,52.7607066766017,18.7389439809872,1.7007193,0,0,0,4449,4.8252,32601.8623046875,,,,,,,,,,,,,,,,,12.252253,,,,,,4.9940755,,,,
,46594058.4,4.99681975,36534.630859375,-3.75228300212549E-5,7.81875968027563E-7,1,0.999253354069792,40.0298881530762,1.99460108365572,15.5500008817762,-0.000405046660599635,-6.48511506004363E-5,0.25,6.49497332566575E-7,-3.73392473854248E-5,4.97648942366601E-7,4.9963088,4.9973307,36507.3046875,36561.95703125,52.3886515014479,18.7404676753111,1.72646075,0,0,0,4449,4.82785,36534.630859375,,,,,,,,,,,,,,,,,12.252253,,,,,,4.99681975,,,,
,46594135.92,4.9921992,40410.587890625,-4.66262260808546E-5,5.14892727564742E-7,1,0.999253354069792,40.0298881530762,1.99470488359641,15.5500008817762,-0.000500648580053634,-9.61599201951554E-5,0.25,-6.29501364621966E-7,-4.63994894963347E-5,-8.20072452837946E-7,4.9914799,4.9929185,40380.4140625,40440.76171875,52.9975401179287,18.7358584130262,1.73521405,0,0,0,4449,4.8334,40410.587890625,,,,,,,,,,,,,,,,,12.252253,,,,,,4.9921992,,,,
,46594215.06,4.9915788,44365.52734375,-5.38733703301661E-5,7.51047033605331E-7,1,0.999253354069792,40.0298881530762,1.99461889997766,15.5500008817762,-0.00058122521231881,-9.60407374944336E-5,0.25,6.83736166381854E-7,-5.36263100979552E-5,4.46647134125375E-7,4.9914174,4.9917402,44343.1015625,44387.953125,52.3018907358132,18.7360922914324,1.7437073,0,0,0,4449,4.84295,44365.52734375,,,,,,,,,,,,,,,,,13.003003,,,,,,4.9915788,,,,
,46594293.935,4.9926567,48306.828125,-6.71538907566954E-5,7.54717105740865E-7,1,0.999253354069792,40.0298881530762,1.99480114965942,15.5500008817762,-0.000720566167808754,-0.000142883205901988,0.25,-1.28419924028724E-6,-6.6848026282645E-5,-1.58233725959849E-6,4.9926567,4.9926567,48301.80859375,48311.84765625,52.9201588945248,18.7357810903758,1.7437073,0,0,0,4449,4.8514,48306.828125,,,,,,,,,,,,,,,,,13.003003,,,,,,4.9926567,,,,
,46594373.12,4.99265765,52264.923828125,-7.95528173556096E-5,9.64204629269716E-7,1,0.999253354069792,40.0298881530762,1.99486510648579,15.5500008817762,-0.000858267093395545,-0.000144221306783897,0.25,8.21592763738025E-7,-7.92156071782779E-5,4.44004529299049E-7,4.9916072,4.9937081,52239.88671875,52289.9609375,53.2679835855826,18.7383613657546,1.7092142,0,0,0,4449,4.8571,52264.923828125,,,,,,,,,,,,,,,,,13.003003,,,,,,4.99265765,,,,
,46594451.965,4.98459005,56205.26171875,-9.1612188932912E-5,1.06697043519561E-6,1,0.999253354069792,40.0298881530762,1.99493651023025,15.5500008817762,-0.000983189980977355,-0.000196326607086209,0.25,-1.84281654168958E-6,-9.12275102993243E-5,-2.28149233737492E-6,4.9840989,4.9850812,56182.890625,56227.6328125,53.239063330371,18.7333327152173,1.7177944,0,0,0,4449,4.87365,56205.26171875,,,,,,,,,,,,,,,,,12.252253,,,,,,4.98459005,,,,
,46594531.89,4.9897945,60200.986328125,-0.000106491780642108,7.4782094602285E-7,1,0.999253354069792,40.0298881530762,1.99494842519178,15.5500008817762,-0.00114872546750341,-0.000196870054923666,0.25,7.88978031938114E-7,-0.000106079775232337,2.49824469246809E-7,4.988555,4.991034,60175.96484375,60226.0078125,52.4933897230248,18.7357274832401,1.7612139,0,0,0,4449,4.8784,60200.986328125,,,,,,,,,,,,,,,,,13.003003,,,,,,4.9897945,,,,
,46594610.665,4.9933646,64139.6171875,-0.000117620764487275,1.14169489053982E-6,1,0.999253354069792,40.0298881530762,1.99489617345941,15.5500008817762,-0.00126497827209469,-0.000239904537006249,0.25,-1.191813986858E-6,-0.00011717831393107,-1.79739753885895E-6,4.9922619,4.9944673,64114.5625,64164.671875,52.8685714122556,18.7368456967151,1.7524606,0,0,0,4449,4.88185,64139.6171875,,,,,,,,,,,,,,,,,13.003003,,,,,,4.9933646,,,,
,46594690.03,4.9957049,68105.54296875,-0.000131352622781743,1.25506888670064E-6,1,0.999253354069792,40.0298881530762,1.99486572943042,15.5500008817762,-0.00140981898134027,-0.000285293690249044,0.25,-2.92028873848161E-6,-0.000130876485743299,-3.61025447424685E-6,4.9950438,4.996366,68078.15625,68132.9296875,53.2460979870441,18.7317516719061,1.7437073,0,0,0,4449,4.8848,68105.54296875,,,,,,,,,,,,,,,,,12.252253,,,,,,4.9957049,,,,
,46594769.665,4.9970427,72085.9375,-0.000145929228746328,1.13822070621759E-6,1,0.999253354069792,40.0298881530762,1.99475390064388,15.5500008817762,-0.0015692925104587,-0.000301498290978022,0.25,-1.78607743926037E-6,-0.000145438011110877,-2.57793383516649E-6,4.9970427,4.9970427,72081.09375,72090.78125,52.4543082970632,18.7344661139298,1.7612139,0,0,0,4449,4.88445,72085.9375,,,,,,,,,,,,,,,,,13.003003,,,,,,4.9970427,,,,
,46594850.375,4.98737575,76121.52734375,-0.000160405403572359,1.09322417949047E-6,1,0.999253354069792,40.0298881530762,1.99487282353524,15.5500008817762,-0.0017268954864212,-0.000323338305912376,0.25,-1.18604612009626E-6,-0.000159903717874623,-2.0798619207207E-6,4.9872952,4.9874563,76094,76149.0546875,52.9764361479095,18.7372774534943,1.74379425,0,0,0,4449,4.8991,76121.52734375,,,,,,,,,,,,,,,,,13.003003,,,,,,4.98737575,,,,
,46594930.585,4.9942765,80129.3828125,-0.000173695806443044,1.21434484429418E-6,1,0.999253354069792,40.0298881530762,1.99494469958765,15.5500008817762,-0.00186781935394037,-0.000364807069164583,0.25,-2.61723491689285E-6,-0.000173181916855711,-3.60204318977499E-6,4.9941201,4.9944329,80106.765625,80152,53.2296837881402,18.7340049291602,1.7263746,0,0,0,4449,4.9009,80129.3828125,,,,,,,,,,,,,,,,,12.252253,,,,,,4.9942765,,,,
,46595010.43,4.99690175,84117.58984375,-0.000184840748629027,1.16940399657191E-6,1,0.999253354069792,40.0298881530762,1.99495166725991,15.5500008817762,-0.0019920192493458,-0.000366487042910258,0.25,-7.42926116670797E-7,-0.000184345074452457,-1.81690431188815E-6,4.9968486,4.9969549,84095.15625,84140.0234375,52.8396511570441,18.7324096158714,1.74379425,0,0,0,4449,4.90365,84117.58984375,,,,,,,,,,,,,,,,,13.003003,,,,,,4.99690175,,,,
,46595086.14,4.9940078,87903.09375,-0.000202618944418716,1.1865895459843E-6,1,0.999253354069792,40.0298881530762,1.99491605630029,15.5500008817762,-0.00218521572736221,-0.000395191478863155,0.25,-1.81815686068533E-7,-0.00020212062944414,-1.37982173343378E-6,4.9938259,4.9941897,87878.046875,87928.140625,53.371158550121,18.7367279199704,1.74379425,0,0,0,4449,4.9054,87903.09375,,,,,,,,,,,,,,,,,13.003003,,,,,,4.9940078,,,,
,46595129.335,4.99527645,89999.5859375,-0.000208696015970503,1.19726902729452E-6,1,0.999253354069792,40.0298881530762,1.995060025461,15.5500008817762,-0.00225302231164218,-0.000396799251822202,0.25,7.79200202962915E-7,-0.000208212136313025,-4.67118252565574E-7,4.9949088,4.9956441,89999.578125,89999.59375,52.9365730934287,18.7344650845749,1.74379425,0,0,0,4417,4.908,89999.5859375,,,,,,,,,,,,,,,,,13.003003,,,,,,4.99527645,,,,