File: data/monolayers/nanoparticles/Ol_CoFe_C/vsm/Backup/rawdata/DD172_6_HYST_10K.DAT
[Header]
; VSM Data File (default extension .dat)
; Copyright (c) 2003-2013, Quantum Design, Inc. All rights reserved.
TITLE,
FILEOPENTIME,26760202.75,11/07/2018,1:23 am
BYAPP,VSM,2.0,2.0
INFO,PPMS VSM Option Release 1.4.10 Build 1,APPNAME
INFO,Quantum Design Linear Motor Servo Controller,MOTOR_MODULE_NAME
INFO,3101-100 M1,MOTOR_HW_VERSION
INFO,MMC1014,MOTOR_SERIAL_NUMBER
INFO,SRV No X-over 01.03.11,MOTOR_SOFTWARE_VERSION
INFO,Quantum Design VSM Detection Module,VSM_MODULE_NAME
INFO,3101-150 F0,VSM_HW_VERSION
INFO,VSM707,VSM_SERIAL_NUMBER
INFO,VSM No X-over 01.02.05 May 20 2008 13:51:47,VSM_SOFTWARE_VERSION
INFO,704,PREAMP_SERIAL_NUMBER
INFO,822,COIL_SERIAL_NUMBER
INFO,0,MOMENT_UNITS
INFO,CoFe2O4 DD67,SAMPLE_MATERIAL
INFO,Colloidal Crystal,SAMPLE_COMMENT
INFO,31.86,SAMPLE_MASS
INFO,,SAMPLE_VOLUME
INFO,,SAMPLE_MOLECULAR_WEIGHT
INFO,,SAMPLE_SIZE
INFO,,SAMPLE_SHAPE
DATATYPE,COMMENT,1
DATATYPE,TIME,2
STARTUPAXIS,X,2
STARTUPAXIS,Y1,5
[Data]
Comment,Time Stamp (sec),Temperature (K),Magnetic Field (Oe),Moment (emu),M. Std. Err. (emu),Transport Action,Averaging Time (sec),Frequency (Hz),Peak Amplitude (mm),Center Position (mm),Coil Signal' (mV),Coil Signal" (mV),Range (mV),M. Quad. Signal (emu),M. Raw' (emu),M. Raw" (emu),Min. Temperature (K),Max. Temperature (K),Min. Field (Oe),Max. Field (Oe),Mass (grams),Motor Lag (deg),Pressure (Torr),VSM Status (code),Motor Status (code),Measure Status (code),Measure Count,PPMS Status (code),System Temp. (K),System Field (Oe),Sample Position (deg),Bridge 1 Resistance (ohms),Bridge 1 Excitation (에),Bridge 2 Resistance (ohms),Bridge 2 Excitation (에),Bridge 3 Resistance (ohms),Bridge 3 Excitation (에),Bridge 4 Resistance (ohms),Bridge 4 Excitation (에),Signal 1 Vin (V),Signal 2 Vin (V),Digital Inputs (code),Drive 1 Iout (mA),Drive 1 Ipower (W),Drive 2 Iout (mA),Drive 2 Ipower (W),Pressure (),Map 20 (),Map 21 (),Map 22 (),Map 23 (),Map 24 (),Map 25 (),Map 26 (),Map 27 (),Map 28 (),Map 29 ()
sample offset = 36.23 mm,26760244.515,10.0018082,-0.411041870713234,-2.12972037090334E-5,3.76049742551101E-7,1,0.999253354069792,40.0298881530762,1.99825222151781,19.1099997609854,-0.000238230206100471,-4.92125615802875E-5,0.25,-5.95817595152582E-7,-2.11719884001466E-5,-6.95046003252771E-7,10.0018082,10.0018082,-0.441489428281784,-0.380594313144684,55.4659229816597,20.5463758613572,13.038077,0,0,0,40,4417,10.0018,-0.411041870713234,,,,,,,,,,,,,0,,,,0,,,,,,10.0018082,,,,
,26760467.625,10.0051346,5041.0126953125,0.000276858370510332,3.72946814677547E-7,1,0.999253354069792,40.0298881530762,1.99703721301658,19.1099997609854,0.00310912938523292,0.000565660370634939,0.25,1.08382847930704E-6,0.000275339700859888,2.4983367890729E-6,10.0051346,10.0051346,5035.89208984375,5046.13330078125,56.3749569495252,20.5780833137117,13.038077,0,0,0,40,4449,9.99735,5041.0126953125,,,,,,,,,,,,,0,,,,0.0049,,,,,,10.0051346,,,,
,26760669.58,10.0046949,10088.1015625,0.000603954440511098,3.60178215242057E-7,1,0.999253354069792,40.0298881530762,1.99752617903018,19.1099997609854,0.00678544757486896,0.0012411672467919,0.25,2.71417542000437E-6,0.000600866968725996,6.02243197376354E-6,10.0046949,10.0046949,10083.244140625,10092.958984375,56.6641595016406,20.5762546004786,12.658426,0,0,0,40,4449,9.9868,10088.1015625,,,,,,,,,,,,,0,,,,0.00245,,,,,,10.0046949,,,,
,26760862.225,10.0031471,14901.8393554687,0.000955526882094822,4.07343410003327E-7,1,0.999253354069792,40.0298881530762,1.99757602520665,19.1099997609854,0.0107400575816237,0.00196473285917186,0.25,3.9779554589618E-6,0.000951037141016108,9.54963371318539E-6,10.0031471,10.0031471,14898.056640625,14905.6220703125,56.3780834636021,20.5745856972479,13.038077,0,0,0,40,4449,9.97865,14901.8393554687,,,,,,,,,,,,,0,,,,-0.00245,,,,,,10.0031471,,,,
,26761043.105,10.0019884,19420.4658203125,0.00133189799891359,4.73451738198359E-7,1,0.999253354069792,40.0298881530762,1.99743073383396,19.1099997609854,0.0149742962631878,0.00274780594506288,0.25,5.86502064753154E-6,0.00132619868283182,1.40436645217784E-5,10.0019884,10.0019884,19415.541015625,19425.390625,56.6219515616021,20.5753538688167,13.038077,0,0,0,40,4449,9.97795,19420.4658203125,,,,,,,,,,,,,0,,,,-0.00245,,,,,,10.0019884,,,,
,26761222.465,10.0001841,23904.7236328125,0.00174881155063764,5.02692513458103E-7,1,0.999253354069792,40.0298881530762,1.9972773048229,19.1099997609854,0.019668610043633,0.00361098180754943,0.25,7.36770888382543E-6,0.00174210444512212,1.85988756644502E-5,10.0001841,10.0001841,23900.923828125,23908.5234375,56.8705094307176,20.5780106205099,13.038077,0,0,0,40,4449,9.9757,23904.7236328125,,,,,,,,,,,,,0,,,,0.0049,,,,,,10.0001841,,,,
,26761405.74,9.9984388,28483.3984375,0.00221517014801418,6.27937233446918E-7,1,0.999253354069792,40.0298881530762,1.99689214420063,19.1099997609854,0.0249198444162324,0.00458100472904179,0.25,9.29212669370524E-6,0.00220771551682383,2.4079161927521E-5,9.9984388,9.9984388,28480.75,28486.046875,56.8853603725829,20.5875763082025,13.038077,0,0,0,40,4449,9.97565,28483.3984375,,,,,,,,,,,,,0,,,,0.00245,,,,,,9.9984388,,,,
,26761600.865,9.99842265,33361.197265625,0.00272106269166461,8.0313942031989E-7,1,0.999253354069792,40.0298881530762,1.9971685605196,19.1099997609854,0.0306280065058948,0.00564627341732062,0.25,1.21739178959703E-5,0.00271329457815113,3.09593765275709E-5,9.9984179,9.9984274,33358.5078125,33363.88671875,57.0002597649099,20.5814449605779,12.658426,0,0,0,40,4449,9.97825,33361.197265625,,,,,,,,,,,,,0,,,,0,,,,,,9.99842265,,,,
,26761797.6,9.9983587,38275.611328125,0.00320664526605412,9.18244163311648E-7,1,0.999253354069792,40.0298881530762,1.99719055592571,19.1099997609854,0.0361113047967826,0.00666657300806945,0.25,1.45741258104319E-5,0.00319915916493871,3.73132561399145E-5,9.9983587,9.9983587,38270.97265625,38280.25,56.9682129956214,20.5822984543995,13.038077,0,0,0,40,4449,9.98055,38275.611328125,,,,,,,,,,,,,0,,,,-0.0049,,,,,,9.9983587,,,,
,26761993.765,9.9989014,43178.775390625,0.00364463726597677,7.34231829179502E-7,1,0.999253354069792,40.0298881530762,1.99719157984443,19.1099997609854,0.0410643374992059,0.00758501328314746,0.25,1.64064900520314E-5,0.00363801463704883,4.27790163706149E-5,9.9989014,9.9989014,43173.65625,43183.89453125,57.088583787583,20.580382354729,12.658426,0,0,0,40,4449,9.9843,43178.775390625,,,,,,,,,,,,,0,,,,-0.0049,,,,,,9.9989014,,,,
,26762190.075,9.9978561,48084.490234375,0.00402946302976371,7.24579168587465E-7,1,0.999253354069792,40.0298881530762,1.99684891480341,19.1099997609854,0.0454121367827645,0.0084099220859607,0.25,1.96154868374529E-5,0.00402418174735738,4.91902061292958E-5,9.9978561,9.9978561,48080.8046875,48088.17578125,56.5969394489868,20.5842349742732,13.038077,0,0,0,40,4449,9.9884,48084.490234375,,,,,,,,,,,,,0,,,,0,,,,,,9.9978561,,,,
,26762386.845,9.997345,53001.91015625,0.00436168513916391,9.65892838849255E-7,1,0.999253354069792,40.0298881530762,1.99634713768202,19.1099997609854,0.0491693144692216,0.00910381202834731,0.25,2.08045150647288E-5,0.00435813982501092,5.31090483023551E-5,9.997345,9.997345,52998.32421875,53005.49609375,56.7884384361983,20.5971397683529,13.038077,0,0,0,40,4449,9.99245,53001.91015625,,,,,,,,,,,,,0,,,,0,,,,,,9.997345,,,,
,26762584.53,9.9979401,57943.27734375,0.00464625292021475,6.71488237146374E-7,1,0.999253354069792,40.0298881530762,1.99627405717629,19.1099997609854,0.0524006684145754,0.00970238447999826,0.25,2.20623281142859E-5,0.00464471847444583,5.66253291076668E-5,9.9979401,9.9979401,57938.3125,57948.2421875,56.7728058658137,20.5921804645788,12.278775,0,0,0,40,4449,9.996,57943.27734375,,,,,,,,,,,,,0,,,,0,,,,,,9.9979401,,,,
,26762779.135,9.9978838,62805.107421875,0.00488910207425744,9.19604893656461E-7,1,0.999253354069792,40.0298881530762,1.99635132668923,19.1099997609854,0.0551663380563019,0.0102164027668439,0.25,2.33991562802714E-5,0.00488971139375003,5.97778323668389E-5,9.9978838,9.9978838,62801.5546875,62808.66015625,56.3679222928521,20.5967108138581,12.658426,0,0,0,40,4449,10.00035,62805.107421875,,,,,,,,,,,,,0,,,,0,,,,,,9.9978838,,,,
,26762978.275,9.9970112,67781.546875,0.00510406604100735,9.50542400970365E-7,1,0.999253354069792,40.0298881530762,1.99655783586429,19.1099997609854,0.0576208211288994,0.0106841970141193,0.25,2.57173619665877E-5,0.00510695848264173,6.35685732663163E-5,9.9970112,9.9970112,67776.546875,67786.546875,57.1128142716791,20.5892468338325,12.658426,0,0,0,40,4449,10.0051,67781.546875,,,,,,,,,,,,,0,,,,-0.00245,,,,,,9.9970112,,,,
,26763179.435,9.9991474,72809.0625,0.00529448063407647,9.6237605393375E-7,1,0.999253354069792,40.0298881530762,1.99629317298511,19.1099997609854,0.0597898937809437,0.011076868033343,0.25,2.61480790546654E-5,0.00529973371128612,6.51518547006739E-5,9.9991474,9.9991474,72801.140625,72816.984375,56.9588334533906,20.5906055536371,12.658426,0,0,0,40,4449,10.00895,72809.0625,,,,,,,,,,,,,0,,,,0.00245,,,,,,9.9991474,,,,
,26763382.32,9.9973855,77880.49609375,0.00546841470500158,1.25076855832966E-6,1,0.999253354069792,40.0298881530762,1.99625252857257,19.1099997609854,0.0617757134339423,0.0114566383962851,0.25,2.84308244473101E-5,0.00547603773488432,6.83367300763108E-5,9.9969692,9.9978018,77876.3828125,77884.609375,56.9002113144483,20.5918588868377,12.658426,0,0,0,40,4449,10.01435,77880.49609375,,,,,,,,,,,,,0,,,,-0.0049,,,,,,9.9973855,,,,
,26763586.705,9.9975233,82988.57421875,0.0056211308483178,8.95484107778015E-7,1,0.999253354069792,40.0298881530762,1.99555147161458,19.1099997609854,0.0635060831388715,0.0117643253930175,0.25,2.86092397915781E-5,0.00563111599971796,6.91385776085686E-5,9.9975233,9.9975233,82987.4609375,82989.6875,56.8408075469868,20.6017910694001,11.899124,0,0,0,40,4449,10.01855,82988.57421875,,,,,,,,,,,,,0,,,,0,,,,,,9.9975233,,,,
,26763778.785,9.9972668,87789.3203125,0.00575263758335484,1.07404384260446E-6,1,0.999253354069792,40.0298881530762,1.99603338616446,19.1099997609854,0.0650277511491656,0.0120508147940324,0.25,3.02390360347948E-5,0.00576478254301681,7.11744462281778E-5,9.9972668,9.9972668,87782.78125,87795.859375,56.7345060683714,20.5918992643725,12.278775,0,0,0,40,4449,10.0221,87789.3203125,,,,,,,,,,,,,0,,,,-0.00245,,,,,,9.9972668,,,,
,26763987.775,9.9991035,87525.3671875,0.00575731323296401,1.14124654243885E-6,1,0.999253354069792,40.0298881530762,1.99615628707747,19.1099997609854,0.0650800906682122,0.01207876590382,0.25,3.17918940228134E-5,0.00576935402108121,7.27953408901416E-5,9.9991035,9.9991035,87519.34375,87531.390625,56.6454004171791,20.5929022524618,12.278775,0,0,0,40,4449,10.0259,87525.3671875,,,,,,,,,,,,,0,,,,-0.00245,,,,,,9.9991035,,,,
,26764181.21,10.0009718,82690.67578125,0.0056464678513041,9.26271886396651E-7,1,0.999253354069792,40.0298881530762,1.99637002626786,19.1099997609854,0.0638143301671932,0.0118306580332822,0.25,2.94953988775723E-5,0.00565637075080026,7.02398016982526E-5,10.0009718,10.0009718,82685.6796875,82695.671875,57.0385595623522,20.5917486619693,12.658426,0,0,0,40,4449,10.0227,82690.67578125,,,,,,,,,,,,,0,,,,0,,,,,,10.0009718,,,,
,26764384.75,10.0018826,77603.5703125,0.00552446634492795,8.2614339636606E-7,1,0.999253354069792,40.0298881530762,1.99586215571895,19.1099997609854,0.0623982693114267,0.0115587181508866,0.25,2.75522301179119E-5,0.00553205776500317,6.78890988124561E-5,10.0018826,10.0018826,77602.25,77604.890625,56.8150138058522,20.5934792480471,12.658426,0,0,0,40,4449,10.02105,77603.5703125,,,,,,,,,,,,,0,,,,0,,,,,,10.0018826,,,,
,26764590.605,10.0025635,72457.734375,0.00539023922241683,7.76737356429413E-7,1,0.999253354069792,40.0298881530762,1.99613557571338,19.1099997609854,0.0608639116844681,0.0112817509732191,0.25,2.71027048504804E-5,0.00539542800013535,6.68345910061959E-5,10.0025635,10.0025635,72453.859375,72461.609375,56.8947399148137,20.5916799679713,11.899124,0,0,0,40,4449,10.0156,72457.734375,,,,,,,,,,,,,0,,,,-0.00245,,,,,,10.0025635,,,,
,26764795.44,10.002594,67338.83203125,0.00524711809563902,9.71732540547445E-7,1,0.999253354069792,40.0298881530762,1.99628020718809,19.1099997609854,0.0592284645037006,0.0109659862217644,0.25,2.50222511500906E-5,0.00524989973441065,6.39504200463256E-5,10.002594,10.002594,67336.4765625,67341.1875,56.7431039820829,20.5936035577762,12.278775,0,0,0,40,4449,10.01145,67338.83203125,,,,,,,,,,,,,0,,,,-0.0049,,,,,,10.002594,,,,
,26765002.265,10.0017419,62169.533203125,0.00509395498516236,1.17751369142673E-6,1,0.999253354069792,40.0298881530762,1.99633400427613,19.1099997609854,0.0574764733957424,0.0106298973839408,0.25,2.31416431170249E-5,0.00509430188695125,6.10511499213321E-5,10.001523,10.0019608,62163.1875,62175.87890625,56.3882446343521,20.5940650546438,11.899124,0,0,0,40,4449,10.00975,62169.533203125,,,,,,,,,,,,,0,,,,0.00245,,,,,,10.0017419,,,,
,26765208.21,10.0021887,57021.86328125,0.00492589578306247,9.99254465846675E-7,1,0.999253354069792,40.0298881530762,1.99664559817861,19.1099997609854,0.0555624873646427,0.0102703586995668,0.25,2.19058108864246E-5,0.00492384398686317,5.85318928517019E-5,10.0021887,10.0021887,57018.16015625,57025.56640625,57.2996234877753,20.5852988469159,11.899124,0,0,0,40,4449,10.00545,57021.86328125,,,,,,,,,,,,,0,,,,0.00245,,,,,,10.0021887,,,,
,26765410.575,10.00197505,51965.96875,0.00474814111660982,7.82749219392133E-7,1,0.999253354069792,40.0298881530762,1.99672091407223,19.1099997609854,0.0535310702792048,0.00990443494951174,0.25,2.20970279670154E-5,0.00474379464459492,5.72117340655408E-5,10.0019703,10.0019798,51961.1015625,51970.8359375,56.9611783389483,20.5917039528749,12.278775,0,0,0,40,4449,10.00245,51965.96875,,,,,,,,,,,,,0,,,,0.0049,,,,,,10.00197505,,,,
,26765614.84,10.0019913,46861.291015625,0.00455241643887382,7.83540616869533E-7,1,0.999253354069792,40.0298881530762,1.99670857915109,19.1099997609854,0.0512954934179399,0.00950189999482021,0.25,2.24648610946094E-5,0.00454587445407947,5.57756770582249E-5,10.0019913,10.0019913,46856.43359375,46866.1484375,56.6110087623329,20.5938449277888,12.658426,0,0,0,40,4449,9.99975,46861.291015625,,,,,,,,,,,,,0,,,,0,,,,,,10.0019913,,,,
,26765811.645,10.00145005,41943.369140625,0.00434757228333854,8.05487894450152E-7,1,0.999253354069792,40.0298881530762,1.99677178078481,19.1099997609854,0.0489654418836334,0.00905993496215334,0.25,2.10369716494681E-5,0.00433909773430778,5.23517362867151E-5,10.0013857,10.0015144,41938.4296875,41948.30859375,56.9447641400445,20.5952189435386,11.899124,0,0,0,40,4449,9.99555,41943.369140625,,,,,,,,,,,,,0,,,,-0.00245,,,,,,10.00145005,,,,
,26766006.025,10.0007658,37086.33984375,0.00412275105998664,7.6674375582244E-7,1,0.999253354069792,40.0298881530762,1.99682219484313,19.1099997609854,0.0464136062306192,0.00857009958392292,0.25,1.90404842018571E-5,0.00411260444565949,4.81043171230165E-5,10.0007658,10.0007658,37083.71484375,37088.96484375,56.7102755842752,20.5932923057295,12.278775,0,0,0,40,4449,9.99435,37086.33984375,,,,,,,,,,,,,0,,,,0.0049,,,,,,10.0007658,,,,
,26766204.75,10.0014248,32120.43359375,0.00387059293133727,8.36167958781004E-7,1,0.999253354069792,40.0298881530762,1.99674402678233,19.1099997609854,0.0435508055018195,0.00803789392635191,0.25,1.83213029187299E-5,0.00385902899127828,4.48297570588605E-5,10.0014248,10.0014248,32119.36328125,32121.50390625,56.9205336559483,20.5914072748701,12.278775,0,0,0,40,4449,9.9936,32120.43359375,,,,,,,,,,,,,0,,,,0,,,,,,10.0014248,,,,
,26766404.205,10.0001507,27135.857421875,0.00358804738182384,6.6022250837236E-7,1,0.999253354069792,40.0298881530762,1.99683384244629,19.1099997609854,0.0403529966499346,0.00744344317606256,0.25,1.7482047034312E-5,0.00357545522163231,4.11711664720565E-5,10.0001507,10.0001507,27129.802734375,27141.912109375,57.1972301517561,20.5922367910646,12.278775,0,0,0,40,4449,9.9918,27135.857421875,,,,,,,,,,,,,0,,,,0,,,,,,10.0001507,,,,
,26766601.07,10.0004044,22216.556640625,0.00327839042233951,4.95014883756268E-7,1,0.999253354069792,40.0298881530762,1.99671953981228,19.1099997609854,0.0368521243112607,0.00678482333171892,0.25,1.5785618813767E-5,0.0032652502284711,3.64974314364082E-5,10.0004044,10.0004044,22211.458984375,22221.654296875,56.6063189912175,20.5981922661657,12.278775,0,0,0,40,4449,9.99165,22216.556640625,,,,,,,,,,,,,0,,,,0.0049,,,,,,10.0004044,,,,
,26766800.01,9.9994955,17245.9970703125,0.00293000327681029,6.21081224504603E-7,1,0.999253354069792,40.0298881530762,1.99659211613152,19.1099997609854,0.0329195335051747,0.00605194601677433,0.25,1.42880295608303E-5,0.00291685296017336,3.18446063612079E-5,9.9994955,9.9994955,17242.140625,17249.853515625,56.902556200006,20.59695174838,12.278775,0,0,0,40,4449,9.99215,17245.9970703125,,,,,,,,,,,,,0,,,,-0.0049,,,,,,9.9994955,,,,
,26766991.615,9.9999123,12457.2026367188,0.00255680239620514,5.28133337938251E-7,1,0.999253354069792,40.0298881530762,1.9965525061893,19.1099997609854,0.0287133845231165,0.00527947558461194,0.25,1.34009560366023E-5,0.00254422475830952,2.78442107543602E-5,9.9999123,9.9999123,12454.6142578125,12459.791015625,57.688092861833,20.5943840140332,11.519473,0,0,0,40,4449,9.9933,12457.2026367188,,,,,,,,,,,,,0,,,,-0.00245,,,,,,9.9999123,,,,
,26767184.745,9.9986134,7630.99096679688,0.00214478067529278,4.72403412423973E-7,1,0.999253354069792,40.0298881530762,1.9965114434975,19.1099997609854,0.024077869804713,0.00441854789912966,0.25,1.12621213356555E-5,0.00213339716642277,2.26104946941018E-5,9.9986134,9.9986134,7627.240234375,7634.74169921875,57.0604451608906,20.5999324153409,11.519473,0,0,0,40,4449,9.9939,7630.99096679688,,,,,,,,,,,,,0,,,,-0.00245,,,,,,9.9986134,,,,
,26767381.15,10.0003166,2722.11584472656,0.00168485097945943,4.10888510928033E-7,1,0.999253354069792,40.0298881530762,1.99672197888301,19.1099997609854,0.0189100814059831,0.00347060223971852,0.25,9.4678781825518E-6,0.00167534739869604,1.77901282995407E-5,10.0003166,10.0003166,2717.208984375,2727.02270507813,57.2480360055061,20.5940804878531,11.899124,0,0,0,40,4449,9.99435,2722.11584472656,,,,,,,,,,,,,0,,,,-0.0049,,,,,,10.0003166,,,,
,26767571,9.9990911,-2020.05926513672,0.00120294784476399,3.60008246502548E-7,1,0.999253354069792,40.0298881530762,1.99632881280957,19.1099997609854,0.0134983943484999,0.00247693689647228,0.25,6.77530527427456E-6,0.00119611463091221,1.26628225143709E-5,9.9990911,9.9990911,-2023.78637695313,-2016.33215332031,57.0713879601599,20.5996401033888,11.519473,0,0,0,40,4449,9.9933,-2020.05926513672,,,,,,,,,,,,,0,,,,0,,,,,,9.9990911,,,,
,26767765.86,9.9993496,-6890.458984375,0.000681107957061436,3.45601421575265E-7,1,0.999253354069792,40.0298881530762,1.99641104987866,19.1099997609854,0.00764576218292913,0.00140159633770862,0.25,3.48569678825941E-6,0.000677456147756375,7.05276243888263E-6,9.9993496,9.9993496,-6894.3203125,-6886.59765625,57.4403166212368,20.5975468865203,11.899124,0,0,0,40,4449,9.9954,-6890.458984375,,,,,,,,,,,,,0,,,,-0.00245,,,,,,9.9993496,,,,
,26767963.79,10.0004654,-11837.208984375,0.00011864870227399,4.36441031302151E-7,1,0.999253354069792,40.0298881530762,1.99651896021724,19.1099997609854,0.00133183536804613,0.000247894072238902,0.25,8.86700108899034E-7,0.000118057301966772,1.55022499641004E-6,10.0004654,10.0004654,-11839.7744140625,-11834.6435546875,56.9510171681983,20.5997965132838,12.278775,0,0,0,40,4449,9.99455,-11837.208984375,,,,,,,,,,,,,0,,,,-0.00245,,,,,,10.0004654,,,,
,26768160.725,10.0000362,-16757.8408203125,-0.000474590869269145,3.91467959482637E-7,1,0.999253354069792,40.0298881530762,1.99645804248469,19.1099997609854,-0.00533096820233838,-0.000983674374987303,0.25,-2.64239109337767E-6,-0.000472437325021881,-5.46865880835512E-6,10.0000362,10.0000362,-16758.892578125,-16756.7890625,57.4246840508522,20.6007752633166,12.278775,0,0,0,40,4449,9.9952,-16757.8408203125,,,,,,,,,,,,,0,,,,0.00245,,,,,,10.0000362,,,,
,26768354.29,10.0003252,-21595.841796875,-0.00108840968657403,5.89332947108778E-7,1,0.999253354069792,40.0298881530762,1.99622161777003,19.1099997609854,-0.0122305728437783,-0.00225455351317404,0.25,-5.52241037901721E-6,-0.00108397854920145,-1.23553736390943E-5,10.0003252,10.0003252,-21599.880859375,-21591.802734375,57.0158923352945,20.6046602491526,12.278775,0,0,0,40,4449,9.99445,-21595.841796875,,,,,,,,,,,,,0,,,,-0.0049,,,,,,10.0003252,,,,
,26768549.13,10.0012169,-26464.13671875,-0.00171571558448003,5.79043021977078E-7,1,0.999253354069792,40.0298881530762,1.99625768650278,19.1099997609854,-0.0192890569300582,-0.00355854605248733,0.25,-8.46571177528765E-6,-0.00170957486318026,-1.97302653014006E-5,10.0012169,10.0012169,-26469.056640625,-26459.216796875,57.5239508727946,20.6047206405429,11.899124,0,0,0,40,4449,9.9938,-26464.13671875,,,,,,,,,,,,,0,,,,-0.0049,,,,,,10.0012169,,,,
,26768732.25,9.9995422,-31040.4033203125,-0.00228847958311839,6.83385103932452E-7,1,0.999253354069792,40.0298881530762,1.99635336368052,19.1099997609854,-0.0257406518143675,-0.00475603951077745,0.25,-1.13946242881295E-5,-0.00228137834722735,-2.69526091622192E-5,9.9995422,9.9995422,-31046.45703125,-31034.349609375,57.5505262424484,20.6062980311412,12.278775,0,0,0,40,4449,9.9927,-31040.4033203125,,,,,,,,,,,,,0,,,,-0.00245,,,,,,9.9995422,,,,
,26768912.935,9.9986429,-35555.294921875,-0.00281217016152814,5.9570269262113E-7,1,0.999253354069792,40.0298881530762,1.99658029208281,19.1099997609854,-0.0316502718383423,-0.00584464501480828,0.25,-1.31897623623776E-5,-0.0028047911529595,-3.28533808585646E-5,9.9986429,9.9986429,-35559.0390625,-35551.55078125,57.1409528983714,20.6055964393116,12.278775,0,0,0,40,4449,9.9938,-35555.294921875,,,,,,,,,,,,,0,,,,0.00245,,,,,,9.9986429,,,,
,26769091.75,9.9988489,-40022.9453125,-0.00327237835324143,5.2440872375411E-7,1,0.999253354069792,40.0298881530762,1.99651439387329,19.1099997609854,-0.0368463515860508,-0.00680303983295473,0.25,-1.47611716017719E-5,-0.00326534466376849,-3.81510780464755E-5,9.9987116,9.9989862,-40026.51953125,-40019.37109375,57.268358347006,20.6053298037735,12.278775,0,0,0,40,4449,9.9956,-40022.9453125,,,,,,,,,,,,,0,,,,0,,,,,,9.9988489,,,,
,26769269.745,9.9988289,-44470.025390625,-0.00367269483202714,7.67182015413509E-7,1,0.999253354069792,40.0298881530762,1.99656037131767,19.1099997609854,-0.0413737065713763,-0.00764146817179662,0.25,-1.63646172145564E-5,-0.00366651836217135,-4.30551513092525E-5,9.9988289,9.9988289,-44473.875,-44466.17578125,56.7321611828137,20.603580142398,12.278775,0,0,0,40,4449,9.9968,-44470.025390625,,,,,,,,,,,,,0,,,,0.00245,,,,,,9.9988289,,,,
,26769446.315,9.9982357,-48882.9921875,-0.00401197239661909,7.50189800292866E-7,1,0.999253354069792,40.0298881530762,1.99656199488036,19.1099997609854,-0.0452141403235006,-0.00836396246639205,0.25,-1.86835925715726E-5,-0.00400704817071708,-4.81844004354609E-5,9.9981661,9.9983053,-48901.8515625,-48864.1328125,57.1276652135445,20.600777739155,11.899124,0,0,0,40,4449,9.99945,-48882.9921875,,,,,,,,,,,,,0,,,,0,,,,,,9.9982357,,,,
,26769631.08,9.9976444,-53501.7890625,-0.0043168298298739,7.0704520269945E-7,1,0.999253354069792,40.0298881530762,1.99676595890337,19.1099997609854,-0.0486776715467652,-0.00900218868686341,0.25,-1.96640043790279E-5,-0.00431354211885006,-5.16576956876839E-5,9.9976444,9.9976444,-53506.86328125,-53496.71484375,57.1175040427945,20.6037870355104,12.278775,0,0,0,40,4449,10.00375,-53501.7890625,,,,,,,,,,,,,0,,,,0.00245,,,,,,9.9976444,,,,
,26769815.21,9.9981966,-58101.53125,-0.00457984807397488,8.14791122063397E-7,1,0.999253354069792,40.0298881530762,1.99689556396674,19.1099997609854,-0.0516684663899709,-0.00956345919498793,0.25,-2.14582008605984E-5,-0.00457840700989225,-5.55296372736883E-5,9.9981966,9.9981966,-58103.94140625,-58099.12109375,57.2167708647368,20.6003427164457,12.278775,0,0,0,40,4449,10.0078,-58101.53125,,,,,,,,,,,,,0,,,,0,,,,,,9.9981966,,,,
,26769999.545,9.9978666,-62708.126953125,-0.00480609484748619,8.25398823580627E-7,1,0.999253354069792,40.0298881530762,1.99673912123164,19.1099997609854,-0.0542390850436902,-0.0100458935572589,0.25,-2.31040342461425E-5,-0.00480665039839711,-5.88661912764346E-5,9.9978666,9.9978666,-62711.96875,-62704.28515625,57.3293253715061,20.6018163071021,11.519473,0,0,0,40,4449,10.011,-62708.126953125,,,,,,,,,,,,,0,,,,0.00245,,,,,,9.9978666,,,,
,26770182.495,9.9982882,-67279.265625,-0.0050035419574094,9.10538509916639E-7,1,0.999253354069792,40.0298881530762,1.99678513557665,19.1099997609854,-0.0564915270603456,-0.0104640552315484,0.25,-2.42697938011338E-5,-0.00500616544063914,-6.13932141903328E-5,9.9982882,9.9982882,-67284.1328125,-67274.3984375,57.1346998702176,20.6025386852511,11.899124,0,0,0,40,4449,10.0147,-67279.265625,,,,,,,,,,,,,0,,,,-0.00245,,,,,,9.9982882,,,,
,26770367.74,9.9973726,-71908.5234375,-0.00518329565213497,1.00171499030398E-6,1,0.999253354069792,40.0298881530762,1.99685871853332,19.1099997609854,-0.058544657335303,-0.0108526238445653,0.25,-2.60929424961195E-5,-0.00518804969311728,-6.43317606578704E-5,9.9973726,9.9973726,-71913.5703125,-71903.4765625,57.3559007411599,20.6024685146256,11.899124,0,0,0,40,4449,10.0176,-71908.5234375,,,,,,,,,,,,,0,,,,0,,,,,,9.9973726,,,,
,26770565.61,9.9972296,-76852.73828125,-0.00535126644649599,1.19938689595081E-6,1,0.999253354069792,40.0298881530762,1.99684082206392,19.1099997609854,-0.0604658513074931,-0.0112059742088238,0.25,-2.7070653243832E-5,-0.00535830458583964,-6.62040289050239E-5,9.9972296,9.9972296,-76855.6875,-76849.7890625,57.698254032583,20.6036006893072,11.899124,0,0,0,40,4449,10.0232,-76852.73828125,,,,,,,,,,,,,0,,,,0,,,,,,9.9972296,,,,
,26770769.75,9.9968023,-81955.125,-0.0055056407214163,1.05449518019525E-6,1,0.999253354069792,40.0298881530762,1.9968962192737,19.1099997609854,-0.0622339750607075,-0.0115440262233003,0.25,-2.92260849237228E-5,-0.00551499813006937,-6.90286296453896E-5,9.9968023,9.9968023,-81957.734375,-81952.515625,57.3801312252561,20.6038143461707,11.519473,0,0,0,40,4449,10.02735,-81955.125,,,,,,,,,,,,,0,,,,0,,,,,,9.9968023,,,,
,26770964.795,9.9974222,-86826.7890625,-0.00564027088666241,1.05712623536448E-6,1,0.999253354069792,40.0298881530762,1.996941801264,19.1099997609854,-0.0637786460707508,-0.0118333380634328,0.25,-3.0729703808852E-5,-0.00565180062505114,-7.09795181523828E-5,9.9974222,9.9974222,-86829.40625,-86824.171875,57.3770047111791,20.6040370340372,11.899124,0,0,0,40,4449,10.0331,-86826.7890625,,,,,,,,,,,,,0,,,,-0.00245,,,,,,9.9974222,,,,
,26771175.11,9.9987679,-88435.36328125,-0.00569360077851063,1.08655092978577E-6,1,0.999253354069792,40.0298881530762,1.99676003314199,19.1099997609854,-0.064380472961211,-0.0119600642938484,0.25,-3.25051996111187E-5,-0.00570585097278926,-7.29491841569011E-5,9.9987679,9.9987679,-88439.03125,-88431.6953125,57.5755383550638,20.6036846862376,11.899124,0,0,0,40,4449,10.0362,-88435.36328125,,,,,,,,,,,,,0,,,,0.0049,,,,,,9.9987679,,,,
,26771369.4,10.001092,-83581.41015625,-0.00559205540558092,1.00845994616146E-6,1,0.999253354069792,40.0298881530762,1.99690584590523,19.1099997609854,-0.0632216250348466,-0.0117092381433737,0.25,-2.83214055051908E-5,-0.00560222848066132,-6.8578921953892E-5,10.001092,10.001092,-83587.234375,-83575.5859375,57.4911224749868,20.6023329094722,11.899124,0,0,0,40,4449,10.03365,-83581.41015625,,,,,,,,,,,,,0,,,,0.00245,,,,,,10.001092,,,,
,26771573.43,10.0014796,-78482.578125,-0.0054770836424931,1.04265592977726E-6,1,0.999253354069792,40.0298881530762,1.99702346813024,19.1099997609854,-0.0618993906329826,-0.0114790930350859,0.25,-2.84895048528445E-5,-0.0054849720947372,-6.84069302643638E-5,10.0014038,10.0015554,-78485.125,-78480.03125,56.7900016932368,20.5955142332538,12.278775,0,0,0,40,4449,10.0302,-78482.578125,,,,,,,,,,,,,0,,,,-0.0049,,,,,,10.0014796,,,,
,26771781.525,10.0020008,-73281.9609375,-0.00535293665870011,1.02407013468882E-6,1,0.999253354069792,40.0298881530762,1.99717335251929,19.1099997609854,-0.0604761962193366,-0.0112132325892035,0.25,-2.72586059510795E-5,-0.00535844882585622,-6.66634112819462E-5,10.0020008,10.0020008,-73285.5234375,-73278.3984375,57.1401712698522,20.5964082816197,12.278775,0,0,0,40,4449,10.0273,-73281.9609375,,,,,,,,,,,,,0,,,,0,,,,,,10.0020008,,,,
,26771966.35,10.0028324,-68664.140625,-0.00523285856416727,9.70779690176469E-7,1,0.999253354069792,40.0298881530762,1.99721826480489,19.1099997609854,-0.059098416098195,-0.0109554407154112,0.25,-2.61735257460729E-5,-0.00523622472919251,-6.49432415666677E-5,10.0028324,10.0028324,-68666.703125,-68661.578125,57.034651419756,20.598602018214,11.899124,0,0,0,40,4449,10.02135,-68664.140625,,,,,,,,,,,,,0,,,,0.00245,,,,,,10.0028324,,,,
,26772148.425,10.0027227,-64114.4921875,-0.00510818563816557,1.07878680544896E-6,1,0.999253354069792,40.0298881530762,1.99700334497181,19.1099997609854,-0.0576625166671203,-0.0106825946805568,0.25,-2.48116282859643E-5,-0.00510942749680855,-6.27996058480857E-5,10.0027227,10.0027227,-64122.14453125,-64106.83984375,57.078422616833,20.5976238458041,11.899124,0,0,0,40,4449,10.0171,-64114.4921875,,,,,,,,,,,,,0,,,,0,,,,,,10.0027227,,,,
,26772337.095,10.0027161,-59400.6328125,-0.00496916132703043,8.74899405657836E-7,1,0.999253354069792,40.0298881530762,1.99707904812479,19.1099997609854,-0.0560701320956627,-0.0103912936978043,0.25,-2.43988538262734E-5,-0.0049682027829602,-6.13812798854241E-5,10.0027161,10.0027161,-59404.33984375,-59396.92578125,57.0612267894099,20.5966851877363,11.899124,0,0,0,40,4449,10.0137,-59400.6328125,,,,,,,,,,,,,0,,,,0,,,,,,10.0027161,,,,
,26772520.105,10.0030584,-54827.13671875,-0.00482415112952318,8.5212761826188E-7,1,0.999253354069792,40.0298881530762,1.99719300971155,19.1099997609854,-0.054413594880832,-0.0100800798714264,0.25,-2.33970000453445E-5,-0.00482109709451249,-5.92028553270326E-5,10.0030584,10.0030584,-54832.0625,-54822.2109375,57.0330881627176,20.5960520456878,11.899124,0,0,0,40,4449,10.01015,-54827.13671875,,,,,,,,,,,,,0,,,,0.0049,,,,,,10.0030584,,,,
,26772705.895,10.0024738,-50185.001953125,-0.00466385469344594,8.83358650219341E-7,1,0.999253354069792,40.0298881530762,1.99704339335641,19.1099997609854,-0.0525780501520802,-0.00973621907257242,0.25,-2.24964398871433E-5,-0.00465874243591988,-5.68812111071613E-5,10.0024738,10.0024738,-50187.51171875,-50182.4921875,57.5927341824868,20.5972687478603,11.899124,0,0,0,40,4449,10.00525,-50185.001953125,,,,,,,,,,,,,0,,,,-0.0049,,,,,,10.0024738,,,,
,26772892.34,10.002389,-45525.298828125,-0.00449092430051026,8.02093738719753E-7,1,0.999253354069792,40.0298881530762,1.99700482554049,19.1099997609854,-0.0506034719152356,-0.00936962708191609,0.25,-2.19255083760214E-5,-0.00448385113733127,-5.4664764712472E-5,10.002389,10.002389,-45527.71875,-45522.87890625,57.2120810936214,20.5954229315936,12.278775,0,0,0,40,4449,10.0027,-45525.298828125,,,,,,,,,,,,,0,,,,0.0049,,,,,,10.002389,,,,
,26773076.86,10.002121,-40914.970703125,-0.00430167538987917,7.05762404736825E-7,1,0.999253354069792,40.0298881530762,1.99698455270195,19.1099997609854,-0.048448066788753,-0.00896483795811173,0.25,-2.09888963552428E-5,-0.00429282305011074,-5.18475306903727E-5,10.002121,10.002121,-40920.16015625,-40909.78125,57.146424298006,20.5957127556491,11.519473,0,0,0,40,4449,9.99865,-40914.970703125,,,,,,,,,,,,,0,,,,0,,,,,,10.002121,,,,
,26773255.385,10.0016918,-36453.83984375,-0.00410365610169008,7.66783819074942E-7,1,0.999253354069792,40.0298881530762,1.99706732521796,19.1099997609854,-0.046195904272529,-0.00855880779086045,0.25,-2.15269106064288E-5,-0.00409326315744227,-5.03549888230384E-5,10.0016918,10.0016918,-36455.07421875,-36452.60546875,57.1511140691214,20.5968499469875,12.278775,0,0,0,40,4449,9.9965,-36453.83984375,,,,,,,,,,,,,0,,,,-0.00245,,,,,,10.0016918,,,,
,26773436.715,10.0012703,-31923.341796875,-0.00387946793791033,5.94951007479314E-7,1,0.999253354069792,40.0298881530762,1.99702520048763,19.1099997609854,-0.0436549891992632,-0.00806074178552626,0.25,-1.87079778580777E-5,-0.00386779450877241,-4.52417292921972E-5,10.0012703,10.0012703,-31928.50390625,-31918.1796875,56.6110087623329,20.5950242292563,11.519473,0,0,0,40,4449,9.9955,-31923.341796875,,,,,,,,,,,,,0,,,,-0.00245,,,,,,10.0012703,,,,
,26773618.41,10.0007582,-27383.3486328125,-0.00363279444877846,5.24947440262622E-7,1,0.999253354069792,40.0298881530762,1.99675874761832,19.1099997609854,-0.0408546402602857,-0.00754282744127276,0.25,-1.82420648892438E-5,-0.0036201345584708,-4.22728825878201E-5,10.0007582,10.0007582,-27385.828125,-27380.869140625,57.2316218066022,20.5995910814982,11.899124,0,0,0,40,4449,9.9953,-27383.3486328125,,,,,,,,,,,,,0,,,,0.0049,,,,,,10.0007582,,,,
,26773801.395,10.0007296,-22809.38671875,-0.00335783716957515,7.34579634384325E-7,1,0.999253354069792,40.0298881530762,1.99691784608783,19.1099997609854,-0.0377482071204272,-0.0069659213137065,0.25,-1.7434581293674E-5,-0.00334456874364586,-3.8765589301533E-5,10.0007296,10.0007296,-22813.140625,-22805.6328125,56.9932251082368,20.5971244208368,11.519473,0,0,0,40,4449,9.9952,-22809.38671875,,,,,,,,,,,,,0,,,,-0.00245,,,,,,10.0007296,,,,
,26773981.62,9.999938,-18305.6142578125,-0.00305841922493857,7.11285915497407E-7,1,0.999253354069792,40.0298881530762,1.99688589946271,19.1099997609854,-0.0343676393463579,-0.00633532000934561,0.25,-1.61723403379888E-5,-0.00304498976073896,-3.47136984024933E-5,9.999938,9.999938,-18308.0703125,-18303.158203125,56.8908317722176,20.5989341694336,11.519473,0,0,0,40,4449,9.9944,-18305.6142578125,,,,,,,,,,,,,0,,,,-0.00245,,,,,,9.999938,,,,
,26774161.225,9.9998198,-13818.0390625,-0.00272586222760614,4.91461798623465E-7,1,0.999253354069792,40.0298881530762,1.99698778012735,19.1099997609854,-0.0306198221791733,-0.00564247057837214,0.25,-1.50921571561478E-5,-0.00271276990826905,-3.07567994236854E-5,9.9998198,9.9998198,-13820.482421875,-13815.595703125,57.0729512171983,20.5893077382701,11.899124,0,0,0,40,4449,9.9945,-13818.0390625,,,,,,,,,,,,,0,,,,0,,,,,,9.9998198,,,,
,26774340.57,9.9988184,-9336.61083984375,-0.00235989554144912,2.98896258597468E-7,1,0.999253354069792,40.0298881530762,1.99695024129258,19.1099997609854,-0.0264993412498232,-0.00487761835896146,0.25,-1.3361072551784E-5,-0.00234767486511338,-2.61417878245648E-5,9.9988184,9.9988184,-9337.7392578125,-9335.482421875,56.8376810329099,20.5925969684979,11.519473,0,0,0,40,4449,9.99575,-9336.61083984375,,,,,,,,,,,,,0,,,,-0.00245,,,,,,9.9988184,,,,
,26774514.365,9.9995003,-4991.72314453125,-0.00196542998594454,3.28243517698531E-7,1,0.999253354069792,40.0298881530762,1.99686790386708,19.1099997609854,-0.0220627245376793,-0.00405614661454178,0.25,-1.13352023780006E-5,-0.00195462369781778,-2.13500224218769E-5,9.9995003,9.9995003,-4994.19091796875,-4989.25537109375,56.8439340610637,20.5936417450433,11.519473,0,0,0,40,4449,9.9977,-4991.72314453125,,,,,,,,,,,,,0,,,,0.00245,,,,,,9.9995003,,,,
,26774692.51,10.0025263,-539.413818359375,-0.00152490076335367,3.88700172874042E-7,1,0.999253354069792,40.0298881530762,1.99707550426884,19.1099997609854,-0.0171152310532509,-0.0031445611818434,0.25,-9.05675032282258E-6,-0.00151612556613411,-1.63883081036268E-5,10.0025263,10.0025263,-543.356750488281,-535.470886230469,57.1010898438907,20.5937603261531,11.519473,0,0,0,40,4449,9.99585,-539.413818359375,,,,,,,,,,,,,0,,,,-0.00245,,,,,,10.0025263,,,,
,26774867.33,9.9992428,3825.77685546875,-0.00105087041576278,3.00677012962218E-7,1,0.999253354069792,40.0298881530762,1.99689538967613,19.1099997609854,-0.0117959341857147,-0.00216717105795768,0.25,-6.0203236114961E-6,-0.00104501283679174,-1.12888655109876E-5,9.9992428,9.9992428,3824.43481445313,3827.11889648438,56.9009929429675,20.5926968535588,11.519473,0,0,0,40,4449,9.9961,3825.77685546875,,,,,,,,,,,,,0,,,,-0.00245,,,,,,9.9992428,,,,
,26775044.92,9.9991255,8265.22265625,-0.000533804871915108,3.14981055923985E-7,1,0.999253354069792,40.0298881530762,1.99693009752343,19.1099997609854,-0.0059920100176227,-0.00111185006072697,0.25,-3.83356413455096E-6,-0.000530991772596914,-6.67774018033805E-6,9.9991255,9.9991255,8260.1552734375,8270.2900390625,57.2449094914291,20.593373159587,11.899124,0,0,0,40,4449,9.9971,8265.22265625,,,,,,,,,,,,,0,,,,-0.00245,,,,,,9.9991255,,,,
,26775220.215,10.0002565,12647.7763671875,1.27503537104972E-5,3.72532500639344E-7,1,0.999253354069792,40.0298881530762,1.99690232154271,19.1099997609854,0.000145061590004252,1.59872181722924E-5,0.25,-8.53541311893301E-7,1.26930746497756E-5,-7.7685206230246E-7,10.0002565,10.0002565,12646.51171875,12649.041015625,57.1214121853907,20.5903183853674,11.519473,0,0,0,40,4449,9.9963,12647.7763671875,,,,,,,,,,,,,0,,,,0.0049,,,,,,10.0002565,,,,
,26775399.455,10.0009909,17125.6904296875,0.000606169538218739,4.87120730604243E-7,1,0.999253354069792,40.0298881530762,1.99703679133027,19.1099997609854,0.00681393745670492,0.00124079939148251,0.25,1.93840126542446E-6,0.000603448262727273,5.57009570418551E-6,10.0009909,10.0009909,17124.509765625,17126.87109375,56.963523224506,20.5869819810724,11.899124,0,0,0,40,4449,9.99555,17125.6904296875,,,,,,,,,,,,,0,,,,-0.00245,,,,,,10.0009909,,,,
,26775573.645,10.0002775,21479.0390625,0.00120597800485194,6.10068733197658E-7,1,0.999253354069792,40.0298881530762,1.99680238089228,19.1099997609854,0.0135566944539504,0.00249099782050002,0.25,5.43847672030949E-6,0.00120105861454993,1.30034176043587E-5,10.0002775,10.0002775,21476.521484375,21481.556640625,57.0878021590637,20.5947355250279,11.899124,0,0,0,40,4449,9.99545,21479.0390625,,,,,,,,,,,,,0,,,,0.0049,,,,,,10.0002775,,,,
,26775751.325,10.0007353,25919.2451171875,0.00180950031051466,5.97259899506571E-7,1,0.999253354069792,40.0298881530762,1.99679416246095,19.1099997609854,0.0203495872613646,0.00374223576829941,0.25,7.9532663128836E-6,0.00180292911500872,1.97824690067047E-5,10.0007353,10.0007353,25916.638671875,25921.8515625,56.8540952318137,20.5906457250584,11.519473,0,0,0,40,4449,9.99475,25919.2451171875,,,,,,,,,,,,,0,,,,-0.0049,,,,,,10.0007353,,,,
,26775925.78,9.9998074,30278.6650390625,0.00236527851980256,6.87580046042849E-7,1,0.999253354069792,40.0298881530762,1.99681512360435,19.1099997609854,0.0266095149720147,0.0049090865536312,0.25,1.12167891504179E-5,0.0023577536264686,2.72129882442662E-5,9.9998074,9.9998074,30274.912109375,30282.41796875,56.8744175733137,20.5905348668521,11.519473,0,0,0,40,4449,9.99515,30278.6650390625,,,,,,,,,,,,,0,,,,0.0049,,,,,,9.9998074,,,,
,26776104.01,9.9999161,34732.775390625,0.00287567198328241,6.48072932613909E-7,1,0.999253354069792,40.0298881530762,1.99686566028645,19.1099997609854,0.0323681110147549,0.00596822028625587,0.25,1.28063128776225E-5,0.00286788042896955,3.28225309462607E-5,9.9999161,9.9999161,34727.65625,34737.89453125,57.3707516830253,20.5881796294572,11.139823,0,0,0,40,4449,9.9965,34732.775390625,,,,,,,,,,,,,0,,,,0,,,,,,9.9999161,,,,
,26776281.26,9.9988766,39162.447265625,0.00332103826546192,8.12574880026133E-7,1,0.999253354069792,40.0298881530762,1.99677359804247,19.1099997609854,0.0373959847400706,0.00690155760045432,0.25,1.4812816290043E-5,0.00331359896357097,3.84609796808117E-5,9.9988766,9.9988766,39160.0625,39164.83203125,57.4606389627369,20.5916914018122,11.519473,0,0,0,40,4449,9.9974,39162.447265625,,,,,,,,,,,,,0,,,,0,,,,,,9.9988766,,,,
,26776456.525,9.998354,43541.599609375,0.00369562288225242,5.92816805999759E-7,1,0.999253354069792,40.0298881530762,1.99681411099774,19.1099997609854,0.0416334584167643,0.00768677141253863,0.25,1.63153198553709E-5,0.00368905038637857,4.30908140218451E-5,9.998354,9.998354,43537.69921875,43545.5,57.4536043060638,20.5884246691021,11.899124,0,0,0,40,4449,9.9987,43541.599609375,,,,,,,,,,,,,0,,,,-0.0049,,,,,,9.998354,,,,
,26776632.875,9.9979849,47949.908203125,0.00402107536390745,7.77750623835227E-7,1,0.999253354069792,40.0298881530762,1.99684910119672,19.1099997609854,0.0453201952316524,0.00837447751938968,0.25,1.80033099515864E-5,0.00401576108138545,4.75090683694815E-5,9.9979849,9.9979849,47946.11328125,47953.703125,56.8040710065829,20.58865589706,11.899124,0,0,0,40,4449,10.0017,47949.908203125,,,,,,,,,,,,,0,,,,0,,,,,,9.9979849,,,,
,26776809.73,9.9979048,52368.63671875,0.00430148654172156,1.12510675962783E-6,1,0.999253354069792,40.0298881530762,1.99678191924641,19.1099997609854,0.0484993249936541,0.0089704894823021,0.25,1.97472378460603E-5,0.00429772427910752,5.1578235190372E-5,9.9979048,9.9979048,52363.53125,52373.7421875,56.8525319747752,20.5875219996436,11.519473,0,0,0,40,4449,10.0049,52368.63671875,,,,,,,,,,,,,0,,,,0,,,,,,9.9979048,,,,
,26776991.875,9.9979744,56919.90625,0.00454928202651344,9.98685692252356E-7,1,0.999253354069792,40.0298881530762,1.99676433305344,19.1099997609854,0.0513147462844872,0.00949705412626818,0.25,2.1249433658079E-5,0.00454733480931941,5.50727337917368E-5,9.9979744,9.9979744,56915.9296875,56923.8828125,57.095618444256,20.5903515811369,11.899124,0,0,0,40,4449,10.0088,56919.90625,,,,,,,,,,,,,0,,,,0,,,,,,9.9979744,,,,
,26777170.24,9.9975834,61377.841796875,0.00476190343444232,1.14701938022321E-6,1,0.999253354069792,40.0298881530762,1.99692835274227,19.1099997609854,0.053742939903273,0.00992933099629282,0.25,2.07609987526384E-5,0.00476188586470376,5.62041890323947E-5,9.9975834,9.9975834,61376.49609375,61379.1875,57.1378263842945,20.5865777350527,11.519473,0,0,0,40,4449,10.0127,61377.841796875,,,,,,,,,,,,,0,,,,0.0049,,,,,,9.9975834,,,,
,26777350.37,9.9981003,65879.56640625,0.00495220852912925,1.28026221136671E-6,1,0.999253354069792,40.0298881530762,1.99693246064419,19.1099997609854,0.0559100213108014,0.0103505615219569,0.25,2.34743818520895E-5,0.00495419904798983,6.02606576405722E-5,9.9981003,9.9981003,65877.109375,65882.0234375,57.0330881627176,20.5849751887162,11.519473,0,0,0,40,4449,10.01675,65879.56640625,,,,,,,,,,,,,0,,,,0,,,,,,9.9981003,,,,
,26777529.04,9.9981403,70343.67578125,0.00512212003787708,1.00454587362719E-6,1,0.999253354069792,40.0298881530762,1.99713860638883,19.1099997609854,0.0578545760625164,0.0107206102007262,0.25,2.53426689568002E-5,0.00512615041981973,6.32137227665439E-5,9.9981403,9.9981403,70340.0078125,70347.34375,57.2488176340253,20.5832910294282,11.139823,0,0,0,40,4449,10.0193,70343.67578125,,,,,,,,,,,,,0,,,,0.0049,,,,,,9.9981403,,,,
,26777708.215,9.9979401,74823.125,0.00527292384905442,1.20271958085967E-6,1,0.999253354069792,40.0298881530762,1.9969276867632,19.1099997609854,0.0595781827776223,0.0110149490450151,0.25,2.42439354306574E-5,0.00527902990855662,6.29525677393975E-5,9.9979401,9.9979401,74818.3125,74827.9375,56.9174071418714,20.5819155999609,11.519473,0,0,0,40,4449,10.02225,74823.125,,,,,,,,,,,,,0,,,,-0.0049,,,,,,9.9979401,,,,
,26777887.72,9.9973273,79308.19921875,0.00541354707885424,1.05939712367276E-6,1,0.999253354069792,40.0298881530762,1.99692984508859,19.1099997609854,0.0611853825349515,0.011329733192695,0.25,2.67854825499322E-5,0.00542169450567301,6.61655449538092E-5,9.9973154,9.9973392,79303.0078125,79313.390625,56.8634747740445,20.5853979657572,11.519473,0,0,0,40,4449,10.02605,79308.19921875,,,,,,,,,,,,,0,,,,0.00245,,,,,,9.9973273,,,,
,26778066.475,9.9978924,83776.25390625,0.00554297686857331,1.4057910949843E-6,1,0.999253354069792,40.0298881530762,1.99709234034186,19.1099997609854,0.0626687546700213,0.0116324740191662,0.25,3.02860307441853E-5,0.00555312211073118,7.01739709646274E-5,9.9978924,9.9978924,83772.5390625,83779.96875,57.0862389020253,20.5824414476729,12.278775,0,0,0,40,4449,10.02975,83776.25390625,,,,,,,,,,,,,0,,,,0,,,,,,9.9978924,,,,
,26778234.35,9.9973125,87973.41796875,0.00565046964065559,1.13460661511991E-6,1,0.999253354069792,40.0298881530762,1.99689719713445,19.1099997609854,0.0638955848264178,0.0118664868730662,0.25,3.19030841952788E-5,0.00566245367390336,7.20945628910386E-5,9.9973125,9.9973125,87970.890625,87975.9453125,56.8548768603329,20.5829912751636,11.899124,0,0,0,40,4449,10.0336,87973.41796875,,,,,,,,,,,,,0,,,,0,,,,,,9.9973125,,,,
,26778415.625,9.9991503,87983.39453125,0.00566408446119114,1.06474648604885E-6,1,0.999253354069792,40.0298881530762,1.99687412774044,19.1099997609854,0.0640529803699146,0.0118721501155328,0.25,2.99664163393635E-5,0.00567611547063467,7.02492058832774E-5,9.9991503,9.9991503,87979.3125,87987.4765625,56.9283499411406,20.5821821145041,12.278775,0,0,0,40,4449,10.0368,87983.39453125,,,,,,,,,,,,,0,,,,0,,,,,,9.9991503,,,,
,26778586.14,10.0012026,83720.3125,0.00557699970687784,9.97799186961485E-7,1,0.999253354069792,40.0298881530762,1.99701381249625,19.1099997609854,0.0630498641365046,0.0117085773220213,0.25,3.09242939685247E-5,0.00558718162117944,7.10638040097895E-5,10.0012026,10.0012026,83717.6328125,83722.9921875,56.8884868866599,20.5843123071462,11.519473,0,0,0,40,4449,10.0346,83720.3125,,,,,,,,,,,,,0,,,,-0.00245,,,,,,10.0012026,,,,
,26778765.485,10.0019026,79237.57421875,0.00547862950710212,9.58250914959661E-7,1,0.999253354069792,40.0298881530762,1.99684975528493,19.1099997609854,0.0619141124180781,0.0114884792662874,0.25,2.91374828956074E-5,0.00548683075870911,6.90004427720155E-5,10.0019026,10.0019026,79236.2890625,79238.859375,56.9752476522945,20.5860016505581,11.139823,0,0,0,40,4449,10.03155,79237.57421875,,,,,,,,,,,,,0,,,,0,,,,,,10.0019026,,,,
,26778947.495,10.0023632,74687.6875,0.00537127631678402,1.04964195230086E-6,1,0.999253354069792,40.0298881530762,1.99707437281936,19.1099997609854,0.0606886207184362,0.0112456761850705,0.25,2.68616545942177E-5,0.00537742201750761,6.630458018413E-5,10.0023632,10.0023632,74682.5078125,74692.8671875,56.7884384361983,20.5881114237802,11.519473,0,0,0,40,4449,10.02725,74687.6875,,,,,,,,,,,,,0,,,,0.0049,,,,,,10.0023632,,,,
,26779131.785,10.0021219,70082.4140625,0.00525471348469642,1.09476304163115E-6,1,0.999253354069792,40.0298881530762,1.99680329966576,19.1099997609854,0.0593432159768273,0.0109860742080992,0.25,2.50948764077571E-5,0.00525873874727486,6.39588653797563E-5,10.0021219,10.0021219,70077.53125,70087.296875,56.9994781363906,20.5892135271132,11.519473,0,0,0,40,4449,10.0239,70082.4140625,,,,,,,,,,,,,0,,,,-0.00245,,,,,,10.0021219,,,,
,26779316.71,10.002717,65459.412109375,0.00513290023738759,9.75746062622243E-7,1,0.999253354069792,40.0298881530762,1.99701909816225,19.1099997609854,0.057949148621302,0.0107343947438288,0.25,2.48590824592987E-5,0.00513476777003466,6.29995424986067E-5,10.002717,10.002717,65454.5078125,65464.31640625,57.268358347006,20.5824980579281,11.519473,0,0,0,40,4449,10.0196,65459.412109375,,,,,,,,,,,,,0,,,,0,,,,,,10.002717,,,,
,26779502.89,10.0027714,60807.69921875,0.00499947250028513,9.79495295382201E-7,1,0.999253354069792,40.0298881530762,1.99691728568573,19.1099997609854,0.056417249482897,0.0104441154595172,0.25,2.35649717915067E-5,0.00499917573667554,6.0777857959299E-5,10.0027714,10.0027714,60803.7890625,60811.609375,56.7751507513714,20.5871719846186,11.139823,0,0,0,40,4449,10.01615,60807.69921875,,,,,,,,,,,,,0,,,,-0.0049,,,,,,10.0027714,,,,
,26779685.335,10.0021124,56247.2109375,0.00485783358760105,1.01597803110933E-6,1,0.999253354069792,40.0298881530762,1.99692805538933,19.1099997609854,0.0547940413756079,0.0101513342713076,0.25,2.35906496234468E-5,0.00485543130434876,5.96910514465283E-5,10.0021124,10.0021124,56245.91015625,56248.51171875,56.6524350738522,20.588179426043,11.519473,0,0,0,40,4449,10.0139,56247.2109375,,,,,,,,,,,,,0,,,,0,,,,,,10.0021124,,,,
,26779865.985,10.0022993,51733.833984375,0.00470822629022162,8.09827727038996E-7,1,0.999253354069792,40.0298881530762,1.99680443070718,19.1099997609854,0.0530816710166261,0.00982287104723925,0.25,2.20585566369067E-5,0.00470380567329332,5.68652714955034E-5,10.0022993,10.0022993,51731.296875,51736.37109375,56.6625962446021,20.5889108465067,11.899124,0,0,0,40,4449,10.00865,51733.833984375,,,,,,,,,,,,,0,,,,0.0049,,,,,,10.0022993,,,,
,26780048.845,10.0016937,47164.494140625,0.00454287320538673,8.84343815114874E-7,1,0.999253354069792,40.0298881530762,1.99684294565673,19.1099997609854,0.051195273698061,0.00946946437442074,0.25,2.12031778174824E-5,0.00453649591259535,5.44720127931691E-5,10.0016937,10.0016937,47160.5234375,47168.46484375,57.1206305568714,20.5902477438658,11.519473,0,0,0,40,4449,10.0066,47164.494140625,,,,,,,,,,,,,0,,,,0,,,,,,10.0016937,,,,
,26780232.485,10.0023184,42575.357421875,0.00436239147307648,6.97879060201531E-7,1,0.999253354069792,40.0298881530762,1.99692160712729,19.1099997609854,0.0491423385810642,0.00907431125913365,0.25,1.946242977175E-5,0.0043541896968522,5.09610621495713E-5,10.0023184,10.0023184,42573.02734375,42577.6875,56.8087607776983,20.5924233521818,11.519473,0,0,0,40,4449,10.0017,42575.357421875,,,,,,,,,,,,,0,,,,-0.00245,,,,,,10.0023184,,,,
,26780412.135,10.0020103,38084.0078125,0.00416856990246687,7.54295314991263E-7,1,0.999253354069792,40.0298881530762,1.99677250780889,19.1099997609854,0.0469321308181953,0.00867257183133252,0.25,1.96891695973078E-5,0.00415874821408998,4.92206942843447E-5,10.0020103,10.0020103,38082.68359375,38085.33203125,56.7735874943329,20.5912774565499,12.278775,0,0,0,40,4449,9.9988,38084.0078125,,,,,,,,,,,,,0,,,,0,,,,,,10.0020103,,,,
,26780591.485,10.0011244,33603.08203125,0.00395778031241078,7.61974782812033E-7,1,0.999253354069792,40.0298881530762,1.9967232262951,19.1099997609854,0.0445386450215404,0.00821871780666787,0.25,1.8356459979816E-5,0.00394657834999268,4.57186484555636E-5,10.0011244,10.0011244,33598.078125,33608.0859375,56.7939098358329,20.5931059814677,11.899124,0,0,0,40,4449,9.99845,33603.08203125,,,,,,,,,,,,,0,,,,-0.00245,,,,,,10.0011244,,,,
,26780766.245,10.0010071,29235.3134765625,0.00373300458408562,7.15024334492596E-7,1,0.999253354069792,40.0298881530762,1.99663129372734,19.1099997609854,0.0419867165466914,0.00775453865001104,0.25,1.86271670813085E-5,0.00372071466731418,4.36788244663612E-5,10.0009861,10.0010281,29232.78515625,29237.841796875,57.3410497992945,20.5898581953054,11.519473,0,0,0,40,4449,9.9966,29235.3134765625,,,,,,,,,,,,,0,,,,0,,,,,,10.0010071,,,,
,26780944.21,10.0005112,24788.673828125,0.00347731215082889,6.5257055069854E-7,1,0.999253354069792,40.0298881530762,1.99676973301355,19.1099997609854,0.0390993464488154,0.00719834548371258,0.25,1.61981820340836E-5,0.00346427711296681,3.87038372762698E-5,10.0005112,10.0005112,24787.384765625,24789.962890625,57.2238055214099,20.5953543031303,11.519473,0,0,0,40,4449,9.9964,24788.673828125,,,,,,,,,,,,,0,,,,-0.0049,,,,,,10.0005112,,,,
,26781121.025,10.0002508,20371.2431640625,0.00319801626029203,6.11540510770942E-7,1,0.999253354069792,40.0298881530762,1.99654417228615,19.1099997609854,0.0359386521993184,0.00661897258837245,0.25,1.59673584199278E-5,0.00318461428722789,3.57956771329604E-5,10.0002508,10.0002508,20367.490234375,20374.99609375,56.7665528376599,20.5950896762814,11.139823,0,0,0,40,4449,9.99595,20371.2431640625,,,,,,,,,,,,,0,,,,0,,,,,,10.0002508,,,,
,26781295.115,9.9996271,16020.0908203125,0.00289223463841399,5.23117185237944E-7,1,0.999253354069792,40.0298881530762,1.99662134761882,19.1099997609854,0.0324912104791058,0.00597735514762483,0.25,1.47053175294099E-5,0.00287892248047941,3.17864267694895E-5,9.9996271,9.9996271,16014.953125,16025.228515625,56.8900501436983,20.595284354796,11.519473,0,0,0,40,4449,9.9952,16020.0908203125,,,,,,,,,,,,,0,,,,-0.0049,,,,,,9.9996271,,,,
,26781469.71,9.9995174,11657.6391601562,0.00255559980554943,4.8265248351139E-7,1,0.999253354069792,40.0298881530762,1.9967202718761,19.1200003027916,0.0287006012311832,0.0052749080388659,0.25,1.33528161390029E-5,0.00254285526713198,2.76391872785806E-5,9.9995174,9.9995174,11655.0771484375,11660.201171875,57.1573670972753,20.5941738049994,11.519473,0,0,0,40,4449,9.9965,11657.6391601562,,,,,,,,,,,,,0,,,,0,,,,,,9.9995174,,,,
,26781640.54,9.9997311,7388.14013671875,0.00219074044524468,3.99005039412738E-7,1,0.999253354069792,40.0298881530762,1.99685237700232,19.1099997609854,0.0245968738210545,0.00451675170647186,0.25,1.17977550342142E-5,0.00217907176905838,2.3348365995172E-5,9.9997311,9.9997311,7384.53271484375,7391.74755859375,57.1010898438907,20.5955192163225,11.519473,0,0,0,40,4449,9.99785,7388.14013671875,,,,,,,,,,,,,0,,,,0,,,,,,9.9997311,,,,
,26781814.885,10.0005741,3031.7890625,0.00178014663809839,3.81144351968628E-7,1,0.999253354069792,40.0298881530762,1.99677973246609,19.1099997609854,0.0199811640045291,0.00366368529600323,0.25,9.66571667781191E-6,0.00177013979781734,1.84971547687424E-5,10.0005741,10.0005741,3026.908203125,3036.669921875,57.2542890336599,20.5939784992188,11.899124,0,0,0,40,4449,9.99745,3031.7890625,,,,,,,,,,,,,0,,,,-0.00245,,,,,,10.0005741,,,,
,26781936.82,10.0031681,-0.266416028141975,0.00147038708960298,3.55900334810319E-7,1,0.999253354069792,40.0298881530762,1.99660055749104,19.1099997609854,0.0165004685364757,0.00302494507506349,0.25,8.19060371922482E-6,0.00146190084890604,1.52307194123242E-5,10.0031681,10.0031681,-0.274027913808823,-0.258804142475128,57.1542405831984,20.597790787085,11.519473,0,0,0,40,4417,9.995,-0.266416028141975,,,,,,,,,,,,,0,,,,0,,,,,,10.0031681,,,,