File: data/monolayers/nanoparticles/Ol_CoFe_C/vsm/Backup/rawdata/DD172_6_HYST_300K_INIT.DAT
[Header]
; VSM Data File (default extension .dat)
; Copyright (c) 2003-2013, Quantum Design, Inc. All rights reserved.
TITLE,
FILEOPENTIME,26733885.30,11/06/2018,6:04 pm
BYAPP,VSM,2.0,2.0
INFO,PPMS VSM Option Release 1.4.10 Build 1,APPNAME
INFO,Quantum Design Linear Motor Servo Controller,MOTOR_MODULE_NAME
INFO,3101-100 M1,MOTOR_HW_VERSION
INFO,MMC1014,MOTOR_SERIAL_NUMBER
INFO,SRV No X-over 01.03.11,MOTOR_SOFTWARE_VERSION
INFO,Quantum Design VSM Detection Module,VSM_MODULE_NAME
INFO,3101-150 F0,VSM_HW_VERSION
INFO,VSM707,VSM_SERIAL_NUMBER
INFO,VSM No X-over 01.02.05 May 20 2008 13:51:47,VSM_SOFTWARE_VERSION
INFO,704,PREAMP_SERIAL_NUMBER
INFO,822,COIL_SERIAL_NUMBER
INFO,0,MOMENT_UNITS
INFO,CoFe2O4 DD67,SAMPLE_MATERIAL
INFO,Colloidal Crystal,SAMPLE_COMMENT
INFO,31.86,SAMPLE_MASS
INFO,,SAMPLE_VOLUME
INFO,,SAMPLE_MOLECULAR_WEIGHT
INFO,,SAMPLE_SIZE
INFO,,SAMPLE_SHAPE
DATATYPE,COMMENT,1
DATATYPE,TIME,2
STARTUPAXIS,X,2
STARTUPAXIS,Y1,5
[Data]
Comment,Time Stamp (sec),Temperature (K),Magnetic Field (Oe),Moment (emu),M. Std. Err. (emu),Transport Action,Averaging Time (sec),Frequency (Hz),Peak Amplitude (mm),Center Position (mm),Coil Signal' (mV),Coil Signal" (mV),Range (mV),M. Quad. Signal (emu),M. Raw' (emu),M. Raw" (emu),Min. Temperature (K),Max. Temperature (K),Min. Field (Oe),Max. Field (Oe),Mass (grams),Motor Lag (deg),Pressure (Torr),VSM Status (code),Motor Status (code),Measure Status (code),Measure Count,PPMS Status (code),System Temp. (K),System Field (Oe),Sample Position (deg),Bridge 1 Resistance (ohms),Bridge 1 Excitation (에),Bridge 2 Resistance (ohms),Bridge 2 Excitation (에),Bridge 3 Resistance (ohms),Bridge 3 Excitation (에),Bridge 4 Resistance (ohms),Bridge 4 Excitation (에),Signal 1 Vin (V),Signal 2 Vin (V),Digital Inputs (code),Drive 1 Iout (mA),Drive 1 Ipower (W),Drive 2 Iout (mA),Drive 2 Ipower (W),Pressure (),Map 20 (),Map 21 (),Map 22 (),Map 23 (),Map 24 (),Map 25 (),Map 26 (),Map 27 (),Map 28 (),Map 29 ()
,26733900.45,300.0213623,0.106566414237022,,,2,,,,19.1199999400973,,,,,,,300.0213623,300.0213623,0.106566414237022,0.106566414237022,,,22.909004,,,,-99999999,4369,300.5107,0.106566414237022,,,,,,,,,,,,,,,,,,,,,,,300.0213623,,,,
,26734128.19,300.0255432,4217.07836914063,0.00134635954107292,6.11048977752453E-7,1,0.999253354069792,40.0298881530762,2.00095169231536,19.1099997609854,0.0152503876183303,0.00265882555864094,0.25,1.41886393718039E-6,0.0013463172965378,2.31081048053002E-6,300.0255432,300.0255432,4214.76171875,4219.39501953125,56.0810646262944,20.5428288148036,22.909004,0,0,0,40,4449,300.4503,4217.07836914063,,,,,,,,,,,,,0,,,,0,,,,,,300.0255432,,,,
,26734307.63,300.0153809,8699.93310546875,0.00197062646625638,9.73586975121151E-7,1,0.999253354069792,40.0298881530762,2.00070211240729,19.1099997609854,0.0223206451612206,0.0038810619835501,0.25,1.18410774668224E-6,0.00197056601449026,2.48888417779307E-6,300.0153809,300.0153809,8696.2275390625,8703.638671875,56.5054889122367,20.5436606614675,23.288654,0,0,0,40,4449,300.4198,8699.93310546875,,,,,,,,,,,,,0,,,,0,,,,,,300.0153809,,,,
,26734490.82,300.0100098,13277.6274414062,0.00242245522652619,1.01913414087991E-6,1,0.999253354069792,40.0298881530762,2.00064419469441,19.1099997609854,0.027438217259194,0.00476729021193344,0.25,1.14799846937554E-6,0.00242238169355286,2.75074929471923E-6,300.0100098,300.0100098,13274.0966796875,13281.158203125,56.3679222928521,20.5501686276179,22.909004,0,0,0,40,4449,300.4048,13277.6274414062,,,,,,,,,,,,,0,,,,0,,,,,,300.0100098,,,,
,26734676.21,300.0123596,17910.4775390625,0.00277904279752176,7.67894111119916E-7,1,0.999253354069792,40.0298881530762,2.00040148468862,19.1099997609854,0.0314730833187511,0.00547082524546403,0.25,1.53200328148114E-6,0.00277895819449761,3.36922596080617E-6,300.0123596,300.0123596,17909.11328125,17911.841796875,56.6000659630637,20.5505047996355,22.909004,0,0,0,40,4449,300.3828,17910.4775390625,,,,,,,,,,,,,0,,,,0,,,,,,300.0123596,,,,
,26734862.42,300.0095215,22563.0751953125,0.00307452571496795,1.30767294783218E-6,1,0.999253354069792,40.0298881530762,2.00022225895236,19.1099997609854,0.0348132158988621,0.00607095729369753,0.25,3.37084138644012E-6,0.00307443148111588,5.40160658478322E-6,300.0090027,300.0100403,22559.54296875,22566.607421875,56.7626446950637,20.5534250343714,23.288654,0,0,0,40,4449,300.3669,22563.0751953125,,,,,,,,,,,,,0,,,,-0.00245,,,,,,300.0095215,,,,
,26735049.4,300.0121155,27237.36328125,0.00332724107708505,1.86604928411687E-6,1,0.999253354069792,40.0298881530762,2.0001236205,19.1099997609854,0.0376760264455154,0.00655200439697844,0.25,2.09112126797516E-6,0.00332714001464365,4.2866538518604E-6,300.0121155,300.0121155,27234.845703125,27239.880859375,56.8283014906791,20.5565396260735,23.668306,0,0,0,40,4449,300.3757,27237.36328125,,,,,,,,,,,,,0,,,,0,,,,,,300.0121155,,,,
,26735236.115,300.0090637,31902.587890625,0.00354894128501679,1.63403892186151E-6,1,0.999253354069792,40.0298881530762,1.99961105307356,19.1099997609854,0.0401742888377878,0.00700037481987626,0.25,3.42535516331274E-6,0.00354883326885846,5.76516150159598E-6,300.0090637,300.0090637,31900.189453125,31904.986328125,56.7587365524675,20.5613743447828,22.909004,0,0,0,40,4449,300.3372,31902.587890625,,,,,,,,,,,,,0,,,,0,,,,,,300.0090637,,,,
,26735420.65,300.0170288,36514.650390625,0.00373886522251002,1.49713300826065E-6,1,0.999253354069792,40.0298881530762,1.99903530744788,19.1099997609854,0.0423157150749117,0.00735501873218863,0.25,2.02457772221387E-6,0.00373875162067898,4.4872016989791E-6,300.0170288,300.0170288,36509.484375,36519.81640625,56.7884384361983,20.5669768717814,22.909004,0,0,0,40,4449,300.3313,36514.650390625,,,,,,,,,,,,,0,,,,0.0049,,,,,,300.0170288,,,,
,26735603.29,300.0084534,41078.751953125,0.0039153613421821,1.63402115278304E-6,1,0.999253354069792,40.0298881530762,1.99887943998906,19.1099997609854,0.0443083668788365,0.00771096478327886,0.25,2.94571675246004E-6,0.0039152432549137,5.52218565650732E-6,300.0084534,300.0084534,41077.53515625,41079.96875,56.7626446950637,20.567228080802,23.288654,0,0,0,40,4449,300.3044,41078.751953125,,,,,,,,,,,,,0,,,,0.0049,,,,,,300.0084534,,,,
,26735787.61,300.0069275,45685.2421875,0.00407550614234252,2.38660445548715E-6,1,0.999253354069792,40.0298881530762,1.99939014035708,19.1099997609854,0.0461266343523693,0.00805872272066003,0.25,5.75505658217344E-6,0.00407538192865686,8.43407893949005E-6,300.0069275,300.0069275,45680.15234375,45690.33203125,56.8454973181022,20.5597392351682,22.909004,0,0,0,40,4449,300.29525,45685.2421875,,,,,,,,,,,,,0,,,,0,,,,,,300.0069275,,,,
,26735967.78,300.0059814,50186.74609375,0.00422170874093314,2.10245053637305E-6,1,0.999253354069792,40.0298881530762,1.99942200662262,19.1099997609854,0.0477831430772372,0.00834185852330004,0.25,5.42673381504637E-6,0.00422158082396557,8.19903324935999E-6,300.0059814,300.0059814,50180.51953125,50192.97265625,56.7681160946983,20.5618138533611,22.909004,0,0,0,40,4449,300.2872,50186.74609375,,,,,,,,,,,,,0,,,,0.00245,,,,,,300.0059814,,,,
,26736151.215,300.0082703,54770.19140625,0.00435698584207614,2.37072813759976E-6,1,0.999253354069792,40.0298881530762,1.99964974177634,19.1099997609854,0.049310926445403,0.00866031432297745,0.25,1.00391562694439E-5,0.0043568508243707,1.28971932543186E-5,300.0082703,300.0082703,54767.97265625,54772.41015625,56.7493570102368,20.5571809849057,23.668306,0,0,0,40,4449,300.27225,54770.19140625,,,,,,,,,,,,,0,,,,-0.00245,,,,,,300.0082703,,,,
,26736335.205,300.0030212,59368.1171875,0.00448616732113516,3.94867873665342E-6,1,0.999253354069792,40.0298881530762,1.99956369698221,19.1099997609854,0.0507817652723153,0.00885393892639383,0.25,4.79468809449467E-6,0.00448603307802306,7.73434520281444E-6,300.0030212,300.0030212,59365.6875,59370.546875,56.5867782782368,20.5560736049435,23.288654,0,0,0,40,4449,300.2724,59368.1171875,,,,,,,,,,,,,0,,,,-0.00245,,,,,,300.0030212,,,,
,26736516.025,300.0032501,63888.8359375,0.00460121052353485,2.94127415817177E-6,1,0.999253354069792,40.0298881530762,1.99952056332368,19.1099997609854,0.0520812283659766,0.0090906983345555,0.25,5.7949491402444E-6,0.00460107251887459,8.80671082452678E-6,300.0031738,300.0033264,63886.3359375,63891.3359375,56.699332785006,20.5553167795597,23.288654,0,0,0,40,4449,300.26395,63888.8359375,,,,,,,,,,,,,0,,,,0.00245,,,,,,300.0032501,,,,
,26736698.225,300.0050354,68441.5078125,0.00471474508959121,3.30595191383543E-6,1,0.999253354069792,40.0298881530762,1.99943399645733,19.1099997609854,0.0533628480233835,0.00932199349928481,0.25,6.5920633729097E-6,0.004714603250068,9.67478763404327E-6,300.0050354,300.0050354,68438.921875,68444.09375,56.6813553290637,20.5543151995781,22.909004,0,0,0,40,4449,300.2498,68441.5078125,,,,,,,,,,,,,0,,,,0,,,,,,300.0050354,,,,
,26736877.485,300.0066833,72920.53125,0.00481739334221786,3.45516388005915E-6,1,0.999253354069792,40.0298881530762,1.99945741520792,19.1200003027916,0.0545127644928778,0.00959718209779282,0.25,1.31099115908363E-5,0.00481724427490097,1.62561396260986E-5,300.0066833,300.0066833,72916.9453125,72924.1171875,56.5187765970637,20.5546746535755,22.909004,0,0,0,40,4449,300.23885,72920.53125,,,,,,,,,,,,,0,,,,0,,,,,,300.0066833,,,,
,26737057.65,300.0085754,77423.6953125,0.00491495877295396,5.04977025732037E-6,1,0.999253354069792,40.0298881530762,1.99931056608924,19.1099997609854,0.0556251236270763,0.00972030701991842,0.25,7.14616642736197E-6,0.00491481074473274,1.03527085431519E-5,300.0085754,300.0085754,77419.84375,77427.546875,56.5484784807944,20.557161185363,23.288654,0,0,0,40,4449,300.23065,77423.6953125,,,,,,,,,,,,,0,,,,0,,,,,,300.0085754,,,,
,26737245.16,300.005127,82110.5859375,0.00501363536648112,4.26894886760704E-6,1,0.999253354069792,40.0298881530762,1.99919583037064,19.1099997609854,0.0567317893145405,0.00995539096183994,0.25,1.08688587655826E-5,0.00501348300012511,1.413584182162E-5,300.005127,300.005127,82108.3046875,82112.8671875,56.7438856106022,20.5587063369225,23.668306,0,0,0,40,4449,300.22115,82110.5859375,,,,,,,,,,,,,0,,,,0.0049,,,,,,300.005127,,,,
,26737425.98,300.0135498,86630.27734375,0.00510126180103625,4.54224530216191E-6,1,0.999253354069792,40.0298881530762,1.99918446467682,19.1099997609854,0.0577271870091977,0.0101051582775742,0.25,8.92708012161718E-6,0.00510110694634291,1.22475761636161E-5,300.0135498,300.0135498,86628.703125,86631.8515625,56.8595666314483,20.5575459303498,23.288654,0,0,0,40,4449,300.2001,86630.27734375,,,,,,,,,,,,,0,,,,0,,,,,,300.0135498,,,,
,26737625.125,300.0137634,88913.76171875,0.00514860090745836,4.70527920700709E-6,1,0.999253354069792,40.0298881530762,1.99914566821286,19.1099997609854,0.0582622205068061,0.0101963800159288,0.25,8.80284635466391E-6,0.00514844487274074,1.21523681545603E-5,300.0137634,300.0137634,88911.375,88916.1484375,56.7345060683714,20.5604186787334,23.288654,0,0,0,40,4449,300.1835,88913.76171875,,,,,,,,,,,,,0,,,,0.0049,,,,,,300.0137634,,,,
,26737804.875,300.006012,84420.48828125,0.00506351863365443,4.94636456283772E-6,1,0.999253354069792,40.0298881530762,1.99919761266133,19.1099997609854,0.0572942394303695,0.0100662976361727,0.25,1.20250620028956E-5,0.0050633640439995,1.53230160080621E-5,300.006012,300.006012,84417.84375,84423.1328125,56.7884384361983,20.5603018039315,23.668306,0,0,0,40,4449,300.1836,84420.48828125,,,,,,,,,,,,,0,,,,0,,,,,,300.006012,,,,
,26737993.25,299.99487305,79711.484375,0.00496569760456157,4.78147628424704E-6,1,0.999253354069792,40.0298881530762,1.99918144604196,19.1099997609854,0.0561929818582234,0.00983705110858456,0.25,8.72299271386458E-6,0.0049655496391586,1.19611894937617E-5,299.9945984,299.9951477,79709.1484375,79713.8203125,56.9416376259676,20.5590470455193,23.668306,0,0,0,40,4449,300.19095,79711.484375,,,,,,,,,,,,,0,,,,0,,,,,,299.99487305,,,,
,26738186.25,299.9985962,74887.90234375,0.00486270337104826,3.03143594404147E-6,1,0.999253354069792,40.0298881530762,1.99915728126053,19.1099997609854,0.0550258914376442,0.00963831827864731,0.25,9.01606927915135E-6,0.00486255714344156,1.21911925915358E-5,299.9985962,299.9985962,74885.515625,74890.2890625,56.9869720800829,20.5594381596318,23.668306,0,0,0,40,4449,300.1765,74887.90234375,,,,,,,,,,,,,0,,,,0,,,,,,299.9985962,,,,
,26738375.25,300.0007019,70165.10546875,0.00475286315674316,3.26471609915301E-6,1,0.999253354069792,40.0298881530762,1.99925346235851,19.1099997609854,0.0537859587453902,0.00941787752590073,0.25,8.5298552729094E-6,0.00475271973809099,1.16367877911404E-5,300.0007019,300.0007019,70162.4140625,70167.796875,57.0424677049483,20.5619910759607,23.288654,0,0,0,40,4449,300.19295,70165.10546875,,,,,,,,,,,,,0,,,,-0.00245,,,,,,300.0007019,,,,
,26738564.36,299.9987793,65438.376953125,0.00464100529815271,4.00386993977775E-6,1,0.999253354069792,40.0298881530762,1.99921885514911,19.1099997609854,0.0525173381043401,0.00920709788092891,0.25,9.29907037227287E-6,0.00464086461522967,1.23364412167844E-5,299.9987793,299.9987793,65437.19140625,65439.5625,56.7712426087752,20.5602905625462,23.288654,0,0,0,40,4449,300.1937,65438.376953125,,,,,,,,,,,,,0,,,,0,,,,,,299.9987793,,,,
,26738755.22,299.9909363,60669.083984375,0.00452001260037381,2.83097154114007E-6,1,0.999253354069792,40.0298881530762,1.99919228053672,19.1099997609854,0.0511509704836257,0.00894723492692232,0.25,7.31131563981991E-6,0.00451987769798608,1.02728979246458E-5,299.9909363,299.9909363,60666.62890625,60671.5390625,56.8071975206598,20.563551943045,23.668306,0,0,0,40,4449,300.2065,60669.083984375,,,,,,,,,,,,,0,,,,-0.0049,,,,,,299.9909363,,,,
,26738947.26,299.994751,55868.71875,0.00438913765250266,3.94113718241485E-6,1,0.999253354069792,40.0298881530762,1.99908230924704,19.1099997609854,0.0496735950674355,0.00865137651747064,0.25,3.88609133473213E-6,0.00438900786662872,6.76527901497744E-6,299.994751,299.994751,55866.15625,55871.28125,56.9103724851983,20.5638658698187,23.288654,0,0,0,40,4449,300.2155,55868.71875,,,,,,,,,,,,,0,,,,-0.00245,,,,,,299.994751,,,,
,26739135.43,299.9888306,51166.333984375,0.00424974436317932,3.42144257316245E-6,1,0.999253354069792,40.0298881530762,1.99909259075668,19.1099997609854,0.0480919572002025,0.00840155333506818,0.25,5.95860551943899E-6,0.00424961788433565,8.74936153436713E-6,299.9888306,299.9888306,51161.3984375,51171.26953125,56.7821854080445,20.567238485196,23.668306,0,0,0,40,4449,300.2225,51166.333984375,,,,,,,,,,,,,0,,,,-0.00245,,,,,,299.9888306,,,,
,26739326.445,299.99823,46393.89453125,0.00409958592263896,2.9574124954833E-6,1,0.999253354069792,40.0298881530762,1.99886683729849,19.1099997609854,0.0463881536909951,0.00810108993436161,0.25,5.50382130341074E-6,0.00409946241576355,8.19898824256859E-6,299.99823,299.99823,46388.8203125,46398.96875,57.2902439455445,20.5666738439077,22.909004,0,0,0,40,4449,300.224,46393.89453125,,,,,,,,,,,,,0,,,,0.0049,,,,,,299.99823,,,,
,26739520.17,299.9967957,41552.66796875,0.00393392828134024,3.09759226378217E-6,1,0.999253354069792,40.0298881530762,1.99900985861154,19.1099997609854,0.0445163445399893,0.00777644901364149,0.25,5.47133104352507E-6,0.00393380959619497,8.06030429088307E-6,299.9967957,299.9967957,41546.04296875,41559.29296875,56.8064158921406,20.5659276613427,23.668306,0,0,0,40,4449,300.2414,41552.66796875,,,,,,,,,,,,,0,,,,0,,,,,,299.9967957,,,,
,26739712.735,299.9918518,36740.494140625,0.00375227521750519,2.91587465841208E-6,1,0.999253354069792,40.0298881530762,1.99906302948706,19.1099997609854,0.0424602440252967,0.00742676672904231,0.25,6.0299413701516E-6,0.00375216189330058,8.50210942759036E-6,299.9918518,299.9918518,36736.73046875,36744.2578125,57.0260535060445,20.5667699750198,23.668306,0,0,0,40,4449,300.2333,36740.494140625,,,,,,,,,,,,,0,,,,-0.00245,,,,,,299.9918518,,,,
,26739901.65,299.9969482,32019.4111328125,0.00355448710213503,2.21503232738854E-6,1,0.999253354069792,40.0298881530762,1.99912151308585,19.1099997609854,0.0402261309065267,0.00701864568671892,0.25,4.22207027754588E-6,0.00355437987032188,6.56630584308394E-6,299.9969482,299.9969482,32014.80859375,32024.013671875,56.6962062709291,20.56808607361,23.668306,0,0,0,40,4449,300.24435,32019.4111328125,,,,,,,,,,,,,0,,,,-0.00245,,,,,,299.9969482,,,,
,26740086.985,299.9949646,27387.998046875,0.00333677007246395,2.32996662697627E-6,1,0.999253354069792,40.0298881530762,1.99912997821949,19.1099997609854,0.0377640892768548,0.0065789076038337,0.25,3.08995076680246E-6,0.0033366700295178,5.29275645352513E-6,299.9949646,299.9949646,27386.58203125,27389.4140625,57.0995265868522,20.5684895020986,23.288654,0,0,0,40,4449,300.25055,27387.998046875,,,,,,,,,,,,,0,,,,-0.00245,,,,,,299.9949646,,,,
,26740268.985,299.9964294,22840.3916015625,0.00309203117684365,1.32202798314362E-6,1,0.999253354069792,40.0298881530762,1.99898567753583,19.1099997609854,0.0349924304673267,0.00609247492084303,0.25,2.55436750093182E-6,0.00309193833989862,4.59752505380435E-6,299.9964294,299.9964294,22836.767578125,22844.015625,56.9111541137176,20.5712093845478,23.668306,0,0,0,40,4449,300.25255,22840.3916015625,,,,,,,,,,,,,0,,,,0,,,,,,299.9964294,,,,
,26740453.165,299.9976807,18237.841796875,0.00280475617207186,1.35320422328518E-6,1,0.999253354069792,40.0298881530762,1.99880197936988,19.1099997609854,0.0317372963307032,0.00553324590547372,0.25,2.96012840229775E-6,0.00280467125840533,4.81510210077816E-6,299.9976807,299.9976807,18236.576171875,18239.107421875,56.8978664288906,20.5751310506324,22.909004,0,0,0,40,4449,300.25805,18237.841796875,,,,,,,,,,,,,0,,,,0,,,,,,299.9976807,,,,
,26740637.25,299.9992676,13636.8681640625,0.00245650167447275,1.17137112604657E-6,1,0.999253354069792,40.0298881530762,1.99877817932603,19.1099997609854,0.0277951232560798,0.00485290847557543,0.25,3.1882835517173E-6,0.00245642664405244,4.81429756056435E-6,299.9992676,299.9992676,13634.4892578125,13639.2470703125,57.0158923352945,20.5753652491957,23.668306,0,0,0,40,4449,300.26365,13636.8681640625,,,,,,,,,,,,,0,,,,-0.00245,,,,,,299.9992676,,,,
,26740825.135,300.0009766,8943.384765625,0.00200098181163088,5.55120568921713E-7,1,0.999253354069792,40.0298881530762,1.99886583769761,19.1099997609854,0.0226430867405032,0.00394631003067817,0.25,1.98923215891343E-6,0.0020009208771195,3.31480935036905E-6,300.0009766,300.0009766,8942.1787109375,8944.5908203125,56.8673829166406,20.5755735671052,24.047956,0,0,0,40,4449,300.2707,8943.384765625,,,,,,,,,,,,,0,,,,-0.0049,,,,,,300.0009766,,,,
,26741005.385,299.9963989,4437.58984375,0.00139114934831597,6.77079058793745E-7,1,0.999253354069792,40.0298881530762,1.99896463616477,19.1099997609854,0.0157429197646458,0.00274405036344323,0.25,1.41010373087335E-6,0.00139110713778624,2.33232145790238E-6,299.9963989,299.9963989,4433.63525390625,4441.54443359375,57.0878021590637,20.574503232852,22.909004,0,0,0,40,4449,300.27865,4437.58984375,,,,,,,,,,,,,0,,,,-0.00245,,,,,,299.9963989,,,,
,26741181.94,299.9989929,25.7045135498047,1.91734482639317E-5,9.33899272952399E-7,1,0.999253354069792,40.0298881530762,1.99888760656837,19.1099997609854,0.000217824365688493,3.2875795784147E-5,0.25,-4.17268458684408E-7,1.91731537397409E-5,-4.04537941318051E-7,299.9989929,299.9989929,25.7045135498047,25.7045135498047,57.1847240954484,20.5758357078892,23.288654,0,0,0,40,4449,300.2751,25.7045135498047,,,,,,,,,,,,,0,,,,0,,,,,,299.9989929,,,,
,26741362.095,300.0029297,-4475.12622070313,-0.00139129331265402,6.41899520895112E-7,1,0.999253354069792,40.0298881530762,1.99886000469631,19.1099997609854,-0.015742526267991,-0.00275131031220084,0.25,-2.03877041063039E-6,-0.00139125035333302,-2.96107896065597E-6,300.0029297,300.0029297,-4477.63671875,-4472.61572265625,57.2269320354868,20.5754976365233,23.668306,0,0,0,40,4449,300.2732,-4475.12622070313,,,,,,,,,,,,,0,,,,0.0049,,,,,,300.0029297,,,,
,26741546.18,300.0075989,-9076.447265625,-0.00201347617990388,7.08942148359413E-7,1,0.999253354069792,40.0298881530762,1.99892065334239,19.1099997609854,-0.0227853788649459,-0.00396923564521341,0.25,-1.84104017762672E-6,-0.0020134144983228,-3.17483262642315E-6,300.0075989,300.0075989,-9078.8310546875,-9074.0634765625,56.8970848003714,20.5758797720975,23.668306,0,0,0,40,4449,300.2775,-9076.447265625,,,,,,,,,,,,,0,,,,0,,,,,,300.0075989,,,,
,26741736.085,300.006012,-13822.568359375,-0.00246916665384738,1.34253723593881E-6,1,0.999253354069792,40.0298881530762,1.99909532995134,19.1099997609854,-0.0279428606545337,-0.00487745125401773,0.25,-3.09747526672679E-6,-0.00246909071620528,-4.73179964477674E-6,300.006012,300.006012,-13824.1875,-13820.94921875,57.2847725459099,20.5758488472101,24.047956,0,0,0,40,4449,300.2666,-13822.568359375,,,,,,,,,,,,,0,,,,0,,,,,,300.006012,,,,
,26741926.935,300.0006409,-18591.23828125,-0.00282604215020814,8.91336577602211E-7,1,0.999253354069792,40.0298881530762,1.99887546536079,19.1099997609854,-0.0319773370695418,-0.00558663161980199,0.25,-3.97213021930496E-6,-0.00282595565365508,-5.84097074480281E-6,300.0006409,300.0006409,-18596.0078125,-18586.46875,57.3519925985638,20.5773003771843,23.668306,0,0,0,40,4449,300.26515,-18591.23828125,,,,,,,,,,,,,0,,,,0,,,,,,300.0006409,,,,
,26742118.025,300.00787355,-23366.169921875,-0.00311858970749191,1.54963560499461E-6,1,0.999253354069792,40.0298881530762,1.99872433921623,19.1099997609854,-0.0352865038745184,-0.00615599108075482,0.25,-3.63283727389452E-6,-0.00311849410928757,-5.69333090797681E-6,300.0073853,300.0083618,-23369.0390625,-23363.30078125,57.0205821064099,20.5782934894297,23.668306,0,0,0,40,4449,300.24745,-23366.169921875,,,,,,,,,,,,,0,,,,-0.00245,,,,,,300.00787355,,,,
,26742310,300.0062866,-28163.2578125,-0.0033703110208509,1.62759287159108E-6,1,0.999253354069792,40.0298881530762,1.99879156868746,19.1099997609854,-0.0381380520790071,-0.00664085549856353,0.25,-2.84667173826324E-6,-0.00337020879711503,-5.07146616263222E-6,300.0062866,300.0062866,-28168.115234375,-28158.400390625,57.1808159528522,20.5782835422975,23.288654,0,0,0,40,4449,300.22705,-28163.2578125,,,,,,,,,,,,,0,,,,0,,,,,,300.0062866,,,,
,26742503,300.0036926,-32985.78515625,-0.00359235932750996,1.78562584760236E-6,1,0.999253354069792,40.0298881530762,1.99868503501257,19.1099997609854,-0.0406444839488578,-0.00710214606348847,0.25,-5.16855176324758E-6,-0.00359224952242789,-7.5373609901576E-6,300.0036926,300.0036926,-32988.7421875,-32982.828125,57.0635716749676,20.5792786520794,23.668306,0,0,0,40,4449,300.231,-32985.78515625,,,,,,,,,,,,,0,,,,-0.0049,,,,,,300.0036926,,,,
,26742696.845,300.0111389,-37828.869140625,-0.00378962736522349,2.24108111015019E-6,1,0.999253354069792,40.0298881530762,1.99863405959947,19.1099997609854,-0.0428780273530957,-0.00747651740299759,0.25,-4.08993133224651E-6,-0.00378951164067123,-6.58637040735872E-6,300.0111389,300.0111389,-37834.63671875,-37823.1015625,56.9627415959868,20.5782448969045,23.668306,0,0,0,40,4449,300.21115,-37828.869140625,,,,,,,,,,,,,0,,,,0,,,,,,300.0111389,,,,
,26742894.71,300.0093079,-42773.822265625,-0.00397267497482196,1.7098989489297E-6,1,0.999253354069792,40.0298881530762,1.99852888756967,19.1099997609854,-0.0449494284090143,-0.00782256027294282,0.25,-2.9914831460711E-6,-0.00397255502760648,-5.60575174294878E-6,300.0093079,300.0093079,-42780.05078125,-42767.59375,56.9916618511983,20.5802968694835,23.668306,0,0,0,40,4449,300.1968,-42773.822265625,,,,,,,,,,,,,0,,,,0,,,,,,300.0093079,,,,
,26743091.905,300.0083618,-47702.4296875,-0.00413959922908064,1.77648011127176E-6,1,0.999253354069792,40.0298881530762,1.99846531750277,19.1099997609854,-0.0468359928025921,-0.00815508924400004,0.25,-3.48127902189598E-6,-0.00413947441071685,-6.20241596075757E-6,300.0083618,300.0083618,-47704.96484375,-47699.89453125,56.8697278021983,20.5796140177243,23.668306,0,0,0,40,4449,300.18265,-47702.4296875,,,,,,,,,,,,,0,,,,0,,,,,,300.0083618,,,,
,26743286.96,300.0080872,-52575.642578125,-0.00428886663877686,1.92241426013788E-6,1,0.999253354069792,40.0298881530762,1.99869284669178,19.1099997609854,-0.0485295304180661,-0.00845335822337408,0.25,-3.90069283099299E-6,-0.0042887374490681,-6.71683307539277E-6,300.0080872,300.0080872,-52579.31640625,-52571.96875,56.8877052581406,20.5786598107319,23.668306,0,0,0,40,4449,300.1694,-52575.642578125,,,,,,,,,,,,,0,,,,-0.00245,,,,,,300.0080872,,,,
,26743480.755,300.006897,-57417.90625,-0.00442913852992968,3.38513235070913E-6,1,0.999253354069792,40.0298881530762,1.99852434161632,19.1099997609854,-0.050110026666205,-0.00874463773927097,0.25,-5.4016396029395E-6,-0.00442900469190316,-8.30664291821133E-6,300.006897,300.006897,-57418.90234375,-57416.91015625,57.0526288756983,20.5835565390047,23.668306,0,0,0,40,4449,300.15245,-57417.90625,,,,,,,,,,,,,0,,,,0,,,,,,300.006897,,,,
,26743676.72,300.00753785,-62314.9609375,-0.00455720239467742,2.36449332844315E-6,1,0.999253354069792,40.0298881530762,1.99867671643082,19.1099997609854,-0.0515622427699702,-0.00900053724450627,0.25,-5.77365678032203E-6,-0.00455706476061164,-8.75910411483323E-6,300.0073242,300.0077515,-62318.66796875,-62311.25390625,57.027616763083,20.5800434938264,23.668306,0,0,0,40,4449,300.1491,-62314.9609375,,,,,,,,,,,,,0,,,,-0.00245,,,,,,300.00753785,,,,
,26743868.995,300.0032043,-67120.5234375,-0.00468055601328836,2.31388464333617E-6,1,0.999253354069792,40.0298881530762,1.99868533160268,19.1099997609854,-0.0529606599068011,-0.00922972169488994,0.25,-4.65411542146134E-6,-0.00468041655448593,-7.71667327263047E-6,300.0032043,300.0032043,-67124.109375,-67116.9375,56.8134505488137,20.5804873565703,24.047956,0,0,0,40,4449,300.15565,-67120.5234375,,,,,,,,,,,,,0,,,,-0.0049,,,,,,300.0032043,,,,
,26744057.245,300.0062561,-71824.71484375,-0.00479125532504085,1.94706960376078E-6,1,0.999253354069792,40.0298881530762,1.99880569220656,19.1099997609854,-0.0542091384863108,-0.00949012055748972,0.25,-8.44025564262357E-6,-0.00479110995086283,-1.15716769583161E-5,300.0062561,300.0062561,-71828.421875,-71821.0078125,57.0541921327368,20.5785549481208,23.668306,0,0,0,40,4449,300.13505,-71824.71484375,,,,,,,,,,,,,0,,,,0.00245,,,,,,300.0062561,,,,
,26744254.365,300.0073547,-76750.25390625,-0.00490180559584001,2.13105823614771E-6,1,0.999253354069792,40.0298881530762,1.99875353637988,19.1099997609854,-0.0554625483514523,-0.00968574140983968,0.25,-6.59715925877496E-6,-0.00490165835219685,-9.79704918067379E-6,300.0073547,300.0073547,-76755.8203125,-76744.6875,56.973684395256,20.5803865335428,24.047956,0,0,0,40,4449,300.1208,-76750.25390625,,,,,,,,,,,,,0,,,,-0.00245,,,,,,300.0073547,,,,
,26744448.35,300.0090332,-81596.29296875,-0.00499875770606929,5.05677451698663E-6,1,0.999253354069792,40.0298881530762,1.99867958278091,19.1099997609854,-0.056550448908877,-0.00991788253680199,0.25,-1.03471500179171E-5,-0.00499860524578417,-1.36062557047211E-5,300.0090332,300.0090332,-81599.8671875,-81592.71875,56.7876568076791,20.583548002618,23.288654,0,0,0,40,4449,300.11235,-81596.29296875,,,,,,,,,,,,,0,,,,-0.0049,,,,,,300.0090332,,,,
,26744637.335,300.0022583,-86319.29296875,-0.00509383536815839,4.07413907000209E-6,1,0.999253354069792,40.0298881530762,1.99882640774641,19.1099997609854,-0.0576305905431626,-0.0101044662765636,0.25,-1.03032942997155E-5,-0.00509368176363434,-1.36204358109045E-5,300.0022583,300.0022583,-86321.7109375,-86316.875,57.0721695886791,20.5837815478214,24.047956,0,0,0,40,4449,300.1029,-86319.29296875,,,,,,,,,,,,,0,,,,0,,,,,,300.0022583,,,,
,26744842.25,300.006958,-89082.44921875,-0.00514408244373863,3.34058163653001E-6,1,0.999253354069792,40.0298881530762,1.99900547903727,19.1099997609854,-0.0582035448069709,-0.0102078907690974,0.25,-1.06618610337589E-5,-0.00514392651332447,-1.40092280049731E-5,300.006958,300.006958,-89086.1953125,-89078.703125,56.8861420011022,20.5828996710219,23.668306,0,0,0,40,4449,300.10725,-89082.44921875,,,,,,,,,,,,,0,,,,0,,,,,,300.006958,,,,
,26745027.93,300.0030212,-84442.640625,-0.005058611677443,3.06464405580106E-6,1,0.999253354069792,40.0298881530762,1.99909180803662,19.1099997609854,-0.0572417582921647,-0.0100218229515639,0.25,-8.98981424545261E-6,-0.00505845965483138,-1.22857217217478E-5,300.0030212,300.0030212,-84446.5625,-84438.71875,57.0846756449868,20.5828117355926,24.047956,0,0,0,40,4449,300.0988,-84442.640625,,,,,,,,,,,,,0,,,,-0.0049,,,,,,300.0030212,,,,
,26745224.885,299.9920654,-79521.77734375,-0.00495610306281173,2.6672576608189E-6,1,0.999253354069792,40.0298881530762,1.99788772276737,19.1099997609854,-0.0560451302659735,-0.00983879850445653,0.25,-1.10753801356775E-5,-0.00495595422358147,-1.43085131274313E-5,299.9920654,299.9920654,-79524.2578125,-79519.296875,56.8900501436983,20.5934881105152,23.288654,0,0,0,40,4449,300.1029,-79521.77734375,,,,,,,,,,,,,0,,,,0.0049,,,,,,299.9920654,,,,
,26745419.905,299.9993286,-74648.52734375,-0.00485282556022234,2.86487218411536E-6,1,0.999253354069792,40.0298881530762,1.99751837248035,19.1099997609854,-0.0548679977768039,-0.00962940545535113,0.25,-1.06050581251899E-5,-0.00485267835573391,-1.37747478747163E-5,299.9993286,299.9993286,-74652.28125,-74644.7734375,56.8689461736791,20.5963328751786,24.047956,0,0,0,40,4449,300.1057,-74648.52734375,,,,,,,,,,,,,0,,,,0.0049,,,,,,299.9993286,,,,
,26745614.785,299.9970398,-69779.25,-0.00474202587489652,2.80742554692304E-6,1,0.999253354069792,40.0298881530762,1.99770606311543,19.1099997609854,-0.0536212732778801,-0.00940339056374676,0.25,-9.74035037407475E-6,-0.00474188248984231,-1.28414093527668E-5,299.9970398,299.9970398,-69785.46875,-69773.03125,56.963523224506,20.5958841058114,23.288654,0,0,0,40,4449,300.11455,-69779.25,,,,,,,,,,,,,0,,,,0,,,,,,299.9970398,,,,
,26745809.89,299.9911499,-64904.681640625,-0.00462390043132609,2.67008241455195E-6,1,0.999253354069792,40.0298881530762,1.99794379981201,19.1099997609854,-0.0522939695254462,-0.00915590936059711,0.25,-8.23164962470217E-6,-0.00462376209812385,-1.12590960156266E-5,299.9911499,299.9911499,-64910.84375,-64898.51953125,56.861911517006,20.5947938451026,24.427608,0,0,0,40,4449,300.1227,-64904.681640625,,,,,,,,,,,,,0,,,,0.00245,,,,,,299.9911499,,,,
,26746001.31,299.9974976,-60120.974609375,-0.00450021463202572,1.70507200879348E-6,1,0.999253354069792,40.0298881530762,1.99824040784953,19.1099997609854,-0.0509026113434907,-0.00891069808009302,0.25,-7.87042712533289E-6,-0.00450007875924872,-1.08202648442247E-5,299.9974976,299.9974976,-60123.5625,-60118.38671875,56.9596150819099,20.5894401096001,23.668306,0,0,0,40,4449,300.1324,-60120.974609375,,,,,,,,,,,,,0,,,,-0.0049,,,,,,299.9974976,,,,
,26746196.235,300.0027771,-55249.951171875,-0.00436475727995454,2.0407161963035E-6,1,0.999253354069792,40.0298881530762,1.99848477388035,19.1099997609854,-0.0493772938142194,-0.00863707087086379,0.25,-7.06280862088377E-6,-0.00436462473563137,-9.92726079023648E-6,300.0027771,300.0027771,-55251.19921875,-55248.703125,57.0573186468137,20.5871459706627,23.668306,0,0,0,40,4449,300.1326,-55249.951171875,,,,,,,,,,,,,0,,,,0,,,,,,300.0027771,,,,
,26746392.315,299.9970703,-50350.5078125,-0.00422213942811275,1.81308842057709E-6,1,0.999253354069792,40.0298881530762,1.99855328885324,19.1099997609854,-0.0477659107238656,-0.00835256811779829,0.25,-6.60257787694315E-6,-0.00422201195470228,-9.37648376432968E-6,299.9970703,299.9970703,-50351.75390625,-50349.26171875,56.7540467813522,20.5849497265077,23.668306,0,0,0,40,4449,300.152,-50350.5078125,,,,,,,,,,,,,0,,,,-0.00245,,,,,,299.9970703,,,,
,26746581.56,299.9955139,-45620.93359375,-0.00407075214195859,1.99060895367386E-6,1,0.999253354069792,40.0298881530762,1.99854814596357,19.1099997609854,-0.0460561086047547,-0.00803582632364951,0.25,-4.83979603863154E-6,-0.00407063020274198,-7.51723310220335E-6,299.9955139,299.9955139,-45627.26171875,-45614.60546875,57.075296102756,20.5848682014986,24.047956,0,0,0,40,4449,300.1547,-45620.93359375,,,,,,,,,,,,,0,,,,-0.00245,,,,,,299.9955139,,,,
,26746773.7,299.991333,-40819.826171875,-0.00390302616711925,1.68520442550468E-6,1,0.999253354069792,40.0298881530762,1.99842446112778,19.1099997609854,-0.044155791782573,-0.00770471689647882,0.25,-4.67676798643406E-6,-0.00390290956644689,-7.24662318849716E-6,299.991333,299.991333,-40824.65234375,-40815,57.0323065341983,20.5854388163361,23.668306,0,0,0,40,4449,300.1652,-40819.826171875,,,,,,,,,,,,,0,,,,-0.0049,,,,,,299.991333,,,,
,26746968.045,299.9983521,-35963.546875,-0.00371715197854657,1.29712689685259E-6,1,0.999253354069792,40.0298881530762,1.99855201482792,19.1099997609854,-0.0420550417323451,-0.00734091039189715,0.25,-4.68754043488491E-6,-0.0037170396068677,-7.13756789216609E-6,299.9983521,299.9983521,-35969.9453125,-35957.1484375,57.2269320354868,20.5830541628,23.668306,0,0,0,40,4449,300.177,-35963.546875,,,,,,,,,,,,,0,,,,-0.0049,,,,,,299.9983521,,,,
,26747160.69,299.9924011,-31149.923828125,-0.00351199294622156,1.20135727759611E-6,1,0.999253354069792,40.0298881530762,1.99874913244606,19.1099997609854,-0.0397382688378499,-0.00693290659877217,0.25,-4.11773259008972E-6,-0.00351188752007908,-6.43488645679397E-6,299.9924011,299.9924011,-31152.388671875,-31147.458984375,56.8001628639868,20.5816348522619,24.047956,0,0,0,40,4449,300.18885,-31149.923828125,,,,,,,,,,,,,0,,,,0,,,,,,299.9924011,,,,
,26747354.235,299.993927,-26314.10546875,-0.00327796731296433,1.25944053574171E-6,1,0.999253354069792,40.0298881530762,1.9988303784523,19.1099997609854,-0.0370939703766402,-0.00645806317193708,0.25,-2.68265196886318E-6,-0.00327786929971324,-4.84762573777601E-6,299.993927,299.993927,-26317.853515625,-26310.357421875,56.9650864815445,20.5817130003483,24.427608,0,0,0,40,4449,300.1931,-26314.10546875,,,,,,,,,,,,,0,,,,-0.00245,,,,,,299.993927,,,,
,26747545.4,299.9996948,-21536.875,-0.00301346000171957,1.2197511456347E-6,1,0.999253354069792,40.0298881530762,1.99880985242429,19.1099997609854,-0.0340979620707566,-0.00595108896374863,0.25,-3.71923954513578E-6,-0.00301336827644844,-5.71133429694756E-6,299.9996948,299.9996948,-21540.69140625,-21533.05859375,57.2558522906984,20.5797183401612,24.047956,0,0,0,40,4449,300.2057,-21536.875,,,,,,,,,,,,,0,,,,0.00245,,,,,,299.9996948,,,,
,26747738.91,299.9960022,-16701.310546875,-0.00269467585781029,1.58651333154998E-6,1,0.999253354069792,40.0298881530762,1.99890348347018,19.1099997609854,-0.0304924301206539,-0.00532053801743922,0.25,-3.21431813231699E-6,-0.00269459411557397,-4.99734220351117E-6,299.9960022,299.9960022,-16706.208984375,-16696.412109375,57.1237570709483,20.5789825674352,24.047956,0,0,0,40,4449,300.21025,-16701.310546875,,,,,,,,,,,,,0,,,,0.0049,,,,,,299.9960022,,,,
,26747928.25,299.993042,-11968.4282226563,-0.00230667286057043,9.51404273243997E-7,1,0.999253354069792,40.0298881530762,1.99888823283625,19.1099997609854,-0.0261021489937839,-0.00455167013545917,0.25,-2.50830059054339E-6,-0.00230660317314228,-4.03592981156031E-6,299.993042,299.993042,-11973.3779296875,-11963.478515625,57.210517836583,20.576836323864,23.668306,0,0,0,40,4449,300.2118,-11968.4282226563,,,,,,,,,,,,,0,,,,0.00245,,,,,,299.993042,,,,
,26748114.555,299.9953308,-7314.28466796875,-0.00180693553339682,7.01663428865774E-7,1,0.999253354069792,40.0298881530762,1.99896690403819,19.1099997609854,-0.0204479902466337,-0.00356529482175155,0.25,-1.92896286525052E-6,-0.00180688073441121,-3.12656132211457E-6,299.994812,299.9958496,-7320.47998046875,-7308.08935546875,57.1065612435253,20.5763292155147,23.668306,0,0,0,40,4449,300.2179,-7314.28466796875,,,,,,,,,,,,,0,,,,-0.0049,,,,,,299.9953308,,,,
,26748300.735,299.9972534,-2660.97717285156,-0.00104652806031288,5.74160351843692E-7,1,0.999253354069792,40.0298881530762,1.99918510158532,19.1099997609854,-0.0118442231365303,-0.00206473653058538,0.25,-1.08137660915214E-6,-0.00104649623240237,-1.77544719194958E-6,299.9972534,299.9972534,-2664.63305664062,-2657.3212890625,56.7157469839098,20.5742060936289,23.288654,0,0,0,40,4449,300.22905,-2660.97717285156,,,,,,,,,,,,,0,,,,0,,,,,,299.9972534,,,,
,26748478.155,300.0001221,1771.89434814453,0.000828380448852877,5.21455227739261E-7,1,0.999253354069792,40.0298881530762,1.99900279425813,19.1099997609854,0.00937606512680874,0.00162511736547738,0.25,5.32753506186166E-8,0.000828355697236811,6.02749278686236E-7,300.0001221,300.0001221,1767.26501464844,1776.52368164062,57.004167907506,20.5749667714791,24.047956,0,0,0,40,4449,300.23125,1771.89434814453,,,,,,,,,,,,,0,,,,0,,,,,,300.0001221,,,,
,26748662.08,300.0045471,6368.19067382813,0.00167803316721894,6.11943627488269E-7,1,0.999253354069792,40.0298881530762,1.99911829029355,19.1099997609854,0.0189918376497911,0.00330431869920152,0.25,1.18387700626862E-6,0.00167798211360663,2.29617956962435E-6,300.0045471,300.0045471,6366.8076171875,6369.57373046875,57.1769078102561,20.5721768949909,23.668306,0,0,0,40,4449,300.2289,6368.19067382813,,,,,,,,,,,,,0,,,,-0.00245,,,,,,300.0045471,,,,
,26748846.685,299.9987793,10982.5444335938,0.0022108997941685,9.27945295836537E-7,1,0.999253354069792,40.0298881530762,1.99898216815389,19.1099997609854,0.0250219623405028,0.00434869209687783,0.25,1.15048348867846E-6,0.00221083335568992,2.61493315755106E-6,299.9987793,299.9987793,10980.0556640625,10985.033203125,57.2738297466407,20.5739459961574,24.047956,0,0,0,40,4449,300.2197,10982.5444335938,,,,,,,,,,,,,0,,,,0,,,,,,299.9987793,,,,
,26749032.945,300.0064392,15637.4848632812,0.00261181516524705,1.40993660098665E-6,1,0.999253354069792,40.0298881530762,1.99904296185057,19.1099997609854,0.0295594163469159,0.00514189127920796,0.25,1.75614632020833E-6,0.00261173582979124,3.48468023186615E-6,300.0059814,300.006897,15634.7783203125,15640.19140625,56.8353361473522,20.5760309196764,23.668306,0,0,0,40,4449,300.2178,15637.4848632812,,,,,,,,,,,,,0,,,,0,,,,,,300.0064392,,,,
,26749219.78,300.0090332,20306.01171875,0.00293505630768616,1.15013972841643E-6,1,0.999253354069792,40.0298881530762,1.99903106178219,19.1099997609854,0.0332147466602337,0.005794303319258,0.25,3.39575359322453E-6,0.00293496609517474,5.33645226199359E-6,300.0090332,300.0090332,20302.078125,20309.9453125,57.1323549846599,20.5730513811548,24.047956,0,0,0,40,4449,300.21215,20306.01171875,,,,,,,,,,,,,0,,,,-0.00245,,,,,,300.0090332,,,,
,26749408.14,300.0097961,25013.71484375,0.00320873947422535,1.25605658278758E-6,1,0.999253354069792,40.0298881530762,1.99900356500223,19.1099997609854,0.0363107868899477,0.00633819263431081,0.25,4.03906567870335E-6,0.00320864072756308,6.15872147667756E-6,300.0094604,300.0101318,25010.005859375,25017.423828125,56.8564401173714,20.574024186098,23.668306,0,0,0,40,4449,300.2081,25013.71484375,,,,,,,,,,,,,0,,,,-0.00245,,,,,,300.0097961,,,,
,26749599.945,300.0030212,29806.8037109375,0.00344840057394701,2.00016497187612E-6,1,0.999253354069792,40.0298881530762,1.99907961739543,19.1099997609854,0.0390253023432505,0.0068058953237731,0.25,3.81754961684195E-6,0.00344829583627126,6.09334342984076E-6,300.0030212,300.0030212,29800.51171875,29813.095703125,56.6446187886598,20.5717809154499,24.427608,0,0,0,40,4449,300.1962,29806.8037109375,,,,,,,,,,,,,0,,,,0,,,,,,300.0030212,,,,
,26749794.7,300.0059509,34673.16015625,0.0036624425091045,1.81375591835497E-6,1,0.999253354069792,40.0298881530762,1.99902091676195,19.1099997609854,0.0414447075794398,0.00723811184005899,0.25,4.93851405920541E-6,0.00366233052556111,7.35307669580216E-6,300.0059509,300.0059509,34670.30859375,34676.01171875,56.6625962446021,20.5721988756005,24.047956,0,0,0,40,4449,300.1859,34673.16015625,,,,,,,,,,,,,0,,,,0,,,,,,300.0059509,,,,
,26749988.085,300.0083618,39506.263671875,0.00385164999184992,1.25310684013499E-6,1,0.999253354069792,40.0298881530762,1.99915120776605,19.1099997609854,0.0435896762382617,0.00760581795963931,0.25,4.60447278630507E-6,0.00385153251949711,7.14113040165233E-6,300.0083618,300.0083618,39502.5078125,39510.01953125,56.9447641400445,20.5703248021886,23.668306,0,0,0,40,4449,300.1776,39506.263671875,,,,,,,,,,,,,0,,,,0.00245,,,,,,300.0083618,,,,
,26750181.73,300.0073853,44345.326171875,0.0040268889205104,1.94472637232503E-6,1,0.999253354069792,40.0298881530762,1.99905796575787,19.1099997609854,0.0455713461006512,0.00794868115674946,0.25,4.56702986368518E-6,0.00402676665805364,7.21633860102289E-6,300.0073853,300.0073853,44340.4140625,44350.23828125,56.7696793517368,20.5713040111946,24.047956,0,0,0,40,4449,300.1611,44345.326171875,,,,,,,,,,,,,0,,,,0,,,,,,300.0073853,,,,
,26750373.38,300.0069275,49134.435546875,0.00418106342012476,2.15747453211254E-6,1,0.999253354069792,40.0298881530762,1.99925748804454,19.1099997609854,0.0473193135023043,0.00826129182256609,0.25,5.40729023118284E-6,0.00418093637766823,8.15503294528301E-6,300.0069275,300.0069275,49130.41796875,49138.453125,56.5594212800637,20.567375511974,23.668306,0,0,0,40,4449,300.15175,49134.435546875,,,,,,,,,,,,,0,,,,0.00245,,,,,,300.0069275,,,,
,26750566.05,300.0119324,53949.392578125,0.0043261733819791,2.2536488903001E-6,1,0.999253354069792,40.0298881530762,1.99916731905795,19.1099997609854,0.0489632601544977,0.00852586575281265,0.25,3.67425950967495E-6,0.00432604270136113,6.51424273578004E-6,300.0119324,300.0119324,53945.55859375,53953.2265625,56.7188734979868,20.568122586047,23.668306,0,0,0,40,4449,300.14455,53949.392578125,,,,,,,,,,,,,0,,,,0.00245,,,,,,300.0119324,,,,
,26750757.82,300.0043335,58740.93359375,0.00446313514923718,2.27094701602185E-6,1,0.999253354069792,40.0298881530762,1.99914673915522,19.1099997609854,0.0505084996779254,0.00882111563207305,0.25,6.03912063592428E-6,0.00446300037951167,8.96557006424185E-6,300.0043335,300.0043335,58738.55078125,58743.31640625,56.8728543162753,20.5690208345608,24.047956,0,0,0,40,4449,300.14295,58740.93359375,,,,,,,,,,,,,0,,,,0.00245,,,,,,300.0043335,,,,
,26750954.52,300.006134,63658.501953125,0.00458889581254685,1.77377457091135E-6,1,0.999253354069792,40.0298881530762,1.99923312288444,19.1099997609854,0.0519326226423773,0.00907714378575445,0.25,6.83954674576787E-6,0.00458875684427683,9.84502456075363E-6,300.006134,300.006134,63653.734375,63663.26953125,56.6008475915829,20.5703961918934,23.668306,0,0,0,40,4449,300.12375,63658.501953125,,,,,,,,,,,,,0,,,,0,,,,,,300.006134,,,,
,26751151.03,300.0063477,68567.64453125,0.00471084840989675,2.7095331638874E-6,1,0.999253354069792,40.0298881530762,1.99916303523089,19.1099997609854,0.0533100437111037,0.00932348088152456,0.25,7.50362156778641E-6,0.00471070572993134,1.05852737958691E-5,300.0063477,300.0063477,68566.1484375,68569.140625,57.0158923352945,20.5706446168603,24.047956,0,0,0,40,4449,300.11595,68567.64453125,,,,,,,,,,,,,0,,,,0.00245,,,,,,300.0063477,,,,
,26751345.805,300.0141296,73435.08984375,0.00482165433866155,2.14372218102019E-6,1,0.999253354069792,40.0298881530762,1.9992022377476,19.1099997609854,0.054569255463256,0.00951829344054893,0.25,5.50482726637363E-6,0.0048215087107348,8.65532671402153E-6,300.0141296,300.0141296,73431.1796875,73439,56.8275198621599,20.569389150895,24.427608,0,0,0,40,4449,300.1012,73435.08984375,,,,,,,,,,,,,0,,,,0,,,,,,300.0141296,,,,
,26751540.86,300.0033264,78311.91015625,0.0049282219787972,2.39576032900843E-6,1,0.999253354069792,40.0298881530762,1.99921466514216,19.1099997609854,0.0557718721405822,0.00975079497179765,0.25,7.57986319382171E-6,0.00492807412473044,1.07959932071396E-5,300.0033264,300.0033264,78309.296875,78314.5234375,56.8392442899483,20.567936363448,23.668306,0,0,0,40,4449,300.09575,78311.91015625,,,,,,,,,,,,,0,,,,0,,,,,,300.0033264,,,,
,26751735.56,300.0111084,83177.8515625,0.00502906553483142,2.21210728540199E-6,1,0.999253354069792,40.0298881530762,1.9991659846102,19.1099997609854,0.0569112353908456,0.00995315859997234,0.25,8.01021291885975E-6,0.00502891342065961,1.12882531262435E-5,300.0111084,300.0111084,83172.875,83182.828125,56.7931282073137,20.5668342021871,24.427608,0,0,0,40,4449,300.0767,83177.8515625,,,,,,,,,,,,,0,,,,0.0049,,,,,,300.0111084,,,,
,26751922.325,300.0090332,87845.65625,0.00512190272303606,2.81396865280174E-6,1,0.999253354069792,40.0298881530762,1.9991806052608,19.1099997609854,0.0579597572447777,0.0101512804106554,0.25,9.42655660805634E-6,0.00512174772035336,1.27610390721434E-5,300.0090332,300.0090332,87843.1171875,87848.1953125,56.7509202672752,20.5685927534006,24.427608,0,0,0,40,4449,300.0738,87845.65625,,,,,,,,,,,,,0,,,,0,,,,,,300.0090332,,,,
,26752126.705,299.9998779,87536.55859375,0.00511354849126332,2.77420356897043E-6,1,0.999253354069792,40.0298881530762,1.99904787912456,19.1099997609854,0.0578671390340993,0.0101019553525965,0.25,6.57225673073512E-6,0.0051133972320626,9.90182546443375E-6,299.9998779,299.9998779,87533.9765625,87539.140625,56.7923465787945,20.5706406591018,24.047956,0,0,0,40,4449,300.06065,87536.55859375,,,,,,,,,,,,,0,,,,0.00245,,,,,,299.9998779,,,,
,26752312.255,299.9967041,82899.66796875,0.00502478705619168,2.41742541361746E-6,1,0.999253354069792,40.0298881530762,1.99904297901921,19.1099997609854,0.0568632110152396,0.0099227411336682,0.25,6.11498871259661E-6,0.0050246388724851,9.39063339446344E-6,299.9967041,299.9967041,82895.8671875,82903.46875,56.7962547213906,20.5686132122486,24.047956,0,0,0,40,4449,300.0691,82899.66796875,,,,,,,,,,,,,0,,,,0.0049,,,,,,299.9967041,,,,
,26752507.9,299.9946899,78009.42578125,0.00492602675291621,2.71818989204935E-6,1,0.999253354069792,40.0298881530762,1.99906120045726,19.1099997609854,0.0557459649449708,0.00972840917580672,0.25,6.04479087218627E-6,0.00492588144560635,9.26005839408442E-6,299.9946899,299.9946899,78006.8203125,78012.03125,56.6500901882945,20.5718038543954,23.668306,0,0,0,40,4449,300.07385,78009.42578125,,,,,,,,,,,,,0,,,,0,,,,,,299.9946899,,,,
,26752701.835,299.9904175,73161.140625,0.00481819325529929,2.44762761371551E-6,1,0.999253354069792,40.0298881530762,1.9991120784939,19.1099997609854,0.0545232620803728,0.00953715959478,0.25,7.80629401207715E-6,0.00481805029635156,1.0954840427344E-5,299.9904175,299.9904175,73158.5625,73163.71875,56.719655126506,20.5711288487968,24.427608,0,0,0,40,4449,300.0891,73161.140625,,,,,,,,,,,,,0,,,,-0.0049,,,,,,299.9904175,,,,
,26752893.125,299.9959412,68380.8046875,0.00470570669414209,2.58106063137658E-6,1,0.999253354069792,40.0298881530762,1.99915963607516,19.1099997609854,0.0532535990166264,0.00930285592481277,0.25,6.572917358142E-6,0.00470556648915063,9.65171702819122E-6,299.9959412,299.9959412,68378.2421875,68383.3671875,56.7571732954291,20.5712212608879,24.427608,0,0,0,40,4449,300.08785,68380.8046875,,,,,,,,,,,,,0,,,,0,,,,,,299.9959412,,,,
,26753080.98,299.9926147,63685.16796875,0.00459092599832287,2.11184841851933E-6,1,0.999253354069792,40.0298881530762,1.99896476708283,19.1099997609854,0.0519478587210939,0.00908640483720973,0.25,7.40817824811258E-6,0.00459078880964369,1.04151729626035E-5,299.9926147,299.9926147,63680.3515625,63689.984375,56.9150622563137,20.5743576630889,23.668306,0,0,0,40,4449,300.10505,63685.16796875,,,,,,,,,,,,,0,,,,0.00245,,,,,,299.9926147,,,,
,26753268.86,299.99029545,58991.19140625,0.00446870723630936,2.24377676539703E-6,1,0.999253354069792,40.0298881530762,1.9990400250297,19.1099997609854,0.0505737282701542,0.00880443356673594,0.25,3.63904780702676E-6,0.00446857611423744,6.56940612090019E-6,299.9900208,299.9905701,58987.49609375,58994.88671875,56.6829185861022,20.5729385335114,23.668306,0,0,0,40,4449,300.11135,58991.19140625,,,,,,,,,,,,,0,,,,0.00245,,,,,,299.99029545,,,,
,26753463.24,299.9923096,54133.6484375,0.00433364454174544,2.29726061057454E-6,1,0.999253354069792,40.0298881530762,1.99913035669307,19.1099997609854,0.049045041801631,0.00855167285521193,0.25,4.67229212602553E-6,0.00433351601824505,7.51738753630285E-6,299.9923096,299.9923096,54130.19140625,54137.10546875,56.8431524325445,20.5751982945578,24.427608,0,0,0,40,4449,300.1123,54133.6484375,,,,,,,,,,,,,0,,,,-0.00245,,,,,,299.9923096,,,,
,26753653.255,299.9873962,49386.3359375,0.00419092700360571,2.14755373820165E-6,1,0.999253354069792,40.0298881530762,1.99920463549376,19.1099997609854,0.0474317516076463,0.00826920791572477,0.25,4.4156478011347E-6,0.00419080326616361,7.16986075659956E-6,299.9873962,299.9873962,49382.46484375,49390.20703125,56.831428004756,20.5754738900915,23.668306,0,0,0,40,4449,300.14085,49386.3359375,,,,,,,,,,,,,0,,,,-0.00245,,,,,,299.9873962,,,,
,26753845.33,299.9882202,44585.158203125,0.00403554517002856,1.60092323655342E-6,1,0.999253354069792,40.0298881530762,1.99910610930948,19.1099997609854,0.0456690211748017,0.00797384503974705,0.25,5.27387619436127E-6,0.00403542497339084,7.92876600120916E-6,299.9882202,299.9882202,44580.359375,44589.95703125,56.8290831191983,20.5759427134818,24.047956,0,0,0,40,4449,300.1564,44585.158203125,,,,,,,,,,,,,0,,,,0,,,,,,299.9882202,,,,
,26754039.19,299.993988,39740.720703125,0.00386279579155684,1.75057678811448E-6,1,0.999253354069792,40.0298881530762,1.99918122544735,19.1099997609854,0.0437184436198749,0.00761651342437718,0.25,3.60826528320002E-6,0.00386268063644738,6.15232122681057E-6,299.993988,299.993988,39734.4609375,39746.98046875,56.9564885678329,20.5762238744359,24.047956,0,0,0,40,4449,300.16155,39740.720703125,,,,,,,,,,,,,0,,,,0.00245,,,,,,299.993988,,,,
,26754226.835,299.997345,35052.27734375,0.00367906760469849,1.49846088565208E-6,1,0.999253354069792,40.0298881530762,1.99916144620371,19.1099997609854,0.0416360905438678,0.00726888809643355,0.25,4.73389394967004E-6,0.00367895640063774,7.15941760453777E-6,299.997345,299.997345,35049.765625,35054.7890625,56.8048526351022,20.5782522363936,24.427608,0,0,0,40,4449,300.1654,35052.27734375,,,,,,,,,,,,,0,,,,-0.0049,,,,,,299.997345,,,,
,26754416.59,299.99615475,30309.9248046875,0.00347311062953503,1.46863199168979E-6,1,0.999253354069792,40.0298881530762,1.99912910813937,19.1099997609854,0.0393063201202137,0.006852302327688,0.25,3.62185658666326E-6,0.00347300614987729,5.91391474138701E-6,299.9953613,299.9969482,30307.376953125,30312.47265625,56.7642079521022,20.5779998709857,24.047956,0,0,0,40,4449,300.17435,30309.9248046875,,,,,,,,,,,,,0,,,,-0.0049,,,,,,299.99615475,,,,
,26754608.135,299.9902954,25523.78515625,0.00323710758126129,1.03729336673905E-6,1,0.999253354069792,40.0298881530762,1.99910603004399,19.1099997609854,0.0366347949016568,0.00638778689256876,0.25,3.47772494000099E-6,0.00323701062437806,5.61613400474328E-6,299.9902954,299.9902954,25517.49609375,25530.07421875,57.1362631272561,20.5789598493022,24.047956,0,0,0,40,4449,300.1821,25523.78515625,,,,,,,,,,,,,0,,,,0.00245,,,,,,299.9902954,,,,
,26754798.315,299.9865417,20769.587890625,0.002966238842002,1.01913027753763E-6,1,0.999253354069792,40.0298881530762,1.99936601652484,19.1099997609854,0.0335743026422856,0.00584940243091288,0.25,2.77810699856324E-6,0.0029661505082309,4.73935549428341E-6,299.9865417,299.9865417,20764.5,20774.67578125,57.0612267894099,20.5766734212872,23.668306,0,0,0,40,4449,300.20055,20769.587890625,,,,,,,,,,,,,0,,,,0.00245,,,,,,299.9865417,,,,
,26754987.08,299.997406,16054.0029296875,0.00264695954521289,7.44626813363533E-7,1,0.999253354069792,40.0298881530762,1.99936686238025,19.1099997609854,0.029960009017999,0.0052222660798254,0.25,2.69658580073206E-6,0.00264687939738194,4.44831958437499E-6,299.997406,299.997406,16050.3564453125,16057.6494140625,56.8798889729483,20.5762519883799,24.047956,0,0,0,40,4449,300.20255,16054.0029296875,,,,,,,,,,,,,0,,,,0.00245,,,,,,299.997406,,,,
,26755177.04,299.9946899,11306.5297851562,0.00224520511022094,7.53914375324336E-7,1,0.999253354069792,40.0298881530762,1.9992733383977,19.1099997609854,0.0254125926039047,0.00442346364722925,0.25,1.75854532874146E-6,0.00224513758352155,3.24565916892347E-6,299.9946899,299.9946899,11303.01953125,11310.0400390625,57.1096877576022,20.5788327780567,24.427608,0,0,0,40,4449,300.2123,11306.5297851562,,,,,,,,,,,,,0,,,,0,,,,,,299.9946899,,,,
,26755362.91,299.997467,6662.59497070312,0.00172122602467093,5.47912275539063E-7,1,0.999253354069792,40.0298881530762,1.99923235817813,19.1099997609854,0.0194809352262794,0.00339429730316021,0.25,1.63298895030533E-6,0.00172117381299143,2.77395660419212E-6,299.997467,299.997467,6660.279296875,6664.91064453125,56.8157954343714,20.5781734760015,23.668306,0,0,0,40,4449,300.2068,6662.59497070312,,,,,,,,,,,,,0,,,,0,,,,,,299.997467,,,,
,26755545.71,299.9924927,2093.61071777344,0.000915467646610368,5.28913387682928E-7,1,0.999253354069792,40.0298881530762,1.99931977099434,19.1099997609854,0.0103627133158076,0.00179983497361676,0.25,3.76695056315706E-7,0.000915440334606932,9.83907422996611E-7,299.9924927,299.9924927,2089.80737304687,2097.4140625,57.1769078102561,20.5777310822849,24.427608,0,0,0,40,4449,300.2287,2093.61071777344,,,,,,,,,,,,,0,,,,-0.00245,,,,,,299.9924927,,,,
,26755629.575,300.0010376,-0.418653756380081,-8.08846712054858E-6,5.17991298448512E-7,1,0.999253354069792,40.0298881530762,1.9993690893997,19.1099997609854,-9.15452123946272E-5,-1.59890949527626E-5,0.25,-1.09741908594576E-8,-8.08821812535468E-6,-1.63403086911811E-8,300.0007935,300.0012817,-0.456713199615479,-0.380594313144684,56.8751992018329,20.5790268051282,24.427608,0,0,0,40,4417,300.2176,-0.418653756380081,,,,,,,,,,,,,0,,,,-0.00245,,,,,,300.0010376,,,,