File: data/monolayers/nanoparticles/Ol_CoFe_C/vsm/Backup/rawdata/DD172_6_HYST_50K.DAT
[Header]
; VSM Data File (default extension .dat)
; Copyright (c) 2003-2013, Quantum Design, Inc. All rights reserved.
TITLE,
FILEOPENTIME,26804591.06,11/07/2018,1:43 pm
BYAPP,VSM,2.0,2.0
INFO,PPMS VSM Option Release 1.4.10 Build 1,APPNAME
INFO,Quantum Design Linear Motor Servo Controller,MOTOR_MODULE_NAME
INFO,3101-100 M1,MOTOR_HW_VERSION
INFO,MMC1014,MOTOR_SERIAL_NUMBER
INFO,SRV No X-over 01.03.11,MOTOR_SOFTWARE_VERSION
INFO,Quantum Design VSM Detection Module,VSM_MODULE_NAME
INFO,3101-150 F0,VSM_HW_VERSION
INFO,VSM707,VSM_SERIAL_NUMBER
INFO,VSM No X-over 01.02.05 May 20 2008 13:51:47,VSM_SOFTWARE_VERSION
INFO,704,PREAMP_SERIAL_NUMBER
INFO,822,COIL_SERIAL_NUMBER
INFO,0,MOMENT_UNITS
INFO,CoFe2O4 DD67,SAMPLE_MATERIAL
INFO,Colloidal Crystal,SAMPLE_COMMENT
INFO,31.86,SAMPLE_MASS
INFO,,SAMPLE_VOLUME
INFO,,SAMPLE_MOLECULAR_WEIGHT
INFO,,SAMPLE_SIZE
INFO,,SAMPLE_SHAPE
DATATYPE,COMMENT,1
DATATYPE,TIME,2
STARTUPAXIS,X,2
STARTUPAXIS,Y1,5
[Data]
Comment,Time Stamp (sec),Temperature (K),Magnetic Field (Oe),Moment (emu),M. Std. Err. (emu),Transport Action,Averaging Time (sec),Frequency (Hz),Peak Amplitude (mm),Center Position (mm),Coil Signal' (mV),Coil Signal" (mV),Range (mV),M. Quad. Signal (emu),M. Raw' (emu),M. Raw" (emu),Min. Temperature (K),Max. Temperature (K),Min. Field (Oe),Max. Field (Oe),Mass (grams),Motor Lag (deg),Pressure (Torr),VSM Status (code),Motor Status (code),Measure Status (code),Measure Count,PPMS Status (code),System Temp. (K),System Field (Oe),Sample Position (deg),Bridge 1 Resistance (ohms),Bridge 1 Excitation (에),Bridge 2 Resistance (ohms),Bridge 2 Excitation (에),Bridge 3 Resistance (ohms),Bridge 3 Excitation (에),Bridge 4 Resistance (ohms),Bridge 4 Excitation (에),Signal 1 Vin (V),Signal 2 Vin (V),Digital Inputs (code),Drive 1 Iout (mA),Drive 1 Ipower (W),Drive 2 Iout (mA),Drive 2 Ipower (W),Pressure (),Map 20 (),Map 21 (),Map 22 (),Map 23 (),Map 24 (),Map 25 (),Map 26 (),Map 27 (),Map 28 (),Map 29 ()
,26804606.7,50.0116119,-0.289251685142517,,,2,,,,20.3600000688434,,,,,,,50.0116119,50.0116119,-0.289251685142517,-0.289251685142517,,,17.214239,,,,-99999999,4369,50.0136,-0.289251685142517,,,,,,,,,,,,,,,,,,,,,,,50.0116119,,,,
,26804846.95,50.0005951,4501.5537109375,0.00127026842789012,3.54406907187549E-7,1,0.999253354069792,40.0298881530762,1.99695924916648,20.3499998897314,0.0143312349568696,0.0026445281384398,0.25,5.25716199716255E-6,0.00126975015583277,1.47079630278067E-5,50.0005951,50.0005951,4498.9560546875,4504.1513671875,56.6547799594098,20.5956768295844,16.834587,0,0,0,40,4449,50.0095,4501.5537109375,,,,,,,,,,,,,0,,,,0,,,,,,50.0005951,,,,
,26805029.39,50.000248,9060.2119140625,0.00174275340221017,4.27671527107786E-7,1,0.999253354069792,40.0298881530762,1.99683953271248,20.3499998897314,0.0196641951482364,0.00363409923605006,0.25,7.68903633269907E-6,0.00174243242930045,2.06533019568498E-5,50.000248,50.000248,9056.3974609375,9064.0263671875,57.0487207331022,20.6024233219792,17.214239,0,0,0,40,4449,50.0139,9060.2119140625,,,,,,,,,,,,,0,,,,0.00245,,,,,,50.000248,,,,
,26805218.145,49.9997063,13776.7631835938,0.0022450670694697,4.03162076072969E-7,1,0.999253354069792,40.0298881530762,1.99700781688504,20.3499998897314,0.025340844747046,0.00468012695374354,0.25,9.66949265508435E-6,0.00224521094529324,2.63504176888479E-5,49.9997063,49.9997063,13774.22265625,13779.3037109375,57.0080760501022,20.600560794845,17.214239,0,0,0,40,4449,50.006,13776.7631835938,,,,,,,,,,,,,0,,,,-0.00245,,,,,,49.9997063,,,,
,26805403.875,50.0004997,18417.5908203125,0.00272864577415261,5.36387541710068E-7,1,0.999253354069792,40.0298881530762,1.99703064825717,20.3499998897314,0.0308065974123092,0.00569367348678926,0.25,1.21593387362974E-5,0.00272951010218933,3.23849739613231E-5,50.0004997,50.0004997,18413.869140625,18421.3125,57.146424298006,20.6017687947207,17.593889,0,0,0,40,4449,50.0061,18417.5908203125,,,,,,,,,,,,,0,,,,-0.0049,,,,,,50.0004997,,,,
,26805590.67,50.0016289,23086.7607421875,0.00318868844801667,5.4124289381961E-7,1,0.999253354069792,40.0298881530762,1.99698633194453,20.3499998897314,0.0360084811719835,0.00665822509562722,0.25,1.45740101802166E-5,0.00319051879640478,3.81237728094731E-5,50.0016289,50.0016289,23081.599609375,23091.921875,57.3379232852176,20.6040920072603,17.214239,0,0,0,40,4449,50.0068,23086.7607421875,,,,,,,,,,,,,0,,,,0.00245,,,,,,50.0016289,,,,
,26805775.89,50.0023346,27714.685546875,0.00360502198930045,5.92742011434536E-7,1,0.999253354069792,40.0298881530762,1.99707734459866,20.3499998897314,0.0407209369279193,0.00753588908677224,0.25,1.71544174757935E-5,0.00360800065686691,4.36518748245316E-5,50.0023346,50.0023346,27712.357421875,27717.013671875,57.1284468420637,20.6026791897406,17.214239,0,0,0,40,4449,50.00195,27714.685546875,,,,,,,,,,,,,0,,,,0,,,,,,50.0023346,,,,
,26805963.165,50.0018158,32395.8388671875,0.00397249864144308,8.63534642861835E-7,1,0.999253354069792,40.0298881530762,1.99705627964357,20.3499998897314,0.0448825274343059,0.00830752197617642,0.25,1.92192021658131E-5,0.00397679240349941,4.82406928684348E-5,50.0018158,50.0018158,32394.369140625,32397.30859375,56.8783257159099,20.6042400350717,17.214239,0,0,0,40,4449,50.0042,32395.8388671875,,,,,,,,,,,,,0,,,,-0.00245,,,,,,50.0018158,,,,
,26806149.65,50.0014305,37055.33984375,0.00429770321591495,7.49528030059103E-7,1,0.999253354069792,40.0298881530762,1.99708668740399,20.3499998897314,0.0485684431940818,0.00899567541662604,0.25,2.15344755981108E-5,0.0043034060335997,5.27090394083284E-5,50.0014305,50.0014305,37051.6171875,37059.0625,57.1401712698522,20.6048985785814,17.214239,0,0,0,40,4449,49.9988,37055.33984375,,,,,,,,,,,,,0,,,,0,,,,,,50.0014305,,,,
,26806335.245,49.9997864,41693.49609375,0.00458144652138349,9.93702430562423E-7,1,0.999253354069792,40.0298881530762,1.99721703429055,20.3499998897314,0.0517918024625759,0.00958624753527889,0.25,2.26887358205496E-5,0.00458863035770023,5.56501815964543E-5,49.9997864,49.9997864,41687.28125,41699.7109375,57.1440794124484,20.6038342911597,17.593889,0,0,0,40,4449,49.9955,41693.49609375,,,,,,,,,,,,,0,,,,-0.00245,,,,,,49.9997864,,,,
,26806523.025,50.0018578,46385.888671875,0.00483429867254346,1.04788210695337E-6,1,0.999253354069792,40.0298881530762,1.99725117406921,20.3499998897314,0.0546639189835106,0.0101185643217555,0.25,2.43381184827202E-5,0.00484302456717041,5.87963517665236E-5,50.0018578,50.0018578,46382.1796875,46389.59765625,57.0268351345637,20.6035336819062,17.593889,0,0,0,40,4449,49.99815,46385.888671875,,,,,,,,,,,,,0,,,,0.0049,,,,,,50.0018578,,,,
,26806706.87,50.0014114,50980.08984375,0.00505710973566839,7.64130257407104E-7,1,0.999253354069792,40.0298881530762,1.99720480853781,20.3499998897314,0.057197056962558,0.0105748608940284,0.25,2.47546146112322E-5,0.00506737697413881,6.04405763683639E-5,50.0014114,50.0014114,50977.5859375,50982.59375,57.1690915250637,20.6049032942922,17.593889,0,0,0,40,4449,49.9971,50980.08984375,,,,,,,,,,,,,0,,,,0.00245,,,,,,50.0014114,,,,
,26806893.545,50.0018501,55644.998046875,0.00525967668481875,9.27792807361522E-7,1,0.999253354069792,40.0298881530762,1.99734664611561,20.3499998897314,0.0595065459945992,0.0109938382688603,0.25,2.54796652494138E-5,0.00527151029883419,6.21889561295121E-5,50.0018501,50.0018501,55640.07421875,55649.921875,57.1847240954484,20.6026556918767,17.214239,0,0,0,40,4449,49.994,55644.998046875,,,,,,,,,,,,,0,,,,0,,,,,,50.0018501,,,,
,26807080.7,50.0021477,60322.267578125,0.00544492493160311,8.81180584402591E-7,1,0.999253354069792,40.0298881530762,1.99732181898908,20.3499998897314,0.0616145508309833,0.0113837153425868,0.25,2.68708773249771E-5,0.00545832328202763,6.44290671312621E-5,50.0018425,50.0024529,60317.2421875,60327.29296875,57.0815491309099,20.6039098313443,17.973541,0,0,0,40,4449,49.991,60322.267578125,,,,,,,,,,,,,0,,,,-0.0049,,,,,,50.0021477,,,,
,26807264.545,50.0016594,64916.87890625,0.00560774121346682,1.22651861599233E-6,1,0.999253354069792,40.0298881530762,1.99726584479098,20.3499998897314,0.0634711574242319,0.0117080610973234,0.25,2.65636433953884E-5,0.00562267044979528,6.47689338425695E-5,50.0016594,50.0016594,64913.15625,64920.6015625,57.1268835850253,20.6013003165924,17.593889,0,0,0,40,4449,49.9933,64916.87890625,,,,,,,,,,,,,0,,,,0.00245,,,,,,50.0016594,,,,
,26807456.08,50.0000916,69703.34765625,0.0057649169785615,1.48811586174082E-6,1,0.999253354069792,40.0298881530762,1.99733611506893,20.3499998897314,0.0652606498120122,0.0120646925572187,0.25,3.01107658554494E-5,0.0057813938777521,6.88709768556553E-5,50.0000916,50.0000916,69698.2734375,69708.421875,57.1315733561406,20.5991890604238,17.593889,0,0,0,40,4449,49.9921,69703.34765625,,,,,,,,,,,,,0,,,,0,,,,,,50.0000916,,,,
,26807644.025,50.002491,74401.23828125,0.00590951705043333,1.21998150756962E-6,1,0.999253354069792,40.0298881530762,1.99739019385553,20.3499998897314,0.066915216410305,0.0123503425930011,0.25,2.96914601271517E-5,0.00592751786734812,6.88786672176794E-5,50.002491,50.002491,74398.734375,74403.7421875,56.9596150819099,20.599690980122,17.593889,0,0,0,40,4449,49.9899,74401.23828125,,,,,,,,,,,,,0,,,,-0.00245,,,,,,50.002491,,,,
,26807826.75,50.0008583,78967.79296875,0.00603704469139135,1.0538282371934E-6,1,0.999253354069792,40.0298881530762,1.99738257294768,20.3499998897314,0.068368070266374,0.0126340620529232,0.25,3.22218210570718E-5,0.00605646804696537,7.17111135163141E-5,50.0008583,50.0008583,78964.1875,78971.3984375,57.1964485232368,20.5982443134388,17.593889,0,0,0,40,4449,49.9878,78967.79296875,,,,,,,,,,,,,0,,,,0.00245,,,,,,50.0008583,,,,
,26808014.835,50.0016747,83667.41015625,0.00616083084271176,9.87016150360362E-7,1,0.999253354069792,40.0298881530762,1.99735988262583,20.3499998897314,0.0697861060090817,0.0128663983752343,0.25,3.09424437423661E-5,0.00618171332064612,7.0648760763395E-5,50.0016747,50.0016747,83665.0546875,83669.765625,56.963523224506,20.599175739513,17.973541,0,0,0,40,4449,49.98515,83667.41015625,,,,,,,,,,,,,0,,,,0,,,,,,50.0016747,,,,
,26808196.255,50.0028496,88203.08984375,0.00626964758499989,1.30503293424537E-6,1,0.999253354069792,40.0298881530762,1.99736039632533,20.3499998897314,0.0710302737909293,0.0130928801498974,0.25,3.1832273680403E-5,0.00629187820057962,7.1658961631398E-5,50.0028496,50.0028496,88198.125,88208.0546875,57.187068981006,20.5990788715668,17.214239,0,0,0,40,4449,49.9823,88203.08984375,,,,,,,,,,,,,0,,,,-0.00245,,,,,,50.0028496,,,,
,26808394.29,50.0006332,87365.41796875,0.00625717778495904,1.49589229335333E-6,1,0.999253354069792,40.0298881530762,1.99750810797065,20.3499998897314,0.0708946037358232,0.0130528996252938,0.25,3.0381415288018E-5,0.00627919550238225,7.02317369536179E-5,50.0006332,50.0006332,87359.1953125,87371.640625,57.0948368157368,20.5962298292304,17.593889,0,0,0,40,4449,49.98255,87365.41796875,,,,,,,,,,,,,0,,,,-0.00245,,,,,,50.0006332,,,,
,26808574.89,49.9995193,82853.3828125,0.0061556932627011,1.46773927021658E-6,1,0.999253354069792,40.0298881530762,1.99753420617493,20.3499998897314,0.0697324918444413,0.0128520112980267,0.25,3.04280710224926E-5,0.00617638296410531,7.02021182809615E-5,49.9995193,49.9995193,82851.1328125,82855.6328125,57.098744958333,20.5956654222825,17.593889,0,0,0,40,4449,49.98445,82853.3828125,,,,,,,,,,,,,0,,,,0.00245,,,,,,49.9995193,,,,
,26808762.375,50.0006027,78165.5,0.00604457509288625,1.63860326871297E-6,1,0.999253354069792,40.0298881530762,1.99749191828168,20.3499998897314,0.0684648788200206,0.0125939784063449,0.25,2.72089320242249E-5,0.00606386823071633,6.68322441582762E-5,50.0006027,50.0006027,78159.453125,78171.546875,57.1362631272561,20.5965979465984,17.973541,0,0,0,40,4449,49.979,78165.5,,,,,,,,,,,,,0,,,,0.00245,,,,,,50.0006027,,,,
,26808948.99,50.0000992,73500.87890625,0.0059240109325711,1.42307204885859E-6,1,0.999253354069792,40.0298881530762,1.99743884348376,20.3499998897314,0.0670824734242434,0.0123582376768482,0.25,2.76915605290599E-5,0.00594185540804279,6.70769091312485E-5,50.0000992,50.0000992,73498.359375,73503.3984375,56.8322096332752,20.5977180370337,17.593889,0,0,0,40,4449,49.9822,73500.87890625,,,,,,,,,,,,,0,,,,0,,,,,,50.0000992,,,,
,26809132.345,50.0002899,68919.16015625,0.00579783016934319,9.07245613337476E-7,1,0.999253354069792,40.0298881530762,1.99745624970575,20.3499998897314,0.0656454024324642,0.012074948130092,0.25,2.49898704278543E-5,0.00581424319010841,6.4047339756302E-5,50.0002899,50.0002899,68915.390625,68922.9296875,57.3770047111791,20.5982883815048,17.593889,0,0,0,40,4449,49.98275,68919.16015625,,,,,,,,,,,,,0,,,,-0.0049,,,,,,50.0002899,,,,
,26809317.515,50.0009079,64290.66015625,0.00566130354406547,9.6605154718394E-7,1,0.999253354069792,40.0298881530762,1.99757471009355,20.3499998897314,0.0640907282946401,0.0117897203631596,0.25,2.39581925454304E-5,0.00567623471467174,6.25906789892835E-5,50.0008163,50.0009995,64284.2109375,64297.109375,57.3269804859484,20.5979209013042,17.593889,0,0,0,40,4449,49.98315,64290.66015625,,,,,,,,,,,,,0,,,,-0.0049,,,,,,50.0009079,,,,
,26809507.345,49.9989967,59546.36328125,0.00551030986297402,9.54809182411666E-7,1,0.999253354069792,40.0298881530762,1.99720706743248,20.3499998897314,0.0623543657547004,0.0114884284240843,0.25,2.43797277912369E-5,0.00552369134036337,6.24612035106964E-5,49.9989967,49.9989967,59541.32421875,59551.40234375,57.0471574760637,20.6001676958051,17.973541,0,0,0,40,4449,49.9834,59546.36328125,,,,,,,,,,,,,0,,,,0,,,,,,49.9989967,,,,
,26809694.865,49.9998627,54860.580078125,0.0053492561214576,1.02492747639036E-6,1,0.999253354069792,40.0298881530762,1.99735701776912,20.3499998897314,0.0605256639257264,0.0111384360572084,0.25,2.21039335423047E-5,0.00536111718368068,5.95034258420895E-5,49.9998627,49.9998627,54857.0078125,54864.15234375,57.3183825722368,20.5997929646878,17.973541,0,0,0,40,4449,49.9874,54860.580078125,,,,,,,,,,,,,0,,,,0,,,,,,49.9998627,,,,
,26809882.685,50.0004997,50166.73828125,0.00517587981911826,1.04400840688338E-6,1,0.999253354069792,40.0298881530762,1.99726744561047,20.3499998897314,0.0585471971980848,0.0107812287122963,0.25,2.15634263226343E-5,0.00518619664397851,5.81520700582272E-5,50.0004997,50.0004997,50164.2890625,50169.1875,57.0088576786214,20.6021708318402,17.973541,0,0,0,40,4449,49.98115,50166.73828125,,,,,,,,,,,,,0,,,,-0.00245,,,,,,50.0004997,,,,
,26810073.63,50.0007973,45395.810546875,0.00498363619151782,1.06605065030725E-6,1,0.999253354069792,40.0298881530762,1.99744423163724,20.3499998897314,0.0563599351514303,0.0104031068261098,0.25,2.2496168382689E-5,0.00499238929636819,5.80912455241718E-5,50.0007973,50.0007973,45392.12109375,45399.5,57.1714364106214,20.6002188877311,17.593889,0,0,0,40,4449,49.9833,45395.810546875,,,,,,,,,,,,,0,,,,0,,,,,,50.0007973,,,,
,26810262.825,49.9995499,40667.8828125,0.00477129405039979,9.81711094241594E-7,1,0.999253354069792,40.0298881530762,1.99738323298028,20.3499998897314,0.0539444177210747,0.00995490542425411,0.25,2.10097100583112E-5,0.00477852628590658,5.5402514776752E-5,49.9995499,49.9995499,40664.203125,40671.5625,57.2081729510253,20.601793542332,17.973541,0,0,0,40,4449,49.97955,40667.8828125,,,,,,,,,,,,,0,,,,0,,,,,,49.9995499,,,,
,26810451.53,49.9988518,35951.73046875,0.00454081980138756,9.89536426944225E-7,1,0.999253354069792,40.0298881530762,1.99733748197667,20.3499998897314,0.0513249941576905,0.00947120191854667,0.25,1.96893726447827E-5,0.00454658617084546,5.26864024835877E-5,49.9988518,49.9988518,35946.51171875,35956.94921875,57.4309370790061,20.6025006127915,17.973541,0,0,0,40,4449,49.9829,35951.73046875,,,,,,,,,,,,,0,,,,0,,,,,,49.9988518,,,,
,26810640.28,50.0003204,31235.7998046875,0.00428151345749927,7.0701278979032E-7,1,0.999253354069792,40.0298881530762,1.99748375185693,20.3499998897314,0.0483828679099843,0.00894167907326063,0.25,1.94805175736635E-5,0.00428585909420247,5.08130103584585E-5,50.0003204,50.0003204,31231.912109375,31239.6875,57.2933704596215,20.6007370864132,17.593889,0,0,0,40,4449,49.9821,31235.7998046875,,,,,,,,,,,,,0,,,,0.0049,,,,,,50.0003204,,,,
,26810826.5,49.9999771,26581.2080078125,0.00399795691286654,8.24632261134568E-7,1,0.999253354069792,40.0298881530762,1.99743567416613,20.3499998897314,0.0451679659327563,0.008336634450534,0.25,1.70774671150872E-5,0.00400100661166002,4.65023549065343E-5,49.9999771,49.9999771,26576.1796875,26586.236328125,57.342613056333,20.6020829008644,17.973541,0,0,0,40,4449,49.983,26581.2080078125,,,,,,,,,,,,,0,,,,-0.00245,,,,,,49.9999771,,,,
,26811015.235,50.0000992,21865.2470703125,0.00367292348884785,6.26893790147974E-7,1,0.999253354069792,40.0298881530762,1.99751526481229,20.3499998897314,0.0414852534983529,0.00766470875782525,0.25,1.62206060866181E-5,0.00367476532630099,4.33780361952334E-5,50.0000992,50.0000992,21861.36328125,21869.130859375,57.0487207331022,20.6040064475736,18.353191,0,0,0,40,4449,49.98375,21865.2470703125,,,,,,,,,,,,,0,,,,-0.0049,,,,,,50.0000992,,,,
,26811199.68,50.0002441,17257.0380859375,0.00331259038024186,5.38826492845324E-7,1,0.999253354069792,40.0298881530762,1.99751930612668,20.3499998897314,0.0374040700783077,0.00692096804020588,0.25,1.54202306205659E-5,0.0033133999616812,3.99937423438217E-5,50.0002441,50.0002441,17252.037109375,17262.0390625,57.0221453634483,20.6026240489817,17.593889,0,0,0,40,4449,49.9812,17257.0380859375,,,,,,,,,,,,,0,,,,-0.00245,,,,,,50.0002441,,,,
,26811387.24,49.9991188,12569.4697265625,0.0028981591855539,4.76149555520632E-7,1,0.999253354069792,40.0298881530762,1.99756566655987,20.3499998897314,0.0327171988300311,0.00605240071898945,0.25,1.33229808881031E-5,0.00289813432961368,3.48662401143484E-5,49.9991188,49.9991188,12564.619140625,12574.3203125,57.210517836583,20.6015068273956,17.593889,0,0,0,40,4449,49.9874,12569.4697265625,,,,,,,,,,,,,0,,,,0,,,,,,49.9991188,,,,
,26811570.76,50.0012627,7982.65966796875,0.00243095268224474,4.58766601740175E-7,1,0.999253354069792,40.0298881530762,1.99752635537502,20.3499998897314,0.0274349768122842,0.00507988696878368,0.25,1.15510148382719E-5,0.00243034242146582,2.96369370825658E-5,50.0012627,50.0012627,7978.73193359375,7986.58740234375,56.8548768603329,20.6007325314035,17.593889,0,0,0,40,4449,49.98385,7982.65966796875,,,,,,,,,,,,,0,,,,0,,,,,,50.0012627,,,,
,26811756.75,49.9999504,3333.9814453125,0.00189020797300484,3.961866334736E-7,1,0.999253354069792,40.0298881530762,1.99753698601871,20.3499998897314,0.021327756521306,0.00394849117323693,0.25,8.92894960721275E-6,0.0018893128295689,2.29899011243535E-5,49.9999504,49.9999504,3331.40063476562,3336.56225585937,57.3942005386022,20.60391468054,17.973541,0,0,0,40,4449,49.9826,3333.9814453125,,,,,,,,,,,,,0,,,,0.0049,,,,,,49.9999504,,,,
,26811943.83,50.0002251,-1338.98095703125,0.00126012100491668,4.3167738288117E-7,1,0.999253354069792,40.0298881530762,1.99750833556049,20.3499998897314,0.0142165637384941,0.00263425447632472,0.25,6.14978665874152E-6,0.00125942108775294,1.55209820651572E-5,50.0002251,50.0002251,-1340.24951171875,-1337.71240234375,57.2347483206791,20.6027295587948,18.353191,0,0,0,40,4449,49.9852,-1338.98095703125,,,,,,,,,,,,,0,,,,0,,,,,,50.0002251,,,,
,26812130.175,49.9991722,-5995.08349609375,0.00052851918402966,3.95466301859322E-7,1,0.999253354069792,40.0298881530762,1.99755977317285,20.3499998897314,0.00596345688287836,0.00110854735446357,0.25,2.88303119619958E-6,0.000528332064444469,6.8152145129672E-6,49.9991722,49.9991722,-5997.79541015625,-5992.37158203125,57.2675767184868,20.600542091389,17.973541,0,0,0,40,4449,49.98695,-5995.08349609375,,,,,,,,,,,,,0,,,,0.00245,,,,,,49.9991722,,,,
,26812315.125,50.0020599,-10616.7163085938,-0.000293691234610721,3.92876270571325E-7,1,0.999253354069792,40.0298881530762,1.99757819500379,20.3499998897314,-0.00331659549912581,-0.000605189439778544,0.25,-6.33166337949526E-7,-0.000293663087598756,-2.81746716199369E-6,50.0020599,50.0020599,-10620.482421875,-10612.9501953125,57.1745629246983,20.6032109570633,18.353191,0,0,0,40,4449,49.98235,-10616.7163085938,,,,,,,,,,,,,0,,,,-0.0049,,,,,,50.0020599,,,,
,26812501.58,50.0001564,-15277.0810546875,-0.00118343204305584,5.71130263191915E-7,1,0.999253354069792,40.0298881530762,1.99754110306675,20.3499998897314,-0.0133620095114208,-0.00246896863959863,0.25,-5.20412548763166E-6,-0.00118359622479306,-1.39919253949599E-5,50.0001564,50.0001564,-15281.109375,-15273.052734375,57.217552493256,20.602246553503,17.973541,0,0,0,40,4449,49.9846,-15277.0810546875,,,,,,,,,,,,,0,,,,0,,,,,,50.0001564,,,,
,26812688.86,49.9997787,-19958.1484375,-0.00205818931971682,5.87849417929753E-7,1,0.999253354069792,40.0298881530762,1.99754714349534,20.3499998897314,-0.0232450446338412,-0.00429397835736074,0.25,-9.00283642768089E-6,-0.00205900496155276,-2.42437500345265E-5,49.9997787,49.9997787,-19960.666015625,-19955.630859375,57.1401712698522,20.6036791209711,17.973541,0,0,0,40,4449,49.9839,-19958.1484375,,,,,,,,,,,,,0,,,,-0.00245,,,,,,49.9997787,,,,
,26812874.875,50.0002365,-24605.435546875,-0.00281331355335185,5.84087910875831E-7,1,0.999253354069792,40.0298881530762,1.99764608067119,20.3499998897314,-0.0317832915105828,-0.00586946535239021,0.25,-1.22471127135826E-5,-0.002815148715461,-3.299667330723E-5,50.0002365,50.0002365,-24607.82421875,-24603.046875,57.2019199228714,20.6041829866287,17.973541,0,0,0,40,4449,49.9793,-24605.435546875,,,,,,,,,,,,,0,,,,0.00245,,,,,,50.0002365,,,,
,26813064.91,50.0007668,-29354.1875,-0.00343992057723165,7.39395733151425E-7,1,0.999253354069792,40.0298881530762,1.99758088462182,20.3499998897314,-0.0388710725995852,-0.00717948581434143,0.25,-1.52157557890082E-5,-0.00344306004726169,-4.0451574862019E-5,50.0007668,50.0007668,-29355.669921875,-29352.705078125,57.4567308201407,20.6054759733944,18.353191,0,0,0,40,4449,49.9787,-29354.1875,,,,,,,,,,,,,0,,,,-0.0049,,,,,,50.0007668,,,,
,26813252.78,50.0014267,-34049.052734375,-0.00392764058848665,7.83482048065754E-7,1,0.999253354069792,40.0298881530762,1.99753659829956,20.3499998897314,-0.0443915473917158,-0.0082052205656673,0.25,-1.80933029244584E-5,-0.00393221749673314,-4.67214051362786E-5,50.0014267,50.0014267,-34052.80859375,-34045.296875,57.4919041035061,20.6065764177812,18.353191,0,0,0,40,4449,49.9781,-34049.052734375,,,,,,,,,,,,,0,,,,0,,,,,,50.0014267,,,,
,26813442.4,50.0004997,-38786.31640625,-0.00432197164223152,8.72959742642261E-7,1,0.999253354069792,40.0298881530762,1.99761663142268,20.3499998897314,-0.0488638912272924,-0.00902411224214278,0.25,-1.95007338262232E-5,-0.00432809861749598,-5.07599747298809E-5,50.0004997,50.0004997,-38787.640625,-38784.9921875,57.1354814987368,20.6061918177284,17.973541,0,0,0,40,4449,49.9816,-38786.31640625,,,,,,,,,,,,,0,,,,0,,,,,,50.0004997,,,,
,26813631.78,49.9995403,-43519.533203125,-0.00464421699008931,8.60668111297801E-7,1,0.999253354069792,40.0298881530762,1.99755066310881,20.3499998897314,-0.0525177518168153,-0.00970156371299838,0.25,-2.14871083945695E-5,-0.00465192382775859,-5.47858315385008E-5,49.9995384,49.9995422,-43524.390625,-43514.67578125,57.2347483206791,20.6056868245906,18.353191,0,0,0,40,4449,49.97575,-43519.533203125,,,,,,,,,,,,,0,,,,-0.00245,,,,,,49.9995403,,,,
,26813818.42,50.0005035,-48183.732421875,-0.00490719770624777,6.54901097883951E-7,1,0.999253354069792,40.0298881530762,1.99756904384309,20.3499998897314,-0.0555077136418327,-0.0102379891690817,0.25,-2.16932352793379E-5,-0.00491649019219564,-5.65388677050146E-5,50.0005035,50.0005035,-48187.41015625,-48180.0546875,57.3840393678522,20.6044657786716,17.593889,0,0,0,40,4449,49.9749,-48183.732421875,,,,,,,,,,,,,0,,,,0.00245,,,,,,50.0005035,,,,
,26814007.73,50.0006027,-52913.5,-0.00514003490251858,9.4419353650836E-7,1,0.999253354069792,40.0298881530762,1.99744258298966,20.3499998897314,-0.0581495577602356,-0.0107341139858137,0.25,-2.38785232202694E-5,-0.0051509289221605,-5.99936291623875E-5,50.0006027,50.0006027,-52917.1953125,-52909.8046875,57.301968373333,20.6080123788817,18.353191,0,0,0,40,4449,49.97115,-52913.5,,,,,,,,,,,,,0,,,,0,,,,,,50.0006027,,,,
,26814198.035,50.0014076,-57667.947265625,-0.00534411255953663,6.02855597540209E-7,1,0.999253354069792,40.0298881530762,1.99755055767724,20.3499998897314,-0.0604756516906733,-0.0111581941486714,0.25,-2.4818625715138E-5,-0.00535662102358666,-6.19348815019825E-5,50.0014076,50.0014076,-57671.76953125,-57664.125,57.4004535667561,20.60634915303,17.973541,0,0,0,40,4449,49.97395,-57667.947265625,,,,,,,,,,,,,0,,,,0.00245,,,,,,50.0014076,,,,
,26814385.925,50.0007591,-62364.166015625,-0.00552394610501516,1.05095296470422E-6,1,0.999253354069792,40.0298881530762,1.9975238131582,20.3499998897314,-0.0625238758188628,-0.0115305746668886,0.25,-2.5657349158302E-5,-0.00553803096013963,-6.35584977409977E-5,50.0007591,50.0007591,-62366.7109375,-62361.62109375,57.4168677656599,20.6061937476718,17.973541,0,0,0,40,4449,49.9734,-62364.166015625,,,,,,,,,,,,,0,,,,-0.00245,,,,,,50.0007591,,,,
,26814573.73,50.0009041,-67058.29296875,-0.00568685552829767,1.22708955288098E-6,1,0.999253354069792,40.0298881530762,1.9975748062846,20.3499998897314,-0.0643831778331617,-0.0118680140409904,0.25,-2.64592430265042E-5,-0.00570249831909103,-6.49790755384806E-5,50.0009041,50.0009041,-67059.5859375,-67057,57.566158812833,20.6092091149666,18.353191,0,0,0,40,4449,49.97685,-67058.29296875,,,,,,,,,,,,,0,,,,0.00245,,,,,,50.0009041,,,,
,26814764.72,50.0001907,-71830.18359375,-0.00583817139979489,7.45752605913835E-7,1,0.999253354069792,40.0298881530762,1.99756171157386,20.3499998897314,-0.0661111988904191,-0.0121717359608587,0.25,-2.64443271238695E-5,-0.00585536851554037,-6.54520939391092E-5,50.0001907,50.0001907,-71833.890625,-71826.4765625,57.4676736194099,20.608764046825,17.593889,0,0,0,40,4449,49.9715,-71830.18359375,,,,,,,,,,,,,0,,,,0.0049,,,,,,50.0001907,,,,
,26814953.88,50.0001068,-76557.15234375,-0.00597617053018898,1.10685954206976E-6,1,0.999253354069792,40.0298881530762,1.99751404030937,20.3499998897314,-0.0676826188588524,-0.0124732751637008,0.25,-2.86822782760983E-5,-0.00599486443805036,-6.80588041109416E-5,50.0001068,50.0001068,-76558.1484375,-76556.15625,57.3770047111791,20.6086736582133,17.973541,0,0,0,40,4449,49.97075,-76557.15234375,,,,,,,,,,,,,0,,,,0.00245,,,,,,50.0001068,,,,
,26815144.095,50.0004272,-81309.7109375,-0.00610526414444694,1.21120575793115E-6,1,0.999253354069792,40.0298881530762,1.99747125871687,20.3499998897314,-0.0691574101704083,-0.0127333677657611,0.25,-2.88977504230697E-5,-0.00612544329752815,-6.8539029740245E-5,50.0004272,50.0004272,-81313.390625,-81306.03125,57.484869446833,20.6083442096527,17.973541,0,0,0,40,4449,49.97045,-81309.7109375,,,,,,,,,,,,,0,,,,0.00245,,,,,,50.0004272,,,,
,26815331.495,50.0005684,-85992.74609375,-0.00622179845726115,1.13090229328974E-6,1,0.999253354069792,40.0298881530762,1.99749625021706,20.3499998897314,-0.0704889597426682,-0.012983979249556,0.25,-3.05185251938963E-5,-0.00624338805386238,-7.03252191508259E-5,50.0005684,50.0005684,-85995.40625,-85990.0859375,57.4301554504868,20.610153294856,18.353191,0,0,0,40,4449,49.97,-85992.74609375,,,,,,,,,,,,,0,,,,-0.0049,,,,,,50.0005684,,,,
,26815532.015,50.000885,-89521.38671875,-0.00630871694520259,1.44117259597227E-6,1,0.999253354069792,40.0298881530762,1.99752681163584,20.3499998897314,-0.0714820297679015,-0.013173706113218,0.25,-3.19893999329606E-5,-0.00633135517262488,-7.18990640965034E-5,50.000885,50.000885,-89525.1484375,-89517.625,57.4989387601791,20.6066070806772,17.973541,0,0,0,40,4449,49.96665,-89521.38671875,,,,,,,,,,,,,0,,,,0,,,,,,50.000885,,,,
,26815713.195,49.9999809,-84996.7578125,-0.00620958542930907,1.22244287786482E-6,1,0.999253354069792,40.0298881530762,1.99753154363228,20.3499998897314,-0.07034959413534,-0.012956977801837,0.25,-3.02162840728267E-5,-0.00623091930374183,-7.00707827499817E-5,49.9999809,49.9999809,-85001.59375,-84991.921875,57.5083183024099,20.6080172681211,18.353191,0,0,0,40,4449,49.9701,-84996.7578125,,,,,,,,,,,,,0,,,,-0.00245,,,,,,49.9999809,,,,
,26815902.62,50.0006943,-80261.33203125,-0.0060991893378534,9.43632475310258E-7,1,0.999253354069792,40.0298881530762,1.99759817505737,20.3499998897314,-0.0690919528349792,-0.0127111796192054,0.25,-2.78732978078637E-5,-0.0061191243550407,-6.75999324240589E-5,50.0006943,50.0006943,-80264.1171875,-80258.546875,57.4504777919868,20.6071835450735,18.353191,0,0,0,40,4449,49.9743,-80261.33203125,,,,,,,,,,,,,0,,,,0.0049,,,,,,50.0006943,,,,
,26816092.265,49.99744605,-75523.13671875,-0.0059841573682718,9.86880358596446E-7,1,0.999253354069792,40.0298881530762,1.99763049936094,20.3499998897314,-0.0677752270831898,-0.0124845652874182,0.25,-2.81037079032196E-5,-0.00600264746564757,-6.76522728274804E-5,49.9974403,49.9974518,-75529.546875,-75516.7265625,57.0237086204868,20.6059381551199,17.973541,0,0,0,40,4449,49.97575,-75523.13671875,,,,,,,,,,,,,0,,,,-0.0049,,,,,,49.99744605,,,,
,26816282.595,49.9991722,-70768.28125,-0.00585686883994041,1.14059847163241E-6,1,0.999253354069792,40.0298881530762,1.99751910844171,20.3499998897314,-0.066319643519841,-0.0122051017739665,0.25,-2.5977412954611E-5,-0.0058738754668205,-6.52296440583377E-5,49.9991722,49.9991722,-70769.4453125,-70767.1171875,57.2433462343907,20.6058737032493,17.973541,0,0,0,40,4449,49.9717,-70768.28125,,,,,,,,,,,,,0,,,,0.0049,,,,,,49.9991722,,,,
,26816474.89,49.9995308,-65962.45703125,-0.00571885203018691,1.08070765606098E-6,1,0.999253354069792,40.0298881530762,1.99753205688775,20.3499998897314,-0.0647427266516355,-0.0119248235956532,0.25,-2.56757165730072E-5,-0.00573432087225781,-6.45305710996691E-5,49.9995308,49.9995308,-65964.9765625,-65959.9375,57.6107116384292,20.6035386101344,17.593889,0,0,0,40,4449,49.9707,-65962.45703125,,,,,,,,,,,,,0,,,,0,,,,,,49.9995308,,,,
,26816666.375,49.99882885,-61176.759765625,-0.00557503163964259,1.11737556783783E-6,1,0.999253354069792,40.0298881530762,1.99757583848673,20.3499998897314,-0.0631006344466262,-0.0116353909843838,0.25,-2.56375474570713E-5,-0.00558895529211346,-6.40102576035782E-5,49.9987144,49.9989433,-61180.4375,-61173.08203125,57.301968373333,20.6085495713714,17.593889,0,0,0,40,4449,49.9701,-61176.759765625,,,,,,,,,,,,,0,,,,0,,,,,,49.99882885,,,,
,26816855.085,49.9993801,-56461.89453125,-0.0054176028951173,8.1778187740627E-7,1,0.999253354069792,40.0298881530762,1.99750392105415,20.3499998897314,-0.0613032210070262,-0.0113069764535277,0.25,-2.47083726769608E-5,-0.00542998590402428,-6.24481529085972E-5,49.9993286,49.9994316,-56465.65625,-56458.1328125,57.3168193151984,20.6042292345921,18.353191,0,0,0,40,4449,49.9718,-56461.89453125,,,,,,,,,,,,,0,,,,-0.00245,,,,,,49.9993801,,,,
,26817044.615,49.9995308,-51726.080078125,-0.00525000702811071,8.75885193491475E-7,1,0.999253354069792,40.0298881530762,1.99748222887699,20.3499998897314,-0.0593952162896908,-0.0109424888354291,0.25,-2.24404271839063E-5,-0.00526085105822876,-5.94261907275115E-5,49.9995308,49.9995308,-51728.84765625,-51723.3125,57.5106631879676,20.6031571935971,18.353191,0,0,0,40,4449,49.9708,-51726.080078125,,,,,,,,,,,,,0,,,,0,,,,,,49.9995308,,,,
,26817233.29,50.0007477,-47012.615234375,-0.00506636470508778,1.15267534253564E-6,1,0.999253354069792,40.0298881530762,1.99746252228151,20.3499998897314,-0.0573007608611155,-0.0105753311663475,0.25,-2.28701090840255E-5,-0.00507566243726144,-5.89371447080934E-5,50.0007477,50.0007477,-47018.984375,-47006.24609375,57.2933704596215,20.6041605959165,18.353191,0,0,0,40,4449,49.9747,-47012.615234375,,,,,,,,,,,,,0,,,,-0.0049,,,,,,50.0007477,,,,
,26817422.07,49.9989071,-42293.876953125,-0.00486408921440124,6.53452733572468E-7,1,0.999253354069792,40.0298881530762,1.99748754302286,20.3499998897314,-0.0550001764702584,-0.0101533215514775,0.25,-2.18339872545453E-5,-0.00487185825101717,-5.67918626246779E-5,49.9988327,49.9989815,-42296.359375,-42291.39453125,57.0995265868522,20.6035820907263,17.973541,0,0,0,40,4449,49.9721,-42293.876953125,,,,,,,,,,,,,0,,,,-0.00245,,,,,,49.9989071,,,,
,26817610.9,50.0001106,-37575.3359375,-0.00464241329140822,7.29641672093857E-7,1,0.999253354069792,40.0298881530762,1.99741521861372,20.3499998897314,-0.0524779205108861,-0.00969380928909534,0.25,-2.10650449765887E-5,-0.00464869059889718,-5.47137916049119E-5,50.0001106,50.0001106,-37579.1953125,-37571.4765625,57.220679007333,20.6037483040417,17.593889,0,0,0,40,4449,49.9736,-37575.3359375,,,,,,,,,,,,,0,,,,-0.00245,,,,,,50.0001106,,,,
,26817798.53,49.9986038,-32888.185546875,-0.00439731685985865,8.86631543243761E-7,1,0.999253354069792,40.0298881530762,1.99749835588878,20.3499998897314,-0.0496943595177498,-0.00919476513043805,0.25,-2.10019587496762E-5,-0.00440216177947448,-5.31092392693729E-5,49.9986038,49.9986038,-32889.140625,-32887.23046875,57.2019199228714,20.6038143538491,18.353191,0,0,0,40,4449,49.9784,-32888.185546875,,,,,,,,,,,,,0,,,,-0.0049,,,,,,49.9986038,,,,
,26817986.72,50.0000801,-28184.7275390625,-0.00412038454879359,7.18825351217228E-7,1,0.999253354069792,40.0298881530762,1.99752172095234,20.3499998897314,-0.0465541493002841,-0.00860928090374486,0.25,-1.9097597219658E-5,-0.00412387493330703,-4.93696004063009E-5,50.0000801,50.0000801,-28187.126953125,-28182.328125,57.332451885583,20.6021669612735,17.973541,0,0,0,40,4449,49.9786,-28184.7275390625,,,,,,,,,,,,,0,,,,0.0049,,,,,,50.0000801,,,,
,26818175.57,49.9998894,-23465.775390625,-0.00380879278213932,6.12916556371422E-7,1,0.999253354069792,40.0298881530762,1.99751821631009,20.3499998897314,-0.0430218549389436,-0.00795888419870494,0.25,-1.77430583776037E-5,-0.00381102441317066,-4.58668813341444E-5,49.9998894,49.9998894,-23466.86328125,-23464.6875,57.230840178083,20.602570046945,18.353191,0,0,0,40,4449,49.97495,-23465.775390625,,,,,,,,,,,,,0,,,,0.00245,,,,,,49.9998894,,,,
,26818365.695,49.9989738,-18713.7294921875,-0.0034511122533164,5.20514745119915E-7,1,0.999253354069792,40.0298881530762,1.99751868512032,20.3499998897314,-0.0389710181905533,-0.00721240399187265,0.25,-1.62194854308037E-5,-0.00345222964262854,-4.17979245655469E-5,49.9989738,49.9989738,-18715.138671875,-18712.3203125,57.3918556530445,20.601624355788,18.353191,0,0,0,40,4449,49.97905,-18713.7294921875,,,,,,,,,,,,,0,,,,0,,,,,,49.9989738,,,,
,26818551,50.0000877,-14084.0200195313,-0.00305102524159698,5.42204386154937E-7,1,0.999253354069792,40.0298881530762,1.99760710719497,20.3499998897314,-0.0344460537692775,-0.00637339021474931,0.25,-1.41398910974174E-5,-0.00305123553518697,-3.68080330414229E-5,50.0000877,50.0000877,-14087.642578125,-14080.3974609375,57.2488176340253,20.6035512324813,17.593889,0,0,0,40,4449,49.9739,-14084.0200195313,,,,,,,,,,,,,0,,,,-0.00245,,,,,,50.0000877,,,,
,26818739.23,50.0002251,-9379.76953125,-0.00258573620606365,4.72815645643102E-7,1,0.999253354069792,40.0298881530762,1.9975390817931,20.3499998897314,-0.0291843301262532,-0.0054021282609012,0.25,-1.21483147168471E-5,-0.00258526937181269,-3.13830902502378E-5,50.0002251,50.0002251,-9384.83984375,-9374.69921875,57.2300585495638,20.6007998803528,17.593889,0,0,0,40,4449,49.9786,-9379.76953125,,,,,,,,,,,,,0,,,,0.00245,,,,,,50.0002251,,,,
,26818924.235,50.0001793,-4755.43823242188,-0.00205710256839577,4.14792933177798E-7,1,0.999253354069792,40.0298881530762,1.9976010272047,20.3499998897314,-0.0232122619131046,-0.00430208171910396,0.25,-1.0120035097995E-5,-0.00205625794782624,-2.54243535113926E-5,50.0001793,50.0001793,-4759.2451171875,-4751.63134765625,57.3066581444484,20.6014451942709,17.973541,0,0,0,40,4449,49.9824,-4755.43823242188,,,,,,,,,,,,,0,,,,0,,,,,,50.0001793,,,,
,26819111.505,50.0005112,-75.7246055603027,-0.00143557461708108,3.40366381182914E-7,1,0.999253354069792,40.0298881530762,1.99758627026243,20.3499998897314,-0.0161955705750513,-0.00300309941147389,0.25,-7.19116224678183E-6,-0.00143471628161688,-1.78650705654288E-5,50.0005112,50.0005112,-78.0934600830078,-73.3557510375977,57.4012351952753,20.6008536491115,17.973541,0,0,0,40,4449,49.9806,-75.7246055603027,,,,,,,,,,,,,0,,,,0.00245,,,,,,50.0005112,,,,
,26819292.645,50.0001984,4448.88305664063,-0.000735561676935563,3.67557181499519E-7,1,0.999253354069792,40.0298881530762,1.99744378569632,20.3499998897314,-0.00829802696994344,-0.00154527652628419,0.25,-4.24830595884214E-6,-0.000735244714392157,-9.72032969295099E-6,50.0001984,50.0001984,4447.49853515625,4450.267578125,57.2660134614484,20.6017689428088,17.973541,0,0,0,40,4449,49.9833,4448.88305664063,,,,,,,,,,,,,0,,,,0,,,,,,50.0001984,,,,
,26819480.54,49.999321,9146.0380859375,8.51466625654448E-5,4.4298418422443E-7,1,0.999253354069792,40.0298881530762,1.99756455795854,20.3499998897314,0.000962956175731386,0.000167150361956544,0.25,-5.50594632725326E-7,8.51372418125312E-5,8.29665843906478E-8,49.999321,49.999321,9143.890625,9148.185546875,57.4051433378714,20.598934405391,17.973541,0,0,0,40,4449,49.9751,9146.0380859375,,,,,,,,,,,,,0,,,,0.0049,,,,,,49.999321,,,,
,26819664.595,49.9996948,13745.03125,0.00095999425165352,5.02220268665163E-7,1,0.999253354069792,40.0298881530762,1.99762182866184,20.3499998897314,0.010840570284628,0.00199233018871799,0.25,3.29618487921997E-6,0.000960053017040468,1.04293709510922E-5,49.9996948,49.9996948,13741.7646484375,13748.2978515625,57.0627900464484,20.5995826720653,17.973541,0,0,0,40,4449,49.97985,13745.03125,,,,,,,,,,,,,0,,,,-0.0049,,,,,,49.9996948,,,,
,26819851.18,49.9991989,18407.5302734375,0.00184669546470771,4.33678788249815E-7,1,0.999253354069792,40.0298881530762,1.99747240721691,20.3499998897314,0.0208556338351271,0.00384258172717691,0.25,7.20396116440485E-6,0.00184727286363559,2.08932485061689E-5,49.9991989,49.9991989,18403.751953125,18411.30859375,57.1073428720445,20.600687713891,17.973541,0,0,0,40,4449,49.9786,18407.5302734375,,,,,,,,,,,,,0,,,,0,,,,,,49.9991989,,,,
,26820039.01,49.999752,23101.7578125,0.00264256716107354,6.54515409659205E-7,1,0.999253354069792,40.0298881530762,1.99758300656419,20.3499998897314,0.0298500540371718,0.00551721566863275,0.25,1.18808006384814E-5,0.00264406587954844,3.13995086363711E-5,49.999752,49.999752,23096.7109375,23106.8046875,57.4309370790061,20.5979903605001,18.353191,0,0,0,40,4449,49.9756,23101.7578125,,,,,,,,,,,,,0,,,,-0.00245,,,,,,49.999752,,,,
,26820225.245,50.0006599,27756.6357421875,0.00328935079554824,8.62035478101202E-7,1,0.999253354069792,40.0298881530762,1.99749922372652,20.3499998897314,0.0371666552130995,0.00685492562560141,0.25,1.36648495876358E-5,0.00329207281288324,3.78420157809595E-5,50.0006599,50.0006599,27751.98828125,27761.283203125,57.1003082153714,20.6011985792692,18.353191,0,0,0,40,4449,49.9801,27756.6357421875,,,,,,,,,,,,,0,,,,0.0049,,,,,,50.0006599,,,,
,26820413.25,49.9998055,32454.142578125,0.00380639648865903,6.70854559787713E-7,1,0.999253354069792,40.0298881530762,1.99747748455228,20.3499998897314,0.0430188139791371,0.00793683117188543,0.25,1.62110348251456E-5,0.00381051082047355,4.40196940260289E-5,49.9998055,49.9998055,32448.76171875,32459.5234375,57.1386080128137,20.5998603632926,17.593889,0,0,0,40,4449,49.97315,32454.142578125,,,,,,,,,,,,,0,,,,-0.00245,,,,,,49.9998055,,,,
,26820601.825,50.0017967,37166.533203125,0.00421976574989015,1.01957564983786E-6,1,0.999253354069792,40.0298881530762,1.9975259003557,20.3499998897314,0.0477028341021097,0.00880571967171148,0.25,1.86092739692327E-5,0.00422538281575673,4.92151980981427E-5,50.0017967,50.0017967,37163.93359375,37169.1328125,57.2378748347561,20.6009310416656,17.973541,0,0,0,40,4449,49.97185,37166.533203125,,,,,,,,,,,,,0,,,,-0.00245,,,,,,50.0017967,,,,
,26820790.285,50.0006943,41876.8046875,0.00455444402329385,9.37466014708149E-7,1,0.999253354069792,40.0298881530762,1.99754906769723,20.3499998897314,0.0514990783391919,0.00950852262270445,0.25,2.0547991116805E-5,0.00456162308954727,5.33058159902572E-5,50.0006943,50.0006943,41871.76171875,41881.84765625,57.2480360055061,20.60116343582,17.973541,0,0,0,40,4449,49.975,41876.8046875,,,,,,,,,,,,,0,,,,0.0049,,,,,,50.0006943,,,,
,26820978.855,50.000309,46588.548828125,0.00483303471437832,9.47164424634416E-7,1,0.999253354069792,40.0298881530762,1.99764111342659,20.3499998897314,0.0546674682586543,0.0100769606244886,0.25,2.07270606681643E-5,0.00484181069290463,5.5161651328868E-5,50.000309,50.000309,46584.92578125,46592.171875,56.9494539111599,20.5986150198736,17.593889,0,0,0,40,4449,49.97505,46588.548828125,,,,,,,,,,,,,0,,,,0.00245,,,,,,50.000309,,,,
,26821161.43,49.999794,51151.287109375,0.0050647941286685,7.65080851143616E-7,1,0.999253354069792,40.0298881530762,1.99743502998456,20.3499998897314,0.0572949474819161,0.0105674536820716,0.25,2.2619116860246E-5,0.00507511334846001,5.83477920830197E-5,49.999794,49.999794,51147.47265625,51155.1015625,56.861911517006,20.5978157702681,17.973541,0,0,0,40,4449,49.9751,51151.287109375,,,,,,,,,,,,,0,,,,0,,,,,,49.999794,,,,
,26821351.045,50.000309,55889.72265625,0.00527599694908474,9.19907951350303E-7,1,0.999253354069792,40.0298881530762,1.99755070976371,20.3499998897314,0.059699672656643,0.01101677981253,0.25,2.44851283126559E-5,0.00528791448659746,6.12912033914341E-5,50.000309,50.000309,55887.10546875,55892.33984375,56.9314764552176,20.5964390755251,17.973541,0,0,0,40,4449,49.9721,55889.72265625,,,,,,,,,,,,,0,,,,0,,,,,,50.000309,,,,
,26821542.82,49.9993362,60682.42578125,0.00546490971775586,9.5350300209452E-7,1,0.999253354069792,40.0298881530762,1.99742726489446,20.3499998897314,0.0618457389247295,0.0114199032925086,0.25,2.64410287808387E-5,0.00547843110707414,6.41073526156883E-5,49.9993362,49.9993362,60679.96484375,60684.88671875,56.9502355396791,20.5969606592562,17.973541,0,0,0,40,4449,49.9715,60682.42578125,,,,,,,,,,,,,0,,,,0,,,,,,49.9993362,,,,
,26821735.005,50.0009995,65485.505859375,0.00563429033836343,1.2026703054725E-6,1,0.999253354069792,40.0298881530762,1.99734981281013,20.3499998897314,0.0637753800861865,0.0117651555485302,0.25,2.68264369491831E-5,0.00564940818291298,6.51606166578611E-5,50.0009995,50.0009995,65477.91015625,65493.1015625,56.9447641400445,20.5993208427726,17.973541,0,0,0,40,4449,49.97295,65485.505859375,,,,,,,,,,,,,0,,,,0,,,,,,50.0009995,,,,
,26821924.67,50.0016537,70225.4609375,0.00578971949678998,1.06325251116427E-6,1,0.999253354069792,40.0298881530762,1.99730718294471,20.3499998897314,0.0655444028796515,0.0121014950434516,0.25,2.89535672697625E-5,0.00580637969138406,6.78274000908315E-5,50.0016022,50.0017052,70223.1953125,70227.7265625,57.1386080128137,20.5991192421621,18.353191,0,0,0,40,4449,49.96885,70225.4609375,,,,,,,,,,,,,0,,,,0,,,,,,50.0016537,,,,
,26822112.15,49.9993744,74910.3671875,0.00593121046145258,1.20299398514435E-6,1,0.999253354069792,40.0298881530762,1.99730549914174,20.3499998897314,0.0671589010580549,0.0123975910320698,0.25,3.00478968077318E-5,0.00594937849318414,6.93273792908423E-5,49.9993744,49.9993744,74905.59375,74915.140625,57.0104209356599,20.5984852889207,17.973541,0,0,0,40,4449,49.9711,74910.3671875,,,,,,,,,,,,,0,,,,0,,,,,,49.9993744,,,,
,26822303.435,50.0002365,79691.23828125,0.00606241425973145,1.70095213094804E-6,1,0.999253354069792,40.0298881530762,1.99723960216246,20.3499998897314,0.0686552665838231,0.012670527395471,0.25,3.10229111265016E-5,0.00608207913273241,7.05914881717916E-5,50.0002365,50.0002365,79688.7109375,79693.765625,56.9369478548522,20.5998223539346,18.353191,0,0,0,40,4449,49.9726,79691.23828125,,,,,,,,,,,,,0,,,,0,,,,,,50.0002365,,,,
,26822490.805,50.0005836,84374.74609375,0.00618339404568742,1.39597483482203E-6,1,0.999253354069792,40.0298881530762,1.997317724115,20.3499998897314,0.0700385619339669,0.0129321205347528,0.25,3.27773734455221E-5,0.00620448518941493,7.25521399133949E-5,50.0005836,50.0005836,84372.3359375,84377.15625,57.115940785756,20.5969396890992,17.593889,0,0,0,40,4449,49.9692,84374.74609375,,,,,,,,,,,,,0,,,,-0.0049,,,,,,50.0005836,,,,
,26822673.45,49.9993477,88938.96484375,0.00629226203273213,1.33001557636561E-6,1,0.999253354069792,40.0298881530762,1.99722244014452,20.3499998897314,0.0712810619933247,0.0131527743600718,0.25,3.32050143506945E-5,0.00631471182140562,7.30900797491787E-5,49.9993477,49.9993477,88937.640625,88940.2890625,57.0033862789868,20.5973751244634,18.353191,0,0,0,40,4449,49.96855,88938.96484375,,,,,,,,,,,,,0,,,,-0.0049,,,,,,49.9993477,,,,
,26822867.155,49.9997215,86700.75390625,0.00624668204423585,1.32615881885339E-6,1,0.999253354069792,40.0298881530762,1.99723154147531,20.3499998897314,0.0707594743968368,0.0130576117363895,0.25,3.27632444460728E-5,0.00626849369205958,7.26477196202907E-5,49.9997215,49.9997215,86684.59375,86716.9140625,56.9291315696599,20.5997028526497,17.973541,0,0,0,40,4449,49.96525,86700.75390625,,,,,,,,,,,,,0,,,,-0.00245,,,,,,49.9997215,,,,
,26823051.445,49.9992905,82093.546875,0.00614338468328598,1.08200516042048E-6,1,0.999253354069792,40.0298881530762,1.99719069498783,20.3499998897314,0.0695718992702155,0.0128668282728027,0.25,3.40557031589876E-5,0.00616382848579527,7.38652393629966E-5,49.9992905,49.9992905,82091.046875,82096.046875,56.9900985941599,20.5977904600118,18.353191,0,0,0,40,4449,49.9658,82093.546875,,,,,,,,,,,,,0,,,,0,,,,,,49.9992905,,,,
,26823243.435,50.0000648,77294.625,0.00602612579910937,1.21947368342656E-6,1,0.999253354069792,40.0298881530762,1.99730836371328,20.3499998897314,0.0682390942424773,0.012601434337412,0.25,3.11977675454674E-5,0.00604512662063121,7.08234239859273E-5,50.0000648,50.0000648,77292.0546875,77297.1953125,57.1167224142753,20.5981109986463,17.973541,0,0,0,40,4449,49.9667,77294.625,,,,,,,,,,,,,0,,,,0,,,,,,50.0000648,,,,
,26823429.355,50.0004082,72647.37890625,0.0059049220427318,1.17184854677427E-6,1,0.999253354069792,40.0298881530762,1.99724768025533,20.3499998897314,0.0668542439314632,0.0123370391269493,0.25,2.92772452395746E-5,0.00592248969713019,6.86445952018949E-5,50.0004082,50.0004082,72646.1640625,72648.59375,57.0518472471791,20.5992822294764,17.973541,0,0,0,40,4449,49.9702,72647.37890625,,,,,,,,,,,,,0,,,,-0.0049,,,,,,50.0004082,,,,
,26823615.68,49.999218,67992.09375,0.00577688443543174,1.12064146800084E-6,1,0.999253354069792,40.0298881530762,1.99731097898392,20.3499998897314,0.0653971889910654,0.0120519776567562,0.25,2.6729232887511E-5,0.00579299700448166,6.57572562263961E-5,49.999218,49.999218,67990.5703125,67993.6171875,57.2808644033138,20.5986216559691,17.593889,0,0,0,40,4449,49.9729,67992.09375,,,,,,,,,,,,,0,,,,-0.0049,,,,,,49.999218,,,,
,26823803.535,49.99972345,63296.71484375,0.00563835283922729,1.03686533999487E-6,1,0.999253354069792,40.0298881530762,1.99725944937009,20.3499998897314,0.063815721803187,0.0117548360329581,0.25,2.50919452244502E-5,0.00565296270311383,6.36797490503496E-5,49.9995766,49.9998703,63293.00390625,63300.42578125,57.2550706621791,20.6005984139345,17.973541,0,0,0,40,4449,49.9703,63296.71484375,,,,,,,,,,,,,0,,,,0,,,,,,49.99972345,,,,
,26823992.925,49.9989052,58562.609375,0.0054892654243835,1.20417608631202E-6,1,0.999253354069792,40.0298881530762,1.99725605130315,20.3499998897314,0.0621110746697591,0.0114651853483668,0.25,2.60285670597442E-5,0.00550233025844198,6.40689216846399E-5,49.9989052,49.9989052,58557.69140625,58567.52734375,57.0424677049483,20.5997947759942,18.353191,0,0,0,40,4449,49.9714,58562.609375,,,,,,,,,,,,,0,,,,0,,,,,,49.9989052,,,,
,26824180.915,49.9990196,53866.001953125,0.00532607120822767,9.58036672453949E-7,1,0.999253354069792,40.0298881530762,1.99726041448047,20.3499998897314,0.0602523305114718,0.0111182131371963,0.25,2.44814695449309E-5,0.00533759842960572,6.18197563278465E-5,49.9990196,49.9990196,53862.21875,53869.78515625,57.1315733561406,20.6004290845513,17.593889,0,0,0,40,4449,49.9688,53866.001953125,,,,,,,,,,,,,0,,,,0,,,,,,49.9990196,,,,
,26824370.125,49.9998512,49136.423828125,0.00514896888278257,7.39737066967801E-7,1,0.999253354069792,40.0298881530762,1.9972529975872,20.3499998897314,0.0582361911312227,0.0107426172759712,0.25,2.2959120742913E-5,0.00515895934498049,5.94455124890172E-5,49.9998512,49.9998512,49130.0625,49142.78515625,57.0518472471791,20.6001254547199,17.973541,0,0,0,40,4449,49.97645,49136.423828125,,,,,,,,,,,,,0,,,,0.0049,,,,,,49.9998512,,,,
,26824555.35,50.0002441,44506.865234375,0.00495837335271488,1.03252480053173E-6,1,0.999253354069792,40.0298881530762,1.99729167128326,20.3499998897314,0.0560682187997039,0.0103454821547385,0.25,2.19901328543153E-5,0.0049668549988135,5.7470372868897E-5,50.0002441,50.0002441,44501.83984375,44511.890625,56.9807190519291,20.6020758136726,17.973541,0,0,0,40,4449,49.97485,44506.865234375,,,,,,,,,,,,,0,,,,0.00245,,,,,,50.0002441,,,,
,26824744.155,49.9995689,39789.384765625,0.00474526480434948,1.05609405862484E-6,1,0.999253354069792,40.0298881530762,1.9972960354373,20.3499998897314,0.0536428853674444,0.00991364285716927,0.25,2.20668625250885E-5,0.00475222690362697,5.63298698323499E-5,49.9995689,49.9995689,39784.3515625,39794.41796875,57.1370447557753,20.6024671554878,17.973541,0,0,0,40,4449,49.9735,39789.384765625,,,,,,,,,,,,,0,,,,-0.00245,,,,,,49.9995689,,,,
,26824931.525,49.9997711,35106.9609375,0.00451380165553087,6.90909306807341E-7,1,0.999253354069792,40.0298881530762,1.99726611132785,20.3499998897314,0.0510142499775915,0.00942099516488591,0.25,2.01348586233959E-5,0.00451931897986604,5.29818572328926E-5,49.9997711,49.9997711,35101.9375,35111.984375,57.2050464369484,20.6028464911436,17.973541,0,0,0,40,4449,49.9754,35106.9609375,,,,,,,,,,,,,0,,,,0,,,,,,49.9997711,,,,
,26825122.515,49.9991989,30334.6728515625,0.00424819630510651,8.55015824019707E-7,1,0.999253354069792,40.0298881530762,1.99725994902591,20.3499998897314,0.0479973512373769,0.00887881584351441,0.25,2.00052966812262E-5,0.00425228811175904,5.11333534854046E-5,49.9991989,49.9991989,30332.255859375,30337.08984375,56.933039712256,20.6027649835068,17.973541,0,0,0,40,4449,49.9752,30334.6728515625,,,,,,,,,,,,,0,,,,0,,,,,,49.9991989,,,,
,26825311.565,49.9999504,25610.900390625,0.00395474068325301,7.92465105295338E-7,1,0.999253354069792,40.0298881530762,1.99732169154428,20.3499998897314,0.0446719082385923,0.00826177958969486,0.25,1.82886404469027E-5,0.00395752849058054,4.74280562840124E-5,49.9999504,49.9999504,25609.751953125,25612.048828125,57.3723149400638,20.6040847404648,17.973541,0,0,0,40,4449,49.97585,25610.900390625,,,,,,,,,,,,,0,,,,0,,,,,,49.9999504,,,,
,26825499.33,49.9992371,20919.666015625,0.00362249816917719,7.35404777700454E-7,1,0.999253354069792,40.0298881530762,1.99739065433782,20.3499998897314,0.0409109935411192,0.00755888859935173,0.25,1.59980341770405E-5,0.00362411725421884,4.28040426095047E-5,49.9992371,49.9992371,20914.734375,20924.59765625,57.2136443506599,20.6058288802987,17.593889,0,0,0,40,4449,49.9757,20919.666015625,,,,,,,,,,,,,0,,,,0,,,,,,49.9992371,,,,
,26825684.765,50.0002823,16285.1030273438,0.00324899287816462,4.8385574734393E-7,1,0.999253354069792,40.0298881530762,1.9973619317627,20.3499998897314,0.0366816595237148,0.00678450536475791,0.25,1.48695858207184E-5,0.00324960894786444,3.89844661385362E-5,50.0002823,50.0002823,16280.25390625,16289.9521484375,57.0518472471791,20.6021894620471,17.973541,0,0,0,40,4449,49.9743,16285.1030273438,,,,,,,,,,,,,0,,,,-0.00245,,,,,,50.0002823,,,,
,26825869.8,49.9988632,11661.3354492187,0.00282417051268524,5.42390402740443E-7,1,0.999253354069792,40.0298881530762,1.99739014473838,20.3499998897314,0.0318785760781716,0.00589176354200459,0.25,1.25042184566079E-5,0.00282400333010159,3.35032878823498E-5,49.9988632,49.9988632,11657.609375,11665.0615234375,57.2363115777176,20.6029720583961,17.973541,0,0,0,40,4449,49.9762,11661.3354492187,,,,,,,,,,,,,0,,,,0,,,,,,49.9988632,,,,
,26826058.36,50.000164,6949.919921875,0.00232297128272958,4.72652296725485E-7,1,0.999253354069792,40.0298881530762,1.99735764515721,20.3499998897314,0.0262130642653358,0.00485210000512319,0.25,1.09038906676956E-5,0.00232226305890101,2.81873320185375E-5,50.000164,50.000164,6945.04931640625,6954.79052734375,57.0268351345637,20.6037865007412,17.973541,0,0,0,40,4449,49.97605,6949.919921875,,,,,,,,,,,,,0,,,,-0.00245,,,,,,50.000164,,,,
,26826243.375,50.0003815,2324.59387207031,0.00175543346805987,4.09982838077226E-7,1,0.999253354069792,40.0298881530762,1.99740752425439,20.3499998897314,0.0198045047836135,0.00366890550691982,0.25,8.50052759926404E-6,0.00175452041075753,2.15569997225807E-5,50.0003815,50.0003815,2322.16625976562,2327.021484375,57.2230238928907,20.6035207594852,17.593889,0,0,0,40,4449,49.9741,2324.59387207031,,,,,,,,,,,,,0,,,,0,,,,,,50.0003815,,,,
,26826338.225,50.0004311,-0.11417829990387,0.00143135220698913,3.97835663321405E-7,1,0.999253354069792,40.0298881530762,1.99729600509134,20.3499998897314,0.0161457678727428,0.00299322151069448,0.25,7.1149752781748E-6,0.00143049326487454,1.77573907448468E-5,50.0004311,50.0004311,-0.121790185570717,-0.106566414237022,57.1769078102561,20.6036018588663,17.973541,0,0,0,40,4417,49.97705,-0.11417829990387,,,,,,,,,,,,,0,,,,0,,,,,,50.0004311,,,,