File: data/monolayers/nanoparticles/Ol_CoFe_C/vsm/Backup/rawdata/DD172_6_HYST_100K.DAT
[Header]
; VSM Data File (default extension .dat)
; Copyright (c) 2003-2013, Quantum Design, Inc. All rights reserved.
TITLE,
FILEOPENTIME,26826978.16,11/07/2018,7:56 pm
BYAPP,VSM,2.0,2.0
INFO,PPMS VSM Option Release 1.4.10 Build 1,APPNAME
INFO,Quantum Design Linear Motor Servo Controller,MOTOR_MODULE_NAME
INFO,3101-100 M1,MOTOR_HW_VERSION
INFO,MMC1014,MOTOR_SERIAL_NUMBER
INFO,SRV No X-over 01.03.11,MOTOR_SOFTWARE_VERSION
INFO,Quantum Design VSM Detection Module,VSM_MODULE_NAME
INFO,3101-150 F0,VSM_HW_VERSION
INFO,VSM707,VSM_SERIAL_NUMBER
INFO,VSM No X-over 01.02.05 May 20 2008 13:51:47,VSM_SOFTWARE_VERSION
INFO,704,PREAMP_SERIAL_NUMBER
INFO,822,COIL_SERIAL_NUMBER
INFO,0,MOMENT_UNITS
INFO,CoFe2O4 DD67,SAMPLE_MATERIAL
INFO,Colloidal Crystal,SAMPLE_COMMENT
INFO,31.86,SAMPLE_MASS
INFO,,SAMPLE_VOLUME
INFO,,SAMPLE_MOLECULAR_WEIGHT
INFO,,SAMPLE_SIZE
INFO,,SAMPLE_SHAPE
DATATYPE,COMMENT,1
DATATYPE,TIME,2
STARTUPAXIS,X,2
STARTUPAXIS,Y1,5
[Data]
Comment,Time Stamp (sec),Temperature (K),Magnetic Field (Oe),Moment (emu),M. Std. Err. (emu),Transport Action,Averaging Time (sec),Frequency (Hz),Peak Amplitude (mm),Center Position (mm),Coil Signal' (mV),Coil Signal" (mV),Range (mV),M. Quad. Signal (emu),M. Raw' (emu),M. Raw" (emu),Min. Temperature (K),Max. Temperature (K),Min. Field (Oe),Max. Field (Oe),Mass (grams),Motor Lag (deg),Pressure (Torr),VSM Status (code),Motor Status (code),Measure Status (code),Measure Count,PPMS Status (code),System Temp. (K),System Field (Oe),Sample Position (deg),Bridge 1 Resistance (ohms),Bridge 1 Excitation (에),Bridge 2 Resistance (ohms),Bridge 2 Excitation (에),Bridge 3 Resistance (ohms),Bridge 3 Excitation (에),Bridge 4 Resistance (ohms),Bridge 4 Excitation (에),Signal 1 Vin (V),Signal 2 Vin (V),Digital Inputs (code),Drive 1 Iout (mA),Drive 1 Ipower (W),Drive 2 Iout (mA),Drive 2 Ipower (W),Pressure (),Map 20 (),Map 21 (),Map 22 (),Map 23 (),Map 24 (),Map 25 (),Map 26 (),Map 27 (),Map 28 (),Map 29 ()
,26826993.06,100.1873932,-0.106566414237022,,,2,,,,20.1499998667836,,,,,,,100.1873932,100.1873932,-0.106566414237022,-0.106566414237022,,,19.871798,,,,-99999999,4369,100.0267,-0.106566414237022,,,,,,,,,,,,,,,,,,,,,,,100.1873932,,,,
,26827267.935,100.026535,4820.5078125,0.00125736378819669,4.06068032303136E-7,1,0.999253354069792,40.0298881530762,1.99729849818806,20.1399996876717,0.0142855597536222,0.00256370147002137,0.25,4.51480938816043E-6,0.00126442548655522,8.44318569909007E-6,100.026535,100.026535,4816.830078125,4824.185546875,56.4632809721983,20.5996713705363,20.251448,0,0,0,40,4449,99.9058,4820.5078125,,,,,,,,,,,,,0,,,,-0.00245,,,,,,100.026535,,,,
,26827466.02,100.0041275,9769.826171875,0.00195455829022653,7.32218261558531E-7,1,0.999253354069792,40.0298881530762,1.99735545869198,20.1399996876717,0.0222087410537305,0.00397839212328471,0.25,6.43229492119306E-6,0.00196555179083638,1.25065375084517E-5,100.0041275,100.0041275,9763.4833984375,9776.1689453125,56.6938613853714,20.6034447515047,20.631098,0,0,0,40,4449,99.90195,9769.826171875,,,,,,,,,,,,,0,,,,-0.00245,,,,,,100.0041275,,,,
,26827665.465,100.0014725,14753.3969726562,0.00259883631276064,7.80797245697421E-7,1,0.999253354069792,40.0298881530762,1.9972673639476,20.1399996876717,0.029530200290803,0.00527911068960982,0.25,7.67321409056012E-6,0.00261347641213502,1.57012233506241E-5,100.0014725,100.0014725,14746.0439453125,14760.75,56.9213152844676,20.6037098088013,20.251448,0,0,0,40,4449,99.90225,14753.3969726562,,,,,,,,,,,,,0,,,,0,,,,,,100.0014725,,,,
,26827868.88,99.9991837,19836.8916015625,0.0031541026210032,7.69367381205057E-7,1,0.999253354069792,40.0298881530762,1.99727038757457,20.1399996876717,0.0358389909637178,0.00641259961948705,0.25,9.85289901838913E-6,0.00317189523860995,1.95421214332179E-5,99.9991837,99.9991837,19830.6640625,19843.119140625,56.6672860157175,20.6033282955405,20.251448,0,0,0,40,4449,99.9024,19836.8916015625,,,,,,,,,,,,,0,,,,-0.00245,,,,,,99.9991837,,,,
,26828054.15,99.9992981,24466.814453125,0.00357525282341667,7.736283727784E-7,1,0.999253354069792,40.0298881530762,1.99715472577551,20.1399996876717,0.0406227030061292,0.00726701580925544,0.25,1.10997485089424E-5,0.00359544918537751,2.20209456950926E-5,99.9992981,99.9992981,24460.646484375,24472.982421875,56.8587850029291,20.6062710624055,20.251448,0,0,0,40,4449,99.9031,24466.814453125,,,,,,,,,,,,,0,,,,-0.00245,,,,,,99.9992981,,,,
,26828238.32,100.0015182,29069.796875,0.00393150786611762,8.11047388537603E-7,1,0.999253354069792,40.0298881530762,1.99723957182026,20.1399996876717,0.044673879779868,0.00798477790838453,0.25,1.16809244272203E-5,0.00395374887314965,2.36189322488076E-5,100.0015182,100.0015182,29063.4375,29076.15625,57.0401228193907,20.6056317161086,20.251448,0,0,0,40,4449,99.90135,29069.796875,,,,,,,,,,,,,0,,,,0,,,,,,100.0015182,,,,
,26828428.86,100.0024071,33831.35546875,0.00424804278402492,1.15648519260342E-6,1,0.999253354069792,40.0298881530762,1.99718157254472,20.1399996876717,0.0482678019784267,0.00863846013825394,0.25,1.36647758073328E-5,0.00427210605086094,2.64919052226275E-5,100.0022278,100.0025864,33826.4609375,33836.25,57.0057311645445,20.6058901299859,20.631098,0,0,0,40,4449,99.8986,33831.35546875,,,,,,,,,,,,,0,,,,-0.00245,,,,,,100.0024071,,,,
,26828618.88,100.0019455,38578.5390625,0.00452079089558789,1.34895395636624E-6,1,0.999253354069792,40.0298881530762,1.99728766499119,20.1399996876717,0.0513726004016099,0.00917818480351948,0.25,1.32664066411614E-5,0.00454644013235498,2.68261284090942E-5,100.0019455,100.0019455,38573.3984375,38583.6796875,56.8845787440637,20.6051422176623,20.251448,0,0,0,40,4449,99.89425,38578.5390625,,,,,,,,,,,,,0,,,,0,,,,,,100.0019455,,,,
,26828807.55,100.004158,43295.025390625,0.00476067481454163,1.55695859589389E-6,1,0.999253354069792,40.0298881530762,1.99716439841685,20.1399996876717,0.0540951820568915,0.00966821215566952,0.25,1.4366062343729E-5,0.00478772229667575,2.8559713992662E-5,100.004158,100.004158,43288.79296875,43301.2578125,57.0815491309099,20.6088357766022,20.631098,0,0,0,40,4449,99.88595,43295.025390625,,,,,,,,,,,,,0,,,,-0.00245,,,,,,100.004158,,,,
,26828995.47,100.00491715,47991.328125,0.0049728861421566,1.28658667966073E-6,1,0.999253354069792,40.0298881530762,1.99716664415019,20.1399996876717,0.0564997351214654,0.0101408491781497,0.25,1.87555214007385E-5,0.00500116851963944,3.35108195164734E-5,100.004364,100.0054703,47983.87109375,47998.78515625,57.0252718775253,20.6065973860977,20.631098,0,0,0,40,4449,99.8781,47991.328125,,,,,,,,,,,,,0,,,,0.00245,,,,,,100.00491715,,,,
,26829182.565,100.0044327,52666.78125,0.00516120232834556,1.846010125333E-6,1,0.999253354069792,40.0298881530762,1.9971633930841,20.1399996876717,0.058644978024894,0.0104947588723853,0.25,1.69074917099868E-5,0.00519060510872566,3.21105932481529E-5,100.0044327,100.0044327,52661.953125,52671.609375,57.1683098965445,20.6065922648208,20.631098,0,0,0,40,4449,99.87085,52666.78125,,,,,,,,,,,,,0,,,,0,,,,,,100.0044327,,,,
,26829368.795,100.0043411,57320.197265625,0.00533405814130803,1.52523657487581E-6,1,0.999253354069792,40.0298881530762,1.99713983826245,20.1399996876717,0.0606093088869287,0.01084375346902,0.25,1.73571726949885E-5,0.00536448885085928,3.29692601924415E-5,100.0043411,100.0043411,57316.36328125,57324.03125,56.9650864815445,20.6053391866223,20.631098,0,0,0,40,4449,99.8628,57320.197265625,,,,,,,,,,,,,0,,,,-0.0049,,,,,,100.0043411,,,,
,26829556.67,100.0052567,62015.17578125,0.00549459910845546,1.19716171629244E-6,1,0.999253354069792,40.0298881530762,1.99714351906815,20.1399996876717,0.0624332904082386,0.0111748069624687,0.25,1.8385552730047E-5,0.00552598844601805,3.43666896469385E-5,100.0052567,100.0052567,62009.0234375,62021.328125,56.8595666314483,20.6054839965635,21.01075,0,0,0,40,4449,99.85405,62015.17578125,,,,,,,,,,,,,0,,,,0,,,,,,100.0052567,,,,
,26829741.03,100.0042419,66622.3046875,0.0056351363880404,1.36875677112875E-6,1,0.999253354069792,40.0298881530762,1.99718246099283,20.1399996876717,0.064029359921174,0.0114751867027761,0.25,2.02143973899806E-5,0.00566736939797983,3.65069061166307E-5,100.0042419,100.0042419,66617.34375,66627.265625,56.7743691228522,20.6052776937539,20.631098,0,0,0,40,4449,99.84725,66622.3046875,,,,,,,,,,,,,0,,,,-0.00245,,,,,,100.0042419,,,,
,26829928.555,100.0034332,71308.734375,0.00577483245772002,1.29866234055734E-6,1,0.999253354069792,40.0298881530762,1.99703878965014,20.1399996876717,0.0656148634384849,0.011746461129204,0.25,1.97266284538734E-5,0.00580791352886751,3.63079263885957E-5,100.0034332,100.0034332,71302.546875,71314.921875,56.9947883652753,20.6053933194847,20.631098,0,0,0,40,4449,99.8389,71308.734375,,,,,,,,,,,,,0,,,,-0.00245,,,,,,100.0034332,,,,
,26830114.28,100.00528335,75950.796875,0.00590091336234149,1.87612993878072E-6,1,0.999253354069792,40.0298881530762,1.99715021151922,20.1399996876717,0.067051289565182,0.0120049110320108,0.25,2.03790333226511E-5,0.00593476231640914,3.72123223568999E-5,100.0050735,100.0054932,75945.8515625,75955.7421875,56.9900985941599,20.6046244359888,20.631098,0,0,0,40,4449,99.8323,75950.796875,,,,,,,,,,,,,0,,,,0,,,,,,100.00528335,,,,
,26830301.915,100.0041351,80640.30078125,0.00602204611752766,1.98044078170672E-6,1,0.999253354069792,40.0298881530762,1.99711310360124,20.1399996876717,0.0684271158621613,0.012250733252506,0.25,2.08691787008966E-5,0.00605663767844857,3.79330502964491E-5,100.0041351,100.0041351,80636.640625,80643.9609375,56.7673344661791,20.6031338785173,21.01075,0,0,0,40,4449,99.82815,80640.30078125,,,,,,,,,,,,,0,,,,0,,,,,,100.0041351,,,,
,26830491.875,100.0046387,85388.24609375,0.00613187343502453,2.16718160151046E-6,1,0.999253354069792,40.0298881530762,1.99704180064035,20.1399996876717,0.0696740347748144,0.0124691997604926,0.25,2.09592566287598E-5,0.00616714468694967,3.82157392792679E-5,100.0046387,100.0046387,85381.9453125,85394.546875,56.6962062709291,20.6053023772497,20.251448,0,0,0,40,4449,99.8169,85388.24609375,,,,,,,,,,,,,0,,,,-0.00245,,,,,,100.0046387,,,,
,26830704.095,100.0039978,89973.93359375,0.006235872548261,2.488979362219E-6,1,0.999253354069792,40.0298881530762,1.99708368104625,20.1399996876717,0.0708551370197198,0.0126955864082565,0.25,2.27114421939555E-5,0.00627178596164427,4.01516354619029E-5,100.0039978,100.0039978,89969.6953125,89978.171875,57.1128142716791,20.60537860034,20.251448,0,0,0,40,4449,99.81485,89973.93359375,,,,,,,,,,,,,0,,,,0.00245,,,,,,100.0039978,,,,
,26830889.34,100.0005264,85351.28515625,0.00613776069188516,1.76394270430016E-6,1,0.999253354069792,40.0298881530762,1.99707112384535,20.1399996876717,0.0697414275763356,0.0124840814464484,0.25,2.12187924977342E-5,0.00617306519900863,3.84943603245645E-5,100.0005264,100.0005264,85347.671875,85354.8984375,56.9557069393137,20.6067527159247,20.631098,0,0,0,40,4449,99.81615,85351.28515625,,,,,,,,,,,,,0,,,,0.00245,,,,,,100.0005264,,,,
,26831077.76,99.9988861,80642.46875,0.00602624698644979,1.76193638465631E-6,1,0.999253354069792,40.0298881530762,1.99701274832081,20.1399996876717,0.0684775990191511,0.0122242495951138,0.25,1.78509137291155E-5,0.00606087039085592,3.49128261805052E-5,99.9988861,99.9988861,80636.4296875,80648.5078125,56.9955699937945,20.60634108378,21.01075,0,0,0,40,4449,99.8145,80642.46875,,,,,,,,,,,,,0,,,,-0.00245,,,,,,99.9988861,,,,
,26831268.92,99.9975204,75863.6171875,0.00590918582721267,1.78980658679054E-6,1,0.999253354069792,40.0298881530762,1.99711679736079,20.1399996876717,0.0671447050703353,0.012018664222653,0.25,2.014826615917E-5,0.0059430814591663,3.70095885757808E-5,99.9975204,99.9975204,75854.6640625,75872.5703125,56.8978664288906,20.6053885899528,20.251448,0,0,0,40,4449,99.818,75863.6171875,,,,,,,,,,,,,0,,,,-0.00245,,,,,,99.9975204,,,,
,26831455.275,99.9984512,71205.04296875,0.00578908570729734,2.07359166979369E-6,1,0.999253354069792,40.0298881530762,1.99708000658495,20.1399996876717,0.0657803780354005,0.0117625671979046,0.25,1.86140272269333E-5,0.00582224899637057,3.52375656775109E-5,99.9984512,99.9984512,71201.53125,71208.5546875,56.7118388413137,20.6079357510891,20.631098,0,0,0,40,4449,99.81805,71205.04296875,,,,,,,,,,,,,0,,,,-0.00245,,,,,,99.9984512,,,,
,26831647.795,99.997818,66393.4921875,0.00565353557189769,1.39722428275504E-6,1,0.999253354069792,40.0298881530762,1.9971834199135,20.1399996876717,0.0642351971948146,0.0115309087035406,0.25,2.18742392002525E-5,0.0056858649059696,3.82411295435773E-5,99.997818,99.997818,66388.546875,66398.4375,57.0010413934291,20.6058464544025,21.01075,0,0,0,40,4449,99.82155,66393.4921875,,,,,,,,,,,,,0,,,,0,,,,,,99.997818,,,,
,26831838.195,99.9985886,61635.40625,0.00550918636475114,1.90195124754203E-6,1,0.999253354069792,40.0298881530762,1.99738491713389,20.1399996876717,0.0626134484174071,0.0111644294676178,0.25,1.47840751766506E-5,0.00554066355984396,3.0802718814295E-5,99.9985886,99.9985886,61630.52734375,61640.28515625,56.976810909333,20.6038558891469,20.631098,0,0,0,40,4449,99.8256,61635.40625,,,,,,,,,,,,,0,,,,0.00245,,,,,,99.9985886,,,,
,26832028.86,99.9972,56870.1875,0.00535242916329478,1.62629267619102E-6,1,0.999253354069792,40.0298881530762,1.99726530035158,20.1399996876717,0.0608212465391376,0.0108838498994087,0.25,1.75837699158235E-5,0.00538295684278128,3.32695658088019E-5,99.9972,99.9972,56865.29296875,56875.08203125,57.0096393071407,20.6083427984169,20.251448,0,0,0,40,4449,99.82705,56870.1875,,,,,,,,,,,,,0,,,,0,,,,,,99.9972,,,,
,26832215.925,99.9961777,52197.09765625,0.00519019721651652,1.89549637144058E-6,1,0.999253354069792,40.0298881530762,1.99744865275161,20.1399996876717,0.0589806079002264,0.0105653056566367,0.25,1.78772018037661E-5,0.00521975515940119,3.31900073050395E-5,99.9961777,99.9961777,52190.8125,52203.3828125,57.1386080128137,20.6048416996007,21.3904,0,0,0,40,4449,99.8335,52197.09765625,,,,,,,,,,,,,0,,,,0,,,,,,99.9961777,,,,
,26832400.905,99.9962692,47573.162109375,0.00500940345546525,1.48127881029277E-6,1,0.999253354069792,40.0298881530762,1.9971698126382,20.1399996876717,0.0569104974491951,0.0102389100117416,0.25,2.09510127720749E-5,0.00503788077957184,3.58437476850996E-5,99.9962692,99.9962692,47565.65234375,47580.671875,57.0502839901407,20.6059548674664,20.631098,0,0,0,40,4449,99.8419,47573.162109375,,,,,,,,,,,,,0,,,,-0.00245,,,,,,99.9962692,,,,
,26832588.02,99.9956131,42897.826171875,0.00481365938297318,1.36525129149515E-6,1,0.999253354069792,40.0298881530762,1.99729937368339,20.1399996876717,0.0546964550167252,0.00980057773935859,0.25,1.66325248368942E-5,0.00484099500362091,3.10132207974136E-5,99.9956131,99.9956131,42892.72265625,42902.9296875,56.926005055583,20.609261274092,20.631098,0,0,0,40,4449,99.84655,42897.826171875,,,,,,,,,,,,,0,,,,0.00245,,,,,,99.9956131,,,,
,26832776.29,99.9969177,38192.845703125,0.004592887778968,1.05674300682923E-6,1,0.999253354069792,40.0298881530762,1.99737973218387,20.1399996876717,0.052189751795582,0.00934972091371491,0.25,1.56397069773537E-5,0.0046189327414913,2.94445965506197E-5,99.9969177,99.9969177,38187.57421875,38198.1171875,57.1010898438907,20.6101060221541,21.01075,0,0,0,40,4449,99.85265,38192.845703125,,,,,,,,,,,,,0,,,,0,,,,,,99.9969177,,,,
,26832963.73,99.99645235,33509.267578125,0.00434763859830778,9.23079614529943E-7,1,0.999253354069792,40.0298881530762,1.99740705147245,20.1399996876717,0.0494028447881987,0.00885250503149644,0.25,1.49007634015017E-5,0.00437225737701222,2.80482881348782E-5,99.9963608,99.9965439,33505.4453125,33513.08984375,56.8392442899483,20.6117914334234,21.01075,0,0,0,40,4449,99.858,33509.267578125,,,,,,,,,,,,,0,,,,0,,,,,,99.99645235,,,,
,26833156.055,99.9950638,28703.3134765625,0.00406490335456589,1.11227682113229E-6,1,0.999253354069792,40.0298881530762,1.99735214074322,20.1399996876717,0.0461873183302907,0.00828325923647578,0.25,1.44501259519252E-5,0.00408788655723361,2.68195978202314E-5,99.9950638,99.9950638,28695.982421875,28710.64453125,56.7204367550252,20.6137813417582,21.01075,0,0,0,40,4449,99.8668,28703.3134765625,,,,,,,,,,,,,0,,,,-0.00245,,,,,,99.9950638,,,,
,26833340.985,99.9957962,24082.021484375,0.00375417293805451,6.86736648891779E-7,1,0.999253354069792,40.0298881530762,1.99729469904308,20.1399996876717,0.0426545199627258,0.00765343362871943,0.25,1.36010240932071E-5,0.00377536943401119,2.50906952734038E-5,99.9957962,99.9957962,24080.84765625,24083.1953125,57.065134932006,20.610731109891,21.01075,0,0,0,40,4449,99.875,24082.021484375,,,,,,,,,,,,,0,,,,0,,,,,,99.9957962,,,,
,26833529.58,99.9958954,19368.177734375,0.00338793116634426,9.65656714470718E-7,1,0.999253354069792,40.0298881530762,1.99732817174375,20.1399996876717,0.0384945542606026,0.00690164778834738,0.25,1.17584706500327E-5,0.00340703507439891,2.21823202184604E-5,99.9958954,99.9958954,19360.708984375,19375.646484375,56.8767624588714,20.6122058836991,21.3904,0,0,0,40,4449,99.88055,19368.177734375,,,,,,,,,,,,,0,,,,-0.00245,,,,,,99.9958954,,,,
,26833715.75,99.9959564,14717.1958007813,0.00296802724415452,6.27979278116815E-7,1,0.999253354069792,40.0298881530762,1.9972945159051,20.1399996876717,0.0337207489477182,0.00605725837165105,0.25,1.12339369741979E-5,0.00298473858815036,2.0419138206881E-5,99.9959564,99.9959564,14713.310546875,14721.0810546875,57.0354330482753,20.6106782821425,21.01075,0,0,0,40,4449,99.887,14717.1958007813,,,,,,,,,,,,,0,,,,0.00245,,,,,,99.9959564,,,,
,26833901.455,99.9959793,10075.8784179688,0.00247318155163344,5.88904060438425E-7,1,0.999253354069792,40.0298881530762,1.99740864684513,20.1399996876717,0.0281009614393674,0.00504200730110716,0.25,8.83132605706686E-6,0.00248709090929216,1.65200058893522E-5,99.9959793,99.9959793,10068.419921875,10083.3369140625,56.7829670365637,20.6087656854051,20.631098,0,0,0,40,4449,99.89265,10075.8784179688,,,,,,,,,,,,,0,,,,0.00245,,,,,,99.9959793,,,,
,26834088.83,99.997303,5393.2841796875,0.0018745320922707,4.81961788496103E-7,1,0.999253354069792,40.0298881530762,1.99757385965869,20.1399996876717,0.0212998270908398,0.00382559441294154,0.25,6.99815856752088E-6,0.00188506146525109,1.28537199508331E-5,99.9972763,99.9973297,5388.35791015625,5398.21044921875,57.159711982833,20.6045416984542,21.01075,0,0,0,40,4449,99.90065,5393.2841796875,,,,,,,,,,,,,0,,,,-0.00245,,,,,,99.997303,,,,
,26834271.53,99.99530415,827.561950683594,0.00116906246103928,3.70664349691128E-7,1,0.999253354069792,40.0298881530762,1.99745378060028,20.1399996876717,0.0132823438862902,0.00238901259921671,0.25,4.64209307965904E-6,0.00117562213076515,8.30888605143331E-6,99.9949799,99.9956284,820.030578613281,835.093322753906,57.2027015513907,20.6069234993072,20.631098,0,0,0,40,4449,99.90455,827.561950683594,,,,,,,,,,,,,0,,,,-0.00245,,,,,,99.99530415,,,,
,26834454.175,99.9999313,-3733.77099609375,0.000311945651084678,4.32218893171192E-7,1,0.999253354069792,40.0298881530762,1.99746674497985,20.1399996876717,0.00354412961023768,0.000637960567032262,0.25,1.28355283598767E-6,0.000313696876188108,2.25997104123017E-6,99.9999313,99.9999313,-3737.62182617188,-3729.92016601562,57.2472543769868,20.6083399254839,20.631098,0,0,0,40,4449,99.9087,-3733.77099609375,,,,,,,,,,,,,0,,,,-0.00245,,,,,,99.9999313,,,,
,26834639.415,100.004631,-8363.10302734375,-0.000711460410126334,6.53786225114773E-7,1,0.999253354069792,40.0298881530762,1.99736573902912,20.1399996876717,-0.00808401634042487,-0.00144815084547803,0.25,-2.33895017570372E-6,-0.000715460546220619,-4.55322797131053E-6,100.004631,100.004631,-8367.947265625,-8358.2587890625,57.0080760501022,20.607085835526,21.01075,0,0,0,40,4449,99.89995,-8363.10302734375,,,,,,,,,,,,,0,,,,0,,,,,,100.004631,,,,
,26834826.355,100.0062866,-13036.65625,-0.00173642533858616,7.79173716780757E-7,1,0.999253354069792,40.0298881530762,1.9973420423529,20.1399996876717,-0.0197277367263098,-0.003548183389301,0.25,-6.94539663755439E-6,-0.00174619618060476,-1.23310481195956E-5,100.0062866,100.0062866,-13041.6787109375,-13031.6337890625,57.1675282680253,20.6108158649784,21.3904,0,0,0,40,4449,99.8893,-13036.65625,,,,,,,,,,,,,0,,,,0.0049,,,,,,100.0062866,,,,
,26835014.94,100.0057755,-17747.572265625,-0.00258171587310479,8.25304949067016E-7,1,0.999253354069792,40.0298881530762,1.99732945479238,20.1399996876717,-0.0293309784469428,-0.005276807218637,0.25,-1.04872493751462E-5,-0.00259626143581466,-1.84546366911205E-5,100.0057755,100.0057755,-17751.443359375,-17743.701171875,57.149550812083,20.611779190493,21.01075,0,0,0,40,4449,99.87785,-17747.572265625,,,,,,,,,,,,,0,,,,0,,,,,,100.0057755,,,,
,26835202.595,100.0068283,-22439.0703125,-0.00321304492664908,7.56032385788443E-7,1,0.999253354069792,40.0298881530762,1.99734133680713,20.1399996876717,-0.036506613459937,-0.00655246573577532,0.25,-1.18021229344145E-5,-0.00323117537147308,-2.16576631537374E-5,100.0067291,100.0069275,-22446.328125,-22431.8125,57.2230238928907,20.6130448143605,20.631098,0,0,0,40,4449,99.86675,-22439.0703125,,,,,,,,,,,,,0,,,,0,,,,,,100.0068283,,,,
,26835390.86,100.0070343,-27143.27734375,-0.00369049659468834,1.2743026554684E-6,1,0.999253354069792,40.0298881530762,1.99741354001912,20.1399996876717,-0.0419333335915213,-0.00752563343028981,0.25,-1.3546002656223E-5,-0.00371134989281911,-2.48025240726973E-5,100.0070343,100.0070343,-27146.8828125,-27139.671875,57.2081729510253,20.6103532462274,21.01075,0,0,0,40,4449,99.8568,-27143.27734375,,,,,,,,,,,,,0,,,,-0.0049,,,,,,100.0070343,,,,
,26835581.43,100.0047684,-31905.6357421875,-0.00406962294131269,1.30937406860107E-6,1,0.999253354069792,40.0298881530762,1.9973420287729,20.1399996876717,-0.0462398045686214,-0.0082993779164302,0.25,-1.50852353726318E-5,-0.00409265106540105,-2.74258953790269E-5,100.0047684,100.0047684,-31911.841796875,-31899.4296875,57.0846756449868,20.6104068214191,21.01075,0,0,0,40,4449,99.84875,-31905.6357421875,,,,,,,,,,,,,0,,,,-0.00245,,,,,,100.0047684,,,,
,26835769.11,100.0064316,-36594.8515625,-0.00437747108738554,1.02026680055815E-6,1,0.999253354069792,40.0298881530762,1.9973752327501,20.1399996876717,-0.0497404857044661,-0.00891786087595544,0.25,-1.54654402367142E-5,-0.00440227816121636,-2.86571133307619E-5,100.0064316,100.0064316,-36598.69140625,-36591.01171875,57.2386564632753,20.6101125476478,20.631098,0,0,0,40,4449,99.83755,-36594.8515625,,,,,,,,,,,,,0,,,,0.00245,,,,,,100.0064316,,,,
,26835958.07,100.007225,-41315.908203125,-0.00464153030519921,1.35029944548521E-6,1,0.999253354069792,40.0298881530762,1.99725065333314,20.1399996876717,-0.0527350769518505,-0.00947324396336238,0.25,-1.80589485333568E-5,-0.00466786604149022,-3.19715968872059E-5,100.007225,100.007225,-41321.04296875,-41310.7734375,57.1448610409676,20.6101595481348,21.01075,0,0,0,40,4449,99.824,-41315.908203125,,,,,,,,,,,,,0,,,,-0.0049,,,,,,100.007225,,,,
,26836147.385,100.0038605,-46047.45703125,-0.00487036194085718,1.78178400601512E-6,1,0.999253354069792,40.0298881530762,1.997341630435,20.1399996876717,-0.0553387321068923,-0.00993564753799387,0.25,-1.8588145184087E-5,-0.00489803794784188,-3.30925449123859E-5,100.0038605,100.0038605,-46053.734375,-46041.1796875,57.2042648084291,20.6118432891846,21.01075,0,0,0,40,4449,99.8207,-46047.45703125,,,,,,,,,,,,,0,,,,0.00245,,,,,,100.0038605,,,,
,26836340.68,100.0051041,-50877.298828125,-0.0050797514439819,1.7221732925063E-6,1,0.999253354069792,40.0298881530762,1.99731439048822,20.1399996876717,-0.0577152741932863,-0.0103760545964472,0.25,-2.06534231493677E-5,-0.00510865570105865,-3.5691789933236E-5,100.0051041,100.0051041,-50881.20703125,-50873.390625,57.3183825722368,20.6150984360798,20.631098,0,0,0,40,4449,99.8089,-50877.298828125,,,,,,,,,,,,,0,,,,0,,,,,,100.0051041,,,,
,26836532.71,100.004982,-55676.673828125,-0.0052662446162732,1.77545567613548E-6,1,0.999253354069792,40.0298881530762,1.99728629247744,20.1399996876717,-0.0598387174254928,-0.0107293190487801,0.25,-1.90841433482501E-5,-0.00529626087396883,-3.45596640242472E-5,100.004982,100.004982,-55682.9453125,-55670.40234375,57.2832092888714,20.6141794926275,21.01075,0,0,0,40,4449,99.8019,-55676.673828125,,,,,,,,,,,,,0,,,,0.00245,,,,,,100.004982,,,,
,26836720.875,100.003212,-60377.576171875,-0.00543394022182924,2.01787158035097E-6,1,0.999253354069792,40.0298881530762,1.99738117559489,20.1399996876717,-0.0617503488470121,-0.0110552865504203,0.25,-1.83628241758006E-5,-0.00546496070445412,-3.4220229038942E-5,100.003212,100.003212,-60382.5078125,-60372.64453125,57.149550812083,20.6145677565825,20.631098,0,0,0,40,4449,99.7952,-60377.576171875,,,,,,,,,,,,,0,,,,0,,,,,,100.003212,,,,
,26836911.15,100.00354,-65132.607421875,-0.00558662573237377,1.93748798845286E-6,1,0.999253354069792,40.0298881530762,1.9973181952218,20.1399996876717,-0.0634829650572908,-0.011371813240731,0.25,-1.95259236674442E-5,-0.00561856168452933,-3.57251472139226E-5,100.00354,100.00354,-65134.9765625,-65130.23828125,57.1323549846599,20.6136014129637,21.01075,0,0,0,40,4449,99.78705,-65132.607421875,,,,,,,,,,,,,0,,,,0,,,,,,100.00354,,,,
,26837102.4,100.0038147,-69912.31640625,-0.00573205320845726,1.58478496876264E-6,1,0.999253354069792,40.0298881530762,1.99734439458266,20.1399996876717,-0.0651372583097625,-0.0116657820095231,0.25,-1.99432002893707E-5,-0.00576486770849209,-3.64523828489441E-5,100.0038147,100.0038147,-69919.953125,-69904.6796875,56.9830639374868,20.6127049248481,21.01075,0,0,0,40,4449,99.7794,-69912.31640625,,,,,,,,,,,,,0,,,,-0.00245,,,,,,100.0038147,,,,
,26837293.71,100.0042572,-74692.953125,-0.00586377541237918,2.19137900468892E-6,1,0.999253354069792,40.0298881530762,1.99735617812772,20.1399996876717,-0.0666323624295375,-0.0119491793977713,0.25,-2.18485391170486E-5,-0.00589738786199924,-3.86307951330872E-5,100.0042572,100.0042572,-74701.515625,-74684.390625,57.3644986548715,20.6143223439474,21.01075,0,0,0,40,4449,99.77445,-74692.953125,,,,,,,,,,,,,0,,,,0,,,,,,100.0042572,,,,
,26837483.32,100.0051956,-79429.96484375,-0.00598667380254122,2.42460725657373E-6,1,0.999253354069792,40.0298881530762,1.99735108327238,20.1399996876717,-0.0680216672706864,-0.0122430691956363,0.25,-2.62371188305968E-5,-0.00602102777141567,-4.32777681310493E-5,100.0051956,100.0051956,-79435.859375,-79424.0703125,57.1620568683907,20.6161968019972,21.01075,0,0,0,40,4449,99.76965,-79429.96484375,,,,,,,,,,,,,0,,,,0,,,,,,100.0051956,,,,
,26837674.085,100.0030441,-84197.03125,-0.00610250232158495,1.70124423757728E-6,1,0.999253354069792,40.0298881530762,1.99734093542923,20.1399996876717,-0.0693404550485991,-0.012465705754482,0.25,-2.56075516152037E-5,-0.00613757355313734,-4.28525436185469E-5,100.0030441,100.0030441,-84203.140625,-84190.921875,57.0198004778906,20.6149179439743,21.01075,0,0,0,40,4449,99.7649,-84197.03125,,,,,,,,,,,,,0,,,,0.00245,,,,,,100.0030441,,,,
,26837858.48,100.0026474,-88803.97265625,-0.00620969603422664,1.92603074027168E-6,1,0.999253354069792,40.0298881530762,1.99750643843961,20.1399996876717,-0.0705655159945081,-0.0126804342132558,0.25,-2.57052709185243E-5,-0.00624543261859631,-4.31334185637603E-5,100.0026474,100.0026474,-88810,-88797.9453125,57.0487207331022,20.6137276566125,20.631098,0,0,0,40,4449,99.7644,-88803.97265625,,,,,,,,,,,,,0,,,,-0.00245,,,,,,100.0026474,,,,
,26838065.085,99.9990387,-86728.1328125,-0.00616756901156839,2.10794804582388E-6,1,0.999253354069792,40.0298881530762,1.99740130863576,20.1399996876717,-0.07008218186739,-0.0125985849540392,0.25,-2.59040547964825E-5,-0.00620304063200883,-4.32697627855491E-5,99.9990387,99.9990387,-86733.0390625,-86723.2265625,56.780622151006,20.6157242224736,21.3904,0,0,0,40,4449,99.76095,-86728.1328125,,,,,,,,,,,,,0,,,,-0.00245,,,,,,99.9990387,,,,
,26838249.905,99.9977646,-82110.765625,-0.00605951283796258,1.97073713603669E-6,1,0.999253354069792,40.0298881530762,1.99751679991218,20.1399996876717,-0.068861885197551,-0.0123540696847667,0.25,-2.3192129438698E-5,-0.00609432219245227,-4.03555469545678E-5,99.9977646,99.9977646,-82115.7265625,-82105.8046875,57.1987934087945,20.6143720855412,20.631098,0,0,0,40,4449,99.76265,-82110.765625,,,,,,,,,,,,,0,,,,-0.00245,,,,,,99.9977646,,,,
,26838439.815,99.9975815,-77364.5390625,-0.00594978018024045,2.29295645593677E-6,1,0.999253354069792,40.0298881530762,1.99749292497951,20.1399996876717,-0.0676122737793706,-0.0121373491979823,0.25,-2.32927285377973E-5,-0.00598390959711296,-4.02644453364494E-5,99.9975052,99.9976578,-77368.15625,-77360.921875,57.1503324406022,20.6129108211629,20.631098,0,0,0,40,4449,99.7648,-77364.5390625,,,,,,,,,,,,,0,,,,-0.00245,,,,,,99.9975815,,,,
,26838628.055,99.9979172,-72659.94921875,-0.00582543309260028,1.90785935086704E-6,1,0.999253354069792,40.0298881530762,1.99788087291638,20.1399996876717,-0.0662154991962582,-0.0118599248532414,0.25,-2.04197524872708E-5,-0.00585880917052415,-3.71351179811478E-5,99.9979172,99.9979172,-72663.796875,-72656.1015625,57.1128142716791,20.6104829893404,20.631098,0,0,0,40,4449,99.76975,-72659.94921875,,,,,,,,,,,,,0,,,,-0.00245,,,,,,99.9979172,,,,
,26838817.67,99.9956627,-67923.33984375,-0.0056983480161678,1.53485537894989E-6,1,0.999253354069792,40.0298881530762,1.99752807173016,20.1399996876717,-0.064757128993294,-0.0116128605544225,0.25,-2.10700676609764E-5,-0.00573094657513601,-3.75376680981738E-5,99.9954987,99.9958267,-67932.171875,-67914.5078125,56.8736359447945,20.6129298306763,21.01075,0,0,0,40,4449,99.7737,-67923.33984375,,,,,,,,,,,,,0,,,,0.00245,,,,,,99.9956627,,,,
,26839006.27,99.9967651,-63211.71875,-0.00555837199210243,1.96942149430123E-6,1,0.999253354069792,40.0298881530762,1.99751482315974,20.1399996876717,-0.0631703952189876,-0.0112995634166988,0.25,-1.7994567552993E-5,-0.00559013157507811,-3.41502176345121E-5,99.9967651,99.9967651,-63218.16015625,-63205.27734375,57.0588819038522,20.6141048069343,20.631098,0,0,0,40,4449,99.77755,-63211.71875,,,,,,,,,,,,,0,,,,-0.00245,,,,,,99.9967651,,,,
,26839196.645,99.9960938,-58452.2421875,-0.00540793272265617,1.71630468662501E-6,1,0.999253354069792,40.0298881530762,1.99738649806342,20.1399996876717,-0.0614474115451453,-0.0110441590179226,0.25,-2.19047982358996E-5,-0.00543877531571818,-3.77530029531474E-5,99.9960938,99.9960938,-58459.703125,-58444.78125,57.3129111726022,20.6157214631537,20.631098,0,0,0,40,4449,99.7832,-58452.2421875,,,,,,,,,,,,,0,,,,0.00245,,,,,,99.9960938,,,,
,26839387.065,99.9950943,-53695.12109375,-0.00524338758340031,2.3249373272452E-6,1,0.999253354069792,40.0298881530762,1.99734299279756,20.1399996876717,-0.0595783924197094,-0.0106944744006298,0.25,-1.99649722719668E-5,-0.00527325222757666,-3.54242156235206E-5,99.9950943,99.9950943,-53700.07421875,-53690.16796875,56.8806706014676,20.6147057569185,21.01075,0,0,0,40,4449,99.79085,-53695.12109375,,,,,,,,,,,,,0,,,,0.00245,,,,,,99.9950943,,,,
,26839580.575,99.9954758,-48860.4453125,-0.00506320664647321,1.27653709848666E-6,1,0.999253354069792,40.0298881530762,1.99742112400063,20.1399996876717,-0.0575324642224687,-0.0103288542593702,0.25,-1.93199098320311E-5,-0.00509200223463646,-3.43463309212304E-5,99.9954758,99.9954758,-48865.34375,-48855.546875,57.2144259791791,20.6134571683774,21.01075,0,0,0,40,4449,99.79825,-48860.4453125,,,,,,,,,,,,,0,,,,0,,,,,,99.9954758,,,,
,26839771.275,99.9950333,-44094.287109375,-0.0048676362197377,1.29356980553651E-6,1,0.999253354069792,40.0298881530762,1.99742668366454,20.1399996876717,-0.0553114323324208,-0.00992121835244544,0.25,-1.77230499049679E-5,-0.00489528153356067,-3.2256953339846E-5,99.9950333,99.9950333,-44102.99609375,-44085.578125,57.0627900464484,20.6105786139131,20.631098,0,0,0,40,4449,99.8039,-44094.287109375,,,,,,,,,,,,,0,,,,-0.00245,,,,,,99.9950333,,,,
,26839961.835,99.9958725,-39331.76953125,-0.00465198135963351,1.64718610400869E-6,1,0.999253354069792,40.0298881530762,1.99743582554804,20.1399996876717,-0.0528624676467314,-0.0094716967263559,0.25,-1.59766856416384E-5,-0.00467836613005177,-2.99486429977609E-5,99.9958725,99.9958725,-39335.69921875,-39327.83984375,57.1284468420637,20.6123249239316,21.01075,0,0,0,40,4449,99.8107,-39331.76953125,,,,,,,,,,,,,0,,,,-0.00245,,,,,,99.9958725,,,,
,26840151.965,99.9946899,-34581.017578125,-0.00441019407277461,1.37725226169161E-6,1,0.999253354069792,40.0298881530762,1.99753118719699,20.1399996876717,-0.0501151689173005,-0.0089891223943055,0.25,-1.58907369097733E-5,-0.00443516950148123,-2.92215292450193E-5,99.9946899,99.9946899,-34586.12890625,-34575.90625,57.0385595623522,20.6103700577241,20.631098,0,0,0,40,4449,99.82115,-34581.017578125,,,,,,,,,,,,,0,,,,-0.00245,,,,,,99.9946899,,,,
,26840342,99.9946365,-29834.0634765625,-0.004139173055981,1.21061486405726E-6,1,0.999253354069792,40.0298881530762,1.99747876872922,20.1399996876717,-0.0470324677246082,-0.00844442190384928,0.25,-1.55420229946617E-5,-0.00416257819872173,-2.81322134982659E-5,99.9946365,99.9946365,-29838.818359375,-29829.30859375,57.1073428720445,20.6108113155327,21.01075,0,0,0,40,4449,99.82895,-29834.0634765625,,,,,,,,,,,,,0,,,,-0.00245,,,,,,99.9946365,,,,
,26840535.15,99.9943466,-25006.587890625,-0.00382624066609577,1.14781197023462E-6,1,0.999253354069792,40.0298881530762,1.99747149753571,20.1399996876717,-0.0434742553856714,-0.00781692192003324,0.25,-1.52665912593832E-5,-0.0038478425394619,-2.69789643255123E-5,99.9943466,99.9943466,-25009.025390625,-25004.150390625,56.8454973181022,20.6096933205068,20.631098,0,0,0,40,4449,99.8374,-25006.587890625,,,,,,,,,,,,,0,,,,-0.00245,,,,,,99.9943466,,,,
,26840725.795,99.993454,-20241.9150390625,-0.00346633300608868,1.19117477873848E-6,1,0.999253354069792,40.0298881530762,1.99742366042128,20.1399996876717,-0.0393843832856052,-0.00707770663687297,0.25,-1.34437508314156E-5,-0.00348587685617158,-2.41124339310068E-5,99.993454,99.993454,-20246.865234375,-20236.96484375,57.2222422643714,20.6090074236321,21.01075,0,0,0,40,4449,99.84415,-20241.9150390625,,,,,,,,,,,,,0,,,,0.0049,,,,,,99.993454,,,,
,26840919.79,99.994873,-15396.2124023438,-0.00303952634044174,7.94641597422325E-7,1,0.999253354069792,40.0298881530762,1.99736193751594,20.1399996876717,-0.0345327525528439,-0.00621160260154133,0.25,-1.22299669743783E-5,-0.00305663902354522,-2.16385085859744E-5,99.994873,99.994873,-15402.5703125,-15389.8544921875,57.1472059265253,20.605736741616,21.3904,0,0,0,40,4449,99.85515,-15396.2124023438,,,,,,,,,,,,,0,,,,-0.0049,,,,,,99.994873,,,,
,26841112.38,99.9951019,-10582.029296875,-0.00253352910210928,6.17526086194625E-7,1,0.999253354069792,40.0298881530762,1.99757980363039,20.1399996876717,-0.0287861853929583,-0.00518147900787929,0.25,-1.04556744057545E-5,-0.00254777350287208,-1.83400131912514E-5,99.9951019,99.9951019,-10587.0908203125,-10576.9677734375,57.2425646058714,20.6070839676304,21.01075,0,0,0,40,4449,99.86125,-10582.029296875,,,,,,,,,,,,,0,,,,0.00245,,,,,,99.9951019,,,,
,26841300.6,99.995224,-5877.81201171875,-0.00194176630205846,4.44341415153521E-7,1,0.999253354069792,40.0298881530762,1.99754263801339,20.1399996876717,-0.022062009796867,-0.00397100794852236,0.25,-7.97511385276223E-6,-0.00195267094056176,-1.40452693554564E-5,99.995224,99.995224,-5881.7275390625,-5873.896484375,57.2839909173907,20.6060656117639,20.631098,0,0,0,40,4449,99.87015,-5877.81201171875,,,,,,,,,,,,,0,,,,-0.00245,,,,,,99.995224,,,,
,26841490.96,99.9958191,-1120.83410644531,-0.00121398846703865,4.62358336993852E-7,1,0.999253354069792,40.0298881530762,1.99741454609356,20.1399996876717,-0.0137916580800184,-0.00248560259819638,0.25,-5.24408627501917E-6,-0.00122079830741092,-9.05541445318876E-6,99.9958191,99.9958191,-1123.52319335938,-1118.14501953125,57.0541921327368,20.6071366174787,21.01075,0,0,0,40,4449,99.8749,-1120.83410644531,,,,,,,,,,,,,0,,,,-0.0049,,,,,,99.9958191,,,,
,26841681.85,99.9998322,3648.16479492188,-0.000310436921572616,4.66737381115023E-7,1,0.999253354069792,40.0298881530762,1.997455529189,20.1399996876717,-0.00352529321664176,-0.000644390133089688,0.25,-2.11397956667471E-6,-0.000312176793023839,-3.09099148348042E-6,99.9998322,99.9998322,3641.96069335937,3654.36889648438,57.3402681707753,20.6061630445349,21.01075,0,0,0,40,4449,99.877,3648.16479492188,,,,,,,,,,,,,0,,,,-0.0049,,,,,,99.9998322,,,,
,26841870.8,100.0020218,8370.03173828125,0.000727702228117229,6.35249471434614E-7,1,0.999253354069792,40.0298881530762,1.99750346539998,20.1399996876717,0.00826981462018508,0.00147726728058072,0.25,2.03606650589038E-6,0.000731794376096764,4.29985950221842E-6,100.0020218,100.0020218,8362.3251953125,8377.73828125,57.1636201254291,20.6050980934528,21.3904,0,0,0,40,4449,99.8749,8370.03173828125,,,,,,,,,,,,,0,,,,-0.0049,,,,,,100.0020218,,,,
,26842065.01,100.0044785,13224.1298828125,0.00178378300739738,6.86577129119634E-7,1,0.999253354069792,40.0298881530762,1.99754327693343,20.1399996876717,0.0202694417758949,0.00363547996263764,0.25,6.2696244710824E-6,0.00179382246600101,1.17985770663554E-5,100.0044785,100.0044785,13220.3837890625,13227.8759765625,57.139389641333,20.6043363388095,21.3904,0,0,0,40,4449,99.86385,13224.1298828125,,,,,,,,,,,,,0,,,,0.00245,,,,,,100.0044785,,,,
,26842259.475,100.0065727,18084.484375,0.00264237072140099,7.39934190236701E-7,1,0.999253354069792,40.0298881530762,1.99757240771382,20.1399996876717,0.030026611213892,0.00538408119019188,0.25,9.2101175439311E-6,0.00265726277700285,1.73557889578663E-5,100.0063858,100.0067596,18078.234375,18090.734375,57.1487691835637,20.6030706261514,21.01075,0,0,0,40,4449,99.8572,18084.484375,,,,,,,,,,,,,0,,,,0.00245,,,,,,100.0065727,,,,
,26842452.375,100.0051956,22905.8046875,0.00327125170637507,1.11559269344493E-6,1,0.999253354069792,40.0298881530762,1.99753666962846,20.1399996876717,0.0371727355198066,0.00666441917957497,0.25,1.13694736714677E-5,0.00328971363291805,2.13977950151219E-5,100.0051956,100.0051956,22900.90234375,22910.70703125,57.0737328457176,20.6028605622797,21.01075,0,0,0,40,4449,99.8459,22905.8046875,,,,,,,,,,,,,0,,,,0.00245,,,,,,100.0051956,,,,
,26842644.445,100.0071869,27703.732421875,0.00374117622862782,1.1366089194496E-6,1,0.999253354069792,40.0298881530762,1.99751155220898,20.1399996876717,0.042510516448537,0.00763320298807403,0.25,1.40761985369378E-5,0.0037623168534488,2.54847781276216E-5,100.0071869,100.0071869,27701.38671875,27706.078125,57.0377779338329,20.6037231918077,21.3904,0,0,0,40,4449,99.8385,27703.732421875,,,,,,,,,,,,,0,,,,0,,,,,,100.0071869,,,,
,26842838.44,100.004982,32552.2822265625,0.0041145410058399,9.89259653743505E-7,1,0.999253354069792,40.0298881530762,1.9975658792701,20.1399996876717,0.0467558775389067,0.00838805059286864,0.25,1.49208908548633E-5,0.0041378271216562,2.73895255237302E-5,100.004982,100.004982,32548.60546875,32555.958984375,57.126101956506,20.6011246375016,21.01075,0,0,0,40,4449,99.8296,32552.2822265625,,,,,,,,,,,,,0,,,,0,,,,,,100.004982,,,,
,26843028.045,100.0052261,37290.8125,0.00441695698866526,1.03582134590599E-6,1,0.999253354069792,40.0298881530762,1.99745801004978,20.1399996876717,0.0501914731026652,0.0089970144910145,0.25,1.54676048916253E-5,0.00444199184767721,2.876961126922E-5,100.0052261,100.0052261,37283.2265625,37298.3984375,57.2863358029484,20.6027571492125,21.01075,0,0,0,40,4449,99.8182,37290.8125,,,,,,,,,,,,,0,,,,0,,,,,,100.0052261,,,,
,26843224.515,100.0043869,42201.00390625,0.00468341754043879,1.36143380290538E-6,1,0.999253354069792,40.0298881530762,1.99745455111987,20.1399996876717,0.0532194663045108,0.00954127829188635,0.25,1.66168821165743E-5,0.00471000182501765,3.06327261070999E-5,100.0039749,100.0047989,42195.8671875,42206.140625,57.034651419756,20.6023085878715,20.631098,0,0,0,40,4449,99.80935,42201.00390625,,,,,,,,,,,,,0,,,,0.00245,,,,,,100.0043869,,,,
,26843414.08,100.0067596,46937.5078125,0.0049082026361799,1.67149733426255E-6,1,0.999253354069792,40.0298881530762,1.99751190937298,20.1399996876717,0.0557759573589102,0.00999847558373031,0.25,1.74094032146287E-5,0.0049361029912327,3.2005923364508E-5,100.0067596,100.0067596,46931.15234375,46943.86328125,57.115940785756,20.6047220939692,20.631098,0,0,0,40,4449,99.8013,46937.5078125,,,,,,,,,,,,,0,,,,0,,,,,,100.0067596,,,,
,26843607.65,100.0044174,51775.041015625,0.00511439840318266,1.22527936067623E-6,1,0.999253354069792,40.0298881530762,1.99751077677609,20.1399996876717,0.0581212460754544,0.010409136986898,0.25,1.74074697128102E-5,0.00514351635008228,3.25140548088385E-5,100.0044174,100.0044174,51771.40625,51778.67578125,57.2089545795445,20.6004475338918,21.01075,0,0,0,40,4449,99.7939,51775.041015625,,,,,,,,,,,,,0,,,,0,,,,,,100.0044174,,,,
,26843796.545,100.0051422,56496.28125,0.00529260339395299,1.47231979247534E-6,1,0.999253354069792,40.0298881530762,1.99761140703097,20.1399996876717,0.060150111861393,0.0107705971737507,0.25,1.79526925945448E-5,0.00532277949414625,3.3484629097705E-5,100.0051422,100.0051422,56491.14453125,56501.41796875,56.9142806277945,20.5914875644763,21.3904,0,0,0,40,4449,99.78695,56496.28125,,,,,,,,,,,,,0,,,,-0.00245,,,,,,100.0051422,,,,
,26843986.4,100.0033188,61239.9296875,0.00545877841908948,1.64240764053308E-6,1,0.999253354069792,40.0298881530762,1.99752050660706,20.1399996876717,0.062030852517982,0.0111405108720877,0.25,2.14468811413933E-5,0.00548993865632031,3.73783293822961E-5,100.0033188,100.0033188,61236.0546875,61243.8046875,57.017455592333,20.5982550063848,21.3904,0,0,0,40,4449,99.7804,61239.9296875,,,,,,,,,,,,,0,,,,-0.00245,,,,,,100.0033188,,,,
,26844179.225,100.0023117,66058.25,0.00561425770153383,1.37491497819954E-6,1,0.999253354069792,40.0298881530762,1.99757214821434,20.1399996876717,0.0638043327856384,0.0114320803734224,0.25,1.98718477486624E-5,0.0056463591825795,3.61334085377684E-5,100.0021591,100.0024643,66051.8515625,66064.6484375,57.1573670972753,20.5989402453107,20.631098,0,0,0,40,4449,99.7784,66058.25,,,,,,,,,,,,,0,,,,0.00245,,,,,,100.0023117,,,,
,26844375.345,100.0047684,70960.75390625,0.00575831968469371,2.22866666779614E-6,1,0.999253354069792,40.0298881530762,1.9975318766606,20.1399996876717,0.0654332283431714,0.0117686175425437,0.25,2.43048341574265E-5,0.00579128150163732,4.08921405917234E-5,100.0047684,100.0047684,70957.0703125,70964.4375,56.9682129956214,20.5984812796467,21.01075,0,0,0,40,4449,99.7682,70960.75390625,,,,,,,,,,,,,0,,,,-0.00245,,,,,,100.0047684,,,,
,26844566.735,100.0032349,75743.60546875,0.00589026452523202,2.12349034561043E-6,1,0.999253354069792,40.0298881530762,1.99755929591271,20.1399996876717,0.0669406627867377,0.0120004109379847,0.25,2.16241575029937E-5,0.00592403936217246,3.84576015440512E-5,100.0032349,100.0032349,75736.96875,75750.2421875,57.1026531009291,20.5983190183425,21.01075,0,0,0,40,4449,99.7638,75743.60546875,,,,,,,,,,,,,0,,,,0,,,,,,100.0032349,,,,
,26844764.21,100.00549695,80679.609375,0.00601756522832809,1.85843278341761E-6,1,0.999253354069792,40.0298881530762,1.99749752844335,20.1399996876717,0.0683797434464772,0.012294764175815,0.25,2.5312868983053E-5,0.0060521108973229,4.24076637177719E-5,100.0053558,100.0056381,80673.65625,80685.5625,57.0088576786214,20.6004278180155,21.01075,0,0,0,40,4449,99.757,80679.609375,,,,,,,,,,,,,0,,,,0.00245,,,,,,100.00549695,,,,
,26844959.335,100.0028992,85555.14453125,0.00613433517898957,2.03057400774128E-6,1,0.999253354069792,40.0298881530762,1.99737365189527,20.1399996876717,0.0697042947045575,0.0125258195766587,0.25,2.5320842017385E-5,0.00616960340573872,4.26221044223456E-5,100.0028992,100.0028992,85548.890625,85561.3984375,56.8329912617945,20.6016941039393,21.01075,0,0,0,40,4449,99.75335,85555.14453125,,,,,,,,,,,,,0,,,,-0.00245,,,,,,100.0028992,,,,
,26845173.255,100.0031128,89776.70703125,0.00622966925311571,2.28364758250743E-6,1,0.999253354069792,40.0298881530762,1.99747073705074,20.1399996876717,0.0707886010567583,0.0127368293864925,0.25,2.71989635337443E-5,0.00626552532345862,4.46704219956645E-5,100.0031128,100.0031128,89771.8203125,89781.59375,57.1644017539484,20.600064619843,21.3904,0,0,0,40,4449,99.7493,89776.70703125,,,,,,,,,,,,,0,,,,0,,,,,,100.0031128,,,,
,26845356.135,99.9990387,85206.796875,0.00613010889781741,2.09392079365397E-6,1,0.999253354069792,40.0298881530762,1.99744983173613,20.1399996876717,0.0696570090778012,0.0125276678098985,0.25,2.61758362804284E-5,0.00616534695642329,4.34797504655318E-5,99.9990387,99.9990387,85197.9296875,85215.6640625,56.7751507513714,20.6014334225418,21.3904,0,0,0,40,4449,99.7506,85206.796875,,,,,,,,,,,,,0,,,,0,,,,,,99.9990387,,,,
,26845550.04,99.9977493,80360.8203125,0.00601804255998942,1.68406534690414E-6,1,0.999253354069792,40.0298881530762,1.99748083138753,20.1399996876717,0.0683872913791901,0.0122802683747525,0.25,2.39552685876954E-5,0.00605259237516314,4.1051798575418E-5,99.9977493,99.9977493,80354.53125,80367.109375,57.1487691835637,20.599795055518,21.3904,0,0,0,40,4449,99.756,80360.8203125,,,,,,,,,,,,,0,,,,0.00245,,,,,,99.9977493,,,,
,26845744.455,99.9977112,75500.35546875,0.00589754139236558,2.13626853394085E-6,1,0.999253354069792,40.0298881530762,1.99754328565593,20.1399996876717,0.0670198056062204,0.0120323313183484,0.25,2.31553658316441E-5,0.005931351316962,4.00255532532513E-5,99.9977112,99.9977112,75493.015625,75507.6953125,56.9603967104291,20.5985938931887,21.3904,0,0,0,40,4449,99.75865,75500.35546875,,,,,,,,,,,,,0,,,,0,,,,,,99.9977112,,,,
,26845938.085,99.9964294,70660.71875,0.00577142793755038,2.13924985123752E-6,1,0.999253354069792,40.0298881530762,1.99761917981986,20.1399996876717,0.065589471179077,0.0117697945545105,0.25,2.20572135651167E-5,0.00580446906586374,3.86769240250874E-5,99.9964294,99.9964294,70656.921875,70664.515625,57.0119841926983,20.59966236623,21.01075,0,0,0,40,4449,99.7656,70660.71875,,,,,,,,,,,,,0,,,,-0.0049,,,,,,99.9964294,,,,
,26846129.55,99.9982986,65875.46484375,0.0056358979897099,1.85460339229541E-6,1,0.999253354069792,40.0298881530762,1.99757450954275,20.1399996876717,0.064045433231295,0.0115039396398171,0.25,2.23845209092549E-5,0.0056681135288899,3.87301237749857E-5,99.9982986,99.9982986,65869.265625,65881.6640625,56.8368994043906,20.6014041769799,21.770052,0,0,0,40,4449,99.76635,65875.46484375,,,,,,,,,,,,,0,,,,0,,,,,,99.9982986,,,,
,26846322.245,99.99603275,61061.26953125,0.00549064197897481,2.08721859373812E-6,1,0.999253354069792,40.0298881530762,1.9975931485185,20.1399996876717,0.0623977306172374,0.0111908395639287,0.25,2.02399382636191E-5,0.00552198641774345,3.62623224151087E-5,99.9959183,99.9961472,61056.48046875,61066.05859375,57.0643533034868,20.604293513595,21.01075,0,0,0,40,4449,99.77455,61061.26953125,,,,,,,,,,,,,0,,,,0,,,,,,99.99603275,,,,
,26846513.705,99.9967957,56275.9375,0.00533283005763058,1.39625577124911E-6,1,0.999253354069792,40.0298881530762,1.99755672062382,20.1399996876717,0.060604982828205,0.010856140130047,0.25,1.84313053884376E-5,0.00536323250779017,3.40900670181928E-5,99.9967957,99.9967957,56268.44921875,56283.42578125,57.1729996676599,20.6024178762038,21.3904,0,0,0,40,4449,99.77915,56275.9375,,,,,,,,,,,,,0,,,,0,,,,,,99.9967957,,,,
,26846707.93,99.9971466,51421.951171875,0.00516048139308666,1.47507241196639E-6,1,0.999253354069792,40.0298881530762,1.99764799584112,20.1399996876717,0.0586462191539153,0.0105180461070376,0.25,1.8824773958877E-5,0.00518985487192948,3.40836915487704E-5,99.9971466,99.9971466,51416.1875,51427.71484375,56.8368994043906,20.6028619550969,21.3904,0,0,0,40,4449,99.7876,51421.951171875,,,,,,,,,,,,,0,,,,0,,,,,,99.9971466,,,,
,26846898.675,99.995575,46656.28515625,0.00497288949552483,1.61538538718854E-6,1,0.999253354069792,40.0298881530762,1.99754549212658,20.1399996876717,0.0565111264001498,0.0101349685330138,0.25,1.80319396158031E-5,0.00500115400425489,3.28311955742732E-5,99.995575,99.995575,46648.83203125,46663.73828125,57.0643533034868,20.6017846236565,21.01075,0,0,0,40,4449,99.7913,46656.28515625,,,,,,,,,,,,,0,,,,0.00245,,,,,,99.995575,,,,
,26847088.22,99.9961624,41918.75,0.00477091036140157,1.52051892430593E-6,1,0.999253354069792,40.0298881530762,1.99734317199659,20.1399996876717,0.054211547649192,0.00971456566912992,0.25,1.65299569014997E-5,0.00479799005877798,3.08126843374413E-5,99.9961624,99.9961624,41911.30859375,41926.19140625,57.2120810936214,20.6024100265709,21.3904,0,0,0,40,4449,99.8014,41918.75,,,,,,,,,,,,,0,,,,0,,,,,,99.9961624,,,,
,26847277.115,99.9953003,37197.6796875,0.0045472361390107,1.31755648887439E-6,1,0.999253354069792,40.0298881530762,1.99748357297504,20.1399996876717,0.0516709232968733,0.0092715125428532,0.25,1.671350965306E-5,0.00457300649788645,3.04156964983798E-5,99.9953003,99.9953003,37191.40625,37203.953125,57.3043132588907,20.6028321911546,21.01075,0,0,0,40,4449,99.81095,37197.6796875,,,,,,,,,,,,,0,,,,-0.0049,,,,,,99.9953003,,,,
,26847466.93,99.995842,32455.2998046875,0.00429345715992983,1.279432011501E-6,1,0.999253354069792,40.0298881530762,1.99755761584127,20.1399996876717,0.04879013199323,0.00874516098032985,0.25,1.48969649744709E-5,0.00431775663058944,2.790857525384E-5,99.995842,99.995842,32449.294921875,32461.3046875,57.1284468420637,20.6007370346167,21.3904,0,0,0,40,4449,99.81605,32455.2998046875,,,,,,,,,,,,,0,,,,-0.0049,,,,,,99.995842,,,,
,26847657.085,99.9938126,27704.171875,0.00400556106551811,1.18689859928705E-6,1,0.999253354069792,40.0298881530762,1.99746100799209,20.1399996876717,0.0455154531433445,0.00816182375565215,0.25,1.41351030860969E-5,0.00402819848244139,2.63471556080325E-5,99.9938126,99.9938126,27696.6328125,27711.7109375,57.1417345268907,20.6021987794711,21.01075,0,0,0,40,4449,99.82625,27704.171875,,,,,,,,,,,,,0,,,,-0.00245,,,,,,99.9938126,,,,
,26847843.065,99.9927826,23054.8310546875,0.00368524770236075,1.0107526944832E-6,1,0.999253354069792,40.0298881530762,1.99760107070813,20.1399996876717,0.0418786017628786,0.00750726708495004,0.25,1.27372193067851E-5,0.00370604714796939,2.40345365464783E-5,99.9927826,99.9927826,23053.76171875,23055.900390625,57.210517836583,20.6029935157315,21.3904,0,0,0,40,4449,99.834,23054.8310546875,,,,,,,,,,,,,0,,,,0.0049,,,,,,99.9927826,,,,
,26848030.645,99.9945068,18368.0126953125,0.00330927481169371,8.19011270506682E-7,1,0.999253354069792,40.0298881530762,1.99755392907338,20.1399996876717,0.0376030853636069,0.00675188362065535,0.25,1.2324767636999E-5,0.00332792404095344,2.25303866962341E-5,99.9945068,99.9945068,18361.662109375,18374.36328125,57.0033862789868,20.6016315555332,20.631098,0,0,0,40,4449,99.8402,18368.0126953125,,,,,,,,,,,,,0,,,,0,,,,,,99.9945068,,,,
,26848219.895,99.9936447,13639.3276367188,0.00286642707392695,6.7074176363801E-7,1,0.999253354069792,40.0298881530762,1.99758697594327,20.1399996876717,0.032571338863452,0.00584823121624025,0.25,1.06147622549514E-5,0.00288255963855716,1.95007413425518E-5,99.9932098,99.9940796,13631.724609375,13646.9306640625,56.9353845978137,20.6050468194452,21.01075,0,0,0,40,4449,99.84875,13639.3276367188,,,,,,,,,,,,,0,,,,-0.00245,,,,,,99.9936447,,,,
,26848408.15,99.9944305,8934.478515625,0.00234402539414937,5.30886849496788E-7,1,0.999253354069792,40.0298881530762,1.99743151756559,20.1399996876717,0.0266328705037391,0.00478335033517681,0.25,8.76297290355595E-6,0.00235720140590848,1.60649593121659E-5,99.9944305,99.9944305,8929.427734375,8939.529296875,57.3988903097176,20.6050210168657,21.01075,0,0,0,40,4449,99.86095,8934.478515625,,,,,,,,,,,,,0,,,,-0.00245,,,,,,99.9944305,,,,
,26848594.57,99.9953079,4274.9580078125,0.00171873682186539,4.49238165392401E-7,1,0.999253354069792,40.0298881530762,1.99754084188302,20.1399996876717,0.0195291162248403,0.00350813118879962,0.25,6.45637701210361E-6,0.00172838701568097,1.18341467792303E-5,99.9953079,99.9953079,4268.70556640625,4281.21044921875,57.014329078256,20.6036064350592,21.3904,0,0,0,40,4449,99.86645,4274.9580078125,,,,,,,,,,,,,0,,,,0,,,,,,99.9953079,,,,
,26848767.825,99.9983444,-0.0304475463926792,0.00102323433496068,3.5229342492347E-7,1,0.999253354069792,40.0298881530762,1.99753814283963,20.1399996876717,0.0116260536835807,0.0020905746394531,0.25,4.01444926644587E-6,0.00102897430365623,7.2268747890938E-6,99.9983444,99.9983444,-0.0304475463926792,-0.0304475463926792,57.1096877576022,20.6031478708782,21.01075,0,0,0,40,4417,99.871,-0.0304475463926792,,,,,,,,,,,,,0,,,,0,,,,,,99.9983444,,,,