File: data/monolayers/nanoparticles/Ol_CoFe_C/vsm/data_disorderedWafer/DD227_HYST_150K.DAT
[Header]
; VSM Data File (default extension .dat)
; Copyright (c) 2003-2013, Quantum Design, Inc. All rights reserved.
TITLE,
FILEOPENTIME,28512916.45,11/27/2018,8:16 am
BYAPP,VSM,2.0,2.0
INFO,PPMS VSM Option Release 1.4.10 Build 1,APPNAME
INFO,Quantum Design Linear Motor Servo Controller,MOTOR_MODULE_NAME
INFO,3101-100 M1,MOTOR_HW_VERSION
INFO,MMC1014,MOTOR_SERIAL_NUMBER
INFO,SRV No X-over 01.03.11,MOTOR_SOFTWARE_VERSION
INFO,Quantum Design VSM Detection Module,VSM_MODULE_NAME
INFO,3101-150 F0,VSM_HW_VERSION
INFO,VSM707,VSM_SERIAL_NUMBER
INFO,VSM No X-over 01.02.05 May 20 2008 13:51:47,VSM_SOFTWARE_VERSION
INFO,704,PREAMP_SERIAL_NUMBER
INFO,822,COIL_SERIAL_NUMBER
INFO,0,MOMENT_UNITS
INFO,CoFe2O4 FeO,SAMPLE_MATERIAL
INFO,disordered monolayer,SAMPLE_COMMENT
INFO,25.46,SAMPLE_MASS
INFO,,SAMPLE_VOLUME
INFO,,SAMPLE_MOLECULAR_WEIGHT
INFO,,SAMPLE_SIZE
INFO,,SAMPLE_SHAPE
DATATYPE,COMMENT,1
DATATYPE,TIME,2
STARTUPAXIS,X,2
STARTUPAXIS,Y1,5
[Data]
Comment,Time Stamp (sec),Temperature (K),Magnetic Field (Oe),Moment (emu),M. Std. Err. (emu),Transport Action,Averaging Time (sec),Frequency (Hz),Peak Amplitude (mm),Center Position (mm),Coil Signal' (mV),Coil Signal" (mV),Range (mV),M. Quad. Signal (emu),M. Raw' (emu),M. Raw" (emu),Min. Temperature (K),Max. Temperature (K),Min. Field (Oe),Max. Field (Oe),Mass (grams),Motor Lag (deg),Pressure (Torr),VSM Status (code),Motor Status (code),Measure Status (code),Measure Count,PPMS Status (code),System Temp. (K),System Field (Oe),Sample Position (deg),Bridge 1 Resistance (ohms),Bridge 1 Excitation (에),Bridge 2 Resistance (ohms),Bridge 2 Excitation (에),Bridge 3 Resistance (ohms),Bridge 3 Excitation (에),Bridge 4 Resistance (ohms),Bridge 4 Excitation (에),Signal 1 Vin (V),Signal 2 Vin (V),Digital Inputs (code),Drive 1 Iout (mA),Drive 1 Ipower (W),Drive 2 Iout (mA),Drive 2 Ipower (W),Pressure (),Map 20 (),Map 21 (),Map 22 (),Map 23 (),Map 24 (),Map 25 (),Map 26 (),Map 27 (),Map 28 (),Map 29 ()
,28512931.44,150.2795868,0.228356599807739,,,2,,,,15.2500003826618,,,,,,,150.2795868,150.2795868,0.228356599807739,0.228356599807739,,,21.01075,,,,-99999999,4369,150.0538,0.228356599807739,,,,,,,,,,,,,,,,,,,,,,,150.2795868,,,,
,28513081.53,150.1382446,4711.111328125,-7.80610742462921E-6,6.3135800366444E-7,1,0.999253354069792,40.0298881530762,1.99733211047453,15.2399996295571,-8.79262493108117E-5,-1.99227010899442E-5,0.25,-3.93229434547885E-7,-7.84367976498612E-6,-4.07675926832602E-7,150.1382446,150.1382446,4706.05322265625,4716.16943359375,56.5953761919483,20.6017602925858,21.01075,0,0,0,40,4449,149.8474,4711.111328125,,,,,,,,,,,,,0,,,,0.0049,,,,,,150.1382446,,,,
,28513179.435,150.0609436,9600.21728515625,-1.9592578736241E-5,7.63176259770637E-7,1,0.999253354069792,40.0298881530762,1.99718842000054,15.2399996295571,-0.000222305856594078,-4.06222066530099E-5,0.25,-1.61652454208883E-7,-1.96882625555291E-5,-1.93810816487652E-7,150.0609436,150.0609436,9592.755859375,9607.6787109375,56.7814037795252,20.6014465682485,21.01075,0,0,0,40,4449,149.8208,9600.21728515625,,,,,,,,,,,,,0,,,,-0.0049,,,,,,150.0609436,,,,
,28513278.575,150.0186615,14557.6201171875,-3.29201226717529E-5,8.48933904180769E-7,1,0.999253354069792,40.0298881530762,1.99707626561416,15.2399996295571,-0.000372119256195077,-7.62152673421964E-5,0.25,-9.72663592112348E-7,-3.30798438675292E-5,-1.02999971924157E-6,150.0186615,150.0186615,14550.2392578125,14565.0009765625,57.0330881627176,20.6056193589602,21.01075,0,0,0,40,4449,149.81965,14557.6201171875,,,,,,,,,,,,,0,,,,-0.00245,,,,,,150.0186615,,,,
,28513377.625,149.9960556,19507.2783203125,-4.68420391753153E-5,1.39809807467193E-6,1,0.999253354069792,40.0298881530762,1.99697919823794,15.2399996295571,-0.000528736442583098,-0.000112622867159135,0.25,-1.75220546810433E-6,-4.70688025614145E-5,-1.83538465963399E-6,149.9958649,149.9962463,19502.3515625,19512.205078125,57.1042163579676,20.6067450423252,21.3904,0,0,0,40,4449,149.8328,19507.2783203125,,,,,,,,,,,,,0,,,,-0.0049,,,,,,149.9960556,,,,
,28513477.095,149.9869537,24479.630859375,-6.07985490813408E-5,1.27596057937884E-6,1,0.999253354069792,40.0298881530762,1.99707819425799,15.2399996295571,-0.000688479607658615,-0.000133708953098533,0.25,-1.17646573536817E-6,-6.1094709397613E-5,-1.27875874890694E-6,149.9869537,149.9869537,24474.6953125,24484.56640625,56.9119357422368,20.6054944201293,21.3904,0,0,0,40,4449,149.8498,24479.630859375,,,,,,,,,,,,,0,,,,-0.0049,,,,,,149.9869537,,,,
,28513576.62,149.9861145,29452.6025390625,-7.63772649413412E-5,2.12103645997229E-6,1,0.999253354069792,40.0298881530762,1.997100188078,15.2399996295571,-0.000869575050822153,-0.0001411475409625,0.25,8.82505963232605E-7,-7.67531386681878E-5,7.65947802616356E-7,149.9861145,149.9861145,29447.912109375,29457.29296875,57.0870205305445,20.6054234250188,20.631098,0,0,0,40,4449,149.864,29452.6025390625,,,,,,,,,,,,,0,,,,-0.00245,,,,,,149.9861145,,,,
,28513676.75,149.9869843,34457.595703125,-9.33580316069499E-5,2.77892296142089E-6,1,0.999253354069792,40.0298881530762,1.99712069225312,15.2399996295571,-0.0010628930021071,-0.000172668010301186,0.25,1.06613301591999E-6,-9.38175467880314E-5,9.24068292929076E-7,149.9869843,149.9869843,34455.17578125,34460.015625,57.0909286731407,20.6096891344718,21.3904,0,0,0,40,4449,149.8749,34457.595703125,,,,,,,,,,,,,0,,,,0,,,,,,149.9869843,,,,
,28513775.805,149.9929352,39409.900390625,-0.000105916634176747,2.5243132436213E-6,1,0.999253354069792,40.0298881530762,1.9968926792833,15.2399996295571,-0.00120243539780036,-0.000214868081226605,0.25,-4.62774881123174E-7,-0.000106435424859029,-6.31621933285533E-7,149.9929352,149.9929352,39402.125,39417.67578125,57.3355783996599,20.6046619267204,21.01075,0,0,0,40,4449,149.88125,39409.900390625,,,,,,,,,,,,,0,,,,0.00245,,,,,,149.9929352,,,,
,28513875.54,149.9956665,44392.6171875,-0.000121267376201814,2.21126454169054E-6,1,0.999253354069792,40.0298881530762,1.99681624854304,15.2399996295571,-0.00137983853047597,-0.000227742433332194,0.25,1.0766582504115E-6,-0.000121863999981524,8.91829663753181E-7,149.9956665,149.9956665,44385.42578125,44399.80859375,57.1972301517561,20.6074305652366,21.3904,0,0,0,40,4449,149.8805,44392.6171875,,,,,,,,,,,,,0,,,,0.00245,,,,,,149.9956665,,,,
,28513973.915,149.9988251,49310.537109375,-0.000137899750219347,2.37250649384626E-6,1,0.999253354069792,40.0298881530762,1.99690219071794,15.2399996295571,-0.00156798248401927,-0.000265724432571649,0.25,6.30820391306847E-7,-0.000138577407624812,4.1842559548509E-7,149.9988251,149.9988251,49303.1953125,49317.87890625,56.9955699937945,20.6059223242592,21.01075,0,0,0,40,4449,149.88,49310.537109375,,,,,,,,,,,,,0,,,,-0.0049,,,,,,149.9988251,,,,
,28514074.745,150.0003357,54350.26171875,-0.000153374685427474,2.21921090024575E-6,1,0.999253354069792,40.0298881530762,1.99671203552361,15.2399996295571,-0.00174244355693567,-0.000303206421372011,0.25,2.39577427556148E-8,-0.000154127496297583,-2.14790804483586E-7,150.0003357,150.0003357,54340.109375,54360.4140625,57.2269320354868,20.6064463475839,21.3904,0,0,0,40,4449,149.88085,54350.26171875,,,,,,,,,,,,,0,,,,0.00245,,,,,,150.0003357,,,,
,28514176.36,150.0052032,59427.8125,-0.000171026384120809,2.5016822526662E-6,1,0.999253354069792,40.0298881530762,1.99671543747519,15.2399996295571,-0.00194259770912831,-0.000340322228906931,0.25,-1.69532041619378E-7,-0.000171865699336322,-4.35822194208937E-7,150.0052032,150.0052032,59417.88671875,59437.73828125,56.9924434797176,20.6059089728859,21.01075,0,0,0,40,4449,149.8747,59427.8125,,,,,,,,,,,,,0,,,,0,,,,,,150.0052032,,,,
,28514276.655,150.0053406,64443.25,-0.000189445120131745,2.2802570974555E-6,1,0.999253354069792,40.0298881530762,1.99678075511215,15.2399996295571,-0.00214881253969833,-0.000394574708578474,0.25,-1.73701987412745E-6,-0.000190372642895901,-2.03859492862473E-6,150.0053406,150.0053406,64435.671875,64450.828125,57.1784710672945,20.6030500356465,21.3904,0,0,0,40,4449,149.87095,64443.25,,,,,,,,,,,,,0,,,,0,,,,,,150.0053406,,,,
,28514376.055,150.0059052,69408.375,-0.000206920422401671,2.7360932147467E-6,1,0.999253354069792,40.0298881530762,1.9968213962159,15.2399996295571,-0.00234564972843558,-0.000439177958210353,0.25,-2.61982769672073E-6,-0.000207932627273483,-2.9516885873478E-6,150.0059052,150.0059052,69403.265625,69413.484375,57.2941520881407,20.6076290029042,20.631098,0,0,0,40,4449,149.8646,69408.375,,,,,,,,,,,,,0,,,,0.0049,,,,,,150.0059052,,,,
,28514469.4,150.006546,74076.0234375,-0.000217782570150495,2.46257787126926E-6,1,0.999253354069792,40.0298881530762,1.99667082017194,15.2399996295571,-0.00247579356459275,-0.000420939298508986,0.25,8.73553308611211E-7,-0.000218853728087555,5.43184977988067E-7,150.006546,150.006546,74066.0390625,74086.0078125,57.1206305568714,20.6057599471855,20.631098,0,0,0,40,4449,149.8585,74076.0234375,,,,,,,,,,,,,0,,,,0.0049,,,,,,150.006546,,,,
,28514567.045,150.0060883,78958.9140625,-0.00023604172399614,3.33626572304575E-6,1,0.999253354069792,40.0298881530762,1.99674100686476,15.2399996295571,-0.00267688678198122,-0.000493992621188287,0.25,-2.37690778552671E-6,-0.000237197857881205,-2.75006933111911E-6,150.0060883,150.0060883,78953.703125,78964.125,57.0487207331022,20.6040891025214,21.3904,0,0,0,40,4449,149.8528,78958.9140625,,,,,,,,,,,,,0,,,,-0.00245,,,,,,150.0060883,,,,
,28514663.26,150.0067902,83767.3515625,-0.000250991820670963,2.37806362479002E-6,1,0.999253354069792,40.0298881530762,1.99672262762796,15.2399996295571,-0.0028579074099667,-0.000459253124591259,0.25,3.2828638651E-6,-0.000252230330491099,2.91592278126522E-6,150.0067902,150.0067902,83757.234375,83777.46875,57.0557553897753,20.6071963601321,21.01075,0,0,0,40,4449,149.8479,83767.3515625,,,,,,,,,,,,,0,,,,0.00245,,,,,,150.0067902,,,,
,28514754.96,150.0084839,88350.61328125,-0.000263325552788578,2.07799611150312E-6,1,0.999253354069792,40.0298881530762,1.99675079399433,15.2399996295571,-0.0029896868129282,-0.000531795358182542,0.25,-9.55364531426021E-7,-0.000264618470164681,-1.36067224473889E-6,150.0084839,150.0084839,88345.625,88355.6015625,56.9596150819099,20.6068577371392,21.01075,0,0,0,40,4449,149.8372,88350.61328125,,,,,,,,,,,,,0,,,,0,,,,,,150.0084839,,,,
,28514866.84,150.0050964,87121.234375,-0.000261389208212839,2.95450431514309E-6,1,0.999253354069792,40.0298881530762,1.99678646733445,15.2399996295571,-0.0029710831959993,-0.00050876616749694,0.25,7.35658294599216E-7,-0.000262675127748262,3.41234004232055E-7,150.0050964,150.0050964,87118.625,87123.84375,57.0612267894099,20.6044483237136,21.3904,0,0,0,40,4449,149.83155,87121.234375,,,,,,,,,,,,,0,,,,-0.00245,,,,,,150.0050964,,,,
,28514963.455,149.99642185,82290.50390625,-0.000242124125691436,2.01000997105178E-6,1,0.999253354069792,40.0298881530762,1.99672665003106,15.2399996295571,-0.00274689495926298,-0.000500716334505361,0.25,-1.91060094069802E-6,-0.000243311105363832,-2.2899622668954E-6,149.9963837,149.99646,82280.4296875,82300.578125,57.0526288756983,20.6073283765515,21.3904,0,0,0,40,4449,149.83635,82290.50390625,,,,,,,,,,,,,0,,,,-0.00245,,,,,,149.99642185,,,,
,28515064.805,149.9922485,77221.453125,-0.000225811042666908,1.89223392148319E-6,1,0.999253354069792,40.0298881530762,1.99688439903708,15.2399996295571,-0.00256097538890318,-0.000472977591035802,0.25,-2.30542854690517E-6,-0.000226917004511447,-2.6630315088755E-6,149.9922485,149.9922485,77216.40625,77226.5,57.1933220091599,20.6083159436722,21.3904,0,0,0,40,4449,149.84265,77221.453125,,,,,,,,,,,,,0,,,,0.0049,,,,,,149.9922485,,,,
,28515160.485,149.9929199,72440.37109375,-0.000210759210261239,2.01394017100643E-6,1,0.999253354069792,40.0298881530762,1.99680007633021,15.2399996295571,-0.00239100146984576,-0.000436657834410695,0.25,-1.73044223859997E-6,-0.000211791857100024,-2.06321694706334E-6,149.9929199,149.9929199,72432.859375,72447.8828125,57.115940785756,20.6057979648382,21.3904,0,0,0,40,4449,149.8473,72440.37109375,,,,,,,,,,,,,0,,,,-0.00245,,,,,,149.9929199,,,,
,28515256.415,149.9929504,67644.81640625,-0.000197009375355598,2.55088284560743E-6,1,0.999253354069792,40.0298881530762,1.99684684871299,15.2399996295571,-0.00223284172584618,-0.000420922684332156,0.25,-2.73823066116173E-6,-0.000197972703264605,-3.05579321962185E-6,149.9929504,149.9929504,67639.7421875,67649.890625,56.9924434797176,20.6088325618532,21.3904,0,0,0,40,4449,149.8556,67644.81640625,,,,,,,,,,,,,0,,,,-0.0049,,,,,,149.9929504,,,,
,28515352.91,149.9924011,62822.06640625,-0.000178491086879859,2.48805325967449E-6,1,0.999253354069792,40.0298881530762,1.99677120128886,15.2399996295571,-0.00202697870163043,-0.00035784343226975,0.25,-4.11459210243659E-7,-0.000179366867857836,-6.89910713931496E-7,149.9924011,149.9924011,62817.21484375,62826.91796875,56.8454973181022,20.610407148643,21.3904,0,0,0,40,4449,149.86295,62822.06640625,,,,,,,,,,,,,0,,,,-0.00245,,,,,,149.9924011,,,,
,28515448.14,149.9925537,58061.423828125,-0.00016529655379392,2.33917300005719E-6,1,0.999253354069792,40.0298881530762,1.99677678287598,15.2399996295571,-0.0018742914828523,-0.000347758115763415,0.25,-1.82087775492204E-6,-0.000166105180072993,-2.08663275521517E-6,149.9925537,149.9925537,58054.09375,58068.75390625,57.2456911199484,20.6126986114547,21.01075,0,0,0,40,4449,149.86935,58061.423828125,,,,,,,,,,,,,0,,,,-0.00245,,,,,,149.9925537,,,,
,28515544.26,149.9892273,53256.060546875,-0.00014904148831825,1.83651667437248E-6,1,0.999253354069792,40.0298881530762,1.99671795525149,15.2399996295571,-0.00169150280171506,-0.000304501869720721,0.25,-8.44552395794481E-7,-0.000149771687718835,-1.08098695869417E-6,149.9892273,149.9892273,53246.15234375,53265.96875,57.383257739333,20.6125733652655,21.770052,0,0,0,40,4449,149.8803,53256.060546875,,,,,,,,,,,,,0,,,,-0.00245,,,,,,149.9892273,,,,
,28515640.64,149.9899902,48440.6953125,-0.000133048823023438,2.09700276408569E-6,1,0.999253354069792,40.0298881530762,1.99685978687533,15.2399996295571,-0.00151109485055479,-0.00026613112364963,0.25,-2.50273155225283E-7,-0.000133701310894233,-4.59514130613448E-7,149.9899902,149.9899902,48438.14453125,48443.24609375,57.2316218066022,20.61212257597,21.3904,0,0,0,40,4449,149.8884,48440.6953125,,,,,,,,,,,,,0,,,,0,,,,,,149.9899902,,,,
,28515734.83,149.9898834,43732.796875,-0.000118501311679508,2.18651759514495E-6,1,0.999253354069792,40.0298881530762,1.99684474517232,15.2399996295571,-0.00134557691434512,-0.000238662842257035,0.25,-3.66033311475203E-7,-0.000119082111625303,-5.53654298436081E-7,149.9898834,149.9898834,43730.41796875,43735.17578125,57.0018230219483,20.6125005174648,21.01075,0,0,0,40,4449,149.89675,43732.796875,,,,,,,,,,,,,0,,,,-0.00245,,,,,,149.9898834,,,,
,28515831.88,149.9918518,38880.478515625,-0.000104434728943654,1.85893484895256E-6,1,0.999253354069792,40.0298881530762,1.99687312594298,15.2399996295571,-0.00118278895793538,-0.000228001917065324,0.25,-1.87708646816352E-6,-0.000104944024511106,-2.05056251527573E-6,149.9918518,149.9918518,38877.87890625,38883.078125,56.851750346256,20.6121394156794,21.3904,0,0,0,40,4449,149.9022,38880.478515625,,,,,,,,,,,,,0,,,,-0.00245,,,,,,149.9918518,,,,
,28515928.095,149.9941406,34070.75,-9.04986657862315E-5,1.8987372677464E-6,1,0.999253354069792,40.0298881530762,1.99684890862664,15.2399996295571,-0.00102854594668582,-0.000176880576248995,0.25,1.952686362191E-7,-9.09427691132081E-5,5.34576637568629E-8,149.9941406,149.9941406,34060.59375,34080.90625,57.2034831799099,20.6116424764297,21.3904,0,0,0,40,4449,149.9097,34070.75,,,,,,,,,,,,,0,,,,0,,,,,,149.9941406,,,,
,28516026.125,149.9910583,29173.1103515625,-7.57860545032843E-5,1.97990812363395E-6,1,0.999253354069792,40.0298881530762,1.99680811788475,15.2399996295571,-0.000859047617660838,-0.000161137180096017,0.25,-9.8178773623017E-7,-7.61560786017989E-5,-1.10650616922806E-6,149.9910583,149.9910583,29163.08984375,29183.130859375,57.1659650109868,20.6132429932801,21.01075,0,0,0,40,4449,149.9203,29173.1103515625,,,,,,,,,,,,,0,,,,0,,,,,,149.9910583,,,,
,28516126.395,149.988739,24163.2802734375,-5.93443378431536E-5,1.83356645956873E-6,1,0.999253354069792,40.0298881530762,1.99680788246632,15.2399996295571,-0.000673723555070023,-0.000120172284622519,0.25,-2.39837102969044E-7,-5.9634864772375E-5,-3.35180945093312E-7,149.988739,149.988739,24155.634765625,24170.92578125,57.2152076076984,20.6140897313176,21.01075,0,0,0,40,4449,149.92315,24163.2802734375,,,,,,,,,,,,,0,,,,-0.0049,,,,,,149.988739,,,,
,28516221.83,149.9888458,19392.859375,-4.62259369622128E-5,1.24706122786453E-6,1,0.999253354069792,40.0298881530762,1.99691708477195,15.2399996295571,-0.000526230963549916,-8.55134813995991E-5,0.25,5.26206549886093E-7,-4.64533339451653E-5,4.55247768872473E-7,149.9888458,149.9888458,19387.66796875,19398.05078125,57.3574639981984,20.6128015175009,21.3904,0,0,0,40,4449,149.94275,19392.859375,,,,,,,,,,,,,0,,,,-0.00245,,,,,,149.9888458,,,,
,28516316.455,149.9920654,14663.5942382812,-3.25653383292915E-5,1.02198832328021E-6,1,0.999253354069792,40.0298881530762,1.99688416536225,15.2399996295571,-0.000369029533596742,-6.99110217496148E-5,0.25,-4.80251051379068E-7,-3.27241477643848E-5,-5.34542511655129E-7,149.9920654,149.9920654,14661.203125,14665.9853515625,57.3465211989291,20.6142348355756,21.3904,0,0,0,40,4449,149.94565,14663.5942382812,,,,,,,,,,,,,0,,,,0,,,,,,149.9920654,,,,
,28516412.515,149.99269865,9861.4345703125,-1.98294235576741E-5,9.5801773608522E-7,1,0.999253354069792,40.0298881530762,1.9969088000482,15.2399996295571,-0.000225833104064945,-3.61173550091926E-5,0.25,2.75606562850694E-7,-1.9927014362485E-5,2.45254665685015E-7,149.99263,149.9927673,9858.8203125,9864.048828125,57.403580080833,20.6146760771193,21.770052,0,0,0,40,4449,149.94975,9861.4345703125,,,,,,,,,,,,,0,,,,0,,,,,,149.99269865,,,,
,28516508.135,149.9931793,5083.48388671875,-7.61948866049248E-6,4.68098303485086E-7,1,0.999253354069792,40.0298881530762,1.99683134054981,15.2399996295571,-8.58750410762396E-5,-1.9034504198505E-5,0.25,-3.47988082434159E-7,-7.65625530657013E-6,-3.61900690120217E-7,149.9931793,149.9931793,5075.94091796875,5091.02685546875,57.3363600281791,20.6157624751087,21.770052,0,0,0,40,4449,149.9548,5083.48388671875,,,,,,,,,,,,,0,,,,0,,,,,,149.9931793,,,,
,28516604.49,149.9938049,264.453750610352,4.19513749125701E-6,3.52927655125534E-7,1,0.999253354069792,40.0298881530762,1.99688321886228,15.2399996295571,4.849287171473E-5,3.53131019472858E-6,0.25,-4.20060314263262E-7,4.21635901414774E-6,-4.15384869570936E-7,149.9938049,149.9938049,256.9169921875,271.990509033203,57.4004535667561,20.6158529997309,21.3904,0,0,0,40,4449,149.96285,264.453750610352,,,,,,,,,,,,,0,,,,0,,,,,,149.9938049,,,,
,28516698.64,149.9981995,-4436.7236328125,1.14081237144064E-5,4.48542106203905E-7,1,0.999253354069792,40.0298881530762,1.99688119981837,15.2399996295571,0.000130053132410812,2.00307963602056E-5,0.25,-2.2441442369709E-7,1.14643638187165E-5,-2.07231903444741E-7,149.9981995,149.9981995,-4441.70166015625,-4431.74560546875,57.1526773261599,20.6149995543421,21.01075,0,0,0,40,4449,149.96265,-4436.7236328125,,,,,,,,,,,,,0,,,,0.0049,,,,,,149.9981995,,,,
,28516794.435,150.0048218,-9225.86279296875,2.08599287920194E-5,6.91813194076933E-7,1,0.999253354069792,40.0298881530762,1.99688602731473,15.2399996295571,0.000237511092994263,3.83126237301059E-5,0.25,-2.61884044110579E-7,2.09625373310071E-5,-2.29807882299015E-7,150.0048218,150.0048218,-9230.7548828125,-9220.970703125,57.4160861371407,20.614998611159,21.770052,0,0,0,40,4449,149.95255,-9225.86279296875,,,,,,,,,,,,,0,,,,0.0049,,,,,,150.0048218,,,,
,28516889.815,150.0081482,-13993.4926757813,3.26632960633525E-5,1.32763090590137E-6,1,0.999253354069792,40.0298881530762,1.99689382789061,15.2399996295571,0.000371505042252958,6.22923324913113E-5,0.25,-2.07443040301549E-7,3.28236641445809E-5,-1.56349268602117E-7,150.0081482,150.0081482,-13998.5849609375,-13988.400390625,57.3418314278138,20.6175072399103,21.3904,0,0,0,40,4449,149.9508,-13993.4926757813,,,,,,,,,,,,,0,,,,-0.00245,,,,,,150.0081482,,,,
,28516985.045,150.0072174,-18753.458984375,4.58407817901629E-5,1.35286375613165E-6,1,0.999253354069792,40.0298881530762,1.99692253336673,15.2399996295571,0.00052204404539469,8.36724978891276E-5,0.25,-6.21190698074596E-7,4.60664127832486E-5,-5.51282148322822E-7,150.0072174,150.0072174,-18760.890625,-18746.02734375,57.2636685758907,20.6172777720793,21.3904,0,0,0,40,4449,149.94035,-18753.458984375,,,,,,,,,,,,,0,,,,0,,,,,,150.0072174,,,,
,28517080.62,150.0098724,-23530.2783203125,5.98505479963458E-5,1.27550242646881E-6,1,0.999253354069792,40.0298881530762,1.99687527781497,15.2399996295571,0.000678986875364082,0.00012409999690417,0.25,4.97004764014633E-7,6.01431058282487E-5,5.94442392618805E-7,150.0098724,150.0098724,-23537.705078125,-23522.8515625,57.2902439455445,20.6184237711333,21.3904,0,0,0,40,4449,149.9282,-23530.2783203125,,,,,,,,,,,,,0,,,,0.00245,,,,,,150.0098724,,,,
,28517178.19,150.0151672,-28405.673828125,7.30847835296909E-5,1.90879462059322E-6,1,0.999253354069792,40.0298881530762,1.99677113238017,15.2399996295571,0.000830245794397718,0.000144868994878,0.25,2.05643401643393E-8,7.34430213878278E-5,1.36356319165414E-7,150.0151672,150.0151672,-28415.638671875,-28395.708984375,56.9541436822753,20.61921371859,21.3904,0,0,0,40,4449,149.91405,-28405.673828125,,,,,,,,,,,,,0,,,,0,,,,,,150.0151672,,,,
,28517274.485,150.011795,-33217.6640625,8.93282242778979E-5,1.3666787937012E-6,1,0.999253354069792,40.0298881530762,1.99681180568099,15.2399996295571,0.00101275943059099,0.000188742836378419,0.25,1.05296552739837E-6,8.97645576721593E-5,1.19912308922636E-6,150.011795,150.011795,-33222.5859375,-33212.7421875,57.6161830380638,20.6177988136569,21.3904,0,0,0,40,4449,149.911,-33217.6640625,,,,,,,,,,,,,0,,,,0,,,,,,150.011795,,,,
,28517373.585,150.0114441,-38169.423828125,0.000103049527453758,2.25557101824835E-6,1,0.999253354069792,40.0298881530762,1.99683434057293,15.2399996295571,0.00117099206210157,0.000202504416249342,0.25,-1.25625695213712E-7,0.000103555104477232,3.59294747947E-8,150.0114441,150.0114441,-38174.37109375,-38164.4765625,57.281646031833,20.6211005255629,21.01075,0,0,0,40,4449,149.89695,-38169.423828125,,,,,,,,,,,,,0,,,,-0.0049,,,,,,150.0114441,,,,
,28517470.295,150.0112076,-43004.412109375,0.000118600467545477,2.34212170024196E-6,1,0.999253354069792,40.0298881530762,1.99692775394233,15.2399996295571,0.00134838247800865,0.000229529550248936,0.25,-4.56039892854734E-7,0.000119182949587298,-2.72191222786683E-7,150.0109711,150.0114441,-43016.93359375,-42991.890625,57.2472543769868,20.6220270295722,21.770052,0,0,0,40,4449,149.8869,-43004.412109375,,,,,,,,,,,,,0,,,,0,,,,,,150.0112076,,,,
,28517568.33,150.0103149,-47904.5546875,0.000132799045530616,2.03363856636405E-6,1,0.999253354069792,40.0298881530762,1.99696351900101,15.2399996295571,0.00150791665196413,0.000268027461468281,0.25,4.59451596276024E-7,0.000133449885187087,6.694173356411E-7,150.0103149,150.0103149,-47914.390625,-47894.71875,57.1933220091599,20.622326083827,21.01075,0,0,0,40,4449,149.8803,-47904.5546875,,,,,,,,,,,,,0,,,,0,,,,,,150.0103149,,,,
,28517665.705,150.0118408,-52768.857421875,0.000149862211712708,1.83029319100656E-6,1,0.999253354069792,40.0298881530762,1.99677927430417,15.2399996295571,0.00170351926042083,0.000290953407182586,0.25,-4.91832783015711E-7,0.000150598404849888,-2.6057425807545E-7,150.0118408,150.0118408,-52771.29296875,-52766.421875,57.2253687784484,20.623447579105,21.770052,0,0,0,40,4449,149.8678,-52768.857421875,,,,,,,,,,,,,0,,,,0,,,,,,150.0118408,,,,
,28517762.655,150.0112915,-57613.73828125,0.000162545027708265,2.16059564056037E-6,1,0.999253354069792,40.0298881530762,1.99675844949967,15.2399996295571,0.00184742934132501,0.00031696349815395,0.25,-4.10349029113393E-7,0.000163343504276699,-1.59712939769996E-7,150.0112915,150.0112915,-57618.72265625,-57608.75390625,57.4317187075253,20.6246081126905,21.3904,0,0,0,40,4449,149.8557,-57613.73828125,,,,,,,,,,,,,0,,,,0,,,,,,150.0112915,,,,
,28517859.715,150.01345825,-62466.43359375,0.000179134852247038,2.51405148604781E-6,1,0.999253354069792,40.0298881530762,1.99673742161263,15.2399996295571,0.00203984514532949,0.000327031812198429,0.25,-2.41239542697645E-6,0.000180018039743744,-2.14670262359849E-6,150.0134277,150.0134888,-62471.515625,-62461.3515625,57.3543374841214,20.6283165686293,21.01075,0,0,0,40,4449,149.8474,-62466.43359375,,,,,,,,,,,,,0,,,,0,,,,,,150.01345825,,,,
,28517958.415,150.0123138,-67398.6875,0.000197161904958232,2.41880054780048E-6,1,0.999253354069792,40.0298881530762,1.99678513995227,15.2399996295571,0.00224908864628341,0.000337487347672414,0.25,-4.63144778432877E-6,0.000198137228934684,-4.34972545517156E-6,150.0123138,150.0123138,-67403.8125,-67393.5625,57.4676736194099,20.6283420653478,21.770052,0,0,0,40,4449,149.8333,-67398.6875,,,,,,,,,,,,,0,,,,0,,,,,,150.0123138,,,,
,28518055.26,150.0112305,-72237.89453125,0.000209791714853993,2.11218343745324E-6,1,0.999253354069792,40.0298881530762,1.99680818309434,15.2399996295571,0.00238028826579542,0.000433190264350274,0.25,1.59347219962323E-6,0.000210819684940203,1.92420628113836E-6,150.0112305,150.0112305,-72245.625,-72230.1640625,57.2722664896022,20.6270789406849,21.01075,0,0,0,40,4449,149.82195,-72237.89453125,,,,,,,,,,,,,0,,,,-0.00245,,,,,,150.0112305,,,,
,28518153.35,150.0140991,-77139.89453125,0.000229337079732536,2.44864503528295E-6,1,0.999253354069792,40.0298881530762,1.99680733776184,15.2399996295571,0.00260785392518846,0.000440226472000792,0.25,-1.18994872015291E-6,0.000230465560501478,-8.43991270705221E-7,150.0140991,150.0140991,-77147.3515625,-77132.4375,57.4215575367753,20.623062299711,21.3904,0,0,0,40,4449,149.81175,-77139.89453125,,,,,,,,,,,,,0,,,,0,,,,,,150.0140991,,,,
,28518251.305,150.01055145,-82037.03125,0.00024361935937354,2.48907300350001E-6,1,0.999253354069792,40.0298881530762,1.99679021328971,15.2399996295571,0.00276862119451778,0.000476946858953333,0.25,-4.4349441115057E-7,0.000244817148674128,-7.32310979737182E-8,150.0105133,150.0105896,-82049.5390625,-82024.5234375,57.4997203886984,20.6253012278822,21.3904,0,0,0,40,4449,149.8018,-82037.03125,,,,,,,,,,,,,0,,,,-0.0049,,,,,,150.01055145,,,,
,28518346.015,150.0104828,-86769.04296875,0.000257848746533142,2.91689506337842E-6,1,0.999253354069792,40.0298881530762,1.9968113758327,15.2399996295571,0.00292763215908477,0.00052049950720354,0.25,9.12876336460368E-7,0.000259114662413466,1.31025523026779E-6,150.0104828,150.0104828,-86776.6484375,-86761.4375,57.291807202583,20.6232050873989,21.01075,0,0,0,40,4449,149.79175,-86769.04296875,,,,,,,,,,,,,0,,,,0.00245,,,,,,150.0104828,,,,
,28518458.01,150.0105743,-88610.26171875,0.000264675012136427,2.94205570053878E-6,1,0.999253354069792,40.0298881530762,1.99676151435153,15.2399996295571,0.00300935501439482,0.00050964589088526,0.25,-1.22961194710239E-6,0.000265977847468865,-8.32874827362962E-7,150.0105743,150.0105743,-88617.875,-88602.6484375,57.4215575367753,20.625987631307,21.770052,0,0,0,40,4449,149.7851,-88610.26171875,,,,,,,,,,,,,0,,,,0.00245,,,,,,150.0105743,,,,
,28518551.535,150.0029755,-83936.3828125,0.000250908127483719,2.74725833906786E-6,1,0.999253354069792,40.0298881530762,1.99678025615894,15.2399996295571,0.00285087137903953,0.000494495770934886,0.25,-1.67469652279644E-7,0.000252141462362148,2.14824953662821E-7,150.0029755,150.0029755,-83941.3046875,-83931.4609375,57.3824761108138,20.6259113084116,21.3904,0,0,0,40,4449,149.78625,-83936.3828125,,,,,,,,,,,,,0,,,,-0.0049,,,,,,150.0029755,,,,
,28518650.79,149.9960632,-78976.42578125,0.000232590131260244,3.45914282446993E-6,1,0.999253354069792,40.0298881530762,1.99682681580972,15.2399996295571,0.00263967523628008,0.00047631718636001,0.25,1.42020978793342E-6,0.000233730790640299,1.78359754596555E-6,149.9960632,149.9960632,-78983.8515625,-78969,57.2753930036791,20.6227313638099,21.01075,0,0,0,40,4449,149.78685,-78976.42578125,,,,,,,,,,,,,0,,,,-0.00245,,,,,,149.9960632,,,,
,28518745.96,149.9945374,-74221.65234375,0.000222709016580597,3.20009701679485E-6,1,0.999253354069792,40.0298881530762,1.99703347202085,15.2399996295571,0.00253204979766568,0.000431614925123167,0.25,-7.98526540571856E-7,0.00022380429997953,-4.60052248072283E-7,149.9945374,149.9945374,-74226.390625,-74216.9140625,57.3668435404292,20.6216968913625,21.01075,0,0,0,40,4449,149.79475,-74221.65234375,,,,,,,,,,,,,0,,,,0,,,,,,149.9945374,,,,
,28518843.775,149.9924927,-69332.4296875,0.000201280376039642,1.72368336945211E-6,1,0.999253354069792,40.0298881530762,1.99677991296028,15.2399996295571,0.00228465925065856,0.000410030750782569,0.25,1.03705760829008E-6,0.000202267354539275,1.3526462765395E-6,149.9924927,149.9924927,-69334.734375,-69330.125,57.3129111726022,20.6223405858061,21.3904,0,0,0,40,4449,149.80255,-69332.4296875,,,,,,,,,,,,,0,,,,0,,,,,,149.9924927,,,,
,28518939.69,149.99111935,-64537.755859375,0.000187687254433677,3.14956654000154E-6,1,0.999253354069792,40.0298881530762,1.99683830650535,15.2399996295571,0.00212720699673779,0.000400832979480712,0.25,2.59292304675938E-6,0.000188604865701946,2.89611992260963E-6,149.990921,149.9913177,-64543,-64532.51171875,57.2347483206791,20.6217137168131,21.3904,0,0,0,40,4449,149.81325,-64537.755859375,,,,,,,,,,,,,0,,,,-0.00245,,,,,,149.99111935,,,,
,28519036.545,149.9917908,-59697.748046875,0.000170888005870262,2.4383851852992E-6,1,0.999253354069792,40.0298881530762,1.99665563466914,15.2399996295571,0.00193892668750807,0.000351774691868273,0.25,1.20252491195069E-6,0.00017172508377328,1.47375849979234E-6,149.9917908,149.9917908,-59700.3984375,-59695.09765625,57.3770047111791,20.6239458173273,21.770052,0,0,0,40,4449,149.8202,-59697.748046875,,,,,,,,,,,,,0,,,,0.0049,,,,,,149.9917908,,,,
,28519132.56,149.9909058,-54900.23046875,0.000157149296104568,2.2267377679291E-6,1,0.999253354069792,40.0298881530762,1.99672045515635,15.2399996295571,0.00178126810209253,0.00033400999677113,0.25,2.0299382439923E-6,0.000157917468462493,2.28467965222313E-6,149.9909058,149.9909058,-54907.71875,-54892.7421875,57.1440794124484,20.6213032166598,21.3904,0,0,0,40,4449,149.8272,-54900.23046875,,,,,,,,,,,,,0,,,,0.0049,,,,,,149.9909058,,,,
,28519230.665,149.9921722,-49998.7890625,0.000140345693677956,2.07404474975876E-6,1,0.999253354069792,40.0298881530762,1.9967343957179,15.2399996295571,0.00159490985837608,0.000274758899803308,0.25,-2.59719652176756E-7,0.000141034801169308,-4.16887797257915E-8,149.9921722,149.9921722,-50001.0703125,-49996.5078125,57.3207274577945,20.6239395357465,21.3904,0,0,0,40,4449,149.8352,-49998.7890625,,,,,,,,,,,,,0,,,,0,,,,,,149.9921722,,,,
,28519327.21,149.9923096,-45171.484375,0.000126953203745686,2.40148611655043E-6,1,0.999253354069792,40.0298881530762,1.9966967431813,15.2399996295571,0.0014428262811527,0.000247742084734192,0.25,-3.0537099445897E-7,0.000127576531776437,-1.07876782118626E-7,149.9923096,149.9923096,-45183.83984375,-45159.12890625,57.4723633905253,20.6207771072125,21.01075,0,0,0,40,4449,149.844,-45171.484375,,,,,,,,,,,,,0,,,,-0.00245,,,,,,149.9923096,,,,
,28519424.835,149.9906311,-40293.705078125,0.000108019331565119,1.7152726199737E-6,1,0.999253354069792,40.0298881530762,1.99678036459936,15.2399996295571,0.00122945226101713,0.000200686318044593,0.25,-1.15074621360852E-6,0.00010855099111914,-9.86557991891827E-7,149.9906311,149.9906311,-40301.39453125,-40286.015625,57.2847725459099,20.6196458059583,21.3904,0,0,0,40,4449,149.8538,-40293.705078125,,,,,,,,,,,,,0,,,,0,,,,,,149.9906311,,,,
,28519519.6,149.991272,-35556.40234375,9.47160410635477E-5,2.0372669916502E-6,1,0.999253354069792,40.0298881530762,1.99676665722874,15.2399996295571,0.00107802129499129,0.000176013518989372,0.25,-1.00556168470089E-6,9.51821243853651E-5,-8.61131816029913E-7,149.991272,149.991272,-35563.76171875,-35549.04296875,57.4254656793715,20.6191249815594,21.770052,0,0,0,40,4449,149.85535,-35556.40234375,,,,,,,,,,,,,0,,,,-0.00245,,,,,,149.991272,,,,
,28519615.515,149.99043275,-30761.7734375,7.99885984139622E-5,1.26255647908504E-6,1,0.999253354069792,40.0298881530762,1.9969115647305,15.2399996295571,0.000911977919494479,0.000139950035760074,0.25,-1.61577608996589E-6,8.03833500330333E-5,-1.49720231662146E-6,149.9899292,149.9909363,-30771.80078125,-30751.74609375,57.2370932062368,20.6187044664303,21.3904,0,0,0,40,4449,149.86745,-30761.7734375,,,,,,,,,,,,,0,,,,-0.00245,,,,,,149.99043275,,,,
,28519710.85,149.9894562,-25999.37109375,6.71996302877503E-5,1.41271391215133E-6,1,0.999253354069792,40.0298881530762,1.99670544482784,15.2399996295571,0.000764483415347592,0.000126786801481642,0.25,-5.45746122206793E-7,6.75299233608091E-5,-4.41855365323124E-7,149.9894562,149.9894562,-26004.62109375,-25994.12109375,57.4840878183138,20.6199448638263,21.01075,0,0,0,40,4449,149.8765,-25999.37109375,,,,,,,,,,,,,0,,,,0,,,,,,149.9894562,,,,
,28519806.14,149.99201965,-21234.5224609375,5.24042990495101E-5,1.56076036945252E-6,1,0.999253354069792,40.0298881530762,1.99667887174701,15.2399996295571,0.000597937494606447,8.86621849371132E-5,0.25,-1.3244559020042E-6,5.26632495635334E-5,-1.247618442221E-6,149.9915924,149.9924469,-21246.9921875,-21222.052734375,57.3660619119099,20.6186565174523,21.3904,0,0,0,40,4449,149.88205,-21234.5224609375,,,,,,,,,,,,,0,,,,0.00245,,,,,,149.99201965,,,,
,28519902.65,149.9906311,-16412.6640625,3.8562259669407E-5,1.27947451480746E-6,1,0.999253354069792,40.0298881530762,1.99666078544845,15.2399996295571,0.000438910827009193,7.14629740288776E-5,0.25,-4.27184090305493E-7,3.87519092347203E-5,-3.67800896877063E-7,149.9906311,149.9906311,-16420.287109375,-16405.041015625,57.1221938139099,20.6238335370697,21.770052,0,0,0,40,4449,149.8927,-16412.6640625,,,,,,,,,,,,,0,,,,0.0049,,,,,,149.9906311,,,,
,28519995.66,149.9918365,-11762.3657226563,2.48290129963555E-5,8.9955978841871E-7,1,0.999253354069792,40.0298881530762,1.99662176093152,15.2399996295571,0.000282600592290584,4.59810283356273E-5,0.25,-2.77856688034896E-7,2.49511062356681E-5,-2.39540845903644E-7,149.9918365,149.9918365,-11772.2587890625,-11752.47265625,57.3277621144676,20.6217804960463,21.01075,0,0,0,40,4449,149.8989,-11762.3657226563,,,,,,,,,,,,,0,,,,0,,,,,,149.9918365,,,,
,28520089.585,149.9922943,-7069.30541992188,1.29051034569853E-5,5.72892974167769E-7,1,0.999253354069792,40.0298881530762,1.99654542193195,15.2399996295571,0.000147796809094813,1.86285082491576E-5,0.25,-6.08370764478192E-7,1.29692958878027E-5,-5.90683036044997E-7,149.9922943,149.9922943,-7074.3564453125,-7064.25439453125,57.2574155477368,20.6209417723246,21.3904,0,0,0,40,4449,149.90705,-7069.30541992188,,,,,,,,,,,,,0,,,,0.00245,,,,,,149.9922943,,,,
,28520184.985,149.9910278,-2300.95703125,1.22859248670164E-6,4.10257362165098E-7,1,0.999253354069792,40.0298881530762,1.99652136284935,15.2399996295571,1.44765202819025E-5,-5.57648215767523E-7,0.25,-2.63139740204203E-7,1.2350324253627E-6,-2.6245717452385E-7,149.9910278,149.9910278,-2310.96508789062,-2290.94897460938,57.3902923960061,20.6215159318515,21.3904,0,0,0,40,4449,149.91455,-2300.95703125,,,,,,,,,,,,,0,,,,0,,,,,,149.9910278,,,,
,28520278.72,149.9965973,2382.70739746094,-7.16381992202678E-6,4.46006984747354E-7,1,0.999253354069792,40.0298881530762,1.99665434067855,15.2399996295571,-8.10739839126644E-5,-1.59349606025224E-5,0.25,-1.54650339926257E-7,-7.19865950157845E-6,-1.66902368134224E-7,149.9965973,149.9965973,2377.759765625,2387.65502929687,57.301968373333,20.6198552134671,21.770052,0,0,0,40,4449,149.91775,2382.70739746094,,,,,,,,,,,,,0,,,,-0.00245,,,,,,149.9965973,,,,
,28520375.405,149.9971924,7214.28369140625,-1.6107159545699E-5,4.7903894101735E-7,1,0.999253354069792,40.0298881530762,1.99665577249518,15.2399996295571,-0.000182729647859066,-3.32893034608589E-5,0.25,-1.24265104829395E-7,-1.61858632008033E-5,-1.50666017799774E-7,149.9971924,149.9971924,7206.77880859375,7221.78857421875,57.2198973788137,20.6163895104782,21.3904,0,0,0,40,4449,149.91595,7214.28369140625,,,,,,,,,,,,,0,,,,0,,,,,,149.9971924,,,,
,28520471.065,150.0050964,11994.9155273437,-2.7009390163991E-5,8.69476847671868E-7,1,0.999253354069792,40.0298881530762,1.99652791060847,15.2399996295571,-0.000307437547673324,-4.98210863078254E-5,0.25,3.19459917250825E-7,-2.71422248564892E-5,2.77874774957532E-7,150.0050964,150.0050964,11984.6767578125,12005.154296875,57.3269804859484,20.6138059778751,21.770052,0,0,0,40,4449,149.9135,11994.9155273437,,,,,,,,,,,,,0,,,,0,,,,,,150.0050964,,,,
,28520567.04,150.0049438,16792.3583984375,-3.97798415667896E-5,1.00841658139302E-6,1,0.999253354069792,40.0298881530762,1.99650330228065,15.2399996295571,-0.000451409577875163,-8.13218440493124E-5,0.25,-2.29124096233894E-7,-3.99744002151273E-5,-2.93643019239493E-7,150.0049438,150.0049438,16787.4453125,16797.271484375,57.505191788333,20.617748695317,21.3904,0,0,0,40,4449,149.9063,16792.3583984375,,,,,,,,,,,,,0,,,,0,,,,,,150.0049438,,,,
,28520665.305,150.0076141,21702.267578125,-5.42851377981825E-5,1.20786445798899E-6,1,0.999253354069792,40.0298881530762,1.99642749215219,15.2399996295571,-0.000616468413658904,-0.00010822185844848,0.25,-7.08639364706089E-8,-5.45510718737549E-5,-1.57495816323619E-7,150.0076141,150.0076141,21694.8203125,21709.71484375,57.383257739333,20.6147054281583,21.3904,0,0,0,40,4449,149.8965,21702.267578125,,,,,,,,,,,,,0,,,,0,,,,,,150.0076141,,,,
,28520762.09,150.0077057,26542.3515625,-6.83358692629704E-5,1.13043644021947E-6,1,0.999253354069792,40.0298881530762,1.99645210452932,15.2399996295571,-0.000776008697202649,-0.000136414767579033,0.25,-1.05338592165397E-7,-6.86706751183129E-5,-2.14176152134866E-7,150.0077057,150.0077057,26532.44140625,26552.26171875,57.0237086204868,20.6160681252901,21.3904,0,0,0,40,4449,149.88795,26542.3515625,,,,,,,,,,,,,0,,,,0.00245,,,,,,150.0077057,,,,
,28520857.345,150.0103302,31302.93359375,-8.1826752303653E-5,1.48767254563967E-6,1,0.999253354069792,40.0298881530762,1.99653415588378,15.2399996295571,-0.000928368660939124,-0.000168387579405989,0.25,-5.69761664191521E-7,-8.22270274997768E-5,-7.01900608035242E-7,150.0103302,150.0103302,31300.462890625,31305.404296875,57.3715333115445,20.6132524434946,21.770052,0,0,0,40,4449,149.87935,31302.93359375,,,,,,,,,,,,,0,,,,0,,,,,,150.0103302,,,,
,28520954.455,150.0141144,36158.392578125,-9.77482512005626E-5,1.77684695587913E-6,1,0.999253354069792,40.0298881530762,1.99653444113657,15.2399996295571,-0.0011127593743277,-0.000179615053665369,0.25,1.21489322292971E-6,-9.82294877725395E-5,1.06678456084232E-6,150.0141144,150.0141144,36148.49609375,36168.2890625,57.1956668947176,20.6163543388017,21.770052,0,0,0,40,4449,149.868,36158.392578125,,,,,,,,,,,,,0,,,,0,,,,,,150.0141144,,,,
,28521051.51,150.0121307,41008.341796875,-0.000113208564847928,1.38178802595073E-6,1,0.999253354069792,40.0298881530762,1.99658548079119,15.2399996295571,-0.00128640566835415,-0.000221724571228826,0.25,2.00893010679483E-7,-0.000113764134839144,2.3972614628707E-8,150.0121307,150.0121307,41001.0859375,41015.59765625,57.220679007333,20.6132814025728,21.01075,0,0,0,40,4449,149.85635,41008.341796875,,,,,,,,,,,,,0,,,,0,,,,,,150.0121307,,,,
,28521146.75,150.0102539,45768.3828125,-0.000129544977330896,1.51058797125855E-6,1,0.999253354069792,40.0298881530762,1.9965561854235,15.2399996295571,-0.0014704476165657,-0.000262742247585985,0.25,-5.65238096783416E-7,-0.000130179609621844,-7.70980736283323E-7,150.0102539,150.0102539,45763.234375,45773.53125,57.2011382943522,20.6146027491873,21.3904,0,0,0,40,4449,149.8471,45768.3828125,,,,,,,,,,,,,0,,,,0,,,,,,150.0102539,,,,
,28521243.195,150.0098419,50588.283203125,-0.000142813736040135,1.77392203851971E-6,1,0.999253354069792,40.0298881530762,1.99655128284673,15.2399996295571,-0.00162037447877676,-0.000293574458206349,0.25,-9.68988870218691E-7,-0.000143512983591851,-1.19681550186958E-6,150.0098419,150.0098419,50575.73046875,50600.8359375,57.1823792098907,20.6114301454527,21.770052,0,0,0,40,4449,149.8364,50588.283203125,,,,,,,,,,,,,0,,,,0.00245,,,,,,150.0098419,,,,
,28521341.175,150.0133514,55483.587890625,-0.000157929835719834,2.13731190620129E-6,1,0.999253354069792,40.0298881530762,1.9965961030374,15.2399996295571,-0.00178618918557967,-0.000357574996318113,0.25,-3.97026888817105E-6,-0.000158698738627376,-4.23565791588701E-6,150.0133514,150.0133514,55473.62109375,55493.5546875,57.2363115777176,20.6124010447486,21.3904,0,0,0,40,4449,149.82415,55483.587890625,,,,,,,,,,,,,0,,,,-0.0049,,,,,,150.0133514,,,,
,28521439.555,150.0103149,60401.08203125,-0.000171542096975979,2.01174906043646E-6,1,0.999253354069792,40.0298881530762,1.99652826434801,15.2399996295571,-0.00195090289535629,-0.000326263359616733,0.25,1.15521299348481E-6,-0.000172385982137526,8.94658235843643E-7,150.0103149,150.0103149,60396.25390625,60405.91015625,57.1229754424291,20.6141439067916,22.149702,0,0,0,40,4449,149.8169,60401.08203125,,,,,,,,,,,,,0,,,,0,,,,,,150.0103149,,,,
,28521537.605,150.0106125,65304.21875,-0.000191305981121352,2.81779936841381E-6,1,0.999253354069792,40.0298881530762,1.99654134603047,15.2399996295571,-0.00217523598616171,-0.000366452005160222,0.25,1.05879887452753E-6,-0.000192246935471856,7.68063803410692E-7,150.0105286,150.0106964,65299.0703125,65309.3671875,57.1237570709483,20.6129847708035,21.3904,0,0,0,40,4449,149.8038,65304.21875,,,,,,,,,,,,,0,,,,0,,,,,,150.0106125,,,,
,28521634.83,150.0111084,70164.7421875,-0.000204835419973044,1.95971725166045E-6,1,0.999253354069792,40.0298881530762,1.99656132260932,15.2399996295571,-0.00232495177703269,-0.000416170917934423,0.25,-9.62388428569801E-7,-0.000205839901803427,-1.28293232111305E-6,150.0111084,150.0111084,70162.46875,70167.015625,57.2394380917945,20.6108356804895,21.770052,0,0,0,40,4449,149.7949,70164.7421875,,,,,,,,,,,,,0,,,,-0.0049,,,,,,150.0111084,,,,
,28521732.26,150.011673,75032.0703125,-0.000222200140385252,2.31449787396889E-6,1,0.999253354069792,40.0298881530762,1.99670107010121,15.2399996295571,-0.00252817154152947,-0.000417298838769183,0.25,1.9638694808683E-6,-0.00022329464084494,1.63206191612936E-6,150.011673,150.011673,75024.6796875,75039.4609375,57.1550222117176,20.6106340643704,21.770052,0,0,0,40,4449,149.7835,75032.0703125,,,,,,,,,,,,,0,,,,-0.0049,,,,,,150.011673,,,,
,28521829.395,150.0092316,79890.37109375,-0.000235953960235591,2.77991483653741E-6,1,0.999253354069792,40.0298881530762,1.99675531864795,15.2399996295571,-0.00267427756802009,-0.000503183323915704,0.25,-3.20087006143861E-6,-0.000237108376357267,-3.57796235653472E-6,150.0092316,150.0092316,79887.7109375,79893.03125,57.1659650109868,20.6098366729944,21.3904,0,0,0,40,4449,149.7757,79890.37109375,,,,,,,,,,,,,0,,,,0,,,,,,150.0092316,,,,
,28521925.585,150.0107727,84698.8671875,-0.000254330531162763,2.80797833019034E-6,1,0.999253354069792,40.0298881530762,1.99680375778109,15.2399996295571,-0.00288528021805978,-0.00052714144346783,0.25,-2.10968865367697E-6,-0.000255577184416147,-2.50825337584156E-6,150.0107727,150.0107727,84696.4921875,84701.2421875,57.1143775287176,20.6090819158695,21.3904,0,0,0,40,4449,149.76755,84698.8671875,,,,,,,,,,,,,0,,,,0.0049,,,,,,150.0107727,,,,
,28522017.77,150.0107727,89304.6328125,-0.000263981674183562,2.56615234668918E-6,1,0.999253354069792,40.0298881530762,1.99659718583538,15.2399996295571,-0.00299395162534386,-0.000550103651772255,0.25,-2.45619137397528E-6,-0.000265275512768552,-2.8698910172829E-6,150.0107727,150.0107727,89299.6640625,89309.6015625,57.0166739638137,20.6112106606607,21.770052,0,0,0,40,4449,149.75715,89304.6328125,,,,,,,,,,,,,0,,,,0,,,,,,150.0107727,,,,
,28522125.58,150.0054321,86233.58984375,-0.000258334018673258,3.2888722083986E-6,1,0.999253354069792,40.0298881530762,1.99671929266908,15.2399996295571,-0.00293060587723734,-0.000535276597612596,0.25,-2.13083221102884E-6,-0.000259600435757604,-2.53523364328239E-6,150.0054321,150.0054321,86228.5625,86238.6171875,57.1542405831984,20.6114899437266,21.770052,0,0,0,40,4449,149.7517,86233.58984375,,,,,,,,,,,,,0,,,,-0.0049,,,,,,150.0054321,,,,
,28522220.775,149.9998627,81475.10546875,-0.000241659697911761,2.74377253857986E-6,1,0.999253354069792,40.0298881530762,1.99675692083929,15.2399996295571,-0.00274616148807884,-0.000473938020801219,0.25,3.6672120153278E-7,-0.000242847747673721,-1.23643527113746E-9,149.9998627,149.9998627,81470.03125,81480.1796875,56.8814522299868,20.6099783558413,21.3904,0,0,0,40,4449,149.75365,81475.10546875,,,,,,,,,,,,,0,,,,0,,,,,,149.9998627,,,,
,28522318.9,149.9947052,76566.11328125,-0.000225459833716595,2.68567312097853E-6,1,0.999253354069792,40.0298881530762,1.99663819056375,15.2399996295571,-0.00255618737997315,-0.000475072998560825,0.25,-2.55554415648199E-6,-0.000226563576966597,-2.91425798086262E-6,149.9947052,149.9947052,76560.84375,76571.3828125,57.2785195177561,20.6153786824655,21.3904,0,0,0,40,4449,149.7612,76566.11328125,,,,,,,,,,,,,0,,,,0,,,,,,149.9947052,,,,
,28522415.68,149.9936829,71730.40234375,-0.000207381552677341,2.74015255287916E-6,1,0.999253354069792,40.0298881530762,1.99671077925516,15.2399996295571,-0.00235885133088732,-0.000393639958762694,0.25,1.46669967584048E-6,-0.000208402439936352,1.15442500944139E-6,149.9936829,149.9936829,71723.0625,71737.7421875,57.0635716749676,20.6122396638239,21.3904,0,0,0,40,4449,149.7657,71730.40234375,,,,,,,,,,,,,0,,,,0,,,,,,149.9936829,,,,
,28522512.635,149.9897461,66885.07421875,-0.000193058085595939,2.54286468361911E-6,1,0.999253354069792,40.0298881530762,1.99670410825381,15.2399996295571,-0.00219150190560284,-0.000391822425027279,0.25,-8.6698836908289E-7,-0.000194004830031926,-1.1696471819168E-6,149.989502,149.9899902,66880.0390625,66890.109375,56.9236601700253,20.609466512455,21.3904,0,0,0,40,4449,149.7735,66885.07421875,,,,,,,,,,,,,0,,,,0,,,,,,149.9897461,,,,
,28522609.61,149.9934082,62036.796875,-0.000177666467412591,2.18622923226035E-6,1,0.999253354069792,40.0298881530762,1.99669178675362,15.2399996295571,-0.00201956084630871,-0.000344554386903832,0.25,6.13844436919406E-7,-0.00017853970746963,3.413479167706E-7,149.9934082,149.9934082,62026.8515625,62046.7421875,57.2128627221407,20.6127534714478,21.3904,0,0,0,40,4449,149.78245,62036.796875,,,,,,,,,,,,,0,,,,0.0049,,,,,,149.9934082,,,,
,28522707.4,149.9898834,57148.654296875,-0.000165184256696281,2.02815388159061E-6,1,0.999253354069792,40.0298881530762,1.99664289501136,15.2399996295571,-0.00187398148564137,-0.000341276146522174,0.25,-1.27147096175809E-6,-0.000165993121564737,-1.53469728276357E-6,149.9898834,149.9898834,57143.70703125,57153.6015625,57.2120810936214,20.6156403904398,21.770052,0,0,0,40,4449,149.79305,57148.654296875,,,,,,,,,,,,,0,,,,0,,,,,,149.9898834,,,,
,28522805.645,149.9890594,52238.9453125,-0.000146197973953017,1.83176138484981E-6,1,0.999253354069792,40.0298881530762,1.99667637641449,15.2399996295571,-0.00166062032987839,-0.000290516803544099,0.25,-1.08982397039175E-7,-0.000146915294151045,-3.37699471979995E-7,149.9890594,149.9890594,52231.44140625,52246.44921875,57.1120326431599,20.6115291707986,21.770052,0,0,0,40,4449,149.80155,52238.9453125,,,,,,,,,,,,,0,,,,0,,,,,,149.9890594,,,,
,28522902.295,149.990448,47408.857421875,-0.000132016575388296,2.67721142997994E-6,1,0.999253354069792,40.0298881530762,1.99666573662181,15.2399996295571,-0.00150510764804407,-0.000230305175019936,0.25,2.72169987977352E-6,-0.00013266858595607,2.5283637604999E-6,149.990448,149.990448,47399,47418.71484375,57.2777378892368,20.6108728526907,21.3904,0,0,0,40,4449,149.8112,47408.857421875,,,,,,,,,,,,,0,,,,0,,,,,,149.990448,,,,
,28522996.04,149.9911194,42720.576171875,-0.000115366435761388,1.9339316875058E-6,1,0.999253354069792,40.0298881530762,1.9967092441984,15.2399996295571,-0.00131130636464456,-0.000224231622922809,0.25,3.571172023519E-7,-0.000115932932381797,1.77708986079733E-7,149.9911194,149.9911194,42710.625,42730.52734375,57.2550706621791,20.6118213250455,21.770052,0,0,0,40,4449,149.8199,42720.576171875,,,,,,,,,,,,,0,,,,0.00245,,,,,,149.9911194,,,,
,28523089.91,149.991272,38030.44921875,-0.000104591646932748,1.82332201823465E-6,1,0.999253354069792,40.0298881530762,1.99669340081646,15.2399996295571,-0.00118978149788536,-0.000197797250175653,0.25,8.07530877907622E-7,-0.000105105893454712,6.46769254666051E-7,149.991272,149.991272,38023.046875,38037.8515625,57.0252718775253,20.6134304491046,21.770052,0,0,0,40,4449,149.82725,38030.44921875,,,,,,,,,,,,,0,,,,0,,,,,,149.991272,,,,
,28523185.845,149.9910889,33235.84765625,-8.69843484966577E-5,1.40650427212108E-6,1,0.999253354069792,40.0298881530762,1.99673301613916,15.2399996295571,-0.00098995317319818,-0.00016194445766951,0.25,8.97152285375053E-7,-8.74122969342206E-5,7.64154191131803E-7,149.9910889,149.9910889,33230.484375,33241.2109375,57.1995750373137,20.6147424939331,21.770052,0,0,0,40,4449,149.83215,33235.84765625,,,,,,,,,,,,,0,,,,0,,,,,,149.9910889,,,,
,28523285.535,149.9896698,28253.78515625,-7.20676095841522E-5,1.51691357553551E-6,1,0.999253354069792,40.0298881530762,1.99661226084404,15.2399996295571,-0.000819948542237953,-0.000135266331328962,0.25,6.46693303829284E-7,-7.24219508889267E-5,5.3569563992131E-7,149.9896698,149.9896698,28243.779296875,28263.791015625,57.3394865422561,20.6150135011301,21.770052,0,0,0,40,4449,149.84415,28253.78515625,,,,,,,,,,,,,0,,,,-0.00245,,,,,,149.9896698,,,,
,28523381.78,149.9884033,23443.51953125,-5.79008233800902E-5,1.63792620964864E-6,1,0.999253354069792,40.0298881530762,1.99671648752638,15.2399996295571,-0.000657870521565933,-0.000114007339676207,0.25,5.10093727779964E-8,-5.81847138453497E-5,-4.07208626040658E-8,149.9884033,149.9884033,23441.177734375,23445.861328125,57.2441278629099,20.6135010504049,21.3904,0,0,0,40,4449,149.8506,23443.51953125,,,,,,,,,,,,,0,,,,-0.00245,,,,,,149.9884033,,,,
,28523475.795,149.9898682,18743.7119140625,-4.42179048426627E-5,1.34985892383752E-6,1,0.999253354069792,40.0298881530762,1.99667483766691,15.2399996295571,-0.000504253399529303,-7.63927153951525E-5,0.25,9.78480403632215E-7,-4.44361623758725E-5,9.12851112030991E-7,149.9898682,149.9898682,18738.73828125,18748.685546875,57.1175040427945,20.6130442228412,21.3904,0,0,0,40,4449,149.8608,18743.7119140625,,,,,,,,,,,,,0,,,,0,,,,,,149.9898682,,,,
,28523573.445,149.9903107,13863.9140625,-3.08863177846556E-5,7.90735480654147E-7,1,0.999253354069792,40.0298881530762,1.99679751092674,15.2399996295571,-0.000351096063949614,-5.9944993892924E-5,0.25,1.04283936256322E-7,-3.10378207587809E-5,5.54755877218002E-8,149.9903107,149.9903107,13861.484375,13866.34375,57.2269320354868,20.6131528185016,21.770052,0,0,0,40,4449,149.8656,13863.9140625,,,,,,,,,,,,,0,,,,0,,,,,,149.9903107,,,,
,28523669.315,149.9912567,9071.6767578125,-1.7564962917635E-5,6.86437116985407E-7,1,0.999253354069792,40.0298881530762,1.99685407975802,15.2399996295571,-0.000200338407163656,-3.02696756982983E-5,0.25,3.95765285307711E-7,-1.76516461495563E-5,3.69591282065374E-7,149.9912567,149.9912567,9064.20703125,9079.146484375,57.3050948874099,20.612513064324,21.770052,0,0,0,40,4449,149.87595,9071.6767578125,,,,,,,,,,,,,0,,,,0,,,,,,149.9912567,,,,
,28523763.415,149.9909515,4368.25463867188,-5.84796264821649E-6,4.78106219730288E-7,1,0.999253354069792,40.0298881530762,1.99688875029967,15.2399996295571,-6.73484364776055E-5,-6.35836209184012E-6,0.25,4.59177802330132E-7,-5.87734372469203E-6,4.52047984271863E-7,149.9909515,149.9909515,4360.58740234375,4375.921875,57.3559007411599,20.6116601826482,21.770052,0,0,0,40,4449,149.8837,4368.25463867188,,,,,,,,,,,,,0,,,,-0.0049,,,,,,149.9909515,,,,
,28523851.89,149.9942627,-0.258804142475128,4.72925754750122E-6,3.36569728872241E-7,1,0.999253354069792,40.0298881530762,1.9967332183058,15.2399996295571,5.47057213742513E-5,3.73541556399334E-6,0.25,-4.95132778034371E-7,4.75321486942893E-6,-4.89961744329192E-7,149.9942627,149.9942627,-0.274027913808823,-0.243580371141434,57.2441278629099,20.6147384843826,21.770052,0,0,0,40,4417,149.88835,-0.258804142475128,,,,,,,,,,,,,0,,,,0,,,,,,149.9942627,,,,