File: data/monolayers/nanoparticles/Ol_CoFe_C/vsm/data_disorderedWafer/DD227_FCC_100OE.DAT
[Header]
; VSM Data File (default extension .dat)
; Copyright (c) 2003-2013, Quantum Design, Inc. All rights reserved.
TITLE,
FILEOPENTIME,28567094.58,11/27/2018,11:19 pm
BYAPP,VSM,2.0,2.0
INFO,PPMS VSM Option Release 1.4.10 Build 1,APPNAME
INFO,Quantum Design Linear Motor Servo Controller,MOTOR_MODULE_NAME
INFO,3101-100 M1,MOTOR_HW_VERSION
INFO,MMC1014,MOTOR_SERIAL_NUMBER
INFO,SRV No X-over 01.03.11,MOTOR_SOFTWARE_VERSION
INFO,Quantum Design VSM Detection Module,VSM_MODULE_NAME
INFO,3101-150 F0,VSM_HW_VERSION
INFO,VSM707,VSM_SERIAL_NUMBER
INFO,VSM No X-over 01.02.05 May 20 2008 13:51:47,VSM_SOFTWARE_VERSION
INFO,704,PREAMP_SERIAL_NUMBER
INFO,822,COIL_SERIAL_NUMBER
INFO,0,MOMENT_UNITS
INFO,CoFe2O4 FeO,SAMPLE_MATERIAL
INFO,disordered monolayer,SAMPLE_COMMENT
INFO,25.46,SAMPLE_MASS
INFO,,SAMPLE_VOLUME
INFO,,SAMPLE_MOLECULAR_WEIGHT
INFO,,SAMPLE_SIZE
INFO,,SAMPLE_SHAPE
DATATYPE,COMMENT,1
DATATYPE,TIME,2
STARTUPAXIS,X,2
STARTUPAXIS,Y1,5
[Data]
Comment,Time Stamp (sec),Temperature (K),Magnetic Field (Oe),Moment (emu),M. Std. Err. (emu),Transport Action,Averaging Time (sec),Frequency (Hz),Peak Amplitude (mm),Center Position (mm),Coil Signal' (mV),Coil Signal" (mV),Range (mV),M. Quad. Signal (emu),M. Raw' (emu),M. Raw" (emu),Min. Temperature (K),Max. Temperature (K),Min. Field (Oe),Max. Field (Oe),Mass (grams),Motor Lag (deg),Pressure (Torr),VSM Status (code),Motor Status (code),Measure Status (code),Measure Count,PPMS Status (code),System Temp. (K),System Field (Oe),Sample Position (deg),Bridge 1 Resistance (ohms),Bridge 1 Excitation (에),Bridge 2 Resistance (ohms),Bridge 2 Excitation (에),Bridge 3 Resistance (ohms),Bridge 3 Excitation (에),Bridge 4 Resistance (ohms),Bridge 4 Excitation (에),Signal 1 Vin (V),Signal 2 Vin (V),Digital Inputs (code),Drive 1 Iout (mA),Drive 1 Ipower (W),Drive 2 Iout (mA),Drive 2 Ipower (W),Pressure (),Map 20 (),Map 21 (),Map 22 (),Map 23 (),Map 24 (),Map 25 (),Map 26 (),Map 27 (),Map 28 (),Map 29 ()
,28567265.165,349.6239319,99.7461624145508,6.77905076896745E-7,4.57451533903484E-7,1,0.999253354069792,40.0298881530762,1.99741787560839,14.2299998551607,8.10800324721133E-6,-1.29637890162291E-6,0.25,-2.32198311032276E-7,6.76841205633489E-7,-2.31411747515144E-7,349.6239319,349.6239319,99.7461624145508,99.7461624145508,56.9338213407753,20.6034748879774,25.566563,0,0,0,40,4369,350.2617,99.7461624145508,,,,,,,,,,,,,0,,,,-0.00245,,,,,,349.6239319,,,,
,28567418.69,346.9794312,99.7461624145508,8.82816936972721E-7,3.66616038936307E-7,1,0.999253354069792,40.0298881530762,1.9972903108814,14.2299998551607,9.5847793840077E-6,3.93871936108541E-6,0.25,1.9596678094376E-7,8.8123059386985E-7,1.96138681059058E-7,346.9794312,346.9794312,99.7461624145508,99.7461624145508,56.8986480574099,20.6033034086948,25.566563,0,0,0,40,4374,345.1587,99.7461624145508,,,,,,,,,,,,,0,,,,0,,,,,,346.9794312,,,,
,28567570.93,343.4565735,99.7461624145508,-4.83544276164414E-8,4.65341168746434E-7,1,0.999253354069792,40.0298881530762,1.99703443384965,14.2299998551607,2.36591587000627E-7,-4.61364661371437E-6,0.25,-4.0023925706349E-7,-4.80501739581247E-8,-3.99645832100349E-7,343.4565735,343.4565735,99.7461624145508,99.7461624145508,56.9963516223137,20.6055371349256,25.186911,0,0,0,40,4374,341.1597,99.7461624145508,,,,,,,,,,,,,0,,,,0,,,,,,343.4565735,,,,
,28567715.55,339.9790344,99.7461624145508,6.8799339029848E-7,4.38846206878516E-7,1,0.999253354069792,40.0298881530762,1.99711574403908,14.2299998551607,7.35032241205418E-6,3.76514530703523E-6,0.25,2.14269194013948E-7,6.86883207146914E-7,2.14360766532477E-7,339.9482727,340.0097961,99.7461624145508,99.7461624145508,57.0127658212176,20.603976814335,25.566563,0,0,0,40,4374,337.45915,99.7461624145508,,,,,,,,,,,,,0,,,,0.0049,,,,,,339.9790344,,,,
,28567859.93,336.4855347,99.7461624145508,3.41621794201936E-7,3.86293796906646E-7,1,0.999253354069792,40.0298881530762,1.99703402601278,14.2299998551607,4.89838208113877E-6,-5.3383521524605E-6,0.25,-5.31847881825519E-7,3.4148508105761E-7,-5.30949043825083E-7,336.4855347,336.4855347,99.7461624145508,99.7461624145508,57.0424677049483,20.6047285382754,25.566563,0,0,0,40,4374,333.75335,99.7461624145508,,,,,,,,,,,,,0,,,,0.00245,,,,,,336.4855347,,,,
,28568018.89,332.5791626,99.7461624145508,,,2,,,,14.2000003036857,,,,,,,332.5791626,332.5791626,99.7461624145508,99.7461624145508,,,25.186911,,,,-99999999,4374,329.7352,99.7461624145508,,,,,,,,,,,,,,,,,,,,,,,332.5791626,,,,
,28568142.87,329.4889832,99.7461624145508,-1.29785260382897E-7,3.77477935810026E-7,1,0.999253354069792,40.0298881530762,1.99716987146535,14.189999550581,-1.18085755842479E-7,-8.03766732341664E-6,0.25,-6.89001390793811E-7,-1.29232155935885E-7,-6.88341282529399E-7,329.4889832,329.4889832,99.7461624145508,99.7461624145508,57.2097362080637,20.6004683221237,25.186911,0,0,0,40,4374,326.593,99.7461624145508,,,,,,,,,,,,,0,,,,-0.0049,,,,,,329.4889832,,,,
,28568286.86,325.9619141,99.7461624145508,7.41305333554077E-7,3.90072156718445E-7,1,0.999253354069792,40.0298881530762,1.99708707069728,14.189999550581,8.78353785778183E-6,-9.06346626649763E-7,0.25,-2.08618835510672E-7,7.40729270821834E-7,-2.07969712359605E-7,325.9619141,325.9619141,99.7461624145508,99.7461624145508,57.1612752398714,20.6060453993235,25.566563,0,0,0,40,4374,322.9428,99.7461624145508,,,,,,,,,,,,,0,,,,0,,,,,,325.9619141,,,,
,28568442.7,322.0992126,99.7461624145508,,,2,,,,14.2200004559755,,,,,,,322.0992126,322.0992126,99.7461624145508,99.7461624145508,,,25.946213,,,,-99999999,4374,319.0187,99.7461624145508,,,,,,,,,,,,,,,,,,,,,,,322.0992126,,,,
,28568569.455,318.9509888,99.7461624145508,3.40530983860385E-8,4.29106446977508E-7,1,0.999253354069792,40.0298881530762,1.99694416187438,14.2099997028708,7.02031565881319E-7,-1.76471457460357E-6,0.25,-1.62067886714511E-7,3.41304143269945E-8,-1.61932735238032E-7,318.9509888,318.9509888,99.7461624145508,99.7461624145508,57.024490249006,20.6084640984432,25.946213,0,0,0,40,4374,315.82725,99.7461624145508,,,,,,,,,,,,,0,,,,0,,,,,,318.9509888,,,,
,28568710.57,315.4534607,99.7461624145508,4.0274787182321E-7,3.3613346604155E-7,1,0.999253354069792,40.0298881530762,1.9970277285939,14.2099997028708,5.207826268676E-6,-2.99857228560469E-6,0.25,-3.35084663885715E-7,4.02726638200633E-7,-3.34635567084948E-7,315.4534607,315.4534607,99.7461624145508,99.7461624145508,57.1300100991022,20.6109918114755,25.186911,0,0,0,40,4374,312.28685,99.7461624145508,,,,,,,,,,,,,0,,,,0,,,,,,315.4534607,,,,
,28568863.25,311.6940308,99.7461624145508,,,2,,,,14.2300000664592,,,,,,,311.6940308,311.6940308,99.7461624145508,99.7461624145508,,,25.946213,,,,-99999999,4374,308.4527,99.7461624145508,,,,,,,,,,,,,,,,,,,,,,,311.6940308,,,,
,28568991.98,308.4858398,99.7461624145508,3.66175308347665E-7,4.1503216876189E-7,1,0.999253354069792,40.0298881530762,1.99675213807369,14.2200002446771,4.26974243380435E-6,-3.80603754675484E-8,0.25,-6.68059798970481E-8,3.66096925199939E-7,-6.65455659690438E-8,308.4858398,308.4858398,99.7461624145508,99.7461624145508,57.1503324406022,20.6047053842919,26.325863,0,0,0,40,4374,305.2033,99.7461624145508,,,,,,,,,,,,,0,,,,-0.00735,,,,,,308.4858398,,,,
,28569134.335,304.9680176,99.7461624145508,7.12003728216607E-7,3.92484751187995E-7,1,0.999253354069792,40.0298881530762,1.99674485881548,14.2200002446771,8.62476333496501E-6,-1.92969215640825E-6,0.25,-2.94060791644052E-7,7.12049808902556E-7,-2.93530046343198E-7,304.9680176,304.9680176,99.7461624145508,99.7461624145508,57.1112510146407,20.6101852665658,26.325863,0,0,0,40,4374,301.64165,99.7461624145508,,,,,,,,,,,,,0,,,,-0.00245,,,,,,304.9680176,,,,
,28569283.23,301.3093567,99.7461624145508,,,2,,,,14.2500002187491,,,,,,,301.3093567,301.3093567,99.7461624145508,99.7461624145508,,,25.946213,,,,-99999999,4374,297.8884,99.7461624145508,,,,,,,,,,,,,,,,,,,,,,,301.3093567,,,,
,28569416.94,297.9615173,99.7461624145508,6.47789531833841E-7,4.2884907023013E-7,1,0.999253354069792,40.0298881530762,2.00952069283339,14.2400003969669,8.0636762345423E-6,-2.72967459984048E-6,0.25,-3.52190889246292E-7,6.4805580412994E-7,-3.51766014323302E-7,297.9615173,297.9615173,99.7461624145508,99.7461624145508,57.0323065341983,20.6136433599882,26.325863,0,0,0,40,4374,294.54015,99.7461624145508,,,,,,,,,,,,,0,,,,-0.0049,,,,,,297.9615173,,,,
,28569557.76,294.4599609,99.7461624145508,2.57766990436273E-7,3.69203842969002E-7,1,0.999253354069792,40.0298881530762,2.00948202214061,14.2400003969669,3.16360897355645E-6,-8.24133735089E-7,0.25,-1.1710301847848E-7,2.57890715522213E-7,-1.16945079351409E-7,294.4599609,294.4599609,99.7461624145508,99.7461624145508,57.1018714724099,20.6164948539273,25.946213,0,0,0,40,4374,291.00745,99.7461624145508,,,,,,,,,,,,,0,,,,-0.00245,,,,,,294.4599609,,,,
,28569701.66,290.8917542,99.7461624145508,,,2,,,,14.2700003710389,,,,,,,290.8917542,290.8917542,99.7461624145508,99.7461624145508,,,26.325863,,,,-99999999,4374,287.405,99.7461624145508,,,,,,,,,,,,,,,,,,,,,,,290.8917542,,,,
,28569818.115,287.9997864,99.7461624145508,6.84499971093844E-7,3.6998153695409E-7,1,0.999253354069792,40.0298881530762,2.00927568876286,14.2599996179342,8.5197559157476E-6,-2.86739491871329E-6,0.25,-3.70618902580341E-7,6.85034879152042E-7,-3.70282071988455E-7,287.9997864,287.9997864,99.7461624145508,99.7461624145508,57.1065612435253,20.6171030261179,26.325863,0,0,0,40,4374,284.4777,99.7461624145508,,,,,,,,,,,,,0,,,,-0.00245,,,,,,287.9997864,,,,
,28569960.31,284.4642944,99.7461624145508,5.87647788331867E-7,3.45326734015238E-7,1,0.999253354069792,40.0298881530762,2.00932330983518,14.2599996179342,7.61788569430688E-6,-4.20733505585704E-6,0.25,-4.71542099526573E-7,5.88295049879372E-7,-4.71367334279718E-7,284.4642944,284.4642944,99.7461624145508,99.7461624145508,57.0878021590637,20.6169571587082,26.325863,0,0,0,40,4374,280.91285,99.7461624145508,,,,,,,,,,,,,0,,,,0.0049,,,,,,284.4642944,,,,
,28570100.375,280.9904785,99.7461624145508,5.48985588745055E-7,3.45008877318273E-7,1,0.999253354069792,40.0298881530762,2.0092984726302,14.2599996179342,5.77609185723449E-6,3.80847219016678E-6,0.25,2.39454129832492E-7,5.49167324585223E-7,2.40010108045901E-7,280.9904785,280.9904785,99.7461624145508,99.7461624145508,57.1878506095253,20.6182024086169,26.705515,0,0,0,40,4374,277.3955,99.7461624145508,,,,,,,,,,,,,0,,,,0,,,,,,280.9904785,,,,
,28570222.925,277.9499207,99.7461624145508,6.53493704656109E-7,3.56388678031821E-7,1,0.999253354069792,40.0298881530762,2.00934550825013,14.2700001597404,7.22184608713162E-6,2.54191996479977E-6,0.25,1.10026509491296E-7,6.53907768101908E-7,1.10593124163861E-7,277.9499207,277.9499207,99.7461624145508,99.7461624145508,57.0213637349291,20.6175198382221,25.946213,0,0,0,40,4374,274.3207,99.7461624145508,,,,,,,,,,,,,0,,,,-0.0049,,,,,,277.9499207,,,,
,28570361.69,274.4993896,99.7461624145508,8.96732152781049E-8,3.76497607532142E-7,1,0.999253354069792,40.0298881530762,2.00934177677654,14.2700001597404,1.39424505344639E-6,-1.97672113043679E-6,0.25,-1.89174255205519E-7,8.98943057556037E-8,-1.89273700418391E-7,274.4993896,274.4993896,99.7461624145508,99.7461624145508,57.1018714724099,20.6191869376762,26.705515,0,0,0,40,4374,270.85755,99.7461624145508,,,,,,,,,,,,,0,,,,0.00245,,,,,,274.4993896,,,,
,28570501.44,270.9859314,99.7461624145508,5.50251944001352E-7,2.91150265604986E-7,1,0.999253354069792,40.0298881530762,2.00934137658143,14.2700001597404,7.18677222557806E-6,-4.22956967151698E-6,0.25,-4.66859827847363E-7,5.5116222900692E-7,-4.66910395014489E-7,270.9859314,270.9859314,99.7461624145508,99.7461624145508,56.9783741663714,20.6180272215844,26.325863,0,0,0,40,4374,267.3578,99.7461624145508,,,,,,,,,,,,,0,,,,0,,,,,,270.9859314,,,,
,28570641.585,267.4924622,99.7461624145508,1.02262334260728E-6,3.79257501402419E-7,1,0.999253354069792,40.0298881530762,2.00935992160173,14.3100004643202,1.21057991666767E-5,-6.37496648602917E-7,0.25,-2.33277833718654E-7,1.02396168848586E-6,-2.32749466772636E-7,267.4924622,267.4924622,99.7461624145508,99.7461624145508,56.8447156895829,20.6167877604561,26.705515,0,0,0,40,4374,263.8492,99.7461624145508,,,,,,,,,,,,,0,,,,0,,,,,,267.4924622,,,,
,28570784.525,263.9595337,99.7461624145508,-5.64021068697601E-8,3.6373350153291E-7,1,0.999253354069792,40.0298881530762,2.00936867720226,14.3100004643202,2.80531157706621E-7,-5.43414368959474E-6,0.25,-4.67357571180169E-7,-5.610491507676E-8,-4.67989898908877E-7,263.9595337,263.9595337,99.7461624145508,99.7461624145508,57.1307917276214,20.6193722829833,25.946213,0,0,0,40,4374,260.27925,99.7461624145508,,,,,,,,,,,,,0,,,,-0.0049,,,,,,263.9595337,,,,
,28570924.64,260.4526367,99.7461624145508,6.5918176305015E-7,3.62070368469237E-7,1,0.999253354069792,40.0298881530762,2.00927855511402,14.3100004643202,8.83128879730595E-6,-6.3291568362768E-6,0.25,-6.6998031279786E-7,6.60629671758198E-7,-6.7037889917558E-7,260.4526367,260.4526367,99.7461624145508,99.7461624145508,56.9002113144483,20.6185559275067,26.325863,0,0,0,40,4374,256.7655,99.7461624145508,,,,,,,,,,,,,0,,,,-0.0049,,,,,,260.4526367,,,,
,28571065.675,256.9543152,99.7461624145508,4.8022487269566E-7,3.86666901901086E-7,1,0.999253354069792,40.0298881530762,1.99648295910599,14.3400002270937,5.50111059546404E-6,5.74183513329549E-7,0.25,-3.2564374691511E-8,4.80975035046056E-7,-3.22224744227912E-8,256.9543152,256.9543152,99.7461624145508,99.7461624145508,57.1417345268907,20.6144867757175,25.946213,0,0,0,40,4374,253.2348,99.7461624145508,,,,,,,,,,,,,0,,,,0.0049,,,,,,256.9543152,,,,
,28571204.415,253.4672394,99.7461624145508,7.04758454732552E-7,4.27342582354098E-7,1,0.999253354069792,40.0298881530762,1.99646759148023,14.3400002270937,8.11894660670482E-6,5.84441590497701E-7,0.25,-7.0611264025629E-8,7.05965926202141E-7,-7.0143033996769E-8,253.4672394,253.4672394,99.7461624145508,99.7461624145508,57.0291800201214,20.6133240228824,26.705515,0,0,0,40,4374,249.7734,99.7461624145508,,,,,,,,,,,,,0,,,,-0.0049,,,,,,253.4672394,,,,
,28571343.055,249.9918518,99.7461624145508,2.71236015546084E-7,3.39910794752723E-7,1,0.999253354069792,40.0298881530762,1.99653672469267,14.3400002270937,3.35717745137367E-6,-1.11264645513722E-6,0.25,-1.45289311972111E-7,2.71833812315965E-7,-1.45315691541153E-7,249.9918518,249.9918518,99.7461624145508,99.7461624145508,56.8329912617945,20.6138954125106,26.325863,0,0,0,40,4374,246.30415,99.7461624145508,,,,,,,,,,,,,0,,,,0,,,,,,249.9918518,,,,
,28571483.5,246.4725952,99.7461624145508,9.52797538188723E-7,2.44758063694455E-7,1,0.999253354069792,40.0298881530762,2.00928066509681,14.3699999898672,1.14826836461278E-5,-1.72035080875386E-6,0.25,-3.1623717824061E-7,9.54856657880686E-7,-3.16014716075086E-7,246.4725952,246.4725952,99.7461624145508,99.7461624145508,56.8837971155445,20.6177215481488,25.946213,0,0,0,40,4374,242.8013,99.7461624145508,,,,,,,,,,,,,0,,,,0,,,,,,246.4725952,,,,
,28571623.68,242.9731293,99.7461624145508,7.45523200814707E-7,4.01889060336194E-7,1,0.999253354069792,40.0298881530762,2.0090888445224,14.3699999898672,9.6760571797821E-6,-5.32962282387211E-6,0.25,-5.97009956262703E-7,7.47534193896149E-7,-5.97553951659284E-7,242.9731293,242.9731293,99.7461624145508,99.7461624145508,56.9674313671022,20.6185610343594,26.325863,0,0,0,40,4374,239.3067,99.7461624145508,,,,,,,,,,,,,0,,,,0,,,,,,242.9731293,,,,
,28571763.3,239.4959106,99.7461624145508,7.59074640499417E-7,3.43186198267493E-7,1,0.999253354069792,40.0298881530762,2.00914490532064,14.3699999898672,9.33000994784758E-6,-2.40983723311234E-6,0.25,-3.43126732133978E-7,7.60988912467283E-7,-3.43181094018764E-7,239.4959106,239.4959106,99.7461624145508,99.7461624145508,57.1659650109868,20.6224526193669,26.325863,0,0,0,40,4374,235.82115,99.7461624145508,,,,,,,,,,,,,0,,,,0.0049,,,,,,239.4959106,,,,
,28571882.54,236.4870224,99.7461624145508,7.17004347199411E-7,3.36075158093429E-7,1,0.999253354069792,40.0298881530762,2.00912745562919,14.3900001421571,9.06987312865859E-6,-3.75234115672317E-6,0.25,-4.53596826155604E-7,7.19008604772244E-7,-4.53960365077492E-7,236.4581909,236.5158539,99.7461624145508,99.7461624145508,57.1448610409676,20.6185045260961,26.325863,0,0,0,40,4374,232.8363,99.7461624145508,,,,,,,,,,,,,0,,,,-0.0049,,,,,,236.4870224,,,,
,28572022.69,232.9848785,99.7461624145508,1.17452123842408E-6,3.46737189618903E-7,1,0.999253354069792,40.0298881530762,2.00920902532726,14.3900001421571,1.42082772242788E-5,-2.39275116798539E-6,0.25,-4.13686818544442E-7,1.17765689047484E-6,-4.13579838209436E-7,232.9848785,232.9848785,99.7461624145508,99.7461624145508,57.1745629246983,20.6195125923942,26.325863,0,0,0,40,4374,229.3221,99.7461624145508,,,,,,,,,,,,,0,,,,0,,,,,,232.9848785,,,,
,28572164.48,229.4562836,99.7461624145508,8.46394636287737E-7,3.60326228831589E-7,1,0.999253354069792,40.0298881530762,2.00929735169845,14.3900001421571,1.08338691716359E-5,-5.14305703197324E-6,0.25,-5.97941265726582E-7,8.49042568410093E-7,-5.98625502289499E-7,229.4562836,229.4562836,99.7461624145508,99.7461624145508,57.2441278629099,20.6171520999954,26.705515,0,0,0,40,4374,225.78335,99.7461624145508,,,,,,,,,,,,,0,,,,0.00245,,,,,,229.4562836,,,,
,28572281.095,226.4963226,99.7461624145508,6.09922711241429E-7,3.8351604372356E-7,1,0.999253354069792,40.0298881530762,1.99667990190741,14.4400000572205,8.13322157436873E-6,-5.82843074539909E-6,0.25,-6.20053543314374E-7,6.12078760763479E-7,-6.21067164424898E-7,226.4963226,226.4963226,99.7461624145508,99.7461624145508,57.0135474497368,20.6157818181226,25.946213,0,0,0,40,4374,222.8638,99.7461624145508,,,,,,,,,,,,,0,,,,-0.00245,,,,,,226.4963226,,,,
,28572421.39,222.9962158,99.7461624145508,8.27922986240093E-7,3.48163389758142E-7,1,0.999253354069792,40.0298881530762,1.99637231415183,14.4400000572205,9.66377131537248E-6,1.7970396195395E-8,0.25,-1.42118483266116E-7,8.30286282237893E-7,-1.41698663929722E-7,222.9962158,222.9962158,99.7461624145508,99.7461624145508,57.1706547821022,20.619503037169,26.325863,0,0,0,40,4374,219.3613,99.7461624145508,,,,,,,,,,,,,0,,,,-0.00245,,,,,,222.9962158,,,,
,28572561.57,219.49954985,99.7461624145508,1.00969250133823E-6,3.48899410534153E-7,1,0.999253354069792,40.0298881530762,1.99650025553367,14.4400000572205,1.2026726772791E-5,-1.35566995083631E-6,0.25,-2.94857479346382E-7,1.01281732142612E-6,-2.94687532973815E-7,219.4689636,219.5301361,99.7461624145508,99.7461624145508,57.166746639506,20.6177980395995,25.946213,0,0,0,40,4374,215.8544,99.7461624145508,,,,,,,,,,,,,0,,,,-0.0049,,,,,,219.49954985,,,,
,28572702.905,215.9626617,99.7461624145508,6.39497021224379E-7,4.03500128628062E-7,1,0.999253354069792,40.0298881530762,1.99663394764872,14.4800003618002,7.12396308932732E-6,1.99064560270441E-6,0.25,6.45390557806566E-8,6.41302465881601E-7,6.53724868574117E-8,215.9626617,215.9626617,99.7461624145508,99.7461624145508,57.2769562607176,20.6170564035148,25.946213,0,0,0,40,4374,212.3293,99.7461624145508,,,,,,,,,,,,,0,,,,-0.0049,,,,,,215.9626617,,,,
,28572842.22,212.4633026,99.7461624145508,7.10464886169016E-7,3.70097975780676E-7,1,0.999253354069792,40.0298881530762,1.9965735041981,14.4800003618002,8.29237490888293E-6,3.95822939013006E-8,0.25,-1.19869707756222E-7,7.12749031567205E-7,-1.19503277266429E-7,212.4633026,212.4633026,99.7461624145508,99.7461624145508,56.8556584888522,20.620130464485,25.946213,0,0,0,40,4374,208.84615,99.7461624145508,,,,,,,,,,,,,0,,,,-0.00245,,,,,,212.4633026,,,,
,28572981.955,208.9606018,99.7461624145508,7.32340788562314E-7,3.11843126761812E-7,1,0.999253354069792,40.0298881530762,1.9966695421014,14.4800003618002,8.72017659860981E-6,-9.44261297446919E-7,0.25,-2.10433320597346E-7,7.34873875396491E-7,-2.10328197134065E-7,208.9606018,208.9606018,99.7461624145508,99.7461624145508,57.1182856713137,20.6205774019185,26.325863,0,0,0,40,4374,205.3595,99.7461624145508,,,,,,,,,,,,,0,,,,0,,,,,,208.9606018,,,,
,28573122.535,205.43267825,99.7461624145508,1.64643000064267E-6,3.39031313697016E-7,1,0.999253354069792,40.0298881530762,2.00924339930699,14.5300002768636,1.9747696548879E-5,-2.26862150156974E-6,0.25,-4.8476467671135E-7,1.65233813745798E-6,-4.84583453785114E-7,205.405777,205.4595795,99.7461624145508,99.7461624145508,57.312129544083,20.629085007509,25.946213,0,0,0,40,4374,201.85515,99.7461624145508,,,,,,,,,,,,,0,,,,0.0049,,,,,,205.43267825,,,,
,28573259.865,201.9983063,99.7461624145508,1.00429382427041E-6,4.01989064415815E-7,1,0.999253354069792,40.0298881530762,2.00926091330531,14.5300002768636,1.18707248240799E-5,-3.67621229130719E-7,0.25,-2.06662057204621E-7,1.00791865059789E-6,-2.06259632072852E-7,201.9983063,201.9983063,99.7461624145508,99.7461624145508,57.0823307594291,20.6317719464227,25.186911,0,0,0,40,4374,198.42845,99.7461624145508,,,,,,,,,,,,,0,,,,0.00245,,,,,,201.9983063,,,,
,28573400.25,198.4608917,99.7461624145508,8.46026224637854E-7,3.53035219576605E-7,1,0.999253354069792,40.0298881530762,2.00924508836947,14.5300002768636,1.06277336446024E-5,-3.91661859409111E-6,0.25,-4.90144147317532E-7,8.49534776698379E-7,-4.90908899027724E-7,198.4608917,198.4608917,99.7461624145508,99.7461624145508,56.9166255133522,20.6301874376615,26.325863,0,0,0,40,4374,194.9242,99.7461624145508,,,,,,,,,,,,,0,,,,0,,,,,,198.4608917,,,,
,28573539.565,194.980484,99.7461624145508,9.86367703257756E-7,3.39085307384469E-7,1,0.999253354069792,40.0298881530762,2.00919981286208,14.5699996501207,1.18041277507276E-5,-1.18357959589206E-6,0.25,-2.75080464510927E-7,9.90241772098347E-7,-2.74940102447702E-7,194.980484,194.980484,99.7461624145508,99.7461624145508,56.966649738583,20.6289481308964,25.566563,0,0,0,40,4374,191.4298,99.7461624145508,,,,,,,,,,,,,0,,,,-0.0049,,,,,,194.980484,,,,
,28573680.72,191.4758759,99.7461624145508,8.95637723469496E-7,3.56836268773848E-7,1,0.999253354069792,40.0298881530762,2.00922589927919,14.5699996501207,1.0813611760268E-5,-1.61509329011517E-6,0.25,-2.97129734311457E-7,8.99316437235732E-7,-2.97180718836596E-7,191.4758759,191.4758759,99.7461624145508,99.7461624145508,57.0971817012945,20.6305478216492,25.946213,0,0,0,40,4374,187.89855,99.7461624145508,,,,,,,,,,,,,0,,,,-0.0049,,,,,,191.4758759,,,,
,28573820.915,187.9480896,99.7461624145508,8.60425088006683E-7,3.26406924710046E-7,1,0.999253354069792,40.0298881530762,2.00880227857171,14.5699996501207,1.02823091423288E-5,-9.45650991890327E-7,0.25,-2.32400812156235E-7,8.63997500027831E-7,-2.3225287940892E-7,187.9480896,187.9480896,99.7461624145508,99.7461624145508,56.7415407250445,20.6299813240862,25.566563,0,0,0,40,4374,184.395,99.7461624145508,,,,,,,,,,,,,0,,,,0,,,,,,187.9480896,,,,
,28573941.295,184.9340668,99.7461624145508,8.71999585491842E-7,3.16275991601514E-7,1,0.999253354069792,40.0298881530762,1.98406498656588,14.6199995651841,1.06099728843364E-5,-2.73527883011526E-6,0.25,-3.94052692809967E-7,8.75901825449241E-7,-3.94522682512617E-7,184.9340668,184.9340668,99.7461624145508,99.7461624145508,56.5945945634291,20.6387942924279,25.566563,0,0,0,40,4374,181.38705,99.7461624145508,,,,,,,,,,,,,0,,,,-0.00245,,,,,,184.9340668,,,,
,28574083.555,181.4506836,99.7461624145508,6.00961838187797E-7,3.09830942332507E-7,1,0.999253354069792,40.0298881530762,1.98423200701949,14.6199995651841,6.91975258372565E-6,3.79700028558174E-7,0.25,-7.0840205399583E-8,6.03469260601806E-7,-7.03649246198696E-8,181.4506836,181.4506836,99.7461624145508,99.7461624145508,56.7860935506406,20.6300242126156,25.186911,0,0,0,40,4374,177.7653,99.7461624145508,,,,,,,,,,,,,0,,,,-0.0049,,,,,,181.4506836,,,,
,28574220.25,177.9903641,99.7461624145508,9.42447917279446E-7,3.30680441516968E-7,1,0.999253354069792,40.0298881530762,1.98404268300084,14.6199995651841,1.14467526106671E-5,-2.82476606851619E-6,0.25,-4.14249427227559E-7,9.46874227208282E-7,-4.14735398961363E-7,177.9577637,178.0229645,99.7461624145508,99.7461624145508,57.149550812083,20.636947423409,25.566563,0,0,0,40,4374,174.397,99.7461624145508,,,,,,,,,,,,,0,,,,-0.00245,,,,,,177.9903641,,,,
,28574338.525,174.9935455,99.7461624145508,7.77856545753119E-7,3.3925581258345E-7,1,0.999253354069792,40.0298881530762,1.98468869263256,14.6800000220537,8.98037726318756E-6,3.76454523309517E-7,0.25,-1.01948707320188E-7,7.8126969886704E-7,-1.0134524256234E-7,174.9935455,174.9935455,99.7461624145508,99.7461624145508,57.2972786022176,20.6317754402461,25.186911,0,0,0,40,4374,171.46475,99.7461624145508,,,,,,,,,,,,,0,,,,-0.00245,,,,,,174.9935455,,,,
,28574477.635,171.484726,99.7461624145508,7.86753800932668E-7,3.44512232952497E-7,1,0.999253354069792,40.0298881530762,1.98454982933314,14.6800000220537,9.10415685875961E-6,2.61741002305102E-7,0.25,-1.13689776849946E-7,7.90303772059967E-7,-1.13105950056395E-7,171.484726,171.484726,99.7461624145508,99.7461624145508,56.8470605751406,20.6271728958586,25.186911,0,0,0,40,4374,168.0076,99.7461624145508,,,,,,,,,,,,,0,,,,0.0049,,,,,,171.484726,,,,
,28574617.83,167.942749,99.7461624145508,9.58136063695554E-7,3.50067604872585E-7,1,0.999253354069792,40.0298881530762,1.98420937116818,14.6800000220537,1.09380723303389E-5,1.1728866760277E-6,0.25,-6.28202887088598E-8,9.62454433877259E-7,-6.17507959683337E-8,167.942749,167.942749,99.7461624145508,99.7461624145508,56.9557069393137,20.6294408691931,24.427608,0,0,0,40,4374,164.52875,99.7461624145508,,,,,,,,,,,,,0,,,,0,,,,,,167.942749,,,,
,28574756.775,164.4925385,99.7461624145508,1.11380653852067E-6,2.97394286465069E-7,1,0.999253354069792,40.0298881530762,1.98467649933323,14.7399995476007,1.36035216521943E-5,-3.71600886011085E-6,0.25,-5.22990996743191E-7,1.11958731083241E-6,-5.23737034917687E-7,164.4925385,164.4925385,99.7461624145508,99.7461624145508,56.9650864815445,20.6278905640495,25.186911,0,0,0,40,4374,161.0818,99.7461624145508,,,,,,,,,,,,,0,,,,0.00245,,,,,,164.4925385,,,,
,28574897.255,160.9699402,99.7461624145508,1.26236340700006E-6,2.51333843276256E-7,1,0.999253354069792,40.0298881530762,1.98424545251973,14.7399995476007,1.48419549693374E-5,-9.11219281519474E-7,0.25,-3.00503082918348E-7,1.26862595906823E-6,-3.00001024202565E-7,160.9699402,160.9699402,99.7461624145508,99.7461624145508,56.8705094307176,20.6340251208458,24.807261,0,0,0,40,4374,157.5641,99.7461624145508,,,,,,,,,,,,,0,,,,0.0049,,,,,,160.9699402,,,,
,28575035.76,157.4991302,99.7461624145508,7.81454629300454E-7,3.56487971395142E-7,1,0.999253354069792,40.0298881530762,1.98420652999646,14.7399995476007,9.77141110075932E-6,-3.91088162456933E-6,0.25,-4.82495887232436E-7,7.85869104083446E-7,-4.83556790306322E-7,157.4991302,157.4991302,99.7461624145508,99.7461624145508,56.7798405224868,20.6365982876434,24.427608,0,0,0,40,4374,154.1085,99.7461624145508,,,,,,,,,,,,,0,,,,-0.00245,,,,,,157.4991302,,,,
,28575174.83,153.9904175,99.7461624145508,1.06281131404261E-6,3.01223994630215E-7,1,0.999253354069792,40.0298881530762,2.00880619516617,14.809999614954,1.30329565587659E-5,-2.99796942024821E-6,0.25,-4.47567574669395E-7,1.0686122614756E-6,-4.48015617828791E-7,153.9904175,153.9904175,99.7461624145508,99.7461624145508,57.0565370182945,20.6297376316639,24.047956,0,0,0,40,4374,150.6426,99.7461624145508,,,,,,,,,,,,,0,,,,-0.0049,,,,,,153.9904175,,,,
,28575314.31,150.4994202,99.7461624145508,4.09498227968394E-7,3.57901482259484E-7,1,0.999253354069792,40.0298881530762,2.00835621222514,14.809999614954,5.71363853683792E-6,-5.12931296230116E-6,0.25,-5.20395861154153E-7,4.12352625858363E-7,-5.22256293676488E-7,150.4994202,150.4994202,99.7461624145508,99.7461624145508,56.9775925378522,20.6391113586863,24.427608,0,0,0,40,4374,147.16265,99.7461624145508,,,,,,,,,,,,,0,,,,0,,,,,,150.4994202,,,,
,28575453.505,146.9958954,99.7461624145508,1.08286391261731E-6,3.18823415281785E-7,1,0.999253354069792,40.0298881530762,2.00823314622342,14.809999614954,1.36422554238949E-5,-5.14299663592624E-6,0.25,-6.38999368305554E-7,1.08932504236608E-6,-6.40315826647363E-7,146.9958954,146.9958954,99.7461624145508,99.7461624145508,56.9009929429675,20.647995364194,24.427608,0,0,0,40,4374,143.70225,99.7461624145508,,,,,,,,,,,,,0,,,,-0.0049,,,,,,146.9958954,,,,
,28575593.715,143.4667664,99.7461624145508,9.85697077412059E-7,3.51146553136964E-7,1,0.999253354069792,40.0298881530762,1.98451083360294,14.8700000718236,1.15136133397927E-5,-2.37394083907332E-7,0.25,-1.9291893137904E-7,9.91006688570775E-7,-1.92141533962688E-7,143.4667664,143.4667664,99.7461624145508,99.7461624145508,57.0416860764291,20.6372026633744,24.047956,0,0,0,40,4374,140.2012,99.7461624145508,,,,,,,,,,,,,0,,,,-0.00245,,,,,,143.4667664,,,,
,28575734.9,139.9416199,99.7461624145508,9.84108449812179E-7,3.26564752358976E-7,1,0.999253354069792,40.0298881530762,1.98421036997094,14.8700000718236,1.13886202052459E-5,3.69548258143487E-7,0.25,-1.38975639991589E-7,9.89400673980457E-7,-1.37870518511925E-7,139.9416199,139.9416199,99.7461624145508,99.7461624145508,56.8142321773329,20.6382209634679,23.668306,0,0,0,40,4374,136.68555,99.7461624145508,,,,,,,,,,,,,0,,,,0,,,,,,139.9416199,,,,
,28575870.75,136.4866486,99.7461624145508,6.04669087861306E-7,3.7166115575801E-7,1,0.999253354069792,40.0298881530762,1.98409224831837,14.8700000718236,6.92684181630793E-6,6.33206224673329E-7,0.25,-4.94766719609257E-8,6.07902179761165E-7,-4.85730906351558E-8,136.4866486,136.4866486,99.7461624145508,99.7461624145508,57.007294421583,20.6332853526764,23.668306,0,0,0,40,4374,133.3075,99.7461624145508,,,,,,,,,,,,,0,,,,-0.0049,,,,,,136.4866486,,,,
,28576012.585,132.9400024,99.7461624145508,1.10325745305894E-6,3.33004731371313E-7,1,0.999253354069792,40.0298881530762,1.98407036072372,14.9299995973706,1.19599484883964E-5,5.04567756685667E-6,0.25,2.5406583715621E-7,1.10855180977659E-6,2.57611054407701E-7,132.9400024,132.9400024,99.7461624145508,99.7461624145508,57.1917587521214,20.6333651763207,23.668306,0,0,0,40,4374,129.77835,99.7461624145508,,,,,,,,,,,,,0,,,,0.00245,,,,,,132.9400024,,,,
,28576150.11,129.4547424,99.7461624145508,8.49124869117462E-7,2.67900311531646E-7,1,0.999253354069792,40.0298881530762,1.98405865032844,14.9299995973706,1.01891376518706E-5,-1.74709469741134E-6,0.25,-3.03031875853564E-7,8.54279089321554E-7,-3.02871158306847E-7,129.4547424,129.4547424,99.7461624145508,99.7461624145508,57.464547105333,20.6360619632649,23.668306,0,0,0,40,4374,126.36875,99.7461624145508,,,,,,,,,,,,,0,,,,0,,,,,,129.4547424,,,,
,28576288.685,125.981781,99.7461624145508,1.2439727604003E-6,2.92635591647077E-7,1,0.999253354069792,40.0298881530762,1.9840142896006,14.9299995973706,1.50563565908005E-5,-3.29273798874953E-6,0.25,-5.08975027529915E-7,1.25178138544833E-6,-5.08995992050011E-7,125.981781,125.981781,99.7461624145508,99.7461624145508,57.2535074051407,20.6379349478085,24.047956,0,0,0,40,4374,122.9177,99.7461624145508,,,,,,,,,,,,,0,,,,0.0049,,,,,,125.981781,,,,
,28576408.535,122.97342685,99.7461624145508,9.5958872083252E-7,2.76863779554753E-7,1,0.999253354069792,40.0298881530762,2.00871225988527,14.9999996647239,1.13937684074175E-5,-5.15076878249223E-7,0.25,-2.12903627842183E-7,9.65282731958078E-7,-2.11875772419429E-7,122.9409485,123.0059052,99.7461624145508,99.7461624145508,57.1995750373137,20.6244245528709,23.288654,0,0,0,40,4374,119.9391,99.7461624145508,,,,,,,,,,,,,0,,,,-0.0049,,,,,,122.97342685,,,,
,28576548.605,119.43899155,99.7461624145508,7.00344953676807E-7,3.00018481682085E-7,1,0.999253354069792,40.0298881530762,2.00888017042439,14.9999996647239,7.39848726914934E-6,4.8712304173703E-6,0.25,3.03554116784041E-7,7.03455060837713E-7,3.06890385999724E-7,119.4090805,119.4689026,99.7461624145508,99.7461624145508,56.7134020983521,20.6240988936928,23.288654,0,0,0,40,4374,116.4645,99.7461624145508,,,,,,,,,,,,,0,,,,-0.0049,,,,,,119.43899155,,,,
,28576686.42,115.9773254,99.7461624145508,8.56977015763821E-7,3.50821778575577E-7,1,0.999253354069792,40.0298881530762,2.00906669352406,14.9999996647239,1.09622357832311E-5,-4.93458459619534E-6,0.25,-5.81730181056084E-7,8.63165912953565E-7,-5.82784581753111E-7,115.9773254,115.9773254,99.7461624145508,99.7461624145508,57.126101956506,20.6203188632787,22.909004,0,0,0,40,4374,113.0368,99.7461624145508,,,,,,,,,,,,,0,,,,0,,,,,,115.9773254,,,,
,28576805.235,112.9465485,99.7461624145508,8.53483459770231E-7,3.13654452282971E-7,1,0.999253354069792,40.0298881530762,2.0092257105361,15.0499995797873,1.04792200035518E-5,-2.40320739595109E-6,0.25,-3.59782315449955E-7,8.59160383696435E-7,-3.59532266803746E-7,112.9465485,112.9465485,99.7461624145508,99.7461624145508,57.1511140691214,20.6168964581035,22.909004,0,0,0,40,4374,110.0921,99.7461624145508,,,,,,,,,,,,,0,,,,0,,,,,,112.9465485,,,,
,28576943.74,109.4639206,99.7461624145508,1.10944865185421E-6,2.86217341757393E-7,1,0.999253354069792,40.0298881530762,2.00920927039509,15.0499995797873,1.26799213713605E-5,2.25206158997752E-6,0.25,2.35175059100671E-9,1.11561519683394E-6,5.44653552619836E-9,109.4639206,109.4639206,99.7461624145508,99.7461624145508,57.3996719382368,20.621654742433,23.288654,0,0,0,40,4374,106.65505,99.7461624145508,,,,,,,,,,,,,0,,,,0,,,,,,109.4639206,,,,
,28577081.98,105.9905472,99.7461624145508,1.17975158566305E-6,3.37156650314015E-7,1,0.999253354069792,40.0298881530762,2.00895928066911,15.0499995797873,1.36619719451982E-5,1.36917553768091E-6,0.25,-8.73827476622051E-8,1.1865830791431E-6,-8.43999425332112E-8,105.9905472,105.9905472,99.7461624145508,99.7461624145508,57.2558522906984,20.6227484441985,22.529354,0,0,0,40,4374,103.2199,99.7461624145508,,,,,,,,,,,,,0,,,,0,,,,,,105.9905472,,,,
,28577200.605,102.9568024,99.7461624145508,6.73811515252301E-7,2.9768960849466E-7,1,0.999253354069792,40.0298881530762,2.00921368947042,15.1199996471405,8.47419864505078E-6,-3.0312820718091E-6,0.25,-3.83560267706156E-7,6.7875157374575E-7,-3.83612211081889E-7,102.9568024,102.9568024,99.7461624145508,99.7461624145508,57.1425161554099,20.6145756260648,22.909004,0,0,0,40,4374,100.2965,99.7461624145508,,,,,,,,,,,,,0,,,,0,,,,,,102.9568024,,,,
,28577341.14,99.4384613,99.7461624145508,1.02459778281961E-6,2.61410642581297E-7,1,0.999253354069792,40.0298881530762,2.00921279961968,15.1199996471405,1.12320485665592E-5,4.79616915168755E-6,0.25,2.39253659139774E-7,1.02949438043427E-6,2.43957437655647E-7,99.4384613,99.4384613,99.7461624145508,99.7461624145508,57.4840878183138,20.6209376580961,22.909004,0,0,0,40,4374,96.79105,99.7461624145508,,,,,,,,,,,,,0,,,,-0.00245,,,,,,99.4384613,,,,
,28577475.27,95.9994965,99.7461624145508,1.03832176218716E-6,3.19181357671256E-7,1,0.999253354069792,40.0298881530762,2.00924890575362,15.1199996471405,1.22431723602337E-5,-2.987232551339E-8,0.25,-1.85533292350364E-7,1.0446939459124E-6,-1.8291587270335E-7,95.9994965,95.9994965,99.7461624145508,99.7461624145508,57.2269320354868,20.6205175381078,22.909004,0,0,0,40,4374,93.48965,99.7461624145508,,,,,,,,,,,,,0,,,,0,,,,,,95.9994965,,,,
,28577618.3,92.4348602,99.7461624145508,9.6325413245789E-7,3.18515027579694E-7,1,0.999253354069792,40.0298881530762,2.00905485007097,15.1800001040101,1.16248128523382E-5,-1.54731900411625E-6,0.25,-3.05326359608839E-7,9.69642261160747E-7,-3.0337046295203E-7,92.4348602,92.4348602,99.7461624145508,99.7461624145508,56.7180918694675,20.6118319216721,21.770052,0,0,0,40,4374,89.95615,99.7461624145508,,,,,,,,,,,,,0,,,,0,,,,,,92.4348602,,,,
,28577757.405,88.89326095,99.7461624145508,9.63250168272228E-7,2.71155355086469E-7,1,0.999253354069792,40.0298881530762,2.00920511977877,15.1800001040101,1.12625617017804E-5,5.06282067356454E-7,0.25,-1.25910342669361E-7,9.68903204280655E-7,-1.22703485379452E-7,88.8525925,88.9339294,99.7461624145508,99.7461624145508,57.312129544083,20.6135107628709,22.149702,0,0,0,40,4374,86.49585,99.7461624145508,,,,,,,,,,,,,0,,,,0.00245,,,,,,88.89326095,,,,
,28577893.2,85.4451752,99.7461624145508,1.02933134117965E-6,3.05353811285692E-7,1,0.999253354069792,40.0298881530762,1.99616997683231,15.1800001040101,1.19330757506874E-5,6.8736745736894E-7,0.25,-1.21663341300277E-7,1.03521885379522E-6,-1.17852621876386E-7,85.4045792,85.4857712,99.7461624145508,99.7461624145508,57.0252718775253,20.621119774386,22.149702,0,0,0,40,4374,83.1618,99.7461624145508,,,,,,,,,,,,,0,,,,-0.00245,,,,,,85.4451752,,,,
,28578028.805,81.9984398,99.7461624145508,1.09514246573776E-6,2.45333108466911E-7,1,0.999253354069792,40.0298881530762,1.98482186039903,15.2700003236532,1.28587437333547E-5,-5.88992982648835E-7,0.25,-2.46369788040605E-7,1.10179271862194E-6,-2.42528421013627E-7,81.9713135,82.0255661,99.7461624145508,99.7461624145508,57.0831123879483,20.6161189708264,21.770052,0,0,0,40,4374,79.8116,99.7461624145508,,,,,,,,,,,,,0,,,,0,,,,,,81.9984398,,,,
,28578167.525,78.4867401,99.7461624145508,1.29999304928464E-6,3.15569397405453E-7,1,0.999253354069792,40.0298881530762,1.98516566798915,15.2700003236532,1.49286128205923E-5,1.18866066283698E-6,0.25,-1.25724870688352E-7,1.3068407857311E-6,-1.19829192899269E-7,78.4867401,78.4867401,99.7461624145508,99.7461624145508,57.3090030300061,20.6145493369444,21.3904,0,0,0,40,4374,76.3873,99.7461624145508,,,,,,,,,,,,,0,,,,0,,,,,,78.4867401,,,,
,28578305.395,74.9758148,99.7461624145508,8.78278188152074E-7,2.91100956822735E-7,1,0.999253354069792,40.0298881530762,1.98519643712382,15.2700003236532,1.00311351663596E-5,1.09510285075624E-6,0.25,-5.93833652606738E-8,8.82522804808645E-7,-5.49228052632453E-8,74.9758148,74.9758148,99.7461624145508,99.7461624145508,57.5856995258138,20.6105871943498,21.01075,0,0,0,40,4374,73.0017,99.7461624145508,,,,,,,,,,,,,0,,,,0,,,,,,74.9758148,,,,
,28578442.595,71.4988708,99.7461624145508,9.09103787436096E-7,3.27498770135209E-7,1,0.999253354069792,40.0298881530762,2.00940471845318,15.3299998492002,1.07100511942894E-5,-2.98140427639017E-8,0.25,-1.64902252437285E-7,9.13752893659259E-7,-1.60313174299384E-7,71.4988708,71.4988708,99.7461624145508,99.7461624145508,57.1534589546791,20.6101135027064,21.01075,0,0,0,40,4374,69.6211,99.7461624145508,,,,,,,,,,,,,0,,,,-0.0049,,,,,,71.4988708,,,,
,28578580.79,67.9406586,99.7461624145508,7.19603093089441E-7,3.36705733042561E-7,1,0.999253354069792,40.0298881530762,2.00907881743079,15.3299998492002,8.42247581443607E-6,2.56425633012614E-7,0.25,-1.0628321167522E-7,7.22817631802438E-7,-1.0219808044634E-7,67.9406586,67.9406586,99.7461624145508,99.7461624145508,57.2644502044099,20.6210060476672,20.631098,0,0,0,40,4374,66.21975,99.7461624145508,,,,,,,,,,,,,0,,,,0,,,,,,67.9406586,,,,
,28578715.765,64.4965897,99.7461624145508,8.28612580324831E-7,2.75474788869111E-7,1,0.999253354069792,40.0298881530762,2.00897696188964,15.3299998492002,9.63783006485621E-6,5.999850973365E-7,0.25,-9.59620393685115E-8,8.31676206840333E-7,-9.07782573515616E-8,64.4965897,64.4965897,99.7461624145508,99.7461624145508,56.9924434797176,20.6211056380259,20.631098,0,0,0,40,4374,62.91135,99.7461624145508,,,,,,,,,,,,,0,,,,0,,,,,,64.4965897,,,,
,28578855.685,60.9634438,99.7461624145508,8.68395471220948E-7,3.01286709627325E-7,1,0.999253354069792,40.0298881530762,1.98493401748517,15.3900003060699,1.02578959123382E-5,-9.36590057779806E-7,0.25,-2.39301839986703E-7,8.71937214865119E-7,-2.33771245119847E-7,60.9634438,60.9634438,99.7461624145508,99.7461624145508,56.7462304961599,20.6137889437234,20.631098,0,0,0,40,4374,59.4774,99.7461624145508,,,,,,,,,,,,,0,,,,-0.00245,,,,,,60.9634438,,,,
,28578992.345,57.4863853,99.7461624145508,1.06779411048124E-6,2.97900383703616E-7,1,0.999253354069792,40.0298881530762,1.9850271885379,15.3900003060699,1.22538744879604E-5,7.92843980901552E-7,0.25,-1.21737049781566E-7,1.07004241907699E-6,-1.14156431917305E-7,57.4863853,57.4863853,99.7461624145508,99.7461624145508,56.8439340610637,20.6166282407257,20.631098,0,0,0,40,4374,56.13015,99.7461624145508,,,,,,,,,,,,,0,,,,0,,,,,,57.4863853,,,,
,28579130.205,53.9555511,99.7461624145508,8.72381920259586E-7,2.89801158007797E-7,1,0.999253354069792,40.0298881530762,1.98480944040919,15.3900003060699,1.06782973160668E-5,-3.1136254710918E-6,0.25,-4.34419547594321E-7,8.7584974923323E-7,-4.28076583723224E-7,53.9555511,53.9555511,99.7461624145508,99.7461624145508,57.3394865422561,20.619055510432,19.871798,0,0,0,40,4374,52.7385,99.7461624145508,,,,,,,,,,,,,0,,,,0,,,,,,53.9555511,,,,
,28579244.625,50.9972553,99.7461624145508,9.78803601371872E-7,2.65895437484171E-7,1,0.999253354069792,40.0298881530762,1.98471012626817,15.4499998316169,1.19515347933703E-5,-3.38661748068868E-6,0.25,-4.78211197011373E-7,9.81794128586959E-7,-4.70654376801269E-7,50.9667015,51.0278091,99.7461624145508,99.7461624145508,56.8275198621599,20.6208365613383,19.112494,0,0,0,40,4374,49.9579,99.7461624145508,,,,,,,,,,,,,0,,,,0,,,,,,50.9972553,,,,
,28579381.93,47.4536438,99.7461624145508,9.23861926031829E-7,3.38480396408343E-7,1,0.999253354069792,40.0298881530762,1.98426766324863,15.4499998316169,1.0383306037734E-5,1.70709782935997E-6,0.25,-1.41163749291426E-8,9.22465631515756E-7,-7.32755250794416E-9,47.4536438,47.4536438,99.7461624145508,99.7461624145508,57.4504777919868,20.6295740793771,18.353191,0,0,0,40,4370,46.607,99.7461624145508,,,,,,,,,,,,,0,,,,0,,,,,,47.4536438,,,,
,28579518.62,43.9595871,99.7461624145508,7.66344304128615E-7,2.45854279012655E-7,1,0.999253354069792,40.0298881530762,1.98409934026218,15.4499998316169,8.89087430939626E-6,-1.81913341475113E-7,0.25,-1.54096088098477E-7,7.6543324329853E-7,-1.48280851477011E-7,43.9595871,43.9595871,99.7461624145508,99.7461624145508,57.0502839901407,20.6364471161186,18.353191,0,0,0,40,4370,43.26675,99.7461624145508,,,,,,,,,,,,,0,,,,-0.00245,,,,,,43.9595871,,,,
touchdown = 10.8899995684624 mm,28579650.095,40.6321144,99.7461624145508,8.67172272864386E-7,2.76170042600817E-7,1,0.999253354069792,40.0298881530762,2.00843993217516,15.4900001361966,1.07793054476472E-5,-3.6075654269904E-6,0.25,-4.74395634511782E-7,8.67358097940781E-7,-4.66938031001494E-7,40.6321144,40.6321144,99.7461624145508,99.7461624145508,57.0932735586983,20.6299266003829,17.593889,0,0,0,40,4370,40.0413,99.7461624145508,,,,,,,,,,,,,0,,,,0,,,,,,40.6321144,,,,
,28579772.675,37.4998093,99.7461624145508,8.06377111404056E-7,2.86081664718158E-7,1,0.999253354069792,40.0298881530762,2.00807625869834,15.4900001361966,9.59780720101198E-6,-1.03317457577254E-6,0.25,-2.35794011328419E-7,8.04540485783751E-7,-2.29718873043755E-7,37.4998093,37.4998093,99.7461624145508,99.7461624145508,57.2722664896022,20.6360647395463,16.834587,0,0,0,40,4370,37.0108,99.7461624145508,,,,,,,,,,,,,0,,,,0,,,,,,37.4998093,,,,
,28579912.74,33.9624405,99.7461624145508,9.90297816375922E-7,2.1674351600191E-7,1,0.999253354069792,40.0298881530762,2.00814933687142,15.4900001361966,1.18454449506518E-5,-1.64229832994067E-6,0.25,-3.22219472438068E-7,9.87503274645139E-7,-3.14865065267337E-7,33.9624405,33.9624405,99.7461624145508,99.7461624145508,57.6701154058907,20.6382234287088,16.454937,0,0,0,40,4370,33.5429,99.7461624145508,,,,,,,,,,,,,0,,,,0.0049,,,,,,33.9624405,,,,
touchdown = 10.9299998730421 mm,28580061.305,30.20379065,99.7461624145508,8.82277623730391E-7,2.41500257990467E-7,1,0.999253354069792,40.0298881530762,1.98438887080013,15.54000005126,1.0506026922954E-5,-1.88449197482089E-6,0.25,-3.25937226226271E-7,8.79469459540757E-7,-3.19416283951674E-7,30.1791153,30.228466,99.7461624145508,99.7461624145508,57.2120810936214,20.6324125106115,16.454937,0,0,0,40,4370,29.8791,99.7461624145508,,,,,,,,,,,,,0,,,,0,,,,,,30.20379065,,,,
,28580188.705,26.9925404,99.7461624145508,9.44810190153989E-7,2.6316186482485E-7,1,0.999253354069792,40.0298881530762,1.98454895510923,15.54000005126,1.1517321801138E-5,-3.5353504142029E-6,0.25,-4.84616162797433E-7,9.42146527961216E-7,-4.77065428471649E-7,26.9925404,26.9925404,99.7461624145508,99.7461624145508,57.3660619119099,20.6315310248893,15.315984,0,0,0,40,4370,26.7184,99.7461624145508,,,,,,,,,,,,,0,,,,0,,,,,,26.9925404,,,,
,28580329.025,23.4633999,99.7461624145508,1.06711889287497E-6,3.02004000265459E-7,1,0.999253354069792,40.0298881530762,1.9846671217627,15.54000005126,1.23031589964688E-5,-4.24460521072356E-8,0.25,-1.93447877969221E-7,1.06203384888001E-6,-1.87057751959222E-7,23.4633999,23.4633999,99.7461624145508,99.7461624145508,57.6998172896215,20.6322213517512,14.556682,0,0,0,40,4370,23.2329,99.7461624145508,,,,,,,,,,,,,0,,,,-0.0049,,,,,,23.4633999,,,,
touchdown = 10.9700001776218 mm,28580474.345,19.8104134,99.7461624145508,7.94646240818952E-7,2.93350625018864E-7,1,0.999253354069792,40.0298881530762,2.00915849788726,15.5800003558397,9.72984607538425E-6,-2.62930588281722E-6,0.25,-3.73802987079028E-7,7.91883994955641E-7,-3.67805166142262E-7,19.8104134,19.8104134,99.7461624145508,99.7461624145508,57.1862873524868,20.6233764565989,13.797379,0,0,0,40,4370,19.62385,99.7461624145508,,,,,,,,,,,,,0,,,,-0.00245,,,,,,19.8104134,,,,
,28580608.245,16.4512825,99.7461624145508,1.01905751138579E-6,2.19475301995398E-7,1,0.999253354069792,40.0298881530762,2.00902989410053,15.5800003558397,1.19207816608262E-5,-2.41147975443746E-7,0.25,-2.02301687270952E-7,1.01416609495517E-6,-1.96222294966197E-7,16.4512825,16.4512825,99.7461624145508,99.7461624145508,57.3777863396984,20.6251072995766,13.417728,0,0,0,40,4370,16.29995,99.7461624145508,,,,,,,,,,,,,0,,,,-0.0049,,,,,,16.4512825,,,,
,28580748,12.9451828,99.7461624145508,7.231155722443E-7,2.90291828890149E-7,1,0.999253354069792,40.0298881530762,2.00904189954984,15.5899999663234,8.55542450561367E-6,-7.13971453393012E-7,0.25,-1.91593078124357E-7,7.19883282347211E-7,-1.87004396710714E-7,12.9451828,12.9451828,99.7461624145508,99.7461624145508,57.3465211989291,20.6247622985924,12.658426,0,0,0,40,4370,12.80595,99.7461624145508,,,,,,,,,,,,,0,,,,0.0049,,,,,,12.9451828,,,,
,28580999.98,10.0031548,99.7461624145508,1.39770456372562E-6,2.32347020881095E-7,1,0.999253354069792,40.0298881530762,2.00893549948148,15.599999576807,1.60672590238254E-5,1.25954582139831E-6,0.25,-1.36726634266951E-7,1.3903381905197E-6,-1.29200635353127E-7,10.0031548,10.0031548,99.7461624145508,99.7461624145508,57.2636685758907,20.6309740292693,12.278775,0,0,0,40,4369,9.99325,99.7461624145508,,,,,,,,,,,,,0,,,,-0.00245,,,,,,10.0031548,,,,