File: data/monolayers/nanoparticles/Ol_CoFe_C/vsm/data_disorderedWafer/DD227_HYST_300K.DAT
[Header]
; VSM Data File (default extension .dat)
; Copyright (c) 2003-2013, Quantum Design, Inc. All rights reserved.
TITLE,
FILEOPENTIME,28536589.97,11/27/2018,2:50 pm
BYAPP,VSM,2.0,2.0
INFO,PPMS VSM Option Release 1.4.10 Build 1,APPNAME
INFO,Quantum Design Linear Motor Servo Controller,MOTOR_MODULE_NAME
INFO,3101-100 M1,MOTOR_HW_VERSION
INFO,MMC1014,MOTOR_SERIAL_NUMBER
INFO,SRV No X-over 01.03.11,MOTOR_SOFTWARE_VERSION
INFO,Quantum Design VSM Detection Module,VSM_MODULE_NAME
INFO,3101-150 F0,VSM_HW_VERSION
INFO,VSM707,VSM_SERIAL_NUMBER
INFO,VSM No X-over 01.02.05 May 20 2008 13:51:47,VSM_SOFTWARE_VERSION
INFO,704,PREAMP_SERIAL_NUMBER
INFO,822,COIL_SERIAL_NUMBER
INFO,0,MOMENT_UNITS
INFO,CoFe2O4 FeO,SAMPLE_MATERIAL
INFO,disordered monolayer,SAMPLE_COMMENT
INFO,25.46,SAMPLE_MASS
INFO,,SAMPLE_VOLUME
INFO,,SAMPLE_MOLECULAR_WEIGHT
INFO,,SAMPLE_SIZE
INFO,,SAMPLE_SHAPE
DATATYPE,COMMENT,1
DATATYPE,TIME,2
STARTUPAXIS,X,2
STARTUPAXIS,Y1,5
[Data]
Comment,Time Stamp (sec),Temperature (K),Magnetic Field (Oe),Moment (emu),M. Std. Err. (emu),Transport Action,Averaging Time (sec),Frequency (Hz),Peak Amplitude (mm),Center Position (mm),Coil Signal' (mV),Coil Signal" (mV),Range (mV),M. Quad. Signal (emu),M. Raw' (emu),M. Raw" (emu),Min. Temperature (K),Max. Temperature (K),Min. Field (Oe),Max. Field (Oe),Mass (grams),Motor Lag (deg),Pressure (Torr),VSM Status (code),Motor Status (code),Measure Status (code),Measure Count,PPMS Status (code),System Temp. (K),System Field (Oe),Sample Position (deg),Bridge 1 Resistance (ohms),Bridge 1 Excitation (에),Bridge 2 Resistance (ohms),Bridge 2 Excitation (에),Bridge 3 Resistance (ohms),Bridge 3 Excitation (에),Bridge 4 Resistance (ohms),Bridge 4 Excitation (에),Signal 1 Vin (V),Signal 2 Vin (V),Digital Inputs (code),Drive 1 Iout (mA),Drive 1 Ipower (W),Drive 2 Iout (mA),Drive 2 Ipower (W),Pressure (),Map 20 (),Map 21 (),Map 22 (),Map 23 (),Map 24 (),Map 25 (),Map 26 (),Map 27 (),Map 28 (),Map 29 ()
,28536606.41,300.2179871,-0.0913426354527473,,,2,,,,14.4700000312924,,,,,,,300.2179871,300.2179871,-0.0913426354527473,-0.0913426354527473,,,24.047956,,,,-99999999,4369,300.6189,-0.0913426354527473,,,,,,,,,,,,,,,,,,,,,,,300.2179871,,,,
,28536761.095,300.17852785,4443.66235351562,-6.14372864282286E-6,6.45989121572296E-7,1,0.999253354069792,40.0298881530762,1.99723933255261,14.4600002095103,-6.82113265791301E-5,-1.93598129079278E-5,0.25,-6.47424754488979E-7,-6.14307723990842E-6,-6.51472825166822E-7,300.177887,300.1791687,4436.11865234375,4451.2060546875,56.5007991411214,20.5946301977269,23.668306,0,0,0,40,4449,300.3683,4443.66235351562,,,,,,,,,,,,,0,,,,0,,,,,,300.17852785,,,,
,28536855.34,300.1319885,9152.32177734375,-1.86722890261119E-5,7.30805297141639E-7,1,0.999253354069792,40.0298881530762,1.99705245080568,14.4600002095103,-0.000210293847683553,-4.15122604162344E-5,0.25,-4.35882188483422E-7,-1.86713561794807E-5,-4.48236380599726E-7,300.1319885,300.1319885,9147.4453125,9157.1982421875,56.5555131374675,20.6000502222852,24.047956,0,0,0,40,4449,300.2817,9152.32177734375,,,,,,,,,,,,,0,,,,0,,,,,,300.1319885,,,,
,28536949.97,300.0783386,13882.3740234375,-3.15893171616163E-5,9.43483772227096E-7,1,0.999253354069792,40.0298881530762,1.99711000619223,14.4600002095103,-0.000357907889834074,-5.79523488331396E-5,0.25,3.48411758898654E-7,-3.15885202569549E-5,3.274882784785E-7,300.0783386,300.0783386,13874.8193359375,13889.9287109375,56.7227816405829,20.6038596685006,24.047956,0,0,0,40,4449,300.2363,13882.3740234375,,,,,,,,,,,,,0,,,,0.0049,,,,,,300.0783386,,,,
,28537044.835,300.0373535,18622.4580078125,-4.59643175471002E-5,1.00169217700779E-6,1,0.999253354069792,40.0298881530762,1.99713702345371,14.4600002095103,-0.00051844896288484,-9.78058657974606E-5,0.25,-6.85130862187113E-7,-4.59624391770589E-5,-7.15512611248444E-7,300.0373535,300.0373535,18612.544921875,18632.37109375,56.9377294833714,20.6063779820102,23.668306,0,0,0,40,4449,300.21965,18622.4580078125,,,,,,,,,,,,,0,,,,0.00245,,,,,,300.0373535,,,,
,28537140.15,300.0111084,23384.9814453125,-6.02799894203812E-5,1.26090916339316E-6,1,0.999253354069792,40.0298881530762,1.9970628328376,14.4600002095103,-0.000679813010549878,-0.000128750534362581,0.25,-9.4164492837004E-7,-6.02775584345187E-5,-9.81449855182907E-7,300.0111084,300.0111084,23380.0078125,23389.955078125,56.9041194570445,20.6057313746037,23.288654,0,0,0,40,4449,300.2254,23384.9814453125,,,,,,,,,,,,,0,,,,0.00245,,,,,,300.0111084,,,,
,28537234.52,299.99568175,28102.7353515625,-7.49317585021686E-5,1.26799535624442E-6,1,0.999253354069792,40.0298881530762,1.99701761156065,14.4600002095103,-0.000844792860899247,-0.000161421332881532,0.25,-1.29259461244769E-6,-7.49287029279241E-5,-1.34202097688708E-6,299.9956665,299.995697,28097.37109375,28108.099609375,56.8642564025637,20.6065955544331,24.427608,0,0,0,40,4449,300.2363,28102.7353515625,,,,,,,,,,,,,0,,,,0.00245,,,,,,299.99568175,,,,
,28537328.515,299.9888916,32800.103515625,-8.84239245298551E-5,1.14664967347318E-6,1,0.999253354069792,40.0298881530762,1.99720718155978,14.4600002095103,-0.0010001255921123,-0.000172442844290688,0.25,7.16667578123166E-8,-8.8421400209425E-5,1.33573479087732E-8,299.9888916,299.9888916,32794.87890625,32805.328125,56.9088092281599,20.6063281820339,24.047956,0,0,0,40,4449,300.2562,32800.103515625,,,,,,,,,,,,,0,,,,0,,,,,,299.9888916,,,,
,28537424.2,299.9830627,37582.51171875,-0.00010174547232265,1.4142593716568E-6,1,0.999253354069792,40.0298881530762,1.99706090171869,14.4600002095103,-0.00115050724208729,-0.000199635630479681,0.25,-2.61268826098926E-8,-0.000101742523909757,-9.31452825732085E-8,299.9830627,299.9830627,37577.5625,37587.4609375,57.0221453634483,20.6071388598544,23.668306,0,0,0,40,4449,300.2619,37582.51171875,,,,,,,,,,,,,0,,,,-0.0049,,,,,,299.9830627,,,,
,28537519.145,299.9886017,42328.015625,-0.000117466076911917,1.99921955623276E-6,1,0.999253354069792,40.0298881530762,1.99724045856318,14.4600002095103,-0.00133005967700105,-0.000220834442915901,0.25,8.24494665375454E-7,-0.000117463219691284,7.47183496467433E-7,299.9882202,299.9889832,42320.35546875,42335.67578125,56.9893169656406,20.6061172082659,24.047956,0,0,0,40,4449,300.27395,42328.015625,,,,,,,,,,,,,0,,,,0,,,,,,299.9886017,,,,
,28537614.095,299.9920349,47075.701171875,-0.000131660252798051,2.35106764400844E-6,1,0.999253354069792,40.0298881530762,1.99699095901808,14.4600002095103,-0.00148743401835756,-0.000265771763728704,0.25,-6.92730738771562E-7,-0.000131655979427924,-7.7924024108661E-7,299.9920349,299.9920349,47063.76171875,47087.640625,57.126101956506,20.6057960113763,24.427608,0,0,0,40,4449,300.27855,47075.701171875,,,,,,,,,,,,,0,,,,-0.0049,,,,,,299.9920349,,,,
,28537707.355,299.9960022,51738.392578125,-0.00014515202169299,2.39203332487537E-6,1,0.999253354069792,40.0298881530762,1.99692876610878,14.4600002095103,-0.00164355222298441,-0.000271390202766844,0.25,1.14708248484122E-6,-0.000145148554204257,1.05175901798818E-6,299.9960022,299.9960022,51735.90625,51740.87890625,56.9002113144483,20.6057927569715,24.047956,0,0,0,40,4449,300.2826,51738.392578125,,,,,,,,,,,,,0,,,,0,,,,,,299.9960022,,,,
,28537802.305,300.0005798,56480.935546875,-0.00015966456034615,2.64549129734065E-6,1,0.999253354069792,40.0298881530762,1.99716971130473,14.4600002095103,-0.00180296364685554,-0.000328120346110756,0.25,-1.35239799259542E-6,-0.000159659015165089,-1.45705901646146E-6,300.0005798,300.0005798,56478.06640625,56483.8046875,56.9721211382176,20.6060637443049,24.047956,0,0,0,40,4449,300.2765,56480.935546875,,,,,,,,,,,,,0,,,,0,,,,,,300.0005798,,,,
,28537896.72,299.998291,61200.984375,-0.000174647612211884,2.55426041272275E-6,1,0.999253354069792,40.0298881530762,1.99711707874514,14.4600002095103,-0.00196887242598944,-0.000377566067564021,0.25,-3.12984508716497E-6,-0.000174640492889548,-3.24414708069168E-6,299.998291,299.998291,61190.87109375,61211.09765625,57.0002597649099,20.6079560028918,24.047956,0,0,0,40,4449,300.2787,61200.984375,,,,,,,,,,,,,0,,,,-0.0049,,,,,,299.998291,,,,
,28537992.405,299.9997559,65983.9375,-0.000189399850374078,2.71704302714564E-6,1,0.999253354069792,40.0298881530762,1.99691342033755,14.4600002095103,-0.0021353981220222,-0.000406962364976791,0.25,-3.17713080908391E-6,-0.000189392277198515,-3.30094951975554E-6,299.9997559,299.9997559,65979.1171875,65988.7578125,57.004167907506,20.6063127605439,24.427608,0,0,0,40,4449,300.274,65983.9375,,,,,,,,,,,,,0,,,,-0.0049,,,,,,299.9997559,,,,
,28538088.445,300.0014648,70781.6171875,-0.000209370971749792,2.5692179283032E-6,1,0.999253354069792,40.0298881530762,1.99690516145526,14.4600002095103,-0.00236414837215173,-0.000429127190484702,0.25,-1.67763963226107E-6,-0.000209363803266224,-1.81440327474508E-6,300.0014648,300.0014648,70776.453125,70786.78125,57.0338697912368,20.6063433932348,24.047956,0,0,0,40,4449,300.273,70781.6171875,,,,,,,,,,,,,0,,,,0.0049,,,,,,300.0014648,,,,
,28538182.465,300.003479,75484.67578125,-0.000223005340759575,3.15803659064747E-6,1,0.999253354069792,40.0298881530762,1.99690616908474,14.4600002095103,-0.00251990447255545,-0.000446682430815968,0.25,-8.6818985556501E-7,-0.000222998305534938,-1.01371468301898E-6,300.003479,300.003479,75479.6484375,75489.703125,56.8259566051214,20.6077905464061,24.427608,0,0,0,40,4449,300.26875,75484.67578125,,,,,,,,,,,,,0,,,,-0.0049,,,,,,300.003479,,,,
,28538276.18,300.0070801,80167.91796875,-0.000239000697482624,3.06422779885954E-6,1,0.999253354069792,40.0298881530762,1.99673731840733,14.4600002095103,-0.00269362787045645,-0.000517944407165582,0.25,-4.40315527959427E-6,-0.000238990880466435,-4.55882764214128E-6,300.0070801,300.0070801,80162.875,80172.9609375,56.7431039820829,20.6076079541012,24.427608,0,0,0,40,4449,300.27185,80167.91796875,,,,,,,,,,,,,0,,,,0,,,,,,300.0070801,,,,
,28538372.595,300.01446535,84986.3984375,-0.000252038393868137,3.61109366910336E-6,1,0.999253354069792,40.0298881530762,1.99694369793859,14.4600002095103,-0.00285021915365834,-0.00049215740628328,0.25,1.40413723754269E-7,-0.000252031110809876,-2.368625119394E-8,300.0137024,300.0152283,84976.7109375,84996.0859375,57.0627900464484,20.6079136726829,23.668306,0,0,0,40,4449,300.2688,84986.3984375,,,,,,,,,,,,,0,,,,0,,,,,,300.01446535,,,,
,28538467.865,300.0086365,89749.49609375,-0.000267980853808938,3.14414482711464E-6,1,0.999253354069792,40.0298881530762,1.99679457615004,14.4600002095103,-0.00302826279714797,-0.000534964224826625,0.25,-8.86841237601027E-7,-0.000267972510789854,-1.06108166814217E-6,300.0086365,300.0086365,89739.4375,89759.5546875,56.8736359447945,20.6063890160967,23.668306,0,0,0,40,4449,300.25645,89749.49609375,,,,,,,,,,,,,0,,,,0,,,,,,300.0086365,,,,
,28538579.755,300.0066528,85643.7421875,-0.000255619872211495,3.02848167629178E-6,1,0.999253354069792,40.0298881530762,1.99700053899488,14.4600002095103,-0.00287913798672202,-0.000566480488271961,0.25,-5.81059585571627E-6,-0.000255608682761163,-5.97684428357287E-6,300.0066528,300.0066528,85628.859375,85658.625,56.966649738583,20.606536741143,23.668306,0,0,0,40,4449,300.24135,85643.7421875,,,,,,,,,,,,,0,,,,0,,,,,,300.0066528,,,,
,28538676.03,300.0007935,80830.484375,-0.000239580784903694,3.26813103991742E-6,1,0.999253354069792,40.0298881530762,1.99723654395555,14.4600002095103,-0.00270825874615469,-0.000476334399302499,0.25,-6.12409991036761E-7,-0.000239573477185945,-7.68560597533998E-7,300.0007935,300.0007935,80820.3359375,80840.6328125,56.9064643426022,20.6106862720838,24.427608,0,0,0,40,4449,300.24455,80830.484375,,,,,,,,,,,,,0,,,,-0.0049,,,,,,300.0007935,,,,
,28538776.28,299.9930725,75819.25,-0.000224323972199326,2.28395958280713E-6,1,0.999253354069792,40.0298881530762,1.9969844860477,14.4600002095103,-0.00253496947351931,-0.000448942587534649,0.25,-8.38123765265008E-7,-0.000224317002486485,-9.84507447329007E-7,299.9930725,299.9930725,75811.640625,75826.859375,56.9134989992753,20.61087010601,24.047956,0,0,0,40,4449,300.252,75819.25,,,,,,,,,,,,,0,,,,-0.0049,,,,,,299.9930725,,,,
,28538876.18,299.9908447,70825.41015625,-0.000208854988829475,2.92786135570741E-6,1,0.999253354069792,40.0298881530762,1.9970356634232,14.4600002095103,-0.00235635239171991,-0.000440319672090233,0.25,-2.7544273681392E-6,-0.000208847211137516,-2.89082596347958E-6,299.9908447,299.9908447,70822.921875,70827.8984375,57.0002597649099,20.6112862140184,24.047956,0,0,0,40,4449,300.2659,70825.41015625,,,,,,,,,,,,,0,,,,-0.0049,,,,,,299.9908447,,,,
,28538976.62,299.9905701,65804.98828125,-0.000190850827114642,2.05238538552565E-6,1,0.999253354069792,40.0298881530762,1.99695964388971,14.4600002095103,-0.00215301710653767,-0.000403095722216045,0.25,-2.5829857722485E-6,-0.000190843662825767,-2.70777872948551E-6,299.9905701,299.9905701,65800.2109375,65809.765625,56.926005055583,20.6125212881251,23.668306,0,0,0,40,4449,300.27135,65804.98828125,,,,,,,,,,,,,0,,,,0,,,,,,299.9905701,,,,
,28539073.655,299.9949036,60954.5546875,-0.000176353852085204,2.3004745064344E-6,1,0.999253354069792,40.0298881530762,1.9974113843101,14.4600002095103,-0.0019953122899816,-0.000341338203909675,0.25,3.73613895254383E-7,-0.000176348998585972,2.58082885403165E-7,299.9945679,299.9952393,60946.95703125,60962.15234375,57.0010413934291,20.6111893744141,24.047956,0,0,0,40,4449,300.2725,60954.5546875,,,,,,,,,,,,,0,,,,0.00245,,,,,,299.9949036,,,,
,28539174.265,299.9910583,55924.1875,-0.000159304849011772,2.17998449056056E-6,1,0.999253354069792,40.0298881530762,1.99704635743034,14.4600002095103,-0.00179828588877891,-0.000330307851481307,0.25,-1.60985332992035E-6,-0.000159299198841786,-1.71428306849707E-6,299.9910583,299.9910583,55919.1015625,55929.2734375,57.1511140691214,20.6106446409075,23.668306,0,0,0,40,4449,300.28275,55924.1875,,,,,,,,,,,,,0,,,,-0.0049,,,,,,299.9910583,,,,
,28539272.64,299.9847412,51009.462890625,-0.00014421321236672,1.513449428549E-6,1,0.999253354069792,40.0298881530762,1.99689492992595,14.4600002095103,-0.00162927834844025,-0.000290513399306254,0.25,-7.07151179419223E-7,-0.000144208611306617,-8.01825235837181E-7,299.9847412,299.9847412,50997.0625,51021.86328125,57.0831123879483,20.6140455669298,24.427608,0,0,0,40,4449,300.27155,51009.462890625,,,,,,,,,,,,,0,,,,0,,,,,,299.9847412,,,,
,28539372.9,299.9880981,45997.005859375,-0.00012917247149718,1.54328205945323E-6,1,0.999253354069792,40.0298881530762,1.99691096456785,14.4600002095103,-0.00146049105838489,-0.000253707512342553,0.25,-5.76925015316626E-8,-0.000129168704438245,-1.42601689449549E-7,299.9880981,299.9880981,45984.2578125,46009.75390625,57.1534589546791,20.6125386778639,24.047956,0,0,0,40,4449,300.294,45997.005859375,,,,,,,,,,,,,0,,,,0,,,,,,299.9880981,,,,
,28539472.535,299.9917908,41014.48828125,-0.000111753541987425,1.78395899607955E-6,1,0.999253354069792,40.0298881530762,1.99684066479607,14.4600002095103,-0.00126258291156888,-0.000224786027161255,0.25,-5.18428385387206E-7,-0.000111749952456328,-5.91955405043432E-7,299.9917908,299.9917908,41011.99609375,41016.98046875,57.3918556530445,20.6127236217529,23.668306,0,0,0,40,4449,300.30425,41014.48828125,,,,,,,,,,,,,0,,,,0,,,,,,299.9917908,,,,
,28539570.61,299.9887695,36116.7109375,-9.94777193383641E-5,2.19319457347755E-6,1,0.999253354069792,40.0298881530762,1.99672425103604,14.4600002095103,-0.00112502015629053,-0.000193208354194577,0.25,1.46598678958268E-7,-9.94749291559924E-5,8.10635690924578E-8,299.9887695,299.9887695,36108.96875,36124.453125,57.1300100991022,20.6144624978208,24.047956,0,0,0,40,4449,300.3242,36116.7109375,,,,,,,,,,,,,0,,,,0.00245,,,,,,299.9887695,,,,
,28539666.72,299.9933167,31311.837890625,-8.44303208492415E-5,1.96323308955405E-6,1,0.999253354069792,40.0298881530762,1.99668254960534,14.4600002095103,-0.000952432589423786,-0.000177793021293833,0.25,-1.09727990120709E-6,-8.44271279842281E-5,-1.15292616177692E-6,299.9933167,299.9933167,31301.78515625,31321.890625,57.2191157502945,20.6170232891167,23.668306,0,0,0,40,4449,300.3184,31311.837890625,,,,,,,,,,,,,0,,,,-0.00245,,,,,,299.9933167,,,,
,28539764.31,299.99331665,26434,-6.91714383758813E-5,1.12572965657519E-6,1,0.999253354069792,40.0298881530762,1.99672517154477,14.4600002095103,-0.000781346726926452,-0.00013972429651861,0.25,-3.73593365612959E-7,-6.91691645509114E-5,-4.19245121009157E-7,299.9927979,299.9938354,26428.71875,26439.28125,57.4629838482945,20.6161940381013,23.668306,0,0,0,40,4449,300.321,26434,,,,,,,,,,,,,0,,,,0.00245,,,,,,299.99331665,,,,
,28539861.615,299.9961243,21571.4248046875,-5.38724564197203E-5,1.32671394443308E-6,1,0.999253354069792,40.0298881530762,1.9966178757928,14.4600002095103,-0.000604087578317555,-0.000134289438546291,0.25,-2.54412893041831E-6,-5.38691876556179E-5,-2.5796538576754E-6,299.9961243,299.9961243,21566.408203125,21576.44140625,57.190195495083,20.6196677980291,23.668306,0,0,0,40,4449,300.31325,21571.4248046875,,,,,,,,,,,,,0,,,,0,,,,,,299.9961243,,,,
,28539961.44,299.9908752,16582.3876953125,-3.91022858079926E-5,9.67658188614709E-7,1,0.999253354069792,40.0298881530762,1.99671084709184,14.4600002095103,-0.000440340913817296,-8.67631875587809E-5,0.25,-8.99097764072409E-7,-3.91005441132495E-5,-9.24934204023554E-7,299.9908752,299.9908752,16580.083984375,16584.69140625,57.2120810936214,20.6174524172077,24.427608,0,0,0,40,4449,300.3332,16582.3876953125,,,,,,,,,,,,,0,,,,0,,,,,,299.9908752,,,,
,28540059.055,299.99575805,11704.7783203125,-2.56464410662097E-5,9.74614937718132E-7,1,0.999253354069792,40.0298881530762,1.99670908120459,14.4600002095103,-0.000289034575587247,-5.56150641348177E-5,0.25,-4.75484858538874E-7,-2.56453681188622E-5,-4.92448927563095E-7,299.9951782,299.9963379,11697.3798828125,11712.1767578125,56.9314764552176,20.6222812812768,24.047956,0,0,0,40,4449,300.335,11704.7783203125,,,,,,,,,,,,,0,,,,0,,,,,,299.99575805,,,,
,28540155.14,299.9932861,6901.94311523437,-1.26329470379268E-5,6.61409283644704E-7,1,0.999253354069792,40.0298881530762,1.99667269385836,14.4600002095103,-0.000141692377014991,-3.13080176465485E-5,0.25,-5.80355478451258E-7,-1.26321895722904E-5,-5.88708261481335E-7,299.9932861,299.9932861,6894.62060546875,6909.265625,57.3058765159291,20.6222940991779,24.427608,0,0,0,40,4449,300.33575,6901.94311523437,,,,,,,,,,,,,0,,,,0,,,,,,299.9932861,,,,
,28540251.39,299.9953003,2091.67028808594,-9.14044151834249E-7,4.84338474129146E-7,1,0.999253354069792,40.0298881530762,1.99654629146071,14.4600002095103,-1.03853247984272E-5,-1.49208358544815E-6,0.25,2.63872449233956E-8,-9.14034558052871E-7,2.57804447550218E-8,299.9953003,299.9953003,2086.65966796875,2096.68090820313,57.0440309619868,20.6236500380591,24.047956,0,0,0,40,4449,300.3379,2091.67028808594,,,,,,,,,,,,,0,,,,-0.0049,,,,,,299.9953003,,,,
,28540343.24,299.9969788,-2494.25610351562,2.8240814928089E-6,3.71792240499259E-7,1,0.999253354069792,40.0298881530762,1.99655526130719,14.4600002095103,3.24621384235974E-5,2.44608022591629E-6,0.25,-2.72936225615025E-7,2.82417858572462E-6,-2.71055847676876E-7,299.9969788,299.9969788,-2496.72802734375,-2491.7841796875,57.1644017539484,20.6247904639665,24.427608,0,0,0,40,4449,300.3401,-2494.25610351562,,,,,,,,,,,,,0,,,,0,,,,,,299.9969788,,,,
,28540440.545,299.9951477,-7361.17602539063,1.42333812058919E-5,7.4774884852492E-7,1,0.999253354069792,40.0298881530762,1.99673865093717,14.4600002095103,0.000160765035790018,2.88284193963862E-5,0.25,8.36711562021884E-8,1.42329047154334E-5,9.30979277288488E-8,299.9951477,299.9951477,-7366.0703125,-7356.28173828125,57.4098331089868,20.6232539752134,24.047956,0,0,0,40,4449,300.34465,-7361.17602539063,,,,,,,,,,,,,0,,,,0,,,,,,299.9951477,,,,
,28540538.155,300.0044556,-12242.0141601562,2.73316887106259E-5,7.69169157269529E-7,1,0.999253354069792,40.0298881530762,1.99685678529191,14.4600002095103,0.000307728644951553,6.1122262258767E-5,0.25,6.7021538284963E-7,2.73304287715365E-5,6.88286679890711E-7,300.0044556,300.0044556,-12249.3837890625,-12234.64453125,57.3465211989291,20.6235790753524,24.047956,0,0,0,40,4449,300.34495,-12242.0141601562,,,,,,,,,,,,,0,,,,0,,,,,,300.0044556,,,,
,28540638.11,300.0116272,-17236.4765625,4.1804778874742E-5,1.18376736102669E-6,1,0.999253354069792,40.0298881530762,1.99675000449478,14.4600002095103,0.0004709086344838,9.20353530833314E-5,0.25,8.97029144672164E-7,4.18029284231374E-5,9.24649621941801E-7,300.0116272,300.0116272,-17241.712890625,-17231.240234375,57.1167224142753,20.6223035448601,24.047956,0,0,0,40,4449,300.3271,-17236.4765625,,,,,,,,,,,,,0,,,,-0.0049,,,,,,300.0116272,,,,
,28540738.265,300.0085754,-22241.330078125,5.56902260549115E-5,1.98299809464156E-6,1,0.999253354069792,40.0298881530762,1.99669098427339,14.4600002095103,0.00062815251776576,0.000117699592625373,0.25,7.61457639733025E-7,5.56880573643069E-5,7.98230863770398E-7,300.0085754,300.0085754,-22248.986328125,-22233.673828125,57.1581487257945,20.624980370554,24.807261,0,0,0,40,4449,300.3141,-22241.330078125,,,,,,,,,,,,,0,,,,0,,,,,,300.0085754,,,,
,28540837.79,300.0100098,-27216.6748046875,7.16443275777365E-5,1.79770746764441E-6,1,0.999253354069792,40.0298881530762,1.99678850157777,14.4600002095103,0.000809781198247298,0.000141969507074706,0.25,1.43360226055503E-7,7.1642090753948E-5,1.90646156125926E-7,300.0100098,300.0100098,-27226.97265625,-27206.376953125,57.2707032325638,20.6249085441561,24.427608,0,0,0,40,4449,300.30555,-27216.6748046875,,,,,,,,,,,,,0,,,,-0.00245,,,,,,300.0100098,,,,
,28540937.15,300.00608825,-32181.130859375,8.5712220923522E-5,1.39665793223846E-6,1,0.999253354069792,40.0298881530762,1.99673317379901,14.4600002095103,0.000969308772525775,0.000166687662468499,0.25,-1.07402807301958E-7,8.57097460866736E-5,-5.08804907594933E-8,300.0056763,300.0065002,-32188.111328125,-32174.150390625,57.4012351952753,20.6235744482256,24.427608,0,0,0,40,4449,300.29085,-32181.130859375,,,,,,,,,,,,,0,,,,0,,,,,,300.00608825,,,,
,28541037.87,300.019104,-37212.798828125,0.000101318115159496,1.32441092673769E-6,1,0.999253354069792,40.0298881530762,1.99683585701152,14.4600002095103,0.00114534128637594,0.000199980796780579,0.25,1.32618658521079E-7,0.000101314977859147,1.99350904189332E-7,300.019104,300.019104,-37225.32421875,-37200.2734375,57.3465211989291,20.6239256771184,24.047956,0,0,0,40,4449,300.28815,-37212.798828125,,,,,,,,,,,,,0,,,,-0.00245,,,,,,300.019104,,,,
,28541138.265,300.0156555,-42232.5859375,0.000117539066849584,1.4506725372488E-6,1,0.999253354069792,40.0298881530762,1.99682654208927,14.4600002095103,0.00132976504245718,0.000225871677513703,0.25,-3.87756262467711E-7,0.000117535806123054,-3.10411601260791E-7,300.0156555,300.0156555,-42237.47265625,-42227.69921875,57.2878990599868,20.6235456687753,24.427608,0,0,0,40,4449,300.2868,-42232.5859375,,,,,,,,,,,,,0,,,,0.0049,,,,,,300.0156555,,,,
,28541240.485,300.0126343,-47339.72265625,0.000131562863077607,1.83269935659111E-6,1,0.999253354069792,40.0298881530762,1.99676180457662,14.4600002095103,0.0014866324788599,0.000262875801974941,0.25,4.56067449720788E-7,0.00013155865095591,5.42516847028946E-7,300.0126343,300.0126343,-47344.6484375,-47334.796875,57.5145713305638,20.6259223632598,24.427608,0,0,0,40,4449,300.2703,-47339.72265625,,,,,,,,,,,,,0,,,,-0.00245,,,,,,300.0126343,,,,
,28541342.69,300.0136414,-52451.953125,0.000149651657405562,1.72790885967939E-6,1,0.999253354069792,40.0298881530762,1.99684871434569,14.4600002095103,0.0016901415105891,0.000304577212753075,0.25,1.00935562947764E-6,0.000149646549284082,1.10756239555856E-6,300.0136414,300.0136414,-52461.82421875,-52442.08203125,57.3871658819292,20.6247699525138,24.427608,0,0,0,40,4449,300.25785,-52451.953125,,,,,,,,,,,,,0,,,,-0.0049,,,,,,300.0136414,,,,
,28541441.165,300.0111084,-57369.064453125,0.000162434724791964,2.32652888214206E-6,1,0.999253354069792,40.0298881530762,1.99678064714293,14.4600002095103,0.00183618221761891,0.000320596499254531,0.25,2.1244529880219E-7,0.000162429785897286,3.18944774611848E-7,300.0111084,300.0111084,-57384.17578125,-57353.953125,57.3660619119099,20.6265722747674,24.427608,0,0,0,40,4449,300.24825,-57369.064453125,,,,,,,,,,,,,0,,,,0,,,,,,300.0111084,,,,
,28541540.115,300.0119019,-62316.154296875,0.000181929642598725,2.49429047670853E-6,1,0.999253354069792,40.0298881530762,1.99679683740221,14.4600002095103,0.00205490319240024,0.000368703878022433,0.25,1.08957368509356E-6,0.000181923561053218,1.20868574575701E-6,300.0119019,300.0119019,-62321.2109375,-62311.09765625,57.1104693861214,20.6271850361895,24.427608,0,0,0,40,4449,300.24745,-62316.154296875,,,,,,,,,,,,,0,,,,-0.0049,,,,,,300.0119019,,,,
,28541640.77,300.0145569,-67346.37890625,0.000198444392375083,3.05932999393288E-6,1,0.999253354069792,40.0298881530762,1.99672717788346,14.4600002095103,0.00224015220214918,0.000409150352268735,0.25,1.80692267194893E-6,0.000198437350036856,1.93667381275625E-6,300.0145569,300.0145569,-67358.8984375,-67333.859375,57.3246356003907,20.6299824456127,24.427608,0,0,0,40,4449,300.233,-67346.37890625,,,,,,,,,,,,,0,,,,0,,,,,,300.0145569,,,,
,28541742.165,300.01776125,-72415.41015625,0.000211642152562144,2.21752510223572E-6,1,0.999253354069792,40.0298881530762,1.99688162159219,14.4600002095103,0.0023927348140199,0.000416638337924603,0.25,1.80122780524365E-7,0.000211635774354181,3.18397062234184E-7,300.0176392,300.0178833,-72420.3984375,-72410.421875,57.3519925985638,20.6282008583428,24.427608,0,0,0,40,4449,300.1975,-72415.41015625,,,,,,,,,,,,,0,,,,0,,,,,,300.01776125,,,,
,28541842.205,300.019104,-77412.4765625,0.000228226414665675,2.99600815648003E-6,1,0.999253354069792,40.0298881530762,1.99694303879118,14.4600002095103,0.00258026732321846,0.000449517532486992,0.25,2.13732296377719E-7,0.000228219530319843,3.62647028152402E-7,300.0183411,300.0198669,-77417.1875,-77407.765625,57.4184310226984,20.6254160233643,24.807261,0,0,0,40,4449,300.2046,-77412.4765625,,,,,,,,,,,,,0,,,,0,,,,,,300.019104,,,,
,28541944.645,300.0155334,-82531.9375,0.00024706273927598,3.5461520128137E-6,1,0.999253354069792,40.0298881530762,1.99684269626158,14.4600002095103,0.00279154036119173,0.000495553153596533,0.25,1.02388045183071E-6,0.000247054820238525,1.18485830768425E-6,300.0155334,300.0155334,-82539.5546875,-82524.3203125,57.4074882234292,20.6263114643158,24.427608,0,0,0,40,4449,300.1904,-82531.9375,,,,,,,,,,,,,0,,,,0,,,,,,300.0155334,,,,
,28542043.9,300.0145569,-87491.25390625,0.000260179519059512,3.54775579164229E-6,1,0.999253354069792,40.0298881530762,1.99689184046075,14.4600002095103,0.00294023565239012,0.000519447258377673,0.25,8.63756326937673E-7,0.000260171347526916,1.03307973436727E-6,300.0145569,300.0145569,-87501.21875,-87481.2890625,57.2503808910638,20.6275331405758,24.807261,0,0,0,40,4449,300.1719,-87491.25390625,,,,,,,,,,,,,0,,,,-0.00245,,,,,,300.0145569,,,,
,28542158.045,300.0153809,-87808.37890625,0.000259947470949086,4.10552856239093E-6,1,0.999253354069792,40.0298881530762,1.99680248334863,14.4600002095103,0.00293871999892807,0.000511849316989296,0.25,2.33948853949256E-7,0.000259939709015169,4.03133249995732E-7,300.0153809,300.0153809,-87813.5546875,-87803.203125,57.2535074051407,20.6288290600122,24.047956,0,0,0,40,4449,300.1601,-87808.37890625,,,,,,,,,,,,,0,,,,-0.0049,,,,,,300.0153809,,,,
,28542255.405,300.0098572,-82944.26953125,0.000245821190444531,2.63244206328203E-6,1,0.999253354069792,40.0298881530762,1.99678661334602,14.4600002095103,0.00277640366613339,0.000499021857830548,0.25,1.54692136671596E-6,0.000245813016819788,1.7070781965808E-6,300.0098572,300.0098572,-82946.421875,-82942.1171875,57.3207274577945,20.6305611529159,24.807261,0,0,0,40,4449,300.1577,-82944.26953125,,,,,,,,,,,,,0,,,,-0.0049,,,,,,300.0098572,,,,
,28542357.955,299.9977417,-77819.25,0.000226549834209805,3.27764188839676E-6,1,0.999253354069792,40.0298881530762,1.99667358197082,14.4600002095103,0.00255653041499856,0.00047186702755703,0.25,2.48603394009378E-6,0.000226541689108003,2.63380401417263E-6,299.9977417,299.9977417,-77824.3359375,-77814.1640625,57.0112025641791,20.6278292234186,24.047956,0,0,0,40,4449,300.1523,-77819.25,,,,,,,,,,,,,0,,,,-0.0049,,,,,,299.9977417,,,,
,28542459.005,299.9944458,-72767.3046875,0.00021311030345771,3.415612608815E-6,1,0.999253354069792,40.0298881530762,1.99685515769229,14.4600002095103,0.00240310822054336,0.000455289360900986,0.25,3.34449117572027E-6,0.00021310199215008,3.4836404062183E-6,299.9944458,299.9944458,-72777.1640625,-72757.4453125,57.2269320354868,20.6276497507112,24.427608,0,0,0,40,4449,300.1626,-72767.3046875,,,,,,,,,,,,,0,,,,0.0049,,,,,,299.9944458,,,,
,28542561.025,299.9954529,-67668.18359375,0.000195538021090384,2.12117964355374E-6,1,0.999253354069792,40.0298881530762,1.99675414069139,14.4600002095103,0.00220957246971528,0.000390470421474029,0.25,6.57810408291835E-7,0.000195531948722565,7.85713303566033E-7,299.9954529,299.9954529,-67670.75,-67665.6171875,57.190195495083,20.6282511057133,24.807261,0,0,0,40,4449,300.17525,-67668.18359375,,,,,,,,,,,,,0,,,,0.00245,,,,,,299.9954529,,,,
,28542663.335,299.9864197,-62558.689453125,0.00018109561153864,3.00061066828948E-6,1,0.999253354069792,40.0298881530762,1.99669129859437,14.4600002095103,0.00204280827996695,0.000381847574476368,0.25,2.39818053679063E-6,0.000181088860786932,2.5167353810784E-6,299.9864197,299.9864197,-62563.27734375,-62554.1015625,57.0815491309099,20.6277621251836,24.807261,0,0,0,40,4449,300.17715,-62558.689453125,,,,,,,,,,,,,0,,,,0,,,,,,299.9864197,,,,
,28542762.025,299.9917908,-57625.876953125,0.000167609104134983,2.84269119518727E-6,1,0.999253354069792,40.0298881530762,1.99686943254378,14.4600002095103,0.00189386128533938,0.000335986155265107,0.25,6.75784237148671E-7,0.000167603823081259,7.85682346076752E-7,299.9917908,299.9917908,-57630.78125,-57620.97265625,57.2988418592561,20.6257376462441,24.807261,0,0,0,40,4449,300.18775,-57625.876953125,,,,,,,,,,,,,0,,,,-0.0049,,,,,,299.9917908,,,,
,28542859.265,299.9830933,-52763.70703125,0.000150460737442445,2.62028047698856E-6,1,0.999253354069792,40.0298881530762,1.99678497445999,14.4600002095103,0.00169497303087847,0.000330781158540593,0.25,3.18751248967953E-6,0.00015045433896811,3.28620377325525E-6,299.9830933,299.9830933,-52768.6171875,-52758.796875,57.3316702570638,20.6266205643308,24.047956,0,0,0,40,4449,300.201,-52763.70703125,,,,,,,,,,,,,0,,,,0,,,,,,299.9830933,,,,
,28542953.82,299.9890137,-48039.36328125,0.000135948611930142,2.62124041998807E-6,1,0.999253354069792,40.0298881530762,1.99670800768351,14.4600002095103,0.00153680288702278,0.000267877137466627,0.25,1.39141947876637E-7,0.000135944592441924,2.2848969028808E-7,299.9890137,299.9890137,-48052.05078125,-48026.67578125,57.3183825722368,20.6260063209529,24.427608,0,0,0,40,4449,300.20985,-48039.36328125,,,,,,,,,,,,,0,,,,-0.0049,,,,,,299.9890137,,,,
,28543050.525,299.992157,-43204.21484375,0.000121356873858856,1.78346214959043E-6,1,0.999253354069792,40.0298881530762,1.99661517257122,14.4600002095103,0.00136981734521875,0.000250514760985657,0.25,1.13247755233968E-6,0.000121352600908002,1.21229215400732E-6,299.9919739,299.9923401,-43209.1796875,-43199.25,57.2425646058714,20.6272411566283,24.807261,0,0,0,40,4449,300.2216,-43204.21484375,,,,,,,,,,,,,0,,,,0.00245,,,,,,299.992157,,,,
,28543146.675,299.9890442,-38399.630859375,0.000105471910057672,1.47719761408911E-6,1,0.999253354069792,40.0298881530762,1.99665449480218,14.4600002095103,0.00119075576391881,0.000216471106063032,0.25,8.73012413148778E-7,0.000105468274067398,9.42457939407607E-7,299.9890442,299.9890442,-38407.05859375,-38392.203125,57.1831608384099,20.6258788743533,24.427608,0,0,0,40,4449,300.2255,-38399.630859375,,,,,,,,,,,,,0,,,,0,,,,,,299.9890442,,,,
,28543243.735,299.9895325,-33549.919921875,9.08796810455459E-5,2.1104393197035E-6,1,0.999253354069792,40.0298881530762,1.99661162154893,14.4600002095103,0.00102894296182528,0.000169482484943827,0.25,-7.54640195273399E-7,9.08775339428686E-5,-6.94696144945327E-7,299.9895325,299.9895325,-33560.01953125,-33539.8203125,57.4098331089868,20.6236005805431,24.807261,0,0,0,40,4449,300.2338,-33549.919921875,,,,,,,,,,,,,0,,,,-0.0049,,,,,,299.9895325,,,,
,28543339.6,299.9894104,-28760.4619140625,7.6239923004896E-5,1.6179504548674E-6,1,0.999253354069792,40.0298881530762,1.99658141493737,14.4600002095103,0.000860103395712961,0.000159927995082179,0.25,9.36839205746228E-7,7.62370818041807E-5,9.871319356216E-7,299.9894104,299.9894104,-28768.025390625,-28752.8984375,57.6013320961984,20.6236088096423,24.807261,0,0,0,40,4449,300.24055,-28760.4619140625,,,,,,,,,,,,,0,,,,0,,,,,,299.9894104,,,,
,28543436.87,299.9874878,-23898.169921875,6.22734501446052E-5,1.37892153361412E-6,1,0.999253354069792,40.0298881530762,1.99654252729924,14.4600002095103,0.000704140568205375,0.000121315502418072,0.25,-5.8560404835133E-8,6.22716738146997E-5,-1.7416003148526E-8,299.9874878,299.9874878,-23905.47265625,-23890.8671875,57.0909286731407,20.6276749769444,24.427608,0,0,0,40,4449,300.2469,-23898.169921875,,,,,,,,,,,,,0,,,,0,,,,,,299.9874878,,,,
,28543533.66,299.9970703,-19060.62109375,4.77699735400954E-5,1.69609240591744E-6,1,0.999253354069792,40.0298881530762,1.99659391823986,14.4600002095103,0.000539484582001404,9.695825569609E-5,0.25,2.99555508698096E-7,4.77683641572669E-5,3.31135605782915E-7,299.9970703,299.9970703,-19067.837890625,-19053.404296875,57.1518956976407,20.626154859019,24.427608,0,0,0,40,4449,300.2657,-19060.62109375,,,,,,,,,,,,,0,,,,0,,,,,,299.9970703,,,,
,28543627.97,299.9931335,-14346.3227539062,3.26209052364129E-5,1.010159865846E-6,1,0.999253354069792,40.0298881530762,1.9966926946842,14.4600002095103,0.000369900228722094,5.7657215909038E-5,0.25,-5.5223611458459E-7,3.26203098612621E-5,-5.30628968268462E-7,299.9931335,299.9931335,-14356.330078125,-14336.3154296875,57.1456426694868,20.6208957476618,24.807261,0,0,0,40,4449,300.2644,-14346.3227539062,,,,,,,,,,,,,0,,,,0,,,,,,299.9931335,,,,
,28543723.395,299.9933167,-9578.50537109375,2.08586131925417E-5,1.09151375829344E-6,1,0.999253354069792,40.0298881530762,1.99663747333999,14.4600002095103,0.000235057475225751,4.52909751979613E-5,0.25,3.92017135526484E-7,2.08577379262879E-5,4.05822800588452E-7,299.9933167,299.9933167,-9583.412109375,-9573.5986328125,57.1167224142753,20.6235516602574,24.427608,0,0,0,40,4449,300.26995,-9578.50537109375,,,,,,,,,,,,,0,,,,0.00245,,,,,,299.9933167,,,,
,28543818.795,299.9942017,-4807.294921875,7.69959672517439E-6,6.001433072319E-7,1,0.999253354069792,40.0298881530762,1.99652327933021,14.4600002095103,8.67691552960026E-5,1.66799922637668E-5,0.25,1.41387661922724E-7,7.69927516791071E-6,1.46487759161305E-7,299.9942017,299.9942017,-4814.68701171875,-4799.90283203125,57.1706547821022,20.6255471255024,24.807261,0,0,0,40,4449,300.27225,-4807.294921875,,,,,,,,,,,,,0,,,,0.00245,,,,,,299.9942017,,,,
,28543911.15,299.995697,-190.625061035156,-1.05328918351015E-7,4.104899822096E-7,1,0.999253354069792,40.0298881530762,1.99664364589626,14.4600002095103,-4.65681564912265E-7,-4.39171122032971E-6,0.25,-3.70193921517477E-7,-1.05080234208057E-7,-3.7025280169332E-7,299.9953918,299.9960022,-195.494689941406,-185.755432128906,57.1792526958137,20.6226626106978,25.186911,0,0,0,40,4449,300.2702,-190.625061035156,,,,,,,,,,,,,0,,,,-0.0049,,,,,,299.995697,,,,
,28543999.81,299.9935608,4235.27221679687,-6.63711058760679E-6,4.57517198236406E-7,1,0.999253354069792,40.0298881530762,1.99648062826414,14.4600002095103,-7.28487831804843E-5,-2.56060010628575E-5,0.25,-1.11506268081028E-6,-6.63617506183907E-6,-1.11942995776203E-6,299.9935608,299.9935608,4202.75732421875,4267.787109375,57.1120326431599,20.6223725465226,24.807261,0,0,0,40,4449,300.27515,4235.27221679687,,,,,,,,,,,,,0,,,,0,,,,,,299.9935608,,,,
,28544094.53,299.9966736,8971.67919921875,-1.8475375555357E-5,1.06253310465977E-6,1,0.999253354069792,40.0298881530762,1.99658263233083,14.4600002095103,-0.000206647470652451,-4.90474880041395E-5,0.25,-1.13730915155971E-6,-1.84740745545834E-5,-1.14951490551534E-6,299.9966736,299.9966736,8961.8212890625,8981.537109375,56.8064158921406,20.6224972830219,24.427608,0,0,0,40,4449,300.2767,8971.67919921875,,,,,,,,,,,,,0,,,,0.00245,,,,,,299.9966736,,,,
,28544189.745,300.0023193,13729.4365234375,-3.12374175316666E-5,1.33113786659864E-6,1,0.999253354069792,40.0298881530762,1.99645251827568,14.4600002095103,-0.000350238277029249,-7.79074768680362E-5,0.25,-1.47933264571605E-6,-3.12355077502762E-5,-1.49996529802613E-6,300.0023193,300.0023193,13719.3857421875,13739.4873046875,57.1049979864868,20.623502256205,25.186911,0,0,0,40,4449,300.27445,13729.4365234375,,,,,,,,,,,,,0,,,,0.0049,,,,,,300.0023193,,,,
,28544284.01,300.0067444,18442.109375,-4.54609280085524E-5,1.47138951670367E-6,1,0.999253354069792,40.0298881530762,1.99645202344859,14.4600002095103,-0.000510365017033453,-0.00010962454138515,0.25,-1.82062131978488E-6,-4.54583646722612E-5,-1.85063303016207E-6,300.0067444,300.0067444,18436.97265625,18447.24609375,57.2230238928907,20.6231731299868,24.807261,0,0,0,40,4449,300.2617,18442.109375,,,,,,,,,,,,,0,,,,-0.0049,,,,,,300.0067444,,,,
,28544380.025,300.0063782,23242.36328125,-5.99436033431596E-5,1.71898540271534E-6,1,0.999253354069792,40.0298881530762,1.99648219733471,14.4600002095103,-0.000675187726285363,-0.000131714635848965,0.25,-1.26527980599641E-6,-5.99409790782152E-5,-1.30485025096826E-6,300.0063782,300.0063782,23240,23244.7265625,56.8556584888522,20.6225310572063,24.807261,0,0,0,40,4449,300.25025,23242.36328125,,,,,,,,,,,,,0,,,,0,,,,,,300.0063782,,,,
,28544473.56,300.0095215,27914.8837890625,-7.45045966737749E-5,1.44783695018667E-6,1,0.999253354069792,40.0298881530762,1.99653417255487,14.4600002095103,-0.000839351306507812,-0.000162952573036429,0.25,-1.50535316586147E-6,-7.45013761545409E-5,-1.55449063801902E-6,300.0095215,300.0095215,27907.423828125,27922.34375,57.3926372815638,20.6213757719459,24.807261,0,0,0,40,4449,300.24585,27914.8837890625,,,,,,,,,,,,,0,,,,0,,,,,,300.0095215,,,,
,28544570.22,300.0116882,32747.6328125,-8.96192261734628E-5,1.43054498243825E-6,1,0.999253354069792,40.0298881530762,1.99679215968391,14.4600002095103,-0.00101129304787386,-0.00018714979314739,0.25,-1.02499825997672E-6,-8.96158701785593E-5,-1.08406678684207E-6,300.0116882,300.0116882,32745.150390625,32750.115234375,57.1284468420637,20.6199625066473,24.807261,0,0,0,40,4449,300.2431,32747.6328125,,,,,,,,,,,,,0,,,,0.00245,,,,,,300.0116882,,,,
,28544665.54,300.0155334,37510.064453125,-0.000102949036453718,1.793708505768E-6,1,0.999253354069792,40.0298881530762,1.99658085397242,14.4600002095103,-0.00115919423881796,-0.00022881328076494,0.25,-2.40248194762772E-6,-0.000102944367067184,-2.47022999965907E-6,300.0155334,300.0155334,37502.6171875,37517.51171875,57.0635716749676,20.6216429070664,24.427608,0,0,0,40,4449,300.23505,37510.064453125,,,,,,,,,,,,,0,,,,-0.00245,,,,,,300.0155334,,,,
,28544760.39,300.0084229,42250.283203125,-0.000118747130409222,1.32217796236211E-6,1,0.999253354069792,40.0298881530762,1.99636972072595,14.4600002095103,-0.00133594621506133,-0.000269661008347614,0.25,-3.28091571061152E-6,-0.000118741448645775,-3.35896341977904E-6,300.0084229,300.0084229,42245.46875,42255.09765625,57.0213637349291,20.6223750300119,25.186911,0,0,0,40,4449,300.2297,42250.283203125,,,,,,,,,,,,,0,,,,-0.0049,,,,,,300.0084229,,,,
,28544855.985,300.017334,47027.919921875,-0.00013386103135344,2.04873323582183E-6,1,0.999253354069792,40.0298881530762,1.99644475858902,14.4600002095103,-0.00150638045563076,-0.000302008405629101,0.25,-3.52297701292717E-6,-0.000133854709789606,-3.61087024798166E-6,300.0162659,300.0184021,47023.015625,47032.82421875,57.1894138665637,20.6204917705997,24.427608,0,0,0,40,4449,300.2152,47027.919921875,,,,,,,,,,,,,0,,,,0,,,,,,300.017334,,,,
,28544950.835,300.010498,51770.6015625,-0.000148617258595267,2.25666040948723E-6,1,0.999253354069792,40.0298881530762,1.99646976112347,14.4600002095103,-0.00167519972168033,-0.000319476589774029,0.25,-2.51135594608072E-6,-0.000148611208285219,-2.60887447622348E-6,300.010498,300.010498,51760.546875,51780.65625,56.9314764552176,20.6195912341178,25.186911,0,0,0,40,4449,300.20715,51770.6015625,,,,,,,,,,,,,0,,,,-0.0049,,,,,,300.010498,,,,
,28545047.165,300.0134888,56583.259765625,-0.000164370637014169,1.51835107431531E-6,1,0.999253354069792,40.0298881530762,1.99642441767682,14.4600002095103,-0.00185408740492697,-0.0003454990654326,0.25,-2.08467525177654E-6,-0.000164364395159007,-2.19242893078627E-6,300.0134888,300.0134888,56578.3359375,56588.18359375,56.9900985941599,20.6190957528206,25.186911,0,0,0,40,4449,300.20095,56583.259765625,,,,,,,,,,,,,0,,,,0,,,,,,300.0134888,,,,
,28545144.585,300.0132141,61453.107421875,-0.000178995131867359,1.95527759566111E-6,1,0.999253354069792,40.0298881530762,1.99652524071997,14.4600002095103,-0.00201911279332514,-0.00037646047883625,0.25,-2.28826918890484E-6,-0.000178988338257076,-2.40547498450414E-6,300.0132141,300.0132141,61440.6328125,61465.58203125,57.1948852661984,20.6169544196083,24.427608,0,0,0,40,4449,300.19015,61453.107421875,,,,,,,,,,,,,0,,,,0.00245,,,,,,300.0132141,,,,
,28545242.005,300.01976015,66324.03125,-0.000194471385258368,1.92252964991422E-6,1,0.999253354069792,40.0298881530762,1.99652154687276,14.4600002095103,-0.00219246548459135,-0.000416047206851468,0.25,-3.10880499113872E-6,-0.000194463565626289,-3.23598209556618E-6,300.0192871,300.0202332,66318.8828125,66329.1796875,57.0065127930637,20.6166726484429,24.807261,0,0,0,40,4449,300.1695,66324.03125,,,,,,,,,,,,,0,,,,0.00245,,,,,,300.01976015,,,,
,28545340.24,300.0150146,71231.62890625,-0.000209917929683651,2.79441641372234E-6,1,0.999253354069792,40.0298881530762,1.99647094010087,14.4600002095103,-0.00236709449005348,-0.000445955666771666,0.25,-3.07932082002541E-6,-0.00020990972305199,-3.21644010150005E-6,300.0150146,300.0150146,71226.7578125,71236.5,57.0838940164676,20.6213714344892,24.427608,0,0,0,40,4449,300.16755,71231.62890625,,,,,,,,,,,,,0,,,,-0.00245,,,,,,300.0150146,,,,
,28545438.915,300.0148926,76167.19921875,-0.000222410647816017,2.11866121581977E-6,1,0.999253354069792,40.0298881530762,1.9964584925668,14.4600002095103,-0.00250750776261793,-0.000475052508211238,0.25,-3.48917684059307E-6,-0.000222401823730469,-3.63427687167939E-6,300.0148926,300.0148926,76159.4921875,76174.90625,57.2957153451791,20.616390267992,24.807261,0,0,0,40,4449,300.1509,76167.19921875,,,,,,,,,,,,,0,,,,-0.00245,,,,,,300.0148926,,,,
,28545537.16,300.0122375,81077.7890625,-0.00023544036737096,2.97658450595949E-6,1,0.999253354069792,40.0298881530762,1.99670210332577,14.4600002095103,-0.00265584233761208,-0.000496448281147125,0.25,-3.11945960095552E-6,-0.000235431442981954,-3.27288753627263E-6,300.0122375,300.0122375,81072.6171875,81082.9609375,57.1112510146407,20.6179415342281,24.427608,0,0,0,40,4449,300.1439,81077.7890625,,,,,,,,,,,,,0,,,,-0.00245,,,,,,300.0122375,,,,
,28545632.93,300.0142822,85863.63671875,-0.000254488462815389,2.2541700624164E-6,1,0.999253354069792,40.0298881530762,1.99659437864045,14.4600002095103,-0.00287085896294344,-0.00053487772106697,0.25,-3.22099467913964E-6,-0.0002544789163729,-3.3866393347946E-6,300.0142822,300.0142822,85861.2421875,85866.03125,57.3269804859484,20.6147569797996,24.807261,0,0,0,40,4449,300.1346,85863.63671875,,,,,,,,,,,,,0,,,,0,,,,,,300.0142822,,,,
,28545743.79,300.0126343,89533.046875,-0.000262225746312779,3.80371902384378E-6,1,0.999253354069792,40.0298881530762,1.9964856242452,14.4600002095103,-0.00295233813392899,-0.00058372888093394,0.25,-6.20430038423136E-6,-0.000262214063650955,-6.37474006903122E-6,300.0126343,300.0126343,89525.5625,89540.53125,57.0213637349291,20.6152731037189,24.807261,0,0,0,40,4449,300.1238,89533.046875,,,,,,,,,,,,,0,,,,0.00245,,,,,,300.0126343,,,,
,28545837.94,300.0056458,84829.0390625,-0.000247925264432776,2.40759131229698E-6,1,0.999253354069792,40.0298881530762,1.99663823906856,14.4600002095103,-0.00279851078491259,-0.000511679252539743,0.25,-2.3051120040681E-6,-0.000247916578606975,-2.4665597229173E-6,300.0056458,300.0056458,84823.96875,84834.109375,57.047939104583,20.6176460318383,25.186911,0,0,0,40,4449,300.1246,84829.0390625,,,,,,,,,,,,,0,,,,0,,,,,,300.0056458,,,,
,28545933.71,300.0023193,80040.08203125,-0.000241423366252072,2.48786559086452E-6,1,0.999253354069792,40.0298881530762,1.9967219573839,14.4600002095103,-0.0027128585036053,-0.000569679715621259,0.25,-8.55942755523404E-6,-0.000241410798697256,-8.71665640183437E-6,300.0023193,300.0023193,80035.1171875,80045.046875,57.0643533034868,20.613315925307,24.427608,0,0,0,40,4449,300.1214,80040.08203125,,,,,,,,,,,,,0,,,,0,,,,,,300.0023193,,,,
,28546031.67,299.9980469,75144.10546875,-0.000222109756194872,3.28734400299172E-6,1,0.999253354069792,40.0298881530762,1.9965840750292,14.4600002095103,-0.00249945038303383,-0.000502241570250386,0.25,-5.94361703652118E-6,-0.000222099466718847,-6.08850604385244E-6,299.9980469,299.9980469,75131.71875,75156.4921875,56.9799374234099,20.617624079918,24.807261,0,0,0,40,4449,300.12215,75144.10546875,,,,,,,,,,,,,0,,,,-0.0049,,,,,,299.9980469,,,,
,28546130.305,299.9895325,70213.453125,-0.000203838757164726,2.30864826328252E-6,1,0.999253354069792,40.0298881530762,1.99645858482401,14.4600002095103,-0.00230009291568471,-0.000424031847153351,0.25,-2.19337263384378E-6,-0.000203831490348303,-2.32659911542928E-6,299.9895325,299.9895325,70203.5625,70223.34375,56.9049010855637,20.6193993902433,24.807261,0,0,0,40,4449,300.1322,70213.453125,,,,,,,,,,,,,0,,,,0.00245,,,,,,299.9895325,,,,
,28546230.465,299.9843445,65208.375,-0.000188685172901912,2.78783004382288E-6,1,0.999253354069792,40.0298881530762,1.99684152137152,14.4600002095103,-0.00212951227495282,-0.000392461609228338,0.25,-2.0196296033058E-6,-0.000188678473922098,-2.14309841589184E-6,299.9843445,299.9843445,65200.6953125,65216.0546875,57.0604451608906,20.6132844724021,24.807261,0,0,0,40,4449,300.15075,65208.375,,,,,,,,,,,,,0,,,,0,,,,,,299.9843445,,,,
,28546326.955,299.98880005,60382.48046875,-0.000176760469352772,2.80502349294995E-6,1,0.999253354069792,40.0298881530762,1.99667138446128,14.4600002095103,-0.00198953648528177,-0.000397816706632458,0.25,-4.56194005958256E-6,-0.00017675240210422,-4.67766288409496E-6,299.9881897,299.9894104,60372.3984375,60392.5625,56.9603967104291,20.6159870640013,24.807261,0,0,0,40,4449,300.1593,60382.48046875,,,,,,,,,,,,,0,,,,0.0049,,,,,,299.98880005,,,,
,28546425.155,299.990448,55477.0078125,-0.000159870321112809,1.76104336565758E-6,1,0.999253354069792,40.0298881530762,1.9966030932805,14.4600002095103,-0.00180226453052138,-0.000343082414176546,0.25,-2.64793382445517E-6,-0.000159863971117477,-2.75276331946603E-6,299.990448,299.990448,55469.6015625,55484.4140625,57.1346998702176,20.6180254817666,24.807261,0,0,0,40,4449,300.1664,55477.0078125,,,,,,,,,,,,,0,,,,0,,,,,,299.990448,,,,
,28546526.095,299.9848633,50432.4140625,-0.000145804021174492,2.22064183034274E-6,1,0.999253354069792,40.0298881530762,1.99674577432911,14.4600002095103,-0.00163920779039572,-0.000339442545591114,0.25,-4.76084343747318E-6,-0.000145796705976566,-4.85649566891745E-6,299.9848633,299.9848633,50427.50390625,50437.32421875,57.3207274577945,20.6170077461333,24.427608,0,0,0,40,4449,300.1727,50432.4140625,,,,,,,,,,,,,0,,,,-0.0049,,,,,,299.9848633,,,,
,28546624.075,299.9935608,45535.001953125,-0.00012924019538246,2.25438774438617E-6,1,0.999253354069792,40.0298881530762,1.99653745387756,14.4600002095103,-0.00145858578616021,-0.000267704175649371,0.25,-1.28797833200684E-6,-0.000129235587691743,-1.37294246695253E-6,299.9935608,299.9935608,45530.03515625,45539.96875,56.9916618511983,20.6189352263304,24.807261,0,0,0,40,4449,300.1822,45535.001953125,,,,,,,,,,,,,0,,,,0.00245,,,,,,299.9935608,,,,
,28546723.75,299.9900208,40552.28515625,-0.000113670653945925,1.8565155237364E-6,1,0.999253354069792,40.0298881530762,1.99664317383085,14.4600002095103,-0.00128392694290628,-0.0002297413059284,0.25,-6.26405298385459E-7,-0.000113666941001015,-7.0123145126223E-7,299.9900208,299.9900208,40547.30078125,40557.26953125,57.1815975813714,20.6190035641864,24.807261,0,0,0,40,4449,300.1923,40552.28515625,,,,,,,,,,,,,0,,,,0,,,,,,299.9900208,,,,
,28546818.915,299.9900818,35797.333984375,-9.77752758828619E-5,1.54562775540063E-6,1,0.999253354069792,40.0298881530762,1.99678444391456,14.4600002095103,-0.00109816404320746,-0.000233971943064191,0.25,-3.75308996288286E-6,-9.77699569163217E-5,-3.81742656561E-6,299.9900818,299.9900818,35794.7734375,35799.89453125,57.0471574760637,20.6147209646432,24.427608,0,0,0,40,4449,300.1979,35797.333984375,,,,,,,,,,,,,0,,,,0,,,,,,299.9900818,,,,
,28546916.255,299.9948425,30932.193359375,-8.41274151307065E-5,1.64896895120171E-6,1,0.999253354069792,40.0298881530762,1.99677663380691,14.4600002095103,-0.000947182827622053,-0.000187987362060797,0.25,-2.05064763014053E-6,-8.41235944424679E-5,-2.10609558178911E-6,299.9948425,299.9948425,30927.21484375,30937.171875,57.1808159528522,20.6193224403146,25.186911,0,0,0,40,4449,300.20375,30932.193359375,,,,,,,,,,,,,0,,,,-0.0049,,,,,,299.9948425,,,,
,28547014.82,299.9859314,26004.283203125,-6.89611060078279E-5,1.74952630667014E-6,1,0.999253354069792,40.0298881530762,1.99684814109916,14.4600002095103,-0.000776909478273932,-0.000151470772023621,0.25,-1.44814611892351E-6,-6.89581447667848E-5,-1.49365066442266E-6,299.9859314,299.9859314,26004.283203125,26004.283203125,57.1448610409676,20.6214924069517,25.186911,0,0,0,40,4449,300.2165,26004.283203125,,,,,,,,,,,,,0,,,,0,,,,,,299.9859314,,,,
,28547114.555,299.9901428,21019.900390625,-5.39437302742961E-5,1.587033036E-6,1,0.999253354069792,40.0298881530762,1.99648699082132,14.4600002095103,-0.00060522439759535,-0.000132292311485088,0.25,-2.35584737601556E-6,-5.39405931996943E-5,-2.39144203464113E-6,299.9901428,299.9901428,21007.408203125,21032.392578125,57.014329078256,20.6204487646867,25.186911,0,0,0,40,4449,300.22275,21019.900390625,,,,,,,,,,,,,0,,,,-0.00245,,,,,,299.9901428,,,,
,28547213.86,299.982605,16057.8154296875,-3.95333439266675E-5,1.07880479424106E-6,1,0.999253354069792,40.0298881530762,1.99665841572901,14.4600002095103,-0.000445326013710188,-8.68985569904727E-5,0.25,-8.36564379419841E-7,-3.95316412857745E-5,-8.6270066052219E-7,299.982605,299.982605,16050.30078125,16065.330078125,57.1268835850253,20.6196997374323,25.186911,0,0,0,40,4449,300.23555,16057.8154296875,,,,,,,,,,,,,0,,,,0,,,,,,299.982605,,,,
,28547308.835,299.9913635,11310.1533203125,-2.52521722446833E-5,7.74340761696707E-7,1,0.999253354069792,40.0298881530762,1.99667486257214,14.4600002095103,-0.000283453563879485,-6.12985112075216E-5,0.25,-1.04655587087878E-6,-2.52507358695621E-5,-1.06324992309785E-6,299.9913635,299.9913635,11302.5654296875,11317.7412109375,57.1784710672945,20.6227896883808,24.807261,0,0,0,40,4449,300.2354,11310.1533203125,,,,,,,,,,,,,0,,,,0.0049,,,,,,299.9913635,,,,
,28547405.14,299.9933777,6497.48486328125,-1.18623422815155E-5,6.05824388346107E-7,1,0.999253354069792,40.0298881530762,1.99663507996179,14.4600002095103,-0.000132850842481417,-3.05287216985101E-5,0.25,-6.44988103657146E-7,-1.18615642373702E-5,-6.52831635016091E-7,299.9933777,299.9933777,6494.9365234375,6500.033203125,57.1096877576022,20.6193285279529,25.186911,0,0,0,40,4449,300.24775,6497.48486328125,,,,,,,,,,,,,0,,,,0,,,,,,299.9933777,,,,
,28547500.055,299.993988,1754.30438232422,-8.37970819838087E-7,4.03663440245255E-7,1,0.999253354069792,40.0298881530762,1.99655445302906,14.4600002095103,-8.9246753192679E-6,-4.80982067006477E-6,0.25,-2.80256035691634E-7,-8.37760124768568E-7,-2.80803526354667E-7,299.993988,299.993988,1751.86108398438,1756.74768066406,57.115940785756,20.6243112169873,25.186911,0,0,0,40,4449,300.2535,1754.30438232422,,,,,,,,,,,,,0,,,,0.0049,,,,,,299.993988,,,,
,28547536.74,299.9946289,-0.357758671045303,6.35993926293087E-7,4.0424690417582E-7,1,0.999253354069792,40.0298881530762,1.99641895932087,14.4600002095103,7.42695233469319E-6,-1.23477441811163E-7,0.25,-1.21114945689044E-7,6.36055416902174E-7,-1.20689451776309E-7,299.9946289,299.9946289,-0.395818114280701,-0.319699227809906,56.9963516223137,20.6251002803984,25.186911,0,0,0,40,4417,300.2529,-0.357758671045303,,,,,,,,,,,,,0,,,,0,,,,,,299.9946289,,,,