File: data/monolayers/nanoparticles/Ol_CoFe_C/vsm/data_disorderedWafer/DD227_HYST_200K.DAT
[Header]
; VSM Data File (default extension .dat)
; Copyright (c) 2003-2013, Quantum Design, Inc. All rights reserved.
TITLE,
FILEOPENTIME,28524558.58,11/27/2018,11:30 am
BYAPP,VSM,2.0,2.0
INFO,PPMS VSM Option Release 1.4.10 Build 1,APPNAME
INFO,Quantum Design Linear Motor Servo Controller,MOTOR_MODULE_NAME
INFO,3101-100 M1,MOTOR_HW_VERSION
INFO,MMC1014,MOTOR_SERIAL_NUMBER
INFO,SRV No X-over 01.03.11,MOTOR_SOFTWARE_VERSION
INFO,Quantum Design VSM Detection Module,VSM_MODULE_NAME
INFO,3101-150 F0,VSM_HW_VERSION
INFO,VSM707,VSM_SERIAL_NUMBER
INFO,VSM No X-over 01.02.05 May 20 2008 13:51:47,VSM_SOFTWARE_VERSION
INFO,704,PREAMP_SERIAL_NUMBER
INFO,822,COIL_SERIAL_NUMBER
INFO,0,MOMENT_UNITS
INFO,CoFe2O4 FeO,SAMPLE_MATERIAL
INFO,disordered monolayer,SAMPLE_COMMENT
INFO,25.46,SAMPLE_MASS
INFO,,SAMPLE_VOLUME
INFO,,SAMPLE_MOLECULAR_WEIGHT
INFO,,SAMPLE_SIZE
INFO,,SAMPLE_SHAPE
DATATYPE,COMMENT,1
DATATYPE,TIME,2
STARTUPAXIS,X,2
STARTUPAXIS,Y1,5
[Data]
Comment,Time Stamp (sec),Temperature (K),Magnetic Field (Oe),Moment (emu),M. Std. Err. (emu),Transport Action,Averaging Time (sec),Frequency (Hz),Peak Amplitude (mm),Center Position (mm),Coil Signal' (mV),Coil Signal" (mV),Range (mV),M. Quad. Signal (emu),M. Raw' (emu),M. Raw" (emu),Min. Temperature (K),Max. Temperature (K),Min. Field (Oe),Max. Field (Oe),Mass (grams),Motor Lag (deg),Pressure (Torr),VSM Status (code),Motor Status (code),Measure Status (code),Measure Count,PPMS Status (code),System Temp. (K),System Field (Oe),Sample Position (deg),Bridge 1 Resistance (ohms),Bridge 1 Excitation (에),Bridge 2 Resistance (ohms),Bridge 2 Excitation (에),Bridge 3 Resistance (ohms),Bridge 3 Excitation (에),Bridge 4 Resistance (ohms),Bridge 4 Excitation (에),Signal 1 Vin (V),Signal 2 Vin (V),Digital Inputs (code),Drive 1 Iout (mA),Drive 1 Ipower (W),Drive 2 Iout (mA),Drive 2 Ipower (W),Pressure (),Map 20 (),Map 21 (),Map 22 (),Map 23 (),Map 24 (),Map 25 (),Map 26 (),Map 27 (),Map 28 (),Map 29 ()
,28524573.66,200.2307281,-0.182685270905495,,,2,,,,14.9700001132488,,,,,,,200.2307281,200.2307281,-0.182685270905495,-0.182685270905495,,,22.529354,,,,-99999999,4385,200.1396,-0.182685270905495,,,,,,,,,,,,,,,,,,,,,,,200.2307281,,,,
,28524733.735,200.140625,4840.55102539063,-7.13800855041575E-6,4.9332034913539E-7,1,0.999253354069792,40.0298881530762,1.9970019803652,14.9600002914667,-8.07073121089379E-5,-1.56972555017073E-5,0.25,-1.43654212185077E-7,-7.1624572100692E-6,-1.51897716247409E-7,200.140625,200.140625,4835.62255859375,4845.4794921875,56.6774471864675,20.598005766863,22.529354,0,0,0,40,4449,199.93525,4840.55102539063,,,,,,,,,,,,,0,,,,0,,,,,,200.140625,,,,
,28524838.495,200.0775299,10074.5234375,-2.0051929375465E-5,6.91522550842667E-7,1,0.999253354069792,40.0298881530762,1.99713936285972,14.9600002914667,-0.00022813350791968,-3.60564190881179E-5,0.25,3.05232373918923E-7,-2.01214247638998E-5,2.84544949748573E-7,200.0775299,200.0775299,10067.2744140625,10081.7724609375,56.926005055583,20.6009197151579,22.149702,0,0,0,40,4449,199.8837,10074.5234375,,,,,,,,,,,,,0,,,,-0.0049,,,,,,200.0775299,,,,
,28524940.705,200.0323181,15181.97265625,-3.49376711712577E-5,1.09475748862167E-6,1,0.999253354069792,40.0298881530762,1.99731821293129,14.9600002914667,-0.000395724482265959,-7.31966161695918E-5,0.25,-3.81857255028296E-7,-3.50578284473775E-5,-4.20993837948311E-7,200.0323181,200.0323181,15174.4208984375,15189.5244140625,57.1112510146407,20.6029641425871,22.529354,0,0,0,40,4449,199.87455,15181.97265625,,,,,,,,,,,,,0,,,,-0.0049,,,,,,200.0323181,,,,
,28525042.25,200.0081253,20259.0556640625,-4.89416068512596E-5,1.49680513334657E-6,1,0.999253354069792,40.0298881530762,1.99721297966814,14.9600002914667,-0.000556031349458372,-9.26428905642852E-5,0.25,3.36349264166227E-7,-4.91109218859042E-5,2.84626985864432E-7,200.0074005,200.0088501,20251.642578125,20266.46875,56.9111541137176,20.6013187258429,22.149702,0,0,0,40,4449,199.87735,20259.0556640625,,,,,,,,,,,,,0,,,,0,,,,,,200.0081253,,,,
,28525144.61,199.9994507,25374.1943359375,-6.4876228615272E-5,1.7899547005435E-6,1,0.999253354069792,40.0298881530762,1.99733299561277,14.9600002914667,-0.000736474212825519,-0.000126468816919517,0.25,1.23584089821223E-7,-6.51003598774581E-5,5.4043585278507E-8,199.9993439,199.9995575,25369.193359375,25379.1953125,57.0112025641791,20.6004574897169,22.529354,0,0,0,40,4449,199.8857,25374.1943359375,,,,,,,,,,,,,0,,,,0.0049,,,,,,199.9994507,,,,
,28525249.655,199.9914398,30624.0078125,-7.85219235328697E-5,1.17361607782385E-6,1,0.999253354069792,40.0298881530762,1.99749930722306,14.9600002914667,-0.000892076479605864,-0.000149482430799556,0.25,4.66556973194671E-7,-7.87935839584283E-5,3.8365465088127E-7,199.9914398,199.9914398,30616.359375,30631.65625,57.024490249006,20.6029346758445,22.909004,0,0,0,40,4449,199.88935,30624.0078125,,,,,,,,,,,,,0,,,,0,,,,,,199.9914398,,,,
,28525353.15,199.9884949,35796.388671875,-9.63415277634431E-5,1.9734129208183E-6,1,0.999253354069792,40.0298881530762,1.9973901591475,14.9600002914667,-0.00109146091098634,-0.00020069787449797,0.25,-9.52351154610137E-7,-9.66732404330648E-5,-1.05911623317134E-6,199.9884949,199.9884949,35789.00390625,35803.7734375,57.1276652135445,20.6024969862492,22.149702,0,0,0,40,4449,199.9005,35796.388671875,,,,,,,,,,,,,0,,,,0,,,,,,199.9884949,,,,
,28525459.04,199.9891815,41086.396484375,-0.000113327072464715,1.75322195357798E-6,1,0.999253354069792,40.0298881530762,1.99724145863402,14.9600002914667,-0.00128295087728448,-0.000240958622771135,0.25,-1.55173519684018E-6,-0.000113716844750299,-1.67854633203498E-6,199.9891815,199.9891815,41076.21484375,41096.578125,57.0471574760637,20.6031324533446,22.149702,0,0,0,40,4449,199.9128,41086.396484375,,,,,,,,,,,,,0,,,,0,,,,,,199.9891815,,,,
,28525564.365,199.995636,46351.154296875,-0.000128715357091571,1.83348621466073E-6,1,0.999253354069792,40.0298881530762,1.99722594902323,14.9600002914667,-0.00146059238413727,-0.000253841349202491,0.25,-1.48742535130653E-8,-0.000129159944173889,-1.52569466501757E-7,199.995636,199.995636,46348.93359375,46353.375,56.976810909333,20.6054571398763,22.529354,0,0,0,40,4449,199.9131,46351.154296875,,,,,,,,,,,,,0,,,,0,,,,,,199.995636,,,,
,28525665.015,199.9979553,51383.775390625,-0.000143799737633372,1.88823537804369E-6,1,0.999253354069792,40.0298881530762,1.99733010305195,14.9600002914667,-0.00162794679582803,-0.000306040284200976,0.25,-1.99404029101867E-6,-0.000144294352851041,-2.15437805114564E-6,199.9979553,199.9979553,51376.296875,51391.25390625,57.2871174314676,20.6037839571396,22.529354,0,0,0,40,4449,199.9133,51383.775390625,,,,,,,,,,,,,0,,,,0,,,,,,199.9979553,,,,
,28525767.96,200.0027161,56528.52734375,-0.000158917766206532,2.19771316801042E-6,1,0.999253354069792,40.0298881530762,1.99727785491032,14.9600002914667,-0.00180292621526749,-0.000315901051165871,0.25,-2.38441923697515E-7,-0.000159466507734364,-4.08478999358484E-7,200.0027161,200.0027161,56523.359375,56533.6953125,57.0823307594291,20.6043839822136,22.529354,0,0,0,40,4449,199.9094,56528.52734375,,,,,,,,,,,,,0,,,,-0.0049,,,,,,200.0027161,,,,
,28525870.82,200.0025177,61668.4921875,-0.000178242105913215,2.01065739255229E-6,1,0.999253354069792,40.0298881530762,1.99726055340902,14.9600002914667,-0.00201890618295925,-0.000372963248783895,0.25,-1.91147226579824E-6,-0.000178855890834365,-2.10744186369245E-6,200.0025177,200.0025177,61661.14453125,61675.83984375,57.0666981890445,20.6043659892253,22.149702,0,0,0,40,4449,199.9099,61668.4921875,,,,,,,,,,,,,0,,,,0,,,,,,200.0025177,,,,
,28525970.57,200.0037384,66656.5625,-0.000194256710931893,2.10388939459701E-6,1,0.999253354069792,40.0298881530762,1.99720047925828,14.9600002914667,-0.0021991541573597,-0.000412698793256996,0.25,-2.63331538482205E-6,-0.000194925121246183,-2.8483470169557E-6,200.0037384,200.0037384,66649.125,66664,57.2394380917945,20.6047673094169,22.529354,0,0,0,40,4449,199.9046,66656.5625,,,,,,,,,,,,,0,,,,0,,,,,,200.0037384,,,,
,28526074.235,200.006012,71836.90625,-0.000207402696053424,2.98848466964658E-6,1,0.999253354069792,40.0298881530762,1.99707748057558,14.9600002914667,-0.00234383639236188,-0.000463660206490644,0.25,-4.84415494604571E-6,-0.000208114252974484,-5.08026471997148E-6,200.006012,200.006012,71831.6953125,71842.1171875,57.2456911199484,20.6070239522778,22.149702,0,0,0,40,4449,199.8972,71836.90625,,,,,,,,,,,,,0,,,,0,,,,,,200.006012,,,,
,28526173.285,200.0107727,76787.40625,-0.000221604134359117,1.64709692297366E-6,1,0.999253354069792,40.0298881530762,1.99729870657538,14.9600002914667,-0.00250721954342046,-0.000480322943999748,0.25,-3.8424053922448E-6,-0.000222365871368891,-4.0895645306845E-6,200.0107727,200.0107727,76774.9609375,76799.8515625,57.2417829773522,20.6031763316445,22.149702,0,0,0,40,4449,199.88785,76787.40625,,,,,,,,,,,,,0,,,,0,,,,,,200.0107727,,,,
,28526277.12,200.0098877,81980.5,-0.00023817423737504,2.55626089660125E-6,1,0.999253354069792,40.0298881530762,1.9971531440631,14.9600002914667,-0.00269894242062437,-0.000490659526461439,0.25,-1.87927411450858E-6,-0.000238995402411602,-2.13655575548424E-6,200.0098877,200.0098877,81973.0078125,81987.9921875,57.1581487257945,20.6049453864078,22.149702,0,0,0,40,4449,199.87895,81980.5,,,,,,,,,,,,,0,,,,0,,,,,,200.0098877,,,,
,28526376.85,200.0089417,86965.734375,-0.000251193379737357,3.40036821832008E-6,1,0.999253354069792,40.0298881530762,1.99709139661385,14.9600002914667,-0.00284654380050474,-0.000516578345384841,0.25,-1.90445451349775E-6,-0.000252059611292409,-2.17493420153549E-6,200.0089417,200.0089417,86955.7421875,86975.7265625,56.9791557948906,20.6032364639986,22.149702,0,0,0,40,4449,199.8728,86965.734375,,,,,,,,,,,,,0,,,,0,,,,,,200.0089417,,,,
,28526484.625,200.0094147,88580.09765625,-0.00026155615812346,2.01562350441183E-6,1,0.999253354069792,40.0298881530762,1.99689791847238,14.9600002914667,-0.00295728619276186,-0.00057478475060875,0.25,-5.23943881661984E-6,-0.000262454731272425,-5.53214216816632E-6,200.0094147,200.0094147,88572.765625,88587.4296875,56.8705094307176,20.6058295549504,22.909004,0,0,0,40,4449,199.8636,88580.09765625,,,,,,,,,,,,,0,,,,0,,,,,,200.0094147,,,,
,28526577.525,200.0032959,83936.53515625,-0.000243711845941452,2.38787782822467E-6,1,0.999253354069792,40.0298881530762,1.99720029361858,14.9600002914667,-0.00276146099135105,-0.000503781596891967,0.25,-2.07321886421174E-6,-0.000244552029948118,-2.33679379717615E-6,200.0032043,200.0033875,83934.015625,83939.0546875,57.0299616486406,20.6053264870135,22.909004,0,0,0,40,4449,199.8645,83936.53515625,,,,,,,,,,,,,0,,,,0,,,,,,200.0032959,,,,
,28526678.57,199.9945068,78885.4375,-0.000228589777601951,3.2581191457802E-6,1,0.999253354069792,40.0298881530762,1.99692719714357,14.9600002914667,-0.00258380742198891,-0.000506835901421365,0.25,-4.97371032778861E-6,-0.000229374617655655,-5.23195099351003E-6,199.9945068,199.9945068,78875.515625,78895.359375,57.0198004778906,20.6051190544824,22.909004,0,0,0,40,4449,199.8697,78885.4375,,,,,,,,,,,,,0,,,,-0.00245,,,,,,199.9945068,,,,
,28526775.075,199.9925842,74059.33203125,-0.000214219564577958,2.34966489897373E-6,1,0.999253354069792,40.0298881530762,1.99725999979197,14.9600002914667,-0.00242424293232524,-0.000460761568394611,0.25,-3.40150350121511E-6,-0.000214956331093869,-3.63963588015962E-6,199.9925842,199.9925842,74046.8203125,74071.84375,57.1284468420637,20.6045180995497,22.529354,0,0,0,40,4449,199.88105,74059.33203125,,,,,,,,,,,,,0,,,,0.00245,,,,,,199.9925842,,,,
,28526872.55,199.9915161,69188.80859375,-0.000195913741458805,2.80755382174905E-6,1,0.999253354069792,40.0298881530762,1.997239070228,14.9600002914667,-0.00221532071106632,-0.000431397942372354,0.25,-3.99288541939299E-6,-0.00019658654949936,-4.21416548287745E-6,199.9915161,199.9915161,69183.78125,69193.8359375,57.1182856713137,20.6040094777133,22.909004,0,0,0,40,4449,199.8841,69188.80859375,,,,,,,,,,,,,0,,,,0,,,,,,199.9915161,,,,
,28526974.58,199.9907074,64088.486328125,-0.000181414034361097,2.17303549446662E-6,1,0.999253354069792,40.0298881530762,1.99709873418653,14.9600002914667,-0.00204854539585139,-0.000414872835199089,0.25,-5.05676001071803E-6,-0.000182035539068137,-5.2667860330216E-6,199.9907074,199.9907074,64085.93359375,64091.0390625,57.2363115777176,20.6060218906417,22.149702,0,0,0,40,4449,199.89135,64088.486328125,,,,,,,,,,,,,0,,,,-0.00245,,,,,,199.9907074,,,,
,28527073.99,199.9911804,59118.458984375,-0.000168965398526324,2.50248191709468E-6,1,0.999253354069792,40.0298881530762,1.99703209512675,14.9600002914667,-0.00190730699734232,-0.000389879084968442,0.25,-5.01672709442981E-6,-0.000169543860808765,-5.21378010842915E-6,199.9911804,199.9911804,59108.26171875,59128.65625,57.1073428720445,20.6070787511474,22.529354,0,0,0,40,4449,199.90105,59118.458984375,,,,,,,,,,,,,0,,,,0,,,,,,199.9911804,,,,
,28527172.74,199.9875336,54185.572265625,-0.000150629259219605,2.4974807938924E-6,1,0.999253354069792,40.0298881530762,1.99715245933496,14.9600002914667,-0.00170327535092463,-0.000331166811157202,0.25,-3.02472520780527E-6,-0.000151146450113832,-3.19572193768233E-6,199.9875336,199.9875336,54180.40234375,54190.7421875,57.1104693861214,20.6065256953494,22.529354,0,0,0,40,4449,199.91245,54185.572265625,,,,,,,,,,,,,0,,,,-0.00245,,,,,,199.9875336,,,,
,28527271.345,199.9893646,49255.443359375,-0.00013497329916991,1.92124209453064E-6,1,0.999253354069792,40.0298881530762,1.99727844925475,14.9600002914667,-0.00152524245985113,-0.000303044465277446,0.25,-3.2634889680248E-6,-0.000135436087029489,-3.41891746183339E-6,199.9893646,199.9893646,49252.87890625,49258.0078125,57.2495992625445,20.6060618216454,22.529354,0,0,0,40,4449,199.91985,49255.443359375,,,,,,,,,,,,,0,,,,0,,,,,,199.9893646,,,,
,28527367.665,199.9890137,44439.87890625,-0.000122002941371044,2.21059739013728E-6,1,0.999253354069792,40.0298881530762,1.99714992718814,14.9600002914667,-0.00137648254705657,-0.000286029428266099,0.25,-4.01800610079758E-6,-0.000122420072876619,-4.16243953730927E-6,199.9890137,199.9890137,44434.97265625,44444.78515625,57.2574155477368,20.6078774953114,22.529354,0,0,0,40,4449,199.9319,44439.87890625,,,,,,,,,,,,,0,,,,0.0049,,,,,,199.9890137,,,,
,28527464.47,199.9878235,39602.21484375,-0.000106763845903969,1.7611666563112E-6,1,0.999253354069792,40.0298881530762,1.99730128174717,14.9600002914667,-0.00120808209794165,-0.00023047899472495,0.25,-1.76748657872223E-6,-0.000107130713762502,-1.88806091312689E-6,199.9878235,199.9878235,39592.18359375,39612.24609375,57.3183825722368,20.6067252593447,22.909004,0,0,0,40,4449,199.9371,39602.21484375,,,,,,,,,,,,,0,,,,0.0049,,,,,,199.9878235,,,,
,28527559.405,199.9893646,34857.400390625,-9.1739236733478E-5,1.73997598650421E-6,1,0.999253354069792,40.0298881530762,1.9972453700497,14.9600002914667,-0.00104133390729134,-0.000179094195017093,0.25,1.50892648868562E-7,-9.20562353062464E-5,5.28711037307677E-8,199.9893646,199.9893646,34855.2578125,34859.54296875,57.2495992625445,20.6090181553413,22.909004,0,0,0,40,4449,199.94445,34857.400390625,,,,,,,,,,,,,0,,,,-0.0049,,,,,,199.9893646,,,,
,28527657.055,199.9882507,29977.3564453125,-7.82045427809274E-5,1.87562664191837E-6,1,0.999253354069792,40.0298881530762,1.99718324675418,14.9600002914667,-0.000883230512006759,-0.000178255539773972,0.25,-2.12621399711479E-6,-7.8472326830091E-5,-2.21771718269617E-6,199.9882507,199.9882507,29967.140625,29987.572265625,57.1909771236022,20.6090105968678,22.909004,0,0,0,40,4449,199.9513,29977.3564453125,,,,,,,,,,,,,0,,,,0,,,,,,199.9882507,,,,
,28527752.67,199.9866943,25197.2236328125,-6.29232549675065E-5,1.46688274495015E-6,1,0.999253354069792,40.0298881530762,1.99705987099721,14.9600002914667,-0.000709904546488493,-0.000147441782897372,0.25,-2.06545804882971E-6,-6.31383138380688E-5,-2.14042434733913E-6,199.9866943,199.9866943,25194.828125,25199.619140625,57.3949821671215,20.6117046535196,22.529354,0,0,0,40,4449,199.9606,25197.2236328125,,,,,,,,,,,,,0,,,,0,,,,,,199.9866943,,,,
,28527849.63,199.9892731,20354.95703125,-4.93185381378514E-5,1.13937746996028E-6,1,0.999253354069792,40.0298881530762,1.99721263266828,14.9600002914667,-0.000557047163077252,-0.000112165498362208,0.25,-1.31863121835403E-6,-4.94874025202076E-5,-1.37644261467332E-6,199.9892731,199.9892731,20347.359375,20362.5546875,57.1886322380445,20.6084250309841,22.529354,0,0,0,40,4449,199.9693,20354.95703125,,,,,,,,,,,,,0,,,,0,,,,,,199.9892731,,,,
,28527944.455,199.9914093,15612.7963867188,-3.57468428688083E-5,1.32451284460483E-6,1,0.999253354069792,40.0298881530762,1.99724429717822,14.9600002914667,-0.000403191772845605,-8.45858742041569E-5,0.25,-1.24522043109635E-6,-3.58689119475237E-5,-1.28818432360404E-6,199.9914093,199.9914093,15610.423828125,15615.1689453125,57.3981086811984,20.611598248565,22.529354,0,0,0,40,4449,199.9754,15612.7963867188,,,,,,,,,,,,,0,,,,0.0049,,,,,,199.9914093,,,,
,28528043,199.9922791,10688.0048828125,-2.14156095408635E-5,9.96871882184247E-7,1,0.999253354069792,40.0298881530762,1.99720004371277,14.9600002914667,-0.000240735685530263,-5.53235950616443E-5,0.25,-1.15575055559174E-6,-2.14882888630651E-5,-1.18294060581603E-6,199.9922791,199.9922791,10678.21484375,10697.794921875,57.3316702570638,20.6100296317888,22.909004,0,0,0,40,4449,199.9817,10688.0048828125,,,,,,,,,,,,,0,,,,-0.0049,,,,,,199.9922791,,,,
,28528140.98,199.9928131,5789.94311523437,-8.89498157002204E-6,5.89239497129161E-7,1,0.999253354069792,40.0298881530762,1.99716799528107,14.9600002914667,-0.000100841506040924,-1.80649104890446E-5,0.25,-4.70264115336826E-8,-8.9256358297519E-6,-5.68384234976089E-8,199.9928131,199.9928131,5780.04052734375,5799.845703125,57.3754414541407,20.6112961630637,22.529354,0,0,0,40,4449,199.99135,5789.94311523437,,,,,,,,,,,,,0,,,,0.00245,,,,,,199.9928131,,,,
,28528239.67,199.9950409,856.913269042969,2.12704878448778E-6,3.12482966062717E-7,1,0.999253354069792,40.0298881530762,1.99704679514334,14.9600002914667,2.41414257615911E-5,4.15440422268464E-6,0.25,-3.31583206649236E-9,2.13439434518027E-6,-1.01699941399188E-9,199.9950409,199.9950409,851.94189453125,861.884643554687,57.2284952925253,20.6163804971202,22.909004,0,0,0,40,4449,199.9935,856.913269042969,,,,,,,,,,,,,0,,,,0,,,,,,199.9950409,,,,
,28528331.2,199.9932861,-3711.66564941406,5.17981173788686E-6,3.95745315585642E-7,1,0.999253354069792,40.0298881530762,1.99713908192327,14.9600002914667,5.89431295573036E-5,9.24752751681762E-6,0.25,-8.47216881747636E-8,5.19778379364035E-6,-7.93920581184339E-8,199.9932861,199.9932861,-3721.85717773438,-3701.47412109375,57.3277621144676,20.6132195047369,22.909004,0,0,0,40,4449,200.00095,-3711.66564941406,,,,,,,,,,,,,0,,,,0,,,,,,199.9932861,,,,
,28528428.85,199.9979248,-8598.04443359375,1.67467360107474E-5,8.62452933504105E-7,1,0.999253354069792,40.0298881530762,1.99731531048283,14.9600002914667,0.000188870479837984,3.97647732151483E-5,0.25,5.95356010987962E-7,1.6803899545707E-5,6.15563037477201E-7,199.9979248,199.9979248,-8605.552734375,-8590.5361328125,57.4410982497561,20.6114677950738,22.909004,0,0,0,40,4449,199.9994,-8598.04443359375,,,,,,,,,,,,,0,,,,-0.00245,,,,,,199.9979248,,,,
,28528522.57,200.0029907,-13278.640625,2.92939641546977E-5,8.13569386273589E-7,1,0.999253354069792,40.0298881530762,1.99726755012579,14.9600002914667,0.000332278436426014,5.85755488280413E-5,0.25,7.38118828158637E-8,2.93950073751835E-5,1.05772441947022E-7,200.0029907,200.0029907,-13283.70703125,-13273.57421875,57.4231207938138,20.6142556860957,22.909004,0,0,0,40,4449,199.9959,-13278.640625,,,,,,,,,,,,,0,,,,0.0049,,,,,,200.0029907,,,,
,28528618.545,200.0074921,-18076.3095703125,4.17114311805683E-5,8.90894405078371E-7,1,0.999253354069792,40.0298881530762,1.99730624799937,14.9600002914667,0.000472378519599022,8.7775423815768E-5,0.25,4.90137382540382E-7,4.18548940135251E-5,5.36904649362413E-7,200.0074921,200.0074921,-18081.451171875,-18071.16796875,57.4067065949099,20.6144774952189,22.909004,0,0,0,40,4449,199.9853,-18076.3095703125,,,,,,,,,,,,,0,,,,0,,,,,,200.0074921,,,,
,28528712.105,200.009079,-22751.2509765625,5.64982180162797E-5,1.26882955998707E-6,1,0.999253354069792,40.0298881530762,1.99723523172051,14.9600002914667,0.000639754570988308,0.000119242198538673,0.25,6.95206186877657E-7,5.66925177819293E-5,7.5856123741363E-7,200.009079,200.009079,-22753.828125,-22748.673828125,57.3340151426215,20.6151031781667,22.909004,0,0,0,40,4449,199.9797,-22751.2509765625,,,,,,,,,,,,,0,,,,0.00245,,,,,,200.009079,,,,
,28528808.32,200.0085754,-27561.513671875,7.02859722661158E-5,1.72099381269095E-6,1,0.999253354069792,40.0298881530762,1.99723372983162,14.9600002914667,0.000792438751470472,0.000168150411331022,0.25,2.61059362743042E-6,7.05258302090595E-5,2.69530818171877E-6,200.0085754,200.0085754,-27566.580078125,-27556.447265625,57.3371416566984,20.6148526595584,22.529354,0,0,0,40,4449,199.9667,-27561.513671875,,,,,,,,,,,,,0,,,,0,,,,,,200.0085754,,,,
,28528905.46,200.0113831,-32415.845703125,8.67959735763107E-5,1.43985163684112E-6,1,0.999253354069792,40.0298881530762,1.99717283674243,14.9600002914667,0.000981482817354448,0.000190770286372966,0.25,1.73709878970954E-6,8.70937950476649E-5,1.83641008898118E-6,200.0113831,200.0113831,-32418.4140625,-32413.27734375,57.2621053188522,20.6156870196257,22.529354,0,0,0,40,4449,199.9594,-32415.845703125,,,,,,,,,,,,,0,,,,-0.0049,,,,,,200.0113831,,,,
,28529003.395,200.0131073,-37310.375,0.000100707413226888,1.96202264557163E-6,1,0.999253354069792,40.0298881530762,1.99721625620216,14.9600002914667,0.00113683748411315,0.000232744938291705,0.25,3.01978706859416E-6,0.000101051918500113,3.1382846341911E-6,200.0131073,200.0131073,-37315.46875,-37305.28125,57.3316702570638,20.6170069942312,22.529354,0,0,0,40,4449,199.9449,-37310.375,,,,,,,,,,,,,0,,,,0.0049,,,,,,200.0131073,,,,
,28529100.6,200.0157623,-42170.392578125,0.000115388220502297,1.4012705988399E-6,1,0.999253354069792,40.0298881530762,1.9972286017924,14.9600002914667,0.0013056315534921,0.000249047924138898,0.25,1.90683924828988E-6,0.000115784641591802,2.03701241538163E-6,200.0157623,200.0157623,-42177.64453125,-42163.140625,57.268358347006,20.6182494292403,22.909004,0,0,0,40,4449,199.93525,-42170.392578125,,,,,,,,,,,,,0,,,,-0.0049,,,,,,200.0157623,,,,
,28529198.875,200.0111389,-47080.52734375,0.000131455204064071,1.26538928126935E-6,1,0.999253354069792,40.0298881530762,1.99721116149771,14.9600002914667,0.00148756920440127,0.000282863206588852,0.25,2.09678697801556E-6,0.000131906969918184,2.24454831268471E-6,200.0111389,200.0111389,-47090.6796875,-47070.375,57.3230723433522,20.6195320211128,22.149702,0,0,0,40,4449,199.92615,-47080.52734375,,,,,,,,,,,,,0,,,,0,,,,,,200.0111389,,,,
,28529290.265,200.0163727,-51647.568359375,0.000143586749543157,2.20692562682755E-6,1,0.999253354069792,40.0298881530762,1.99736713215051,14.9600002914667,0.00162134656707747,0.000329872575825999,0.25,4.13063664707495E-6,0.000144078265001723,4.29810493516625E-6,200.0163727,200.0163727,-51652.46875,-51642.66796875,57.4450063923522,20.6177992546282,22.909004,0,0,0,40,4449,199.9167,-51647.568359375,,,,,,,,,,,,,0,,,,-0.00245,,,,,,200.0163727,,,,
,28529388.515,200.0139618,-56557.07421875,0.00016307904053465,2.24746192222492E-6,1,0.999253354069792,40.0298881530762,1.99737850711695,14.9600002914667,0.00184534779450309,0.000352267472278766,0.25,2.71893072763362E-6,0.000163639455283397,2.90196876661983E-6,200.0139618,200.0139618,-56559.5703125,-56554.578125,57.2980602307368,20.6184528810898,22.909004,0,0,0,40,4449,199.9054,-56557.07421875,,,,,,,,,,,,,0,,,,-0.00245,,,,,,200.0139618,,,,
,28529487.41,200.0133972,-61499.078125,0.000177209944975602,2.20323390093186E-6,1,0.999253354069792,40.0298881530762,1.99735560637789,14.9600002914667,0.00200483722842865,0.000385033072956769,0.25,3.15278688342903E-6,0.000177818776727639,3.35197488305073E-6,200.0133972,200.0133972,-61506.56640625,-61491.58984375,57.4379717356792,20.6196006730611,22.909004,0,0,0,40,4449,199.89805,-61499.078125,,,,,,,,,,,,,0,,,,-0.0049,,,,,,200.0133972,,,,
,28529586.25,200.0140686,-66439.09765625,0.000193907765257056,2.52121033466349E-6,1,0.999253354069792,40.0298881530762,1.99749079131489,14.9600002914667,0.00218914702919488,0.000448639391046922,0.25,5.85565043077541E-6,0.000194571479938469,6.08148722588687E-6,200.0140686,200.0140686,-66444.0703125,-66434.125,57.3895107674868,20.6190604920281,22.529354,0,0,0,40,4449,199.88575,-66439.09765625,,,,,,,,,,,,,0,,,,0,,,,,,200.0140686,,,,
,28529686.275,200.0118561,-71438.58203125,0.00020905197777521,2.06306904835951E-6,1,0.999253354069792,40.0298881530762,1.99743164599183,14.9600002914667,0.00235627367192796,0.000505432940347262,0.25,8.23155353360442E-6,0.00020976559712824,8.48118356046417E-6,200.0118561,200.0118561,-71446.1953125,-71430.96875,57.3410497992945,20.6181150353669,22.529354,0,0,0,40,4449,199.87255,-71438.58203125,,,,,,,,,,,,,0,,,,0.0049,,,,,,200.0118561,,,,
,28529783.085,200.0105591,-76277.90625,0.000224811154480302,2.29026987709851E-6,1,0.999253354069792,40.0298881530762,1.9975943404493,14.9600002914667,0.00254004493641543,0.000509327489885209,0.25,5.83493527928244E-6,0.000225581857150595,6.0924552871938E-6,200.0105591,200.0105591,-76282.9296875,-76272.8828125,57.4199942797368,20.6189147585145,22.529354,0,0,0,40,4449,199.8628,-76277.90625,,,,,,,,,,,,,0,,,,0.0049,,,,,,200.0105591,,,,
,28529881.79,200.0119019,-81210.63671875,0.000240489339408336,2.50386655379332E-6,1,0.999253354069792,40.0298881530762,1.99759967375315,14.9600002914667,0.00272447880525477,0.000502899493416654,0.25,2.54632696194647E-6,0.000241317767474772,2.80847899823157E-6,200.0119019,200.0119019,-81215.734375,-81205.5390625,57.2480360055061,20.6184571767874,22.529354,0,0,0,40,4449,199.854,-81210.63671875,,,,,,,,,,,,,0,,,,-0.0049,,,,,,200.0119019,,,,
,28529978.47,200.013382,-86039.66015625,0.00025554743199698,2.72772229730511E-6,1,0.999253354069792,40.0298881530762,1.99751104370803,14.9600002914667,0.00289229068105517,0.000549671640975846,0.25,4.05495415896712E-6,0.000256426388928426,4.33761155010911E-6,200.013382,200.013382,-86042.1875,-86037.1328125,57.075296102756,20.6192547529027,22.149702,0,0,0,40,4449,199.8381,-86039.66015625,,,,,,,,,,,,,0,,,,0,,,,,,200.013382,,,,
,28530086.335,200.0131912,-89577.8203125,0.000267649060673957,2.39679228988711E-6,1,0.999253354069792,40.0298881530762,1.9974492598638,14.9600002914667,0.0030249772742994,0.000599820623614746,0.25,6.37411815059423E-6,0.000268567481815265,6.67706479358484E-6,200.0130615,200.0133209,-89610.046875,-89545.59375,57.3957637956407,20.6206230497923,22.149702,0,0,0,40,4449,199.8306,-89577.8203125,,,,,,,,,,,,,0,,,,-0.00245,,,,,,200.0131912,,,,
,28530180.735,200.0043335,-84863.1015625,0.00025069944002749,3.93303042990725E-6,1,0.999253354069792,40.0298881530762,1.9973941296956,14.9600002914667,0.00283007359980246,0.000580614427002272,0.25,7.62593315225399E-6,0.000251557935112131,7.91599574353301E-6,200.0043335,200.0043335,-84865.65625,-84860.546875,57.2777378892368,20.6201585662258,22.909004,0,0,0,40,4449,199.829,-84863.1015625,,,,,,,,,,,,,0,,,,0,,,,,,200.0043335,,,,
,28530276.74,199.998764,-80065.25,0.000237230184466246,2.31428959359512E-6,1,0.999253354069792,40.0298881530762,1.99739868567779,14.9600002914667,0.00268269779865921,0.000522532210176761,0.25,4.84633967849088E-6,0.000238045002569446,5.11317197989388E-6,199.998764,199.998764,-80072.7109375,-80057.7890625,57.4176493941791,20.6203505291367,22.529354,0,0,0,40,4449,199.83275,-80065.25,,,,,,,,,,,,,0,,,,-0.0049,,,,,,199.998764,,,,
,28530375.61,199.9907608,-75123.5625,0.000223336395954082,2.63333499529767E-6,1,0.999253354069792,40.0298881530762,1.99743977492029,14.9600002914667,0.00252832892134603,0.000476399485017193,0.25,3.19274792785039E-6,0.000224104913652687,3.43973934241242E-6,199.9905243,199.9909973,-75131,-75116.125,57.4786164186792,20.6196184061239,22.529354,0,0,0,40,4449,199.8394,-75123.5625,,,,,,,,,,,,,0,,,,0,,,,,,199.9907608,,,,
,28530473.97,199.9894409,-70208.75,0.000204455632883864,1.85815549979267E-6,1,0.999253354069792,40.0298881530762,1.99753245009662,14.9600002914667,0.0023124889561705,0.000448800093498726,0.25,4.03750232170057E-6,0.00020515793583329,4.26792761649876E-6,199.9894409,199.9894409,-70218.921875,-70198.578125,57.3535558556022,20.6186145549859,22.909004,0,0,0,40,4449,199.85135,-70208.75,,,,,,,,,,,,,0,,,,-0.00245,,,,,,199.9894409,,,,
,28530569.775,199.9916458,-65419.306640625,0.000191198642466093,3.17248528438124E-6,1,0.999253354069792,40.0298881530762,1.99745786183051,14.9600002914667,0.00216242745406309,0.000419919040653236,0.25,3.79594207395405E-6,0.000191855301981292,4.01192362902498E-6,199.9911804,199.9921112,-65426.8828125,-65411.73046875,57.3308886285445,20.6169772084331,22.529354,0,0,0,40,4449,199.8541,-65419.306640625,,,,,,,,,,,,,0,,,,-0.00245,,,,,,199.9916458,,,,
,28530669.21,199.9896851,-60449.59765625,0.000174619080925308,1.54886570087858E-6,1,0.999253354069792,40.0298881530762,1.99749194017861,14.9600002914667,0.00197696722504286,0.000371878028593325,0.25,2.44126062142852E-6,0.000175219836285614,2.63536083253616E-6,199.9896851,199.9896851,-60454.58984375,-60444.60546875,57.3973270526791,20.6173419596401,22.529354,0,0,0,40,4449,199.8661,-60449.59765625,,,,,,,,,,,,,0,,,,-0.0049,,,,,,199.9896851,,,,
,28530767.33,199.990921,-55547.091796875,0.000156130229952717,2.64772053892818E-6,1,0.999253354069792,40.0298881530762,1.99733129378586,14.9600002914667,0.00176619684210535,0.000340024408821056,0.25,2.84745934797475E-6,0.000156666607720209,3.02364580675662E-6,199.990921,199.990921,-55551.84375,-55542.33984375,57.3746598256215,20.6184947806253,22.529354,0,0,0,40,4449,199.87675,-55547.091796875,,,,,,,,,,,,,0,,,,0,,,,,,199.990921,,,,
,28530865.425,199.9877167,-50643.109375,0.000144320202438212,2.30165448938629E-6,1,0.999253354069792,40.0298881530762,1.99732790811022,14.9600002914667,0.00163396684971658,0.000306403779562834,0.25,1.93562896451659E-6,0.000144816715118308,2.09639456271619E-6,199.9877167,199.9877167,-50645.41015625,-50640.80859375,57.2292769210445,20.6173237796729,22.529354,0,0,0,40,4449,199.8865,-50643.109375,,,,,,,,,,,,,0,,,,0,,,,,,199.9877167,,,,
,28530962.895,199.9884644,-45773.357421875,0.000128351073360002,1.74688315888692E-6,1,0.999253354069792,40.0298881530762,1.99742527600097,14.9600002914667,0.00144876149221893,0.000298267011186438,0.25,3.99053818310853E-6,0.000128790172730723,4.14162501850554E-6,199.9884644,199.9884644,-45783.3203125,-45763.39453125,57.3105662870445,20.6150655413549,22.909004,0,0,0,40,4449,199.8955,-45773.357421875,,,,,,,,,,,,,0,,,,-0.00245,,,,,,199.9884644,,,,
,28531061.345,199.98820495,-40853.15625,0.00011142169656552,1.77749751930759E-6,1,0.999253354069792,40.0298881530762,1.99736730130435,14.9600002914667,0.00126108469191934,0.000239061871853162,0.25,1.71422679587691E-6,0.000111804714922802,1.83957063846848E-6,199.9876404,199.9887695,-40855.890625,-40850.421875,57.3082214014868,20.6153842395028,22.529354,0,0,0,40,4449,199.91,-40853.15625,,,,,,,,,,,,,0,,,,-0.0049,,,,,,199.98820495,,,,
,28531157.815,199.9904175,-36030.7578125,9.99597942991856E-5,1.69551136086543E-6,1,0.999253354069792,40.0298881530762,1.99724415483155,14.9600002914667,0.00112964863622164,0.000223909946854811,0.25,2.37070308141666E-6,0.00010030247655881,2.48623578283075E-6,199.9904175,199.9904175,-36038.19921875,-36023.31640625,57.3433946848522,20.6121313965835,22.529354,0,0,0,40,4449,199.91115,-36030.7578125,,,,,,,,,,,,,0,,,,-0.0049,,,,,,199.9904175,,,,
,28531252.455,199.9913483,-31304.193359375,8.43075131648986E-5,1.62250270438896E-6,1,0.999253354069792,40.0298881530762,1.99724849311148,14.9600002914667,0.000954368295061897,0.000179608525463815,0.25,1.18501057834314E-6,8.45973821252322E-5,1.27980229658637E-6,199.9913483,199.9913483,-31306.853515625,-31301.533203125,57.2019199228714,20.6127148501003,23.288654,0,0,0,40,4449,199.92,-31304.193359375,,,,,,,,,,,,,0,,,,0.0049,,,,,,199.9913483,,,,
,28531347.89,199.9902954,-26531.544921875,6.68859344720652E-5,1.51866708225732E-6,1,0.999253354069792,40.0298881530762,1.99727336263914,14.9600002914667,0.000757224020367904,0.000142145803735975,0.25,9.09211028642879E-7,6.71159190339707E-5,9.84435722128355E-7,199.9902954,199.9902954,-26539.041015625,-26524.048828125,57.3410497992945,20.6124940056147,22.909004,0,0,0,40,4449,199.9267,-26531.544921875,,,,,,,,,,,,,0,,,,0,,,,,,199.9902954,,,,
,28531444.775,199.9897003,-21689.51953125,5.43844676855553E-5,1.29270282038874E-6,1,0.999253354069792,40.0298881530762,1.99727532319324,14.9600002914667,0.000613618109464165,0.000127528456817969,0.25,1.79228575472514E-6,5.45703143248904E-5,1.8571880405406E-6,199.9897003,199.9897003,-21697.056640625,-21681.982421875,57.3136928011214,20.6129058095757,22.909004,0,0,0,40,4449,199.93405,-21689.51953125,,,,,,,,,,,,,0,,,,-0.0049,,,,,,199.9897003,,,,
,28531540.47,199.9888763,-16907.0751953125,4.03489177730937E-5,1.34479418899794E-6,1,0.999253354069792,40.0298881530762,1.99712333011304,14.9600002914667,0.00045598699199766,9.02061728924792E-5,0.25,9.41648519697791E-7,4.04872091477758E-5,9.88531055459974E-7,199.9888763,199.9888763,-16914.4765625,-16899.673828125,57.1831608384099,20.6140289266784,22.909004,0,0,0,40,4449,199.94545,-16907.0751953125,,,,,,,,,,,,,0,,,,0,,,,,,199.9888763,,,,
,28531635.33,199.9905853,-12167.23828125,2.65128255074621E-5,9.56005517526638E-7,1,0.999253354069792,40.0298881530762,1.99723373299201,14.9600002914667,0.000299970560049858,5.73716269048066E-5,0.25,4.50830767493769E-7,2.66038679873932E-5,4.81101371642372E-7,199.9905853,199.9905853,-12177.201171875,-12157.275390625,57.2839909173907,20.6139592782326,22.909004,0,0,0,40,4449,199.9504,-12167.23828125,,,,,,,,,,,,,0,,,,0,,,,,,199.9905853,,,,
,28531732.61,199.9923859,-7304.05834960937,1.3067897595426E-5,6.20625980311618E-7,1,0.999253354069792,40.0298881530762,1.99734556538307,14.9600002914667,0.00014737065624423,3.10981123011439E-5,0.25,4.70572512959173E-7,1.31124978551203E-5,4.8637094845554E-7,199.9923859,199.9923859,-7313.88427734375,-7294.232421875,57.4270289364099,20.6110262935452,23.288654,0,0,0,40,4449,199.95205,-7304.05834960937,,,,,,,,,,,,,0,,,,-0.00245,,,,,,199.9923859,,,,
,28531829.495,199.9927979,-2460.77038574219,1.66854788865564E-6,3.21169980232506E-7,1,0.999253354069792,40.0298881530762,1.99726616069032,14.9600002914667,1.89586273139338E-5,3.14941300095009E-6,0.25,-1.22785145533155E-8,1.67432073219209E-6,-1.05088802795239E-8,199.9927979,199.9927979,-2465.81420898438,-2455.7265625,57.4231207938138,20.6111869799509,22.529354,0,0,0,40,4449,199.9615,-2460.77038574219,,,,,,,,,,,,,0,,,,0.0049,,,,,,199.9927979,,,,
,28531921.665,199.9924927,2143.47143554687,-1.36567770914801E-6,3.00608820395131E-7,1,0.999253354069792,40.0298881530762,1.99742742677967,14.9600002914667,-1.46767405957431E-5,-7.42426186001973E-6,0.25,-4.16987073486231E-7,-1.36993890076E-6,-4.19909626353646E-7,199.9924927,199.9924927,2138.51977539062,2148.42309570313,57.1065612435253,20.6108975702158,22.149702,0,0,0,40,4449,199.9638,2143.47143554687,,,,,,,,,,,,,0,,,,0.0049,,,,,,199.9924927,,,,
,28532019.445,199.9967194,7031.94018554687,-1.2246854674696E-5,6.28091793988808E-7,1,0.999253354069792,40.0298881530762,1.99732587985684,14.9600002914667,-0.000137508017120169,-3.26108925991394E-5,0.25,-7.46511880467528E-7,-1.22883196564831E-5,-7.62372059181368E-7,199.9967194,199.9967194,7026.92138671875,7036.958984375,57.2464727484676,20.6112733844585,22.529354,0,0,0,40,4449,199.9666,7031.94018554687,,,,,,,,,,,,,0,,,,0,,,,,,199.9967194,,,,
,28532113.1,199.9994812,11712.5043945313,-2.47532940824904E-5,1.00118107678549E-6,1,0.999253354069792,40.0298881530762,1.99726495591587,14.9600002914667,-0.00028021288231909,-5.27251303787307E-5,0.25,-3.46905044583522E-7,-2.48383671233451E-5,-3.74912589194679E-7,199.9994812,199.9994812,11705.2080078125,11719.80078125,57.0713879601599,20.6108327883095,23.288654,0,0,0,40,4449,199.96505,11712.5043945313,,,,,,,,,,,,,0,,,,0,,,,,,199.9994812,,,,
,28532209.08,200.0066833,16507.8505859375,-3.85906993914522E-5,1.35298033164887E-6,1,0.999253354069792,40.0298881530762,1.99729031397674,14.9600002914667,-0.000435663170592898,-8.90951535168883E-5,0.25,-1.14849033264289E-6,-3.87226732962574E-5,-1.1941883046717E-6,200.0066833,200.0066833,16498.02734375,16517.673828125,57.3316702570638,20.6106103547429,22.909004,0,0,0,40,4449,199.9549,16507.8505859375,,,,,,,,,,,,,0,,,,0.00245,,,,,,200.0066833,,,,
,28532306.375,200.0077515,21372.7939453125,-5.26333924854778E-5,7.31503491331431E-7,1,0.999253354069792,40.0298881530762,1.9973442602367,14.9600002914667,-0.000595156378413873,-0.000116077425784839,0.25,-1.08700290949783E-6,-5.28139227006819E-5,-1.14757987591434E-6,200.0077515,200.0077515,21370.1484375,21375.439453125,57.068261446083,20.6099552919612,22.909004,0,0,0,40,4449,199.94935,21372.7939453125,,,,,,,,,,,,,0,,,,-0.0049,,,,,,200.0077515,,,,
,28532402.49,200.0093994,26177.0546875,-6.63762529966244E-5,1.10939770604603E-6,1,0.999253354069792,40.0298881530762,1.99747835434299,14.9600002914667,-0.000750084207575433,-0.000149383290923449,0.25,-1.63423097217468E-6,-6.66036536421338E-5,-1.71141210773551E-6,200.0093994,200.0093994,26166.89453125,26187.21484375,57.3183825722368,20.6072630530239,22.909004,0,0,0,40,4449,199.94075,26177.0546875,,,,,,,,,,,,,0,,,,0,,,,,,200.0093994,,,,
,28532498.875,200.0099335,30992.9736328125,-8.13451210454914E-5,1.38935904072237E-6,1,0.999253354069792,40.0298881530762,1.99731087643247,14.9600002914667,-0.00092320872605102,-0.000159782996223821,0.25,4.79745964173114E-8,-8.1626035875948E-5,-3.93744597792846E-8,200.0099335,200.0099335,30985.173828125,31000.7734375,57.044812590506,20.6083608168083,22.909004,0,0,0,40,4449,199.9352,30992.9736328125,,,,,,,,,,,,,0,,,,0,,,,,,200.0099335,,,,
,28532598.22,200.0132751,35958.03125,-9.74423726261533E-5,1.33141252543261E-6,1,0.999253354069792,40.0298881530762,1.99755572620273,14.9600002914667,-0.00110412112182597,-0.000202418693938816,0.25,-9.11414993934599E-7,-9.7777854636139E-5,-1.01919878192071E-6,200.0132751,200.0132751,35948.0625,35968,57.2488176340253,20.6089875140744,22.529354,0,0,0,40,4449,199.9233,35958.03125,,,,,,,,,,,,,0,,,,-0.00735,,,,,,200.0132751,,,,
,28532696.26,200.01049805,40861.01171875,-0.000112652352150367,1.91507368416705E-6,1,0.999253354069792,40.0298881530762,1.99754847684488,14.9600002914667,-0.00127731357479329,-0.000229109232342673,0.25,-6.21753248919364E-7,-0.000113040709002781,-7.44642104440516E-7,200.0101471,200.010849,40856.1328125,40865.890625,56.9963516223137,20.607414530622,22.909004,0,0,0,40,4449,199.9095,40861.01171875,,,,,,,,,,,,,0,,,,-0.00245,,,,,,200.01049805,,,,
,28532792.695,200.0126953,45678.56640625,-0.000128796914992686,1.55280601230079E-6,1,0.999253354069792,40.0298881530762,1.99738438350164,14.9600002914667,-0.00145722604506071,-0.000279365011045555,0.25,-2.24805579001504E-6,-0.00012923931565881,-2.39359509020578E-6,200.0126953,200.0126953,45673.42578125,45683.70703125,57.0612267894099,20.6076628912294,22.909004,0,0,0,40,4449,199.90595,45678.56640625,,,,,,,,,,,,,0,,,,-0.00245,,,,,,200.0126953,,,,
,28532889.46,200.013031,50516.25390625,-0.000145837891335888,1.79348846644082E-6,1,0.999253354069792,40.0298881530762,1.99779483790284,14.9600002914667,-0.00165461726366287,-0.000291842743539913,0.25,-3.83225661329302E-7,-0.000146341182406585,-5.40246960004195E-7,200.013031,200.013031,50511.40625,50521.1015625,57.146424298006,20.6061749399848,22.909004,0,0,0,40,4449,199.8964,50516.25390625,,,,,,,,,,,,,0,,,,-0.00245,,,,,,200.013031,,,,
,28532985.385,200.01139835,55311.138671875,-0.000158702577174233,1.7385570724655E-6,1,0.999253354069792,40.0298881530762,1.99741278557189,14.9600002914667,-0.00179634029710403,-0.000340022613256973,0.25,-2.3994071330749E-6,-0.000159248210668975,-2.57679193421477E-6,200.0113373,200.0114594,55308.62890625,55313.6484375,56.9799374234099,20.6066039637297,22.909004,0,0,0,40,4449,199.8862,55311.138671875,,,,,,,,,,,,,0,,,,0,,,,,,200.01139835,,,,
,28533082.72,200.0120544,60173.541015625,-0.000173874455329703,1.95066937713336E-6,1,0.999253354069792,40.0298881530762,1.99744165229847,14.9600002914667,-0.00196815129759015,-0.000372222426916864,0.25,-2.60172680028696E-6,-0.000174472336828914,-2.79559748747429E-6,200.0120544,200.0120544,60165.83984375,60181.2421875,57.095618444256,20.6079219536688,22.909004,0,0,0,40,4449,199.8771,60173.541015625,,,,,,,,,,,,,0,,,,0,,,,,,200.0120544,,,,
,28533180.17,200.012146,65044.21484375,-0.000189227185409067,2.00208274292579E-6,1,0.999253354069792,40.0298881530762,1.99736578481689,14.9600002914667,-0.00214331129402378,-0.000396704791147437,0.25,-2.09436476916177E-6,-0.000189878706134486,-2.30239468402149E-6,200.012146,200.012146,65039.125,65049.3046875,56.9244417985445,20.606535512749,22.909004,0,0,0,40,4449,199.86375,65044.21484375,,,,,,,,,,,,,0,,,,0,,,,,,200.012146,,,,
,28533277.34,200.0123138,69902.20703125,-0.000206062440973801,2.49643710166602E-6,1,0.999253354069792,40.0298881530762,1.9973477126701,14.9600002914667,-0.0023352336988919,-0.000424770980761472,0.25,-1.64454556967699E-6,-0.000206772669893416,-1.8684303975535E-6,200.0123138,200.0123138,69897.0859375,69907.328125,56.997133250833,20.6070902985505,22.909004,0,0,0,40,4449,199.85165,69902.20703125,,,,,,,,,,,,,0,,,,0,,,,,,200.0123138,,,,
,28533375.175,200.0137024,74792.2109375,-0.000218461048943699,2.88206711492194E-6,1,0.999253354069792,40.0298881530762,1.99727382829484,14.9600002914667,-0.00247273620315833,-0.000467127228789793,0.25,-3.2256553965916E-6,-0.000219212511272697,-3.46763563167045E-6,200.0135803,200.0138245,74784.6953125,74799.7265625,57.0776409883137,20.6073319379848,22.909004,0,0,0,40,4449,199.8437,74792.2109375,,,,,,,,,,,,,0,,,,0.00245,,,,,,200.0137024,,,,
,28533471.155,200.0119934,79590.31640625,-0.000238444013537346,2.56811854046309E-6,1,0.999253354069792,40.0298881530762,1.99729628822505,14.9600002914667,-0.00269790031005979,-0.000515913338805365,0.25,-4.05451682523352E-6,-0.000239263749449534,-4.31993814448278E-6,200.0119934,200.0119934,79582.8515625,79597.78125,56.8540952318137,20.6067718147993,23.288654,0,0,0,40,4449,199.837,79590.31640625,,,,,,,,,,,,,0,,,,0,,,,,,200.0119934,,,,
,28533567.645,200.0138245,84413.78125,-0.000254420639594966,3.28857901407336E-6,1,0.999253354069792,40.0298881530762,1.99723389157582,14.9600002914667,-0.00288606038162557,-0.000507415884138104,0.25,-5.33127231703889E-7,-0.000255299368311921,-8.02650661770309E-7,200.0138245,200.0138245,84406.109375,84421.453125,57.0917103016599,20.6091529472613,22.909004,0,0,0,40,4449,199.82475,84413.78125,,,,,,,,,,,,,0,,,,0.00245,,,,,,200.0138245,,,,
,28533658.43,200.0123901,88952.10546875,-0.000265122300857748,3.22856611511465E-6,1,0.999253354069792,40.0298881530762,1.99725727715101,14.9600002914667,-0.00299522235276089,-0.000599415316481214,0.25,-6.78192855191411E-6,-0.000266031549517295,-7.08373883092046E-6,200.0123901,200.0123901,88949.71875,88954.4921875,56.9807190519291,20.606312111368,23.288654,0,0,0,40,4449,199.8156,88952.10546875,,,,,,,,,,,,,0,,,,0,,,,,,200.0123901,,,,
,28533767.325,200.005188,86526.1171875,-0.000258995008595331,2.94030665423886E-6,1,0.999253354069792,40.0298881530762,1.99724048766993,14.9600002914667,-0.00293609439945561,-0.000527289374463436,0.25,-1.49014165122195E-6,-0.00025988864965265,-1.7675450189318E-6,200.005188,200.005188,86518.5546875,86533.6796875,57.0643533034868,20.606838474259,22.909004,0,0,0,40,4449,199.8094,86526.1171875,,,,,,,,,,,,,0,,,,-0.0049,,,,,,200.005188,,,,
,28533862.6,199.9997559,81762.51171875,-0.000244113416674675,2.98076612774074E-6,1,0.999253354069792,40.0298881530762,1.99723452822178,14.9600002914667,-0.00276660808973387,-0.000501441457888646,0.25,-1.79620593132289E-6,-0.000244955257993433,-2.0595822822575E-6,199.9997559,199.9997559,81754.8984375,81770.125,57.1120326431599,20.605868795363,22.529354,0,0,0,40,4449,199.8134,81762.51171875,,,,,,,,,,,,,0,,,,0,,,,,,199.9997559,,,,
,28533959.45,199.9946594,76921.296875,-0.000230918474037396,2.69339757232321E-6,1,0.999253354069792,40.0298881530762,1.99719673346928,14.9600002914667,-0.0026151856480625,-0.000484881480769793,0.25,-2.62855291889729E-6,-0.000231713789456175,-2.88143460684632E-6,199.9946594,199.9946594,76916.171875,76926.421875,57.166746639506,20.6066290461795,22.529354,0,0,0,40,4449,199.8199,76921.296875,,,,,,,,,,,,,0,,,,0,,,,,,199.9946594,,,,
,28534054.135,199.9918823,72190.09765625,-0.000216419714574534,3.30087700311351E-6,1,0.999253354069792,40.0298881530762,1.99732159093741,14.9600002914667,-0.00244813873896536,-0.00047169259461492,0.25,-3.98120138311973E-6,-0.000217163433831134,-4.22393001318538E-6,199.9918823,199.9918823,72187.5,72192.6953125,57.0205821064099,20.6051653982788,22.909004,0,0,0,40,4449,199.8267,72190.09765625,,,,,,,,,,,,,0,,,,0.00245,,,,,,199.9918823,,,,
,28534151.345,199.9897614,67329.9453125,-0.000196972450424076,1.90153612234389E-6,1,0.999253354069792,40.0298881530762,1.99724753297916,14.9600002914667,-0.00223200632453263,-0.000406636020293849,0.25,-1.62655376199154E-6,-0.000197651397675456,-1.84101947344315E-6,199.9897614,199.9897614,67329.9453125,67329.9453125,57.1472059265253,20.6090277041565,22.909004,0,0,0,40,4449,199.8296,67329.9453125,,,,,,,,,,,,,0,,,,-0.0049,,,,,,199.9897614,,,,
,28534246.79,199.989502,62559.64453125,-0.000182594423788268,2.96247603032093E-6,1,0.999253354069792,40.0298881530762,1.9971836556055,14.9600002914667,-0.00206303253803276,-0.000411401077642548,0.25,-4.54415359167739E-6,-0.000183220527345468,-4.75384542646013E-6,199.989502,199.989502,62552.42578125,62566.86328125,57.241001348833,20.608050737593,22.529354,0,0,0,40,4449,199.84545,62559.64453125,,,,,,,,,,,,,0,,,,0,,,,,,199.989502,,,,
,28534343.145,199.9866943,57740.962890625,-0.000166867730060237,1.56312258079789E-6,1,0.999253354069792,40.0298881530762,1.99716761032995,14.9600002914667,-0.00188961636656184,-0.000351285774018416,0.25,-1.97757222769271E-6,-0.000167442177469622,-2.16204976882532E-6,199.9866943,199.9866943,57738.09375,57743.83203125,57.2495992625445,20.6104215758178,22.909004,0,0,0,40,4449,199.8548,57740.962890625,,,,,,,,,,,,,0,,,,0.00245,,,,,,199.9866943,,,,
,28534437.62,199.9884186,53020.853515625,-0.000153435789071909,1.74491704225965E-6,1,0.999253354069792,40.0298881530762,1.99727414268306,14.9600002914667,-0.00173583168772452,-0.000333209484438029,0.25,-2.71549413086835E-6,-0.000153962980139484,-2.88854409095204E-6,199.9884186,199.9884186,53016.0859375,53025.62109375,57.105779615006,20.6075696797568,22.909004,0,0,0,40,4449,199.8633,53020.853515625,,,,,,,,,,,,,0,,,,0,,,,,,199.9884186,,,,
,28534533.215,199.9875031,48240.572265625,-0.000136778855406632,1.37666905412428E-6,1,0.999253354069792,40.0298881530762,1.99739934301753,14.9600002914667,-0.00154706608441104,-0.000299451892653701,0.25,-2.63170258401293E-6,-0.000137248546531351,-2.78698192456556E-6,199.9875031,199.9875031,48238.01953125,48243.125,57.2589788047753,20.6075216246727,23.288654,0,0,0,40,4449,199.87215,48240.572265625,,,,,,,,,,,,,0,,,,0.0049,,,,,,199.9875031,,,,
,28534630.05,199.9901886,43403.181640625,-0.000122343680990015,1.67305120400178E-6,1,0.999253354069792,40.0298881530762,1.9972540294406,14.9600002914667,-0.00138354462391393,-0.000268709255780392,0.25,-2.43118340654949E-6,-0.000122763666501262,-2.5705980044914E-6,199.9901886,199.9901886,43395.76171875,43410.6015625,57.2636685758907,20.6116119868362,22.909004,0,0,0,40,4449,199.8795,43403.181640625,,,,,,,,,,,,,0,,,,0.00245,,,,,,199.9901886,,,,
,28534727.305,199.9867401,38540.505859375,-0.000106532890646102,2.21774156677435E-6,1,0.999253354069792,40.0298881530762,1.99716722737025,14.9600002914667,-0.00120541611560112,-0.000229823406288798,0.25,-1.7510453601418E-6,-0.000106898968986937,-1.87139661586683E-6,199.9867401,199.9867401,38538.4609375,38542.55078125,57.146424298006,20.6110724313009,23.288654,0,0,0,40,4449,199.891,38540.505859375,,,,,,,,,,,,,0,,,,0.0049,,,,,,199.9867401,,,,
,28534821.54,199.9873962,33830.51171875,-9.12211143575631E-5,1.88148406645866E-6,1,0.999253354069792,40.0298881530762,1.99729413629273,14.9600002914667,-0.00103193891343157,-0.000198456852492426,0.25,-1.6449152425109E-6,-9.15343893000952E-5,-1.74865020022953E-6,199.9873962,199.9873962,33825.66796875,33835.35546875,57.0729512171983,20.6105910384017,22.909004,0,0,0,40,4449,199.89785,33830.51171875,,,,,,,,,,,,,0,,,,0.00245,,,,,,199.9873962,,,,
,28534917.195,199.98874665,29051.0673828125,-7.59369981842621E-5,1.33100363104172E-6,1,0.999253354069792,40.0298881530762,1.99729757513542,14.9600002914667,-0.000859431066790249,-0.000162944986634447,0.25,-1.16995787718743E-6,-7.61979709765972E-5,-1.25576976184289E-6,199.988739,199.9887543,29043.771484375,29058.36328125,57.0057311645445,20.6103676063334,22.529354,0,0,0,40,4449,199.90705,29051.0673828125,,,,,,,,,,,,,0,,,,0,,,,,,199.98874665,,,,
,28535013.93,199.9921875,24215.775390625,-6.25822521914906E-5,1.54573382510868E-6,1,0.999253354069792,40.0298881530762,1.99739358212165,14.9600002914667,-0.000707625807820873,-0.000138282517688295,0.25,-1.31548734418125E-6,-6.27969233290513E-5,-1.38753932249126E-6,199.9921875,199.9921875,24210.966796875,24220.583984375,57.3207274577945,20.6120463545825,22.909004,0,0,0,40,4449,199.9154,24215.775390625,,,,,,,,,,,,,0,,,,-0.0049,,,,,,199.9921875,,,,
,28535111.04,199.9891205,19363.3759765625,-4.6521042688476E-5,1.72836624536706E-6,1,0.999253354069792,40.0298881530762,1.99732551080874,14.9600002914667,-0.000526326926730268,-0.000100921474235798,0.25,-8.13130969354983E-7,-4.66807888371048E-5,-8.6620678040366E-7,199.9891205,199.9891205,19358.380859375,19368.37109375,57.3316702570638,20.6080878687074,22.529354,0,0,0,40,4449,199.92715,19363.3759765625,,,,,,,,,,,,,0,,,,0,,,,,,199.9891205,,,,
,28535209.18,199.9898834,14458.4575195313,-3.32048487373175E-5,7.09281521408504E-7,1,0.999253354069792,40.0298881530762,1.99730431011889,14.9600002914667,-0.000375512781766687,-7.29211939181937E-5,0.25,-6.58594865658399E-7,-3.33187738151732E-5,-6.9680755546037E-7,199.9898834,199.9898834,14455.98828125,14460.9267578125,57.1175040427945,20.6087440244385,22.909004,0,0,0,40,4449,199.9321,14458.4575195313,,,,,,,,,,,,,0,,,,0,,,,,,199.9898834,,,,
,28535308.595,199.9905853,9488.6591796875,-1.90485736817394E-5,4.72837662746611E-7,1,0.999253354069792,40.0298881530762,1.99728915594013,14.9600002914667,-0.000215697001126401,-4.02271252852403E-5,0.25,-2.36334574670193E-7,-1.91140763316041E-5,-2.57800321796431E-7,199.9905853,199.9905853,9478.6005859375,9498.7177734375,57.1042163579676,20.6114449061262,22.909004,0,0,0,40,4449,199.93275,9488.6591796875,,,,,,,,,,,,,0,,,,0.0049,,,,,,199.9905853,,,,
,28535408.055,199.9909363,4518.54711914063,-6.52557773504025E-6,5.86840803129529E-7,1,0.999253354069792,40.0298881530762,1.99715100805734,14.9600002914667,-7.36016722886764E-5,-1.5426374950085E-5,0.25,-2.26050217992316E-7,-6.54785820048672E-6,-2.33914469812938E-7,199.9909363,199.9909363,4516.26708984375,4520.8271484375,57.3136928011214,20.6145176618541,23.288654,0,0,0,40,4449,199.9406,4518.54711914063,,,,,,,,,,,,,0,,,,0.00245,,,,,,199.9909363,,,,
,28535499.14,199.9916992,-0.175073400139809,2.53709020625075E-6,3.858055905467E-7,1,0.999253354069792,40.0298881530762,1.99717612548558,14.9600002914667,2.97078175435509E-5,-2.8791138784256E-7,0.25,-4.66044948402559E-7,2.54635402175581E-6,-4.64896872107121E-7,199.9916992,199.9916992,-0.19790905714035,-0.152237743139267,57.3949821671215,20.6140145851755,22.529354,0,0,0,40,4417,199.951,-0.175073400139809,,,,,,,,,,,,,0,,,,0,,,,,,199.9916992,,,,