File: data/monolayers/nanoparticles/Ol_CoFe_C/vsm/data_disorderedWafer/DD227_HYST_300K_INIT.DAT
[Header]
; VSM Data File (default extension .dat)
; Copyright (c) 2003-2013, Quantum Design, Inc. All rights reserved.
TITLE,
FILEOPENTIME,28451414.27,11/26/2018,3:10 pm
BYAPP,VSM,2.0,2.0
INFO,PPMS VSM Option Release 1.4.10 Build 1,APPNAME
INFO,Quantum Design Linear Motor Servo Controller,MOTOR_MODULE_NAME
INFO,3101-100 M1,MOTOR_HW_VERSION
INFO,MMC1014,MOTOR_SERIAL_NUMBER
INFO,SRV No X-over 01.03.11,MOTOR_SOFTWARE_VERSION
INFO,Quantum Design VSM Detection Module,VSM_MODULE_NAME
INFO,3101-150 F0,VSM_HW_VERSION
INFO,VSM707,VSM_SERIAL_NUMBER
INFO,VSM No X-over 01.02.05 May 20 2008 13:51:47,VSM_SOFTWARE_VERSION
INFO,704,PREAMP_SERIAL_NUMBER
INFO,822,COIL_SERIAL_NUMBER
INFO,0,MOMENT_UNITS
INFO,CoFe2O4 FeO,SAMPLE_MATERIAL
INFO,disordered monolayer,SAMPLE_COMMENT
INFO,25.46,SAMPLE_MASS
INFO,,SAMPLE_VOLUME
INFO,,SAMPLE_MOLECULAR_WEIGHT
INFO,,SAMPLE_SIZE
INFO,,SAMPLE_SHAPE
DATATYPE,COMMENT,1
DATATYPE,TIME,2
STARTUPAXIS,X,2
STARTUPAXIS,Y1,5
[Data]
Comment,Time Stamp (sec),Temperature (K),Magnetic Field (Oe),Moment (emu),M. Std. Err. (emu),Transport Action,Averaging Time (sec),Frequency (Hz),Peak Amplitude (mm),Center Position (mm),Coil Signal' (mV),Coil Signal" (mV),Range (mV),M. Quad. Signal (emu),M. Raw' (emu),M. Raw" (emu),Min. Temperature (K),Max. Temperature (K),Min. Field (Oe),Max. Field (Oe),Mass (grams),Motor Lag (deg),Pressure (Torr),VSM Status (code),Motor Status (code),Measure Status (code),Measure Count,PPMS Status (code),System Temp. (K),System Field (Oe),Sample Position (deg),Bridge 1 Resistance (ohms),Bridge 1 Excitation (에),Bridge 2 Resistance (ohms),Bridge 2 Excitation (에),Bridge 3 Resistance (ohms),Bridge 3 Excitation (에),Bridge 4 Resistance (ohms),Bridge 4 Excitation (에),Signal 1 Vin (V),Signal 2 Vin (V),Digital Inputs (code),Drive 1 Iout (mA),Drive 1 Ipower (W),Drive 2 Iout (mA),Drive 2 Ipower (W),Pressure (),Map 20 (),Map 21 (),Map 22 (),Map 23 (),Map 24 (),Map 25 (),Map 26 (),Map 27 (),Map 28 (),Map 29 ()
,28451429.52,299.9926758,0.563279569149017,,,2,,,,14.2799999815226,,,,,,,299.9926758,299.9926758,0.563279569149017,0.563279569149017,,,22.149702,,,,-99999999,4369,300.1961,0.563279569149017,,,,,,,,,,,,,,,,,,,,,,,299.9926758,,,,
,28451582.54,300.0028076,4416.51513671875,-5.35970523159934E-6,5.24896157143574E-7,1,0.999253354069792,40.0298881530762,1.97451751787789,14.2700001597404,-5.70659233813437E-5,-2.70618805783535E-5,0.25,-1.4905931962137E-6,-5.35855636300904E-6,-1.49410295849776E-6,300.0028076,300.0028076,4406.0947265625,4426.935546875,56.1740784200829,20.5674085676193,22.909004,0,0,0,40,4449,300.197,4416.51513671875,,,,,,,,,,,,,0,,,,-0.0049,,,,,,300.0028076,,,,
,28451677.435,300.0140991,9158.1005859375,-1.60033610200957E-5,9.49968263804222E-7,1,0.999253354069792,40.0298881530762,1.97414997491627,14.2700001597404,-0.000174790245059272,-5.52235301486516E-5,0.25,-2.16489302648798E-6,-1.60014417968585E-5,-2.17543248400527E-6,300.0140991,300.0140991,9153.3203125,9162.880859375,56.4562463155252,20.5771891855759,22.529354,0,0,0,40,4449,300.192,9158.1005859375,,,,,,,,,,,,,0,,,,0,,,,,,300.0140991,,,,
,28451772.94,300.0056763,13932.8764648438,-2.78379334386109E-5,1.5582085655303E-6,1,0.999253354069792,40.0298881530762,1.97411063265671,14.2700001597404,-0.000308017390252561,-7.31203147386462E-5,0.25,-1.71476118472323E-6,-2.78359648930493E-5,-1.733141963815E-6,300.0056763,300.0056763,13925.375,13940.3779296875,56.821266834006,20.580496821769,22.909004,0,0,0,40,4449,300.18815,13932.8764648438,,,,,,,,,,,,,0,,,,0.00245,,,,,,300.0056763,,,,
,28451872.425,300.0080872,18905.337890625,-4.2031193758866E-5,1.97083228904176E-6,1,0.999253354069792,40.0298881530762,1.97403380673767,14.2700001597404,-0.000461479656747723,-0.000130967860772847,0.25,-4.42845410235317E-6,-4.20270050362552E-5,-4.45612533059093E-6,300.0080872,300.0080872,18897.859375,18912.81640625,56.7720242372945,20.5797356305432,22.909004,0,0,0,40,4449,300.18325,18905.337890625,,,,,,,,,,,,,0,,,,0.00245,,,,,,300.0080872,,,,
,28451968.565,300.0051575,23710.109375,-5.40761478834936E-5,2.67114407226586E-6,1,0.999253354069792,40.0298881530762,1.97393173767154,14.2700001597404,-0.00059649796854101,-0.000152327573020311,0.25,-4.25218502768105E-6,-5.40717261999794E-5,-4.28779669912415E-6,300.0051575,300.0051575,23705.115234375,23715.103515625,56.973684395256,20.5837753685451,23.288654,0,0,0,40,4449,300.1749,23710.109375,,,,,,,,,,,,,0,,,,0.0049,,,,,,300.0051575,,,,
,28452065.81,300.0109558,28570.498046875,-7.06130298815591E-5,2.93463384021484E-6,1,0.999253354069792,40.0298881530762,1.97384346091683,14.2700001597404,-0.00077529213507062,-0.000219598977424438,0.25,-7.4034098557439E-6,-7.06060271514135E-5,-7.44980896786282E-6,300.0109558,300.0109558,28563.1640625,28577.83203125,56.6563432164483,20.582050484343,23.288654,0,0,0,40,4449,300.1705,28570.498046875,,,,,,,,,,,,,0,,,,0.00245,,,,,,300.0109558,,,,
,28452164.415,300.010437,33497.98828125,-8.23303178022501E-5,1.69332474570609E-6,1,0.999253354069792,40.0298881530762,1.97376107258579,14.2700001597404,-0.000904593493038958,-0.000252057713506572,0.25,-8.27688043656679E-6,-8.23223998783085E-5,-8.33093294727824E-6,300.010437,300.010437,33490.3984375,33505.578125,56.7634263235829,20.5842257187212,23.288654,0,0,0,40,4449,300.1674,33497.98828125,,,,,,,,,,,,,0,,,,-0.00245,,,,,,300.010437,,,,
,28452262.475,300.0101624,38400.21484375,-9.89568630700131E-5,1.39501822494644E-6,1,0.999253354069792,40.0298881530762,1.9737765978682,14.2700001597404,-0.00108760296625792,-0.000301120669341662,0.25,-9.78371193759203E-6,-9.89474683907262E-5,-9.84861865256896E-6,300.0101624,300.0101624,38392.5625,38407.8671875,57.0940551872176,20.5831619221612,22.909004,0,0,0,40,4449,300.1523,38400.21484375,,,,,,,,,,,,,0,,,,0,,,,,,300.0101624,,,,
,28452362.15,300.0131531,43380.359375,-0.000112341217297751,2.01388215947243E-6,1,0.999253354069792,40.0298881530762,1.97358537557783,14.2700001597404,-0.00123387987399792,-0.000345925814127774,0.25,-1.14745669881733E-5,-0.000112330313252545,-1.1548160039002E-5,300.0131531,300.0131531,43370.07421875,43390.64453125,56.9775925378522,20.5857439483114,23.288654,0,0,0,40,4449,300.1424,43380.359375,,,,,,,,,,,,,0,,,,-0.0049,,,,,,300.0131531,,,,
,28452458.875,300.0066223,48218.02734375,-0.000127189520959922,3.37073178630003E-6,1,0.999253354069792,40.0298881530762,1.97349756065777,14.2700001597404,-0.00139365110234499,-0.000410410100288098,0.25,-1.46708840668687E-5,-0.000127176119076499,-1.4754065508175E-5,300.0066223,300.0066223,48207.98828125,48228.06640625,56.6782288149868,20.5865943057042,22.909004,0,0,0,40,4449,300.13785,48218.02734375,,,,,,,,,,,,,0,,,,0.00245,,,,,,300.0066223,,,,
,28452554.735,300.0057068,53007.8828125,-0.000139304584448994,1.69359316159168E-6,1,0.999253354069792,40.0298881530762,1.97349105648334,14.2700001597404,-0.00153472194966419,-0.000401437162589984,0.25,-1.17695797348181E-5,-0.000139292754949259,-1.18607069114464E-5,300.0057068,300.0057068,53000.59375,53015.171875,57.0362146767945,20.5864655923115,22.909004,0,0,0,40,4449,300.1422,53007.8828125,,,,,,,,,,,,,0,,,,0.00245,,,,,,300.0057068,,,,
,28452650.39,300.0134888,57788.001953125,-0.000155119161690608,2.08961239600587E-6,1,0.999253354069792,40.0298881530762,1.97341471580424,14.2700001597404,-0.00170664193344447,-0.000459958248357232,0.25,-1.42654191155967E-5,-0.00015510520446175,-1.43667433851158E-5,300.0134888,300.0134888,57782.9140625,57793.08984375,56.729816297256,20.5879469730198,23.288654,0,0,0,40,4449,300.1255,57788.001953125,,,,,,,,,,,,,0,,,,-0.0049,,,,,,300.0134888,,,,
,28452749.02,300.0143433,62718.97265625,-0.000167373642869078,2.72059722688559E-6,1,0.999253354069792,40.0298881530762,1.97330821282435,14.2700001597404,-0.00184378743291347,-0.000482331141524692,0.25,-1.41457606301182E-5,-0.000167359418368341,-1.42549957971982E-5,300.0143433,300.0143433,62711.375,62726.5703125,57.0401228193907,20.5887998377529,23.288654,0,0,0,40,4449,300.12215,62718.97265625,,,,,,,,,,,,,0,,,,0.0049,,,,,,300.0143433,,,,
,28452848.81,300.009613,67706.56640625,-0.000180883377049681,2.52960407430913E-6,1,0.999253354069792,40.0298881530762,1.97333794110666,14.2700001597404,-0.0019963246424611,-0.000500002533516351,0.25,-1.33853328974655E-5,-0.000180869304548513,-1.35033024108749E-5,300.009613,300.009613,67699.078125,67714.0546875,56.8861420011022,20.5867470715109,22.909004,0,0,0,40,4449,300.11175,67706.56640625,,,,,,,,,,,,,0,,,,0,,,,,,300.009613,,,,
,28452947.865,300.0137329,72656.34765625,-0.000199831625427499,2.23107724573694E-6,1,0.999253354069792,40.0298881530762,1.97340685717855,14.2700001597404,-0.00219683642874999,-0.000602526399466997,0.25,-1.92713025607788E-5,-0.000199813144504106,-1.94013383828964E-5,300.0137329,300.0137329,72651.5,72661.1953125,56.8728543162753,20.5884911399587,23.668306,0,0,0,40,4449,300.10195,72656.34765625,,,,,,,,,,,,,0,,,,0,,,,,,300.0137329,,,,
,28453045.235,300.0144653,77524.4453125,-0.000209408762853917,3.05823586430155E-6,1,0.999253354069792,40.0298881530762,1.97327596421018,14.2700001597404,-0.00230246787661259,-0.000628526080617351,0.25,-1.99412884025638E-5,-0.000209389585753564,-2.00774053643053E-5,300.0144653,300.0144653,77519.4453125,77529.4453125,56.983845566006,20.5892699069843,23.668306,0,0,0,40,4449,300.0815,77524.4453125,,,,,,,,,,,,,0,,,,-0.0049,,,,,,300.0144653,,,,
,28453144.99,300.0160065,82510.10546875,-0.000223142451899428,3.11356717435413E-6,1,0.999253354069792,40.0298881530762,1.97320789077013,14.2700001597404,-0.00245113520587176,-0.000682741407796064,0.25,-2.24136512651777E-5,-0.000223121279171297,-2.25584781030603E-5,300.0157776,300.0162354,82502.4140625,82517.796875,56.6422739031022,20.5909867950702,23.668306,0,0,0,40,4449,300.07385,82510.10546875,,,,,,,,,,,,,0,,,,-0.0049,,,,,,300.0160065,,,,
,28453238.245,300.0084534,87170.7734375,-0.000237094673471158,2.63481050182809E-6,1,0.999253354069792,40.0298881530762,1.97322929124145,14.2700001597404,-0.00261255064739154,-0.000678525771531372,0.25,-1.96188856702481E-5,-0.000237075008368334,-1.97727153679591E-5,300.0084534,300.0084534,87165.9375,87175.609375,57.0909286731407,20.5918533931711,23.668306,0,0,0,40,4449,300.06485,87170.7734375,,,,,,,,,,,,,0,,,,0,,,,,,300.0084534,,,,
,28453348.595,300.007782,88257.79296875,-0.000240923066581082,2.03115363734976E-6,1,0.999253354069792,40.0298881530762,1.97314247283077,14.2700001597404,-0.00265492356082264,-0.000687725415738943,0.25,-1.97811750957219E-5,-0.000240903198021872,-1.99374491099256E-5,300.007782,300.007782,88252.8515625,88262.734375,56.973684395256,20.5902120964737,23.668306,0,0,0,40,4449,300.065,88257.79296875,,,,,,,,,,,,,0,,,,0,,,,,,300.007782,,,,
,28453443.465,300.0073853,83517.66015625,-0.000224756242613445,2.66044507346971E-6,1,0.999253354069792,40.0298881530762,1.97322616725123,14.2700001597404,-0.00248005969290686,-0.000623183113308386,0.25,-1.68059757593613E-5,-0.000224738754875712,-1.69519840942768E-5,300.0073853,300.0073853,83515.0546875,83520.265625,57.1331366131791,20.589574593027,23.288654,0,0,0,40,4449,300.0785,83517.66015625,,,,,,,,,,,,,0,,,,-0.0049,,,,,,300.0073853,,,,
,28453541.275,299.9959717,78627.89453125,-0.000211860293779849,2.94585026333161E-6,1,0.999253354069792,40.0298881530762,1.97315239412937,14.2700001597404,-0.00232904073189144,-0.000637255482139875,0.25,-2.03008105041773E-5,-0.000211840957201773,-2.0438495427053E-5,299.9959717,299.9959717,78620.5234375,78635.265625,57.0393411908714,20.5909395655477,24.047956,0,0,0,40,4449,300.0749,78627.89453125,,,,,,,,,,,,,0,,,,0,,,,,,299.9959717,,,,
,28453638.1,299.9969482,73784.38671875,-0.000197919051880279,2.721063815341E-6,1,0.999253354069792,40.0298881530762,1.97314493752389,14.2700001597404,-0.00218090482721382,-0.000565694904732163,0.25,-1.63147257158023E-5,-0.000197902682333364,-1.64435888617133E-5,299.9969482,299.9969482,73781.75,73787.0234375,57.0698247031214,20.5919675548098,23.288654,0,0,0,40,4449,300.0675,73784.38671875,,,,,,,,,,,,,0,,,,-0.00245,,,,,,299.9969482,,,,
,28453737.285,299.9941711,68826.578125,-0.00018039672339849,3.68137563131073E-6,1,0.999253354069792,40.0298881530762,1.97309881993528,14.2700001597404,-0.00198222710857103,-0.000547644604594257,0.25,-1.7736729871422E-5,-0.000180379921031341,-1.78542463136947E-5,299.9941711,299.9941711,68823.984375,68829.171875,57.0377779338329,20.5936392588496,23.668306,0,0,0,40,4449,300.0761,68826.578125,,,,,,,,,,,,,0,,,,-0.00245,,,,,,299.9941711,,,,
,28453834.59,299.986969,63966.244140625,-0.000170390734861492,2.97819585035939E-6,1,0.999253354069792,40.0298881530762,1.97295231709627,14.2700001597404,-0.00187871402845518,-0.000479327697053881,0.25,-1.33617649420581E-5,-0.000170377105547563,-1.34729932475849E-5,299.986969,299.986969,63956.3359375,63976.15234375,56.7798405224868,20.5964990194214,23.288654,0,0,0,40,4449,300.08905,63966.244140625,,,,,,,,,,,,,0,,,,0.00245,,,,,,299.986969,,,,
,28453929.655,299.99079895,59213.326171875,-0.000156134350757197,2.57681307100054E-6,1,0.999253354069792,40.0298881530762,1.97293443145512,14.2700001597404,-0.00171836665160567,-0.000457356259529559,0.25,-1.38663229415056E-5,-0.000156120758062594,-1.39683050533453E-5,299.9907227,299.9908752,59203.30078125,59223.3515625,57.2089545795445,20.5965536816204,23.288654,0,0,0,40,4449,300.11525,59213.326171875,,,,,,,,,,,,,0,,,,0,,,,,,299.99079895,,,,
,28454028.96,299.9835815,54250.392578125,-0.000143614512695981,2.31179150785083E-6,1,0.999253354069792,40.0298881530762,1.97301173731313,14.2700001597404,-0.00158235873017653,-0.000410758184093121,0.25,-1.1865064595986E-5,-0.000143602610843453,-1.19590106991418E-5,299.9835815,299.9835815,54245.3984375,54255.38671875,56.9791557948906,20.5955010726642,23.668306,0,0,0,40,4449,300.11465,54250.392578125,,,,,,,,,,,,,0,,,,0,,,,,,299.9835815,,,,
,28454126.095,299.9883423,49395.380859375,-0.000128457570295845,2.11406898838173E-6,1,0.999253354069792,40.0298881530762,1.97287337323244,14.2700001597404,-0.00140843722175194,-0.000406778460451208,0.25,-1.41373753929945E-5,-0.000128444569591082,-1.42213978724743E-5,299.9883423,299.9883423,49362.90234375,49427.859375,56.8126689202945,20.5975825290552,23.668306,0,0,0,40,4449,300.1209,49395.380859375,,,,,,,,,,,,,0,,,,0.00245,,,,,,299.9883423,,,,
,28454224.67,299.9912415,44467.0703125,-0.000114817846980851,1.21531567198741E-6,1,0.999253354069792,40.0298881530762,1.97293856276156,14.2700001597404,-0.00126122231108629,-0.000350353833226452,0.25,-1.14513146883742E-5,-0.000114806977518246,-1.15265327159011E-5,299.9912415,299.9912415,44459.67578125,44474.46484375,56.9986965078714,20.602481514856,23.288654,0,0,0,40,4449,300.1285,44467.0703125,,,,,,,,,,,,,0,,,,0.0049,,,,,,299.9912415,,,,
,28454322.29,299.9870911,39587.23828125,-9.803433741069E-5,1.45619897090683E-6,1,0.999253354069792,40.0298881530762,1.97294730079104,14.2700001597404,-0.00107589417570102,-0.000304760565293196,0.25,-1.02799976782804E-5,-9.8024727718857E-5,-1.03442738717606E-5,299.9870911,299.9870911,39577.1171875,39597.359375,56.9213152844676,20.5984436166044,23.668306,0,0,0,40,4449,300.14965,39587.23828125,,,,,,,,,,,,,0,,,,-0.0049,,,,,,299.9870911,,,,
,28454416.735,299.986145,34867.470703125,-8.72119103912999E-5,1.6467002152184E-6,1,0.999253354069792,40.0298881530762,1.97299127332576,14.2700001597404,-0.000959021048673995,-0.000260276683241861,0.25,-8.17479963132103E-6,-8.72039926336135E-5,-8.23206819180034E-6,299.986145,299.986145,34859.78125,34875.16015625,57.1362631272561,20.6034150208253,23.288654,0,0,0,40,4449,300.152,34867.470703125,,,,,,,,,,,,,0,,,,0.00245,,,,,,299.986145,,,,
,28454513.21,299.9862671,30047.640625,-7.12872335486717E-5,2.06558876333555E-6,1,0.999253354069792,40.0298881530762,1.97288494798135,14.2700001597404,-0.000780202767422564,-0.000233881555458111,0.25,-8.57352486452565E-6,-7.12795040254272E-5,-8.62032886586418E-6,299.9852295,299.9873047,30037.763671875,30057.517578125,57.0487207331022,20.6045869816374,23.668306,0,0,0,40,4449,300.1603,30047.640625,,,,,,,,,,,,,0,,,,0,,,,,,299.9862671,,,,
,28454608.63,299.9899902,25277.4599609375,-5.76226512676475E-5,2.00056127831251E-6,1,0.999253354069792,40.0298881530762,1.97281379712966,14.2700001597404,-0.000629333658594061,-0.000196519586014171,0.25,-7.59894092105508E-6,-5.76159458611481E-5,-7.63679013944955E-6,299.9899902,299.9899902,25270.041015625,25284.87890625,57.146424298006,20.605278813236,23.668306,0,0,0,40,4449,300.1651,25277.4599609375,,,,,,,,,,,,,0,,,,0.00245,,,,,,299.9899902,,,,
,28454708.05,299.9875183,20309.8935546875,-4.37658263828741E-5,1.78338315268604E-6,1,0.999253354069792,40.0298881530762,1.97300512251438,14.2700001597404,-0.000480259989759305,-0.00013645488400284,0.25,-4.6246257811179E-6,-4.37614896904441E-5,-4.65343477800526E-6,299.9875183,299.9875183,20302.416015625,20317.37109375,57.2597604332945,20.6107402627961,23.668306,0,0,0,40,4449,300.17705,20309.8935546875,,,,,,,,,,,,,0,,,,-0.00245,,,,,,299.9875183,,,,
,28454804.5,299.9859009,15488.16796875,-3.23006083549463E-5,1.44469478393218E-6,1,0.999253354069792,40.0298881530762,1.97284197140964,14.2700001597404,-0.00035253497550571,-0.000111577162831711,0.25,-4.38624804161005E-6,-3.22967617137546E-5,-4.40750081744808E-6,299.9854126,299.9863892,15485.8779296875,15490.4580078125,57.1229754424291,20.6094910690216,24.047956,0,0,0,40,4449,300.18665,15488.16796875,,,,,,,,,,,,,0,,,,0,,,,,,299.9859009,,,,
,28454903.565,299.9859924,10535.84765625,-1.95814607910866E-5,1.01638314475858E-6,1,0.999253354069792,40.0298881530762,1.97268491823156,14.2700001597404,-0.000213101851065288,-7.10851752125114E-5,0.25,-2.96767874031586E-6,-1.9578921845099E-5,-2.98056456592328E-6,299.9859924,299.9859924,10528.474609375,10543.220703125,57.1409528983714,20.6120961631763,24.047956,0,0,0,40,4449,300.2,10535.84765625,,,,,,,,,,,,,0,,,,0,,,,,,299.9859924,,,,
,28454998.35,299.9917603,5797.90405273437,-8.83445857365491E-6,6.50200842882174E-7,1,0.999253354069792,40.0298881530762,1.9728313011589,14.2700001597404,-9.43209600945288E-5,-4.26344246757675E-5,0.25,-2.28379014880353E-6,-8.83268371728762E-6,-2.28958004309605E-6,299.9917603,299.9917603,5790.580078125,5805.22802734375,57.126101956506,20.6108800172082,23.288654,0,0,0,40,4449,300.20485,5797.90405273437,,,,,,,,,,,,,0,,,,-0.00245,,,,,,299.9917603,,,,
,28455091.715,299.9970703,1134.41711425781,9.20387352884228E-7,3.75254940682218E-7,1,0.999253354069792,40.0298881530762,1.97290046910691,14.2700001597404,1.21909445861097E-5,-9.20304014774355E-6,0.25,-9.82822690150458E-7,9.21012028584876E-7,-9.82182837237391E-7,299.9970703,299.9970703,1127.10168457031,1141.73254394531,56.831428004756,20.6129263661127,23.288654,0,0,0,40,4449,300.20055,1134.41711425781,,,,,,,,,,,,,0,,,,-0.00245,,,,,,299.9970703,,,,
,28455185.14,299.9889221,-3533.55346679687,4.23188967011873E-6,5.99025524524298E-7,1,0.999253354069792,40.0298881530762,1.9727035795407,14.2700001597404,4.55866595424312E-5,1.80681096050838E-5,0.25,8.83413185529404E-7,4.23117926290927E-6,8.86193804112469E-7,299.9889221,299.9889221,-3541.1689453125,-3525.93798828125,57.1792526958137,20.6149237858539,23.668306,0,0,0,40,4449,300.21325,-3533.55346679687,,,,,,,,,,,,,0,,,,0,,,,,,299.9889221,,,,
,28455279.17,300.0011292,-8235.38623046875,1.41731589264951E-5,7.87792868185804E-7,1,0.999253354069792,40.0298881530762,1.9728946885095,14.2700001597404,0.000154193164333869,5.18414428132581E-5,0.25,2.18241139277447E-6,1.41712899229112E-5,2.19173930211317E-6,300.0011292,300.0011292,-8240.3935546875,-8230.37890625,57.1253203279868,20.6150072260733,23.668306,0,0,0,40,4449,300.2098,-8235.38623046875,,,,,,,,,,,,,0,,,,0,,,,,,300.0011292,,,,
,28455376.705,300.0042725,-13110.990234375,2.71531314477505E-5,1.6021337746432E-6,1,0.999253354069792,40.0298881530762,1.97284889181274,14.2700001597404,0.000296305495015951,9.40832750789869E-5,0.25,3.71291738844077E-6,2.71498614160624E-5,3.73078656001676E-6,300.0042725,300.0042725,-13118.4755859375,-13103.5048828125,57.0831123879483,20.6130644081854,24.047956,0,0,0,40,4449,300.20605,-13110.990234375,,,,,,,,,,,,,0,,,,0,,,,,,300.0042725,,,,
,28455473.655,300.0010986,-17955.890625,3.83997437905562E-5,1.17346790149762E-6,1,0.999253354069792,40.0298881530762,1.9728594512205,14.2700001597404,0.000420362970786964,0.000125388629112949,0.25,4.56513128788662E-6,3.83955824727035E-5,4.59040029071838E-6,300.0010986,300.0010986,-17960.90625,-17950.875,56.9322580837368,20.6155808346408,24.047956,0,0,0,40,4449,300.2006,-17955.890625,,,,,,,,,,,,,0,,,,0,,,,,,300.0010986,,,,
,28455570.405,300.0107117,-22788.4443359375,5.23147167142338E-5,1.20556494687601E-6,1,0.999253354069792,40.0298881530762,1.97273475843657,14.2700001597404,0.000572266500984768,0.000173062481882239,0.25,6.42047884366262E-6,5.23089033472302E-5,6.45486391181879E-6,300.0107117,300.0107117,-22793.625,-22783.263671875,57.2159892362176,20.6184321572571,23.668306,0,0,0,40,4449,300.19745,-22788.4443359375,,,,,,,,,,,,,0,,,,0,,,,,,300.0107117,,,,
,28455669.315,300.0049438,-27733.2919921875,6.9456198421421E-5,2.14928783137452E-6,1,0.999253354069792,40.0298881530762,1.97259333733882,14.2700001597404,0.000757906090430041,0.000240245087413773,0.25,9.46312169554981E-6,6.94478845390564E-5,9.50870139259291E-6,300.0049438,300.0049438,-27735.7109375,-27730.873046875,56.9963516223137,20.6202773220086,23.288654,0,0,0,40,4449,300.1933,-27733.2919921875,,,,,,,,,,,,,0,,,,0.0049,,,,,,300.0049438,,,,
,28455767.305,300.0090027,-32630.3251953125,8.14266966720927E-5,1.1590946100331E-6,1,0.999253354069792,40.0298881530762,1.97277827097674,14.2700001597404,0.000891467225829997,0.000265171766571939,0.25,9.61749525682515E-6,8.14179247160725E-5,9.67091717959676E-6,300.0090027,300.0090027,-32637.744140625,-32622.90625,57.146424298006,20.6208568468884,23.288654,0,0,0,40,4449,300.1922,-32630.3251953125,,,,,,,,,,,,,0,,,,0.0049,,,,,,300.0090027,,,,
,28455866.725,300.015686,-37599.65234375,9.54025249908742E-5,1.02788110056682E-6,1,0.999253354069792,40.0298881530762,1.97252617912117,14.2700001597404,0.00104408661983842,0.000312156859452261,0.25,1.14033790754864E-5,9.53921488483396E-5,1.14658996974478E-5,300.015686,300.015686,-37604.640625,-37594.6640625,57.2050464369484,20.6205007885406,24.047956,0,0,0,40,4449,300.17265,-37599.65234375,,,,,,,,,,,,,0,,,,-0.00245,,,,,,300.015686,,,,
,28455966.275,300.008606,-42574.154296875,0.000109055531520268,2.65580074093838E-6,1,0.999253354069792,40.0298881530762,1.97205922343152,14.2700001597404,0.00119767061207765,0.000331150864460799,0.25,1.07443176395057E-5,0.000109045222468716,1.08157795514903E-5,300.008606,300.008606,-42581.54296875,-42566.765625,57.1878506095253,20.6240885768055,23.668306,0,0,0,40,4449,300.1621,-42574.154296875,,,,,,,,,,,,,0,,,,0,,,,,,300.008606,,,,
,28456065.88,300.0108337,-47554.1796875,0.00012347408152486,2.66080047732878E-6,1,0.999253354069792,40.0298881530762,1.97217680307406,14.2700001597404,0.00135303918348022,0.000392595494315528,0.25,1.3743745478334E-5,0.000123461378432125,1.38245185057728E-5,300.0108337,300.0108337,-47564.140625,-47544.21875,57.3504293415253,20.6251712524255,24.047956,0,0,0,40,4449,300.14965,-47554.1796875,,,,,,,,,,,,,0,,,,0.00245,,,,,,300.0108337,,,,
,28456165.625,300.0110779,-52538.857421875,0.000139653227912115,2.18994737576607E-6,1,0.999253354069792,40.0298881530762,1.97213152444039,14.2700001597404,0.00152880537292139,0.000452645291341218,0.25,1.63159117401786E-5,0.000139638373831981,1.64071406762203E-5,300.0110779,300.0110779,-52541.31640625,-52536.3984375,57.1307917276214,20.6257662795158,23.668306,0,0,0,40,4449,300.1432,-52538.857421875,,,,,,,,,,,,,0,,,,-0.00245,,,,,,300.0110779,,,,
,28456265.44,300.0131531,-57526.21875,0.000153417705479509,2.22780026999744E-6,1,0.999253354069792,40.0298881530762,1.97210830053131,14.2700001597404,0.00168309394294216,0.000476327237588946,0.25,1.60512788889402E-5,0.000153402628820687,1.61514360856616E-5,300.0131531,300.0131531,-57528.7890625,-57523.6484375,57.0893654161022,20.6257630469645,23.288654,0,0,0,40,4449,300.1374,-57526.21875,,,,,,,,,,,,,0,,,,-0.0049,,,,,,300.0131531,,,,
,28456362.115,300.0118408,-62358.142578125,0.000166500190220823,2.29884988197873E-6,1,0.999253354069792,40.0298881530762,1.97214703595586,14.2700001597404,0.00182744351798169,0.000512387355198704,0.25,1.70113425795379E-5,0.00016648412782148,1.71199292277655E-5,300.0118408,300.0118408,-62365.6875,-62350.59765625,57.2722664896022,20.6270028654942,23.288654,0,0,0,40,4449,300.1283,-62358.142578125,,,,,,,,,,,,,0,,,,0,,,,,,300.0118408,,,,
,28456464.355,300.01242065,-67468.265625,0.000182422707891239,2.86038320501746E-6,1,0.999253354069792,40.0298881530762,1.97219195656524,14.2700001597404,0.00200437924738659,0.000549092056260659,0.25,1.75368184119236E-5,0.000182405854289605,1.76556763943265E-5,300.0120544,300.0127869,-67473.2109375,-67463.3203125,57.4199942797368,20.6266948101435,23.668306,0,0,0,40,4449,300.1164,-67468.265625,,,,,,,,,,,,,0,,,,0.0049,,,,,,300.01242065,,,,
,28456564.96,300.0092773,-72494.52734375,0.000194647628317488,2.75833226724169E-6,1,0.999253354069792,40.0298881530762,1.97229746659821,14.2700001597404,0.00214342060681696,0.000559313523720905,0.25,1.63312117206557E-5,0.000194631252630472,1.64579495604192E-5,300.0092773,300.0092773,-72504.21875,-72484.8359375,57.1675282680253,20.6247418415292,23.668306,0,0,0,40,4449,300.11075,-72494.52734375,,,,,,,,,,,,,0,,,,0,,,,,,300.0092773,,,,
,28456663.595,300.0114746,-77424.24609375,0.000209695815024694,2.32706406535438E-6,1,0.999253354069792,40.0298881530762,1.972719184829,14.2700001597404,0.00230637153251971,0.000621314600755052,0.25,1.92614918448544E-5,0.000209677096698222,1.93978132519319E-5,300.0114746,300.0114746,-77426.75,-77421.7421875,57.230840178083,20.621093824059,24.047956,0,0,0,40,4449,300.0977,-77424.24609375,,,,,,,,,,,,,0,,,,0,,,,,,300.0114746,,,,
,28456759.48,300.0151367,-82216.56640625,0.000221832422318897,3.03640430697274E-6,1,0.999253354069792,40.0298881530762,1.97240251189347,14.2700001597404,0.00243947913260959,0.000657198289208055,0.25,2.03786706077013E-5,0.000221812621166003,2.05227073172752E-5,300.0150146,300.0152588,-82219.1875,-82213.9453125,57.1010898438907,20.628149994224,23.288654,0,0,0,40,4449,300.0872,-82216.56640625,,,,,,,,,,,,,0,,,,-0.0049,,,,,,300.0151367,,,,
,28456856.405,300.0084839,-87060.96484375,0.000237180238196539,3.11526006700105E-6,1,0.999253354069792,40.0298881530762,1.97236384926901,14.2700001597404,0.00260717751289913,0.00070861628532191,0.25,2.23222919028609E-5,0.000237158810831782,2.24760934016357E-5,300.0084839,300.0084839,-87065.984375,-87055.9453125,57.1745629246983,20.6276532847527,24.047956,0,0,0,40,4449,300.08135,-87060.96484375,,,,,,,,,,,,,0,,,,0,,,,,,300.0084839,,,,
,28456966.595,300.0125732,-88317.96875,0.000238891733411039,3.57948158795485E-6,1,0.999253354069792,40.0298881530762,1.97236163180359,14.2700001597404,0.00263285553046019,0.000674087667182005,0.25,1.89359723987123E-5,0.000238872433423005,1.90909422726006E-5,300.0125732,300.0125732,-88322.9921875,-88312.9453125,57.1612752398714,20.6281604054765,23.668306,0,0,0,40,4449,300.0658,-88317.96875,,,,,,,,,,,,,0,,,,0,,,,,,300.0125732,,,,
,28457062.03,300.0053711,-83548.8828125,0.000229829074625775,3.17642245814933E-6,1,0.999253354069792,40.0298881530762,1.97220588278738,14.2700001597404,0.00252760751651479,0.000678344856940324,0.25,2.08914139727054E-5,0.000229808792313,2.1040616179685E-5,300.0053711,300.0053711,-83556.4765625,-83541.2890625,57.3035316303714,20.6283594477096,23.668306,0,0,0,40,4449,300.06835,-83548.8828125,,,,,,,,,,,,,0,,,,0.00245,,,,,,300.0053711,,,,
,28457160.51,299.9967651,-78629.1015625,0.000212479576569014,2.33727875803128E-6,1,0.999253354069792,40.0298881530762,1.97205233270894,14.2700001597404,0.00233288941485634,0.000648670843456714,0.25,2.12456230464955E-5,0.000212459598798955,2.13836881686132E-5,299.9967651,299.9967651,-78633.859375,-78624.34375,57.1268835850253,20.6271355865775,23.668306,0,0,0,40,4449,300.0677,-78629.1015625,,,,,,,,,,,,,0,,,,0,,,,,,299.9967651,,,,
,28457259.575,299.9857788,-73676.76171875,0.000198003520642262,2.97199240177292E-6,1,0.999253354069792,40.0298881530762,1.97222967736494,14.2700001597404,0.00217357209844287,0.00060780221067376,0.25,2.00909024423678E-5,0.000197984761366105,2.02197154210756E-5,299.9857788,299.9857788,-73686.8828125,-73666.640625,57.3598088837561,20.6238548977421,24.047956,0,0,0,40,4449,300.08375,-73676.76171875,,,,,,,,,,,,,0,,,,-0.00245,,,,,,299.9857788,,,,
,28457358.705,299.98600765,-68722.421875,0.000182741900036978,2.78337025356786E-6,1,0.999253354069792,40.0298881530762,1.97241485002713,14.2700001597404,0.00200887276177425,0.000545683228564294,0.25,1.71711450890514E-5,0.000182725454949465,1.72902106360923E-5,299.985321,299.9866943,-68730.1953125,-68714.6484375,57.2238055214099,20.626290851208,23.288654,0,0,0,40,4449,300.09725,-68722.421875,,,,,,,,,,,,,0,,,,0.00245,,,,,,299.98600765,,,,
,28457456.445,299.9923096,-63838.189453125,0.00016676391412656,1.93302244121282E-6,1,0.999253354069792,40.0298881530762,1.97264182515021,14.2700001597404,0.00183994098122574,0.000460436805500561,0.25,1.23062829913326E-5,0.000166751047846213,1.24151643910953E-5,299.9923096,299.9923096,-63843.44140625,-63832.9375,57.0377779338329,20.6219652316751,24.047956,0,0,0,40,4449,300.095,-63838.189453125,,,,,,,,,,,,,0,,,,-0.00245,,,,,,299.9923096,,,,
,28457555.45,299.9822083,-58890.916015625,0.000154627562653986,2.48393978542937E-6,1,0.999253354069792,40.0298881530762,1.97220554240066,14.2700001597404,0.00169588308825607,0.000483371963770744,0.25,1.64701045997596E-5,0.0001546123516789,1.65710391127179E-5,299.9822083,299.9822083,-58896.21875,-58885.61328125,57.1862873524868,20.6228865597076,23.288654,0,0,0,40,4449,300.10895,-58890.916015625,,,,,,,,,,,,,0,,,,-0.00245,,,,,,299.9822083,,,,
,28457652.735,299.9897156,-54030.927734375,0.000140428702081536,2.09194545762125E-6,1,0.999253354069792,40.0298881530762,1.97207283134574,14.2700001597404,0.00154031878682387,0.000437445539809916,0.25,1.48223064113958E-5,0.000140414918806787,1.49140740832452E-5,299.9897156,299.9897156,-54038.20703125,-54023.6484375,57.2034831799099,20.6260435989373,23.288654,0,0,0,40,4449,300.12515,-54030.927734375,,,,,,,,,,,,,0,,,,-0.00245,,,,,,299.9897156,,,,
,28457749.735,299.9897156,-49181.66796875,0.000126558066204028,1.82706754144576E-6,1,0.999253354069792,40.0298881530762,1.97227746620405,14.2700001597404,0.00138487359799661,0.000414132010731617,0.25,1.51350734808149E-5,0.000126544458037705,1.52178193840633E-5,299.9897156,299.9897156,-49186.62109375,-49176.71484375,57.139389641333,20.6223426077393,23.288654,0,0,0,40,4449,300.1293,-49181.66796875,,,,,,,,,,,,,0,,,,-0.00245,,,,,,299.9897156,,,,
,28457847.98,299.9920654,-44271.478515625,0.000112143720948722,1.80619983268448E-6,1,0.999253354069792,40.0298881530762,1.97233776362223,14.2700001597404,0.00122509948256845,0.000378976807515561,0.25,1.44852159089446E-5,0.000112130929153087,1.45585874194947E-5,299.9920654,299.9920654,-44278.9140625,-44264.04296875,57.1284468420637,20.6223957034634,24.047956,0,0,0,40,4449,300.13445,-44271.478515625,,,,,,,,,,,,,0,,,,0.0049,,,,,,299.9920654,,,,
,28457946.055,299.9836426,-39369.173828125,9.97525188824043E-5,2.48015054374611E-6,1,0.999253354069792,40.0298881530762,1.9722768236238,14.2700001597404,0.00109298547622002,0.000318137013033116,0.25,1.11882644618729E-5,9.97422732877718E-5,1.12536487206408E-5,299.9836426,299.9836426,-39376.734375,-39361.61328125,57.0932735586983,20.6209065617935,23.668306,0,0,0,40,4449,300.15745,-39369.173828125,,,,,,,,,,,,,0,,,,0,,,,,,299.9836426,,,,
,28458045.4,299.9894409,-34405.125,8.64603251585391E-5,2.20598521946935E-6,1,0.999253354069792,40.0298881530762,1.97198125839697,14.2700001597404,0.000946279168188493,0.000281061563952014,0.25,1.01767785391693E-5,8.64510981222472E-5,1.02334959513191E-5,299.9894409,299.9894409,-34410.1875,-34400.0625,57.0010413934291,20.6256313287148,23.668306,0,0,0,40,4449,300.1615,-34405.125,,,,,,,,,,,,,0,,,,-0.00245,,,,,,299.9894409,,,,
,28458144.06,299.9905548,-29475.52734375,7.16121634459391E-5,1.59301294266229E-6,1,0.999253354069792,40.0298881530762,1.9721433800427,14.2700001597404,0.000782232925008426,0.000242044478806482,0.25,9.25531969734652E-6,7.16039625073823E-5,9.3023211346377E-6,299.9899902,299.9911194,-29487.94140625,-29463.11328125,57.0893654161022,20.6241545831802,23.668306,0,0,0,40,4449,300.16865,-29475.52734375,,,,,,,,,,,,,0,,,,0,,,,,,299.9905548,,,,
,28458242.375,299.9866638,-24560.666015625,5.76026058918897E-5,1.96469023701E-6,1,0.999253354069792,40.0298881530762,1.97228091123015,14.2700001597404,0.000628226076667558,0.000200592168355286,0.25,7.97141618978704E-6,5.7595661056894E-5,8.00924570167994E-6,299.9866638,299.9866638,-24570.822265625,-24550.509765625,57.1886322380445,20.6221365871069,23.668306,0,0,0,40,4449,300.1794,-24560.666015625,,,,,,,,,,,,,0,,,,0,,,,,,299.9866638,,,,
,28458339.295,299.9827271,-19716.068359375,4.44152389270385E-5,1.2050646280463E-6,1,0.999253354069792,40.0298881530762,1.97217705520056,14.2700001597404,0.000483195885901761,0.000161481392781614,0.25,6.7568031744611E-6,4.44094802515148E-5,6.7859828579396E-6,299.9827271,299.9827271,-19718.279296875,-19713.857421875,56.8400259184676,20.6246892873914,24.047956,0,0,0,40,4449,300.18675,-19716.068359375,,,,,,,,,,,,,0,,,,0,,,,,,299.9827271,,,,
,28458432.86,299.98695375,-15041.2866210938,3.18704217855802E-5,6.17867888061646E-7,1,0.999253354069792,40.0298881530762,1.97235477118657,14.2700001597404,0.000346648350565382,0.000116467937085211,0.25,4.90081051404082E-6,3.18662456347575E-5,4.92176437603401E-6,299.9868164,299.9870911,-15046.0966796875,-15036.4765625,57.4504777919868,20.620611365171,23.668306,0,0,0,40,4449,300.19515,-15041.2866210938,,,,,,,,,,,,,0,,,,0,,,,,,299.98695375,,,,
,28458527.195,299.991333,-10325.826171875,2.00087349620668E-5,1.13546194228864E-6,1,0.999253354069792,40.0298881530762,1.97238866458137,14.2700001597404,0.000219016172692303,6.5147581533964E-5,0.25,2.36322221295777E-6,2.00065802159103E-5,2.37640791530143E-6,299.991333,299.991333,-10328.208984375,-10323.443359375,57.251162519583,20.6224608660554,23.288654,0,0,0,40,4449,300.2174,-10325.826171875,,,,,,,,,,,,,0,,,,0.0049,,,,,,299.991333,,,,
,28458617.425,299.987793,-5815.01318359375,9.25621192754217E-6,7.35705108398483E-7,1,0.999253354069792,40.0298881530762,1.97228852684251,14.2700001597404,0.000101444903457052,2.93799007844161E-5,0.25,1.02554439227852E-6,9.25526022496823E-6,1.0316509037224E-6,299.987793,299.987793,-5819.83447265625,-5810.19189453125,57.1198489283522,20.6239829830805,23.288654,0,0,0,40,4449,300.216,-5815.01318359375,,,,,,,,,,,,,0,,,,0,,,,,,299.987793,,,,
,28458708.01,299.9926147,-1286.11273193359,-5.00785225621584E-7,4.67692299929824E-7,1,0.999253354069792,40.0298881530762,1.97221461587259,14.2700001597404,-5.27120449556524E-6,-2.84210691663481E-6,0.25,-1.67589517756645E-7,-5.00659240918355E-7,-1.6791677100016E-7,299.9926147,299.9926147,-1296.0966796875,-1276.12878417969,56.9627415959868,20.6222989172941,23.668306,0,0,0,40,4449,300.22155,-1286.11273193359,,,,,,,,,,,,,0,,,,-0.00245,,,,,,299.9926147,,,,
,28458797.375,299.9938965,3173.92053222656,-2.32111776734445E-6,4.38886165366433E-7,1,0.999253354069792,40.0298881530762,1.97214887040781,14.2700001597404,-2.41928464600853E-5,-1.45473165189157E-5,0.25,-8.99803304329895E-7,-2.32045229368809E-6,-9.01316056922249E-7,299.9938965,299.9938965,3171.47729492188,3176.36376953125,57.0737328457176,20.6227790355375,23.668306,0,0,0,40,4449,300.2239,3173.92053222656,,,,,,,,,,,,,0,,,,0,,,,,,299.9938965,,,,
,28458887.275,299.9942932,7668.71044921875,-1.32064542533757E-5,6.0864372946787E-7,1,0.999253354069792,40.0298881530762,1.97196246513009,14.2700001597404,-0.000142122679894792,-5.68753998297122E-5,0.25,-2.80256775264558E-6,-1.32042060977849E-5,-2.81123792572146E-6,299.9942932,299.9942932,7661.18798828125,7676.23291015625,57.0198004778906,20.6258127958053,24.047956,0,0,0,40,4449,300.21195,7668.71044921875,,,,,,,,,,,,,0,,,,-0.0049,,,,,,299.9942932,,,,
,28458981.895,300.0034485,12401.5991210938,-2.47831588482464E-5,1.05461054009761E-6,1,0.999253354069792,40.0298881530762,1.97187335070869,14.2700001597404,-0.000268754579490696,-9.48405076147198E-5,0.25,-4.19529621611274E-6,-2.47796406042839E-5,-4.21158308833281E-6,300.0034485,300.0034485,12389.056640625,12414.1416015625,56.9596150819099,20.6264654128541,24.047956,0,0,0,40,4449,300.2179,12401.5991210938,,,,,,,,,,,,,0,,,,0.00245,,,,,,300.0034485,,,,
,28459075.32,300.0005188,17069.5185546875,-3.70521400361981E-5,1.59460816696341E-6,1,0.999253354069792,40.0298881530762,1.97202182212309,14.2700001597404,-0.000401639247428291,-0.000142910984302432,0.25,-6.37148476940169E-6,-3.70468237635608E-5,-6.39581137129552E-6,300.0005188,300.0005188,17062.14453125,17076.892578125,56.9236601700253,20.6223122859786,23.668306,0,0,0,40,4449,300.21575,17069.5185546875,,,,,,,,,,,,,0,,,,0.0049,,,,,,300.0005188,,,,
,28459167.555,300.0064697,21679.396484375,-4.99972808613431E-5,9.34240957184185E-7,1,0.999253354069792,40.0298881530762,1.97201815746175,14.2700001597404,-0.000542325710904525,-0.000190738213675456,0.25,-8.40941232120304E-6,-4.99902286854345E-5,-8.44221248418429E-6,300.0064697,300.0064697,21674.412109375,21684.380859375,56.9744660237753,20.6243303832082,24.047956,0,0,0,40,4449,300.2139,21679.396484375,,,,,,,,,,,,,0,,,,-0.0049,,,,,,300.0064697,,,,
,28459261.5,300.0040741,26372.1005859375,-6.25739835551555E-5,2.10441902484767E-6,1,0.999253354069792,40.0298881530762,1.97180564288495,14.2700001597404,-0.000681347398729249,-0.000223279002013373,0.25,-9.14502703444233E-6,-6.25660842577901E-5,-9.18608088375396E-6,300.0038452,300.004303,26362.244140625,26381.95703125,56.9932251082368,20.6243653114651,24.047956,0,0,0,40,4449,300.21225,26372.1005859375,,,,,,,,,,,,,0,,,,0,,,,,,300.0040741,,,,
,28459355.72,300.0137634,31082.4287109375,-7.54596057805069E-5,1.81165171965351E-6,1,0.999253354069792,40.0298881530762,1.97168931668501,14.2700001597404,-0.000825424994459607,-0.000247212764136304,0.25,-9.05619172540191E-6,-7.54513660439484E-5,-9.10570739944579E-6,300.0137634,300.0137634,31074.875,31089.982421875,57.0745144742368,20.6216382573773,24.047956,0,0,0,40,4449,300.2032,31082.4287109375,,,,,,,,,,,,,0,,,,-0.00245,,,,,,300.0137634,,,,
,28459449.515,300.0088806,35772.955078125,-8.91999734720025E-5,1.41777722298746E-6,1,0.999253354069792,40.0298881530762,1.9718658163135,14.2700001597404,-0.000973525078285667,-0.000305438870263554,0.25,-1.18855941992981E-5,-8.91894833922223E-5,-1.1944034399919E-5,300.0088806,300.0088806,35767.91015625,35778,57.1620568683907,20.6191569541147,23.668306,0,0,0,40,4449,300.19715,35772.955078125,,,,,,,,,,,,,0,,,,0,,,,,,300.0088806,,,,
,28459542.29,300.0127869,40408.0234375,-0.000101794636839198,1.68351299041941E-6,1,0.999253354069792,40.0298881530762,1.97182539697008,14.2700001597404,-0.00111114460453617,-0.000347498866062284,0.25,-1.34689866967888E-5,-0.000101782728453744,-1.3535614096386E-5,300.0127869,300.0127869,40400.6484375,40415.3984375,56.8157954343714,20.6204519369078,24.047956,0,0,0,40,4449,300.18235,40408.0234375,,,,,,,,,,,,,0,,,,-0.00245,,,,,,300.0127869,,,,
,28459635.38,300.0101624,45060.91796875,-0.000114308755419081,1.78950222301913E-6,1,0.999253354069792,40.0298881530762,1.97181298170663,14.2700001597404,-0.00124979444812633,-0.000378334735450396,0.25,-1.40613175797848E-5,-0.000114296110753614,-1.41360915092764E-5,300.0101624,300.0101624,45058.62109375,45063.21484375,57.0557553897753,20.6206931622972,23.668306,0,0,0,40,4449,300.1748,45060.91796875,,,,,,,,,,,,,0,,,,0,,,,,,300.0101624,,,,
,28459732.2,300.0167542,49900.919921875,-0.000130137408970741,2.19914087712958E-6,1,0.999253354069792,40.0298881530762,1.97191539691859,14.2700001597404,-0.00142479707133944,-0.000419954383504378,0.25,-1.50426572005519E-5,-0.000130123636833642,-1.51277185980504E-5,300.0167542,300.0167542,49891.0234375,49910.81640625,56.9603967104291,20.6202710269105,23.288654,0,0,0,40,4449,300.1617,49900.919921875,,,,,,,,,,,,,0,,,,0,,,,,,300.0167542,,,,
,28459823.33,300.0104065,54456.240234375,-0.000141949279523737,2.20771237269613E-6,1,0.999253354069792,40.0298881530762,1.97194299772759,14.2700001597404,-0.00155365151143517,-0.000460894840513628,0.25,-1.66602549835995E-5,-0.000141934144548087,-1.67529346960034E-5,300.0104065,300.0104065,54453.6796875,54458.80078125,57.0182372208522,20.6230020775773,23.668306,0,0,0,40,4449,300.1567,54456.240234375,,,,,,,,,,,,,0,,,,0.0049,,,,,,300.0104065,,,,
,28459919.64,300.0038452,59268.70703125,-0.000158991615767089,2.10412825539962E-6,1,0.999253354069792,40.0298881530762,1.97191717287648,14.2700001597404,-0.00173952076840393,-0.000519917360182999,0.25,-1.89912445531736E-5,-0.000158974509238271,-1.90949265981574E-5,300.0038452,300.0038452,59261.1484375,59276.265625,57.0534105042176,20.6232011946943,24.047956,0,0,0,40,4449,300.1541,59268.70703125,,,,,,,,,,,,,0,,,,0.0049,,,,,,300.0038452,,,,
,28460019.195,300.0102844,64244.193359375,-0.000169483452111399,2.91952251291905E-6,1,0.999253354069792,40.0298881530762,1.97185718311202,14.2700001597404,-0.00185497522342487,-0.000550067551437763,0.25,-1.98737741667244E-5,-0.000169465448365665,-1.99841710395039E-5,300.0102844,300.0102844,64239.05078125,64249.3359375,56.9955699937945,20.6236832450864,23.668306,0,0,0,40,4449,300.15095,64244.193359375,,,,,,,,,,,,,0,,,,-0.0049,,,,,,300.0102844,,,,
,28460117.195,300.0108032,69141.5859375,-0.00018261034020327,2.12085375853468E-6,1,0.999253354069792,40.0298881530762,1.97186062698693,14.2700001597404,-0.00200571787506655,-0.000551882661979552,0.25,-1.77620528569496E-5,-0.000182593355979844,-1.78809657649005E-5,300.0108032,300.0108032,69136.625,69146.546875,56.9314764552176,20.6218839135462,24.047956,0,0,0,40,4449,300.1436,69141.5859375,,,,,,,,,,,,,0,,,,0.0049,,,,,,300.0108032,,,,
,28460218.26,300.0134583,74194.31640625,-0.000198021502838565,1.94268077948457E-6,1,0.999253354069792,40.0298881530762,1.97177677055779,14.2700001597404,-0.00217887836116052,-0.000575467670737508,0.25,-1.72054208057844E-5,-0.000198004438053509,-1.73342742983648E-5,300.0134583,300.0134583,74189.265625,74199.3671875,57.004167907506,20.6191164234478,24.047956,0,0,0,40,4449,300.1222,74194.31640625,,,,,,,,,,,,,0,,,,0.0049,,,,,,300.0134583,,,,
,28460316.995,300.0113831,79129.90625,-0.000211785362236913,3.41939819962993E-6,1,0.999253354069792,40.0298881530762,1.97181494406408,14.2700001597404,-0.00232507036417504,-0.000646062524469553,0.25,-2.11391710560725E-5,-0.000211765370456225,-2.127673423822E-5,300.0113831,300.0113831,79122.3984375,79137.4140625,56.9455457685637,20.6225166782251,24.047956,0,0,0,40,4449,300.1112,79129.90625,,,,,,,,,,,,,0,,,,0,,,,,,300.0113831,,,,
,28460414.165,300.0110474,83988.49609375,-0.0002280720604364,3.8675069347351E-6,1,0.999253354069792,40.0298881530762,1.97175968623161,14.2700001597404,-0.00250709643124281,-0.000676734920985995,0.25,-2.10648841660726E-5,-0.000228051676166647,-2.12128952098732E-5,300.0110474,300.0110474,83986.0625,83990.9296875,56.9979148793522,20.6220068863684,24.047956,0,0,0,40,4449,300.10285,83988.49609375,,,,,,,,,,,,,0,,,,0,,,,,,300.0110474,,,,
,28460508.21,300.0162659,88686.51171875,-0.000241493883267938,2.80026502029857E-6,1,0.999253354069792,40.0298881530762,1.97171700136693,14.2700001597404,-0.0026569136323858,-0.000703084432463422,0.25,-2.10997524943901E-5,-0.000241473072379161,-2.12563180677344E-5,300.0162659,300.0162659,88684.1796875,88688.84375,56.8658196596022,20.6225957974707,23.668306,0,0,0,40,4449,300.09445,88686.51171875,,,,,,,,,,,,,0,,,,0,,,,,,300.0162659,,,,
,28460618.455,300.0090027,86771.3203125,-0.000237950204118524,3.49424780525806E-6,1,0.999253354069792,40.0298881530762,1.97167151387351,14.2700001597404,-0.00261232583076853,-0.000724747132498705,0.25,-2.36541910342295E-5,-0.000237927880149475,-2.38084678477083E-5,300.0090027,300.0090027,86763.8359375,86778.8046875,56.9377294833714,20.6244238839697,23.288654,0,0,0,40,4449,300.079,86771.3203125,,,,,,,,,,,,,0,,,,-0.00245,,,,,,300.0090027,,,,
,28460714.235,300.0066528,81985.4140625,-0.000221205844356027,2.9158303262641E-6,1,0.999253354069792,40.0298881530762,1.97174913328573,14.2700001597404,-0.00243042334498359,-0.000663189671980601,0.25,-2.10421501034701E-5,-0.000221185694192915,-2.11857772947528E-5,300.0066528,300.0066528,81980.65625,81990.171875,56.8564401173714,20.6188116104413,23.668306,0,0,0,40,4449,300.08095,81985.4140625,,,,,,,,,,,,,0,,,,-0.00245,,,,,,300.0066528,,,,
,28460813.61,299.9856567,77013.9609375,-0.000207163982447858,3.63914770935542E-6,1,0.999253354069792,40.0298881530762,1.97186864998463,14.2700001597404,-0.00227824035409099,-0.000609792293148438,0.25,-1.86916282411917E-5,-0.000207145899918199,-1.88263449943721E-5,299.9856567,299.9856567,77006.625,77021.296875,57.0745144742368,20.61937578438,23.668306,0,0,0,40,4449,300.0981,77013.9609375,,,,,,,,,,,,,0,,,,0,,,,,,299.9856567,,,,
,28460910.355,299.9906616,72178.45703125,-0.00019120082095789,3.20556848529415E-6,1,0.999253354069792,40.0298881530762,1.97200488877099,14.2700001597404,-0.00210924331281567,-0.000525807657257728,0.25,-1.39365030155122E-5,-0.00019118623644975,-1.40610846360529E-5,299.9906616,299.9906616,72173.4140625,72183.5,56.9783741663714,20.6184674090768,23.668306,0,0,0,40,4449,300.0962,72178.45703125,,,,,,,,,,,,,0,,,,0.0049,,,,,,299.9906616,,,,
,28461009.645,299.981781,67217.7890625,-0.000178182092464524,2.58998062650078E-6,1,0.999253354069792,40.0298881530762,1.97206302431261,14.2700001597404,-0.00195551515387215,-0.000548703809389156,0.25,-1.82397693871148E-5,-0.000178165098385472,-1.83558600833301E-5,299.981781,299.981781,67210.453125,67225.125,56.997133250833,20.6189143126264,23.668306,0,0,0,40,4449,300.1142,67217.7890625,,,,,,,,,,,,,0,,,,0.00245,,,,,,299.981781,,,,
,28461108.4,299.9885864,62279.47265625,-0.00016406575033102,2.55383343009711E-6,1,0.999253354069792,40.0298881530762,1.97202795645153,14.2700001597404,-0.00180015948448844,-0.000507533929515378,0.25,-1.70013232204018E-5,-0.000164049903098696,-1.71083311348877E-5,299.9885864,299.9885864,62276.88671875,62282.05859375,56.9705578811791,20.6196880780908,23.668306,0,0,0,40,4449,300.1292,62279.47265625,,,,,,,,,,,,,0,,,,0.0049,,,,,,299.9885864,,,,
,28461208.265,299.9883728,57286.720703125,-0.000147280495445507,2.84514285601668E-6,1,0.999253354069792,40.0298881530762,1.97233908400954,14.2700001597404,-0.00163041664527683,-0.000373805876437725,0.25,-7.93513207361635E-6,-0.000147271054725914,-8.03151700254288E-6,299.9883728,299.9883728,57278.96484375,57294.4765625,56.8900501436983,20.6162041054607,23.668306,0,0,0,40,4449,300.1373,57286.720703125,,,,,,,,,,,,,0,,,,0,,,,,,299.9883728,,,,
,28461307,299.990509,52354.49609375,-0.000137106537798987,2.04653620257955E-6,1,0.999253354069792,40.0298881530762,1.97207756082653,14.2700001597404,-0.00150079521811061,-0.000444916277515589,0.25,-1.60664038968488E-5,-0.000137092023519501,-1.61559837092732E-5,299.990509,299.990509,52346.90234375,52362.08984375,57.1808159528522,20.6177451783632,24.047956,0,0,0,40,4449,300.143,52354.49609375,,,,,,,,,,,,,0,,,,0,,,,,,299.990509,,,,
,28461404.485,299.9910889,47479.40234375,-0.000119948491487274,2.30589630116268E-6,1,0.999253354069792,40.0298881530762,1.97209889589062,14.2700001597404,-0.00131241443191172,-0.000392582327796075,0.25,-1.43546903501777E-5,-0.000119935576206108,-1.44331388051567E-5,299.9910889,299.9910889,47474.10546875,47484.69921875,56.966649738583,20.619097608708,23.288654,0,0,0,40,4449,300.1498,47479.40234375,,,,,,,,,,,,,0,,,,0,,,,,,299.9910889,,,,
,28461500.045,299.9886169,42703.923828125,-0.000107524406160605,2.31537542680312E-6,1,0.999253354069792,40.0298881530762,1.97199276418669,14.2700001597404,-0.00117412420786831,-0.000365128402701962,0.25,-1.40516839431898E-5,-0.000107512043114589,-1.41220487780169E-5,299.9886169,299.9886169,42701.32421875,42706.5234375,56.882233858506,20.621199673451,23.668306,0,0,0,40,4449,300.15905,42703.923828125,,,,,,,,,,,,,0,,,,-0.0049,,,,,,299.9886169,,,,
,28461596.985,299.9916992,37861.37890625,-9.40963509332876E-5,1.77278505509539E-6,1,0.999253354069792,40.0298881530762,1.97196820281113,14.2700001597404,-0.00102960831868751,-0.000307256715951094,0.25,-1.11986235669312E-5,-9.40862303809441E-5,-1.12602974098978E-5,299.9916992,299.9916992,37854.08984375,37868.66796875,57.027616763083,20.6235221462999,24.427608,0,0,0,40,4449,300.1658,37861.37890625,,,,,,,,,,,,,0,,,,0,,,,,,299.9916992,,,,
,28461694.22,299.98880005,33001.791015625,-8.08295349635565E-5,2.32012849397336E-6,1,0.999253354069792,40.0298881530762,1.97203647588537,14.2700001597404,-0.000887033496926502,-0.000249155754904599,0.25,-8.29599204937181E-6,-8.08217112993701E-5,-8.34906468443968E-6,299.9877625,299.9898376,32996.89453125,33006.6875,57.0940551872176,20.6227552734953,23.288654,0,0,0,40,4449,300.1757,33001.791015625,,,,,,,,,,,,,0,,,,0,,,,,,299.98880005,,,,
,28461790.335,299.9908447,28196.904296875,-6.63926156432921E-5,1.64616914675758E-6,1,0.999253354069792,40.0298881530762,1.97200616007455,14.2700001597404,-0.000724639361816436,-0.000227453747534148,0.25,-8.85513892368719E-6,-6.6384828475115E-5,-8.89871595879299E-6,299.9908447,299.9908447,28194.66015625,28199.1484375,57.159711982833,20.6219487802018,23.668306,0,0,0,40,4449,300.1824,28196.904296875,,,,,,,,,,,,,0,,,,0,,,,,,299.9908447,,,,
,28461883.35,299.9889221,23549.2509765625,-5.42210599950028E-5,1.51116018493201E-6,1,0.999253354069792,40.0298881530762,1.97203157208596,14.2700001597404,-0.000591619549118019,-0.000186803113270605,0.25,-7.32529334536165E-6,-5.42146346928607E-5,-7.36091320977202E-6,299.9889221,299.9889221,23541.607421875,23556.89453125,57.0635716749676,20.6231141968948,23.288654,0,0,0,40,4449,300.1854,23549.2509765625,,,,,,,,,,,,,0,,,,0,,,,,,299.9889221,,,,
,28461981.75,299.984436,18629.6591796875,-4.01822872548071E-5,1.40125980533899E-6,1,0.999253354069792,40.0298881530762,1.97200931270985,14.2700001597404,-0.000436129392149631,-0.000151738178075157,0.25,-6.61930843638942E-6,-4.01767387883234E-5,-6.64569664285513E-6,299.984436,299.984436,18620.0703125,18639.248046875,57.169873153583,20.6231558973573,24.047956,0,0,0,40,4449,300.19665,18629.6591796875,,,,,,,,,,,,,0,,,,0,,,,,,299.984436,,,,
,28462077.465,299.9879456,13844.5190429688,-2.77487642887809E-5,6.62125854496002E-7,1,0.999253354069792,40.0298881530762,1.97215874012668,14.2700001597404,-0.000302565796736522,-9.69136315035346E-5,0.25,-3.86584312065712E-6,-2.7745391969749E-5,-3.88410224848681E-6,299.9879456,299.9879456,13837.330078125,13851.7080078125,56.9861904515637,20.6209744906157,24.047956,0,0,0,40,4449,300.20215,13844.5190429688,,,,,,,,,,,,,0,,,,0,,,,,,299.9879456,,,,
,28462174.945,299.987915,8974.912109375,-1.59244648592069E-5,9.78154391287613E-7,1,0.999253354069792,40.0298881530762,1.97211286443305,14.2700001597404,-0.000171757679095067,-6.64371637813599E-5,0.25,-3.18705313012359E-6,-1.59218859166081E-5,-3.19751143235839E-6,299.9877319,299.9880981,8944.9208984375,9004.9033203125,57.2050464369484,20.621503778429,23.288654,0,0,0,40,4449,300.2226,8974.912109375,,,,,,,,,,,,,0,,,,-0.00245,,,,,,299.987915,,,,
,28462273.78,299.9926453,4036.32189941406,-4.28599425628517E-6,5.16161494491476E-7,1,0.999253354069792,40.0298881530762,1.97211514628639,14.2700001597404,-4.4860035374816E-5,-2.57755716774324E-5,0.25,-1.56431648128847E-6,-4.28483020960677E-6,-1.56711251516632E-6,299.9926453,299.9926453,4026.20678710937,4046.43701171875,57.0080760501022,20.6241283992443,23.668306,0,0,0,40,4449,300.21555,4036.32189941406,,,,,,,,,,,,,0,,,,0,,,,,,299.9926453,,,,
,28466886.81,10.0033102,-0.137013956904411,,,2,,,,15.400000127852,,,,,,,10.0033102,10.0033102,-0.137013956904411,-0.137013956904411,,,12.278775,,,,-99999999,4369,10.0077,-0.137013956904411,,,,,,,,,,,,,,,,,,,,,,,10.0033102,,,,