File: data/monolayers/nanoparticles/Ol_CoFe_C/vsm/data_disorderedWafer/DD227_HYST_10K.DAT
[Header]
; VSM Data File (default extension .dat)
; Copyright (c) 2003-2013, Quantum Design, Inc. All rights reserved.
TITLE,
FILEOPENTIME,28466888.20,11/26/2018,7:28 pm
BYAPP,VSM,2.0,2.0
INFO,PPMS VSM Option Release 1.4.10 Build 1,APPNAME
INFO,Quantum Design Linear Motor Servo Controller,MOTOR_MODULE_NAME
INFO,3101-100 M1,MOTOR_HW_VERSION
INFO,MMC1014,MOTOR_SERIAL_NUMBER
INFO,SRV No X-over 01.03.11,MOTOR_SOFTWARE_VERSION
INFO,Quantum Design VSM Detection Module,VSM_MODULE_NAME
INFO,3101-150 F0,VSM_HW_VERSION
INFO,VSM707,VSM_SERIAL_NUMBER
INFO,VSM No X-over 01.02.05 May 20 2008 13:51:47,VSM_SOFTWARE_VERSION
INFO,704,PREAMP_SERIAL_NUMBER
INFO,822,COIL_SERIAL_NUMBER
INFO,0,MOMENT_UNITS
INFO,CoFe2O4 FeO,SAMPLE_MATERIAL
INFO,disordered monolayer,SAMPLE_COMMENT
INFO,25.46,SAMPLE_MASS
INFO,,SAMPLE_VOLUME
INFO,,SAMPLE_MOLECULAR_WEIGHT
INFO,,SAMPLE_SIZE
INFO,,SAMPLE_SHAPE
DATATYPE,COMMENT,1
DATATYPE,TIME,2
STARTUPAXIS,X,2
STARTUPAXIS,Y1,5
[Data]
Comment,Time Stamp (sec),Temperature (K),Magnetic Field (Oe),Moment (emu),M. Std. Err. (emu),Transport Action,Averaging Time (sec),Frequency (Hz),Peak Amplitude (mm),Center Position (mm),Coil Signal' (mV),Coil Signal" (mV),Range (mV),M. Quad. Signal (emu),M. Raw' (emu),M. Raw" (emu),Min. Temperature (K),Max. Temperature (K),Min. Field (Oe),Max. Field (Oe),Mass (grams),Motor Lag (deg),Pressure (Torr),VSM Status (code),Motor Status (code),Measure Status (code),Measure Count,PPMS Status (code),System Temp. (K),System Field (Oe),Sample Position (deg),Bridge 1 Resistance (ohms),Bridge 1 Excitation (에),Bridge 2 Resistance (ohms),Bridge 2 Excitation (에),Bridge 3 Resistance (ohms),Bridge 3 Excitation (에),Bridge 4 Resistance (ohms),Bridge 4 Excitation (에),Signal 1 Vin (V),Signal 2 Vin (V),Digital Inputs (code),Drive 1 Iout (mA),Drive 1 Ipower (W),Drive 2 Iout (mA),Drive 2 Ipower (W),Pressure (),Map 20 (),Map 21 (),Map 22 (),Map 23 (),Map 24 (),Map 25 (),Map 26 (),Map 27 (),Map 28 (),Map 29 ()
sample offset = 36.55 mm touchdown = 10.780000127852 mm,28466930.98,10.00543545,0.129402078688145,6.02746947948098E-7,3.50082545312437E-7,1,0.999253354069792,40.0298881530762,1.99728785680615,15.3900003060699,7.13987459846172E-6,-8.64161965647222E-7,0.25,-1.83937261804285E-7,6.00170979518254E-7,-1.79975418755602E-7,10.0053577,10.0055132,0.106566414237022,0.152237743139267,55.6214670569867,20.583807316417,12.658426,0,0,0,40,4417,10.00565,0.129402078688145,,,,,,,,,,,,,0,,,,0,,,,,,10.00543545,,,,
,28467051.72,9.9993572,4955.72338867188,-1.40012262073441E-5,3.83043177281492E-7,1,0.999253354069792,40.0298881530762,1.99755152854066,15.3900003060699,-0.000156560671347364,-3.26121086053149E-5,0.25,-4.10641527786098E-7,-1.39225205679756E-5,-4.80143650049625E-7,9.9993572,9.9993572,4945.87158203125,4965.5751953125,56.3804283491598,20.6018565208334,12.278775,0,0,0,40,4449,9.998,4955.72338867188,,,,,,,,,,,,,0,,,,0.00245,,,,,,9.9993572,,,,
,28467151.97,10.0062714,9964.837890625,-2.89709690313748E-5,3.5131357671909E-7,1,0.999253354069792,40.0298881530762,1.99747908691574,15.3900003060699,-0.000323758127689463,-6.91897595996546E-5,0.25,-9.89109274016488E-7,-2.88178622172709E-5,-1.14315893161058E-6,10.0062714,10.0062714,9952.0888671875,9977.5869140625,56.7204367550252,20.6035490744409,11.899124,0,0,0,40,4449,10.00405,9964.837890625,,,,,,,,,,,,,0,,,,0.00245,,,,,,10.0062714,,,,
,28467249.58,10.005331,14844.8491210938,-4.35730830792235E-5,4.2161561182962E-7,1,0.999253354069792,40.0298881530762,1.99740291334928,15.3900003060699,-0.000489981648524755,-8.80960333407564E-5,0.25,-4.90910983451337E-8,-4.33688963669112E-5,-3.03607892422191E-7,10.005331,10.005331,14834.89453125,14854.8037109375,56.7008960420445,20.6070264525293,11.899124,0,0,0,40,4449,9.9932,14844.8491210938,,,,,,,,,,,,,0,,,,-0.00245,,,,,,10.005331,,,,
,28467344.905,10.005682,19609.5947265625,-5.7275842353131E-5,5.20226511615002E-7,1,0.999253354069792,40.0298881530762,1.99719995463218,15.3900003060699,-0.000644182050673034,-0.000116483094566803,0.25,-1.03035959528717E-7,-5.70327177744406E-5,-4.5608794692464E-7,10.0055695,10.0057945,19597.05078125,19622.138671875,56.6344576179098,20.6058836672099,12.278775,0,0,0,40,4449,9.9886,19609.5947265625,,,,,,,,,,,,,0,,,,0,,,,,,10.005682,,,,
,28467441.9,10.0042543,24457.0205078125,-7.13461611497876E-5,4.38878383340882E-7,1,0.999253354069792,40.0298881530762,1.99722191432732,15.3900003060699,-0.000802058007942125,-0.00014946913988313,0.25,-4.89116807124422E-7,-7.10752970713959E-5,-9.48918736096187E-7,10.0042543,10.0042543,24449.599609375,24464.44140625,56.7376325824483,20.6100366456235,12.278775,0,0,0,40,4449,9.98485,24457.0205078125,,,,,,,,,,,,,0,,,,-0.0049,,,,,,10.0042543,,,,
,28467527.22,10.0035715,28720.2236328125,-8.295120137063E-5,3.53474156781262E-7,1,0.999253354069792,40.0298881530762,1.99701943136506,15.3900003060699,-0.000935128180155473,-0.000161097482143083,0.25,5.82190225922974E-7,-8.26803267400864E-5,2.43765309430298E-8,10.0035715,10.0035715,28717.458984375,28722.98828125,56.4687523718329,20.6087847672047,12.658426,0,0,0,40,4449,9.9825,28720.2236328125,,,,,,,,,,,,,0,,,,-0.00245,,,,,,10.0035715,,,,
,28467613.235,10.0021791,33018.232421875,-9.54993244376966E-5,5.70513175161509E-7,1,0.999253354069792,40.0298881530762,1.9970371821714,15.3900003060699,-0.00107697998059469,-0.000186147341034895,0.25,6.36411368388358E-7,-9.52305702763946E-5,-2.45255216060395E-8,10.0021791,10.0021791,33015.68359375,33020.78125,56.953362053756,20.6086718141915,11.899124,0,0,0,40,4449,9.9809,33018.232421875,,,,,,,,,,,,,0,,,,0,,,,,,10.0021791,,,,
,28467701.665,10.0002632,37440.775390625,-0.000107880402638555,6.26844773125574E-7,1,0.999253354069792,40.0298881530762,1.99681957652631,15.3900003060699,-0.0012178916450672,-0.00020570529506805,0.25,1.15004915327174E-6,-0.000107630607628694,3.84230792331777E-7,10.0002327,10.0002937,37428.359375,37453.19140625,56.9049010855637,20.60876322272,12.658426,0,0,0,40,4449,9.9802,37440.775390625,,,,,,,,,,,,,0,,,,0.0049,,,,,,10.0002632,,,,
,28467789.375,9.9988384,41823.318359375,-0.000120586520743764,5.62942656733245E-7,1,0.999253354069792,40.0298881530762,1.99677725012023,15.3900003060699,-0.00136012397134016,-0.000240141503765831,0.25,4.05002816128164E-7,-0.000120357069502858,-4.65066246234487E-7,9.9988384,9.9988384,41815.7265625,41830.91015625,56.7173102409483,20.6120832573302,11.899124,0,0,0,40,4449,9.9816,41823.318359375,,,,,,,,,,,,,0,,,,0.00245,,,,,,9.9988384,,,,
,28467875.19,9.9978752,46111.53125,-0.000131496026494738,8.18629734391456E-7,1,0.999253354069792,40.0298881530762,1.99715805408618,15.3900003060699,-0.00148531486971062,-0.000255360478810645,0.25,1.04603799904802E-6,-0.000131309257158979,8.33104684525202E-8,9.9978752,9.9978752,46109,46114.0625,56.9783741663714,20.6139282499155,12.278775,0,0,0,40,4449,9.98335,46111.53125,,,,,,,,,,,,,0,,,,0.00245,,,,,,9.9978752,,,,
,28467962.835,9.9970388,50494.3984375,-0.000146657990597915,6.44668644321269E-7,1,0.999253354069792,40.0298881530762,1.9971831613698,15.3900003060699,-0.00165875675544743,-0.000277096391227877,0.25,1.87153484323972E-6,-0.000146520865304545,7.87000620889294E-7,9.9970388,9.9970388,50486.94921875,50501.84765625,57.2535074051407,20.6110831998552,12.278775,0,0,0,40,4449,9.9872,50494.3984375,,,,,,,,,,,,,0,,,,0,,,,,,9.9970388,,,,
,28468055.04,9.9958611,55101.509765625,-0.000158845686484373,6.29661426879892E-7,1,0.999253354069792,40.0298881530762,1.99696985643565,15.3900003060699,-0.001793410338803,-0.000321523808723368,0.25,1.47475512497695E-7,-0.000158756217355963,-1.03234870534573E-6,9.9958611,9.9958611,55093.98046875,55109.0390625,57.0237086204868,20.6089377951943,12.278775,0,0,0,40,4449,9.98985,55101.509765625,,,,,,,,,,,,,0,,,,0.00245,,,,,,9.9958611,,,,
,28468148.165,9.9951191,59754.5625,-0.000171194555714675,7.22722523902051E-7,1,0.999253354069792,40.0298881530762,1.99686895159981,15.3900003060699,-0.00193446901985672,-0.00034185983170447,0.25,5.86068592667023E-7,-0.000171177868547735,-6.88282990978314E-7,9.9951191,9.9951191,59722.1171875,59787.0078125,57.129228470583,20.6120638699077,12.278775,0,0,0,40,4449,9.99435,59754.5625,,,,,,,,,,,,,0,,,,0,,,,,,9.9951191,,,,
,28468245.61,9.9947844,64625.03125,-0.000187917883362399,6.53322620178482E-7,1,0.999253354069792,40.0298881530762,1.99671213783301,15.3900003060699,-0.00212678917388098,-0.000361206938922399,0.25,1.89661494074788E-6,-0.000187993094004032,5.00435218122033E-7,9.9947844,9.9947844,64615.05078125,64635.01171875,57.1198489283522,20.6145877660839,12.278775,0,0,0,40,4449,9.99895,64625.03125,,,,,,,,,,,,,0,,,,0,,,,,,9.9947844,,,,
,28468343.915,9.9951029,69540.0234375,-0.00020362864449245,7.85356918401835E-7,1,0.999253354069792,40.0298881530762,1.99666026965436,15.3900003060699,-0.00230252135913807,-0.000408261176509533,0.25,5.69881497535253E-7,-0.000203786659046512,-9.36029778679652E-7,9.9951029,9.9951029,69532.46875,69547.578125,57.034651419756,20.6131959806027,12.278775,0,0,0,40,4449,10.0036,69540.0234375,,,,,,,,,,,,,0,,,,-0.0049,,,,,,9.9951029,,,,
,28468441.64,9.9954519,74425.37109375,-0.000216219226546567,9.56507250105159E-7,1,0.999253354069792,40.0298881530762,1.99661806594089,15.3900003060699,-0.00244736691596001,-0.000425117831614555,0.25,1.34873403705109E-6,-0.000216479902620917,-2.36959876482221E-7,9.9954519,9.9954519,74415.421875,74435.3203125,57.0659165605253,20.6150385538635,12.278775,0,0,0,40,4449,10.0083,74425.37109375,,,,,,,,,,,,,0,,,,0,,,,,,9.9954519,,,,
,28468540.035,9.9956102,79340.3828125,-0.000235298811389711,8.02763390415209E-7,1,0.999253354069792,40.0298881530762,1.99643199290376,15.3900003060699,-0.00266651477258116,-0.000449398510145185,0.25,2.6315253763917E-6,-0.000235681092744103,9.25861164266353E-7,9.9956102,9.9956102,79333.0078125,79347.7578125,57.0213637349291,20.6196152602805,12.658426,0,0,0,40,4449,10.01355,79340.3828125,,,,,,,,,,,,,0,,,,0,,,,,,9.9956102,,,,
,28468637.56,9.9945211,84219.1640625,-0.000248635235717664,6.73808852302091E-7,1,0.999253354069792,40.0298881530762,1.99646199162468,15.3900003060699,-0.00281539114743422,-0.000493383311775433,0.25,1.13717158556194E-6,-0.000249116075553287,-6.45199227653673E-7,9.9945211,9.9945211,84211.75,84226.578125,57.0510656186599,20.6170652621694,11.899124,0,0,0,40,4449,10.0171,84219.1640625,,,,,,,,,,,,,0,,,,0.00245,,,,,,9.9945211,,,,
,28468728.07,9.9949398,88742.1640625,-0.000264644427597771,1.08179656936133E-6,1,0.999253354069792,40.0298881530762,1.99653994488485,15.3900003060699,-0.00299122287591258,-0.000561396949497219,0.25,-2.00106527047683E-6,-0.000265215801129797,-3.8803154171053E-6,9.9949398,9.9949398,88734.8203125,88749.5078125,57.0119841926983,20.6187657788636,11.899124,0,0,0,40,4449,10.022,88742.1640625,,,,,,,,,,,,,0,,,,-0.0049,,,,,,9.9949398,,,,
,28468837.33,9.9981661,86831.04296875,-0.00025884865535455,8.98874697331494E-7,1,0.999253354069792,40.0298881530762,1.99660664152728,15.3900003060699,-0.00293248466148619,-0.000509837152417533,0.25,1.51827982219767E-6,-0.000259398729449454,-3.22779336040647E-7,9.9981661,9.9981661,86828.3515625,86833.734375,57.0792042453522,20.6154981343077,12.278775,0,0,0,40,4449,10.0238,86831.04296875,,,,,,,,,,,,,0,,,,0,,,,,,9.9981661,,,,
,28468930.89,10.0006723,82155.28125,-0.000243911592838387,9.26666096368408E-7,1,0.999253354069792,40.0298881530762,1.9966030513939,15.3900003060699,-0.00276428503160506,-0.000469507776349086,0.25,2.40381924586832E-6,-0.000244356406374123,6.47842814455448E-7,10.0006723,10.0006723,82144.953125,82165.609375,57.0229269919676,20.618760593363,11.519473,0,0,0,40,4449,10.0224,82155.28125,,,,,,,,,,,,,0,,,,0,,,,,,10.0006723,,,,
,28469028.85,10.0014935,77258.69140625,-0.000226243847692222,8.13335025271053E-7,1,0.999253354069792,40.0298881530762,1.99655002588156,15.3900003060699,-0.00255663282030614,-0.000470954744296816,0.25,-9.01300601296399E-7,-0.000226550343353825,-2.55409257651362E-6,10.0014935,10.0014935,77246.0625,77271.3203125,56.8767624588714,20.6223322032996,12.278775,0,0,0,40,4449,10.01955,77258.69140625,,,,,,,,,,,,,0,,,,-0.0049,,,,,,10.0014935,,,,
,28469127.08,10.0027599,72347.5546875,-0.00021113948376102,7.1859704918573E-7,1,0.999253354069792,40.0298881530762,1.99662246397465,15.3900003060699,-0.00237901885930756,-0.000473079019340517,0.25,-3.80950426707924E-6,-0.000211320568925367,-5.36882044044631E-6,10.0027599,10.0027599,72342.359375,72352.75,57.1104693861214,20.6208627950605,12.278775,0,0,0,40,4449,10.017,72347.5546875,,,,,,,,,,,,,0,,,,0,,,,,,10.0027599,,,,
,28469226.44,10.0031242,67380.0703125,-0.000195991737605071,7.95306296958909E-7,1,0.999253354069792,40.0298881530762,1.9968630469179,15.3900003060699,-0.00221027836093432,-0.000424498068843598,0.25,-2.24241387491301E-6,-0.000196086645003852,-3.69715589228849E-6,10.0031242,10.0031242,67370.171875,67389.96875,57.149550812083,20.6216092164994,11.899124,0,0,0,40,4449,10.01465,67380.0703125,,,,,,,,,,,,,0,,,,0,,,,,,10.0031242,,,,
,28469324.205,10.0029812,62494.296875,-0.000179503370806281,8.59112484877813E-7,1,0.999253354069792,40.0298881530762,1.99699128898697,15.3900003060699,-0.00202303593291745,-0.000391610189063542,0.25,-2.31166696784735E-6,-0.00017950982006417,-3.64762676656102E-6,10.0029173,10.0030451,62486.55078125,62502.04296875,57.1300100991022,20.6208696384004,12.278775,0,0,0,40,4449,10.01105,62494.296875,,,,,,,,,,,,,0,,,,-0.00245,,,,,,10.0029812,,,,
,28469425.635,10.0023422,57426.087890625,-0.000165366108871177,8.47698578352133E-7,1,0.999253354069792,40.0298881530762,1.9968874099354,15.3900003060699,-0.0018605875904723,-0.000372443758596912,0.25,-3.18031940036749E-6,-0.000165285476885729,-4.40932389873133E-6,10.0023422,10.0023422,57418.68359375,57433.4921875,57.1034347294484,20.6211360273282,11.899124,0,0,0,40,4449,10.0085,57426.087890625,,,,,,,,,,,,,0,,,,0,,,,,,10.0023422,,,,
,28469527.84,10.0033092,52313.8359375,-0.000147914049808237,7.94845214332178E-7,1,0.999253354069792,40.0298881530762,1.99675105996725,15.3900003060699,-0.00166510933449538,-0.000322831260295212,0.25,-1.95274432809923E-6,-0.000147774437001538,-3.04614230264507E-6,10.0033092,10.0033092,52306.1328125,52321.5390625,57.2159892362176,20.6209563077971,11.899124,0,0,0,40,4449,10.0058,52313.8359375,,,,,,,,,,,,,0,,,,0.0049,,,,,,10.0033092,,,,
,28469625.835,10.0035324,47418.8515625,-0.000131207023760685,7.60000516716552E-7,1,0.999253354069792,40.0298881530762,1.99662753351431,15.3900003060699,-0.00147565992571579,-0.000289272819887378,0.25,-2.01252640808884E-6,-0.000131016003423733,-2.97213292907926E-6,10.0035324,10.0035324,47413.8359375,47423.8671875,57.3043132588907,20.6220361500858,12.278775,0,0,0,40,4449,10.0026,47418.8515625,,,,,,,,,,,,,0,,,,-0.00245,,,,,,10.0035324,,,,
,28469724.845,10.0032835,42468.431640625,-0.000116033064219217,7.72971004183359E-7,1,0.999253354069792,40.0298881530762,1.99659146340787,15.3900003060699,-0.00130406490990745,-0.000257021652608835,0.25,-1.91074361092742E-6,-0.000115803539703632,-2.74564273500113E-6,10.0032835,10.0032835,42460.8359375,42476.02734375,57.5067550453715,20.6221314337358,12.278775,0,0,0,40,4449,10.0001,42468.431640625,,,,,,,,,,,,,0,,,,0,,,,,,10.0032835,,,,
,28469822.085,10.002636,37611.232421875,-9.97378527074297E-5,5.90438742500427E-7,1,0.999253354069792,40.0298881530762,1.99686211275885,15.3900003060699,-0.00112139528259365,-0.000215847829323339,0.25,-1.21352143425841E-6,-9.94926046364023E-5,-1.9167052219647E-6,10.002636,10.002636,37603.609375,37618.85546875,57.1042163579676,20.6218002069439,12.278775,0,0,0,40,4449,9.997,37611.232421875,,,,,,,,,,,,,0,,,,0.00245,,,,,,10.002636,,,,
,28469917.955,10.001586,32816.455078125,-8.45278496828428E-5,5.57600077713703E-7,1,0.999253354069792,40.0298881530762,1.99666706247359,15.3900003060699,-0.000946464603515992,-0.000201439351339754,0.25,-2.69718780786182E-6,-8.42656862969289E-5,-3.27207695002555E-6,10.001586,10.001586,32806.45703125,32826.453125,57.0323065341983,20.6253026968511,11.519473,0,0,0,40,4449,9.9966,32816.455078125,,,,,,,,,,,,,0,,,,0,,,,,,10.001586,,,,
,28470016.25,10.0013189,27906.3876953125,-7.14678328053412E-5,5.30008754048862E-7,1,0.999253354069792,40.0298881530762,1.99663698567747,15.3900003060699,-0.000801570779219752,-0.000160414443417662,0.25,-1.42526521536845E-6,-7.12155442873798E-5,-1.8963767233131E-6,10.0013189,10.0013189,27903.931640625,27908.84375,56.926005055583,20.6233979307843,11.519473,0,0,0,40,4449,9.99545,27906.3876953125,,,,,,,,,,,,,0,,,,0,,,,,,10.0013189,,,,
,28470113.18,10.0004091,23061.2958984375,-5.79707051870275E-5,5.89500222470536E-7,1,0.999253354069792,40.0298881530762,1.99665049987984,15.3900003060699,-0.000650162931898069,-0.000128434540035953,0.25,-1.027615075909E-6,-5.77384535141422E-5,-1.39393877292096E-6,10.0004091,10.0004091,23051.173828125,23071.41796875,57.1948852661984,20.6262637767767,11.519473,0,0,0,40,4449,9.99465,23061.2958984375,,,,,,,,,,,,,0,,,,-0.00245,,,,,,10.0004091,,,,
,28470209.67,9.9998102,18239.173828125,-4.25691236601762E-5,3.94096446807135E-7,1,0.999253354069792,40.0298881530762,1.99653100497202,15.3900003060699,-0.000476424538685227,-9.8467484033381E-5,0.25,-1.14152585095331E-6,-4.23763627250095E-5,-1.39540551261679E-6,9.9998102,9.9998102,18229.06640625,18249.28125,57.2925888311022,20.6274083226023,11.899124,0,0,0,40,4449,9.99535,18239.173828125,,,,,,,,,,,,,0,,,,-0.0049,,,,,,9.9998102,,,,
,28470302.745,9.9998169,13587.0473632812,-2.95348188870875E-5,3.2494271304783E-7,1,0.999253354069792,40.0298881530762,1.99655083151743,15.3900003060699,-0.00033111693132566,-6.43368759451826E-5,0.25,-4.4996075265469E-7,-2.93907159738874E-5,-6.17821047296439E-7,9.9998169,9.9998169,13581.955078125,13592.1396484375,57.1784710672945,20.6297839726706,11.519473,0,0,0,40,4449,9.99475,13587.0473632812,,,,,,,,,,,,,0,,,,0,,,,,,9.9998169,,,,
,28470396.18,9.9979782,8916.38720703125,-1.55225677648077E-5,3.48185848969705E-7,1,0.999253354069792,40.0298881530762,1.99653485043986,15.3900003060699,-0.00017320020474301,-3.80402958408073E-5,0.25,-6.19115874093693E-7,-1.54387965063388E-5,-6.99945137077539E-7,9.9979782,9.9979782,8909.1171875,8923.6572265625,57.3488660844868,20.6261477240107,12.278775,0,0,0,40,4449,9.9967,8916.38720703125,,,,,,,,,,,,,0,,,,0.00245,,,,,,9.9979782,,,,
,28470489.255,9.99897,4266.26098632812,-2.83872859688543E-6,3.34397868237378E-7,1,0.999253354069792,40.0298881530762,1.9965782148824,15.3900003060699,-3.1657848282792E-5,-6.99342347613921E-6,0.25,-1.17639906303663E-7,-2.82247081202172E-6,-1.31399825315791E-7,9.99897,9.99897,4260.96044921875,4271.5615234375,57.1878506095253,20.6295118959851,11.519473,0,0,0,40,4449,9.9983,4266.26098632812,,,,,,,,,,,,,0,,,,0.00245,,,,,,9.99897,,,,
,28470584.625,10.0029736,-501.866607666016,9.22929721123398E-6,2.7770547410292E-7,1,0.999253354069792,40.0298881530762,1.99657750082512,15.3900003060699,0.000104189145332417,1.55033733873408E-5,0.25,-2.58903213803064E-7,9.17769042726079E-6,-2.12749825912006E-7,10.0029736,10.0029736,-511.537658691406,-492.195556640625,56.953362053756,20.6299235253275,11.519473,0,0,0,40,4449,9.9967,-501.866607666016,,,,,,,,,,,,,0,,,,-0.00245,,,,,,10.0029736,,,,
,28470678.35,9.9983568,-5184.33447265625,2.17478332163885E-5,3.39252764128635E-7,1,0.999253354069792,40.0298881530762,1.99650202885763,15.3900003060699,0.000244570430002496,4.21657972366985E-5,0.25,-1.15986556580586E-7,2.16297837322069E-5,-3.55326099725151E-9,9.9983568,9.9983568,-5191.88134765625,-5176.78759765625,57.098744958333,20.6318410654841,11.519473,0,0,0,40,4449,9.99855,-5184.33447265625,,,,,,,,,,,,,0,,,,0,,,,,,9.9983568,,,,
,28470774.61,9.9993496,-9995.3154296875,3.54500522014491E-5,3.25614406748002E-7,1,0.999253354069792,40.0298881530762,1.99650630210441,15.3900003060699,0.000397944573150838,7.36061209248215E-5,0.25,2.29842237837389E-7,3.52681758532763E-5,4.23421893632312E-7,9.9993496,9.9993496,-10005.3984375,-9985.232421875,57.2832092888714,20.6325259985875,11.899124,0,0,0,40,4449,9.99765,-9995.3154296875,,,,,,,,,,,,,0,,,,0,,,,,,9.9993496,,,,
,28470871.67,10.0012207,-14847.6396484375,4.78332190947599E-5,3.59906118979523E-7,1,0.999253354069792,40.0298881530762,1.99659201959867,15.3900003060699,0.000535983435891005,0.000106162721983591,0.25,8.98053427253089E-7,4.76041458830775E-5,1.17351375656859E-6,10.0010738,10.0013676,-14857.8388671875,-14837.4404296875,56.9338213407753,20.6356317373984,11.899124,0,0,0,40,4449,9.998,-14847.6396484375,,,,,,,,,,,,,0,,,,0,,,,,,10.0012207,,,,
,28470967.42,10.0002346,-19632.41015625,6.00936445184297E-5,5.42295657879104E-7,1,0.999253354069792,40.0298881530762,1.99656556379642,15.3900003060699,0.000674405273594305,0.000129246588487109,0.25,7.36583130144458E-7,5.98348122527128E-5,1.10443450848599E-6,10.0002346,10.0002346,-19640.0390625,-19624.78125,57.423902422333,20.6358774330362,11.899124,0,0,0,40,4449,9.9968,-19632.41015625,,,,,,,,,,,,,0,,,,0,,,,,,10.0002346,,,,
,28471063.58,10.0004454,-24439.982421875,7.3331680813479E-5,4.67767493907321E-7,1,0.999253354069792,40.0298881530762,1.99664740282216,15.3900003060699,0.000824059018536674,0.000154099595118446,0.25,5.48413693093995E-7,7.30528571693497E-5,1.0207670382425E-6,10.0004454,10.0004454,-24452.5,-24427.46484375,57.2034831799099,20.6369011307681,11.899124,0,0,0,40,4449,9.99695,-24439.982421875,,,,,,,,,,,,,0,,,,0.00245,,,,,,10.0004454,,,,
,28471158.54,9.9994645,-29184.6630859375,8.66046145151085E-5,5.12575588586694E-7,1,0.999253354069792,40.0298881530762,1.99659986493864,15.3900003060699,0.000978102924220395,0.000157378668613868,0.25,-1.56818305384266E-6,8.63324858094418E-5,-9.80682832744355E-7,9.9992704,9.9996586,-29194.689453125,-29174.63671875,57.2347483206791,20.6318805932469,11.519473,0,0,0,40,4449,9.99585,-29184.6630859375,,,,,,,,,,,,,0,,,,-0.00245,,,,,,9.9994645,,,,
,28471254.33,9.9997101,-33971.849609375,9.95034314005907E-5,6.05063870421347E-7,1,0.999253354069792,40.0298881530762,1.99668308015282,15.3900003060699,0.00112338682009759,0.000186558434293274,0.25,-1.32231125672505E-6,9.92380662447795E-5,-6.27934292952826E-7,9.9997101,9.9997101,-33977.2109375,-33966.48828125,57.2316218066022,20.6283882000952,11.519473,0,0,0,40,4449,9.99835,-33971.849609375,,,,,,,,,,,,,0,,,,-0.0049,,,,,,9.9997101,,,,
,28471351.04,9.9993515,-38803.955078125,0.000112335564129146,5.72994372779302E-7,1,0.999253354069792,40.0298881530762,1.99674352953934,15.3900003060699,0.00127088214553943,0.000200017552180846,0.25,-2.46325247536696E-6,0.000112100766628387,-1.65799467830067E-6,9.9993515,9.9993515,-38814.046875,-38793.86328125,57.2605420618137,20.6305879833545,11.139823,0,0,0,40,4449,9.99845,-38803.955078125,,,,,,,,,,,,,0,,,,-0.00245,,,,,,9.9993515,,,,
,28471444.415,9.9991255,-43471.25390625,0.000124899204729706,6.86198445574822E-7,1,0.999253354069792,40.0298881530762,1.99669239226974,15.3900003060699,0.00140789059181127,0.000254678182073808,0.25,1.00037373118112E-7,0.000124679430131724,1.00553047419673E-6,9.9991255,9.9991255,-43481.328125,-43461.1796875,57.2527257766214,20.6310106803517,11.899124,0,0,0,40,4449,9.99905,-43471.25390625,,,,,,,,,,,,,0,,,,0,,,,,,9.9991255,,,,
,28471541.075,9.9970789,-48303.7421875,0.000138267694114211,7.44985216651689E-7,1,0.999253354069792,40.0298881530762,1.99672459864152,15.3900003060699,0.00156161000612102,0.000269766380986618,0.25,-9.94356362605992E-7,0.000138101834176059,2.30835211412172E-8,9.9970789,9.9970789,-48313.7421875,-48293.7421875,57.1925403806407,20.6318634446312,11.519473,0,0,0,40,4449,10.0024,-48303.7421875,,,,,,,,,,,,,0,,,,0.00245,,,,,,9.9970789,,,,
,28471638.39,9.996953,-53165.935546875,0.000152546202723768,8.07098804503118E-7,1,0.999253354069792,40.0298881530762,1.99692725771292,15.3900003060699,0.00172176680679449,0.000309574319605826,0.25,-6.27077065592044E-8,0.000152430553725854,1.06796323493019E-6,9.996953,9.996953,-53176.10546875,-53155.765625,57.4887775894292,20.6321740061558,11.899124,0,0,0,40,4449,10.0056,-53165.935546875,,,,,,,,,,,,,0,,,,0,,,,,,9.996953,,,,
,28471733.54,9.9951792,-57920.71484375,0.000166191947109208,6.90903172980049E-7,1,0.999253354069792,40.0298881530762,1.99694448835892,15.3900003060699,0.00188016985167363,0.000318017197947894,0.25,-1.79142694482684E-6,0.000166155903442835,-5.54387875565357E-7,9.9951792,9.9951792,-57933.1953125,-57908.234375,56.9650864815445,20.6295556664899,11.519473,0,0,0,40,4449,10.00955,-57920.71484375,,,,,,,,,,,,,0,,,,0.00245,,,,,,9.9951792,,,,
,28471830.895,9.9971724,-62785.833984375,0.000180017087360023,6.97255125840042E-7,1,0.999253354069792,40.0298881530762,1.99695832954249,15.3900003060699,0.00203478662151673,0.000359787390558158,0.25,-5.98175136052969E-7,0.00018005006578856,7.41067346694608E-7,9.9971724,9.9971724,-62795.92578125,-62775.7421875,57.3449579418907,20.6312609023427,12.278775,0,0,0,40,4449,10.01265,-62785.833984375,,,,,,,,,,,,,0,,,,0.0049,,,,,,9.9971724,,,,
,28471930.205,9.9961443,-67747.94921875,0.000196909933866726,8.50509151982573E-7,1,0.999253354069792,40.0298881530762,1.99691360132493,15.3900003060699,0.00222798304473631,0.000386419796997457,0.25,-1.29392429713161E-6,0.00019703789374632,1.65014041165129E-7,9.9961443,9.9961443,-67753,-67742.8984375,57.5825730117369,20.6314827656681,11.139823,0,0,0,40,4449,10.01695,-67747.94921875,,,,,,,,,,,,,0,,,,-0.0049,,,,,,9.9961443,,,,
,28472027.985,9.9958658,-72634.54296875,0.000212346180369564,7.82397507407898E-7,1,0.999253354069792,40.0298881530762,1.99709122556505,15.3900003060699,0.00240269603385064,0.00042323702512428,0.25,-8.25533270681748E-7,0.000212567624599998,7.37330360536494E-7,9.9958658,9.9958658,-72639.375,-72629.7109375,57.3246356003907,20.6307883594524,11.519473,0,0,0,40,4449,10.0203,-72634.54296875,,,,,,,,,,,,,0,,,,0,,,,,,9.9958658,,,,
,28472127.11,9.9955769,-77589.26171875,0.000227982773642001,6.976976690441E-7,1,0.999253354069792,40.0298881530762,1.99696722711545,15.3900003060699,0.00257804921939412,0.000468094420575869,0.25,3.27100266442024E-7,0.000228301712912791,1.99062407941903E-6,9.9955769,9.9955769,-77596.6640625,-77581.859375,57.2628869473714,20.63117209783,11.519473,0,0,0,40,4449,10.0242,-77589.26171875,,,,,,,,,,,,,0,,,,0.00245,,,,,,9.9955769,,,,
,28472225.03,9.9947186,-82481.1953125,0.0002413901489341,7.93974377297814E-7,1,0.999253354069792,40.0298881530762,1.99697527727948,15.3900003060699,0.00272849524077019,0.000507888424534983,0.25,1.43509110856482E-6,0.00024180857794637,3.17817532761135E-6,9.9947186,9.9947186,-82483.5078125,-82478.8828125,57.2581971762561,20.631620545125,11.139823,0,0,0,40,4449,10.0288,-82481.1953125,,,,,,,,,,,,,0,,,,0,,,,,,9.9947186,,,,
,28472318.85,9.9950733,-87170.77734375,0.000255196635486352,8.73610434451536E-7,1,0.999253354069792,40.0298881530762,1.99712728195284,15.3900003060699,0.00288073760899129,0.000564814063528828,0.25,3.98491019598645E-6,0.000255705850683996,5.8097029397841E-6,9.9950733,9.9950733,-87180.8125,-87160.7421875,57.2222422643714,20.6364762167193,11.519473,0,0,0,40,4449,10.03245,-87170.77734375,,,,,,,,,,,,,0,,,,0,,,,,,9.9950733,,,,
,28472433.71,9.9968042,-88232.9140625,0.000261755459411068,9.02655158389005E-7,1,0.999253354069792,40.0298881530762,1.99704527975631,15.3900003060699,0.00295892123917374,0.000556840963380306,0.25,2.10503215181972E-6,0.000262310748522005,3.96683114056075E-6,9.9968042,9.9968042,-88243.0078125,-88222.8203125,57.4379717356792,20.6343727491097,11.139823,0,0,0,40,4449,10.03655,-88232.9140625,,,,,,,,,,,,,0,,,,-0.0049,,,,,,9.9968042,,,,
,28472526.43,9.9992695,-83600.97265625,0.000243829907911705,7.12235964074332E-7,1,0.999253354069792,40.0298881530762,1.99688512583974,15.3900003060699,0.00275180933372757,0.000537302132636981,0.25,3.59889643842926E-6,0.000244256830764325,5.35854158118807E-6,9.9992695,9.9992695,-83610.96875,-83590.9765625,57.2730481181214,20.6324190132848,11.139823,0,0,0,40,4449,10.03575,-83600.97265625,,,,,,,,,,,,,0,,,,-0.00245,,,,,,9.9992695,,,,
,28472627.205,10.0021849,-78566.0859375,0.000229214407247974,6.72962049935712E-7,1,0.999253354069792,40.0298881530762,1.99701775157795,15.3900003060699,0.00259018701574787,0.000482033843570396,0.25,1.3371601856839E-6,0.000229544946832452,3.0076036025588E-6,10.0021849,10.0021849,-78568.625,-78563.546875,57.637287008083,20.633042017892,11.519473,0,0,0,40,4449,10.0319,-78566.0859375,,,,,,,,,,,,,0,,,,0.0049,,,,,,10.0021849,,,,
,28472723.23,10.0039253,-73766.40625,0.000216301474479398,6.79851009646656E-7,1,0.999253354069792,40.0298881530762,1.99695010491139,15.3900003060699,0.00244802945643493,0.000428250603167556,0.25,-1.09243854607988E-6,0.000216548860984182,4.96103404843426E-7,10.0039253,10.0039253,-73771.5859375,-73761.2265625,57.3097846585253,20.6289449757366,11.519473,0,0,0,40,4449,10.03015,-73766.40625,,,,,,,,,,,,,0,,,,0.00245,,,,,,10.0039253,,,,
,28472814.015,10.0037985,-69226.9375,0.0002006143576313,6.85120393700586E-7,1,0.999253354069792,40.0298881530762,1.99686867696768,15.3900003060699,0.00226751242355488,0.000408298630220179,0.25,-2.66609953254229E-8,0.00020076071571374,1.45795272413911E-6,10.0037985,10.0037985,-69229.3125,-69224.5625,57.2691399755253,20.6330389586867,11.519473,0,0,0,40,4449,10.0265,-69226.9375,,,,,,,,,,,,,0,,,,0,,,,,,10.0037985,,,,
,28472904.005,10.0038986,-64729.82421875,0.000187528398500464,9.84803229586278E-7,1,0.999253354069792,40.0298881530762,1.99686983197353,15.3900003060699,0.00211817059380472,0.000384847831750489,0.25,2.63457636547226E-7,0.000187589188083455,1.65735181688096E-6,10.0038986,10.0038986,-64737.3984375,-64722.25,57.1784710672945,20.631010824667,11.899124,0,0,0,40,4449,10.0233,-64729.82421875,,,,,,,,,,,,,0,,,,-0.0049,,,,,,10.0038986,,,,
,28472990.985,10.0046978,-60384.5234375,0.00017340629216921,6.9934462139736E-7,1,0.999253354069792,40.0298881530762,1.99675967902416,15.3900003060699,0.00195460339104493,0.000373304360524404,0.25,1.79953974980615E-6,0.000173381830407412,3.09019657410047E-6,10.0046978,10.0046978,-60389.65234375,-60379.39453125,57.3942005386022,20.6335952519394,11.139823,0,0,0,40,4449,10.0192,-60384.5234375,,,,,,,,,,,,,0,,,,0,,,,,,10.0046978,,,,
,28473082.035,10.003437,-55834.1796875,0.000160147896448729,7.87886823927588E-7,1,0.999253354069792,40.0298881530762,1.99676472453991,15.3900003060699,0.00180596685391792,0.00033579104969708,0.25,8.81861211159389E-7,0.000160061496070396,2.07154614160996E-6,10.003437,10.003437,-55841.91015625,-55826.44921875,57.1042163579676,20.6330381627613,11.899124,0,0,0,40,4449,10.0161,-55834.1796875,,,,,,,,,,,,,0,,,,-0.00245,,,,,,10.003437,,,,
,28473171.5,10.0037284,-51362.51171875,0.000145142554513432,6.87554006784148E-7,1,0.999253354069792,40.0298881530762,1.99689455588312,15.3900003060699,0.00163433787348512,0.00031415479085243,0.25,1.68549123438104E-6,0.000144993429715586,2.75689765899448E-6,10.0037279,10.0037289,-51369.6640625,-51355.359375,57.4481329064291,20.6320795743467,11.899124,0,0,0,40,4449,10.01375,-51362.51171875,,,,,,,,,,,,,0,,,,0,,,,,,10.0037284,,,,
,28473262.115,10.0040855,-46834.65625,0.000128866855322081,6.93515580667729E-7,1,0.999253354069792,40.0298881530762,1.99672564741558,15.3900003060699,0.00144871652504813,0.000287465897403947,0.25,2.27555365445332E-6,0.000128669306326076,3.21612702479602E-6,10.0040855,10.0040855,-46836.9453125,-46832.3671875,57.3293253715061,20.631914250833,11.519473,0,0,0,40,4449,10.0097,-46834.65625,,,,,,,,,,,,,0,,,,0,,,,,,10.0040855,,,,
,28473353.2,10.0038042,-42282.54296875,0.000115767513578965,5.69219022032473E-7,1,0.999253354069792,40.0298881530762,1.99666009913831,15.3900003060699,0.0012989165981977,0.000268551693316945,0.25,2.9816628132853E-6,0.000115528494973331,3.81203076580598E-6,10.0037165,10.0038919,-42290.15625,-42274.9296875,57.5473997283715,20.6314619149183,11.139823,0,0,0,40,4449,10.00715,-42282.54296875,,,,,,,,,,,,,0,,,,0,,,,,,10.0038042,,,,
,28473450.105,10.0028944,-37437.484375,0.000101105024869625,5.82092566762671E-7,1,0.999253354069792,40.0298881530762,1.99692734017219,15.3900003060699,0.00113510381344314,0.000228135376422118,0.25,2.0583882080308E-6,0.000100848699317049,2.76859908192651E-6,10.0028944,10.0028944,-37442.26953125,-37432.69921875,57.1933220091599,20.6303165091229,11.519473,0,0,0,40,4449,10.0054,-37437.484375,,,,,,,,,,,,,0,,,,0.00245,,,,,,10.0028944,,,,
,28473549.835,10.0024433,-32456.029296875,8.55967550767582E-5,5.33240695710051E-7,1,0.999253354069792,40.0298881530762,1.99699362456446,15.3900003060699,0.000959998928210669,0.00019592796367153,0.25,2.01497484181635E-6,8.53329818131925E-5,2.5977803440617E-6,10.0024433,10.0024433,-32461.08203125,-32450.9765625,57.3949821671215,20.6267573015733,11.139823,0,0,0,40,4449,10.0037,-32456.029296875,,,,,,,,,,,,,0,,,,-0.0049,,,,,,10.0024433,,,,
,28473649.155,10.0018396,-27491.6474609375,7.0838868817969E-5,5.05014781854227E-7,1,0.999253354069792,40.0298881530762,1.99706638876733,15.3900003060699,0.000794982671973126,0.000157148919516392,0.25,1.24728763983417E-6,7.05868782755084E-5,1.7132256500082E-6,10.0018396,10.0018396,-27499.291015625,-27484.00390625,57.2925888311022,20.6274588423709,11.519473,0,0,0,40,4449,10.0011,-27491.6474609375,,,,,,,,,,,,,0,,,,0,,,,,,10.0018396,,,,
,28473748.485,10.0008469,-22526.66015625,5.62512481185638E-5,5.61960083614919E-7,1,0.999253354069792,40.0298881530762,1.99706908589863,15.3900003060699,0.000631449716569607,0.000121971944689272,0.25,7.61543715759807E-7,5.602440245313E-5,1.11605936984942E-6,10.0008469,10.0008469,-22536.666015625,-22516.654296875,57.2871174314676,20.6267518275878,11.519473,0,0,0,40,4449,10.00275,-22526.66015625,,,,,,,,,,,,,0,,,,-0.0049,,,,,,10.0008469,,,,
,28473847.925,10.000061,-17556.9443359375,4.10561073263593E-5,5.05631591096405E-7,1,0.999253354069792,40.0298881530762,1.99712475433394,15.3900003060699,0.000461173602783434,8.61456286490769E-5,0.25,3.16676914334986E-7,4.08723325001591E-5,5.6304486954561E-7,10.000061,10.000061,-17564.54296875,-17549.345703125,57.2808644033138,20.6267134309967,11.519473,0,0,0,40,4449,10.00205,-17556.9443359375,,,,,,,,,,,,,0,,,,0.00245,,,,,,10.000061,,,,
,28473945.52,9.9995117,-12676.9145507813,2.70616375146884E-5,3.32511313733287E-7,1,0.999253354069792,40.0298881530762,1.99714184048451,15.3900003060699,0.00030397126123894,5.605003368248E-5,0.25,1.55133174332686E-7,2.69289473043781E-5,3.08373840406736E-7,9.9995117,9.9995117,-12686.505859375,-12667.3232421875,57.1620568683907,20.6262585098336,11.139823,0,0,0,40,4449,10.0032,-12676.9145507813,,,,,,,,,,,,,0,,,,-0.00245,,,,,,9.9995117,,,,
,28474041.32,9.9984341,-7888.75952148438,1.35295850948174E-5,4.08461647612018E-7,1,0.999253354069792,40.0298881530762,1.99697347788965,15.3900003060699,0.00015176664563781,2.87584751621637E-5,0.25,1.48987120577069E-7,1.34576225131827E-5,2.20422847561996E-7,9.9984341,9.9984341,-7898.86376953125,-7878.6552734375,57.291807202583,20.6280566292796,11.139823,0,0,0,40,4449,10.0041,-7888.75952148438,,,,,,,,,,,,,0,,,,-0.0049,,,,,,9.9984341,,,,
,28474139.125,9.99985075,-3000.73706054687,-6.44044823521905E-7,2.45863490268062E-7,1,0.999253354069792,40.0298881530762,1.99691431257181,15.3900003060699,-6.46956378994041E-6,-5.60092950550675E-6,0.25,-3.84003080706848E-7,-6.38524732632802E-7,-3.85067539271244E-7,9.9998322,9.9998693,-3005.66748046875,-2995.806640625,57.1964485232368,20.6266051844728,11.899124,0,0,0,40,4449,10.0041,-3000.73706054687,,,,,,,,,,,,,0,,,,-0.0049,,,,,,9.99985075,,,,
,28474236.915,9.9990797,1881.52044677734,-1.2824905154014E-5,3.1755514609248E-7,1,0.999253354069792,40.0298881530762,1.99700352115595,15.3900003060699,-0.000143088808798865,-3.12897353628854E-5,0.25,-5.06151386200912E-7,-1.27498245074108E-5,-5.66352896704409E-7,9.9990797,9.9990797,1878.833984375,1884.20690917969,57.5005020172176,20.6255504269235,11.519473,0,0,0,40,4449,10.0041,1881.52044677734,,,,,,,,,,,,,0,,,,0,,,,,,9.9990797,,,,
,28474332.455,9.99934765,6659.36108398438,-2.55996315767651E-5,2.69396401117426E-7,1,0.999253354069792,40.0298881530762,1.99689724902974,15.3900003060699,-0.000285975120286145,-6.08636251619001E-5,0.25,-8.58687606801159E-7,-2.54581292070217E-5,-9.8842735791385E-7,9.9992027,9.9994926,6652.009765625,6666.71240234375,56.943200883006,20.626285124723,11.519473,0,0,0,40,4449,10.0053,6659.36108398438,,,,,,,,,,,,,0,,,,0,,,,,,9.99934765,,,,
,28474428.875,10.0004053,11479.9028320312,-3.86934590157908E-5,3.75112798829245E-7,1,0.999253354069792,40.0298881530762,1.99693433463843,15.3900003060699,-0.00043420454724045,-8.19990534506234E-5,0.25,-3.91832651790143E-7,-3.84988596980653E-5,-6.06686962316259E-7,10.0004053,10.0004053,11474.927734375,11484.8779296875,57.1487691835637,20.6294807800036,11.139823,0,0,0,40,4449,10.0029,11479.9028320312,,,,,,,,,,,,,0,,,,0,,,,,,10.0004053,,,,
,28474524.825,10.0007353,16275.111328125,-5.06913082467939E-5,5.57413114539692E-7,1,0.999253354069792,40.0298881530762,1.99678404610704,15.3900003060699,-0.000568244729025572,-0.000111915568842353,0.25,-8.9192198077881E-7,-5.04554042756781E-5,-1.18931811049805E-6,10.0007353,10.0007353,16262.494140625,16287.728515625,57.3230723433522,20.6307149833818,11.519473,0,0,0,40,4449,10.0023,16275.111328125,,,,,,,,,,,,,0,,,,0,,,,,,10.0007353,,,,
,28474616.795,10.001297,20870.037109375,-6.27389156499707E-5,4.53134269515658E-7,1,0.999253354069792,40.0298881530762,1.99677089049598,15.3900003060699,-0.000702536485135279,-0.000144513905757247,0.25,-1.61282312066784E-6,-6.24709232849175E-5,-1.99848592374529E-6,10.001297,10.001297,20864.94140625,20875.1328125,57.119067299833,20.6304404326097,11.519473,0,0,0,40,4449,10.0011,20870.037109375,,,,,,,,,,,,,0,,,,0,,,,,,10.001297,,,,
,28474707.67,10.0004072,25412.8447265625,-7.45003413611751E-5,5.76179111642015E-7,1,0.999253354069792,40.0298881530762,1.99679604374218,15.3900003060699,-0.000836334619493998,-0.0001621582732819,0.25,-1.04852072930183E-6,-7.42212292925225E-5,-1.53079365360556E-6,10.0004072,10.0004072,25402.89453125,25422.794921875,57.1565854687561,20.6297557006204,11.519473,0,0,0,40,4449,10.00235,25412.8447265625,,,,,,,,,,,,,0,,,,0,,,,,,10.0004072,,,,
,28474803.495,9.9999533,30203.1884765625,-8.74935312972092E-5,5.10572293336509E-7,1,0.999253354069792,40.0298881530762,1.99682767071077,15.3900003060699,-0.00098349663643941,-0.000186092890468126,0.25,-8.15086156720289E-7,-8.7211776370125E-5,-1.4052161152352E-6,9.9999533,9.9999533,30195.896484375,30210.48046875,57.3215090863138,20.6261758768046,11.899124,0,0,0,40,4449,10.00155,30203.1884765625,,,,,,,,,,,,,0,,,,-0.00245,,,,,,9.9999533,,,,
,28474902.58,9.999795,35155.759765625,-0.000100311757491157,6.07249598519179E-7,1,0.999253354069792,40.0298881530762,1.99679317010949,15.3900003060699,-0.00112694774171379,-0.000220189504336467,0.25,-1.51020402552315E-6,-0.000100037029116269,-2.2073139245379E-6,9.999795,9.999795,35148.2421875,35163.27734375,56.8697278021983,20.6272356107958,11.519473,0,0,0,40,4449,10.0027,35155.759765625,,,,,,,,,,,,,0,,,,0.00245,,,,,,9.999795,,,,
,28474998.54,9.9988055,39950.4921875,-0.000113233287936039,6.83307379829445E-7,1,0.999253354069792,40.0298881530762,1.99672476204103,15.3900003060699,-0.00127411712670686,-0.000240906434920745,0.25,-9.97327471310871E-7,-0.000112985554629414,-1.80539625707188E-6,9.9987154,9.9988956,39940.53515625,39960.44921875,57.1823792098907,20.6246228817658,11.519473,0,0,0,40,4449,10.00265,39950.4921875,,,,,,,,,,,,,0,,,,0,,,,,,9.9988055,,,,
,28475093.925,9.9972458,44718.716796875,-0.000126758565696179,6.23275385563229E-7,1,0.999253354069792,40.0298881530762,1.99678286928214,15.3900003060699,-0.00142730362256603,-0.000268480795190737,0.25,-9.8182786190492E-7,-0.000126545643723421,-1.90306381508246E-6,9.9972458,9.9972458,44713.59375,44723.83984375,57.2128627221407,20.6228185065654,11.899124,0,0,0,40,4449,10.0042,44718.716796875,,,,,,,,,,,,,0,,,,-0.0049,,,,,,9.9972458,,,,
,28475188.495,9.9976091,49443.951171875,-0.000141271697223607,8.18969821272771E-7,1,0.999253354069792,40.0298881530762,1.99689015500771,15.3900003060699,-0.00159058213697092,-0.000304919868296624,0.25,-1.57333100384458E-6,-0.000141099639415509,-2.61232652070458E-6,9.9976091,9.9976091,49436.3203125,49451.58203125,57.3230723433522,20.6256472492422,11.899124,0,0,0,40,4449,10.00895,49443.951171875,,,,,,,,,,,,,0,,,,0,,,,,,9.9976091,,,,
,28475284.605,9.9963818,54249.00390625,-0.000157956357355246,8.33534888076492E-7,1,0.999253354069792,40.0298881530762,1.99688693841186,15.3900003060699,-0.00177928528345941,-0.000341123180875092,0.25,-1.7536553256479E-6,-0.000157840050478846,-2.9246812114438E-6,9.9963818,9.9963818,54238.92578125,54259.08203125,57.2316218066022,20.6266157596591,11.519473,0,0,0,40,4449,10.0119,54249.00390625,,,,,,,,,,,,,0,,,,-0.00245,,,,,,9.9963818,,,,
,28475383.27,9.9958944,59181.55078125,-0.000171791495547334,6.73238383231641E-7,1,0.999253354069792,40.0298881530762,1.99682625016992,15.3900003060699,-0.00193745365241376,-0.000363087192328558,0.25,-1.188470761019E-6,-0.000171752232545682,-2.46688598112481E-6,9.9958944,9.9958944,59171.4296875,59191.671875,56.7782772654483,20.6227173707247,11.519473,0,0,0,40,4449,10.01445,59181.55078125,,,,,,,,,,,,,0,,,,-0.00245,,,,,,9.9958944,,,,
,28475480.21,9.9955988,64024.529296875,-0.000185544027410298,6.82029667039181E-7,1,0.999253354069792,40.0298881530762,1.99684388973023,15.3900003060699,-0.00209100973035912,-0.000406201537028856,0.25,-2.51319624942918E-6,-0.000185575643211828,-3.89352926066852E-6,9.9955988,9.9955988,64019.62890625,64029.4296875,57.2261504069676,20.6217703812844,10.760172,0,0,0,40,4449,10.0187,64024.529296875,,,,,,,,,,,,,0,,,,0.0049,,,,,,9.9955988,,,,
,28475577.875,9.9962597,68907.171875,-0.000203088230674763,8.36453548900249E-7,1,0.999253354069792,40.0298881530762,1.99691966609742,15.3900003060699,-0.00228608706951634,-0.000465386233504714,0.25,-4.57788588708151E-6,-0.000203196744332458,-6.08462803943257E-6,9.9962597,9.9962597,68902.109375,68912.234375,57.2667950899676,20.6223135280539,11.519473,0,0,0,40,4449,10.0228,68907.171875,,,,,,,,,,,,,0,,,,-0.0049,,,,,,9.9962597,,,,
,28475675.9,9.995409,73804.734375,-0.000216238651631347,7.11732263731528E-7,1,0.999253354069792,40.0298881530762,1.99697595886013,15.3900003060699,-0.00243788841503199,-0.000480689564728588,0.25,-3.55591851006445E-6,-0.000216452481028356,-5.14904578893072E-6,9.995409,9.995409,73799.6484375,73809.8203125,57.1894138665637,20.6218372901372,11.519473,0,0,0,40,4449,10.0275,73804.734375,,,,,,,,,,,,,0,,,,0.0049,,,,,,9.995409,,,,
,28475772.845,9.99553635,78652.97265625,-0.000233242009837965,1.01773871439765E-6,1,0.999253354069792,40.0298881530762,1.99675566947979,15.3900003060699,-0.00263226518844417,-0.000507784580832086,0.25,-2.89394980265283E-6,-0.000233568750692376,-4.59570887409351E-6,9.9954615,9.9956112,78642.859375,78663.0859375,57.159711982833,20.6207347609226,11.139823,0,0,0,40,4449,10.0311,78652.97265625,,,,,,,,,,,,,0,,,,0,,,,,,9.99553635,,,,
,28475863.43,9.995225,83181.484375,-0.000247318977054132,8.63459508327294E-7,1,0.999253354069792,40.0298881530762,1.99678523017324,15.3900003060699,-0.00279301622536464,-0.000533573048888232,0.25,-2.64304185563896E-6,-0.000247751785141495,-4.42789780720328E-6,9.995225,9.995225,83171.59375,83191.375,57.3152560581599,20.6186375688074,11.139823,0,0,0,40,4449,10.03395,83181.484375,,,,,,,,,,,,,0,,,,-0.0049,,,,,,9.995225,,,,
,28475944.685,9.9957848,87242.48046875,-0.000261061126534809,1.07421834938654E-6,1,0.999253354069792,40.0298881530762,1.99682231961761,15.3900003060699,-0.00294402479069933,-0.000591597395028324,0.25,-5.30364634902167E-6,-0.000261574593240454,-7.17259312039119E-6,9.9957848,9.9957848,87234.8984375,87250.0625,57.1440794124484,20.6196496741106,11.519473,0,0,0,40,4449,10.03885,87242.48046875,,,,,,,,,,,,,0,,,,0,,,,,,9.9957848,,,,
,28476044.86,9.9975643,88760.12109375,-0.000264727064089356,8.04091374663649E-7,1,0.999253354069792,40.0298881530762,1.99689616800695,15.3900003060699,-0.0029870712180156,-0.000592796326819577,0.25,-4.75156580463043E-6,-0.000265279453205913,-6.63739038361433E-6,9.9975643,9.9975643,88752.6796875,88767.5625,57.2284952925253,20.6205024227658,11.139823,0,0,0,40,4449,10.0389,88760.12109375,,,,,,,,,,,,,0,,,,0,,,,,,9.9975643,,,,
,28476127.82,9.9998741,84611.77734375,-0.000251489894566532,8.17477259394156E-7,1,0.999253354069792,40.0298881530762,1.99691612993802,15.3900003060699,-0.00283726470967705,-0.000561118019631096,0.25,-4.32570406712634E-6,-0.000251943974798105,-6.13713264084213E-6,9.9998178,9.9999304,84604.0859375,84619.46875,57.1753445532176,20.6212864136978,11.899124,0,0,0,40,4449,10.0383,84611.77734375,,,,,,,,,,,,,0,,,,0.0049,,,,,,9.9998741,,,,
,28476219.515,10.0023203,80027.73046875,-0.000235936704609576,9.21347814716892E-7,1,0.999253354069792,40.0298881530762,1.99687365094414,15.3900003060699,-0.00266154458065427,-0.00052239102628771,0.25,-3.69830379229975E-6,-0.000236286233329444,-5.41580209464177E-6,10.0023203,10.0023203,80020.21875,80035.2421875,57.2535074051407,20.620378245815,11.139823,0,0,0,40,4449,10.03635,80027.73046875,,,,,,,,,,,,,0,,,,0.0049,,,,,,10.0023203,,,,
,28476310.5,10.003397,75481.859375,-0.00022148952496065,7.67668119481724E-7,1,0.999253354069792,40.0298881530762,1.9969503799234,15.3900003060699,-0.00249785460579396,-0.000489857679949836,0.25,-3.42077625887479E-6,-0.000221740049267202,-5.04773046300493E-6,10.003397,10.003397,75476.625,75487.09375,56.9611783389483,20.6219069874368,11.899124,0,0,0,40,4449,10.0333,75481.859375,,,,,,,,,,,,,0,,,,0,,,,,,10.003397,,,,
,28476397.265,10.0034971,71145.75390625,-0.000207125258191616,7.73167910660722E-7,1,0.999253354069792,40.0298881530762,1.9970330235944,15.3900003060699,-0.00233770387317636,-0.000443647546255651,0.25,-1.92238231125913E-6,-0.000207295573992917,-3.45290207729086E-6,10.0034971,10.0034971,71138.171875,71153.3359375,57.4215575367753,20.6230319089293,11.139823,0,0,0,40,4449,10.0307,71145.75390625,,,,,,,,,,,,,0,,,,-0.00245,,,,,,10.0034971,,,,
,28476487.65,10.0036936,66625.55078125,-0.000192817023344974,6.21698602236441E-7,1,0.999253354069792,40.0298881530762,1.99696101341985,15.3900003060699,-0.00217620158738703,-0.000407806018709595,0.25,-1.33703278237925E-6,-0.000192904088473256,-2.76867240136572E-6,10.0036936,10.0036936,66620.453125,66630.6484375,57.2081729510253,20.6212513208727,11.139823,0,0,0,40,4449,10.0275,66625.55078125,,,,,,,,,,,,,0,,,,-0.00245,,,,,,10.0036936,,,,
,28476576.905,10.0040703,62164.25390625,-0.000179509625474809,7.3536698131376E-7,1,0.999253354069792,40.0298881530762,1.99699229576665,15.3900003060699,-0.00202602391153945,-0.000375091188186952,0.25,-8.49028353736771E-7,-0.00017952151283995,-2.18495437400724E-6,10.0040703,10.0040703,62157.03125,62171.4765625,57.3011867448138,20.6236945853476,11.139823,0,0,0,40,4449,10.02455,62164.25390625,,,,,,,,,,,,,0,,,,-0.00245,,,,,,10.0040703,,,,
,28476666.245,10.004035,57698.75,-0.000165537576535145,7.43164726971373E-7,1,0.999253354069792,40.0298881530762,1.99688605556596,15.3900003060699,-0.00186625448668953,-0.000352367313824553,0.25,-1.3703192939882E-6,-0.000165474681379524,-2.60140978077006E-6,10.004035,10.004035,57693.75390625,57703.74609375,57.2925888311022,20.6237033887864,11.139823,0,0,0,40,4449,10.0202,57698.75,,,,,,,,,,,,,0,,,,-0.00245,,,,,,10.004035,,,,
,28476755.11,10.0036621,53256.08984375,-0.000151014601086984,6.72869018655805E-7,1,0.999253354069792,40.0298881530762,1.99685110733589,15.3900003060699,-0.00170125707579036,-0.000324080093140266,0.25,-1.49928495988188E-6,-0.000150889890998995,-2.61755356405047E-6,10.0036621,10.0036621,53251.20703125,53260.97265625,57.2753930036791,20.6256029718445,11.139823,0,0,0,40,4449,10.0172,53256.08984375,,,,,,,,,,,,,0,,,,0,,,,,,10.0036621,,,,
,28476843.05,10.00378945,48860.833984375,-0.000138440513692148,6.19832266688404E-7,1,0.999253354069792,40.0298881530762,1.99682285315387,15.3900003060699,-0.00155595876305449,-0.000313234648371103,0.25,-2.82418440151846E-6,-0.000138254242229753,-3.83950963882281E-6,10.0036755,10.0039034,48858.3203125,48863.34765625,57.3363600281791,20.6230701861849,11.139823,0,0,0,40,4449,10.0142,48860.833984375,,,,,,,,,,,,,0,,,,0,,,,,,10.00378945,,,,
,28476934.75,10.0036325,44277.634765625,-0.000123040724837049,6.26759897211829E-7,1,0.999253354069792,40.0298881530762,1.9968476323771,15.3900003060699,-0.00138320964095254,-0.000272874212119969,0.25,-2.04258063236697E-6,-0.00012282046834466,-2.93370772618793E-6,10.0036325,10.0036325,44270.18359375,44285.0859375,57.190195495083,20.6234056382702,11.519473,0,0,0,40,4449,10.0107,44277.634765625,,,,,,,,,,,,,0,,,,0,,,,,,10.0036325,,,,
,28477026.175,10.0037041,39710.0625,-0.000107971368053527,6.41031668928825E-7,1,0.999253354069792,40.0298881530762,1.99693832654526,15.3900003060699,-0.00121235496409914,-0.000244439618576268,0.25,-2.25693004570265E-6,-0.000107723070671276,-3.02382218566391E-6,10.0037041,10.0037041,39702.625,39717.5,57.2605420618137,20.626649171769,11.519473,0,0,0,40,4449,10.0089,39710.0625,,,,,,,,,,,,,0,,,,0,,,,,,10.0037041,,,,
,28477113.98,10.0029287,35322.79296875,-9.50115760123357E-5,5.99012466068432E-7,1,0.999253354069792,40.0298881530762,1.99696148791198,15.3900003060699,-0.00106867787522126,-0.000202068990289761,0.25,-8.52244139784894E-7,-9.47570832184785E-5,-1.5146735376958E-6,10.0029287,10.0029287,35315.12109375,35330.46484375,57.403580080833,20.6253465282846,11.519473,0,0,0,40,4449,10.0068,35322.79296875,,,,,,,,,,,,,0,,,,0.00245,,,,,,10.0029287,,,,
,28477202.07,10.0021963,30919.859375,-8.11654621600821E-5,6.01018446175783E-7,1,0.999253354069792,40.0298881530762,1.99699604740413,15.3900003060699,-0.000910277107570208,-0.000185072139102324,0.25,-1.85557450073562E-6,-8.09026926493491E-5,-2.40243664723265E-6,10.0020418,10.0023508,30907.53125,30932.1875,57.2722664896022,20.6268060533762,11.899124,0,0,0,40,4449,10.00565,30919.859375,,,,,,,,,,,,,0,,,,0,,,,,,10.0021963,,,,
,28477291.47,10.0017672,26449.4970703125,-6.8564400543216E-5,4.94984508235078E-7,1,0.999253354069792,40.0298881530762,1.99705233114058,15.3900003060699,-0.000767270865100677,-0.00016378617332542,0.25,-2.25043106706598E-6,-6.83063123017676E-5,-2.69375196373963E-6,10.0017672,10.0017672,26439.419921875,26459.57421875,57.2636685758907,20.6277659724684,10.760172,0,0,0,40,4449,10.00335,26449.4970703125,,,,,,,,,,,,,0,,,,0.00245,,,,,,10.0017672,,,,
,28477379.075,10.001008,22072.021484375,-5.47752705876049E-5,5.60497726228966E-7,1,0.999253354069792,40.0298881530762,1.99698869567576,15.3900003060699,-0.000613384182062939,-0.000126830934972848,0.25,-1.46023101766094E-6,-5.45473675113584E-5,-1.80101643477168E-6,10.0008926,10.0011234,22066.86328125,22077.1796875,57.3551191126407,20.6300027863023,11.519473,0,0,0,40,4449,10.0035,22072.021484375,,,,,,,,,,,,,0,,,,0,,,,,,10.001008,,,,
,28477468.695,10.0002365,17594.34765625,-4.0442923564024E-5,4.94938615116893E-7,1,0.999253354069792,40.0298881530762,1.99698930364574,15.3900003060699,-0.000451946827091388,-9.77781018144571E-5,0.25,-1.46091576666605E-6,-4.0255098188429E-5,-1.69862252897107E-6,10.0002365,10.0002365,17589.21875,17599.4765625,57.3308886285445,20.6289327364357,11.139823,0,0,0,40,4449,10.0032,17594.34765625,,,,,,,,,,,,,0,,,,0,,,,,,10.0002365,,,,
,28477556.22,9.9997921,13219.9458007813,-2.81591423431115E-5,4.40101135408751E-7,1,0.999253354069792,40.0298881530762,1.99697420339767,15.3900003060699,-0.000315066060176794,-6.51701937140912E-5,0.25,-7.69456694031045E-7,-2.80189068605994E-5,-9.27096059031017E-7,9.9997921,9.9997921,13212.6328125,13227.2587890625,57.0463758475445,20.6283740509597,11.519473,0,0,0,40,4449,10.0036,13219.9458007813,,,,,,,,,,,,,0,,,,-0.00245,,,,,,9.9997921,,,,
,28477642.005,9.9992228,8932.15771484375,-1.56591904145618E-5,3.73267807167948E-7,1,0.999253354069792,40.0298881530762,1.99698838916476,15.3900003060699,-0.000174494547440023,-3.98885167722054E-5,0.25,-7.58443942761677E-7,-1.55739754935265E-5,-8.39310237059673E-7,9.9992228,9.9992228,8929.927734375,8934.3876953125,57.3816944822945,20.6284455929109,10.760172,0,0,0,40,4449,10.00415,8932.15771484375,,,,,,,,,,,,,0,,,,0.0049,,,,,,9.9992228,,,,
,28477729.265,9.9991846,4571.6904296875,-3.5996283681836E-6,3.78838134390826E-7,1,0.999253354069792,40.0298881530762,1.99701961231318,15.3900003060699,-3.96390402165835E-5,-1.17582597318689E-5,0.25,-4.06115274281248E-7,-3.57777211666524E-6,-4.22231239470037E-7,9.9991846,9.9991846,4566.74462890625,4576.63623046875,57.1276652135445,20.6269517294481,11.139823,0,0,0,40,4449,10.0056,4571.6904296875,,,,,,,,,,,,,0,,,,0,,,,,,9.9991846,,,,
,28477817.225,10.0025129,172.46549987793,8.57739923287011E-6,3.26536589893108E-7,1,0.999253354069792,40.0298881530762,1.99702592960355,15.3900003060699,9.74260356537523E-5,1.11639918469149E-5,0.25,-5.29510966733113E-7,8.53072166993068E-6,-4.85081153462424E-7,10.0025129,10.0025129,167.508895874023,177.422103881836,57.3090030300061,20.6294233710352,11.139823,0,0,0,40,4449,10.0026,172.46549987793,,,,,,,,,,,,,0,,,,-0.0049,,,,,,10.0025129,,,,
,28477821.495,10.0033655,-0.365370541810989,9.81508695539909E-6,3.36328206825371E-7,1,0.999253354069792,40.0298881530762,1.99703236305231,15.3900003060699,0.000111495482914703,1.27103792811656E-5,0.25,-6.11603939435558E-7,9.76165125814457E-6,-5.60782456883503E-7,10.0033655,10.0033655,-0.365370541810989,-0.365370541810989,57.3637170263522,20.6325150588271,10.760172,0,0,0,40,4417,10.00095,-0.365370541810989,,,,,,,,,,,,,0,,,,-0.00245,,,,,,10.0033655,,,,