File: data/monolayers/nanoparticles/Ol_CoFe_C/vsm/data_disorderedWafer/DD227_FCW_100OE.DAT
[Header]
; VSM Data File (default extension .dat)
; Copyright (c) 2003-2013, Quantum Design, Inc. All rights reserved.
TITLE,
FILEOPENTIME,28581037.28,11/28/2018,3:11 am
BYAPP,VSM,2.0,2.0
INFO,PPMS VSM Option Release 1.4.10 Build 1,APPNAME
INFO,Quantum Design Linear Motor Servo Controller,MOTOR_MODULE_NAME
INFO,3101-100 M1,MOTOR_HW_VERSION
INFO,MMC1014,MOTOR_SERIAL_NUMBER
INFO,SRV No X-over 01.03.11,MOTOR_SOFTWARE_VERSION
INFO,Quantum Design VSM Detection Module,VSM_MODULE_NAME
INFO,3101-150 F0,VSM_HW_VERSION
INFO,VSM707,VSM_SERIAL_NUMBER
INFO,VSM No X-over 01.02.05 May 20 2008 13:51:47,VSM_SOFTWARE_VERSION
INFO,704,PREAMP_SERIAL_NUMBER
INFO,822,COIL_SERIAL_NUMBER
INFO,0,MOMENT_UNITS
INFO,CoFe2O4 FeO,SAMPLE_MATERIAL
INFO,disordered monolayer,SAMPLE_COMMENT
INFO,25.46,SAMPLE_MASS
INFO,,SAMPLE_VOLUME
INFO,,SAMPLE_MOLECULAR_WEIGHT
INFO,,SAMPLE_SIZE
INFO,,SAMPLE_SHAPE
DATATYPE,COMMENT,1
DATATYPE,TIME,2
STARTUPAXIS,X,2
STARTUPAXIS,Y1,5
[Data]
Comment,Time Stamp (sec),Temperature (K),Magnetic Field (Oe),Moment (emu),M. Std. Err. (emu),Transport Action,Averaging Time (sec),Frequency (Hz),Peak Amplitude (mm),Center Position (mm),Coil Signal' (mV),Coil Signal" (mV),Range (mV),M. Quad. Signal (emu),M. Raw' (emu),M. Raw" (emu),Min. Temperature (K),Max. Temperature (K),Min. Field (Oe),Max. Field (Oe),Mass (grams),Motor Lag (deg),Pressure (Torr),VSM Status (code),Motor Status (code),Measure Status (code),Measure Count,PPMS Status (code),System Temp. (K),System Field (Oe),Sample Position (deg),Bridge 1 Resistance (ohms),Bridge 1 Excitation (에),Bridge 2 Resistance (ohms),Bridge 2 Excitation (에),Bridge 3 Resistance (ohms),Bridge 3 Excitation (에),Bridge 4 Resistance (ohms),Bridge 4 Excitation (에),Signal 1 Vin (V),Signal 2 Vin (V),Digital Inputs (code),Drive 1 Iout (mA),Drive 1 Ipower (W),Drive 2 Iout (mA),Drive 2 Ipower (W),Pressure (),Map 20 (),Map 21 (),Map 22 (),Map 23 (),Map 24 (),Map 25 (),Map 26 (),Map 27 (),Map 28 (),Map 29 ()
,28581165.895,10.0035124,99.7461624145508,8.08385873489146E-7,3.33828898447935E-7,1,0.999253354069792,40.0298881530762,2.00892458289822,15.599999576807,9.27782044671518E-6,8.12383883179407E-7,0.25,-7.16520620523447E-8,8.04089592807041E-7,-6.73419157534416E-8,10.0035124,10.0035124,99.7461624145508,99.7461624145508,57.0713879601599,20.6293075024837,11.899124,0,0,0,40,4369,9.9926,99.7461624145508,,,,,,,,,,,,,0,,,,0,,,,,,10.0035124,,,,
,28581297.47,13.0377388,99.7461624145508,6.16612236278492E-7,2.84953028413418E-7,1,0.999253354069792,40.0298881530762,2.0087305934031,15.599999576807,7.79232179854547E-6,-3.41345944049672E-6,0.25,-4.11624618573915E-7,6.15053141543379E-7,-4.06284803045211E-7,13.0377388,13.0377388,99.7461624145508,99.7461624145508,57.2292769210445,20.6297228945312,12.658426,0,0,0,40,4370,13.1733,99.7461624145508,,,,,,,,,,,,,0,,,,0,,,,,,13.0377388,,,,
,28581436.385,16.5296783,99.7461624145508,9.96708130590909E-7,3.00596890701411E-7,1,0.999253354069792,40.0298881530762,2.00882261786062,15.599999576807,1.176808677919E-5,-8.54696780256461E-7,0.25,-2.52639105129811E-7,9.92187904291803E-7,-2.46377626819433E-7,16.5296783,16.5296783,99.7461624145508,99.7461624145508,57.251162519583,20.6321880121445,13.417728,0,0,0,40,4370,16.6659,99.7461624145508,,,,,,,,,,,,,0,,,,-0.0049,,,,,,16.5296783,,,,
,28581590.09,20.3402481,99.7461624145508,,,2,,,,15.629999550879,,,,,,,20.3402481,20.3402481,99.7461624145508,99.7461624145508,,,14.177031,,,,-99999999,4370,20.5196,99.7461624145508,,,,,,,,,,,,,,,,,,,,,,,20.3402481,,,,
,28581719.435,23.5473747,99.7461624145508,7.15519298471914E-7,2.77240211538525E-7,1,0.999253354069792,40.0298881530762,1.9845409936629,15.6100001186132,7.87770498343864E-6,2.06155972875E-6,0.25,5.73958764250373E-8,7.11197617945385E-7,6.06422642308652E-8,23.5473747,23.5473747,99.7461624145508,99.7461624145508,57.4676736194099,20.6344952813357,14.177031,0,0,0,40,4370,23.7865,99.7461624145508,,,,,,,,,,,,,0,,,,0.0049,,,,,,23.5473747,,,,
,28581860.495,27.0374699,99.7461624145508,9.44226582188446E-7,2.35693116989319E-7,1,0.999253354069792,40.0298881530762,1.9845617267356,15.6100001186132,1.15981949080444E-5,-4.02241277598061E-6,0.25,-5.28147595751362E-7,9.41865836026268E-7,-5.2033945689094E-7,27.0374699,27.0374699,99.7461624145508,99.7461624145508,57.149550812083,20.6307228923683,14.556682,0,0,0,40,4370,27.3522,99.7461624145508,,,,,,,,,,,,,0,,,,0.0049,,,,,,27.0374699,,,,
,28582008.73,30.7120285,99.7461624145508,,,2,,,,15.629999550879,,,,,,,30.7120285,30.7120285,99.7461624145508,99.7461624145508,,,14.556682,,,,-99999999,4370,31.0674,99.7461624145508,,,,,,,,,,,,,,,,,,,,,,,30.7120285,,,,
,28582141.9,34.0384331,99.7461624145508,1.28328028630802E-6,2.78665422210896E-7,1,0.999253354069792,40.0298881530762,2.00916331009191,15.6100001186132,1.49492611176224E-5,1.68534356099441E-7,0.25,-2.14531380379501E-7,1.27867310689679E-6,-2.05853290842573E-7,34.0384331,34.0384331,99.7461624145508,99.7461624145508,57.2996234877753,20.6218010730079,15.695635,0,0,0,40,4370,34.422,99.7461624145508,,,,,,,,,,,,,0,,,,0,,,,,,34.0384331,,,,
,28582283.75,37.5466309,99.7461624145508,7.20826254106663E-7,2.6933282722243E-7,1,0.999253354069792,40.0298881530762,2.00924344927474,15.6100001186132,8.87179030212677E-6,-2.51597987289467E-6,0.25,-3.51503831640602E-7,7.20273771256387E-7,-3.45475407777422E-7,37.5466309,37.5466309,99.7461624145508,99.7461624145508,57.4504777919868,20.6232602174259,15.315984,0,0,0,40,4370,38.0025,99.7461624145508,,,,,,,,,,,,,0,,,,0.0049,,,,,,37.5466309,,,,
,28582428.72,41.1230698,99.7461624145508,,,2,,,,15.6199999403954,,,,,,,41.1230698,41.1230698,99.7461624145508,99.7461624145508,,,15.695635,,,,-99999999,4370,41.6607,99.7461624145508,,,,,,,,,,,,,,,,,,,,,,,41.1230698,,,,
,28582547.23,44.0403481,99.7461624145508,8.61759614176716E-7,2.50896600328341E-7,1,0.999253354069792,40.0298881530762,2.009161835978,15.6100001186132,9.77882289305855E-6,1.70408779510641E-6,0.25,-4.79796547492743E-9,8.5990578918098E-7,1.40774916975556E-9,44.0403481,44.0403481,99.7461624145508,99.7461624145508,57.4129596230638,20.6236293990774,16.454937,0,0,0,40,4370,44.673,99.7461624145508,,,,,,,,,,,,,0,,,,0,,,,,,44.0403481,,,,
,28582691.985,47.5562935,99.7461624145508,9.93242153881478E-7,2.4968321692712E-7,1,0.999253354069792,40.0298881530762,2.00915685702172,15.6100001186132,1.21411697950208E-5,-2.79244441270976E-6,0.25,-4.25062447060854E-7,9.95331936400604E-7,-4.17257381430033E-7,47.5562935,47.5562935,99.7461624145508,99.7461624145508,57.5505262424484,20.6245164526282,16.834587,0,0,0,40,4370,48.3506,99.7461624145508,,,,,,,,,,,,,0,,,,0,,,,,,47.5562935,,,,
,28582832.58,51.0120621,99.7461624145508,1.17801730344832E-6,3.16280513394589E-7,1,0.999253354069792,40.0298881530762,2.00905919781102,15.6100001186132,1.36886870659939E-5,7.17114348490881E-7,0.25,-1.49201616678463E-7,1.17920053588196E-6,-1.40457523137013E-7,51.0120621,51.0120621,99.7461624145508,99.7461624145508,57.5856995258138,20.6255228982964,17.214239,0,0,0,40,4374,51.9408,99.7461624145508,,,,,,,,,,,,,0,,,,0,,,,,,51.0120621,,,,
,28582958.875,54.0251656,99.7461624145508,1.17946526786362E-6,3.53490945028391E-7,1,0.999253354069792,40.0298881530762,1.98452735100738,15.599999576807,1.31962085635266E-5,2.723377774287E-6,0.25,2.98793183221149E-8,1.1804765685825E-6,3.85268009058602E-8,54.0251656,54.0251656,99.7461624145508,99.7461624145508,57.6701154058907,20.6253412584994,17.593889,0,0,0,40,4374,55.1893,99.7461624145508,,,,,,,,,,,,,0,,,,0.00245,,,,,,54.0251656,,,,
,28583103.35,57.5368042,99.7461624145508,1.10618718276406E-6,3.29170795135719E-7,1,0.999253354069792,40.0298881530762,1.98481075433238,15.599999576807,1.26800594048939E-5,9.47484509083038E-7,0.25,-1.14691755696243E-7,1.10926732028908E-6,-1.07164702163992E-7,57.5368042,57.5368042,99.7461624145508,99.7461624145508,57.6044586102753,20.6212767215105,18.353191,0,0,0,40,4374,58.9155,99.7461624145508,,,,,,,,,,,,,0,,,,0.0049,,,,,,57.5368042,,,,
,28583247.125,61.0375481,99.7461624145508,7.95831666887627E-7,2.96767108965761E-7,1,0.999253354069792,40.0298881530762,1.98479152307555,15.599999576807,8.81574774840151E-6,2.4324249625491E-6,0.25,7.31908009250554E-8,7.97656833110102E-7,7.86842744329554E-8,61.0375481,61.0375481,99.7461624145508,99.7461624145508,57.4325003360445,20.6247746021469,19.112494,0,0,0,40,4374,62.5635,99.7461624145508,,,,,,,,,,,,,0,,,,-0.0049,,,,,,61.0375481,,,,
,28583386,64.5195694,99.7461624145508,8.08568811066471E-7,3.0527047531023E-7,1,0.999253354069792,40.0298881530762,2.00851587550795,15.5800003558397,9.88074171250875E-6,-2.05475260052078E-6,0.25,-3.24946433647108E-7,8.13478480906049E-7,-3.21077543852122E-7,64.5195694,64.5195694,99.7461624145508,99.7461624145508,57.2839909173907,20.6267818986078,19.871798,0,0,0,40,4374,66.06605,99.7461624145508,,,,,,,,,,,,,0,,,,0,,,,,,64.5195694,,,,
,28583530.295,68.0479736,99.7461624145508,1.06476187563216E-6,2.87516615552348E-7,1,0.999253354069792,40.0298881530762,2.00837474844753,15.5800003558397,1.20430340858694E-5,2.74089558799827E-6,0.25,5.02269907248642E-8,1.06887150914719E-6,5.65816411014669E-8,68.0479736,68.0479736,99.7461624145508,99.7461624145508,57.2245871499291,20.6274579649234,19.492144,0,0,0,40,4374,69.7219,99.7461624145508,,,,,,,,,,,,,0,,,,-0.00245,,,,,,68.0479736,,,,
,28583670.33,71.5354156,99.7461624145508,1.19410815692072E-6,3.25138030517689E-7,1,0.999253354069792,40.0298881530762,2.00843706722048,15.5800003558397,1.40281186861403E-5,1.78686535167556E-7,0.25,-1.96975732313675E-7,1.20060034456786E-6,-1.91481846385317E-7,71.5354156,71.5354156,99.7461624145508,99.7461624145508,57.1956668947176,20.62888904724,19.871798,0,0,0,40,4374,73.2522,99.7461624145508,,,,,,,,,,,,,0,,,,0,,,,,,71.5354156,,,,
,28583810.385,75.0057678,99.7461624145508,9.16175266940949E-7,3.23039855101246E-7,1,0.999253354069792,40.0298881530762,2.00837460876011,15.5600002035499,1.12372482841773E-5,-2.5183271935543E-6,0.25,-3.83348148505256E-7,9.22546624177362E-7,-3.80680675162874E-7,75.0057678,75.0057678,99.7461624145508,99.7461624145508,57.0932735586983,20.6263275357843,20.251448,0,0,0,40,4374,76.7934,99.7461624145508,,,,,,,,,,,,,0,,,,0.00245,,,,,,75.0057678,,,,
,28583956.245,78.556488,99.7461624145508,9.42384170594693E-7,2.82277223641015E-7,1,0.999253354069792,40.0298881530762,2.00827194844537,15.5600002035499,1.06321286264891E-5,2.63980858649279E-6,0.25,6.41085099938869E-8,9.46936475021395E-7,6.87461789397602E-8,78.556488,78.556488,99.7461624145508,99.7461624145508,57.1206305568714,20.6285964910078,20.251448,0,0,0,40,4374,80.4943,99.7461624145508,,,,,,,,,,,,,0,,,,-0.0049,,,,,,78.556488,,,,
,28584095.695,82.00757215,99.7461624145508,1.18932085300372E-6,2.44700722859939E-7,1,0.999253354069792,40.0298881530762,2.00855035484252,15.5600002035499,1.37014596734139E-5,1.75664159375854E-6,0.25,-5.66518154318136E-8,1.19589545628374E-6,-5.19113822797624E-8,81.9736938,82.0414505,99.7461624145508,99.7461624145508,57.474708276083,20.6282847465606,19.871798,0,0,0,40,4374,84.03325,99.7461624145508,,,,,,,,,,,,,0,,,,-0.00245,,,,,,82.00757215,,,,
,28584235.205,85.5091858,99.7461624145508,1.11368112280041E-6,3.29235965081859E-7,1,0.999253354069792,40.0298881530762,2.00844292425409,15.5300004407763,1.25660159876406E-5,3.14478217768648E-6,0.25,7.85428670895269E-8,1.11945047039262E-6,8.33631447555398E-8,85.5091858,85.5091858,99.7461624145508,99.7461624145508,57.2042648084291,20.6272382182974,20.251448,0,0,0,40,4374,87.53255,99.7461624145508,,,,,,,,,,,,,0,,,,0.00245,,,,,,85.5091858,,,,
,28584375.34,89.0137024,99.7461624145508,9.92052211396244E-7,2.77990611326203E-7,1,0.999253354069792,40.0298881530762,2.00834934962149,15.5300004407763,1.19138839955098E-5,-1.27854550794248E-6,0.25,-2.86833161187915E-7,9.98615332615763E-7,-2.84778939009114E-7,89.0137024,89.0137024,99.7461624145508,99.7461624145508,57.3480844559676,20.631073914607,20.631098,0,0,0,40,4374,91.0392,99.7461624145508,,,,,,,,,,,,,0,,,,0,,,,,,89.0137024,,,,
,28584515.97,92.5127716,99.7461624145508,7.791247310089E-7,2.42478427044837E-7,1,0.999253354069792,40.0298881530762,2.00853305345952,15.5300004407763,9.6677794338529E-6,-2.76606258151292E-6,0.25,-3.79223189820263E-7,7.84803672323339E-7,-3.78677867962053E-7,92.5127716,92.5127716,99.7461624145508,99.7461624145508,56.9197520274291,20.6263558222518,20.631098,0,0,0,40,4374,94.5789,99.7461624145508,,,,,,,,,,,,,0,,,,0,,,,,,92.5127716,,,,
,28584659.225,96.0631638,99.7461624145508,9.83892171154021E-7,2.74239037591824E-7,1,0.999253354069792,40.0298881530762,1.9844774687885,15.5100002884865,1.1654055148422E-5,-1.09787083365341E-6,0.25,-2.70199998216061E-7,9.90326675187577E-7,-2.68567392580526E-7,96.0631638,96.0631638,99.7461624145508,99.7461624145508,57.0026046504676,20.6239379175402,20.631098,0,0,0,40,4374,98.183,99.7461624145508,,,,,,,,,,,,,0,,,,0,,,,,,96.0631638,,,,
,28584798.575,99.5152054,99.7461624145508,1.08054426991435E-6,3.33392669255572E-7,1,0.999253354069792,40.0298881530762,1.98433676625834,15.5100002884865,1.30926078811062E-5,-2.88507828649016E-6,0.25,-4.45160913500224E-7,1.08802185900936E-6,-4.44423996489091E-7,99.4864731,99.5439377,99.7461624145508,99.7461624145508,57.1135959001984,20.6264525614647,21.01075,0,0,0,40,4374,101.6773,99.7461624145508,,,,,,,,,,,,,0,,,,-0.00245,,,,,,99.5152054,,,,
,28584940.57,103.0587082,99.7461624145508,8.85475114518323E-7,3.64140128802955E-7,1,0.999253354069792,40.0298881530762,1.98420485894256,15.5100002884865,1.05418649191721E-5,-1.30571320688921E-6,0.25,-2.70955192886916E-7,8.91272736465392E-7,-2.69976645535203E-7,103.0587082,103.0587082,99.7461624145508,99.7461624145508,56.8798889729483,20.6275607543042,20.631098,0,0,0,40,4374,105.2582,99.7461624145508,,,,,,,,,,,,,0,,,,0.00245,,,,,,103.0587082,,,,
,28585061.995,106.0387573,99.7461624145508,9.0760198275065E-7,2.89331949252979E-7,1,0.999253354069792,40.0298881530762,1.98457695499981,15.4699999839067,1.03784130743695E-5,1.10384673706408E-6,0.25,-6.1467135982648E-8,9.12913180554365E-7,-5.93606759881902E-8,106.0387573,106.0387573,99.7461624145508,99.7461624145508,57.2456911199484,20.618778908586,21.3904,0,0,0,40,4374,108.31125,99.7461624145508,,,,,,,,,,,,,0,,,,0,,,,,,106.0387573,,,,
,28585201.1,109.5070038,99.7461624145508,9.40245713227708E-7,2.84204038422518E-7,1,0.999253354069792,40.0298881530762,1.98455142315828,15.4699999839067,1.07230118868769E-5,1.30447415879906E-6,0.25,-4.92983302221441E-8,9.45680982162928E-7,-4.7168447767668E-8,109.5070038,109.5070038,99.7461624145508,99.7461624145508,57.2707032325638,20.6262693171142,21.3904,0,0,0,40,4374,111.805,99.7461624145508,,,,,,,,,,,,,0,,,,-0.0049,,,,,,109.5070038,,,,
,28585343.205,113.0117798,99.7461624145508,1.00777328882626E-6,3.36944727936804E-7,1,0.999253354069792,40.0298881530762,1.98459493092727,15.4699999839067,1.17660369322357E-5,-1.6196005258485E-7,0.25,-1.90756767112362E-7,1.01389449748779E-6,-1.89380801208923E-7,113.0117798,113.0117798,99.7461624145508,99.7461624145508,57.014329078256,20.6297331482343,21.770052,0,0,0,40,4374,115.38205,99.7461624145508,,,,,,,,,,,,,0,,,,0,,,,,,113.0117798,,,,
,28585464.095,116.029026,99.7461624145508,1.04357396373881E-6,2.82807510504748E-7,1,0.999253354069792,40.0298881530762,1.99574697996535,15.429999679327,1.15844733476575E-5,3.62798423057628E-6,0.25,1.36748052555216E-7,1.04907851205614E-6,1.39936955238526E-7,115.9932632,116.0647888,99.7461624145508,99.7461624145508,56.9080275996406,20.6210710797408,21.01075,0,0,0,40,4374,118.4196,99.7461624145508,,,,,,,,,,,,,0,,,,0.00245,,,,,,116.029026,,,,
,28585604.09,119.5165787,99.7461624145508,8.18846410035221E-7,3.24263481414854E-7,1,0.999253354069792,40.0298881530762,1.99569820690508,15.429999679327,9.86943487494243E-6,-1.61521757305615E-6,0.25,-2.85348284528407E-7,8.24008190820121E-7,-2.85113299099805E-7,119.5165787,119.5165787,99.7461624145508,99.7461624145508,57.3676251689484,20.6246185007546,22.149702,0,0,0,40,4374,121.93885,99.7461624145508,,,,,,,,,,,,,0,,,,-0.00245,,,,,,119.5165787,,,,
,28585746.525,123.0559616,99.7461624145508,1.03164216327331E-6,2.93401580158449E-7,1,0.999253354069792,40.0298881530762,1.99583863581104,15.429999679327,1.26359649473621E-5,-3.19101643431068E-6,0.25,-4.6114517542898E-7,1.03826697700152E-6,-4.61491441242335E-7,123.0559616,123.0559616,99.7461624145508,99.7461624145508,56.8877052581406,20.6228745300515,22.149702,0,0,0,40,4374,125.51645,99.7461624145508,,,,,,,,,,,,,0,,,,-0.00245,,,,,,123.0559616,,,,
,28585886.665,126.5429993,99.7461624145508,7.91385896393176E-7,3.14520554098701E-7,1,0.999253354069792,40.0298881530762,1.98446603043962,15.3900003060699,1.04054869224372E-5,-6.82023440159566E-6,0.25,-7.41844390807766E-7,7.97172406660537E-7,-7.44264093435352E-7,126.5429993,126.5429993,99.7461624145508,99.7461624145508,57.007294421583,20.6234903555879,21.770052,0,0,0,40,4374,129.0345,99.7461624145508,,,,,,,,,,,,,0,,,,0,,,,,,126.5429993,,,,
,28586026.04,130.0277405,99.7461624145508,1.09140555095993E-6,2.55632559947198E-7,1,0.999253354069792,40.0298881530762,1.98436878322647,15.3900003060699,1.23883181756654E-5,1.81972755054182E-6,0.25,-2.94450224940704E-8,1.09730456353378E-6,-2.74886878532401E-8,130.0277405,130.0277405,99.7461624145508,99.7461624145508,57.3988903097176,20.6257037257612,21.770052,0,0,0,40,4374,132.5344,99.7461624145508,,,,,,,,,,,,,0,,,,-0.00245,,,,,,130.0277405,,,,
,28586166.07,133.5199127,99.7461624145508,1.03777675531043E-6,3.16941397773773E-7,1,0.999253354069792,40.0298881530762,1.98441229867367,15.3900003060699,1.23260090053893E-5,-1.40484580354161E-6,0.25,-3.05426734149108E-7,1.04382750216361E-6,-3.05110972100691E-7,133.5199127,133.5199127,99.7461624145508,99.7461624145508,57.5989872106407,20.6279375941356,21.770052,0,0,0,40,4374,136.053,99.7461624145508,,,,,,,,,,,,,0,,,,0.0049,,,,,,133.5199127,,,,
,28586309.085,137.0683594,99.7461624145508,1.04066542952489E-6,2.94288464080739E-7,1,0.999253354069792,40.0298881530762,1.9844832323504,15.3500000014901,1.24159577539342E-5,-1.73205021793697E-6,0.25,-3.34820708293045E-7,1.04668397740393E-6,-3.34705736666553E-7,137.0683594,137.0683594,99.7461624145508,99.7461624145508,57.1214121853907,20.6246438852022,21.770052,0,0,0,40,4374,139.63215,99.7461624145508,,,,,,,,,,,,,0,,,,0,,,,,,137.0683594,,,,
,28586448.41,140.5450592,99.7461624145508,1.10193168908957E-6,2.55324539998614E-7,1,0.999253354069792,40.0298881530762,1.98450354329063,15.3500000014901,1.30238905858447E-5,-1.13484057723268E-6,0.25,-2.92572302138361E-7,1.10808988742502E-6,-2.9217792560876E-7,140.5450592,140.5450592,99.7461624145508,99.7461624145508,57.2027015513907,20.6243845674846,22.529354,0,0,0,40,4374,143.1301,99.7461624145508,,,,,,,,,,,,,0,,,,-0.0049,,,,,,140.5450592,,,,
,28586588.155,144.0318451,99.7461624145508,1.00460932961517E-6,3.04815929505626E-7,1,0.999253354069792,40.0298881530762,1.98467422142766,15.3500000014901,1.14914964732653E-5,1.15708138343812E-6,0.25,-7.26510297663375E-8,1.0098045080351E-6,-7.13514749513327E-8,144.0318451,144.0318451,99.7461624145508,99.7461624145508,57.1948852661984,20.6207007837248,22.529354,0,0,0,40,4374,146.65365,99.7461624145508,,,,,,,,,,,,,0,,,,0,,,,,,144.0318451,,,,
,28586729.61,147.5285797,99.7461624145508,1.06666722937032E-6,3.13736602340477E-7,1,0.999253354069792,40.0298881530762,1.98485748747223,15.3000000864267,1.2089009180994E-5,1.87350838779034E-6,0.25,-1.99853702015554E-8,1.07199808657244E-6,-1.83763037602656E-8,147.5285797,147.5285797,99.7461624145508,99.7461624145508,57.2667950899676,20.6228390880623,22.529354,0,0,0,40,4374,150.1876,99.7461624145508,,,,,,,,,,,,,0,,,,-0.0098,,,,,,147.5285797,,,,
,28586868.375,151.0170135,99.7461624145508,8.34059265650641E-7,3.47925652923032E-7,1,0.999253354069792,40.0298881530762,1.98479253748537,15.3000000864267,9.27557506248472E-6,2.47569995171531E-6,0.25,7.39152256948174E-8,8.38015948189557E-7,7.55680248808813E-8,151.0170135,151.0170135,99.7461624145508,99.7461624145508,57.4332819645638,20.6215793972682,22.149702,0,0,0,40,4374,153.6639,99.7461624145508,,,,,,,,,,,,,0,,,,0,,,,,,151.0170135,,,,
,28587009.245,154.5071564,99.7461624145508,1.00148294945438E-6,2.99775996637903E-7,1,0.999253354069792,40.0298881530762,1.98477212196393,15.3000000864267,1.20911836349539E-5,-2.51103722716058E-6,0.25,-3.96699100160127E-7,1.00687696710394E-6,-3.97098757641808E-7,154.5071564,154.5071564,99.7461624145508,99.7461624145508,56.9658681100637,20.6254358226334,22.149702,0,0,0,40,4374,157.2024,99.7461624145508,,,,,,,,,,,,,0,,,,-0.00245,,,,,,154.5071564,,,,
,28587129.975,157.5181885,99.7461624145508,8.1738630707391E-7,2.94060508325734E-7,1,0.999253354069792,40.0298881530762,2.00866576991013,15.259999781847,1.00293590142808E-5,-2.35089178039987E-6,0.25,-3.48083520374221E-7,8.21746848406576E-7,-3.48531537070617E-7,157.5181885,157.5181885,99.7461624145508,99.7461624145508,57.2136443506599,20.6230634435657,22.529354,0,0,0,40,4374,160.2313,99.7461624145508,,,,,,,,,,,,,0,,,,0,,,,,,157.5181885,,,,
,28587268.7,161.0262909,99.7461624145508,9.37510990602818E-7,3.17100070265714E-7,1,0.999253354069792,40.0298881530762,2.00857846740696,15.259999781847,1.02826699520353E-5,4.30781889102551E-6,0.25,2.14004517913587E-7,9.41538623608826E-7,2.16320447012693E-7,161.0262909,161.0262909,99.7461624145508,99.7461624145508,57.1135959001984,20.6268147182705,22.529354,0,0,0,40,4374,163.7008,99.7461624145508,,,,,,,,,,,,,0,,,,-0.00245,,,,,,161.0262909,,,,
,28587411.155,164.546524,99.7461624145508,1.13033970960202E-6,2.82155378236797E-7,1,0.999253354069792,40.0298881530762,2.0085662589775,15.259999781847,1.35483301126561E-5,-1.42698846166412E-6,0.25,-3.21610552292501E-7,1.13589405179526E-6,-3.21511883154361E-7,164.546524,164.546524,99.7461624145508,99.7461624145508,57.3770047111791,20.6280903474805,22.909004,0,0,0,40,4374,167.2674,99.7461624145508,,,,,,,,,,,,,0,,,,-0.0049,,,,,,164.546524,,,,
,28587549.97,168.0278168,99.7461624145508,9.9059980480375E-7,3.53160062548004E-7,1,0.999253354069792,40.0298881530762,2.00865210112028,15.2099998667836,1.15387551417156E-5,6.68751101243478E-7,0.25,-1.13752785828047E-7,9.95135588140867E-7,-1.1293268209478E-7,168.0278168,168.0278168,99.7461624145508,99.7461624145508,57.1675282680253,20.6271340940006,22.529354,0,0,0,40,4374,170.7354,99.7461624145508,,,,,,,,,,,,,0,,,,0,,,,,,168.0278168,,,,
,28587689.695,171.5275116,99.7461624145508,1.08944875899022E-6,3.24576723768889E-7,1,0.999253354069792,40.0298881530762,2.00829459473186,15.2099998667836,1.32592632230102E-5,-2.55699203818983E-6,0.25,-4.13426862232567E-7,1.09469860888155E-6,-4.13798972049811E-7,171.5275116,171.5275116,99.7461624145508,99.7461624145508,56.9752476522945,20.6275229118454,22.909004,0,0,0,40,4374,174.22865,99.7461624145508,,,,,,,,,,,,,0,,,,0,,,,,,171.5275116,,,,
,28587831.71,175.0617065,99.7461624145508,1.12639039713615E-6,3.37031680797547E-7,1,0.999253354069792,40.0298881530762,2.00833644581866,15.2099998667836,1.23078962152287E-5,5.40639400845774E-6,0.25,2.77719007083074E-7,1.1307956162419E-6,2.80316946749228E-7,175.0617065,175.0617065,99.7461624145508,99.7461624145508,57.2066096939868,20.6305111590722,23.288654,0,0,0,40,4374,177.77755,99.7461624145508,,,,,,,,,,,,,0,,,,0.0049,,,,,,175.0617065,,,,
,28587970.535,178.5325928,99.7461624145508,7.70475810603065E-7,3.92290846609112E-7,1,0.999253354069792,40.0298881530762,1.98423886831734,15.1599999517202,9.25597874612462E-6,-1.71923735967657E-6,0.25,-2.86296191139633E-7,7.74003510050708E-7,-2.86525666571967E-7,178.5325928,178.5325928,99.7461624145508,99.7461624145508,57.4199942797368,20.6254403701346,22.909004,0,0,0,40,4374,181.2492,99.7461624145508,,,,,,,,,,,,,0,,,,-0.0049,,,,,,178.5325928,,,,
,28588109.04,182.0204773,99.7461624145508,9.13993298471566E-7,3.16392375358048E-7,1,0.999253354069792,40.0298881530762,1.98423974753267,15.1599999517202,1.06978611443259E-5,-4.22675309514893E-7,0.25,-1.9632219473673E-7,9.17899792130698E-7,-1.96011136939039E-7,182.0204773,182.0204773,99.7461624145508,99.7461624145508,57.3418314278138,20.6274132508151,22.909004,0,0,0,40,4374,184.72,99.7461624145508,,,,,,,,,,,,,0,,,,0,,,,,,182.0204773,,,,
,28588250.705,185.5384979,99.7461624145508,5.51490752236838E-7,3.7005243817214E-7,1,0.999253354069792,40.0298881530762,1.98393207015987,15.1599999517202,7.20889376113821E-6,-4.60320160887315E-6,0.25,-5.0390692723623E-7,5.54237694875582E-7,-5.05229398389696E-7,185.5384979,185.5384979,99.7461624145508,99.7461624145508,57.2839909173907,20.6354005988199,22.909004,0,0,0,40,4374,188.2708,99.7461624145508,,,,,,,,,,,,,0,,,,-0.00245,,,,,,185.5384979,,,,
,28588391.46,189.0438232,99.7461624145508,6.7876726263216E-7,2.8222438227355E-7,1,0.999253354069792,40.0298881530762,1.98394913011273,15.1100000366569,7.72502858068317E-6,9.33467145237293E-7,0.25,-3.51788048232368E-8,6.81387317232141E-7,-3.45348214549964E-8,189.0438232,189.0438232,99.7461624145508,99.7461624145508,57.2292769210445,20.6326546812303,23.288654,0,0,0,40,4374,191.7985,99.7461624145508,,,,,,,,,,,,,0,,,,0,,,,,,189.0438232,,,,
,28588532.655,192.5467987,99.7461624145508,8.52180957889697E-7,3.05179881093037E-7,1,0.999253354069792,40.0298881530762,1.98383183276854,15.1100000366569,1.01963822762269E-5,-1.70264163884023E-6,0.25,-2.9902117436681E-7,8.55661272215155E-7,-2.99171159901936E-7,192.5467987,192.5467987,99.7461624145508,99.7461624145508,56.9822823089676,20.6347469702504,23.668306,0,0,0,40,4374,195.34365,99.7461624145508,,,,,,,,,,,,,0,,,,0,,,,,,192.5467987,,,,
,28588672.08,196.0223846,99.7461624145508,8.92759010474054E-7,3.66165684982789E-7,1,0.999253354069792,40.0298881530762,1.98391598765753,15.1100000366569,1.03928176120645E-5,-1.24081767109191E-7,0.25,-1.66075329328461E-7,8.96138145087411E-7,-1.65693165082965E-7,196.0223846,196.0223846,99.7461624145508,99.7461624145508,57.4184310226984,20.6319298497352,23.288654,0,0,0,40,4374,198.84325,99.7461624145508,,,,,,,,,,,,,0,,,,0.00245,,,,,,196.0223846,,,,
,28588810.565,199.5147705,99.7461624145508,4.04237844602212E-7,3.53733612128089E-7,1,0.999253354069792,40.0298881530762,1.98435833284336,15.0499995797873,4.9675257139212E-6,-1.56036922132669E-6,0.25,-2.08560899776761E-7,4.05863813698216E-7,-2.08851747128936E-7,199.5147705,199.5147705,99.7461624145508,99.7461624145508,57.2433462343907,20.6297286398629,23.288654,0,0,0,40,4374,202.3135,99.7461624145508,,,,,,,,,,,,,0,,,,0,,,,,,199.5147705,,,,
,28588953.115,203.0180359,99.7461624145508,9.79353954700333E-7,3.63543381992972E-7,1,0.999253354069792,40.0298881530762,1.98455018345709,15.0499995797873,1.14914355658007E-5,-6.52769291708207E-7,0.25,-2.27947447916278E-7,9.82880286290144E-7,-2.27686711100022E-7,203.0180359,203.0180359,99.7461624145508,99.7461624145508,57.3660619119099,20.6284212181272,23.288654,0,0,0,40,4374,205.8876,99.7461624145508,,,,,,,,,,,,,0,,,,0,,,,,,203.0180359,,,,
,28589092.17,206.5149994,99.7461624145508,9.65926866115307E-7,3.46960215194738E-7,1,0.999253354069792,40.0298881530762,1.98455499812444,15.0499995797873,1.13921830660313E-5,-9.87090518454073E-7,0.25,-2.55247870102673E-7,9.69321084098651E-7,-2.55084683916251E-7,206.4776459,206.5523529,99.7461624145508,99.7461624145508,57.6052402387946,20.6253515720199,23.288654,0,0,0,40,4374,209.381,99.7461624145508,,,,,,,,,,,,,0,,,,0,,,,,,206.5149994,,,,
,28589212.51,209.5500793,99.7461624145508,8.57836617928907E-7,3.67928883885953E-7,1,0.999253354069792,40.0298881530762,1.98458323902128,14.9999996647239,1.01969992086428E-5,-1.34054096091381E-6,0.25,-2.6781788311561E-7,8.60802797909557E-7,-2.67794997739635E-7,209.5500793,209.5500793,99.7461624145508,99.7461624145508,57.291807202583,20.6212644619596,23.668306,0,0,0,40,4374,212.38785,99.7461624145508,,,,,,,,,,,,,0,,,,0.00245,,,,,,209.5500793,,,,
,28589353.515,213.0482635,99.7461624145508,5.88095042931359E-7,3.67640646001628E-7,1,0.999253354069792,40.0298881530762,1.98446531861917,14.9999996647239,7.77808461531721E-6,-5.46239805289841E-6,0.25,-5.8660904604112E-7,5.90454724183087E-7,-5.87803914940996E-7,213.0482635,213.0482635,99.7461624145508,99.7461624145508,57.3793495967368,20.625673347182,23.288654,0,0,0,40,4374,215.91015,99.7461624145508,,,,,,,,,,,,,0,,,,0,,,,,,213.0482635,,,,
,28589492.985,216.5492859,99.7461624145508,3.44810930172491E-7,3.39441123896174E-7,1,0.999253354069792,40.0298881530762,1.98443014115075,14.9999996647239,3.53314643253765E-6,2.71230601012143E-6,0.25,1.80766706553012E-7,3.45639322460439E-7,1.81626734033599E-7,216.5492859,216.5492859,99.7461624145508,99.7461624145508,57.2574155477368,20.6270688210621,24.047956,0,0,0,40,4374,219.4011,99.7461624145508,,,,,,,,,,,,,0,,,,0,,,,,,216.5492859,,,,
,28589614.165,219.5619354,99.7461624145508,9.35881038864343E-7,3.3326108628838E-7,1,0.999253354069792,40.0298881530762,2.0086535991587,14.9400001391768,1.13415827487694E-5,-2.00944590134363E-6,0.25,-3.38655080008712E-7,9.38832350903118E-7,-3.38714989205306E-7,219.5619354,219.5619354,99.7461624145508,99.7461624145508,57.2058280654676,20.6232994566781,23.288654,0,0,0,40,4374,222.44075,99.7461624145508,,,,,,,,,,,,,0,,,,0,,,,,,219.5619354,,,,
,28589753.23,223.0053711,99.7461624145508,8.58383232524713E-7,3.01794235052333E-7,1,0.999253354069792,40.0298881530762,2.0086318658477,14.9400001391768,9.38867870009639E-6,3.9908588766256E-6,0.25,2.01080363309108E-7,8.60506346353708E-7,2.02423953109108E-7,223.0053711,223.0053711,99.7461624145508,99.7461624145508,57.3465211989291,20.623747126205,23.668306,0,0,0,40,4374,225.9228,99.7461624145508,,,,,,,,,,,,,0,,,,-0.0049,,,,,,223.0053711,,,,
,28589894.67,226.5728607,99.7461624145508,7.44583096604785E-7,2.63956295772615E-7,1,0.999253354069792,40.0298881530762,2.00863997561057,14.9400001391768,9.00322222708035E-6,-1.49583890311208E-6,0.25,-2.60415459991747E-7,7.46736028896742E-7,-2.60402052712702E-7,226.5728607,226.5728607,99.7461624145508,99.7461624145508,57.3246356003907,20.6254912323943,23.668306,0,0,0,40,4374,229.46325,99.7461624145508,,,,,,,,,,,,,0,,,,0,,,,,,226.5728607,,,,
,28590034.115,230.0236053,99.7461624145508,8.4389739332563E-7,3.66500163075044E-7,1,0.999253354069792,40.0298881530762,2.00862849412357,14.8999998345971,1.01379693602234E-5,-1.3216229750914E-6,0.25,-2.62365621415568E-7,8.46203210856368E-7,-2.62249176129442E-7,230.0236053,230.0236053,99.7461624145508,99.7461624145508,57.0487207331022,20.6221592604128,24.047956,0,0,0,40,4374,232.96845,99.7461624145508,,,,,,,,,,,,,0,,,,0,,,,,,230.0236053,,,,
,28590176.22,233.5494385,99.7461624145508,5.674780550744E-7,4.36883858665542E-7,1,0.999253354069792,40.0298881530762,2.0087004339563,14.8999998345971,6.98799585729118E-6,-1.87636797234803E-6,0.25,-2.63079317678294E-7,5.69033328536898E-7,-2.63190815047966E-7,233.5494385,233.5494385,99.7461624145508,99.7461624145508,57.1964485232368,20.627012990793,23.668306,0,0,0,40,4374,236.531,99.7461624145508,,,,,,,,,,,,,0,,,,0,,,,,,233.5494385,,,,
,28590314.07,237.0102539,99.7461624145508,6.31581576091198E-7,3.77526404449951E-7,1,0.999253354069792,40.0298881530762,2.00873745529359,14.8999998345971,8.4409169490466E-6,-5.9181186195492E-6,0.25,-6.28860462423458E-7,6.33524195088111E-7,-6.2970211984033E-7,237.0102539,237.0102539,99.7461624145508,99.7461624145508,57.1995750373137,20.62301329571,24.427608,0,0,0,40,4374,239.9975,99.7461624145508,,,,,,,,,,,,,0,,,,0.0049,,,,,,237.0102539,,,,
,28590457.955,240.5635529,99.7461624145508,5.01014525735258E-7,3.74905679876656E-7,1,0.999253354069792,40.0298881530762,1.98442748788689,14.8400003090501,5.64172666673191E-6,9.86590788241461E-7,0.25,6.90609473601617E-10,5.02059596848297E-7,1.11952411685898E-9,240.5635529,240.5635529,99.7461624145508,99.7461624145508,57.2144259791791,20.6235138219349,23.668306,0,0,0,40,4374,243.60805,99.7461624145508,,,,,,,,,,,,,0,,,,0.0049,,,,,,240.5635529,,,,
,28590595.72,244.0097351,99.7461624145508,9.06763723721438E-7,2.95868487820452E-7,1,0.999253354069792,40.0298881530762,1.98456394264172,14.8400003090501,1.00445996806466E-5,2.74000528407954E-6,0.25,8.60129348011463E-8,9.08474721820844E-7,8.69427512472092E-8,244.0097351,244.0097351,99.7461624145508,99.7461624145508,57.1323549846599,20.6219631758721,24.427608,0,0,0,40,4374,247.06005,99.7461624145508,,,,,,,,,,,,,0,,,,0,,,,,,244.0097351,,,,
,28590736.735,247.5132904,99.7461624145508,4.11094313595565E-7,4.20352014873878E-7,1,0.999253354069792,40.0298881530762,1.98468939195274,14.8400003090501,4.82394936781769E-6,-3.16831228343753E-7,0.25,-9.94265389217225E-8,4.11934134490248E-7,-9.92707935757047E-8,247.5132904,247.5132904,99.7461624145508,99.7461624145508,57.0487207331022,20.6230860166629,24.047956,0,0,0,40,4374,250.58645,99.7461624145508,,,,,,,,,,,,,0,,,,0,,,,,,247.5132904,,,,
,28590878.165,251.0283051,99.7461624145508,4.29142035631493E-7,3.91087588591006E-7,1,0.999253354069792,40.0298881530762,1.9849129750307,14.7799998521805,5.39842633673737E-6,-2.42285441146652E-6,0.25,-2.89555365927995E-7,4.30114732926304E-7,-2.8970529515379E-7,251.0283051,251.0283051,99.7461624145508,99.7461624145508,57.4520410490253,20.6224642790198,24.047956,0,0,0,40,4374,254.1441,99.7461624145508,,,,,,,,,,,,,0,,,,-0.0049,,,,,,251.0283051,,,,
,28591018.11,254.5194092,99.7461624145508,3.36912186071048E-7,3.28702742275223E-7,1,0.999253354069792,40.0298881530762,1.98487695717035,14.7799998521805,4.35061430179992E-6,-2.5537393580482E-6,0.25,-2.85210507793703E-7,3.37677383484546E-7,-2.85396997794661E-7,254.5194092,254.5194092,99.7461624145508,99.7461624145508,57.1206305568714,20.6205318706278,24.047956,0,0,0,40,4374,257.6522,99.7461624145508,,,,,,,,,,,,,0,,,,0,,,,,,254.5194092,,,,
,28591156.585,258.0104065,99.7461624145508,5.19059910356956E-7,3.28550939693809E-7,1,0.999253354069792,40.0298881530762,1.98484466880413,14.7799998521805,6.79057728273228E-6,-4.446289263007E-6,0.25,-4.84914209149337E-7,5.20204657478207E-7,-4.85220680031182E-7,258.0104065,258.0104065,99.7461624145508,99.7461624145508,57.4450063923522,20.6236144274332,24.427608,0,0,0,40,4374,261.1087,99.7461624145508,,,,,,,,,,,,,0,,,,0,,,,,,258.0104065,,,,
,28591278.23,261.0224609,99.7461624145508,4.92502213948014E-7,3.32678312426088E-7,1,0.999253354069792,40.0298881530762,2.00880607429432,14.7299999371171,6.97893500053983E-6,-6.93364849660627E-6,0.25,-6.94281231570903E-7,4.93711873652602E-7,-6.94847799147023E-7,261.0224609,261.0224609,99.7461624145508,99.7461624145508,57.0323065341983,20.6240532513845,24.047956,0,0,0,40,4374,264.1655,99.7461624145508,,,,,,,,,,,,,0,,,,-0.0049,,,,,,261.0224609,,,,
,28591420.51,264.5551758,99.7461624145508,9.39532855862988E-7,3.78434855282032E-7,1,0.999253354069792,40.0298881530762,2.00868112399883,14.7299999371171,1.10818406713987E-5,-3.6690086930399E-7,0.25,-1.95103745251366E-7,9.40845734151534E-7,-1.94629959630086E-7,264.5551758,264.5551758,99.7461624145508,99.7461624145508,57.484869446833,20.6270168568599,24.807261,0,0,0,40,4374,267.7209,99.7461624145508,,,,,,,,,,,,,0,,,,0.00245,,,,,,264.5551758,,,,
,28591558.415,268.0052795,99.7461624145508,8.37751471189588E-7,3.59166396520259E-7,1,0.999253354069792,40.0298881530762,2.00883968438368,14.7299999371171,9.85877572683515E-6,-1.99921907549224E-7,0.25,-1.6278342181679E-7,8.38808535508309E-7,-1.62336806353169E-7,267.9802856,268.0302734,99.7461624145508,99.7461624145508,57.4160861371407,20.6230094897805,24.807261,0,0,0,40,4374,271.1663,99.7461624145508,,,,,,,,,,,,,0,,,,-0.00245,,,,,,268.0052795,,,,
,28591681.025,271.0442505,99.7461624145508,5.81312882011169E-7,3.92880418950663E-7,1,0.999253354069792,40.0298881530762,2.00881032306913,14.6800000220537,6.35375945696058E-6,2.66714225977606E-6,0.25,1.33539653227208E-7,5.81799720336456E-7,1.34104277005476E-7,271.0112,271.077301,99.7461624145508,99.7461624145508,57.105779615006,20.6298477134548,24.807261,0,0,0,40,4374,274.23955,99.7461624145508,,,,,,,,,,,,,0,,,,0,,,,,,271.0442505,,,,
,28591820.655,274.5120239,99.7461624145508,5.12248639801605E-7,3.78730147963815E-7,1,0.999253354069792,40.0298881530762,2.00851791633181,14.6800000220537,6.75235501194522E-6,-4.31364090373214E-6,0.25,-4.67830081583443E-7,5.13042012558982E-7,-4.67870108940934E-7,274.5120239,274.5120239,99.7461624145508,99.7461624145508,57.2300585495638,20.6328917059377,24.427608,0,0,0,40,4374,277.7451,99.7461624145508,,,,,,,,,,,,,0,,,,0,,,,,,274.5120239,,,,
,28591959.495,278.0186768,99.7461624145508,3.25211106110333E-7,4.00377561926267E-7,1,0.999253354069792,40.0298881530762,2.00843199654918,14.6800000220537,3.83460199155646E-6,-1.32992940905431E-7,0.25,-6.80522556267883E-8,3.25506387577383E-7,-6.78703839307131E-8,278.0186768,278.0186768,99.7461624145508,99.7461624145508,57.2378748347561,20.6344887009762,25.186911,0,0,0,40,4374,281.21265,99.7461624145508,,,,,,,,,,,,,0,,,,-0.00245,,,,,,278.0186768,,,,
,28592101.375,281.5305786,99.7461624145508,5.70308173324876E-7,3.50080697870658E-7,1,0.999253354069792,40.0298881530762,2.00847334926906,14.6199995651841,6.79602711606267E-6,-6.49723367228246E-7,0.25,-1.55944119102012E-7,5.70778830257735E-7,-1.55639441223699E-7,281.5305786,281.5305786,99.7461624145508,99.7461624145508,57.0901470446214,20.6277581488269,24.427608,0,0,0,40,4374,284.76635,99.7461624145508,,,,,,,,,,,,,0,,,,0,,,,,,281.5305786,,,,
,28592241.525,285.0452271,99.7461624145508,4.16990934498613E-7,4.5374489722439E-7,1,0.999253354069792,40.0298881530762,2.00846483619011,14.6199995651841,4.08151544470851E-6,4.64267287349348E-6,0.25,3.35856094613017E-7,4.16967910256434E-7,3.36316572644589E-7,285.0452271,285.0452271,99.7461624145508,99.7461624145508,57.2394380917945,20.6294393010117,25.186911,0,0,0,40,4374,288.2468,99.7461624145508,,,,,,,,,,,,,0,,,,0,,,,,,285.0452271,,,,
,28592380.65,288.5072937,99.7461624145508,1.24427403343821E-7,3.66250261933244E-7,1,0.999253354069792,40.0298881530762,2.00867522568356,14.6199995651841,1.31318411007601E-6,8.35322652778175E-7,0.25,5.18701476841385E-8,1.24439307232835E-7,5.1975405198836E-8,288.5072937,288.5072937,99.7461624145508,99.7461624145508,57.4020168237945,20.6303919409508,25.186911,0,0,0,40,4374,291.7476,99.7461624145508,,,,,,,,,,,,,0,,,,0,,,,,,288.5072937,,,,
,28592523.905,292.0491333,99.7461624145508,5.11926884374319E-7,3.74045849377958E-7,1,0.999253354069792,40.0298881530762,1.9845927782073,14.5600000396371,6.12970875732318E-6,-1.15894397947797E-6,0.25,-1.91776160758697E-7,5.12187270570115E-7,-1.91478629153779E-7,292.0491333,292.0491333,99.7461624145508,99.7461624145508,57.2566339192176,20.6257776340375,24.427608,0,0,0,40,4374,295.3125,99.7461624145508,,,,,,,,,,,,,0,,,,-0.0049,,,,,,292.0491333,,,,
,28592663.5,295.5074158,99.7461624145508,2.24368106151465E-7,3.97412323067684E-7,1,0.999253354069792,40.0298881530762,1.98433976202644,14.5600000396371,3.27271782596012E-6,-3.89484031974802E-6,0.25,-3.85353954046603E-7,2.24654699962102E-7,-3.85254884365983E-7,295.5074158,295.5074158,99.7461624145508,99.7461624145508,57.6927826329484,20.6290956285113,25.186911,0,0,0,40,4374,298.8353,99.7461624145508,,,,,,,,,,,,,0,,,,0,,,,,,295.5074158,,,,
,28592804.39,299.0406494,99.7461624145508,5.5381095469235E-7,4.33251906378048E-7,1,0.999253354069792,40.0298881530762,1.98456114295712,14.5600000396371,6.50127906983169E-6,-5.13838160552831E-7,0.25,-1.41661251887847E-7,5.53906996372812E-7,-1.41297602736432E-7,299.0406494,299.0406494,99.7461624145508,99.7461624145508,57.0768593597945,20.6285779168431,24.807261,0,0,0,40,4374,302.3533,99.7461624145508,,,,,,,,,,,,,0,,,,0,,,,,,299.0406494,,,,
,28592945.5,302.5375061,99.7461624145508,7.94157070480514E-7,2.99456249338916E-7,1,0.999253354069792,40.0298881530762,2.00948752737342,14.4999995827675,9.61083952298392E-6,-1.77054461064053E-6,0.25,-2.9324560374668E-7,7.94252345163969E-7,-2.92695188918471E-7,302.5375061,302.5375061,99.7461624145508,99.7461624145508,57.4942489890638,20.620357915061,24.807261,0,0,0,40,4374,305.8829,99.7461624145508,,,,,,,,,,,,,0,,,,0,,,,,,302.5375061,,,,
,28593085.39,306.0373535,99.7461624145508,7.14202989660812E-7,3.49490194739043E-7,1,0.999253354069792,40.0298881530762,2.0091048653039,14.4999995827675,8.2704443412435E-6,5.44715829131936E-7,0.25,-7.58212123299125E-8,7.1407706345262E-7,-7.53454715001825E-8,306.0373535,306.0373535,99.7461624145508,99.7461624145508,57.5466180998522,20.6240610426255,25.186911,0,0,0,40,4374,309.3905,99.7461624145508,,,,,,,,,,,,,0,,,,0,,,,,,306.0373535,,,,
,28593227.235,309.5500183,99.7461624145508,7.79363812306019E-7,3.97972112750435E-7,1,0.999253354069792,40.0298881530762,2.00900553540167,14.4999995827675,9.79078029155007E-6,-3.83533497027437E-6,0.25,-4.72360386264966E-7,7.79374504036786E-7,-4.71693789184759E-7,309.5500183,309.5500183,99.7461624145508,99.7461624145508,57.1995750373137,20.6182126656333,25.566563,0,0,0,40,4374,312.9434,99.7461624145508,,,,,,,,,,,,,0,,,,0,,,,,,309.5500183,,,,
,28593365.615,313.0048828,99.7461624145508,7.03374637009537E-7,4.93254032166107E-7,1,0.999253354069792,40.0298881530762,2.00932342011068,14.4400000572205,7.58787417585726E-6,3.74615109967843E-6,0.25,2.07660804947533E-7,7.02899422967059E-7,2.07997289975139E-7,313.0048828,313.0048828,99.7461624145508,99.7461624145508,57.0401228193907,20.6191278366992,24.807261,0,0,0,40,4374,316.4063,99.7461624145508,,,,,,,,,,,,,0,,,,0.00245,,,,,,313.0048828,,,,
,28593508.5,316.5327148,99.7461624145508,6.60108212104425E-7,3.35244608066086E-7,1,0.999253354069792,40.0298881530762,2.00929178047733,14.4400000572205,7.94616394541214E-6,-1.25362497534897E-6,0.25,-2.24617790179956E-7,6.59839668924224E-7,-2.24073196375113E-7,316.5327148,316.5327148,99.7461624145508,99.7461624145508,57.1128142716791,20.620137401154,25.566563,0,0,0,40,4374,320.0134,99.7461624145508,,,,,,,,,,,,,0,,,,-0.00245,,,,,,316.5327148,,,,
,28593648.745,320.0312805,99.7461624145508,2.67395402691707E-7,3.53093906416318E-7,1,0.999253354069792,40.0298881530762,2.00917818563572,14.4400000572205,3.76025856146222E-6,-3.63711683065541E-6,0.25,-3.66322753130674E-7,2.67420269185449E-7,-3.65889406607713E-7,320.0312805,320.0312805,99.7461624145508,99.7461624145508,57.2089545795445,20.6204573401338,25.566563,0,0,0,40,4374,323.52615,99.7461624145508,,,,,,,,,,,,,0,,,,-0.00245,,,,,,320.0312805,,,,
,28593771.08,323.0396729,99.7461624145508,7.1274573714612E-7,3.87326743992995E-7,1,0.999253354069792,40.0298881530762,1.97131881849149,14.3900001421571,9.50561990894281E-6,-7.58005295213151E-6,0.25,-8.02666440503418E-7,7.12625942489627E-7,-8.01559707952579E-7,323.0396729,323.0396729,99.7461624145508,99.7461624145508,56.8439340610637,20.6166910479886,24.807261,0,0,0,40,4374,326.5844,99.7461624145508,,,,,,,,,,,,,0,,,,-0.0049,,,,,,323.0396729,,,,
,28593911.17,326.5575867,99.7461624145508,1.45641484014872E-7,3.65085971054754E-7,1,0.999253354069792,40.0298881530762,1.97149020895508,14.3900001421571,3.42522826507791E-6,-1.01114715179539E-5,0.25,-9.31311493357821E-7,1.46053588836508E-7,-9.30323404628942E-7,326.5575867,326.5575867,99.7461624145508,99.7461624145508,57.1612752398714,20.6145229082301,25.186911,0,0,0,40,4374,330.0984,99.7461624145508,,,,,,,,,,,,,0,,,,0.0049,,,,,,326.5575867,,,,
,28594052.73,330.0716858,99.7461624145508,1.93858025170402E-7,4.80366815564544E-7,1,0.999253354069792,40.0298881530762,1.97165163172542,14.3900001421571,4.39412418481745E-6,-1.25069827836452E-5,0.25,-1.15437042392792E-6,1.94324083588201E-7,-1.15299784164142E-6,330.0716858,330.0716858,99.7461624145508,99.7461624145508,57.1237570709483,20.6145367714253,25.566563,0,0,0,40,4374,333.6407,99.7461624145508,,,,,,,,,,,,,0,,,,-0.0049,,,,,,330.0716858,,,,
,28594171.195,333.0089417,99.7461624145508,2.31099781594426E-7,3.88305321478645E-7,1,0.999253354069792,40.0298881530762,1.99725134579798,14.3299996852875,2.51514205480579E-6,1.00304256998091E-6,0.25,4.87735730850062E-8,2.30795886363288E-7,4.88497276239131E-8,333.0089417,333.0089417,99.7461624145508,99.7461624145508,57.0971817012945,20.6104261004356,25.566563,0,0,0,40,4374,336.6082,99.7461624145508,,,,,,,,,,,,,0,,,,-0.0049,,,,,,333.0089417,,,,
,28594313.805,336.5423584,99.7461624145508,8.30067465520488E-7,3.95809898624682E-7,1,0.999253354069792,40.0298881530762,1.99716765871294,14.3299996852875,9.77626290037959E-6,-6.93010504607953E-7,0.25,-2.05100910319718E-7,8.29094338101077E-7,-2.04354424469564E-7,336.5423584,336.5423584,99.7461624145508,99.7461624145508,56.9627415959868,20.6146704791702,25.566563,0,0,0,40,4374,340.1905,99.7461624145508,,,,,,,,,,,,,0,,,,-0.0049,,,,,,336.5423584,,,,
,28594454.29,340.0596313,99.7461624145508,3.86592437977376E-7,3.64632255857381E-7,1,0.999253354069792,40.0298881530762,1.99715449644228,14.3299996852875,4.44496962508598E-6,2.98680967694727E-7,0.25,-4.04950910143174E-8,3.86060657101744E-7,-4.02172670072734E-8,340.0596313,340.0596313,99.7461624145508,99.7461624145508,57.3027500018522,20.6168331581074,25.946213,0,0,0,40,4374,343.70475,99.7461624145508,,,,,,,,,,,,,0,,,,0,,,,,,340.0596313,,,,
,28594592.625,343.5065918,99.7461624145508,8.41798945316391E-7,4.36980761691257E-7,1,0.999253354069792,40.0298881530762,1.99706209204222,14.2700001597404,1.04567534962524E-5,-3.85129293852337E-6,0.25,-4.86852472921374E-7,8.40765638101576E-7,-4.85623038328431E-7,343.5065918,343.5065918,99.7461624145508,99.7461624145508,57.0432493334676,20.61053332907,25.566563,0,0,0,40,4374,347.17295,99.7461624145508,,,,,,,,,,,,,0,,,,-0.00245,,,,,,343.5065918,,,,
,28594735.085,347.0247192,99.7461624145508,-5.86717047989652E-8,4.00232462516086E-7,1,0.999253354069792,40.0298881530762,1.99702903063371,14.2700001597404,9.55883224837296E-8,-4.49220725507931E-6,0.25,-3.8774607293065E-7,-5.83577657340506E-8,-3.87130351080658E-7,347.0247192,347.0247192,99.7461624145508,99.7461624145508,57.2878990599868,20.613966815831,25.566563,0,0,0,40,4374,350.7585,99.7461624145508,,,,,,,,,,,,,0,,,,0.0049,,,,,,347.0247192,,,,
,28595123.6,349.7890625,99.7461624145508,3.01306632713761E-7,3.9410973377579E-7,1,0.999253354069792,40.0298881530762,1.99692560778111,14.2700001597404,3.98136885319986E-6,-2.76198456608613E-6,0.25,-2.96854201218402E-7,3.00939818031587E-7,-2.96162318423292E-7,349.7890625,349.7890625,99.7461624145508,99.7461624145508,57.2300585495638,20.6147340306716,25.946213,0,0,0,40,4369,350.74845,99.7461624145508,,,,,,,,,,,,,0,,,,-0.0049,,,,,,349.7890625,,,,