File: data/monolayers/nanoparticles/Ol_CoFe_C/vsm/data_disorderedWafer/DD227_HYST_100K.DAT
[Header]
; VSM Data File (default extension .dat)
; Copyright (c) 2003-2013, Quantum Design, Inc. All rights reserved.
TITLE,
FILEOPENTIME,28501271.64,11/27/2018,5:01 am
BYAPP,VSM,2.0,2.0
INFO,PPMS VSM Option Release 1.4.10 Build 1,APPNAME
INFO,Quantum Design Linear Motor Servo Controller,MOTOR_MODULE_NAME
INFO,3101-100 M1,MOTOR_HW_VERSION
INFO,MMC1014,MOTOR_SERIAL_NUMBER
INFO,SRV No X-over 01.03.11,MOTOR_SOFTWARE_VERSION
INFO,Quantum Design VSM Detection Module,VSM_MODULE_NAME
INFO,3101-150 F0,VSM_HW_VERSION
INFO,VSM707,VSM_SERIAL_NUMBER
INFO,VSM No X-over 01.02.05 May 20 2008 13:51:47,VSM_SOFTWARE_VERSION
INFO,704,PREAMP_SERIAL_NUMBER
INFO,822,COIL_SERIAL_NUMBER
INFO,0,MOMENT_UNITS
INFO,CoFe2O4 FeO,SAMPLE_MATERIAL
INFO,disordered monolayer,SAMPLE_COMMENT
INFO,25.46,SAMPLE_MASS
INFO,,SAMPLE_VOLUME
INFO,,SAMPLE_MOLECULAR_WEIGHT
INFO,,SAMPLE_SIZE
INFO,,SAMPLE_SHAPE
DATATYPE,COMMENT,1
DATATYPE,TIME,2
STARTUPAXIS,X,2
STARTUPAXIS,Y1,5
[Data]
Comment,Time Stamp (sec),Temperature (K),Magnetic Field (Oe),Moment (emu),M. Std. Err. (emu),Transport Action,Averaging Time (sec),Frequency (Hz),Peak Amplitude (mm),Center Position (mm),Coil Signal' (mV),Coil Signal" (mV),Range (mV),M. Quad. Signal (emu),M. Raw' (emu),M. Raw" (emu),Min. Temperature (K),Max. Temperature (K),Min. Field (Oe),Max. Field (Oe),Mass (grams),Motor Lag (deg),Pressure (Torr),VSM Status (code),Motor Status (code),Measure Status (code),Measure Count,PPMS Status (code),System Temp. (K),System Field (Oe),Sample Position (deg),Bridge 1 Resistance (ohms),Bridge 1 Excitation (에),Bridge 2 Resistance (ohms),Bridge 2 Excitation (에),Bridge 3 Resistance (ohms),Bridge 3 Excitation (에),Bridge 4 Resistance (ohms),Bridge 4 Excitation (에),Signal 1 Vin (V),Signal 2 Vin (V),Digital Inputs (code),Drive 1 Iout (mA),Drive 1 Ipower (W),Drive 2 Iout (mA),Drive 2 Ipower (W),Pressure (),Map 20 (),Map 21 (),Map 22 (),Map 23 (),Map 24 (),Map 25 (),Map 26 (),Map 27 (),Map 28 (),Map 29 ()
,28501285.63,100.1980743,-0.19790905714035,,,2,,,,15.5400002625585,,,,,,,100.1980743,100.1980743,-0.19790905714035,-0.19790905714035,,,19.112494,,,,-99999999,4369,100.0461,-0.19790905714035,,,,,,,,,,,,,,,,,,,,,,,100.1980743,,,,
,28501421.945,100.1016693,4051.94958496094,-6.39218033553895E-6,5.81701607340102E-7,1,0.999253354069792,40.0298881530762,1.9979717159825,15.5300004407763,-7.18372557732417E-5,-1.76506991027893E-5,0.25,-4.28594947920411E-7,-6.42680659521033E-6,-4.50856926476742E-7,100.1016693,100.1016693,4036.873046875,4067.02612304687,56.6704125297944,20.6046676794811,18.732843,0,0,0,40,4449,99.9187,4051.94958496094,,,,,,,,,,,,,0,,,,0,,,,,,100.1016693,,,,
,28501526.085,100.0424576,9254.740234375,-2.00844493023464E-5,7.9138338882033E-7,1,0.999253354069792,40.0298881530762,1.99791622553352,15.5300004407763,-0.000226829209934318,-4.90959330489804E-5,0.25,-7.87495679974204E-7,-2.01951512209573E-5,-8.54015409910931E-7,100.0424576,100.0424576,9242.3095703125,9267.1708984375,56.7454488676406,20.6091192049338,19.492144,0,0,0,40,4449,99.89655,9254.740234375,,,,,,,,,,,,,0,,,,-0.0049,,,,,,100.0424576,,,,
,28501632.31,100.0160141,14566.9194335938,-3.43124741260794E-5,9.95733350752175E-7,1,0.999253354069792,40.0298881530762,1.99765062515218,15.5300004407763,-0.000387543974408326,-8.34545727596923E-5,0.25,-1.3097729324468E-6,-3.45020240222178E-5,-1.42262555729622E-6,100.0160141,100.0160141,14554.1064453125,14579.732421875,56.9181887703906,20.6140004155969,19.492144,0,0,0,40,4449,99.8919,14566.9194335938,,,,,,,,,,,,,0,,,,0.00245,,,,,,100.0160141,,,,
,28501740.015,100.0044556,19949.4609375,-5.01481113822835E-5,1.67985336982522E-6,1,0.999253354069792,40.0298881530762,1.99789069222455,15.5300004407763,-0.00057089409697422,-9.68103498299397E-5,0.25,2.98483532679645E-7,-5.04323837568715E-5,1.46996646783427E-7,100.0044556,100.0044556,19936.8828125,19962.0390625,56.9689946241406,20.6154267130263,19.112494,0,0,0,40,4449,99.89215,19949.4609375,,,,,,,,,,,,,0,,,,0,,,,,,100.0044556,,,,
,28501845.27,100.0005493,25209.076171875,-6.51852533506797E-5,1.5194377573298E-6,1,0.999253354069792,40.0298881530762,1.99762921448439,15.5300004407763,-0.000740571843117602,-0.000133914277736393,0.25,-3.24707077173734E-7,-6.55531751040671E-5,-5.24368557437786E-7,100.0005493,100.0005493,25203.88671875,25214.265625,57.0455942190253,20.615349247122,19.492144,0,0,0,40,4449,99.8936,25209.076171875,,,,,,,,,,,,,0,,,,0.00245,,,,,,100.0005493,,,,
,28501950.57,100.002594,30471.5244140625,-8.16656649339595E-5,1.50885513420097E-6,1,0.999253354069792,40.0298881530762,1.99773317693715,15.5300004407763,-0.000927601140685532,-0.000169258195040597,0.25,-5.38341272354746E-7,-8.21269423918767E-5,-7.87596214551492E-7,100.002594,100.002594,30461.640625,30481.408203125,56.8908317722176,20.6160120277508,19.112494,0,0,0,40,4449,99.8911,30471.5244140625,,,,,,,,,,,,,0,,,,0.0049,,,,,,100.002594,,,,
,28502050.77,100.0033035,35479.046875,-9.58932647857126E-5,2.75646157170265E-6,1,0.999253354069792,40.0298881530762,1.99782354687824,15.5300004407763,-0.00109062985570282,-0.000190968778719855,0.25,5.07867091544105E-8,-9.64377857641633E-5,-2.36155531632683E-7,100.0033035,100.0033035,35468.9765625,35489.1171875,56.9783741663714,20.6184541844166,19.112494,0,0,0,40,4449,99.8885,35479.046875,,,,,,,,,,,,,0,,,,-0.00245,,,,,,100.0033035,,,,
,28502145.97,100.0058212,40236.412109375,-0.000109606841033028,1.89574037440814E-6,1,0.999253354069792,40.0298881530762,1.997848941608,15.5300004407763,-0.00125106462579863,-0.000193002075865283,0.25,2.27902384556357E-6,-0.000110236731985218,1.96571252995009E-6,100.0058212,100.0058212,40231.80859375,40241.015625,56.8400259184676,20.622059427565,19.112494,0,0,0,40,4449,99.8826,40236.412109375,,,,,,,,,,,,,0,,,,-0.00245,,,,,,100.0058212,,,,
,28502238.615,100.0059204,44866.994140625,-0.000125689109416111,2.15558424272377E-6,1,0.999253354069792,40.0298881530762,1.99774101259704,15.5300004407763,-0.00143517847359958,-0.000217824766514903,0.25,2.91766148915085E-6,-0.000126413283023436,2.56245062737465E-6,100.0059204,100.0059204,44854.71484375,44879.2734375,57.3191642007561,20.6169977837974,19.871798,0,0,0,40,4449,99.8792,44866.994140625,,,,,,,,,,,,,0,,,,-0.00245,,,,,,100.0059204,,,,
,28502336.71,100.0073624,49772.09375,-0.000141436187447128,1.27541960453085E-6,1,0.999253354069792,40.0298881530762,1.9976000185715,15.5300004407763,-0.00161015245688566,-0.000272082102373714,0.25,9.07711779006709E-7,-0.000142245235515391,4.97248709269353E-7,100.0073624,100.0073624,49762.30859375,49781.87890625,56.9799374234099,20.6174250836328,19.492144,0,0,0,40,4449,99.8723,49772.09375,,,,,,,,,,,,,0,,,,-0.00245,,,,,,100.0073624,,,,
,28502427.5,100.0073624,54309.736328125,-0.000156761068127516,1.66665150336697E-6,1,0.999253354069792,40.0298881530762,1.99758741278751,15.5300004407763,-0.00178511829398118,-0.000298716167818431,0.25,1.25356720401044E-6,-0.000157659714676363,8.02925330930655E-7,100.0072556,100.0074692,54294.46875,54325.00390625,56.9815006804483,20.6183575124724,19.492144,0,0,0,40,4449,99.86825,54309.736328125,,,,,,,,,,,,,0,,,,0.0049,,,,,,100.0073624,,,,
,28502523.36,100.0068207,59099.703125,-0.000170163362748912,1.64933460407803E-6,1,0.999253354069792,40.0298881530762,1.99762195245517,15.5300004407763,-0.00193956346548313,-0.000314128972307188,0.25,2.24860754292673E-6,-0.00017114278765861,1.76780985640061E-6,100.0068207,100.0068207,59092.171875,59107.234375,56.9517987967176,20.6159317284402,19.112494,0,0,0,40,4449,99.8607,59099.703125,,,,,,,,,,,,,0,,,,-0.00245,,,,,,100.0068207,,,,
,28502599.605,100.006485,62910.79296875,-0.000181352136163038,2.13733746720586E-6,1,0.999253354069792,40.0298881530762,1.99746141195643,15.5300004407763,-0.00206318560723242,-0.000356207594864053,0.25,5.07531651110187E-7,-0.000182391667181746,-1.2853564867713E-8,100.006485,100.006485,62895.76171875,62925.82421875,57.119067299833,20.6161990825635,19.492144,0,0,0,40,4449,99.858,62910.79296875,,,,,,,,,,,,,0,,,,-0.00245,,,,,,100.006485,,,,
,28502690.175,100.0062714,67438.63671875,-0.000195642461876271,2.48808735178669E-6,1,0.999253354069792,40.0298881530762,1.99742923404997,15.5300004407763,-0.0022285726103589,-0.000368161864944007,0.25,1.96080824054367E-6,-0.000196769466931833,1.41114025639556E-6,100.0062714,100.0062714,67428.7109375,67448.5625,57.3910740245253,20.6166687107031,19.112494,0,0,0,40,4449,99.85395,67438.63671875,,,,,,,,,,,,,0,,,,0,,,,,,100.0062714,,,,
,28502769.89,100.0076447,71424.24609375,-0.000204766342101676,2.15049912817346E-6,1,0.999253354069792,40.0298881530762,1.99764206353487,15.5300004407763,-0.00232640211041932,-0.00042157450222946,0.25,-1.13434342220782E-6,-0.000205938157002739,-1.72461673928399E-6,100.0076447,100.0076447,71421.78125,71426.7109375,57.1628384969099,20.6151247656564,19.112494,0,0,0,40,4449,99.8465,71424.24609375,,,,,,,,,,,,,0,,,,0,,,,,,100.0076447,,,,
,28502843.46,100.0041504,75099.90234375,-0.000219193404002379,2.02728872349104E-6,1,0.999253354069792,40.0298881530762,1.99759454232523,15.5300004407763,-0.00249034313126242,-0.000450857248868075,0.25,-1.18128405676947E-6,-0.000220449273032102,-1.80966622576681E-6,100.0041504,100.0041504,75084.890625,75114.9140625,57.3621537693137,20.6149488877769,19.492144,0,0,0,40,4449,99.84335,75099.90234375,,,,,,,,,,,,,0,,,,-0.00735,,,,,,100.0041504,,,,
,28502921.21,100.0052795,78983.49609375,-0.000231735126599544,1.75057075087333E-6,1,0.999253354069792,40.0298881530762,1.99752722734018,15.5300004407763,-0.00263729807781139,-0.000450818776696289,0.25,1.01827315866775E-6,-0.000233070767031145,3.7062931496903E-7,100.0052795,100.0052795,78973.5625,78993.4296875,57.1323549846599,20.616060631838,19.112494,0,0,0,40,4449,99.838,78983.49609375,,,,,,,,,,,,,0,,,,0.00245,,,,,,100.0052795,,,,
,28502995.145,100.0060883,82682.2109375,-0.000245114831534547,1.69801977094792E-6,1,0.999253354069792,40.0298881530762,1.99763184758837,15.5300004407763,-0.00279229946475283,-0.000462195962352445,0.25,2.36407092606176E-6,-0.000246532690580988,1.69015372473503E-6,100.0060883,100.0060883,82672.0859375,82692.3359375,57.0666981890445,20.6116458973712,19.112494,0,0,0,40,4449,99.83445,82682.2109375,,,,,,,,,,,,,0,,,,-0.0049,,,,,,100.0060883,,,,
,28503074.215,100.0054474,86633.578125,-0.000257075910651237,2.63449269470646E-6,1,0.999253354069792,40.0298881530762,1.99756584365076,15.5300004407763,-0.00292118229492977,-0.000526358066973689,0.25,-1.18447505267734E-6,-0.000258554386131884,-1.90823600138995E-6,100.0054474,100.0054474,86625.984375,86641.171875,57.0377779338329,20.6163344048311,19.112494,0,0,0,40,4449,99.8307,86633.578125,,,,,,,,,,,,,0,,,,0,,,,,,100.0054474,,,,
,28503183.96,100.0045013,89010.16796875,-0.000267981638444532,1.97914452022251E-6,1,0.999253354069792,40.0298881530762,1.99750442688868,15.5300004407763,-0.00305219265848979,-0.00050783066062263,0.25,2.35420355757026E-6,-0.000269533871752108,1.62302615653099E-6,100.0045013,100.0045013,89002.7265625,89017.609375,56.7540467813522,20.6158079863714,19.492144,0,0,0,40,4449,99.82815,89010.16796875,,,,,,,,,,,,,0,,,,-0.00245,,,,,,100.0045013,,,,
,28503276.76,99.9992676,84371.8984375,-0.000253654171849255,2.74390963667064E-6,1,0.999253354069792,40.0298881530762,1.99736599684298,15.5300004407763,-0.00289359890628654,-0.000453273530677345,0.25,4.64020131606147E-6,-0.000255128279391803,3.95715822545155E-6,99.9992676,99.9992676,84359.421875,84384.375,57.0815491309099,20.617100881528,19.112494,0,0,0,40,4449,99.82915,84371.8984375,,,,,,,,,,,,,0,,,,0,,,,,,99.9992676,,,,
,28503374.52,99.9985809,79485.36328125,-0.000233903591202485,1.62828362878832E-6,1,0.999253354069792,40.0298881530762,1.99747699078425,15.5300004407763,-0.0026620375723467,-0.000454327745272208,0.25,1.08887654450185E-6,-0.000235252095900895,4.35922364404534E-7,99.9985809,99.9985809,79475.6484375,79495.078125,56.9353845978137,20.6167945285988,19.871798,0,0,0,40,4449,99.82965,79485.36328125,,,,,,,,,,,,,0,,,,-0.0049,,,,,,99.9985809,,,,
,28503465.375,99.9991226,74942.05859375,-0.000222768209795468,1.77935489305827E-6,1,0.999253354069792,40.0298881530762,1.99749046262702,15.5300004407763,-0.00252957480364477,-0.000465346562824081,0.25,-1.82987268842549E-6,-0.00022404269232116,-2.47237201507005E-6,99.9991226,99.9991226,74932.1171875,74952,57.3035316303714,20.6166272317365,19.871798,0,0,0,40,4449,99.8325,74942.05859375,,,,,,,,,,,,,0,,,,0,,,,,,99.9991226,,,,
,28503557.985,99.9946442,70316.23046875,-0.00020638565923025,1.90886921459707E-6,1,0.999253354069792,40.0298881530762,1.99756013246554,15.5300004407763,-0.0023450405059853,-0.000422970547027878,0.25,-9.73395583638344E-7,-0.000207566840059363,-1.56840974252698E-6,99.9946442,99.9946442,70313.7578125,70318.703125,57.0721695886791,20.6182683195776,19.492144,0,0,0,40,4449,99.8354,70316.23046875,,,,,,,,,,,,,0,,,,0,,,,,,99.9946442,,,,
,28503656.17,99.9962692,65405.87890625,-0.000188495512588971,1.79610442753653E-6,1,0.999253354069792,40.0298881530762,1.99749327898392,15.5300004407763,-0.00214609663237147,-0.000361120398030573,0.25,1.3282319786401E-6,-0.000189579073321487,7.93710736433587E-7,99.9962692,99.9962692,65395.58203125,65416.17578125,57.3762230826599,20.6175120071361,19.112494,0,0,0,40,4449,99.83895,65405.87890625,,,,,,,,,,,,,0,,,,-0.00245,,,,,,99.9962692,,,,
,28503756.93,99.9942093,60369.759765625,-0.000173062405753037,1.71755346075902E-6,1,0.999253354069792,40.0298881530762,1.99750279943532,15.5300004407763,-0.00196944926451744,-0.000336837781016519,0.25,7.58204955829823E-7,-0.000174054452686845,2.612534896281E-7,99.9942093,99.9942093,60362.5234375,60376.99609375,57.4082698519484,20.6192962350593,19.871798,0,0,0,40,4449,99.845,60369.759765625,,,,,,,,,,,,,0,,,,-0.0049,,,,,,99.9942093,,,,
,28503856.6,99.9953537,55387.61328125,-0.000156741478931893,1.48861746085892E-6,1,0.999253354069792,40.0298881530762,1.99752870187122,15.5300004407763,-0.00178152262984832,-0.000317612901698761,0.25,-4.12906955856029E-7,-0.000157635420523859,-8.72460718248575E-7,99.9953537,99.9953537,55375.5,55399.7265625,57.0573186468137,20.6185618458168,19.112494,0,0,0,40,4449,99.84875,55387.61328125,,,,,,,,,,,,,0,,,,0,,,,,,99.9953537,,,,
,28503955.345,99.9952087,50455.115234375,-0.000141788425749363,1.78902615226182E-6,1,0.999253354069792,40.0298881530762,1.99760078764082,15.5300004407763,-0.00161334668664271,-0.000277418233025956,0.25,5.00097356090061E-7,-0.000142598423012644,8.6517023203465E-8,99.9952087,99.9952087,50447.55078125,50462.6796875,57.0526288756983,20.6193091398853,19.492144,0,0,0,40,4449,99.85005,50455.115234375,,,,,,,,,,,,,0,,,,0,,,,,,99.9952087,,,,
,28504055.625,99.9929657,45440.3984375,-0.000125277439413492,1.83583932140898E-6,1,0.999253354069792,40.0298881530762,1.99761431529594,15.5300004407763,-0.00142229363352802,-0.000263217509160933,0.25,-1.14776514532631E-6,-0.000125987353306508,-1.52473017784123E-6,99.9929657,99.9929657,45425.34375,45455.453125,57.210517836583,20.6180489316582,19.492144,0,0,0,40,4449,99.86025,45440.3984375,,,,,,,,,,,,,0,,,,0,,,,,,99.9929657,,,,
,28504152.215,99.9920044,40612.767578125,-0.000112517630585096,1.68377828152979E-6,1,0.999253354069792,40.0298881530762,1.99755668287821,15.5300004407763,-0.00127961117761268,-0.000223716607832899,0.25,8.66735470892783E-8,-0.000113157607475379,-2.47692395150486E-7,99.9920044,99.9920044,40602.5703125,40622.96484375,57.2292769210445,20.6192773204665,19.492144,0,0,0,40,4449,99.8655,40612.767578125,,,,,,,,,,,,,0,,,,-0.00245,,,,,,99.9920044,,,,
,28504251.93,99.9943695,35629.958984375,-9.64113662940199E-5,1.43262621696261E-6,1,0.999253354069792,40.0298881530762,1.99750890624705,15.5300004407763,-0.001096849364008,-0.000189172320404257,0.25,2.97285952996195E-7,-9.69595719075553E-5,1.01618846166277E-8,99.9943695,99.9943695,35619.765625,35640.15234375,56.9072459711214,20.6211501929037,19.871798,0,0,0,40,4449,99.87075,35629.958984375,,,,,,,,,,,,,0,,,,0.00245,,,,,,99.9943695,,,,
,28504352.695,99.9898834,30592.5849609375,-8.1009442485533E-5,1.45497745502446E-6,1,0.999253354069792,40.0298881530762,1.99761819542161,15.5300004407763,-0.000919645796371953,-0.000170457979744104,0.25,-7.59936319618085E-7,-8.14663505305054E-5,-1.00847610238402E-6,99.9898834,99.9898834,30577.443359375,30607.7265625,57.2542890336599,20.6211506328602,19.492144,0,0,0,40,4449,99.8803,30592.5849609375,,,,,,,,,,,,,0,,,,-0.00245,,,,,,99.9898834,,,,
,28504450.88,99.9920998,25685.005859375,-6.51166990747303E-5,1.01612065654939E-6,1,0.999253354069792,40.0298881530762,1.99757982579973,15.5300004407763,-0.000737352930801937,-0.000147563558714547,0.25,-1.53750542705496E-6,-6.54806104957754E-5,-1.74372442345089E-6,99.9920197,99.9921799,25670.111328125,25699.900390625,57.1300100991022,20.6220122943076,19.492144,0,0,0,40,4449,99.88835,25685.005859375,,,,,,,,,,,,,0,,,,0,,,,,,99.9920998,,,,
,28504551.26,99.9905243,20667.9658203125,-4.99741932250706E-5,9.61593164714886E-7,1,0.999253354069792,40.0298881530762,1.99757802962975,15.5300004407763,-0.000567628969441333,-0.000103296346685003,0.25,-3.03891657400734E-7,-5.02557213228341E-5,-4.58111571707804E-7,99.9905243,99.9905243,20658.171875,20677.759765625,57.1245386994676,20.6201666705568,19.871798,0,0,0,40,4449,99.8954,20667.9658203125,,,,,,,,,,,,,0,,,,-0.00245,,,,,,99.9905243,,,,
,28504651.76,99.9910507,15645.7001953125,-3.56380519694607E-5,9.2810010886286E-7,1,0.999253354069792,40.0298881530762,1.99757076756922,15.5300004407763,-0.000403000266869931,-8.38371266839413E-5,0.25,-1.11089672521131E-6,-3.5835786125949E-5,-1.22654739229708E-6,99.9910507,99.9910507,15635.8955078125,15655.5048828125,56.8775440873906,20.6221082395548,19.871798,0,0,0,40,4449,99.904,15645.7001953125,,,,,,,,,,,,,0,,,,-0.0049,,,,,,99.9910507,,,,
,28504750.935,99.9915771,10690.6684570312,-2.08476476772382E-5,7.71669542713569E-7,1,0.999253354069792,40.0298881530762,1.99752211854995,15.5300004407763,-0.000237763768730534,-3.75308802378441E-5,0.25,3.62874428866839E-7,-2.09662756497373E-5,3.00588238089443E-7,99.9915771,99.9915771,10677.8251953125,10703.51171875,57.6357237510446,20.622700947863,19.492144,0,0,0,40,4449,99.90925,10690.6684570312,,,,,,,,,,,,,0,,,,0,,,,,,99.9915771,,,,
,28504850.83,99.9917068,5698.166015625,-7.99332829105829E-6,4.65949138266352E-7,1,0.999253354069792,40.0298881530762,1.99758342264825,15.5300004407763,-9.02912015994219E-5,-1.93596159681238E-5,0.25,-2.97794511067298E-7,-8.03740429931627E-6,-3.2425722580794E-7,99.9917068,99.9917068,5685.49365234375,5710.83837890625,57.2793011462753,20.620888440901,19.492144,0,0,0,40,4449,99.9186,5698.166015625,,,,,,,,,,,,,0,,,,0,,,,,,99.9917068,,,,
,28504947.805,99.9936752,849.773345947266,4.49311469570549E-6,3.32569855187084E-7,1,0.999253354069792,40.0298881530762,1.99766574739014,15.5300004407763,5.16355065811888E-5,5.87363760742972E-6,0.25,-2.73176002763496E-7,4.51923424952882E-6,-2.60724944201455E-7,99.9936752,99.9936752,837.275451660156,862.271240234375,57.4004535667561,20.6208529544207,19.871798,0,0,0,40,4449,99.92415,849.773345947266,,,,,,,,,,,,,0,,,,-0.00245,,,,,,99.9936752,,,,
,28505048.1,99.997818,-4158.66064453125,1.42076741262238E-5,4.91324922813392E-7,1,0.999253354069792,40.0298881530762,1.9975888292018,15.5300004407763,0.000161275522601164,2.99265031531775E-5,0.25,1.34883474828688E-7,1.42872104736391E-5,1.79757207349457E-7,99.997818,99.997818,-4171.26806640625,-4146.05322265625,57.2793011462753,20.6215917982056,19.492144,0,0,0,40,4449,99.9232,-4158.66064453125,,,,,,,,,,,,,0,,,,-0.00245,,,,,,99.997818,,,,
,28505147.425,100.0021057,-9125.5419921875,2.51831065048993E-5,5.27810838593309E-7,1,0.999253354069792,40.0298881530762,1.99748339104306,15.5300004407763,0.000286799611833382,4.76301258750958E-5,0.25,-2.36571627647116E-7,2.53257266321595E-5,-1.60083986042737E-7,100.0021057,100.0021057,-9140.6318359375,-9110.4521484375,57.4481329064291,20.6236615446411,19.871798,0,0,0,40,4449,99.9217,-9125.5419921875,,,,,,,,,,,,,0,,,,0,,,,,,100.0021057,,,,
,28505249.27,100.0063019,-14218.3276367188,3.64452829235019E-5,6.73623457347569E-7,1,0.999253354069792,40.0298881530762,1.99751624377753,15.5300004407763,0.000415006916972993,6.92871548632453E-5,0.25,-3.10566839622915E-7,3.66518550227369E-5,-2.00304968115657E-7,100.0063019,100.0063019,-14233.34375,-14203.3115234375,57.2777378892368,20.6205832651027,19.492144,0,0,0,40,4449,99.91695,-14218.3276367188,,,,,,,,,,,,,0,,,,0,,,,,,100.0063019,,,,
,28505348.695,100.0085106,-19182.376953125,4.82079225212003E-5,1.26044323838944E-6,1,0.999253354069792,40.0298881530762,1.99742590022233,15.5300004407763,0.00054801330285467,9.6862976763612E-5,0.25,4.88533074663423E-8,4.84801245176906E-5,1.96470486115179E-7,100.008461,100.0085602,-19194.849609375,-19169.904296875,57.2574155477368,20.6234929962461,19.112494,0,0,0,40,4449,99.9081,-19182.376953125,,,,,,,,,,,,,0,,,,0,,,,,,100.0085106,,,,
,28505448.305,100.010231,-24162.2412109375,6.14277313273213E-5,1.31797579614966E-6,1,0.999253354069792,40.0298881530762,1.99738728097447,15.5300004407763,0.000699757046518842,0.000115044053298387,0.25,-6.73694490366203E-7,6.17773061938615E-5,-4.9085794423578E-7,100.010231,100.010231,-24172.21875,-24152.263671875,57.180034324333,20.6230056198694,19.871798,0,0,0,40,4449,99.8982,-24162.2412109375,,,,,,,,,,,,,0,,,,0.00245,,,,,,100.010231,,,,
,28505547.605,100.0107956,-29124.3466796875,7.61166928399905E-5,9.11169349055618E-7,1,0.999253354069792,40.0298881530762,1.99764212796355,15.5300004407763,0.00086570507310727,0.000151079470858538,0.25,-8.52868730659648E-8,7.65482034652119E-5,1.44113295108528E-7,100.0107956,100.0107956,-29129.380859375,-29119.3125,57.1956668947176,20.6228193981479,19.492144,0,0,0,40,4449,99.8879,-29124.3466796875,,,,,,,,,,,,,0,,,,0,,,,,,100.0107956,,,,
,28505651.015,100.012764,-34293.970703125,9.14638157027168E-5,1.52753391688169E-6,1,0.999253354069792,40.0298881530762,1.99774638531985,15.5300004407763,0.00104392767277027,0.000160981783455493,0.25,-1.90954475430946E-6,9.19885369061718E-5,-1.64593069759275E-6,100.012764,100.012764,-34306.27734375,-34281.6640625,57.6325972369676,20.6224265598709,19.112494,0,0,0,40,4449,99.8757,-34293.970703125,,,,,,,,,,,,,0,,,,0,,,,,,100.012764,,,,
,28505753.68,100.0123749,-39423.376953125,0.000107537319618974,1.22855270812376E-6,1,0.999253354069792,40.0298881530762,1.99770512949162,15.5300004407763,0.00122202337507774,0.000219708883055657,0.25,4.33705966233923E-7,0.000108147157110912,7.56728073527664E-7,100.0123749,100.0123749,-39433.33984375,-39413.4140625,57.4121779945445,20.6228060876443,20.251448,0,0,0,40,4449,99.86385,-39423.376953125,,,,,,,,,,,,,0,,,,-0.00245,,,,,,100.0123749,,,,
,28505852.97,100.0090408,-44388.205078125,0.000120464920174944,1.67300853328088E-6,1,0.999253354069792,40.0298881530762,1.99768178690691,15.5300004407763,0.00137190759219677,0.000229138489572522,0.25,-1.00516833965624E-6,0.000121153526581784,-6.54145311347798E-7,100.0090408,100.0090408,-44400.80078125,-44375.609375,57.5200427301984,20.6226287917734,19.871798,0,0,0,40,4449,99.8549,-44388.205078125,,,,,,,,,,,,,0,,,,0,,,,,,100.0090408,,,,
,28505955.04,100.00868605,-49488.29296875,0.000137816744053266,1.61111540839276E-6,1,0.999253354069792,40.0298881530762,1.99766968641683,15.5300004407763,0.00156537144093961,0.000285783118685424,0.25,9.31547116305647E-7,0.000138599608938879,1.34217601546558E-6,100.008316,100.0090561,-49498.390625,-49478.1953125,57.4778347901599,20.6257349387923,19.492144,0,0,0,40,4449,99.8488,-49488.29296875,,,,,,,,,,,,,0,,,,0.00245,,,,,,100.00868605,,,,
,28506054.78,100.0112,-54472.46875,0.000155096498130098,1.73682529468443E-6,1,0.999253354069792,40.0298881530762,1.99751506468626,15.5300004407763,0.00175989455868582,0.000330885422079679,0.25,1.86849678366208E-6,0.000155976455749013,2.33222783790658E-6,100.0112,100.0112,-54480.0859375,-54464.8515625,57.3097846585253,20.6271722636489,19.492144,0,0,0,40,4449,99.83735,-54472.46875,,,,,,,,,,,,,0,,,,0,,,,,,100.0112,,,,
,28506154.5,100.0097656,-59457.2109375,0.000171319890238674,1.81361807216249E-6,1,0.999253354069792,40.0298881530762,1.9976338754528,15.5300004407763,0.00194669969554711,0.000350769801590838,0.25,7.70249064068356E-7,0.000172297157819047,1.27166516482443E-6,100.0097656,100.0097656,-59472.35546875,-59442.06640625,57.423902422333,20.624355165828,19.492144,0,0,0,40,4449,99.8292,-59457.2109375,,,,,,,,,,,,,0,,,,-0.00245,,,,,,100.0097656,,,,
,28506257.12,100.0075035,-64584.400390625,0.00018750972747083,1.9466136733483E-6,1,0.999253354069792,40.0298881530762,1.99763751894154,15.5300004407763,0.00213376941912233,0.000366357788246097,0.25,-6.97577007775062E-7,0.000188585451495868,-1.61478477485368E-7,100.0071945,100.0078125,-64594.44921875,-64574.3515625,57.5176978446407,20.6252346359634,20.251448,0,0,0,40,4449,99.8203,-64584.400390625,,,,,,,,,,,,,0,,,,-0.00245,,,,,,100.0075035,,,,
,28506358.54,100.0112305,-69651.61328125,0.000204668521684077,1.71716318804899E-6,1,0.999253354069792,40.0298881530762,1.99753185738669,15.5300004407763,0.00232738386872646,0.000408675863301482,0.25,1.75205235894647E-8,0.000205842191437915,6.02914974432054E-7,100.0112305,100.0112305,-69656.5546875,-69646.671875,57.4590757056984,20.6240645070102,20.251448,0,0,0,40,4449,99.81345,-69651.61328125,,,,,,,,,,,,,0,,,,0,,,,,,100.0112305,,,,
,28506460.285,100.0082626,-74737.96875,0.000219652991644702,1.83182218225932E-6,1,0.999253354069792,40.0298881530762,1.99772958209781,15.5300004407763,0.00250319227161809,0.000409263028666942,0.25,-2.55988243604718E-6,0.000220921812201856,-1.95098955253796E-6,100.0082626,100.0082626,-74748.0625,-74727.875,57.3277621144676,20.6271542217898,19.871798,0,0,0,40,4449,99.80625,-74737.96875,,,,,,,,,,,,,0,,,,-0.00245,,,,,,100.0082626,,,,
,28506563.88,100.00590895,-79914.77734375,0.000233591235189357,1.98029060936517E-6,1,0.999253354069792,40.0298881530762,1.99768828112409,15.5300004407763,0.00265661020867574,0.000465969019998545,0.25,-1.43679357440605E-8,0.000234934932137619,6.43757413918973E-7,100.0057907,100.0060272,-79929.734375,-79899.8203125,57.2316218066022,20.6277535450658,20.251448,0,0,0,40,4449,99.80215,-79914.77734375,,,,,,,,,,,,,0,,,,0,,,,,,100.00590895,,,,
,28506667.3,100.0060577,-85084.44921875,0.000254055399364554,1.49070126703367E-6,1,0.999253354069792,40.0298881530762,1.99761154264701,15.5300004407763,0.00288931277525794,0.00050650906658023,0.25,-3.38174070672959E-8,0.000255519053952977,6.76485167965435E-7,100.0060577,100.0060577,-85102.1875,-85066.7109375,57.3105662870445,20.6297968421595,19.492144,0,0,0,40,4449,99.7977,-85084.44921875,,,,,,,,,,,,,0,,,,0,,,,,,100.0060577,,,,
,28506763.845,100.0049591,-89908.66796875,0.000266765316119863,2.47191814347371E-6,1,0.999253354069792,40.0298881530762,1.99755379132279,15.5300004407763,0.00303396260576439,0.000530910053447984,0.25,-1.1192626111211E-7,0.00026830452542335,6.28242900300582E-7,100.0049591,100.0049591,-89918.625,-89898.7109375,57.5333304150253,20.6295892714819,19.492144,0,0,0,40,4449,99.79115,-89908.66796875,,,,,,,,,,,,,0,,,,0,,,,,,100.0049591,,,,
,28506885.54,100.001442,-85420.6796875,0.000254155607436566,2.09334307186793E-6,1,0.999253354069792,40.0298881530762,1.99763513399328,15.5300004407763,0.00289309168517284,0.000491865392510513,0.25,-1.33927955959287E-6,0.000255623622011124,-6.36486085374501E-7,100.001442,100.001442,-85430.796875,-85410.5625,57.3856026248907,20.6318949158814,19.871798,0,0,0,40,4449,99.7901,-85420.6796875,,,,,,,,,,,,,0,,,,0,,,,,,100.001442,,,,
,28506987.29,99.9990997,-80333.140625,0.00023628707920709,1.47836865525126E-6,1,0.999253354069792,40.0298881530762,1.99759066437929,15.5300004407763,0.00268864727011983,0.000462769915237918,0.25,-7.66522648583942E-7,0.000237648554221543,-1.05419117631763E-7,99.9990997,99.9990997,-80343.5234375,-80322.7578125,57.3996719382368,20.630603193484,20.251448,0,0,0,40,4449,99.79095,-80333.140625,,,,,,,,,,,,,0,,,,-0.0049,,,,,,99.9990997,,,,
,28507089.08,99.9967804,-75248.46484375,0.000221119203314687,1.81918456753995E-6,1,0.999253354069792,40.0298881530762,1.99765893229579,15.5300004407763,0.00252080359991618,0.000406368507968975,0.25,-3.07014588535094E-6,0.000222398095498779,-2.46039760830004E-6,99.9967804,99.9967804,-75260.9609375,-75235.96875,57.4825245612753,20.6249833845702,20.251448,0,0,0,40,4449,99.7969,-75248.46484375,,,,,,,,,,,,,0,,,,0,,,,,,99.9967804,,,,
,28507191.165,99.9964447,-70146.875,0.000202849135724209,2.1145565817753E-6,1,0.999253354069792,40.0298881530762,1.99760832299609,15.5300004407763,0.00230815979813013,0.000397202295618845,0.25,-6.73152490466741E-7,0.000204014526467614,-9.72058754862212E-8,99.9964447,99.9964447,-70159.71875,-70134.03125,57.2871174314676,20.6243880544512,20.251448,0,0,0,40,4449,99.79925,-70146.875,,,,,,,,,,,,,0,,,,-0.00245,,,,,,99.9964447,,,,
,28507292.055,99.9957886,-65102.39453125,0.000187730256439818,1.81303962340408E-6,1,0.999253354069792,40.0298881530762,1.99765524675084,15.5300004407763,0.00213374030263135,0.000381366857672074,0.25,5.8344042684568E-7,0.000188803691966957,1.1272908314537E-6,99.9957886,99.9957886,-65112.33984375,-65092.44921875,57.342613056333,20.6254305083892,19.871798,0,0,0,40,4449,99.7994,-65102.39453125,,,,,,,,,,,,,0,,,,0.00245,,,,,,99.9957886,,,,
,28507391.15,99.99393465,-60149.962890625,0.000169655177799358,1.9467800493156E-6,1,0.999253354069792,40.0298881530762,1.99755504979712,15.5300004407763,0.0019288025046839,0.000341144169471522,0.25,2.17483460082845E-7,0.000170624731973257,7.10568954487455E-7,99.9936066,99.9942627,-60159.9921875,-60139.93359375,57.4426615067945,20.6258125742653,20.251448,0,0,0,40,4449,99.81135,-60149.962890625,,,,,,,,,,,,,0,,,,0.00245,,,,,,99.99393465,,,,
,28507491.86,99.9944458,-55120.041015625,0.000155801930366995,1.48941249660786E-6,1,0.999253354069792,40.0298881530762,1.99755809297821,15.5300004407763,0.00177860547787366,0.000271633362774183,0.25,-3.46638071512402E-6,0.0001567016453576,-3.03127475042411E-6,99.9944458,99.9944458,-55127.42578125,-55112.65625,57.2394380917945,20.6266656848013,19.492144,0,0,0,40,4449,99.8123,-55120.041015625,,,,,,,,,,,,,0,,,,0.00245,,,,,,99.9944458,,,,
,28507590.235,99.9923172,-50200.947265625,0.00013785753047402,1.78769417948223E-6,1,0.999253354069792,40.0298881530762,1.99754379335284,15.5300004407763,0.00156858167673983,0.000269678643665135,0.25,-4.90181847877162E-7,0.000138644941344835,-8.77374285353719E-8,99.9923172,99.9923172,-50210.90234375,-50190.9921875,57.4520410490253,20.6258866039145,19.871798,0,0,0,40,4449,99.81885,-50200.947265625,,,,,,,,,,,,,0,,,,-0.0049,,,,,,99.9923172,,,,
,28507690.75,99.9934616,-45181.552734375,0.000122843300590101,1.41353292097673E-6,1,0.999253354069792,40.0298881530762,1.99754247480114,15.5300004407763,0.00139973165502287,0.000228922937917264,0.25,-1.44025246731569E-6,0.000123546865798546,-1.08488634135636E-6,99.9934616,99.9934616,-45193.9765625,-45169.12890625,57.4395349927176,20.6268635348919,20.251448,0,0,0,40,4449,99.8266,-45181.552734375,,,,,,,,,,,,,0,,,,0.00245,,,,,,99.9934616,,,,
,28507789.135,99.9911728,-40261.490234375,0.00010766471855845,1.68620857988158E-6,1,0.999253354069792,40.0298881530762,1.99760482861299,15.5300004407763,0.00122861014776921,0.000190373302979324,0.25,-2.16736040829496E-6,0.000108283169971808,-1.85895617707987E-6,99.9911728,99.9911728,-40271.52734375,-40251.453125,57.423902422333,20.6271986812736,19.871798,0,0,0,40,4449,99.83645,-40261.490234375,,,,,,,,,,,,,0,,,,-0.00245,,,,,,99.9911728,,,,
,28507887.875,99.9924622,-35326.576171875,9.47942880075623E-5,1.48147259529496E-6,1,0.999253354069792,40.0298881530762,1.99755732081133,15.5300004407763,0.00107778567298686,0.000189933705707513,0.25,5.30915976801644E-8,9.53321578577079E-5,3.37609919237323E-7,99.9924622,99.9924622,-35333.8984375,-35319.25390625,57.3770047111791,20.6262282982387,19.871798,0,0,0,40,4449,99.8425,-35326.576171875,,,,,,,,,,,,,0,,,,0,,,,,,99.9924622,,,,
,28507985.85,99.990715,-30432.0869140625,7.74324611345292E-5,9.15962791175624E-7,1,0.999253354069792,40.0298881530762,1.99771704704497,15.5300004407763,0.000882628519969109,0.000142735077281524,0.25,-1.05048436643572E-6,7.7874476202984E-5,-8.22818356252448E-7,99.990715,99.990715,-30437.21484375,-30426.958984375,56.9072459711214,20.6242190673618,20.251448,0,0,0,40,4449,99.8493,-30432.0869140625,,,,,,,,,,,,,0,,,,-0.00245,,,,,,99.990715,,,,
,28508083.985,99.9897385,-25525.1279296875,6.34439433506012E-5,1.52723947285679E-6,1,0.999253354069792,40.0298881530762,1.99772483760288,15.5300004407763,0.000722973417069231,0.000118095348285962,0.25,-7.61043481238484E-7,6.3805304950916E-5,-5.72777271560823E-7,99.9897385,99.9897385,-25530.341796875,-25519.9140625,57.1182856713137,20.6269771188545,20.251448,0,0,0,40,4449,99.8604,-25525.1279296875,,,,,,,,,,,,,0,,,,0.00245,,,,,,99.9897385,,,,
,28508183.12,99.9922714,-20570.6611328125,4.93758395320085E-5,8.92314552736105E-7,1,0.999253354069792,40.0298881530762,1.99763095285441,15.5300004407763,0.000566286825079283,7.10981432002737E-5,0.25,-2.42292657655915E-6,4.9662269556754E-5,-2.28585390491689E-6,99.9922714,99.9922714,-20583.134765625,-20558.1875,57.3598088837561,20.6255301968922,19.492144,0,0,0,40,4449,99.8681,-20570.6611328125,,,,,,,,,,,,,0,,,,0.0049,,,,,,99.9922714,,,,
,28508278.4,99.9913864,-15808.1083984375,3.52902367336222E-5,8.6536726209889E-7,1,0.999253354069792,40.0298881530762,1.99763399578222,15.5300004407763,0.000403192302151,5.96132438983672E-5,0.25,-9.58606772694907E-7,3.54923432757244E-5,-8.55665994675644E-7,99.9911194,99.9916534,-15820.6728515625,-15795.5439453125,57.4059249663907,20.6248982063648,19.871798,0,0,0,40,4449,99.87335,-15808.1083984375,,,,,,,,,,,,,0,,,,0,,,,,,99.9913864,,,,
,28508377.435,99.989975,-10860.6127929688,2.18550521185122E-5,8.14806041776929E-7,1,0.999253354069792,40.0298881530762,1.99756910124526,15.5300004407763,0.000248802451498771,4.1940524340997E-5,0.25,-1.52187898309198E-7,2.19786987168734E-5,-8.55826996817878E-8,99.989975,99.989975,-10873.072265625,-10848.1533203125,57.4598573342176,20.6231656052893,20.251448,0,0,0,40,4449,99.8796,-10860.6127929688,,,,,,,,,,,,,0,,,,-0.0049,,,,,,99.989975,,,,
,28508477.145,99.99108505,-5874.87939453125,8.92601095256717E-6,4.31327658549341E-7,1,0.999253354069792,40.0298881530762,1.99747757489683,15.5300004407763,0.000102816720704349,1.02649891105361E-5,0.25,-6.65950780494928E-7,8.9783228908465E-6,-6.42012637182554E-7,99.9905167,99.9916534,-5879.6220703125,-5870.13671875,57.0870205305445,20.6216454754314,19.492144,0,0,0,40,4449,99.89155,-5874.87939453125,,,,,,,,,,,,,0,,,,0,,,,,,99.99108505,,,,
,28508576.655,99.9921799,-898.778106689453,-3.83017315758935E-6,3.65859377906655E-7,1,0.999253354069792,40.0298881530762,1.99740550391356,15.5300004407763,-4.30497979235115E-5,-1.0477218006978E-5,0.25,-2.48322737395344E-7,-3.85093829559206E-6,-2.6164790796126E-7,99.9921799,99.9921799,-916.138854980469,-881.417358398438,57.261323690333,20.6221713381068,19.492144,0,0,0,40,4449,99.8979,-898.778106689453,,,,,,,,,,,,,0,,,,0,,,,,,99.9921799,,,,
,28508673.22,99.9954758,3921.74682617188,-1.37062415366037E-5,3.7602838879189E-7,1,0.999253354069792,40.0298881530762,1.99742150639494,15.5300004407763,-0.000155108216872409,-3.15012924263229E-5,0.25,-3.61713383399418E-7,-1.37822400245495E-5,-4.06331816788209E-7,99.9954758,99.9954758,3911.71533203125,3931.7783203125,57.2785195177561,20.6221483958535,19.871798,0,0,0,40,4449,99.90115,3921.74682617188,,,,,,,,,,,,,0,,,,-0.00245,,,,,,99.9954758,,,,
,28508771.035,100.0013123,8810.85400390625,-2.40740079186755E-5,6.27451603333842E-7,1,0.999253354069792,40.0298881530762,1.9973951071258,15.5300004407763,-0.000273302387628285,-5.03916008663076E-5,0.25,-2.01356438111069E-7,-2.42089991070054E-5,-2.76942098842229E-7,100.0013123,100.0013123,8801.07421875,8820.6337890625,57.3105662870445,20.6149599721366,19.871798,0,0,0,40,4449,99.8956,8810.85400390625,,,,,,,,,,,,,0,,,,-0.00245,,,,,,100.0013123,,,,
,28508868.045,100.0042801,13661.5004882812,-3.44402844160849E-5,6.75876073612275E-7,1,0.999253354069792,40.0298881530762,1.99740115103244,15.5300004407763,-0.000390784221141023,-7.3264550948379E-5,0.25,-3.91828446999324E-7,-3.46333359048252E-5,-5.00000669100012E-7,100.0042801,100.0042801,13648.9921875,13674.0087890625,57.4653287338522,20.6180623526041,19.492144,0,0,0,40,4449,99.89285,13661.5004882812,,,,,,,,,,,,,0,,,,-0.0049,,,,,,100.0042801,,,,
,28508966.625,100.0087585,18586.6982421875,-4.61200222266233E-5,9.19178728430469E-7,1,0.999253354069792,40.0298881530762,1.99732590642555,15.5300004407763,-0.000525116869701208,-8.77456099993279E-5,0.25,3.85967611109601E-7,-4.63816842847839E-5,2.47022761807098E-7,100.0087585,100.0087585,18576.673828125,18596.72265625,57.3301070000253,20.62254099528,19.871798,0,0,0,40,4449,99.88125,18586.6982421875,,,,,,,,,,,,,0,,,,0,,,,,,100.0087585,,,,
,28509064.975,100.0089722,23501.3203125,-5.91769779679294E-5,1.58002011263562E-6,1,0.999253354069792,40.0298881530762,1.99733447289839,15.5300004407763,-0.000671666332637456,-0.000124674102202683,0.25,-5.688101650933E-7,-5.95099436478502E-5,-7.52058636537662E-7,100.0089722,100.0089722,23488.85546875,23513.78515625,57.1339182416984,20.6207860567135,19.871798,0,0,0,40,4449,99.87375,23501.3203125,,,,,,,,,,,,,0,,,,0,,,,,,100.0089722,,,,
,28509163.595,100.0111923,28431.857421875,-7.45813969254958E-5,9.88678334644249E-7,1,0.999253354069792,40.0298881530762,1.99723662446559,15.5300004407763,-0.000847812003820674,-0.000149515848271793,0.25,-4.91883194795285E-8,-7.50036704304521E-5,-2.75009492010325E-7,100.0111923,100.0111923,28417.09375,28446.62109375,57.2738297466407,20.620424591745,19.871798,0,0,0,40,4449,99.86265,28431.857421875,,,,,,,,,,,,,0,,,,0,,,,,,100.0111923,,,,
,28509262.67,100.010704,33386.515625,-8.90783080369645E-5,1.53937084857607E-6,1,0.999253354069792,40.0298881530762,1.99732992301539,15.5300004407763,-0.00101608484499657,-0.000159094105339047,0.25,1.65413210613487E-6,-8.95885525812433E-5,1.39580241521112E-6,100.010704,100.010704,33374.08984375,33398.94140625,57.2628869473714,20.6189534998591,19.492144,0,0,0,40,4449,99.8529,33386.515625,,,,,,,,,,,,,0,,,,-0.00245,,,,,,100.010704,,,,
,28509363.74,100.0087204,38433.888671875,-0.000102484027087551,1.09917600057364E-6,1,0.999253354069792,40.0298881530762,1.99736240626582,15.5300004407763,-0.00116663090435723,-0.000196682503085648,0.25,7.01294512172248E-7,-0.000103068317608661,3.99273213465578E-7,100.0087204,100.0087204,38426.51171875,38441.265625,57.4199942797368,20.6179050626895,20.251448,0,0,0,40,4449,99.84315,38433.888671875,,,,,,,,,,,,,0,,,,0,,,,,,100.0087204,,,,
,28509461.565,100.0105438,43324.1953125,-0.00011823388028565,1.28881145957931E-6,1,0.999253354069792,40.0298881530762,1.99729534095788,15.5300004407763,-0.00134801132134208,-0.000214811382906244,0.25,1.87034938894235E-6,-0.000118912085259167,1.53022800357238E-6,100.0105438,100.0105438,43309.2265625,43339.1640625,56.9549253107945,20.6159379192657,20.251448,0,0,0,40,4449,99.83485,43324.1953125,,,,,,,,,,,,,0,,,,-0.00245,,,,,,100.0105438,,,,
,28509562.805,100.0120316,48384.0859375,-0.000134879664187964,1.44246093874046E-6,1,0.999253354069792,40.0298881530762,1.99713860279255,15.5300004407763,-0.00153344613234104,-0.000269212280945214,0.25,4.6183342837499E-9,-0.000135648195406727,-3.92813539960245E-7,100.0120316,100.0120316,48371.6640625,48396.5078125,57.322290714833,20.6162136089408,20.251448,0,0,0,40,4449,99.82285,48384.0859375,,,,,,,,,,,,,0,,,,-0.0049,,,,,,100.0120316,,,,
,28509662.705,100.01063155,53379.2578125,-0.000150854329223897,1.70124549322569E-6,1,0.999253354069792,40.0298881530762,1.99726048465654,15.5300004407763,-0.00171573176228123,-0.000297954470621226,0.25,2.80308430200407E-7,-0.000151715989141586,-1.59606663911549E-7,100.010498,100.0107651,53369.12109375,53389.39453125,57.3965454241599,20.6146881674721,20.251448,0,0,0,40,4449,99.8144,53379.2578125,,,,,,,,,,,,,0,,,,0.00245,,,,,,100.01063155,,,,
,28509762.975,100.0101471,58389.60546875,-0.000165489017792644,1.55382666795297E-6,1,0.999253354069792,40.0298881530762,1.99722596029692,15.5300004407763,-0.00188715962445282,-0.000298396913070747,0.25,2.80733514296216E-6,-0.000166442955301695,2.34237355636271E-6,100.0101471,100.0101471,58387.09765625,58392.11328125,57.5098815594484,20.61644553073,19.871798,0,0,0,40,4449,99.80605,58389.60546875,,,,,,,,,,,,,0,,,,-0.0049,,,,,,100.0101471,,,,
,28509860.68,100.0078964,63275.052734375,-0.000182434000866211,1.55899369191895E-6,1,0.999253354069792,40.0298881530762,1.99726291048599,15.5300004407763,-0.0020712581631592,-0.00038129994937922,0.25,-1.51222816208489E-6,-0.000183473798615409,-2.04751096994189E-6,100.0078964,100.0078964,63265.19921875,63284.90625,56.8877052581406,20.6171264471013,19.871798,0,0,0,40,4449,99.8006,63275.052734375,,,,,,,,,,,,,0,,,,0.0049,,,,,,100.0078964,,,,
,28509963.045,100.0064926,68390.1328125,-0.000196790644281066,1.65861747180435E-6,1,0.999253354069792,40.0298881530762,1.99718818397059,15.5300004407763,-0.00224400912724606,-0.000355381855710038,0.25,3.28245602075995E-6,-0.000197928096956635,2.73726794355632E-6,100.0064926,100.0064926,68387.6796875,68392.5859375,57.1300100991022,20.6168185236029,19.871798,0,0,0,40,4449,99.7901,68390.1328125,,,,,,,,,,,,,0,,,,0,,,,,,100.0064926,,,,
,28510064.32,100.0079269,73452.765625,-0.000214634085535817,1.67625625574707E-6,1,0.999253354069792,40.0298881530762,1.99724125400517,15.5300004407763,-0.00243900885930945,-0.000436346699775876,0.25,-7.09989106199181E-7,-0.000215864231957313,-1.32477130242745E-6,100.0079269,100.0079269,73440.2265625,73465.3046875,57.1604936113522,20.6161160553911,19.492144,0,0,0,40,4449,99.7838,73452.765625,,,,,,,,,,,,,0,,,,0.00245,,,,,,100.0079269,,,,
,28510162.455,100.0069962,78358.19921875,-0.000231497635007585,1.9136132805661E-6,1,0.999253354069792,40.0298881530762,1.99710054523116,15.5300004407763,-0.00263282689560122,-0.000457248969935055,0.25,4.04074958880428E-7,-0.000232829674756771,-2.47642706418533E-7,100.0069962,100.0069962,78343.2265625,78373.171875,56.8751992018329,20.6153801569048,19.871798,0,0,0,40,4449,99.7787,78358.19921875,,,,,,,,,,,,,0,,,,-0.00245,,,,,,100.0069962,,,,
,28510260.315,100.0062561,83251.671875,-0.000243286935454929,2.24948291094424E-6,1,0.999253354069792,40.0298881530762,1.9972634961434,15.5300004407763,-0.00276574342196615,-0.000488562531083175,0.25,-2.82562676500862E-7,-0.000244686814898888,-9.66666862549554E-7,100.0062561,100.0062561,83236.53125,83266.8125,57.1526773261599,20.6120231850089,20.251448,0,0,0,40,4449,99.77385,83251.671875,,,,,,,,,,,,,0,,,,-0.00245,,,,,,100.0062561,,,,
,28510356.01,100.0046844,88034.71875,-0.00026273536060056,2.01684656584837E-6,1,0.999253354069792,40.0298881530762,1.99715225186748,15.5300004407763,-0.00299222815112499,-0.000496097663657449,0.25,2.45985343598767E-6,-0.000264256961167375,1.74217096216162E-6,100.0046844,100.0046844,88029.796875,88039.640625,57.0033862789868,20.6119702643226,19.871798,0,0,0,40,4449,99.7724,88034.71875,,,,,,,,,,,,,0,,,,-0.0049,,,,,,100.0046844,,,,
,28510476.895,100.0014114,87268.58203125,-0.000256861973409159,1.94828234421713E-6,1,0.999253354069792,40.0298881530762,1.99715302224454,15.5300004407763,-0.00291729596210821,-0.000530831061409834,0.25,-1.62450564193063E-6,-0.000258337997176252,-2.35023798613457E-6,100.0014114,100.0014114,87258.625,87278.5390625,57.2277136640061,20.6124661854196,19.492144,0,0,0,40,4449,99.7676,87268.58203125,,,,,,,,,,,,,0,,,,-0.00245,,,,,,100.0014114,,,,
,28510574.885,99.9990768,82372.67578125,-0.00024062837397814,1.70860795101587E-6,1,0.999253354069792,40.0298881530762,1.99706912416341,15.5300004407763,-0.0027372227598492,-0.00047200462514177,0.25,7.04213177733191E-7,-0.000242015374784706,3.23165232641128E-8,99.9990768,99.9990768,82365.2890625,82380.0625,57.0416860764291,20.6132070970029,19.871798,0,0,0,40,4449,99.76855,82372.67578125,,,,,,,,,,,,,0,,,,0.00245,,,,,,99.9990768,,,,
,28510672.73,99.9964981,77478.8515625,-0.000227632202552922,2.29832012812875E-6,1,0.999253354069792,40.0298881530762,1.9970649896361,15.5300004407763,-0.00258419274583552,-0.000475963166546524,0.25,-1.92008645663008E-6,-0.000228935134868684,-2.57511994965579E-6,99.9964981,99.9964981,77471.453125,77486.25,56.9002113144483,20.6138729046383,19.492144,0,0,0,40,4449,99.7739,77478.8515625,,,,,,,,,,,,,0,,,,0.0049,,,,,,99.9964981,,,,
,28510773.985,99.99614335,72418.3125,-0.000210130773036767,1.84988863067009E-6,1,0.999253354069792,40.0298881530762,1.99703623444276,15.5300004407763,-0.00239058434008298,-0.000410128445145851,0.25,8.02964241578301E-7,-0.000211339028043953,2.08717310507058E-7,99.9960556,99.9962311,72408.4765625,72428.1484375,57.2097362080637,20.6148756881776,19.871798,0,0,0,40,4449,99.7773,72418.3125,,,,,,,,,,,,,0,,,,0,,,,,,99.99614335,,,,
,28510872.04,99.9959793,67517.61328125,-0.000194274779295361,1.97169340951804E-6,1,0.999253354069792,40.0298881530762,1.99707503332718,15.5300004407763,-0.00220706855893717,-0.000397134264747797,0.25,-8.32482660350974E-7,-0.000195385716426998,-1.39485910164138E-6,99.9959793,99.9959793,67500.1484375,67535.078125,57.1487691835637,20.6115885464932,20.251448,0,0,0,40,4449,99.77775,67517.61328125,,,,,,,,,,,,,0,,,,0,,,,,,99.9959793,,,,
,28510972.345,99.9942017,62504.82421875,-0.000179167939151134,1.56182745098859E-6,1,0.999253354069792,40.0298881530762,1.99709851699918,15.5300004407763,-0.00203684210267456,-0.000358335157871521,0.25,-6.75836817123666E-8,-0.000180192968603389,-5.8587194936875E-7,99.9942017,99.9942017,62497.3671875,62512.28125,57.271484861083,20.611019084845,20.251448,0,0,0,40,4449,99.7849,62504.82421875,,,,,,,,,,,,,0,,,,-0.00245,,,,,,99.9942017,,,,
,28511072.21,99.9940414,57514.033203125,-0.000163122070782427,2.06844497541748E-6,1,0.999253354069792,40.0298881530762,1.99732477226083,15.5300004407763,-0.00185247692311619,-0.000338437334599746,0.25,-1.12781530963935E-6,-0.000164050792878089,-1.60909133504288E-6,99.9940414,99.9940414,57508.9375,57519.12890625,57.095618444256,20.6129568335629,20.251448,0,0,0,40,4449,99.79085,57514.033203125,,,,,,,,,,,,,0,,,,0,,,,,,99.9940414,,,,
,28511173.545,99.9936905,52448.630859375,-0.000144323799852432,1.64771110388773E-6,1,0.999253354069792,40.0298881530762,1.99736004951208,15.5300004407763,-0.00164425410288049,-0.000269569243229043,0.25,1.63203539394123E-6,-0.000145151919073131,1.21826916958467E-6,99.9936905,99.9936905,52436.00390625,52461.2578125,57.0541921327368,20.6116938871819,20.251448,0,0,0,40,4449,99.7965,52448.630859375,,,,,,,,,,,,,0,,,,-0.00245,,,,,,99.9936905,,,,
,28511272.43,99.9937668,47504.056640625,-0.000131502830884783,1.43848226359982E-6,1,0.999253354069792,40.0298881530762,1.99738423573629,15.5300004407763,-0.0014951221436882,-0.000263106010776864,0.25,-4.79602230795343E-8,-0.000132251757339488,-4.36340543474898E-7,99.9937668,99.9937668,47489.00390625,47519.109375,57.1956668947176,20.6145000280093,19.492144,0,0,0,40,4449,99.8029,47504.056640625,,,,,,,,,,,,,0,,,,-0.00245,,,,,,99.9937668,,,,
,28511371.915,99.9935074,42533.212890625,-0.000116105542581559,1.91487148408846E-6,1,0.999253354069792,40.0298881530762,1.99734496609155,15.5300004407763,-0.00132044878287941,-0.000229889583132364,0.25,1.71356355676419E-7,-0.00011676641757883,-1.72629162049325E-7,99.993187,99.9938278,42525.8203125,42540.60546875,57.4348452216022,20.6140889320241,20.251448,0,0,0,40,4449,99.8103,42533.212890625,,,,,,,,,,,,,0,,,,0,,,,,,99.9935074,,,,
,28511470.925,99.9918594,37586.384765625,-9.97686450385153E-5,1.08227956863147E-6,1,0.999253354069792,40.0298881530762,1.99722974587221,15.5300004407763,-0.00113300171840839,-0.000206516354404076,0.25,-6.41254077909583E-7,-0.000100333332440281,-9.43250904681774E-7,99.9918594,99.9918594,37578.78125,37593.98828125,57.1542405831984,20.6136551953331,20.631098,0,0,0,40,4449,99.81915,37586.384765625,,,,,,,,,,,,,0,,,,0,,,,,,99.9918594,,,,
,28511568.04,99.99266815,32729.2314453125,-8.24276632127679E-5,1.45520726339505E-6,1,0.999253354069792,40.0298881530762,1.99735164113367,15.5300004407763,-0.000939245890017139,-0.000152830289176652,0.25,1.03728023289269E-6,-8.28982221023251E-5,7.95114944914527E-7,99.9925919,99.9927444,32716.8046875,32741.658203125,57.1237570709483,20.6148407829568,20.251448,0,0,0,40,4449,99.8267,32729.2314453125,,,,,,,,,,,,,0,,,,-0.00245,,,,,,99.99266815,,,,
,28511666.395,99.9911652,27814.501953125,-7.00687138057887E-5,1.46853602177005E-6,1,0.999253354069792,40.0298881530762,1.99734411925264,15.5300004407763,-0.000799937709261814,-0.000121212653006744,0.25,1.64836704869859E-6,-7.04704792969425E-5,1.44554148344746E-6,99.9911652,99.9911652,27804.544921875,27824.458984375,57.271484861083,20.6185792301437,19.871798,0,0,0,40,4449,99.8357,27814.501953125,,,,,,,,,,,,,0,,,,-0.0049,,,,,,99.9911652,,,,
,28511764.055,99.98957825,22934.470703125,-5.60194978099066E-5,1.32957830362313E-6,1,0.999253354069792,40.0298881530762,1.99728870317722,15.5300004407763,-0.00063814441300513,-0.000104754438524943,0.25,6.28483446529016E-7,-5.63381814397307E-5,4.61408571966037E-7,99.9894104,99.9897461,22926.97265625,22941.96875,57.1745629246983,20.6197436897797,19.871798,0,0,0,40,4449,99.845,22934.470703125,,,,,,,,,,,,,0,,,,0,,,,,,99.98957825,,,,
,28511861.76,99.9893417,18052.0341796875,-4.01202156044203E-5,1.15030983609782E-6,1,0.999253354069792,40.0298881530762,1.99728243447026,15.5300004407763,-0.000457039462417326,-7.49311634810821E-5,0.25,4.5884438998646E-7,-4.03481714524476E-5,3.38535400398003E-7,99.9893417,99.9893417,18044.6484375,18059.419921875,57.3598088837561,20.6185471401594,19.871798,0,0,0,40,4449,99.8545,18052.0341796875,,,,,,,,,,,,,0,,,,0,,,,,,99.9893417,,,,
,28511958.525,99.99071125,13214.548828125,-2.82321532330358E-5,8.87324021867063E-7,1,0.999253354069792,40.0298881530762,1.99712582524441,15.5300004407763,-0.000321209235776642,-5.48746963518211E-5,0.25,1.34156082109942E-7,-2.83917721003014E-5,4.79564504808532E-8,99.9903107,99.9911118,13202.15625,13226.94140625,57.2050464369484,20.6194446704087,20.251448,0,0,0,40,4449,99.859,13214.548828125,,,,,,,,,,,,,0,,,,0,,,,,,99.99071125,,,,
,28512056.895,99.9897766,8296.53955078125,-1.40483737095918E-5,5.24225998587839E-7,1,0.999253354069792,40.0298881530762,1.99712624141309,15.5300004407763,-0.000159020974987798,-3.19273457438642E-5,0.25,-3.39590083736542E-7,-1.41264427986023E-5,-3.84993303342486E-7,99.9897766,99.9897766,8284.001953125,8309.0771484375,57.3316702570638,20.6209913468285,20.251448,0,0,0,40,4449,99.86705,8296.53955078125,,,,,,,,,,,,,0,,,,0,,,,,,99.9897766,,,,
,28512154.455,99.9895477,3421.31176757812,-1.82362894677516E-6,2.96949643328078E-7,1,0.999253354069792,40.0298881530762,1.99714619899359,15.5300004407763,-2.02486421501478E-5,-6.38640903917404E-6,0.25,-2.41270543719554E-7,-1.83313785162887E-6,-2.48298520635299E-7,99.9895477,99.9895477,3411.21875,3431.40478515625,57.1284468420637,20.6221827257215,20.251448,0,0,0,40,4449,99.8763,3421.31176757812,,,,,,,,,,,,,0,,,,0,,,,,,99.9895477,,,,
,28512222.88,99.9923477,0.0608950946480036,6.58134287091422E-6,2.92540079582662E-7,1,0.999253354069792,40.0298881530762,1.99731031329098,15.5300004407763,7.59298676670546E-5,6.84344586544669E-6,0.25,-5.54847332269778E-7,6.62007426086932E-6,-5.37453860927659E-7,99.9923477,99.9923477,0.0456713177263737,0.0761188715696335,57.5098815594484,20.6207600234012,20.251448,0,0,0,40,4417,99.8817,0.0608950946480036,,,,,,,,,,,,,0,,,,-0.00245,,,,,,99.9923477,,,,