File: data/monolayers/nanoparticles/Ol_CoFe_C/vsm/data_disorderedWafer/DD227_ZFCW_100OE.DAT
[Header]
; VSM Data File (default extension .dat)
; Copyright (c) 2003-2013, Quantum Design, Inc. All rights reserved.
TITLE,
FILEOPENTIME,28548363.95,11/27/2018,6:06 pm
BYAPP,VSM,2.0,2.0
INFO,PPMS VSM Option Release 1.4.10 Build 1,APPNAME
INFO,Quantum Design Linear Motor Servo Controller,MOTOR_MODULE_NAME
INFO,3101-100 M1,MOTOR_HW_VERSION
INFO,MMC1014,MOTOR_SERIAL_NUMBER
INFO,SRV No X-over 01.03.11,MOTOR_SOFTWARE_VERSION
INFO,Quantum Design VSM Detection Module,VSM_MODULE_NAME
INFO,3101-150 F0,VSM_HW_VERSION
INFO,VSM707,VSM_SERIAL_NUMBER
INFO,VSM No X-over 01.02.05 May 20 2008 13:51:47,VSM_SOFTWARE_VERSION
INFO,704,PREAMP_SERIAL_NUMBER
INFO,822,COIL_SERIAL_NUMBER
INFO,0,MOMENT_UNITS
INFO,CoFe2O4 FeO,SAMPLE_MATERIAL
INFO,disordered monolayer,SAMPLE_COMMENT
INFO,25.46,SAMPLE_MASS
INFO,,SAMPLE_VOLUME
INFO,,SAMPLE_MOLECULAR_WEIGHT
INFO,,SAMPLE_SIZE
INFO,,SAMPLE_SHAPE
DATATYPE,COMMENT,1
DATATYPE,TIME,2
STARTUPAXIS,X,2
STARTUPAXIS,Y1,5
[Data]
Comment,Time Stamp (sec),Temperature (K),Magnetic Field (Oe),Moment (emu),M. Std. Err. (emu),Transport Action,Averaging Time (sec),Frequency (Hz),Peak Amplitude (mm),Center Position (mm),Coil Signal' (mV),Coil Signal" (mV),Range (mV),M. Quad. Signal (emu),M. Raw' (emu),M. Raw" (emu),Min. Temperature (K),Max. Temperature (K),Min. Field (Oe),Max. Field (Oe),Mass (grams),Motor Lag (deg),Pressure (Torr),VSM Status (code),Motor Status (code),Measure Status (code),Measure Count,PPMS Status (code),System Temp. (K),System Field (Oe),Sample Position (deg),Bridge 1 Resistance (ohms),Bridge 1 Excitation (에),Bridge 2 Resistance (ohms),Bridge 2 Excitation (에),Bridge 3 Resistance (ohms),Bridge 3 Excitation (에),Bridge 4 Resistance (ohms),Bridge 4 Excitation (에),Signal 1 Vin (V),Signal 2 Vin (V),Digital Inputs (code),Drive 1 Iout (mA),Drive 1 Ipower (W),Drive 2 Iout (mA),Drive 2 Ipower (W),Pressure (),Map 20 (),Map 21 (),Map 22 (),Map 23 (),Map 24 (),Map 25 (),Map 26 (),Map 27 (),Map 28 (),Map 29 ()
,28553046.11,9.9987173,99.7461624145508,,,2,,,,15.4200002801418,,,,,,,9.9987173,9.9987173,99.7461624145508,99.7461624145508,,,11.899124,,,,-99999999,4373,9.9991,99.7461624145508,,,,,,,,,,,,,,,,,,,,,,,9.9987173,,,,
,28553253.93,12.5514975,99.7461624145508,6.76239626976035E-11,3.26512580707671E-7,1,0.999253354069792,40.0298881530762,1.99743414292044,15.4100004583597,1.24272270721207E-6,-6.99384039297609E-6,0.25,-6.22383279771849E-7,3.06887282051547E-9,-6.18806183655055E-7,12.5514975,12.5514975,99.7461624145508,99.7461624145508,56.3147715535444,20.5908847765827,13.038077,0,0,0,40,4370,12.68,99.7461624145508,,,,,,,,,,,,,0,,,,0,,,,,,12.5514975,,,,
,28553394.24,16.0331593,99.7461624145508,-2.08986672564765E-7,3.22525495025251E-7,1,0.999253354069792,40.0298881530762,1.99672708266093,15.4100004583597,-1.9717462195119E-6,-2.53376794913928E-6,0.25,-1.88443417677786E-7,-2.06874916754743E-7,-1.88366622719933E-7,16.0331593,16.0331593,99.7461624145508,99.7461624145508,56.790783321756,20.5930406509096,13.797379,0,0,0,40,4370,16.1793,99.7461624145508,,,,,,,,,,,,,0,,,,0,,,,,,16.0331593,,,,
,28553532.1,19.5042782,99.7461624145508,-1.21099909709147E-7,3.27488279984031E-7,1,0.999253354069792,40.0298881530762,1.99680637911709,15.4100004583597,-1.11360415449919E-6,-1.63142304100352E-6,0.25,-1.23715832077379E-7,-1.19804355351612E-7,-1.2359054064495E-7,19.5042782,19.5042782,99.7461624145508,99.7461624145508,57.0190188493714,20.5970730676263,13.797379,0,0,0,40,4370,19.6391,99.7461624145508,,,,,,,,,,,,,0,,,,-0.0049,,,,,,19.5042782,,,,
,28553674.105,23.0147247,99.7461624145508,-4.77931241630366E-8,2.72738146721337E-7,1,0.999253354069792,40.0298881530762,1.99688002888973,15.4400002211332,2.63972367326739E-8,-3.26537589738622E-6,0.25,-2.82146563085265E-7,-4.61228842136787E-8,-2.80785782070742E-7,23.0147247,23.0147247,99.7461624145508,99.7461624145508,56.8071975206598,20.5948593242309,14.936333,0,0,0,40,4370,23.2149,99.7461624145508,,,,,,,,,,,,,0,,,,0,,,,,,23.0147247,,,,
,28553815.75,26.5107384,99.7461624145508,-1.10665051095361E-7,3.03254190968992E-7,1,0.999253354069792,40.0298881530762,1.99691545356702,15.4400002211332,-9.52113101660081E-7,-1.85900153447096E-6,0.25,-1.45741729680421E-7,-1.09303694830297E-7,-1.45518801700355E-7,26.5107384,26.5107384,99.7461624145508,99.7461624145508,57.2034831799099,20.5995764552043,14.936333,0,0,0,40,4370,26.792,99.7461624145508,,,,,,,,,,,,,0,,,,0,,,,,,26.5107384,,,,
,28553958.29,30.0553474,99.7461624145508,-3.69911920136342E-7,3.25178930223972E-7,1,0.999253354069792,40.0298881530762,1.99710249612046,15.4400002211332,-3.72322449238043E-6,-3.18103774530218E-6,0.25,-2.17029515046662E-7,-3.66810387915465E-7,-2.17954948184704E-7,30.0553474,30.0553474,99.7461624145508,99.7461624145508,57.0002597649099,20.6004970402966,15.695635,0,0,0,40,4370,30.37635,99.7461624145508,,,,,,,,,,,,,0,,,,0,,,,,,30.0553474,,,,
,28554099.815,33.5329208,99.7461624145508,4.6041237565928E-8,3.25332845401552E-7,1,0.999253354069792,40.0298881530762,1.99746093374191,15.4499998316169,1.17766359821435E-6,-3.59925960084273E-6,0.25,-3.28231893060986E-7,4.77741357423122E-8,-3.26426027626774E-7,33.5329208,33.5329208,99.7461624145508,99.7461624145508,57.1315733561406,20.5992095768798,16.075285,0,0,0,40,4370,33.94085,99.7461624145508,,,,,,,,,,,,,0,,,,0,,,,,,33.5329208,,,,
,28554237.91,37.008625,99.7461624145508,-1.02886652053986E-7,2.91358547769298E-7,1,0.999253354069792,40.0298881530762,1.99667371231552,15.4499998316169,-4.11944591154168E-7,-4.36794885423723E-6,0.25,-3.6983975656021E-7,-1.00111758971838E-7,-3.69003234739191E-7,37.008625,37.008625,99.7461624145508,99.7461624145508,57.1214121853907,20.6083618968564,15.695635,0,0,0,40,4370,37.42175,99.7461624145508,,,,,,,,,,,,,0,,,,-0.00245,,,,,,37.008625,,,,
,28554383.015,40.5420113,99.7461624145508,1.82021217124448E-7,2.90790862459314E-7,1,0.999253354069792,40.0298881530762,1.99674859338078,15.4499998316169,2.81021794128431E-6,-3.86739881927169E-6,0.25,-3.76200164269175E-7,1.84011233855258E-7,-3.73757800031482E-7,40.5420113,40.5420113,99.7461624145508,99.7461624145508,56.7462304961599,20.6115099487159,16.454937,0,0,0,40,4370,41.0797,99.7461624145508,,,,,,,,,,,,,0,,,,0,,,,,,40.5420113,,,,
,28554524.63,44.0363541,99.7461624145508,1.0881799553573E-8,2.58882813412809E-7,1,0.999253354069792,40.0298881530762,1.99667907400521,15.4400002211332,1.2673287407443E-6,-6.33721557346571E-6,0.25,-5.6432097280644E-7,1.49145337288222E-8,-5.63005052798741E-7,44.0363541,44.0363541,99.7461624145508,99.7461624145508,56.9150622563137,20.6073812464353,16.834587,0,0,0,40,4370,44.66625,99.7461624145508,,,,,,,,,,,,,0,,,,0,,,,,,44.0363541,,,,
,28554664.95,47.5063629,99.7461624145508,-2.70682232750013E-7,2.76606472363147E-7,1,0.999253354069792,40.0298881530762,1.99668517470502,15.4400002211332,-3.10729015974772E-6,-2.51998441292775E-7,0.25,2.64421803453112E-8,-2.70579498775326E-7,2.44103333564709E-8,47.5063629,47.5063629,99.7461624145508,99.7461624145508,57.2214606358522,20.6081578080221,17.593889,0,0,0,40,4370,48.231,99.7461624145508,,,,,,,,,,,,,0,,,,0.0049,,,,,,47.5063629,,,,
,28554811.07,51.0298653,99.7461624145508,-2.94650315003937E-7,3.05166021444133E-7,1,0.999253354069792,40.0298881530762,1.99650955081022,15.4400002211332,-2.4421979504292E-6,-5.51174973643576E-6,0.25,-4.34954861743912E-7,-2.91439322558831E-7,-4.37174996870036E-7,51.0298653,51.0298653,99.7461624145508,99.7461624145508,56.8837971155445,20.6120359155538,17.973541,0,0,0,40,4370,51.9648,99.7461624145508,,,,,,,,,,,,,0,,,,0,,,,,,51.0298653,,,,
,28554934.18,54.0582428,99.7461624145508,-8.78053319859397E-8,2.74246868325416E-7,1,0.999253354069792,40.0298881530762,2.00927911335253,15.4400002211332,-8.96210504420092E-9,-5.67473556453982E-6,0.25,-4.83146984029057E-7,-8.43637715552089E-8,-4.84282796678205E-7,54.0582428,54.0582428,99.7461624145508,99.7461624145508,57.2066096939868,20.6142152475947,18.353191,0,0,0,40,4374,55.1244,99.7461624145508,,,,,,,,,,,,,0,,,,0.00245,,,,,,54.0582428,,,,
,28555076.485,57.5063477,99.7461624145508,2.44232955060721E-7,2.6613670565856E-7,1,0.999253354069792,40.0298881530762,2.00928076724246,15.4400002211332,3.30029859801875E-6,-2.39029643292094E-6,0.25,-2.53866809797942E-7,2.46511346875707E-7,-2.52662820028655E-7,57.5063477,57.5063477,99.7461624145508,99.7461624145508,57.3363600281791,20.614620619634,19.492144,0,0,0,40,4374,58.7792,99.7461624145508,,,,,,,,,,,,,0,,,,0,,,,,,57.5063477,,,,
,28555218.885,61.0183296,99.7461624145508,4.35850125616074E-8,3.22878437415507E-7,1,0.999253354069792,40.0298881530762,2.00934673233102,15.4400002211332,8.91453839109133E-7,-2.1111660020536E-6,0.25,-1.93079906979192E-7,4.49949515866384E-8,-1.93342808415654E-7,61.0183296,61.0183296,99.7461624145508,99.7461624145508,57.0713879601599,20.6161066463609,19.871798,0,0,0,40,4374,62.38635,99.7461624145508,,,,,,,,,,,,,0,,,,0,,,,,,61.0183296,,,,
,28555342.505,64.0663528,99.7461624145508,-5.86475251826232E-8,3.22897916078698E-7,1,0.999253354069792,40.0298881530762,2.00899794068315,15.429999679327,-2.79251090134902E-7,-2.29476444304402E-6,0.25,-1.90769466795883E-7,-5.76513967724459E-8,-1.91800676730552E-7,64.0663528,64.0663528,99.7461624145508,99.7461624145508,57.1792526958137,20.6148851241562,19.871798,0,0,0,40,4374,65.5013,99.7461624145508,,,,,,,,,,,,,0,,,,-0.0049,,,,,,64.0663528,,,,
,28555482.58,67.5319672,99.7461624145508,5.21494844091383E-8,2.6454832426726E-7,1,0.999253354069792,40.0298881530762,2.00907906185647,15.429999679327,8.0361847041352E-7,-1.06199746627612E-6,0.25,-1.02396207305736E-7,5.29595758691804E-8,-1.02504165264663E-7,67.5319672,67.5319672,99.7461624145508,99.7461624145508,57.2355299491984,20.6117556482818,19.871798,0,0,0,40,4374,69.0465,99.7461624145508,,,,,,,,,,,,,0,,,,-0.00245,,,,,,67.5319672,,,,
,28555624.965,71.0542297,99.7461624145508,1.22036456640185E-7,2.78882318807574E-7,1,0.999253354069792,40.0298881530762,2.00908583218467,15.429999679327,2.47772618902899E-6,-5.84058714061157E-6,0.25,-5.3339138396679E-7,1.25476668510805E-7,-5.35122790453754E-7,71.0542297,71.0542297,99.7461624145508,99.7461624145508,57.0964000727753,20.613466426935,19.492144,0,0,0,40,4374,72.6439,99.7461624145508,,,,,,,,,,,,,0,,,,-0.00245,,,,,,71.0542297,,,,
,28555766.4,74.5465851,99.7461624145508,1.49911842789434E-7,3.40074044298222E-7,1,0.999253354069792,40.0298881530762,1.98494367416414,15.4100004583597,2.67072579258996E-6,-5.20436085515929E-6,0.25,-4.87659634455745E-7,1.53083004045546E-7,-4.89263571958924E-7,74.5465851,74.5465851,99.7461624145508,99.7461624145508,56.9783741663714,20.6156050142483,19.871798,0,0,0,40,4374,76.20995,99.7461624145508,,,,,,,,,,,,,0,,,,0,,,,,,74.5465851,,,,
,28555909.045,78.05434035,99.7461624145508,-6.00539023561825E-8,3.07276729723197E-7,1,0.999253354069792,40.0298881530762,1.98489055203592,15.4100004583597,5.8367780640965E-8,-4.27358186165631E-6,0.25,-3.67800724744132E-7,-5.86545021712456E-8,-3.69954351148715E-7,78.026741,78.0819397,99.7461624145508,99.7461624145508,57.3261988574291,20.6183014050001,20.251448,0,0,0,40,4374,79.83225,99.7461624145508,,,,,,,,,,,,,0,,,,0.0049,,,,,,78.05434035,,,,
,28556049.52,81.530098,99.7461624145508,2.00559834019101E-8,3.25244788639307E-7,1,0.999253354069792,40.0298881530762,1.98477695727565,15.4100004583597,1.00752133617288E-6,-4.37279728206622E-6,0.25,-3.9070860010636E-7,2.18408130709156E-8,-3.92691088640373E-7,81.530098,81.530098,99.7461624145508,99.7461624145508,57.0964000727753,20.6222211256241,20.251448,0,0,0,40,4374,83.4009,99.7461624145508,,,,,,,,,,,,,0,,,,0,,,,,,81.530098,,,,
,28556192.615,85.0812531,99.7461624145508,-7.37453690006911E-10,3.6502469049187E-7,1,0.999253354069792,40.0298881530762,1.98472532745647,15.3900003060699,8.5887291836233E-8,-5.3479016762118E-7,0.25,-4.72108986410528E-8,-5.53211495357326E-10,-4.74705939370478E-8,85.0812531,85.0812531,99.7461624145508,99.7461624145508,57.0393411908714,20.6158363195466,21.01075,0,0,0,40,4374,86.9864,99.7461624145508,,,,,,,,,,,,,0,,,,-0.00245,,,,,,85.0812531,,,,
,28556332.03,88.53952025,99.7461624145508,7.71896543304598E-9,2.93707790134503E-7,1,0.999253354069792,40.0298881530762,1.98507099428305,15.3900003060699,1.81871819775956E-7,-5.21210388052391E-7,0.25,-4.74861181869849E-8,7.93816779679716E-9,-4.77204657257351E-8,88.5057449,88.5732956,99.7461624145508,99.7461624145508,57.0698247031214,20.612141890832,21.01075,0,0,0,40,4374,90.49525,99.7461624145508,,,,,,,,,,,,,0,,,,0,,,,,,88.53952025,,,,
,28556474.75,92.0586624,99.7461624145508,-8.41048235061052E-9,2.53464945505942E-7,1,0.999253354069792,40.0298881530762,1.98474405535932,15.3900003060699,5.97149294809327E-7,-3.94671456923516E-6,0.25,-3.47799669108336E-7,-7.25181016462787E-9,-3.49779625565173E-7,92.0586624,92.0586624,99.7461624145508,99.7461624145508,57.4395349927176,20.6167065639867,20.631098,0,0,0,40,4374,94.07325,99.7461624145508,,,,,,,,,,,,,0,,,,0.0049,,,,,,92.0586624,,,,
,28556611.985,95.5061951,99.7461624145508,8.32105427295591E-8,2.68810029855407E-7,1,0.999253354069792,40.0298881530762,2.00888825144693,15.3599996119738,1.22978504408429E-6,-1.41619944742325E-6,0.25,-1.38522314864587E-7,8.41311779522399E-8,-1.39034292195592E-7,95.5061951,95.5061951,99.7461624145508,99.7461624145508,57.2417829773522,20.6155879124864,20.631098,0,0,0,40,4374,97.51215,99.7461624145508,,,,,,,,,,,,,0,,,,0,,,,,,95.5061951,,,,
,28556754.24,99.04953,99.7461624145508,3.96205896715599E-7,2.69550112257556E-7,1,0.999253354069792,40.0298881530762,2.00895888236301,15.3599996119738,5.85117552853002E-6,-6.72540259573182E-6,0.25,-6.57879215292871E-7,4.00460315692409E-7,-6.60401727168754E-7,99.04953,99.04953,99.7461624145508,99.7461624145508,56.9627415959868,20.619040200263,21.01075,0,0,0,40,4374,101.0954,99.7461624145508,,,,,,,,,,,,,0,,,,-0.00245,,,,,,99.04953,,,,
,28556895.15,102.5337982,99.7461624145508,1.27190995989073E-7,3.22967489223609E-7,1,0.999253354069792,40.0298881530762,2.00876020435939,15.3599996119738,1.59954081191357E-6,-5.73765630173564E-7,0.25,-7.2514103264609E-8,1.28121257956582E-7,-7.25604868206059E-8,102.5337982,102.5337982,99.7461624145508,99.7461624145508,57.1518956976407,20.6218027275487,21.01075,0,0,0,40,4374,104.64305,99.7461624145508,,,,,,,,,,,,,0,,,,0.0049,,,,,,102.5337982,,,,
,28557035.155,106.0013885,99.7461624145508,6.61813600937896E-8,2.97849603035248E-7,1,0.999253354069792,40.0298881530762,1.98493482729206,15.3299998492002,1.43540201598344E-6,-3.7887441099072E-6,0.25,-3.46812307400699E-7,6.74967382864496E-8,-3.48598244899158E-7,106.0013885,106.0013885,99.7461624145508,99.7461624145508,57.3058765159291,20.6193334484723,21.3904,0,0,0,40,4374,108.16005,99.7461624145508,,,,,,,,,,,,,0,,,,0.0049,,,,,,106.0013885,,,,
,28557177.235,109.5407028,99.7461624145508,3.0856780236588E-7,2.88360249127098E-7,1,0.999253354069792,40.0298881530762,1.98484473854374,15.3299998492002,4.37248060708278E-6,-4.44009855816109E-6,0.25,-4.46913181362301E-7,3.1145535985643E-7,-4.48644800758801E-7,109.5407028,109.5407028,99.7461624145508,99.7461624145508,57.3793495967368,20.6190177388179,20.631098,0,0,0,40,4374,111.74205,99.7461624145508,,,,,,,,,,,,,0,,,,0.0049,,,,,,109.5407028,,,,
,28557317.305,113.0084763,99.7461624145508,3.58016313069546E-8,3.06236964242269E-7,1,0.999253354069792,40.0298881530762,1.98484577351519,15.3299998492002,9.28898945160716E-8,1.85154658885884E-6,0.25,1.57554812146769E-7,3.56194114127297E-8,1.58526254083323E-7,113.0084763,113.0084763,99.7461624145508,99.7461624145508,57.1612752398714,20.6201720120756,21.01075,0,0,0,40,4374,115.2705,99.7461624145508,,,,,,,,,,,,,0,,,,0.00245,,,,,,113.0084763,,,,
,28557459.21,116.5429916,99.7461624145508,2.03046182374634E-7,2.96159950213195E-7,1,0.999253354069792,40.0298881530762,1.98506052107702,15.3000000864267,2.73816981281059E-6,-2.13142027218512E-6,0.25,-2.24091611308761E-7,2.04695412215788E-7,-2.24870895643969E-7,116.5429916,116.5429916,99.7461624145508,99.7461624145508,57.454385934583,20.6147002322523,21.3904,0,0,0,40,4374,118.83275,99.7461624145508,,,,,,,,,,,,,0,,,,-0.0049,,,,,,116.5429916,,,,
,28557598.91,120.0148239,99.7461624145508,-2.13799343643534E-7,3.06728848583812E-7,1,0.999253354069792,40.0298881530762,1.98495861031991,15.3000000864267,-2.84360602126082E-6,2.02101530945665E-6,0.25,2.16195365999189E-7,-2.15456535895603E-7,2.16918618436283E-7,120.0148239,120.0148239,99.7461624145508,99.7461624145508,57.2769562607176,20.6195457373535,21.3904,0,0,0,40,4374,122.3417,99.7461624145508,,,,,,,,,,,,,0,,,,-0.0049,,,,,,120.0148239,,,,
,28557739.805,123.5311737,99.7461624145508,2.86239458399865E-7,3.55550418000293E-7,1,0.999253354069792,40.0298881530762,1.98496746347162,15.3000000864267,3.58022993842709E-6,-1.41035782826238E-6,0.25,-1.74805335471264E-7,2.88172364332822E-7,-1.75159279110008E-7,123.5311737,123.5311737,99.7461624145508,99.7461624145508,57.0088576786214,20.6197363499987,21.3904,0,0,0,40,4374,125.8722,99.7461624145508,,,,,,,,,,,,,0,,,,0,,,,,,123.5311737,,,,
,28557861.015,126.5454865,99.7461624145508,1.07169468637337E-7,3.566121875692E-7,1,0.999253354069792,40.0298881530762,2.00901253822553,15.2700003236532,1.65389425599122E-6,-2.24082669497856E-6,0.25,-2.14730371177552E-7,1.08184475123891E-7,-2.15676655029268E-7,126.5454865,126.5454865,99.7461624145508,99.7461624145508,57.2120810936214,20.6161269831858,21.3904,0,0,0,40,4374,128.9297,99.7461624145508,,,,,,,,,,,,,0,,,,0.0049,,,,,,126.5454865,,,,
,28558002.72,130.0589142,99.7461624145508,-5.71186581604328E-8,2.47768421491233E-7,1,0.999253354069792,40.0298881530762,2.00912761136906,15.2700003236532,2.07617948415434E-7,-5.04403369713732E-6,0.25,-4.31247157348252E-7,-5.65884901517721E-8,-4.33665712894267E-7,130.0589142,130.0589142,99.7461624145508,99.7461624145508,57.2839909173907,20.6180143196327,21.3904,0,0,0,40,4374,132.4779,99.7461624145508,,,,,,,,,,,,,0,,,,0,,,,,,130.0589142,,,,
,28558141.795,133.5181732,99.7461624145508,2.02173113978345E-7,2.5628804205434E-7,1,0.999253354069792,40.0298881530762,2.00921808736268,15.2700003236532,2.96403329224964E-6,-3.33808008781736E-6,0.25,-3.27272074137794E-7,2.03850185135384E-7,-3.28624815196835E-7,133.5181732,133.5181732,99.7461624145508,99.7461624145508,57.4199942797368,20.6165696373747,21.770052,0,0,0,40,4374,135.97465,99.7461624145508,,,,,,,,,,,,,0,,,,-0.00245,,,,,,133.5181732,,,,
,28558261.33,136.5100174,99.7461624145508,-5.68490347237088E-8,2.56738389989762E-7,1,0.999253354069792,40.0298881530762,2.00910146603392,15.2300000190735,-3.63945943344532E-7,-1.75236313264926E-6,0.25,-1.43387516759499E-7,-5.68878261696926E-8,-1.44238310211152E-7,136.480484,136.5395508,99.7461624145508,99.7461624145508,56.9017745714868,20.6126721774569,22.149702,0,0,0,40,4374,138.98045,99.7461624145508,,,,,,,,,,,,,0,,,,0,,,,,,136.5100174,,,,
,28558403.315,140.0183105,99.7461624145508,2.20691716404444E-7,2.96179827268456E-7,1,0.999253354069792,40.0298881530762,2.00929333471262,15.2300000190735,2.87552725677222E-6,-1.58365986921657E-6,0.25,-1.77018535167057E-7,2.22133268617353E-7,-1.7754694437443E-7,140.0183105,140.0183105,99.7461624145508,99.7461624145508,57.2527257766214,20.613536089999,22.149702,0,0,0,40,4374,142.5391,99.7461624145508,,,,,,,,,,,,,0,,,,0,,,,,,140.0183105,,,,
,28558543.14,143.5514679,99.7461624145508,2.21383535370939E-7,3.67667157507074E-7,1,0.999253354069792,40.0298881530762,2.00913859715641,15.2300000190735,3.28166315798654E-6,-3.87021440246999E-6,0.25,-3.77204688500597E-7,2.23133867704276E-7,-3.78744600429564E-7,143.5514679,143.5514679,99.7461624145508,99.7461624145508,57.166746639506,20.6157189585343,22.529354,0,0,0,40,4374,146.0402,99.7461624145508,,,,,,,,,,,,,0,,,,0,,,,,,143.5514679,,,,
,28558683.665,147.0421143,99.7461624145508,8.20135123939049E-8,3.50276079163431E-7,1,0.999253354069792,40.0298881530762,2.00912716603431,15.1800001040101,1.90747106301489E-6,-5.40515334880329E-6,0.25,-4.87244163604641E-7,8.32069299414531E-8,-4.89538037691843E-7,147.0421143,147.0421143,99.7461624145508,99.7461624145508,57.075296102756,20.6144468426626,21.770052,0,0,0,40,4374,149.5731,99.7461624145508,,,,,,,,,,,,,0,,,,0,,,,,,147.0421143,,,,
,28558824.17,150.5057678,99.7461624145508,4.37528419707718E-7,2.80247522250385E-7,1,0.999253354069792,40.0298881530762,2.00900620978423,15.1800001040101,5.66620040021847E-6,-2.95634051527212E-6,0.25,-3.34922168312836E-7,4.40191204357556E-7,-3.35879832778557E-7,150.5057678,150.5057678,99.7461624145508,99.7461624145508,57.322290714833,20.6141698288166,21.770052,0,0,0,40,4374,153.09805,99.7461624145508,,,,,,,,,,,,,0,,,,-0.0049,,,,,,150.5057678,,,,
,28558964.375,154.0476837,99.7461624145508,4.75583520891679E-8,3.21796770000277E-7,1,0.999253354069792,40.0298881530762,2.00910841194911,15.1800001040101,1.24325214504661E-6,-3.92453231736571E-6,0.25,-3.51737434934931E-7,4.83169726049665E-8,-3.5335538885126E-7,154.0476837,154.0476837,99.7461624145508,99.7461624145508,57.0760777312753,20.6176209960428,22.149702,0,0,0,40,4374,156.6108,99.7461624145508,,,,,,,,,,,,,0,,,,0,,,,,,154.0476837,,,,
,28559103.285,157.5067444,99.7461624145508,-7.9120603138703E-8,3.54463434407558E-7,1,0.999253354069792,40.0298881530762,1.98526551064595,15.1500003412366,-3.19541762104613E-7,-3.45428472009073E-6,0.25,-2.92018950262029E-7,-7.90669113664582E-8,-2.93510926993344E-7,157.5067444,157.5067444,99.7461624145508,99.7461624145508,57.1644017539484,20.6102289307408,22.149702,0,0,0,40,4374,160.0887,99.7461624145508,,,,,,,,,,,,,0,,,,0,,,,,,157.5067444,,,,
,28559245.43,161.0331573,99.7461624145508,-9.14330238834119E-8,3.25687171870605E-7,1,0.999253354069792,40.0298881530762,1.98505078811367,15.1500003412366,-4.11506724507673E-7,-3.74890223681558E-6,0.25,-3.16023896084407E-7,-9.14077207264803E-8,-3.17613110958596E-7,161.0331573,161.0331573,99.7461624145508,99.7461624145508,57.0815491309099,20.612868560479,22.149702,0,0,0,40,4374,163.65205,99.7461624145508,,,,,,,,,,,,,0,,,,0,,,,,,161.0331573,,,,
,28559384.26,164.5211945,99.7461624145508,-6.40954288854419E-8,3.29509616942002E-7,1,0.999253354069792,40.0298881530762,1.98491840052691,15.1500003412366,-2.02014683088389E-7,-3.12483990457975E-6,0.25,-2.65570310723242E-7,-6.40199960192833E-8,-2.66859755267804E-7,164.5211945,164.5211945,99.7461624145508,99.7461624145508,57.3090030300061,20.612043100944,22.909004,0,0,0,40,4374,167.1274,99.7461624145508,,,,,,,,,,,,,0,,,,-0.00245,,,,,,164.5211945,,,,
,28559503.54,167.5036774,99.7461624145508,4.0737786208839E-7,3.09720817828929E-7,1,0.999253354069792,40.0298881530762,2.00916804308849,15.1100000366569,5.98060041067199E-6,-6.81947436457628E-6,0.25,-6.67855356022882E-7,4.1008337870314E-7,-6.70273631188114E-7,167.5036774,167.5036774,99.7461624145508,99.7461624145508,57.3105662870445,20.6121578278833,22.909004,0,0,0,40,4374,170.11195,99.7461624145508,,,,,,,,,,,,,0,,,,0,,,,,,167.5036774,,,,
,28559644.305,171.0240631,99.7461624145508,4.6470763569484E-7,3.43960659000534E-7,1,0.999253354069792,40.0298881530762,2.00894709100413,15.1100000366569,5.98428653939842E-6,-2.96932415850869E-6,0.25,-3.40812247578497E-7,4.67169455144407E-7,-3.41684462636395E-7,171.0240631,171.0240631,99.7461624145508,99.7461624145508,57.0307432771599,20.6171615602274,22.529354,0,0,0,40,4374,173.63585,99.7461624145508,,,,,,,,,,,,,0,,,,-0.00245,,,,,,171.0240631,,,,
,28559783.405,174.5142517,99.7461624145508,3.8910072986093E-7,3.05829770596571E-7,1,0.999253354069792,40.0298881530762,2.0089133222096,15.1100000366569,4.32948493769107E-6,1.42750464509314E-6,0.25,5.73480470412618E-8,3.90677086028574E-7,5.80859083201345E-8,174.5142517,174.5142517,99.7461624145508,99.7461624145508,57.0385595623522,20.6197961106123,22.909004,0,0,0,40,4374,177.1114,99.7461624145508,,,,,,,,,,,,,0,,,,0,,,,,,174.5142517,,,,
,28559906.125,177.5554047,99.7461624145508,4.68505750363733E-7,3.55103442273609E-7,1,0.999253354069792,40.0298881530762,2.0089777401822,15.0600001215935,5.9295630908671E-6,-2.40449995061595E-6,0.25,-2.92021616112977E-7,4.70812643974689E-7,-2.92650982213414E-7,177.5554047,177.5554047,99.7461624145508,99.7461624145508,57.2316218066022,20.6149565456625,22.529354,0,0,0,40,4374,180.1804,99.7461624145508,,,,,,,,,,,,,0,,,,0.0049,,,,,,177.5554047,,,,
,28560044.1,181.0118256,99.7461624145508,4.35586234209971E-7,3.90287865396811E-7,1,0.999253354069792,40.0298881530762,2.0087169526369,15.0600001215935,5.72847398933935E-6,-3.48286871395249E-6,0.25,-3.8078916926051E-7,4.37810210870378E-7,-3.81801842215152E-7,181.0118256,181.0118256,99.7461624145508,99.7461624145508,57.1448610409676,20.6198855190267,23.288654,0,0,0,40,4374,183.6367,99.7461624145508,,,,,,,,,,,,,0,,,,-0.00245,,,,,,181.0118256,,,,
,28560184.275,184.5142822,99.7461624145508,3.87121722045075E-7,3.07195462389993E-7,1,0.999253354069792,40.0298881530762,2.00898968164403,15.0600001215935,5.20210343012623E-6,-3.73407903152586E-6,0.25,-3.94348216654881E-7,3.89113294851851E-7,-3.95444111323317E-7,184.5142822,184.5142822,99.7461624145508,99.7461624145508,57.2675767184868,20.6227163971877,22.909004,0,0,0,40,4374,187.1509,99.7461624145508,,,,,,,,,,,,,0,,,,0,,,,,,184.5142822,,,,
,28560306.165,187.5271301,99.7461624145508,3.74931645030656E-7,4.14950996439747E-7,1,0.999253354069792,40.0298881530762,2.00879081321429,15.0199998170137,5.15476848531088E-6,-4.29215258715848E-6,0.25,-4.41170884374235E-7,3.76885120115709E-7,-4.4243406602055E-7,187.5271301,187.5271301,99.7461624145508,99.7461624145508,57.2808644033138,20.6197976108077,22.529354,0,0,0,40,4374,190.1999,99.7461624145508,,,,,,,,,,,,,0,,,,0,,,,,,187.5271301,,,,
,28560447.075,191.0358429,99.7461624145508,7.65793171544658E-7,3.48760299230191E-7,1,0.999253354069792,40.0298881530762,2.00897434830641,15.0199998170137,9.44121049385946E-6,-2.51089439532743E-6,0.25,-3.5302146925734E-7,7.69055390601631E-7,-3.53475125301329E-7,191.0358429,191.0358429,99.7461624145508,99.7461624145508,57.2964969736984,20.6211681963112,22.909004,0,0,0,40,4374,193.7443,99.7461624145508,,,,,,,,,,,,,0,,,,-0.0049,,,,,,191.0358429,,,,
,28560586.23,194.5414124,99.7461624145508,5.89192447682273E-7,3.73607736273317E-7,1,0.999253354069792,40.0298881530762,2.00919648166858,15.0199998170137,7.36686416958615E-6,-2.52488714009033E-6,0.25,-3.23549911048584E-7,5.91687926009638E-7,-3.24072441884508E-7,194.5414124,194.5414124,99.7461624145508,99.7461624145508,57.1925403806407,20.6205697507422,23.288654,0,0,0,40,4374,197.2384,99.7461624145508,,,,,,,,,,,,,0,,,,0,,,,,,194.5414124,,,,
,28560727.765,198.0358276,99.7461624145508,6.78926765541601E-7,3.52401321517083E-7,1,0.999253354069792,40.0298881530762,2.00919588936656,14.9699999019504,8.10684956029854E-6,-7.15824244580405E-7,0.25,-1.80638897490749E-7,6.8150996875307E-7,-1.80540344809184E-7,198.0358276,198.0358276,99.7461624145508,99.7461624145508,56.8181403199291,20.6152441807267,22.909004,0,0,0,40,4374,200.7874,99.7461624145508,,,,,,,,,,,,,0,,,,-0.00245,,,,,,198.0358276,,,,
,28560867.775,201.52773285,99.7461624145508,8.0014859419482E-7,2.83966723437245E-7,1,0.999253354069792,40.0298881530762,2.00933862187215,14.9699999019504,9.88481288995291E-6,-2.74942582650172E-6,0.25,-3.79863055036897E-7,8.03274898322101E-7,-3.80310150290347E-7,201.4936371,201.5618286,99.7461624145508,99.7461624145508,57.332451885583,20.6193242947731,22.909004,0,0,0,40,4374,204.29795,99.7461624145508,,,,,,,,,,,,,0,,,,-0.0049,,,,,,201.52773285,,,,
,28561005.98,205.0056915,99.7461624145508,6.61600188841767E-7,3.62736114693828E-7,1,0.999253354069792,40.0298881530762,2.00934981902602,14.9699999019504,8.29462031280735E-6,-2.97774150393493E-6,0.25,-3.75819874525246E-7,6.64167536460623E-7,-3.763717625548E-7,205.0056915,205.0056915,99.7461624145508,99.7461624145508,57.1753445532176,20.6236859361137,22.909004,0,0,0,40,4374,207.74805,99.7461624145508,,,,,,,,,,,,,0,,,,-0.0049,,,,,,205.0056915,,,,
,28561147.25,208.5219269,99.7461624145508,8.21957432608182E-7,3.34777584041561E-7,1,0.999253354069792,40.0298881530762,1.98540617762021,14.919999986887,9.90503626955032E-6,-2.03557839574948E-6,0.25,-3.23157139148489E-7,8.24896519386501E-7,-3.23349954452653E-7,208.5219269,208.5219269,99.7461624145508,99.7461624145508,57.1081245005637,20.6091194291039,23.288654,0,0,0,40,4374,211.28725,99.7461624145508,,,,,,,,,,,,,0,,,,0,,,,,,208.5219269,,,,
,28561287.92,212.0457764,99.7461624145508,8.28595350640464E-7,2.98047772390437E-7,1,0.999253354069792,40.0298881530762,1.98545504901995,14.919999986887,1.00220283391017E-5,-2.27074274425541E-6,0.25,-3.45157122859475E-7,8.31474262508702E-7,-3.45389842640644E-7,212.0457764,212.0457764,99.7461624145508,99.7461624145508,57.0471574760637,20.6109247455742,22.909004,0,0,0,40,4374,214.809,99.7461624145508,,,,,,,,,,,,,0,,,,0.0049,,,,,,212.0457764,,,,
,28561430.2,215.5679474,99.7461624145508,8.05889996142963E-7,3.70766894176001E-7,1,0.999253354069792,40.0298881530762,1.98526993441673,14.919999986887,9.53385317925225E-6,-9.89794027338644E-7,0.25,-2.27653019017315E-7,8.08483513954619E-7,-2.27538052320907E-7,215.5679474,215.5679474,99.7461624145508,99.7461624145508,57.0455942190253,20.6149465207646,23.668306,0,0,0,40,4374,218.38745,99.7461624145508,,,,,,,,,,,,,0,,,,-0.00245,,,,,,215.5679474,,,,
,28561568.64,219.0480347,99.7461624145508,6.64365435114377E-7,2.92909394630602E-7,1,0.999253354069792,40.0298881530762,2.00938579753048,14.8799996823072,7.80573196368936E-6,4.25169226755905E-9,0.25,-1.14933281267528E-7,6.66352856440171E-7,-1.14623280449327E-7,219.0480347,219.0480347,99.7461624145508,99.7461624145508,57.1003082153714,20.6160652968661,22.909004,0,0,0,40,4374,221.8425,99.7461624145508,,,,,,,,,,,,,0,,,,-0.0049,,,,,,219.0480347,,,,
,28561709.595,222.5569153,99.7461624145508,4.6409914296287E-7,4.24564600791851E-7,1,0.999253354069792,40.0298881530762,2.0093890586755,14.8799996823072,5.95247742229841E-6,-2.88028739148521E-6,0.25,-3.33077319005787E-7,4.65667871507884E-7,-3.33544129096916E-7,222.5569153,222.5569153,99.7461624145508,99.7461624145508,57.1933220091599,20.6192952555295,22.909004,0,0,0,40,4374,225.384,99.7461624145508,,,,,,,,,,,,,0,,,,0.00245,,,,,,222.5569153,,,,
,28561850.28,226.04776,99.7461624145508,5.44560882908786E-7,3.41490915929146E-7,1,0.999253354069792,40.0298881530762,2.00956896424273,14.8799996823072,7.07610272240172E-6,-3.90940843818545E-6,0.25,-4.37272500812675E-7,5.46372761339946E-7,-4.37903541864862E-7,226.04776,226.04776,99.7461624145508,99.7461624145508,57.1018714724099,20.6195604973188,23.288654,0,0,0,40,4374,228.90405,99.7461624145508,,,,,,,,,,,,,0,,,,0,,,,,,226.04776,,,,
,28561991.1,229.5621338,99.7461624145508,8.14741726767698E-7,4.24019423387438E-7,1,0.999253354069792,40.0298881530762,2.00954090854467,14.8200001567602,9.89693203493843E-6,-1.88064550152338E-6,0.25,-3.06279038975748E-7,8.17029250320005E-7,-3.062993126657E-7,229.5621338,229.5621338,99.7461624145508,99.7461624145508,57.0330881627176,20.6166911914686,23.668306,0,0,0,40,4374,232.4252,99.7461624145508,,,,,,,,,,,,,0,,,,-0.0049,,,,,,229.5621338,,,,
,28562130.315,233.0524292,99.7461624145508,7.16955751998345E-7,4.05237349153084E-7,1,0.999253354069792,40.0298881530762,2.00946237682474,14.8200001567602,8.93265271761765E-6,-2.95146695130693E-6,0.25,-3.83243440224742E-7,7.18978986519662E-7,-3.83507479000491E-7,233.0524292,233.0524292,99.7461624145508,99.7461624145508,57.180034324333,20.6210290545532,23.288654,0,0,0,40,4374,235.92825,99.7461624145508,,,,,,,,,,,,,0,,,,0,,,,,,233.0524292,,,,
,28562269.815,236.5188751,99.7461624145508,5.78888055524882E-7,2.75993036646492E-7,1,0.999253354069792,40.0298881530762,2.00923365822398,14.8200001567602,6.75946652142661E-6,2.18902685600995E-7,0.25,-8.12175589971718E-8,5.80248501651453E-7,-8.08941750320865E-8,236.5188751,236.5188751,99.7461624145508,99.7461624145508,57.129228470583,20.6214566025764,23.668306,0,0,0,40,4374,239.4257,99.7461624145508,,,,,,,,,,,,,0,,,,0.00245,,,,,,236.5188751,,,,
,28562389.865,239.5259552,99.7461624145508,7.90463723423171E-7,4.39271909826655E-7,1,0.999253354069792,40.0298881530762,2.00920336033625,14.7799998521805,9.45960003297086E-6,-1.03143974652069E-6,0.25,-2.27606820481861E-7,7.92337374988791E-7,-2.27411777681102E-7,239.5259552,239.5259552,99.7461624145508,99.7461624145508,56.7923465787945,20.6193245760247,23.668306,0,0,0,40,4374,242.4526,99.7461624145508,,,,,,,,,,,,,0,,,,-0.00245,,,,,,239.5259552,,,,
,28562531.03,243.01960755,99.7461624145508,4.4414900052184E-7,3.0310351496634E-7,1,0.999253354069792,40.0298881530762,2.00903979618431,14.7799998521805,5.742415401506E-6,-3.04881745005591E-6,0.25,-3.44577429538335E-7,4.45328397719577E-7,-3.44892429259683E-7,242.9943695,243.0448456,99.7461624145508,99.7461624145508,57.1980117802753,20.6241782410519,23.668306,0,0,0,40,4374,245.98265,99.7461624145508,,,,,,,,,,,,,0,,,,0.00245,,,,,,243.01960755,,,,
,28562669.995,246.5038605,99.7461624145508,2.99670659695677E-7,3.51347349463438E-7,1,0.999253354069792,40.0298881530762,2.00917383469893,14.7799998521805,3.63941338321768E-6,-7.0323008684902E-7,0.25,-1.13685558771975E-7,3.00327968368597E-7,-1.13650698514181E-7,246.5038605,246.5038605,99.7461624145508,99.7461624145508,57.1737812961791,20.6227723559263,23.668306,0,0,0,40,4374,249.4754,99.7461624145508,,,,,,,,,,,,,0,,,,0.0049,,,,,,246.5038605,,,,
,28562811.775,250.00881195,99.7461624145508,2.96547942028795E-7,3.82162610288918E-7,1,0.999253354069792,40.0298881530762,1.98525273158899,14.7299999371171,3.69296551031002E-6,-1.45409517021144E-6,0.25,-1.8051671906725E-7,2.97215663247468E-7,-1.80591888395712E-7,249.9778137,250.0398102,99.7461624145508,99.7461624145508,56.9869720800829,20.6137732306798,24.047956,0,0,0,40,4374,253.0339,99.7461624145508,,,,,,,,,,,,,0,,,,0.00245,,,,,,250.00881195,,,,
,28562951.835,253.5170288,99.7461624145508,6.3123278022449E-7,3.32619312860981E-7,1,0.999253354069792,40.0298881530762,1.98511073369607,14.7299999371171,6.4398208776061E-6,5.09143245349812E-6,0.25,3.42633914929325E-7,6.31987914517622E-7,3.43699003790353E-7,253.5170288,253.5170288,99.7461624145508,99.7461624145508,57.2589788047753,20.6216985636558,23.668306,0,0,0,40,4374,256.5362,99.7461624145508,,,,,,,,,,,,,0,,,,0,,,,,,253.5170288,,,,
,28563093.655,257.0460815,99.7461624145508,5.95452875853032E-7,4.08226006669294E-7,1,0.999253354069792,40.0298881530762,1.98518284171482,14.7299999371171,7.32003910207726E-6,-2.38232064585166E-6,0.25,-3.14799424382812E-7,5.96598110672334E-7,-3.14804057850242E-7,257.0460815,257.0460815,99.7461624145508,99.7461624145508,57.0221453634483,20.6219245042722,23.668306,0,0,0,40,4374,260.0856,99.7461624145508,,,,,,,,,,,,,0,,,,0.00245,,,,,,257.0460815,,,,
,28563232.54,260.5015869,99.7461624145508,6.9450389619263E-7,3.60891334774843E-7,1,0.999253354069792,40.0298881530762,2.00916039937967,14.6800000220537,8.4857462213399E-6,-1.94955836300402E-6,0.25,-2.91582805744626E-7,6.95691109254189E-7,-2.9144720331387E-7,260.5015869,260.5015869,99.7461624145508,99.7461624145508,56.8939582862945,20.6114044483305,23.668306,0,0,0,40,4374,263.5518,99.7461624145508,,,,,,,,,,,,,0,,,,-0.0049,,,,,,260.5015869,,,,
,28563373.43,264.026886,99.7461624145508,8.05684013474968E-7,3.99205701665681E-7,1,0.999253354069792,40.0298881530762,2.00908803727778,14.6800000220537,8.56090201830437E-6,5.13171309809359E-6,0.25,3.10965285146594E-7,8.06460061094815E-7,3.11971868820847E-7,264.026886,264.026886,99.7461624145508,99.7461624145508,57.2449094914291,20.6216372149337,24.047956,0,0,0,40,4374,267.0826,99.7461624145508,,,,,,,,,,,,,0,,,,0,,,,,,264.026886,,,,
,28563514.455,267.5245056,99.7461624145508,6.28319192617816E-7,3.78549066417001E-7,1,0.999253354069792,40.0298881530762,2.00933338976894,14.6800000220537,7.28622573452781E-6,4.83327734988427E-7,0.25,-6.64756563492807E-8,6.2908118732985E-7,-6.60785821110063E-8,267.5245056,267.5245056,99.7461624145508,99.7461624145508,57.1315733561406,20.6245160068942,24.047956,0,0,0,40,4374,270.6023,99.7461624145508,,,,,,,,,,,,,0,,,,-0.0049,,,,,,267.5245056,,,,
,28563653.07,271.005127,99.7461624145508,1.61533415051937E-7,4.11363719134962E-7,1,0.999253354069792,40.0298881530762,1.97091385048719,14.6300001069903,2.23097621950019E-6,-2.14076729063269E-6,0.25,-2.19513402876483E-7,1.61858897806431E-7,-2.19615248463647E-7,271.005127,271.005127,99.7461624145508,99.7461624145508,56.8368994043906,20.6207794394951,23.668306,0,0,0,40,4374,274.07235,99.7461624145508,,,,,,,,,,,,,0,,,,0,,,,,,271.005127,,,,
,28563794.51,274.5132446,99.7461624145508,7.47254217548804E-7,3.56532520434218E-7,1,0.999253354069792,40.0298881530762,1.98534983801358,14.6300001069903,8.15293752520071E-6,2.9428486526191E-6,0.25,1.31951056085257E-7,7.47818058211879E-7,1.32612362404062E-7,274.5132446,274.5132446,99.7461624145508,99.7461624145508,56.9009929429675,20.614305134659,24.047956,0,0,0,40,4374,277.6213,99.7461624145508,,,,,,,,,,,,,0,,,,0,,,,,,274.5132446,,,,
,28563935.58,278.0231934,99.7461624145508,3.46590057701332E-7,3.65110029232108E-7,1,0.999253354069792,40.0298881530762,1.98532198121678,14.6300001069903,4.78526425604442E-6,-4.42988162090963E-6,0.25,-4.5371577118977E-7,3.47178415168145E-7,-4.53810628063557E-7,278.0231934,278.0231934,99.7461624145508,99.7461624145508,57.281646031833,20.61718055575,24.047956,0,0,0,40,4374,281.1346,99.7461624145508,,,,,,,,,,,,,0,,,,0.0049,,,,,,278.0231934,,,,
,28564075.32,281.5303955,99.7461624145508,5.6455294958014E-7,3.65363529023251E-7,1,0.999253354069792,40.0298881530762,2.00950089408213,14.5699996501207,7.05143391266896E-6,-2.49400961518353E-6,0.25,-3.16942856264682E-7,5.65133912616718E-7,-3.1674374543684E-7,281.5303955,281.5303955,99.7461624145508,99.7461624145508,57.1980117802753,20.6221138494911,24.047956,0,0,0,40,4374,284.6273,99.7461624145508,,,,,,,,,,,,,0,,,,0.0049,,,,,,281.5303955,,,,
,28564218.235,285.06004335,99.7461624145508,5.1825686000798E-7,3.45803344651167E-7,1,0.999253354069792,40.0298881530762,2.00947458339932,14.5699996501207,6.15027373748567E-6,-4.31210956200661E-7,0.25,-1.27698655912767E-7,5.18607788785021E-7,-1.27402063014294E-7,285.0291443,285.0909424,99.7461624145508,99.7461624145508,57.1815975813714,20.6235655723294,24.047956,0,0,0,40,4374,288.2233,99.7461624145508,,,,,,,,,,,,,0,,,,-0.0049,,,,,,285.06004335,,,,
,28564357.63,288.5472717,99.7461624145508,8.69725299295381E-7,3.84026502958585E-7,1,0.999253354069792,40.0298881530762,2.0096194164772,14.5699996501207,1.09700952185734E-5,-4.47161283939568E-6,0.25,-5.43623547008906E-7,8.70429601450358E-7,-5.43233024351685E-7,288.5472717,288.5472717,99.7461624145508,99.7461624145508,57.2331850636407,20.6222058211781,24.047956,0,0,0,40,4374,291.702,99.7461624145508,,,,,,,,,,,,,0,,,,0.0049,,,,,,288.5472717,,,,
,28564477.455,291.5038452,99.7461624145508,6.45977033195958E-7,2.93075571807504E-7,1,0.999253354069792,40.0298881530762,2.00959797751381,14.5100001245737,8.3077856926871E-6,-4.24929026374423E-6,0.25,-4.8535364598058E-7,6.46483705423372E-7,-4.85048686793881E-7,291.5038452,291.5038452,99.7461624145508,99.7461624145508,56.9056827140829,20.6121064411417,24.427608,0,0,0,40,4374,294.7117,99.7461624145508,,,,,,,,,,,,,0,,,,0.00245,,,,,,291.5038452,,,,
,28564619.89,295.0646667,99.7461624145508,4.76429257767791E-7,3.54538048239628E-7,1,0.999253354069792,40.0298881530762,2.00951871909257,14.5100001245737,5.22693902194577E-6,2.0566817190906E-6,0.25,9.82192071132032E-8,4.76433705376646E-7,9.85522614811654E-8,295.0646667,295.0646667,99.7461624145508,99.7461624145508,57.0659165605253,20.6178570568117,24.427608,0,0,0,40,4374,298.2733,99.7461624145508,,,,,,,,,,,,,0,,,,0,,,,,,295.0646667,,,,
,28564760.065,298.542572,99.7461624145508,3.73964768800509E-7,4.14618331834462E-7,1,0.999253354069792,40.0298881530762,2.00964296800201,14.5100001245737,3.90560137628875E-6,2.75090914612472E-6,0.25,1.77009434357532E-7,3.73856605816944E-7,1.77260088923684E-7,298.542572,298.542572,99.7461624145508,99.7461624145508,57.2136443506599,20.6177462299986,24.427608,0,0,0,40,4374,301.7824,99.7461624145508,,,,,,,,,,,,,0,,,,0.0049,,,,,,298.542572,,,,
,28564900.04,302.0369263,99.7461624145508,5.58760146023435E-7,4.32625623173874E-7,1,0.999253354069792,40.0298881530762,1.99677669013334,14.4600002095103,6.7996509461381E-6,-1.68995780616129E-6,0.25,-2.46279628771215E-7,5.58863434437959E-7,-2.45891144616721E-7,302.0369263,302.0369263,99.7461624145508,99.7461624145508,57.1636201254291,20.6048004700927,24.807261,0,0,0,40,4374,305.2957,99.7461624145508,,,,,,,,,,,,,0,,,,0.00245,,,,,,302.0369263,,,,
,28565040.2,305.500946,99.7461624145508,9.46967734918683E-7,4.57719975239324E-7,1,0.999253354069792,40.0298881530762,1.99673361547889,14.4600002095103,1.06368106576367E-5,2.24668018586244E-6,0.25,3.46960723150171E-8,9.46732214186745E-7,3.52958342950876E-8,305.500946,305.500946,99.7461624145508,99.7461624145508,57.2527257766214,20.6119219355087,24.047956,0,0,0,40,4374,308.81185,99.7461624145508,,,,,,,,,,,,,0,,,,0,,,,,,305.500946,,,,
,28565182.925,309.05482485,99.7461624145508,5.28963810706661E-7,3.10977266273209E-7,1,0.999253354069792,40.0298881530762,1.99695420936134,14.4600002095103,6.34229285991315E-6,-1.05894554634893E-6,0.25,-1.85310413995492E-7,5.28895160072977E-7,-1.84910457382518E-7,309.0259705,309.0836792,99.7461624145508,99.7461624145508,57.0323065341983,20.6114946302057,24.807261,0,0,0,40,4374,312.3741,99.7461624145508,,,,,,,,,,,,,0,,,,0,,,,,,309.05482485,,,,
,28565324.005,312.552124,99.7461624145508,-8.22094001154239E-8,3.96699229871289E-7,1,0.999253354069792,40.0298881530762,1.99698328125259,14.4100002944469,-1.24529408816544E-7,-4.80629224844978E-6,0.25,-4.10989973229878E-7,-8.19135952990889E-8,-4.1084589013455E-7,312.552124,312.552124,99.7461624145508,99.7461624145508,57.1980117802753,20.6049671595066,24.427608,0,0,0,40,4374,315.9234,99.7461624145508,,,,,,,,,,,,,0,,,,0,,,,,,312.552124,,,,
,28565461.67,316.0085144,99.7461624145508,2.30096596251006E-7,3.7259258318662E-7,1,0.999253354069792,40.0298881530762,1.99700679441251,14.4100002944469,3.1789353236657E-6,-2.88931741746E-6,0.25,-2.95512109222163E-7,2.30141311011498E-7,-2.95193572791057E-7,316.0085144,316.0085144,99.7461624145508,99.7461624145508,57.1182856713137,20.6069168735346,25.186911,0,0,0,40,4374,319.3929,99.7461624145508,,,,,,,,,,,,,0,,,,0,,,,,,316.0085144,,,,
,28565603.605,319.51028445,99.7461624145508,1.50204158119133E-7,3.54143840428505E-7,1,0.999253354069792,40.0298881530762,1.99701427269124,14.4100002944469,2.44620675630194E-6,-4.02961731498382E-6,0.25,-3.82612433359443E-7,1.50328832952662E-7,-3.82245056768181E-7,319.4844666,319.5361023,99.7461624145508,99.7461624145508,57.2019199228714,20.609761245776,24.807261,0,0,0,40,4374,322.9147,99.7461624145508,,,,,,,,,,,,,0,,,,0,,,,,,319.51028445,,,,
,28565744.7,323.017395,99.7461624145508,1.62600848273203E-7,4.31449553863869E-7,1,0.999253354069792,40.0298881530762,1.99684878652804,14.3499998375773,1.6768165270622E-6,1.24335838631212E-6,0.25,8.18898016664552E-8,1.62414325052628E-7,8.19184436203326E-8,323.017395,323.017395,99.7461624145508,99.7461624145508,56.8580033744099,20.6049472349951,24.807261,0,0,0,40,4374,326.4785,99.7461624145508,,,,,,,,,,,,,0,,,,0,,,,,,323.017395,,,,
,28565886.74,326.519043,99.7461624145508,3.07765976496695E-7,4.06006635519572E-7,1,0.999253354069792,40.0298881530762,1.99681650852974,14.3499998375773,4.60208450891661E-6,-5.89619058878799E-6,0.25,-5.75254726592377E-7,3.07810175816426E-7,-5.74515768635027E-7,326.519043,326.519043,99.7461624145508,99.7461624145508,57.2785195177561,20.6088109446547,24.807261,0,0,0,40,4374,330.018,99.7461624145508,,,,,,,,,,,,,0,,,,0,,,,,,326.519043,,,,
,28566027.61,330.0404968,99.7461624145508,6.43236624424583E-7,3.95599430420328E-7,1,0.999253354069792,40.0298881530762,1.99678526119761,14.3499998375773,7.79181588603942E-6,-1.78222261768391E-6,0.25,-2.69187561842316E-7,6.42693893261696E-7,-2.68516737517438E-7,330.0404968,330.0404968,99.7461624145508,99.7461624145508,57.0065127930637,20.6100708719828,24.427608,0,0,0,40,4374,333.57595,99.7461624145508,,,,,,,,,,,,,0,,,,0.00245,,,,,,330.0404968,,,,
,28566168.22,333.5536499,99.7461624145508,7.57190746471614E-7,3.75623164434838E-7,1,0.999253354069792,40.0298881530762,1.99700994398145,14.2900003120303,9.72604364138434E-6,-5.29704633667663E-6,0.25,-6.00111368435783E-7,7.56621872689378E-7,-5.98945135509675E-7,333.5536499,333.5536499,99.7461624145508,99.7461624145508,56.7931282073137,20.6094407177213,24.807261,0,0,0,40,4374,337.0837,99.7461624145508,,,,,,,,,,,,,0,,,,-0.00245,,,,,,333.5536499,,,,
,28566308.915,337.047821,99.7461624145508,5.19400690345769E-7,3.88221741792347E-7,1,0.999253354069792,40.0298881530762,1.99683302358507,14.2900003120303,5.49029404555437E-6,3.18113226608774E-6,0.25,1.91761692761661E-7,5.18598958308251E-7,1.91804353752271E-7,337.047821,337.047821,99.7461624145508,99.7461624145508,56.8079791491791,20.6138604059529,25.186911,0,0,0,40,4374,340.6046,99.7461624145508,,,,,,,,,,,,,0,,,,-0.0049,,,,,,337.047821,,,,
,28566449.67,340.5348511,99.7461624145508,4.47608479147342E-8,3.64116499181569E-7,1,0.999253354069792,40.0298881530762,1.99702806519078,14.2900003120303,4.55465087018012E-7,3.76152446744173E-7,0.25,2.556018895514E-8,4.46813767512863E-8,2.55484964245487E-8,340.4998169,340.5698853,99.7461624145508,99.7461624145508,57.126101956506,20.6124845269254,24.807261,0,0,0,40,4374,344.145,99.7461624145508,,,,,,,,,,,,,0,,,,-0.0049,,,,,,340.5348511,,,,
,28566569.325,343.5308533,99.7461624145508,9.53854950331738E-7,4.49789118756275E-7,1,0.999253354069792,40.0298881530762,1.99719467364566,14.2299998551607,1.23465094612721E-5,-7.23483356748578E-6,0.25,-8.05878494813552E-7,9.52826315512698E-7,-8.04089948194376E-7,343.5308533,343.5308533,99.7461624145508,99.7461624145508,56.9306948266983,20.6065690581218,24.807261,0,0,0,40,4374,347.1478,99.7461624145508,,,,,,,,,,,,,0,,,,-0.00245,,,,,,343.5308533,,,,
,28566712.765,347.0681,99.7461624145508,-4.22169850086276E-9,4.97872688421358E-7,1,0.999253354069792,40.0298881530762,1.99711486739855,14.2299998551607,9.21955522869616E-7,-5.60809861368141E-6,0.25,-4.95996537799569E-7,-3.93853312485335E-9,-4.95168762215142E-7,347.0381775,347.0980225,99.7461624145508,99.7461624145508,57.1049979864868,20.6070682300471,25.186911,0,0,0,40,4374,350.7385,99.7461624145508,,,,,,,,,,,,,0,,,,-0.0049,,,,,,347.0681,,,,
,28567087.815,349.7817688,99.7461624145508,5.71261806217336E-7,3.39027952284847E-7,1,0.999253354069792,40.0298881530762,1.99760991168415,14.2299998551607,6.90379619852514E-6,-1.50083833902857E-6,0.25,-2.31829502984633E-7,5.70382270065074E-7,-2.31102208419867E-7,349.7817688,349.7817688,99.7461624145508,99.7461624145508,57.1487691835637,20.6054460416179,25.186911,0,0,0,40,4369,350.7118,99.7461624145508,,,,,,,,,,,,,0,,,,-0.0049,,,,,,349.7817688,,,,