File: data/monolayers/nanoparticles/Ol_CoFe_C/vsm/data_disorderedWafer/DD227_HYST_20K.DAT
[Header]
; VSM Data File (default extension .dat)
; Copyright (c) 2003-2013, Quantum Design, Inc. All rights reserved.
TITLE,
FILEOPENTIME,28478126.45,11/26/2018,10:36 pm
BYAPP,VSM,2.0,2.0
INFO,PPMS VSM Option Release 1.4.10 Build 1,APPNAME
INFO,Quantum Design Linear Motor Servo Controller,MOTOR_MODULE_NAME
INFO,3101-100 M1,MOTOR_HW_VERSION
INFO,MMC1014,MOTOR_SERIAL_NUMBER
INFO,SRV No X-over 01.03.11,MOTOR_SOFTWARE_VERSION
INFO,Quantum Design VSM Detection Module,VSM_MODULE_NAME
INFO,3101-150 F0,VSM_HW_VERSION
INFO,VSM707,VSM_SERIAL_NUMBER
INFO,VSM No X-over 01.02.05 May 20 2008 13:51:47,VSM_SOFTWARE_VERSION
INFO,704,PREAMP_SERIAL_NUMBER
INFO,822,COIL_SERIAL_NUMBER
INFO,0,MOMENT_UNITS
INFO,CoFe2O4 FeO,SAMPLE_MATERIAL
INFO,disordered monolayer,SAMPLE_COMMENT
INFO,25.46,SAMPLE_MASS
INFO,,SAMPLE_VOLUME
INFO,,SAMPLE_MOLECULAR_WEIGHT
INFO,,SAMPLE_SIZE
INFO,,SAMPLE_SHAPE
DATATYPE,COMMENT,1
DATATYPE,TIME,2
STARTUPAXIS,X,2
STARTUPAXIS,Y1,5
[Data]
Comment,Time Stamp (sec),Temperature (K),Magnetic Field (Oe),Moment (emu),M. Std. Err. (emu),Transport Action,Averaging Time (sec),Frequency (Hz),Peak Amplitude (mm),Center Position (mm),Coil Signal' (mV),Coil Signal" (mV),Range (mV),M. Quad. Signal (emu),M. Raw' (emu),M. Raw" (emu),Min. Temperature (K),Max. Temperature (K),Min. Field (Oe),Max. Field (Oe),Mass (grams),Motor Lag (deg),Pressure (Torr),VSM Status (code),Motor Status (code),Measure Status (code),Measure Count,PPMS Status (code),System Temp. (K),System Field (Oe),Sample Position (deg),Bridge 1 Resistance (ohms),Bridge 1 Excitation (에),Bridge 2 Resistance (ohms),Bridge 2 Excitation (에),Bridge 3 Resistance (ohms),Bridge 3 Excitation (에),Bridge 4 Resistance (ohms),Bridge 4 Excitation (에),Signal 1 Vin (V),Signal 2 Vin (V),Digital Inputs (code),Drive 1 Iout (mA),Drive 1 Ipower (W),Drive 2 Iout (mA),Drive 2 Ipower (W),Pressure (),Map 20 (),Map 21 (),Map 22 (),Map 23 (),Map 24 (),Map 25 (),Map 26 (),Map 27 (),Map 28 (),Map 29 ()
,28478141.92,19.998848,-0.274027913808823,,,2,,,,15.7600000751019,,,,,,,19.998848,19.998848,-0.274027913808823,-0.274027913808823,,,12.278775,,,,-99999999,4369,20.0154,-0.274027913808823,,,,,,,,,,,,,,,,,,,,,,,19.998848,,,,
,28478294.03,20.01206015,4603.47094726562,-6.5937276664838E-6,3.11608642393522E-7,1,0.999253354069792,40.0298881530762,1.99766830590311,15.7500002533197,-7.33207330926251E-5,-1.76739200748521E-5,0.25,-3.99351035005851E-7,-6.55541889501488E-6,-4.309401250813E-7,20.0115547,20.0125656,4595.95849609375,4610.9833984375,57.0182372208522,20.6182809571394,12.658426,0,0,0,40,4449,20.01905,4603.47094726562,,,,,,,,,,,,,0,,,,0.00245,,,,,,20.01206015,,,,
,28478396,19.995636,9697.0986328125,-2.18381975876055E-5,3.64997036040901E-7,1,0.999253354069792,40.0298881530762,1.99755692225155,15.7500002533197,-0.000245176991406244,-4.58344755231971E-5,0.25,-1.8337357798694E-7,-2.17252983928328E-5,-3.02386703394307E-7,19.995636,19.995636,9692.015625,9702.181640625,57.1432977839291,20.6184216945195,13.038077,0,0,0,40,4449,20.0027,9697.0986328125,,,,,,,,,,,,,0,,,,0,,,,,,19.995636,,,,
,28478501.46,20.0004616,14969.3403320313,-3.71607938779368E-5,3.7424147951882E-7,1,0.999253354069792,40.0298881530762,1.9973921844245,15.7500002533197,-0.000416837321690966,-8.0944302889729E-5,0.25,-5.57654902005883E-7,-3.69838691612554E-5,-7.73307856824989E-7,20.0004616,20.0004616,14959.298828125,14979.3818359375,57.3371416566984,20.6189227224567,12.658426,0,0,0,40,4449,20.00745,14969.3403320313,,,,,,,,,,,,,0,,,,0.00245,,,,,,20.0004616,,,,
,28478606.045,20.002882,20196.2509765625,-5.23887740252566E-5,5.02739794857908E-7,1,0.999253354069792,40.0298881530762,1.9974054262427,15.7500002533197,-0.000588592961105207,-0.000110542656683736,0.25,-4.45395237091419E-7,-5.2166927371663E-5,-7.69639327443337E-7,20.002882,20.002882,20191.248046875,20201.25390625,57.3418314278138,20.6209226353796,13.038077,0,0,0,40,4449,20.0085,20196.2509765625,,,,,,,,,,,,,0,,,,0,,,,,,20.002882,,,,
,28478709.26,20.0042686,25353.638671875,-6.78762792026208E-5,4.58241376146964E-7,1,0.999253354069792,40.0298881530762,1.99738937189098,15.7500002533197,-0.000762761344745969,-0.000144541424912107,0.25,-6.66971156489975E-7,-6.7623059615499E-5,-1.10800310061239E-6,20.0042686,20.0042686,25343.712890625,25363.564453125,57.1722180391407,20.6215727289509,13.038077,0,0,0,40,4449,20.00545,25353.638671875,,,,,,,,,,,,,0,,,,0.00245,,,,,,20.0042686,,,,
,28478812.745,20.0014172,30528.6328125,-8.36620729848233E-5,5.69172721890407E-7,1,0.999253354069792,40.0298881530762,1.99730056419839,15.7500002533197,-0.000941520116807518,-0.000173235457133798,0.25,-3.55277628007319E-7,-8.33978150413643E-5,-9.22990171723895E-7,20.0014172,20.0014172,30521.203125,30536.0625,57.2433462343907,20.6234540020936,13.038077,0,0,0,40,4449,20.0013,30528.6328125,,,,,,,,,,,,,0,,,,-0.00245,,,,,,20.0014172,,,,
,28478916.725,20.0025959,35723.66796875,-9.92991935017077E-5,5.40900979146843E-7,1,0.999253354069792,40.0298881530762,1.99723551335602,15.7500002533197,-0.00111905593723583,-0.000200286827828084,0.25,8.20313281942066E-8,-9.9043449254245E-5,-6.15043237113241E-7,20.0025959,20.0025959,35718.625,35728.7109375,57.3809128537753,20.6217867126898,12.658426,0,0,0,40,4449,19.99975,35723.66796875,,,,,,,,,,,,,0,,,,-0.00245,,,,,,20.0025959,,,,
,28479022.59,20.0017395,41016.044921875,-0.000115030970399864,5.83898190530874E-7,1,0.999253354069792,40.0298881530762,1.99722274603722,15.7500002533197,-0.00129629010590064,-0.000236462493372372,0.25,-2.6823873513518E-7,-0.000114796483190383,-1.09490479525441E-6,20.0017395,20.0017395,41011.19921875,41020.890625,57.2832092888714,20.6215902037133,12.658426,0,0,0,40,4449,19.998,41016.044921875,,,,,,,,,,,,,0,,,,0,,,,,,20.0017395,,,,
,28479123.535,20.0028534,46061.158203125,-0.000130342518814943,6.75200313506931E-7,1,0.999253354069792,40.0298881530762,1.99732281570468,15.7500002533197,-0.00146880885031042,-0.000272947108317768,0.25,-7.1913081564536E-7,-0.000130142424618516,-1.67107393053945E-6,20.0028534,20.0028534,46058.51171875,46063.8046875,57.1792526958137,20.6211402490316,13.417728,0,0,0,40,4449,19.9954,46061.158203125,,,,,,,,,,,,,0,,,,0,,,,,,20.0028534,,,,
,28479219.145,20.0012474,50838.890625,-0.000143699841810592,6.02535564049793E-7,1,0.999253354069792,40.0298881530762,1.99733512512629,15.7500002533197,-0.00162128200902051,-0.000294681703542268,0.25,-2.16541014022962E-7,-0.000143553546239407,-1.27797885133434E-6,20.0012474,20.0012474,50831.34375,50846.4375,57.1448610409676,20.6203405683007,13.038077,0,0,0,40,4449,19.99435,50838.890625,,,,,,,,,,,,,0,,,,0,,,,,,20.0012474,,,,
,28479315.105,20.0013733,55636.11328125,-0.000159418286555639,6.38454998205693E-7,1,0.999253354069792,40.0298881530762,1.99725231063522,15.7500002533197,-0.00179635536255117,-0.000343996996237078,0.25,-1.73428283427134E-6,-0.000159320601591384,-2.91798194141084E-6,20.0013733,20.0013733,55628.671875,55643.5546875,57.2988418592561,20.6224457829056,13.038077,0,0,0,40,4449,19.9935,55636.11328125,,,,,,,,,,,,,0,,,,0,,,,,,20.0013733,,,,
,28479410.1,20.0012054,60383.833984375,-0.000174544389221293,7.49818118611109E-7,1,0.999253354069792,40.0298881530762,1.99719189237511,15.7500002533197,-0.00196855870092801,-0.000371659909723349,0.25,-1.44251132524334E-6,-0.000174519803742876,-2.74159914059421E-6,20.0012054,20.0012054,60381.296875,60386.37109375,57.0924919301791,20.6195098183171,13.038077,0,0,0,40,4449,19.9932,60383.833984375,,,,,,,,,,,,,0,,,,0,,,,,,20.0012054,,,,
,28479505.55,20.00167085,65154.38671875,-0.000189597323242211,9.31705943190682E-7,1,0.999253354069792,40.0298881530762,1.99717175953181,15.7500002533197,-0.0021405976642536,-0.00039634952012758,0.25,-9.03391570662805E-7,-0.000189658063256323,-2.31231330098826E-6,20.0016594,20.0016823,65144.34765625,65164.42578125,57.2027015513907,20.6205967986565,13.038077,0,0,0,40,4449,19.9921,65154.38671875,,,,,,,,,,,,,0,,,,-0.0049,,,,,,20.00167085,,,,
,28479600.705,20.0010643,69909.46875,-0.000204370934768142,7.00678056965062E-7,1,0.999253354069792,40.0298881530762,1.99719702877799,15.7500002533197,-0.00230715457450745,-0.000434186705395617,0.25,-1.58096875895478E-6,-0.00020451630790628,-3.09300279473083E-6,20.0010643,20.0010643,69901.8984375,69917.0390625,57.3910740245253,20.6188332025161,13.038077,0,0,0,40,4449,19.98915,69909.46875,,,,,,,,,,,,,0,,,,0.00245,,,,,,20.0010643,,,,
,28479696.6,20.0021381,74704.82421875,-0.00021884815895951,8.59834485462318E-7,1,0.999253354069792,40.0298881530762,1.99719027626433,15.7500002533197,-0.00247329791285558,-0.000455445793148679,0.25,-8.50189125165093E-7,-0.00021909640857471,-2.45652672487065E-6,20.0021381,20.0021381,74699.8125,74709.8359375,57.2073913225061,20.6195711108531,13.038077,0,0,0,40,4449,19.9885,74704.82421875,,,,,,,,,,,,,0,,,,0.0049,,,,,,20.0021381,,,,
,28479789.9,20.001976,79368.09375,-0.000231887765023096,9.62865447900714E-7,1,0.999253354069792,40.0298881530762,1.99735756111075,15.7500002533197,-0.00261962449772724,-0.000494994479720595,0.25,-1.99621394525888E-6,-0.00023222688566914,-3.68364396863333E-6,20.001976,20.001976,79363.1640625,79373.0234375,57.058100275333,20.618545589744,13.038077,0,0,0,40,4449,19.9859,79368.09375,,,,,,,,,,,,,0,,,,0,,,,,,20.001976,,,,
,28479885.825,20.00268365,84161.60546875,-0.000248894794768444,9.24615244080557E-7,1,0.999253354069792,40.0298881530762,1.99711775398712,15.7500002533197,-0.00281357484700609,-0.000524972859809278,0.25,-1.59500510482927E-6,-0.000249350130666906,-3.38416482260844E-6,20.0025368,20.0028305,84156.5234375,84166.6875,57.2183341217753,20.6187224145779,13.417728,0,0,0,40,4449,19.9841,84161.60546875,,,,,,,,,,,,,0,,,,-0.0049,,,,,,20.00268365,,,,
,28479975.85,20.0014706,88662.12890625,-0.000263493671176043,9.19800574515064E-7,1,0.999253354069792,40.0298881530762,1.99711315585373,15.7500002533197,-0.00297754635559364,-0.000566894545165827,0.25,-2.68148376945793E-6,-0.000264050349363598,-4.55392266438087E-6,20.0014706,20.0014706,88654.5546875,88669.703125,57.1909771236022,20.6157008104743,12.658426,0,0,0,40,4449,19.9827,88662.12890625,,,,,,,,,,,,,0,,,,-0.0049,,,,,,20.0014706,,,,
,28480080.28,20.0017242,87078.4453125,-0.000259158606161137,9.46365067169516E-7,1,0.999253354069792,40.0298881530762,1.99734851589954,15.7500002533197,-0.00293291000021558,-0.000533480982073535,0.25,-5.00576658759053E-7,-0.000259693587303399,-2.34618102000453E-6,20.0017242,20.0017242,87073.453125,87083.4375,57.1925403806407,20.6178850807788,13.038077,0,0,0,40,4449,19.9815,87078.4453125,,,,,,,,,,,,,0,,,,0,,,,,,20.0017242,,,,
,28480170.525,20.0007,82567.38671875,-0.000241836499837624,7.94547146464593E-7,1,0.999253354069792,40.0298881530762,1.99734489286611,15.7500002533197,-0.0027360823413847,-0.000497243074693895,0.25,-4.07705002543451E-7,-0.000242259504540097,-2.15130316001498E-6,20.0007,20.0007,82559.8515625,82574.921875,56.9111541137176,20.6170747106871,12.658426,0,0,0,40,4449,19.98185,82567.38671875,,,,,,,,,,,,,0,,,,-0.00245,,,,,,20.0007,,,,
,28480263.28,19.9986954,77931.0390625,-0.000227616919317221,7.53745603397706E-7,1,0.999253354069792,40.0298881530762,1.99721767408216,15.7500002533197,-0.00257322869562869,-0.000472995384581449,0.25,-8.22680073431147E-7,-0.000227933138445681,-2.48258266469736E-6,19.9986954,19.9986954,77920.9375,77941.140625,57.098744958333,20.6199897157283,12.658426,0,0,0,40,4449,19.9826,77931.0390625,,,,,,,,,,,,,0,,,,0.00245,,,,,,19.9986954,,,,
,28480350.19,19.9992504,73585.0078125,-0.00021561511212157,7.83839576367394E-7,1,0.999253354069792,40.0298881530762,1.99726938340786,15.7500002533197,-0.00243575924351347,-0.000453542842485297,0.25,-1.26302952858375E-6,-0.000215837123153381,-2.84924162444388E-6,19.9992504,19.9992504,73577.578125,73592.4375,57.2558522906984,20.6207469404779,13.417728,0,0,0,40,4449,19.98365,73585.0078125,,,,,,,,,,,,,0,,,,-0.00245,,,,,,19.9992504,,,,
,28480442.615,19.9986877,68964.734375,-0.000201465886791476,7.99008540492581E-7,1,0.999253354069792,40.0298881530762,1.99717234142174,15.7500002533197,-0.00227346066690736,-0.000431800447210448,0.25,-1.89494154842496E-6,-0.00020159050528156,-3.387402372121E-6,19.9986877,19.9986877,68954.734375,68974.734375,57.2722664896022,20.6225929401378,12.658426,0,0,0,40,4449,19.9845,68964.734375,,,,,,,,,,,,,0,,,,-0.00245,,,,,,19.9986877,,,,
,28480535.97,19.9989014,64301.208984375,-0.000186355330275666,5.79896472447734E-7,1,0.999253354069792,40.0298881530762,1.99725578214771,15.7500002533197,-0.00209944245009013,-0.000414393290492227,0.25,-3.08493588998185E-6,-0.000186384467887952,-4.47111238589449E-6,19.9989014,19.9989014,64296.17578125,64306.2421875,57.4559491916215,20.6195546181166,12.658426,0,0,0,40,4449,19.986,64301.208984375,,,,,,,,,,,,,0,,,,0,,,,,,19.9989014,,,,
,28480627.165,19.9984722,59740.6953125,-0.000172130311781133,8.01608901901588E-7,1,0.999253354069792,40.0298881530762,1.99724256045558,15.7500002533197,-0.00194086893888414,-0.000368687451253415,0.25,-1.61560313025605E-6,-0.000172094256445912,-2.89659826408608E-6,19.9984722,19.9984722,59733.10546875,59748.28515625,57.3418314278138,20.6207606176999,13.038077,0,0,0,40,4449,19.98655,59740.6953125,,,,,,,,,,,,,0,,,,-0.0049,,,,,,19.9984722,,,,
,28480720.36,19.9982872,55082.833984375,-0.000158349229285402,6.53874870752005E-7,1,0.999253354069792,40.0298881530762,1.997153245626,15.7500002533197,-0.00178414251967976,-0.000341576083714652,0.25,-1.7160799293235E-6,-0.000158243705355648,-2.8912242841828E-6,19.9982872,19.9982872,55075.359375,55090.30859375,57.261323690333,20.6225451429658,13.038077,0,0,0,40,4449,19.98725,55082.833984375,,,,,,,,,,,,,0,,,,0,,,,,,19.9982872,,,,
,28480815.58,19.9991894,50325.154296875,-0.000142704467227474,6.78899155121471E-7,1,0.999253354069792,40.0298881530762,1.99716782023779,15.7500002533197,-0.00160858343860858,-0.000299571790188605,0.25,-8.33600100656879E-7,-0.000142547215878462,-1.88608435434816E-6,19.9991894,19.9991894,50312.7109375,50337.59765625,57.2925888311022,20.6230930326187,13.417728,0,0,0,40,4449,19.98785,50325.154296875,,,,,,,,,,,,,0,,,,0,,,,,,19.9991894,,,,
,28480906.46,19.9993706,45782.66015625,-0.000127328935463841,7.05294184027674E-7,1,0.999253354069792,40.0298881530762,1.99717578858761,15.7500002533197,-0.00143268802858774,-0.000277818542179995,0.25,-1.69694733704786E-6,-0.000127122527084612,-2.62463604901265E-6,19.9993706,19.9993706,45775.390625,45789.9296875,57.1690915250637,20.6227877577804,12.658426,0,0,0,40,4449,19.98905,45782.66015625,,,,,,,,,,,,,0,,,,0,,,,,,19.9993706,,,,
,28480999.56,19.9995251,41127.427734375,-0.00011388291057276,4.27379902551914E-7,1,0.999253354069792,40.0298881530762,1.99705363027377,15.7500002533197,-0.00128422130879336,-0.000228766907228606,0.25,2.0665078142394E-7,-0.000113655480067314,-6.13068338744517E-7,19.9995251,19.9995251,41117.828125,41137.02734375,57.5200427301984,20.6248649763552,13.417728,0,0,0,40,4449,19.9885,41127.427734375,,,,,,,,,,,,,0,,,,0,,,,,,19.9995251,,,,
,28481093.015,19.9986229,36457.271484375,-9.91498391534653E-5,5.83898485068943E-7,1,0.999253354069792,40.0298881530762,1.99717276414927,15.7500002533197,-0.00111612986187165,-0.000207203812283164,0.25,-5.55193638653975E-7,-9.88976835561716E-5,-1.25228864001064E-6,19.9986229,19.9986229,36449.734375,36464.80859375,57.3863842534099,20.6220037246555,13.417728,0,0,0,40,4449,19.98925,36457.271484375,,,,,,,,,,,,,0,,,,0.0049,,,,,,19.9986229,,,,
,28481185.715,19.9989624,31825.0048828125,-8.44343030077612E-5,5.49767617108664E-7,1,0.999253354069792,40.0298881530762,1.99712379358797,15.7500002533197,-0.000948802662121349,-0.000182956740503679,0.25,-1.07397519738635E-6,-8.41741751340823E-5,-1.64982046495533E-6,19.9989624,19.9989624,31822.58984375,31827.419921875,57.3011867448138,20.6225817487986,13.417728,0,0,0,40,4449,19.9911,31825.0048828125,,,,,,,,,,,,,0,,,,-0.0049,,,,,,19.9989624,,,,
,28481280.08,19.9985332,27109.787109375,-6.93755356329444E-5,4.72807915545134E-7,1,0.999253354069792,40.0298881530762,1.99704327788322,15.7500002533197,-0.000779802314883059,-0.00014672642645757,0.25,-5.85450971817137E-7,-6.91297985165172E-5,-1.04328530091681E-6,19.9985332,19.9985332,27104.71484375,27114.859375,57.434063593083,20.6228426240092,13.038077,0,0,0,40,4449,19.99095,27109.787109375,,,,,,,,,,,,,0,,,,0.0049,,,,,,19.9985332,,,,
,28481375.245,19.9983768,22352.494140625,-5.42190855206302E-5,4.429830674496E-7,1,0.999253354069792,40.0298881530762,1.99703133765483,15.7500002533197,-0.000609775321479348,-0.000111071019816322,0.25,-1.57122780882173E-7,-5.40028597819029E-5,-5.01265070192055E-7,19.9983768,19.9983768,22347.146484375,22357.841796875,57.4215575367753,20.6225732204908,13.797379,0,0,0,40,4449,19.99195,22352.494140625,,,,,,,,,,,,,0,,,,0,,,,,,19.9983768,,,,
,28481469.485,19.9979897,17642.0576171875,-4.1059811203871E-5,4.5993358270282E-7,1,0.999253354069792,40.0298881530762,1.99702790751997,15.7500002533197,-0.000460749474818149,-8.86419607574808E-5,0.25,-5.37376364383904E-7,-4.08747978888992E-5,-7.8369805751474E-7,19.9979897,19.9979897,17639.451171875,17644.6640625,57.5317671579869,20.6233118914476,13.797379,0,0,0,40,4449,19.99265,17642.0576171875,,,,,,,,,,,,,0,,,,0.0049,,,,,,19.9979897,,,,
,28481562.89,19.9979191,12974.7939453125,-2.7082854825015E-5,4.36265258750461E-7,1,0.999253354069792,40.0298881530762,1.99700950220675,15.7500002533197,-0.000303633232127178,-5.92483191827332E-5,0.25,-4.34906765463842E-7,-2.69490184834251E-5,-5.88018907367545E-7,19.9979191,19.9979191,12967.3955078125,12982.1923828125,57.4473512779099,20.6256082630436,13.038077,0,0,0,40,4449,19.9965,12974.7939453125,,,,,,,,,,,,,0,,,,0.0049,,,,,,19.9979191,,,,
,28481652.415,19.9978161,8499.34814453125,-1.39472623984693E-5,3.28477151967869E-7,1,0.999253354069792,40.0298881530762,1.99692669156661,15.7500002533197,-0.000155345764099768,-3.58719023466099E-5,0.25,-7.06504133898802E-7,-1.38706634419602E-5,-7.78199361425038E-7,19.9978161,19.9978161,8489.17578125,8509.5205078125,57.1307917276214,20.6263545457906,13.038077,0,0,0,40,4449,19.99795,8499.34814453125,,,,,,,,,,,,,0,,,,0.00245,,,,,,19.9978161,,,,
,28481745.085,19.9993229,3866.50817871094,-9.46846636074992E-7,2.80167727013413E-7,1,0.999253354069792,40.0298881530762,1.9970546046873,15.7500002533197,-1.03797158883542E-5,-3.35487865845255E-6,0.25,-1.30171346975989E-7,-9.40933366023124E-7,-1.3425195634864E-7,19.9993229,19.9993229,3861.47485351562,3871.54150390625,57.3785679682176,20.626783963718,13.417728,0,0,0,40,4449,19.99835,3866.50817871094,,,,,,,,,,,,,0,,,,-0.0049,,,,,,19.9993229,,,,
,28481836.83,20.0002098,-718.704467773437,1.05965417707511E-5,3.3449914783807E-7,1,0.999253354069792,40.0298881530762,1.99730777872657,15.7500002533197,0.000119237453881931,2.0220310662038E-5,0.25,-8.28242269984172E-8,1.05362929691745E-5,-3.06748571859491E-8,20.0002098,20.0002098,-726.310668945313,-711.098266601562,57.3981086811984,20.6261494130624,13.038077,0,0,0,40,4449,19.9972,-718.704467773437,,,,,,,,,,,,,0,,,,-0.00245,,,,,,20.0002098,,,,
,28481930.08,19.9997559,-5376.27001953125,2.30624132862348E-5,3.3596689826655E-7,1,0.999253354069792,40.0298881530762,1.9971996812809,15.7500002533197,0.000259666749936624,4.346976099618E-5,0.25,-2.3598060119501E-7,2.29380009891321E-5,-1.15277216301001E-7,19.9997559,19.9997559,-5381.26171875,-5371.2783203125,57.3988903097176,20.6256284569586,13.417728,0,0,0,40,4449,19.9974,-5376.27001953125,,,,,,,,,,,,,0,,,,0,,,,,,19.9997559,,,,
,28482025.095,19.9998283,-10124.6762695312,3.50982842948584E-5,3.45429860584169E-7,1,0.999253354069792,40.0298881530762,1.99724563869144,15.7500002533197,0.000394157320987028,7.27893809897434E-5,0.25,2.16481705523237E-7,3.49184634064086E-5,4.09265362519467E-7,19.9998283,19.9998283,-10129.6318359375,-10119.720703125,57.2910255740638,20.6265682629054,13.797379,0,0,0,40,4449,19.99785,-10124.6762695312,,,,,,,,,,,,,0,,,,0,,,,,,19.9998283,,,,
,28482117.955,20.0022564,-14767.3471679687,4.69592540242402E-5,3.82548079883343E-7,1,0.999253354069792,40.0298881530762,1.99720569829016,15.7500002533197,0.000528514125898415,9.20727991383208E-5,0.25,-2.01941329790545E-7,4.67401368370507E-5,7.41405892809122E-8,20.0022564,20.0022564,-14772.4677734375,-14762.2265625,57.3269804859484,20.6284557272458,13.417728,0,0,0,40,4449,19.99725,-14767.3471679687,,,,,,,,,,,,,0,,,,0,,,,,,20.0022564,,,,
,28482212.51,20.00207425,-19491.8837890625,5.90770070415836E-5,5.82171379589544E-7,1,0.999253354069792,40.0298881530762,1.99708985771477,15.7500002533197,0.000664394750956974,0.000120132527132201,0.25,1.0534752270764E-7,5.88252645901866E-5,4.69951821135665E-7,20.0020542,20.0020943,-19499.330078125,-19484.4375,57.555997642083,20.6303152686038,13.038077,0,0,0,40,4449,19.99465,-19491.8837890625,,,,,,,,,,,,,0,,,,0.00245,,,,,,20.00207425,,,,
,28482306.99,20.0016899,-24214.4833984375,7.07494195915229E-5,4.24280485111579E-7,1,0.999253354069792,40.0298881530762,1.99710830540257,15.7500002533197,0.00079557954223405,0.000146547451123761,0.25,3.37716064673549E-7,7.04796254027454E-5,7.94108975203486E-7,20.0016899,20.0016899,-24216.802734375,-24212.1640625,57.5145713305638,20.6305271342505,13.417728,0,0,0,40,4449,19.993,-24214.4833984375,,,,,,,,,,,,,0,,,,0,,,,,,20.0016899,,,,
,28482407.695,20.0018272,-29249.0361328125,8.42795773816085E-5,4.34782580739046E-7,1,0.999253354069792,40.0298881530762,1.99710787765107,15.7500002533197,0.000948002784091138,0.000175875525714654,0.25,4.87434281097366E-7,8.40012130545738E-5,1.05369440525829E-6,20.0018272,20.0018272,-29258.859375,-29239.212890625,57.3996719382368,20.6321543118621,13.038077,0,0,0,40,4449,19.9922,-29249.0361328125,,,,,,,,,,,,,0,,,,0,,,,,,20.0018272,,,,
,28482505.835,20.0019779,-34153.935546875,9.66082941802225E-5,5.0200226887063E-7,1,0.999253354069792,40.0298881530762,1.99716990154566,15.7500002533197,0.00108853265315915,0.000194719827045526,0.25,-8.29518274760523E-8,9.63434275856394E-5,5.8935761829822E-7,20.0019779,20.0019779,-34156.359375,-34151.51171875,57.1776894387753,20.6285719035544,13.417728,0,0,0,40,4449,19.99185,-34153.935546875,,,,,,,,,,,,,0,,,,-0.0049,,,,,,20.0019779,,,,
,28482596.065,20.0010471,-38661.046875,0.000109519099104146,5.18345938030148E-7,1,0.999253354069792,40.0298881530762,1.99713774972143,15.7500002533197,0.00123341170538771,0.000227327194822933,0.25,4.6355468597874E-7,0.000109267145625832,1.24228675854068E-6,20.0010471,20.0010471,-38693.76953125,-38628.32421875,57.4184310226984,20.6310916314711,13.038077,0,0,0,40,4449,19.98985,-38661.046875,,,,,,,,,,,,,0,,,,0,,,,,,20.0010471,,,,
,28482691.535,20.0007839,-43433.52734375,0.000123757600057874,6.32483376890968E-7,1,0.999253354069792,40.0298881530762,1.99711760732546,15.7500002533197,0.00139516436891921,0.000253071907989272,0.25,1.58501683547347E-7,0.000123537629265035,1.05598105266811E-6,20.0007839,20.0007839,-43441.03515625,-43426.01953125,57.4504777919868,20.6291878380026,12.658426,0,0,0,40,4449,19.9893,-43433.52734375,,,,,,,,,,,,,0,,,,-0.00245,,,,,,20.0007839,,,,
,28482786.11,20.0016384,-48160.6796875,0.000138017247576559,6.32134977311006E-7,1,0.999253354069792,40.0298881530762,1.99722306929484,15.7500002533197,0.00155601346342693,0.000286530378722675,0.25,5.31588956258481E-7,0.000137836831669935,1.54527150877784E-6,20.0016384,20.0016384,-48163.21484375,-48158.14453125,57.4793980471984,20.6321671334947,13.038077,0,0,0,40,4449,19.98945,-48160.6796875,,,,,,,,,,,,,0,,,,0,,,,,,20.0016384,,,,
,28482881.13,20.0001736,-52910.681640625,0.000150919202380166,6.64036268618935E-7,1,0.999253354069792,40.0298881530762,1.99712937459833,15.7500002533197,0.00170596685791495,0.000292611960674054,0.25,-1.27379912661983E-6,0.000150807930996048,-1.5439589518666E-7,20.0001736,20.0001736,-52925.64453125,-52895.71875,57.3738781971022,20.632375248564,13.417728,0,0,0,40,4449,19.988,-52910.681640625,,,,,,,,,,,,,0,,,,-0.00245,,,,,,20.0001736,,,,
,28482976.12,20.0001087,-57655.15234375,0.000164297582088063,6.81745555536244E-7,1,0.999253354069792,40.0298881530762,1.99723260480111,15.7500002533197,0.00185842382585704,0.000317173953568814,0.25,-1.52733986521958E-6,0.000164253537916496,-3.04507957457345E-7,20.000103,20.0001144,-57662.61328125,-57647.69140625,57.3902923960061,20.6321463567613,13.038077,0,0,0,40,4449,19.98825,-57655.15234375,,,,,,,,,,,,,0,,,,0,,,,,,20.0001087,,,,
,28483070.445,20.0008373,-62369.908203125,0.0001797535309518,6.62259162105227E-7,1,0.999253354069792,40.0298881530762,1.99713211296414,15.7500002533197,0.0020296404034293,0.000371619225920958,0.25,4.95596689604542E-7,0.00017976858011686,1.83312400998284E-6,20.0008373,20.0008373,-62374.8828125,-62364.93359375,57.3652802833907,20.6317006705542,13.417728,0,0,0,40,4449,19.9874,-62369.908203125,,,,,,,,,,,,,0,,,,-0.0049,,,,,,20.0008373,,,,
,28483164.865,20.0011711,-67090.26953125,0.000196518631964702,7.48536768880584E-7,1,0.999253354069792,40.0298881530762,1.99718968058707,15.7500002533197,0.00221909866608519,0.000411110627371472,0.25,9.58412479591852E-7,0.000196614957421201,2.41649382197211E-6,20.0011711,20.0011711,-67097.6328125,-67082.90625,57.3387049137368,20.6333500013252,13.417728,0,0,0,40,4449,19.9859,-67090.26953125,,,,,,,,,,,,,0,,,,-0.0049,,,,,,20.0011711,,,,
,28483257.755,20.0008888,-71729.76953125,0.000209853671562878,7.38411871355537E-7,1,0.999253354069792,40.0298881530762,1.99715143707655,15.7500002533197,0.00237107840866836,0.000436346203160775,0.25,7.83334749798609E-7,0.000210041125734874,2.33131596235419E-6,20.0008888,20.0008888,-71764.5859375,-71694.953125,57.5403650716984,20.6332021782949,13.417728,0,0,0,40,4449,19.9851,-71729.76953125,,,,,,,,,,,,,0,,,,-0.00245,,,,,,20.0008888,,,,
,28483354.39,20.0006981,-76561.71875,0.000224185799339106,6.57245462703609E-7,1,0.999253354069792,40.0298881530762,1.99713513873308,15.7500002533197,0.00253669141596865,0.000451250568692742,0.25,-4.80788086853887E-7,0.000224482894010514,1.15708212193081E-6,20.0006981,20.0006981,-76571.671875,-76551.765625,57.4481329064291,20.6328629699686,12.658426,0,0,0,40,4449,19.98415,-76561.71875,,,,,,,,,,,,,0,,,,0.00245,,,,,,20.0006981,,,,
,28483449.155,20.00187205,-81296.703125,0.000239204842731298,6.82659778049721E-7,1,0.999253354069792,40.0298881530762,1.99716611059987,15.7500002533197,0.0027072416162412,0.000483887273494139,0.25,-2.96868247862172E-7,0.000239606123535035,1.43212642503185E-6,20.0016289,20.0021152,-81304.390625,-81289.015625,57.5599057846792,20.6345821568602,13.797379,0,0,0,40,4449,19.9827,-81296.703125,,,,,,,,,,,,,0,,,,-0.00245,,,,,,20.00187205,,,,
,28483542.985,20.0012302,-85986.0078125,0.000251260922806353,9.67747669452189E-7,1,0.999253354069792,40.0298881530762,1.99714856045688,15.7500002533197,0.00284674168070127,0.000496603516672983,0.25,-1.3343924838937E-6,0.000251773746324144,4.56944085566792E-7,20.0012302,20.0012302,-85995.9921875,-85976.0234375,57.4606389627369,20.6344775739907,12.658426,0,0,0,40,4449,19.98055,-85986.0078125,,,,,,,,,,,,,0,,,,-0.00245,,,,,,20.0012302,,,,
,28483647.25,20.0009861,-89718.3984375,0.000266288806147183,1.00985573304564E-6,1,0.999253354069792,40.0298881530762,1.99715341555867,15.7500002533197,0.00301949709384796,0.000516814910082003,0.25,-2.24269772273853E-6,0.000266905034118653,-3.67478462553484E-7,20.0009861,20.0009861,-89728.4140625,-89708.3828125,57.5653771843138,20.6334402664732,13.038077,0,0,0,40,4449,19.9803,-89718.3984375,,,,,,,,,,,,,0,,,,0,,,,,,20.0009861,,,,
,28483734.885,19.9999599,-85345.1796875,0.000251280710829544,7.31256896438729E-7,1,0.999253354069792,40.0298881530762,1.99706747779875,15.7500002533197,0.00284145808296904,0.000525898085617871,0.25,1.25066691449932E-6,0.000251763922946512,3.05052272671488E-6,19.9999599,19.9999599,-85350.0703125,-85340.2890625,57.3895107674868,20.6340744601094,13.417728,0,0,0,40,4449,19.9813,-85345.1796875,,,,,,,,,,,,,0,,,,0,,,,,,19.9999599,,,,
,28483828.755,20.0000391,-80653.12109375,0.000238816618502856,7.27171529602511E-7,1,0.999253354069792,40.0298881530762,1.99706317126732,15.7500002533197,0.00270080861595497,0.000492932727822538,0.25,5.738234549603E-7,0.000239199596726355,2.30417537484168E-6,20.0000057,20.0000725,-80657.6015625,-80648.640625,57.4285921934484,20.6340277938877,13.417728,0,0,0,40,4449,19.98135,-80653.12109375,,,,,,,,,,,,,0,,,,-0.0049,,,,,,20.0000391,,,,
,28483925.535,19.9983349,-75815.41796875,0.00022082825074818,7.65365605850627E-7,1,0.999253354069792,40.0298881530762,1.9970639618398,15.7500002533197,0.00249587194430121,0.000458872648079036,0.25,7.99012727467714E-7,0.00022109865198254,2.41641474370191E-6,19.9981861,19.9984837,-75820.59375,-75810.2421875,57.5302039009484,20.6330398359597,13.038077,0,0,0,40,4449,19.9824,-75815.41796875,,,,,,,,,,,,,0,,,,0.00245,,,,,,19.9983349,,,,
,28484020.225,19.9983253,-71085.8828125,0.000206498963080321,7.63831418670222E-7,1,0.999253354069792,40.0298881530762,1.99701199854734,15.7500002533197,0.00233445886608172,0.000420636183386385,0.25,1.16668720670593E-9,0.000206678045210474,1.52518311943914E-6,19.9983253,19.9983253,-71098.5390625,-71073.2265625,57.1925403806407,20.6354376649233,13.797379,0,0,0,40,4449,19.98375,-71085.8828125,,,,,,,,,,,,,0,,,,-0.00245,,,,,,19.9983253,,,,
,28484114.735,19.9990005,-66363.69140625,0.000190266286697151,6.96315398460966E-7,1,0.999253354069792,40.0298881530762,1.99714308290536,15.7500002533197,0.00214621122460958,0.000409655457576379,0.25,1.95851192004248E-6,0.000190339788456049,3.37159219154535E-6,19.9990005,19.9990005,-66371.015625,-66356.3671875,57.3762230826599,20.632526830553,12.658426,0,0,0,40,4449,19.98555,-66363.69140625,,,,,,,,,,,,,0,,,,0,,,,,,19.9990005,,,,
,28484211.245,19.9983482,-61538.66796875,0.000175706258876433,7.26558835354114E-7,1,0.999253354069792,40.0298881530762,1.9971622630807,15.7500002533197,0.00198612150847044,0.000350453756882026,0.25,-6.469396924088E-7,0.000175715960833388,6.60704118479944E-7,19.9983482,19.9983482,-61553.65625,-61523.6796875,57.4684552479292,20.6316783138544,13.038077,0,0,0,40,4449,19.98765,-61538.66796875,,,,,,,,,,,,,0,,,,-0.00245,,,,,,19.9983482,,,,
,28484305.155,19.9979553,-56846.6171875,0.000161475046523474,6.97873783411675E-7,1,0.999253354069792,40.0298881530762,1.9971800337617,15.7500002533197,0.00182036055469836,0.000344697256438353,0.25,1.42225907120072E-6,0.000161397486644006,2.62252293597938E-6,19.9979553,19.9979553,-56851.5546875,-56841.6796875,57.3105662870445,20.6298876276084,13.417728,0,0,0,40,4449,19.98835,-56846.6171875,,,,,,,,,,,,,0,,,,-0.00245,,,,,,19.9979553,,,,
,28484399.485,19.9982224,-52129.8515625,0.000147432091534205,5.77453337170054E-7,1,0.999253354069792,40.0298881530762,1.99717621200767,15.7500002533197,0.00166304668824278,0.000304756304027839,0.25,4.33205574761007E-7,0.000147299506129945,1.52422647465789E-6,19.9982224,19.9982224,-52140.2421875,-52119.4609375,57.4184310226984,20.6322073455704,13.417728,0,0,0,40,4449,19.9895,-52129.8515625,,,,,,,,,,,,,0,,,,0,,,,,,19.9982224,,,,
,28484495.62,19.9992485,-47327.396484375,0.000132593993564806,6.28512781930537E-7,1,0.999253354069792,40.0298881530762,1.99725452586253,15.7500002533197,0.00149272824283111,0.00028656305332935,0.25,1.51515674957395E-6,0.000132401977018277,2.48570904724505E-6,19.9992485,19.9992485,-47332.38671875,-47322.40625,57.4903408464676,20.6283230731726,13.417728,0,0,0,40,4449,19.9891,-47327.396484375,,,,,,,,,,,,,0,,,,0,,,,,,19.9992485,,,,
,28484590.985,20.0000381,-42559.662109375,0.000116924392866945,6.6880340300817E-7,1,0.999253354069792,40.0298881530762,1.99726939630751,15.7500002533197,0.00131662984662661,0.000247291600806949,0.25,8.79208654351642E-7,0.000116700599268386,1.72323369326704E-6,20.0000381,20.0000381,-42569.70703125,-42549.6171875,57.4207759082561,20.6290485946596,12.658426,0,0,0,40,4449,19.98975,-42559.662109375,,,,,,,,,,,,,0,,,,0.00245,,,,,,20.0000381,,,,
,28484687.07,19.9988308,-37757.501953125,0.000101830522176537,4.71243347535653E-7,1,0.999253354069792,40.0298881530762,1.99714010159776,15.7500002533197,0.00114746134502634,0.000207192421103582,0.25,6.52389669865364E-8,0.000101589127571239,7.87086775360739E-7,19.9988308,19.9988308,-37762.79296875,-37752.2109375,57.5169162161215,20.628941242694,13.038077,0,0,0,40,4449,19.99,-37757.501953125,,,,,,,,,,,,,0,,,,0,,,,,,19.9988308,,,,
,28484781.97,19.9991703,-33015.66015625,8.76628133114735E-5,5.24265655578527E-7,1,0.999253354069792,40.0298881530762,1.99721872370014,15.7500002533197,0.00098591874660946,0.0001862667259642,0.25,7.80499603306488E-7,8.74060050553889E-5,1.38399075592547E-6,19.9991703,19.9991703,-33025.66796875,-33005.65234375,57.301968373333,20.6286329720078,13.417728,0,0,0,40,4449,19.99115,-33015.66015625,,,,,,,,,,,,,0,,,,-0.00245,,,,,,19.9991703,,,,
,28484876.47,19.99824715,-28293.876953125,7.29902241510502E-5,4.52282030335957E-7,1,0.999253354069792,40.0298881530762,1.99724665006539,15.7500002533197,0.000821520842608019,0.000149349220240398,0.25,1.62478967485972E-7,7.27436417623096E-5,6.50242824051228E-7,19.9981327,19.9983616,-28303.8203125,-28283.93359375,57.3942005386022,20.6305183727358,13.038077,0,0,0,40,4449,19.9936,-28293.876953125,,,,,,,,,,,,,0,,,,0.0049,,,,,,19.99824715,,,,
,28484970.1,19.99824335,-23613.2802734375,5.87846974653257E-5,4.95974198050461E-7,1,0.999253354069792,40.0298881530762,1.99719178127671,15.7500002533197,0.000662175640190788,0.00011532464628482,0.25,-2.89307336425658E-7,5.85606376156932E-5,9.00225518518902E-8,19.9982338,19.9982529,-23620.728515625,-23605.83203125,57.4958122461022,20.6287832515394,13.417728,0,0,0,40,4449,19.99415,-23613.2802734375,,,,,,,,,,,,,0,,,,0,,,,,,19.99824335,,,,
,28485064.37,19.9981766,-18901.3779296875,4.43686919056257E-5,5.09254118106612E-7,1,0.999253354069792,40.0298881530762,1.99739138042401,15.7500002533197,0.000500452847673006,8.22500649441509E-5,0.25,-6.28554994393763E-7,4.41814569743401E-5,-3.53390042180416E-7,19.9981766,19.9981766,-18908.646484375,-18894.109375,57.3840393678522,20.6261236657712,13.797379,0,0,0,40,4449,19.9967,-18901.3779296875,,,,,,,,,,,,,0,,,,0,,,,,,19.9981766,,,,
,28485162.045,19.9981709,-14021.4013671875,3.00906914131537E-5,4.18578229674192E-7,1,0.999253354069792,40.0298881530762,1.99735808855876,15.7500002533197,0.000338556959663881,5.96022813259929E-5,0.25,-7.41743111804033E-8,2.99479547973073E-5,1.00892081124645E-7,19.9981709,19.9981709,-14031.369140625,-14011.43359375,57.3535558556022,20.6272266824019,12.658426,0,0,0,40,4449,19.998,-14021.4013671875,,,,,,,,,,,,,0,,,,0,,,,,,19.9981709,,,,
,28485257.845,19.9979343,-9231.58056640625,1.63151492328668E-5,3.26327048852004E-7,1,0.999253354069792,40.0298881530762,1.99747372390185,15.7500002533197,0.000184133512657485,2.87539780594142E-5,0.25,-3.50389976857866E-7,1.62328617327826E-5,-2.595242668686E-7,19.9979343,19.9979343,-9234.0771484375,-9229.083984375,57.3004051162945,20.62717653722,13.038077,0,0,0,40,4449,19.9999,-9231.58056640625,,,,,,,,,,,,,0,,,,0.0049,,,,,,19.9979343,,,,
,28485352.8,19.9985409,-4485.34765625,2.63357428462561E-6,2.7733854644123E-7,1,0.999253354069792,40.0298881530762,1.99744746601249,15.7500002533197,2.98901245851379E-5,3.63626967467864E-6,0.25,-1.44932912838624E-7,2.61981082529042E-6,-1.30663284637651E-7,19.9985409,19.9985409,-4490.2802734375,-4480.4150390625,57.1886322380445,20.6247289405869,13.417728,0,0,0,40,4449,20.0011,-4485.34765625,,,,,,,,,,,,,0,,,,-0.00245,,,,,,19.9985409,,,,
,28485444.11,19.9999657,81.0560340881348,-9.06199865340711E-6,3.26103716509664E-7,1,0.999253354069792,40.0298881530762,1.99736492680207,15.7500002533197,-0.00010172144338311,-1.86931111071341E-5,0.25,-5.41033808963897E-8,-9.00964492259911E-6,-9.77267770694967E-8,19.9999657,19.9999657,73.5390548706055,88.5730133056641,57.169873153583,20.6231172341484,13.038077,0,0,0,40,4449,20.00115,81.0560340881348,,,,,,,,,,,,,0,,,,0,,,,,,19.9999657,,,,
,28485537.545,19.9982195,4747.72265625,-2.07287517415473E-5,3.20723507054542E-7,1,0.999253354069792,40.0298881530762,1.99713464520346,15.7500002533197,-0.000232788706986176,-4.23578292597919E-5,0.25,-8.15413139959538E-8,-2.06145280346658E-5,-1.87507456149421E-7,19.9981823,19.9982567,4742.58935546875,4752.85595703125,57.4879959609099,20.6257003716984,13.038077,0,0,0,40,4449,20.00165,4747.72265625,,,,,,,,,,,,,0,,,,0.0049,,,,,,19.9982195,,,,
,28485631.7,19.9999485,9453.52001953125,-3.27154905073105E-5,3.24605015105137E-7,1,0.999253354069792,40.0298881530762,1.99729678576198,15.7500002533197,-0.000366721548280396,-7.15811721867202E-5,0.25,-5.35659045525648E-7,-3.25442955934144E-5,-7.12017934079676E-7,19.9999485,19.9999485,9441.0634765625,9465.9765625,57.2636685758907,20.6248650032812,13.038077,0,0,0,40,4449,20.00165,9453.52001953125,,,,,,,,,,,,,0,,,,-0.00245,,,,,,19.9999485,,,,
,28485727.7,20.0009842,14251.5522460938,-4.48591933592595E-5,3.41875473054628E-7,1,0.999253354069792,40.0298881530762,1.99728668561666,15.7500002533197,-0.000502437603814892,-0.000101598298616075,0.25,-1.0219198389512E-6,-4.46407288542075E-5,-1.27827675959368E-6,20.0009842,20.0009842,14248.9951171875,14254.109375,57.1362631272561,20.6253960826399,13.038077,0,0,0,40,4449,20.0014,14251.5522460938,,,,,,,,,,,,,0,,,,0,,,,,,20.0009842,,,,
,28485818.455,20.0018082,18786.3125,-5.61293879935602E-5,3.8155995318869E-7,1,0.999253354069792,40.0298881530762,1.99725047079834,15.7500002533197,-0.000630830140563304,-0.000116488896445172,0.25,-3.11491093851339E-7,-5.58851146312023E-5,-6.54401913233135E-7,20.0018082,20.0018082,18776.228515625,18796.396484375,57.1987934087945,20.6256939306755,13.417728,0,0,0,40,4449,20.0004,18786.3125,,,,,,,,,,,,,0,,,,0,,,,,,20.0018082,,,,
,28485913.775,20.0023861,23548.8701171875,-6.85989422299435E-5,4.82199877084402E-7,1,0.999253354069792,40.0298881530762,1.99709489759628,15.7500002533197,-0.00076914113473787,-0.000154352951102281,0.25,-1.42040823381873E-6,-6.83257279857764E-5,-1.85604620328322E-6,20.0023861,20.0023861,23543.998046875,23553.7421875,57.2378748347561,20.6244376475194,13.038077,0,0,0,40,4449,19.998,23548.8701171875,,,,,,,,,,,,,0,,,,0,,,,,,20.0023861,,,,
,28486007.775,20.00190545,28249.271484375,-8.00300200354231E-5,5.02748483448167E-7,1,0.999253354069792,40.0298881530762,1.99703805945848,15.7500002533197,-0.000898427515712877,-0.000176181662123269,0.25,-1.28371052093922E-6,-7.97518944002407E-5,-1.81461537463797E-6,20.0016022,20.0022087,28241.806640625,28256.736328125,57.2066096939868,20.6265131465681,12.658426,0,0,0,40,4449,19.9971,28249.271484375,,,,,,,,,,,,,0,,,,-0.0049,,,,,,20.00190545,,,,
,28486101.845,20.001173,32951.998046875,-9.23290487863139E-5,6.38640261297654E-7,1,0.999253354069792,40.0298881530762,1.99713229484621,15.7500002533197,-0.00103698659180221,-0.000203751620676309,0.25,-1.49516662759874E-6,-9.20533092595496E-5,-2.12859464083083E-6,20.001173,20.001173,32944.546875,32959.44921875,57.2214606358522,20.6238803767873,13.797379,0,0,0,40,4449,19.99575,32951.998046875,,,,,,,,,,,,,0,,,,-0.0049,,,,,,20.001173,,,,
,28486198.17,20.0015831,37764.337890625,-0.000106352026649462,5.03772577867706E-7,1,0.999253354069792,40.0298881530762,1.99711290169676,15.7500002533197,-0.00119518847407607,-0.000234221791635002,0.25,-1.65045087845482E-6,-0.000106088776928238,-2.40063467211041E-6,20.0013733,20.0017929,37756.796875,37771.87890625,57.2808644033138,20.6244022061879,13.038077,0,0,0,40,4449,19.9941,37764.337890625,,,,,,,,,,,,,0,,,,0,,,,,,20.0015831,,,,
,28486295.185,20.0014496,42614.169921875,-0.000119609700791541,5.76610153186031E-7,1,0.999253354069792,40.0298881530762,1.99697188931874,15.7500002533197,-0.00134702958308835,-0.000251017654061175,0.25,-7.2904600868912E-7,-0.000119382687057024,-1.59294341375473E-6,20.0014496,20.0014496,42609.2734375,42619.06640625,57.2191157502945,20.6238381883641,13.417728,0,0,0,40,4449,19.99295,42614.169921875,,,,,,,,,,,,,0,,,,-0.0049,,,,,,20.0014496,,,,
,28486390.765,20.00148675,47392.033203125,-0.000134873186320705,6.49232677053252E-7,1,0.999253354069792,40.0298881530762,1.99712681427875,15.7500002533197,-0.00151844471279414,-0.000290695297629866,0.25,-1.47210914702484E-6,-0.000134679273609351,-2.45960334747878E-6,20.0013084,20.0016651,47381.84375,47402.22265625,57.1276652135445,20.622753769378,13.417728,0,0,0,40,4449,19.9917,47392.033203125,,,,,,,,,,,,,0,,,,0,,,,,,20.00148675,,,,
,28486484.735,20.0010662,52087.390625,-0.000147573220462942,6.2209763625883E-7,1,0.999253354069792,40.0298881530762,1.99714951494322,15.7500002533197,-0.00166171071779603,-0.000321132606368899,0.25,-1.85933615168589E-6,-0.000147429330777854,-2.95007691174257E-6,20.0008354,20.001297,52084.90234375,52089.87890625,57.1346998702176,20.6236104052266,13.417728,0,0,0,40,4449,19.9913,52087.390625,,,,,,,,,,,,,0,,,,0.00245,,,,,,20.0010662,,,,
,28486580.65,20.001112,56882.0859375,-0.000162689622736594,7.22878152132627E-7,1,0.999253354069792,40.0298881530762,1.99703829133183,15.7500002533197,-0.0018322754561966,-0.000356474173240238,0.25,-2.24835789784226E-6,-0.000162605971993336,-3.45734279495809E-6,20.001112,20.001112,56877.12109375,56887.05078125,57.2949337166599,20.6238995818751,13.417728,0,0,0,40,4449,19.99015,56882.0859375,,,,,,,,,,,,,0,,,,-0.0049,,,,,,20.001112,,,,
,28486676.865,20.0012836,61689.951171875,-0.000176918455067724,6.24837990527859E-7,1,0.999253354069792,40.0298881530762,1.99697648164534,15.7500002533197,-0.00199296519635952,-0.000390065189697273,0.25,-2.64383979164773E-6,-0.000176906170741979,-3.96058867748277E-6,20.0012836,20.0012836,61684.83203125,61695.0703125,57.119067299833,20.6235474059221,13.417728,0,0,0,40,4449,19.9895,61689.951171875,,,,,,,,,,,,,0,,,,0,,,,,,20.0012836,,,,
,28486773.445,20.0004368,66518.08203125,-0.00019163224875677,7.07064786113921E-7,1,0.999253354069792,40.0298881530762,1.99689566545071,15.7500002533197,-0.00216147435039917,-0.000412102405058794,0.25,-1.93289075582418E-6,-0.000191709177258046,-3.35592378743429E-6,20.0004368,20.0004368,66513.1875,66522.9765625,57.2324034351214,20.6222510726711,13.797379,0,0,0,40,4449,19.9883,66518.08203125,,,,,,,,,,,,,0,,,,0,,,,,,20.0004368,,,,
,28486867.395,20.0013618,71213.2265625,-0.000207238160779013,5.99582289125802E-7,1,0.999253354069792,40.0298881530762,1.99697996455367,15.7500002533197,-0.00233864346689983,-0.000445233690518541,0.25,-2.0442860397771E-6,-0.000207405012728019,-3.57526060265488E-6,20.0013618,20.0013618,71205.7734375,71220.6796875,57.2402197203138,20.6213463764798,13.038077,0,0,0,40,4449,19.9882,71213.2265625,,,,,,,,,,,,,0,,,,0.0049,,,,,,20.0013618,,,,
,28486963.47,20.0014629,76016.58984375,-0.000222607524528656,6.64794554078761E-7,1,0.999253354069792,40.0298881530762,1.99749831407496,15.7500002533197,-0.00251390235185284,-0.000477339696074022,0.25,-2.10264455170004E-6,-0.000222874145160562,-3.73407838308833E-6,20.0014629,20.0014629,76009.0546875,76024.125,57.2011382943522,20.6209156163689,13.797379,0,0,0,40,4449,19.98635,76016.58984375,,,,,,,,,,,,,0,,,,-0.00245,,,,,,20.0014629,,,,
,28487060.24,20.0007038,80852.58203125,-0.000235799798154935,8.2561560303724E-7,1,0.999253354069792,40.0298881530762,1.99738771193173,15.7500002533197,-0.00266297755146787,-0.000509931544664164,0.25,-2.61260224514606E-6,-0.000236166619485557,-4.32361792439845E-6,20.0007038,20.0007038,80842.546875,80862.6171875,56.9979148793522,20.6217568890281,12.658426,0,0,0,40,4449,19.9848,80852.58203125,,,,,,,,,,,,,0,,,,-0.00245,,,,,,20.0007038,,,,
,28487155.935,20.0011425,85638.21875,-0.000251689339213266,8.71400931032849E-7,1,0.999253354069792,40.0298881530762,1.99739400627528,15.7500002533197,-0.0028418494399898,-0.000553141882217525,0.25,-3.57714990731548E-6,-0.000252161865852487,-5.38307203923287E-6,20.0011005,20.0011845,85625.7734375,85650.6640625,56.8134505488137,20.6236929867337,13.797379,0,0,0,40,4449,19.98355,85638.21875,,,,,,,,,,,,,0,,,,0.00245,,,,,,20.0011425,,,,
,28487243.63,20.0012379,89999.515625,-0.000266384816116315,8.81978435138458E-7,1,0.999253354069792,40.0298881530762,1.9972818803377,15.7500002533197,-0.00301205598762682,-0.00056581238334604,0.25,-2.06534629903617E-6,-0.000266975765856473,-3.94934932304285E-6,20.0012379,20.0012379,89999.5,89999.53125,57.1620568683907,20.6204567540572,13.038077,0,0,0,40,4417,19.9817,89999.515625,,,,,,,,,,,,,0,,,,-0.0049,,,,,,20.0012379,,,,
,28487348.855,20.0003071,85619.09375,-0.000252363592235843,8.10135379797656E-7,1,0.999253354069792,40.0298881530762,1.9973892411591,15.7500002533197,-0.00285234976547541,-0.000538518122145692,0.25,-2.16405611256374E-6,-0.000252847216476563,-3.97209559783791E-6,20.0003071,20.0003071,85614.2109375,85623.9765625,56.997133250833,20.6235142456145,13.417728,0,0,0,40,4449,19.9828,85619.09375,,,,,,,,,,,,,0,,,,0,,,,,,20.0003071,,,,
,28487444.06,20.0004654,80860.5,-0.000238491406804139,7.78907944660001E-7,1,0.999253354069792,40.0298881530762,1.99729036477137,15.7500002533197,-0.00269173869935884,-0.000524130035957546,0.25,-3.38493228656732E-6,-0.000238857178320592,-5.11666266486007E-6,20.0004654,20.0004654,80850.1640625,80870.8359375,57.3895107674868,20.6218997787323,13.417728,0,0,0,40,4449,19.9827,80860.5,,,,,,,,,,,,,0,,,,0.00245,,,,,,20.0004654,,,,
,28487538.105,19.999155,76159.203125,-0.000223049607555753,6.90378023635217E-7,1,0.999253354069792,40.0298881530762,1.99712618936264,15.7500002533197,-0.00251786599054617,-0.000481589851564168,0.25,-2.40631396176123E-6,-0.000223317068352188,-4.04092590415192E-6,19.999155,19.999155,76151.59375,76166.8125,57.1909771236022,20.6245218359938,13.038077,0,0,0,40,4449,19.9834,76159.203125,,,,,,,,,,,,,0,,,,0,,,,,,19.999155,,,,
,28487636.785,19.9984646,71228.359375,-0.000207771552436323,7.90083310786071E-7,1,0.999253354069792,40.0298881530762,1.99715485187575,15.7500002533197,-0.00234486360383524,-0.000446406345197998,0.25,-2.0485965790727E-6,-0.000207939100842463,-3.58347919963445E-6,19.9984455,19.9984837,71223.34375,71233.375,57.1143775287176,20.6267648022087,13.038077,0,0,0,40,4449,19.9854,71228.359375,,,,,,,,,,,,,0,,,,0.00245,,,,,,19.9984646,,,,
,28487733.465,19.9979553,66392.890625,-0.000192111724012848,8.93915325779642E-7,1,0.999253354069792,40.0298881530762,1.99703968004684,15.7500002533197,-0.00216586772467784,-0.000419483194531757,0.25,-2.49732967184982E-6,-0.000192182576025728,-3.92432512827687E-6,19.9979553,19.9979553,66390.359375,66395.421875,57.1018714724099,20.6250832199577,13.038077,0,0,0,40,4449,19.9862,66392.890625,,,,,,,,,,,,,0,,,,-0.00245,,,,,,19.9979553,,,,
,28487829.09,19.9981232,61611.806640625,-0.000177679053192372,7.15383480240835E-7,1,0.999253354069792,40.0298881530762,1.99702299992496,15.7500002533197,-0.00200480851795738,-0.000373744120306048,0.25,-1.06126871313535E-6,-0.00017767729730537,-2.38362815574854E-6,19.9981232,19.9981232,61606.73828125,61616.875,57.1010898438907,20.6257438958019,13.038077,0,0,0,40,4449,19.98805,61611.806640625,,,,,,,,,,,,,0,,,,-0.0049,,,,,,19.9981232,,,,
,28487922.68,19.998579,56936.33984375,-0.000162551315302918,6.14630657500297E-7,1,0.999253354069792,40.0298881530762,1.99709714875835,15.7500002533197,-0.00183166956161746,-0.000351241353292041,0.25,-1.80875116536889E-6,-0.000162471838994297,-3.01693291058535E-6,19.998579,19.998579,56929.18359375,56943.49609375,57.3684067974676,20.6243859332923,13.417728,0,0,0,40,4449,19.98915,56936.33984375,,,,,,,,,,,,,0,,,,-0.0049,,,,,,19.998579,,,,
,28488017.775,19.9989529,52184.126953125,-0.000148407850895128,6.08496077564405E-7,1,0.999253354069792,40.0298881530762,1.99704601360416,15.7500002533197,-0.00167097352196094,-0.00032331784590603,0.25,-1.90354928494386E-6,-0.00014826432845445,-3.00059774978219E-6,19.9989529,19.9989529,52181.57421875,52186.6796875,57.3621537693137,20.6233813337462,13.038077,0,0,0,40,4449,19.99025,52184.126953125,,,,,,,,,,,,,0,,,,0,,,,,,19.9989529,,,,
,28488111.89,19.9995823,47479.123046875,-0.000132381976898909,5.15695960937489E-7,1,0.999253354069792,40.0298881530762,1.99694605977857,15.7500002533197,-0.00148919017861118,-0.000291366996716837,0.25,-1.98225688541015E-6,-0.00013218888326969,-2.95100125754735E-6,19.9995823,19.9995823,47469.15625,47489.08984375,57.0666981890445,20.6255880552268,13.417728,0,0,0,40,4449,19.99025,47479.123046875,,,,,,,,,,,,,0,,,,-0.00245,,,,,,19.9995823,,,,
,28488207.45,19.9996471,42703.626953125,-0.00011727423523552,5.6358997439077E-7,1,0.999253354069792,40.0298881530762,1.99698600633655,15.7500002533197,-0.0013214485713788,-0.000242235787153915,0.25,-3.70009426154903E-7,-0.000117055244806366,-1.21794630954285E-6,19.999464,19.9998302,42690.875,42716.37890625,57.115940785756,20.6247784379482,13.038077,0,0,0,40,4449,19.99115,42703.626953125,,,,,,,,,,,,,0,,,,0.00245,,,,,,19.9996471,,,,
,28488301.195,19.9993458,38016.09375,-0.000102880948582209,6.07821698950788E-7,1,0.999253354069792,40.0298881530762,1.99703976407113,15.7500002533197,-0.00115844324693255,-0.000213944326823201,0.25,-4.7489658886193E-7,-0.00010263698088595,-1.20413140475572E-6,19.9993458,19.9993458,38008.53515625,38023.65234375,57.3090030300061,20.6286526866579,13.038077,0,0,0,40,4449,19.993,38016.09375,,,,,,,,,,,,,0,,,,0.00245,,,,,,19.9993458,,,,
,28488395.51,19.998045,33304.15625,-8.79445399733696E-5,5.74842747977277E-7,1,0.999253354069792,40.0298881530762,1.99698364682732,15.7500002533197,-0.000987995804217275,-0.000192472592178474,0.25,-1.28112466917327E-6,-8.76861311598869E-5,-1.88623307244147E-6,19.998045,19.998045,33301.5078125,33306.8046875,57.2128627221407,20.6250743487043,13.038077,0,0,0,40,4449,19.9918,33304.15625,,,,,,,,,,,,,0,,,,0,,,,,,19.998045,,,,
,28488489.775,19.9990921,28594.1982421875,-7.29268793521644E-5,4.39070203996782E-7,1,0.999253354069792,40.0298881530762,1.99709078031662,15.7500002533197,-0.000818994946316394,-0.000159115559384975,0.25,-1.04073582621146E-6,-7.26768987561389E-5,-1.52626016081448E-6,19.998951,19.9992332,28589.05859375,28599.337890625,57.2183341217753,20.6278422477554,13.038077,0,0,0,40,4449,19.9947,28594.1982421875,,,,,,,,,,,,,0,,,,0.00245,,,,,,19.9990921,,,,
,28488584.25,19.99843125,23871.1455078125,-5.90620694540299E-5,4.22166493807564E-7,1,0.999253354069792,40.0298881530762,1.99708602259753,15.7500002533197,-0.000663349970642334,-0.000126655253954783,0.25,-6.6713215780287E-7,-5.8832317723572E-5,-1.04547872008762E-6,19.9981976,19.9986649,23861.08203125,23881.208984375,57.3480844559676,20.6276835036224,13.038077,0,0,0,40,4449,19.99555,23871.1455078125,,,,,,,,,,,,,0,,,,-0.0049,,,,,,19.99843125,,,,
,28488678.38,19.9988632,19166.1279296875,-4.47831302408185E-5,4.67721062793967E-7,1,0.999253354069792,40.0298881530762,1.99712050473262,15.7500002533197,-0.000502056203259085,-9.98799010048225E-5,0.25,-8.64411604354178E-7,-4.45860652921366E-5,-1.13648945059267E-6,19.9988632,19.9988632,19153.58984375,19178.666015625,57.2793011462753,20.626525448266,12.658426,0,0,0,40,4449,19.99695,19166.1279296875,,,,,,,,,,,,,0,,,,0,,,,,,19.9988632,,,,
,28488770.715,19.999218,14551.4653320313,-3.1232931508608E-5,4.43374997627739E-7,1,0.999253354069792,40.0298881530762,1.99696778579268,15.7500002533197,-0.000349692670648983,-7.11890668781931E-5,0.25,-7.51824584727222E-7,-3.10814108254229E-5,-9.30801873383175E-7,19.999218,19.999218,14546.41796875,14556.5126953125,57.2652318329291,20.6294867555349,13.417728,0,0,0,40,4449,19.9982,14551.4653320313,,,,,,,,,,,,,0,,,,0,,,,,,19.999218,,,,
,28488863.75,19.9971962,9902.064453125,-1.74718726424188E-5,4.01140417270686E-7,1,0.999253354069792,40.0298881530762,1.99702150130334,15.7500002533197,-0.000195905764313755,-3.78037813629842E-5,0.25,-2.48059306616693E-7,-1.73812731687729E-5,-3.43023627913864E-7,19.9971962,19.9971962,9899.5791015625,9904.5498046875,57.2081729510253,20.6289888046193,13.417728,0,0,0,40,4449,19.9998,9902.064453125,,,,,,,,,,,,,0,,,,0,,,,,,19.9971962,,,,
,28488956.18,19.99879745,5283.95703125,-4.65046792805927E-6,3.28869503770738E-7,1,0.999253354069792,40.0298881530762,1.99711661371853,15.7500002533197,-5.22862843619313E-5,-9.17168810930305E-6,0.25,1.13799103966492E-8,-4.6251637769298E-6,-1.27321725064355E-8,19.9983559,19.999239,5276.345703125,5291.568359375,57.1729996676599,20.6305196192818,13.417728,0,0,0,40,4449,20.0008,5283.95703125,,,,,,,,,,,,,0,,,,0,,,,,,19.99879745,,,,
,28489047.805,20.0005579,702.505310058594,8.11586254896605E-6,3.69150975773813E-7,1,0.999253354069792,40.0298881530762,1.99705611873665,15.7500002533197,9.14089486686265E-5,1.49423792634684E-5,0.25,-1.11706470605178E-7,8.06994795190885E-6,-7.14953873720687E-8,20.0005283,20.0005875,697.489074707031,707.521545410156,57.4622022197753,20.6280740644517,13.417728,0,0,0,40,4449,19.9993,702.505310058594,,,,,,,,,,,,,0,,,,0,,,,,,20.0005579,,,,
,28489064.04,20.0005283,0.31208735704422,9.63128268951988E-6,3.73370800132603E-7,1,0.999253354069792,40.0298881530762,1.99712363356159,15.7500002533197,0.000108759249410992,1.61475446516258E-5,0.25,-2.73347117895383E-7,9.57722457393506E-6,-2.25102853370546E-7,20.0005283,20.0005283,0.304475486278534,0.319699227809906,57.4051433378714,20.6285307535667,12.658426,0,0,0,40,4417,19.9995,0.31208735704422,,,,,,,,,,,,,0,,,,0,,,,,,20.0005283,,,,