File: data/monolayers/nanoparticles/Ol_CoFe_C/vsm/data_disorderedWafer/DD227_HYST_50K.DAT
[Header]
; VSM Data File (default extension .dat)
; Copyright (c) 2003-2013, Quantum Design, Inc. All rights reserved.
TITLE,
FILEOPENTIME,28489690.56,11/27/2018,1:48 am
BYAPP,VSM,2.0,2.0
INFO,PPMS VSM Option Release 1.4.10 Build 1,APPNAME
INFO,Quantum Design Linear Motor Servo Controller,MOTOR_MODULE_NAME
INFO,3101-100 M1,MOTOR_HW_VERSION
INFO,MMC1014,MOTOR_SERIAL_NUMBER
INFO,SRV No X-over 01.03.11,MOTOR_SOFTWARE_VERSION
INFO,Quantum Design VSM Detection Module,VSM_MODULE_NAME
INFO,3101-150 F0,VSM_HW_VERSION
INFO,VSM707,VSM_SERIAL_NUMBER
INFO,VSM No X-over 01.02.05 May 20 2008 13:51:47,VSM_SOFTWARE_VERSION
INFO,704,PREAMP_SERIAL_NUMBER
INFO,822,COIL_SERIAL_NUMBER
INFO,0,MOMENT_UNITS
INFO,CoFe2O4 FeO,SAMPLE_MATERIAL
INFO,disordered monolayer,SAMPLE_COMMENT
INFO,25.46,SAMPLE_MASS
INFO,,SAMPLE_VOLUME
INFO,,SAMPLE_MOLECULAR_WEIGHT
INFO,,SAMPLE_SIZE
INFO,,SAMPLE_SHAPE
DATATYPE,COMMENT,1
DATATYPE,TIME,2
STARTUPAXIS,X,2
STARTUPAXIS,Y1,5
[Data]
Comment,Time Stamp (sec),Temperature (K),Magnetic Field (Oe),Moment (emu),M. Std. Err. (emu),Transport Action,Averaging Time (sec),Frequency (Hz),Peak Amplitude (mm),Center Position (mm),Coil Signal' (mV),Coil Signal" (mV),Range (mV),M. Quad. Signal (emu),M. Raw' (emu),M. Raw" (emu),Min. Temperature (K),Max. Temperature (K),Min. Field (Oe),Max. Field (Oe),Mass (grams),Motor Lag (deg),Pressure (Torr),VSM Status (code),Motor Status (code),Measure Status (code),Measure Count,PPMS Status (code),System Temp. (K),System Field (Oe),Sample Position (deg),Bridge 1 Resistance (ohms),Bridge 1 Excitation (에),Bridge 2 Resistance (ohms),Bridge 2 Excitation (에),Bridge 3 Resistance (ohms),Bridge 3 Excitation (에),Bridge 4 Resistance (ohms),Bridge 4 Excitation (에),Signal 1 Vin (V),Signal 2 Vin (V),Digital Inputs (code),Drive 1 Iout (mA),Drive 1 Ipower (W),Drive 2 Iout (mA),Drive 2 Ipower (W),Pressure (),Map 20 (),Map 21 (),Map 22 (),Map 23 (),Map 24 (),Map 25 (),Map 26 (),Map 27 (),Map 28 (),Map 29 ()
,28489706.7,50.0114174,0.319699227809906,,,2,,,,15.7500004646182,,,,,,,50.0114174,50.0114174,0.319699227809906,0.319699227809906,,,16.454937,,,,-99999999,4369,50.0252,0.319699227809906,,,,,,,,,,,,,,,,,,,,,,,50.0114174,,,,
,28489859.165,50.0025024,4578.9443359375,-7.02206380699481E-6,3.94651927927942E-7,1,0.999253354069792,40.0298881530762,1.9971114332834,15.7399997115135,-7.86626673292483E-5,-1.77655956011819E-5,0.25,-3.07630992025239E-7,-7.01717768539154E-6,-3.59772680265473E-7,50.0025024,50.0025024,4571.34765625,4586.541015625,56.7251265261406,20.6087787350613,16.075285,0,0,0,40,4449,50.0216,4578.9443359375,,,,,,,,,,,,,0,,,,-0.00245,,,,,,50.0025024,,,,
,28489954.755,49.9997883,9355.48974609375,-2.07048563794189E-5,5.43051931457062E-7,1,0.999253354069792,40.0298881530762,1.99723757598055,15.7399997115135,-0.000233643071146582,-4.33337851306109E-5,0.25,-1.04616716484682E-7,-2.07013251648093E-5,-2.58629625852374E-7,49.999588,49.9999886,9352.736328125,9358.2431640625,56.6938613853714,20.6156898894882,16.454937,0,0,0,40,4449,50.0242,9355.48974609375,,,,,,,,,,,,,0,,,,-0.00245,,,,,,49.9997883,,,,
,28490049.955,49.9996948,14112.587890625,-3.35834005494613E-5,6.25136372021573E-7,1,0.999253354069792,40.0298881530762,1.99739165055697,15.7399997115135,-0.000378870554300233,-7.1550363121746E-5,0.25,-2.79849359888099E-7,-3.35853320850249E-5,-5.29348716704026E-7,49.9996948,49.9996948,14110.1474609375,14115.0283203125,56.8071975206598,20.6164057004184,16.075285,0,0,0,40,4449,50.0237,14112.587890625,,,,,,,,,,,,,0,,,,0,,,,,,49.9996948,,,,
,28490147.95,49.9996147,19012.4130859375,-4.66796222547272E-5,5.48000381950498E-7,1,0.999253354069792,40.0298881530762,1.99736576496186,15.7399997115135,-0.000529033299989389,-8.68094971695954E-5,0.25,7.30886723590797E-7,-4.67031538419389E-5,3.8540657385924E-7,49.9996147,49.9996147,19002.37109375,19022.455078125,56.9033378285253,20.6159177970134,16.075285,0,0,0,40,4449,50.02615,19012.4130859375,,,,,,,,,,,,,0,,,,0.00245,,,,,,49.9996147,,,,
,28490244.735,49.999897,23847.4248046875,-6.01327591762961E-5,7.74442754121976E-7,1,0.999253354069792,40.0298881530762,1.99729192081262,15.7399997115135,-0.000679355091072281,-0.000124637597049924,0.25,-1.91325338990719E-7,-6.01707089505517E-5,-6.35022637586211E-7,49.999897,49.999897,23840.001953125,23854.84765625,57.1526773261599,20.6170270987097,16.454937,0,0,0,40,4449,50.0251,23847.4248046875,,,,,,,,,,,,,0,,,,-0.00245,,,,,,49.999897,,,,
,28490342.72,50.0011139,28745.0439453125,-7.39233922667884E-5,7.63509732091281E-7,1,0.999253354069792,40.0298881530762,1.99733616121486,15.7399997115135,-0.000835250811942627,-0.000154083701697067,0.25,-3.10687636436623E-7,-7.39893973162306E-5,-8.53251647448378E-7,50.0011139,50.0011139,28737.630859375,28752.45703125,56.9979148793522,20.6202544833642,16.454937,0,0,0,40,4449,50.0267,28745.0439453125,,,,,,,,,,,,,0,,,,0,,,,,,50.0011139,,,,
,28490439.93,50.0010681,33605.158203125,-8.63421436077918E-5,6.30640195856427E-7,1,0.999253354069792,40.0298881530762,1.99726536937096,15.7399997115135,-0.000976896679995282,-0.000173865461573457,0.25,1.75956551311137E-7,-8.64457430806379E-5,-4.52945014771665E-7,50.0010681,50.0010681,33595.265625,33615.05078125,56.699332785006,20.6174013464623,16.454937,0,0,0,40,4449,50.0207,33605.158203125,,,,,,,,,,,,,0,,,,-0.00245,,,,,,50.0010681,,,,
,28490534.985,50.0005913,38354.923828125,-0.000101285332584111,8.94411926813126E-7,1,0.999253354069792,40.0298881530762,1.99734792931219,15.7399997115135,-0.00114403892526693,-0.000216578946590398,0.25,-9.10010272622792E-7,-0.000101424292770184,-1.64354555387229E-6,50.0005913,50.0005913,38347.4296875,38362.41796875,56.9924434797176,20.6178694896757,16.454937,0,0,0,40,4449,50.0236,38354.923828125,,,,,,,,,,,,,0,,,,0,,,,,,50.0005913,,,,
,28490628.15,50.0011368,43012.673828125,-0.000115352138131648,8.604725768886E-7,1,0.999253354069792,40.0298881530762,1.9974653614388,15.7399997115135,-0.00130552516665911,-0.000234431941946698,0.25,4.2951097042283E-8,-0.000115545877220107,-7.83649148825784E-7,50.0011368,50.0011368,43005.19921875,43020.1484375,56.9979148793522,20.6171702830287,16.834587,0,0,0,40,4449,50.02435,43012.673828125,,,,,,,,,,,,,0,,,,0.00245,,,,,,50.0011368,,,,
,28490724.695,50.0014191,47835.591796875,-0.000128039407056023,8.84707151748674E-7,1,0.999253354069792,40.0298881530762,1.99731762653778,15.7399997115135,-0.0014470845688666,-0.000272914613469129,0.25,-1.07965529945616E-6,-0.000128277213366004,-1.99015305622051E-6,50.0014191,50.0014191,47833.14453125,47838.0390625,57.115940785756,20.6182878817571,16.834587,0,0,0,40,4449,50.02255,47835.591796875,,,,,,,,,,,,,0,,,,0,,,,,,50.0014191,,,,
,28490818.765,50.0021629,52538.16796875,-0.00014245229822978,1.04022546403562E-6,1,0.999253354069792,40.0298881530762,1.99733210788827,15.7399997115135,-0.00160961899339573,-0.000307780456732785,0.25,-1.57201236313807E-6,-0.000142746546347555,-2.5753115432316E-6,50.0021629,50.0021629,52530.87109375,52545.46484375,57.4489145349484,20.6200717036514,16.075285,0,0,0,40,4449,50.0197,52538.16796875,,,,,,,,,,,,,0,,,,0,,,,,,50.0021629,,,,
,28490917.85,50.0019226,57490.396484375,-0.000157006177043214,9.93570930503644E-7,1,0.999253354069792,40.0298881530762,1.99737437547774,15.7399997115135,-0.00177922844146685,-0.000313063043123456,0.25,5.71448365707021E-7,-0.000157382682955209,-5.15915015600261E-7,50.0019226,50.0019226,57487.82421875,57492.96875,57.1534589546791,20.6163509904209,16.834587,0,0,0,40,4449,50.0217,57490.396484375,,,,,,,,,,,,,0,,,,0,,,,,,50.0019226,,,,
,28491015.89,50.0012283,62393.546875,-0.00017272643799279,1.22622236605402E-6,1,0.999253354069792,40.0298881530762,1.99734203789701,15.7399997115135,-0.00195962030374207,-0.000334154709863526,0.25,1.52446463434341E-6,-0.000173184254378658,3.4599219968098E-7,50.0012283,50.0012283,62385.875,62401.21875,56.9783741663714,20.6149243152978,16.454937,0,0,0,40,4449,50.0195,62393.546875,,,,,,,,,,,,,0,,,,0,,,,,,50.0012283,,,,
,28491114.255,50.0023918,67308.94140625,-0.000189372353921469,1.30528566335955E-6,1,0.999253354069792,40.0298881530762,1.99730441872922,15.7399997115135,-0.00214308916295123,-0.00039866769108322,0.25,-1.19211731959993E-6,-0.000189894285950758,-2.47427138531468E-6,50.0023918,50.0023918,67299.0703125,67318.8125,56.9830639374868,20.6144351226334,16.454937,0,0,0,40,4449,50.01835,67308.94140625,,,,,,,,,,,,,0,,,,-0.00245,,,,,,50.0023918,,,,
,28491208.785,50.00253485,72031.59765625,-0.000204509344376989,9.16277117363657E-7,1,0.999253354069792,40.0298881530762,1.99736969344655,15.7399997115135,-0.00231739095575085,-0.000416769317814972,0.25,-8.32940830989067E-8,-0.000205120169087864,-1.44582630180151E-6,50.0023193,50.0027504,72026.65625,72036.5390625,57.1253203279868,20.6167029367477,16.454937,0,0,0,40,4449,50.0132,72031.59765625,,,,,,,,,,,,,0,,,,0,,,,,,50.00253485,,,,
,28491305.71,50.0021629,76877.24609375,-0.00021820866212431,1.23527639012758E-6,1,0.999253354069792,40.0298881530762,1.99731886894957,15.7399997115135,-0.00247435380824872,-0.00043736173915345,0.25,5.42406093068536E-7,-0.000218905664250201,-8.88197536948151E-7,50.0021629,50.0021629,76869.6796875,76884.8125,57.1354814987368,20.616624831837,16.454937,0,0,0,40,4449,50.01935,76877.24609375,,,,,,,,,,,,,0,,,,0.00245,,,,,,50.0021629,,,,
,28491403.955,50.0012245,81787.83984375,-0.000233198365767114,9.07472494420085E-7,1,0.999253354069792,40.0298881530762,1.99741323793936,15.7399997115135,-0.00264200435345636,-0.00048378270236553,0.25,-8.79047157011639E-7,-0.00023397584928019,-2.38948454501494E-6,50.0012245,50.0012245,81782.7421875,81792.9375,56.8580033744099,20.6141669929689,16.075285,0,0,0,40,4449,50.01525,81787.83984375,,,,,,,,,,,,,0,,,,-0.00245,,,,,,50.0012245,,,,
,28491497.415,50.0008335,86461.140625,-0.000249975204068659,1.18886850981336E-6,1,0.999253354069792,40.0298881530762,1.99717125938619,15.7399997115135,-0.00283265590196891,-0.00051612014567186,0.25,-7.46723213924863E-7,-0.000250850828276335,-2.34128757063361E-6,50.0006599,50.0010071,86451.1484375,86471.1328125,57.0760777312753,20.6164311741287,16.454937,0,0,0,40,4449,50.011,86461.140625,,,,,,,,,,,,,0,,,,0,,,,,,50.0008335,,,,
,28491608.735,50.0002441,89036.9140625,-0.000254694665067922,1.09409476344974E-6,1,0.999253354069792,40.0298881530762,1.99720108952159,15.7399997115135,-0.00288194516240465,-0.000550945874002157,0.25,-2.98181318172546E-6,-0.00025559502626539,-4.60094102445929E-6,50.0002441,50.0002441,89031.9765625,89041.8515625,57.0924919301791,20.613509524234,16.454937,0,0,0,40,4449,50.0119,89036.9140625,,,,,,,,,,,,,0,,,,-0.00245,,,,,,50.0002441,,,,
,28491706.805,49.9996605,84136.6171875,-0.000239854841013454,9.13766008677067E-7,1,0.999253354069792,40.0298881530762,1.99723845895606,15.7399997115135,-0.00271394752966988,-0.000516952166011166,0.25,-2.62348270009091E-6,-0.000240663475885045,-4.17148237399814E-6,49.9996605,49.9996605,84129.2109375,84144.0234375,57.200356665833,20.6184280382301,16.834587,0,0,0,40,4449,50.013,84136.6171875,,,,,,,,,,,,,0,,,,-0.00245,,,,,,49.9996605,,,,
,28491809.745,50.0002174,78988.05078125,-0.000223047251339107,9.07163789434944E-7,1,0.999253354069792,40.0298881530762,1.99730026568291,15.7399997115135,-0.00252476149550929,-0.000472930366220484,0.25,-1.734698258002E-6,-0.000223762184741132,-3.19499371032083E-6,49.9998779,50.0005569,78980.421875,78995.6796875,57.085457273506,20.615924963682,16.834587,0,0,0,40,4449,50.013,78988.05078125,,,,,,,,,,,,,0,,,,-0.00245,,,,,,50.0002174,,,,
,28491909.945,49.9997139,73979.66015625,-0.000208158388637118,9.76060242474265E-7,1,0.999253354069792,40.0298881530762,1.99737957868471,15.7399997115135,-0.00235543258363078,-0.000443742177347738,0.25,-1.81370843175506E-6,-0.000208784632749706,-3.19779528069208E-6,49.9997139,49.9997139,73972.171875,73987.1484375,57.1010898438907,20.6178256853029,16.454937,0,0,0,40,4449,50.01445,73979.66015625,,,,,,,,,,,,,0,,,,0.00245,,,,,,49.9997139,,,,
,28492009.65,50.0019493,68994.03515625,-0.000193821933035116,8.90587590561429E-7,1,0.999253354069792,40.0298881530762,1.99747544620208,15.7399997115135,-0.00219554704816299,-0.000398215308513157,0.25,-3.54444067035155E-7,-0.00019437529181023,-1.65808262719935E-6,50.0019493,50.0019493,68989.046875,68999.0234375,56.9275683126214,20.6203860781035,17.214239,0,0,0,40,4449,50.01335,68994.03515625,,,,,,,,,,,,,0,,,,-0.0049,,,,,,50.0019493,,,,
,28492107.395,50.0007019,64111.6796875,-0.000179824999546081,1.10105958834281E-6,1,0.999253354069792,40.0298881530762,1.99755010529233,15.7399997115135,-0.00203369650778311,-0.000385865880377455,0.25,-1.76560824886431E-6,-0.000180291914401736,-2.99562425382361E-6,50.0007019,50.0007019,64106.59375,64116.765625,56.966649738583,20.6187564721201,16.454937,0,0,0,40,4449,50.0146,64111.6796875,,,,,,,,,,,,,0,,,,0.00245,,,,,,50.0007019,,,,
,28492204.885,49.9991074,59235.40234375,-0.000164838405053926,9.38871655669518E-7,1,0.999253354069792,40.0298881530762,1.99740245089805,15.7399997115135,-0.00186350079988055,-0.000354603836734964,0.25,-1.69143037849859E-6,-0.000165230588594408,-2.83356465020093E-6,49.9991074,49.9991074,59227.953125,59242.8515625,57.1182856713137,20.6197636756608,16.834587,0,0,0,40,4449,50.0136,59235.40234375,,,,,,,,,,,,,0,,,,-0.00245,,,,,,49.9991074,,,,
,28492299.345,49.9990158,54515.275390625,-0.000149705196068834,9.29968218807073E-7,1,0.999253354069792,40.0298881530762,1.99736529841444,15.7399997115135,-0.00169348640032925,-0.000313844706593508,0.25,-8.0561047181771E-7,-0.000150034069215287,-1.85333860510719E-6,49.9990158,49.9990158,54504.953125,54525.59765625,56.9564885678329,20.6187470656067,16.834587,0,0,0,40,4449,50.0117,54515.275390625,,,,,,,,,,,,,0,,,,0,,,,,,49.9990158,,,,
,28492394.7,49.9997749,49750.2890625,-0.000135045057548675,8.1712704960305E-7,1,0.999253354069792,40.0298881530762,1.99737198777875,15.7399997115135,-0.00152384058073334,-0.000302338907269784,0.25,-2.41997287165295E-6,-0.000135299230857485,-3.37896288307167E-6,49.9997253,49.9998245,49748.14453125,49752.43359375,57.1980117802753,20.6205290920153,16.834587,0,0,0,40,4449,50.0141,49750.2890625,,,,,,,,,,,,,0,,,,0,,,,,,49.9997749,,,,
,28492493.35,50.0001907,44817.7890625,-0.000118859644229925,9.69757160222049E-7,1,0.999253354069792,40.0298881530762,1.99742885808234,15.7399997115135,-0.00134134475817908,-0.000263652333748383,0.25,-1.90927696363593E-6,-0.00011905578212475,-2.76145984763591E-6,50.0001907,50.0001907,44810.39453125,44825.18359375,57.2238055214099,20.6203591630771,16.834587,0,0,0,40,4449,50.0094,44817.7890625,,,,,,,,,,,,,0,,,,0,,,,,,50.0001907,,,,
,28492588.855,50.0003014,40044.517578125,-0.000104575749846409,1.03040582180418E-6,1,0.999253354069792,40.0298881530762,1.99745767016769,15.7399997115135,-0.00117998651291621,-0.00023131403720129,0.25,-1.61957707080243E-6,-0.00010472320550704,-2.37583773278493E-6,50.0003014,50.0003014,40037.0390625,40051.99609375,57.0932735586983,20.6219534947144,16.834587,0,0,0,40,4449,50.00945,40044.517578125,,,,,,,,,,,,,0,,,,0,,,,,,50.0003014,,,,
,28492684.405,50.0002251,35267.591796875,-8.96929237389878E-5,7.03763787975056E-7,1,0.999253354069792,40.0298881530762,1.99770009533532,15.7399997115135,-0.00101427529068283,-0.000185280334542044,0.25,-2.26792955723928E-7,-8.98052870097546E-5,-8.78954357328815E-7,50.0002251,50.0002251,35265.4921875,35269.69140625,57.105779615006,20.6247326600121,16.834587,0,0,0,40,4449,50.0096,35267.591796875,,,,,,,,,,,,,0,,,,0.0049,,,,,,50.0002251,,,,
,28492780.37,49.9999504,30472.49609375,-7.62487241946497E-5,7.70206699157261E-7,1,0.999253354069792,40.0298881530762,1.99767669884161,15.7399997115135,-0.000860695616213791,-0.000164780379703689,0.25,-8.35385890012128E-7,-7.63199022387684E-5,-1.39435349492716E-6,49.9999504,49.9999504,30462.53515625,30482.45703125,57.0463758475445,20.6234253030858,17.214239,0,0,0,40,4449,50.01035,30472.49609375,,,,,,,,,,,,,0,,,,0.00245,,,,,,49.9999504,,,,
,28492875.625,50.0006104,25712.24609375,-6.21577031454985E-5,7.38092701480347E-7,1,0.999253354069792,40.0298881530762,1.9976147038695,15.7399997115135,-0.000702060679427489,-0.000130805916018227,0.25,-3.70125699429028E-7,-6.2201828101125E-5,-8.28050352385334E-7,50.0006104,50.0006104,25709.787109375,25714.705078125,57.3949821671215,20.6238259776022,16.834587,0,0,0,40,4449,50.0115,25712.24609375,,,,,,,,,,,,,0,,,,0,,,,,,50.0006104,,,,
,28492969.81,49.9998779,21004.8369140625,-4.82704416084342E-5,6.95609980947584E-7,1,0.999253354069792,40.0298881530762,1.99760738823639,15.7399997115135,-0.000543941118637203,-0.000107779835668456,0.25,-8.36441793173894E-7,-4.82880886503831E-5,-1.19387227847418E-6,49.9998779,49.9998779,20997.427734375,21012.24609375,57.2621053188522,20.6237149742288,17.214239,0,0,0,40,4449,50.01045,21004.8369140625,,,,,,,,,,,,,0,,,,0.00245,,,,,,49.9998779,,,,
,28493066.07,50.0000458,16192.9663085938,-3.5198395794516E-5,5.33420856734743E-7,1,0.999253354069792,40.0298881530762,1.99759913206549,15.7399997115135,-0.000397497085232541,-7.32064431612532E-5,0.25,-1.34287210435783E-7,-3.52054281654354E-5,-3.95521709689911E-7,50.0000458,50.0000458,16185.6015625,16200.3310546875,57.3144744296407,20.6234643364966,16.834587,0,0,0,40,4449,50.00785,16192.9663085938,,,,,,,,,,,,,0,,,,-0.0049,,,,,,50.0000458,,,,
,28493162.81,50.0002937,11357.9760742187,-2.13499121550534E-5,4.91152846722272E-7,1,0.999253354069792,40.0298881530762,1.99742120799686,15.7399997115135,-0.000240311197597742,-4.83331741395801E-5,0.25,-4.30258305022463E-7,-2.13460129301857E-5,-5.88999138439234E-7,50.0002937,50.0002937,11353.06640625,11362.8857421875,57.1253203279868,20.6225334201599,16.834587,0,0,0,40,4449,50.00845,11357.9760742187,,,,,,,,,,,,,0,,,,-0.00245,,,,,,50.0002937,,,,
,28493257.87,50.0001717,6607.43872070312,-8.382929415633E-6,3.9109668669371E-7,1,0.999253354069792,40.0298881530762,1.99737704019198,15.7399997115135,-9.45521931044109E-5,-1.77508138150505E-5,0.25,-6.06819672629985E-8,-8.38016195599411E-6,-1.23047142773386E-7,50.0001717,50.0001717,6600.10791015625,6614.76953125,57.1448610409676,20.6224968683911,16.834587,0,0,0,40,4449,50.0102,6607.43872070312,,,,,,,,,,,,,0,,,,-0.00245,,,,,,50.0001717,,,,
,28493353.88,49.9995766,1806.76672363281,4.34752494608966E-6,3.05943842838861E-7,1,0.999253354069792,40.0298881530762,1.99748631588096,15.7399997115135,5.00051719295476E-5,3.78462905009644E-6,0.25,-4.48489717682499E-7,4.34871897228167E-6,-4.15923510350911E-7,49.9995766,49.9995766,1801.91040039062,1811.623046875,57.3809128537753,20.6238747574928,16.454937,0,0,0,40,4449,50.0114,1806.76672363281,,,,,,,,,,,,,0,,,,0.00245,,,,,,49.9995766,,,,
,28493449.795,50.0007133,-2980.79663085937,1.47154129005486E-5,3.57159654265475E-7,1,0.999253354069792,40.0298881530762,1.99755256741322,15.7399997115135,0.000166641537826663,2.73933634773473E-5,0.25,-2.26776878986216E-7,1.47105578396785E-5,-1.1718138472709E-7,50.0007133,50.0007133,-2985.77514648438,-2975.81811523438,57.2542890336599,20.6241770574433,17.214239,0,0,0,40,4449,50.01125,-2980.79663085937,,,,,,,,,,,,,0,,,,0,,,,,,50.0007133,,,,
,28493546.635,50.0000153,-7823.07543945313,2.62193376603641E-5,4.04502802997402E-7,1,0.999253354069792,40.0298881530762,1.99754959065148,15.7399997115135,0.000295868488527481,5.50000272467734E-5,0.25,1.43151948223962E-7,2.6212591567924E-5,3.38216128010771E-7,50.0000153,50.0000153,-7825.685546875,-7820.46533203125,57.3183825722368,20.6265419242524,16.834587,0,0,0,40,4449,50.0068,-7823.07543945313,,,,,,,,,,,,,0,,,,0.00245,,,,,,50.0000153,,,,
,28493643.54,50.00134275,-12665.8862304687,3.81555868242157E-5,4.74886112347981E-7,1,0.999253354069792,40.0298881530762,1.9975898616336,15.7399997115135,0.000429795840058832,8.49593932837786E-5,0.25,6.42297288622429E-7,3.81522134967266E-5,9.2592264926279E-7,50.0012474,50.0014381,-12673.46875,-12658.3037109375,57.3332335141022,20.625000175055,16.834587,0,0,0,40,4449,50.0076,-12665.8862304687,,,,,,,,,,,,,0,,,,0.0049,,,,,,50.00134275,,,,
,28493739.13,50.0004005,-17443.6123046875,4.81482741608955E-5,5.58051462578735E-7,1,0.999253354069792,40.0298881530762,1.99758550549475,15.7399997115135,0.000543777900901349,0.000100124924107406,0.25,1.8210770185926E-7,4.81611830083837E-5,5.39204533210012E-7,50.0004005,50.0004005,-17456.2265625,-17430.998046875,57.3918556530445,20.6259203622574,16.454937,0,0,0,40,4449,50.00595,-17443.6123046875,,,,,,,,,,,,,0,,,,0.00245,,,,,,50.0004005,,,,
,28493835.015,50.0016365,-22238.314453125,5.98516452814871E-5,5.35166958079557E-7,1,0.999253354069792,40.0298881530762,1.9977844605844,15.7399997115135,0.000676390940390179,0.000123430397556461,0.25,1.32882100801331E-7,5.98842505711481E-5,5.75163735781322E-7,50.0016365,50.0016365,-22243.21875,-22233.41015625,57.5700669554292,20.627880541763,17.214239,0,0,0,40,4449,50.00785,-22238.314453125,,,,,,,,,,,,,0,,,,-0.00245,,,,,,50.0016365,,,,
,28493933.015,50.000164,-27136.271484375,7.17209420089376E-5,8.12483953130262E-7,1,0.999253354069792,40.0298881530762,1.99763758253705,15.7399997115135,0.00081075847621462,0.000147547961842084,0.25,1.27608382619761E-7,7.17795529173297E-5,6.54934809213533E-7,50.000164,50.000164,-27146.138671875,-27126.404296875,57.3856026248907,20.6273747941769,16.454937,0,0,0,40,4449,50.00495,-27136.271484375,,,,,,,,,,,,,0,,,,0.00245,,,,,,50.000164,,,,
,28494029.875,50.0004082,-31973.2802734375,8.37716705086659E-5,5.56301406935389E-7,1,0.999253354069792,40.0298881530762,1.99775941023763,15.7399997115135,0.000945663825676383,0.000181410973656437,0.25,9.50168571160021E-7,8.38563027865869E-5,1.56313664388246E-6,50.0004082,50.0004082,-31978.1640625,-31968.396484375,57.1620568683907,20.6311831231491,16.834587,0,0,0,40,4449,50.00295,-31973.2802734375,,,,,,,,,,,,,0,,,,0,,,,,,50.0004082,,,,
,28494127.205,50.0005569,-36839.880859375,9.77708108446562E-5,7.15724755983969E-7,1,0.999253354069792,40.0298881530762,1.99767411098077,15.7399997115135,0.0011038791597209,0.000212092814218067,0.25,1.14280955673977E-6,9.7894861774339E-5,1.85311741094579E-6,50.0005569,50.0005569,-36849.85546875,-36829.90625,57.2910255740638,20.6299249883829,16.834587,0,0,0,40,4449,50.006,-36839.880859375,,,,,,,,,,,,,0,,,,-0.00245,,,,,,50.0005569,,,,
,28494222.745,50.0004311,-41612.39453125,0.000111024307867143,9.16703528994628E-7,1,0.999253354069792,40.0298881530762,1.99778388181044,15.7399997115135,0.00125495763941516,0.000235011013476414,0.25,7.830844971416E-7,0.00011119656440642,1.58226909513851E-6,50.0004311,50.0004311,-41622.4609375,-41602.328125,57.1675282680253,20.6319216805586,16.834587,0,0,0,40,4449,50.0086,-41612.39453125,,,,,,,,,,,,,0,,,,0,,,,,,50.0004311,,,,
,28494322.51,50.0018311,-46599.78515625,0.00012596374756589,8.71683191080214E-7,1,0.999253354069792,40.0298881530762,1.99775143609858,15.7399997115135,0.00142607287735121,0.000256057795626139,0.25,-4.20402113782807E-8,0.00012619742969759,8.54107435457306E-7,50.0018311,50.0018311,-46610.06640625,-46589.50390625,57.3129111726022,20.6299449377236,16.834587,0,0,0,40,4449,50.00495,-46599.78515625,,,,,,,,,,,,,0,,,,0.00245,,,,,,50.0018311,,,,
,28494419.34,50.0015221,-51439.736328125,0.000141410950524917,6.82183329058808E-7,1,0.999253354069792,40.0298881530762,1.99774410053838,15.7399997115135,0.00159631154517622,0.000315396835787511,0.25,2.42524308914664E-6,0.000141689045652902,3.42566723836251E-6,50.0015221,50.0015221,-51447.359375,-51432.11328125,57.3105662870445,20.6306378830639,16.834587,0,0,0,40,4449,50.0001,-51439.736328125,,,,,,,,,,,,,0,,,,0,,,,,,50.0015221,,,,
,28494517.08,50.001564,-56324.134765625,0.00015632046484085,1.14459722044383E-6,1,0.999253354069792,40.0298881530762,1.99774913678954,15.7399997115135,0.00176555222541507,0.000345800992835893,0.25,2.43539680023166E-6,0.000156665572730095,3.52841445408444E-6,50.001564,50.001564,-56334.328125,-56313.94140625,57.3582456267176,20.6307789505373,16.834587,0,0,0,40,4449,50.0009,-56324.134765625,,,,,,,,,,,,,0,,,,-0.0049,,,,,,50.001564,,,,
,28494616.015,50.0008621,-61268.77734375,0.000171490474693686,7.80563351184507E-7,1,0.999253354069792,40.0298881530762,1.99770643220274,15.7399997115135,0.00193968337325719,0.000366054483394643,0.25,1.50595617311606E-6,0.000171915352948554,2.6875172185634E-6,50.0008621,50.0008621,-61276.2734375,-61261.28125,57.5317671579869,20.6320766852552,16.834587,0,0,0,40,4449,49.9998,-61268.77734375,,,,,,,,,,,,,0,,,,-0.00245,,,,,,50.0008621,,,,
,28494714.5,50.0021172,-66190.87890625,0.000186095132835699,8.15438001338343E-7,1,0.999253354069792,40.0298881530762,1.99766600089057,15.7399997115135,0.00210446291205319,0.000401835766682506,0.25,2.05142967991898E-6,0.000186592860136708,3.31796861200431E-6,50.0021172,50.0021172,-66198.421875,-66183.3359375,57.3496477130061,20.6295303166586,16.834587,0,0,0,40,4449,50.00005,-66190.87890625,,,,,,,,,,,,,0,,,,-0.0049,,,,,,50.0021172,,,,
,28494812.76,50.0018311,-71100.609375,0.00020037577041976,9.86482064161887E-7,1,0.999253354069792,40.0298881530762,1.99758419470447,15.7399997115135,0.00226568214380371,0.00043631195630794,0.25,2.54310628645951E-6,0.000200949962090682,3.88923543344432E-6,50.0018311,50.0018311,-71100.609375,-71100.609375,57.149550812083,20.6319152588388,17.214239,0,0,0,40,4449,49.9983,-71100.609375,,,,,,,,,,,,,0,,,,0.00245,,,,,,50.0018311,,,,
,28494910.565,50.001812,-75987.4296875,0.000216635747551477,9.79849461826293E-7,1,0.999253354069792,40.0298881530762,1.99773991127428,15.7399997115135,0.00245026491794068,0.000471407366210863,0.25,2.73233323324464E-6,0.00021729830783305,4.16710877403584E-6,50.001812,50.001812,-75992.1171875,-75982.7421875,57.3691884259868,20.6311726520783,16.834587,0,0,0,40,4449,49.9984,-75987.4296875,,,,,,,,,,,,,0,,,,0,,,,,,50.001812,,,,
,28495008.925,50.001152,-80905.14453125,0.000232625239741683,9.00148712145779E-7,1,0.999253354069792,40.0298881530762,1.9976859568593,15.7399997115135,0.00263101383553588,0.000509149270357545,0.25,3.21040029436631E-6,0.00023337774555018,4.7293423848727E-6,50.001152,50.001152,-80910.2265625,-80900.0625,57.2347483206791,20.6308565460568,17.593889,0,0,0,40,4449,49.9969,-80905.14453125,,,,,,,,,,,,,0,,,,-0.0049,,,,,,50.001152,,,,
,28495103.165,50.0017014,-85612.02734375,0.000247867886083295,9.9160201704598E-7,1,0.999253354069792,40.0298881530762,1.99775769566328,15.7399997115135,0.00280205835761918,0.000553313124044714,0.25,4.38784031874393E-6,0.00024870520277318,5.98625157526446E-6,50.0017014,50.0017014,-85621.984375,-85602.0703125,57.261323690333,20.6328766460288,17.214239,0,0,0,40,4449,49.9973,-85612.02734375,,,,,,,,,,,,,0,,,,-0.00245,,,,,,50.0017014,,,,
,28495215.18,49.9992104,-89784.671875,0.000260326136861182,9.09415459892417E-7,1,0.999253354069792,40.0298881530762,1.997780894668,15.7399997115135,0.0029418885707544,0.000589335612341698,0.25,5.34721443674724E-6,0.000261237948596034,7.0068180496117E-6,49.9990273,49.9993935,-89797.109375,-89772.234375,57.3058765159291,20.6335376034852,16.834587,0,0,0,40,4449,49.99415,-89784.671875,,,,,,,,,,,,,0,,,,0,,,,,,49.9992104,,,,
,28495308.545,50.0004196,-85122.62109375,0.000245594849005982,1.15361173858272E-6,1,0.999253354069792,40.0298881530762,1.99764813890959,15.7399997115135,0.00277530085480841,0.000553046341409106,0.25,4.77234696760596E-6,0.00024641747085081,6.36003872715535E-6,50.0004196,50.0004196,-85125.5234375,-85119.71875,57.3215090863138,20.6329729005188,16.834587,0,0,0,40,4449,49.99395,-85122.62109375,,,,,,,,,,,,,0,,,,0.0049,,,,,,50.0004196,,,,
,28495403.985,49.9987411,-80355.83984375,0.000231939909603021,1.09063901272684E-6,1,0.999253354069792,40.0298881530762,1.99772234602742,15.7399997115135,0.00262039518868584,0.000523606743405123,0.25,4.60585262001973E-6,0.000232676401714814,6.12750387140394E-6,49.9987411,49.9987411,-80363.5703125,-80348.109375,57.3254172289099,20.6325514728273,16.834587,0,0,0,40,4449,49.99675,-80355.83984375,,,,,,,,,,,,,0,,,,0,,,,,,49.9987411,,,,
,28495503.265,49.999733,-75390.87890625,0.000214572471489077,9.21327077959405E-7,1,0.999253354069792,40.0298881530762,1.99779704449964,15.7399997115135,0.00242420767983688,0.000482148755931489,0.25,4.04711656195897E-6,0.000215214954922687,5.47491641461879E-6,49.999733,49.999733,-75400.7265625,-75381.03125,57.6130565239869,20.6284899143112,16.834587,0,0,0,40,4449,49.9985,-75390.87890625,,,,,,,,,,,,,0,,,,0.0049,,,,,,49.999733,,,,
,28495599.185,49.9981728,-70598.5390625,0.00019940832327072,9.92620907996077E-7,1,0.999253354069792,40.0298881530762,1.997724584557,15.7399997115135,0.00225728464388494,0.000420645030455895,0.25,1.33052165365028E-6,0.000199983616254745,2.66860625085388E-6,49.9981728,49.9981728,-70608.59375,-70588.484375,57.3136928011214,20.6307134420983,17.214239,0,0,0,40,4449,49.99395,-70598.5390625,,,,,,,,,,,,,0,,,,-0.00245,,,,,,49.9981728,,,,
,28495697.485,49.9995117,-65684.4296875,0.000183472775379654,9.24970629068115E-7,1,0.999253354069792,40.0298881530762,1.9975852267836,15.7399997115135,0.00207331201795022,0.000403792967359855,0.25,2.6953458476492E-6,0.00018395505961602,3.94757232496874E-6,49.9995117,49.9995117,-65686.921875,-65681.9375,57.4059249663907,20.6309943821771,17.214239,0,0,0,40,4449,50.0022,-65684.4296875,,,,,,,,,,,,,0,,,,0.0049,,,,,,49.9995117,,,,
,28495795.125,49.9995193,-60804.263671875,0.000167981109505291,8.97441662482062E-7,1,0.999253354069792,40.0298881530762,1.99756478266244,15.7399997115135,0.00189757493781662,0.000371042498488953,0.25,2.5781156916952E-6,0.000168386253765034,3.73967543381587E-6,49.9995193,49.9995193,-60814.15234375,-60794.375,57.3887291389676,20.6307566334979,17.214239,0,0,0,40,4449,49.9994,-60804.263671875,,,,,,,,,,,,,0,,,,0,,,,,,49.9995193,,,,
,28495893.67,50.0005646,-55882.197265625,0.000154617467604303,7.92453556546053E-7,1,0.999253354069792,40.0298881530762,1.99762201755063,15.7399997115135,0.00174967118787219,0.000322554106148694,0.25,6.9005859653551E-7,0.000154967508272286,1.76840678405806E-6,50.0005646,50.0005646,-55887.2578125,-55877.13671875,57.3715333115445,20.6281493033305,16.454937,0,0,0,40,4449,49.9964,-55882.197265625,,,,,,,,,,,,,0,,,,-0.0049,,,,,,50.0005646,,,,
,28495992.625,49.9993172,-50935.322265625,0.000138152382258584,8.0560567526799E-7,1,0.999253354069792,40.0298881530762,1.99747764157256,15.7399997115135,0.00156236525210781,0.000290983391187061,0.25,8.57893975638882E-7,0.000138431302429654,1.83324989982436E-6,49.9993172,49.9993172,-50950.40625,-50920.23828125,57.5622506702369,20.6283874381318,17.214239,0,0,0,40,4449,49.99745,-50935.322265625,,,,,,,,,,,,,0,,,,0,,,,,,49.9993172,,,,
,28496089.22,49.9989624,-46107.794921875,0.000123652644753944,7.59291679161688E-7,1,0.999253354069792,40.0298881530762,1.99724642292328,15.7399997115135,0.00139720191533684,0.00026426379450418,0.25,1.1038486299259E-6,0.000123870779778514,1.98659491929198E-6,49.9989624,49.9989624,-46117.875,-46097.71484375,57.2667950899676,20.6277638057601,17.214239,0,0,0,40,4449,50.0013,-46107.794921875,,,,,,,,,,,,,0,,,,0,,,,,,49.9989624,,,,
,28496185.735,49.9998703,-41285.73046875,0.000109578936276528,7.43593184089032E-7,1,0.999253354069792,40.0298881530762,1.99741434769709,15.7399997115135,0.00123601993613312,0.000245008457268798,0.25,1.93021755603443E-6,0.000109738565244118,2.72136599046104E-6,49.9998703,49.9998703,-41290.9375,-41280.5234375,57.2972786022176,20.6280971665242,16.454937,0,0,0,40,4449,49.999,-41285.73046875,,,,,,,,,,,,,0,,,,0.00245,,,,,,49.9998703,,,,
,28496285.14,49.9997253,-36313.509765625,9.40569270489737E-5,7.41906358053632E-7,1,0.999253354069792,40.0298881530762,1.99748274263397,15.7399997115135,0.00106338776989486,0.000195299355800788,0.25,3.28620029042724E-7,9.41790677630642E-5,1.0115333452041E-6,49.9997253,49.9997253,-36323.18359375,-36303.8359375,57.3441763133715,20.6269805130693,16.834587,0,0,0,40,4449,49.99795,-36313.509765625,,,,,,,,,,,,,0,,,,0.0049,,,,,,49.9997253,,,,
,28496379.805,49.9993477,-31587.048828125,8.0835686274757E-5,6.89427968428626E-7,1,0.999253354069792,40.0298881530762,1.99757252197818,15.7399997115135,0.000910588723274146,0.000185204367933262,0.25,1.81575788947834E-6,8.09091179724775E-5,2.40850924937389E-6,49.9993477,49.9993477,-31591.9140625,-31582.18359375,57.3004051162945,20.6272022331911,17.214239,0,0,0,40,4449,50.0042,-31587.048828125,,,,,,,,,,,,,0,,,,0.0049,,,,,,49.9993477,,,,
,28496477.6,50.0006943,-26696.5078125,6.63483847868311E-5,7.37909742722425E-7,1,0.999253354069792,40.0298881530762,1.99749949312421,15.7399997115135,0.000746135277258186,0.000157695762795436,0.25,1.99387664611974E-6,6.63871365958478E-5,2.48346916062813E-6,50.0006943,50.0006943,-26704.173828125,-26688.841796875,57.0878021590637,20.6269951261005,16.834587,0,0,0,40,4449,50.0008,-26696.5078125,,,,,,,,,,,,,0,,,,0,,,,,,50.0006943,,,,
,28496574.235,49.9996567,-21869.1904296875,5.20624812938961E-5,6.50882896648276E-7,1,0.999253354069792,40.0298881530762,1.99745995248385,15.7399997115135,0.000587374030755852,0.000112269805697848,0.25,5.50857900216282E-7,5.20865164702094E-5,9.35945077702421E-7,49.9996567,49.9996567,-21876.55078125,-21861.830078125,57.2058280654676,20.6250398786267,17.214239,0,0,0,40,4449,50.00435,-21869.1904296875,,,,,,,,,,,,,0,,,,-0.00245,,,,,,49.9996567,,,,
,28496669.65,49.9989815,-17102.2275390625,3.77330068790712E-5,6.74198826747785E-7,1,0.999253354069792,40.0298881530762,1.99751198742226,15.7399997115135,0.000426279295232489,7.76147130976107E-5,0.25,6.76754651878585E-8,3.77429540520972E-5,3.47563027417962E-7,49.9989815,49.9989815,-17109.595703125,-17094.859375,57.4160861371407,20.6261806658557,17.214239,0,0,0,40,4449,50.0042,-17102.2275390625,,,,,,,,,,,,,0,,,,-0.00245,,,,,,49.9989815,,,,
,28496765.375,50.0003548,-12314.5419921875,2.42056594182335E-5,4.38917667996755E-7,1,0.999253354069792,40.0298881530762,1.99754082821261,15.7399997115135,0.000273691148181105,4.81080330715891E-5,0.25,-1.04798068015774E-7,2.42068560698845E-5,7.51377950968682E-8,50.0003548,50.0003548,-12321.986328125,-12307.09765625,57.1995750373137,20.6265342295149,16.834587,0,0,0,40,4449,50.0054,-12314.5419921875,,,,,,,,,,,,,0,,,,0,,,,,,50.0003548,,,,
,28496860.88,49.9990997,-7538.95947265625,1.13114712354844E-5,3.64616527327242E-7,1,0.999253354069792,40.0298881530762,1.99763837539195,15.7399997115135,0.000127702987019896,2.34139307363446E-5,0.25,3.38964893698079E-8,1.13086015054601E-5,1.18058389573194E-7,49.9990997,49.9990997,-7548.9609375,-7528.9580078125,57.169873153583,20.6273187407457,16.834587,0,0,0,40,4449,50.0054,-7538.95947265625,,,,,,,,,,,,,0,,,,-0.00245,,,,,,49.9990997,,,,
,28496957.775,49.9991531,-2698.44030761719,-1.6882083183513E-6,2.95848534058568E-7,1,0.999253354069792,40.0298881530762,1.99777689163321,15.7399997115135,-1.7988002274657E-5,-9.42032700785126E-6,0.25,-5.29800041667677E-7,-1.68349014363493E-6,-5.42117682465859E-7,49.9991531,49.9991531,-2705.9931640625,-2690.88745117187,57.1784710672945,20.6275658945438,16.834587,0,0,0,40,4449,50.0014,-2698.44030761719,,,,,,,,,,,,,0,,,,0,,,,,,49.9991531,,,,
,28497053.445,50.0004196,2081.103515625,-1.1887553023573E-5,2.82078950088565E-7,1,0.999253354069792,40.0298881530762,1.99761017437555,15.7399997115135,-0.000134213214185367,-2.43649989375678E-5,0.25,-1.48203878574118E-8,-1.18816745875778E-5,-1.03257409072658E-7,50.0004196,50.0004196,2073.77758789062,2088.42944335938,57.1448610409676,20.6283630294661,17.214239,0,0,0,40,4449,50.00135,2081.103515625,,,,,,,,,,,,,0,,,,0,,,,,,50.0004196,,,,
,28497149.72,50.0009995,6894.20288085938,-2.35090989456283E-5,3.91386103864555E-7,1,0.999253354069792,40.0298881530762,1.99782106867088,15.7399997115135,-0.0002647854986704,-5.22113963165314E-5,0.25,-3.84394355163049E-7,-2.35000202866109E-5,-5.59234528775232E-7,50.0009995,50.0009995,6891.49755859375,6896.908203125,57.4285921934484,20.6276515441737,17.214239,0,0,0,40,4449,50.0025,6894.20288085938,,,,,,,,,,,,,0,,,,0.0049,,,,,,50.0009995,,,,
,28497245.68,50.0003624,11690.0874023437,-3.43736288900334E-5,5.7346134412116E-7,1,0.999253354069792,40.0298881530762,1.99792142366396,15.7399997115135,-0.000387625825793189,-7.43773061272928E-5,0.25,-3.86591251161887E-7,-3.43701369882322E-5,-6.42161021307016E-7,50.0003624,50.0003624,11685.2080078125,11694.966796875,57.3394865422561,20.6242633092478,17.214239,0,0,0,40,4449,49.999,11690.0874023437,,,,,,,,,,,,,0,,,,0.00245,,,,,,50.0003624,,,,
,28497338.735,49.9999809,16340.2651367188,-4.5056278302559E-5,5.95951725173384E-7,1,0.999253354069792,40.0298881530762,1.99789339248019,15.7399997115135,-0.000507611778117192,-0.000100855222113564,0.25,-8.0296531292816E-7,-4.50608709572449E-5,-1.13749098871169E-6,49.9999809,49.9999809,16337.6982421875,16342.83203125,57.3176009437176,20.6249128743974,17.593889,0,0,0,40,4449,50.00085,16340.2651367188,,,,,,,,,,,,,0,,,,0.0049,,,,,,49.9999809,,,,
,28497436.84,50.0007668,21242.0869140625,-5.66157490096882E-5,5.87574462488106E-7,1,0.999253354069792,40.0298881530762,1.99771081494119,15.7399997115135,-0.000637421803710285,-0.000129738472228743,0.25,-1.27457551908426E-6,-5.66348865555028E-5,-1.69389135165526E-6,50.0007668,50.0007668,21234.5078125,21249.666015625,57.2261504069676,20.6217638682942,17.593889,0,0,0,40,4449,50.0018,21242.0869140625,,,,,,,,,,,,,0,,,,0.0049,,,,,,50.0007668,,,,
,28497534.135,50.0014763,26104.5517578125,-6.83218951059478E-5,7.07374924220294E-7,1,0.999253354069792,40.0298881530762,1.99753966327066,15.7399997115135,-0.000771194302539918,-0.000146419298237501,0.25,-6.40855426860623E-7,-6.83699248325838E-5,-1.14419527219963E-6,50.0014763,50.0014763,26092.021484375,26117.08203125,57.1206305568714,20.6218247266364,16.834587,0,0,0,40,4449,49.99875,26104.5517578125,,,,,,,,,,,,,0,,,,0,,,,,,50.0014763,,,,
,28497629.61,50.0006485,30877.8359375,-8.05674726085285E-5,6.05103420360162E-7,1,0.999253354069792,40.0298881530762,1.99768682351072,15.7399997115135,-0.000910030682008254,-0.000170994256031895,0.25,-6.06841411676886E-7,-8.06463014478098E-5,-1.19690621337365E-6,50.0006485,50.0006485,30875.27734375,30880.39453125,57.0627900464484,20.6198090283491,17.214239,0,0,0,40,4449,50.0015,30877.8359375,,,,,,,,,,,,,0,,,,0,,,,,,50.0006485,,,,
,28497730.155,50.0007591,35902.6875,-9.47469899291082E-5,7.23251005040777E-7,1,0.999253354069792,40.0298881530762,1.99765257529232,15.7399997115135,-0.00106970533423343,-0.000205341275510479,0.25,-1.09046949902028E-6,-9.48624653475448E-5,-1.77983733027488E-6,50.0007591,50.0007591,35892.49609375,35912.87890625,57.2972786022176,20.6229166920107,17.593889,0,0,0,40,4449,49.9987,35902.6875,,,,,,,,,,,,,0,,,,0,,,,,,50.0007591,,,,
,28497827.665,50.0005379,40777.88671875,-0.000109213911367774,6.98914418947276E-7,1,0.999253354069792,40.0298881530762,1.99778040388042,15.7399997115135,-0.0012357650270926,-0.0002237855826862,0.25,-1.16655708327068E-7,-0.000109383129334315,-9.03062576913355E-7,50.0005379,50.0005379,40770.52734375,40785.24609375,57.1675282680253,20.6212721945128,17.214239,0,0,0,40,4449,49.9981,40777.88671875,,,,,,,,,,,,,0,,,,0.00245,,,,,,50.0005379,,,,
,28497926.455,50.0002098,45715.7734375,-0.000123824496102913,6.68625617629901E-7,1,0.999253354069792,40.0298881530762,1.99774787916388,15.7399997115135,-0.00139980093124771,-0.000262739238751782,0.25,-9.32355546847444E-7,-0.000124041604629412,-1.81676235549331E-6,50.0002098,50.0002098,45713.36328125,45718.18359375,57.4371901071599,20.622103583166,17.214239,0,0,0,40,4449,49.9957,45715.7734375,,,,,,,,,,,,,0,,,,-0.0049,,,,,,50.0002098,,,,
,28498023.545,50.00099755,50565.916015625,-0.000137170358929736,7.26847777395107E-7,1,0.999253354069792,40.0298881530762,1.99784597446264,15.7399997115135,-0.00155002301733347,-0.000297201755167492,0.25,-1.57874372479178E-6,-0.000137439726012543,-2.54946082632038E-6,50.0008125,50.0011826,50560.921875,50570.91015625,57.3902923960061,20.6225224850522,17.214239,0,0,0,40,4449,49.99735,50565.916015625,,,,,,,,,,,,,0,,,,0.0049,,,,,,50.00099755,,,,
,28498119.88,50.0003204,55383.275390625,-0.00015211741962307,1.04911747568095E-6,1,0.999253354069792,40.0298881530762,1.99784116914601,15.7399997115135,-0.00172049806353828,-0.000323053280583338,0.25,-1.1798223699403E-6,-0.000152454761705155,-2.24318347049937E-6,50.0003204,50.0003204,55373.37109375,55393.1796875,57.0362146767945,20.6225542559101,16.834587,0,0,0,40,4449,49.99495,55383.275390625,,,,,,,,,,,,,0,,,,0,,,,,,50.0003204,,,,
,28498217.845,50.0014381,60278.197265625,-0.000167370645474726,7.63182530765036E-7,1,0.999253354069792,40.0298881530762,1.99763760872734,15.7399997115135,-0.00189520360194972,-0.000344624487180683,0.25,-3.53587102426944E-7,-0.000167785497915444,-1.50700595845712E-6,50.0014381,50.0014381,60270.5703125,60285.82421875,57.1722180391407,20.6200479057257,17.593889,0,0,0,40,4449,49.9938,60278.197265625,,,,,,,,,,,,,0,,,,0,,,,,,50.0014381,,,,
,28498312.975,50.0012817,65033.787109375,-0.000182713752401987,8.85109783323251E-7,1,0.999253354069792,40.0298881530762,1.99750184401718,15.7399997115135,-0.00206828449311312,-0.000381534487240712,0.25,-8.6702811219551E-7,-0.000183201057552225,-2.11146448557738E-6,50.0012817,50.0012817,65028.73046875,65038.84375,57.2245871499291,20.6194855630921,16.834587,0,0,0,40,4449,49.9924,65033.787109375,,,,,,,,,,,,,0,,,,0.00245,,,,,,50.0012817,,,,
,28498409.77,50.0024109,69871.390625,-0.000197600819508829,8.22323408054277E-7,1,0.999253354069792,40.0298881530762,1.99753335080249,15.7399997115135,-0.0022363919249665,-0.000417681054743669,0.25,-1.39495485599664E-6,-0.00019816450146038,-2.72392830338808E-6,50.0024109,50.0024109,69866.390625,69876.390625,57.2832092888714,20.6204406412454,17.593889,0,0,0,40,4449,49.9921,69871.390625,,,,,,,,,,,,,0,,,,-0.0049,,,,,,50.0024109,,,,
,28498507.78,50.0006752,74769.23046875,-0.000212025163821669,1.00704385871506E-6,1,0.999253354069792,40.0298881530762,1.99769749637836,15.7399997115135,-0.00240053382138143,-0.000446961600791606,0.25,-1.40011928155164E-6,-0.000212671898386588,-2.80555634766496E-6,50.0006752,50.0006752,74764.2109375,74774.25,57.1550222117176,20.6215642226659,17.214239,0,0,0,40,4449,49.99245,74769.23046875,,,,,,,,,,,,,0,,,,0,,,,,,50.0006752,,,,
,28498605.43,50.0018845,79652.234375,-0.000228615693146555,1.07804070062431E-6,1,0.999253354069792,40.0298881530762,1.9977598051527,15.7399997115135,-0.00259182581857834,-0.00046584288482793,0.25,-1.04007420627632E-7,-0.000229364402970174,-1.59254491169246E-6,50.0018845,50.0018845,79642.1640625,79662.3046875,57.1151591572368,20.6180808302512,17.214239,0,0,0,40,4449,49.9919,79652.234375,,,,,,,,,,,,,0,,,,0.00245,,,,,,50.0018845,,,,
,28498700.72,50.0014839,84415.55078125,-0.000243304936492617,1.13301984787103E-6,1,0.999253354069792,40.0298881530762,1.9977672277811,15.7399997115135,-0.00275676615211758,-0.000507415385563516,0.25,-1.15356020401221E-6,-0.000244136651673294,-2.71760180372987E-6,50.0014839,50.0014839,84405.515625,84425.5859375,57.065134932006,20.6173359140123,16.834587,0,0,0,40,4449,49.991,84415.55078125,,,,,,,,,,,,,0,,,,0,,,,,,50.0014839,,,,
,28498792.915,50.0015755,89023.875,-0.000256242044070522,1.02581214743826E-6,1,0.999253354069792,40.0298881530762,1.99767558330167,15.7399997115135,-0.00290115518926857,-0.000548539982552703,0.25,-2.4812506447897E-6,-0.000257150365492647,-4.10881995153347E-6,50.0015755,50.0015755,89014.0625,89033.6875,56.9900985941599,20.6156800132586,16.834587,0,0,0,40,4449,49.9871,89023.875,,,,,,,,,,,,,0,,,,0.0049,,,,,,50.0015755,,,,
,28498906.025,49.9993782,86358.71484375,-0.000247694342195426,1.0977510911399E-6,1,0.999253354069792,40.0298881530762,1.99781516377465,15.7399997115135,-0.0028027559675766,-0.000538924550608953,0.25,-3.15138466905626E-6,-0.000248545122543578,-4.74077334775958E-6,49.9991913,49.9995651,86348.8046875,86368.625,57.0096393071407,20.6170287334198,17.593889,0,0,0,40,4449,49.98805,86358.71484375,,,,,,,,,,,,,0,,,,0.00245,,,,,,49.9993782,,,,
,28498997.115,49.9992294,81802.3828125,-0.000234199368557988,1.13559812324099E-6,1,0.999253354069792,40.0298881530762,1.99780674914795,15.7399997115135,-0.00265075623127825,-0.000503142033442412,0.25,-2.39868987410583E-6,-0.000234969806626463,-3.92102941729135E-6,49.9992294,49.9992294,81769.8046875,81834.9609375,57.1143775287176,20.6173679136232,17.593889,0,0,0,40,4449,49.98945,81802.3828125,,,,,,,,,,,,,0,,,,0.00245,,,,,,49.9992294,,,,
,28499094.18,50.0003929,76951.140625,-0.000218776812701269,1.04966754603437E-6,1,0.999253354069792,40.0298881530762,1.99775031526963,15.7399997115135,-0.00247659594784673,-0.000464848739019125,0.25,-1.77226908058445E-6,-0.000219460155427908,-3.21410221397435E-6,50.0003929,50.0003929,76941.2578125,76961.0234375,57.1620568683907,20.6194836750168,17.214239,0,0,0,40,4449,49.9873,76951.140625,,,,,,,,,,,,,0,,,,-0.00245,,,,,,50.0003929,,,,
,28499193.055,49.9997253,72008.07421875,-0.000203620217702742,1.05843906488809E-6,1,0.999253354069792,40.0298881530762,1.99785071695246,15.7399997115135,-0.00230553983115551,-0.000427851024586702,0.25,-1.21176006746805E-6,-0.000204220006605963,-2.57216834572359E-6,49.9997253,49.9997253,71998.265625,72017.8828125,57.187068981006,20.617282535328,17.214239,0,0,0,40,4449,49.98885,72008.07421875,,,,,,,,,,,,,0,,,,-0.00245,,,,,,49.9997253,,,,
,28499288.795,49.9992294,67222.93359375,-0.000188552342002212,1.18078717944852E-6,1,0.999253354069792,40.0298881530762,1.99773668409245,15.7399997115135,-0.00213417905961949,-0.000397327450941805,0.25,-1.21338908853302E-6,-0.000189070430013865,-2.49070717317288E-6,49.9992294,49.9992294,67220.328125,67225.5390625,57.1878506095253,20.6187650209428,17.214239,0,0,0,40,4449,49.9917,67222.93359375,,,,,,,,,,,,,0,,,,0,,,,,,49.9992294,,,,
,28499385.965,49.9992638,62366.818359375,-0.000172551006114091,7.15479064612082E-7,1,0.999253354069792,40.0298881530762,1.99777881484547,15.7399997115135,-0.00195302068665921,-0.000361762055840716,0.25,-9.37400408413329E-7,-0.00017299059647805,-2.12143532436528E-6,49.9992638,49.9992638,62361.7109375,62371.92578125,57.2581971762561,20.6189861823428,16.834587,0,0,0,40,4449,49.99295,62366.818359375,,,,,,,,,,,,,0,,,,0.0049,,,,,,49.9992638,,,,
,28499485.005,49.9985313,57416.064453125,-0.000156665782337186,1.03657731831472E-6,1,0.999253354069792,40.0298881530762,1.99747582837328,15.7399997115135,-0.00177055097345132,-0.000339622274665622,0.25,-1.83325019458125E-6,-0.000157023609632747,-2.92441048553491E-6,49.9985313,49.9985313,57408.640625,57423.48828125,57.1198489283522,20.620347245235,16.834587,0,0,0,40,4449,49.99645,57416.064453125,,,,,,,,,,,,,0,,,,-0.0049,,,,,,49.9985313,,,,
,28499580.76,49.9980354,52631.37109375,-0.000143693824897376,7.9590311306348E-7,1,0.999253354069792,40.0298881530762,1.99737321199007,15.7399997115135,-0.00162427062629424,-0.000307171895912548,0.25,-1.29447933524894E-6,-0.000143992551364349,-2.30594545460357E-6,49.9978256,49.9982452,52616.41796875,52646.32421875,57.2089545795445,20.6213215128568,16.834587,0,0,0,40,4449,49.9901,52631.37109375,,,,,,,,,,,,,0,,,,0.00245,,,,,,49.9980354,,,,
,28499675.39,49.9985771,47901.2734375,-0.00012910572156687,7.14672237967284E-7,1,0.999253354069792,40.0298881530762,1.99764216055918,15.7399997115135,-0.00145959233608033,-0.000273928092006205,0.25,-9.73585679254422E-7,-0.0001293459761045,-1.89155415199224E-6,49.9985771,49.9985771,47898.76953125,47903.77734375,56.9408559974483,20.619414277144,16.834587,0,0,0,40,4449,49.9918,47901.2734375,,,,,,,,,,,,,0,,,,-0.00245,,,,,,49.9985771,,,,
,28499772.58,49.9998245,43043.322265625,-0.000113475637931262,7.38415360154569E-7,1,0.999253354069792,40.0298881530762,1.9977448072438,15.7399997115135,-0.00128156950336714,-0.000246674724149494,0.25,-1.37358326743846E-6,-0.000113655603519032,-2.18923801061134E-6,49.9998245,49.9998245,43040.76171875,43045.8828125,57.3512109700445,20.6204618362074,17.214239,0,0,0,40,4449,49.99655,43043.322265625,,,,,,,,,,,,,0,,,,-0.0049,,,,,,49.9998245,,,,
,28499869.385,50.0002289,38203.349609375,-9.91790587894459E-5,7.83386686820146E-7,1,0.999253354069792,40.0298881530762,1.99793269934444,15.7399997115135,-0.00111797425484406,-0.000226409203816561,0.25,-2.15241715954906E-6,-9.93045408078274E-5,-2.8728344576493E-6,50.0002289,50.0002289,38198.55078125,38208.1484375,57.2793011462753,20.6229581314577,17.593889,0,0,0,40,4449,49.9926,38203.349609375,,,,,,,,,,,,,0,,,,0,,,,,,50.0002289,,,,
,28499967.465,49.9990616,33303.75390625,-8.41167269510951E-5,6.67963309158965E-7,1,0.999253354069792,40.0298881530762,1.99817329784289,15.7399997115135,-0.000947301808249618,-0.000196144992584899,0.25,-2.18714318357212E-6,-8.41984998138073E-5,-2.80298351248693E-6,49.9990425,49.9990807,33296.0078125,33311.5,57.2027015513907,20.6205992499372,17.214239,0,0,0,40,4449,49.99005,33303.75390625,,,,,,,,,,,,,0,,,,-0.00245,,,,,,49.9990616,,,,
,28500063.805,49.9991074,28486.4228515625,-7.09670780565232E-5,6.58248578122248E-7,1,0.999253354069792,40.0298881530762,1.99812461072307,15.7399997115135,-0.000797248625887116,-0.000175085428071385,0.25,-2.69479181713035E-6,-7.10113028382095E-5,-3.21807517972652E-6,49.9991074,49.9991074,28478.984375,28493.861328125,57.4074882234292,20.6195194012627,17.214239,0,0,0,40,4449,49.9955,28486.4228515625,,,,,,,,,,,,,0,,,,-0.0049,,,,,,49.9991074,,,,
,28500162.09,49.9989738,23576.37890625,-5.59502993359267E-5,6.4961447828886E-7,1,0.999253354069792,40.0298881530762,1.998256255045,15.7399997115135,-0.000631827492101729,-0.00011908806608529,0.25,-4.49188920392966E-7,-5.59823464523222E-5,-8.62358955986989E-7,49.9989738,49.9989738,23566.4765625,23586.28125,57.2839909173907,20.6186999062382,16.834587,0,0,0,40,4449,49.9962,23576.37890625,,,,,,,,,,,,,0,,,,0.0049,,,,,,49.9989738,,,,
,28500258.055,49.9995193,18779.0517578125,-4.27055546560174E-5,4.83670636134167E-7,1,0.999253354069792,40.0298881530762,1.99845249161362,15.7399997115135,-0.000481482739203211,-9.47324025041588E-5,0.25,-6.82074227432095E-7,-4.27161843095403E-5,-9.98736960585474E-7,49.9995193,49.9995193,18768.94140625,18789.162109375,57.3668435404292,20.6157852351671,17.593889,0,0,0,40,4449,49.9972,18779.0517578125,,,,,,,,,,,,,0,,,,0.00245,,,,,,49.9995193,,,,
,28500354.385,49.9985199,13967.0263671875,-2.83167515976477E-5,4.96630558758849E-7,1,0.999253354069792,40.0298881530762,1.99841156554653,15.7399997115135,-0.000320142751020702,-5.73778014625721E-5,0.25,2.77198052731548E-8,-2.83198941736934E-5,-1.826476206444E-7,49.9985199,49.9985199,13962.3916015625,13971.6611328125,57.0526288756983,20.6184998249316,17.214239,0,0,0,40,4449,49.9968,13967.0263671875,,,,,,,,,,,,,0,,,,0,,,,,,49.9985199,,,,
,28500447.035,49.9992256,9334.30810546875,-1.57450830592314E-5,4.16520323268776E-7,1,0.999253354069792,40.0298881530762,1.99832235973202,15.7399997115135,-0.000176609033104022,-3.93858009869668E-5,0.25,-6.47282258591502E-7,-1.573805253456E-5,-7.64324579189264E-7,49.9992256,49.9992256,9324.2646484375,9344.3515625,57.3449579418907,20.6188358482395,17.214239,0,0,0,40,4449,50.0024,9334.30810546875,,,,,,,,,,,,,0,,,,0,,,,,,49.9992256,,,,
,28500542.32,50.0000267,4571.5751953125,-2.87801863494783E-6,3.89710233407285E-7,1,0.999253354069792,40.0298881530762,1.99836049364623,15.7399997115135,-3.17239353537362E-5,-1.02549000599698E-5,0.25,-3.8890113273667E-7,-2.874036776164E-6,-4.10171082290195E-7,50.0000267,50.0000267,4561.4697265625,4581.6806640625,57.2495992625445,20.6188882546882,16.834587,0,0,0,40,4449,49.9968,4571.5751953125,,,,,,,,,,,,,0,,,,0,,,,,,50.0000267,,,,
,28500634.115,50.000042,-0.342534884810448,8.88873854183209E-6,2.84809429691593E-7,1,0.999253354069792,40.0298881530762,1.99839187707583,15.7399997115135,0.000101881040652642,9.93086577497833E-6,0.25,-7.23065584562296E-7,8.88916691365014E-6,-6.56546609262619E-7,50.000042,50.000042,-0.365370541810989,-0.319699227809906,57.3027500018522,20.6204449786879,16.834587,0,0,0,40,4417,49.9962,-0.342534884810448,,,,,,,,,,,,,0,,,,-0.0049,,,,,,50.000042,,,,