File: data/looselyPackedNP/ios-7/ppms/background/DTOLUENE_HYS300K.DAT
[Header]
; VSM Data File (default extension .dat)
; Copyright (c) 2003-2013, Quantum Design, Inc. All rights reserved.
TITLE,
FILEOPENTIME,27854256.23,11/19/2018,5:18 pm
BYAPP,VSM,2.0,2.0
INFO,PPMS VSM Option Release 1.4.10 Build 1,APPNAME
INFO,Quantum Design Linear Motor Servo Controller,MOTOR_MODULE_NAME
INFO,3101-100 M1,MOTOR_HW_VERSION
INFO,MMC1014,MOTOR_SERIAL_NUMBER
INFO,SRV No X-over 01.03.11,MOTOR_SOFTWARE_VERSION
INFO,Quantum Design VSM Detection Module,VSM_MODULE_NAME
INFO,3101-150 F0,VSM_HW_VERSION
INFO,VSM707,VSM_SERIAL_NUMBER
INFO,VSM No X-over 01.02.05 May 20 2008 13:51:47,VSM_SOFTWARE_VERSION
INFO,704,PREAMP_SERIAL_NUMBER
INFO,822,COIL_SERIAL_NUMBER
INFO,0,MOMENT_UNITS
INFO,dtoluene,SAMPLE_MATERIAL
INFO,dispersion,SAMPLE_COMMENT
INFO,,SAMPLE_MASS
INFO,,SAMPLE_VOLUME
INFO,,SAMPLE_MOLECULAR_WEIGHT
INFO,,SAMPLE_SIZE
INFO,,SAMPLE_SHAPE
DATATYPE,COMMENT,1
DATATYPE,TIME,2
STARTUPAXIS,X,2
STARTUPAXIS,Y1,5
[Data]
Comment,Time Stamp (sec),Temperature (K),Magnetic Field (Oe),Moment (emu),M. Std. Err. (emu),Transport Action,Averaging Time (sec),Frequency (Hz),Peak Amplitude (mm),Center Position (mm),Coil Signal' (mV),Coil Signal" (mV),Range (mV),M. Quad. Signal (emu),M. Raw' (emu),M. Raw" (emu),Min. Temperature (K),Max. Temperature (K),Min. Field (Oe),Max. Field (Oe),Mass (grams),Motor Lag (deg),Pressure (Torr),VSM Status (code),Motor Status (code),Measure Status (code),Measure Count,PPMS Status (code),System Temp. (K),System Field (Oe),Sample Position (deg),Bridge 1 Resistance (ohms),Bridge 1 Excitation (에),Bridge 2 Resistance (ohms),Bridge 2 Excitation (에),Bridge 3 Resistance (ohms),Bridge 3 Excitation (에),Bridge 4 Resistance (ohms),Bridge 4 Excitation (에),Signal 1 Vin (V),Signal 2 Vin (V),Digital Inputs (code),Drive 1 Iout (mA),Drive 1 Ipower (W),Drive 2 Iout (mA),Drive 2 Ipower (W),Pressure (),Map 20 (),Map 21 (),Map 22 (),Map 23 (),Map 24 (),Map 25 (),Map 26 (),Map 27 (),Map 28 (),Map 29 ()
,27854278.91,299.9847107,0.487160742282867,,,2,,,,21.3500002884865,,,,,,,299.9847107,299.9847107,0.487160742282867,0.487160742282867,,,22.529354,,,,-99999999,4369,300.3034,0.487160742282867,,,,,,,,,,,,,,,,,,,,,,,299.9847107,,,,
,27854374.68,300.0840454,1967.98291015625,-6.34189013243598E-5,7.07318428084359E-7,1,0.999253354069792,40.0298881530762,2.00695007258229,21.3099997490644,-0.000679896942662204,-0.000359407771322095,0.25,-2.06456837145577E-5,-6.34031202745662E-5,-2.06870792463274E-5,300.0840454,300.0840454,1967.98291015625,1967.98291015625,58.9426066351985,21.7014414155592,22.529354,0,0,0,40,4449,300.1797,1967.98291015625,,,,,,,,,,,,,0,,,,0,,,,,,300.0840454,,,,
,27854416.22,300.0913696,4039.70190429687,-0.000130170907122315,7.97071631169827E-7,1,0.999253354069792,40.0298881530762,1.99752683856858,21.3200002908707,-0.00138937286708175,-0.000733833677004105,0.25,-4.23264128372098E-5,-0.000130138522133487,-4.24113523321508E-5,300.0913696,300.0913696,4037.0673828125,4042.33642578125,58.7503260194678,21.6669496386602,22.909004,0,0,0,40,4449,300.16185,4039.70190429687,,,,,,,,,,,,,0,,,,0.00245,,,,,,300.0913696,,,,
,27854458.6,300.09375,6156.6435546875,-0.000194909479377392,9.81147132126854E-7,1,0.999253354069792,40.0298881530762,2.00026098133172,21.3200002908707,-0.00208140031958131,-0.00110989023220338,0.25,-6.42298008651449E-5,-0.000194860411947615,-6.43569357136027E-5,300.09375,300.09375,6149.27392578125,6164.01318359375,59.0707937123524,21.6301306696847,22.529354,0,0,0,40,4449,300.1096,6156.6435546875,,,,,,,,,,,,,0,,,,0,,,,,,300.09375,,,,
,27854502.655,300.0901794,8357.8388671875,-0.000266944365721781,1.53662586945755E-6,1,0.999253354069792,40.0298881530762,2.00173903371088,21.3200002908707,-0.00285621756232156,-0.00150060762673486,0.25,-8.61548286632642E-5,-0.000266878419914916,-8.63289759837759E-5,300.0901794,300.0901794,8352.8310546875,8362.8466796875,59.3615595215063,21.609670845822,22.529354,0,0,0,40,4449,300.086,8357.8388671875,,,,,,,,,,,,,0,,,,0.0049,,,,,,300.0901794,,,,
,27854547.56,300.0840759,10602.1616210938,-0.000339275029584812,2.31726289145225E-6,1,0.999253354069792,40.0298881530762,2.00300444268705,21.3200002908707,-0.00363395972732306,-0.00189890984631287,0.25,-0.000108665903914831,-0.000339191864307704,-0.000108887236644907,300.0840759,300.0840759,10597.0087890625,10607.314453125,59.2560396714101,21.5964443400014,22.909004,0,0,0,40,4449,300.04955,10602.1616210938,,,,,,,,,,,,,0,,,,0,,,,,,300.0840759,,,,
,27854590.075,300.08003235,12725.7905273437,-0.000402411211639785,2.17273296964827E-6,1,0.999253354069792,40.0298881530762,2.00482116851506,21.3200002908707,-0.00430981913371995,-0.00227800791793822,0.25,-0.000130982758027023,-0.000402311277771567,-0.000131245140226038,300.0794373,300.0806274,12720.974609375,12730.6064453125,59.0543795134486,21.5774608857133,22.149702,0,0,0,40,4449,300.04055,12725.7905273437,,,,,,,,,,,,,0,,,,-0.00245,,,,,,300.08003235,,,,
,27854633.265,300.0773621,14885.0380859375,-0.00046953226469555,2.81405851218314E-6,1,0.999253354069792,40.0298881530762,2.00528238637906,21.3200002908707,-0.0050280230599384,-0.00266875030494591,0.25,-0.000153728295890966,-0.00046941514691792,-0.000154034347244523,300.0773621,300.0773621,14880.0029296875,14890.0732421875,59.4670793716024,21.572513102338,22.529354,0,0,0,40,4449,300.0074,14885.0380859375,,,,,,,,,,,,,0,,,,-0.0049,,,,,,300.0773621,,,,
,27854678.39,300.0534973,17141.4814453125,-0.000537466594953845,3.3732729793459E-6,1,0.999253354069792,40.0298881530762,2.00587531411938,21.3200002908707,-0.00575977852958685,-0.00304046799038863,0.25,-0.0001746254868509,-0.000537333939745254,-0.000174975881796242,300.0534973,300.0534973,17133.884765625,17149.078125,59.2873048121794,21.5647735719653,22.529354,0,0,0,40,4449,299.9949,17141.4814453125,,,,,,,,,,,,,0,,,,0,,,,,,300.0534973,,,,
,27854722.095,300.0531311,19325.3369140625,-0.000602875567597094,3.52794041471294E-6,1,0.999253354069792,40.0298881530762,2.00644613907824,21.3200002908707,-0.00645302495744472,-0.00346604669199611,0.25,-0.000200686954488471,-0.000602723656598354,-0.000201079692407648,300.0531311,300.0531311,19312.77734375,19337.896484375,59.4600447149294,21.5545487821516,22.909004,0,0,0,40,4449,299.9851,19325.3369140625,,,,,,,,,,,,,0,,,,-0.00245,,,,,,300.0531311,,,,
,27854767.36,300.0478821,21589.111328125,-0.000673633808477295,4.17990901568509E-6,1,0.999253354069792,40.0298881530762,2.00701087797722,21.3200002908707,-0.00722300962010024,-0.0038123113557906,0.25,-0.000218821572834979,-0.000673467841874228,-0.000219260479504407,300.0478821,300.0478821,21581.623046875,21596.599609375,59.5968297057948,21.5454327360811,22.909004,0,0,0,40,4449,299.9518,21589.111328125,,,,,,,,,,,,,0,,,,-0.00245,,,,,,300.0478821,,,,
,27854811.315,300.0390015,23785.578125,-0.000749923527824401,4.99309650693176E-6,1,0.999253354069792,40.0298881530762,1.99402702268505,21.3200002908707,-0.00799955943820798,-0.00417066814438518,0.25,-0.000239424303039372,-0.000749741859861149,-0.000239912910849448,300.0390015,300.0390015,23780.61328125,23790.54296875,59.2771436414293,21.5593809157228,22.909004,0,0,0,40,4449,299.9506,23785.578125,,,,,,,,,,,,,0,,,,0,,,,,,300.0390015,,,,
,27854855.64,300.02926635,25999.435546875,-0.000810402436602794,4.67860051507582E-6,1,0.999253354069792,40.0298881530762,1.99474994471773,21.3200002908707,-0.00864118997448009,-0.00454611922688885,0.25,-0.000262056594700831,-0.000810204297081994,-0.000262584373910073,300.0283203,300.0302124,25994.455078125,26004.416015625,59.3654676641024,21.5531372331765,22.529354,0,0,0,40,4449,299.94225,25999.435546875,,,,,,,,,,,,,0,,,,0,,,,,,300.02926635,,,,
,27854899.01,300.026123,28169.00390625,-0.000877017942719017,6.84059062172204E-6,1,0.999253354069792,40.0298881530762,1.99565007966516,21.3200002908707,-0.00935840731709822,-0.00490532847253824,0.25,-0.000282128727513282,-0.000876804693261101,-0.000282699715152141,300.026123,300.026123,28158.97265625,28179.03515625,59.4186184034101,21.5440136401434,22.529354,0,0,0,40,4449,299.9399,28169.00390625,,,,,,,,,,,,,0,,,,-0.0049,,,,,,300.026123,,,,
,27854943.555,300.0217896,30392.7265625,-0.000950618149648048,5.62723813346346E-6,1,0.999253354069792,40.0298881530762,1.99583013449151,21.3200002908707,-0.0101441863223154,-0.00532012592001097,0.25,-0.000306042508315237,-0.000950387102879477,-0.000306661200378668,300.0217896,300.0217896,30387.63671875,30397.81640625,59.3693758066986,21.5437702697669,22.529354,0,0,0,40,4449,299.9247,30392.7265625,,,,,,,,,,,,,0,,,,0,,,,,,300.0217896,,,,
,27854989.29,300.013916,32679.11328125,-0.00102113451682236,6.922844949969E-6,1,0.999253354069792,40.0298881530762,1.99592653343539,21.3200002908707,-0.0108820607700327,-0.00580232310789315,0.25,-0.000336468090466917,-0.00102088166551993,-0.000337132195293466,300.013916,300.013916,32671.55859375,32686.66796875,59.4373774878717,21.5463716089591,22.909004,0,0,0,40,4449,299.93145,32679.11328125,,,,,,,,,,,,,0,,,,-0.00245,,,,,,300.013916,,,,
,27855034.49,300.0100403,34940.322265625,-0.00108587946748187,7.59923548215307E-6,1,0.999253354069792,40.0298881530762,1.99627790099816,21.3200002908707,-0.0115849516203237,-0.00610795727905695,0.25,-0.00035220238227549,-0.00108561457283711,-0.000352908482783905,300.0100403,300.0100403,34935.3125,34945.33203125,59.5257015105448,21.5437397443281,22.909004,0,0,0,40,4449,299.9252,34940.322265625,,,,,,,,,,,,,0,,,,0.00245,,,,,,300.0100403,,,,
,27855080.36,300.0175171,37231.80859375,-0.00115951198539475,7.08453482467632E-6,1,0.999253354069792,40.0298881530762,1.99598114824323,21.3200002908707,-0.0123574851956688,-0.00658628377567405,0.25,-0.000381843265844411,-0.00115922519954289,-0.000382596548413809,300.0175171,300.0175171,37224.1328125,37239.484375,59.6015194769101,21.5460653104404,22.909004,0,0,0,40,4449,299.9403,37231.80859375,,,,,,,,,,,,,0,,,,-0.0049,,,,,,300.0175171,,,,
,27855123.68,300.0213623,39398.078125,-0.00122398003264753,8.27105749877167E-6,1,0.999253354069792,40.0298881530762,1.99635820049583,21.3200002908707,-0.0130416311962369,-0.00698416366710868,0.25,-0.000405766011085694,-0.00122367547372439,-0.000406560768842737,300.0213623,300.0213623,39393.06640625,39403.08984375,59.7617533233525,21.5435398142718,22.149702,0,0,0,40,4449,299.9035,39398.078125,,,,,,,,,,,,,0,,,,0.00245,,,,,,300.0213623,,,,
,27855186.4,300.0096741,38457.001953125,-0.00119705698361528,7.79961610562624E-6,1,0.999253354069792,40.0298881530762,1.99612969045136,21.3200002908707,-0.0127684147720997,-0.00674298632220794,0.25,-0.000389160571837738,-0.00119676464659023,-0.000389938345973035,300.0096741,300.0096741,38452.03125,38461.97265625,59.7367412107371,21.5441923993281,22.529354,0,0,0,40,4449,299.9238,38457.001953125,,,,,,,,,,,,,0,,,,0.00245,,,,,,300.0096741,,,,
,27855231.795,300.0133057,36189.46875,-0.00112243062078256,6.35760997347585E-6,1,0.999253354069792,40.0298881530762,1.99616980443794,21.3200002908707,-0.0119663010655983,-0.00635931613454951,0.25,-0.000368135307961405,-0.0011221540542453,-0.000368864854654306,300.0133057,300.0133057,36184.52734375,36194.41015625,59.9423095112948,21.5444625260442,22.909004,0,0,0,40,4449,299.90985,36189.46875,,,,,,,,,,,,,0,,,,0,,,,,,300.0133057,,,,
,27855276.195,300.0050049,33970.33203125,-0.001047587850218,5.72077265224161E-6,1,0.999253354069792,40.0298881530762,1.99673229182905,21.3200002908707,-0.0111616863497207,-0.00599296324598392,0.25,-0.0003485483366248,-0.00104732662297867,-0.000349229518308429,300.0050049,300.0050049,33960.24609375,33980.41796875,59.6335662461986,21.5379487188074,23.288654,0,0,0,40,4449,299.91165,33970.33203125,,,,,,,,,,,,,0,,,,-0.00245,,,,,,300.0050049,,,,
,27855321.555,299.9987488,31704.03125,-0.000978850980692559,4.93250892677718E-6,1,0.999253354069792,40.0298881530762,1.99672081460923,21.3200002908707,-0.0104413527251797,-0.00552992554202596,0.25,-0.000319506185002334,-0.000978611049252908,-0.00032014325091344,299.9987488,299.9987488,31701.546875,31706.515625,59.7132923551602,21.5396765780663,22.909004,0,0,0,40,4449,299.9064,31704.03125,,,,,,,,,,,,,0,,,,0,,,,,,299.9987488,,,,
,27855366.445,299.9952698,29457.6279296875,-0.00091044168407298,6.52568313999695E-6,1,0.999253354069792,40.0298881530762,1.99653873313259,21.3200002908707,-0.00970035122435642,-0.0052032509431992,0.25,-0.000302505323841726,-0.000910215003368832,-0.000303098004499902,299.9952698,299.9952698,29452.5625,29462.693359375,59.6679579010448,21.5444865009868,22.909004,0,0,0,40,4449,299.9177,29457.6279296875,,,,,,,,,,,,,0,,,,0,,,,,,299.9952698,,,,
,27855412.565,299.9932861,27154.03125,-0.000842793953178859,5.63132857108505E-6,1,0.999253354069792,40.0298881530762,1.99647427080486,21.3200002908707,-0.00899237689481944,-0.0047411133667289,0.25,-0.000273360715818677,-0.000842588462299936,-0.000273909853583196,299.9932861,299.9932861,27149.1015625,27158.9609375,59.7461207529678,21.5470486024476,22.909004,0,0,0,40,4449,299.9112,27154.03125,,,,,,,,,,,,,0,,,,0.0049,,,,,,299.9932861,,,,
,27855457.765,299.9969482,24894.1142578125,-0.000775387113677765,4.36543245577762E-6,1,0.999253354069792,40.0298881530762,1.99642409733615,21.3200002908707,-0.00826738023130826,-0.00439404139465379,0.25,-0.000254347946708411,-0.000775195977924569,-0.000254853264179543,299.9969482,299.9969482,24884.2109375,24904.017578125,59.729706554064,21.546550480488,22.909004,0,0,0,40,4449,299.92045,24894.1142578125,,,,,,,,,,,,,0,,,,-0.0049,,,,,,299.9969482,,,,
,27855502.445,299.9932251,22663.2021484375,-0.000704713180341615,4.46787793888779E-6,1,0.999253354069792,40.0298881530762,1.99629550491648,21.3200002908707,-0.00751423081979985,-0.00398835035813669,0.25,-0.000230727423134026,-0.000704539755442954,-0.000231186945457337,299.9932251,299.9932251,22655.677734375,22670.7265625,59.6640497584486,21.5498544034547,22.529354,0,0,0,40,4449,299.914,22663.2021484375,,,,,,,,,,,,,0,,,,0.0049,,,,,,299.9932251,,,,
,27855545.39,299.989624,20513.912109375,-0.000633840416467279,3.15919566173153E-6,1,0.999253354069792,40.0298881530762,1.99639048909603,21.3200002908707,-0.006761348818381,-0.00357289325392019,0.25,-0.000206239249358812,-0.000633685300175202,-0.000206652772479201,299.989624,299.989624,20511.126953125,20516.697265625,59.8078694059871,21.548299673158,22.149702,0,0,0,40,4449,299.9304,20513.912109375,,,,,,,,,,,,,0,,,,0,,,,,,299.989624,,,,
,27855588.54,299.9986267,18357.4716796875,-0.000569375978784092,3.33929461289296E-6,1,0.999253354069792,40.0298881530762,1.99667155061494,21.3200002908707,-0.00607058646702858,-0.00323254543477554,0.25,-0.00018726266874443,-0.000569235056412263,-0.000187634188764302,299.9986267,299.9986267,18352.10546875,18362.837890625,59.7922368356025,21.5436603227128,22.909004,0,0,0,40,4449,299.91825,18357.4716796875,,,,,,,,,,,,,0,,,,0.00245,,,,,,299.9986267,,,,
,27855631.75,299.9932251,16198.2958984375,-0.000501172087607291,3.55290928209236E-6,1,0.999253354069792,40.0298881530762,1.99630713380635,21.3200002908707,-0.00533932961785537,-0.00286300566968112,0.25,-0.000166438506416536,-0.000501047023721832,-0.000166765633785732,299.9932251,299.9932251,16193.4130859375,16203.1787109375,59.885250629391,21.5482217578296,22.909004,0,0,0,40,4449,299.92475,16198.2958984375,,,,,,,,,,,,,0,,,,0,,,,,,299.9932251,,,,
,27855676.58,299.9921265,13957.2265625,-0.000429685325390142,2.529246106123E-6,1,0.999253354069792,40.0298881530762,1.99641870498826,21.3200002908707,-0.00458036710789707,-0.00244095915599417,0.25,-0.00014147695405266,-0.000429578879305195,-0.000141757570752185,299.9921265,299.9921265,13954.6533203125,13959.7998046875,59.9962418791217,21.5456368501157,22.909004,0,0,0,40,4449,299.93165,13957.2265625,,,,,,,,,,,,,0,,,,-0.0049,,,,,,299.9921265,,,,
,27855720.35,299.9909973,11770.560546875,-0.000363286964223149,1.89664026251158E-6,1,0.999253354069792,40.0298881530762,1.99647368236321,21.3200002908707,-0.00387246825348332,-0.00206500589430451,0.25,-0.000119719882004065,-0.000363196873748296,-0.000119957226107923,299.9909973,299.9909973,11765.5283203125,11775.5927734375,59.7726961226217,21.5449936704333,22.149702,0,0,0,40,4449,299.93635,11770.560546875,,,,,,,,,,,,,0,,,,-0.00245,,,,,,299.9909973,,,,
,27855764.555,299.989624,9559.67236328125,-0.000295850127838713,1.90134228144774E-6,1,0.999253354069792,40.0298881530762,1.99651372507489,21.3200002908707,-0.00315547352828916,-0.00167138005351851,0.25,-9.65823617433918E-5,-0.000295777350781614,-9.67757508302987E-5,299.989624,299.989624,9556.990234375,9562.3544921875,59.7351779536986,21.5452958070307,22.149702,0,0,0,40,4449,299.9397,9559.67236328125,,,,,,,,,,,,,0,,,,0.0049,,,,,,299.989624,,,,
,27855808.875,299.990387,7345.09985351562,-0.000224567449985638,1.41712707443557E-6,1,0.999253354069792,40.0298881530762,1.99651403913942,21.3200002908707,-0.00239346785655886,-0.00127860250863737,0.25,-7.41897332684876E-5,-0.000224511597429515,-7.43365495628564E-5,299.990387,299.990387,7332.63525390625,7357.564453125,59.803961263391,21.5464085415249,22.529354,0,0,0,40,4449,299.94495,7345.09985351562,,,,,,,,,,,,,0,,,,0,,,,,,299.990387,,,,
,27855851.645,299.9924622,5206.01245117188,-0.000162357374868199,1.15178894685352E-6,1,0.999253354069792,40.0298881530762,1.99664869805295,21.3200002908707,-0.00173001285153707,-0.000927481864350634,0.25,-5.39047027665961E-5,-0.000162316789890119,-5.40108713216738E-5,299.9924622,299.9924622,5203.2587890625,5208.76611328125,59.9337115975833,21.5459769439747,22.149702,0,0,0,40,4449,299.9445,5206.01245117188,,,,,,,,,,,,,0,,,,0,,,,,,299.9924622,,,,
,27855894.305,299.9959717,3074.271484375,-9.59773023953204E-5,6.79593524652501E-7,1,0.999253354069792,40.0298881530762,1.99682279129035,21.3200002908707,-0.00102429865903111,-0.000539555367413967,0.25,-3.10900663622881E-5,-9.59538069293053E-5,-3.11528618474931E-5,299.9959717,299.9959717,3064.39868164063,3084.14428710937,60.0900373014294,21.5429436682656,22.909004,0,0,0,40,4449,299.9611,3074.271484375,,,,,,,,,,,,,0,,,,0.00245,,,,,,299.9959717,,,,
,27855935.985,299.9870911,992.156188964844,-3.1567119073012E-5,5.20839992320309E-7,1,0.999253354069792,40.0298881530762,1.99707993839616,21.3200002908707,-0.000336788155200006,-0.00017833179278237,0.25,-1.03006651601117E-5,-3.1559348620759E-5,-1.03213266921213E-5,299.9870911,299.9870911,984.805053710937,999.50732421875,59.9180790271986,21.5405257769374,22.909004,0,0,0,40,4449,299.94105,992.156188964844,,,,,,,,,,,,,0,,,,0.0049,,,,,,299.9870911,,,,
,27855975.93,299.9880066,-1006.41473388672,3.21079080183718E-5,5.27217101119303E-7,1,0.999253354069792,40.0298881530762,1.99669608808917,21.3200002908707,0.000342931152242816,0.0001788360561809,0.25,1.02544635652596E-5,3.21001518951474E-5,1.02754837990849E-5,299.9880066,299.9880066,-1019.02233886719,-993.80712890625,59.7852021789294,21.5451549935546,22.909004,0,0,0,40,4449,299.9587,-1006.41473388672,,,,,,,,,,,,,0,,,,0.00245,,,,,,299.9880066,,,,
,27856017.685,299.9913635,-3088.48803710937,9.74875977830022E-5,7.52513494077841E-7,1,0.999253354069792,40.0298881530762,1.99654285705946,21.3200002908707,0.00104225053768262,0.000536587356593415,0.25,3.05722358656281E-5,9.74644159610962E-5,3.06360578036791E-5,299.9913635,299.9913635,-3093.99169921875,-3082.984375,59.9993683931987,21.5510455743345,22.909004,0,0,0,40,4449,299.9474,-3088.48803710937,,,,,,,,,,,,,0,,,,0,,,,,,299.9913635,,,,
,27856061.84,299.9968262,-5296.98706054687,0.000163518457414217,1.21684544856341E-6,1,0.999253354069792,40.0298881530762,1.99646100710137,21.3200002908707,0.00174445526168087,0.000921177389922799,0.25,5.31532375996655E-5,0.000163478313528826,5.32601853198456E-5,299.9968262,299.9968262,-5309.60205078125,-5284.3720703125,60.0970719581025,21.5514031471322,22.529354,0,0,0,40,4449,299.95395,-5296.98706054687,,,,,,,,,,,,,0,,,,-0.0049,,,,,,299.9968262,,,,
,27856105.595,299.9980164,-7483.65869140625,0.000229582778382186,1.25771265996624E-6,1,0.999253354069792,40.0298881530762,1.99628428154931,21.3200002908707,0.00244885698098451,0.00129429013679948,0.25,7.47210338196443E-5,0.000229526365152758,7.48711352844908E-5,299.9980164,299.9980164,-7488.8955078125,-7478.421875,60.0486109899102,21.549420631002,22.529354,0,0,0,40,4449,299.9502,-7483.65869140625,,,,,,,,,,,,,0,,,,-0.00245,,,,,,299.9980164,,,,
,27856149.315,300.0007935,-9670.8701171875,0.000298271388476194,1.60273514660688E-6,1,0.999253354069792,40.0298881530762,1.99647805419808,21.3200002908707,0.00317960137847014,0.0016945025445055,0.25,9.8210772937592E-5,0.000298197345361869,9.84056689401769E-5,300.0007935,300.0007935,-9678.6416015625,-9663.0986328125,59.946217653891,21.5502296741087,22.529354,0,0,0,40,4449,299.9502,-9670.8701171875,,,,,,,,,,,,,0,,,,-0.00245,,,,,,300.0007935,,,,
,27856193.265,299.9977722,-11864.4248046875,0.000363711435236274,2.16647230307642E-6,1,0.999253354069792,40.0298881530762,1.99676075972119,21.3200002908707,0.003880634042432,0.00204975267223599,0.25,0.000118272279620828,0.000363622213409607,0.000118509896000172,299.9977722,299.9977722,-11876.8486328125,-11852.0009765625,59.7531554096409,21.5482341782704,22.909004,0,0,0,40,4449,299.957,-11864.4248046875,,,,,,,,,,,,,0,,,,0,,,,,,299.9977722,,,,
,27856235.79,300.0019531,-13993.9106445313,0.000431457464080598,2.20367318570401E-6,1,0.999253354069792,40.0298881530762,1.99650218094755,21.3200002908707,0.00459828626375853,0.00245778125549657,0.25,0.000142649396147753,0.000431350046122358,0.000142931079848819,300.0019531,300.0019531,-14001.462890625,-13986.3583984375,59.9829541942948,21.5503902600165,22.529354,0,0,0,40,4449,299.9505,-13993.9106445313,,,,,,,,,,,,,0,,,,0.00245,,,,,,300.0019531,,,,
,27856279.42,300.0032043,-16172.5708007813,0.000497725425401486,3.00997405488047E-6,1,0.999253354069792,40.0298881530762,1.99637662801046,21.3200002908707,0.00531041842342293,0.00279934815191263,0.25,0.000161396197022386,0.000497603635963216,0.000161721107326977,300.0032043,300.0032043,-16175.2099609375,-16169.931640625,59.8930669145833,21.5531136733844,22.909004,0,0,0,40,4449,299.94535,-16172.5708007813,,,,,,,,,,,,,0,,,,0,,,,,,300.0032043,,,,
,27856322.845,300.0027161,-18344.18359375,0.000557895300599065,3.248621553249E-6,1,0.999253354069792,40.0298881530762,1.99625548903303,21.3200002908707,0.00594390856569316,0.00318456562959478,0.25,0.000185064195132582,0.000557756112632449,0.000185428105004652,300.0027161,300.0027161,-18354.07421875,-18334.29296875,60.1619471251987,21.5515476855838,22.909004,0,0,0,40,4449,299.9507,-18344.18359375,,,,,,,,,,,,,0,,,,0,,,,,,300.0027161,,,,
,27856366.27,300.0042725,-20512.90625,0.000626629929876316,4.1404176230344E-6,1,0.999253354069792,40.0298881530762,1.99663870711381,21.3200002908707,0.0066771398450536,0.00357931621807887,0.25,0.0002080193223711,0.000626473527946517,0.000208427885700043,300.0042725,300.0042725,-20517.966796875,-20507.845703125,59.9782644231794,21.5473093543525,22.909004,0,0,0,40,4449,299.94615,-20512.90625,,,,,,,,,,,,,0,,,,0,,,,,,300.0042725,,,,
,27856411.45,300.0072021,-22774.0927734375,0.000696763829927733,4.94320273753413E-6,1,0.999253354069792,40.0298881530762,1.99611919346542,21.3200002908707,0.00742156741804814,0.00398499361152557,0.25,0.00023183771436341,0.000696589580329442,0.000232291768246407,300.0072021,300.0072021,-22776.388671875,-22771.796875,60.0368865621217,21.5571415773878,22.909004,0,0,0,40,4449,299.94175,-22774.0927734375,,,,,,,,,,,,,0,,,,0,,,,,,300.0072021,,,,
,27856455.275,300.0064087,-24960.3984375,0.000764579592633945,4.52871706459623E-6,1,0.999253354069792,40.0298881530762,1.9965629744149,21.3200002908707,0.00815324502293504,0.00432985746510301,0.25,0.000250517561421308,0.000764391064743311,0.000251015724140253,300.0063477,300.0064697,-24970.12890625,-24950.66796875,59.9180790271986,21.5451865063792,22.529354,0,0,0,40,4449,299.9349,-24960.3984375,,,,,,,,,,,,,0,,,,0,,,,,,300.0064087,,,,
,27856499.615,300.0062866,-27179.6298828125,0.000839376280419349,5.75096077847877E-6,1,0.999253354069792,40.0298881530762,1.99638617111296,21.3200002908707,0.00895752628786738,0.00471016419875786,0.25,0.000271232969154491,0.000839171913950584,0.000271779761446918,300.0062866,300.0062866,-27184.66796875,-27174.591796875,59.6288764750832,21.5470170472501,22.909004,0,0,0,40,4449,299.92005,-27179.6298828125,,,,,,,,,,,,,0,,,,-0.0049,,,,,,300.0062866,,,,
,27856545.5,300.01651,-29470.7978515625,0.000906367347385215,6.23982528980848E-6,1,0.999253354069792,40.0298881530762,1.99645096181308,21.3200002908707,0.00967269885810331,0.00508641335917193,0.25,0.000292895783821469,0.000906146457551987,0.000293485801249553,300.01651,300.01651,-29473.275390625,-29468.3203125,59.8578936312179,21.5444786997875,22.909004,0,0,0,40,4449,299.9301,-29470.7978515625,,,,,,,,,,,,,0,,,,0,,,,,,300.01651,,,,
,27856591.09,300.0080566,-31749.7744140625,0.000970856996801353,6.32381139846886E-6,1,0.999253354069792,40.0298881530762,1.99698249385763,21.3200002908707,0.0103574105877598,0.00548523350044001,0.25,0.000316877887234429,0.000970618725206158,0.000317509615893753,300.0080566,300.0080566,-31752.30859375,-31747.240234375,59.800834749314,21.5388458252495,22.529354,0,0,0,40,4449,299.9157,-31749.7744140625,,,,,,,,,,,,,0,,,,0,,,,,,300.0080566,,,,
,27856635.655,300.006134,-33977.810546875,0.00102578337526913,5.35472212240675E-6,1,0.999253354069792,40.0298881530762,1.99694695763952,21.3200002908707,0.0109358896878465,0.00583765323374084,0.25,0.000338536757540025,0.00102552938913874,0.000339203770084669,300.006134,300.006134,-33985.4921875,-33970.12890625,59.6069908765448,21.5419546252027,22.529354,0,0,0,40,4449,299.9342,-33977.810546875,,,,,,,,,,,,,0,,,,-0.0049,,,,,,300.006134,,,,
,27856680.04,300.0116272,-36193.873046875,0.00110079136507572,6.97098997678133E-6,1,0.999253354069792,40.0298881530762,1.99677783288628,21.3200002908707,0.011730471996035,0.00628784495816956,0.25,0.000365399777708649,0.00110051733613447,0.000366115111107944,300.0116272,300.0116272,-36203.69921875,-36184.046875,59.9266769409102,21.5413898736781,23.288654,0,0,0,40,4449,299.92395,-36193.873046875,,,,,,,,,,,,,0,,,,-0.00245,,,,,,300.0116272,,,,
,27856724.655,300.0110474,-38425.919921875,0.00117331318410766,7.38553492529216E-6,1,0.999253354069792,40.0298881530762,1.99684120258258,21.3200002908707,0.0125005111527873,0.0067205576613403,0.25,0.000391087845895941,0.00117302021790813,0.000391849905644804,300.0110474,300.0110474,-38433.6015625,-38418.23828125,59.5436789664871,21.5413009433877,22.529354,0,0,0,40,4449,299.9188,-38425.919921875,,,,,,,,,,,,,0,,,,0,,,,,,300.0110474,,,,
,27856783.39,300.01506045,-39552.61328125,0.00119713071354473,7.19605029078309E-6,1,0.999253354069792,40.0298881530762,1.99624563226076,21.3200002908707,0.0127353473004146,0.00694324887731442,0.25,0.00040683141289224,0.00119682656126608,0.000407608468585755,300.01474,300.0153809,-39560.3203125,-39544.90625,59.8750894586409,21.5486888935202,22.909004,0,0,0,40,4449,299.91425,-39552.61328125,,,,,,,,,,,,,0,,,,0.00245,,,,,,300.01506045,,,,
,27856830.575,300.0076294,-37201.423828125,0.0011433217313679,7.48631485129696E-6,1,0.999253354069792,40.0298881530762,1.99677042331136,21.3200002908707,0.0122013268137093,0.00642874355695421,0.25,0.00037049471034665,0.0011430432749097,0.000371237904353756,300.0076294,300.0076294,-37208.97265625,-37193.875,59.719545383314,21.542472241304,22.529354,0,0,0,40,4449,299.9015,-37201.423828125,,,,,,,,,,,,,0,,,,0.00245,,,,,,300.0076294,,,,
,27856874.18,300.0023193,-35019.884765625,0.00106133317491609,8.29510594752131E-6,1,0.999253354069792,40.0298881530762,1.99661010020081,21.3200002908707,0.0113110711951236,0.00605051167165284,0.25,0.000351288114094933,0.0010610699021134,0.000351978162202756,300.0023193,300.0023193,-35029.76953125,-35010,59.7523737811217,21.5408423598986,22.529354,0,0,0,40,4449,299.91245,-35019.884765625,,,,,,,,,,,,,0,,,,0,,,,,,300.0023193,,,,
,27856918.08,300.0064697,-32826.357421875,0.0010126561805068,6.46684132365714E-6,1,0.999253354069792,40.0298881530762,1.99701479482183,21.3200002908707,0.0107914109372943,0.00579129045578393,0.25,0.000336694161714359,0.00101240368675962,0.000337352795321478,300.0064697,300.0064697,-32836.30078125,-32816.4140625,59.9978051361602,21.5385480717345,22.909004,0,0,0,40,4449,299.90625,-32826.357421875,,,,,,,,,,,,,0,,,,0,,,,,,300.0064697,,,,
,27856961.735,300.0023499,-30644.9921875,0.000930932663193596,5.54733759633004E-6,1,0.999253354069792,40.0298881530762,1.99678311883704,21.3200002908707,0.00991642921669764,0.00534060967565414,0.25,0.000311050038955969,0.000930699554243121,0.000311655796701422,300.0023499,300.0023499,-30652.39453125,-30637.58984375,59.689061871064,21.5404418977271,22.909004,0,0,0,40,4449,299.9089,-30644.9921875,,,,,,,,,,,,,0,,,,0,,,,,,300.0023499,,,,
,27857007.055,299.9973145,-28381.2109375,0.000857560638267267,5.63411245143891E-6,1,0.999253354069792,40.0298881530762,1.9964989005316,21.3200002908707,0.0091315116048769,0.00493118259496445,0.25,0.000287610137817186,0.000857345226249113,0.000288168446695991,299.9973145,299.9973145,-28393.54296875,-28368.87890625,59.8070877774679,21.5441157681449,23.288654,0,0,0,40,4449,299.9055,-28381.2109375,,,,,,,,,,,,,0,,,,-0.00245,,,,,,299.9973145,,,,
,27857049.4,299.9951782,-26264.3388671875,0.000801936874733048,4.81286166620245E-6,1,0.999253354069792,40.0298881530762,1.99604034071012,21.3200002908707,0.00854709553892978,0.00455403823860588,0.25,0.000263975072598179,0.000801738693672894,0.000264497553531446,299.9951782,299.9951782,-26269.458984375,-26259.21875,59.6695211580832,21.5486540051513,22.909004,0,0,0,40,4449,299.91135,-26264.3388671875,,,,,,,,,,,,,0,,,,0.0049,,,,,,299.9951782,,,,
,27857092.625,299.9954224,-24103.560546875,0.00073068017963907,4.62231915383602E-6,1,0.999253354069792,40.0298881530762,1.9965286717021,21.3200002908707,0.00777982396923471,0.00420593906230905,0.25,0.000245435846285646,0.000730496262221272,0.000245911956502169,299.9954224,299.9954224,-24106.466796875,-24100.654296875,59.8641466593717,21.5435688203512,22.149702,0,0,0,40,4449,299.9161,-24103.560546875,,,,,,,,,,,,,0,,,,0.0049,,,,,,299.9954224,,,,
,27857134.825,299.994812,-21994.2685546875,0.000665141109258967,3.15779208288548E-6,1,0.999253354069792,40.0298881530762,1.99606863051648,21.3200002908707,0.00708230839077096,0.00381709653097384,0.25,0.000222470440295688,0.000664974251214903,0.000222904063006511,299.994812,299.994812,-22001.8203125,-21986.716796875,59.8195938337756,21.5476545731927,22.529354,0,0,0,40,4449,299.91565,-21994.2685546875,,,,,,,,,,,,,0,,,,0.00245,,,,,,299.994812,,,,
,27857177.53,299.9929199,-19860.953125,0.000611642244906574,2.99708135482289E-6,1,0.999253354069792,40.0298881530762,1.99645814296514,21.3200002908707,0.00651784131124641,0.00348783599538302,0.25,0.00020255112026897,0.000611490121153255,0.000202950097131498,299.9923706,299.9934692,-19868.34375,-19853.5625,59.8805608582756,21.5437150420857,22.909004,0,0,0,40,4449,299.9222,-19860.953125,,,,,,,,,,,,,0,,,,0,,,,,,299.9929199,,,,
,27857221.38,299.9877625,-17669.4248046875,0.000537557432101527,3.23005992957936E-6,1,0.999253354069792,40.0298881530762,1.99628141364045,21.3200002908707,0.00572573767945611,0.00307752610250555,0.25,0.000179115006508271,0.000537423046927387,0.000179465796188578,299.9877625,299.9877625,-17674.287109375,-17664.5625,59.7469023814871,21.5442094072862,22.909004,0,0,0,40,4449,299.9301,-17669.4248046875,,,,,,,,,,,,,0,,,,0,,,,,,299.9877625,,,,
,27857264.47,299.9908142,-15515.615234375,0.000473829125497171,3.15918434791259E-6,1,0.999253354069792,40.0298881530762,1.99602802343324,21.3200002908707,0.00503791806332092,0.00276090009908195,0.25,0.000162175869940992,0.000473707720935637,0.000162485050743567,299.9908142,299.9908142,-15520.3173828125,-15510.9130859375,59.9141708846025,21.548858008726,23.288654,0,0,0,40,4449,299.93345,-15515.615234375,,,,,,,,,,,,,0,,,,0,,,,,,299.9908142,,,,
,27857310.155,299.989563,-13231.4956054687,0.000407336576142074,2.25814148415305E-6,1,0.999253354069792,40.0298881530762,1.99607050607,21.3200002908707,0.00434235345914943,0.00230817524543225,0.25,0.000133637144960965,0.000407236009306426,0.000133903224655129,299.989563,299.989563,-13241.4921875,-13221.4990234375,59.7336146966602,21.5478374953963,23.288654,0,0,0,40,4449,299.9347,-13231.4956054687,,,,,,,,,,,,,0,,,,0,,,,,,299.989563,,,,
,27857353.725,299.9931335,-11052.9643554688,0.00033875918679964,1.89637410209504E-6,1,0.999253354069792,40.0298881530762,1.99644872377147,21.3200002908707,0.00360925963804769,0.00193543399167348,0.25,0.000112510131506479,0.000338674562203698,0.000112731443454654,299.9931335,299.9931335,-11063.3115234375,-11042.6171875,59.6304397321217,21.5426576372882,22.909004,0,0,0,40,4449,299.9375,-11052.9643554688,,,,,,,,,,,,,0,,,,0.00245,,,,,,299.9931335,,,,
,27857397.305,299.9892578,-8873.26904296875,0.000272788300484372,1.89516570820555E-6,1,0.999253354069792,40.0298881530762,1.99593566444463,21.3200002908707,0.0029047580853475,0.0015634022116883,0.25,9.10651164210565E-5,0.000272719856803661,9.12433933591806E-5,299.9892578,299.9892578,-8883.2451171875,-8863.29296875,59.7406493533332,21.5477342589713,22.529354,0,0,0,40,4449,299.93935,-8873.26904296875,,,,,,,,,,,,,0,,,,-0.0049,,,,,,299.9892578,,,,
,27857442.335,299.9914246,-6624.41845703125,0.000203698451647751,1.45700251317901E-6,1,0.999253354069792,40.0298881530762,1.99608152925003,21.3200002908707,0.00217258257143012,0.0011480674624632,0.25,6.62800602422177E-5,0.000203648448943582,6.64132757250341E-5,299.9914246,299.9914246,-6634.55126953125,-6614.28564453125,59.6210601898909,21.5468406535643,22.529354,0,0,0,40,4449,299.94485,-6624.41845703125,,,,,,,,,,,,,0,,,,-0.00245,,,,,,299.9914246,,,,
,27857485.315,299.9931946,-4475.17919921875,0.00013827750249932,1.01361711778271E-6,1,0.999253354069792,40.0298881530762,1.99623869813762,21.3200002908707,0.00147451575818823,0.000781821428995867,0.25,4.52068250153457E-5,0.000138243395416062,4.52972772349398E-5,299.9931946,299.9931946,-4480.19482421875,-4470.16357421875,59.5460238520448,21.5445794064261,22.909004,0,0,0,40,4449,299.9429,-4475.17919921875,,,,,,,,,,,,,0,,,,0,,,,,,299.9931946,,,,
,27857527.27,299.9931335,-2378.52331542969,7.6082893951549E-5,6.33233907245294E-7,1,0.999253354069792,40.0298881530762,1.99651239466585,21.3200002908707,0.000812446710832836,0.000424260213116901,0.25,2.434564886623E-5,7.60644718599448E-5,2.43954482287994E-5,299.9931335,299.9931335,-2381.10107421875,-2375.94555664062,59.7250167829486,21.543186819965,22.529354,0,0,0,40,4449,299.9389,-2378.52331542969,,,,,,,,,,,,,0,,,,0,,,,,,299.9931335,,,,
,27857568.995,299.9975281,-293.41276550293,1.13007087167304E-5,5.2023272779114E-7,1,0.999253354069792,40.0298881530762,1.99667728294311,21.3200002908707,0.000122112414203823,5.47734372719909E-5,0.25,2.88661857349555E-6,1.12984544962205E-5,2.89403813122297E-6,299.9975281,299.9975281,-300.564697265625,-286.260833740234,59.4365958593524,21.5394653750947,22.529354,0,0,0,40,4449,299.94335,-293.41276550293,,,,,,,,,,,,,0,,,,0,,,,,,299.9975281,,,,
,27857611.24,299.997467,1814.38812255859,-5.50124532783228E-5,6.88285768611561E-7,1,0.999253354069792,40.0298881530762,1.99584241149746,21.3200002908707,-0.000584683513973751,-0.00032153174262658,0.25,-1.89186224543722E-5,-5.49982496165519E-5,-1.89545916512995E-5,299.997467,299.997467,1804.18310546875,1824.59313964844,59.4920914842178,21.5486791430908,22.909004,0,0,0,40,4449,299.9338,1814.38812255859,,,,,,,,,,,,,0,,,,0,,,,,,299.997467,,,,
,27857654.03,299.9911499,3954.75170898438,-0.000119476685721851,9.72759072308204E-7,1,0.999253354069792,40.0298881530762,1.99607203917189,21.3200002908707,-0.00127297762290706,-0.000680979911198419,0.25,-3.95479780559402E-5,-0.000119446898370532,-3.9626126585972E-5,299.9911499,299.9911499,3942.22143554687,3967.28198242188,59.5725992216986,21.5426844223035,23.288654,0,0,0,40,4449,299.94195,3954.75170898438,,,,,,,,,,,,,0,,,,0.00245,,,,,,299.9911499,,,,
,27857697.26,299.9989319,6115.0146484375,-0.000184672761429198,1.19389203984052E-6,1,0.999253354069792,40.0298881530762,1.99571129643044,21.3200002908707,-0.0019659164985497,-0.00106024598789307,0.25,-6.1823258610939E-5,-0.000184626224821316,-6.19439724555291E-5,299.9989319,299.9989319,6112.5869140625,6117.4423828125,59.6491988165832,21.5489586988323,23.288654,0,0,0,40,4449,299.94655,6115.0146484375,,,,,,,,,,,,,0,,,,0.00245,,,,,,299.9989319,,,,
,27857741.345,299.99588015,8318.7763671875,-0.000251075465186311,1.6035425975572E-6,1,0.999253354069792,40.0298881530762,1.99583844700786,21.3200002908707,-0.00267685174018347,-0.00141912345395087,0.25,-8.20672838683026E-5,-0.000251013564660565,-8.22314153963554E-5,299.9956665,299.9960938,8316.490234375,8321.0625,59.6398192743525,21.545399800911,22.909004,0,0,0,40,4449,299.943,8318.7763671875,,,,,,,,,,,,,0,,,,0,,,,,,299.99588015,,,,
,27857784.375,299.9963379,10468.4809570312,-0.00031575205823979,2.14612666937671E-6,1,0.999253354069792,40.0298881530762,1.99585199130649,21.3200002908707,-0.0033586189850184,-0.00182975911269998,0.25,-0.00010719481480466,-0.000315671598448967,-0.000107401023707448,299.9963379,299.9963379,10465.98828125,10470.9736328125,59.8305366330448,21.5490028680123,22.909004,0,0,0,40,4449,299.9527,10468.4809570312,,,,,,,,,,,,,0,,,,0,,,,,,299.9963379,,,,
,27857828.525,300.0030212,12674.7451171875,-0.00038536840554801,2.52042928750084E-6,1,0.999253354069792,40.0298881530762,1.99575480759118,21.3200002908707,-0.00409903698201491,-0.00223245434942314,0.25,-0.000130773969136908,-0.000385270195398923,-0.000131025510418566,300.0030212,300.0030212,12669.92578125,12679.564453125,59.7367412107371,21.5475841661104,22.529354,0,0,0,40,4449,299.95765,12674.7451171875,,,,,,,,,,,,,0,,,,0.0049,,,,,,300.0030212,,,,
,27857872.475,299.9999695,14873.8364257813,-0.000453394890621366,3.45214772040761E-6,1,0.999253354069792,40.0298881530762,1.99562750797739,21.3200002908707,-0.00482883916192677,-0.00258874699958113,0.25,-0.000150528946146751,-0.000453281647310575,-0.000150824899848635,299.9999695,299.9999695,14868.8046875,14878.8681640625,59.6742109291986,21.5479547146709,22.909004,0,0,0,40,4449,299.9474,14873.8364257813,,,,,,,,,,,,,0,,,,0,,,,,,299.9999695,,,,
,27857916.555,300.0022583,17075.259765625,-0.000516908058514307,3.586721784805E-6,1,0.999253354069792,40.0298881530762,1.99586827776602,21.3200002908707,-0.00550351511417981,-0.00296557508862534,0.25,-0.00017284096302073,-0.000516778156994761,-0.000173178187607513,300.0022583,300.0022583,17067.96484375,17082.5546875,59.6710844151217,21.5464598055112,22.529354,0,0,0,40,4449,299.9456,17075.259765625,,,,,,,,,,,,,0,,,,-0.00245,,,,,,300.0022583,,,,
,27857961.54,300.0024414,19324.3388671875,-0.000588250624367737,3.69890861934512E-6,1,0.999253354069792,40.0298881530762,1.99570868867264,21.3200002908707,-0.00626616526363846,-0.00335416633049057,0.25,-0.000194886345053448,-0.000588104058919047,-0.000195270004263639,300.0024414,300.0024414,19316.931640625,19331.74609375,59.6171520472948,21.548210024185,22.529354,0,0,0,40,4449,299.94245,19324.3388671875,,,,,,,,,,,,,0,,,,0,,,,,,300.0024414,,,,
,27858005.595,300.003952,21525.298828125,-0.000653180449865869,3.32282868167256E-6,1,0.999253354069792,40.0298881530762,1.99620527032878,21.3200002908707,-0.00695784136309873,-0.00373464145734111,0.25,-0.000217226163411279,-0.000653017202105587,-0.000217651951373251,300.0038452,300.0040588,21520.470703125,21530.126953125,59.6249683324871,21.5403692132122,22.909004,0,0,0,40,4449,299.94125,21525.298828125,,,,,,,,,,,,,0,,,,0,,,,,,300.003952,,,,
,27858049.675,300.0107117,23729.3173828125,-0.000711409654434459,5.01064938156227E-6,1,0.999253354069792,40.0298881530762,1.99576191726024,21.3200002908707,-0.00755854406141011,-0.00417038334688516,0.25,-0.000245765056418744,-0.000711225701931768,-0.000246228263508291,300.0107117,300.0107117,23724.05078125,23734.583984375,59.5718175931794,21.545417311232,22.909004,0,0,0,40,4449,299.94155,23729.3173828125,,,,,,,,,,,,,0,,,,0.00245,,,,,,300.0107117,,,,
,27858094.195,300.0127258,25952.7607421875,-0.000787386255725794,4.05480643834289E-6,1,0.999253354069792,40.0298881530762,1.99628719793272,21.3200002908707,-0.00837906950153972,-0.00455233300413316,0.25,-0.000266297924039213,-0.00078718647008884,-0.000266810549950693,300.0127258,300.0127258,25947.77734375,25957.744140625,59.6015194769101,21.5428968778091,23.288654,0,0,0,40,4449,299.9265,25952.7607421875,,,,,,,,,,,,,0,,,,0.00245,,,,,,300.0127258,,,,
,27858136.7,300.0094604,28077.6708984375,-0.000850089160936579,6.21629143330296E-6,1,0.999253354069792,40.0298881530762,1.99586606552553,21.3200002908707,-0.00904641194657872,-0.00490289531433662,0.25,-0.000286533942203285,-0.000849874327314709,-0.000287087179997158,300.0094604,300.0094604,28067.771484375,28087.5703125,59.5647829365063,21.5471655489055,23.288654,0,0,0,40,4449,299.9403,28077.6708984375,,,,,,,,,,,,,0,,,,0.0049,,,,,,300.0094604,,,,
,27858180.335,300.0066223,30258.671875,-0.000913817644060781,6.61015268787023E-6,1,0.999253354069792,40.0298881530762,1.99600233893896,21.3099997490644,-0.00972789253675332,-0.0052554187182537,0.25,-0.000306654376463443,-0.000913587804123044,-0.000307248916723895,300.0066223,300.0066223,30251.2890625,30266.0546875,59.6828088429102,21.5470281765592,22.529354,0,0,0,40,4449,299.92765,30258.671875,,,,,,,,,,,,,0,,,,0,,,,,,300.0066223,,,,
,27858223.17,300.006073,32400.4208984375,-0.000974292679811896,6.83515048101133E-6,1,0.999253354069792,40.0298881530762,1.99639234173511,21.3200002908707,-0.0103715954246951,-0.00561586048992244,0.25,-0.000327974815237179,-0.000974047106121827,-0.000328608368635441,300.006073,300.006073,32395.59765625,32405.244140625,59.6085541335832,21.5440651862919,22.909004,0,0,0,40,4449,299.93525,32400.4208984375,,,,,,,,,,,,,0,,,,-0.00245,,,,,,300.006073,,,,
,27858267.455,300.0114136,34614.525390625,-0.00104281477141399,6.23398909087294E-6,1,0.999253354069792,40.0298881530762,1.99616003690533,21.3200002908707,-0.011096784612642,-0.00602754261613137,0.25,-0.000352579775222234,-0.00104255083039737,-0.000353257501482934,300.0114136,300.0114136,34609.796875,34619.25390625,59.7289249255448,21.5429417251915,22.529354,0,0,0,40,4449,299.9149,34614.525390625,,,,,,,,,,,,,0,,,,-0.0049,,,,,,300.0114136,,,,
,27858312.455,300.0063477,36863.173828125,-0.00112241576869025,6.6493530717971E-6,1,0.999253354069792,40.0298881530762,1.99604660381386,21.3200002908707,-0.0119478601061684,-0.00646033329669514,0.25,-0.000377108380276363,-0.00112213359381837,-0.000377837671256185,300.0063477,300.0063477,36858.30078125,36868.046875,59.597611334314,21.5448047311357,23.288654,0,0,0,40,4449,299.89675,36863.173828125,,,,,,,,,,,,,0,,,,-0.00245,,,,,,300.0063477,,,,
,27858356.945,300.0218811,39086.509765625,-0.00117415697724654,7.96506631209681E-6,1,0.999253354069792,40.0298881530762,1.99634831825764,21.3200002908707,-0.0125034988256363,-0.00674141212292898,0.25,-0.000392926868209302,-0.00117386236545871,-0.00039368916369218,300.0218811,300.0218811,39076.5,39096.51953125,59.5819787639294,21.540650310962,22.909004,0,0,0,40,4449,299.91895,39086.509765625,,,,,,,,,,,,,0,,,,0,,,,,,300.0218811,,,,
,27858419.39,300.0144043,38743.365234375,-0.00117053009256951,6.34037957903884E-6,1,0.999253354069792,40.0298881530762,1.99581354101109,21.3200002908707,-0.0124575071955188,-0.00674302696696931,0.25,-0.000393850397851396,-0.0011702352510677,-0.00039461048206275,300.0144043,300.0144043,38740.82421875,38745.90625,59.6828088429102,21.5449867062019,22.529354,0,0,0,40,4449,299.90395,38743.365234375,,,,,,,,,,,,,0,,,,0.0049,,,,,,300.0144043,,,,
,27858463.305,300.0062256,36552.2109375,-0.001106714117648,4.49350252542586E-6,1,0.999253354069792,40.0298881530762,1.99639759667426,21.3200002908707,-0.0117899983366453,-0.00632888390012782,0.25,-0.00036810487749099,-0.00110643833381323,-0.00036882412652862,300.0062256,300.0062256,36549.6484375,36554.7734375,59.7648798374294,21.5428819487635,22.909004,0,0,0,40,4449,299.8973,36552.2109375,,,,,,,,,,,,,0,,,,0.00245,,,,,,300.0062256,,,,
,27858505.9,300.0012512,34422.849609375,-0.00104129005624944,7.00577230988012E-6,1,0.999253354069792,40.0298881530762,1.9962573958848,21.3200002908707,-0.0110826735256125,-0.00600981168469731,0.25,-0.000351250313691944,-0.00104102740120513,-0.000351927240976084,300.0012512,300.0012512,34415.0390625,34430.66015625,59.5983929628332,21.5420905555269,22.909004,0,0,0,40,4449,299.91075,34422.849609375,,,,,,,,,,,,,0,,,,0.0049,,,,,,300.0012512,,,,
,27858550.39,299.9985657,32196.6279296875,-0.000979564400110547,6.4950018219025E-6,1,0.999253354069792,40.0298881530762,1.9959690179896,21.3200002908707,-0.0104257396765336,-0.00564433461133205,0.25,-0.000329681114353969,-0.000979317763388922,-0.000330318285856026,299.9985657,299.9985657,32191.376953125,32201.87890625,59.7351779536986,21.5449224828247,22.529354,0,0,0,40,4449,299.9064,32196.6279296875,,,,,,,,,,,,,0,,,,-0.0049,,,,,,299.9985657,,,,
,27858593.725,300.0019531,30032.1025390625,-0.000908238468305302,6.42950377657727E-6,1,0.999253354069792,40.0298881530762,1.99588181451506,21.3200002908707,-0.009660281082581,-0.00526726349928996,0.25,-0.000308695718858865,-0.000908007572540045,-0.000309286623037801,300.0019531,300.0019531,30022.302734375,30041.90234375,59.7109474696025,21.5443968536944,23.288654,0,0,0,40,4449,299.9144,30032.1025390625,,,,,,,,,,,,,0,,,,0.00245,,,,,,300.0019531,,,,
,27858636.995,299.9999237,27868.65234375,-0.000853972115338088,5.53212206326734E-6,1,0.999253354069792,40.0298881530762,1.99656524515643,21.3200002908707,-0.00908760008891298,-0.00494525998127897,0.25,-0.000289463197381358,-0.000853755473362626,-0.000290019122896759,299.9985962,300.0012512,27858.609375,27878.6953125,59.7023495558909,21.5415784950676,22.529354,0,0,0,40,4449,299.9005,27868.65234375,,,,,,,,,,,,,0,,,,0.00245,,,,,,299.9999237,,,,
,27858681,299.9945679,25669.1728515625,-0.000780622555992692,4.63063717978759E-6,1,0.999253354069792,40.0298881530762,1.99661474273997,21.3200002908707,-0.00830600623657125,-0.00452774710383906,0.25,-0.000265231786966671,-0.00078042416394031,-0.000265740200206656,299.9945679,299.9945679,25659.158203125,25679.1875,59.7406493533332,21.5406022064234,23.288654,0,0,0,40,4449,299.914,25669.1728515625,,,,,,,,,,,,,0,,,,0,,,,,,299.9945679,,,,
,27858724.845,299.9912109,23478.1767578125,-0.000708546667862312,4.6731389275592E-6,1,0.999253354069792,40.0298881530762,1.99673837281826,21.3200002908707,-0.00754160875796409,-0.00409804000270709,0.25,-0.000239690110908593,-0.000708367286048269,-0.000240151843181162,299.9912109,299.9912109,23470.541015625,23485.8125,59.9180790271986,21.537990174597,22.909004,0,0,0,40,4449,299.9165,23478.1767578125,,,,,,,,,,,,,0,,,,0.00245,,,,,,299.9912109,,,,
,27858769.57,299.994812,21243.908203125,-0.000637751903819592,3.48757810308847E-6,1,0.999253354069792,40.0298881530762,1.99587320419652,21.3099997490644,-0.0067841978834915,-0.00369328144780112,0.25,-0.000216291991770771,-0.000637589920031107,-0.00021670772238954,299.994812,299.994812,21236.78125,21251.03515625,59.7234535259102,21.5458116049352,22.909004,0,0,0,40,4449,299.92205,21243.908203125,,,,,,,,,,,,,0,,,,0.0049,,,,,,299.994812,,,,
,27858813.61,299.9926758,19040.138671875,-0.000577335851455342,3.65195268873275E-6,1,0.999253354069792,40.0298881530762,1.99626286899453,21.3200002908707,-0.00613551683822034,-0.00338523226855756,0.25,-0.000199446875035933,-0.000577186767785012,-0.000199823301218407,299.9923401,299.9930115,19032.486328125,19047.791015625,59.7179821262755,21.5426189336778,23.288654,0,0,0,40,4449,299.91605,19040.138671875,,,,,,,,,,,,,0,,,,0.0049,,,,,,299.9926758,,,,
,27858857.995,299.9873047,16823.7578125,-0.000515768251857228,3.21224979945787E-6,1,0.999253354069792,40.0298881530762,1.99516288105831,21.3200002908707,-0.0054831543704098,-0.00299483588951768,0.25,-0.000175716726995415,-0.000515636730913405,-0.000176053263068648,299.9873047,299.9873047,16814.1640625,16833.3515625,59.7109474696025,21.5521377884306,23.288654,0,0,0,40,4449,299.9137,16823.7578125,,,,,,,,,,,,,0,,,,0,,,,,,299.9873047,,,,
,27858901.835,299.9942627,14632.4819335938,-0.000446233990862429,1.98637084607832E-6,1,0.999253354069792,40.0298881530762,1.99626033528937,21.3200002908707,-0.00475546387215075,-0.00254025206665443,0.25,-0.000147410123825433,-0.000446123104784492,-0.000147701488015397,299.9942627,299.9942627,14619.990234375,14644.9736328125,59.7875470644871,21.5431056098939,23.288654,0,0,0,40,4449,299.9302,14632.4819335938,,,,,,,,,,,,,0,,,,0,,,,,,299.9942627,,,,
,27858946.83,299.9924011,12380.6220703125,-0.000374282895577544,2.65181382467855E-6,1,0.999253354069792,40.0298881530762,1.99628311372162,21.3200002908707,-0.00398139441022872,-0.00217303700901772,0.25,-0.000127388308176164,-0.000374187386003903,-0.000127632691444358,299.9924011,299.9924011,12370.26171875,12390.982421875,59.7984898637563,21.5424042669444,22.909004,0,0,0,40,4449,299.9286,12380.6220703125,,,,,,,,,,,,,0,,,,0.00245,,,,,,299.9924011,,,,
,27858991.345,299.99266055,10159.783203125,-0.000306197262268318,1.97764004346854E-6,1,0.999253354069792,40.0298881530762,1.99596307396569,21.3200002908707,-0.00325930836206452,-0.00176207900887606,0.25,-0.000102853435798389,-0.000306119994731258,-0.000103053475554192,299.9919434,299.9933777,10152.3701171875,10167.1962890625,59.7781675222563,21.5418902751055,22.909004,0,0,0,40,4449,299.93465,10159.783203125,,,,,,,,,,,,,0,,,,0,,,,,,299.99266055,,,,
,27859033.89,299.9914856,8030.1533203125,-0.000243277638707873,1.59657030137415E-6,1,0.999253354069792,40.0298881530762,1.99582019654924,21.3200002908707,-0.00259043793284293,-0.0013938218471577,0.25,-8.11806154616597E-5,-0.000243216592046821,-8.13396227989152E-5,299.9914856,299.9914856,8022.609375,8037.697265625,59.7257984114679,21.5497662149372,23.288654,0,0,0,40,4449,299.9392,8030.1533203125,,,,,,,,,,,,,0,,,,-0.00245,,,,,,299.9914856,,,,
,27859075.6,299.9873962,5948.92041015625,-0.000181220685079967,1.28923262771315E-6,1,0.999253354069792,40.0298881530762,1.99576202216751,21.3200002908707,-0.00192935304044534,-0.00103965758952086,0.25,-6.05972496661926E-5,-0.000181175136577066,-6.07157424241059E-5,299.9873962,299.9873962,5944.13525390625,5953.70556640625,59.5968297057948,21.5458815721376,22.909004,0,0,0,40,4449,299.93545,5948.92041015625,,,,,,,,,,,,,0,,,,0.00245,,,,,,299.9873962,,,,
,27859119.04,299.9865112,3774.48999023438,-0.000116479693982733,9.5859897605454E-7,1,0.999253354069792,40.0298881530762,1.9960840416558,21.3200002908707,-0.00123880814309323,-0.000676859490475345,0.25,-3.97023388099087E-5,-0.000116449912905418,-3.97784981118367E-5,299.9865112,299.9865112,3764.47534179687,3784.50463867188,59.6859353569871,21.5433614270758,22.909004,0,0,0,40,4449,299.9541,3774.48999023438,,,,,,,,,,,,,0,,,,0,,,,,,299.9865112,,,,
,27859162.77,299.9902649,1590.06939697266,-5.00373900968382E-5,6.65946508746077E-7,1,0.999253354069792,40.0298881530762,1.99566512728093,21.3200002908707,-0.000533087553685932,-0.000284781961923763,0.25,-1.65310018674212E-5,-5.00249333622303E-5,-1.65637424643509E-5,299.9898071,299.9907227,1579.95166015625,1600.18713378906,59.6007378483909,21.549916353418,22.529354,0,0,0,40,4449,299.9421,1590.06939697266,,,,,,,,,,,,,0,,,,0,,,,,,299.9902649,,,,
,27859194.485,299.9934692,-0.47954885661602,1.18378888351005E-7,4.70383826486456E-7,1,0.999253354069792,40.0298881530762,1.99542365309503,21.3200002908707,3.54661694319293E-6,-1.25178954451783E-5,0.25,-1.12835411738582E-6,1.19124789208008E-7,-1.12824201061176E-6,299.9934692,299.9934692,-0.487160742282867,-0.471936970949173,59.9008831997756,21.5527208181843,22.909004,0,0,0,40,4417,299.9521,-0.47954885661602,,,,,,,,,,,,,0,,,,0.0049,,,,,,299.9934692,,,,