File: data/doubleLayers/dl_2-5/ppms/DD205_5/KoelnPPMS/DD205_5_HYST_100OE_200K.DAT
[Header]
; VSM Data File (default extension .dat)
; Copyright (c) 2003-2013, Quantum Design, Inc. All rights reserved.
TITLE,
FILEOPENTIME,23177751.20,09/26/2018,3:14 pm
BYAPP,VSM,2.0,2.0
INFO,PPMS VSM Option Release 1.4.10 Build 1,APPNAME
INFO,Quantum Design Linear Motor Servo Controller,MOTOR_MODULE_NAME
INFO,3101-100 M1,MOTOR_HW_VERSION
INFO,MMC1014,MOTOR_SERIAL_NUMBER
INFO,SRV No X-over 01.03.11,MOTOR_SOFTWARE_VERSION
INFO,Quantum Design VSM Detection Module,VSM_MODULE_NAME
INFO,3101-150 F0,VSM_HW_VERSION
INFO,VSM707,VSM_SERIAL_NUMBER
INFO,VSM No X-over 01.02.05 May 20 2008 13:51:47,VSM_SOFTWARE_VERSION
INFO,704,PREAMP_SERIAL_NUMBER
INFO,822,COIL_SERIAL_NUMBER
INFO,0,MOMENT_UNITS
INFO,,SAMPLE_MATERIAL
INFO,,SAMPLE_COMMENT
INFO,,SAMPLE_MASS
INFO,,SAMPLE_VOLUME
INFO,,SAMPLE_MOLECULAR_WEIGHT
INFO,,SAMPLE_SIZE
INFO,,SAMPLE_SHAPE
DATATYPE,COMMENT,1
DATATYPE,TIME,2
STARTUPAXIS,X,2
STARTUPAXIS,Y1,5
[Data]
Comment,Time Stamp (sec),Temperature (K),Magnetic Field (Oe),Moment (emu),M. Std. Err. (emu),Transport Action,Averaging Time (sec),Frequency (Hz),Peak Amplitude (mm),Center Position (mm),Coil Signal' (mV),Coil Signal" (mV),Range (mV),M. Quad. Signal (emu),M. Raw' (emu),M. Raw" (emu),Min. Temperature (K),Max. Temperature (K),Min. Field (Oe),Max. Field (Oe),Mass (grams),Motor Lag (deg),Pressure (Torr),VSM Status (code),Motor Status (code),Measure Status (code),Measure Count,PPMS Status (code),System Temp. (K),System Field (Oe),Sample Position (deg),Bridge 1 Resistance (ohms),Bridge 1 Excitation (에),Bridge 2 Resistance (ohms),Bridge 2 Excitation (에),Bridge 3 Resistance (ohms),Bridge 3 Excitation (에),Bridge 4 Resistance (ohms),Bridge 4 Excitation (에),Signal 1 Vin (V),Signal 2 Vin (V),Digital Inputs (code),Drive 1 Iout (mA),Drive 1 Ipower (W),Drive 2 Iout (mA),Drive 2 Ipower (W),Pressure (),Map 20 (),Map 21 (),Map 22 (),Map 23 (),Map 24 (),Map 25 (),Map 26 (),Map 27 (),Map 28 (),Map 29 ()
,23177766.64,200.4118805,-0.243580371141434,,,2,,,,16.2400003299117,,,,,,,200.4118805,200.4118805,-0.243580371141434,-0.243580371141434,,,26.705515,,,,-99999999,4369,200.6907,-0.243580371141434,,,,,,,,,,,,,,,,,,,,,,,200.4118805,,,,
,23177925.57,200.2823334,4421.146484375,4.68844840886797E-5,4.60533919052567E-7,1,0.999253354069792,40.0298881530762,1.99688847789891,16.2300001829863,0.000528334554966788,0.000113134021852747,0.25,1.82822795934273E-6,4.70439086702232E-5,1.88531195921994E-6,200.2823334,200.2823334,4411.068359375,4431.224609375,56.1412500222752,20.5480306248711,26.705515,0,0,0,40,4449,200.2766,4421.146484375,,,,,,,,,,,,,0,,,,0,,,,,,200.2823334,,,,
,23178022.365,200.1785278,9257.16455078125,4.25356544311152E-5,8.13439596683986E-7,1,0.999253354069792,40.0298881530762,1.99698149665279,16.2300001829863,0.000474188163745394,0.000132371194766953,0.25,4.27858916703888E-6,4.26776073795781E-5,4.3393812518576E-6,200.1785278,200.1785278,9252.3837890625,9261.9453125,56.2139414745636,20.5525384973439,26.705515,0,0,0,40,4449,200.16545,9257.16455078125,,,,,,,,,,,,,0,,,,0.00245,,,,,,200.1785278,,,,
,23178117.36,200.1005096,14007.494140625,3.20058862213265E-5,7.32840816682742E-7,1,0.999253354069792,40.0298881530762,1.99683866957724,16.2300001829863,0.000351719626656866,0.00012872423075184,0.25,5.78684073155827E-6,3.21100152510215E-5,5.84140660331324E-6,200.1005096,200.1005096,14005.0771484375,14009.9111328125,56.3898078913906,20.5570796965687,26.705515,0,0,0,40,4449,200.1121,14007.494140625,,,,,,,,,,,,,0,,,,0,,,,,,200.1005096,,,,
,23178212.415,200.052948,18754.75,1.79037570222162E-5,2.08555148833526E-6,1,0.999253354069792,40.0298881530762,1.99675607853665,16.2300001829863,0.000186082319492354,0.00013337170344461,0.25,8.64629226800618E-6,1.79562032680969E-5,8.69545857721877E-6,200.0519867,200.0539093,18752.439453125,18757.060546875,56.4093486043714,20.5548029150716,27.464817,0,0,0,40,4449,200.0922,18754.75,,,,,,,,,,,,,0,,,,-0.0049,,,,,,200.052948,,,,
,23178306.88,200.0247955,23479.724609375,2.64926826042724E-6,1.24286766416154E-6,1,0.999253354069792,40.0298881530762,1.99678123026538,16.2300001829863,1.05988465871931E-5,0.000117250327593924,0.25,9.87463125375929E-6,2.64776952386508E-6,9.91157355201916E-6,200.0247955,200.0247955,23469.51171875,23489.9375,56.3726120639675,20.5591919777117,26.705515,0,0,0,40,4449,200.08365,23479.724609375,,,,,,,,,,,,,0,,,,0,,,,,,200.0247955,,,,
,23178401.825,200.0110168,28225.6083984375,-1.39845930982128E-5,1.05014707456152E-6,1,0.999253354069792,40.0298881530762,1.99639279084967,16.2300001829863,-0.000181297266071157,0.000102964471948361,0.25,1.15061066640621E-5,-1.40452579953726E-5,1.15307860459652E-5,200.0110168,200.0110168,28217.80859375,28233.408203125,56.2616208142367,20.5601668332587,26.705515,0,0,0,40,4449,200.08215,28225.6083984375,,,,,,,,,,,,,0,,,,0,,,,,,200.0110168,,,,
,23178496.415,200.0083771,32950.37890625,-3.17093942135563E-5,1.97604200295468E-6,1,0.999253354069792,40.0298881530762,1.99696095557603,16.2300001829863,-0.000355868449125194,-8.50201780281351E-5,0.25,-1.98599098014963E-6,-3.18167550093727E-5,-2.02690753262004E-6,200.0083771,200.0083771,32945.15625,32955.6015625,56.3061736398329,20.55465892917,26.705515,0,0,0,40,4449,200.0756,32950.37890625,,,,,,,,,,,,,0,,,,0,,,,,,200.0083771,,,,
,23178591.705,200.0067444,37712.98046875,-5.0131841700342E-5,3.18982317402353E-6,1,0.999253354069792,40.0298881530762,1.99695157767206,16.2300001829863,-0.000566275277327577,-0.000113355319824009,0.25,-1.28385355620531E-6,-5.03035901664312E-5,-1.34203294518766E-6,200.0067444,200.0067444,37707.78515625,37718.17578125,56.6368025034675,20.5517298049575,26.705515,0,0,0,40,4449,200.0732,37712.98046875,,,,,,,,,,,,,0,,,,0.0049,,,,,,200.0067444,,,,
,23178686.4,200.0085449,42445.384765625,-6.76045884646983E-5,2.78669036620773E-6,1,0.999253354069792,40.0298881530762,1.99716025271869,16.2300001829863,-0.00076330024417541,-0.000155289667770821,0.25,-1.9439001330156E-6,-6.78359890497233E-5,-2.02295693521838E-6,200.0085449,200.0085449,42440.5390625,42450.23046875,56.6696309012752,20.5536399675414,26.325863,0,0,0,40,4449,200.0643,42445.384765625,,,,,,,,,,,,,0,,,,-0.00245,,,,,,200.0085449,,,,
,23178781.205,200.0111542,47185.8203125,-8.76393430820347E-5,2.71285460165845E-6,1,0.999253354069792,40.0298881530762,1.99701379034958,16.2300001829863,-0.000987339737386557,-0.000213370794174396,0.25,-3.58433622818622E-6,-8.79382062826937E-5,-3.69032076472753E-6,200.0111542,200.0111542,47173.41796875,47198.22265625,56.8064158921406,20.5521454552431,27.464817,0,0,0,40,4449,200.0539,47185.8203125,,,,,,,,,,,,,0,,,,0.00245,,,,,,200.0111542,,,,
,23178874.83,200.0148697,51863.380859375,-0.000103824875803535,3.58768054787866E-6,1,0.999253354069792,40.0298881530762,1.99699233548587,16.2300001829863,-0.00116506469839215,-0.000279310743315684,0.25,-6.58526125816463E-6,-0.000104176466956751,-6.71868903008374E-6,200.01474,200.0149994,51856.046875,51870.71484375,56.6446187886598,20.5537770711404,27.085165,0,0,0,40,4449,200.0418,51863.380859375,,,,,,,,,,,,,0,,,,-0.00245,,,,,,200.0148697,,,,
,23178972.655,200.0129089,56755.962890625,-0.00012337771891234,2.81335215014062E-6,1,0.999253354069792,40.0298881530762,1.99696502271567,16.2300001829863,-0.00139703144808318,-0.000259511141287765,0.25,-1.44504632799919E-6,-0.000123802374998343,-1.58129908624698E-6,200.0129089,200.0129089,56753.44921875,56758.4765625,56.8806706014676,20.5510537035624,26.705515,0,0,0,40,4449,200.03,56755.962890625,,,,,,,,,,,,,0,,,,-0.0049,,,,,,200.0129089,,,,
,23179069.575,200.015686,61598.482421875,-0.000136791462296937,2.84051564898891E-6,1,0.999253354069792,40.0298881530762,1.99708012571386,16.2300001829863,-0.0015394786690694,-0.000342587666090278,0.25,-6.43604319123333E-6,-0.000137257190159407,-6.60350623476239E-6,200.015686,200.015686,61590.84375,61606.12109375,56.5140868259483,20.5527304099125,26.705515,0,0,0,40,4449,200.02665,61598.482421875,,,,,,,,,,,,,0,,,,0,,,,,,200.015686,,,,
,23179164.475,200.0144196,66341.53515625,-0.000153814702735652,3.39183726811157E-6,1,0.999253354069792,40.0298881530762,1.99694121977198,16.2300001829863,-0.00172792218367775,-0.000402616581434078,0.25,-8.77266569488183E-6,-0.000154336829711576,-8.96595570319352E-6,200.0144196,200.0144196,66333.8359375,66349.234375,56.7321611828137,20.5548438627695,27.464817,0,0,0,40,4449,200.0073,66341.53515625,,,,,,,,,,,,,0,,,,0,,,,,,200.0144196,,,,
,23179262.5,200.0151672,71239.24609375,-0.000171980234186955,2.63063697397683E-6,1,0.999253354069792,40.0298881530762,1.99695383843575,16.2300001829863,-0.0019453105945449,-0.000373536023700878,0.25,-3.05510937699125E-6,-0.000172571239011885,-3.24750684797205E-6,200.0151672,200.0151672,71236.75,71241.7421875,56.6782288149868,20.5515520694043,27.464817,0,0,0,40,4449,199.9984,71239.24609375,,,,,,,,,,,,,0,,,,-0.0098,,,,,,200.0151672,,,,
,23179356.39,200.017334,75935.08984375,-0.000191985978284004,4.03949965864588E-6,1,0.999253354069792,40.0298881530762,1.99689953979554,16.2300001829863,-0.00217626329625063,-0.000389805713973268,0.25,-1.0160886516666E-6,-0.000192648311115711,-1.22218532682843E-6,200.017334,200.017334,75930.0859375,75940.09375,56.7438856106022,20.5527845546414,26.705515,0,0,0,40,4449,199.9814,75935.08984375,,,,,,,,,,,,,0,,,,0,,,,,,200.017334,,,,
,23179454.145,200.01543425,80820.87109375,-0.000206874408869669,3.59565102333237E-6,1,0.999253354069792,40.0298881530762,1.99665338240924,16.2300001829863,-0.00233111769322821,-0.000498524896959577,0.25,-8.01837303085336E-6,-0.000207580897469661,-8.26391422273449E-6,200.0151825,200.015686,80818.4375,80823.3046875,56.7477937531983,20.5577876582928,27.464817,0,0,0,40,4449,199.96605,80820.87109375,,,,,,,,,,,,,0,,,,0.0049,,,,,,200.01543425,,,,
,23179550.86,200.0153961,85654.05859375,-0.000222038941253095,3.69311971854019E-6,1,0.999253354069792,40.0298881530762,1.99674092586512,16.2300001829863,-0.00251891010805588,-0.000438298146414901,0.25,-7.49789792480004E-8,-0.000222806273214401,-3.08533127169668E-7,200.0153961,200.0153961,85646.3515625,85661.765625,56.5602029085829,20.5554847170005,26.705515,0,0,0,40,4449,199.95455,85654.05859375,,,,,,,,,,,,,0,,,,0,,,,,,200.0153961,,,,
,23179661.08,200.0167847,89836.44140625,-0.000240399347318706,4.72172622349945E-6,1,0.999253354069792,40.0298881530762,1.99679584318169,16.2300001829863,-0.00271617395400225,-0.000538457487088014,0.25,-5.71421580451047E-6,-0.000241224278310503,-5.98608515405322E-6,200.0167847,200.0167847,89826.796875,89846.0859375,56.5398805670829,20.5544262123648,27.085165,0,0,0,40,4449,199.9398,89836.44140625,,,,,,,,,,,,,0,,,,-0.0049,,,,,,200.0167847,,,,
,23179753.325,200.0083923,85232.34375,-0.000225221789596769,4.44640556417195E-6,1,0.999253354069792,40.0298881530762,1.99680454179188,16.2300001829863,-0.00253196915510387,-0.000577770809663534,0.25,-1.18142591588614E-5,-0.000225987825552488,-1.20918066989373E-5,200.0083923,200.0083923,85224.8125,85239.875,56.3358755235637,20.5565920925375,27.085165,0,0,0,40,4449,199.93525,85232.34375,,,,,,,,,,,,,0,,,,0,,,,,,200.0083923,,,,
,23179848.61,200.0046082,80468.30078125,-0.000208458925807417,3.73752703064769E-6,1,0.999253354069792,40.0298881530762,1.9967816538477,16.2300001829863,-0.00235248899140582,-0.000482957785305084,0.25,-6.36830988280069E-6,-0.00020917268908495,-6.6098961477899E-6,200.0046082,200.0046082,80455.734375,80480.8671875,56.7939098358329,20.5578996445902,27.464817,0,0,0,40,4449,199.9347,80468.30078125,,,,,,,,,,,,,0,,,,0.00245,,,,,,200.0046082,,,,
,23179946.48,199.9959106,75574.1171875,-0.000179538001213553,3.32999516602017E-6,1,0.999253354069792,40.0298881530762,1.99657621900413,16.2300001829863,-0.00202312180355268,-0.000431985683364149,0.25,-6.90120514231267E-6,-0.000180151223355127,-7.11458512122992E-6,199.9959106,199.9959106,75566.7265625,75581.5078125,56.5641110511791,20.5580499824045,27.085165,0,0,0,40,4449,199.94045,75574.1171875,,,,,,,,,,,,,0,,,,-0.00245,,,,,,199.9959106,,,,
,23180043.005,199.9910736,70751.14453125,-0.000177565703643759,3.90725047486762E-6,1,0.999253354069792,40.0298881530762,1.99631406190077,16.2300001829863,-0.00200483224226331,-0.000403079368894612,0.25,-4.69966427095434E-6,-0.000178174393200636,-4.90375480556316E-6,199.9910736,199.9910736,70738.65625,70763.6328125,56.8345545188329,20.5616538465901,27.085165,0,0,0,40,4449,199.94545,70751.14453125,,,,,,,,,,,,,0,,,,0,,,,,,199.9910736,,,,
,23180140.415,199.9919128,65880.40234375,-0.000152518484366115,2.98657025578541E-6,1,0.999253354069792,40.0298881530762,1.99631418026262,16.2300001829863,-0.00171809388613452,-0.000368899226720888,0.25,-6.03571641171448E-6,-0.000153039130470638,-6.21826925879287E-6,199.9916534,199.9921722,65875.3828125,65885.421875,56.7517018957945,20.561584969791,27.085165,0,0,0,40,4449,199.9512,65880.40234375,,,,,,,,,,,,,0,,,,-0.0049,,,,,,199.9919128,,,,
,23180235.235,199.9923553,61140.05859375,-0.000134409607740688,3.35593187543316E-6,1,0.999253354069792,40.0298881530762,1.99673882944666,16.2300001829863,-0.00151040704451042,-0.000348199197856974,0.25,-7.34913307398498E-6,-0.000134866224275716,-7.51731403739654E-6,199.9923553,199.9923553,61132.8515625,61147.265625,56.699332785006,20.5636232224834,26.705515,0,0,0,40,4449,199.95935,61140.05859375,,,,,,,,,,,,,0,,,,0.00245,,,,,,199.9923553,,,,
,23180331.235,199.9925385,56344.38671875,-0.000122323668705901,2.28393432393374E-6,1,0.999253354069792,40.0298881530762,1.99633391300894,16.2300001829863,-0.00137973213350885,-0.000285702266829776,0.25,-3.94395242274583E-6,-0.000122742094084132,-4.08779486371242E-6,199.9925385,199.9925385,56339.28515625,56349.48828125,56.8587850029291,20.5606398751828,26.705515,0,0,0,40,4449,199.9629,56344.38671875,,,,,,,,,,,,,0,,,,0.00245,,,,,,199.9925385,,,,
,23180426.525,199.9915466,51579.201171875,-9.79808711234897E-5,2.13686899781793E-6,1,0.999253354069792,40.0298881530762,1.99683713811453,16.2300001829863,-0.00110991597303865,-0.000203051700550863,0.25,-8.80478321066669E-7,-9.83184254513338E-5,-9.88029960628144E-7,199.9915466,199.9915466,51571.81640625,51586.5859375,56.689171614256,20.5619494294541,27.085165,0,0,0,40,4449,199.9717,51579.201171875,,,,,,,,,,,,,0,,,,-0.0049,,,,,,199.9915466,,,,
,23180522.48,199.9934998,46784.302734375,-8.66357290006904E-5,1.85767858398719E-6,1,0.999253354069792,40.0298881530762,1.99645208069756,16.2300001829863,-0.000982518968489334,-0.000172019418947288,0.25,-1.18236031533627E-7,-8.69348698019862E-5,-2.11237121005055E-7,199.9934998,199.9934998,46779.49609375,46789.109375,56.7571732954291,20.562141166655,27.464817,0,0,0,40,4449,199.9762,46784.302734375,,,,,,,,,,,,,0,,,,0.00245,,,,,,199.9934998,,,,
,23180620.915,199.99137115,41866.603515625,-6.85440639702741E-5,1.62692462909982E-6,1,0.999253354069792,40.0298881530762,1.99672627680848,16.2300001829863,-0.000776852046879736,-0.000139538830454547,0.25,-3.95162182970305E-7,-6.87803972866127E-5,-4.69929477321056E-7,199.9911499,199.9915924,41856.5703125,41876.63671875,56.7681160946983,20.5611826638129,27.085165,0,0,0,40,4449,199.9839,41866.603515625,,,,,,,,,,,,,0,,,,0.00245,,,,,,199.99137115,,,,
,23180718.305,199.9934998,36996.71875,-4.95074058849009E-5,2.43575080694703E-6,1,0.999253354069792,40.0298881530762,1.99704640212138,16.2300001829863,-0.000553652840374846,-0.000144160324091182,0.25,-4.10669126459569E-6,-4.96739834228724E-5,-4.17399403494811E-6,199.9934998,199.9934998,36984.21484375,37009.22265625,57.014329078256,20.5590142279765,26.705515,0,0,0,40,4449,199.9879,36996.71875,,,,,,,,,,,,,0,,,,-0.00245,,,,,,199.9934998,,,,
,23180816.245,199.9914093,32101.958984375,-3.11434513215123E-5,1.2472124391513E-6,1,0.999253354069792,40.0298881530762,1.99693876886681,16.2300001829863,-0.000353378574953763,-6.12473724001071E-5,0.25,1.09058620287696E-8,-3.12510161620724E-5,-2.25354040069203E-8,199.9914093,199.9914093,32091.908203125,32112.009765625,56.9306948266983,20.5623606572359,26.705515,0,0,0,40,4449,199.99405,32101.958984375,,,,,,,,,,,,,0,,,,-0.0049,,,,,,199.9914093,,,,
,23180913.045,199.9909058,27264.482421875,-1.22201223782896E-5,1.26465421888549E-6,1,0.999253354069792,40.0298881530762,1.99689923046142,16.2300001829863,-0.000135829066872818,-4.03121212566853E-5,0.25,-1.4305981473141E-6,-1.22607803471569E-5,-1.44869846913492E-6,199.9909058,199.9909058,27254.4296875,27274.53515625,56.8095424062176,20.5611185668202,27.464817,0,0,0,40,4449,200.00275,27264.482421875,,,,,,,,,,,,,0,,,,-0.0049,,,,,,199.9909058,,,,
,23181009.665,199.9889832,22434.28515625,2.28365424974407E-6,9.77295096298204E-7,1,0.999253354069792,40.0298881530762,1.99701820646186,16.2300001829863,2.45306515005458E-5,1.24510648123416E-5,0.25,7.00711295924527E-7,2.29078378176885E-6,7.05594432595047E-7,199.9889832,199.9889832,22427,22441.5703125,57.004167907506,20.5638983716907,27.085165,0,0,0,40,4449,200.0123,22434.28515625,,,,,,,,,,,,,0,,,,0.00245,,,,,,199.9889832,,,,
,23181105.81,199.992981,17629.1767578125,2.15393706120608E-5,1.14572375987366E-6,1,0.999253354069792,40.0298881530762,1.99696447035708,16.2300001829863,0.000228932330298754,0.000131448859356459,0.25,7.84415978660001E-6,2.16052609905648E-5,7.89451800327456E-6,199.992981,199.992981,17619.099609375,17639.25390625,56.5719273363714,20.5725721903532,26.705515,0,0,0,40,4449,200.01675,17629.1767578125,,,,,,,,,,,,,0,,,,0,,,,,,199.992981,,,,
,23181202.485,199.9910736,12797.0498046875,3.57999411043989E-5,6.22863910498243E-7,1,0.999253354069792,40.0298881530762,1.99684135244106,16.2300001829863,0.000395580369794408,0.000131517784507939,0.25,5.3739991020603E-6,3.59177207945613E-5,5.43129910246522E-6,199.9910736,199.9910736,12792.0302734375,12802.0693359375,56.5617661656214,20.5730596210725,27.464817,0,0,0,40,4449,200.02375,12797.0498046875,,,,,,,,,,,,,0,,,,0.00245,,,,,,199.9910736,,,,
,23181296.605,199.99437715,8093.90478515625,4.5280637906727E-5,7.44927006901082E-7,1,0.999253354069792,40.0298881530762,1.99676945683694,16.2300001829863,0.000505941665330628,0.000133987608145346,0.25,3.94535041430384E-6,4.54326735852786E-5,4.00804835840692E-6,199.9942322,199.9945221,8088.9130859375,8098.896484375,56.9088092281599,20.571018832303,27.085165,0,0,0,40,4449,200.0289,8093.90478515625,,,,,,,,,,,,,0,,,,-0.00245,,,,,,199.99437715,,,,
,23181391.655,199.9946442,3341.18103027344,4.72783888080914E-5,3.8912312497407E-7,1,0.999253354069792,40.0298881530762,1.99667455737467,16.2300001829863,0.000533483385643809,0.000109700726018011,0.25,1.4580115482688E-6,4.74400045907993E-5,1.51435407632214E-6,199.9946442,199.9946442,3336.26879882812,3346.09326171875,56.4929828559291,20.5748707252595,27.085165,0,0,0,40,4449,200.0329,3341.18103027344,,,,,,,,,,,,,0,,,,0,,,,,,199.9946442,,,,
,23181484.785,199.99263,-1309.68273925781,1.23783453066756E-5,3.99818092942466E-7,1,0.999253354069792,40.0298881530762,1.99696104101735,16.2300001829863,0.000141286424913304,1.95621350573046E-5,0.25,-4.25895233057238E-7,1.24215359106787E-5,-4.13925579771796E-7,199.99263,199.99263,-1315,-1304.36547851562,56.9392927404099,20.561571165895,27.085165,0,0,0,40,4449,200.0369,-1309.68273925781,,,,,,,,,,,,,0,,,,0,,,,,,199.99263,,,,
,23181581.555,200.0011444,-6146.72875976563,-3.56199172585433E-5,5.40848596404963E-7,1,0.999253354069792,40.0298881530762,1.99663232632964,16.2300001829863,-0.000396711891435569,-0.000112647343548312,0.25,-3.74294630698725E-6,-3.57388096941238E-5,-3.79449380735788E-6,200.0011444,200.0011444,-6151.7724609375,-6141.68505859375,56.4734421429483,20.573219152327,27.085165,0,0,0,40,4449,200.0347,-6146.72875976563,,,,,,,,,,,,,0,,,,-0.0049,,,,,,200.0011444,,,,
,23181679.01,200.0075531,-11017.4375,-3.73004910850727E-5,1.00344078386804E-6,1,0.999253354069792,40.0298881530762,1.99667192841374,16.2300001829863,-0.000411552304691573,-0.000140330195701982,0.25,-5.89108763153108E-6,-3.74228643851356E-5,-5.95181570876241E-6,200.0075531,200.0075531,-11029.970703125,-11004.904296875,56.6633778731214,20.5761395315949,27.464817,0,0,0,40,4449,200.0257,-11017.4375,,,,,,,,,,,,,0,,,,-0.00245,,,,,,200.0075531,,,,
,23181774.21,200.0085297,-15777.3525390625,-2.49857475511266E-5,1.43045227585505E-6,1,0.999253354069792,40.0298881530762,1.99669968089366,16.2300001829863,-0.00026861786503885,-0.000134674689557352,0.25,-7.5313752330329E-6,-2.50638546457491E-5,-7.58438949751879E-6,200.0080872,200.0089722,-15782.1962890625,-15772.5087890625,56.8611298884868,20.5731605197446,26.705515,0,0,0,40,4449,200.02105,-15777.3525390625,,,,,,,,,,,,,0,,,,-0.00245,,,,,,200.0085297,,,,
,23181870.735,200.0102997,-20599.6669921875,-1.1573102501515E-5,1.2171111048997E-6,1,0.999253354069792,40.0298881530762,1.99664049932594,16.2300001829863,-0.00010953438173435,-0.000148066593080296,0.25,-1.10418009697979E-5,-1.16011353731164E-5,-1.10924125054663E-5,200.0102997,200.0102997,-20604.751953125,-20594.58203125,56.6305494753137,20.5729191980498,27.085165,0,0,0,40,4449,200.0124,-20599.6669921875,,,,,,,,,,,,,0,,,,0,,,,,,200.0102997,,,,
,23181968.45,200.0142517,-25484.51171875,4.18134568593878E-6,4.88897770244001E-7,1,0.999253354069792,40.0298881530762,1.99657897912885,16.2300001829863,7.56138575724942E-5,-0.00015401171003436,0.25,-1.43025482182323E-5,4.21119442991698E-6,-1.43474191725375E-5,200.0142517,200.0142517,-25497.181640625,-25471.841796875,56.5148684544675,20.5750982480352,26.705515,0,0,0,40,4449,199.9993,-25484.51171875,,,,,,,,,,,,,0,,,,-0.00245,,,,,,200.0142517,,,,
,23182065.26,200.0124512,-30324.5771484375,1.86016808840817E-5,1.17132467484242E-6,1,0.999253354069792,40.0298881530762,1.9965647889531,16.2300001829863,0.000244218784390108,-0.000154504893980241,0.25,-1.68506357001676E-5,1.86840336152647E-5,-1.68888041725908E-5,200.0124512,200.0124512,-30329.646484375,-30319.5078125,56.7970363499099,20.5724557808945,27.464817,0,0,0,40,4449,199.98815,-30324.5771484375,,,,,,,,,,,,,0,,,,0.00245,,,,,,200.0124512,,,,
,23182161.055,200.0139923,-35111.3046875,3.62115234872835E-5,1.6880425017533E-6,1,0.999253354069792,40.0298881530762,1.99640970834063,16.2300001829863,0.000446069715048564,-0.000131988150515409,0.25,-1.79250233465397E-5,3.63558065659692E-5,-1.79480315567027E-5,200.0139923,200.0139923,-35121.27734375,-35101.33203125,57.1237570709483,20.5783945639849,26.705515,0,0,0,40,4449,199.9778,-35111.3046875,,,,,,,,,,,,,0,,,,0,,,,,,200.0139923,,,,
,23182259.05,200.01220705,-40008.505859375,5.68577156155145E-5,1.9984619409331E-6,1,0.999253354069792,40.0298881530762,1.99676875013879,16.2300001829863,0.000649835995423556,8.45433324120959E-5,0.25,-2.4229626266594E-6,5.70566566310007E-5,-2.37038997910313E-6,200.0119019,200.0125122,-40018.515625,-39998.49609375,57.098744958333,20.5661745612364,26.705515,0,0,0,40,4449,199.9678,-40008.505859375,,,,,,,,,,,,,0,,,,0,,,,,,200.01220705,,,,
,23182356.275,200.0142212,-44866.59375,7.5808743849399E-5,2.03517931409537E-6,1,0.999253354069792,40.0298881530762,1.99680701797316,16.2300001829863,0.000862080208645663,0.000137863834676679,0.25,-1.01455504607605E-6,7.60716336946207E-5,-9.36963681487461E-7,200.0142212,200.0142212,-44871.59375,-44861.59375,56.9424192544868,20.5655762505735,27.464817,0,0,0,40,4449,199.95735,-44866.59375,,,,,,,,,,,,,0,,,,0,,,,,,200.0142212,,,,
,23182452.82,200.0118866,-49691.365234375,8.77986734364173E-5,2.45446499840234E-6,1,0.999253354069792,40.0298881530762,1.99696583322522,16.2300001829863,0.000996332171297235,0.000172181078983608,0.25,-7.31094947791387E-8,8.81019964385603E-5,2.03768834008238E-8,200.0118866,200.0118866,-49704.12109375,-49678.609375,57.017455592333,20.565939778239,27.085165,0,0,0,40,4449,199.9456,-49691.365234375,,,,,,,,,,,,,0,,,,0,,,,,,200.0118866,,,,
,23182551.145,200.0119934,-54605.697265625,0.000108087997444646,2.2169629185441E-6,1,0.999253354069792,40.0298881530762,1.99695244837054,16.2300001829863,0.00123498987488951,0.000163465694899942,0.25,-4.36461395360261E-6,0.000108466003132497,-4.26452338954727E-6,200.0119934,200.0119934,-54615.8125,-54595.58203125,56.8392442899483,20.5651596275321,27.085165,0,0,0,40,4449,199.9363,-54605.697265625,,,,,,,,,,,,,0,,,,-0.0049,,,,,,200.0119934,,,,
,23182648.58,200.0141602,-59475.244140625,0.000137004897993133,2.64268684931028E-6,1,0.999253354069792,40.0298881530762,1.99720004899321,16.2300001829863,0.00156451352713678,0.000213326124394746,0.25,-4.99409996775711E-6,0.000137483480839107,-4.86567029991454E-6,200.0141602,200.0141602,-59482.74609375,-59467.7421875,56.7837486650829,20.568563568605,26.705515,0,0,0,40,4449,199.92435,-59475.244140625,,,,,,,,,,,,,0,,,,0,,,,,,200.0141602,,,,
,23182746,200.0145416,-64342.869140625,0.000159010998951698,2.24794493374803E-6,1,0.999253354069792,40.0298881530762,1.99694207576065,16.2300001829863,0.00182039974779966,0.000219845212526254,0.25,-8.23863414144006E-6,0.000159569080463474,-8.09836330594349E-6,200.0145416,200.0145416,-64355.12890625,-64330.609375,56.8142321773329,20.5664987408121,27.464817,0,0,0,40,4449,199.9126,-64342.869140625,,,,,,,,,,,,,0,,,,-0.00245,,,,,,200.0145416,,,,
,23182846.415,200.0158844,-69359.54296875,0.000177865510914545,3.27735127438572E-6,1,0.999253354069792,40.0298881530762,1.9970204966092,16.2300001829863,0.00204028010764379,0.000223163964834393,0.25,-1.12208573843119E-5,0.000178491918992073,-1.10712881318781E-5,200.0158844,200.0158844,-69362.2578125,-69356.828125,56.9611783389483,20.56429746472,27.085165,0,0,0,40,4449,199.8978,-69359.54296875,,,,,,,,,,,,,0,,,,0.0049,,,,,,200.0158844,,,,
,23182944.69,200.0156403,-74274.14453125,0.000202407863752233,2.72384057475442E-6,1,0.999253354069792,40.0298881530762,1.99702911755086,16.2300001829863,0.00230887787189603,0.000328444607757491,0.25,-6.20403933255084E-6,0.000203113806964826,-6.01160718490208E-6,200.0156403,200.0156403,-74279.0078125,-74269.28125,56.8869236296214,20.56646586079,27.464817,0,0,0,40,4449,199.8844,-74274.14453125,,,,,,,,,,,,,0,,,,-0.0049,,,,,,200.0156403,,,,
,23183045.535,200.0173645,-79313.3359375,0.000198898149398038,3.42040712361183E-6,1,0.999253354069792,40.0298881530762,1.99724334865091,16.2300001829863,0.00225287379214595,0.000416076499156222,0.25,2.1253050514523E-6,0.000199583224723788,2.34234579565528E-6,200.0173645,200.0173645,-79315.828125,-79310.84375,57.1003082153714,20.5637746071413,26.705515,0,0,0,40,4449,199.87135,-79313.3359375,,,,,,,,,,,,,0,,,,0,,,,,,200.0173645,,,,
,23183144.51,200.0121918,-84258.03515625,0.000220893905016551,3.16992691587911E-6,1,0.999253354069792,40.0298881530762,1.99693813906306,16.2300001829863,0.00249929761099922,0.000475574890893843,0.25,3.5553037628632E-6,0.000221653601819451,3.79996178120969E-6,200.0121918,200.0121918,-84263.3046875,-84252.765625,56.872072687756,20.5699751355964,27.085165,0,0,0,40,4449,199.8626,-84258.03515625,,,,,,,,,,,,,0,,,,0,,,,,,200.0121918,,,,
,23183239.34,200.0095062,-89000,0.000233939490796194,3.6351281772167E-6,1,0.999253354069792,40.0298881530762,1.99698579640625,16.2300001829863,0.00264961531256688,0.000488399479113968,0.25,2.41967978382249E-6,0.000234745571202148,2.67360962642564E-6,200.0095062,200.0095062,-89009.828125,-88990.171875,57.0612267894099,20.5694912287961,27.085165,0,0,0,40,4449,199.854,-89000,,,,,,,,,,,,,0,,,,-0.00245,,,,,,200.0095062,,,,
,23183351.72,200.0097809,-86394.4609375,0.000224634421897519,3.35533672362659E-6,1,0.999253354069792,40.0298881530762,1.99711592172999,16.2300001829863,0.00254228166326084,0.000481103562194888,0.25,3.38960782343721E-6,0.000225407271957548,3.63741831016915E-6,200.0097809,200.0097809,-86399.5703125,-86389.3515625,57.119067299833,20.566366137472,27.085165,0,0,0,40,4449,199.8465,-86394.4609375,,,,,,,,,,,,,0,,,,0,,,,,,200.0097809,,,,
,23183447.005,200.0024109,-81634.78515625,0.000203909061666811,2.90397833614117E-6,1,0.999253354069792,40.0298881530762,1.99720814397855,16.2300001829863,0.00230679078833523,0.000442693381068111,0.25,3.60149124145281E-6,0.000204610029160217,3.82872176612382E-6,200.0024109,200.0024109,-81642.203125,-81627.3671875,57.210517836583,20.5689001410167,27.085165,0,0,0,40,4449,199.84685,-81634.78515625,,,,,,,,,,,,,0,,,,0,,,,,,200.0024109,,,,
,23183545.205,200.0002136,-76724.87890625,0.000188568210199848,3.38134562647537E-6,1,0.999253354069792,40.0298881530762,1.99708305314441,16.2300001829863,0.00213482999043042,0.000399482227969773,0.25,2.45930197605346E-6,0.000189217306022206,2.66685058851E-6,200.0002136,200.0002136,-76735.125,-76714.6328125,57.0151107067753,20.5678834079847,27.464817,0,0,0,40,4449,199.8641,-76724.87890625,,,,,,,,,,,,,0,,,,-0.00245,,,,,,200.0002136,,,,
,23183644.565,199.9916687,-71760.55859375,0.000194030805628918,2.97388682488887E-6,1,0.999253354069792,40.0298881530762,1.99714912608433,16.2300001829863,0.00221415071716751,0.000310826870050926,0.25,-6.30379801152152E-6,0.000194708033631809,-6.12030489640141E-6,199.9916687,199.9916687,-71763.2109375,-71757.90625,57.054973761256,20.5706569371126,27.085165,0,0,0,40,4449,199.8617,-71760.55859375,,,,,,,,,,,,,0,,,,-0.0049,,,,,,199.9916687,,,,
,23183743.075,199.9913025,-66838.23046875,0.000168515406470581,2.23211750104136E-6,1,0.999253354069792,40.0298881530762,1.99700796549993,16.2300001829863,0.00192072171074104,0.000282222510097208,0.25,-4.39222887524248E-6,0.000169102389051516,-4.22873864671639E-6,199.9913025,199.9913025,-66850.4921875,-66825.96875,56.922878541506,20.5693365616212,27.085165,0,0,0,40,4449,199.8696,-66838.23046875,,,,,,,,,,,,,0,,,,0.00245,,,,,,199.9913025,,,,
,23183841.06,199.99076845,-61940.724609375,0.000148308036443416,2.58833524765904E-6,1,0.999253354069792,40.0298881530762,1.99716468885331,16.2300001829863,0.00169967418143576,0.000195724029573695,0.25,-8.50787302431618E-6,0.000148829527127782,-8.37969397591105E-6,199.9904633,199.9910736,-61948.421875,-61933.02734375,56.9392927404099,20.5611767327669,27.464817,0,0,0,40,4449,199.8769,-61940.724609375,,,,,,,,,,,,,0,,,,0,,,,,,199.99076845,,,,
,23183940.515,199.989151,-56971.12109375,0.000118857947078299,2.56336562390135E-6,1,0.999253354069792,40.0298881530762,1.99697065412847,16.2300001829863,0.00135295850484292,0.000209117913527057,0.25,-2.21155986780318E-6,0.00011927096098511,-2.09264598305546E-6,199.989151,199.989151,-56976.05078125,-56966.19140625,57.1175040427945,20.5647700399521,26.705515,0,0,0,40,4449,199.88255,-56971.12109375,,,,,,,,,,,,,0,,,,0.0049,,,,,,199.989151,,,,
,23184039.815,199.9864807,-52009.544921875,0.000101605381286783,2.83262129844028E-6,1,0.999253354069792,40.0298881530762,1.99696258441051,16.2300001829863,0.00114957839456314,0.00021900972407206,0.25,1.65635446147521E-6,0.00010195464186047,1.77048233436621E-6,199.9864807,199.9864807,-52019.64453125,-51999.4453125,56.9244417985445,20.567346499685,27.085165,0,0,0,40,4449,199.89745,-52009.544921875,,,,,,,,,,,,,0,,,,-0.0049,,,,,,199.9864807,,,,
,23184138.93,199.9886017,-47054.58984375,8.07722907804651E-5,1.99450442766193E-6,1,0.999253354069792,40.0298881530762,1.99686162504899,16.2300001829863,0.000916068234795119,0.000161180663163872,0.25,1.78247757650337E-7,8.10511224597337E-5,2.6521608339823E-7,199.9886017,199.9886017,-47061.625,-47047.5546875,56.9174071418714,20.5663053999289,27.085165,0,0,0,40,4449,199.90795,-47054.58984375,,,,,,,,,,,,,0,,,,-0.00245,,,,,,199.9886017,,,,
,23184236.04,199.990387,-42202.36328125,6.54662983471002E-5,1.93630316686517E-6,1,0.999253354069792,40.0298881530762,1.99692617611632,16.2300001829863,0.000739276407474973,0.000149202450447582,0.25,1.78021598931966E-6,6.56905160482811E-5,1.85649270546426E-6,199.990387,199.990387,-42214.9296875,-42189.796875,57.105779615006,20.5674151607691,26.705515,0,0,0,40,4449,199.9124,-42202.36328125,,,,,,,,,,,,,0,,,,0,,,,,,199.990387,,,,
,23184331.705,199.9892426,-37420.19921875,4.63800186860118E-5,1.6006719883737E-6,1,0.999253354069792,40.0298881530762,1.99694059269801,16.2300001829863,0.000523925970720704,0.000104682615685071,0.25,1.17108008574476E-6,4.65389493798682E-5,1.22490100716272E-6,199.9892426,199.9892426,-37427.5390625,-37412.859375,57.1049979864868,20.5669403003933,27.464817,0,0,0,40,4449,199.92045,-37420.19921875,,,,,,,,,,,,,0,,,,0,,,,,,199.9892426,,,,
,23184431.295,199.9896698,-32443.2119140625,2.9955412797475E-5,1.34275915738018E-6,1,0.999253354069792,40.0298881530762,1.99707770895918,16.2300001829863,0.000338138831850446,6.9174405021493E-5,0.25,8.93675882771902E-7,3.0057902601425E-5,9.28972399860767E-7,199.9896698,199.9896698,-32445.5546875,-32440.869140625,56.8197035769676,20.5656834376942,26.705515,0,0,0,40,4449,199.9304,-32443.2119140625,,,,,,,,,,,,,0,,,,-0.0049,,,,,,199.9896698,,,,
,23184528.305,199.9901886,-27596.21875,1.47150213570448E-5,1.07659697477072E-6,1,0.999253354069792,40.0298881530762,1.99694131058616,16.2300001829863,0.000167971710921252,2.31632903008251E-5,0.25,-5.14224185532135E-7,1.47663890089511E-5,-5.00148433406092E-7,199.9901886,199.9901886,-27603.802734375,-27588.634765625,56.8142321773329,20.5657197243946,27.085165,0,0,0,40,4449,199.9371,-27596.21875,,,,,,,,,,,,,0,,,,-0.00245,,,,,,199.9901886,,,,
,23184625.62,199.9910736,-22733.8564453125,-2.01208488181488E-6,9.40562687971018E-7,1,0.999253354069792,40.0298881530762,1.99711609560942,16.2300001829863,-2.19070905573716E-5,-9.28631658389626E-6,0.25,-4.68922030123758E-7,-2.01852635037677E-6,-4.72712429659502E-7,199.9910736,199.9910736,-22741.51953125,-22726.193359375,56.9041194570445,20.5637214616188,27.464817,0,0,0,40,4449,199.9465,-22733.8564453125,,,,,,,,,,,,,0,,,,0.00245,,,,,,199.9910736,,,,
,23184723.32,199.9927368,-17846.9541015625,-1.70066060463894E-5,9.68721533857171E-7,1,0.999253354069792,40.0298881530762,1.99707449920348,16.2300001829863,-0.000194535527242277,-2.45086245228948E-5,0.25,7.93859657431279E-7,-1.70661804197382E-5,7.78217288572264E-7,199.9927368,199.9927368,-17854.412109375,-17839.49609375,56.8580033744099,20.564269621416,27.085165,0,0,0,40,4449,199.9536,-17846.9541015625,,,,,,,,,,,,,0,,,,0,,,,,,199.9927368,,,,
,23184820.125,199.9892578,-13008.9448242187,-3.14044122173914E-5,9.68444559929822E-7,1,0.999253354069792,40.0298881530762,1.99699995243608,16.2300001829863,-0.000355261343679173,-6.80284580775323E-5,0.25,-5.41019537348615E-7,-3.15122476884294E-5,-5.76887356900298E-7,199.9892578,199.9892578,-13021.2607421875,-12996.62890625,57.068261446083,20.5629405086762,27.085165,0,0,0,40,4449,199.96285,-13008.9448242187,,,,,,,,,,,,,0,,,,-0.00245,,,,,,199.9892578,,,,
,23184916.76,199.9911499,-8178.15307617187,-4.2814103882644E-5,6.26444163406606E-7,1,0.999253354069792,40.0298881530762,1.99694952003901,16.2300001829863,-0.000485356291422839,-8.67828680253041E-5,0.25,-2.1230373979035E-7,-4.29616731021138E-5,-2.59458084658018E-7,199.9911499,199.9911499,-8183.23193359375,-8173.07421875,56.933039712256,20.5625791964098,27.464817,0,0,0,40,4449,199.96795,-8178.15307617187,,,,,,,,,,,,,0,,,,0,,,,,,199.9911499,,,,
,23185014.165,199.9933929,-3310.20690917969,-4.6257207024163E-5,3.14402016144717E-7,1,0.999253354069792,40.0298881530762,1.99693594438522,16.2300001829863,-0.000523844445312496,-9.68735166198649E-5,0.25,-5.03611505417685E-7,-4.64163325453299E-5,-5.55570120967181E-7,199.9933929,199.9933929,-3320.2294921875,-3300.18432617188,56.8173586914099,20.5604987783555,27.085165,0,0,0,40,4449,199.97435,-3310.20690917969,,,,,,,,,,,,,0,,,,0,,,,,,199.9933929,,,,
,23185107.415,199.9933548,1348.63427734375,-1.03495481557373E-5,3.70114970332993E-7,1,0.999253354069792,40.0298881530762,1.9969901776657,16.2300001829863,-0.000116987049577842,-2.29443942760151E-5,0.25,-2.24553232792289E-7,-1.03850284777427E-5,-2.36569515245676E-7,199.9931793,199.9935303,1341.15295410156,1356.11560058594,56.9486722826406,20.564218328822,27.085165,0,0,0,40,4449,199.9765,1348.63427734375,,,,,,,,,,,,,0,,,,0,,,,,,199.9933548,,,,
,23185202.555,199.9958115,6102.77661132813,3.45520600717173E-5,5.25162987880834E-7,1,0.999253354069792,40.0298881530762,1.99703782762158,16.2300001829863,0.000394070115374216,5.6457666460114E-5,0.25,-1.02562706349842E-6,3.46724422730766E-5,-9.91684217368482E-7,199.9957886,199.9958344,6097.84375,6107.70947265625,56.9760292808137,20.5614552668748,27.085165,0,0,0,40,4449,199.97925,6102.77661132813,,,,,,,,,,,,,0,,,,0,,,,,,199.9958115,,,,
,23185298.385,200.0019379,10890.9111328125,3.71551738936749E-5,7.5934365896831E-7,1,0.999253354069792,40.0298881530762,1.99707226264522,16.2300001829863,0.000422602400242215,6.74107952365298E-5,0.25,-5.12481991200953E-7,3.72839851530287E-5,-4.74000900081631E-7,200.0019379,200.0019379,10880.84765625,10900.974609375,56.9017745714868,20.5633877861006,27.464817,0,0,0,40,4449,199.97595,10890.9111328125,,,,,,,,,,,,,0,,,,-0.00245,,,,,,200.0019379,,,,
,23185394.585,200.0074463,15701.1459960938,2.45604308150067E-5,7.86937119667639E-7,1,0.999253354069792,40.0298881530762,1.99687230593084,16.2300001829863,0.000280690106378951,3.66864405659339E-5,0.25,-1.03232234424436E-6,2.46463292161089E-5,-1.00932058828965E-6,200.0074463,200.0074463,15693.69140625,15708.6005859375,57.0495023616214,20.5638212809434,27.464817,0,0,0,40,4449,199.97015,15701.1459960938,,,,,,,,,,,,,0,,,,0,,,,,,200.0074463,,,,
,23185490.89,200.0104065,20515.6162109375,9.27486617689448E-6,9.91004739073221E-7,1,0.999253354069792,40.0298881530762,1.99695515530156,16.2300001829863,0.000105480628326604,1.68591760432137E-5,0.25,-1.2501627480884E-7,9.3070191795615E-6,-1.15431963849772E-7,200.0104065,200.0104065,20505.708984375,20525.5234375,56.9807190519291,20.5598938579766,27.085165,0,0,0,40,4449,199.9586,20515.6162109375,,,,,,,,,,,,,0,,,,0.0049,,,,,,200.0104065,,,,
,23185586.31,200.0121307,25283.5966796875,-6.28259373691337E-6,9.02070220582055E-7,1,0.999253354069792,40.0298881530762,1.99713565882329,16.2300001829863,-6.96621388079004E-5,-2.1752096630737E-5,0.25,-8.25782074886619E-7,-6.30339309463598E-6,-8.35406093229024E-7,200.0121307,200.0121307,25273.55078125,25293.642578125,57.1042163579676,20.5625593739911,27.464817,0,0,0,40,4449,199.9495,25283.5966796875,,,,,,,,,,,,,0,,,,0,,,,,,200.0121307,,,,
,23185684.265,200.0117798,30178.599609375,-2.139151069979E-5,1.63259960817559E-6,1,0.999253354069792,40.0298881530762,1.99686177928049,16.2300001829863,-0.000239471768886633,-6.07472111094121E-5,0.25,-1.63890770241448E-6,-2.14636039839384E-5,-1.66758660727333E-6,200.0117798,200.0117798,30171.04296875,30186.15625,56.861911517006,20.5600457648177,27.464817,0,0,0,40,4449,199.9408,30178.599609375,,,,,,,,,,,,,0,,,,-0.0049,,,,,,200.0117798,,,,
,23185780.1,200.0105133,34968.7578125,-3.84797234699956E-5,1.84871963963611E-6,1,0.999253354069792,40.0298881530762,1.99678647222607,16.2300001829863,-0.000430140185603855,-0.000112804667194327,0.25,-3.25973841450837E-6,-3.86090909200041E-5,-3.31232818870862E-6,200.0105133,200.0105133,34963.765625,34973.75,56.9197520274291,20.5604306519071,27.085165,0,0,0,40,4449,199.9348,34968.7578125,,,,,,,,,,,,,0,,,,0.0049,,,,,,200.0105133,,,,
,23185878.49,200.01482395,39885.890625,-5.58520429736854E-5,1.85685494433796E-6,1,0.999253354069792,40.0298881530762,1.99688040515589,16.2300001829863,-0.000633381489215868,-0.000111809755731731,0.25,-1.54500023373019E-7,-5.60447407123573E-5,-2.14916125329949E-7,200.0147858,200.0148621,39875.91015625,39895.87109375,56.7735874943329,20.5598051285571,27.464817,0,0,0,40,4449,199.91975,39885.890625,,,,,,,,,,,,,0,,,,-0.0049,,,,,,200.01482395,,,,
,23185976.655,200.0085602,44794.26171875,-7.40854288806174E-5,1.64448657621149E-6,1,0.999253354069792,40.0298881530762,1.99703182626996,16.2300001829863,-0.000841238327852889,-0.000142433273120063,0.25,3.13876420823597E-7,-7.43416282621853E-5,2.35684996441453E-7,200.0085602,200.0085602,44789.21484375,44799.30859375,56.8462789466214,20.5608696432517,27.464817,0,0,0,40,4449,199.91345,44794.26171875,,,,,,,,,,,,,0,,,,0,,,,,,200.0085602,,,,
,23186074.725,200.0099487,49694.30859375,-9.08076646778001E-5,2.34836791807557E-6,1,0.999253354069792,40.0298881530762,1.99706184032586,16.2300001829863,-0.00102680128427514,-0.000199532650067085,0.25,-1.8140986744295E-6,-9.11193669658731E-5,-1.91734185840864E-6,200.0097656,200.0101318,49686.75,49701.8671875,56.8392442899483,20.5589485567016,27.085165,0,0,0,40,4449,199.9017,49694.30859375,,,,,,,,,,,,,0,,,,0.0049,,,,,,200.0099487,,,,
,23186170.95,200.0112457,54504.23828125,-0.000108322106982788,2.75707601514562E-6,1,0.999253354069792,40.0298881530762,1.99692827890183,16.2300001829863,-0.00123101339267763,-0.00020203419054754,0.25,1.00586114244571E-6,-0.000108697340522628,8.93884305164733E-7,200.0112457,200.0112457,54499.51171875,54508.96484375,56.9627415959868,20.5609739769852,27.085165,0,0,0,40,4449,199.8938,54504.23828125,,,,,,,,,,,,,0,,,,0.0049,,,,,,200.0112457,,,,
,23186268.1,200.0110321,59359.423828125,-0.00012419862192722,2.67132022750839E-6,1,0.999253354069792,40.0298881530762,1.99703540634508,16.2300001829863,-0.00139969193246105,-0.000299723486773714,0.25,-4.84571787860169E-6,-0.000124622509114313,-4.99456107888712E-6,200.0110321,200.0110321,59346.97265625,59371.875,56.9424192544868,20.5581828213242,27.085165,0,0,0,40,4449,199.88345,59359.423828125,,,,,,,,,,,,,0,,,,0,,,,,,200.0110321,,,,
,23186365.575,200.0128326,64234.736328125,-0.000147446231072773,2.25215791870544E-6,1,0.999253354069792,40.0298881530762,1.99671789511726,16.2300001829863,-0.0016796941507706,-0.000250638192691055,0.25,3.51395290031081E-6,-0.000147959348835672,3.36958628057067E-6,200.0128326,200.0128326,64224.89453125,64244.578125,56.7790588939676,20.5599960076475,27.085165,0,0,0,40,4449,199.87305,64234.736328125,,,,,,,,,,,,,0,,,,0.00245,,,,,,200.0128326,,,,
,23186463.165,200.0118408,69110.39453125,-0.00016340376521247,2.46490635795992E-6,1,0.999253354069792,40.0298881530762,1.99691816318341,16.2300001829863,-0.0018498353188355,-0.000345878131288404,0.25,-2.10711317455908E-6,-0.000163966108628197,-2.28747145477975E-6,200.0118408,200.0118408,69102.90625,69117.8828125,56.7454488676406,20.5568106380271,27.464817,0,0,0,40,4449,199.865,69110.39453125,,,,,,,,,,,,,0,,,,-0.00245,,,,,,200.0118408,,,,
,23186564.455,200.01454165,74172.80859375,-0.000183071041962781,3.17290336493373E-6,1,0.999253354069792,40.0298881530762,1.99695647650488,16.2300001829863,-0.00207258666295432,-0.000387131331834778,0.25,-2.32730898232245E-6,-0.000183701153779454,-2.52884127544279E-6,200.0137024,200.0153809,74165.2421875,74180.375,56.9338213407753,20.5569171073376,27.464817,0,0,0,40,4449,199.8466,74172.80859375,,,,,,,,,,,,,0,,,,0,,,,,,200.01454165,,,,
,23186664.055,200.0157776,79150.578125,-0.000198469581899382,3.44715230348645E-6,1,0.999253354069792,40.0298881530762,1.99703624907725,16.2300001829863,-0.0022598920845019,-0.000345490761875239,0.25,4.01751527433775E-6,-0.000199159655605304,3.82209363141639E-6,200.0157776,200.0157776,79138.0546875,79163.1015625,56.8032893780637,20.5559583545307,27.085165,0,0,0,40,4449,199.83625,79150.578125,,,,,,,,,,,,,0,,,,-0.00245,,,,,,200.0157776,,,,
,23186760.055,200.0079346,83948.98828125,-0.000216950475896578,3.10500842971681E-6,1,0.999253354069792,40.0298881530762,1.99684425110232,16.2300001829863,-0.00246135812755525,-0.000427973813190735,0.25,-4.63811934764593E-8,-0.000217700254644814,-2.74839529193906E-7,200.0079346,200.0079346,83936.3984375,83961.578125,56.7040225561214,20.5543309711045,27.464817,0,0,0,40,4449,199.83115,83948.98828125,,,,,,,,,,,,,0,,,,0,,,,,,200.0079346,,,,
,23186854.54,200.0137024,88672.3828125,-0.000234890735963407,3.11372888578871E-6,1,0.999253354069792,40.0298881530762,1.99717177088037,16.2300001829863,-0.00266400989635088,-0.00047093748565955,0.25,-7.11741593224303E-7,-0.00023570185182742,-9.6085341671879E-7,200.0137024,200.0137024,88669.9921875,88674.7734375,56.6469636742175,20.5533425788566,27.464817,0,0,0,40,4449,199.8206,88672.3828125,,,,,,,,,,,,,0,,,,0,,,,,,200.0137024,,,,
,23186965.125,200.0111694,86751.09375,-0.000226929291504329,3.01291159210945E-6,1,0.999253354069792,40.0298881530762,1.99708412877874,16.2300001829863,-0.00257564003465067,-0.000443250982870564,0.25,3.44193541695326E-7,-0.000227713985271065,1.06862283420728E-7,200.0111694,200.0111694,86748.84375,86753.34375,56.7509202672752,20.5534361281546,27.464817,0,0,0,40,4449,199.80925,86751.09375,,,,,,,,,,,,,0,,,,0,,,,,,200.0111694,,,,
,23187061.32,200.0009003,81943.015625,-0.000206701995769471,3.3817049478459E-6,1,0.999253354069792,40.0298881530762,1.99720647540863,16.2300001829863,-0.00234045983523192,-0.000436808943368383,0.25,-2.59792898859878E-6,-0.000207413681228059,-2.82464919360831E-6,200.0009003,200.0009003,81935.3203125,81950.7109375,56.8290831191983,20.5552867161502,27.085165,0,0,0,40,4449,199.81105,81943.015625,,,,,,,,,,,,,0,,,,-0.00245,,,,,,200.0009003,,,,
,23187159.245,199.9929657,77046.6328125,-0.000191432442308868,3.38316578380357E-6,1,0.999253354069792,40.0298881530762,1.99728401590088,16.2300001829863,-0.00217209960502205,-0.000378903255256656,0.25,-1.45046978218719E-7,-0.000192093921863115,-3.47647961592077E-7,199.9929657,199.9929657,77041.59375,77051.671875,56.506270540756,20.5551410545522,27.464817,0,0,0,40,4449,199.81795,77046.6328125,,,,,,,,,,,,,0,,,,-0.00245,,,,,,199.9929657,,,,
,23187254.805,199.9920654,72268.0390625,-0.000172352942300333,2.53699104462848E-6,1,0.999253354069792,40.0298881530762,1.99727756275048,16.2300001829863,-0.00195730413411494,-0.000331361449731645,0.25,7.31311464175536E-7,-0.000172949355172761,5.51494997323919E-7,199.9920654,199.9920654,72257.953125,72278.125,56.7618630665445,20.5555336982716,27.085165,0,0,0,40,4449,199.8244,72268.0390625,,,,,,,,,,,,,0,,,,0,,,,,,199.9920654,,,,
,23187352.195,199.9898529,67399.99609375,-0.000154374953316778,2.20209925841886E-6,1,0.999253354069792,40.0298881530762,1.99731704188282,16.2300001829863,-0.00174660006393707,-0.000334645887569638,0.25,-2.6793287115934E-6,-0.000154905582418933,-2.85225845086913E-6,199.9898529,199.9898529,67394.9609375,67405.03125,56.9361662263329,20.5543073622789,27.085165,0,0,0,40,4449,199.8335,67399.99609375,,,,,,,,,,,,,0,,,,0,,,,,,199.9898529,,,,
,23187449.605,199.990509,62532.68359375,-0.000137910877218185,2.42159911116763E-6,1,0.999253354069792,40.0298881530762,1.99716981536275,16.2300001829863,-0.00156795624759701,-0.000254359346480566,0.25,1.53497359067481E-6,-0.000138389036152671,1.39375690279652E-6,199.990509,199.990509,62528.15625,62537.2109375,56.8580033744099,20.5556865749654,27.464817,0,0,0,40,4449,199.8444,62532.68359375,,,,,,,,,,,,,0,,,,-0.0049,,,,,,199.990509,,,,
,23187546.5,199.98980715,57689.083984375,-0.000121321592182846,2.05760879839191E-6,1,0.999253354069792,40.0298881530762,1.99726369400651,16.2300001829863,-0.00137340571151442,-0.000258336691208873,0.25,-1.6952680011279E-6,-0.000121738957979807,-1.83028850370421E-6,199.9896698,199.9899445,57684.38671875,57693.78125,56.7485753817175,20.5558362868926,27.464817,0,0,0,40,4449,199.85055,57689.083984375,,,,,,,,,,,,,0,,,,0.00245,,,,,,199.98980715,,,,
,23187645.375,199.9882507,52746.267578125,-0.000104797157880562,2.00260962249073E-6,1,0.999253354069792,40.0298881530762,1.99715818616793,16.2300001829863,-0.00119262443289924,-0.00018662386479287,0.25,1.7538110822779E-6,-0.000105161079019772,1.64806946139463E-6,199.9882507,199.9882507,52741.4765625,52751.05859375,56.8978664288906,20.5553131159829,27.464817,0,0,0,40,4449,199.86125,52746.267578125,,,,,,,,,,,,,0,,,,0,,,,,,199.9882507,,,,
,23187741.15,199.9885941,47960.96484375,-8.68342761247438E-5,1.67162643918198E-6,1,0.999253354069792,40.0298881530762,1.9972181620954,16.2300001829863,-0.000990174012489019,-0.000143442088508564,0.25,2.44016317565866E-6,-8.71368494055752E-5,2.35577255398583E-6,199.988205,199.9889832,47953.3671875,47968.5625,56.7860935506406,20.5536580491312,27.464817,0,0,0,40,4449,199.86965,47960.96484375,,,,,,,,,,,,,0,,,,0,,,,,,199.9885941,,,,
,23187837.81,199.9863739,43128.623046875,-6.87409572431316E-5,1.53768636949136E-6,1,0.999253354069792,40.0298881530762,1.99714358548595,16.2300001829863,-0.000784531020229578,-0.000109497395200742,0.25,2.28896240987796E-6,-6.89808555203434E-5,2.22324802777752E-6,199.9863739,199.9863739,43121.06640625,43136.1796875,56.8345545188329,20.5575174430546,27.844467,0,0,0,40,4449,199.88295,43128.623046875,,,,,,,,,,,,,0,,,,0,,,,,,199.9863739,,,,
,23187936.1,199.9895935,38215.919921875,-4.92593714508823E-5,1.22886366703651E-6,1,0.999253354069792,40.0298881530762,1.99719537191869,16.2300001829863,-0.000560382833324329,-8.89535815203322E-5,0.25,7.16238962970002E-7,-4.94302728123569E-5,6.65853862847479E-7,199.9895935,199.9895935,38208.19921875,38223.640625,56.6360208749483,20.5590732461674,27.844467,0,0,0,40,4449,199.892,38215.919921875,,,,,,,,,,,,,0,,,,0.00245,,,,,,199.9895935,,,,
,23188032.23,199.99156185,33411.306640625,-3.22150338180012E-5,1.37367779901079E-6,1,0.999253354069792,40.0298881530762,1.99732663750848,16.2300001829863,-0.000365644621238731,-6.31404779243592E-5,0.25,3.12023163858476E-8,-3.23263205384266E-5,-3.32395019964759E-9,199.9913177,199.991806,33406.30859375,33416.3046875,56.8236117195637,20.5597938822566,27.844467,0,0,0,40,4449,199.8968,33411.306640625,,,,,,,,,,,,,0,,,,0.00245,,,,,,199.99156185,,,,
,23188130.3,199.9907837,28508.9482421875,-1.59234311657827E-5,1.22771668291169E-6,1,0.999253354069792,40.0298881530762,1.99732689453203,16.2300001829863,-0.000182912011068049,-1.86628394368297E-5,0.25,1.12105510732918E-6,-1.59796252834292E-5,1.10777598761457E-6,199.9907837,199.9907837,28503.87890625,28514.017578125,56.8173586914099,20.5592779704385,27.085165,0,0,0,40,4449,199.9082,28508.9482421875,,,,,,,,,,,,,0,,,,0,,,,,,199.9907837,,,,
,23188224.83,199.9881592,23786.1064453125,-6.78478669472098E-8,1.10745751138392E-6,1,0.999253354069792,40.0298881530762,1.99713006034451,16.2300001829863,-1.49621278639973E-6,4.04820719933711E-6,0.25,3.68544350443642E-7,-6.84797680273938E-8,3.69743736349791E-7,199.9881592,199.9881592,23776.11328125,23796.099609375,56.6438371601406,20.5615859089054,27.844467,0,0,0,40,4449,199.9167,23786.1064453125,,,,,,,,,,,,,0,,,,-0.0049,,,,,,199.9881592,,,,
,23188323.25,199.9909515,18868.8955078125,1.44363275156815E-5,8.56454749503022E-7,1,0.999253354069792,40.0298881530762,1.99720807885337,16.2300001829863,0.000162753372624988,3.45764206063599E-5,0.25,5.396495401659E-7,1.44855878766287E-5,5.57114316998957E-7,199.9909515,199.9909515,18864.20703125,18873.583984375,56.8931766577752,20.5605125810773,27.464817,0,0,0,40,4449,199.9305,18868.8955078125,,,,,,,,,,,,,0,,,,-0.0049,,,,,,199.9909515,,,,
,23188421.15,199.9871826,13974.0541992187,2.93240983780362E-5,6.33717041630621E-7,1,0.999253354069792,40.0298881530762,1.99724837528908,16.2300001829863,0.000332286268625265,6.05415577486413E-5,0.25,2.41868355452266E-7,2.94250782877041E-5,2.74446894113019E-7,199.9871826,199.9871826,13961.4990234375,13986.609375,56.8142321773329,20.5578783978662,27.085165,0,0,0,40,4449,199.93345,13974.0541992187,,,,,,,,,,,,,0,,,,0,,,,,,199.9871826,,,,
,23188516.165,199.9893799,9224.54931640625,3.95290535675675E-5,6.50574848978117E-7,1,0.999253354069792,40.0298881530762,1.9973361048595,16.2300001829863,0.000447118249413322,8.63589644200756E-5,0.25,7.44122128081946E-7,3.96647092294072E-5,7.89543764954068E-7,199.9888153,199.9899445,9219.8046875,9229.2939453125,56.7915649502752,20.5600700298721,27.844467,0,0,0,40,4449,199.94295,9224.54931640625,,,,,,,,,,,,,0,,,,0,,,,,,199.9893799,,,,
,23188612.67,199.9916687,4398.51513671875,4.72420838909649E-5,4.71057701908409E-7,1,0.999253354069792,40.0298881530762,1.9973766645486,16.2300001829863,0.000536337709018762,9.18915224907039E-5,0.25,-1.08248530886473E-7,4.74052767866755E-5,-5.73379457165092E-8,199.9916687,199.9916687,4391.14111328125,4405.88916015625,56.8673829166406,20.5601047682881,27.085165,0,0,0,40,4449,199.94605,4398.51513671875,,,,,,,,,,,,,0,,,,0.00245,,,,,,199.9916687,,,,
,23188702.215,199.9911499,-0.11417829990387,3.31660844935576E-5,3.825087547891E-7,1,0.999253354069792,40.0298881530762,1.99725304196444,16.2300001829863,0.000378232266935374,5.45988655091634E-5,0.25,-9.49268745342869E-7,3.32815978635889E-5,-9.16508020232034E-7,199.9911499,199.9911499,-0.121790185570717,-0.106566414237022,56.9291315696599,20.5574757357131,27.464817,0,0,0,40,4417,199.9519,-0.11417829990387,,,,,,,,,,,,,0,,,,-0.0049,,,,,,199.9911499,,,,