File: data/doubleLayers/dl_2-5/ppms/DD205_5/KoelnPPMS/DD205_5_HYST_100OE_50K.DAT
[Header]
; VSM Data File (default extension .dat)
; Copyright (c) 2003-2013, Quantum Design, Inc. All rights reserved.
TITLE,
FILEOPENTIME,23142680.66,09/26/2018,5:29 am
BYAPP,VSM,2.0,2.0
INFO,PPMS VSM Option Release 1.4.10 Build 1,APPNAME
INFO,Quantum Design Linear Motor Servo Controller,MOTOR_MODULE_NAME
INFO,3101-100 M1,MOTOR_HW_VERSION
INFO,MMC1014,MOTOR_SERIAL_NUMBER
INFO,SRV No X-over 01.03.11,MOTOR_SOFTWARE_VERSION
INFO,Quantum Design VSM Detection Module,VSM_MODULE_NAME
INFO,3101-150 F0,VSM_HW_VERSION
INFO,VSM707,VSM_SERIAL_NUMBER
INFO,VSM No X-over 01.02.05 May 20 2008 13:51:47,VSM_SOFTWARE_VERSION
INFO,704,PREAMP_SERIAL_NUMBER
INFO,822,COIL_SERIAL_NUMBER
INFO,0,MOMENT_UNITS
INFO,,SAMPLE_MATERIAL
INFO,,SAMPLE_COMMENT
INFO,,SAMPLE_MASS
INFO,,SAMPLE_VOLUME
INFO,,SAMPLE_MOLECULAR_WEIGHT
INFO,,SAMPLE_SIZE
INFO,,SAMPLE_SHAPE
DATATYPE,COMMENT,1
DATATYPE,TIME,2
STARTUPAXIS,X,2
STARTUPAXIS,Y1,5
[Data]
Comment,Time Stamp (sec),Temperature (K),Magnetic Field (Oe),Moment (emu),M. Std. Err. (emu),Transport Action,Averaging Time (sec),Frequency (Hz),Peak Amplitude (mm),Center Position (mm),Coil Signal' (mV),Coil Signal" (mV),Range (mV),M. Quad. Signal (emu),M. Raw' (emu),M. Raw" (emu),Min. Temperature (K),Max. Temperature (K),Min. Field (Oe),Max. Field (Oe),Mass (grams),Motor Lag (deg),Pressure (Torr),VSM Status (code),Motor Status (code),Measure Status (code),Measure Count,PPMS Status (code),System Temp. (K),System Field (Oe),Sample Position (deg),Bridge 1 Resistance (ohms),Bridge 1 Excitation (에),Bridge 2 Resistance (ohms),Bridge 2 Excitation (에),Bridge 3 Resistance (ohms),Bridge 3 Excitation (에),Bridge 4 Resistance (ohms),Bridge 4 Excitation (에),Signal 1 Vin (V),Signal 2 Vin (V),Digital Inputs (code),Drive 1 Iout (mA),Drive 1 Ipower (W),Drive 2 Iout (mA),Drive 2 Ipower (W),Pressure (),Map 20 (),Map 21 (),Map 22 (),Map 23 (),Map 24 (),Map 25 (),Map 26 (),Map 27 (),Map 28 (),Map 29 ()
,23142695.78,49.9637833,-0.106566414237022,,,2,,,,16.9999995976686,,,,,,,49.9637833,49.9637833,-0.106566414237022,-0.106566414237022,,,17.214239,,,,-99999999,4369,50.2237,-0.106566414237022,,,,,,,,,,,,,,,,,,,,,,,49.9637833,,,,
,23142858.955,50.00971225,4968.265625,6.09416913159626E-5,3.45095110033781E-7,1,0.999253354069792,40.0298881530762,1.98399230957089,16.9799998402596,0.000682395492463806,0.000131313931800846,0.25,7.17304559265524E-7,6.09180257229908E-5,1.17059701386118E-6,50.0095482,50.0098763,4960.96240234375,4975.56884765625,55.4682678672174,20.5944107567326,17.214239,0,0,0,40,4449,50.1832,4968.265625,,,,,,,,,,,,,0,,,,0.00245,,,,,,50.00971225,,,,
,23142955.335,50.0060501,9784.9462890625,5.04899303317742E-5,3.62273066625732E-7,1,0.999253354069792,40.0298881530762,1.98404261865194,16.9799998402596,0.000566463604748072,0.000103527535197685,0.25,1.22958819865467E-7,5.04857898117425E-5,4.9844595473974E-7,50.0060501,50.0060501,9777.4912109375,9792.4013671875,56.1029502248329,20.6011925641016,17.593889,0,0,0,40,4449,50.17875,9784.9462890625,,,,,,,,,,,,,0,,,,0.00245,,,,,,50.0060501,,,,
,23143053.1,50.0044975,14669.6669921875,4.0335894838428E-5,4.88628640805938E-7,1,0.999253354069792,40.0298881530762,1.98401410710547,16.9799998402596,0.000450682144543784,9.36575554266963E-5,0.25,1.07242938816317E-6,4.03357233763612E-5,1.37206753267823E-6,50.0044975,50.0044975,14659.822265625,14679.51171875,56.4718788859098,20.5974657326463,17.214239,0,0,0,40,4449,50.17415,14669.6669921875,,,,,,,,,,,,,0,,,,-0.00245,,,,,,50.0044975,,,,
,23143148.015,50.0039787,19412.1513671875,2.97081035024098E-5,5.31036061619178E-7,1,0.999253354069792,40.0298881530762,1.98398323035901,16.9799998402596,0.000334137579763718,5.72255640377015E-5,0.25,-2.57661660211046E-7,2.97234138275512E-5,-3.79143066604296E-8,50.0039787,50.0039787,19407.16015625,19417.142578125,56.4304525743906,20.6022068905113,17.973541,0,0,0,40,4449,50.1751,19412.1513671875,,,,,,,,,,,,,0,,,,0,,,,,,50.0039787,,,,
,23143244.75,50.003067,24249.8525390625,1.94916305441894E-5,5.67227293189011E-7,1,0.999253354069792,40.0298881530762,1.98415452313485,16.9799998402596,0.000220129917772661,3.29812617813594E-5,0.25,-5.75874587842159E-7,1.95098189854351E-5,-4.32668878235996E-7,50.003067,50.003067,24234.759765625,24264.9453125,56.1357786226406,20.5996046111752,17.973541,0,0,0,40,4449,50.17335,24249.8525390625,,,,,,,,,,,,,0,,,,-0.00245,,,,,,50.003067,,,,
,23143345.705,50.0032272,29294.9833984375,7.87936849928489E-6,4.97061054693974E-7,1,0.999253354069792,40.0298881530762,1.98408965929545,16.9799998402596,8.97052582619907E-5,9.46184611143679E-6,0.25,-5.77183241895273E-7,7.89138664325138E-6,-5.20043371173252E-7,50.0032272,50.0032272,29287.490234375,29302.4765625,55.964601976929,20.6024582488732,17.973541,0,0,0,40,4449,50.1692,29294.9833984375,,,,,,,,,,,,,0,,,,0,,,,,,50.0032272,,,,
,23143442.355,50.003006,34125.20703125,-2.73931842214639E-6,6.12236100139546E-7,1,0.999253354069792,40.0298881530762,1.98400803291004,16.9799998402596,-2.82791172028418E-5,-1.94745155496325E-5,0.25,-1.2394822440843E-6,-2.73372088515319E-6,-1.26095149986794E-6,50.003006,50.003006,34120.3515625,34130.0625,56.2123782175252,20.6015293935101,17.973541,0,0,0,40,4449,50.1701,34125.20703125,,,,,,,,,,,,,0,,,,0.00245,,,,,,50.003006,,,,
,23143539.085,50.0038185,38959.76171875,-1.27091409645464E-5,6.45991701733538E-7,1,0.999253354069792,40.0298881530762,1.98410126475608,16.9799998402596,-0.000137389434612992,-5.62419945524285E-5,0.25,-2.71489553923905E-6,-1.27086097471254E-5,-2.81064760730292E-6,50.0038185,50.0038185,38947.109375,38972.4140625,56.2553677860829,20.6030953803759,17.973541,0,0,0,40,4449,50.16485,38959.76171875,,,,,,,,,,,,,0,,,,0,,,,,,50.0038185,,,,
,23143636.62,50.0028954,43832.3671875,-2.42157893570435E-5,7.44676525496097E-7,1,0.999253354069792,40.0298881530762,1.9839761752537,16.9799998402596,-0.000268128249177615,-7.21937274970186E-5,0.25,-2.06297176206421E-6,-2.4243353528055E-5,-2.23963379674291E-6,50.0028954,50.0028954,43824.9296875,43839.8046875,56.597721077506,20.6040911787384,17.973541,0,0,0,40,4449,50.16515,43832.3671875,,,,,,,,,,,,,0,,,,0,,,,,,50.0028954,,,,
,23143734.295,50.0034065,48715.03515625,-3.56832813434626E-5,1.34286050699328E-6,1,0.999253354069792,40.0298881530762,1.98396227834859,16.9799998402596,-0.000392815608475041,-0.000119640047753026,0.25,-4.21916239260718E-6,-3.57243280083877E-5,-4.47991579825291E-6,50.0034065,50.0034065,48707.54296875,48722.52734375,56.0130629451213,20.604080233023,17.593889,0,0,0,40,4449,50.16115,48715.03515625,,,,,,,,,,,,,0,,,,0,,,,,,50.0034065,,,,
,23143828.5,50.0027313,53425.560546875,-4.64206322289214E-5,8.4729651697013E-7,1,0.999253354069792,40.0298881530762,1.9840207951772,16.9799998402596,-0.00051110779246167,-0.00015591074016908,0.25,-5.51284757740591E-6,-4.64846285851066E-5,-5.84977181710396E-6,50.0027313,50.0027313,53415.4296875,53435.69140625,56.1084216244675,20.6018836757528,17.973541,0,0,0,40,4449,50.15705,53425.560546875,,,,,,,,,,,,,0,,,,-0.00245,,,,,,50.0027313,,,,
,23143923.14,50.0038757,58155.837890625,-5.59782880726319E-5,1.01465440336534E-6,1,0.999253354069792,40.0298881530762,1.98401805954547,16.9799998402596,-0.000618330840292892,-0.000177747076827679,0.25,-5.7367592531995E-6,-5.60744060748753E-5,-6.13767723599394E-6,50.0038757,50.0038757,58148.2265625,58163.44921875,56.2483331294098,20.6030921155088,18.353191,0,0,0,40,4449,50.1575,58155.837890625,,,,,,,,,,,,,0,,,,-0.00245,,,,,,50.0038757,,,,
,23144019.64,50.0033188,62978.75,-6.61143794334757E-5,8.42097172220337E-7,1,0.999253354069792,40.0298881530762,1.98404822663372,16.9799998402596,-0.000733196659182102,-0.000194763284869928,0.25,-5.42947910076711E-6,-6.62516274716606E-5,-5.89506883256626E-6,50.0033188,50.0033188,62971.28125,62986.21875,56.3733936924867,20.5995980806468,18.732843,0,0,0,40,4449,50.1545,62978.75,,,,,,,,,,,,,0,,,,-0.00245,,,,,,50.0033188,,,,
,23144115.03,50.0046921,67746.70703125,-7.46578188023439E-5,1.09818957458425E-6,1,0.999253354069792,40.0298881530762,1.98404442340469,16.9799998402596,-0.000826170754817384,-0.000230783843166793,0.25,-7.09795329168897E-6,-7.48217370323729E-5,-7.62094075670488E-6,50.0046921,50.0046921,67744.0859375,67749.328125,56.3577611221021,20.5992863031852,18.353191,0,0,0,40,4449,50.1509,67746.70703125,,,,,,,,,,,,,0,,,,0.00245,,,,,,50.0046921,,,,
,23144209.44,50.00457575,72464.0546875,-8.56814422861128E-5,1.29443092647151E-6,1,0.999253354069792,40.0298881530762,1.98412126938378,16.9799998402596,-0.000949448796413809,-0.000258969848230751,0.25,-7.62546645566714E-6,-8.5889971920754E-5,-8.2177497632703E-6,50.0044785,50.004673,72451.609375,72476.5,56.1920558760252,20.5999361266587,18.732843,0,0,0,40,4449,50.14965,72464.0546875,,,,,,,,,,,,,0,,,,0,,,,,,50.00457575,,,,
,23144306.5,50.003685,77317.1953125,-9.68906724645486E-5,1.61770197473219E-6,1,0.999253354069792,40.0298881530762,1.98395034609381,16.9799998402596,-0.00107202358775469,-0.000302666340532309,0.25,-9.50138286387216E-6,-9.71394714421728E-5,-1.01662094328379E-5,50.003685,50.003685,77309.7109375,77324.6796875,56.0787197407367,20.5972438349556,17.973541,0,0,0,40,4449,50.1419,77317.1953125,,,,,,,,,,,,,0,,,,-0.00245,,,,,,50.003685,,,,
,23144404.39,50.0046654,82210.62890625,-0.000105231976443329,1.27817498334558E-6,1,0.999253354069792,40.0298881530762,1.98401181996232,16.9799998402596,-0.00116273511388906,-0.00033901128897608,0.25,-1.12370261999464E-5,-0.00010551606833045,-1.19535609176763E-5,50.0046654,50.0046654,82198.1875,82223.0703125,56.9525804252368,20.5999417713543,18.353191,0,0,0,40,4449,50.141,82210.62890625,,,,,,,,,,,,,0,,,,0,,,,,,50.0046654,,,,
,23144498.185,50.0017128,86898.51953125,-0.000114009975191723,1.10817974039762E-6,1,0.999253354069792,40.0298881530762,1.98423332871701,16.9799998402596,-0.00126099896811609,-0.000362242706594878,0.25,-1.17285643501942E-5,-0.000114340339955299,-1.24942513394894E-5,50.0017128,50.0017128,86891.0390625,86906,56.0294771440252,20.5975284378536,17.973541,0,0,0,40,4449,50.14205,86898.51953125,,,,,,,,,,,,,0,,,,0,,,,,,50.0017128,,,,
,23144607.625,50.001976,88677.515625,-0.000115015189334371,1.01066575897827E-6,1,0.999253354069792,40.0298881530762,1.98417246741007,16.9799998402596,-0.0012700794648291,-0.000377062496084241,0.25,-1.28668886270998E-5,-0.000115349148138798,-1.36395723153377E-5,50.001976,50.001976,88667.78125,88687.25,56.3624508932175,20.5988600699512,17.973541,0,0,0,40,4449,50.13545,88677.515625,,,,,,,,,,,,,0,,,,0,,,,,,50.001976,,,,
,23144699.21,50.0000458,84099.43359375,-0.00010269304322769,9.72341690132498E-7,1,0.999253354069792,40.0298881530762,1.98400352988312,16.9799998402596,-0.0011310041759491,-0.000351800342455855,0.25,-1.28292996855148E-5,-0.000102965597806875,-1.35317306553952E-5,50.0000458,50.0000458,84089.171875,84109.6953125,56.7579549239483,20.5995885856653,18.353191,0,0,0,40,4449,50.1408,84099.43359375,,,,,,,,,,,,,0,,,,0,,,,,,50.0000458,,,,
,23144796.1,50.0010471,79253,-9.07713843098632E-5,1.47395740510256E-6,1,0.999253354069792,40.0298881530762,1.98394875387845,16.9799998402596,-0.000998618306619784,-0.000315783770165661,0.25,-1.17648524057403E-5,-9.09926807377047E-5,-1.23941684957744E-5,50.0008888,50.0012054,79245.4765625,79260.5234375,56.1451581648713,20.6014465379687,18.353191,0,0,0,40,4449,50.1411,79253,,,,,,,,,,,,,0,,,,0,,,,,,50.0010471,,,,
,23144892.03,50.0001183,74459.55859375,-7.48824347977925E-5,1.43241651468181E-6,1,0.999253354069792,40.0298881530762,1.98413186059392,16.9799998402596,-0.000817319891297315,-0.000296225880297403,0.25,-1.28720225828665E-5,-7.50296443695456E-5,-1.34064978911694E-5,50.0001183,50.0001183,74452.125,74466.9921875,56.1834579623136,20.5972763272805,18.353191,0,0,0,40,4449,50.13905,74459.55859375,,,,,,,,,,,,,0,,,,-0.00245,,,,,,50.0001183,,,,
,23144985.945,50.0008621,69766.11328125,-6.447837252987E-5,1.27285889195724E-6,1,0.999253354069792,40.0298881530762,1.98404727466229,16.9799998402596,-0.000705073476321683,-0.000246759955768962,0.25,-1.03448836461124E-5,-6.45971324284083E-5,-1.08068755270918E-5,50.0008621,50.0008621,69758.625,69773.6015625,56.2264475308713,20.5994760166194,18.353191,0,0,0,40,4449,50.1387,69766.11328125,,,,,,,,,,,,,0,,,,0.0049,,,,,,50.0008621,,,,
,23145083.07,50.0002689,64910.693359375,-5.16713345887622E-5,1.11558280058211E-6,1,0.999253354069792,40.0298881530762,1.98417694463252,16.9799998402596,-0.000560969122983334,-0.000219843444041425,0.25,-1.0250591993301E-5,-5.1742055740739E-5,-1.06293137124414E-5,50.0002441,50.0002937,64905.7421875,64915.64453125,56.5852150211983,20.6021782101142,17.973541,0,0,0,40,4449,50.13595,64910.693359375,,,,,,,,,,,,,0,,,,-0.00245,,,,,,50.0002689,,,,
,23145181.07,49.9991379,60012.703125,-3.86151862912097E-5,1.29268245176556E-6,1,0.999253354069792,40.0298881530762,1.98410987380073,16.9799998402596,-0.000415138690563915,-0.000186390577022847,0.25,-9.62394882184086E-6,-3.86456826643902E-5,-9.91378083006536E-6,49.9991379,49.9991379,60007.734375,60017.671875,56.4609360866406,20.5987377279479,17.973541,0,0,0,40,4449,50.1373,60012.703125,,,,,,,,,,,,,0,,,,0,,,,,,49.9991379,,,,
,23145276.11,49.9999962,55262.041015625,-2.44687711121085E-5,1.16099233887299E-6,1,0.999253354069792,40.0298881530762,1.98420316685883,16.9799998402596,-0.000255661774097342,-0.000158943477520291,0.25,-9.72708361776447E-6,-2.44570761725123E-5,-9.91980710481022E-6,49.9999962,49.9999962,55254.3984375,55269.68359375,56.4836033136983,20.5998194917391,18.732843,0,0,0,40,4449,50.1381,55262.041015625,,,,,,,,,,,,,0,,,,0,,,,,,49.9999962,,,,
,23145371.11,49.9997406,50514.50390625,-1.44432852532598E-5,1.08438784587069E-6,1,0.999253354069792,40.0298881530762,1.9841116316142,16.9799998402596,-0.000148411110685513,-0.000107441889641528,0.25,-6.95365526362534E-6,-1.44241737776515E-5,-7.06979530006119E-6,49.9997406,49.9997406,50512.03125,50516.9765625,56.3819916061983,20.5989999828881,18.732843,0,0,0,40,4449,50.1379,50514.50390625,,,,,,,,,,,,,0,,,,-0.0049,,,,,,49.9997406,,,,
,23145465.19,50.0010605,45811.96875,-3.95232964112924E-6,6.87532633098954E-7,1,0.999253354069792,40.0298881530762,1.98408609440505,16.9799998402596,-2.80221974796297E-5,-9.9311207609966E-5,0.25,-8.11935782986697E-6,-3.9018037375663E-6,-8.16243603729667E-6,50.0010605,50.0010605,45809.5625,45814.375,56.1498479359867,20.6014506476691,18.732843,0,0,0,40,4449,50.1392,45811.96875,,,,,,,,,,,,,0,,,,0,,,,,,50.0010605,,,,
,23145559.97,50.0005493,41071.958984375,6.82845881373456E-6,5.55769254401938E-7,1,0.999253354069792,40.0298881530762,1.98418238939732,16.9799998402596,9.20246277983881E-5,-7.08812674387565E-5,0.25,-7.53274523148596E-6,6.89353492378897E-6,-7.49573388279092E-6,50.0005493,50.0005493,41066.9453125,41076.97265625,56.2514596434867,20.5994658070826,17.973541,0,0,0,40,4449,50.1372,41071.958984375,,,,,,,,,,,,,0,,,,0,,,,,,50.0005493,,,,
,23145654.38,50.0003929,36354.361328125,1.62536713797269E-5,5.08880962073611E-7,1,0.999253354069792,40.0298881530762,1.98425614948942,16.9799998402596,0.000195904250048575,-4.03329065813559E-5,0.25,-6.51408571223952E-6,1.63229544178697E-5,-6.40511921863463E-6,50.0003929,50.0003929,36344.42578125,36364.296875,56.3733936924867,20.6023242249185,18.353191,0,0,0,40,4449,50.13805,36354.361328125,,,,,,,,,,,,,0,,,,0.00245,,,,,,50.0003929,,,,
,23145751.065,50.0006218,31524.505859375,2.62806883110472E-5,5.89425029655073E-7,1,0.999253354069792,40.0298881530762,1.98418246262204,16.9799998402596,0.000305426860948306,-2.74642764984163E-6,0.25,-4.97749351954981E-6,2.63459855403035E-5,-4.79104504303404E-6,50.0006218,50.0006218,31521.78125,31527.23046875,56.384336491756,20.6021716355292,18.353191,0,0,0,40,4449,50.1387,31524.505859375,,,,,,,,,,,,,0,,,,0,,,,,,50.0006218,,,,
,23145846.035,50.0008392,26777.26171875,3.55052128766923E-5,4.61030189117007E-7,1,0.999253354069792,40.0298881530762,1.98432684944691,16.9799998402596,0.000407992980758193,2.16333249389948E-5,0.25,-4.47084965143761E-6,3.55680626563521E-5,-4.21370968298344E-6,50.0008392,50.0008392,26769.66796875,26784.85546875,56.5422254526406,20.6029321089528,18.353191,0,0,0,40,4449,50.1398,26777.26171875,,,,,,,,,,,,,0,,,,0,,,,,,50.0008392,,,,
,23145939.93,50.0001373,22081.4140625,4.32122226442929E-5,4.64668644412796E-7,1,0.999253354069792,40.0298881530762,1.98414469622357,16.9799998402596,0.000491228983599407,5.49412571613281E-5,0.25,-2.8948955099983E-6,4.32589871686198E-5,-2.57746621424447E-6,50.0001373,50.0001373,22076.390625,22086.4375,56.5375356815252,20.5999650201934,18.732843,0,0,0,40,4449,50.1383,22081.4140625,,,,,,,,,,,,,0,,,,-0.00245,,,,,,50.0001373,,,,
,23146032.9,50.0011597,17439.42578125,5.10288921607105E-5,3.9235095109295E-7,1,0.999253354069792,40.0298881530762,1.98429064254656,16.9799998402596,0.000578722152065644,7.18547871255313E-5,0.25,-2.79787189798138E-6,5.10665657952383E-5,-2.42055422761471E-6,50.0011597,50.0011597,17434.138671875,17444.712890625,56.1951823901021,20.6041323118972,18.353191,0,0,0,40,4449,50.13365,17439.42578125,,,,,,,,,,,,,0,,,,0,,,,,,50.0011597,,,,
,23146124.755,49.9997864,12846.3471679688,5.85849308720524E-5,3.84042644127625E-7,1,0.999253354069792,40.0298881530762,1.98425982590971,16.9799998402596,0.000661490103566197,9.77435779072775E-5,0.25,-1.85317734116336E-6,5.86036557284797E-5,-1.41803233767824E-6,49.9997864,49.9997864,12836.470703125,12856.2236328125,56.3218062102175,20.6023229305409,18.353191,0,0,0,40,4449,50.1371,12846.3471679688,,,,,,,,,,,,,0,,,,-0.0049,,,,,,49.9997864,,,,
,23146214.465,49.999752,8361.103515625,6.47810295373722E-5,3.48145749776691E-7,1,0.999253354069792,40.0298881530762,1.98435678106668,16.9799998402596,0.000729288416980643,0.000119303594766767,0.25,-1.04832901714582E-6,6.477919382459E-5,-5.66230680988735E-7,49.999752,49.999752,8348.5439453125,8373.6630859375,56.577398736006,20.6007998815689,18.732843,0,0,0,40,4449,50.13915,8361.103515625,,,,,,,,,,,,,0,,,,-0.00245,,,,,,49.999752,,,,
,23146310.335,50.0012054,3570.90637207031,7.01784898916138E-5,3.08720935051642E-7,1,0.999253354069792,40.0298881530762,1.98429271125933,16.9799998402596,0.000788407950465652,0.000137186489074046,0.25,-4.25157863255893E-7,7.01550829082122E-5,9.72401840355157E-8,50.0012054,50.0012054,3565.87939453125,3575.93334960937,56.6477453027368,20.6015522776429,18.353191,0,0,0,40,4449,50.1374,3570.90637207031,,,,,,,,,,,,,0,,,,0,,,,,,50.0012054,,,,
,23146403.905,50.0001831,-1105.83685302734,6.49925453738712E-5,3.54701352820844E-7,1,0.999253354069792,40.0298881530762,1.98430427182993,16.9799998402596,0.000728915836094181,0.000133485739050445,0.25,1.81013685752002E-7,6.49600812772203E-5,6.64484685498727E-7,50.0001831,50.0001831,-1115.74780273438,-1095.92590332031,56.2037803038136,20.6013348664671,18.732843,0,0,0,40,4449,50.1359,-1105.83685302734,,,,,,,,,,,,,0,,,,0.0049,,,,,,50.0001831,,,,
,23146497.255,50.0013618,-5769.240234375,6.49006067845605E-5,3.75797581789978E-7,1,0.999253354069792,40.0298881530762,1.98428629734776,16.9799998402596,0.000727144128275082,0.000138207549006337,0.25,6.16028084134013E-7,6.4877983212773E-5,1.09881833166397E-6,50.0013618,50.0013618,-5776.7548828125,-5761.7255859375,56.015407830679,20.6014509009889,18.732843,0,0,0,40,4449,50.13505,-5769.240234375,,,,,,,,,,,,,0,,,,0,,,,,,50.0013618,,,,
,23146594.005,50.0002327,-10605.1323242187,5.92696386928192E-5,3.92500409401798E-7,1,0.999253354069792,40.0298881530762,1.98436512195994,16.9799998402596,0.000661703485615672,0.000140334630164046,0.25,1.81746816862552E-6,5.92540752646917E-5,2.25813021889156E-6,50.0002022,50.0002632,-10610.1689453125,-10600.095703125,56.5938129349098,20.6017242480054,18.732843,0,0,0,40,4449,50.1346,-10605.1323242187,,,,,,,,,,,,,0,,,,0,,,,,,50.0002327,,,,
,23146690.53,50.000843,-15427.6748046875,4.03014629407061E-5,3.66955061510134E-7,1,0.999253354069792,40.0298881530762,1.98444537117154,16.9799998402596,0.000446967057808111,0.000112669911947377,0.25,2.76979799815314E-6,4.02898601313575E-5,3.06950440518598E-6,50.000843,50.000843,-15437.70703125,-15417.642578125,56.5813068786021,20.6020482981248,18.353191,0,0,0,40,4449,50.13265,-15427.6748046875,,,,,,,,,,,,,0,,,,0.0049,,,,,,50.000843,,,,
,23146786.515,50.0019531,-20227.3603515625,1.2175660119141E-5,6.50502342768821E-7,1,0.999253354069792,40.0298881530762,1.98441915779258,16.9799998402596,0.000130202988702054,6.10521922371386E-5,0.25,3.24123870530857E-6,1.21575822772957E-5,3.33287490299098E-6,50.0019531,50.0019531,-20240.02734375,-20214.693359375,56.3397836661598,20.6024118691976,18.732843,0,0,0,40,4449,50.13355,-20227.3603515625,,,,,,,,,,,,,0,,,,0,,,,,,50.0019531,,,,
,23146879.64,50.0005836,-24882.09375,-1.10605029912886E-5,4.54772641167014E-7,1,0.999253354069792,40.0298881530762,1.98461115216197,16.9799998402596,-0.000133502828890071,2.87917259296263E-5,0.25,4.55505019463582E-6,-1.11022308562239E-5,4.47696214917777E-6,50.0005836,50.0005836,-24892.12890625,-24872.05859375,56.2194128741983,20.6007252654461,18.353191,0,0,0,40,4449,50.1335,-24882.09375,,,,,,,,,,,,,0,,,,0,,,,,,50.0005836,,,,
,23146974.67,50.0011368,-29629.599609375,-2.15647647424992E-5,6.6968957691437E-7,1,0.999253354069792,40.0298881530762,1.9843240492295,16.9799998402596,-0.000252917317954382,1.5053141682259E-5,0.25,5.22372654536048E-6,-2.16245344784768E-5,5.07102836348348E-6,50.0011368,50.0011368,-29634.3828125,-29624.81640625,56.0490178570059,20.604291842356,18.732843,0,0,0,40,4449,50.13255,-29629.599609375,,,,,,,,,,,,,0,,,,0.0049,,,,,,50.0011368,,,,
,23147070.81,50.0011787,-34434.283203125,-2.34163345044299E-5,5.09614243964667E-7,1,0.999253354069792,40.0298881530762,1.98456655688312,16.9799998402596,-0.000277293959804085,3.05795172741612E-5,0.25,6.9365090562117E-6,-2.34961592587624E-5,6.77494541815272E-6,50.0011787,50.0011787,-34436.9375,-34431.62890625,56.4476484018137,20.6057409150809,18.353191,0,0,0,40,4449,50.1317,-34434.283203125,,,,,,,,,,,,,0,,,,-0.00245,,,,,,50.0011787,,,,
,23147167.765,50.002697,-39278.98828125,-2.12874921934396E-5,6.88243775674409E-7,1,0.999253354069792,40.0298881530762,1.98443181149137,16.9799998402596,-0.000256918170490988,5.4421940419609E-5,0.25,8.67166254661273E-6,-2.13821195561137E-5,8.53121396035315E-6,50.0025749,50.0028191,-39283.86328125,-39274.11328125,56.5453519667175,20.6021219297968,18.732843,0,0,0,40,4449,50.1268,-39278.98828125,,,,,,,,,,,,,0,,,,0,,,,,,50.002697,,,,
,23147263.89,50.0010452,-44083.85546875,-1.53435662220535E-5,4.48973068662389E-7,1,0.999253354069792,40.0298881530762,1.98445205269868,16.9799998402596,-0.000190385589669826,6.79273721053966E-5,0.25,8.80012729012319E-6,-1.5433332826944E-5,8.70592177936529E-6,50.0010452,50.0010452,-44091.55078125,-44076.16015625,56.7985996069483,20.6022386857854,18.732843,0,0,0,40,4449,50.13015,-44083.85546875,,,,,,,,,,,,,0,,,,-0.00245,,,,,,50.0010452,,,,
,23147361.02,50.0027657,-48938.828125,-1.11363071448213E-5,6.91379737553905E-7,1,0.999253354069792,40.0298881530762,1.98449896547582,16.9799998402596,-0.000148275833542502,0.000105272507578769,0.25,1.13599956132258E-5,-1.12388104949887E-5,1.13038742052903E-5,50.0027657,50.0027657,-48943.82421875,-48933.83203125,56.8376810329099,20.6045993793764,19.112494,0,0,0,40,4449,50.13005,-48938.828125,,,,,,,,,,,,,0,,,,-0.00245,,,,,,50.0027657,,,,
,23147459.205,50.0018044,-53848.67578125,-5.44191962707975E-6,4.64777023711153E-7,1,0.999253354069792,40.0298881530762,1.98452215409473,16.9799998402596,-8.51124802564548E-5,0.000121785120500873,0.25,1.18003133251685E-5,-5.53651122624557E-6,1.17885172745326E-5,50.0018044,50.0018044,-53856.4765625,-53840.875,56.6047557341791,20.6045903527264,18.353191,0,0,0,40,4449,50.1288,-53848.67578125,,,,,,,,,,,,,0,,,,0.00245,,,,,,50.0018044,,,,
,23147556.53,50.0020142,-58710.998046875,4.12214423612812E-7,5.61425662301587E-8,1,0.999253354069792,40.0298881530762,1.98457689409414,16.9799998402596,-2.4660362300669E-5,0.000163904290748143,0.25,1.44869383446531E-5,3.13178533514854E-7,1.45252020127198E-5,50.0020142,50.0020142,-58718.3984375,-58703.59765625,56.6352392464291,20.6042756251712,18.732843,0,0,0,40,4449,50.1236,-58710.998046875,,,,,,,,,,,,,0,,,,0,,,,,,50.0020142,,,,
,23147650.55,50.0017586,-63408.69921875,8.01332167511836E-6,9.71598019318143E-7,1,0.999253354069792,40.0298881530762,1.98454006456887,16.9799998402596,5.95099621023615E-5,0.000187200113884333,0.25,1.51880985603174E-5,7.93098181225653E-6,1.52829996314541E-5,50.0017586,50.0017586,-63421.4609375,-63395.9375,56.4195097751214,20.6044400653728,19.112494,0,0,0,40,4449,50.1249,-63408.69921875,,,,,,,,,,,,,0,,,,0.0049,,,,,,50.0017586,,,,
,23147748.06,50.0019989,-68280.26953125,1.50005907097781E-5,8.01726892505486E-7,1,0.999253354069792,40.0298881530762,1.98450310902266,16.9799998402596,0.000135024388300289,0.000219164998901961,0.25,1.67699269773671E-5,1.49305888205479E-5,1.6918696635325E-5,50.0019989,50.0019989,-68287.7265625,-68272.8125,56.6625962446021,20.6043503302802,18.732843,0,0,0,40,4449,50.1237,-68280.26953125,,,,,,,,,,,,,0,,,,0,,,,,,50.0019989,,,,
,23147844.735,50.0029221,-73112.33203125,2.04231351127556E-5,1.28414109522431E-6,1,0.999253354069792,40.0298881530762,1.98451056158883,16.9799998402596,0.000191215350962422,0.000257645197853909,0.25,1.92109221401218E-5,2.03579406170085E-5,1.9404906191426E-5,50.0029221,50.0029221,-73119.953125,-73104.7109375,56.6414922745829,20.6074261321648,18.732843,0,0,0,40,4449,50.1215,-73112.33203125,,,,,,,,,,,,,0,,,,-0.00245,,,,,,50.0029221,,,,
,23147939.095,50.0030899,-77829.5859375,2.63356423657845E-5,2.60453205698918E-6,1,0.999253354069792,40.0298881530762,1.9846215941522,16.9799998402596,0.000255411093530323,0.000283485412926482,0.25,2.04407726584842E-5,2.62869673605782E-5,2.06789010556068E-5,50.0030899,50.0030899,-77831.9296875,-77827.2421875,57.0440309619868,20.6041581285196,18.353191,0,0,0,40,4449,50.1204,-77829.5859375,,,,,,,,,,,,,0,,,,0.00245,,,,,,50.0030899,,,,
,23148037.07,50.0025635,-82726.58203125,3.26424907095972E-5,2.21382453518285E-6,1,0.999253354069792,40.0298881530762,1.98456123759747,16.9799998402596,0.000323804682315791,0.000311516184138287,0.25,2.17968563196405E-5,3.2613273226716E-5,2.20812097924079E-5,50.0025635,50.0025635,-82729.2265625,-82723.9375,56.5695824508137,20.6037285784251,18.732843,0,0,0,40,4449,50.1195,-82726.58203125,,,,,,,,,,,,,0,,,,0,,,,,,50.0025635,,,,
,23148130.365,50.0030785,-87386.21484375,4.05317309632864E-5,2.33306185594338E-6,1,0.999253354069792,40.0298881530762,1.98455089550572,16.9799998402596,0.000413893891691123,0.000321325388645452,0.25,2.12528489467052E-5,4.05414133310571E-5,2.15856725072787E-5,50.0030785,50.0030785,-87396.3046875,-87376.125,56.5328459104098,20.6026311470108,18.353191,0,0,0,40,4449,50.1147,-87386.21484375,,,,,,,,,,,,,0,,,,0,,,,,,50.0030785,,,,
,23148242.57,49.9996567,-88030.6484375,3.85158493430475E-5,2.16490731856493E-6,1,0.999253354069792,40.0298881530762,1.98441399974152,16.9799998402596,0.00038703501300446,0.000340283203005596,0.25,2.32978363894168E-5,3.8506528220048E-5,2.36251553172182E-5,49.9996567,49.9996567,-88038.265625,-88023.03125,56.1342153656021,20.6070624452376,18.353191,0,0,0,40,4449,50.1156,-88030.6484375,,,,,,,,,,,,,0,,,,0,,,,,,49.9996567,,,,
,23148336.48,50.0003395,-83336.078125,3.13168258056286E-5,1.90658503209599E-6,1,0.999253354069792,40.0298881530762,1.98442465743414,16.9799998402596,0.000307946185009577,0.00031390598011274,0.25,2.224807524966E-5,3.12811306035704E-5,2.25255157518786E-5,50.0003395,50.0003395,-83346.2578125,-83325.8984375,56.5531682519098,20.6074505128221,18.732843,0,0,0,40,4449,50.1169,-83336.078125,,,,,,,,,,,,,0,,,,0,,,,,,50.0003395,,,,
,23148434.86,49.9982147,-78421.6484375,2.20102183478169E-5,2.67787191242423E-6,1,0.999253354069792,40.0298881530762,1.98451369843001,16.9799998402596,0.00021238168588748,0.000242919153806539,0.25,1.76164557847188E-5,2.196673131089E-5,1.78173136100274E-5,49.9980888,49.9983406,-78424.0546875,-78419.2421875,56.364014150256,20.6062099195976,18.353191,0,0,0,40,4449,50.1157,-78421.6484375,,,,,,,,,,,,,0,,,,-0.00245,,,,,,49.9982147,,,,
,23148531.87,49.9994373,-73574.421875,1.08579530570505E-5,1.14072566422267E-6,1,0.999253354069792,40.0298881530762,1.98456878269917,16.9799998402596,7.87285121153719E-5,0.000264846640613181,0.25,2.1565225195897E-5,1.07483816551476E-5,2.17032195939845E-5,49.999382,49.9994926,-73581.8125,-73567.03125,56.3898078913906,20.6066745838229,18.732843,0,0,0,40,4449,50.11655,-73574.421875,,,,,,,,,,,,,0,,,,0,,,,,,49.9994373,,,,
,23148627.72,49.9992828,-68782.18359375,3.52781658147574E-6,3.7485873933788E-7,1,0.999253354069792,40.0298881530762,1.98449869917363,16.9799998402596,-8.48381360185992E-7,0.000233200322873949,0.25,2.00752141703772E-5,3.40309457021264E-6,2.0156601362703E-5,49.9992828,49.9992828,-68784.6015625,-68779.765625,56.5258112537367,20.604080139419,18.732843,0,0,0,40,4449,50.1181,-68782.18359375,,,,,,,,,,,,,0,,,,-0.00245,,,,,,49.9992828,,,,
,23148725.21,49.9994392,-63910.404296875,-4.4101374355664E-6,3.43778741260588E-7,1,0.999253354069792,40.0298881530762,1.98458636674046,16.9799998402596,-8.56501936705828E-5,0.000191527394266759,0.25,1.7802766328138E-5,-4.54316365994406E-6,1.78202848564503E-5,49.9994392,49.9994392,-63918.32421875,-63902.484375,56.3022654972367,20.6035164988143,18.353191,0,0,0,40,4449,50.12105,-63910.404296875,,,,,,,,,,,,,0,,,,-0.0049,,,,,,49.9994392,,,,
,23148821.99,49.9977989,-59072.927734375,-1.17176441022602E-5,5.7447854432157E-7,1,0.999253354069792,40.0298881530762,1.98469940211169,16.9799998402596,-0.00016729037509099,0.000173224913895301,0.25,1.74932218616655E-5,-1.18671663263777E-5,1.74554051414317E-5,49.9977989,49.9977989,-59080.27734375,-59065.578125,56.7696793517368,20.6040011688567,18.732843,0,0,0,40,4449,50.11735,-59072.927734375,,,,,,,,,,,,,0,,,,0,,,,,,49.9977989,,,,
,23148919.9,49.9986305,-54181.146484375,-1.86989231666473E-5,6.59534465909239E-7,1,0.999253354069792,40.0298881530762,1.98456520185383,16.9799998402596,-0.000238991777581459,0.000121031080469915,0.25,1.41160076850717E-5,-1.88393779208416E-5,1.40169862387387E-5,49.9986305,49.9986305,-54193.60546875,-54168.6875,56.9236601700253,20.6025659579012,19.112494,0,0,0,40,4449,50.12105,-54181.146484375,,,,,,,,,,,,,0,,,,0,,,,,,49.9986305,,,,
,23149015.315,49.9990997,-49411.052734375,-2.74357226704771E-5,7.62873266120707E-7,1,0.999253354069792,40.0298881530762,1.98469124211685,16.9799998402596,-0.000336548672711931,9.93156018541741E-5,0.25,1.37607911157035E-5,-2.75881532774864E-5,1.35946878039689E-5,49.9990997,49.9990997,-49415.6953125,-49406.41015625,56.4922012274098,20.6026117411127,19.112494,0,0,0,40,4449,50.1229,-49411.052734375,,,,,,,,,,,,,0,,,,0,,,,,,49.9990997,,,,
,23149110.56,49.9991722,-44651.759765625,-3.31450575663127E-5,7.56460442445339E-7,1,0.999253354069792,40.0298881530762,1.98463118962958,16.9799998402596,-0.000399951347243699,8.35982933311747E-5,0.25,1.339531842233E-5,-3.3299641558964E-5,1.31825987267221E-5,49.9991722,49.9991722,-44664.3984375,-44639.12109375,56.3225878387367,20.6013056548332,18.732843,0,0,0,40,4449,50.1229,-44651.759765625,,,,,,,,,,,,,0,,,,0.0049,,,,,,49.9991722,,,,
,23149205.18,49.9988632,-39923.88671875,-3.93040120906382E-5,5.8500261503185E-7,1,0.999253354069792,40.0298881530762,1.98452942014439,16.9799998402596,-0.000464102409995066,4.33063541469681E-5,0.25,1.09254694473725E-5,-3.94432235536755E-5,1.06591616660006E-5,49.9988632,49.9988632,-39926.17578125,-39921.59765625,56.2076884464098,20.6040040679864,19.112494,0,0,0,40,4449,50.1213,-39923.88671875,,,,,,,,,,,,,0,,,,0.0049,,,,,,49.9988632,,,,
,23149303.36,49.9990807,-35016.775390625,-4.65064540349524E-5,6.93966937392044E-7,1,0.999253354069792,40.0298881530762,1.98449244620175,16.9799998402596,-0.000541755239471589,1.09426610553833E-5,0.25,9.34720744751729E-6,-4.66340893812819E-5,9.02134632457387E-6,49.9990807,49.9990807,-35024.3984375,-35009.15234375,56.1568825926598,20.604000933227,18.353191,0,0,0,40,4449,50.1251,-35016.775390625,,,,,,,,,,,,,0,,,,0,,,,,,49.9990807,,,,
,23149400.36,49.9990807,-30169.5244140625,-5.12831508816987E-5,5.63335772039563E-7,1,0.999253354069792,40.0298881530762,1.98457506655943,16.9799998402596,-0.00059335392820115,-9.7046970024374E-6,0.25,8.37338680220981E-6,-5.1396974471267E-5,8.00669142796056E-6,49.9990807,49.9990807,-30176.9375,-30162.111328125,57.0237086204868,20.6049958999744,18.732843,0,0,0,40,4449,50.12295,-30169.5244140625,,,,,,,,,,,,,0,,,,0,,,,,,49.9990807,,,,
,23149492.865,49.9995308,-25544.609375,-5.72005899006778E-5,6.20254386487465E-7,1,0.999253354069792,40.0298881530762,1.98449862015992,16.9799998402596,-0.000657605363480671,-3.31829929968972E-5,0.25,7.35202948608445E-6,-5.72989324287313E-5,6.93673261646294E-6,49.9995308,49.9995308,-25554.982421875,-25534.236328125,56.1553193356213,20.6027830321872,18.732843,0,0,0,40,4449,50.1233,-25544.609375,,,,,,,,,,,,,0,,,,0.0049,,,,,,49.9995308,,,,
,23149587.37,49.9990883,-20822.6474609375,-6.20605364116841E-5,4.93012250410288E-7,1,0.999253354069792,40.0298881530762,1.98455689386977,16.9799998402596,-0.000708535109031957,-6.25294125207904E-5,0.25,5.61682944056627E-6,-6.213400007361E-5,5.16085320088587E-6,49.9990883,49.9990883,-20832.48828125,-20812.806640625,56.117019538179,20.6018398734362,18.732843,0,0,0,40,4449,50.1241,-20822.6474609375,,,,,,,,,,,,,0,,,,0.0049,,,,,,49.9990883,,,,
,23149683.69,49.99963,-16010.1650390625,-6.5675456989814E-5,4.25753314272239E-7,1,0.999253354069792,40.0298881530762,1.98464138335016,16.9799998402596,-0.000745238960628171,-9.0588256848108E-5,0.25,3.77048759101945E-6,-6.57200035421073E-5,3.28418985525833E-6,49.99963,49.99963,-16020.2744140625,-16000.0556640625,56.4077853473329,20.6021178698406,18.353191,0,0,0,40,4449,50.1277,-16010.1650390625,,,,,,,,,,,,,0,,,,-0.00245,,,,,,49.99963,,,,
,23149780.585,49.99939725,-11165.2895507813,-6.9108714347299E-5,3.75126134689847E-7,1,0.999253354069792,40.0298881530762,1.98446812507131,16.9799998402596,-0.000781025290442576,-0.000111394445245708,0.25,2.53451035093148E-6,-6.91269378533235E-5,2.02067291209672E-6,49.9993286,49.9994659,-11177.58984375,-11152.9892578125,56.4460851447752,20.6006853823275,18.353191,0,0,0,40,4449,50.122,-11165.2895507813,,,,,,,,,,,,,0,,,,0,,,,,,49.99939725,,,,
,23149874.195,49.999794,-6484.83129882813,-7.13018849702619E-5,3.09333227307724E-7,1,0.999253354069792,40.0298881530762,1.9844187113479,16.9799998402596,-0.000802545404979186,-0.000131856313351944,0.25,1.10481258873917E-6,-7.12926135139133E-5,5.73965387794389E-7,49.999794,49.999794,-6490.0693359375,-6479.59326171875,56.0474545999675,20.6026612407723,18.732843,0,0,0,40,4449,50.1287,-6484.83129882813,,,,,,,,,,,,,0,,,,0.0049,,,,,,49.999794,,,,
,23149968.04,50.00069045,-1795.79339599609,-7.2602190337856E-5,3.26452495683121E-7,1,0.999253354069792,40.0298881530762,1.98450244553086,16.9799998402596,-0.000814041122073897,-0.000150882660867411,0.25,-3.58148742935182E-7,-7.25663740054771E-5,-8.98190340382427E-7,50.000679,50.0007019,-1800.78674316406,-1790.80004882813,56.485948199256,20.6000739228599,19.112494,0,0,0,40,4449,50.1251,-1795.79339599609,,,,,,,,,,,,,0,,,,-0.00245,,,,,,50.00069045,,,,
,23150061.175,49.9996948,2854.26135253906,-6.1852300174838E-5,3.12386216938092E-7,1,0.999253354069792,40.0298881530762,1.98449570321311,16.9799998402596,-0.000690940891283036,-0.000142949706952801,0.25,-1.58843005506617E-6,-6.18148791582291E-5,-2.04802990715221E-6,49.9996948,49.9996948,2846.94921875,2861.57348632813,56.269437099429,20.600211437307,18.732843,0,0,0,40,4449,50.1239,2854.26135253906,,,,,,,,,,,,,0,,,,0,,,,,,49.9996948,,,,
,23150158.505,50.0001564,7721.57080078125,-5.72928221285144E-5,3.06368374011113E-7,1,0.999253354069792,40.0298881530762,1.98476511526182,16.9799998402596,-0.000636396283334596,-0.000153766993002854,0.25,-3.3693996820422E-6,-5.72571146826095E-5,-3.79505331008319E-6,50.0001564,50.0001564,7711.591796875,7731.5498046875,56.4023139476983,20.5998836251016,18.353191,0,0,0,40,4449,50.1238,7721.57080078125,,,,,,,,,,,,,0,,,,0,,,,,,50.0001564,,,,
,23150250.985,50.00035095,12342.0346679688,-4.43624778498873E-5,3.95121204770882E-7,1,0.999253354069792,40.0298881530762,1.98478356957412,16.9799998402596,-0.000488883130954875,-0.000141332951441575,0.25,-4.58987840512698E-6,-4.43307650613782E-5,-4.91982408718278E-6,50.0002632,50.0004387,12334.6943359375,12349.375,56.6751023009098,20.5969776270237,18.732843,0,0,0,40,4449,50.12475,12342.0346679688,,,,,,,,,,,,,0,,,,-0.00245,,,,,,50.00035095,,,,
,23150347.45,50.0001907,17164.58203125,-1.80055832469731E-5,6.5150435281693E-7,1,0.999253354069792,40.0298881530762,1.98463944518513,16.9799998402596,-0.000190489171042731,-0.000101621399914277,0.25,-5.80271381400088E-6,-1.79682242834508E-5,-5.93803051503277E-6,50.0001907,50.0001907,17152.177734375,17176.986328125,56.323369467256,20.5990542155466,19.112494,0,0,0,40,4449,50.12505,17164.58203125,,,,,,,,,,,,,0,,,,-0.0049,,,,,,50.0001907,,,,
,23150439.29,50.0004082,21754.625,1.12662717754431E-5,3.61370088840973E-7,1,0.999253354069792,40.0298881530762,1.98472806028444,16.9799998402596,0.000141475797966442,-5.98689866286082E-5,0.25,-7.35879280470291E-6,1.13270132966341E-5,-7.27972442814726E-6,50.0004082,50.0004082,21744.84765625,21764.40234375,56.5039256551983,20.599717691679,19.112494,0,0,0,40,4449,50.125,21754.625,,,,,,,,,,,,,0,,,,-0.00245,,,,,,50.0004082,,,,
,23150533.265,50.0008163,26452.23046875,3.35526695270664E-5,4.59995659522113E-7,1,0.999253354069792,40.0298881530762,1.98462385714815,16.9799998402596,0.000393916345737487,-2.56996960612212E-5,0.25,-8.33150382107595E-6,3.36415417206388E-5,-8.09167835241296E-6,50.0008163,50.0008163,26442.3125,26462.1484375,55.9575673202559,20.5975633748786,19.112494,0,0,0,40,4449,50.12425,26452.23046875,,,,,,,,,,,,,0,,,,-0.00245,,,,,,50.0008163,,,,
,23150630.915,50.0013275,31335.544921875,4.42791382259293E-5,5.68439610628055E-7,1,0.999253354069792,40.0298881530762,1.98473304065877,16.9799998402596,0.000518326750981291,-2.46037880673219E-5,0.25,-1.01634584181518E-5,4.44015267512411E-5,-9.85100802999743E-6,50.0013275,50.0013275,31330.42578125,31340.6640625,56.0927890540829,20.5986232252317,18.353191,0,0,0,40,4449,50.1213,31335.544921875,,,,,,,,,,,,,0,,,,-0.0049,,,,,,50.0013275,,,,
,23150725.75,50.0015373,36073.009765625,4.76420709949012E-5,5.94791073843539E-7,1,0.999253354069792,40.0298881530762,1.98459484324905,16.9799998402596,0.00055915622119807,-3.40700647105191E-5,0.25,-1.16079256486719E-5,4.77900761931422E-5,-1.12779543144391E-5,50.0015373,50.0015373,36068.0625,36077.95703125,56.2678738423906,20.5946887286691,18.732843,0,0,0,40,4449,50.1233,36073.009765625,,,,,,,,,,,,,0,,,,-0.0049,,,,,,50.0015373,,,,
,23150822.335,50.0017662,40900.697265625,4.64247939815327E-5,7.30103983811647E-7,1,0.999253354069792,40.0298881530762,1.9846351611878,16.9799998402596,0.000550400655914953,-6.3174108976882E-5,0.25,-1.39726807449754E-5,4.65990555203304E-5,-1.36610785417411E-5,50.0017662,50.0017662,40890.73828125,40910.65625,56.2756901275829,20.5984903867235,18.732843,0,0,0,40,4449,50.12085,40900.697265625,,,,,,,,,,,,,0,,,,0,,,,,,50.0017662,,,,
,23150917.985,50.0022354,45681.0078125,4.39180112238548E-5,6.75748765216676E-7,1,0.999253354069792,40.0298881530762,1.98462354052502,16.9799998402596,0.000525070163224718,-8.35597069607493E-5,0.25,-1.5329138050048E-5,4.4107512497585E-5,-1.50443811634823E-5,50.0022354,50.0022354,45673.55859375,45688.45703125,56.6579064734868,20.5957487515792,18.353191,0,0,0,40,4449,50.1145,45681.0078125,,,,,,,,,,,,,0,,,,0,,,,,,50.0022354,,,,
,23151013.645,50.00045965,50461.126953125,4.03043299418931E-5,9.17541115825742E-7,1,0.999253354069792,40.0298881530762,1.98461920849267,16.9799998402596,0.000487898260107145,-0.000109695718144003,0.25,-1.69967738614024E-5,4.05072703607563E-5,-1.6747823472934E-5,50.0003357,50.0005836,50451.17578125,50471.078125,56.9932251082368,20.5954648611361,18.353191,0,0,0,40,4449,50.1236,50461.126953125,,,,,,,,,,,,,0,,,,-0.00245,,,,,,50.00045965,,,,
,23151110.975,50.0001068,55328.6171875,3.72456805484393E-5,6.49012880364905E-7,1,0.999253354069792,40.0298881530762,1.98465120378832,16.9799998402596,0.000459128342433596,-0.000146806006510015,0.25,-1.97383030854358E-5,3.74684977167962E-5,-1.95240853559517E-5,50.0001068,50.0001068,55323.99609375,55333.23828125,56.4539014299675,20.5958585647963,18.732843,0,0,0,40,4449,50.12,55328.6171875,,,,,,,,,,,,,0,,,,0.0049,,,,,,50.0001068,,,,
,23151205.805,50.000309,60066.1796875,3.34471864454405E-5,7.52451770972997E-7,1,0.999253354069792,40.0298881530762,1.98463828899522,16.9799998402596,0.000419538438853251,-0.00017175353834716,0.25,-2.1265816742896E-5,3.36772913683167E-5,-2.10889041595951E-5,50.000309,50.000309,60061.375,60070.984375,56.3679222928521,20.5930758750109,18.732843,0,0,0,40,4449,50.1201,60066.1796875,,,,,,,,,,,,,0,,,,0.00245,,,,,,50.000309,,,,
,23151302,50.0024986,64874.3359375,2.79975243593982E-5,8.41758519086499E-7,1,0.999253354069792,40.0298881530762,1.98463334264427,16.9799998402596,0.000363208682289174,-0.000210483745716572,0.25,-2.37204421824241E-5,2.82345719167387E-5,-2.35946032289717E-5,50.0024986,50.0024986,64869.4609375,64879.2109375,55.761378561929,20.5921185080764,18.732843,0,0,0,40,4449,50.1212,64874.3359375,,,,,,,,,,,,,0,,,,0,,,,,,50.0024986,,,,
,23151396.14,50.0026932,69579.8125,2.47319566909403E-5,8.19464820591768E-7,1,0.999253354069792,40.0298881530762,1.98472668234324,16.9799998402596,0.000332414259316012,-0.000250141823059907,0.25,-2.66481519965453E-5,2.49824301270155E-5,-2.65598407801371E-5,50.0026932,50.0026932,69572.453125,69587.171875,56.4867298277752,20.5985065546783,18.732843,0,0,0,40,4449,50.12,69579.8125,,,,,,,,,,,,,0,,,,0.00245,,,,,,50.0026932,,,,
,23151492.835,50.00235935,74412.3828125,1.94018084694311E-5,7.87044206526362E-7,1,0.999253354069792,40.0298881530762,1.98473070625514,16.9799998402596,0.000275079428102806,-0.00027588043192106,0.25,-2.79698455526182E-5,1.96466755618722E-5,-2.79282444341448E-5,50.0023193,50.0023994,74404.984375,74419.78125,56.6141352764098,20.5959298734931,18.353191,0,0,0,40,4449,50.1126,74412.3828125,,,,,,,,,,,,,0,,,,-0.0049,,,,,,50.00235935,,,,
,23151587.505,50.0018883,79145.4921875,1.78822373056432E-5,6.22917194467984E-7,1,0.999253354069792,40.0298881530762,1.98447642124341,16.9799998402596,0.000266178446434936,-0.000324899536659788,0.25,-3.20448350122329E-5,1.8149452574432E-5,-3.20333109920718E-5,50.0018883,50.0018883,79138.015625,79152.96875,56.2850696698137,20.591851865025,18.353191,0,0,0,40,4449,50.114,79145.4921875,,,,,,,,,,,,,0,,,,0,,,,,,50.0018883,,,,
,23151683.25,50.0027962,83931.5234375,1.23138949270742E-5,4.62889995287767E-7,1,0.999253354069792,40.0298881530762,1.98477578760255,16.9799998402596,0.000203634769405843,-0.000337153613094981,0.25,-3.21231260285621E-5,1.25623553260469E-5,-3.21548369181978E-5,50.0027962,50.0027962,83921.40625,83941.640625,56.2241026453136,20.5948048291591,19.112494,0,0,0,40,4449,50.11425,83931.5234375,,,,,,,,,,,,,0,,,,0.0049,,,,,,50.0027962,,,,
,23151777.9,50.0023346,88662.203125,9.28508810494799E-6,3.52005197742499E-7,1,0.999253354069792,40.0298881530762,1.98473781633645,16.9799998402596,0.00017857972258599,-0.000394088704247317,0.25,-3.66260312470854E-5,9.54991855072402E-6,-3.66994795383582E-5,50.0023346,50.0023346,88654.921875,88669.484375,56.6571248449675,20.5929833924857,18.732843,0,0,0,40,4449,50.10835,88662.203125,,,,,,,,,,,,,0,,,,0.00245,,,,,,50.0023346,,,,
,23151889.05,50.0004005,86811.1171875,1.27349013084227E-5,4.43446238322168E-7,1,0.999253354069792,40.0298881530762,1.98473488500683,16.9799998402596,0.000213576022970186,-0.000365377607522476,0.25,-3.46993036637159E-5,1.30005405638788E-5,-3.47413747894068E-5,50.0004005,50.0004005,86798.5390625,86823.6953125,56.2350454445829,20.5967889212537,19.112494,0,0,0,40,4449,50.11045,86811.1171875,,,,,,,,,,,,,0,,,,0,,,,,,50.0004005,,,,
,23151983.68,49.9988594,82082.24609375,1.7048479046296E-5,4.90517916244838E-7,1,0.999253354069792,40.0298881530762,1.98471927623586,16.9799998402596,0.000259085194871875,-0.000339296227557263,0.25,-3.31651957440169E-5,1.73200853900131E-5,-3.31672980887964E-5,49.9988594,49.9988594,82069.640625,82094.8515625,56.2334821875444,20.5915099505775,19.112494,0,0,0,40,4449,50.1101,82082.24609375,,,,,,,,,,,,,0,,,,-0.0049,,,,,,49.9988594,,,,
,23152077.795,49.9993019,77376.38671875,2.35164588620716E-5,6.47742363108564E-7,1,0.999253354069792,40.0298881530762,1.98465308866791,16.9799998402596,0.000327905747841353,-0.000303669595721729,0.25,-3.1170971782198E-5,2.37960033953721E-5,-3.11169877435976E-5,49.9992027,49.9994011,77371.5234375,77381.25,56.6493085597752,20.5950348060325,18.353191,0,0,0,40,4449,50.10965,77376.38671875,,,,,,,,,,,,,0,,,,0,,,,,,49.9993019,,,,
,23152173.895,49.9994526,72570.60546875,2.64745862320858E-5,8.7876007480338E-7,1,0.999253354069792,40.0298881530762,1.98439120927414,16.9799998402596,0.000353536903853692,-0.000255134094697981,0.25,-2.74032911777978E-5,2.6736717890723E-5,-2.73102839495204E-5,49.9993553,49.9995499,72563.3125,72577.8984375,56.6203883045637,20.5962049956688,18.732843,0,0,0,40,4449,50.1145,72570.60546875,,,,,,,,,,,,,0,,,,-0.00245,,,,,,49.9994526,,,,
,23152267.555,49.9988976,67892.3828125,3.19455356985111E-5,8.49352597270967E-7,1,0.999253354069792,40.0298881530762,1.984369645207,16.9799998402596,0.000415956977353057,-0.00024880238713247,0.25,-2.78303762163008E-5,3.22236001791313E-5,-2.76941677200263E-5,49.9988976,49.9988976,67884.8125,67899.953125,56.6711941583137,20.596749689285,18.353191,0,0,0,40,4449,50.115,67892.3828125,,,,,,,,,,,,,0,,,,0,,,,,,49.9988976,,,,
,23152366.06,49.9978523,62969.62890625,3.79068146622977E-5,1.23641634474019E-6,1,0.999253354069792,40.0298881530762,1.98439835477706,16.9799998402596,0.000474770793840068,-0.000190783089337781,0.25,-2.37549812171082E-5,3.81687161765168E-5,-2.35586037743396E-5,49.9978523,49.9978523,62962.109375,62977.1484375,56.6141352764098,20.5968518269445,18.732843,0,0,0,40,4449,50.11415,62969.62890625,,,,,,,,,,,,,0,,,,-0.00245,,,,,,49.9978523,,,,
,23152462.19,49.9976425,58164.166015625,4.04255194236389E-5,7.55723106565625E-7,1,0.999253354069792,40.0298881530762,1.98441257314442,16.9799998402596,0.000502017085032284,-0.000179915861516043,0.25,-2.32492120562684E-5,4.06841073712355E-5,-2.30258717535025E-5,49.9976425,49.9976425,58154.06640625,58174.265625,55.9739815191598,20.596603784054,19.112494,0,0,0,40,4449,50.11655,58164.166015625,,,,,,,,,,,,,0,,,,0.00245,,,,,,49.9976425,,,,
,23152556.635,49.9979172,53440.84375,4.63286385576653E-5,7.55830822246953E-7,1,0.999253354069792,40.0298881530762,1.98443118717807,16.9799998402596,0.000564991533235485,-0.00014918705923703,0.25,-2.15866566172543E-5,4.65817794473434E-5,-2.13100177524224E-5,49.9979172,49.9979172,53435.89453125,53445.79296875,56.3007022401983,20.6002056220327,18.353191,0,0,0,40,4449,50.11905,53440.84375,,,,,,,,,,,,,0,,,,0,,,,,,49.9979172,,,,
,23152650.515,49.99882505,48748.390625,5.12768537300142E-5,6.87127812877206E-7,1,0.999253354069792,40.0298881530762,1.98449248585843,16.9799998402596,0.000617708098331111,-0.000123224585456723,0.25,-2.01754034617772E-5,5.15211310330818E-5,-1.9852593460918E-5,49.9987068,49.9989433,48738.75390625,48758.02734375,56.5258112537367,20.5969022592687,18.353191,0,0,0,40,4449,50.11975,48748.390625,,,,,,,,,,,,,0,,,,0,,,,,,49.99882505,,,,
,23152745.24,49.9987144,44015.22265625,5.43472461573916E-5,8.97665937591053E-7,1,0.999253354069792,40.0298881530762,1.98449004584339,16.9799998402596,0.000647070676746102,-8.89442497353237E-5,0.25,-1.76866694651085E-5,5.45685835875395E-5,-1.73291702635663E-5,49.9987144,49.9987144,44004.94921875,44025.49609375,56.2733452420252,20.5969691793892,19.112494,0,0,0,40,4449,50.11905,44015.22265625,,,,,,,,,,,,,0,,,,-0.0049,,,,,,49.9987144,,,,
,23152839.89,49.9985657,39285.3984375,5.92325511861339E-5,7.7270047673296E-7,1,0.999253354069792,40.0298881530762,1.98452993205577,16.9799998402596,0.000699368575337554,-6.50989533404796E-5,0.25,-1.64510998969176E-5,5.94404480037118E-5,-1.60487072605994E-5,49.9985657,49.9985657,39277.796875,39293,56.4179465180829,20.5973820556215,18.732843,0,0,0,40,4449,50.12225,39285.3984375,,,,,,,,,,,,,0,,,,-0.00245,,,,,,49.9985657,,,,
,23152934.45,49.998909,34558.484375,6.22853209705071E-5,6.00183412572772E-7,1,0.999253354069792,40.0298881530762,1.98453498329829,16.9799998402596,0.000728388076938537,-3.03558948973721E-5,0.25,-1.39155264226365E-5,6.24648928024344E-5,-1.34801925527182E-5,49.998909,49.998909,34556.1796875,34560.7890625,56.4421770021791,20.5982298896956,18.732843,0,0,0,40,4449,50.1192,34558.484375,,,,,,,,,,,,,0,,,,-0.0049,,,,,,49.998909,,,,
,23153029.595,49.9987526,29803.298828125,6.50561025487235E-5,4.78809938541191E-7,1,0.999253354069792,40.0298881530762,1.98458123792821,16.9799998402596,0.000754417128020413,2.75760018655163E-6,0.25,-1.14724394187406E-5,6.52054264821232E-5,-1.10076531406306E-5,49.9987526,49.9987526,29793.515625,29813.08203125,56.188147733429,20.5988677665359,18.353191,0,0,0,40,4449,50.12,29803.298828125,,,,,,,,,,,,,0,,,,-0.0049,,,,,,49.9987526,,,,
,23153125.145,49.9998894,25027.7255859375,6.84025467984675E-5,4.51181589941822E-7,1,0.999253354069792,40.0298881530762,1.98450747129777,16.9799998402596,0.000789343141544815,2.31794434664798E-5,0.25,-1.0260713100871E-5,6.85290870196128E-5,-9.76465195196907E-6,49.9998894,49.9998894,25020.103515625,25035.34765625,56.4648442292367,20.5988556621824,18.732843,0,0,0,40,4449,50.12445,25027.7255859375,,,,,,,,,,,,,0,,,,-0.00245,,,,,,49.9998894,,,,
,23153221.155,49.9979095,20227.869140625,7.0709899715426E-5,4.97147825895725E-7,1,0.999253354069792,40.0298881530762,1.98470229011754,16.9799998402596,0.00081157943765324,4.75735415002396E-5,0.25,-8.50720487144265E-6,7.0806868594376E-5,-7.98821890874051E-6,49.9979095,49.9979095,20222.830078125,20232.908203125,56.4359239740252,20.5997142308643,18.732843,0,0,0,40,4449,50.122,20227.869140625,,,,,,,,,,,,,0,,,,0.00245,,,,,,49.9979095,,,,
,23153314.015,49.9993019,15588.3388671875,7.22044653981045E-5,4.65245810566259E-7,1,0.999253354069792,40.0298881530762,1.98466264710335,16.9799998402596,0.000821887995013738,8.53053001241391E-5,0.25,-5.41760304258976E-6,7.2261040190573E-5,-4.88300156215551E-6,49.9993019,49.9993019,15585.634765625,15591.04296875,56.7900016932368,20.5979311213886,18.732843,0,0,0,40,4449,50.1182,15588.3388671875,,,,,,,,,,,,,0,,,,-0.0049,,,,,,49.9993019,,,,
,23153410.625,49.9984283,10758.5815429688,7.42465961581975E-5,4.17842868401414E-7,1,0.999253354069792,40.0298881530762,1.98453633905362,16.9799998402596,0.000842229480872077,0.000102311294995734,0.25,-4.26978651408124E-6,7.42760168998478E-5,-3.71756950213733E-6,49.9984283,49.9984283,10748.6669921875,10768.49609375,56.3577611221021,20.5957903754733,18.732843,0,0,0,40,4449,50.1185,10758.5815429688,,,,,,,,,,,,,0,,,,-0.0049,,,,,,49.9984283,,,,
,23153506.205,49.9985847,5983.12329101562,7.46717193398118E-5,3.1489032895879E-7,1,0.999253354069792,40.0298881530762,1.98463113294085,16.9799998402596,0.000842795611440075,0.000125580007834914,0.25,-2.27229086394441E-6,7.46683782497351E-5,-1.71600449071507E-6,49.9985847,49.9985847,5975.45458984375,5990.7919921875,56.7204367550252,20.6010176526837,18.732843,0,0,0,40,4449,50.12375,5983.12329101562,,,,,,,,,,,,,0,,,,-0.00245,,,,,,49.9985847,,,,
,23153600.63,50.0014191,1262.11248779297,7.32807673842819E-5,3.35823777039324E-7,1,0.999253354069792,40.0298881530762,1.98469878036215,16.9799998402596,0.000823702162760208,0.00014125589422217,0.25,-6.22908615411923E-7,7.3250466927364E-5,-7.7384906951723E-8,50.0014191,50.0014191,1252.04943847656,1272.17553710938,56.4335790884675,20.5952284551429,19.112494,0,0,0,40,4449,50.125,1262.11248779297,,,,,,,,,,,,,0,,,,0,,,,,,50.0014191,,,,
,23153627.275,50.0006943,-0.42626565694809,6.89194190359938E-5,2.87907646220099E-7,1,0.999253354069792,40.0298881530762,1.98466290288108,16.9799998402596,0.000774001204948979,0.000136362520534419,0.25,-2.72055836411004E-7,6.8885937777976E-5,2.40801837840824E-7,50.0006943,50.0006943,-0.42626565694809,-0.42626565694809,56.1764233056406,20.5970018666573,18.353191,0,0,0,40,4417,50.12435,-0.42626565694809,,,,,,,,,,,,,0,,,,0,,,,,,50.0006943,,,,