File: data/doubleLayers/dl_2-5/ppms/DD205_5/KoelnPPMS/DD205_5_ZFCW_100OE.DAT
[Header]
; VSM Data File (default extension .dat)
; Copyright (c) 2003-2013, Quantum Design, Inc. All rights reserved.
TITLE,
FILEOPENTIME,23086802.42,09/25/2018,1:58 pm
BYAPP,VSM,2.0,2.0
INFO,PPMS VSM Option Release 1.4.10 Build 1,APPNAME
INFO,Quantum Design Linear Motor Servo Controller,MOTOR_MODULE_NAME
INFO,3101-100 M1,MOTOR_HW_VERSION
INFO,MMC1014,MOTOR_SERIAL_NUMBER
INFO,SRV No X-over 01.03.11,MOTOR_SOFTWARE_VERSION
INFO,Quantum Design VSM Detection Module,VSM_MODULE_NAME
INFO,3101-150 F0,VSM_HW_VERSION
INFO,VSM707,VSM_SERIAL_NUMBER
INFO,VSM No X-over 01.02.05 May 20 2008 13:51:47,VSM_SOFTWARE_VERSION
INFO,704,PREAMP_SERIAL_NUMBER
INFO,822,COIL_SERIAL_NUMBER
INFO,0,MOMENT_UNITS
INFO,,SAMPLE_MATERIAL
INFO,,SAMPLE_COMMENT
INFO,,SAMPLE_MASS
INFO,,SAMPLE_VOLUME
INFO,,SAMPLE_MOLECULAR_WEIGHT
INFO,,SAMPLE_SIZE
INFO,,SAMPLE_SHAPE
DATATYPE,COMMENT,1
DATATYPE,TIME,2
STARTUPAXIS,X,2
STARTUPAXIS,Y1,5
[Data]
Comment,Time Stamp (sec),Temperature (K),Magnetic Field (Oe),Moment (emu),M. Std. Err. (emu),Transport Action,Averaging Time (sec),Frequency (Hz),Peak Amplitude (mm),Center Position (mm),Coil Signal' (mV),Coil Signal" (mV),Range (mV),M. Quad. Signal (emu),M. Raw' (emu),M. Raw" (emu),Min. Temperature (K),Max. Temperature (K),Min. Field (Oe),Max. Field (Oe),Mass (grams),Motor Lag (deg),Pressure (Torr),VSM Status (code),Motor Status (code),Measure Status (code),Measure Count,PPMS Status (code),System Temp. (K),System Field (Oe),Sample Position (deg),Bridge 1 Resistance (ohms),Bridge 1 Excitation (에),Bridge 2 Resistance (ohms),Bridge 2 Excitation (에),Bridge 3 Resistance (ohms),Bridge 3 Excitation (에),Bridge 4 Resistance (ohms),Bridge 4 Excitation (에),Signal 1 Vin (V),Signal 2 Vin (V),Digital Inputs (code),Drive 1 Iout (mA),Drive 1 Ipower (W),Drive 2 Iout (mA),Drive 2 Ipower (W),Pressure (),Map 20 (),Map 21 (),Map 22 (),Map 23 (),Map 24 (),Map 25 (),Map 26 (),Map 27 (),Map 28 (),Map 29 ()
,23091529.09,10.0016727,99.4721298217773,,,2,,,,16.709999717772,,,,,,,10.0016727,10.0016727,99.4721298217773,99.4721298217773,,,13.417728,,,,-99999999,4373,10.0004,99.4721298217773,,,,,,,,,,,,,,,,,,,,,,,10.0016727,,,,
,23091737.415,12.5868945,99.4721298217773,4.8795470235017E-7,2.91759157062885E-7,1,0.999253354069792,40.0298881530762,1.99815036521862,16.6999995708466,6.20125697590116E-6,-3.05822497216324E-6,0.25,-3.58702820238923E-7,4.86880389699953E-7,-3.54288053860055E-7,12.5555668,12.6182222,99.4721298217773,99.4721298217773,55.8559556127559,20.5447874644633,13.797379,0,0,0,40,4370,12.72635,99.4721298217773,,,,,,,,,,,,,0,,,,0,,,,,,12.5868945,,,,
,23091876.715,16.0505028,99.4721298217773,3.45518028511601E-7,3.26084880047311E-7,1,0.999253354069792,40.0298881530762,1.99821314777245,16.6999995708466,4.84270488729885E-6,-4.70834196163466E-6,0.25,-4.80191954529973E-7,3.45845038903786E-7,-4.75761568127675E-7,16.0505028,16.0505028,99.4721298217773,99.4721298217773,56.4359239740252,20.5452662947462,14.177031,0,0,0,40,4370,16.2344,99.4721298217773,,,,,,,,,,,,,0,,,,-0.00245,,,,,,16.0505028,,,,
,23092017.2,19.5434895,99.4721298217773,1.19661030475212E-7,2.6210022562997E-7,1,0.999253354069792,40.0298881530762,1.99804696675857,16.6999995708466,2.12185492182384E-6,-4.13499011411942E-6,0.25,-3.89112937570766E-7,1.20857783857914E-7,-3.86295829955278E-7,19.5434895,19.5434895,99.4721298217773,99.4721298217773,56.4038772047367,20.5514569038607,15.315984,0,0,0,40,4370,19.7597,99.4721298217773,,,,,,,,,,,,,0,,,,0.0049,,,,,,19.5434895,,,,
,23092157.735,23.0335217,99.4721298217773,2.27222892156506E-7,2.49248749485877E-7,1,0.999253354069792,40.0298881530762,1.99808796022316,16.7100001126528,3.40128643556642E-6,-4.3114892165748E-6,0.25,-4.23911500690695E-7,2.28041518995508E-7,-4.20384275293859E-7,23.0335217,23.0335217,99.4721298217773,99.4721298217773,56.4882930848137,20.5490904710691,15.695635,0,0,0,40,4370,23.3022,99.4721298217773,,,,,,,,,,,,,0,,,,0.00245,,,,,,23.0335217,,,,
,23092302,26.5533466,99.4721298217773,3.59525732245318E-7,2.79669379866018E-7,1,0.999253354069792,40.0298881530762,1.99800185299395,16.7100001126528,5.48536217847314E-6,-7.39008135595338E-6,0.25,-7.21288693323443E-7,3.61315331252179E-7,-7.15482929057544E-7,26.5533466,26.5533466,99.4721298217773,99.4721298217773,56.2436433582944,20.5545012092804,15.695635,0,0,0,40,4370,26.9546,99.4721298217773,,,,,,,,,,,,,0,,,,0.00245,,,,,,26.5533466,,,,
,23092441.695,30.031086,99.4721298217773,2.91096195618112E-7,2.96080678118201E-7,1,0.999253354069792,40.0298881530762,1.99797578351259,16.7100001126528,4.42813874086244E-6,-5.89108322201046E-6,0.25,-5.75748657006081E-7,2.92786634771981E-7,-5.71182934970639E-7,30.031086,30.031086,99.4721298217773,99.4721298217773,56.381209977679,20.5539874459112,16.454937,0,0,0,40,4370,30.4782,99.4721298217773,,,,,,,,,,,,,0,,,,0,,,,,,30.031086,,,,
,23092584.02,33.5507545,99.4721298217773,5.27424750468127E-7,2.70813334556331E-7,1,0.999253354069792,40.0298881530762,1.99801533030737,16.7299993336201,6.55087604096238E-6,-2.39094674303645E-6,0.25,-3.06786258324685E-7,5.26799985954388E-7,-3.02221649225569E-7,33.5507545,33.5507545,99.4721298217773,99.4721298217773,56.811105663256,20.5563496984419,16.834587,0,0,0,40,4370,34.0798,99.4721298217773,,,,,,,,,,,,,0,,,,0,,,,,,33.5507545,,,,
,23092726.835,37.0524368,99.4721298217773,2.19896675500468E-7,2.53277682320298E-7,1,0.999253354069792,40.0298881530762,1.99767269423515,16.7299993336201,2.71168222587407E-6,-8.76723252784401E-7,0.25,-1.17301302230756E-7,2.19774055565593E-7,-1.15424036774576E-7,37.0524368,37.0524368,99.4721298217773,99.4721298217773,56.6735390438714,20.5667250166427,17.593889,0,0,0,40,4370,37.6886,99.4721298217773,,,,,,,,,,,,,0,,,,0.0049,,,,,,37.0524368,,,,
,23092868.71,40.5499611,99.4721298217773,3.92265295419822E-7,2.34545570153463E-7,1,0.999253354069792,40.0298881530762,1.99765259710086,16.7299993336201,4.7071174224962E-6,-8.12322176146056E-7,0.25,-1.42592110979852E-7,3.92012976792991E-7,-1.39456558886664E-7,40.5499611,40.5499611,99.4721298217773,99.4721298217773,56.6446187886598,20.566921210464,17.593889,0,0,0,40,4370,41.2752,99.4721298217773,,,,,,,,,,,,,0,,,,0,,,,,,40.5499611,,,,
,23093012.69,44.0871029,99.4721298217773,4.60063045838343E-7,2.87663471102145E-7,1,0.999253354069792,40.0298881530762,1.99736933584507,16.7100001126528,5.7505717497541E-6,-2.19946932615565E-6,0.25,-2.77924151278337E-7,4.61094156783829E-7,-2.74019868534463E-7,44.0569344,44.1172714,99.4721298217773,99.4721298217773,56.6031924771406,20.5669531705768,17.973541,0,0,0,40,4374,44.9277,99.4721298217773,,,,,,,,,,,,,0,,,,-0.00245,,,,,,44.0871029,,,,
,23093152.995,47.5048351,99.4721298217773,3.43786379106853E-7,2.7397320478633E-7,1,0.999253354069792,40.0298881530762,1.99724795467381,16.7100001126528,4.63833617560428E-6,-3.51082393855203E-6,0.25,-3.73066137061418E-7,3.46201582667505E-7,-3.70141373628032E-7,47.4701538,47.5395164,99.4721298217773,99.4721298217773,56.6172617904868,20.5676314692076,18.732843,0,0,0,40,4374,48.50515,99.4721298217773,,,,,,,,,,,,,0,,,,-0.00245,,,,,,47.5048351,,,,
,23093300.03,51.0566635,99.4721298217773,3.45681922472456E-7,2.69459584694169E-7,1,0.999253354069792,40.0298881530762,1.99738037411109,16.7100001126528,4.48753387960794E-6,-2.52345964265576E-6,0.25,-2.85637406726379E-7,3.47861777615805E-7,-2.83120023281107E-7,51.0566635,51.0566635,99.4721298217773,99.4721298217773,56.7110572127945,20.5699772544088,18.353191,0,0,0,40,4374,52.2801,99.4721298217773,,,,,,,,,,,,,0,,,,0,,,,,,51.0566635,,,,
,23093443.71,54.5493927,99.4721298217773,2.15216371313018E-7,2.68895307976221E-7,1,0.999253354069792,40.0298881530762,1.99752277963149,16.7100001126528,2.35208709216364E-6,8.96917923361846E-7,0.25,4.05358928187388E-8,2.15196708803247E-7,4.21489410816413E-8,54.5493927,54.5493927,99.4721298217773,99.4721298217773,56.5101786833521,20.5682782028497,20.251448,0,0,0,40,4374,55.9919,99.4721298217773,,,,,,,,,,,,,0,,,,-0.0049,,,,,,54.5493927,,,,
,23093588.915,58.0291061,99.4721298217773,3.12439506346678E-7,2.70913950666526E-7,1,0.999253354069792,40.0298881530762,1.99753120805732,16.7100001126528,4.06765977555161E-6,-2.31024457096926E-6,0.25,-2.60154872281548E-7,3.14952401836353E-7,-2.5857657253377E-7,58.0008926,58.0573196,99.4721298217773,99.4721298217773,56.5109603118714,20.5684358302713,21.01075,0,0,0,40,4374,59.7417,99.4721298217773,,,,,,,,,,,,,0,,,,0,,,,,,58.0291061,,,,
,23093731.675,61.5307999,99.4721298217773,1.86990791539965E-7,2.5923806769469E-7,1,0.999253354069792,40.0298881530762,1.99755346539999,16.7100001126528,2.80034771240345E-6,-3.41752165970228E-6,0.25,-3.35042736617946E-7,1.89757778880127E-7,-3.34849770912538E-7,61.5307999,61.5307999,99.4721298217773,99.4721298217773,56.6227331901214,20.5697283257605,21.01075,0,0,0,40,4374,63.376,99.4721298217773,,,,,,,,,,,,,0,,,,0,,,,,,61.5307999,,,,
,23093853.73,64.5279007,99.4721298217773,2.58737148567036E-7,2.74097182074433E-7,1,0.999253354069792,40.0298881530762,1.9973935307415,16.6999995708466,3.37785804557812E-6,-1.95422827855921E-6,0.25,-2.18610497187837E-7,2.61029570416883E-7,-2.17810656274416E-7,64.5279007,64.5279007,99.4721298217773,99.4721298217773,56.679010443506,20.5648702509705,21.3904,0,0,0,40,4374,66.4671,99.4721298217773,,,,,,,,,,,,,0,,,,-0.0049,,,,,,64.5279007,,,,
,23093996.875,68.0425568,99.4721298217773,1.3425196734742E-7,2.64580483545574E-7,1,0.999253354069792,40.0298881530762,1.99726326227473,16.6999995708466,1.20198370886517E-6,2.07281125730385E-6,0.25,1.58715054867029E-7,1.33905606007802E-7,1.60148730266186E-7,68.0425568,68.0425568,99.4721298217773,99.4721298217773,56.7735874943329,20.5696874867116,21.01075,0,0,0,40,4374,70.1104,99.4721298217773,,,,,,,,,,,,,0,,,,-0.00245,,,,,,68.0425568,,,,
,23094139.01,71.5276947,99.4721298217773,3.02208272057333E-7,2.96994337341139E-7,1,0.999253354069792,40.0298881530762,1.99728405858221,16.6999995708466,4.12499268548185E-6,-3.28829988637957E-6,0.25,-3.434414541836E-7,3.05420768337237E-7,-3.43424990689073E-7,71.5276947,71.5276947,99.4721298217773,99.4721298217773,56.6876083572175,20.5688536236505,22.149702,0,0,0,40,4374,73.7396,99.4721298217773,,,,,,,,,,,,,0,,,,-0.00245,,,,,,71.5276947,,,,
,23094261.63,74.5163803,99.4721298217773,3.7192480377321E-7,2.28694415775208E-7,1,0.999253354069792,40.0298881530762,1.99736412592122,16.6900008916855,4.67342357645545E-6,-1.77934867980931E-6,0.25,-2.2274523520184E-7,3.74847376420061E-7,-2.21994989839318E-7,74.5163803,74.5163803,99.4721298217773,99.4721298217773,56.6977695279675,20.5648415640375,22.149702,0,0,0,40,4374,76.84565,99.4721298217773,,,,,,,,,,,,,0,,,,0,,,,,,74.5163803,,,,
,23094406.845,78.0768356,99.4721298217773,4.44205480261717E-7,3.07041464924921E-7,1,0.999253354069792,40.0298881530762,1.99744443090832,16.6900008916855,5.13910391667051E-6,3.73466509272329E-7,0.25,-4.58681502328546E-8,4.46703674326229E-7,-4.40752653824459E-8,78.0768356,78.0768356,99.4721298217773,99.4721298217773,56.6813553290637,20.5674378246875,21.770052,0,0,0,40,4374,80.5278,99.4721298217773,,,,,,,,,,,,,0,,,,0.00245,,,,,,78.0768356,,,,
,23094546.535,81.5429077,99.4721298217773,3.67472739258501E-7,3.10597870209059E-7,1,0.999253354069792,40.0298881530762,1.99739258226499,16.6900008916855,4.52092455360749E-6,-1.21168462909979E-6,0.25,-1.71641652662478E-7,3.7016069680603E-7,-1.7099982968615E-7,81.5429077,81.5429077,99.4721298217773,99.4721298217773,56.6328943608714,20.5681949522809,21.770052,0,0,0,40,4374,84.04545,99.4721298217773,,,,,,,,,,,,,0,,,,0,,,,,,81.5429077,,,,
,23094685.58,85.0266037,99.4721298217773,3.31146525893936E-7,2.91278716029714E-7,1,0.999253354069792,40.0298881530762,1.99740845559498,16.669999808073,4.4894017306081E-6,-3.44382536808545E-6,0.25,-3.61482765362104E-7,3.34382008876271E-7,-3.62154837695181E-7,85.0266037,85.0266037,99.4721298217773,99.4721298217773,56.4585912010829,20.5624580277952,22.529354,0,0,0,40,4374,87.5673,99.4721298217773,,,,,,,,,,,,,0,,,,-0.00245,,,,,,85.0266037,,,,
,23094827.905,88.5492096,99.4721298217773,3.97002750195903E-7,2.7002137702505E-7,1,0.999253354069792,40.0298881530762,1.99737739024706,16.669999808073,5.62243885412356E-6,-5.496654820373E-6,0.25,-5.53554264890463E-7,4.01242988847992E-7,-5.5517923859551E-7,88.5492096,88.5492096,99.4721298217773,99.4721298217773,56.6000659630637,20.5653105768444,22.149702,0,0,0,40,4374,91.1529,99.4721298217773,,,,,,,,,,,,,0,,,,0,,,,,,88.5492096,,,,
,23094970.64,92.006279,99.4721298217773,2.94496758526123E-7,2.9723757965457E-7,1,0.999253354069792,40.0298881530762,1.99737018466178,16.669999808073,3.88050247447202E-6,-2.43466981803222E-6,0.25,-2.66013974946626E-7,2.97065960488713E-7,-2.66505404482399E-7,92.006279,92.006279,99.4721298217773,99.4721298217773,56.7368509539291,20.5641463328744,22.909004,0,0,0,40,4374,94.7881,99.4721298217773,,,,,,,,,,,,,0,,,,-0.00245,,,,,,92.006279,,,,
,23095093.64,95.0149918,99.4721298217773,5.86394126797029E-7,2.41975294470409E-7,1,0.999253354069792,40.0298881530762,1.99741107893523,16.6400000452995,7.29168128241114E-6,-2.37880538827312E-6,0.25,-3.1236280883826E-7,5.90728027704065E-7,-3.12241805348349E-7,95.0149918,95.0149918,99.4721298217773,99.4721298217773,56.3733936924867,20.5625320609359,22.529354,0,0,0,40,4374,97.93545,99.4721298217773,,,,,,,,,,,,,0,,,,0,,,,,,95.0149918,,,,
,23095237.69,98.5574951,99.4721298217773,5.21674106485688E-7,2.48834171923712E-7,1,0.999253354069792,40.0298881530762,1.99745436529227,16.6400000452995,6.54885149876312E-6,-2.47116275395613E-6,0.25,-3.08977899459763E-7,5.25578987366691E-7,-3.09158836938942E-7,98.5574951,98.5574951,99.4721298217773,99.4721298217773,56.5899047923137,20.563914266401,22.909004,0,0,0,40,4374,101.5837,99.4721298217773,,,,,,,,,,,,,0,,,,0,,,,,,98.5574951,,,,
,23095377.575,102.0117493,99.4721298217773,9.18332992783352E-7,2.43581237624627E-7,1,0.999253354069792,40.0298881530762,1.99742836902354,16.6400000452995,1.1153400826958E-5,-2.22071063562643E-6,0.25,-3.56464555682292E-7,9.24580498427547E-7,-3.55879151031644E-7,102.0117493,102.0117493,99.4721298217773,99.4721298217773,56.7220000120637,20.565947092308,23.288654,0,0,0,40,4374,105.1226,99.4721298217773,,,,,,,,,,,,,0,,,,-0.0049,,,,,,102.0117493,,,,
,23095500.305,105.0442505,99.4721298217773,4.45015190052249E-7,2.89451446346973E-7,1,0.999253354069792,40.0298881530762,1.9973848229335,16.6200008243322,5.52600670162489E-6,-1.76967705887945E-6,0.25,-2.33670197951106E-7,4.48179770279708E-7,-2.33793879749574E-7,105.0442505,105.0442505,99.4721298217773,99.4721298217773,56.4327974599483,20.5631140805204,22.529354,0,0,0,40,4374,108.2134,99.4721298217773,,,,,,,,,,,,,0,,,,0,,,,,,105.0442505,,,,
,23095639.83,108.5297394,99.4721298217773,6.27580192169381E-7,2.65328614470084E-7,1,0.999253354069792,40.0298881530762,1.99746090299231,16.6200008243322,7.35030278010964E-6,2.86281187446873E-8,0.25,-1.07437107568523E-7,6.31412181141276E-7,-1.06436282053322E-7,108.5297394,108.5297394,99.4721298217773,99.4721298217773,56.8400259184676,20.5665848732397,23.288654,0,0,0,40,4374,111.7149,99.4721298217773,,,,,,,,,,,,,0,,,,0.00245,,,,,,108.5297394,,,,
,23095778.98,112.0041122,99.4721298217773,5.7553368514615E-8,2.76322124411505E-7,1,0.999253354069792,40.0298881530762,1.99754302052219,16.6200008243322,1.67785207742423E-6,-5.73101254346034E-6,0.25,-5.14059854217568E-7,5.91289179008366E-8,-5.16816701486311E-7,112.0041122,112.0041122,99.4721298217773,99.4721298217773,56.7352876968906,20.5642676923924,23.288654,0,0,0,40,4374,115.2171,99.4721298217773,,,,,,,,,,,,,0,,,,-0.0049,,,,,,112.0041122,,,,
,23095921.235,115.5551834,99.4721298217773,8.2347573469944E-7,2.96909467030262E-7,1,0.999253354069792,40.0298881530762,1.99748025765597,16.5899991989136,9.76297426755232E-6,-6.4460929932968E-7,0.25,-2.00753566688871E-7,8.28546802271098E-7,-1.99972062845752E-7,115.5551834,115.5551834,99.4721298217773,99.4721298217773,56.7649895806214,20.5631973868457,22.909004,0,0,0,40,4374,118.78355,99.4721298217773,,,,,,,,,,,,,0,,,,-0.0049,,,,,,115.5551834,,,,
,23096061.47,119.0449066,99.4721298217773,8.51982057557394E-7,2.52616536556721E-7,1,0.999253354069792,40.0298881530762,1.99742101227777,16.5899991989136,1.02453153609706E-5,-1.49855137778082E-6,0.25,-2.80752390911313E-7,8.57326411173472E-7,-2.80431894112568E-7,119.0449066,119.0449066,99.4721298217773,99.4721298217773,56.6258597041983,20.5664554115801,23.668306,0,0,0,40,4374,122.3035,99.4721298217773,,,,,,,,,,,,,0,,,,-0.00245,,,,,,119.0449066,,,,
,23096203.72,122.5419312,99.4721298217773,5.62662440606915E-7,3.00041667205699E-7,1,0.999253354069792,40.0298881530762,1.99731226851019,16.5899991989136,7.0891645304001E-6,-2.84343604779861E-6,0.25,-3.48414676052843E-7,5.6648566011355E-7,-3.49145208030561E-7,122.5419312,122.5419312,99.4721298217773,99.4721298217773,56.6164801619675,20.5666396905751,23.288654,0,0,0,40,4374,125.87965,99.4721298217773,,,,,,,,,,,,,0,,,,-0.0049,,,,,,122.5419312,,,,
,23096343.895,126.0396881,99.4721298217773,5.67692840752863E-7,2.57094617565534E-7,1,0.999253354069792,40.0298881530762,1.9974034306974,16.550000756979,6.47104323827959E-6,1.03075341840415E-6,0.25,-8.47854600563534E-9,5.70794030355715E-7,-7.38273258557468E-9,126.0396881,126.0396881,99.4721298217773,99.4721298217773,56.4156016325252,20.5682553204494,23.288654,0,0,0,40,4374,129.41435,99.4721298217773,,,,,,,,,,,,,0,,,,-0.0049,,,,,,126.0396881,,,,
,23096485.405,129.5373383,99.4721298217773,3.16434874725168E-7,2.50146633994479E-7,1,0.999253354069792,40.0298881530762,1.99731500198376,16.550000756979,3.71601588710675E-6,-5.23439772832897E-8,0.25,-5.98385251166448E-8,3.18248765278627E-7,-5.95499661393805E-8,129.5373383,129.5373383,99.4721298217773,99.4721298217773,56.709493955756,20.5623314505262,23.668306,0,0,0,40,4374,132.9698,99.4721298217773,,,,,,,,,,,,,0,,,,-0.0049,,,,,,129.5373383,,,,
,23096625.055,133.0339813,99.4721298217773,8.81338475837328E-7,3.1707483145235E-7,1,0.999253354069792,40.0298881530762,1.99725706873,16.550000756979,1.01401774092549E-5,1.04962246938531E-6,0.25,-6.14315600921007E-8,8.86121680594226E-7,-6.0126358258259E-8,133.0339813,133.0339813,99.4721298217773,99.4721298217773,56.7618630665445,20.5633146604427,23.668306,0,0,0,40,4374,136.47975,99.4721298217773,,,,,,,,,,,,,0,,,,0,,,,,,133.0339813,,,,
,23096763.97,136.5082397,99.4721298217773,8.01944823198685E-7,2.98610970930687E-7,1,0.999253354069792,40.0298881530762,1.99726758176186,16.5199991315603,9.94083260071682E-6,-3.14352550155769E-6,0.25,-4.16418573548799E-7,8.06876126593028E-7,-4.17167304699584E-7,136.5082397,136.5082397,99.4721298217773,99.4721298217773,56.7243448976214,20.5586268541297,24.047956,0,0,0,40,4374,139.97995,99.4721298217773,,,,,,,,,,,,,0,,,,0,,,,,,136.5082397,,,,
,23096907.105,140.0406952,99.4721298217773,8.29297520496571E-7,3.02500996766361E-7,1,0.999253354069792,40.0298881530762,1.99733670473426,16.5199991315603,9.51285107845367E-6,1.14474899208558E-6,0.25,-4.38575722709722E-8,8.33641196003123E-7,-4.2663115205284E-8,140.0406952,140.0406952,99.4721298217773,99.4721298217773,56.8751992018329,20.5600380094979,24.047956,0,0,0,40,4374,143.5697,99.4721298217773,,,,,,,,,,,,,0,,,,0.00245,,,,,,140.0406952,,,,
,23097046.71,143.5466919,99.4721298217773,9.154775646676E-7,3.03784545495728E-7,1,0.999253354069792,40.0298881530762,1.99725199032063,16.5199991315603,1.10561077883945E-5,-1.92686368033032E-6,0.25,-3.29084591683725E-7,9.20659194778779E-7,-3.29239753897421E-7,143.5466919,143.5466919,99.4721298217773,99.4721298217773,56.8243933480829,20.5615923750138,23.668306,0,0,0,40,4374,147.0868,99.4721298217773,,,,,,,,,,,,,0,,,,0,,,,,,143.5466919,,,,
,23097187.865,147.0541229,99.4721298217773,3.10508889368962E-7,2.91339124232941E-7,1,0.999253354069792,40.0298881530762,1.99734621275649,16.4700001478195,3.81493340283655E-6,-1.02763695700571E-6,0.25,-1.44518553141558E-7,3.12286434131927E-7,-1.44743398484212E-7,147.0541229,147.0541229,99.4721298217773,99.4721298217773,56.5781803645252,20.5621380375055,24.047956,0,0,0,40,4374,150.62555,99.4721298217773,,,,,,,,,,,,,0,,,,0,,,,,,147.0541229,,,,
,23097329.79,150.5458527,99.4721298217773,6.74706089936848E-7,3.30633300870391E-7,1,0.999253354069792,40.0298881530762,1.99728842644353,16.4700001478195,8.09098514152082E-6,-1.09944728678588E-6,0.25,-2.14257953070809E-7,6.78339788704412E-7,-2.14266896675798E-7,150.5458527,150.5458527,99.4721298217773,99.4721298217773,56.6235148186406,20.5632493056847,24.047956,0,0,0,40,4374,154.1855,99.4721298217773,,,,,,,,,,,,,0,,,,0,,,,,,150.5458527,,,,
,23097468.71,154.060257,99.4721298217773,8.0691707081637E-7,3.01915789786448E-7,1,0.999253354069792,40.0298881530762,1.99726062008627,16.4700001478195,9.84086898017652E-6,-2.26569550513399E-6,0.25,-3.3989397020949E-7,8.11302786996757E-7,-3.40322916141746E-7,154.060257,154.060257,99.4721298217773,99.4721298217773,56.577398736006,20.5634207150432,24.047956,0,0,0,40,4374,157.6649,99.4721298217773,,,,,,,,,,,,,0,,,,-0.0049,,,,,,154.060257,,,,
,23097588.9,157.0119629,99.4721298217773,4.80638018403993E-7,2.46577904267188E-7,1,0.999253354069792,40.0298881530762,1.99720958424374,16.4299998432398,6.51779455225039E-6,-5.12264296890807E-6,0.25,-5.34549524289955E-7,4.83687971620729E-7,-5.36378968981365E-7,157.0119629,157.0119629,99.4721298217773,99.4721298217773,56.8759808303522,20.5622149049366,23.668306,0,0,0,40,4374,160.67865,99.4721298217773,,,,,,,,,,,,,0,,,,-0.00245,,,,,,157.0119629,,,,
,23097729.43,160.5442657,99.4721298217773,1.091661732957E-6,3.2854866207285E-7,1,0.999253354069792,40.0298881530762,1.99737394076108,16.4299998432398,1.19530643321469E-5,4.74132268622955E-6,0.25,2.27353201621085E-7,1.09640064075929E-6,2.29946012637929E-7,160.5442657,160.5442657,99.4721298217773,99.4721298217773,56.6837002146214,20.5647158479311,24.427608,0,0,0,40,4374,164.2016,99.4721298217773,,,,,,,,,,,,,0,,,,-0.00245,,,,,,160.5442657,,,,
,23097868.695,164.0227051,99.4721298217773,9.95251668983359E-7,3.20763996858558E-7,1,0.999253354069792,40.0298881530762,1.99739259870957,16.4299998432398,1.1566759378115E-5,4.70255422091682E-7,0.25,-1.31760115963706E-7,9.99949943541914E-7,-1.30995288973561E-7,164.0227051,164.0227051,99.4721298217773,99.4721298217773,56.7360693254098,20.5653733421508,24.427608,0,0,0,40,4374,167.6899,99.4721298217773,,,,,,,,,,,,,0,,,,0,,,,,,164.0227051,,,,
,23097989.835,167.0303802,99.4721298217773,8.56816841089491E-7,3.29438528513659E-7,1,0.999253354069792,40.0298881530762,1.99739684575714,16.4000000804663,1.055040516612E-5,-3.00647801819238E-6,0.25,-4.13708962020972E-7,8.61187162457432E-7,-4.14407334727726E-7,167.0303802,167.0303802,99.4721298217773,99.4721298217773,56.8142321773329,20.5597105031682,24.427608,0,0,0,40,4374,170.7249,99.4721298217773,,,,,,,,,,,,,0,,,,0,,,,,,167.0303802,,,,
,23098128.72,170.5061798,99.4721298217773,5.78386959191961E-7,2.56582970118922E-7,1,0.999253354069792,40.0298881530762,1.9974459919818,16.4000000804663,7.1627804718916E-6,-2.26779818880147E-6,0.25,-3.00241361244486E-7,5.81297151741541E-7,-3.00797431972497E-7,170.5061798,170.5061798,99.4721298217773,99.4721298217773,56.638365760506,20.5617747357221,24.427608,0,0,0,40,4374,174.2096,99.4721298217773,,,,,,,,,,,,,0,,,,-0.0049,,,,,,170.5061798,,,,
,23098269.9,174.0317993,99.4721298217773,1.21442872731399E-6,3.02414106320663E-7,1,0.999253354069792,40.0298881530762,1.99741697191075,16.4000000804663,1.43094627105817E-5,-5.73556551724092E-7,0.25,-2.61659227780505E-7,1.21992682373004E-6,-2.61235549234268E-7,174.0317993,174.0317993,99.4721298217773,99.4721298217773,56.4257628032752,20.5620285606541,25.186911,0,0,0,40,4374,177.7483,99.4721298217773,,,,,,,,,,,,,0,,,,-0.00245,,,,,,174.0317993,,,,
,23098409,177.5075989,99.4721298217773,1.32732080422957E-6,2.75494127097203E-7,1,0.999253354069792,40.0298881530762,1.99737664721881,16.3499992340803,1.62036411592346E-5,-3.88255333013592E-6,0.25,-5.72636010907929E-7,1.33353859348257E-6,-5.73376599793654E-7,177.5075989,177.5075989,99.4721298217773,99.4721298217773,56.7446672391214,20.5507245411866,24.807261,0,0,0,40,4374,181.2279,99.4721298217773,,,,,,,,,,,,,0,,,,0,,,,,,177.5075989,,,,
,23098549.975,181.0240173,99.4721298217773,1.3021822798669E-6,3.21646510218223E-7,1,0.999253354069792,40.0298881530762,1.99731212520735,16.3499992340803,1.5995476879769E-5,-4.39004350427317E-6,0.25,-6.12963839793414E-7,1.3081895959196E-6,-6.1387881108334E-7,181.0240173,181.0240173,99.4721298217773,99.4721298217773,56.5758354789675,20.5532006819808,24.807261,0,0,0,40,4374,184.7735,99.4721298217773,,,,,,,,,,,,,0,,,,0,,,,,,181.0240173,,,,
,23098692.46,184.5281982,99.4721298217773,1.04818124678971E-6,2.81878391532076E-7,1,0.999253354069792,40.0298881530762,1.99717762920911,16.3499992340803,1.28155089578055E-5,-3.20188633295917E-6,0.25,-4.64189679038246E-7,1.05285659731886E-6,-4.64789667085703E-7,184.5281982,184.5281982,99.4721298217773,99.4721298217773,56.800944492506,20.5573849281108,25.186911,0,0,0,40,4374,188.3487,99.4721298217773,,,,,,,,,,,,,0,,,,0,,,,,,184.5281982,,,,
,23098833.26,188.046402,99.4721298217773,1.34584648370452E-6,3.16475160457658E-7,1,0.999253354069792,40.0298881530762,1.99738986794175,16.3100007921457,1.63960283352108E-5,-3.77407489669679E-6,0.25,-5.66281387027437E-7,1.35165339130403E-6,-5.66910601145736E-7,188.046402,188.046402,99.4721298217773,99.4721298217773,56.8666012881214,20.5531971906362,24.427608,0,0,0,40,4374,191.87445,99.4721298217773,,,,,,,,,,,,,0,,,,0,,,,,,188.046402,,,,
,23098974.615,191.5567474,99.4721298217773,1.77711119486699E-6,2.89284645878573E-7,1,0.999253354069792,40.0298881530762,1.99750051565441,16.3100007921457,2.06174349014552E-5,9.52167176455803E-7,0.25,-2.24852365228678E-7,1.78397987203372E-6,-2.23701668534067E-7,191.5567474,191.5567474,99.4721298217773,99.4721298217773,56.8204852054868,20.5576000227812,25.186911,0,0,0,40,4374,195.4302,99.4721298217773,,,,,,,,,,,,,0,,,,-0.00245,,,,,,191.5567474,,,,
,23099115.795,195.0702057,99.4721298217773,1.77714885296078E-6,3.31709444497865E-7,1,0.999253354069792,40.0298881530762,1.99742358842447,16.3100007921457,2.07783000064396E-5,1.06097398693691E-8,0.25,-3.07753908468479E-7,1.78390587336026E-6,-3.06922738906633E-7,195.0702057,195.0702057,99.4721298217773,99.4721298217773,56.8861420011022,20.5557962814021,25.186911,0,0,0,40,4374,198.98885,99.4721298217773,,,,,,,,,,,,,0,,,,0,,,,,,195.0702057,,,,
,23099253.93,198.5272217,99.4721298217773,1.75851899169698E-6,2.93040728862886E-7,1,0.999253354069792,40.0298881530762,1.99743302311256,16.2599999457598,2.02133027214472E-5,1.99656618503761E-6,0.25,-1.294915595887E-7,1.76481699461528E-6,-1.28063817875078E-7,198.5272217,198.5272217,99.4721298217773,99.4721298217773,56.8267382336406,20.5529631233127,24.807261,0,0,0,40,4374,202.45745,99.4721298217773,,,,,,,,,,,,,0,,,,0,,,,,,198.5272217,,,,
,23099393.655,202.0099487,99.4721298217773,2.05186867035161E-6,2.94155580983726E-7,1,0.999253354069792,40.0298881530762,1.99758046214404,16.2599999457598,2.39832912349662E-5,3.12812551988218E-8,0.25,-3.53554031538825E-7,2.05919572990744E-6,-3.52604141249649E-7,202.0099487,202.0099487,99.4721298217773,99.4721298217773,56.9064643426022,20.556294538406,25.186911,0,0,0,40,4374,205.9569,99.4721298217773,,,,,,,,,,,,,0,,,,0.0049,,,,,,202.0099487,,,,
,23099535.04,205.5435791,99.4721298217773,2.30419946940788E-6,3.06861781916497E-7,1,0.999253354069792,40.0298881530762,1.99752343172482,16.2599999457598,2.67355646158646E-5,1.14771174598068E-6,0.25,-2.98932770931164E-7,2.31205347334715E-6,-2.97549823820175E-7,205.5435791,205.5435791,99.4721298217773,99.4721298217773,56.7345060683714,20.5559639785466,25.186911,0,0,0,40,4374,209.50865,99.4721298217773,,,,,,,,,,,,,0,,,,0,,,,,,205.5435791,,,,
,23099675.98,209.0535278,99.4721298217773,2.75640434837459E-6,2.99896269535027E-7,1,0.999253354069792,40.0298881530762,1.9975414670925,16.2099990993738,3.21618060587847E-5,3.19830095263949E-7,0.25,-4.50344977150977E-7,2.76556779262841E-6,-4.4900020505063E-7,209.0535278,209.0535278,99.4721298217773,99.4721298217773,56.7274714116983,20.5506429395022,25.186911,0,0,0,40,4374,213.03455,99.4721298217773,,,,,,,,,,,,,0,,,,0,,,,,,209.0535278,,,,
,23099816.655,212.5168915,99.4721298217773,2.76779608904898E-6,3.04344506004838E-7,1,0.999253354069792,40.0298881530762,1.99752657112079,16.2099990993738,3.20460915792639E-5,1.73024669057328E-6,0.25,-3.27940486777872E-7,2.77654875632168E-6,-3.26215491503539E-7,212.5168915,212.5168915,99.4721298217773,99.4721298217773,57.0588819038522,20.5554445170974,25.186911,0,0,0,40,4374,216.5681,99.4721298217773,,,,,,,,,,,,,0,,,,0,,,,,,212.5168915,,,,
,23099956.295,216.0267792,99.4721298217773,2.69297246643737E-6,3.08312896255402E-7,1,0.999253354069792,40.0298881530762,1.99746209704309,16.2099990993738,3.10906596343374E-5,2.16969315494612E-6,0.25,-2.76136546338045E-7,2.70112545304628E-6,-2.7434659835003E-7,216.0267792,216.0267792,99.4721298217773,99.4721298217773,56.9392927404099,20.5557034364511,25.566563,0,0,0,40,4374,220.0709,99.4721298217773,,,,,,,,,,,,,0,,,,-0.0049,,,,,,216.0267792,,,,
,23100075.895,219.0233307,99.4721298217773,3.23502221962879E-6,2.54981279416405E-7,1,0.999253354069792,40.0298881530762,1.99745508817918,16.160000115633,3.77987124954511E-5,-9.60183733647137E-9,0.25,-5.62289726765277E-7,3.24470401035626E-6,-5.60809293288545E-7,219.0233307,219.0233307,99.4721298217773,99.4721298217773,56.8204852054868,20.5533265533472,25.566563,0,0,0,40,4374,223.0745,99.4721298217773,,,,,,,,,,,,,0,,,,0.0049,,,,,,219.0233307,,,,
,23100217.53,222.5193329,99.4721298217773,3.48881245102252E-6,3.07489676312955E-7,1,0.999253354069792,40.0298881530762,1.99748129042318,16.160000115633,4.04699563324723E-5,1.65891134399412E-6,0.25,-4.59148123964879E-7,3.49869314627483E-6,-4.57143631305799E-7,222.5193329,222.5193329,99.4721298217773,99.4721298217773,56.8173586914099,20.5585445347509,25.566563,0,0,0,40,4374,226.6145,99.4721298217773,,,,,,,,,,,,,0,,,,0,,,,,,222.5193329,,,,
,23100357.56,226.0195007,99.4721298217773,3.7926361262867E-6,3.26218190001141E-7,1,0.999253354069792,40.0298881530762,1.99746618635535,16.160000115633,4.36346041114943E-5,3.84351536394806E-6,0.25,-3.19133175887995E-7,3.80275203380691E-6,-3.16493445234094E-7,226.0195007,226.0195007,99.4721298217773,99.4721298217773,56.8736359447945,20.5581099216566,25.566563,0,0,0,40,4374,230.1181,99.4721298217773,,,,,,,,,,,,,0,,,,0,,,,,,226.0195007,,,,
touchdown = 10.8700003474951 mm,23100490.25,229.3319092,99.4721298217773,4.19692209268061E-6,3.26909041006812E-7,1,0.999253354069792,40.0298881530762,1.99746269075494,16.1099992692471,4.84387935004596E-5,3.3394400724231E-6,0.25,-4.33635386807207E-7,4.20770672200858E-6,-4.30939808479185E-7,229.3319092,229.3319092,99.4721298217773,99.4721298217773,56.7454488676406,20.5544535672256,25.946213,0,0,0,40,4374,233.4574,99.4721298217773,,,,,,,,,,,,,0,,,,0,,,,,,229.3319092,,,,
,23100616.635,232.5178528,99.4721298217773,4.6393792183087E-6,3.21172555650133E-7,1,0.999253354069792,40.0298881530762,1.99765662326451,16.1099992692471,5.37846530282035E-5,2.30674844652247E-6,0.25,-6.01410151979652E-7,4.65089245870604E-6,-5.98734062284191E-7,232.5178528,232.5178528,99.4721298217773,99.4721298217773,56.7970363499099,20.5586139459195,25.946213,0,0,0,40,4374,236.6291,99.4721298217773,,,,,,,,,,,,,0,,,,0.00245,,,,,,232.5178528,,,,
,23100760.125,236.0429382,99.4721298217773,5.04808324508432E-6,3.6338392887908E-7,1,0.999253354069792,40.0298881530762,1.99768547782136,16.1099992692471,5.78111039869491E-5,6.57523892243547E-6,0.25,-2.95697202395997E-7,5.05967306418783E-6,-2.91980788614763E-7,236.0429382,236.0429382,99.4721298217773,99.4721298217773,56.9267866841022,20.5591945550361,25.186911,0,0,0,40,4374,240.2331,99.4721298217773,,,,,,,,,,,,,0,,,,-0.00245,,,,,,236.0429382,,,,
touchdown = 10.8099998906255 mm,23100908.895,239.7967682,99.4721298217773,5.42262321067006E-6,3.39390006019222E-7,1,0.999253354069792,40.0298881530762,1.99758985449655,16.0499997437,6.22964629461192E-5,5.86793508015549E-6,0.25,-4.22879625540179E-7,5.43444895895183E-6,-4.19154981643613E-7,239.7967682,239.7967682,99.4721298217773,99.4721298217773,56.455464687006,20.5449739951264,25.946213,0,0,0,40,4374,243.96155,99.4721298217773,,,,,,,,,,,,,0,,,,0,,,,,,239.7967682,,,,
,23101038.98,243.0354156,99.4721298217773,6.26325024675191E-6,3.17071797991989E-7,1,0.999253354069792,40.0298881530762,1.9978819694495,16.0499997437,7.0876526799273E-5,1.29996136691052E-5,0.25,6.05419650176235E-8,6.27573332907326E-6,6.59135257125353E-8,243.0354156,243.0354156,99.4721298217773,99.4721298217773,56.8040710065829,20.5502881443549,25.946213,0,0,0,40,4374,247.2149,99.4721298217773,,,,,,,,,,,,,0,,,,-0.00245,,,,,,243.0354156,,,,
,23101181.365,246.5494537,99.4721298217773,6.51566453471142E-6,3.46784489544423E-7,1,0.999253354069792,40.0298881530762,1.99792677595043,16.0499997437,7.445568753944E-5,9.31127105526079E-6,0.25,-3.08446288634602E-7,6.528154129893E-6,-3.03656899803196E-7,246.5494537,246.5494537,99.4721298217773,99.4721298217773,56.8783257159099,20.5538225454358,25.946213,0,0,0,40,4374,250.7848,99.4721298217773,,,,,,,,,,,,,0,,,,0,,,,,,246.5494537,,,,
touchdown = 10.7599999755621 mm,23101326.25,250.18223575,99.4721298217773,6.92654232765091E-6,3.518929725929E-7,1,0.999253354069792,40.0298881530762,1.99794127110146,16.0000007599592,7.9838972146329E-5,5.87365574164243E-6,0.25,-6.82838706208158E-7,6.93921574193976E-6,-6.78424211245442E-7,250.1511841,250.2132874,99.4721298217773,99.4721298217773,56.6829185861022,20.5464487784965,26.325863,0,0,0,40,4374,254.41395,99.4721298217773,,,,,,,,,,,,,0,,,,0,,,,,,250.18223575,,,,
,23101461.595,253.5514221,99.4721298217773,7.50106756517377E-6,3.62288798557777E-7,1,0.999253354069792,40.0298881530762,1.99786915132188,16.0000007599592,8.57721006820675E-5,1.02572124457459E-5,0.25,-3.95428623384698E-7,7.51361516488049E-6,-3.90095216453949E-7,253.5514221,253.5514221,99.4721298217773,99.4721298217773,56.7735874943329,20.5442813122602,25.946213,0,0,0,40,4374,257.8191,99.4721298217773,,,,,,,,,,,,,0,,,,0,,,,,,253.5514221,,,,
,23101601.91,257.0166016,99.4721298217773,7.86677124591704E-6,3.32799670387337E-7,1,0.999253354069792,40.0298881530762,1.99772609421122,16.0000007599592,9.00638851571758E-5,1.00208448716256E-5,0.25,-4.79430132063817E-7,7.87900967288497E-6,-4.73984547350491E-7,257.0166016,257.0166016,99.4721298217773,99.4721298217773,56.9041194570445,20.5447418561268,25.566563,0,0,0,40,4374,261.3296,99.4721298217773,,,,,,,,,,,,,0,,,,0.00245,,,,,,257.0166016,,,,
touchdown = 10.7100000604987 mm,23101743.045,260.56225585,99.4721298217773,8.91838007954595E-6,4.44224454620356E-7,1,0.999253354069792,40.0298881530762,1.99790628806081,15.9499999135733,0.000101772111399436,1.32468410957114E-5,0.25,-3.76845657141248E-7,8.93099501474675E-6,-3.70485530924083E-7,260.5305176,260.5939941,99.4721298217773,99.4721298217773,56.6774471864675,20.5430315389539,26.325863,0,0,0,40,4374,264.86625,99.4721298217773,,,,,,,,,,,,,0,,,,-0.00245,,,,,,260.56225585,,,,
,23101883.235,264.016571,99.4721298217773,9.82756779168079E-6,3.832283968377E-7,1,0.999253354069792,40.0298881530762,1.99813515343373,15.9499999135733,0.000112568929119404,1.21558999563728E-5,0.25,-6.30638144983525E-7,9.84041807222888E-6,-6.2396897926287E-7,264.016571,264.016571,99.4721298217773,99.4721298217773,56.7626446950637,20.5562440591604,26.325863,0,0,0,40,4374,268.3789,99.4721298217773,,,,,,,,,,,,,0,,,,0,,,,,,264.016571,,,,
,23102021.275,267.5047302,99.4721298217773,9.68835205501548E-6,3.91742747627256E-7,1,0.999253354069792,40.0298881530762,1.99803043681361,15.9499999135733,0.000111549755987768,8.54978072991674E-6,0.25,-9.24585424374056E-7,9.70003326219964E-6,-9.18389102167094E-7,267.5047302,267.5047302,99.4721298217773,99.4721298217773,56.7493570102368,20.5485661390517,25.946213,0,0,0,40,4374,271.82495,99.4721298217773,,,,,,,,,,,,,0,,,,0,,,,,,267.5047302,,,,
touchdown = 10.6499996036291 mm,23102160.5,270.9709167,99.4721298217773,1.11069816241363E-5,4.40759942244761E-7,1,0.999253354069792,40.0298881530762,1.99800430029506,15.87999984622,0.000126310141097282,1.87764747085207E-5,0.25,-2.67241838179738E-7,1.11184013110865E-5,-2.59332665501079E-7,270.9709167,270.9709167,99.4721298217773,99.4721298217773,56.6704125297944,20.544404140276,26.325863,0,0,0,40,4374,275.3174,99.4721298217773,,,,,,,,,,,,,0,,,,0.00245,,,,,,270.9709167,,,,
,23102286.11,274.0588074,99.4721298217773,1.07590168392084E-5,3.6656873950178E-7,1,0.999253354069792,40.0298881530762,1.99798735743544,15.87999984622,0.000121571758517857,2.26098910049219E-5,0.25,1.31909844294623E-7,1.07686036066632E-5,1.39843716883424E-7,274.0588074,274.0588074,99.4721298217773,99.4721298217773,56.7657712091406,20.5507049617304,26.705515,0,0,0,40,4374,278.46555,99.4721298217773,,,,,,,,,,,,,0,,,,0.00245,,,,,,274.0588074,,,,
,23102426.07,277.5352478,99.4721298217773,1.17840480078685E-5,2.85828486249843E-7,1,0.999253354069792,40.0298881530762,1.99795214518124,15.87999984622,0.000134417397650082,1.73631095027413E-5,0.25,-5.08758623980187E-7,1.17935499526826E-5,-5.00721109833247E-7,277.5352478,277.5352478,99.4721298217773,99.4721298217773,56.7673344661791,20.5518776084278,26.325863,0,0,0,40,4374,281.9606,99.4721298217773,,,,,,,,,,,,,0,,,,-0.0049,,,,,,277.5352478,,,,
touchdown = 10.5999996885657 mm,23102579.525,281.3594971,99.4721298217773,1.22042528506572E-5,3.93347337548629E-7,1,0.999253354069792,40.0298881530762,1.99786166937924,15.8399995416403,0.000138684891241086,2.08671618919133E-5,0.25,-2.71621936387083E-7,1.2212235459459E-5,-2.6320464330363E-7,281.3594971,281.3594971,99.4721298217773,99.4721298217773,56.648526931256,20.5420525195523,25.946213,0,0,0,40,4374,285.8242,99.4721298217773,,,,,,,,,,,,,0,,,,0,,,,,,281.3594971,,,,
,23102707.35,284.506134,99.4721298217773,1.28965935378359E-5,3.88276817632063E-7,1,0.999253354069792,40.0298881530762,1.99801111671549,15.8399995416403,0.000146983158631893,1.95292298733443E-5,0.25,-5.0960505712845E-7,1.29037266417569E-5,-5.00916225074352E-7,284.506134,284.506134,99.4721298217773,99.4721298217773,56.7892200647175,20.547740651205,26.705515,0,0,0,40,4374,289.0371,99.4721298217773,,,,,,,,,,,,,0,,,,0,,,,,,284.506134,,,,
,23102849.47,288.0411987,99.4721298217773,1.28437772498573E-5,4.07966624473889E-7,1,0.999253354069792,40.0298881530762,1.99788699133116,15.8399995416403,0.000146804905756906,1.68431143407111E-5,0.25,-7.37343547632673E-7,1.2849406308747E-5,-7.28848802821066E-7,288.0411987,288.0411987,99.4721298217773,99.4721298217773,56.8322096332752,20.5431038366703,26.705515,0,0,0,40,4374,292.6173,99.4721298217773,,,,,,,,,,,,,0,,,,-0.0049,,,,,,288.0411987,,,,
touchdown = 10.5400001630187 mm,23102999.57,291.7304993,99.4721298217773,1.25811381853578E-5,4.29577867159834E-7,1,0.999253354069792,40.0298881530762,1.99802426939154,15.7800000160933,0.000142323675519414,2.49791511171451E-5,0.25,2.73367293438179E-8,1.2584477263912E-5,3.58216080626662E-8,291.7304993,291.7304993,99.4721298217773,99.4721298217773,56.435142345506,20.5486689421379,26.325863,0,0,0,40,4374,296.39665,99.4721298217773,,,,,,,,,,,,,0,,,,0,,,,,,291.7304993,,,,
,23103132.53,295.038208,99.4721298217773,1.35782136176037E-5,4.54565450229298E-7,1,0.999253354069792,40.0298881530762,1.99800358074858,15.7800000160933,0.000153920750263705,2.50080618943155E-5,0.25,-1.42467610895128E-7,1.35803247170407E-5,-1.33461588125951E-7,295.038208,295.038208,99.4721298217773,99.4721298217773,57.0377779338329,20.5518485079801,26.325863,0,0,0,40,4374,299.7435,99.4721298217773,,,,,,,,,,,,,0,,,,-0.0049,,,,,,295.038208,,,,
,23103273.155,298.5104675,99.4721298217773,1.32653698420253E-5,2.94808527294304E-7,1,0.999253354069792,40.0298881530762,1.99807804689904,15.7800000160933,0.000150221407812741,2.52358223381119E-5,0.25,-6.78164320639269E-8,1.32657378472198E-5,-5.91213020710871E-8,298.5104675,298.5104675,99.4721298217773,99.4721298217773,56.7415407250445,20.5476309043411,26.325863,0,0,0,40,4374,303.27055,99.4721298217773,,,,,,,,,,,,,0,,,,0,,,,,,298.5104675,,,,
touchdown = 10.4799997061491 mm,23103419.44,302.1386719,99.4721298217773,1.34143078000951E-5,3.48088622726093E-7,1,0.999253354069792,40.0298881530762,1.99813917691425,15.70999994874,0.000151852779813626,2.57475350411514E-5,0.25,-4.80397048703369E-8,1.34129290934903E-5,-3.93664922117116E-8,302.1386719,302.1386719,99.4721298217773,99.4721298217773,56.5797436215637,20.543609969417,26.325863,0,0,0,40,4374,306.9775,99.4721298217773,,,,,,,,,,,,,0,,,,0,,,,,,302.1386719,,,,
,23103556.49,305.5018616,99.4721298217773,1.40307924970874E-5,4.60846007625033E-7,1,0.999253354069792,40.0298881530762,1.99807973003051,15.70999994874,0.000159792688722883,2.12424948516311E-5,0.25,-5.52654892905267E-7,1.4027989457511E-5,-5.43583326378762E-7,305.5018616,305.5018616,99.4721298217773,99.4721298217773,56.6860451001791,20.5449643066807,27.085165,0,0,0,40,4374,310.4271,99.4721298217773,,,,,,,,,,,,,0,,,,0,,,,,,305.5018616,,,,
,23103698.89,309.0466919,99.4721298217773,1.42472709364045E-5,4.00218133541849E-7,1,0.999253354069792,40.0298881530762,1.99827052000731,15.70999994874,0.000162647265153089,1.92898575377114E-5,0.25,-7.62598164500418E-7,1.42427512264386E-5,-7.53367341879563E-7,309.0466919,309.0466919,99.4721298217773,99.4721298217773,56.8236117195637,20.5510961697357,27.085165,0,0,0,40,4374,314.01165,99.4721298217773,,,,,,,,,,,,,0,,,,0,,,,,,309.0466919,,,,
touchdown = 10.4200001806021 mm,23103839.545,312.5091858,99.4721298217773,1.36437513450254E-5,4.43091264503694E-7,1,0.999253354069792,40.0298881530762,1.99817608073671,15.6599991023541,0.00015505506269907,2.23733141150252E-5,0.25,-3.85006256609025E-7,1.36375277231245E-5,-3.76352693351854E-7,312.5091858,312.5091858,99.4721298217773,99.4721298217773,56.4374872310637,20.5427516457551,26.325863,0,0,0,40,4374,317.5659,99.4721298217773,,,,,,,,,,,,,0,,,,-0.00245,,,,,,312.5091858,,,,
,23103980.93,316.0073547,99.4721298217773,1.36639613689743E-5,4.48046952268623E-7,1,0.999253354069792,40.0298881530762,1.99818971893557,15.6599991023541,0.000154458882070528,2.70665272985122E-5,0.25,2.6870103809889E-8,1.36557826727998E-5,3.5228512669716E-8,316.0073547,316.0073547,99.4721298217773,99.4721298217773,56.8869236296214,20.5521217457766,26.325863,0,0,0,40,4374,321.1312,99.4721298217773,,,,,,,,,,,,,0,,,,0.00245,,,,,,316.0073547,,,,
,23104127.265,319.5689697,99.4721298217773,1.35340914162336E-5,4.08450044777323E-7,1,0.999253354069792,40.0298881530762,1.99821816739595,15.6599991023541,0.000154363529880298,1.87817700901035E-5,0.25,-6.82989336133533E-7,1.35247212609741E-5,-6.74309086649038E-7,319.5689697,319.5689697,99.4721298217773,99.4721298217773,56.8267382336406,20.5469553878799,27.464817,0,0,0,40,4374,324.8226,99.4721298217773,,,,,,,,,,,,,0,,,,-0.0049,,,,,,319.5689697,,,,
touchdown = 10.3700002655387 mm,23104261.815,322.9024353,99.4721298217773,1.35018327019687E-5,5.03343491637263E-7,1,0.999253354069792,40.0298881530762,1.99824565260405,15.6100001186132,0.000153855059480557,1.94537106174496E-5,0.25,-6.17698583947252E-7,1.34908613446611E-5,-6.09108894097852E-7,322.9024353,322.9024353,99.4721298217773,99.4721298217773,56.6805737005445,20.5384798943074,27.085165,0,0,0,40,4374,328.22155,99.4721298217773,,,,,,,,,,,,,0,,,,0.0049,,,,,,322.9024353,,,,
,23104388.79,326.0413513,99.4721298217773,1.36670689605116E-5,3.66184404246743E-7,1,0.999253354069792,40.0298881530762,1.99836865113541,15.6100001186132,0.00015597342830095,1.82847672852968E-5,0.25,-7.49540357556797E-7,1.36545315807955E-5,-7.40747542561861E-7,326.0413513,326.0413513,99.4721298217773,99.4721298217773,56.7368509539291,20.546916869151,27.085165,0,0,0,40,4374,331.4236,99.4721298217773,,,,,,,,,,,,,0,,,,0,,,,,,326.0413513,,,,
,23104531.39,329.5464172,99.4721298217773,1.41202170644222E-5,4.65637942341786E-7,1,0.999253354069792,40.0298881530762,1.9983583511137,15.6100001186132,0.000159722700358014,2.6982288388169E-5,0.25,-5.82643283161535E-8,1.41051152521031E-5,-4.99521527026302E-8,329.5464172,329.5464172,99.4721298217773,99.4721298217773,56.6055373626983,20.5423500230605,27.464817,0,0,0,40,4374,335.0121,99.4721298217773,,,,,,,,,,,,,0,,,,0,,,,,,329.5464172,,,,
,23104668.55,332.9740906,99.4721298217773,,,2,,,,15.5599998086691,,,,,,,332.9740906,332.9740906,99.4721298217773,99.4721298217773,,,26.705515,,,,-99999999,4374,338.4538,99.4721298217773,,,,,,,,,,,,,,,,,,,,,,,332.9740906,,,,
,23104793.09,336.0434723,99.4721298217773,1.40367568117352E-5,4.31152945660472E-7,1,0.999253354069792,40.0298881530762,1.99858763247717,15.5499996617436,0.000160177678506713,1.86343413163196E-5,0.25,-7.81973279334833E-7,1.40190003693164E-5,-7.72928947748645E-7,336.0086365,336.0783081,99.4721298217773,99.4721298217773,56.7118388413137,20.5448923247263,27.085165,0,0,0,40,4374,341.58685,99.4721298217773,,,,,,,,,,,,,0,,,,0.0049,,,,,,336.0434723,,,,
,23104933.61,339.5311279,99.4721298217773,1.38314226647501E-5,3.4110208774796E-7,1,0.999253354069792,40.0298881530762,1.99865915485638,15.5499996617436,0.000157017092488543,2.30023863011679E-5,0.25,-3.59681642900549E-7,1.38120308325481E-5,-3.51344576634565E-7,339.5311279,339.5311279,99.4721298217773,99.4721298217773,56.8275198621599,20.5435856063562,27.085165,0,0,0,40,4374,345.12405,99.4721298217773,,,,,,,,,,,,,0,,,,-0.0049,,,,,,339.5311279,,,,
,23105086.61,343.3062439,99.4721298217773,,,2,,,,15.5000002831221,,,,,,,343.3062439,343.3062439,99.4721298217773,99.4721298217773,,,27.464817,,,,-99999999,4374,348.9491,99.4721298217773,,,,,,,,,,,,,,,,,,,,,,,343.3062439,,,,
,23105214.475,346.5317688,99.4721298217773,1.33252754938774E-5,4.71811152448466E-7,1,0.999253354069792,40.0298881530762,1.99865558697032,15.4900001361966,0.000151137752617803,2.27156079521346E-5,0.25,-2.96777089211658E-7,1.33033831321401E-5,-2.88897631853289E-7,346.5317688,346.5317688,99.4721298217773,99.4721298217773,56.7376325824483,20.5439943590375,27.464817,0,0,0,40,4374,352.1707,99.4721298217773,,,,,,,,,,,,,0,,,,0.0049,,,,,,346.5317688,,,,
,23105727.54,349.86366275,99.4721298217773,1.28485100395053E-5,5.57114052431279E-7,1,0.999253354069792,40.0298881530762,1.9985914063232,15.4900001361966,0.000145296430430102,2.42838854979714E-5,0.25,-7.51194303397451E-8,1.28258334734139E-5,-6.78583128311702E-8,349.8627625,349.864563,99.4721298217773,99.4721298217773,56.8306463762368,20.548647435982,27.844467,0,0,0,40,4369,351.9053,99.4721298217773,,,,,,,,,,,,,0,,,,-0.00245,,,,,,349.86366275,,,,