File: data/doubleLayers/dl_2-5/ppms/DD205_5/KoelnPPMS/DD205_5_HYST_100OE_10K.DAT
[Header]
; VSM Data File (default extension .dat)
; Copyright (c) 2003-2013, Quantum Design, Inc. All rights reserved.
TITLE,
FILEOPENTIME,23120038.41,09/25/2018,11:12 pm
BYAPP,VSM,2.0,2.0
INFO,PPMS VSM Option Release 1.4.10 Build 1,APPNAME
INFO,Quantum Design Linear Motor Servo Controller,MOTOR_MODULE_NAME
INFO,3101-100 M1,MOTOR_HW_VERSION
INFO,MMC1014,MOTOR_SERIAL_NUMBER
INFO,SRV No X-over 01.03.11,MOTOR_SOFTWARE_VERSION
INFO,Quantum Design VSM Detection Module,VSM_MODULE_NAME
INFO,3101-150 F0,VSM_HW_VERSION
INFO,VSM707,VSM_SERIAL_NUMBER
INFO,VSM No X-over 01.02.05 May 20 2008 13:51:47,VSM_SOFTWARE_VERSION
INFO,704,PREAMP_SERIAL_NUMBER
INFO,822,COIL_SERIAL_NUMBER
INFO,0,MOMENT_UNITS
INFO,,SAMPLE_MATERIAL
INFO,,SAMPLE_COMMENT
INFO,,SAMPLE_MASS
INFO,,SAMPLE_VOLUME
INFO,,SAMPLE_MOLECULAR_WEIGHT
INFO,,SAMPLE_SIZE
INFO,,SAMPLE_SHAPE
DATATYPE,COMMENT,1
DATATYPE,TIME,2
STARTUPAXIS,X,2
STARTUPAXIS,Y1,5
[Data]
Comment,Time Stamp (sec),Temperature (K),Magnetic Field (Oe),Moment (emu),M. Std. Err. (emu),Transport Action,Averaging Time (sec),Frequency (Hz),Peak Amplitude (mm),Center Position (mm),Coil Signal' (mV),Coil Signal" (mV),Range (mV),M. Quad. Signal (emu),M. Raw' (emu),M. Raw" (emu),Min. Temperature (K),Max. Temperature (K),Min. Field (Oe),Max. Field (Oe),Mass (grams),Motor Lag (deg),Pressure (Torr),VSM Status (code),Motor Status (code),Measure Status (code),Measure Count,PPMS Status (code),System Temp. (K),System Field (Oe),Sample Position (deg),Bridge 1 Resistance (ohms),Bridge 1 Excitation (에),Bridge 2 Resistance (ohms),Bridge 2 Excitation (에),Bridge 3 Resistance (ohms),Bridge 3 Excitation (에),Bridge 4 Resistance (ohms),Bridge 4 Excitation (에),Signal 1 Vin (V),Signal 2 Vin (V),Digital Inputs (code),Drive 1 Iout (mA),Drive 1 Ipower (W),Drive 2 Iout (mA),Drive 2 Ipower (W),Pressure (),Map 20 (),Map 21 (),Map 22 (),Map 23 (),Map 24 (),Map 25 (),Map 26 (),Map 27 (),Map 28 (),Map 29 ()
,23120054.89,10.0028906,99.4721298217773,,,2,,,,16.879999615252,,,,,,,10.0028906,10.0028906,99.4721298217773,99.4721298217773,,,13.038077,,,,-99999999,4369,9.9888,99.4721298217773,,,,,,,,,,,,,,,,,,,,,,,10.0028906,,,,
,23120211.055,9.992856,4526.57788085937,1.26043023641912E-5,3.54304126219327E-7,1,0.999253354069792,40.0298881530762,1.9848970469222,16.8699994683266,0.000142768540046518,1.40850994827856E-5,0.25,-9.81038491425259E-7,1.25399799722695E-5,-9.11435615803055E-7,9.992856,9.992856,4519.00048828125,4534.1552734375,56.3069552683521,20.5923022016134,12.658426,0,0,0,40,4449,10.0001,4526.57788085937,,,,,,,,,,,,,0,,,,0,,,,,,9.992856,,,,
,23120307.815,9.992136,9364.82763671875,2.2057106592097E-6,2.33025422022594E-7,1,0.999253354069792,40.0298881530762,1.98499933825381,16.8699994683266,2.70884110657826E-5,-9.280941384152E-6,0.25,-1.22352581527591E-6,2.20102597053405E-6,-1.20521571067916E-6,9.992136,9.992136,9357.46484375,9372.1904296875,56.2663105853521,20.5882247334726,12.658426,0,0,0,40,4449,10.008,9364.82763671875,,,,,,,,,,,,,0,,,,-0.00245,,,,,,9.992136,,,,
,23120408.085,9.9930277,14374.7626953125,-6.56354838996523E-6,3.48543619802783E-7,1,0.999253354069792,40.0298881530762,1.9846894646192,16.8699994683266,-7.04686295763083E-5,-2.93543478562107E-5,0.25,-1.45372205281854E-6,-6.52410746863728E-6,-1.48501183493389E-6,9.9930277,9.9930277,14369.744140625,14379.78125,56.5703640793329,20.5914013271607,12.278775,0,0,0,40,4449,10.01305,14374.7626953125,,,,,,,,,,,,,0,,,,0,,,,,,9.9930277,,,,
,23120506.43,9.9943075,19292.025390625,-1.27645586538228E-5,4.12383455872513E-7,1,0.999253354069792,40.0298881530762,1.98491676917044,16.8699994683266,-0.000137663962269531,-5.40363596883701E-5,0.25,-2.54731668563063E-6,-1.2694457878092E-5,-2.61496746775298E-6,9.9943075,9.9943075,19287.2734375,19296.77734375,56.6274229612368,20.5926433682817,12.658426,0,0,0,40,4449,10.01755,19292.025390625,,,,,,,,,,,,,0,,,,-0.00245,,,,,,9.9943075,,,,
,23120604.42,9.9962015,24189.7216796875,-1.41119310185729E-5,4.77246377455583E-7,1,0.999253354069792,40.0298881530762,1.98466448078862,16.8699994683266,-0.000153098608987878,-5.49796827234888E-5,0.25,-2.38461446221033E-6,-1.40432062384628E-5,-2.46669322224498E-6,9.9962015,9.9962015,24184.861328125,24194.58203125,56.6055373626983,20.5896282649862,12.278775,0,0,0,40,4449,10.02095,24189.7216796875,,,,,,,,,,,,,0,,,,0,,,,,,9.9962015,,,,
,23120704.285,9.9977846,29180.01953125,-1.69174857090975E-5,5.33865239646278E-7,1,0.999253354069792,40.0298881530762,1.98448550952282,16.8699994683266,-0.000182197301645148,-7.37865086598028E-5,0.25,-3.55552130405225E-6,-1.68383508628492E-5,-3.65767399249406E-6,9.9977846,9.9977846,29172.474609375,29187.564453125,56.7477937531983,20.5924132481958,13.038077,0,0,0,40,4449,10.0253,29180.01953125,,,,,,,,,,,,,0,,,,0,,,,,,9.9977846,,,,
,23120801.155,9.9965248,34022.251953125,-2.32256639298881E-5,5.5017472910843E-7,1,0.999253354069792,40.0298881530762,1.98458349489729,16.8699994683266,-0.000251771309174022,-9.29658645364283E-5,0.25,-4.12713052222935E-6,-2.31330471622083E-5,-4.27704013299809E-6,9.9965248,9.9965248,34014.74609375,34029.7578125,56.5555131374675,20.5913411820595,12.658426,0,0,0,40,4449,10.02695,34022.251953125,,,,,,,,,,,,,0,,,,-0.0049,,,,,,9.9965248,,,,
,23120898.735,9.9966545,38899.49609375,-3.39427934493509E-5,5.69576100365377E-7,1,0.999253354069792,40.0298881530762,1.98444563770836,16.8699994683266,-0.000370415084890092,-0.000123071192803769,0.25,-4.87836668681375E-6,-3.38321489685971E-5,-5.10920393764661E-6,9.9966545,9.9966545,38886.7890625,38912.203125,56.6821369575829,20.5950445217007,12.278775,0,0,0,40,4449,10.02925,38899.49609375,,,,,,,,,,,,,0,,,,-0.00245,,,,,,9.9966545,,,,
,23120998.155,9.9957933,43869.20703125,-4.53305479387723E-5,6.63091548753742E-7,1,0.999253354069792,40.0298881530762,1.98460934316419,16.8699994683266,-0.00049677354542366,-0.000154489060416159,0.25,-5.61947693512262E-6,-4.52121350233193E-5,-5.93898884197506E-6,9.9957933,9.9957933,43864.23046875,43874.18359375,56.005246659929,20.5926913321922,13.038077,0,0,0,40,4449,10.0332,43869.20703125,,,,,,,,,,,,,0,,,,0,,,,,,9.9957933,,,,
,23121097.59,9.9957199,48837.63671875,-6.05523728528399E-5,8.92029046717529E-7,1,0.999253354069792,40.0298881530762,1.98471950751554,16.8699994683266,-0.00066858980548377,-0.000180773749879185,0.25,-5.20857055216947E-6,-6.04415216340589E-5,-5.64787889703521E-6,9.9957199,9.9957199,48828.05078125,48847.22265625,56.7118388413137,20.5885039692481,12.658426,0,0,0,40,4449,10.03665,48837.63671875,,,,,,,,,,,,,0,,,,0,,,,,,9.9957199,,,,
,23121196.6,9.9953384,53784.9609375,-7.61381718495467E-5,7.84487671760661E-7,1,0.999253354069792,40.0298881530762,1.98438298652483,16.8699994683266,-0.000841664618062862,-0.00022346889912333,0.25,-6.19642077541576E-6,-7.6038932723068E-5,-6.75681125698694E-6,9.9953384,9.9953384,53775.05078125,53794.87109375,56.5000175126021,20.5979801296048,12.278775,0,0,0,40,4449,10.04085,53784.9609375,,,,,,,,,,,,,0,,,,0.00245,,,,,,9.9953384,,,,
,23121295.73,9.9956055,58740.36328125,-9.11199699500801E-5,7.52782706091752E-7,1,0.999253354069792,40.0298881530762,1.98386595075204,16.8699994683266,-0.00100855566626386,-0.000261714122816822,0.25,-6.89787226568743E-6,-9.10486881057134E-5,-7.57449399371791E-6,9.9956055,9.9956055,58732.921875,58747.8046875,56.8775440873906,20.6043114451887,11.899124,0,0,0,40,4449,10.0458,58740.36328125,,,,,,,,,,,,,0,,,,-0.00245,,,,,,9.9956055,,,,
,23121394.925,9.9942875,63700.529296875,-0.000105649504147573,8.07314312027679E-7,1,0.999253354069792,40.0298881530762,1.98401433783596,16.8699994683266,-0.0011709525816127,-0.00029831148402521,0.25,-7.5269936563302E-6,-0.000105619070584055,-8.31452963469247E-6,9.9942875,9.9942875,63690.546875,63710.51171875,56.0896625400059,20.6029725343678,12.278775,0,0,0,40,4449,10.05065,63700.529296875,,,,,,,,,,,,,0,,,,0,,,,,,9.9942875,,,,
,23121494.32,9.9942198,68668.0859375,-0.0001235002467985,8.57064762384954E-7,1,0.999253354069792,40.0298881530762,1.98378774579856,16.8699994683266,-0.00137037941477517,-0.000342580975680659,0.25,-8.24665046369274E-6,-0.000123523239205407,-9.16683994599494E-6,9.9942198,9.9942198,68663.1640625,68673.0078125,56.4679707433137,20.6022952577728,12.658426,0,0,0,40,4449,10.0551,68668.0859375,,,,,,,,,,,,,0,,,,0,,,,,,9.9942198,,,,
,23121595.565,9.995204,73728.2109375,-0.000139759218989735,6.94378586248639E-7,1,0.999253354069792,40.0298881530762,1.98358430842084,16.8699994683266,-0.00155230950006267,-0.000382207715752661,0.25,-8.84193358363551E-6,-0.000139848454455756,-9.87894833598588E-6,9.995204,9.995204,73715.703125,73740.71875,56.343691808756,20.6026336972899,11.899124,0,0,0,40,4449,10.0597,73728.2109375,,,,,,,,,,,,,0,,,,-0.00245,,,,,,9.995204,,,,
,23121694.775,9.9950781,78686.20703125,-0.000155135077866505,9.38091745486957E-7,1,0.999253354069792,40.0298881530762,1.98379440721164,16.8699994683266,-0.00172637772146334,-0.000410945576303231,0.25,-8.62361161125227E-6,-0.00015530404855761,-9.76542026580971E-6,9.9950781,9.9950781,78678.78125,78693.6328125,56.5664559367368,20.6039811369927,12.278775,0,0,0,40,4449,10.0636,78686.20703125,,,,,,,,,,,,,0,,,,0,,,,,,9.9950781,,,,
,23121794.21,9.9947796,83656.921875,-0.000173291163508626,8.35054094556131E-7,1,0.999253354069792,40.0298881530762,1.98369240001277,16.8699994683266,-0.00192683348789118,-0.000471469111518359,0.25,-1.07409329168444E-5,-0.000173536455044813,-1.20065747535539E-5,9.9947796,9.9947796,83651.921875,83661.921875,56.5211214826214,20.6046565997246,12.278775,0,0,0,40,4449,10.0687,83656.921875,,,,,,,,,,,,,0,,,,0,,,,,,9.9947796,,,,
,23121888.32,9.993763,88360.05859375,-0.000188385177922407,1.04762027690542E-6,1,0.999253354069792,40.0298881530762,1.98334166439154,16.8699994683266,-0.00209929518344863,-0.000488758604834853,0.25,-9.57348509472421E-6,-0.000188729278268413,-1.09305456751354E-5,9.993763,9.993763,88354.984375,88365.1328125,56.5453519667175,20.6091871704621,11.899124,0,0,0,40,4449,10.0756,88360.05859375,,,,,,,,,,,,,0,,,,0.0049,,,,,,9.993763,,,,
,23122002.105,9.9974594,87073.1328125,-0.000184364922160022,7.98369895361225E-7,1,0.999253354069792,40.0298881530762,1.9832911893835,16.8699994683266,-0.00205156968852714,-0.000493249986059064,0.25,-1.06957960958116E-5,-0.000184675911360739,-1.20308749011064E-5,9.9974594,9.9974594,87062.921875,87083.34375,56.8994296859291,20.6089003248757,12.658426,0,0,0,40,4449,10.07735,87073.1328125,,,,,,,,,,,,,0,,,,0,,,,,,9.9974594,,,,
,23122097.025,10.0010662,82330.00390625,-0.00016695432116046,8.61586700115053E-7,1,0.999253354069792,40.0298881530762,1.98329667480641,16.8699994683266,-0.00185612150823952,-0.000452534316800977,0.25,-1.02047506189904E-5,-0.00016717543218887,-1.14270520592531E-5,10.0010662,10.0010662,82325.0703125,82334.9375,56.4312342029098,20.6091847482896,12.278775,0,0,0,40,4449,10.0761,82330.00390625,,,,,,,,,,,,,0,,,,0.0049,,,,,,10.0010662,,,,
,23122198.775,10.0023661,77241.109375,-0.000150617427943669,9.25436371378872E-7,1,0.999253354069792,40.0298881530762,1.98354698395003,16.8699994683266,-0.00167225980397614,-0.000418079991853909,0.25,-1.00768050729471E-5,-0.000150752083752744,-1.11902602402935E-5,10.0023661,10.0023661,77231.046875,77251.171875,56.4499932873714,20.6105676631164,12.278775,0,0,0,40,4449,10.07175,77241.109375,,,,,,,,,,,,,0,,,,0.00245,,,,,,10.0023661,,,,
,23122299.315,10.0030155,72215.359375,-0.000134173829583635,1.11705644297822E-6,1,0.999253354069792,40.0298881530762,1.98366605962123,16.8699994683266,-0.0014890309901165,-0.000373085504601919,0.25,-9.03637917137544E-6,-0.000134238687744639,-1.00339500567956E-5,10.0030155,10.0030155,72207.859375,72222.859375,56.4773502855444,20.6115843782905,12.278775,0,0,0,40,4449,10.0697,72215.359375,,,,,,,,,,,,,0,,,,0,,,,,,10.0030155,,,,
,23122400.46,10.0030661,67159.95703125,-0.000118816907373436,7.42615166268095E-7,1,0.999253354069792,40.0298881530762,1.98402105639992,16.8699994683266,-0.00131938678495449,-0.000324036072469643,0.25,-7.4384340567325E-6,-0.00011882706564103,-8.32385956304528E-6,10.0030661,10.0030661,67149.859375,67170.0546875,56.5586396515444,20.603478853298,12.278775,0,0,0,40,4449,10.06635,67159.95703125,,,,,,,,,,,,,0,,,,-0.00245,,,,,,10.0030661,,,,
,23122501.42,10.0035505,62110.927734375,-0.000100721370409389,8.90872232854589E-7,1,0.999253354069792,40.0298881530762,1.98383129710264,16.8699994683266,-0.00111759314875015,-0.000275887092417022,0.25,-6.42314901763195E-6,-0.000100683291621809,-7.17330904169331E-6,10.0035505,10.0035505,62100.78125,62121.07421875,56.5328459104098,20.5991539407492,12.278775,0,0,0,40,4449,10.06195,62110.927734375,,,,,,,,,,,,,0,,,,-0.00245,,,,,,10.0035505,,,,
,23122601.2,10.0031767,57123.16796875,-8.57431852170434E-5,1.15355181591774E-6,1,0.999253354069792,40.0298881530762,1.98406271898133,16.8699994683266,-0.000949341541760113,-0.000244285154204592,0.25,-6.31548668223477E-6,-8.56641719522822E-5,-6.95084354760058E-6,10.0031767,10.0031767,57118.09765625,57128.23828125,56.6321127323521,20.5997037297984,12.278775,0,0,0,40,4449,10.06005,57123.16796875,,,,,,,,,,,,,0,,,,0.00245,,,,,,10.0031767,,,,
,23122701.2,10.0033827,52126.33203125,-7.08485905684168E-5,7.27105537876883E-7,1,0.999253354069792,40.0298881530762,1.9841794149696,16.8699994683266,-0.00078436183894502,-0.000200254610461164,0.25,-5.08629010896159E-6,-7.07496681574994E-5,-5.60626278229429E-6,10.0033827,10.0033827,52116.45703125,52136.20703125,56.8783257159099,20.6017027380842,12.658426,0,0,0,40,4449,10.0567,52126.33203125,,,,,,,,,,,,,0,,,,-0.00245,,,,,,10.0033827,,,,
,23122800.315,10.0037851,47173.578125,-5.58589309645142E-5,7.57618240920148E-7,1,0.999253354069792,40.0298881530762,1.9848652906374,16.8699994683266,-0.000617574241195229,-0.000161926511136004,0.25,-4.37665661159632E-6,-5.57503989321197E-5,-4.78010465020393E-6,10.0037851,10.0037851,47168.671875,47178.484375,56.0615239133136,20.5859968554197,12.278775,0,0,0,40,4449,10.0523,47173.578125,,,,,,,,,,,,,0,,,,0,,,,,,10.0037851,,,,
,23122900.025,10.0026169,42191.130859375,-4.013252438955E-5,5.93018598945414E-7,1,0.999253354069792,40.0298881530762,1.98457888589303,16.8699994683266,-0.000442043333476863,-0.000123881745661705,0.25,-3.82867493110354E-6,-4.00291050262125E-5,-4.11114968711259E-6,10.0026169,10.0026169,42181.09375,42201.16796875,56.2405168442175,20.588021685673,11.899124,0,0,0,40,4449,10.05015,42191.130859375,,,,,,,,,,,,,0,,,,0,,,,,,10.0026169,,,,
,23122999.18,10.0049047,37233.353515625,-2.61649525805383E-5,5.15366698634943E-7,1,0.999253354069792,40.0298881530762,1.98457051112005,16.8699994683266,-0.000285929836747665,-9.24967822401736E-5,0.25,-3.55104231395556E-6,-2.60767270379106E-5,-3.72735621510851E-6,10.0049047,10.0049047,37228.453125,37238.25390625,56.3757385780444,20.5902944986887,12.658426,0,0,0,40,4449,10.046,37233.353515625,,,,,,,,,,,,,0,,,,0,,,,,,10.0049047,,,,
,23123089.67,10.0052319,32710.9521484375,-1.23404357643315E-5,7.11934089651182E-7,1,0.999253354069792,40.0298881530762,1.98485767471741,16.8699994683266,-0.000131844820945825,-6.01271023192312E-5,0.25,-3.15191434575251E-6,-1.2283026152235E-5,-3.2278046497225E-6,10.0052319,10.0052319,32700.7734375,32721.130859375,56.3554162365444,20.5828667509607,12.278775,0,0,0,40,4449,10.04085,32710.9521484375,,,,,,,,,,,,,0,,,,0,,,,,,10.0052319,,,,
,23123183.47,10.0044823,28023.3564453125,8.50063441377407E-7,4.97649446672863E-7,1,0.999253354069792,40.0298881530762,1.98517597614539,16.8699994683266,1.34239433355346E-5,-2.00663889827944E-5,0.25,-1.94507897812563E-6,8.60151276406529E-7,-1.93282832981897E-6,10.0044823,10.0044823,28013.310546875,28033.40234375,56.5000175126021,20.5785568742006,12.658426,0,0,0,40,4449,10.03725,28023.3564453125,,,,,,,,,,,,,0,,,,0,,,,,,10.0044823,,,,
,23123273.65,10.003417,23515.541015625,1.43089028356302E-5,5.10829374802609E-7,1,0.999253354069792,40.0298881530762,1.98540687051124,16.8699994683266,0.000163873926854546,7.81822456284549E-6,0.25,-1.86577074500389E-6,1.4265819822487E-5,-1.76679720665033E-6,10.003417,10.003417,23505.587890625,23525.494140625,56.411693489929,20.5749087125614,12.278775,0,0,0,40,4449,10.0344,23515.541015625,,,,,,,,,,,,,0,,,,-0.00245,,,,,,10.003417,,,,
,23123364.335,10.0029593,18983.0947265625,2.68849721945996E-5,4.40200941151989E-7,1,0.999253354069792,40.0298881530762,1.98507565812496,16.8699994683266,0.000304222285754424,3.41362320819135E-5,0.25,-1.75834654655587E-6,2.67803057770175E-5,-1.58597678623002E-6,10.0029593,10.0029593,18978.130859375,18988.05859375,56.2866329268521,20.5795374067649,11.899124,0,0,0,40,4449,10.03115,18983.0947265625,,,,,,,,,,,,,0,,,,0,,,,,,10.0029593,,,,
,23123456.805,10.002492,14363.4018554687,4.01334501587444E-5,3.80717265072046E-7,1,0.999253354069792,40.0298881530762,1.98491564383403,16.8699994683266,0.00045281205896148,5.70081510224461E-5,0.25,-2.06846068171759E-6,3.9955936787678E-5,-1.82543026955301E-6,10.002492,10.002492,14350.857421875,14375.9462890625,56.0873176544482,20.5839457248483,11.899124,0,0,0,40,4449,10.0305,14363.4018554687,,,,,,,,,,,,,0,,,,-0.00245,,,,,,10.002492,,,,
,23123548.545,10.0028896,9778.419921875,5.21697857765743E-5,3.75759601186126E-7,1,0.999253354069792,40.0298881530762,1.98495009920086,16.8699994683266,0.000584445985913992,9.61572907889796E-5,0.25,-6.9561129413166E-7,5.19068849423332E-5,-4.06288453364234E-7,10.0028896,10.0028896,9768.431640625,9788.408203125,56.2960124690829,20.5839416159079,11.899124,0,0,0,40,4449,10.0275,9778.419921875,,,,,,,,,,,,,0,,,,0,,,,,,10.0028896,,,,
,23123638.405,10.0042419,5285.197265625,6.36090300573474E-5,3.24341488617803E-7,1,0.999253354069792,40.0298881530762,1.98471782275703,16.8699994683266,0.000711013898249494,0.000124261739441063,0.25,-1.94011661533907E-7,6.32634469288577E-5,1.34503723757784E-7,10.0042419,10.0042419,5280.40771484375,5289.98681640625,56.5125235689098,20.5864856443771,12.278775,0,0,0,40,4449,10.0233,5285.197265625,,,,,,,,,,,,,0,,,,0,,,,,,10.0042419,,,,
,23123730.11,10.009305,701.296569824219,7.36568302779208E-5,2.96511116626138E-7,1,0.999253354069792,40.0298881530762,1.98461460309672,16.8699994683266,0.000823121559430956,0.000143499347893087,0.25,-2.33525004847617E-7,7.32367265667423E-5,1.25046460207866E-7,10.009305,10.009305,696.34814453125,706.244995117187,56.4679707433137,20.5853348016124,11.899124,0,0,0,40,4449,10.0139,701.296569824219,,,,,,,,,,,,,0,,,,0,,,,,,10.009305,,,,
,23123821.89,10.0001764,-3881.81677246094,7.49604075068864E-5,2.66854706932774E-7,1,0.999253354069792,40.0298881530762,1.98458907635086,16.8699994683266,0.000836399165095535,0.000154108501366714,0.25,4.67613894531795E-7,7.45426488995291E-5,8.43507705688811E-7,10.0001764,10.0001764,-3891.81982421875,-3871.81372070313,56.7266897831791,20.5910361552416,12.658426,0,0,0,40,4449,10.0168,-3881.81677246094,,,,,,,,,,,,,0,,,,0.00245,,,,,,10.0001764,,,,
,23123913.645,9.9966412,-8468.5595703125,8.29910105903211E-5,3.31147995666977E-7,1,0.999253354069792,40.0298881530762,1.98460794663234,16.8699994683266,0.000925498322923459,0.000175261391890098,0.25,9.00591945384058E-7,8.25533097049002E-5,1.34244607824889E-6,9.9966412,9.9966412,-8475.9404296875,-8461.1787109375,56.5625477941406,20.5926329510107,11.899124,0,0,0,40,4449,10.0198,-8468.5595703125,,,,,,,,,,,,,0,,,,0,,,,,,9.9966412,,,,
,23124004.88,9.9964275,-13029.3046875,8.70887172250534E-5,3.95696485300256E-7,1,0.999253354069792,40.0298881530762,1.98454546719999,16.8699994683266,0.000971466516075145,0.000184339052394122,0.25,9.48133054948354E-7,8.6661777247275E-5,1.44135696899899E-6,9.9964275,9.9964275,-13039.3125,-13019.296875,57.0823307594291,20.5892995642833,12.278775,0,0,0,40,4449,10.0238,-13029.3046875,,,,,,,,,,,,,0,,,,-0.00245,,,,,,9.9964275,,,,
,23124094.86,9.99722,-17526.7578125,8.291994277065E-5,4.47598505891037E-7,1,0.999253354069792,40.0298881530762,1.98447140348092,16.8699994683266,0.000924290421109869,0.000181274917829106,0.25,1.38589614587017E-6,8.254404134502E-5,1.87999909737796E-6,9.99722,9.99722,-17536.7890625,-17516.7265625,56.7657712091406,20.59044848055,11.899124,0,0,0,40,4449,10.0265,-17526.7578125,,,,,,,,,,,,,0,,,,-0.00245,,,,,,9.99722,,,,
,23124186.595,9.997323,-22111.640625,6.85151956109673E-5,4.25908437653711E-7,1,0.999253354069792,40.0298881530762,1.98444085055967,16.8699994683266,0.000763755145077633,0.000151501077244095,0.25,1.27263270127257E-6,6.82338972200484E-5,1.70128463169242E-6,9.997323,9.997323,-22119.3828125,-22103.8984375,56.3773018350829,20.5925337102997,11.519473,0,0,0,40,4449,10.0284,-22111.640625,,,,,,,,,,,,,0,,,,0,,,,,,9.997323,,,,
,23124276.765,9.9969435,-26616.529296875,5.08286756945353E-5,5.33760087023812E-7,1,0.999253354069792,40.0298881530762,1.98430710940024,16.8699994683266,0.000564898450697144,0.000123154043031368,0.25,1.8888632899122E-6,5.06367549319803E-5,2.21722020331713E-6,9.9969435,9.9969435,-26626.509765625,-26606.548828125,56.3655774072944,20.5925119975384,12.278775,0,0,0,40,4449,10.0316,-26616.529296875,,,,,,,,,,,,,0,,,,0,,,,,,9.9969435,,,,
,23124369.025,9.9970036,-31226.966796875,4.06839530277362E-5,6.75802201917811E-7,1,0.999253354069792,40.0298881530762,1.98449784307049,16.8699994683266,0.000451800896803682,0.000102016244147938,0.25,1.80504503309244E-6,4.05475749322225E-5,2.07709829949982E-6,9.9970036,9.9970036,-31234.58203125,-31219.3515625,56.9205336559483,20.589417182738,12.278775,0,0,0,40,4449,10.03445,-31226.966796875,,,,,,,,,,,,,0,,,,0,,,,,,9.9970036,,,,
,23124459.775,9.9960985,-35764.119140625,3.90609188981295E-5,8.42034845194621E-7,1,0.999253354069792,40.0298881530762,1.98447641436756,16.8699994683266,0.00043400464280317,9.78462675786285E-5,0.25,1.71269592010961E-6,3.89485642302869E-5,1.98220756414332E-6,9.9960985,9.9960985,-35776.5078125,-35751.73046875,56.8408075469868,20.5873884714553,11.519473,0,0,0,40,4449,10.0359,-35764.119140625,,,,,,,,,,,,,0,,,,-0.00245,,,,,,9.9960985,,,,
,23124551.995,9.9960289,-40371.419921875,4.5754644396442E-5,6.31325178114722E-7,1,0.999253354069792,40.0298881530762,1.98445348806009,16.8699994683266,0.000505669128634461,0.000131058017374716,0.25,3.46204244027843E-6,4.56346480006506E-5,3.78279407952409E-6,9.9960289,9.9960289,-40378.8359375,-40364.00390625,56.8267382336406,20.5904222038292,11.899124,0,0,0,40,4449,10.03995,-40371.419921875,,,,,,,,,,,,,0,,,,-0.00245,,,,,,9.9960289,,,,
,23124642.025,9.9956217,-44871.89453125,5.53486670828063E-5,7.95620182676675E-7,1,0.999253354069792,40.0298881530762,1.98452044765204,16.8800000101328,0.000612914392082888,0.000153567268985844,0.25,3.73115490837028E-6,5.52325246419741E-5,4.12829518708894E-6,9.9956217,9.9956217,-44876.8515625,-44866.9375,56.2522412720059,20.5977883002382,12.278775,0,0,0,40,4449,10.0444,-44871.89453125,,,,,,,,,,,,,0,,,,0,,,,,,9.9956217,,,,
,23124732.61,9.9960585,-49401.919921875,6.7007170487138E-5,8.14354370630644E-7,1,0.999253354069792,40.0298881530762,1.98438789220067,16.8699994683266,0.000744403434064835,0.000174389242593365,0.25,3.47736869931249E-6,6.69051556137493E-5,3.96702041951431E-6,9.9960585,9.9960585,-49414.58203125,-49389.2578125,56.861911517006,20.591801091784,12.278775,0,0,0,40,4449,10.04675,-49401.919921875,,,,,,,,,,,,,0,,,,0,,,,,,9.9960585,,,,
,23124825.415,9.9950018,-54038.97265625,8.04681187790131E-5,8.96586058268661E-7,1,0.999253354069792,40.0298881530762,1.98427645785433,16.8699994683266,0.000892436422840484,0.000219914070107743,0.25,5.0995381458089E-6,8.03759955256896E-5,5.69310756325009E-6,9.9949017,9.9951019,-54046.328125,-54031.6171875,56.7415407250445,20.5981709259712,11.899124,0,0,0,40,4449,10.0507,-54038.97265625,,,,,,,,,,,,,0,,,,-0.00245,,,,,,9.9950018,,,,
,23124916.35,9.9959679,-58581.322265625,9.44854104694837E-5,7.79773281321465E-7,1,0.999253354069792,40.0298881530762,1.98422880669721,16.8699994683266,0.00105202575746558,0.000237842771684726,0.25,4.1606054888387E-6,9.44323353235399E-5,4.86278009288878E-6,9.9959679,9.9959679,-58588.890625,-58573.75390625,56.3053920113137,20.5977485068777,12.278775,0,0,0,40,4449,10.05525,-58581.322265625,,,,,,,,,,,,,0,,,,0.00245,,,,,,9.9959679,,,,
,23125008.145,9.9949713,-63171.5390625,0.000109364485581217,9.01971219360759E-7,1,0.999253354069792,40.0298881530762,1.9843775958957,16.8699994683266,0.00122144477112588,0.000257997695575957,0.25,3.26362287929862E-6,0.000109361391720199,4.07780442522192E-6,9.9949713,9.9949713,-63176.33203125,-63166.74609375,56.7079306987175,20.5946208485489,11.899124,0,0,0,40,4449,10.05915,-63171.5390625,,,,,,,,,,,,,0,,,,0.00245,,,,,,9.9949713,,,,
,23125105.405,9.9954901,-68031.0859375,0.000125175175202958,1.02045081530628E-6,1,0.999253354069792,40.0298881530762,1.9841269454485,16.8699994683266,0.00139347536157278,0.000323067756691061,0.25,6.20358601510147E-6,0.000125207522087691,7.13512122622482E-6,9.9954901,9.9954901,-68038.5859375,-68023.5859375,57.0674798175637,20.5990415534094,11.899124,0,0,0,40,4449,10.0637,-68031.0859375,,,,,,,,,,,,,0,,,,0,,,,,,9.9954901,,,,
,23125205.855,9.994628,-73050.42578125,0.000142043876555204,1.15448458032742E-6,1,0.999253354069792,40.0298881530762,1.98422239901084,16.8699994683266,0.00158215911816592,0.000365923849178031,0.25,6.97150053071308E-6,0.000142141480544013,8.02408311349987E-6,9.994628,9.994628,-73060.359375,-73040.4921875,57.0080760501022,20.5987042847129,11.899124,0,0,0,40,4449,10.06955,-73050.42578125,,,,,,,,,,,,,0,,,,0,,,,,,9.994628,,,,
,23125306.055,9.9946909,-78059.76953125,0.000155805238883811,8.32535052856757E-7,1,0.999253354069792,40.0298881530762,1.98422586216085,16.8699994683266,0.00173690144082945,0.000397294703416692,0.25,7.28125374735315E-6,0.000155977429287602,8.42716767688788E-6,9.9946909,9.9946909,-78062.28125,-78057.2578125,56.7524835243137,20.5990877560888,12.278775,0,0,0,40,4449,10.07365,-78059.76953125,,,,,,,,,,,,,0,,,,0,,,,,,9.9946909,,,,
,23125406.53,9.9949331,-83081.80859375,0.000178735590241521,1.03017232652873E-6,1,0.999253354069792,40.0298881530762,1.98416253562706,16.8699994683266,0.00199410296914618,0.000451002880438864,0.25,7.93153852873643E-6,0.000179003741424277,9.23272227432765E-6,9.9949331,9.9949331,-83089.5234375,-83074.09375,56.6751023009098,20.6015605009036,12.278775,0,0,0,40,4449,10.07975,-83081.80859375,,,,,,,,,,,,,0,,,,0.00245,,,,,,9.9949331,,,,
,23125500.795,9.994092,-87791.08984375,0.000192344548629908,8.63768442854886E-7,1,0.999253354069792,40.0298881530762,1.98417493054114,16.8699994683266,0.00214857477229012,0.000474858887864632,0.25,7.60769242660803E-6,0.000192703783751993,8.99057113227634E-6,9.994092,9.994092,-87805.9453125,-87776.234375,56.3757385780444,20.6004679692359,12.278775,0,0,0,40,4449,10.08355,-87791.08984375,,,,,,,,,,,,,0,,,,-0.00245,,,,,,9.994092,,,,
,23125614.82,9.9971094,-87665.84375,0.000190750410049898,1.02470595757459E-6,1,0.999253354069792,40.0298881530762,1.98406915774367,16.8699994683266,0.00213257107348947,0.000460164924618643,0.25,6.59030004350041E-6,0.000191111812168515,7.96011564229131E-6,9.9971094,9.9971094,-87673.2421875,-87658.4453125,56.7782772654483,20.6032508615509,11.899124,0,0,0,40,4449,10.0874,-87665.84375,,,,,,,,,,,,,0,,,,0.00245,,,,,,9.9971094,,,,
,23125710.14,9.9996209,-82903.80859375,0.00017328923607515,8.56215510495597E-7,1,0.999253354069792,40.0298881530762,1.9841764911766,16.8699994683266,0.00194110727451916,0.000394033714572618,0.25,3.84594354036417E-6,0.000173574649495109,5.10101659448631E-6,9.9995298,9.999712,-82911.3359375,-82896.28125,55.8606453838713,20.6003921901656,11.899124,0,0,0,40,4449,10.08635,-82903.80859375,,,,,,,,,,,,,0,,,,0,,,,,,9.9996209,,,,
,23125811.665,10.0020876,-77831.921875,0.000161280277021017,8.31695467755061E-7,1,0.999253354069792,40.0298881530762,1.98423548273095,16.8699994683266,0.00180305145264896,0.000382717564808026,0.25,4.99853877831072E-6,0.000161474167532835,6.18154848720473E-6,10.0020876,10.0020876,-77844.2734375,-77819.5703125,56.6641595016406,20.6039257613788,11.519473,0,0,0,40,4449,10.0838,-77831.921875,,,,,,,,,,,,,0,,,,0.0049,,,,,,10.0020876,,,,
,23125914.72,10.0026016,-72679.6484375,0.000144323874454416,7.61005471085373E-7,1,0.999253354069792,40.0298881530762,1.98391535640194,16.8699994683266,0.00161139862936419,0.000348804695473617,0.25,5.04224657984433E-6,0.000144433655477667,6.1100899790322E-6,10.0026016,10.0026016,-72692.1796875,-72667.1171875,56.4265444317944,20.6112361028403,11.899124,0,0,0,40,4449,10.08095,-72679.6484375,,,,,,,,,,,,,0,,,,0,,,,,,10.0026016,,,,
,23126014.345,10.0029564,-67702.78515625,0.000123444724359282,9.60914677708723E-7,1,0.999253354069792,40.0298881530762,1.98291778315489,16.8699994683266,0.00137857712968177,0.00028952611577388,0.25,3.54471830107065E-6,0.00012349216583261,4.46198908608292E-6,10.0029564,10.0029564,-67709.875,-67695.6953125,56.6344576179098,20.6319152375337,11.899124,0,0,0,40,4449,10.07645,-67702.78515625,,,,,,,,,,,,,0,,,,-0.0049,,,,,,10.0029564,,,,
,23126114.805,10.0034361,-62680.83203125,0.000106882455417248,9.80850441465427E-7,1,0.999253354069792,40.0298881530762,1.98299804781462,16.8699994683266,0.00119191357033312,0.000257312781846782,0.25,3.66606762440453E-6,0.000106871088252768,4.46185599868489E-6,10.0034361,10.0034361,-62688.69921875,-62672.96484375,56.6641595016406,20.6272825763088,11.519473,0,0,0,40,4449,10.07455,-62680.83203125,,,,,,,,,,,,,0,,,,0.00245,,,,,,10.0034361,,,,
,23126215.02,10.0035772,-57670.685546875,8.98536699715339E-5,1.01992718052587E-6,1,0.999253354069792,40.0298881530762,1.98318083957404,16.8699994683266,0.00100503306273609,0.000197367007733623,0.25,1.39966240528656E-6,8.98144095892845E-5,2.06767676988693E-6,10.0035772,10.0035772,-57675.66015625,-57665.7109375,56.5344091674483,20.6217491507754,11.519473,0,0,0,40,4449,10.0696,-57670.685546875,,,,,,,,,,,,,0,,,,0,,,,,,10.0035772,,,,
,23126315.07,10.0039291,-52671.515625,7.67027081036527E-5,7.06538405642153E-7,1,0.999253354069792,40.0298881530762,1.98319238448444,16.8699994683266,0.000854834149436435,0.000183311253269853,0.25,2.52713792095754E-6,7.66218286257565E-5,3.09322188488803E-6,10.0039291,10.0039291,-52678.765625,-52664.265625,56.4335790884675,20.6251581406595,11.519473,0,0,0,40,4449,10.0663,-52671.515625,,,,,,,,,,,,,0,,,,0,,,,,,10.0039291,,,,
,23126416.22,10.004509,-47617.044921875,5.72237663671069E-5,9.71069380121591E-7,1,0.999253354069792,40.0298881530762,1.98348933593391,16.8699994683266,0.000635457808495399,0.000148104686116598,0.25,2.9059795812306E-6,5.71267377942987E-5,3.32203138182095E-6,10.004509,10.004509,-47621.890625,-47612.19921875,56.8939582862945,20.618737940395,11.899124,0,0,0,40,4449,10.063,-47617.044921875,,,,,,,,,,,,,0,,,,0,,,,,,10.004509,,,,
,23126518.235,10.0065088,-42517.162109375,4.30024571772259E-5,8.09448843257748E-7,1,0.999253354069792,40.0298881530762,1.98318777573701,16.8699994683266,0.000478224954773829,0.00010559746510051,0.25,1.68613002924152E-6,4.2910545218084E-5,1.99379282570677E-6,10.0060577,10.0069599,-42524.66015625,-42509.6640625,56.6360208749483,20.621088650855,11.519473,0,0,0,40,4449,10.05935,-42517.162109375,,,,,,,,,,,,,0,,,,0,,,,,,10.0065088,,,,
,23126618.015,10.0044765,-37530.091796875,2.78890001688989E-5,6.98340489784767E-7,1,0.999253354069792,40.0298881530762,1.9833838828046,16.8699994683266,0.000306928656155995,8.56229109818799E-5,0.25,2.63110883658547E-6,2.78039662936405E-5,2.82219639495459E-6,10.0044765,10.0044765,-37537.44921875,-37522.734375,56.4445218877367,20.6151101473662,11.519473,0,0,0,40,4449,10.0527,-37530.091796875,,,,,,,,,,,,,0,,,,0,,,,,,10.0044765,,,,
,23126709.96,10.0056162,-32935.556640625,1.44155249775071E-5,7.12958392104573E-7,1,0.999253354069792,40.0298881530762,1.98318680334736,16.8699994683266,0.000158385825471716,4.51903370289627E-5,0.25,1.44815126933477E-6,1.43641778269803E-5,1.54343851169404E-6,10.0056162,10.0056162,-32940.5078125,-32930.60546875,56.4499932873714,20.6186668849946,12.278775,0,0,0,40,4449,10.04965,-32935.556640625,,,,,,,,,,,,,0,,,,0,,,,,,10.0056162,,,,
,23126802.915,10.0037098,-28290.76953125,2.41267758780071E-6,4.43684062204306E-7,1,0.999253354069792,40.0298881530762,1.9837361032759,16.8699994683266,2.26978363369008E-5,2.87624554345899E-5,0.25,2.1380024232112E-6,2.390296722358E-6,2.14694004310687E-6,10.0037098,10.0037098,-28297.99609375,-28283.54296875,56.5250296252175,20.6116622080564,11.899124,0,0,0,40,4449,10.04565,-28290.76953125,,,,,,,,,,,,,0,,,,-0.0049,,,,,,10.0037098,,,,
,23126895.13,10.0036516,-23681.17578125,-1.20996922973157E-5,4.810946145861E-7,1,0.999253354069792,40.0298881530762,1.98364912824951,16.8699994683266,-0.000137982610755532,-9.25852072550313E-6,0.25,1.34057827765702E-6,-1.20619551614167E-5,1.25770176706275E-6,10.0036516,10.0036516,-23686.208984375,-23676.142578125,56.8345545188329,20.6148124913556,11.899124,0,0,0,40,4449,10.0426,-23681.17578125,,,,,,,,,,,,,0,,,,0,,,,,,10.0036516,,,,
,23126987.93,10.0030947,-19042.9990234375,-2.61039868632668E-5,4.79896020882603E-7,1,0.999253354069792,40.0298881530762,1.98353710625539,16.8699994683266,-0.000292339269511725,-4.892950047198E-5,0.25,2.92876008204387E-7,-2.59938412421184E-5,1.31485325884914E-7,10.0030947,10.0030947,-19053.02734375,-19032.970703125,56.4070037188137,20.6171739053509,11.519473,0,0,0,40,4449,10.0398,-19042.9990234375,,,,,,,,,,,,,0,,,,0.00245,,,,,,10.0030947,,,,
,23127082.195,10.0032072,-14333.3251953125,-3.98757528606614E-5,4.51798772768644E-7,1,0.999253354069792,40.0298881530762,1.98361500836751,16.8699994683266,-0.000445175361174509,-8.1502627389562E-5,0.25,-1.73202001594161E-7,-3.9686320955423E-5,-4.04061981945369E-7,10.0032072,10.0032072,-14341.01953125,-14325.630859375,57.4223391652945,20.6094829097712,12.278775,0,0,0,40,4449,10.0375,-14333.3251953125,,,,,,,,,,,,,0,,,,-0.0049,,,,,,10.0032072,,,,
,23127175.11,10.0027027,-9688.24951171875,-5.30349157690778E-5,3.32239778952276E-7,1,0.999253354069792,40.0298881530762,1.98386864949423,16.8699994683266,-0.000592238638919131,-0.000106595840031631,0.25,-8.95647621334534E-8,-5.27629078915537E-5,-3.79258003389101E-7,10.0027027,10.0027027,-9693.669921875,-9682.8291015625,57.0385595623522,20.6094978373373,11.899124,0,0,0,40,4449,10.03525,-9688.24951171875,,,,,,,,,,,,,0,,,,0,,,,,,10.0027027,,,,
,23127267.72,10.0041723,-5059.93920898438,-6.43411611555412E-5,3.25157399193274E-7,1,0.999253354069792,40.0298881530762,1.98408400753566,16.8699994683266,-0.000717338156546347,-0.000134807708415716,0.25,-6.24617719963076E-7,-6.39863958099489E-5,-9.51396242631985E-7,10.0041723,10.0041723,-5064.85986328125,-5055.0185546875,56.4179465180829,20.6060152980223,11.899124,0,0,0,40,4449,10.0306,-5059.93920898438,,,,,,,,,,,,,0,,,,0,,,,,,10.0041723,,,,
,23127357.775,10.010004,-555.8154296875,-7.39932367819472E-5,3.19820187258846E-7,1,0.999253354069792,40.0298881530762,1.98407560836007,16.8699994683266,-0.00082432084592476,-0.000157294101113817,0.25,-9.46126855330158E-7,-7.35650311415241E-5,-1.29903722963677E-6,10.010004,10.010004,-560.987976074219,-550.642883300781,56.3460366943136,20.601926730022,11.899124,0,0,0,40,4449,10.0208,-555.8154296875,,,,,,,,,,,,,0,,,,0,,,,,,10.010004,,,,
,23127448.805,9.999135,3987.55822753906,-7.53815626780206E-5,3.27572440561326E-7,1,0.999253354069792,40.0298881530762,1.98399173947251,16.8699994683266,-0.000839074335169641,-0.000164985577920775,0.25,-1.37007791398311E-6,-7.49574130659979E-5,-1.74365746123343E-6,9.999135,9.999135,3977.51904296875,3997.59741210937,56.5047072837175,20.6000917033495,11.519473,0,0,0,40,4449,10.0239,3987.55822753906,,,,,,,,,,,,,0,,,,-0.0049,,,,,,9.999135,,,,
,23127540.31,9.9967241,8563.638671875,-8.4295390998609E-5,4.3769359850841E-7,1,0.999253354069792,40.0298881530762,1.98415402342649,16.8699994683266,-0.000938721448785341,-0.000184290689249021,0.25,-1.47921224427355E-6,-8.38483839254382E-5,-1.92567054540205E-6,9.9967241,9.9967241,8556.28125,8570.99609375,55.7934253312174,20.5969732896933,11.899124,0,0,0,40,4449,10.0288,8563.638671875,,,,,,,,,,,,,0,,,,0.0049,,,,,,9.9967241,,,,
,23127631.115,9.9972467,13101.9609375,-8.7404815174546E-5,4.29207687930746E-7,1,0.999253354069792,40.0298881530762,1.98428354973409,16.8699994683266,-0.000972209329159724,-0.000199923954685838,0.25,-2.28781379582194E-6,-8.6969227499682E-5,-2.77683491912653E-6,9.9972467,9.9972467,13094.5361328125,13109.3857421875,55.9763264047175,20.5952128851371,12.278775,0,0,0,40,4449,10.0322,13101.9609375,,,,,,,,,,,,,0,,,,0,,,,,,9.9972467,,,,
,23127719.89,9.9969931,17537.51171875,-8.3918606791668E-5,4.86018448354379E-7,1,0.999253354069792,40.0298881530762,1.98411023638185,16.8699994683266,-0.000933643678739205,-0.000192468559712411,0.25,-2.2114291776008E-6,-8.35333817812485E-5,-2.70796137874446E-6,9.9969931,9.9969931,17532.533203125,17542.490234375,56.4030955762175,20.5973565523796,11.899124,0,0,0,40,4449,10.03505,17537.51171875,,,,,,,,,,,,,0,,,,-0.00245,,,,,,9.9969931,,,,
,23127812.315,9.9968958,22159.7216796875,-6.86732481096226E-5,4.69947116558213E-7,1,0.999253354069792,40.0298881530762,1.98421001260514,16.8699994683266,-0.000762470247368156,-0.000168388328724235,0.25,-2.7556075867155E-6,-6.83822521286131E-5,-3.17956217157294E-6,9.9968958,9.9968958,22149.7734375,22169.669921875,56.3108634109483,20.5966175938256,11.519473,0,0,0,40,4449,10.0361,22159.7216796875,,,,,,,,,,,,,0,,,,0.0049,,,,,,9.9968958,,,,
,23127904.705,9.997879,26775.3359375,-5.11944883024216E-5,5.89513198626081E-7,1,0.999253354069792,40.0298881530762,1.98416368177644,16.8699994683266,-0.000567163350357737,-0.000133903046174767,0.25,-2.7841665083191E-6,-5.0996190115435E-5,-3.11225814239006E-6,9.997879,9.997879,26767.6484375,26783.0234375,56.9580518248714,20.5984883856911,11.519473,0,0,0,40,4449,10.0393,26775.3359375,,,,,,,,,,,,,0,,,,0,,,,,,9.997879,,,,
,23127994.875,9.9972153,31283.2578125,-4.08017876649847E-5,7.10298074405673E-7,1,0.999253354069792,40.0298881530762,1.98415982373847,16.8699994683266,-0.000449584655509043,-0.000121522141665705,0.25,-3.52795361772411E-6,-4.06535290388076E-5,-3.79568333612565E-6,9.9972153,9.9972153,31275.828125,31290.6875,55.9044165809482,20.5956673786935,11.899124,0,0,0,40,4449,10.0398,31283.2578125,,,,,,,,,,,,,0,,,,-0.00245,,,,,,9.9972153,,,,
,23128087.635,9.9972525,35918.19921875,-4.14523403091954E-5,6.86935491229341E-7,1,0.999253354069792,40.0298881530762,1.98409376924884,16.8699994683266,-0.000455889777361637,-0.000129446035746904,0.25,-4.10595582623375E-6,-4.1317714077283E-5,-4.38639678410889E-6,9.9972525,9.9972525,35908.18359375,35928.21484375,56.238953587179,20.5949168657199,11.899124,0,0,0,40,4449,10.0443,35918.19921875,,,,,,,,,,,,,0,,,,0,,,,,,9.9972525,,,,
,23128177.875,9.9968662,40428.798828125,-4.52918623825676E-5,7.85407584960378E-7,1,0.999253354069792,40.0298881530762,1.98396734473595,16.8699994683266,-0.00050212732051907,-0.000120330385963524,0.25,-2.5902560325352E-6,-4.51793476820683E-5,-2.90959671914165E-6,9.9968662,9.9968662,40421.19140625,40436.40625,56.2717819849867,20.595428251862,11.519473,0,0,0,40,4449,10.0464,40428.798828125,,,,,,,,,,,,,0,,,,-0.0049,,,,,,9.9968662,,,,
,23128269.955,9.9959669,45031.576171875,-5.57342206967512E-5,8.44327188017774E-7,1,0.999253354069792,40.0298881530762,1.98422908176251,16.8699994683266,-0.000618780055723743,-0.000145331160122397,0.25,-2.92840865420395E-6,-5.56242226858674E-5,-3.32989059006252E-6,9.9959669,9.9959669,45024.04296875,45039.109375,56.2702187279483,20.5899406169781,11.519473,0,0,0,40,4449,10.0507,45031.576171875,,,,,,,,,,,,,0,,,,-0.0049,,,,,,9.9959669,,,,
,23128363.11,9.9959774,49686.9921875,-6.91244685603443E-5,8.85738722514641E-7,1,0.999253354069792,40.0298881530762,1.98417151992468,16.8699994683266,-0.000769701993889951,-0.000169704056571846,0.25,-2.67894573157469E-6,-6.9027916426813E-5,-3.18546967402867E-6,9.9958305,9.9961243,49676.92578125,49697.05859375,56.0521443710829,20.5918686483867,11.519473,0,0,0,40,4449,10.0542,49686.9921875,,,,,,,,,,,,,0,,,,0,,,,,,9.9959774,,,,
,23128458.14,9.9955215,54436.810546875,-8.09195970606612E-5,9.1908390421939E-7,1,0.999253354069792,40.0298881530762,1.98413666679545,16.8699994683266,-0.000897033379126787,-0.000223277172768757,0.25,-5.31827829912679E-6,-8.08287047340195E-5,-5.91550777381764E-6,9.9955215,9.9955215,54434.2734375,54439.34765625,56.4578095725637,20.5943576026256,12.278775,0,0,0,40,4449,10.0569,54436.810546875,,,,,,,,,,,,,0,,,,0.0049,,,,,,9.9955215,,,,
,23128555.115,9.9950886,59284.40625,-9.63214769741884E-5,9.27866697502744E-7,1,0.999253354069792,40.0298881530762,1.98403400294276,16.8699994683266,-0.00107000586043535,-0.000255961828041102,0.25,-5.44461297941143E-6,-9.62648354553555E-5,-6.16062495438475E-6,9.9950886,9.9950886,59281.9765625,59286.8359375,55.8606453838713,20.5948648508108,11.519473,0,0,0,40,4449,10.0625,59284.40625,,,,,,,,,,,,,0,,,,-0.0049,,,,,,9.9950886,,,,
,23128652.92,9.9952383,64172.43359375,-0.000112717585391276,8.50967634093897E-7,1,0.999253354069792,40.0298881530762,1.98404786349229,16.8699994683266,-0.00124887731423708,-0.000320990044437809,0.25,-8.27149149198602E-6,-0.000112688150701915,-9.11190892939936E-6,9.9952383,9.9952383,64165.125,64179.7421875,56.465625857756,20.5959887275415,11.519473,0,0,0,40,4449,10.068,64172.43359375,,,,,,,,,,,,,0,,,,0.0049,,,,,,9.9952383,,,,
,23128750.165,9.9956675,69032.77734375,-0.000129514934789111,9.33979148020668E-7,1,0.999253354069792,40.0298881530762,1.98388634096506,16.8699994683266,-0.0014367984084605,-0.000361704652191585,0.25,-8.86337939264238E-6,-0.000129541536440806,-9.82838681708878E-6,9.9956675,9.9956675,69027.765625,69037.7890625,56.157664221179,20.5970227339507,12.278775,0,0,0,40,4449,10.07015,69032.77734375,,,,,,,,,,,,,0,,,,0,,,,,,9.9956675,,,,
,23128846.46,9.9951572,73845.04296875,-0.000146328739106168,7.43239048522728E-7,1,0.999253354069792,40.0298881530762,1.98396150447097,16.8699994683266,-0.00163085970442593,-0.00037098721800956,0.25,-6.65367255728821E-6,-0.000146442704061357,-7.73640024943962E-6,9.9951572,9.9951572,73839.5859375,73850.5,55.9989936317752,20.5968193095817,11.519473,0,0,0,40,4449,10.0749,73845.04296875,,,,,,,,,,,,,0,,,,-0.00245,,,,,,9.9951572,,,,
,23128946.575,9.9945421,78850.80859375,-0.000159848972793504,1.00796420251488E-6,1,0.999253354069792,40.0298881530762,1.98385697027136,16.8699994683266,-0.00178148584456148,-0.000409151724606647,0.25,-7.6140931420507E-6,-0.000160034356970292,-8.78835940693087E-6,9.9945421,9.9945421,78838.546875,78863.0703125,56.3851181202752,20.5967033910273,11.899124,0,0,0,40,4449,10.0801,78850.80859375,,,,,,,,,,,,,0,,,,0.0049,,,,,,9.9945421,,,,
,23129045.025,9.9948673,83771.65234375,-0.000176617349500744,1.04708638628847E-6,1,0.999253354069792,40.0298881530762,1.98379864260246,16.8699994683266,-0.00196660860421558,-0.000465687688204612,0.25,-9.6260871913468E-6,-0.000176878314313657,-1.09132521494713E-5,9.9948673,9.9948673,83766.0859375,83777.21875,56.8267382336406,20.5997272721945,11.899124,0,0,0,40,4449,10.08475,83771.65234375,,,,,,,,,,,,,0,,,,-0.00245,,,,,,9.9948673,,,,
,23129138.825,9.9947929,88459.796875,-0.000193396522961852,1.0575070631278E-6,1,0.999253354069792,40.0298881530762,1.98392259887296,16.8699994683266,-0.00215485914946257,-0.000506897906641966,0.25,-1.02724797194894E-5,-0.000193747941050232,-1.1666267899342E-5,9.9947929,9.9947929,88449.609375,88469.984375,57.1636201254291,20.5962761322837,11.519473,0,0,0,40,4449,10.08875,88459.796875,,,,,,,,,,,,,0,,,,-0.0049,,,,,,9.9947929,,,,
,23129252.15,9.99828765,86985.98828125,-0.000188283095797482,1.39307302599343E-6,1,0.999253354069792,40.0298881530762,1.98385636372715,16.8800000101328,-0.00209650799402663,-0.000499530589976487,0.25,-1.05372549069271E-5,-0.000188602300452826,-1.190017580197E-5,9.9982595,9.9983158,86973.6328125,86998.34375,56.1396867652367,20.5997296278807,11.899124,0,0,0,40,4449,10.0914,86985.98828125,,,,,,,,,,,,,0,,,,0.00245,,,,,,9.99828765,,,,
,23129348.36,10.0009241,82177.63671875,-0.000172616944554746,1.35009035653377E-6,1,0.999253354069792,40.0298881530762,1.98372987668813,16.8699994683266,-0.00192488065210817,-0.00043783250493699,0.25,-7.86943438200957E-6,-0.000172862958583329,-9.12885860033849E-6,10.0009241,10.0009241,82170.1171875,82185.15625,56.360887636179,20.5999330998328,11.899124,0,0,0,40,4449,10.0898,82177.63671875,,,,,,,,,,,,,0,,,,0.0049,,,,,,10.0009241,,,,
,23129450.675,10.0025616,77061.4375,-0.000154026374221466,9.90834302602541E-7,1,0.999253354069792,40.0298881530762,1.98375751613349,16.8699994683266,-0.00171307767588192,-0.000411920693560085,0.25,-8.9111612254821E-6,-0.00015417207473015,-1.0048192914388E-5,10.0025616,10.0025616,77051.734375,77071.140625,56.2960124690829,20.5999236228015,12.278775,0,0,0,40,4449,10.08645,77061.4375,,,,,,,,,,,,,0,,,,0.00245,,,,,,10.0025616,,,,
,23129550.475,10.0035477,72073.12109375,-0.000137908385586373,1.00048129032097E-6,1,0.999253354069792,40.0298881530762,1.98374864438396,16.8699994683266,-0.00153615732945303,-0.000352185829348964,0.25,-6.50203533501092E-6,-0.000137993945593306,-7.52479675018413E-6,10.0035477,10.0035477,72063.2578125,72082.984375,56.4703156288714,20.5986645027938,12.278775,0,0,0,40,4449,10.08165,72073.12109375,,,,,,,,,,,,,0,,,,0.00245,,,,,,10.0035477,,,,
,23129653.89,10.003315,66905.0625,-0.000121232491114627,8.50994359549416E-7,1,0.999253354069792,40.0298881530762,1.98376361851761,16.8699994683266,-0.00134491400913569,-0.000336674944266308,0.25,-8.13258758876862E-6,-0.000121236108007101,-9.03635390702854E-6,10.0032206,10.0034094,66895.46875,66914.65625,55.9028533239098,20.5993258712172,11.899124,0,0,0,40,4449,10.0779,66905.0625,,,,,,,,,,,,,0,,,,0.0049,,,,,,10.003315,,,,
,23129749.585,10.0041943,62119.376953125,-0.00010867505361742,1.04393997895559E-6,1,0.999253354069792,40.0298881530762,1.98386927993105,16.8699994683266,-0.0012085557748473,-0.000282774724742613,0.25,-5.60262816062067E-6,-0.000108643933070077,-6.41190050429E-6,10.0041943,10.0041943,62106.90234375,62131.8515625,55.9599122058136,20.5993227601642,11.899124,0,0,0,40,4449,10.0744,62119.376953125,,,,,,,,,,,,,0,,,,0,,,,,,10.0041943,,,,
,23129850.18,10.0041037,57093.990234375,-8.97705605139792E-5,8.31193437977055E-7,1,0.999253354069792,40.0298881530762,1.98395210730741,16.8699994683266,-0.000995543071063186,-0.000246499461871449,0.25,-5.78813643072526E-6,-8.96937124999149E-5,-6.45361749193737E-6,10.0041037,10.0041037,57088.796875,57099.18359375,56.5664559367368,20.5984751826015,12.278775,0,0,0,40,4449,10.0707,57093.990234375,,,,,,,,,,,,,0,,,,0,,,,,,10.0041037,,,,
,23129952.115,10.0044127,51996.609375,-7.27227969826172E-5,7.97092746718162E-7,1,0.999253354069792,40.0298881530762,1.98385526284031,16.8699994683266,-0.00080285704306096,-0.000217270132941442,0.25,-6.26896601937055E-6,-7.26125638337095E-5,-6.80160382144388E-6,10.0044127,10.0044127,51981.58203125,52011.63671875,56.0552708851598,20.5981673779933,11.899124,0,0,0,40,4449,10.06715,51996.609375,,,,,,,,,,,,,0,,,,0,,,,,,10.0044127,,,,
,23130053.11,10.0039434,46949.37109375,-5.79430987041424E-5,9.55194539322301E-7,1,0.999253354069792,40.0298881530762,1.98400058475621,16.8699994683266,-0.000640398593292588,-0.000167544055671752,0.25,-4.50892707184689E-6,-5.78294224033533E-5,-4.92712705337665E-6,10.0039434,10.0039434,46939.2890625,46959.453125,56.5430070811598,20.5990100427879,12.278775,0,0,0,40,4449,10.06265,46949.37109375,,,,,,,,,,,,,0,,,,0,,,,,,10.0039434,,,,
,23130154.105,10.0043287,41901.408203125,-4.02082112081676E-5,8.06674034976092E-7,1,0.999253354069792,40.0298881530762,1.98390219940697,16.8699994683266,-0.000443005003696514,-0.000122485360149749,0.25,-3.69464397032065E-6,-4.01044183356416E-5,-3.97749410000856E-6,10.0043287,10.0043287,41891.40625,41911.41015625,55.9778896617559,20.5968027986477,11.899124,0,0,0,40,4449,10.05935,41901.408203125,,,,,,,,,,,,,0,,,,0,,,,,,10.0043287,,,,
,23130253.395,10.0032787,36938.96875,-2.5008530478928E-5,9.37371938529439E-7,1,0.999253354069792,40.0298881530762,1.98404361052201,16.8699994683266,-0.000271074945112043,-0.000100281312852249,0.25,-4.45681795734102E-6,-2.49159598751453E-5,-4.62237480988925E-6,10.0032787,10.0032787,36933.94140625,36943.99609375,55.8160925582751,20.5946245217566,11.899124,0,0,0,40,4449,10.05505,36938.96875,,,,,,,,,,,,,0,,,,0,,,,,,10.0032787,,,,
,23130350.235,10.0049381,32099.2421875,-9.73032227039459E-6,9.10345158412303E-7,1,0.999253354069792,40.0298881530762,1.98429135748228,16.8699994683266,-0.000104134609005968,-4.62221476239701E-5,0.25,-2.38084704649248E-6,-9.68520908289513E-6,-2.44057274666761E-6,10.0049381,10.0049381,32091.404296875,32107.080078125,56.2061251893713,20.5934642710754,11.899124,0,0,0,40,4449,10.05135,32099.2421875,,,,,,,,,,,,,0,,,,0.00245,,,,,,10.0049381,,,,
,23130440.62,10.0043736,27582.0791015625,3.58309355390711E-6,4.40796910503195E-7,1,0.999253354069792,40.0298881530762,1.98406168504005,16.8699994683266,4.40511918825904E-5,-1.48922994691625E-5,0.25,-1.97406996815584E-6,3.58391331489719E-6,-1.9434953363942E-6,10.0043736,10.0043736,27574.560546875,27589.59765625,55.9771080332367,20.5948880813281,11.519473,0,0,0,40,4449,10.0468,27582.0791015625,,,,,,,,,,,,,0,,,,-0.00245,,,,,,10.0043736,,,,
,23130534.795,10.0036812,22874.1591796875,1.59048995435119E-5,5.17173686340399E-7,1,0.999253354069792,40.0298881530762,1.9839808919368,16.8699994683266,0.000181001176750041,1.4339212413259E-5,0.25,-1.56752311536863E-6,1.58526769822287E-5,-1.45996777618821E-6,10.0036812,10.0036812,22866.501953125,22881.81640625,56.4687523718329,20.5987787821906,11.899124,0,0,0,40,4449,10.04355,22874.1591796875,,,,,,,,,,,,,0,,,,-0.0049,,,,,,10.0036812,,,,
,23130626.19,10.0032072,18306.56640625,2.91039919336458E-5,5.36058692626887E-7,1,0.999253354069792,40.0298881530762,1.98389959287759,16.8699994683266,0.000329309226051334,3.58906082934232E-5,0.25,-1.9951818492842E-6,2.89892775430089E-5,-1.80937273897905E-6,10.0032072,10.0032072,18299.009765625,18314.123046875,55.6175589143905,20.5991077292211,11.519473,0,0,0,40,4449,10.0421,18306.56640625,,,,,,,,,,,,,0,,,,0,,,,,,10.0032072,,,,
,23130716.765,10.0034657,13781.58984375,4.20880827394363E-5,4.04449832971053E-7,1,0.999253354069792,40.0298881530762,1.98398027565423,16.8699994683266,0.000471879206449293,7.51380872503896E-5,0.25,-7.90742082673859E-7,4.18917062300554E-5,-5.44098862561453E-7,10.0034657,10.0034657,13771.9033203125,13791.2763671875,56.3421285517175,20.5989564894236,11.519473,0,0,0,40,4449,10.03865,13781.58984375,,,,,,,,,,,,,0,,,,0.0049,,,,,,10.0034657,,,,
,23130807.835,10.0038071,9229.30224609375,5.41310112437799E-5,3.34320430525171E-7,1,0.999253354069792,40.0298881530762,1.98390554474573,16.8699994683266,0.000606302118636035,9.85000856411654E-5,0.25,-8.2855391398476E-7,5.38564075383379E-5,-5.29971397657957E-7,10.0038071,10.0038071,9224.3779296875,9234.2265625,56.7368509539291,20.6002108752925,12.278775,0,0,0,40,4449,10.0355,9229.30224609375,,,,,,,,,,,,,0,,,,0.00245,,,,,,10.0038071,,,,
,23130898.875,10.004878,4678.56323242188,6.63231951856105E-5,2.90922374197375E-7,1,0.999253354069792,40.0298881530762,1.98398793615047,16.8699994683266,0.000741729943808905,0.000125753510205212,0.25,-5.36072325459309E-7,6.5961841368885E-5,-1.94562177195446E-7,10.004878,10.004878,4671.0244140625,4686.10205078125,56.5015807696406,20.5997799179573,11.519473,0,0,0,40,4449,10.03195,4678.56323242188,,,,,,,,,,,,,0,,,,0,,,,,,10.004878,,,,
,23130990.7,10.0115585,87.4217147827148,7.34133261560516E-5,2.73028273967931E-7,1,0.999253354069792,40.0298881530762,1.98403374285484,16.8699994683266,0.000819583648018726,0.000146178623549264,0.25,5.56129152703464E-8,7.29914825589645E-5,4.09322715540212E-7,10.0115585,10.0115585,77.3762741088867,97.467155456543,56.3147715535444,20.5987494392187,11.899124,0,0,0,40,4449,10.0188,87.4217147827148,,,,,,,,,,,,,0,,,,0,,,,,,10.0115585,,,,
,23130994,10.0122833,-0.411041870713234,7.283041551645E-5,3.09365387199331E-7,1,0.999253354069792,40.0298881530762,1.98408231377967,16.8699994683266,0.000813524687403231,0.000142591900214047,0.25,-1.62200826843401E-7,7.24128159237628E-5,1.89768790142827E-7,10.0122833,10.0122833,-0.441489428281784,-0.380594313144684,57.0737328457176,20.5974812310992,11.899124,0,0,0,40,4417,10.0156,-0.411041870713234,,,,,,,,,,,,,0,,,,0,,,,,,10.0122833,,,,