File: data/doubleLayers/dl_2-5/ppms/DD205_5/KoelnPPMS/DD205_5_HYST_100OE_100K.DAT
[Header]
; VSM Data File (default extension .dat)
; Copyright (c) 2003-2013, Quantum Design, Inc. All rights reserved.
TITLE,
FILEOPENTIME,23154330.67,09/26/2018,8:44 am
BYAPP,VSM,2.0,2.0
INFO,PPMS VSM Option Release 1.4.10 Build 1,APPNAME
INFO,Quantum Design Linear Motor Servo Controller,MOTOR_MODULE_NAME
INFO,3101-100 M1,MOTOR_HW_VERSION
INFO,MMC1014,MOTOR_SERIAL_NUMBER
INFO,SRV No X-over 01.03.11,MOTOR_SOFTWARE_VERSION
INFO,Quantum Design VSM Detection Module,VSM_MODULE_NAME
INFO,3101-150 F0,VSM_HW_VERSION
INFO,VSM707,VSM_SERIAL_NUMBER
INFO,VSM No X-over 01.02.05 May 20 2008 13:51:47,VSM_SOFTWARE_VERSION
INFO,704,PREAMP_SERIAL_NUMBER
INFO,822,COIL_SERIAL_NUMBER
INFO,0,MOMENT_UNITS
INFO,,SAMPLE_MATERIAL
INFO,,SAMPLE_COMMENT
INFO,,SAMPLE_MASS
INFO,,SAMPLE_VOLUME
INFO,,SAMPLE_MOLECULAR_WEIGHT
INFO,,SAMPLE_SIZE
INFO,,SAMPLE_SHAPE
DATATYPE,COMMENT,1
DATATYPE,TIME,2
STARTUPAXIS,X,2
STARTUPAXIS,Y1,5
[Data]
Comment,Time Stamp (sec),Temperature (K),Magnetic Field (Oe),Moment (emu),M. Std. Err. (emu),Transport Action,Averaging Time (sec),Frequency (Hz),Peak Amplitude (mm),Center Position (mm),Coil Signal' (mV),Coil Signal" (mV),Range (mV),M. Quad. Signal (emu),M. Raw' (emu),M. Raw" (emu),Min. Temperature (K),Max. Temperature (K),Min. Field (Oe),Max. Field (Oe),Mass (grams),Motor Lag (deg),Pressure (Torr),VSM Status (code),Motor Status (code),Measure Status (code),Measure Count,PPMS Status (code),System Temp. (K),System Field (Oe),Sample Position (deg),Bridge 1 Resistance (ohms),Bridge 1 Excitation (에),Bridge 2 Resistance (ohms),Bridge 2 Excitation (에),Bridge 3 Resistance (ohms),Bridge 3 Excitation (에),Bridge 4 Resistance (ohms),Bridge 4 Excitation (에),Signal 1 Vin (V),Signal 2 Vin (V),Digital Inputs (code),Drive 1 Iout (mA),Drive 1 Ipower (W),Drive 2 Iout (mA),Drive 2 Ipower (W),Pressure (),Map 20 (),Map 21 (),Map 22 (),Map 23 (),Map 24 (),Map 25 (),Map 26 (),Map 27 (),Map 28 (),Map 29 ()
,23154345.3,100.3110886,-0.304475486278534,,,2,,,,16.8299997001886,,,,,,,100.3110886,100.3110886,-0.304475486278534,-0.304475486278534,,,22.909004,,,,-99999999,4369,100.6894,-0.304475486278534,,,,,,,,,,,,,,,,,,,,,,,100.3110886,,,,
,23154503.805,100.1704788,4423.33642578125,5.31036413099089E-5,2.89347531694672E-7,1,0.999253354069792,40.0298881530762,1.98421834107649,16.8099999427795,0.000596603407806114,0.000124481283332249,0.25,1.68633193334209E-6,5.33977658965592E-5,1.85928020324271E-6,100.1704788,100.1704788,4420.87744140625,4425.79541015625,55.9419347498713,20.5815374095917,22.529354,0,0,0,40,4449,100.4098,4423.33642578125,,,,,,,,,,,,,0,,,,0.0049,,,,,,100.1704788,,,,
,23154600.305,100.0979385,9246.72265625,4.10597453575158E-5,8.31465878262881E-7,1,0.999253354069792,40.0298881530762,1.98419266403048,16.8099999427795,0.000458013980694561,0.0001148990904715,0.25,2.95515579920239E-6,4.1282376576654E-5,3.09776007248978E-6,100.0979385,100.0979385,9237.30078125,9256.14453125,56.0443280858905,20.5877285618849,23.288654,0,0,0,40,4449,100.3459,9246.72265625,,,,,,,,,,,,,0,,,,0,,,,,,100.0979385,,,,
,23154697.025,100.0524445,14079.9853515625,3.13311037939826E-5,9.70195786304141E-7,1,0.999253354069792,40.0298881530762,1.98423809453106,16.8099999427795,0.000343850143478863,0.00011985202773755,0.25,5.10318836308281E-6,3.14925541754066E-5,5.22766672951795E-6,100.0524445,100.0524445,14074.681640625,14085.2890625,55.7566887908136,20.5839375251193,22.529354,0,0,0,40,4449,100.31635,14079.9853515625,,,,,,,,,,,,,0,,,,0,,,,,,100.0524445,,,,
,23154790.82,100.0295639,18769.4619140625,1.74029149389534E-5,1.30646614948997E-6,1,0.999253354069792,40.0298881530762,1.98407725835081,16.8099999427795,0.000182893169705992,0.000112592489818518,0.25,6.9088310943887E-6,1.74803903522817E-5,7.00077649207835E-6,100.0295639,100.0295639,18761.94921875,18776.974609375,56.2967940976021,20.5919058067917,22.909004,0,0,0,40,4449,100.29865,18769.4619140625,,,,,,,,,,,,,0,,,,-0.00245,,,,,,100.0295639,,,,
,23154885.345,100.0192795,23491.9443359375,1.95595606706861E-6,1.01852550188764E-6,1,0.999253354069792,40.0298881530762,1.98410529727389,16.8099999427795,6.52040926637742E-6,9.25537187409923E-5,0.25,7.84875514689251E-6,1.94332650699658E-6,7.89912841474938E-6,100.0192795,100.0192795,23478.9140625,23504.974609375,56.0630871703521,20.5889612460215,22.529354,0,0,0,40,4449,100.28425,23491.9443359375,,,,,,,,,,,,,0,,,,0.00245,,,,,,100.0192795,,,,
,23154978.17,100.0156403,28132.0947265625,-1.1529006592897E-5,7.82617180331737E-7,1,0.999253354069792,40.0298881530762,1.98400596164162,16.8099999427795,-0.000149490017575511,8.66848360953853E-5,0.25,9.69828847296792E-6,-1.16235418711321E-5,9.71866901864932E-6,100.0156403,100.0156403,28121.880859375,28142.30859375,56.6352392464291,20.5919070954684,22.909004,0,0,0,40,4449,100.27325,28132.0947265625,,,,,,,,,,,,,0,,,,0,,,,,,100.0156403,,,,
,23155073.025,100.0147476,32872.31640625,-2.71515489785073E-5,1.17321860738052E-6,1,0.999253354069792,40.0298881530762,1.98401845247349,16.8099999427795,-0.000328676160893473,7.102066427221E-5,0.25,1.10553063770696E-5,-2.73387986476997E-5,1.10370114257641E-5,100.0147476,100.0147476,32864.43359375,32880.19921875,56.7345060683714,20.5957249999588,23.288654,0,0,0,40,4449,100.26,32872.31640625,,,,,,,,,,,,,0,,,,0,,,,,,100.0147476,,,,
,23155165.81,100.0135574,37509.884765625,-4.3857928675278E-5,1.44157302097866E-6,1,0.999253354069792,40.0298881530762,1.98405743178825,16.8099999427795,-0.000517821298775922,4.01290576184006E-5,0.25,1.12542501206771E-5,-4.4140810332748E-5,1.1188040803848E-5,100.0135574,100.0135574,37502.36328125,37517.40625,56.0036834028905,20.5931616590237,22.909004,0,0,0,40,4449,100.24855,37509.884765625,,,,,,,,,,,,,0,,,,0.00245,,,,,,100.0135574,,,,
,23155260.725,100.0129814,42255.123046875,-5.95444818801259E-5,1.87354759611304E-6,1,0.999253354069792,40.0298881530762,1.9840649260136,16.8099999427795,-0.000698396873321895,2.80756587011958E-5,0.25,1.29410606814492E-5,-5.99218329284842E-5,1.28390541419997E-5,100.012886,100.0130768,42250.16015625,42260.0859375,56.5437887096791,20.595058854659,23.288654,0,0,0,40,4449,100.2378,42255.123046875,,,,,,,,,,,,,0,,,,0.00245,,,,,,100.0129814,,,,
,23155357.85,100.0135956,47107.923828125,-7.39109620889757E-5,1.51011268853715E-6,1,0.999253354069792,40.0298881530762,1.98385657718247,16.8099999427795,-0.000869342215511222,4.92246285160934E-5,0.25,1.73347403051172E-5,-7.43833788601726E-5,1.72168798396289E-5,100.0135956,100.0135956,47103.3984375,47112.44921875,56.6454004171791,20.5954497928367,23.668306,0,0,0,40,4449,100.2231,47107.923828125,,,,,,,,,,,,,0,,,,0.0049,,,,,,100.0135956,,,,
,23155456.22,100.0137177,52025.560546875,-9.35445331284078E-5,1.54246058203845E-6,1,0.999253354069792,40.0298881530762,1.98387968348062,16.8099999427795,-0.00109222382059061,1.63626723924055E-5,0.25,1.78711884037238E-5,-9.41309359698497E-5,1.77007555206973E-5,100.0137177,100.0137177,52020.51171875,52030.609375,56.5203398541021,20.5943089724933,23.288654,0,0,0,40,4449,100.21085,52025.560546875,,,,,,,,,,,,,0,,,,0,,,,,,100.0137177,,,,
,23155554.765,100.0128098,56950.125,-0.00011086482493485,2.17889894482827E-6,1,0.999253354069792,40.0298881530762,1.98393602979731,16.8099999427795,-0.00128317168565215,-4.5118184963116E-5,0.25,1.54677097326783E-5,-0.000111543777184729,1.52353718411832E-5,100.0128098,100.0128098,56947.69921875,56952.55078125,56.0372934292175,20.5933738636293,22.909004,0,0,0,40,4449,100.2003,56950.125,,,,,,,,,,,,,0,,,,0.00245,,,,,,100.0128098,,,,
,23155651.9,100.0118408,61805.458984375,-0.000127843767436223,1.63933855788459E-6,1,0.999253354069792,40.0298881530762,1.98405410702342,16.8099999427795,-0.00148278283359423,-3.4931095437856E-5,0.25,1.93476168244822E-5,-0.00012863173804756,1.90909521684722E-5,100.0118408,100.0118408,61800.39453125,61810.5234375,56.2155047316021,20.5923482275126,22.909004,0,0,0,40,4449,100.1889,61805.458984375,,,,,,,,,,,,,0,,,,-0.0049,,,,,,100.0118408,,,,
,23155750.125,100.0137863,66716.125,-0.000146853893605831,2.26641211510989E-6,1,0.999253354069792,40.0298881530762,1.98406066067815,16.8099999427795,-0.00169958556375296,-6.11981609248827E-5,0.25,2.03565714960073E-5,-0.000147754456783122,2.0054068414557E-5,100.0137863,100.0137863,66708.53125,66723.71875,56.211596589006,20.592166794593,23.288654,0,0,0,40,4449,100.17745,66716.125,,,,,,,,,,,,,0,,,,0,,,,,,100.0137863,,,,
,23155847.025,100.0104904,71556.51171875,-0.000161793448878287,2.35250429643799E-6,1,0.999253354069792,40.0298881530762,1.98390391368811,16.8099999427795,-0.00186811929074613,-9.1552799991222E-5,0.25,2.02881315290265E-5,-0.000162780434819961,1.99458787753348E-5,100.0102386,100.0107422,71546.6953125,71566.328125,56.3178980676213,20.5943899009888,22.909004,0,0,0,40,4449,100.16845,71556.51171875,,,,,,,,,,,,,0,,,,0.00245,,,,,,100.0104904,,,,
,23155944.015,100.0101242,76406.7265625,-0.000184036524194529,2.48579921034542E-6,1,0.999253354069792,40.0298881530762,1.98409221542022,16.8099999427795,-0.00212558763816545,-0.000101651036742232,0.25,2.3294802135847E-5,-0.000185160833980964,2.29105083815226E-5,100.0101242,100.0101242,76399.125,76414.328125,56.435142345506,20.5915872364672,23.288654,0,0,0,40,4449,100.1597,76406.7265625,,,,,,,,,,,,,0,,,,0.00245,,,,,,100.0101242,,,,
,23156041.465,100.0093918,81277.71484375,-0.000200443075611588,2.06965779447767E-6,1,0.999253354069792,40.0298881530762,1.98397159151552,16.8099999427795,-0.00230471804530412,-0.000169075912532005,0.25,2.02014081175871E-5,-0.000201654259498557,1.97571896654678E-5,100.0093918,100.0093918,81267.7890625,81287.640625,55.9388082357944,20.5935525009998,22.909004,0,0,0,40,4449,100.15145,81277.71484375,,,,,,,,,,,,,0,,,,0,,,,,,100.0093918,,,,
,23156135.6,100.0105209,85983.12109375,-0.000219074960139223,2.5312319944231E-6,1,0.999253354069792,40.0298881530762,1.98408740635077,16.8099999427795,-0.0025101693808571,-0.000235736591602207,0.25,1.75673430428076E-5,-0.000220387438064707,1.70600899921597E-5,100.0105209,100.0105209,85980.7734375,85985.46875,56.0927890540829,20.5914720896811,23.288654,0,0,0,40,4449,100.142,85983.12109375,,,,,,,,,,,,,0,,,,0,,,,,,100.0105209,,,,
,23156247.145,100.0079727,89505.8515625,-0.000233785621348653,2.70331236520645E-6,1,0.999253354069792,40.0298881530762,1.98410128760554,16.8099999427795,-0.00267867639409052,-0.000252014331101578,0.25,1.87042958405415E-5,-0.000235187168677472,1.8166086804304E-5,100.0079727,100.0079727,89495.96875,89515.734375,56.4890747133329,20.588692168979,23.288654,0,0,0,40,4449,100.13125,89505.8515625,,,,,,,,,,,,,0,,,,0.00245,,,,,,100.0079727,,,,
,23156340.235,100.0035172,84854.2421875,-0.000214531173112087,2.61727858338508E-6,1,0.999253354069792,40.0298881530762,1.98412415943411,16.8099999427795,-0.00246380452971639,-0.000198597768415868,0.25,2.00585106171782E-5,-0.00021582406046657,1.95771381410809E-5,100.0035172,100.0035172,84844.1015625,84864.3828125,56.5273745107752,20.5892365200427,23.288654,0,0,0,40,4449,100.1327,84854.2421875,,,,,,,,,,,,,0,,,,0,,,,,,100.0035172,,,,
,23156434.22,100.0023041,80155.0703125,-0.000197448375387309,2.44295063091688E-6,1,0.999253354069792,40.0298881530762,1.98415108909705,16.8099999427795,-0.00227154370763214,-0.000160486407767949,0.25,2.043855668981E-5,-0.000198642671112294,2.00029506780253E-5,100.0023041,100.0023041,80149.8984375,80160.2421875,55.8762779542559,20.5919818291,23.288654,0,0,0,40,4449,100.1306,80155.0703125,,,,,,,,,,,,,0,,,,-0.0049,,,,,,100.0023041,,,,
,23156531.83,99.99879455,75276.53125,-0.000182501771870396,2.24610412777433E-6,1,0.999253354069792,40.0298881530762,1.98407074762499,16.8099999427795,-0.00209939467196062,-0.000148914410107686,0.25,1.88434083795753E-5,-0.000183604433401643,1.84367255937268E-5,99.9986954,99.9988937,75271.0390625,75282.0234375,56.6235148186406,20.5918164771741,23.288654,0,0,0,40,4449,100.1327,75276.53125,,,,,,,,,,,,,0,,,,-0.00245,,,,,,99.99879455,,,,
,23156628.58,99.9979706,70440.61328125,-0.000159007311612683,2.53226238925731E-6,1,0.999253354069792,40.0298881530762,1.98422256189885,16.8099999427795,-0.00183239649159832,-0.000111827011645147,0.25,1.80071573592084E-5,-0.000159971574189406,1.76586902793723E-5,99.9979706,99.9979706,70432.9375,70448.2890625,55.9880508325059,20.5890479354107,22.909004,0,0,0,40,4449,100.1344,70440.61328125,,,,,,,,,,,,,0,,,,-0.00245,,,,,,99.9979706,,,,
,23156726.735,99.998558,65533.052734375,-0.000145371676280461,2.36611817667495E-6,1,0.999253354069792,40.0298881530762,1.98425720619014,16.8099999427795,-0.0016784755087967,-8.40180270176342E-5,0.25,1.80783969714305E-5,-0.000146256989102668,1.77660212250034E-5,99.998558,99.998558,65525.53515625,65540.5703125,56.0935706826021,20.5894204241017,23.668306,0,0,0,40,4449,100.13445,65533.052734375,,,,,,,,,,,,,0,,,,0.0049,,,,,,99.998558,,,,
,23156821.27,99.9974823,60807.203125,-0.000125859400797941,2.48734896628387E-6,1,0.999253354069792,40.0298881530762,1.98419356619031,16.8099999427795,-0.00145895220044342,-3.95819654743049E-5,0.25,1.85887268921969E-5,-0.000126633639942705,1.83325653811419E-5,99.9974823,99.9974823,60797.23828125,60817.16796875,56.6407106460637,20.5925745179287,23.288654,0,0,0,40,4449,100.1383,60807.203125,,,,,,,,,,,,,0,,,,0.00245,,,,,,99.9974823,,,,
,23156916.275,99.9974594,56056.857421875,-0.000108738973007509,2.07558596427127E-6,1,0.999253354069792,40.0298881530762,1.98423315952894,16.8099999427795,-0.001264709906002,-1.02795975075948E-5,0.25,1.81791220862305E-5,-0.000109413466059993,1.79677011344671E-5,99.9974594,99.9974594,56049.23828125,56064.4765625,56.2483331294098,20.5914481345901,23.668306,0,0,0,40,4449,100.14065,56056.857421875,,,,,,,,,,,,,0,,,,0.0049,,,,,,99.9974594,,,,
,23157012.615,99.9968185,51244.0859375,-8.91914248289017E-5,1.91296593995281E-6,1,0.999253354069792,40.0298881530762,1.98421080309537,16.8099999427795,-0.00103848724703036,-1.90881854235752E-6,0.25,1.54902011576386E-5,-8.97459122101727E-5,1.53182388903929E-5,99.9968185,99.9968185,51236.76953125,51251.40234375,56.6235148186406,20.5892012281604,23.288654,0,0,0,40,4449,100.1427,51244.0859375,,,,,,,,,,,,,0,,,,0,,,,,,99.9968185,,,,
,23157107.22,99.994072,46514.408203125,-7.13923179971323E-5,1.44220346418112E-6,1,0.999253354069792,40.0298881530762,1.98413395560956,16.8099999427795,-0.00083798241729671,3.70346275179355E-5,0.25,1.58134635535367E-5,-7.18458470326216E-5,1.56938468889393E-5,99.994072,99.994072,46504.38671875,46524.4296875,56.557076394506,20.5910075173011,23.668306,0,0,0,40,4449,100.14825,46514.408203125,,,,,,,,,,,,,0,,,,0.00245,,,,,,99.994072,,,,
,23157204.975,99.9948502,41629.21875,-5.69827305161314E-5,1.52375437466287E-6,1,0.999253354069792,40.0298881530762,1.9841228258845,16.8099999427795,-0.000673219162420211,5.44933586626712E-5,0.25,1.48297897165524E-5,-5.73510195997055E-5,1.47456839860015E-5,99.9948502,99.9948502,41621.82421875,41636.61328125,56.4546830584867,20.5928143401741,23.288654,0,0,0,40,4449,100.1531,41629.21875,,,,,,,,,,,,,0,,,,0,,,,,,99.9948502,,,,
,23157299.56,99.9934998,36901.181640625,-3.84823567683369E-5,1.13614259361068E-6,1,0.999253354069792,40.0298881530762,1.98423531180645,16.8099999427795,-0.000456200056342749,4.55106903791249E-5,0.25,1.0786491699206E-5,-3.87332477604502E-5,1.07332892130563E-5,99.9934998,99.9934998,36888.5546875,36913.80859375,56.8118872917752,20.5922595011878,23.668306,0,0,0,40,4449,100.1582,36901.181640625,,,,,,,,,,,,,0,,,,0.00245,,,,,,99.9934998,,,,
,23157393.505,99.9939194,32206.751953125,-2.30130007340696E-5,1.56557391574948E-6,1,0.999253354069792,40.0298881530762,1.98419644536322,16.8099999427795,-0.000281290854044125,7.55093677665122E-5,0.25,1.07253816900215E-5,-2.31757711150863E-5,1.07173704721325E-5,99.9939194,99.9939194,32196.560546875,32216.943359375,57.1268835850253,20.5934221459456,23.668306,0,0,0,40,4449,100.1631,32206.751953125,,,,,,,,,,,,,0,,,,0,,,,,,99.9939194,,,,
,23157488.82,99.9940186,27441.533203125,-6.19406828785116E-6,6.43152889783983E-7,1,0.999253354069792,40.0298881530762,1.98417282654965,16.8099999427795,-8.81073580274592E-5,9.0897966099707E-5,0.25,9.13355950551747E-6,-6.25669698688713E-6,9.16668663360118E-6,99.9940186,99.9940186,27429.095703125,27453.970703125,56.5320642818906,20.5947485183794,23.668306,0,0,0,40,4449,100.17015,27441.533203125,,,,,,,,,,,,,0,,,,0,,,,,,99.9940186,,,,
,23157585.235,99.9942551,22623.9150390625,6.62046668294528E-6,8.46970989345199E-7,1,0.999253354069792,40.0298881530762,1.98415812080338,16.8099999427795,6.09270710411955E-5,9.20881124451939E-5,0.25,6.98789237913646E-6,6.63677881593102E-6,7.04751433633222E-6,99.9942551,99.9942551,22616.453125,22631.376953125,56.5203398541021,20.5935401112105,23.668306,0,0,0,40,4449,100.17615,22623.9150390625,,,,,,,,,,,,,0,,,,0.00245,,,,,,99.9942551,,,,
,23157684.655,99.9951172,17653.9775390625,2.24311440748897E-5,9.88734759375328E-7,1,0.999253354069792,40.0298881530762,1.98421898277822,16.8099999427795,0.000242689043519263,0.000105643124045048,0.25,5.40947233087078E-6,2.25414791547234E-5,5.50841574491498E-6,99.9951172,99.9951172,17649.005859375,17658.94921875,56.0505811140444,20.5948213461506,23.288654,0,0,0,40,4449,100.1793,17653.9775390625,,,,,,,,,,,,,0,,,,-0.0049,,,,,,99.9951172,,,,
,23157783.38,99.9908218,12719.0517578125,3.71120913286523E-5,9.32761026366707E-7,1,0.999253354069792,40.0298881530762,1.98423439440229,16.8099999427795,0.000411946762466306,0.000115474138409295,0.25,3.69959860662665E-6,3.73103062663593E-5,3.83420051292403E-6,99.9908218,99.9908218,12711.54296875,12726.560546875,56.6876083572175,20.5942735276278,23.288654,0,0,0,40,4449,100.18945,12719.0517578125,,,,,,,,,,,,,0,,,,-0.00245,,,,,,99.9908218,,,,
,23157877.46,99.9908905,8018.63256835938,4.96657542491091E-5,5.36966139835272E-7,1,0.999253354069792,40.0298881530762,1.98404986287548,16.8099999427795,0.00055647332896803,0.000124738795700843,0.25,2.31408080850338E-6,4.99387326242372E-5,2.48003871287537E-6,99.9908905,99.9908905,8008.7607421875,8028.50439453125,56.6133536478906,20.5961619428894,23.288654,0,0,0,40,4449,100.1983,8018.63256835938,,,,,,,,,,,,,0,,,,-0.0049,,,,,,99.9908905,,,,
,23157968.335,99.9919968,3478.56530761719,5.9801304815983E-5,3.99013953087476E-7,1,0.999253354069792,40.0298881530762,1.98417993274563,16.8099999427795,0.000673928256584813,0.000128269086961584,0.25,8.44046025198222E-7,6.01356097822314E-5,1.03367844308484E-6,99.9919968,99.9919968,3466.05615234375,3491.07446289063,56.4359239740252,20.5991596617035,23.288654,0,0,0,40,4449,100.2037,3478.56530761719,,,,,,,,,,,,,0,,,,-0.00245,,,,,,99.9919968,,,,
,23158053.5,99.9948502,-779.221496582031,5.73757113074717E-5,2.58226897043906E-7,1,0.999253354069792,40.0298881530762,1.98408392232366,16.8099999427795,0.000649027394122202,0.000109028825590039,0.25,-4.32607007543905E-7,5.77001348176014E-5,-2.57310758922318E-7,99.9948502,99.9948502,-786.759521484375,-771.683471679688,56.4945461129675,20.5979179552974,23.668306,0,0,0,40,4449,100.2074,-779.221496582031,,,,,,,,,,,,,0,,,,-0.00245,,,,,,99.9948502,,,,
,23158149.225,99.9997101,-5561.80053710937,5.53137280225587E-5,4.3604321653351E-7,1,0.999253354069792,40.0298881530762,1.98417981342771,16.8099999427795,0.000629138973000314,8.57444972208772E-5,0.25,-2.13105330800369E-6,5.56320772699312E-5,-1.97239155757222E-6,99.9997101,99.9997101,-5571.8662109375,-5551.73486328125,56.6461820456983,20.5985927929646,23.668306,0,0,0,40,4449,100.2077,-5561.80053710937,,,,,,,,,,,,,0,,,,0,,,,,,99.9997101,,,,
,23158246.785,100.0043716,-10437.7685546875,3.95498726002762E-5,6.18063365130849E-7,1,0.999253354069792,40.0298881530762,1.98427058668022,16.8099999427795,0.000453707064953865,3.94356724472143E-5,0.25,-3.45935808159376E-6,3.97836772762354E-5,-3.35742636947483E-6,100.0043716,100.0043716,-10440.2158203125,-10435.3212890625,56.2420801012559,20.594862639613,24.047956,0,0,0,40,4449,100.2018,-10437.7685546875,,,,,,,,,,,,,0,,,,0.00245,,,,,,100.0043716,,,,
,23158342.565,100.0072556,-15222.9946289062,1.5192901809332E-5,7.52447124698445E-7,1,0.999253354069792,40.0298881530762,1.98426741807587,16.8099999427795,0.000182739829206943,-3.29403149758222E-5,0.25,-5.58503472698138E-6,1.52958059202117E-5,-5.57017049957663E-6,100.0072556,100.0072556,-15232.853515625,-15213.1357421875,56.3421285517175,20.5956857768997,23.668306,0,0,0,40,4449,100.1922,-15222.9946289062,,,,,,,,,,,,,0,,,,-0.00245,,,,,,100.0072556,,,,
,23158438.83,100.0096359,-20037.4443359375,3.55080286744637E-6,3.74958251084661E-7,1,0.999253354069792,40.0298881530762,1.98417682121649,16.8099999427795,5.55874944386876E-5,-8.10111093872236E-5,0.25,-7.79434341530117E-6,3.59457724089395E-6,-7.82764807403422E-6,100.0096359,100.0096359,-20044.96875,-20029.919921875,56.4398321166213,20.6002120890633,23.288654,0,0,0,40,4449,100.18095,-20037.4443359375,,,,,,,,,,,,,0,,,,0,,,,,,100.0096359,,,,
,23158537.535,100.0120087,-24969.732421875,7.1188714802626E-6,6.44978721611249E-7,1,0.999253354069792,40.0298881530762,1.98418078336707,16.8099999427795,9.80841703685414E-5,-8.63726313422024E-5,0.25,-8.89555510186406E-6,7.18607736679983E-6,-8.92444084386105E-6,100.0120087,100.0120087,-24972.34375,-24967.12109375,56.3976241765829,20.5988727830984,23.288654,0,0,0,40,4449,100.1697,-24969.732421875,,,,,,,,,,,,,0,,,,0,,,,,,100.0120087,,,,
,23158635.46,100.0125885,-29864.6767578125,1.70292445234006E-5,1.01827943753376E-6,1,0.999253354069792,40.0298881530762,1.98419256465047,16.8099999427795,0.00021398963102989,-8.9119448584568E-5,0.25,-1.08792117055489E-5,1.71585271796115E-5,-1.08897842056058E-5,100.0125885,100.0125885,-29874.57421875,-29854.779296875,56.536754053006,20.5990832408191,23.288654,0,0,0,40,4449,100.1584,-29864.6767578125,,,,,,,,,,,,,0,,,,-0.00245,,,,,,100.0125885,,,,
,23158731.66,100.0114899,-34669.251953125,3.18017415346907E-5,1.38056440547476E-6,1,0.999253354069792,40.0298881530762,1.98421981614746,16.8099999427795,0.000382738347145543,-7.0285471135627E-5,0.25,-1.18063264324715E-5,3.20176538112503E-5,-1.17784539707741E-5,100.0114899,100.0114899,-34676.8984375,-34661.60546875,56.7517018957945,20.5999734295856,23.288654,0,0,0,40,4449,100.14565,-34669.251953125,,,,,,,,,,,,,0,,,,-0.0049,,,,,,100.0114899,,,,
,23158829.035,100.0130463,-39538.736328125,5.09364211759218E-5,1.50284318959783E-6,1,0.999253354069792,40.0298881530762,1.98425680128181,16.8099999427795,0.000603427163576171,-5.78485184031975E-5,0.25,-1.40651675992238E-5,5.12679306129218E-5,-1.39940582491251E-5,100.0130463,100.0130463,-39548.890625,-39528.58203125,56.7688977232175,20.601425388876,24.047956,0,0,0,40,4449,100.13355,-39538.736328125,,,,,,,,,,,,,0,,,,0.00245,,,,,,100.0130463,,,,
,23158927.99,100.0124359,-44483.615234375,6.68721462983001E-5,1.72321278942511E-6,1,0.999253354069792,40.0298881530762,1.98434224782998,16.8099999427795,0.000783200245950271,-2.44275466756751E-5,0.25,-1.39043762940333E-5,6.72941280109554E-5,-1.37864720003229E-5,100.0124359,100.0124359,-44491.19921875,-44476.03125,56.6266413327175,20.5977952717764,23.668306,0,0,0,40,4449,100.124,-44483.615234375,,,,,,,,,,,,,0,,,,0,,,,,,100.0124359,,,,
,23159028.93,100.011673,-49528.798828125,8.36227983446756E-5,1.6476164796478E-6,1,0.999253354069792,40.0298881530762,1.98424420019279,16.8099999427795,0.000978593302756947,-2.62904350177371E-5,0.25,-1.70089835115581E-5,8.41497430240461E-5,-1.68611918499754E-5,100.011673,100.011673,-49533.80078125,-49523.796875,56.1553193356213,20.6018563563927,23.288654,0,0,0,40,4449,100.11425,-49528.798828125,,,,,,,,,,,,,0,,,,0,,,,,,100.011673,,,,
,23159126.895,100.0102921,-54426.052734375,9.98227268806295E-5,2.40213159710414E-6,1,0.999253354069792,40.0298881530762,1.98446567292904,16.8099999427795,0.00116148683278714,7.43335666808078E-6,0.25,-1.68667228359891E-5,0.000100442190337452,-1.66727559162416E-5,100.0102921,100.0102921,-54431.0546875,-54421.05078125,56.9744660237753,20.595321681671,23.288654,0,0,0,40,4449,100.10375,-54426.052734375,,,,,,,,,,,,,0,,,,-0.00245,,,,,,100.0102921,,,,
,23159225.265,100.0089417,-59340.6484375,0.000119337317650146,2.04390316406353E-6,1,0.999253354069792,40.0298881530762,1.98437105181069,16.8099999427795,0.00138686792839061,1.81402165192855E-5,0.25,-1.93426951694714E-5,0.000120076107078866,-1.91086162115776E-5,100.0089417,100.0089417,-59348.08984375,-59333.20703125,56.3124266679867,20.5983155570052,24.047956,0,0,0,40,4449,100.09515,-59340.6484375,,,,,,,,,,,,,0,,,,-0.00245,,,,,,100.0089417,,,,
,23159325.85,100.010952,-64370.5390625,0.000140466835982772,2.10519052355437E-6,1,0.999253354069792,40.0298881530762,1.98434187855323,16.8099999427795,0.00162654288513949,5.47685499113283E-5,0.25,-1.98073182945674E-5,0.000141328661879258,-1.9517839862827E-5,100.0107651,100.0111389,-64375.4375,-64365.640625,56.6235148186406,20.6020224971473,24.047956,0,0,0,40,4449,100.08475,-64370.5390625,,,,,,,,,,,,,0,,,,0,,,,,,100.010952,,,,
,23159424.41,100.0087433,-69292.3828125,0.000157821279289947,2.10057628728439E-6,1,0.999253354069792,40.0298881530762,1.98442296737816,16.8099999427795,0.00182140902263995,9.67054619336737E-5,0.25,-1.91392517412156E-5,0.000158781575528594,-1.87994419757289E-5,100.0087433,100.0087433,-69302.5546875,-69282.2109375,56.4445218877367,20.5985372240215,24.047956,0,0,0,40,4449,100.0773,-69292.3828125,,,,,,,,,,,,,0,,,,-0.00245,,,,,,100.0087433,,,,
,23159524.91,100.0100327,-74314.171875,0.000177227026507475,2.06757740890536E-6,1,0.999253354069792,40.0298881530762,1.98446406566029,16.8099999427795,0.00204056875274906,0.000136258175956542,0.25,-1.90414898077913E-5,0.000178299503741581,-1.86495567810237E-5,100.0100327,100.0100327,-74319.1640625,-74309.1796875,56.5203398541021,20.6009702786432,23.668306,0,0,0,40,4449,100.0674,-74314.171875,,,,,,,,,,,,,0,,,,-0.0049,,,,,,100.0100327,,,,
,23159621.645,100.0085678,-79151.08984375,0.000196358096011816,2.40360868417162E-6,1,0.999253354069792,40.0298881530762,1.98449238584735,16.8099999427795,0.00225594311251013,0.000179138308649188,0.25,-1.86005383219144E-5,0.000197540496220857,-1.81559367522058E-5,100.0085678,100.0085678,-79161.1875,-79140.9921875,56.2756901275829,20.5976478999518,23.668306,0,0,0,40,4449,100.06105,-79151.08984375,,,,,,,,,,,,,0,,,,0.00245,,,,,,100.0085678,,,,
,23159720.5,100.0090256,-84090.93359375,0.000217188453430806,2.79399034447096E-6,1,0.999253354069792,40.0298881530762,1.9844657913841,16.8099999427795,0.00249799064320618,0.000182488710336019,0.25,-2.19544009346387E-5,0.000218501482592203,-2.14750782498196E-5,100.0090256,100.0090256,-84098.6953125,-84083.171875,57.0917103016599,20.5992344210954,23.288654,0,0,0,40,4449,100.05335,-84090.93359375,,,,,,,,,,,,,0,,,,-0.0049,,,,,,100.0090256,,,,
,23159815.29,100.0065002,-88827.6171875,0.000234474740146213,2.40540365716768E-6,1,0.999253354069792,40.0298881530762,1.98444606480307,16.8099999427795,0.00269328880597832,0.000217020754047362,0.25,-2.19267959635246E-5,0.00023588872380413,-2.14037468138243E-5,100.0065002,100.0065002,-88835.0234375,-88820.2109375,55.9802345473136,20.5974059587874,23.668306,0,0,0,40,4449,100.0478,-88827.6171875,,,,,,,,,,,,,0,,,,0,,,,,,100.0065002,,,,
,23159927.56,100.0034561,-86532.1875,0.00022482280538108,2.83240008200949E-6,1,0.999253354069792,40.0298881530762,1.9846134584267,16.8099999427795,0.00258058550872057,0.000219717488447012,0.25,-1.99987227429087E-5,0.00022617509082676,-1.94890853117341E-5,100.0034561,100.0034561,-86544.609375,-86519.765625,56.435142345506,20.5976743639561,24.047956,0,0,0,40,4449,100.046,-86532.1875,,,,,,,,,,,,,0,,,,-0.00245,,,,,,100.0034561,,,,
,23160024.72,100.0008698,-81677.6640625,0.000207549204890561,2.12789757261318E-6,1,0.999253354069792,40.0298881530762,1.98460035768861,16.8099999427795,0.0023861939204822,0.000180549283665753,0.25,-2.04380553467225E-5,0.000208801839054072,-1.99747063163497E-5,100.0008698,100.0008698,-81682.71875,-81672.609375,56.6618146160829,20.5998570538603,23.668306,0,0,0,40,4449,100.0484,-81677.6640625,,,,,,,,,,,,,0,,,,0,,,,,,100.0008698,,,,
,23160124.555,99.9975967,-76687.65625,0.000191723579664167,2.4579089273371E-6,1,0.999253354069792,40.0298881530762,1.98453699040365,16.8099999427795,0.00220889529323644,0.00013982236687518,0.25,-2.126863433353E-5,0.000192886234895831,-2.08502728174603E-5,99.9975967,99.9975967,-76695.0078125,-76680.3046875,56.3679222928521,20.5997633870111,24.047956,0,0,0,40,4449,100.0479,-76687.65625,,,,,,,,,,,,,0,,,,0.00245,,,,,,99.9975967,,,,
,23160222,99.9960327,-71817.73046875,0.000168515979207873,1.8504459765183E-6,1,0.999253354069792,40.0298881530762,1.9845275435775,16.8099999427795,0.00194592624758334,9.76423326757456E-5,0.25,-2.09321088198533E-5,0.000169543256583305,-2.0573754509983E-5,99.9960327,99.9960327,-71822.6953125,-71812.765625,56.9088092281599,20.598108395286,23.668306,0,0,0,40,4449,100.052,-71817.73046875,,,,,,,,,,,,,0,,,,0,,,,,,99.9960327,,,,
,23160322.215,99.9949112,-66810.8984375,0.000149057269649072,1.96529988252535E-6,1,0.999253354069792,40.0298881530762,1.98442244653134,16.8099999427795,0.00172459432083067,6.66301355666249E-5,0.25,-2.02642990773918E-5,0.000149970051383868,-1.99541679451333E-5,99.9949112,99.9949112,-66815.6953125,-66806.1015625,56.5023623981598,20.5969709763076,23.668306,0,0,0,40,4449,100.05625,-66810.8984375,,,,,,,,,,,,,0,,,,-0.00245,,,,,,99.9949112,,,,
,23160419.405,99.9946823,-61953.61328125,0.000134028352185163,2.26027667044835E-6,1,0.999253354069792,40.0298881530762,1.98440362567775,16.8099999427795,0.00155260422104837,4.89891223150336E-5,0.25,-1.91903208573413E-5,0.000134851152665222,-1.89142388417326E-5,99.9946823,99.9946823,-61963.55859375,-61943.66796875,56.3882446343521,20.6002602170371,24.047956,0,0,0,40,4449,100.06345,-61953.61328125,,,,,,,,,,,,,0,,,,0,,,,,,99.9946823,,,,
,23160520.65,99.9939728,-56894.076171875,0.0001134066462269,1.66732157629309E-6,1,0.999253354069792,40.0298881530762,1.98454013364051,16.8099999427795,0.00131871386482083,1.34528459575917E-5,0.25,-1.87178662349737E-5,0.000114109397398022,-1.84959801052056E-5,99.9939728,99.9939728,-56901.26953125,-56886.8828125,56.6430555316214,20.5939880807615,24.047956,0,0,0,40,4449,100.0671,-56894.076171875,,,,,,,,,,,,,0,,,,0,,,,,,99.9939728,,,,
,23160618.42,99.9940109,-52007.05859375,9.70433774978077E-5,2.26178329044307E-6,1,0.999253354069792,40.0298881530762,1.98468735379193,16.8099999427795,0.00112815826015415,1.35333008947928E-5,0.25,-1.58402148550602E-5,9.764372253197E-5,-1.56473161840425E-5,99.9940109,99.9940109,-52019.6328125,-51994.484375,56.2327005590252,20.5946538985848,23.288654,0,0,0,40,4449,100.0763,-52007.05859375,,,,,,,,,,,,,0,,,,0,,,,,,99.9940109,,,,
,23160713.195,99.9937744,-47269.876953125,7.82983372206107E-5,1.65573705331224E-6,1,0.999253354069792,40.0298881530762,1.98459775774801,16.8099999427795,0.000918960312849468,-3.89852798988662E-5,0.25,-1.71979776454276E-5,7.87953062227431E-5,-1.70659347534836E-5,99.9937744,99.9937744,-47282.46875,-47257.28515625,55.964601976929,20.5952159485846,24.047956,0,0,0,40,4449,100.07935,-47269.876953125,,,,,,,,,,,,,0,,,,0,,,,,,99.9937744,,,,
,23160812.385,99.992157,-42315.017578125,5.85935591958871E-5,1.46079073790211E-6,1,0.999253354069792,40.0298881530762,1.98461809273388,16.8099999427795,0.000690350188275718,-4.42876721995591E-5,0.25,-1.42084485403345E-5,5.89691793933192E-5,-1.41160095306539E-5,99.992157,99.992157,-42325.09375,-42304.94140625,56.4437402592175,20.5936865008559,23.668306,0,0,0,40,4449,100.08785,-42315.017578125,,,,,,,,,,,,,0,,,,-0.00245,,,,,,99.992157,,,,
,23160909.625,99.9924393,-37455.0625,4.487188192231E-5,1.44696054621711E-6,1,0.999253354069792,40.0298881530762,1.98456664318804,16.8099999427795,0.0005334732856146,-6.12862623019324E-5,0.25,-1.33040837507871E-5,4.51665875738371E-5,-1.32461288345863E-5,99.9924393,99.9924393,-37462.5,-37447.625,56.7477937531983,20.5963476674543,23.668306,0,0,0,40,4449,100.09495,-37455.0625,,,,,,,,,,,,,0,,,,0.0049,,,,,,99.9924393,,,,
,23161003.93,99.9914627,-32738.259765625,2.47793615252269E-5,1.10501660723192E-6,1,0.999253354069792,40.0298881530762,1.98449709390072,16.8099999427795,0.000305692038010772,-9.70694380000673E-5,0.25,-1.29426870313425E-5,2.49588028078948E-5,-1.294194511614E-5,99.9914627,99.9914627,-32745.802734375,-32730.716796875,56.7720242372945,20.5938318002829,24.047956,0,0,0,40,4449,100.1023,-32738.259765625,,,,,,,,,,,,,0,,,,0,,,,,,99.9914627,,,,
,23161101.175,99.9932098,-27881.2939453125,1.04465800866591E-5,8.58777546605655E-7,1,0.999253354069792,40.0298881530762,1.98439143719376,16.8099999427795,0.000138645668717098,-9.65792672856555E-5,0.25,-1.03825512497033E-5,1.05370901698715E-5,-1.04099275194678E-5,99.9932098,99.9932098,-27888.919921875,-27873.66796875,56.5305010248521,20.5966823690731,23.668306,0,0,0,40,4449,100.1072,-27881.2939453125,,,,,,,,,,,,,0,,,,0,,,,,,99.9932098,,,,
,23161197.01,99.9916687,-23088.802734375,-4.83280236343357E-6,1.25027498357003E-6,1,0.999253354069792,40.0298881530762,1.98449468722186,16.8099999427795,-3.7046000284091E-5,-0.000109563024683324,0.25,-8.84713462434739E-6,-4.83334502149587E-6,-8.91186875747348E-6,99.9916687,99.9916687,-23096.193359375,-23081.412109375,56.3569794935829,20.5959168925315,23.288654,0,0,0,40,4449,100.1163,-23088.802734375,,,,,,,,,,,,,0,,,,-0.00245,,,,,,99.9916687,,,,
,23161294.945,99.9920883,-18193.9111328125,-1.88319432590725E-5,1.42579435993948E-6,1,0.999253354069792,40.0298881530762,1.98434504891716,16.8099999427795,-0.000199084804594742,-0.000115309141675975,0.25,-6.89676627635639E-6,-1.89173823062966E-5,-6.993166258563E-6,99.9920883,99.9920883,-18199.2578125,-18188.564453125,56.313208296506,20.5973842955705,23.668306,0,0,0,40,4449,100.12365,-18193.9111328125,,,,,,,,,,,,,0,,,,-0.00245,,,,,,99.9920883,,,,
,23161394.165,99.989357,-13235.9877929688,-3.37236196018349E-5,6.56771478713571E-7,1,0.999253354069792,40.0298881530762,1.9845035293372,16.8099999427795,-0.000371958031711087,-0.000118743332366623,0.25,-4.58296943806284E-6,-3.38999699873065E-5,-4.71221874397612E-6,99.989357,99.989357,-13245.87890625,-13226.0966796875,56.4288893173521,20.595177525705,23.668306,0,0,0,40,4449,100.1321,-13235.9877929688,,,,,,,,,,,,,0,,,,-0.00245,,,,,,99.989357,,,,
,23161491.82,99.9914551,-8356.04345703125,-4.83157881020579E-5,6.04662564389946E-7,1,0.999253354069792,40.0298881530762,1.98457415547281,16.8099999427795,-0.000538892273956191,-0.00013612632708032,0.25,-3.55621119907533E-6,-4.85772762153616E-5,-3.72511334536509E-6,99.9914551,99.9914551,-8363.5439453125,-8348.54296875,56.1725151630444,20.5910932150265,23.288654,0,0,0,40,4449,100.1411,-8356.04345703125,,,,,,,,,,,,,0,,,,0.00245,,,,,,99.9914551,,,,
,23161587.005,99.9915466,-3597.98706054687,-5.89294500803001E-5,4.19475153898602E-7,1,0.999253354069792,40.0298881530762,1.98450342018989,16.8099999427795,-0.00066218883203774,-0.000137893370709578,0.25,-1.84711865511523E-6,-5.92556627443717E-5,-2.03986805999572E-6,99.9915466,99.9915466,-3600.4677734375,-3595.50634765625,56.5664559367368,20.5919009257105,24.047956,0,0,0,40,4449,100.1469,-3597.98706054687,,,,,,,,,,,,,0,,,,0,,,,,,99.9915466,,,,
,23161683.095,99.9934082,1203.74224853516,-5.67892572604013E-5,2.64150612628596E-7,1,0.999253354069792,40.0298881530762,1.98450399938732,16.8099999427795,-0.000642077854200557,-0.000110467815952668,0.25,2.04250511679373E-7,-5.71096159987559E-5,2.9360034642857E-8,99.9934082,99.9934082,1196.00134277344,1211.48315429688,56.6649411301598,20.5902622118673,23.668306,0,0,0,40,4449,100.1512,1203.74224853516,,,,,,,,,,,,,0,,,,-0.0049,,,,,,99.9934082,,,,
,23161777.9,99.99849315,5939.89526367187,-5.40568705036261E-5,6.60681042217178E-7,1,0.999253354069792,40.0298881530762,1.98442113350326,16.8099999427795,-0.000614073822445359,-8.85891778873602E-5,0.25,1.6593823972944E-6,-5.4366639409476E-5,1.50183987870051E-6,99.9984283,99.998558,5932.3583984375,5947.43212890625,55.8504842131213,20.5957644837552,23.668306,0,0,0,40,4449,100.15365,5939.89526367187,,,,,,,,,,,,,0,,,,-0.0049,,,,,,99.99849315,,,,
,23161873.775,100.0042839,10733.3256835938,-3.777450860484E-5,5.38762740921572E-7,1,0.999253354069792,40.0298881530762,1.98450190468103,16.8099999427795,-0.000432110326087567,-4.49430028942824E-5,0.25,2.66044450203098E-6,-3.79958130535317E-5,2.55937973026249E-6,100.0042801,100.0042877,10730.6611328125,10735.990234375,56.5109603118714,20.5918236100779,24.047956,0,0,0,40,4449,100.1472,10733.3256835938,,,,,,,,,,,,,0,,,,0,,,,,,100.0042839,,,,
,23161969.49,100.0071106,15518.4760742187,-1.2881198444529E-5,8.30337120264289E-7,1,0.999253354069792,40.0298881530762,1.98467041906552,16.8099999427795,-0.000155322152286798,2.99676495818878E-5,0.25,4.91525362876542E-6,-1.29689935297175E-5,4.90364236450938E-6,100.0071106,100.0071106,15513.61328125,15523.3388671875,56.2561494146021,20.5913762904279,24.047956,0,0,0,40,4449,100.1406,15518.4760742187,,,,,,,,,,,,,0,,,,0.0049,,,,,,100.0071106,,,,
,23162066.845,100.009964,20383.2021484375,-2.30016472394283E-6,1.15197920086164E-6,1,0.999253354069792,40.0298881530762,1.98459021711834,16.8099999427795,-3.9521421711665E-5,7.24399905477487E-5,0.25,6.81469936773844E-6,-2.33389444255047E-6,6.84625526326735E-6,100.009964,100.009964,20380.576171875,20385.828125,56.4132567469675,20.5915348142463,23.668306,0,0,0,40,4449,100.1317,20383.2021484375,,,,,,,,,,,,,0,,,,0.0049,,,,,,100.009964,,,,
,23162164.67,100.01039125,25270.9384765625,-6.92042984096295E-6,9.07803423763007E-7,1,0.999253354069792,40.0298881530762,1.9844668959674,16.8099999427795,-9.65968565050734E-5,9.09985986398296E-5,0.25,9.26905361351216E-6,-6.98764928581426E-6,9.30063900105658E-6,100.0101776,100.0106049,25263.46875,25278.408203125,56.1357786226406,20.5910709392362,24.047956,0,0,0,40,4449,100.1197,25270.9384765625,,,,,,,,,,,,,0,,,,0.0049,,,,,,100.01039125,,,,
,23162264.5,100.0107727,30261.033203125,-1.80297439291776E-5,1.1576812305289E-6,1,0.999253354069792,40.0298881530762,1.98464524077536,16.8099999427795,-0.000223165984670426,7.47615893344566E-5,0.25,9.78272100523957E-6,-1.81614118535985E-5,9.78404501507646E-6,100.0107727,100.0107727,30256.205078125,30265.861328125,56.2014354182559,20.5913203467824,24.047956,0,0,0,40,4449,100.1081,30261.033203125,,,,,,,,,,,,,0,,,,0,,,,,,100.0107727,,,,
,23162365.58,100.0110397,35313.5078125,-3.54462867209602E-5,1.39712742538317E-6,1,0.999253354069792,40.0298881530762,1.98434510118611,16.8099999427795,-0.000423461974865222,6.03264055400249E-5,0.25,1.15646582170555E-5,-3.56821825289996E-5,1.15245338455889E-5,100.0110397,100.0110397,35308.609375,35318.40625,56.6672860157175,20.5946388032275,23.668306,0,0,0,40,4449,100.09655,35313.5078125,,,,,,,,,,,,,0,,,,0,,,,,,100.0110397,,,,
,23162464.115,100.0106354,40238.685546875,-5.31116883402027E-5,1.3597473151642E-6,1,0.999253354069792,40.0298881530762,1.98439386824307,16.8099999427795,-0.000628124954002586,5.39824553085981E-5,0.25,1.41046658633994E-5,-5.34556977544317E-5,1.40273607005289E-5,100.0106354,100.0106354,40231.1875,40246.18359375,55.9005084383521,20.5929551497399,23.668306,0,0,0,40,4449,100.0889,40238.685546875,,,,,,,,,,,,,0,,,,0,,,,,,100.0106354,,,,
,23162561.41,100.0096054,45104.044921875,-6.81905432140125E-5,1.49689643773639E-6,1,0.999253354069792,40.0298881530762,1.98449545127239,16.8099999427795,-0.000798847020500957,2.57472278218109E-5,0.25,1.42524876741193E-5,-6.86210705436715E-5,1.4132701118203E-5,100.0096054,100.0096054,45094.1171875,45113.97265625,56.1654805063713,20.5933826766465,24.047956,0,0,0,40,4449,100.0788,45104.044921875,,,,,,,,,,,,,0,,,,-0.0049,,,,,,100.0096054,,,,
,23162659.5,100.0077591,50006.69921875,-8.67444706385673E-5,1.89450939444549E-6,1,0.999253354069792,40.0298881530762,1.98437581715385,16.8099999427795,-0.00101389764274475,1.99189610994888E-5,0.25,1.69930792306628E-5,-8.72891843596548E-5,1.68360422328336E-5,100.0077591,100.0077591,49996.6875,50016.7109375,55.8723698116598,20.5937209077216,23.288654,0,0,0,40,4449,100.07085,50006.69921875,,,,,,,,,,,,,0,,,,0.00245,,,,,,100.0077591,,,,
,23162758.84,100.0093994,54968.880859375,-0.000106300142071391,2.13549295159937E-6,1,0.999253354069792,40.0298881530762,1.98437197762627,16.8099999427795,-0.0012313368394434,-3.90294473407038E-5,0.25,1.52076408817929E-5,-0.000106951805140543,1.49853919565278E-5,100.0093994,100.0093994,54958.96875,54978.79296875,56.3147715535444,20.5926723501421,23.668306,0,0,0,40,4449,100.0646,54968.880859375,,,,,,,,,,,,,0,,,,-0.00245,,,,,,100.0093994,,,,
,23162857.46,100.0072174,59899.228515625,-0.000123421862841366,1.88282442961895E-6,1,0.999253354069792,40.0298881530762,1.98427500642873,16.8099999427795,-0.00143094906974382,-3.7679143766206E-5,0.25,1.83303444730125E-5,-0.00012418112210549,1.80787360413304E-5,100.0072174,100.0072174,59891.81640625,59906.640625,56.0318220295829,20.5932059341387,24.047956,0,0,0,40,4449,100.0569,59899.228515625,,,,,,,,,,,,,0,,,,-0.00245,,,,,,100.0072174,,,,
,23162955.93,100.0082626,64819.716796875,-0.000144550623612607,2.06641577368465E-6,1,0.999253354069792,40.0298881530762,1.98452527444187,16.8099999427795,-0.00166786773701604,-9.11861686091267E-5,0.25,1.73019450235609E-5,-0.000145428680689437,1.69864184983961E-5,100.0082626,100.0082626,64814.9453125,64824.48828125,56.7681160946983,20.5891178264522,24.047956,0,0,0,40,4449,100.0486,64819.716796875,,,,,,,,,,,,,0,,,,0.0049,,,,,,100.0082626,,,,
,23163053.435,100.0084534,69694.9140625,-0.000158247715385877,2.16408413547645E-6,1,0.999253354069792,40.0298881530762,1.98442287622078,16.8099999427795,-0.00182441626956015,-0.000107873911993077,0.25,1.8225773388426E-5,-0.00015920785647013,1.78795030366585E-5,100.0084229,100.0084839,69682.421875,69707.40625,56.1178011666983,20.5886860726398,23.668306,0,0,0,40,4449,100.0407,69694.9140625,,,,,,,,,,,,,0,,,,0,,,,,,100.0084534,,,,
,23163153.52,100.0078201,74697.31640625,-0.000175529416770211,2.12367204023575E-6,1,0.999253354069792,40.0298881530762,1.98446783227549,16.8099999427795,-0.00201828455222239,-0.000150579505119589,0.25,1.74763128229336E-5,-0.000176587727049064,1.70802200569209E-5,100.0078201,100.0078201,74689.8125,74704.8203125,56.3663590358137,20.5873160966855,24.427608,0,0,0,40,4449,100.0364,74697.31640625,,,,,,,,,,,,,0,,,,-0.0049,,,,,,100.0078201,,,,
,23163251.34,100.0065918,79585.7421875,-0.000190772020142319,2.18554403227614E-6,1,0.999253354069792,40.0298881530762,1.98456717254579,16.8099999427795,-0.00219484307868083,-0.000156957294968482,0.25,1.95835928916618E-5,-0.000191925062263786,1.91604223668927E-5,100.0065918,100.0065918,79573.234375,79598.25,57.0940551872176,20.5853693380784,24.047956,0,0,0,40,4449,100.0297,79585.7421875,,,,,,,,,,,,,0,,,,0.0049,,,,,,100.0065918,,,,
,23163348.91,100.0083466,84466.55078125,-0.000219142935995697,2.64363826611349E-6,1,0.999253354069792,40.0298881530762,1.98453741642301,16.8099999427795,-0.00251431936316815,-0.000219693967230813,0.25,1.90057178322828E-5,-0.000220459024103144,1.85040020310534E-5,100.0083466,100.0083466,84456.34375,84476.7578125,56.6477453027368,20.5878684762495,24.047956,0,0,0,40,4449,100.0235,84466.55078125,,,,,,,,,,,,,0,,,,-0.0049,,,,,,100.0083466,,,,
,23163442.095,100.0074005,89122.28125,-0.00023603530760008,1.45973708273493E-6,1,0.999253354069792,40.0298881530762,1.98444353484849,16.8099999427795,-0.00270099779611416,-0.000276686724416923,0.25,1.69208794667596E-5,-0.000237444414802439,1.63645842301301E-5,100.0074005,100.0074005,89109.7265625,89134.8359375,56.5242479966983,20.5898334241093,24.047956,0,0,0,40,4449,100.01675,89122.28125,,,,,,,,,,,,,0,,,,-0.00245,,,,,,100.0074005,,,,
,23163555.485,100.0032349,86228.48828125,-0.000227454821648809,3.08113263611092E-6,1,0.999253354069792,40.0298881530762,1.9844168193495,16.8099999427795,-0.00261245297505414,-0.000211406132089908,0.25,2.11946415004754E-5,-0.000228825430061798,2.06839725961312E-5,100.0032349,100.0032349,86218.6796875,86238.296875,56.3014838687175,20.5903346159014,24.047956,0,0,0,40,4449,100.01475,86228.48828125,,,,,,,,,,,,,0,,,,-0.00245,,,,,,100.0032349,,,,
,23163652.235,99.9974594,81387.9765625,-0.000205788433741356,2.3917722966382E-6,1,0.999253354069792,40.0298881530762,1.98446241892661,16.8099999427795,-0.00236055476457597,-0.000208854135081847,0.25,1.76239478753014E-5,-0.000207022896832958,1.71487871269711E-5,99.9974594,99.9974594,81380.546875,81395.40625,56.0146262021598,20.5880549835773,23.668306,0,0,0,40,4449,100.01835,81387.9765625,,,,,,,,,,,,,0,,,,0,,,,,,99.9974594,,,,
,23163752.96,99.9977646,76354.08203125,-0.000188562194138569,2.55306751950249E-6,1,0.999253354069792,40.0298881530762,1.98446627916996,16.8099999427795,-0.00216517465762974,-0.000178670056554535,0.25,1.7276392113235E-5,-0.000189695253660169,1.68434831835145E-5,99.9977646,99.9977646,76346.4609375,76361.703125,56.2053435608521,20.5895848902357,23.288654,0,0,0,40,4449,100.0211,76354.08203125,,,,,,,,,,,,,0,,,,0,,,,,,99.9977646,,,,
,23163850.955,99.9947357,71457.86328125,-0.00016744956284743,1.9817208582446E-6,1,0.999253354069792,40.0298881530762,1.98445709421821,16.8099999427795,-0.00193093894085011,-0.000111870664901824,0.25,1.94860573265133E-5,-0.000168466479067383,1.91219533212293E-5,99.9947357,99.9947357,71452.8125,71462.9140625,55.7387113348713,20.5886734246949,24.047956,0,0,0,40,4449,100.02505,71457.86328125,,,,,,,,,,,,,0,,,,0.00245,,,,,,99.9947357,,,,
,23163948.77,99.9944839,66565.1796875,-0.000149368477613308,1.61178648603552E-6,1,0.999253354069792,40.0298881530762,1.98435786941409,16.8099999427795,-0.00172346767073695,-9.33903354718732E-5,0.25,1.79508969343583E-5,-0.000150276334519697,1.76262763887293E-5,99.9944839,99.9944839,66550.0390625,66580.3203125,56.3343122665252,20.5931931023697,23.288654,0,0,0,40,4449,100.0321,66565.1796875,,,,,,,,,,,,,0,,,,0.00245,,,,,,99.9944839,,,,
,23164046.325,99.9940262,61688.98828125,-0.00012957079725911,1.49596466329192E-6,1,0.999253354069792,40.0298881530762,1.98438714695714,16.8099999427795,-0.00150090269077151,-4.76539799891995E-5,0.25,1.85263275084048E-5,-0.000130366075487895,1.8258955686788E-5,99.9940262,99.9940262,61676.5,61701.4765625,56.1998721612175,20.5931236666848,24.047956,0,0,0,40,4449,100.03605,61688.98828125,,,,,,,,,,,,,0,,,,0.0049,,,,,,99.9940262,,,,
,23164144.72,99.9943161,56771.51171875,-0.000112055059279756,1.80437093379497E-6,1,0.999253354069792,40.0298881530762,1.98431046517914,16.8099999427795,-0.00130021505406604,-2.83162060019163E-5,0.25,1.71652683306158E-5,-0.000112745524508464,1.69382129974784E-5,99.9943161,99.9943161,56768.703125,56774.3203125,56.1021685963136,20.594071434299,24.427608,0,0,0,40,4449,100.0403,56771.51171875,,,,,,,,,,,,,0,,,,0.0049,,,,,,99.9943161,,,,
,23164241.665,99.994072,51926.611328125,-9.54015576268408E-5,1.68669862946306E-6,1,0.999253354069792,40.0298881530762,1.9843254848163,16.8099999427795,-0.00110652637236364,-2.66960155581737E-5,0.25,1.43870243811203E-5,-9.59882395974657E-5,1.41904464669948E-5,99.994072,99.994072,51921.7734375,51931.44921875,56.0286955155059,20.5934543616529,23.668306,0,0,0,40,4449,100.04715,51926.611328125,,,,,,,,,,,,,0,,,,0,,,,,,99.994072,,,,
,23164337.765,99.99189,47121.5,-7.92597832992557E-5,1.73394782453703E-6,1,0.999253354069792,40.0298881530762,1.98452826826185,16.8099999427795,-0.000927272472103066,2.27157833873599E-5,0.25,1.59273381080544E-5,-7.97584699396865E-5,1.57850685204933E-5,99.99189,99.99189,47119.00390625,47123.99609375,56.5023623981598,20.5928023971301,24.047956,0,0,0,40,4449,100.0542,47121.5,,,,,,,,,,,,,0,,,,0,,,,,,99.99189,,,,
,23164434.795,99.9922638,42273.84375,-6.26884491801725E-5,1.4364251271536E-6,1,0.999253354069792,40.0298881530762,1.98444076619035,16.8099999427795,-0.000733678063501582,1.97324720335472E-5,0.25,1.27549160211288E-5,-6.30830605413894E-5,1.26419834271259E-5,99.9922638,99.9922638,42266.33203125,42281.35546875,56.9385111118906,20.5949539782975,23.668306,0,0,0,40,4449,100.06015,42273.84375,,,,,,,,,,,,,0,,,,0,,,,,,99.9922638,,,,
,23164532.675,99.9944687,37383.794921875,-4.3909370688958E-5,9.54979079317297E-7,1,0.999253354069792,40.0298881530762,1.98432693768489,16.8099999427795,-0.000523952901615961,7.12561851638196E-5,0.25,1.40181164855631E-5,-4.42007195365338E-5,1.3967000583621E-5,99.9944687,99.9944687,37378.71484375,37388.875,56.2866329268521,20.595043631682,23.668306,0,0,0,40,4449,100.0666,37383.794921875,,,,,,,,,,,,,0,,,,0,,,,,,99.9944687,,,,
,23164626.455,99.9917068,32696.4130859375,-2.72835799034786E-5,9.50153854954149E-7,1,0.999253354069792,40.0298881530762,1.98429325169259,16.8099999427795,-0.000330078006201525,7.00080687044628E-5,0.25,1.09883624828268E-5,-2.74713825805175E-5,1.09689739554767E-5,99.9917068,99.9917068,32661.26171875,32731.564453125,56.4632809721983,20.5974260645991,23.668306,0,0,0,40,4449,100.07425,32696.4130859375,,,,,,,,,,,,,0,,,,-0.00245,,,,,,99.9917068,,,,
,23164724.225,99.9915695,27809.24609375,-1.10351297388495E-5,9.62516127676745E-7,1,0.999253354069792,40.0298881530762,1.98434978107305,16.8099999427795,-0.000142523937576992,7.96460368905697E-5,0.25,8.98747685546178E-6,-1.11247783661681E-5,9.00514946060083E-6,99.9915695,99.9915695,27799.365234375,27819.126953125,55.6433526555251,20.5954778677079,23.668306,0,0,0,40,4449,100.08445,27809.24609375,,,,,,,,,,,,,0,,,,-0.00245,,,,,,99.9915695,,,,
,23164822.075,99.9914322,22916.6953125,6.07391458507207E-6,7.80443982982304E-7,1,0.999253354069792,40.0298881530762,1.98433334644255,16.8099999427795,5.20415293256183E-5,0.000106464675628036,0.25,8.35562475438544E-6,6.08295283975816E-6,8.42134268633708E-6,99.9914322,99.9914322,22911.53125,22921.859375,56.2256659023521,20.5972483718586,24.047956,0,0,0,40,4449,100.0931,22916.6953125,,,,,,,,,,,,,0,,,,0.00245,,,,,,99.9914322,,,,
,23164917.05,99.9912033,18171.517578125,2.08094641390698E-5,9.42512954491458E-7,1,0.999253354069792,40.0298881530762,1.98439976609118,16.8099999427795,0.000221905360292931,0.000116553963672358,0.25,6.65919792488455E-6,2.09067860939048E-5,6.76030731069336E-6,99.9912033,99.9912033,18163.900390625,18179.134765625,56.0888809114867,20.5974983705034,24.047956,0,0,0,40,4449,100.09985,18171.517578125,,,,,,,,,,,,,0,,,,-0.00245,,,,,,99.9912033,,,,
,23165013.75,99.9909973,13339.1860351562,3.42463910166574E-5,8.74901662778001E-7,1,0.999253354069792,40.0298881530762,1.98438820427264,16.8099999427795,0.000377428498400721,0.000122138456168293,0.25,4.79215437335319E-6,3.44250332305199E-5,4.92421432366868E-6,99.9909973,99.9909973,13336.60546875,13341.7666015625,56.066213684429,20.5954066052063,24.427608,0,0,0,40,4449,100.1096,13339.1860351562,,,,,,,,,,,,,0,,,,0.00245,,,,,,99.9909973,,,,
,23165110.62,99.99227525,8496.2216796875,4.74834512707274E-5,5.17835007519351E-7,1,0.999253354069792,40.0298881530762,1.98437163117546,16.8099999427795,0.000530323167369651,0.000129407585066803,0.25,3.10896200360008E-6,4.77415990488817E-5,3.27282261264244E-6,99.9921646,99.9923859,8493.6884765625,8498.7548828125,56.4367056025444,20.5969414073707,23.668306,0,0,0,40,4449,100.115,8496.2216796875,,,,,,,,,,,,,0,,,,0,,,,,,99.99227525,,,,
,23165205.62,99.99241255,3745.69396972656,5.90509363712863E-5,3.81835658706703E-7,1,0.999253354069792,40.0298881530762,1.98445436813602,16.8099999427795,0.000664944452804747,0.000130171649970775,0.25,1.14260614955687E-6,5.93799865868216E-5,1.33181646133105E-6,99.9922409,99.9925842,3740.67895507812,3750.708984375,56.3687039213713,20.5971926844897,23.668306,0,0,0,40,4449,100.12295,3745.69396972656,,,,,,,,,,,,,0,,,,-0.00245,,,,,,99.99241255,,,,
,23165280.935,99.9909058,-0.296863570809364,6.16277837198422E-5,2.87811046045667E-7,1,0.999253354069792,40.0298881530762,1.98446549568953,16.8099999427795,0.000697451345401831,0.000115999728329566,0.25,-5.65062911113677E-7,6.19764062712929E-5,-3.7698402761053E-7,99.9909058,99.9909058,-0.319699227809906,-0.274027913808823,56.4476484018137,20.5969322219541,23.668306,0,0,0,40,4417,100.1252,-0.296863570809364,,,,,,,,,,,,,0,,,,-0.0049,,,,,,99.9909058,,,,