File: data/doubleLayers/dl_2-5/ppms/DD205_5/KoelnPPMS/DD205_5_FCC_100OE.DAT
[Header]
; VSM Data File (default extension .dat)
; Copyright (c) 2003-2013, Quantum Design, Inc. All rights reserved.
TITLE,
FILEOPENTIME,23105734.92,09/25/2018,7:14 pm
BYAPP,VSM,2.0,2.0
INFO,PPMS VSM Option Release 1.4.10 Build 1,APPNAME
INFO,Quantum Design Linear Motor Servo Controller,MOTOR_MODULE_NAME
INFO,3101-100 M1,MOTOR_HW_VERSION
INFO,MMC1014,MOTOR_SERIAL_NUMBER
INFO,SRV No X-over 01.03.11,MOTOR_SOFTWARE_VERSION
INFO,Quantum Design VSM Detection Module,VSM_MODULE_NAME
INFO,3101-150 F0,VSM_HW_VERSION
INFO,VSM707,VSM_SERIAL_NUMBER
INFO,VSM No X-over 01.02.05 May 20 2008 13:51:47,VSM_SOFTWARE_VERSION
INFO,704,PREAMP_SERIAL_NUMBER
INFO,822,COIL_SERIAL_NUMBER
INFO,0,MOMENT_UNITS
INFO,,SAMPLE_MATERIAL
INFO,,SAMPLE_COMMENT
INFO,,SAMPLE_MASS
INFO,,SAMPLE_VOLUME
INFO,,SAMPLE_MOLECULAR_WEIGHT
INFO,,SAMPLE_SIZE
INFO,,SAMPLE_SHAPE
DATATYPE,COMMENT,1
DATATYPE,TIME,2
STARTUPAXIS,X,2
STARTUPAXIS,Y1,5
[Data]
Comment,Time Stamp (sec),Temperature (K),Magnetic Field (Oe),Moment (emu),M. Std. Err. (emu),Transport Action,Averaging Time (sec),Frequency (Hz),Peak Amplitude (mm),Center Position (mm),Coil Signal' (mV),Coil Signal" (mV),Range (mV),M. Quad. Signal (emu),M. Raw' (emu),M. Raw" (emu),Min. Temperature (K),Max. Temperature (K),Min. Field (Oe),Max. Field (Oe),Mass (grams),Motor Lag (deg),Pressure (Torr),VSM Status (code),Motor Status (code),Measure Status (code),Measure Count,PPMS Status (code),System Temp. (K),System Field (Oe),Sample Position (deg),Bridge 1 Resistance (ohms),Bridge 1 Excitation (에),Bridge 2 Resistance (ohms),Bridge 2 Excitation (에),Bridge 3 Resistance (ohms),Bridge 3 Excitation (에),Bridge 4 Resistance (ohms),Bridge 4 Excitation (에),Signal 1 Vin (V),Signal 2 Vin (V),Digital Inputs (code),Drive 1 Iout (mA),Drive 1 Ipower (W),Drive 2 Iout (mA),Drive 2 Ipower (W),Pressure (),Map 20 (),Map 21 (),Map 22 (),Map 23 (),Map 24 (),Map 25 (),Map 26 (),Map 27 (),Map 28 (),Map 29 ()
,23106254.815,349.903656,99.4721298217773,1.32582681383258E-5,4.76645057250903E-7,1,0.999253354069792,40.0298881530762,1.99857781232339,15.4900001361966,0.000150414050715882,2.22566167118121E-5,0.25,-3.25512214847104E-7,1.32349877170339E-5,-3.17573690939084E-7,349.903656,349.903656,99.4721298217773,99.4721298217773,56.7618630665445,20.5496913622311,27.844467,0,0,0,40,4369,351.56765,99.4721298217773,,,,,,,,,,,,,0,,,,0.00245,,,,,,349.903656,,,,
,23106420.525,346.9688721,99.4721298217773,1.35651624890309E-5,4.85636642831828E-7,1,0.999253354069792,40.0298881530762,1.99866994581686,15.4900001361966,0.000154213418617093,2.10675820867907E-5,0.25,-4.84312953010789E-7,1.35427693827507E-5,-4.75828374899162E-7,346.9688721,346.9688721,99.4721298217773,99.4721298217773,56.9088092281599,20.5469622422122,27.464817,0,0,0,40,4374,345.1047,99.4721298217773,,,,,,,,,,,,,0,,,,-0.00245,,,,,,346.9688721,,,,
,23106564.295,343.4161682,99.4721298217773,1.36560856007308E-5,3.79858233686921E-7,1,0.999253354069792,40.0298881530762,1.9986438116166,15.4900001361966,0.000155561151907651,1.9494573105605E-5,0.25,-6.39550325979546E-7,1.36352786514957E-5,-6.30748508715594E-7,343.4161682,343.4161682,99.4721298217773,99.4721298217773,56.4765686570252,20.5439310915423,27.844467,0,0,0,40,4374,341.59575,99.4721298217773,,,,,,,,,,,,,0,,,,0,,,,,,343.4161682,,,,
,23106711.32,339.9659119,99.4721298217773,1.31707688148687E-5,3.65215577054379E-7,1,0.999253354069792,40.0298881530762,1.99850297844209,15.4900001361966,0.000150133540040809,1.82648335603947E-5,0.25,-6.64514420598441E-7,1.31522837832618E-5,-6.55936189318958E-7,339.9659119,339.9659119,99.4721298217773,99.4721298217773,56.7384142109675,20.5436266333092,27.844467,0,0,0,40,4374,337.6929,99.4721298217773,,,,,,,,,,,,,0,,,,0.0049,,,,,,339.9659119,,,,
,23106859.05,336.4584351,99.4721298217773,1.4379808523211E-5,4.18215455890508E-7,1,0.999253354069792,40.0298881530762,1.99848907228671,15.4900001361966,0.00016270300437651,2.70525241824079E-5,0.25,-9.66123374917391E-8,1.43609939219433E-5,-8.80537641952502E-8,336.4584351,336.4584351,99.4721298217773,99.4721298217773,56.6672860157175,20.543974954552,27.464817,0,0,0,40,4374,333.8323,99.4721298217773,,,,,,,,,,,,,0,,,,-0.0049,,,,,,336.4584351,,,,
,23107011.27,332.8165894,99.4721298217773,,,2,,,,15.4199996739626,,,,,,,332.8165894,332.8165894,99.4721298217773,99.4721298217773,,,27.844467,,,,-99999999,4374,329.896,99.4721298217773,,,,,,,,,,,,,,,,,,,,,,,332.8165894,,,,
,23107150.5,329.4363403,99.4721298217773,1.38351563211419E-5,4.77764187765425E-7,1,0.999253354069792,40.0298881530762,1.99852701667741,15.4100004583597,0.000157064383368868,2.32458105437293E-5,0.25,-3.39866414390378E-7,1.38205644160983E-5,-3.31180838251704E-7,329.4363403,329.4363403,99.4721298217773,99.4721298217773,56.4476484018137,20.5405471734603,27.464817,0,0,0,40,4374,326.3297,99.4721298217773,,,,,,,,,,,,,0,,,,0,,,,,,329.4363403,,,,
,23107292.72,325.9881592,99.4721298217773,1.43135253070033E-5,4.59492880687891E-7,1,0.999253354069792,40.0298881530762,1.99839777863041,15.4100004583597,0.000162719928099243,2.28079725314119E-5,0.25,-4.61677916851586E-7,1.43002177820864E-5,-4.52519483607182E-7,325.9881592,325.9881592,99.4721298217773,99.4721298217773,56.7634263235829,20.5444120327473,27.844467,0,0,0,40,4374,322.7212,99.4721298217773,,,,,,,,,,,,,0,,,,0,,,,,,325.9881592,,,,
,23107437.98,322.4155579,99.4721298217773,,,2,,,,15.4399998262525,,,,,,,322.4155579,322.4155579,99.4721298217773,99.4721298217773,,,28.224119,,,,-99999999,4374,319.0452,99.4721298217773,,,,,,,,,,,,,,,,,,,,,,,322.4155579,,,,
,23107576.085,318.9742126,99.4721298217773,1.50281137784794E-5,5.05821729125178E-7,1,0.999253354069792,40.0298881530762,1.9986206685418,15.429999679327,0.000169807227012836,3.02860035362461E-5,0.25,7.48416383043653E-8,1.50174941582638E-5,8.41867274825721E-8,318.9742126,318.9742126,99.4721298217773,99.4721298217773,56.6969878994483,20.5513330264266,27.844467,0,0,0,40,4374,315.54615,99.4721298217773,,,,,,,,,,,,,0,,,,-0.0049,,,,,,318.9742126,,,,
,23107720.44,315.449585,99.4721298217773,1.47384350126162E-5,3.83085026108168E-7,1,0.999253354069792,40.0298881530762,1.99837228150816,15.429999679327,0.000166333350607514,3.08664169122102E-5,0.25,1.76201763216149E-7,1.47297847350634E-5,1.85443386078267E-7,315.449585,315.449585,99.4721298217773,99.4721298217773,56.7321611828137,20.5511868290202,27.844467,0,0,0,40,4374,311.8892,99.4721298217773,,,,,,,,,,,,,0,,,,-0.00245,,,,,,315.449585,,,,
,23107861.22,312.0041199,99.4721298217773,,,2,,,,15.4500003680587,,,,,,,312.0041199,312.0041199,99.4721298217773,99.4721298217773,,,27.464817,,,,-99999999,4374,308.325,99.4721298217773,,,,,,,,,,,,,,,,,,,,,,,312.0041199,,,,
,23107985.82,308.9266968,99.4721298217773,1.50284514280354E-5,3.87186520584332E-7,1,0.999253354069792,40.0298881530762,1.99819500108398,15.4400002211332,0.000170324820239543,2.74745585868002E-5,0.25,-1.74563338253472E-7,1.50233278008814E-5,-1.64725926736651E-7,308.9266968,308.9266968,99.4721298217773,99.4721298217773,56.7212183835445,20.5479782554854,27.464817,0,0,0,40,4374,305.1715,99.4721298217773,,,,,,,,,,,,,0,,,,0.00245,,,,,,308.9266968,,,,
,23108127.335,305.4596863,99.4721298217773,1.55403627889149E-5,4.36668328553127E-7,1,0.999253354069792,40.0298881530762,1.99818172098714,15.4400002211332,0.000176691899436454,2.52696418066729E-5,0.25,-4.58594463584472E-7,1.55371636313575E-5,-4.48238334908702E-7,305.4596863,305.4596863,99.4721298217773,99.4721298217773,56.7391958394868,20.5489295690718,27.844467,0,0,0,40,4374,301.593,99.4721298217773,,,,,,,,,,,,,0,,,,0.0049,,,,,,305.4596863,,,,
,23108285.88,301.5801086,99.4721298217773,,,2,,,,15.469999589026,,,,,,,301.5801086,301.5801086,99.4721298217773,99.4721298217773,,,27.844467,,,,-99999999,4374,297.5881,99.4721298217773,,,,,,,,,,,,,,,,,,,,,,,301.5801086,,,,
,23108411.73,298.4620361,99.4721298217773,1.5590476115735E-5,3.86532714282986E-7,1,0.999253354069792,40.0298881530762,1.99787279314726,15.4600003734231,0.000177414756404576,2.45750476753572E-5,0.25,-5.29201782540664E-7,1.5591209690077E-5,-5.18627239586137E-7,298.4620361,298.4620361,99.4721298217773,99.4721298217773,56.8243933480829,20.5547571941283,27.464817,0,0,0,40,4374,294.40885,99.4721298217773,,,,,,,,,,,,,0,,,,0.0049,,,,,,298.4620361,,,,
,23108551.725,294.962616,99.4721298217773,1.53804158073856E-5,3.68181264372671E-7,1,0.999253354069792,40.0298881530762,1.99782535453895,15.4600003734231,0.000174332540425435,2.83423331615803E-5,0.25,-1.60210690033522E-7,1.53828178622297E-5,-1.49637283520265E-7,294.962616,294.962616,99.4721298217773,99.4721298217773,56.7759323798906,20.5557347096466,27.844467,0,0,0,40,4374,290.8751,99.4721298217773,,,,,,,,,,,,,0,,,,0,,,,,,294.962616,,,,
,23108709.69,291.0855408,99.4721298217773,,,2,,,,15.4899997413158,,,,,,,291.0855408,291.0855408,99.4721298217773,99.4721298217773,,,27.844467,,,,-99999999,4374,286.9031,99.4721298217773,,,,,,,,,,,,,,,,,,,,,,,291.0855408,,,,
,23108835.32,287.9948883,99.4721298217773,1.6236546777318E-5,3.83391106317401E-7,1,0.999253354069792,40.0298881530762,1.99794083607154,15.4799995943904,0.000183586773353879,3.2847711887882E-5,0.25,8.84157897321102E-8,1.62429498270382E-5,9.99784098900968E-8,287.9609375,288.0288391,99.4721298217773,99.4721298217773,56.8447156895829,20.5521616690036,28.224119,0,0,0,40,4374,283.7244,99.4721298217773,,,,,,,,,,,,,0,,,,-0.00245,,,,,,287.9948883,,,,
,23108978.265,284.4728699,99.4721298217773,1.6010223272755E-5,3.5713671569696E-7,1,0.999253354069792,40.0298881530762,1.99791275577503,15.4799995943904,0.000181428860320291,3.01966691615081E-5,0.25,-1.07074696139895E-7,1.60186948422507E-5,-9.55880390078945E-8,284.4728699,284.4728699,99.4721298217773,99.4721298217773,56.8408075469868,20.5526625698784,27.464817,0,0,0,40,4374,280.1275,99.4721298217773,,,,,,,,,,,,,0,,,,0,,,,,,284.4728699,,,,
,23109129.48,280.7100525,99.4721298217773,,,2,,,,15.5200004354119,,,,,,,280.7100525,280.7100525,99.4721298217773,99.4721298217773,,,27.844467,,,,-99999999,4374,276.3437,99.4721298217773,,,,,,,,,,,,,,,,,,,,,,,280.7100525,,,,
,23109259.38,277.4581299,99.4721298217773,1.65097208573268E-5,3.1383563981714E-7,1,0.999253354069792,40.0298881530762,1.99780637997602,15.5100002884865,0.00018778424789955,2.73515525014222E-5,0.25,-4.45859223962893E-7,1.65228550771065E-5,-4.33930914749097E-7,277.4581299,277.4581299,99.4721298217773,99.4721298217773,56.6774471864675,20.554507460536,27.844467,0,0,0,40,4374,273.07995,99.4721298217773,,,,,,,,,,,,,0,,,,-0.0049,,,,,,277.4581299,,,,
,23109397.68,273.9931946,99.4721298217773,1.66214937307238E-5,2.98106545183763E-7,1,0.999253354069792,40.0298881530762,1.99773478257393,15.5100002884865,0.000189628490420472,2.43324265068278E-5,0.25,-7.32297738692504E-7,1.6636996689402E-5,-7.20407918247771E-7,273.9931946,273.9931946,99.4721298217773,99.4721298217773,56.7860935506406,20.5558087251343,27.844467,0,0,0,40,4374,269.6193,99.4721298217773,,,,,,,,,,,,,0,,,,0.0049,,,,,,273.9931946,,,,
,23109550.8,270.221344,99.4721298217773,,,2,,,,15.5500001981854,,,,,,,270.221344,270.221344,99.4721298217773,99.4721298217773,,,28.603769,,,,-99999999,4374,265.7875,99.4721298217773,,,,,,,,,,,,,,,,,,,,,,,270.221344,,,,
,23109681.47,266.960907,99.4721298217773,1.7446496930943E-5,3.86557427540524E-7,1,0.999253354069792,40.0298881530762,1.99770928470416,15.54000005126,0.000199501889729385,2.31613551159783E-5,0.25,-9.79665803524979E-7,1.74673352776242E-5,-9.67191486304539E-7,266.960907,266.960907,99.4721298217773,99.4721298217773,56.7313795542945,20.5553581364159,27.844467,0,0,0,40,4374,262.5163,99.4721298217773,,,,,,,,,,,,,0,,,,0.0049,,,,,,266.960907,,,,
,23109820.54,263.46923825,99.4721298217773,1.69447523927914E-5,4.14213251009452E-7,1,0.999253354069792,40.0298881530762,1.99769831889138,15.54000005126,0.000192348565154592,3.07973860768325E-5,0.25,-2.18934420990181E-7,1.69665320708419E-5,-2.05790818414943E-7,263.4394531,263.4990234,99.4721298217773,99.4721298217773,56.780622151006,20.5543148969712,28.603769,0,0,0,40,4374,259.06035,99.4721298217773,,,,,,,,,,,,,0,,,,0.00245,,,,,,263.46923825,,,,
,23109967.34,259.8144226,99.4721298217773,,,2,,,,15.579999960959,,,,,,,259.8144226,259.8144226,99.4721298217773,99.4721298217773,,,28.224119,,,,-99999999,4374,255.3869,99.4721298217773,,,,,,,,,,,,,,,,,,,,,,,259.8144226,,,,
,23110101.86,256.4492493,99.4721298217773,1.7661932692735E-5,3.26459664093839E-7,1,0.999253354069792,40.0298881530762,1.99787765084975,15.5699998140335,0.000200032573271293,3.51347455655538E-5,0.25,3.81586425906114E-8,1.7688827051927E-5,5.26790774868751E-8,256.4492493,256.4492493,99.4721298217773,99.4721298217773,56.6579064734868,20.5530254294378,27.844467,0,0,0,40,4374,252.02175,99.4721298217773,,,,,,,,,,,,,0,,,,0,,,,,,256.4492493,,,,
,23110239.53,252.9841156,99.4721298217773,1.73624775354057E-5,3.52014874078011E-7,1,0.999253354069792,40.0298881530762,1.99794072451885,15.5699998140335,0.000197009368491083,3.25936196190846E-5,0.25,-1.34869957886804E-7,1.73911881939814E-5,-1.20637766927411E-7,252.9841156,252.9841156,99.4721298217773,99.4721298217773,56.6024108486214,20.5521336604871,28.224119,0,0,0,40,4374,248.5782,99.4721298217773,,,,,,,,,,,,,0,,,,0,,,,,,252.9841156,,,,
,23110386.58,249.3439178,99.4721298217773,,,2,,,,15.6200002655387,,,,,,,249.3439178,249.3439178,99.4721298217773,99.4721298217773,,,27.844467,,,,-99999999,4374,244.8995,99.4721298217773,,,,,,,,,,,,,,,,,,,,,,,249.3439178,,,,
,23110520.07,245.9911804,99.4721298217773,1.78330494660432E-5,3.41260999187449E-7,1,0.999253354069792,40.0298881530762,1.99807065028155,15.6100001186132,0.000203413757817968,2.77078557579054E-5,0.25,-6.4891718490557E-7,1.78673738446685E-5,-6.34780040628251E-7,245.9911804,245.9911804,99.4721298217773,99.4721298217773,56.8947399148137,20.5517006146089,28.224119,0,0,0,40,4374,241.5739,99.4721298217773,,,,,,,,,,,,,0,,,,0.0049,,,,,,245.9911804,,,,
,23110659.47,242.4938507,99.4721298217773,1.79211723469283E-5,4.2661496626847E-7,1,0.999253354069792,40.0298881530762,1.99798841584523,15.6100001186132,0.000204308194974407,2.85838968220959E-5,0.25,-5.87397128864564E-7,1.79578146094423E-5,-5.72867663732533E-7,242.4938507,242.4938507,99.4721298217773,99.4721298217773,56.7173102409483,20.5513507405112,27.844467,0,0,0,40,4374,238.1017,99.4721298217773,,,,,,,,,,,,,0,,,,0,,,,,,242.4938507,,,,
,23110803.42,238.926712,99.4721298217773,,,2,,,,15.6599996387959,,,,,,,238.926712,238.926712,99.4721298217773,99.4721298217773,,,27.844467,,,,-99999999,4374,234.4967,99.4721298217773,,,,,,,,,,,,,,,,,,,,,,,238.926712,,,,
,23110938.54,235.4696503,99.4721298217773,1.81585759609629E-5,3.55018276245746E-7,1,0.999253354069792,40.0298881530762,1.99793234270626,15.6399998813868,0.000207342435128727,2.73402355812124E-5,0.25,-7.39396549040324E-7,1.82002912830904E-5,-7.24563073787177E-7,235.4696503,235.4696503,99.4721298217773,99.4721298217773,56.8916134007368,20.5540146093458,28.224119,0,0,0,40,4374,231.11925,99.4721298217773,,,,,,,,,,,,,0,,,,0.0049,,,,,,235.4696503,,,,
,23111077.485,231.9724426,99.4721298217773,1.78625364224538E-5,4.0444481789512E-7,1,0.999253354069792,40.0298881530762,1.99793683588552,15.6399998813868,0.000202882072705864,3.3266895186211E-5,0.25,-1.65976960516977E-7,1.79052214602742E-5,-1.49837309290697E-7,231.9724426,231.9724426,99.4721298217773,99.4721298217773,56.7024592990829,20.5536377014902,27.844467,0,0,0,40,4374,227.6627,99.4721298217773,,,,,,,,,,,,,0,,,,0.0049,,,,,,231.9724426,,,,
,23111219.53,228.4740143,99.4721298217773,,,2,,,,15.6999999433756,,,,,,,228.4740143,228.4740143,99.4721298217773,99.4721298217773,,,27.464817,,,,-99999999,4374,224.1165,99.4721298217773,,,,,,,,,,,,,,,,,,,,,,,228.4740143,,,,
,23111337.935,225.4669342,99.4721298217773,1.77073713848335E-5,3.49625051045601E-7,1,0.999253354069792,40.0298881530762,1.99824801476298,15.6900007277727,0.00019988965402483,4.05075276783658E-5,0.25,4.97565049713824E-7,1.77530011049476E-5,5.15840351657989E-7,225.4669342,225.4669342,99.4721298217773,99.4721298217773,56.4304525743906,20.5511081157081,28.224119,0,0,0,40,4374,221.1571,99.4721298217773,,,,,,,,,,,,,0,,,,-0.00245,,,,,,225.4669342,,,,
,23111477.605,221.9741211,99.4721298217773,1.78514937797819E-5,3.16002127557447E-7,1,0.999253354069792,40.0298881530762,1.99805618711079,15.6900007277727,0.000203160109767478,3.1400212089874E-5,0.25,-3.30701000527028E-7,1.790041527284E-5,-3.14146863789994E-7,221.9440918,222.0041504,99.4721298217773,99.4721298217773,56.8595666314483,20.5523179304306,27.464817,0,0,0,40,4374,217.66415,99.4721298217773,,,,,,,,,,,,,0,,,,-0.00245,,,,,,221.9741211,,,,
,23111616.265,218.4931793,99.4721298217773,1.8139201288879E-5,4.06129904676823E-7,1,0.999253354069792,40.0298881530762,1.99796447665761,15.6900007277727,0.000206193903988579,3.33813770100404E-5,0.25,-2.06563693638535E-7,1.81909170486612E-5,-1.89062569762132E-7,218.4931793,218.4931793,99.4721298217773,99.4721298217773,56.7282530402175,20.5529863495159,27.464817,0,0,0,40,4374,214.20845,99.4721298217773,,,,,,,,,,,,,0,,,,0.00245,,,,,,218.4931793,,,,
,23111737.985,215.4664154,99.4721298217773,1.85726064944439E-5,3.09593070931441E-7,1,0.999253354069792,40.0298881530762,1.99791484557418,15.7299991697073,0.000210452590558511,3.81231714438485E-5,0.25,1.35577868345413E-7,1.86270906368243E-5,1.54826615584461E-7,215.4664154,215.4664154,99.4721298217773,99.4721298217773,56.6563432164483,20.5548672552695,27.844467,0,0,0,40,4374,211.1611,99.4721298217773,,,,,,,,,,,,,0,,,,0.00245,,,,,,215.4664154,,,,
,23111876.2,211.9758911,99.4721298217773,1.79392248799527E-5,3.17982774864724E-7,1,0.999253354069792,40.0298881530762,1.99768887223381,15.7299991697073,0.000203564272164434,3.51693124049378E-5,0.25,-1.52005375021476E-8,1.79940806765955E-5,3.33489784681915E-9,211.9758911,211.9758911,99.4721298217773,99.4721298217773,56.699332785006,20.5563189351855,27.844467,0,0,0,40,4374,207.7183,99.4721298217773,,,,,,,,,,,,,0,,,,-0.0049,,,,,,211.9758911,,,,
,23112017.22,208.4715881,99.4721298217773,1.8111115014559E-5,3.28155812796799E-7,1,0.999253354069792,40.0298881530762,1.99769978405832,15.7299991697073,0.00020530348065816,3.6869721610292E-5,0.25,1.04033364933386E-7,1.81684609875187E-5,1.23526926632012E-7,208.4715881,208.4715881,99.4721298217773,99.4721298217773,56.7180918694675,20.5541640353479,27.844467,0,0,0,40,4374,204.2011,99.4721298217773,,,,,,,,,,,,,0,,,,0,,,,,,208.4715881,,,,
,23112155.68,204.953476,99.4721298217773,1.79995963973707E-5,3.94161782365729E-7,1,0.999253354069792,40.0298881530762,1.99766576742236,15.7800000160933,0.000204468712062135,3.42894766614218E-5,0.25,-1.04698123748789E-7,1.80588801161077E-5,-8.55851889541279E-8,204.953476,204.953476,99.4721298217773,99.4721298217773,56.6368025034675,20.5571516996903,28.224119,0,0,0,40,4374,200.7501,99.4721298217773,,,,,,,,,,,,,0,,,,0,,,,,,204.953476,,,,
,23112297.235,201.4353027,99.4721298217773,1.82814823263397E-5,3.13603336195635E-7,1,0.999253354069792,40.0298881530762,1.99764456466465,15.7800000160933,0.000208320568758683,3.12133379306275E-5,0.25,-4.25456839772399E-7,1.83441287250071E-5,-4.06694360644138E-7,201.4353027,201.4353027,99.4721298217773,99.4721298217773,56.8079791491791,20.562384437466,27.464817,0,0,0,40,4374,197.22095,99.4721298217773,,,,,,,,,,,,,0,,,,0.0049,,,,,,201.4353027,,,,
,23112434.35,197.9859314,99.4721298217773,1.80491153867281E-5,3.0305578110164E-7,1,0.999253354069792,40.0298881530762,1.99755685426965,15.7800000160933,0.000205588074271239,3.13872078645604E-5,0.25,-3.7040547737229E-7,1.81129124596138E-5,-3.51306464409483E-7,197.9859314,197.9859314,99.4721298217773,99.4721298217773,56.861911517006,20.5606914888318,27.844467,0,0,0,40,4374,193.81615,99.4721298217773,,,,,,,,,,,,,0,,,,0,,,,,,197.9859314,,,,
,23112575.595,194.4572906,99.4721298217773,1.80989113079078E-5,4.10065063198392E-7,1,0.999253354069792,40.0298881530762,1.99744188413846,15.8300008624792,0.000205658172854394,3.44038611418617E-5,0.25,-1.13928502229478E-7,1.81646168979404E-5,-9.33967799790098E-8,194.4572906,194.4572906,99.4721298217773,99.4721298217773,56.800944492506,20.5597372351622,27.085165,0,0,0,40,4374,190.2821,99.4721298217773,,,,,,,,,,,,,0,,,,0.0049,,,,,,194.4572906,,,,
,23112713.445,190.9839783,99.4721298217773,1.78220508507936E-5,3.16331672459258E-7,1,0.999253354069792,40.0298881530762,1.99743376721386,15.8300008624792,0.000202806886383175,3.23073732850857E-5,0.25,-2.51309179917003E-7,1.78888553513925E-5,-2.31130831118266E-7,190.9503937,191.0175629,99.4721298217773,99.4721298217773,56.8025077495445,20.5610151530027,27.464817,0,0,0,40,4374,186.84545,99.4721298217773,,,,,,,,,,,,,0,,,,0.00245,,,,,,190.9839783,,,,
,23112852.655,187.4912872,99.4721298217773,1.81695729154031E-5,4.20039757182594E-7,1,0.999253354069792,40.0298881530762,1.99754755859138,15.8300008624792,0.000206803586503133,3.28937533924779E-5,0.25,-2.6105060190235E-7,1.82396528183547E-5,-2.3999063307319E-7,187.4912872,187.4912872,99.4721298217773,99.4721298217773,56.8564401173714,20.5592796143113,27.464817,0,0,0,40,4374,183.36865,99.4721298217773,,,,,,,,,,,,,0,,,,0,,,,,,187.4912872,,,,
,23112993.35,183.9853058,99.4721298217773,1.74024791793024E-5,3.1702382749994E-7,1,0.999253354069792,40.0298881530762,1.9976697786937,15.87999984622,0.000197609311562957,3.4363451172971E-5,0.25,6.97389309836835E-10,1.74711536191825E-5,2.2375764552044E-8,183.9853058,183.9853058,99.4721298217773,99.4721298217773,56.8767624588714,20.5570884701608,27.085165,0,0,0,40,4374,179.86125,99.4721298217773,,,,,,,,,,,,,0,,,,0,,,,,,183.9853058,,,,
,23113135.625,180.4609833,99.4721298217773,1.77949828227743E-5,2.96609986273142E-7,1,0.999253354069792,40.0298881530762,1.99779721509795,15.87999984622,0.000202722995121303,3.15607694986643E-5,0.25,-3.15421352740367E-7,1.78674898476318E-5,-2.93930100539075E-7,180.4609833,180.4609833,99.4721298217773,99.4721298217773,56.8095424062176,20.5589474880041,26.705515,0,0,0,40,4374,176.26145,99.4721298217773,,,,,,,,,,,,,0,,,,0,,,,,,180.4609833,,,,
,23113273.795,176.937088,99.4721298217773,1.80030358518821E-5,3.32549289053225E-7,1,0.999253354069792,40.0298881530762,1.99756022270218,15.87999984622,0.000204818884157603,3.3496181021633E-5,0.25,-1.81766944706449E-7,1.80780978858704E-5,-1.58874391539249E-7,176.937088,176.937088,99.4721298217773,99.4721298217773,56.8306463762368,20.5624483360941,26.705515,0,0,0,40,4374,172.8589,99.4721298217773,,,,,,,,,,,,,0,,,,0,,,,,,176.937088,,,,
,23113412.475,173.4407501,99.4721298217773,1.79396631815211E-5,3.43100832054484E-7,1,0.999253354069792,40.0298881530762,1.99755387051023,15.9200001507998,0.000204427001705601,3.16053596637811E-5,0.25,-3.38158494905307E-7,1.80165019749441E-5,-3.15380127774335E-7,173.4407501,173.4407501,99.4721298217773,99.4721298217773,56.9174071418714,20.55836995846,26.705515,0,0,0,40,4374,169.4195,99.4721298217773,,,,,,,,,,,,,0,,,,0.00245,,,,,,173.4407501,,,,
,23113549.055,169.9931335,99.4721298217773,1.7965420453089E-5,3.51601710401649E-7,1,0.999253354069792,40.0298881530762,1.99732005575816,15.9200001507998,0.000204767203660965,3.13666811781976E-5,0.25,-3.6429668585279E-7,1.80441852755628E-5,-3.40946530512735E-7,169.9931335,169.9931335,99.4721298217773,99.4721298217773,56.7313795542945,20.5579271617106,27.464817,0,0,0,40,4374,166.0296,99.4721298217773,,,,,,,,,,,,,0,,,,0.0049,,,,,,169.9931335,,,,
,23113689.185,166.4716949,99.4721298217773,1.79231963713398E-5,2.81005036400396E-7,1,0.999253354069792,40.0298881530762,1.99717894918922,15.9200001507998,0.000203561925333494,3.54908932792871E-5,0.25,5.33312554163803E-9,1.80030286788631E-5,3.09803705033632E-8,166.4716949,166.4716949,99.4721298217773,99.4721298217773,56.8384626614291,20.558625367615,26.705515,0,0,0,40,4374,162.5487,99.4721298217773,,,,,,,,,,,,,0,,,,0.00245,,,,,,166.4716949,,,,
,23113807.36,163.4679108,99.4721298217773,1.79934311981348E-5,3.09767868235116E-7,1,0.999253354069792,40.0298881530762,1.99718972092417,15.990000218153,0.00020466951437644,3.395523817959E-5,0.25,-1.43021970175698E-7,1.80752760123732E-5,-1.17276386856816E-7,163.4679108,163.4679108,99.4721298217773,99.4721298217773,56.6305494753137,20.5616305735231,27.085165,0,0,0,40,4374,159.6059,99.4721298217773,,,,,,,,,,,,,0,,,,0.00245,,,,,,163.4679108,,,,
,23113948.515,159.95440675,99.4721298217773,1.77549632547293E-5,3.12326268703359E-7,1,0.999253354069792,40.0298881530762,1.99713534203709,15.990000218153,0.000202620118205062,2.97783603623707E-5,0.25,-4.70243517250066E-7,1.78378979992469E-5,-4.4553375795598E-7,159.9263306,159.9824829,99.4721298217773,99.4721298217773,56.536754053006,20.559224242714,26.325863,0,0,0,40,4374,156.0787,99.4721298217773,,,,,,,,,,,,,0,,,,-0.0049,,,,,,159.95440675,,,,
,23114085.955,156.4939728,99.4721298217773,1.78184427919173E-5,3.40132764623237E-7,1,0.999253354069792,40.0298881530762,1.99689591635164,15.990000218153,0.000202389363591462,3.53410491656355E-5,0.25,7.59434815957375E-9,1.79025575415039E-5,3.54937476313789E-8,156.4939728,156.4939728,99.4721298217773,99.4721298217773,56.7571732954291,20.5572417997175,26.705515,0,0,0,40,4374,152.64765,99.4721298217773,,,,,,,,,,,,,0,,,,0.00245,,,,,,156.4939728,,,,
,23114207.125,153.4752808,99.4721298217773,1.76914236084255E-5,3.18906820662172E-7,1,0.999253354069792,40.0298881530762,1.99705791053348,16.0499997437,0.00020169324296964,3.09866352732685E-5,0.25,-3.54850722986692E-7,1.77768788911029E-5,-3.28071500724325E-7,153.4752808,153.4752808,99.4721298217773,99.4721298217773,56.7993812354675,20.5571480335221,26.705515,0,0,0,40,4374,149.63825,99.4721298217773,,,,,,,,,,,,,0,,,,0,,,,,,153.4752808,,,,
,23114346.11,149.9691467,99.4721298217773,1.78706060982443E-5,2.91718472168662E-7,1,0.999253354069792,40.0298881530762,1.99701750395522,16.0499997437,0.000204001606175301,2.98584626933199E-5,0.25,-4.86559348774613E-7,1.79587087384618E-5,-4.59151910930252E-7,149.9691467,149.9691467,99.4721298217773,99.4721298217773,57.0487207331022,20.5608064298922,26.325863,0,0,0,40,4374,146.1773,99.4721298217773,,,,,,,,,,,,,0,,,,0.00245,,,,,,149.9691467,,,,
,23114486.285,146.4509735,99.4721298217773,1.76038401458334E-5,3.21174094015601E-7,1,0.999253354069792,40.0298881530762,1.99711749139418,16.0499997437,0.000200527165021077,3.20315569894798E-5,0.25,-2.50246764807257E-7,1.76917370612956E-5,-2.21067804408811E-7,146.4509735,146.4509735,99.4721298217773,99.4721298217773,56.7532651528329,20.5663693316282,26.325863,0,0,0,40,4374,142.6887,99.4721298217773,,,,,,,,,,,,,0,,,,-0.00245,,,,,,146.4509735,,,,
,23114624.525,142.9612885,99.4721298217773,1.76758541774279E-5,3.68627860259205E-7,1,0.999253354069792,40.0298881530762,1.99724930206057,16.1199998110533,0.000201301610996153,3.25959979727507E-5,0.25,-2.1468865762558E-7,1.7765474866204E-5,-1.84068929174039E-7,142.9612885,142.9612885,99.4721298217773,99.4721298217773,56.8712910592368,20.5726302722307,25.566563,0,0,0,40,4374,139.24455,99.4721298217773,,,,,,,,,,,,,0,,,,-0.0049,,,,,,142.9612885,,,,
,23114764.35,139.456665,99.4721298217773,1.80780051934737E-5,3.31856769792762E-7,1,0.999253354069792,40.0298881530762,1.9970077862361,16.1199998110533,0.000206011661099004,3.25453305684057E-5,0.25,-2.9046338536517E-7,1.81711972854282E-5,-2.58234616237168E-7,139.456665,139.456665,99.4721298217773,99.4721298217773,56.6641595016406,20.5818381039505,25.946213,0,0,0,40,4374,135.7607,99.4721298217773,,,,,,,,,,,,,0,,,,0,,,,,,139.456665,,,,
,23114903.345,135.9820251,99.4721298217773,1.755692089073E-5,3.00679513482589E-7,1,0.999253354069792,40.0298881530762,1.99694679529624,16.1199998110533,0.000199951507088545,3.23578860759826E-5,0.25,-2.17498661863362E-7,1.76485864890189E-5,-1.84534777608882E-7,135.9820251,135.9820251,99.4721298217773,99.4721298217773,56.9775925378522,20.5670543571033,25.566563,0,0,0,40,4374,132.3032,99.4721298217773,,,,,,,,,,,,,0,,,,0.0049,,,,,,135.9820251,,,,
,23115041.42,132.480545,99.4721298217773,1.78495969191225E-5,3.08041721589703E-7,1,0.999253354069792,40.0298881530762,1.99696900965221,16.1799993366003,0.000203219450707148,3.33667504998344E-5,0.25,-1.81510415149482E-7,1.79439519919211E-5,-1.46331891799028E-7,132.480545,132.480545,99.4721298217773,99.4721298217773,56.6852634716598,20.5673704821193,25.566563,0,0,0,40,4374,128.881,99.4721298217773,,,,,,,,,,,,,0,,,,-0.00245,,,,,,132.480545,,,,
,23115181.375,128.9542236,99.4721298217773,1.80419950974432E-5,3.03144979592617E-7,1,0.999253354069792,40.0298881530762,1.9970186475815,16.1799993366003,0.000205220633927634,3.49165114160162E-5,0.25,-8.06510679214457E-8,1.81383189294483E-5,-4.29143574252273E-8,128.9542236,128.9542236,99.4721298217773,99.4721298217773,56.5383173100444,20.5686443660839,25.566563,0,0,0,40,4374,125.4046,99.4721298217773,,,,,,,,,,,,,0,,,,0,,,,,,128.9542236,,,,
,23115319.19,125.4855118,99.4721298217773,1.77883790824245E-5,2.95652539096241E-7,1,0.999253354069792,40.0298881530762,1.99703449319534,16.1799993366003,0.00020244392378242,3.38854644613962E-5,0.25,-1.2896453032618E-7,1.78844878646132E-5,-9.02974638903323E-8,125.4855118,125.4855118,99.4721298217773,99.4721298217773,56.5281561392944,20.5741580003664,25.186911,0,0,0,40,4374,121.9933,99.4721298217773,,,,,,,,,,,,,0,,,,0.0049,,,,,,125.4855118,,,,
,23115459.135,121.9473648,99.4721298217773,1.79792117425553E-5,2.67551788146868E-7,1,0.999253354069792,40.0298881530762,1.9968682325123,16.2400007247925,0.000204856030412024,3.28437233725729E-5,0.25,-2.55842718299831E-7,1.80775977922036E-5,-2.15503619039258E-7,121.9473648,121.9473648,99.4721298217773,99.4721298217773,56.3687039213713,20.570987265951,25.566563,0,0,0,40,4374,118.5199,99.4721298217773,,,,,,,,,,,,,0,,,,0.00245,,,,,,121.9473648,,,,
,23115595.07,118.4619904,99.4721298217773,1.78295540229822E-5,2.94295885493962E-7,1,0.999253354069792,40.0298881530762,1.9968677878749,16.2400007247925,0.000203404642351082,3.1176175121643E-5,0.25,-3.7853587844242E-7,1.79282601126348E-5,-3.3718698493881E-7,118.4619904,118.4619904,99.4721298217773,99.4721298217773,56.6211699330829,20.5769198124898,25.566563,0,0,0,40,4374,115.1626,99.4721298217773,,,,,,,,,,,,,0,,,,0.0049,,,,,,118.4619904,,,,
,23115733.695,114.9875717,99.4721298217773,1.75908267941088E-5,3.00697529713574E-7,1,0.999253354069792,40.0298881530762,1.99696218324663,16.2400007247925,0.000200153568545912,3.38689745807016E-5,0.25,-1.0230590529547E-7,1.76881987643036E-5,-5.77770686941356E-8,114.9875717,114.9875717,99.4721298217773,99.4721298217773,56.5602029085829,20.5656996075429,25.186911,0,0,0,40,4374,111.74095,99.4721298217773,,,,,,,,,,,,,0,,,,-0.0049,,,,,,114.9875717,,,,
,23115869.435,111.4992294,99.4721298217773,1.81555278428958E-5,3.08672825651443E-7,1,0.999253354069792,40.0298881530762,1.99674069329705,16.3100007921457,0.000206400190527791,3.58821051183875E-5,0.25,-2.63825289719151E-8,1.82563329427262E-5,2.25190328380567E-8,111.4992294,111.4992294,99.4721298217773,99.4721298217773,56.1279623374482,20.5767433817559,24.807261,0,0,0,40,4374,108.3798,99.4721298217773,,,,,,,,,,,,,0,,,,0,,,,,,111.4992294,,,,
,23116007.66,107.9990768,99.4721298217773,1.75179099150835E-5,2.91045617431006E-7,1,0.999253354069792,40.0298881530762,1.99670946829938,16.3100007921457,0.000199323893906366,3.36420420099871E-5,0.25,-1.14357367009308E-7,1.76157231012103E-5,-6.49761655991488E-8,107.9990768,107.9990768,99.4721298217773,99.4721298217773,56.6344576179098,20.5744343982804,25.186911,0,0,0,40,4374,104.98185,99.4721298217773,,,,,,,,,,,,,0,,,,-0.0049,,,,,,107.9990768,,,,
,23116147.045,104.477829,99.4721298217773,1.76833622075999E-5,3.08183903356546E-7,1,0.999253354069792,40.0298881530762,1.99675955315761,16.3100007921457,0.000200982765573947,3.52668802722813E-5,0.25,-3.53078578709204E-9,1.77818351114535E-5,4.99724539775764E-8,104.477829,104.477829,99.4721298217773,99.4721298217773,56.7939098358329,20.5805301468899,24.807261,0,0,0,40,4374,101.549,99.4721298217773,,,,,,,,,,,,,0,,,,0,,,,,,104.477829,,,,
,23116265.96,101.489006,99.4721298217773,1.7581116760536E-5,2.61231764456882E-7,1,0.999253354069792,40.0298881530762,2.00943669323356,16.380000859499,0.000201514449374088,3.25129465761152E-5,0.25,-2.47906903878446E-7,1.7679612285926E-5,-1.93228013182043E-7,101.489006,101.489006,99.4721298217773,99.4721298217773,56.9009929429675,20.5792693123911,24.427608,0,0,0,40,4374,98.603,99.4721298217773,,,,,,,,,,,,,0,,,,-0.00245,,,,,,101.489006,,,,
,23116407.095,97.90488815,99.4721298217773,1.77499789726991E-5,2.31566004905384E-7,1,0.999253354069792,40.0298881530762,1.996660383038,16.380000859499,0.000201958817880123,3.40538029691203E-5,0.25,-1.28314022721825E-7,1.78485210234689E-5,-6.86674958441092E-8,97.8621521,97.9476242,99.4721298217773,99.4721298217773,56.1592274782175,20.578322893563,24.427608,0,0,0,40,4374,95.09905,99.4721298217773,,,,,,,,,,,,,0,,,,0.00245,,,,,,97.90488815,,,,
,23116544.76,94.42772295,99.4721298217773,1.76974353269294E-5,2.76968653336256E-7,1,0.999253354069792,40.0298881530762,1.99666072077827,16.380000859499,0.000201338080902923,3.40232597899801E-5,0.25,-1.25660385538195E-7,1.77947578166936E-5,-6.20908098857892E-8,94.3911209,94.464325,99.4721298217773,99.4721298217773,56.7571732954291,20.5804897198542,24.047956,0,0,0,40,4374,91.66805,99.4721298217773,,,,,,,,,,,,,0,,,,-0.00245,,,,,,94.42772295,,,,
,23116682.46,90.9263344,99.4721298217773,1.79887768275228E-5,2.58605847060677E-7,1,0.999253354069792,40.0298881530762,1.99662063297374,16.4500009268522,0.000204746418245584,3.39378047452936E-5,0.25,-1.88789462348784E-7,1.80865391512331E-5,-1.19945246446001E-7,90.8816071,90.9710617,99.4721298217773,99.4721298217773,56.516431711506,20.5778248600747,24.047956,0,0,0,40,4374,88.2789,99.4721298217773,,,,,,,,,,,,,0,,,,-0.00245,,,,,,90.9263344,,,,
,23116816.8,87.491745,99.4721298217773,1.77574653682856E-5,3.10890885420641E-7,1,0.999253354069792,40.0298881530762,1.99655907213443,16.4500009268522,0.000202185077995068,3.29404907468097E-5,0.25,-2.40131058701752E-7,1.78523164522118E-5,-1.67637971381707E-7,87.491745,87.491745,99.4721298217773,99.4721298217773,56.5195582255829,20.5781318341612,24.427608,0,0,0,40,4374,85.0043,99.4721298217773,,,,,,,,,,,,,0,,,,0.00245,,,,,,87.491745,,,,
,23116955.15,83.9416962,99.4721298217773,1.79025090176058E-5,2.49932231508273E-7,1,0.999253354069792,40.0298881530762,1.99669526014133,16.4500009268522,0.000203743234416064,3.36379492175547E-5,0.25,-2.09637611791943E-7,1.79953000014416E-5,-1.30824050614004E-7,83.9013901,83.9820023,99.4721298217773,99.4721298217773,56.7165286124291,20.585600397306,23.668306,0,0,0,40,4374,81.6144,99.4721298217773,,,,,,,,,,,,,0,,,,-0.00245,,,,,,83.9416962,,,,
,23117091.085,80.4720535,99.4721298217773,1.78253727953695E-5,3.17947457326991E-7,1,0.999253354069792,40.0298881530762,1.99695734953805,16.5199991315603,0.000202999625138085,3.26532278913673E-5,0.25,-2.88379460988314E-7,1.79146031851581E-5,-2.04342450798686E-7,80.4720535,80.4720535,99.4721298217773,99.4721298217773,56.7016776705637,20.5800761656499,23.288654,0,0,0,40,4374,78.2946,99.4721298217773,,,,,,,,,,,,,0,,,,0.0049,,,,,,80.4720535,,,,
,23117227.285,76.9948502,99.4721298217773,1.78476589197688E-5,2.6456454777164E-7,1,0.999253354069792,40.0298881530762,1.99660928315239,16.5199991315603,0.000202587478334134,3.59384407893243E-5,0.25,-8.13881454593896E-9,1.79308785028068E-5,8.38664369821741E-8,76.9948502,76.9948502,99.4721298217773,99.4721298217773,56.5070521692752,20.5830299943569,22.909004,0,0,0,40,4374,74.95125,99.4721298217773,,,,,,,,,,,,,0,,,,0.0049,,,,,,76.9948502,,,,
,23117365.04,73.4805222,99.4721298217773,1.7862102599004E-5,2.88294523875613E-7,1,0.999253354069792,40.0298881530762,1.99674636980608,16.5199991315603,0.000202689732811407,3.59839973394257E-5,0.25,-1.28220693935415E-8,1.79391597513194E-5,8.62576819746951E-8,73.4805222,73.4805222,99.4721298217773,99.4721298217773,56.5938129349098,20.5841251224791,22.909004,0,0,0,40,4374,71.5701,99.4721298217773,,,,,,,,,,,,,0,,,,0,,,,,,73.4805222,,,,
,23117504.3,69.9382858,99.4721298217773,1.79271183094499E-5,2.81997452743744E-7,1,0.999253354069792,40.0298881530762,2.00925775773269,16.5899991989136,0.000205097858169303,3.32552427719158E-5,0.25,-2.88524150595774E-7,1.79979442458417E-5,-1.82669226037552E-7,69.9382858,69.9382858,99.4721298217773,99.4721298217773,56.4468667732944,20.5843823538999,23.288654,0,0,0,40,4374,68.1359,99.4721298217773,,,,,,,,,,,,,0,,,,-0.0049,,,,,,69.9382858,,,,
,23117640.235,66.4526596,99.4721298217773,1.80322854721806E-5,3.1462221706111E-7,1,0.999253354069792,40.0298881530762,2.00871960648832,16.5899991989136,0.000205745909524348,3.55996753492905E-5,0.25,-1.06699805371847E-7,1.8092423711914E-5,7.91658089140217E-9,66.4526596,66.4526596,99.4721298217773,99.4721298217773,56.6813553290637,20.5942918764718,22.909004,0,0,0,40,4374,64.7805,99.4721298217773,,,,,,,,,,,,,0,,,,0.00245,,,,,,66.4526596,,,,
,23117777.345,62.9829597,99.4721298217773,1.8050852770712E-5,3.04183250207008E-7,1,0.999253354069792,40.0298881530762,2.00877683013189,16.5899991989136,0.000205964836428584,3.48296961746576E-5,0.25,-1.8264552355202E-7,1.80992791759923E-5,-6.10533044553962E-8,62.9829597,62.9829597,99.4721298217773,99.4721298217773,56.7892200647175,20.5950879013555,22.529354,0,0,0,40,4374,61.42265,99.4721298217773,,,,,,,,,,,,,0,,,,0,,,,,,62.9829597,,,,
,23117914.705,59.4477539,99.4721298217773,1.78325786967636E-5,2.4819557430438E-7,1,0.999253354069792,40.0298881530762,1.98465771362038,16.6400000452995,0.000200901537902683,3.44206157037167E-5,0.25,-1.478831035275E-7,1.78657196593341E-5,-2.16209868822376E-8,59.4477539,59.4477539,99.4721298217773,99.4721298217773,56.8501870892175,20.5970434617961,22.529354,0,0,0,40,4374,58.052,99.4721298217773,,,,,,,,,,,,,0,,,,-0.0049,,,,,,59.4477539,,,,
,23118053.435,55.9055328,99.4721298217773,1.79458437068045E-5,2.72908850009322E-7,1,0.999253354069792,40.0298881530762,1.98431176478894,16.6400000452995,0.000202656164374426,3.070312726094E-5,0.25,-5.0013983514978E-7,1.79648514601151E-5,-3.68930925485695E-7,55.9055328,55.9055328,99.4721298217773,99.4721298217773,56.1451581648713,20.5976351692772,21.3904,0,0,0,40,4374,54.64485,99.4721298217773,,,,,,,,,,,,,0,,,,0,,,,,,55.9055328,,,,
,23118188.1,52.4837685,99.4721298217773,1.78637282714962E-5,2.31809230867159E-7,1,0.999253354069792,40.0298881530762,1.98436810557404,16.6400000452995,0.000200982071209834,3.35950694740265E-5,0.25,-2.27051444665596E-7,1.78628598295684E-5,-9.41401647295104E-8,52.4837685,52.4837685,99.4721298217773,99.4721298217773,57.4301554504868,20.5982261858676,21.770052,0,0,0,40,4374,51.3517,99.4721298217773,,,,,,,,,,,,,0,,,,0.00245,,,,,,52.4837685,,,,
,23118323.77,48.9607582,99.4721298217773,1.81504344959634E-5,2.76839441967926E-7,1,0.999253354069792,40.0298881530762,1.98470324769846,16.7100001126528,0.000204187174944845,3.32309846668171E-5,0.25,-3.07879111227293E-7,1.81313826824951E-5,-1.73346316975705E-7,48.9607582,48.9607582,99.4721298217773,99.4721298217773,56.7985996069483,20.5919613588068,20.631098,0,0,0,40,4374,48.05385,99.4721298217773,,,,,,,,,,,,,0,,,,0,,,,,,48.9607582,,,,
,23118460.97,45.4441566,99.4721298217773,1.81645255799235E-5,2.87000803952003E-7,1,0.999253354069792,40.0298881530762,1.98452191582031,16.7100001126528,0.000204451339404001,3.13712405655831E-5,0.25,-4.69612527729617E-7,1.81280602124486E-5,-3.3794315226262E-7,45.4441566,45.4441566,99.4721298217773,99.4721298217773,56.411693489929,20.601099886907,19.112494,0,0,0,40,4370,44.71105,99.4721298217773,,,,,,,,,,,,,0,,,,-0.00245,,,,,,45.4441566,,,,
,23118598.215,41.9464989,99.4721298217773,1.79260280108649E-5,3.67986639975262E-7,1,0.999253354069792,40.0298881530762,1.98471660192759,16.7100001126528,0.000201440169246402,3.1790904896899E-5,0.25,-3.80968606538095E-7,1.78725379877345E-5,-2.56780892419353E-7,41.9464989,41.9464989,99.4721298217773,99.4721298217773,56.6680676442368,20.5979670389019,19.112494,0,0,0,40,4370,41.3407,99.4721298217773,,,,,,,,,,,,,0,,,,0,,,,,,41.9464989,,,,
,23118736.195,38.4372063,99.4721298217773,1.80723919015313E-5,2.83980632490408E-7,1,0.999253354069792,40.0298881530762,2.00935507522267,16.7599990963936,0.00020572316630146,3.0166455713642E-5,0.25,-5.74304027754191E-7,1.80049879515943E-5,-4.55532250380109E-7,38.4372063,38.4372063,99.4721298217773,99.4721298217773,56.9572701963522,20.5884835663908,18.353191,0,0,0,40,4370,37.94335,99.4721298217773,,,,,,,,,,,,,0,,,,-0.00245,,,,,,38.4372063,,,,
,23118875.115,34.9501038,99.4721298217773,1.79437957153312E-5,2.86106477125505E-7,1,0.999253354069792,40.0298881530762,2.00914389702531,16.7599990963936,0.000203555559054204,3.29873354109593E-5,0.25,-2.91940235832094E-7,1.78633055264245E-5,-1.82827844084169E-7,34.9501038,34.9501038,99.4721298217773,99.4721298217773,56.7149653553906,20.5936129611345,18.353191,0,0,0,40,4370,34.5136,99.4721298217773,,,,,,,,,,,,,0,,,,0,,,,,,34.9501038,,,,
,23119011.875,31.4459476,99.4721298217773,1.79944135881753E-5,2.91486681703257E-7,1,0.999253354069792,40.0298881530762,1.99655858543944,16.7599990963936,0.000202937796511766,3.21517768172582E-5,0.25,-3.49116384882775E-7,1.79052759891721E-5,-2.46530748894875E-7,31.4459476,31.4459476,99.4721298217773,99.4721298217773,57.0463758475445,20.592047188366,17.593889,0,0,0,40,4370,31.1344,99.4721298217773,,,,,,,,,,,,,0,,,,0,,,,,,31.4459476,,,,
,23119149.64,27.9748917,99.4721298217773,1.79556622021506E-5,3.15810355392235E-7,1,0.999253354069792,40.0298881530762,1.98510482101673,16.8099999427795,0.000201146655367204,3.28735733690763E-5,0.25,-2.54752050038924E-7,1.78599877668305E-5,-1.58864573689943E-7,27.9748917,27.9748917,99.4721298217773,99.4721298217773,56.3679222928521,20.5971594692425,16.454937,0,0,0,40,4370,27.70745,99.4721298217773,,,,,,,,,,,,,0,,,,0,,,,,,27.9748917,,,,
,23119288.605,24.4794884,99.4721298217773,1.80141502133316E-5,2.97828697699542E-7,1,0.999253354069792,40.0298881530762,1.9849124940168,16.8099999427795,0.000201639615244178,3.35241643542542E-5,0.25,-2.0152493282596E-7,1.79139109717936E-5,-1.10039328825984E-7,24.4794884,24.4794884,99.4721298217773,99.4721298217773,56.7743691228522,20.5960128108175,16.075285,0,0,0,40,4370,24.26015,99.4721298217773,,,,,,,,,,,,,0,,,,0,,,,,,24.4794884,,,,
,23119429.29,20.9708633,99.4721298217773,1.78177069263561E-5,3.1247126564985E-7,1,0.999253354069792,40.0298881530762,1.98512748407031,16.8099999427795,0.000199254915595883,3.41876658456581E-5,0.25,-1.04518675059973E-7,1.77160166651596E-5,-1.71931282478495E-8,20.9708633,20.9708633,99.4721298217773,99.4721298217773,56.3093001539098,20.5867600452918,15.315984,0,0,0,40,4370,20.7608,99.4721298217773,,,,,,,,,,,,,0,,,,0,,,,,,20.9708633,,,,
,23119548.235,17.9682522,99.4721298217773,1.7853880333046E-5,2.6237894615722E-7,1,0.999253354069792,40.0298881530762,2.00891044887596,16.8399997055531,0.000201882957097808,3.49464876214193E-5,0.25,-7.74569016753706E-8,1.77513478456303E-5,9.06574320402183E-9,17.9682522,17.9682522,99.4721298217773,99.4721298217773,56.6219515616021,20.585625622788,14.936333,0,0,0,40,4370,17.80925,99.4721298217773,,,,,,,,,,,,,0,,,,0.0049,,,,,,17.9682522,,,,
,23119687.205,14.4900913,99.4721298217773,1.79369683015267E-5,3.11732531959805E-7,1,0.999253354069792,40.0298881530762,2.00916339851193,16.8399997055531,0.000203798984960263,2.97657919390296E-5,0.25,-5.51105294367141E-7,1.78364594404618E-5,-4.61429501819999E-7,14.4900913,14.4900913,99.4721298217773,99.4721298217773,56.2053435608521,20.589583626331,13.797379,0,0,0,40,4370,14.3418,99.4721298217773,,,,,,,,,,,,,0,,,,0.0049,,,,,,14.4900913,,,,
,23119825.945,10.9892635,99.4721298217773,1.7877910120345E-5,3.13998730772785E-7,1,0.999253354069792,40.0298881530762,2.00873317887936,16.8399997055531,0.000202400976530671,3.35313809551632E-5,0.25,-2.06806195997832E-7,1.77762207425931E-5,-1.19396449648362E-7,10.9892635,10.9892635,99.4721298217773,99.4721298217773,56.7868751791599,20.588670705338,13.417728,0,0,0,40,4370,10.8779,99.4721298217773,,,,,,,,,,,,,0,,,,0.00245,,,,,,10.9892635,,,,
,23120028.74,10.0050163,99.4721298217773,1.80276681422586E-5,3.11007806740621E-7,1,0.999253354069792,40.0298881530762,1.99646042376703,16.8699994683266,0.000203396762429904,3.08568064027588E-5,0.25,-4.54117127622066E-7,1.79263410903817E-5,-3.64565231685798E-7,10.0050163,10.0050163,99.4721298217773,99.4721298217773,56.3624508932175,20.5797794330879,12.658426,0,0,0,40,4369,9.99095,99.4721298217773,,,,,,,,,,,,,0,,,,-0.0049,,,,,,10.0050163,,,,